model
size = 16 13 11, scale = 0.05, origin = -y
material 
  colors = A:#FFC96B B:#FE8E8E C:#90713B D:#4D2A0A E:#FFF
voxels
2-10(12A4-)12A36-4(12A4-)10A-A4-2(9A-2A5(4-12A)36-5(12A4-))2(9A-2A5(4-12A)4-2(2A14-)5(12A4-))2(9A-2A4-)2(A10-A4-)12A4-12A2(14-2A)5(4-12A)2(4-9A-2A)2(4-A10-A)2(4-12A)2(14-2A)5(4-12A)4-A9-2A3(4-A10-A)2(4-12A)36-5(12A4-)A9-2A3(4-A10-A)2(4-12A)36-8A2B2A2-2C10A2-2C2-2(10A-A4-)12A4-A9-2A3(4-A10-A)2(4-12A)36-A2B6A2BA3-2C2B6A2B2C3-2(A2DA4EA2DA4-)6(12A4-)12A34-
