model
size = 3 28 4, scale = 0.05, origin = -y
material 
  colors = A:#003 B:#EEE C:#444 D:#FF3 E:#AAA
voxels
31-A80-A56-A2(2-B3(2-A))-3A-D16(2-B)5-3(A2-)B3(2-A)2-B2-A-3A-D16(2-C)2-E-
