model
size = 3 28 4, scale = 0.05, origin = -y
material 
  colors = A:#003 B:#06C C:#EEE D:#111 E:#222 F:#888
voxels
31-A80-A56-A2(2-C3(2-A))-3A-D7(2-B)2-F2-E7(2-A)5-3(A2-)C3(2-A)2-C2-A-3A-D7(2-A)2-E2-F8(2-B)-
