model
size = 28 32 29, scale = 0.05, origin = -y
material 
  colors = A:#111 B:#0C0C0C C:#161616 D:#000 E:#FF0 F:#404040 G:#EEE
voxels
458-8B886-2B8-2B18-C2ABAC2A20-4AC3A828-2B12-2B14-2A8-2A16-BA8-AC18-6ABA21-2AEA2E22-2(2AE)24-2A718-B16-B11-3(2A12-)2B14-C2A6-3A16-A2E6AE2A16-A2E8AC17-C2AE3AE2A19-2AE3AEA21-E4AE659-2B16-2B9-A16-A10-A16-C11-BA12-AC12-5A6-4AC13-4A6-3AB14-B13A15-AC10A17-B9A19-AE4AEA22-A2EA603-2B18-2B7-AB16-BA8-AB16-BC9-A16-A10-3A2-A9-2AC10-3A12-3A11-CA12-2A12-AC2A8-3AC13-C2A8-3A15-B9AEA17-AE5A2EA20-2A2EAE573-B22-B5-C20-A6-A20-B7-C2B14-2BA8-C2A14-3A8-B2A14-3A9-2A14-2A10-3A12-2AC11-2A12-2A13-C3A6-3AB15-12A17-AE8A20-6A544-B24-B3-A22-A4-A22-A5-A20-A6-3AB14-B2AC7-2AB14-BAC8-2AB14-B2A8-3AB12-B2AB9-BAB12-B2A11-3A10-3A12-5A6-3A2C14-12A17-8ABA21-C2AB517-BA22-DB3-A22-A4-C22-A5-A20-A6-2A18-2A6-BA18-2A6-2A18-2A7-2A16-AB8-CA16-2A9-CA2B10-2B2A11-C2A10-2AB13-14A15-B10AB18-4A2C2A487-D24-D-BD24-DB-A24-A2-A24-A3-C22-A4-2A20-2A4-2A20-AB5-C20-A6-2A18-2A7-A18-A8-3A14-3A9-3AB10-B3A11-5A6-4AC13-14A16-10A20-2(BA)CA432-D24-D2-D24-D-BD24-DB-A24-A2-A24-A3-A22-A4-2A20-2A4-2A20-AB4-2A20-2A5-2A18-2A6-BA18-AC7-2A16-2A8-C2A2-B8-B2-3A9-B4A8-5A11-5A6-4AC14-12A18-AC2AC3A431-2(D24-D2-)D24-D-B26-BA26-A-B24-B3-B2(22-A4-A)22-A4-2A20-AB5-A20-A6-3A16-2AC7-C2A14-2AB9-4AB8-B3AB11-4AB6-B3AC13-C4A4-3A2C16-2(AC)2ACB2A22-2C378-2(D24-D2-)D24-D29-B26-BA26-A-A24-A2-CA22-2A2-2A22-2A3-A22-C2(4-2A20-2A)5-2A18-2A7-2A16-2A8-CG2A12-4A9-4A-B6-B-2ACA12-4AB4-B4A15-2AC8AB19-4ACA40-F24-F31-2(D22-D4-)D22-D5-D20-D6-D20-D5-3(D22-D4-)D22-D3-2(D24-D2-)D24-D57-B26-BA26-A-A24-A2-2A22-2A2-CA22-AC3-C22-A4-2A20-2A4-CA20-AC5-2A18-2A6-3A16-2AC7-AG2A12-3AC9-4A10-4A11-C3A2(2-B)2-3AB14-BC10A19-2AC3A12-F24-F27-F2-F3(24-D2-D)24-D3-2(D22-D4-)D22-D3-4(D24-D2-)D24-D85-B26-BA26-A-A24-A2-2A22-AC2-2A22-2A2-BA22-2A3-2A20-AB4-2A20-AC5-CA18-2A6-AGA16-3A7-BG2A12-4A9-4A10-4A11-4A3-2B3-4A14-AC10A18-ACAB3AC11-F24-F27-F2-F3(24-D2-D)24-D3-2(D22-D4-)D22-D3-4(D24-D2-)D24-D113-B26-B-A24-A3(2-2A22-2A)3-2A20-2A4-CA20-AC5-2A18-2A6-AGA16-2AC7-AG2A12-4A9-C3A10-3AB11-BC2A3-2B3-3AB14-10ABA18-5ACBA39-F24-F31-2(D22-D4-)D22-D5-D20-D6-D20-D5-3(D22-D4-)D22-D3-2(D24-D2-)D24-D85-B26-B-A24-A2-2A22-2A2-CA22-2A3-A22-C2(4-2A20-2A)5-2A18-2A6-C2A16-2AC7-AG2A12-3AC9-4A10-4A11-B3A2(2-B)2-2ACA14-10ACA19-4ACA376-2(D24-D2-)D24-D57-B26-B-A24-A2-2A22-2A2-2A22-AB3-A22-C4-2A20-AB4-BA20-2A5-CA18-AC7-2A16-AC8-AG2A12-4A9-4A-B6-B-4A12-4AB4-B3AC15-B9ACA19-2CAB2A404-2(D24-D2-)D24-D29-B26-B-A24-A3-2(A22-A4-)A22-C4-2A20-AC5-A20-A6-B2A16-2AB7-3A14-3A9-4AB8-B4A11-4AB6-B4A13-5A4-5A16-CA2C6A22-CA406-4(D24-D2-)B24-B3-A22-A4-2A20-2A2(4-CA20-AC)5-2A18-AC6-2A18-2A7-BA16-AC8-C2A2-B8-B2-3A9-5A8-5A11-B4A6-4AB14-12A18-3AC4A459-3(D24-D2-)B24-B3-C22-A2(4-BA20-2A)5-A20-A6-2A18-2A7-A18-A8-C2A14-3A9-3AB10-B2AC11-5A6-4AC13-C11ACA16-9AC20-B4AC489-2(D22-D4-)B22-B5-A20-A6-2A18-2A6-2A18-AC6-CA18-AB7-CA16-2A8-2A16-2A9-2A2B10-2B2A11-3A10-3A13-C12AC15-AB10A18-ACB5A544-D22-D4-B22-B5-A20-A6-3AB14-B3A7-2(2AB14-B2A8-)3AB12-B2AB9-2AB12-B2A11-3A10-3A12-B4A6-3ABA14-C11A17-8ABA21-BC2A575-B20-B7-A2B14-2BA8-3A14-3A8-3A14-2AC9-2A14-2A10-B2A12-2AC11-CA12-AB13-4A6-4A15-C11A17-C7A2C20-CA2C2A603-2B16-2B9-A16-A10-3A12-3A10-ACA12-3A11-CA12-AB12-4A8-2ACB13-BCA8-2AC15-12A17-8ABA20-2(B2A)632-B16-B11-2(2A12-)4A8-4A13-3A8-2AC14-3A8-2AC15-12A17-8ABC19-3AC4A22-2ABC662-2B12-2B14-CA8-2A16-10ACA16-C10AC17-BC5AC2A19-8A21-CAB3A719-2B8-2B18-7AB21-3AC2A22-BAC3A24-2A779-8B374-
