model
size = 19 21 11, scale = 0.05, origin = -y
material 
  colors = A:#FFC96B B:#FCDFAC C:#FE8E8E D:#90713B E:#4D2A0A F:#FFF
voxels
154-10(12A7-)12A50-2A4-2A11-2A4-2A8-2(5A4B4A6-)3(13A6-)13A4-4(12A7-)10A-A7-9A-2A5(7-12A)50-2A4-2A11-2A4-2A8-3ABA4B4A6-A2B10A4(6-13A)4-5(12A7-)9A-2A5(7-12A)85-2(13B6-B11AB2(6-B12A)6-B14A4-B14A4(2-12A3-2A)2-12A7-9A-2A5(7-12A)7-2A17-2A57-)13B6-B11AB2(6-B12A)6-B11A-2A4-B14A2-2(12A7-)2(12A-4A2-)12A2(-2B4-9A-2A)2(7-A10-A)2(7-12A)2(17-2A)47-13B6-B11AB2(6-B12A)6-B11A-2A4-B14A2-2(12A7-)2(12A-4A2-)12A2(-2B4-9A-2A)2(7-A10-A)2(7-12A)2(17-2A)2(9-2A)6-2A9-2A6-2A9B2A5(6-13A)4-5(12A7-)A9-2A3(7-A10-A)2(7-12A)47-2(2A9-2A6-)2(2A9B2A6-)3(13A6-)13A4-5(12A7-)A9-2A3(7-A10-A)2(7-12A)197-8A2C2A5-2D10A2-2D5-2(10A-A7-)12A7-A9-2A3(7-A10-A)2(7-12A)197-A2C6A2CA6-2D2C6A2C2D6-2(A2EA4FA2EA7-)6(12A7-)12A43-
