model
size = 29 24 31, scale = 0.05, origin = -y
material 
  colors = A:#CFB53B B:#FF3 C:#DDD D:#F09 E:#111 F:#FFF
voxels
89-5A15-3A152-24A439-2A27-2A20-3A4-5A15-3A8-5A11-3A13-15A69-22A6-A21B2A4-26A31-27A-87A-27A234-3A22-2A3-2A20-3A4-5A15-3A8-5A11-3A13-15A41-19A9-A19B2A6-A21B2A4-A23B2A2-27A-32A3(23B6A)23B3A-27A176-2A24-2A-3A22-2A3-2A20-3A4-5A15-3A8-5A11-3A13-15A14-16A11-A-17A9-AB-17B2A6-A2B-18B2A4-A3B-19B2A-6A-28A-25A3(3B-19B6A)3B-19B5A4B-20B2A-27A147-2A24-2A-3A22-2A3-2A20-3A4-5A15-3A8-5A11-3A13-15A13-17A11-19A9-A19B2A6-A21B2A4-A23B2A-61A3(23B6A)23B5A25B31A-27A118-2(2A24-2A-3A22-2A3-2A20-3A4-5A15-3A8-5A11-3A13-15A13-17A11-19A9-A19B2A6-A21B2A4-A23B2A-61A3(23B6A)23B5A25B31A-27A3-26A89-)2A24-2A-3A22-2A3-2A20-3A4-5A15-3A8-5A11-3A13-15A13-17A11-19A9-A19B2A6-A21B2A4-A23B2A-61A3(23B6A)23B5A25B31A-27A3-26A4-24A61-2(2A24-2A-3A22-2A3-2A20-3A4-5A15-3A8-5A11-3A13-15A13-17A11-19A9-A19B2A6-A21B2A4-A23B2A-61A3(23B6A)23B5A25B31A-27A3-26A4-24A6-22A33-)2A24-2A-3A22-2A3-2A20-3A4-5A15-3A8-5A11-3A13-15A13-17A11-19A9-A19B2A6-A21B2A4-A23B2A-61A3(23B6A)23B5A25B31A-27A3-26A4-24A6-22A16-CF15-2A24-2A-3A22-2A3-2A20-3A4-5A15-3A8-5A11-3A13-15A13-17A11-19A9-A19B2A6-A21B2A4-A23B2A-61A3(23B6A)23B5A25B31A-27A3-26A4-24A6-22A16-FC15-2A24-2A-3A22-2A3-2A20-3A4-5A15-3A8-5A11-3A13-15A13-17A11-19A9-A19B2A6-A21B2A4-A23B2A-61A3(23B6A)23B5A25B31A-27A3-26A4-24A6-22A33-2A24-2A-3A22-2A3-2A20-3A4-5A15-3A8-5A11-3A13-15A13-17A11-19A9-A19B2A6-A21B2A4-A23B2A-61A3(23B6A)23B5A14DB10D31A-27A3-26A4-24A61-2A24-2A-3A22-2A3-2A20-3A4-5A15-3A8-5A11-3A13-15A13-17A11-19A9-A19B2A6-A21B2A4-A23B2A-61A7DB15D6A13D2B8D2(6A23B)5A14B-10B31A-27A3-25A90-2A24-2A-3A22-2A3-2A20-3A4-5A15-3A8-5A11-3A13-15A13-17A11-19A9-A19B2A6-A21B2A4-A23B2A2-2A-24A-32A5D2B-6B2D3B4D6A5D8B-2(2D3B4D6A5D9B)2D3B4D19A-12A-2A-24A3-26A4-23A91-2A24-2A-3A22-2A3-2A20-3A4-5A15-3A8-5A11-3A13-15A13-17A11-19A9-A19B2A6-A21B2A4-A6(23B2A2-2A)23B2A2-A25BA2-27A3-25A119-2A24-2A-3A22-2A3-2A20-3A4-5A15-3A8-5A11-3A13-15A13-A9-7A11-19A9-A19B2A6-A21B2A4-AB-21BA4-A23B2A2-2A23B2A2-27A3(2-2A23B2A)2-27A3-25A5-23A120-2A24-2A-3A22-2A3-2A20-3A4-5A15-3A8-5A11-3A13-15A14-15A12-19A9-A19B2A6-A21B2A5-A22B6(A4-A23B)A4-25A5-23A149-2A24-2A-3A22-2A3-2A20-3A4-5A15-3A8-5A11-3A13-15A50-2A18-19A9-21A7-6(23A6-)23A7-21A16-5A158-2A24-2A-3A22-2A3-2A20-3A4-5A15-3A8-5A11-3A13-15A48-5C23-7C20-11C17-13C16-13C15-3(15C14-)15C15-13C17-11C19-9C21-7C23-5C100-2A24-2A-3A22-2A3-2A20-3A4-5A15-3A8-5A11-3A13-15A131-5E3-5E18-E7-2E19-2E5-2E21-E5-2E21-2E3-2E23-E3-2E23-2E2(-2E25-E)-E27-2E130-7(2A24-2A-3A22-2A3-2A20-3A4-5A15-3A8-5A11-3A13-15A530-)2A24-2A-3A22-2A3-2A20-3A4-5A15-3A2(11-2A)14-15A530-2A24-2A-3A22-2A3-2A20-3A4-5A15-3A8-5A11-3A13-15A529-
