model
size = 20 32 26, scale = 0.05, origin = -y
material 
  colors = A:#630 B:#555 C:#888 D:#996 E:#330 F:#363 G:#800 H:#777 I:#AAA J:#111 K:#6F3 L:#444
voxels
64-3(K2(19-D)19-)K418-3F4A13-2F5A2(13-7D)13-6AF2(13-7D)13-3A2F2A2(13-7D)13-AF5A15-F2AE16-A2-A2(16-A2-E)3(16-A2-A)3(16-F2-A)5(16-A2-A)16-A-GA16-A-J2(A16-A2-)A53-F8A2(11-8AF2(11-9D))11-F8A2(11-9D)11-9A11-2EF5AE11-2EFABCA2E11-3FABCA2E11-A2FABC2AE11-E3ABCA2E11-E3ABC2AE11-A2FABC3A11-2AFABC3A11-3FABC2AE11-2(FA)2(BC2AE11-F3A)2(BC3A11-4A)BC3A11-A2EA2(BC3A11-AE2A)BCA2E11-4ABC2AE14-A2-A16-A2-A13-A4F5A9-10AF5(9-11A)3(9-F10A)3(9-11A)2(9-5ABC4A)3-A5-5ABC3AE3-2A4-5ABC3AE4-A4-5ABC3AE4-2A3-E4ABC4A5-A3-E4ABC4A5-2A2-F4ABC3AE6-A2-E4ABC3AE6-E2-F4ABC3AE6-2E2(-F4ABC3AE7-E)-5A2(BC4A7-E-F4A)BC4A7-A-F4ABC3AE6-EF-F4ABC3A2E5-F3-4ABC3A-2E3-EA6-A2-A4-3E2A4-AF8A9-10A2(F9-D9A)F9-11A9-D10A9-D9ADB8-10AD2(B8-D10A)D8-11A2D2(7-D10A-D)7-5ABC4A-2D5-GH4ABC4A2-DA4-2J4ABC4A3-2A4-5ABC4A4-E4-5ABC4A4-AE3-E4ABC4A5-A3-5ABC3AE5-2A2-F2(4ABC3AE6-A2-E)4ABC3AE6-2A-F4ABC4A7-A-5ABC3AE7-E-5ABC4A7-F-F4ABC3AE7-E-F4ABC3AE7-A-F4ABC3AE6-AF-F4ABC4AE5-F3-A2EABC3A-AE3-AF6-A2-A4-A2E2A4-3E7A9-10A2(F9-D9A)F9-11A9-D10A9-D9ADB8-10A2D8-D10AB8-D10AD8-11A2D2(7-D10A-D)7-5ABC4A-2D6-H4ABC4A2-DA5-I4ABC4A3-2A4-5ABC4A2(4-E)4ABC4A4-2A3-E4ABC4A5-A3-E4ABC3AE5-2A2(2-F4ABC3AE6-A)2-E4ABC3AE6-2A2(-E4ABC4A7-F)-5A2(BC4A7-F-E4A)BC3AE7-A-E4ABC3AE6-AF-F4ABC4AE5-F3-F3ABC3A-2A3-AF6-E2-A4-AE3A4-2F8E9-10AF9-D9AF8-2D9AF2(8-L11A2(8-2D10A))8-L11A2(9-D10A)9-5ABC4A9-H4ABC4A3-A5-I4ABC4A3-2A4-E4ABC4A4-E4-5ABC4A4-2A3-E4ABC4A5-A3-E4ABC3AE5-2A2-F4ABC3AE6-A2-F4ABC4A6-A2-5ABC3AE6-2A-E4ABC3AF7-A2(-5ABC4A7-F)2(-E4ABC4A7-F)-F4ABC3AE6-AF-F4ABC5A5-A3-F3ABC3A-2A3-AF6-A2-A4-2E2AF4-A3F4A2E9-10A2(E9-D9A)F9-10AF2(9-D10A)9-11A2(9-D9AE)9-10AE2(9-D10A)9-E4ABC4A9-H4ABC4A9-I4A2(BC4A9-5A)BC4A9-E4ABC3AE9-5ABC3AE9-F4ABC3AF9-5A2(BC3AE9-E4A)BC3AF2(9-5ABC4A)9-E4ABC4A9-E4ABC3AE9-E4ABC4A9-F4ABC4A10-F3ABC3A14-E2-E13-AFA2F4AE9-10A2(E9-D9A)E9-10AF2(9-D10A)9-F10A9-D9AE9-D9AF9-F9AF2(9-D10A)9-F4ABC4A9-H4ABC4A9-I4A3(BC4A9-5A)2(BC3AE9-F4A)BC3AF9-E4ABC3AE9-E4ABC4A9-5ABC3AF9-5A2(BC4A9-E4A)BC4A9-5ABC3AE2(9-5ABC4A)10-AF2ABC3A14-A2-A13-A2FAF5A9-10A2(E9-D9A)E9-F9AF9-D10A9-D9AE9-F2(9AE9-D)10A9-10AF9-D9AF9-D10A9-E4ABC4A9-H4ABC3AF9-I4A2(BC3AF9-5A)2(BC3AE9-5ABC3AE9-E4A)BC3AE9-5ABC4A9-5ABC3AF3(9-5ABC4A)9-5ABC3AE2(9-5ABC4A)10-2F2ABC3A14-A2-A13-2A3F5A9-11A9-D9AF9-D10A9-F9AF2(2(9-D9AE)9-11A)2(9-D9AF)9-5ABC3AF9-H4ABC3AF9-I4A2(BC3AE9-5A)BC3AE9-F4ABC4A9-F4ABC3AE9-5ABC3AE9-E4ABC4A9-5ABC3AE9-3(5ABC3AF8-G)5ABC4A8-G2(5ABC3AE9-)5ABC3AF10-FAEABC2AF14-E2-A13-10A9-11A2(9-D9AF)9-10AE9-D9AE9-D10A9-E2(10A9-D)9AE9-10AE2(9-D10A)9-5ABC3AE9-H4ABC3AE9-I4ABC3AE9-5ABC3AF9-5ABC3AE9-F4ABC3AF2(9-F4ABC3AE)2(9-5ABC3AE)9-5ABC4A8-G5ABC3AF2(8-G5ABC4A)8-G2(5ABC3AE9-)5ABC3AF10-4ABC2AF14-A2-A13-7A3E9-11A9-D10A9-D9AF9-10AE2(9-D10A)9-10AF9-D9AE9-D10A9-10A2(E9-D9A)F9-5ABC3AE9-H4ABC3AF9-I4ABC3AE9-5ABC3AE2(9-E4ABC3AF)9-5A2(BC4A9-F4A)2(BC4A9-5A)BC4A2(8-G5ABC3AF)2(8-G5ABC4A)9-5ABC4A9-5ABC3AF10-4ABC2AE14-A2-A13-7A3E9-11A2(9-D10A)9-E2(9AE9-D)9AE9-E9AF2(9-D9AE)9-10AF2(9-D9AE)9-5ABC3AE9-H4ABC3AF9-I4ABC4A9-5ABC3AE9-E4ABC3AF9-E3(4ABC4A9-F)4A2(BC4A9-5A)BC4A4(8-G5ABC3AE)9-5ABC4A9-5ABC3AF10-A2EABC2AE14-A2-A13-7A3E9-11A2(9-D10A)9-E10A9-D9AE9-D9AF9-E2(9AF9-D)9AE9-10AE9-D9AF9-D9AE9-5ABC3AE9-H4ABC3AF9-I4A2(BC4A9-5A)BC3AF9-E4ABC3AF9-F4A3(BC4A9-5A)BC3AE9-5ABC3AE8-J5ABC4A8-J5ABC3AF2(8-G5ABC4A)9-5ABC4A9-5ABC3AF10-A2EABC2AF14-A2-A13-3A7E9-10AE9-D9AE9-D10A9-11A2(9-D9AE)9-E9AF9-D9AE9-D9AF9-10A2(E9-D9A)F9-5ABC3AE9-H4ABC3AE9-I4ABC3AF9-5ABC3AF9-E4ABC4A9-E4ABC3AF9-F4A2(BC4A9-5A)2(BC3AE9-5A)2(BC4A8-J5A)2(BC3AF8-G5A)2(BC3AF9-E4A)BC4A10-2AEABC2AF14-A2-A13-2A2E2AE3A9-11A2(9-D9AE)9-11A9-D10A9-D9AE9-E2(9AE9-D)9AE9-10AE9-D10A9-D9AE9-5ABC4A9-H4ABC3AE9-I4ABC4A9-5ABC4A9-E4ABC3AF9-5ABC3AF9-F4ABC4A9-5ABC4A9-F4ABC3AE2(9-5ABC4A)8-G5ABC4A8-J5ABC4A8-G5ABC3AF8-G5ABC4A9-E4ABC3AF9-5ABC4A10-FAEABC2AF14-A2-A13-2A4E4A9-11A9-D10A9-D9AE9-10A2(E9-D9A)2(E9-F2(9AE9-D)9A)E9-5ABC3AE9-H4ABC4A9-I4ABC3AE9-5ABC3AE9-E4ABC4A9-5ABC4A9-F4A6(BC4A9-5A)2(BC3AF9-5A)2(BC3AF9-E4A)BC3AF10-AE2ABC2AF14-A2-A13-A7F2A9-10AG2(9-D10A)9-11A2(9-D9AE)9-11A2(9-D10A)9-F2(10A9-D)9AE9-F4ABC3AE9-H4ABC3AE9-I4ABC4A2(9-5ABC3AE)9-5A2(BC4A9-F4A)BC4A9-E4ABC4A9-5A2(BC4A9-E4A)4(BC3AF9-5A)BC4A9-5ABC3AF10-AE2ABC2AF14-A2-A13-AFA5F2A9-11A9-D9AG9-D10A9-11A9-D10A9-D9AE9-11A2(9-D10A)9-F2(10A9-D)10A9-F4ABC4A9-H4ABC3AE9-I4A4(BC3AE9-5A)BC3AF4(9-5ABC4A)9-E4ABC4A9-5ABC3AF9-E2(4ABC3AF9-F)4ABC3AF9-5ABC3AF10-4ABC3A14-A2-A13-2A5F3A9-10AG3(2(9-D10A)9-11A)2(9-D10A)9-5ABC4A9-H4ABC4A3-E5-I4ABC4A3-2E4-5ABC3AE4-A4-5ABC3AE4-2A3-F4ABC3AE5-A3-F4ABC4A5-FA2-E4ABC4A6-F2-E4ABC4A6-E2-E4ABC4A6-2A2(-E4ABC4A7-A)-F4ABC3AF7-D-5ABC4A7-A-F4ABC3AF7-D-F4ABC3AF6-2A-5ABC3A2F5-F3-4ABC3A-2F3-AF6-A2-A4-A4F4-2A5F3A9-11A9-D9AG9-D10A9-11A9-D10A9-D9ADB8-10A2D8-D10AB8-D10AD8-11A2D2(7-D10A-D)7-5ABC4A-2D6-H4ABC4A2-DA5-I4ABC4A3-AE4-5ABC3AF4-E4-F4ABC3AF4-A2(F3-F4ABC4A5-)AF2-E4ABC4A6-F2-5ABC4A6-F2-E4ABC4A6-AE2(-5ABC4A7-A)-F4ABC4A7-D-F4ABC3AF7-A-F4ABC4A7-D-5ABC4A6-2A-5ABC5A5-A3-4ABC3A-2A3-AF6-A2-A4-4AF4-4A3F3A9-10AG2(9-D10A)9-11A9-D10A9-D9ADB8-10AD2(B8-D10A)D8-11A2D2(7-D10A-D)7-5ABC4A-2D6-H4ABC4A2-DA5-I4ABC4A3-2A4-5ABC4A4-A4-F4ABC4A4-2A3-F4ABC4A5-A3-5ABC4A5-AE2(2-E4ABC4A6-F)2-E4ABC4A6-AF-E4ABC4A7-E-5ABC4A7-A-F4ABC4A7-D-F4ABC4A7-A-5ABC4A7-D-5ABC4A6-2A-E4ABC5A5-A3-AF2ABC3A-2A3-AF6-A2-A4-4AF4-4A3F3A12(9-11A)9-F4ABC4A9-5ABC4A3-A5-5ABC4A3-2A4-5ABC4A4-A4-5ABC3AE4-2A2(3-F4ABC4A5-A)3(E2-E4ABC4A6-)AE-5ABC4A7-E-E4ABC4A7-A-E4ABC3AF7-D-E4ABC4A7-A-E4ABC4A7-D-E4ABC4A6-2A-5ABC5A5-A3-4ABC3A-2A3-2A6-A2-A4-5A24-6A3F3(11-9A2(11-9D))2(11-9A)11-F3ABCAFA11-F3ABCAFE11-F3ABCA2E11-4ABCA2E11-F3ABC3A11-3FABCA2F11-AF2ABCAFE11-2F2ABC2AF11-2F2ABC3A11-F3A2(BC3A11-4A)BC3A11-E3ABCA2F11-F3A2(BCA2F11-AF2A)BC3A11-2F2ABC3A14-A2-A16-A2-A34-5A2F3(13-7A2(13-7D))13-4AF2A15-AE2F16-E17(2-A16-A)2-A31-
