model
size = 20 32 26, scale = 0.05, origin = -y
material 
  colors = A:#222 B:#800 C:#555 D:#888 E:#777 F:#AAA G:#444 H:#6F3 I:#111
voxels
64-3(H2(19-B)19-)H418-2(7A13-)2(7B13-)2(7A2(13-7B)13-)7A15-4A14(16-A2-A)16-A-BA16-A-I2(A16-A2-)A53-2(9A11-)2(9B11-)2(9A2(11-9B)11-)2(9A11-)16(4ACD3A11-)4ACD3A14-A2-A16-A2-A13-10A12(9-11A)2(9-5ACD4A)3-A5-5ACD4A3-2A4-5ACD4A4-A4-5ACD4A4-2A3-5ACD4A5-A3-5ACD4A5-2A2(2-5ACD4A6-A)2-5ACD4A6-2A5(-5ACD4A7-A)-5ACD4A6-2A-5ACD5A5-A3-4ACD3A-2A3-2A6-A2-A4-5A4-10A9-11A2(9-B10A)9-11A9-B10A9-B9ABC8-10AB2(C8-B10A)B8-11A2B2(7-B10A-B)7-5ACD4A-2B5-BE4ACD4A2-BA4-2I4ACD4A3-2A4-5ACD4A4-A4-5ACD4A4-2A3-5ACD4A5-A3-5ACD4A5-2A2(2-5ACD4A6-A)2-5ACD4A6-2A5(-5ACD4A7-A)-5ACD4A6-2A-5ACD5A5-A3-4ACD3A-2A3-2A6-A2-A4-5A4-10A9-11A2(9-B10A)9-11A9-B10A9-B9ABC8-10A2B8-B10AC8-B10AB8-11A2B2(7-B10A-B)7-5ACD4A-2B6-E4ACD4A2-BA5-F4ACD4A3-2A4-5ACD4A4-A4-5ACD4A4-2A3-5ACD4A5-A3-5ACD4A5-2A2(2-5ACD4A6-A)2-5ACD4A6-2A5(-5ACD4A7-A)-5ACD4A6-2A-5ACD5A5-A3-4ACD3A-2A3-2A6-A2-A4-5A4-10A9-11A9-B10A8-2B10A2(8-G11A2(8-2B10A))8-G11A2(9-B10A)9-5ACD4A9-E4ACD4A3-A5-F4ACD4A3-2A4-5ACD4A4-A4-5ACD4A4-2A3-5ACD4A5-A3-5ACD4A5-2A2(2-5ACD4A6-A)2-5ACD4A6-2A5(-5ACD4A7-A)-5ACD4A6-2A-5ACD5A5-A3-4ACD3A-2A3-2A6-A2-A4-5A4-3(10A4(9-11A2(9-B10A))9-5ACD4A9-E4ACD4A9-F4A14(CD4A9-5A)CD4A10-4ACD3A14-A2-A13-)4(10A4(9-11A2(9-B10A))9-5ACD4A9-E4ACD4A9-F4A8(CD4A9-5A)4(CD4A8-B5A)2(CD4A9-5A)CD4A10-4ACD3A14-A2-A13-)2(10A4(9-11A2(9-B10A))9-5ACD4A9-E4ACD4A9-F4A8(CD4A9-5A)2(CD4A8-G5A)2(CD4A8-B5A)2(CD4A9-5A)CD4A10-4ACD3A14-A2-A13-)10A4(9-11A2(9-B10A))9-5ACD4A9-E4ACD4A9-F4A8(CD4A9-5A)CD4A8-B5ACD4A8-G2(5ACD4A8-B)2(5ACD4A9-)5ACD4A10-4ACD3A14-A2-A13-10A4(9-11A2(9-B10A))9-5ACD4A9-E4ACD4A9-F4A14(CD4A9-5A)CD4A10-4ACD3A14-A2-A13-10A9-10AB3(2(9-B10A)9-11A)2(9-B10A)9-5ACD4A9-E4ACD4A9-F4A14(CD4A9-5A)CD4A10-4ACD3A14-A2-A13-10A9-11A9-B9AB9-B10A3(9-11A2(9-B10A))9-5ACD4A9-E4ACD4A9-F4A14(CD4A9-5A)CD4A10-4ACD3A14-A2-A13-10A9-10AB3(2(9-B10A)9-11A)2(9-B10A)9-5ACD4A9-E4ACD4A3-A5-F4ACD4A3-2A4-5ACD4A4-A4-5ACD4A4-2A3-5ACD4A5-A3-5ACD4A5-2A2(2-5ACD4A6-A)2-5ACD4A6-2A2(-5ACD4A7-A)-5ACD4A7-B-5ACD4A7-A-5ACD4A7-B-5ACD4A6-2A-5ACD5A5-A3-4ACD3A-2A3-2A6-A2-A4-5A4-10A9-11A9-B9AB9-B10A9-11A9-B10A9-B9ABC8-10A2B8-B10AC8-B10AB8-11A2B2(7-B10A-B)7-5ACD4A-2B6-E4ACD4A2-BA5-F4ACD4A3-2A4-5ACD4A4-A4-5ACD4A4-2A3-5ACD4A5-A3-5ACD4A5-2A2(2-5ACD4A6-A)2-5ACD4A6-2A2(-5ACD4A7-A)-5ACD4A7-B-5ACD4A7-A-5ACD4A7-B-5ACD4A6-2A-5ACD5A5-A3-4ACD3A-2A3-2A6-A2-A4-5A4-10A9-10AB2(9-B10A)9-11A9-B10A9-B9ABC8-10AB2(C8-B10A)B8-11A2B2(7-B10A-B)7-5ACD4A-2B6-E4ACD4A2-BA5-F4ACD4A3-2A4-5ACD4A4-A4-5ACD4A4-2A3-5ACD4A5-A3-5ACD4A5-2A2(2-5ACD4A6-A)2-5ACD4A6-2A2(-5ACD4A7-A)-5ACD4A7-B-5ACD4A7-A-5ACD4A7-B-5ACD4A6-2A-5ACD5A5-A3-4ACD3A-2A3-2A6-A2-A4-5A4-10A12(9-11A)2(9-5ACD4A)3-A5-5ACD4A3-2A4-5ACD4A4-A4-5ACD4A4-2A3-5ACD4A5-A3-5ACD4A5-2A2(2-5ACD4A6-A)2-5ACD4A6-2A2(-5ACD4A7-A)-5ACD4A7-B-5ACD4A7-A-5ACD4A7-B-5ACD4A6-2A-5ACD5A5-A3-4ACD3A-2A3-2A6-A2-A4-5A24-2(9A11-)2(9B11-)2(9A2(11-9B)11-)2(9A11-)16(4ACD3A11-)4ACD3A14-A2-A16-A2-A34-2(7A13-)2(7B13-)2(7A2(13-7B)13-)7A15-4A18(16-A2-A)31-
