model
size = 32 16 32, scale = 0.05, origin = -y
material 
  colors = A:#594D4D B:#5B4D4D C:#5E5E5E D:#534141 E:#2D2D2D F:#FFFCBA G:#666 H:#FFF5A1
voxels
44-8E23-E8-E21-E10-E20-E10-E19-3(E12-E18-)E12-E19-E10-E20-E10-E21-E8-E23-2E4-2E26-4E87-14D18-4A6B4A19-3A6B3A20-3A6B3A21-2A6B2A23-A6BA25-6B26-6B276-5D8-5D15-4A8E4A2(16-16A)17-14A18-14A19-12A22-A6BA25-6B26-6B211-3D14-3D12-3A3E8-3E3A12-6A8-6A13-5A8-5A14-5A8-5A15-16A16-16A17-14A20-10A24-6B26-6B178-3D16-3D10-3A2E12-2E3A2(10-5A12-5A)11-2(4A12-)6A8-6A13-18A15-16A17-14A19-12A22-A6BA25-6B145-2D20-2D8-2A2E16-2E2A2(8-4A16-4A)9-3A16-3A10-5A12-5A11-6A8-6A13-18A14-18A16-14A19-12A22-A6BA25-6B112-2D22-2D6-2A2E18-2E2A6-4A18-4A7-2(3A18-3A8-)4A16-4A9-5A12-5A11-6A8-6A12-20A13-18A16-14A19-12A23-6B26-6B79-3D22-3D5-2AE20-E2A3(6-3A20-3A)7-3A18-3A8-5A14-5A9-5A12-5A10-8A6-8A11-20A13-18A16-14A20-10A24-6B26-6B47-2D24-2D4-2AE22-E2A2(4-3A22-3A)5-2A22-2A6-3A20-3A6-5A16-5A7-5A14-5A9-6A10-6A11-7A6-7A13-18A15-16A17-14A21-A6BA25-6B46-2D26-2D2-2A2E22-2E2A3-3(3A22-3A4-)4A20-4A5-4A18-4A6-5A16-5A7-5A14-5A9-6A10-6A11-7A6-7A13-18A15-16A18-12A23-6B26-6B14-2D26-2D2-2AE24-E2A2(2-3A24-3A)3-2A24-2A4-3A22-3A4-4A20-4A5-4A18-4A7-5A14-5A8-6A12-6A9-6A10-6A11-20A14-16A17-14A21-A6BA25-6B14-2D26-2D2-2AE24-E2A3(2-3A24-3A)3-3A22-3A4-4A20-4A5-4A18-4A6-5A16-5A7-5A14-5A9-5A12-5A11-7A6-7A13-18A16-14A20-10A24-6B13-2D28-2D-AE26-EA3(2-2A26-2A)2-3A24-3A3-3A22-3A4-4A20-4A5-5A16-5A7-5A14-5A8-6A12-6A9-7A8-7A12-18A15-16A18-12A23-6B13-2D28-2D-AE26-EA3(2-2A26-2A)2-3A24-3A3-3A22-3A4-4A20-4A5-4A18-4A6-5A16-5A7-5A14-5A9-6A10-6A11-20A14-16A18-12A23-6B13-2D28-2D-AE26-EA3(2-2A26-2A)2-3A24-3A2-4A22-4A3-4A20-4A5-4A18-4A6-5A16-5A7-5A14-5A9-6A10-6A11-20A14-16A17-2(14A22-6B13-2D28-2D-AE26-EA3(2-2A26-2A)2-3A24-3A2-4A22-4A3-4A20-4A4-5A18-5A5-5A16-5A7-5A14-5A9-6A10-6A11-20A13-18A16-)14A22-6B13-2D28-2D-AE26-EA3(2-2A26-2A)2-3A24-3A2-4A22-4A3-4A20-4A5-4A18-4A6-5A16-5A7-5A14-5A9-6A10-6A11-20A14-16A17-14A22-6B13-2D28-2D-AE26-EA3(2-2A26-2A)2-3A24-3A3-3A22-3A4-4A20-4A5-5A16-5A6-6A14-6A7-6A12-6A9-7A8-7A11-20A14-16A18-12A23-6B13-3D26-3D-2AE24-E2A3(2-3A24-3A)3-3A22-3A4-4A20-4A4-5A18-5A5-5A16-5A7-5A14-5A8-6A12-6A9-8A6-8A12-18A15-16A18-12A23-6B13-3D26-3D-2AE24-E2A2(2-3A24-3A)3-2A24-2A4-3A22-3A4-4A20-4A5-4A18-4A7-5A14-5A8-6A12-6A9-6A10-6A11-20A14-16A17-14A20-10A24-6B13-3D26-3D-2A2E22-2E2A3-3(3A22-3A4-)4A20-4A5-4A18-4A6-5A16-5A7-5A14-5A9-6A10-6A11-7A6-7A13-18A15-16A18-12A22-A6BA25-6B13-4D24-4D2-2AE22-E2A3(4-3A22-3A)5-3A20-3A6-5A16-5A7-5A14-5A9-6A10-6A11-7A6-7A13-18A15-16A16-16A18-3A6B3A23-6B26-6B14-4D22-4D3-3AE20-E3A4-4A20-4A5-2(3A20-3A6-)4A18-4A7-5A14-5A9-5A12-5A10-8A6-8A11-20A13-18A15-16A18-12A22-A6BA25-6B46-4D22-4D4-2A2E18-2E2A6-4A18-4A7-3A18-3A8-3A18-3A9-3A16-3A10-5A12-5A11-6A8-6A13-18A15-16A18-12A21-10A24-2(6B26-)6B47-4D20-4D6-2A2E16-2E2A8-4A16-4A8-4A2-12A2-4A9-3A2-12A2-3A11-4A2-8A2-4A12-20A13-18A15-16A18-12A20-12A23-6A2(26-6B)80-5D16-5D7-4A2E12-2E4A9-22A10-6A10C6A11-5A10C5A13-5A8C5A14-18A15-16A18-12A20-12A22-8A25-6B26-6B113-5D14-5D9-4A3E8-3E4A11-20A12-6A8C6A13-5ACG4CGC5A15-5AG4AG5A16-5AG4AG5A18-3AG4AG3A20-12A21-C8AC23-C6BC25-6B146-7D8-7D12-5A8E5A14-18A15-16A2(16-5A-4F-5A)17-C3A-4F-3AC19-C2A-4F-2AC20-3C6A3C20-3C6B3C21-2C6B2C23-8C27-2C117-20D14-16A16-16A17-4A6G4A2(18-C2AG-4F-C2AC)2(18-3CG-4F-4C)19-3C6G3C20-12C21-10C23-8C26-4C117-18D18-C8BC21-12C19-4C6-4C4(18-3C2-4F2-3C)18-4C6-4C19-4C4-4C21-10C23-8C25-6C118-14D20-10C21-2C8-2C19-E2C8-2CE18-2C4-2H4-2(2C18-2C3-4H3-)2C18-2C4-2H4-2C18-E2C8-2CE19-2C8-2C21-3C4-3C23-8C25-E4CE109-
