model
size = 22 32 26, scale = 0.05, origin = -y
material 
  colors = A:#630 B:#555 C:#960 D:#444 E:#111 F:#222 G:#6F3 H:#B00 I:#FC3
voxels
115-2(G2(21-C)21-)G727-H21-E414-2(7A15-)2(7C15-)2(7A2(15-7C)15-)3(7A15-)16(3ABD2A15-)3ABD2A58-13(10A12-)17(4AB5A12-)4ABD4A33-11A11-11A11(10-12A)3(10-6AB5A)3(11-5AB5A)3(12-4AB5A)9(11-5AB5A)12-4ABD4A11-12A10-13A8-2(C11A10-)3(12A2(10-C11A)10-)6AB5A9-H6AB5A9-E2(B5A)2(11-5AB5A)4-A6-5A2(B5A4-A7-4A)B5A4-2A6-4AB5A5-A5-5AB5A5-2A4-5AB5A6-A4-5AB5A6-2A3-5AB5A7-2A2-5AB5A8-2(A2-5AB6A7-)A2-5AB7A5-2A2-5AB5A-4A-2A4-4ABD4A4-3A4-13A9-13A8-C11AC9-C11A2C8-12A-C8-C11A-2C7-C11A2-C7-12A2-2C2(6-C11A3-C)6-12A2(3-C6-C11A)3-C6-6AB5A3-C6-D5AB5A4-C5-2(B5A)2(4-C6-5AB5A)4-E6-5A2(B5A4-A7-4A)B5A4-2A6-4AB5A5-A5-5AB5A5-2A4-5AB5A6-A4-5AB5A6-2A3-5AB5A7-2A2-5AB5A8-2(A2-5AB6A7-)A2-5AB7A5-2A2-5AB5A-4A-2A4-4ABD4A4-3A4-13A9-13A8-C11AC9-C11A2C7-F12A-C7-2C11A-2C6-2C11A2-C6-F12A2-2C2(5-2C11A3-C)5-F12A3-C5-I2(C11A3-C6-)6AB5A3-C6-D5AB5A4-C5-2(B5A)2(4-C6-5AB5A)4-E6-5A2(B5A4-A7-4A)B5A4-2A6-4AB5A5-A5-5AB5A5-2A4-5AB5A6-A4-5AB5A6-2A3-5AB5A7-2A2-5AB5A8-2(A2-5AB6A7-)A2-5AB7A5-2A2-5AB5A-4A-2A4-4ABD4A4-3A4-12A10-13A8-2(C11A10-)3(12A2(10-C11A)10-)6AB5A10-D5AB5A10-2(B5A)2(11-5AB5A)4-A6-5A2(B5A4-A7-4A)B5A4-2A6-4AB5A5-A5-5AB5A5-2A4-5AB5A6-A4-5AB5A6-2A3-5AB5A7-2A2-5AB5A8-2(A2-5AB6A7-)A2-5AB7A5-2A2-5AB5A-4A-2A4-4ABD4A4-3A4-11A11-2(11A10-C)11A3(10-12A2(10-C11A))6(10-6AB5A10-D5AB5A10-2(B5A)3(11-5AB5A)3(12-4AB5A)2(11-5AB5A)5(11-E4AB5A)2(11-5AB5A)12-4ABD4A2(11-11A)3(2(10-C11A)10-12A)2(10-C11A))10-6AB5A10-D5AB5A10-2(B5A)3(11-5AB5A)3(12-4AB5A)2(11-5AB5A)3(11-F4AB5A)2(11-E4AB5A)2(11-5AB5A)12-4ABD4A2(11-11A)3(2(10-C11A)10-12A)2(10-C11A)10-6AB5A10-D5AB5A10-2(B5A)3(11-5AB5A)3(12-4AB5A)2(11-5AB5A)11-F4AB5A11-D4AB5A11-F2(4AB5A11-E)4A2(B5A11-5A)B5A12-4ABD4A2(11-11A)3(2(10-C11A)10-12A)2(10-C11A)10-6AB5A10-D5AB5A10-2(B5A)3(11-5AB5A)3(12-4AB5A)2(11-5AB5A)3(11-F4AB5A)2(11-E4AB5A)2(11-5AB5A)2(12-4ABD4A2(11-11A)3(2(10-C11A)10-12A)2(10-C11A)10-6AB5A10-D5AB5A10-2(B5A)3(11-5AB5A)3(12-4AB5A)9(11-5AB5A))12-4ABD4A11-12A10-13A8-2(C11A10-)3(12A2(10-C11A)10-)6AB5A10-D5AB5A10-2(B5A)2(11-5AB5A)4-A6-5A2(B5A4-A7-4A)B5A4-2A6-4AB5A5-A5-5AB5A5-2A4-5AB5A6-A4-5AB5A6-2A3-5AB5A7-2A2(2-5AB5A8-A)2-5AB6A7-A2-5AB7A5-2A2-5AB5A-4A-2A4-4ABD4A4-3A4-13A9-13A8-C11AC9-C11A2C8-12A-C8-C11A-2C7-C11A2-C7-12A2-2C2(6-C11A3-C)6-12A2(3-C6-C11A)3-C6-6AB5A3-C6-D5AB5A4-C5-2(B5A)2(4-C6-5AB5A)4-E6-5A2(B5A4-A7-4A)B5A4-2A6-4AB5A5-A5-5AB5A5-2A4-5AB5A6-A4-5AB5A6-2A3-5AB5A7-2A2(2-5AB5A8-A)2-5AB6A7-A2-5AB7A5-2A2-5AB5A-4A-2A4-4ABD4A4-3A4-13A9-13A8-C11AC9-C11A2C8-12A-C8-C11A-2C7-C11A2-C7-12A2-2C2(6-C11A3-C)6-12A2(3-C6-C11A)3-C6-6AB5A3-C6-D5AB5A4-C5-2(B5A)2(4-C6-5AB5A)4-E6-5A2(B5A4-A7-4A)B5A4-2A6-4AB5A5-A5-5AB5A5-2A4-5AB5A6-A4-5AB5A6-2A3-5AB5A7-2A2(2-5AB5A8-A)2-5AB6A7-A2-5AB7A5-2A2-5AB5A-4A-2A4-4ABD4A4-3A4-12A10-13A8-2(C11A10-)3(12A2(10-C11A)10-)6AB5A10-D5AB5A10-2(B5A)2(11-5AB5A)4-A6-5A2(B5A4-A7-4A)B5A4-2A6-4AB5A5-A5-5AB5A5-2A4-5AB5A6-A4-5AB5A6-2A3-5AB5A7-2A2(2-5AB5A8-A)2-5AB6A7-A2-5AB7A5-2A2-5AB5A-4A-2A4-4ABD4A4-3A4-11A11-11A11(10-12A)3(10-6AB5A)3(11-5AB5A)3(12-4AB5A)8(11-5AB5A)11-5ABD4A35-2(8A14-)2(8C14-)2(8A2(14-8C)14-)2(8A14-)17(3ABD3A14-)3ABD3A54-
