model
size = 24 32 20, scale = 0.05, origin = -y
material 
  colors = A:#72636E B:#E98B2A C:#622954 D:#70649A E:#533D5B F:#4A225D G:#77428D H:#CC543A I:#FC9F4D J:#2B5F75 K:#3A8FB7 L:#E2943B M:#FFB11B N:#EBB471 O:#58B2DC P:#7DB9DE
voxels
107-2P22-2P646-2H46-2H16-6F2H6F10-5F4H5F14-2H2B2H20-6(2B22-)2B543-2F12-2F8-2F12-2F10-5C2-5C12-CED6ADEC12-CEDE4AEDEC12-CED6ADEC12-CADED2ADEDAC12-CAGE4AEGAC12-C2(ED)2A2(DE)C12-CAGAD2ADAGAC17-2B519-F14-F8-F14-F9-2(2C10-)6(C12-C10-)C12-C11-BCGAD2ADAGCB17-14(2B22-)2B159-F14-F8-F14-F9-C12-C2(10-A12-A10-G12-G)3(10-G12-G)11-2C8-2C14-CAD2ADAC16-C6AC16-CED2ADEC16-CAG2AGA2(C16-CE4AE)C16-CEG2AGEC16-CDG2AGDC16-CAG2AGA2(C16-CDG2AGDC16-CD4AD)C16-C6AC16-3C2A3C19-2B135-F14-F8-F14-F9-C12-C10-A12-A4(10-E12-E)10-A12-A35-A10-A13-14(C8-C14-)CA6-AC15-9A18-2B111-2(F14-F8-)HC12-CH9-4(D12-D10-)A12-A10-D12-D10-A12-A11-A10-A13-3(A8-A14-)D8-D14-A8-A3(14-D8-D)14-G8-G14-D8-D14-G8-G14-A8-A2(14-G8-G)14-C8-C15-9A18-2B111-F14-F8-H14-H8-HC12-CH9-3(E12-E10-)A12-A10-E12-E10-D12-D10-E12-E11-D10-D13-3(D8-D14-)3(A8-A14-)2(E8-E14-A8-A14-)3(E8-E14-)A8-A14-C8-C15-9A18-2B39-H14-H32-2(H14-H8-)H14-H4-2(N-)B14-B2(-N)4-BA12-AB4-3I-BA12-AB-4I3-BA12-AB3-2I3-BA12-AB3-6IA12-A5I2-3BA12-A3B6-BA12-AB9-BA10-AB11-BA8-AB12-BA8-AB8-N2-2BA8-A2B2-N7-2BA8-A2B7-2(I2-2BA8-A2B2-I4-)3I2BA8-A2B3I6-3IA8-A3I9-2(2BA8-A2B10-)2BA8-A2B8-N2-BA8-AB2-N9-BA8-AB6-N2-I2-BA8-AB2-I2-N3-4IA8-A2(4I3-)B8AB3-4I8-8B36-H14-H32-3(H14-H8-)B14-4(B8-BA12-A)B5-B-2BA12-A2B-B5-BA12-AB9-A12-A10-BA10-AB11-2(BA8-AB12-)BA8-AB11-2BA8-A2B11-BA8-AB11-3(2BA8-A2B10-)2BA8-A2B11-BA8-AB11-2BA8-A2B11-2(BA8-AB12-)BA8-AB10-B-BA8-AB-B4-B6-B8AB6-B8-8B18-4B86-F14-F8-H14-H8-HC12-CH9-3(E12-E10-)A12-A10-E12-E10-D12-D10-E12-E11-D10-D13-3(D8-D14-)3(A8-A14-)2(E8-E14-A8-A14-)3(E8-E14-)A8-A14-C8-C15-8A19-2B111-F14-F8-F14-F9-C12-C4(10-D12-D)10-A12-A10-D12-D10-A12-A11-A10-A13-3(A8-A14-)D8-D14-A8-A3(14-D8-D)14-G8-G14-D8-D14-G8-G14-A8-A2(14-G8-G)14-C8-C15-8A19-2B111-F14-F8-F14-F9-C12-C10-A12-A4(10-E12-E)10-A12-A10-E12-E11-A10-A13-14(C8-C14-)CA6-AC15-8A19-2B111-F14-F8-F14-F9-C12-C2(10-A12-A10-G12-G)3(10-G12-G)11-2C8-2C14-CAD2ADAC16-C6AC16-CED2ADEC16-CAG2AGA2(C16-CE4AE)C16-CEG2AGEC16-CDG2AGDC16-CAG2AGA2(C16-CDG2AGDC16-CD4AD)C16-C6AC16-3C2A3C19-2B135-F14-F8-F14-F9-2(2C10-)6(C12-C10-)C12-C11-BCGAD2ADAGCB17-14(2B22-)2B159-2F12-2F8-2F12-2F10-5C2-5C12-CED6ADEC12-CEDE4AEDEC12-CED6ADEC12-CADED2ADEDAC12-CAGE4AEGAC12-C2(ED)2A2(DE)C12-CAGAD2ADAGAC17-2B498-H8-H12-2FH8FH2F10-2FH8FH2F12-4H2B4H15-3H2B3H17-2H2B2H19-H2BH21-3(2B22-)2B477-4B19-6B17-8B2(16-LMO2KOML)16-L2M2O2ML17-L4ML19-4L620-4J19-3(6J18-)6J19-4J669-2K21-4K20-4K21-2K635-
