model
size = 24 16 29, scale = 0.05, origin = -y
material 
  colors = A:#930 B:#555 C:#444 D:#EEE E:#E00 F:#F3F
voxels
105-2(9(6B18-)6B162-)7(6B18-6B162-)6B18-6B64-31(10B14-)10B10-19(18B6-)B5-12B7(6-18B)6-BA16B6-2BA15B3(6-18B)4-22B13(2-3B15A4B)2-2BFB14-4B2-4B14-4B2-22B6(2-C2B18AB)2-C2B15-3A4(B2-C2B13A-4A)B2-C2B19A2-C2B18AB2-B2DB14-4B2-4B14-4B2-22B3(2-2C19AB)2-2C-18A2(B2-2C19A)B2-2C16-3A3(B2-2C15-4A)B2-2C14A-4AB-E2(2C19AB2-)B2DB14-4B2-4B14-4B2-21BC3(2-2C18A2C)2-2C-17A2(2C2-2C18A)2C2-2C14A2-2A3(2C2-2C14A-3A)2C-E2C14A-3A2(2C2-2C18A)2C2-B2DB14-4B2-4B14-4B2-21BC3(2-2C18A2C)2-2C-17A2(2C2-2C18A)2C2-2C14A2-2A2(2C2-2C14A-3A)2C-E2(2C14A-3A2C2-)2C18A2CE-2C18A2C2-B2DB14-4B2-4B14-4B2-21BC3(2-2C18A2C)2-2C-17A2(2C2-2C18A)2C2-2C14A2-2A2C2-2C14A-3A2C-E2(2C14A-3A2C2-)2C14A-3A2CE-2(2C18A2C2-)B2DB14-4B2-4B14-4B2-21BC3(2-2C18A2C)-E2C-17A2(2C-E2C18A)2C-E2C-14A-2A2C-E2(2C-17A2C2-)2C-17A2CE-3(2C-17A2C2-)B2DB14-4B2-4B14-4B2-21BC3(2-2C18A2C)E-2C-17A2(2CE-2C18A)2CE-2C15A-2A2CE-2C18A2C2E2C18A2CE-3(2C18A2C2-)2C2-16A2C2-B2DB14-4B2-4B14-4B2-21BC3(2-2C18A2C)2-2C-17A2(2C2-2C18A)2C2-2C7A9-2A2(2C2-2C7A8-3A)2C-E2C7A-6A-3A2CE-2C7A-6A-3A2C2-2C18A2C2-2C-17A2C2-B2DB14-4B2-4B14-4B2-21BC3(2-2C18A2C)2-2C-17A2(2C2-2C18A)2C2-2C16-2A2(2C2-2C9A6-3A)2C2-2C8-6A-3A2C-E2C14A-3A2CE-2(2C18A2C2-)B2DB14-4B2-4B14-4B2-21BC3(2-2C18A2C)2-2C-17A2(2C2-2C18A)2C2-2C14A2-2A4(2C2-2C14A-3A)2C-E2C18A2CE-2C18A2C2-B2DB14-4B2-4B14-4B2-21BC3(2-B19A2C)2-B2-17A2(2C2-B19A)2C2-B15A2-2A4(2C2-B15A-3A)2C2-B2-17A2C2-BD2-16A2C2-B2DB14-4B2-4B14-4B2-21BC2-B16A4B2(C2-B17A3B)C2-BA-15A2(3BC2-B17A)3BC2-B15A2-4(3BC2-B15A-A)3BC2-B2-15A3BC2-BD2-14A3BC2-B2DB14-4B2-4B14-4B2-22B3(2-4B13A5B)3(2-4B14A4B)2(2-4B12A-A4B)5(2-4B14A4B)2(2-4B14-4B)4-18B5(6-2B13A3B)6-2B14A2(2B6-2B12A2-)2B5(6-3B11CA3B)6-16BDB2(6-18B)7(6-3B11C-3B)6(6-3B11CD3B)2(6-18B)8-14B13(10-B11CDB)3(10-14B)13(10-B11C2B)2(10-14B)87-6(E23-)E22-E-E20-E3-E18-E5-E16-E7-E57-
