model
size = 22 24 21, scale = 0.05, origin = -y
material 
  colors = A:#FCFAF2 B:#D0104C C:#222 D:#111 E:#CB1B45
voxels
384-6(2B20-)2B173-4A17-3(6A16-)6A17-4A19-9(2B20-)2B150-6A15-8A13-5(10A12-)10A13-8A15-6A18-8(2B20-)2B86-2A17-8A13-10A11-2(12A10-)12A9-14A8-14A9-2(12A10-)12A11-10A13-8A17-2A6(20-2B)86-2A17-8A13-10A11-12A9-2(14A8-)14A7-16A6-16A7-2(14A8-)14A9-12A11-10A13-8A17-2A6(20-2B)61-8A13-10A11-12A9-14A7-7(16A6-)16A7-14A9-12A11-10A13-8A17-4(2B20-)2B62-6A14-10A11-12A9-14A7-16A6-16A5-5(18A4-)18A5-16A6-16A7-14A9-12A11-10A14-6A18-4(2B20-)2B39-8A12-12A9-14A7-16A6-16A5-7(18A4-)18A5-16A6-16A7-14A9-12A12-8A17-3(2B20-)2B41-4A15-10A11-12A9-14A7-16A5-2(18A4-)18A2-C3(D18AD2C)D18ADC2-2(18A4-)18A5-16A7-14A9-12A11-10A15-4A19-3(2B20-)2B18-6A14-10A11-12A9-14A7-16A5-18A4-18A2-C5(D18AD2C)D18ADC2-18A4-18A5-16A7-14A9-12A11-10A14-6A18-2(2B20-)2B40-6A14-10A10-14A7-16A6-16A5-18A4-18A2-C5(D18AD2C)D18ADC-C18AC2-C18AC3-C16AC4-C16AC5-C14AC7-2C10A2C9-3C6A3C13-6C18-2(2B20-)2B18-6A14-10A10-14A7-16A6-16A5-18A4-18A2-C5(D18AD2C)D18ADC-C18AC2-C18AC3-C16AC4-C16AC5-C14AC7-2C10A2C9-3C6A3C13-6C18-2B20-2B40-6A14-10A11-12A9-14A7-16A5-18A4-18A2-C5(D18AD2C)D18ADC2-18A4-18A5-16A7-14A9-12A11-10A14-6A18-3(2B20-)2B19-4A15-10A11-12A9-14A7-16A5-2(18A4-)18A2-C3(D18AD2C)D18ADC2-2(18A4-)18A5-16A7-14A9-12A11-10A15-4A19-2(2B20-)2B61-8A12-12A9-14A7-16A6-16A5-7(18A4-)18A5-16A6-16A7-14A9-12A12-8A17-4(2E20-)2E40-6A14-10A11-12A9-14A7-16A6-16A5-5(18A4-)18A5-16A6-16A7-14A9-12A11-10A14-6A18-3(2E20-)2E83-8A13-10A11-12A9-14A7-7(16A6-)16A7-14A9-12A11-10A13-8A17-5(2B20-)2B64-2A17-8A13-10A11-12A9-2(14A8-)14A7-16A6-16A7-2(14A8-)14A9-12A11-10A13-8A17-2A5(20-2B)108-2A17-8A13-2A6D2A11-2AD6AD2A2(10-12A)9-3AD6AD3A8-2A3D4A3D2A9-2(12A10-)12A11-10A13-8A17-2A7(20-2E)196-2(2A20-)2A152-5(2E20-)2E438-4(2B20-)2E20-2B10-
