model
size = 24 4 19, scale = 0.05, origin = -y
material 
  colors = A:#222 B:#111 C:#AAA
voxels
A2BCBC5B2-3BCBC4B2A2(BC)6B2-2BCBC5B2A10B2-10B25A16(72-A22-A)48-A23-A22-A71-A23-A
