model
size = 24 7 19, scale = 0.05, origin = -y
material 
  colors = A:#111 B:#069 C:#036 D:#AAA
voxels
C2BDBD4BA2-A2BDBD4B2C2(BD)5BA2-A2(BD)5B2C9BA2-A9B2C22AC5A5-4A5-8A8-2A8-5A20-2A72-15(C22-C144-)C22-C120-C23-C22-C143-C23-C72-
