model
size = 29 7 7, scale = 0.05, origin = -y
material 
  colors = A:#EEE B:#D9D9D9 C:#382400 D:#717171 E:#555 F:#C9C9C9 G:#3D2814 H:#9CF
voxels
112-A2BA178-D18-FB3A177-DED17-B2ABA114-ABFA3-ED18-4BF2-E2DE17-B2ABA2-2D2HDG15CGH4CG2-2(ED)17-A2BFA5-DE18-2A2BA26-ABAF89-3D17-3AFA180-E18-ABFAF200-2(BA)87-
