model
size = 15 20 18, scale = 0.05, origin = -y
material 
  colors = A:#E00 B:#111 C:#C90 D:#CC0
voxels
127-A13-3A12-3A146-5A8-3A3-3A5-2A7-2A3-2A9-2A2-A11-A-2A9(11-4A)11-2A-A11-A2-2A9-2A3-2A7-2A5-3A3-3A8-5A10-5A8-9A5-2(4A3-)3A7-3A2-2A9-2A-3A9(9-6A)9-3A-2A9-2A2-3A7-3A2(3-4A)5-9A8-5A25-5A8-9A5-11A4-11A3-3A-5A-3A6(2-13A)2-3A-5A-3A2(2-13A)3-11A4-11A5-9A8-5A40-2B-2B8-2A2B-2B2A5-5A-5A4-11A3-3A-2(CD)C-3A2-13A2-2A4BA4B2A2-2AB7AB2A2-13A2-A-9A-A2-2A3C3A3C2A4-C-C3AC-C4-2A3C3A3C2A2-A-2AB3AB2A-A3-2ABAB-BAB2A4-2(AB)-A-2(BA)5-4A-4A8-2(A-)A84-3A-3A2(7-A)7-7A8-3B-3B9-5A10-5A11-3A9-3C3-3C6-C-C3-C-C6-3C3-3C9-B-B11-B3-B9-B5-2(B7-)B145-A12-5A10-5A12-8(A254-A13-3A12-3A13-)A254-A12-5A10-5A11-3A253-A12-2(5A10-)5A11-3A238-A12-5A10-5A11-3A141-
