model
size = 23 12 23, scale = 0.05, origin = -y
material 
  colors = A:#30F B:#DDD C:#E00
voxels
8-7A16-7A244-11A12-11A14-7A16-7A196-15A8-15A10-11A12-11A14-7A16-7A149-17A6-17A8-13A10-13A11-11A12-11A15-5A18-5A103-19A4-19A6-15A8-15A9-13A10-13A12-9A14-9A16-5A18-5A57-19A4-19A5-17A6-17A7-15A8-15A9-13A10-13A12-9A14-9A16-5A18-5A10-21A2-21A3-19A4-19A5-17A6-17A8-13A10-13A11-11A12-11A13-9A14-9A8-21A2-21A3-19A4-19A5-17A6-17A7-15A8-15A9-13A10-13A11-11A12-11A6-46A-21A2-21A3-19A4-19A6-15A8-15A9-13A10-13A11-11A12-11A6-5(46A-21A2-21A3-19A4-19A5-17A6-17A7-15A8-15A9-13A10-13A5-)46A-21A2-21A3-19A4-19A6-15A8-15A9-13A10-13A11-11A12-11A7-21A2-21A3-19A4-19A5-17A6-17A7-15A8-15A9-13A10-13A11-11A12-11A7-21A2-21A3-19A4-19A5-17A6-17A8-13A10-13A11-11A12-11A13-9A14-9A9-19A4-19A5-17A6-17A7-15A8-15A9-13A10-13A12-9A14-9A16-5A18-5A11-19A4-19A6-15A8-15A9-13A10-13A12-AB5ABA14-9A16-5A18-5A58-4AB7AB4A6-4AB7AB4A8-2AB7AB2A10-2AB7AB2A11-AB7ABA12-A2B5A2BA15-2BCBC18-5B105-3AB7AB3A8-3AB2C5AB3A10-AB2C5ABA12-AB2C5ABA14-2C5B16-2C2(BC)B152-AB7ABA12-AB2C5ABA14-5C2B16-5C2B200-7B16-2C5B238-
