model
size = 29 21 29, scale = 0.05, origin = -y
material 
  colors = A:#FFC B:#F9C C:#F99 D:#FCF E:#800 F:#F9F G:#630
voxels
303-B27-3B25-7B22-7B225-2AC4A22-2C5A22-6AC22-4A2CA22-3AC3A22-A2C4A2(22-C6A)22-6AC22-5ACA22-4AC2A20-2B7A2B17-3B7A3B16-13B19-7B193-12AC16-2AC8ACA16-AC8AC2A16-AC11A16-C12A16-13A16-12AC16-2AC8ACA16-2C8AC2A16-C12A2(15-B13A)B14-B13AB13-17B14-7B3D3B20-E168-C13AC3(14-15A)14-C14A14-C13AC14-14AC2(14-15A)2(14-C14A)-B11-B15A-B10-2B15A2B10-19B12-7B2(2D2B)186-17ACA10-2C17A10-C18A2(10-18AC)10-AC15ACA2(10-C18A)10-18AC10-17ACA10-AC17A10-C18A9-B19AB8-21B9-7BDBD4B3D2B183-2(21A8-)2(C19AC8-)3(21A8-)C19AC8-20AC2(8-21A)2(7-B21A)B6-23B7-5BD11B2D2B23-E158-21A8-20AC2(8-21A)8-C20A8-21A8-20AC8-21A8-C20A3(8-21A)7-B21AB5-25B6-7BD10B2DB18-E2-E159-C21AC6-22AC2(6-23A)6-C22A6-C21AC6-22AC6-23A2(6-C22A)2(6-23A)5-B23AB4-25B5-3BD12B2D5B11-E167-24AC4-C24A3(4-25A)4-C23AC3(4-25A)3-BC24A3(3-B25A)B2-27B3-18BD6B25-E152-2(25A4-)C24A4-25A4-24AC4-25A2(4-C24A)2(4-25A)2(3-B25A)B2-B25AB2-27B3-3B2DBD8B2D8B178-3(25A4-)C23AC4(4-25A)4-C24A3(4-25A)3-B25AB2-27B3-2B2D12B3D4BDB177-3(27A2-)C25AC2-C26A3(2-27A)2-C26A2-27A2-26AC-B27A2B27A30B-2B2D15B4D4B10-E165-3(27A2-)26AC2-27A2-C26A3(2-27A)2-C26A2-26AC2-27A2B27A30B-2BD4BD13B3D3B6-E8-E27-E-E27-E102-2(27A2-)26AC3(2-27A)2-C26A2(2-27A)2-26AC2-C26A2-27A-B27A30B-2BD20BD3B14-3E2-E22-5E25-3E27-E73-2(13A-13A2-)13A-12AC4(2-13A-13A)2-C12A-13A-B2(13A-)B13A-12AC-2(B2(13A-))2(B13A)30B-2BD3BD2F4BE9BD3B13-5E5-E18-5E24-5E25-EGE27-G27-2G15-C26A2-26AC5(2-27A)2-C26A2-26AC3(-B27A)2B27A30B-5B2DF15BD3B14-3E25-5E25-3E27-E73-27A2-C25AC6(2-27A)2-C25AC2(2-27A)2(2B27A)30B-3BDBDF15B2D3B15-E11-E15-3E27-E102-26AC2-C26A4(2-27A)2(2-26AC)2-27A2-C26A2(2-27A)-B27A30B-4BF2D14B2D4B4-E6-E165-25A4-C24A4(4-25A)4-24AC2(4-25A)4-C24A2(4-25A)3-B25AB2-27B3-2B2FBD18BD178-2(25A4-)C24A3(4-25A)4-24AC3(4-25A)4-C24A3-2(B25AB2-)27B3-2BF2B2D18B15-E162-3(25A4-)C24A2(4-24AC)6(4-25A)3-B25AB2-27B3-3BD2B4D15B19-E159-C22A2(6-23A)6-C22A6-C21AC7(6-23A)5-B23AB4-25B5-11BD11B23-E157-4(21A8-)C19AC8-C20A4(8-21A)3(7-B21A)B5-25B6-13BD7B10-E15-E155-2(C20A8-)2(20AC8-)2(21A8-)C20A2(8-21A)8-20AC2(8-21A)B6-B21AB6-23B7-5BD11BD2BD15-E167-19A10-C16ACA10-AC16AC3(10-19A)10-C18A10-2C17A10-17ACA10-18AC10-19AB9-19AB8-B19AB8-21B9-4B2D6BD6B23-E162-15A14-14AC2(14-C14A)3(14-15A)2(14-C13AC)14-15A12-B-2(15A12-2B)15A2B10-19B12-3B8D4B189-2AC8A2C16-12AC16-13A16-C12A16-AC11A16-2AC7AC2A16-11ACA16-12AC16-C12A16-2C8AC2A16-10AC2A16-13A15-B13AB13-17B14-13B193-C6A22-AC5A22-2AC4A22-3A2C2A22-5ACA22-C5AC22-A2C4A22-3AC3A22-4A2CA22-6AC20-B-7A20-2B7AB18-3B7A3B16-13B19-2BD4B490-B25-B2-2B23-7B22-7B214-
