model
size = 13 21 13, scale = 0.05, origin = -y
material 
  colors = A:#03C B:#888 C:#B00 D:#EEE E:#DDD F:#AAA G:#555
voxels
17-5B8-5A8-5D8-5B2(8-5D8-5A)8-5D8-5B8-2(BF)B8-5B8-5D8-5A8-5D8-5C8-4EC8-5C8-5B21-5B6-9B4-9A3(4-A7DA)4-9A4-2D5A2D4-9A5(4-A7DA)4-9A4-2D5A2D4-9C4-5E3CF4-9C4-9B6-5B7-7B4-11B5(2-11A)2-D9AD7(2-11A)2-D9AD2-11C2-E8C2F2-11C2-11B4-2(B5-)9B3-11B5(2-11A)2-D9AD7(2-11A)2-D9AD2-11C2-9C2F2-11C2-11B3(3-B)3-11B-13B25AB13AB11AB13AD11AD13AB11A2B24A2B12AB25AD11AD13CF10CEF13C13B2(-B3-B)2-11B-13B13AB24A2B25AD11AD13AB11A2(B12A)2B11A2B25AD11AD7CA8C5A3CEF3C5A5C13B-B3-3B3-B2-2(5B-)13B25A2B24AB13AD11AD26AB12AB11A2(B12A)B13AD11AD7CA5CF2C5A3CEF3C5A5C13B2(-B3-B)2-11B-13B13AB24A2B25AD11AD25A2(2B11A)B12A2B25AD11AD7CA8C5A3CEF3C5A5C13B-2(B4-)B2-11B-13B25AB13AB11AB13AD11AD13AB11AB25A2B12AB25AD11AD16CA7CEF3CA9C5B3G5B-B9-B3-9B3-11B5(2-11A)2-D9AD7(2-11A)2-D9AD2-11C2(2-2CA8C)2-4BGBG4B3-B7-B5-7B4-11B5(2-11A)2-D9AD7(2-11A)2-D9AD2-11C2-4E7C2-2CA8C2-5BG5B4-B5-B7-5B6-9B5(4-9A)4-2D5A2D7(4-9A)4-2D5A2D4-9C4-3E5CE4-9C4-9B6-5B21-5B8-5A8-BA3B8-5A8-2BA2B8-5A8-5D2(8-5A)8-A3DA8-AD3A8-A3CA2(8-5A)8-5D8-5C8-EC3F8-5C8-5B17-
