model
size = 28 30 28, scale = 0.05, origin = -y
material 
  colors = A:#EEE B:#CC6 C:#111 D:#555 E:#F0C F:#3CF G:#F06 H:#FC9 I:#FF3 J:#F63 K:#CFF L:#CCC M:#F9F N:#CC9 O:#FF6 P:#F9C Q:#F3F R:#FF0 S:#F30 T:#FCF U:#F90 V:#FFC W:#FC0 X:#F99 Y:#CCF Z:#FC3 Aa:#F0F Ab:#CF3 Ac:#F66 Ad:#CFC Ae:#F39 Af:#CC0 Ag:#FF9 Ah:#F36 Ai:#F6C Aj:#F03 Ak:#FFF Al:#F09 Am:#F96 An:#F69 Ao:#F60 Ap:#F00 Aq:#F3C Ar:#F33 As:#CF6 At:#CC3 Au:#CF9 Av:#F93 Aw:#FCC Ax:#CF0 Ay:#FC6 Az:#F6F
voxels
2(28-29D25(26A2D)26A29D)56-D26AD728AD26AD56-D26AD417A8(C2-25A)C2-84AD26AD56-D26AD4A13(20B8A)3(20BAC2-4A)20BA7(C2-25A)C2-56AD26AD56-D3A20-3AD7(3AB20-BAC-)3A5(B20-B6A)4(B20-BC2-3A)B20-BC2-4ASLRZAtTSRAaZBZApMLAoAyAhKGA7(C2-25A)C2-28AD26AD56-D3A20-3AD3A6(B20-B6A)B20-BAC-3A5(B20-B6A)4(B20-BC2-3A)B20-BC2-4ANRISAaSAcHSArAiLGVAcEZAbAqUA7(C2-25A)C2-28AD26AD56-D3A20-3AD3A6(B20-B6A)B20-BAC-3A5(B20-B6A)4(B20-BC2-3A)B20-BC2-4AOHAyNSUAsKAd2AkOWAbAjUArPMPA7(C2-25A)C2-28AD26AD56-D3A20-3AD3A6(B20-B6A)B20-BAC-3A5(B20-B6A)4(B20-BC2-3A)B20-BC2-4AAjKZOAdAsHApAuMAhBMLKAsAk2GAoAC2-2(25ACE-)5(25AC2-)28AD26AD56-D3A20-3AD3A6(B20-B6A)B20-BAC-3A5(B20-B6A)4(B20-BC2-3A)B20-BC2-4AAfApArAjAuAyAtAdAm2VAeAlAcAqIMUNEA4(CE-25A)3(C2-25A)C2-28AD26AD56-D3A20-3AD7(3AB20-BAC-)3A5(B20-B6A)4(B20-BC2-3A)B20-BCE-4AAgAdAkAfAmAdAzOAvAbNAtTAjMHVPAfUA5(CE-25A)2(C2-25A)C2-28AD26AD56-D3A20-3AD7(3AB20-BAC-)3A5(B20-B6A)4(B20-BC2-3A)B20-BCE-4AGOMAgAvAnHJAwLIArAaKGIAbAoXAsA5(CE-25A)2(C2-25A)C2-28AD26AD56-D3A20-3AD3A6(B20-B6A)B20-BAC-3A5(B20-B6A)4(B20-BC2-3A)B20-BC2-4AQJVGAwYAdHAnAcXAmQAqNYLEQIA4(CE-25A)3(C2-25A)C2-28AD26AD13-D27-D14-D3A20-3AD3A6(B20-B6A)B20-BAC-3A5(B20-B6A)4(B20-BC2-3A)B20-BC2-4AGHAbQAnT2WRAjYWAeMAfAeAcUJHAC2-2(25ACE-)5(25AC2-)28AD26AD41-D14-D3A20-3AD3A6(B20-B6A)B20-BAC-3A5(B20-B6A)4(B20-BC2-3A)B20-BC2-4ALWLGRAxPAvAgKAoAyAbGXBAjAsJIA7(C2-25A)C2-28AD26AD41-D14-D3A20-3AD3A6(B20-B6A)B20-BAC-3A5(B20-B6A)4(B20-BC2-3A)B20-BC2-4AAnAvAcLAgAxAaAmKAqAmAcONQTKI2YA7(C2-25A)C2-28AD26AD41-D14-D3A20-3AD3A6(B20-B6A)B20-BAC-3A5(B20-B6A)4(B20-BC2-3A)B20-BC2-4AAlAmAjAnKQAoAgWMAkMZAfJLAqHAiAeAC2-2(25ACF-)5(25AC2-)28AD26AD41-D14-D3A20-3AD3A6(B20-B6A)B20-BAC-3A5(B20-B6A)4(B20-BC2-3A)B20-BC2-4ABAgKAlWAuAgAeAnGESLXJRM2IBA4(CF-25A)3(C2-25A)C2-28AD26AD13-D27-D14-D3A20-3AD7(3AB20-BAC-)3A5(B20-B6A)4(B20-BC2-3A)B20-BCF-4AAiAeAqBAnXApZAhN2VOQYHGYAaTA5(CF-25A)2(C2-25A)C2-28AD26AD56-D3A20-3AD7(3AB20-BAC-)3A5(B20-B6A)4(B20-BC2-3A)B20-BCF-4AAkZMAiAhAgGAxAbAfJAuBJAiKNAePLA5(CF-25A)2(C2-25A)C2-28AD26AD56-D3A20-3AD3A6(B20-B6A)B20-BAC-3A5(B20-B6A)4(B20-BC2-3A)B20-BC2-4AAhAxGAkAbBWAlPXAlAvAeJIApAfBAzRA4(CF-25A)3(C2-25A)C2-28AD26AD56-D3A20-3AD3A6(B20-B6A)B20-BAC-3A5(B20-B6A)4(B20-BC2-3A)B20-BC2-4AVAlNAhPOMTGQAwAhAtYAaAdXTSHAC2-2(25ACF-)5(25AC2-)28AD26AD56-D3A20-3AD3A6(B20-B6A)B20-BAC-3A5(B20-B6A)4(B20-BC2-3A)B20-BC2-4ANTAfVGAuAlOUJAxIArAiPOQLAcKA7(C2-25A)C2-28AD26AD56-D3A20-3AD3A6(B20-B6A)B20-BAC-3A5(B20-B6A)4(B20-BC2-3A)B20-BC2-4AIOXNUAzTAwPJAtUAmIAz2JRAsApA7(C2-25A)C2-28AD26AD56-D3A20-3AD7(3AB20-BAC-)3A5(B20-B6A)4(B20-BC2-3A)B20-BC2-4AXAwQIPArAaRAoYKAiWAaSHJ2HAdA7(C2-25A)C2-28AD26AD56-D26AD4A13(20B8A)3(20BAC2-4A)20BA7(C2-25A)C2-56AD26AD56-D26AD417A8(C2-25A)C2-84AD26AD56-D26AD728AD26AD56-
