model
size = 31 31 16, scale = 0.05, origin = -y
material 
  colors = A:#CF3 B:#C36 C:#66C D:#09F
voxels
13-3(C-)C23-3(C-)C22-C-3(CA)C2-C17-C-4(CA)C2AC17-2(CA)7BAC3AC12-C2AC11B2ACA12-AC15B3AC8-C2A17BACA8-AC19B3AC4-3C21B2C6-2A21B2A4-3C23B3C3-2A9B5D9B2A2-3C9B7D9B2(3C-2A8B9D8B2A-3C8B9D8B)3C-2A8B9D8B2A2-AC9B7D9B3C-C2A9B5D9B2A4-2A23B3C3-ACA21B3A4-C2A21B3C5-2AC19BACA6-2C2A17BC2A2C6-2(CA)15B2(CA)10-2(CA)11B3(AC)10-3(CA)7B3(AC)14-C-6(CA)C-C16-C-3(CA)C-C426-2(C-)C56-3(C-)C56-2(C-)C738-C32-2(C-)C22-2(C-)4A26-6AC22-C7A24-7A-C22-7A23-C7AC24-6A24-3(C-)C58-C-C523-C-C25-C32-3(C-)C20-C2-7A23-9AC-C18-11A18-C-11AC-C17-12A16-C2-12AC-C15-C12A19-12AC-C15-C11A19-C-9AC-C20-7A21-2(C-)C4A2(-C)53-C2-C32-C401-C26-6AC22-9A21-12AC17-14A15-C16A15-16A13-C18AC12-2(18A13-)18A12-C2(18A13-)C16A16-14A17-14AC17-12A19-C9AC23-6A26-C339-C2-C25-C7A22-11A18-C-12AC17-14A15-18A13-18AC11-20A10-C20A11-20AC10-20A10-C20AC10-20A11-20A12-18AC12-18A14-16A16-14A18-12A19-11A21-C7A28-C279-C25-7AC21-11AC19-12A17-16A15-16AC12-20A10-C20AC9-22AC8-4(22A9-)22AC8-22A9-C20A11-20AC11-18A14-16AC13-C16AC16-12A19-11AC21-7AC24-2(C-)C243-6A22-11A18-C-12AC16-16AC12-C18A13-18A11-2(22A9-)22A8-2(24A6-C24A7-)24A7-24A8-2(22A9-)C20A12-18A13-18A14-16A16-C12AC18-11A21-C-6A183-C26-C-C2A-C22-C9AC20-12AC16-16A14-18AC2(11-20A)C8-C22A8-24A6-C24AC6-24A7-24AC5-25A6-25AC6-24A6-C24AC6-24A7-C22AC8-22A10-20AC9-C20A12-18AC12-C16AC15-C12A-C17-C9A-C21-3(C-)C179-7A22-12A17-C14A16-16A13-C18A12-20A10-22A8-24A7-24A3(6-25A)5-C3(25A6-)25A3(7-24A)8-22A10-20A12-18A14-16A16-14A18-12A148-C-C24-C-C4A-C20-C11AC18-14A15-C16AC13-18A11-C20AC9-22A7-C24AC5-25A6-25AC5-25A5-C25AC2(4-27A)C2-C27A4-27AC4-25A5-C25AC5-25A6-C24AC6-24A7-C22AC8-C20A12-18AC12-C16A16-14AC16-2(C-)C4A2(-C)24-C-C118-7A22-12A18-14A15-18A12-20A10-22A9-22A8-24A2(6-25A)5-6(27A4-)27A5-2(25A6-)25A7-24A8-22A9-22A10-20A12-18A15-14A20-7A117-3(C-)C22-C9AC18-C-12A-C15-16A13-C18AC10-C20A10-22A7-C24AC6-24A5-C25AC4-2(27A3-C27AC3-)27A4-27AC2-C27A4-27AC3-27A4-C25AC5-25A6-C24AC6-24A7-C22AC9-20A11-C18AC13-16AC14-C-C9AC-C20-3(C-)C87-6A22-11A19-14A15-18A12-20A10-22A8-24A7-24A6-25A5-2(27A4-)27A3-5(29A2-)29A3-27A4-27A5-25A6-25A2(7-24A)8-22A10-20A12-18A16-11A23-6A56-2(C-)C24-C7AC20-C12AC15-C-14A15-18AC10-C20A10-22AC6-C24A7-24A5-C25AC4-27A3-C27AC2-2(29A-C29AC-)29A2-29A2C29A3-27AC3-27A3-C27AC4-25A6-C24AC6-24A8-22AC8-C20A12-18AC12-C-C12A-C18-C7AC-C22-2(C-)C56-7A22-12A17-16A14-18A12-20A10-22A8-24A2(6-25A)5-27A4-27A3-6(29A2-)29A3-2(27A4-)27A5-25A6-25A7-24A8-22A10-20A12-18A16-12A21-7A43-
