model
size = 32 30 28, scale = 0.05, origin = -y
material 
  colors = A:#E00 B:#333 C:#222 D:#444 E:#EEE F:#300 G:#111 H:#555 I:#100 J:#666
voxels
428-6(5G27-)5G731-6(5G27-)5G764-2B2AB26-B4AB4(25-C5AC)25-D4AD27-4D635-9B22-10B21-10B11E10-5B5AB11E10-4D6AD11E10-3D6ADB11E10-3B6A2B11E10-3B7AB11E10-3C7AC11E10-3C6A3C21-3C4A4C22-10D24-7D473-8B23-9B22-11B19-3B9A2B18-2C10A10E10-B20AF9-D9A2D10AF9-B7A4B2(10AF8-2B6A3B-B)10AF8-2B5A6B10AF8-2B5A4B12AF9-C6A3C3A10E9-2G11A2G18-2G10AG19-4D7A2D20-10H23-8D318-5D24-3B3A3B20-3C7A3C17-C13A2C2(15-B15AB)13-2C18A5E7-B5A5B13AF7-B3A9B11AF7-3A3B8-F9AF7-3A2B9-F9AF7-2A2B10-F9AF6-D2AD11-F9AF6-B2(2AB11-F9AF7-)2A2B10-F9AF7-3A2B9-E3A7E7-B2A2B8-B4A14-C2A4C5-2C3AC14-2G3A9G2AG16-2C3A7C2A2C18-B10AB20-3B6A3B22-8C222-3D2A2D23-2B6A2B19-3C9AC14-2B5AB10AB13-B4A5B8A2B11-2B4A6B7A2B3-E7-3A11B10AF7-3A3B5-3B10AF6-B3AB9-B10AF6-B2AB11-F9AF6-BA2B11-F9AF6-BAB2(12-F9AF5-D2AD)12-F9AF5-2B2(AB12-F9AF6-B)A2B11-F9AF6-B2AB11-E3A7E7-2AC11-C3A14-3A2C9-C2AC14-C2A3C7-C3AC15-2C3A6C3AC18-C12A20-2C8A2C193-2D4-3D19-2H4A2H2-2DG16-3D7A2D-2DG13-6D7A2D-2DG7-3C2A3C-5C6AC-3D7-B3A2B5-4B6A-3D7-3A3B6-3B6A3-E6-B3A11-F9AF6-C2AC11-F9AF6-B2AB11-F9AF5-B2AB12-2(F9AF5-BAB13-)2(F9AF5-DAD13-)3(F9AF5-BAB13-)F9AF5-BA2B12-E5A5E6-BAB13-B2A2B11-B2AB12-3A13-B2AB11-B3A14-D3A2D6-D3AD16-B4A6B3A2B17-B12A22-7B134-2H28-2H2AH-3D22-2H4A-2AD22-2D4AD2AD22-3H3AH2AD24-B7A6-4B14-B4A3D6-C2AC14-C4AC-E5-C2AC12-2(F9AF4-C2AC13-)F9AF4-C2A14-F9AF4-B2A4(14-F9AF4-2AB)14-F9AF4-2AD14-F9AF4-DAD14-F9AF4-D2A14-3E4A4E4-B2A17-BAB10-BAB15-B2AB10-HAH14-H3AH11-D2AD12-3A14-3AD9-2D2AD14-B3A4B-4B3AB18-D9A2D21-9D101-3D27-2D3A-3D24-H3AH2AD24-H2(6AD25-)H6A5-4D16-D3A3D5-B2AB16-B4ABE4-C2AC13-2(F9AF4-C2A14-)F9AF4-2AC2(14-F9AF4-2AB)14-4(F9AF4-AC15-)F9AF4-2AC14-F9AF4-2AB14-4E3A4E4-BAB17-B2AB8-C2A17-CAC9-C2A16-C2AC10-H2AH13-3A13-D2AD11-D3A14-3A2B7-2B2A2B16-D11AD20-3D5A3D24-5B41-B29-2DA28-H3AH28-7A2(25-H6A)26-H2A3D5-3D18-D3AD6-CAC18-C3ACE2(4-C2A14-F9AF)4-2AC14-F9AF4-2AB14-F9AF4-2AC14-5(F9AF3-CAC15-)2(F9AF4-AC15-)5E3A3E4-2AC18-2AC8-2AC17-C2AC8-C2A17-CAC10-BAB14-B2A2B11-DA2D12-3A13-H3AH9-2H2AH15-2B3A4B5AB19-C8A3C21-8B40-2B28-2C2AC28-B2AG-G26-D5A26-D4A3G25-D3A3G25-D2AGA27-H2(AG)4-3H20-H3A5-2AC14-7E3AE2(4-2AC14-F9AF)3-CAC15-F9AF3-BAB15-F9AF3-2B5(16-F9AF3-2C)16-6E2A3E3-2C21-CAC6-CAC19-C2A8-AC19-3A8-2AC18-2AC8-C2A16-C2AC10-BA2B13-B2A2B11-C2AC11-C3A14-2C2A4C-3C3AC18-2(C5A)C20-3B4A4B38-3B28-C2AC28-C2A3G27-B3A3G25-B5AG25-D5AG25-H4A27-DA2GA4-3H21-3AC4-2AG21-3A5-2AC14-7E3AE3-CAC15-F9AF3-BAB15-2(F9AF3-2B16-)F9AF2-CAC16-2(F9AF2-BA17-)F9AF3-C17-7E2A2E3-2(2C22-CAC5-)2C20-C2A8-AC19-C2A8-AG19-2AG8-C2A16-C2AC10-CAC14-C2A2C10-C2A2C12-3A14-C3A2C4-3C2A2C16-2C3A4C4AC20-3B5A3B38-3B29-B2AB28-BA3G27-B3A3G25-D5AG25-B5AG26-4A28-A2GA4-3H2(21-3AC4-2AC)21-3A4-BAB15-7E3AE3-BAB15-F9AF3-2B16-F9AF2-BAB16-F9AF2-C2(A17-F9AF2-B)A17-8E2AE2-CA24-2C4-CA23-CAC5-C23-CAC5-2C21-CA7-CAC19-C2A8-AC19-2AC8-C2A16-C2AC9-C2AC14-C2A2C10-C2AC13-3A14-C2A3C5-2C2A2C16-2B3A5B3AB20-2D7A2D38-3B29-B2AB29-A3G28-3A3G2(26-5AG)26-4A28-A2GA4-2G22-3AC4-2AB21-B2AC4-AB22-B2A4-BAB22-2BA4-2C16-9EAE3-2C16-E9AE2-BAB16-2(E9AE2-BA17-)8E2AE2-BA25-2B3-BA24-BAB3-BA24-AB4-BA23-BAB5-2C21-CAC6-2B20-B2A8-AB19-2AB8-CAC17-CAC9-C2AC15-CA2C10-B2AB13-B2A14-B2A2B7-2B2AB16-2D2A7D2A2D19-2B7A2B38-3B29-C2AB28-BA3G28-3A3G2(26-5AG)26-4A28-A2GA4-2H22-3AC4-2AB21-3AC4-AC22-C2A4-CAC15-7E3AE2(3-2C16-F9AF)2-CAC16-3(F9AF2-BA17-)8E2AE2-BA24-BAB3-BA24-AB4-CA23-CAC5-2C21-CAC6-2C20-C2A8-AB19-2AB8-CAC17-CAC9-B2AB15-BA2B10-B2AB13-B2A14-D2A2D7-2D2AD16-2H2A7H2A2H19-2B7A2B38-3B29-B2AB28-CA3G27-B3A3G25-B2(5AG26-)4A28-A2GA4-2D22-3AC4-2AC21-3AC4-AG15-7E3AE3-CAC15-F9AF3-2C16-F9AF3-2G16-F9AF2-CAC16-2(F9AF2-BA17-)2(F9AF2-CA17-)7E2A2E2-CA23-CAC5-C23-CAC5-2B21-BA7-BAB19-B2A8-AD19-2AD8-C2A17-CAC9-C2AC15-CA2C10-B2AB13-B2A14-D2A3D5-2D2A2D16-2D3A5D3AD20-2C7A2C38-2B29-B2AB28-B2AGBG26-B5A27-2(D3A3G25-)B2AGA27-B2(AG)4-3B20-B3A5-2AB14-6E4AE4-2AB14-F9AF4-2AC14-2(F9AF3-GAG15-)2(F9AF3-2G16-)4(F9AF3-2C16-)5E4A2E3-2B21-B2AB5-C2(AC19-C2A8-)2AC18-2AC8-C2A16-C2AC10-CAC14-C2A2C11-BA2B12-3A14-B3A3B2-3B3A2B16-2B4A2B5AB20-3D5A3D38-2B28-2BAB28-B3AB28-2(B5A26-)D5A27-BA3G27-D3A5-3B20-B3AE4-HAH14-F9AF4-2AB14-F9AF4-2AC14-3(F9AF3-GAG15-)F9AF3-2C2(16-F9AF3-2B)3(16-F9AF3-2C)16-5E3A3E4-AD19-D2A8-AB19-2AB8-2AC17-C2AC8-C2AC15-C2AC10-C2AC13-C2A2C11-B2AB11-B3A14-2B3A7B3AB18-B10A2B20-5DA4D39-B29-2BAB28-3AB3D2(25-B5AD)26-B4AD26-B5A5-2B19-B2A3D5-DAD18-D3ADE4-H2A14-F9AF4-3A14-F9AF4-2AC14-F9AF4-2AG14-2(F9AF3-CAC15-)F9AF3-BAB15-F9AF3-2D16-F9AF3-2B16-2(F9AF3-BAB15-)F9AF4-AB15-4E4A3E4-2AB18-3A8-2AH18-2AH8-CAC17-CAC10-GAG14-G2A2G10-G2AG13-3A13-C2AC10-2C2AC15-2B3A5B4AB19-B8A3B21-8D70-3B27-2D2AD-3D22-2B4AB2AD23-2B3AB2AD23-2B6AD24-D7A6-4D15-4A3D5-B2AB16-B3AB-E5-DAD13-F9AF4-B2AB13-F9AF4-C2A14-F9AF4-3A4(14-F9AF4-2AC)14-F9AF4-2AB14-F9AF4-2AC2(14-F9AF4-2AB)14-4E3A4E4-B2A17-B2AB8-B2A16-B2AB10-BAB15-B2AB11-CA2C12-3A13-B3A10-2B2AB14-B2A3B5-2B3AB17-D10A2D20-10B101-B29-2DAD2-3D20-2D5AD-3G20-3D5A-3G21-2D5AD3G7-4D11-2D4A2(DG)6-D3A12-3D3A4D6-B2AB13-2B3AB2-E2(5-D2AD12-F9AF)5-DAD13-F9AF4-B2A14-F9AF4-D2(2A14-F9AF4-B)AB14-F9AF4-CAC14-F9AF4-BAB2(14-F9AF4-B2A)14-F9AF4-D2A14-3E4A4E5-CAC15-C2AC10-BAB15-B2AB10-B2AB13-B2A2B11-C2AC11-C3A14-3A3C6-2C3AC14-2C4A6C3A2C18-2C7A3C22-7C132-3C25-2B5AB21-4D7AD20-5H6AH11-6D6-3D6A11-3A2D7-3D6A11-3AD9-3D5A3-E6-B2AB11-F9AF6-D2AD11-F9AF5-J2AJ12-F9AF5-HAH13-F9AF5-DAD13-F9AF4-D2AD13-2(F9AF4-B2A14-)F9AF4-D2A14-F9AF4-B2AB13-F9AF5-BAB13-F9AF5-CAC13-2E4AC4E5-C2AC13-C2A2C11-BAB13-B2A2B11-B2AB12-3A14-3A2C7-2C3AC14-G4A7G4AG16-2G12AG20-9C190-6C23-3C4A3C19-3B9AB16-B15AB15-B15A2B13-2D15A2D12-D4A7D7AD5E7-D3A9D11AF7-3A11D10AF6-B3AB10-F9AF6-D2AD11-F9AF6-B2AB11-F9AF6-DA2D11-F9AF6-BA2B11-F9AF6-DA2D2(11-F9AF6-D2AD)11-E3AD6E7-2A2D10-D3AD13-B2A3B7-2B2AB14-C2A4C5-2C2A2C14-2C3A9C2AC17-C12AC19-2C8A2C21-5GA4G221-3I26-7G23-3C3A5C18-3B10A2B17-2B11A2B17-B13AB15-2B15AB14-B16AB6E7-2B22AF7-D3A8D2-F9AF7-D2A6D5-F9AF7-D2A5D6-2(F9AF7-B2A3B8-)F9AF7-C2A3C7-C10AF7-B2A3B6-2B4A7E7-D2A4D5-2D3AD14-2D2A4D3-3D3AD15-2H3A7H3AH16-2B4A5B3AB18-2C11AC19-4C5A3C22-8C28-C287-3G26-10B21-4B3A4B20-3C7A3C18-2B10A3B16-2B12A2B16-B13A2B7E8-2B9AB-B3A7E8-2B6A3B2-B3A7E8-2B5A4B2(2-B3A7E8-B4A6B)2-B3A7E8-2B3A8B4A7E8-2B3A6B4A2B15-2B4A5B3A2B17-B5A3B4A2B18-2B10A2B18-3D6A3D21-11D24-5H508-5C26-7B24-D5A3D2(22-2B5A3B)22-2D5A3D22-2B5A3B22-2C5A3C23-C5A2C24-B5AB25-6B699-7(G4A27-)5G335-
