model
size = 24 20 13, scale = 0.05, origin = -y
material 
  colors = A:#4E70A0 B:#71A0CA C:#4EBAD6 D:#823B39 E:#FFF F:#261B21 G:#F7F48D H:#823A2E I:#B67464
voxels
218-2(A2B6A2IA2BA9-)2(A2FA7EA2FA9-)2(6A2H7A9-)4(15A9-)15A225-10A2B3A9-12A2(-2A9-4AE5AEA)-2A9-15A9-2A2-A7-3A3(9-2A2-A8-2A)2(9-15A)13-2(2A12-2A8-)2(2A12B2A8-)2(16A8-)2A2G12A8-2D2G6D6A8-10D6A4-4A-15A4-20A4-2(4AE5AE4A9-)15A9-2A2-A7-3A3(9-2A2-A8-2A)2(9-15A)13-2(2A12-2A8-)2A12B2A8-2A9B5A3(8-16A)2(8-D15A)4-4A-15A4-20A4-2(4AE10A9-)15A9-2A2-A7-3A3(9-2A2-A8-2A)2(9-15A)61-16B8-13B2AB8-B11AB2AB8-B14AB8-B2(15A8-D)15A4-4A-15A4-20A4-2(4AE10A9-)15A2(9-11A-3A)2(9-2A2-A8-2A)2(9-15A)61-16B8-13B2AB8-B11AB2AB8-B14AB8-B15A8-D15A2-2C4-D15A2-2C4A-11A2C2A2-2C15A4C3A2C4AE10A4C-2A2C4AE10A4C3-2C15A2(2C5-2C11A-3A)2(2C5-2C2A2-A8-2A)2C7-15A9-15A61-16B8-13B2AB8-B11AB2AB8-B14AB8-B15A8-D15A2-2C4-D15A2-2C4A-11A2C2A2-2C15A4C3A2C4AE10A4C-2A2C4AE10A4C3-2C15A2C5-2C2(5A-)3A3(2C5-2C5A-9A)2C7-5A-9A9-15A61-16B8-13B2AB8-B11AB2AB8-B14AB8-B15A8-D15A2-2C4-D15A2-2C20A2-2C15A3C2A2-2(2C4AE10A4C3-)2C15A2C5-2C11A-3A3(2C5-2C15A)2C7-15A9-15A61-16B8-B2ABA4B6AB8-3B12AB8-B14AB8-B2(15A8-D)15A2(4-20A)4-2(4AE10A9-)15A9-11A-3A5(9-15A)17-2A4-2A16-2A4-2A12-6A4B6A2(8-5A4B7A)2(8-16A)2(8-10D6A)4-20A4-4A-15A4-2(4AE10A9-)12A-2A9-11A-3A5(9-15A)17-2A4-2A16-2A4-2A12-2(6A4B6A8-)3(16A8-)10D6A8-10D6A4-20A4-4AE15A4-2(4AE10A9-)6(15A9-)2(15A225-10(15A9-))15A7-
