model
size = 8 29 8, scale = 0.05, origin = -y
material 
  colors = A:#B00 B:#A00 C:#C30 D:#222 E:#930 F:#996 G:#CC0 H:#CC6 I:#396 J:#111
voxels
10-4C2(4-4A)2(4-4B)12(4-4A)2(4-4B)3(4-4A)52-4C2(4-4A)2(4-4B)12(4-4A)2(4-4B)3(4-4A)59-6C2(2-6A)2-2B3AB2-6B12(2-6A)2-2B2A2B2-6B2-6A2-2A2D2(2A2-)2A57-CE4CEC16A3B4A4B4AB96A3B2A11B10A4D4A4-2A27-F7-F15-G4-2C4E2C16A3B4A4B4AB96A3B2A6B4AB9A3DJ2D2A3-I2-A4-F7-F6-F23-F6-GHG3-3C2E3C16A3B4A4B4AB96A3B2A6B4AB9A6D2A6-A51-G4-2(2CE)2C16A14BAB96A3B2A11B10A4D4A4-2A57-E4CE2(2-6A)2(2-6B)12(2-6A)2-2B2A2B2-6B2-6A2-2A2D2(2A2-)2A57-
