model
size = 7 6 3, scale = 0.05, origin = -y
material 
  colors = A:#D9D4D8 B:#AD290C C:#807478
voxels
10AB5A3B5AB10A7-10AB5A3B5AB10A3-C3-10AB5A3B5AB10A7-
