model
size = 21 32 8, scale = 0.05, origin = -y
material 
  colors = A:#400 B:#993 C:#AAA D:#EEE
voxels
428-5B16-5B416-3A16-6(7A14-)7A15-5A16-5A15-2(7A14-)7A13-9A12-9A11-4(11A10-)11A12-7A15-5A206-3A16-7A14-2A4DA14-A5CA14-A2CD2CA14-AC3D2A13-2A4D3A12-A7CA12-2A5C2A14-5A15-2(7A14-)7A13-9A12-9A11-3A-7A6(10-11A)11-9A15-3A16-5(2A3-2A14-)3(2B3-2B14-)2B3A2B14-5ADA14-A5DA14-A5CA14-A2CD2CA14-AC3DCA13-2A5D2A6-3A3BA7CA3B6A3B2A5C2A3B4A7-5A7-3A5-7A5-2A7-7A14-2A3B2A13-3A3B3A12-2A5B2A11-3A5B3A4(10-2A7B2A)2(10-2A2B3A2B2A)2(11-9A13-7A5(14-2A3-2A)3(14-2B3-2B)14-2B3A2B14-AD3ADA14-A5DA14-A5CA14-A2CD2CA14-AC3DCA13-2A5D2A6-3A3BA7CA3B6A3B2A5C2A3B4A7-5A7-3A5-7A5-2A7-7A14-2A3B2A13-3A3B3A12-2A5B2A11-3A5B3A10-2A7B2A10-2A2D3B2D2(2A10-2A7B)2(2A10-2A2B3A2B)2A)11-9A13-7A14-2A3-2A163-3A16-7A14-A5DA14-A5CA14-A2CD2CA14-AC3DCA13-2A5D2A12-A7CA12-2A5C2A14-2(5A16-)2(B3AB16-)5B15-7B14-7B13-9B12-B2D3B2DB12-9B11-2A7B2A10-2A2B3A2B2A11-A2B3A2BA12-9A14-5A15-2A3-2A184-3A16-4(7A14-)3AD3A2(14-7A)15-2(5A16-)2(5B16-)5B15-7B14-7B13-9B12-B2D3B2DB2(12-9B)12-A7BA12-A2B3A2BA13-7A28-
