model
size = 17 30 11, scale = 0.05, origin = -y
material 
  colors = A:#AF7754 B:#F3E1C9 C:#5B4224 D:#4D2A0A E:#3D3123 F:#E8B8AA G:#FFF
voxels
153-10(12A5-)12A181-D5-D10-A5-A9-2A4-2A6-2(5A4B4A4-)11ABA4-13A4-7AB5A4-10AB2A2-4(12A5-)10A-A5-9A-2A5(5-12A)181-D5-D10-A5-A9-2A4-2A6-3ABA4B4A4-A2B10A4(4-13A)2-5(12A5-)9A-2A5(5-12A)228-13B4-B11AB4(4-B12A)2-5(12A5-)9A-2A5(5-12A)5-2(3A14-)3A186-13B4-B11AB3(4-B12A)2B2-B26A4(5-12A)5-9A-2A5(5-12A)5-A2B2(C13-3A)C14-2EC16-C14-3C2(14-C-C)2(16-C)66-13B4-B11AB3(4-B12A)2B2-B26A4(5-12A)2(5-9A-2A)2(5-A10-A)5-12A5-8AB4(3A13-C)2E14-C16-3C2(14-C-C)14-C16-C61-13B4-B11AB4(4-B12A)2-5(12A5-)2(9A-2A5-)2(A10-A5-)12A5-12A14-2BA2(14-3A)127-D10-D5-A10-A4-2A9-2A4-2A9B2A5(4-13A)2-5(12A5-)A9-2A3(5-A10-A)2(5-12A)178-D10-D5-A10-A4-2A9-2(2A4-2A9B)2A4-12AB4-8AB4A4-13A4-11ABA2-5(12A5-)A9-2A3(5-A10-A)2(5-12A)328-A10BA5-12A2(5-10A-A)5-12A5-A9-2A3(5-A10-A)2(5-12A)328-2(B2F6B2FB5-)B2DB4GB2DB5-B2EB4GB2EB5-4BAE2A4B5-4A3E5A5(5-12A)175-
