model
size = 14 19 19, scale = 0.05, origin = -y
material 
  colors = A:#9CE33B B:#6C3 C:#1A222F D:#FFF E:#F3E1C9 F:#FCDFAC G:#FFC86B H:#FB807B
voxels
5-2(4B262-)2(4B10-4B248-)3(4B10-)4B220-3(4B10-)4B24-4B10-4B178-3(4B10-)2(4B24-4B10-)4B109-2A12-2A11-3(4B10-)3(4B24-4B10-)4B67-2A12-2A11-4B10-4B8-7(8A6-)8A3-22AB13AB75A33-4B8-7(8A6-)8A3-112A17-2(2A4-2A6-)3(8A6-)8A4-12A2-12A4-8A6-8A3-112A17-2(2A4-2A6-)AE6A6-A4E3A6-2A4F2A6-8A4-12A2-12A4-8A6-8A3-33A4G2A2C6A4G2A2C57A45-8A6-A4E3A6-2A4F2A5(6-8A)3-18A-93A45-7(8A6-)8A3-3(112A154-)37AD13AD60A154-25A2(-3A2C6ADA)-58A154-A2(2H8A2H2A)2CA6DA2C2A2CA6DA2C57A14-
