model
size = 24 12 9, scale = 0.05, origin = -y
material 
  colors = A:#111 B:#E00 C:#040
voxels
4-17B7-17C7-4A2C2B2C7A7-5A2C2B2C6A9-4A2C2B2C5A10-4A2C2B2C4A11-4A2C2B2C3A12-4A2C2B2C2A17-2C2B2CA20-2B2C20-C2BC20-2C6-21B3-7C13AC3-21A3-3A2C16A6-2C-15A9-15A11-13A12-12A18-6A19-5A19-4A20-2A6-22B2-6C15AC2-AC2B18A2-2A3C17A4-4CB15A6-2CB-9A3-2A8-B-9A3-2A10-A-3A2B2A3-2A12-A-A2B2A3-2A16-B2A3-2A17-2A22-A7-5B4CB3C11B7C16ACA2CB22A4C17AB2-5CAB14AB4-2C3B9A5-A6-3BAB7A5-B8-3(BA)B3A5-A10-2(BA)B3A5-A12-BA2B2(2A5-A16-)A7-8BC4BC10B7C16ACA2CB19AB2A4C18A2-5CB16A4-2C2BAB8A5-A6-2B2(AB)6A5-B8-3(AB)4A5-A10-2(AB)4A5-A12-2(AB)2A5-A16-2C5-A16-C7-8BCB3C11B7C16ACA2CB22A4C17AB2-5CAB14AB4-2C3B9A5-A6-3BAB7A5-B8-3(BA)B3A5-B10-2(BA)B3A5-B12-BA2B2A5-B16-2A5-A16-A8-22B2-6C15AC2-ACB19A2-2A3C17A4-4CB15A6-2CB-9A3-2A8-B-9A3-2A10-A-3A2B2A3-2A12-A-A2B2A3-2A16-B2A3-2A17-2A22-A8-21B3-7C13AC3-21A3-3A2C16A6-2C-15A9-15A11-13A12-12A18-6A19-5A19-4A20-2A9-17B7-17C7-4A2C2B2C7A7-5A2C2B2C6A9-4A2C2B2C5A10-4A2C2B2C4A11-4A2C2B2C3A12-4A2C2B2C2A17-2C2B2CA20-2B2C20-C2BC20-2C5-
