model
size = 31 31 8, scale = 0.05, origin = -y
material 
  colors = A:#7C3B0B B:#989898 C:#712F00 D:#884617 E:#945222 F:#7E7E7E G:#646464 H:#B1B1B1 I:#CBCBCB J:#E5E5E5 K:#FFF L:#9F5D2E M:#4B4B4B
voxels
448-3B27-2H3B26-3H2B26-J3HB27-J2H705-M32-8(A29-2C)A29-C32-M301-7B21-BH9FHB16-2B2FG7-G2F2B13-2BG13-G2B11-BFG15-GFB9-BF19-FB7-BF21-FB5-BFG21-GFB4-FG23-GF3-BF6-2A17-FB2-BF5-3CA16-FB2-FG5-4C16-GF-BF7-2C18-F2B3(F27-FBH)2(F27-F2B)F27-FB-FG16-CA7-GF2(2-BF15-3CA6-FB)3-BG15-2C6-GB4-2BG21-G2B5-BF21-FB7-BF19-FB9-BFG15-GFB11-2BG13-G2B13-2B2FG7-G2F2B16-BH9FHB21-2B3H2B24-6BH21-H2B2DACL2DB2H16-HBACL2DACE2DACL2H13-H2DAC2AEACED2ACL2DH11-HLD2A2(CE2DA)CAD2AI9-HCLADACE3ACE2DAC2(EA)CI7-IACA2DACE2(AC)E2DACE3ACLI5-ID2AE2DACEC2ACED2ACE2DACLDI4-IDACED2ACEADACE2DACED2ACADJ3-IADACE2DACEADA2(CED2A)CEADJ2-JAD2(ACE2D)A2(CED2A)CE2DJ2-JDEA3(CED2A)CE2DACEDAK-J3DA2(CEDEACED2A)CE3D2K2(DA)CED2A2(CE2DA)CEDEAC2(ED)2K2(DA)CED2ACEADACED2ACE2DACEDAD2KDCDACE2DACED2ACEADACED2ACEDCD2KDCDA2(CED2A)CE2D2(ACEDC)D2K3DACEDAECE2(AC)2(ED2AC)EDAD2K2DEACEADACED2ACE2DACED2ACEDADJ-KADACE2DACEADA2(CED2A)CE2DJ2-J2(ADACE)2(D2ACE)2DACE2DJ2-J2DACECDACE2DACEADACED2ACE2DI3-JDACEADACE2D2(ACEAD)ACEDI4-IDACE2DACEADA2(CE)ACED2ACLDI5-I2A3(EADAC)ED2ACLI7-ICAD2ACE2DACEDEACEADACH9-IL2DACED2ACE2DACEADAH11-H2DACLD2ACED2ACA2DH13-2HACL2DACE2DACLBH16-H2B2DACL2D2BH21-7B24-5BHB21-BHB2DACL2D3H16-2HACL2CACE2CACL2H13-H2D2C4ACECA3C2DH11-HLDCACED2ACECD2(AC)2AI9-H3CDACE3ACECDACEA3CI7-IACA2DACE3ACECDACE3ACLI5-ID2AE2DA2(CEC2A)CE2DACLDI4-ID2CED2ACE3ACECDACED2ACADJ3-I2(AC)E2DACE3ACEC2ACED2ACEADJ2-J2(AC)E2DACEDCACEC2ACED2ACECDJ2-JDCA2(CED2A)CEDA2CE2DACECAK-JDCDACEDCACED2ACEDEACED2ACEDCD2KD2(4CE)2(2DACE)C2(E2C)D2K2(DA)CED2ACEADACED2ACE2DACEDAD2KDCDACE2DACED2ACEADACED2ACEDCD2KDCDA2(CED2A)CE2D2(ACEDC)D2KDCDACEDAECE2(AC)2(ED2AC)EDCD2KD2(CEA)DACED2ACE2DACED2ACEDCDJ-K2(AC)E2DACEADACEDA2CED2ACECDJ2-J2(AC)EADACEDCACEC2ACE2DACECDJ2-JDCACECDACE2DACECDACED2ACECDI3-JD2CEADACE2DACECDACEADACEDI4-IDACE2DACEADA2(CE)ACED2ACLDI5-I2A2(EADAC)ECDACED2ACLI7-ICAC2ACE2DA2(CE)ACEAD2CH9-ILDCACED2ACECDACEADAH11-H2D3CD2ACECA2CA2DH13-2HACL2CACE2CACL2H16-BHB2DACL2DBHB21-7B24-7B21-2B9F2B16-2B2FG2-IBG2-G2F2B13-2BG5-IBG5-G2B11-BFG6-IMG6-GFB9-BF8-IFG8-FB7-BF9-IBG9-FB5-BFG9-IBG9-GFB4-FG10-IMG10-GF3-BF11-IFG11-FB2-BF11-3F11-FB2-FG9-G5BG9-GF-BF9-G7BG9-F2BF9-9B9-FBHF8GF9BF8GFBH2(F2BM)2F9BFBMF2BM2(FB)HF8IF9BF8IF2BF9-9B9-F2BF9-G7BG9-FB-FG9-G5BG9-GF2-BF11-3F11-FB2-BF11-IBG11-FB3-BG10-IMG10-GB4-2BG9-IFG9-G2B5-BF9-IBG9-FB7-BF8-IBG8-FB9-BFG6-IMG6-GFB11-2BG5-IFG5-G2B13-2B2FG2-IBG2-G2F2B16-2B9F2B21-2B3H2B151-M123-M90-5B25-7B23-9B22-9B15-M3-M2-9B2-M3-M15-9B22-9B23-7B25-5B90-M123-M524-F3GF25-5B2F24-I2(5BG24-J)5BG24-IK4BF25-I2JIB385-
