model
size = 22 30 30, scale = 0.05, origin = -y
material 
  colors = A:#69A5FF B:#2F2F2F C:#EEE D:#A00
voxels
27-12C10-4C4D4C10-2C2D4-2D2C10-2D8-2D10-4(DC8-C3(D10-))DC8-CD10-CD8-DC10-2CDC4-CD2C11-CD6-DC12-2CDC2-CD2C13-CD4-DC14-2(2CD)2C15-C4DC16-6C17-4C19-2C174-2(2A20-)2A636-3(2A20-)2A592-5(2A20-)2A570-6(2A20-)2A526-7(2A20-)2(2A526-6(2A20-))2A20-2A504-8(2A20-)2A460-10(2A20-)2A438-10(2A20-)2A416-12(2A20-)2A346-12(10A12-)10A13-8A15-6A17-4A18-4A19-2A279-16(12A10-)12A11-10A13-8A15-6A17-4A211-18(14A8-)14A9-12A10-12A12-8A186-5A6B5A20(6-16A)7-14A8-14A10-10A140-4A10B4A4-18A4-7A4B7A5-B3A8B3A2(B5-4A10B4A4-4A10B4A5-B2A10B2A)B5-3(4A10B4A4-)5A8B5A2(4-6A6B6A)2(4-7A4B7A)4-8A2B8A5-16A6-16A7-14A8-14A9-12A11-10A13-8A96-3A14B3A2-8A4B8A3-B4A2B4-2B4AB4-B3AB8-B3A2(B3-4AB10-B4A3-B2AB10-B2AB4-B2AB10-B2A)B3-3(4AB10-B4A2-)5AB8-B5A2(2-6AB6-B6A)2-7AB4-B7A3-6AB4-B6A4-7AB2-B7A5-7A2B7A6-16A7-14A8-14A9-12A11-10A13-8A14-8A16-4A53-4A14B5AB7A4B7ABA-B5A2B4-2B5AB-6AB8-B7AB3AB10-B3ABA-B3AB10-B3AB-5AB10-B6AB3AB10-B3ABA-B3AB10-B3AB-5AB10-B10AB10-B5A-2(4AB10-B4A2-)5AB8-B5A2(2-6AB6-B6A)2-7AB4-B7A3-6AB4-B6A4-7AB2-B7A5-7A2B7A6-16A7-14A8-14A9-12A11-10A13-8A14-8A15-6A17-4A31-4A14B4A2-B6A4B6AB2-7A2B4-2B8AB4AB8-B4ABA2-B2AB10-B2AB2-5AB10-B6AB3AB10-B3ABA2-B2AB10-B2AB2-5A2(B10-B10A)B10-B5A-2(4AB10-B4A2-)5AB8-B5A2(2-6AB6-B6A)2-7AB4-B7A3-2(B5AB4-)B6AB2-B6AB5-B6A2B6AB6-B14AB7-B12AB8-B12AB9-B10AB11-B8AB13-B6AB14-8A15-6A17-4A19-2A10-3A16B3A-B7A4B7AB-7A2B4-2B13AB8-B6A-B3AB10-B3AB-5AB10-B10AB10-B5A-B3AB10-B3AB-5A2(B10-B10A)B10-B5A-2(4AB10-B4A2-)5AB8-B5A2(2-6AB6-B6A)2-7AB4-B7A3-2(B5AB4-)B6AB2-B6AB5-C6A2B6AC6-C14AC7-C12AC8-C12AC9-C10AC11-B8AB13-B6AB14-8A15-6A17-4A19-2A10-3A16B3A-B7A4B7AB-7A2B4-2B13AB8-B6A-B3AB10-B3AB-5AB10-B10AB10-B5A-B3AB10-B3AB-5A2(B10-B10A)B10-B5A-2(B3AB10-B3AB2-)B4AB8-B4A2(B2-B5AB6-B5A)B2-B6AB4-B6AB3-2(B5AB4-)C6AB2-B6AC5-C6A2B6AC6-C14AC7-B12AB8-B12AB9-B10AB11-B8AB13-B6AB14-B6AB15-6A17-4A19-2A10-3A16B3A-B7A4B7AB-7A2B4-2B13AB8-B6A-B3AB10-B3AB-5AB10-B10AB10-B5A-B3AB10-B3AB-5A2(B10-B10A)B10-B5A-2(4AB10-B4A2-)5AB8-B5A2(2-6AB6-B6A)2-B6AB4-B6AB3-2(B5AB4-)C6AB2-B6AC5-C6A2B6AC6-C14AC7-C12AC8-B12AB9-C10AC11-B8AB13-B6AB14-B6AB15-B4AB17-4A19-2A10-3A16B3A-B7A4B7AB-7A2B4-2B13AB8-B6A-B3AB10-B3AB-5AB10-B10AB10-B5A-B3AB10-B3AB-5A2(B10-B10A)B10-B5A-2(4AB10-B4A2-)5AB8-B5A2(2-6AB6-B6A)2-7AB4-B7A3-2(B5AB4-)B6AB2-B6AB5-C6A2B6AC6-C14AC7-C12AC8-B12AB9-B10AB11-B8AB13-B6AB14-8A15-6A17-4A19-2A10-4A14B4A-B7A4B7AB-7A2B4-2B13AB8-B6A-B3AB10-B3AB-5AB10-B10AB10-B5A-B3AB10-B3AB-5A2(B10-B10A)B10-B5A-2(4AB10-B4A2-)5AB8-B5A2(2-6AB6-B6A)2-7AB4-B7A3-2(B5AB4-)B6AB2-B6AB5-B6A2B6AB6-B14AB7-B12AB8-B12AB9-B10AB11-B8AB13-B6AB14-8A15-6A17-4A31-4A14B13A4B16A2B4-2B13AB8-B11A6(B10-B10A)B10-B5A-2(4AB10-B4A2-)5AB8-B5A2(2-6AB6-B6A)2-7AB4-B7A3-6AB4-B6A4-7AB2-B7A5-7A2B7A6-16A7-14A8-14A9-12A11-10A13-8A14-8A15-6A53-4A12B4A2-8A4B8A2-6A2B4-2B6A2-5AB8-B5A9(2-4AB10-B4A)2-5AB8-B5A2(2-6AB6-B6A)2-7AB4-B7A3-6AB4-B6A4-7AB2-B7A5-7A2B7A6-16A7-14A8-14A9-12A11-10A14-6A16-6A76-5A8B5A4-7A4B7A4-5A2B4-2B5A4-4AB8-B4A9(4-3AB10-B3A)4-4AB8-B4A2(4-5AB6-B5A)2(4-6AB4-B6A)4-7AB2-B7A5-7A2B7A6-16A7-14A8-14A9-12A13-6A16-2A2C2A100-14A7-6A4B6A6-4A2B4-2B4A6-3AB8-B3A9(6-2AB10-B2A)6-3AB8-B3A2(6-4AB6-B4A)2(6-5AB4-B5A)6-6AB2-B6A6-7A2B7A8-12A10-12A11-2C6A2C13-2C4A2C15-6C122-C12AC8-C4A4B4AC8-C2A2B4-2B2AC8-CAB8-BA9(C8-CB10-B)C8-CAB8-BAC8-C2AB6-B2AC8-2CAB6-BA2C8-2C2AB4-B2A2C8-3CAB4-BA3C9-2C2AB2-B2A2C10-3C2A2B2A3C11-2C6A2C12-3C4A3C14-2C2A2C17-4C141-
