model
size = 19 32 32, scale = 0.05, origin = -y
material 
  colors = A:#630 B:#633 C:#111 D:#444
voxels
26-4C15-4D15-4A1022-BAB16-B3AB14-B3AB12-2AB3AB2A9-2(AB)2A2B2A8-B7AB4A6-13B10-5C14-5D14-5B3(14-5A)5(14-B3AB)4(14-AB2AB)14-ABA2B14-AB3A14-5A14-2AB2A14-AB3A2(14-AB2AB)3(14-2(AB)A)12-B-A2-BA12-2A5-2A9-B2A5-2A8-AB9-2A6-B10-2A5-A13-B4-3B10-2B7-9C10-2D5-2D10-2B5-2B8(10-2A5-2A)2(9-3A5-2A)9-3A16-3(3A5-2A9-)ABA5-2A9-3A5-2A9-ABA5-2A9-2B3(A5-3A8-AB)2(A5-3A7-A-B)A5-3A7-AB9-AB7-A9-A2(B6-A11-)B4-2A13-BA2-2B13-2B5-11C8-D9-D8-B9-B5(8-A9-A)15(8-A9-B)7-A10-2(A7-2A9-)A7-A11-B6-A12-2(A4-A13-)2A2-A15-A2-B15-B5-11C8-D9-D8-B9-B3(8-A9-A)5(8-B9-A)5(7-B10-A)3(7-A10-A)6-2A2(10-A6-BA)10-A6-2B10-A2(8-B9-B)7-B11-B6-B11-A5-B12-A5-B13-A3-B14-A2-B16-2A2B16-B3-13C6-D11-D6-B11-B2(6-A11-A)2(5-2A11-B)2(A4-2A11-B)A3(5-A11-AB)5-8(A11-A6-)B11-A6-A11-BA5-A2(11-AB4-2A)11-AB4-A12-B4-2A13-B2-2A14-B3-A15-B-A16-B-A17-2B17-B3-13C6-D11-D6-B11-B5(6-A11-A)5(4-2A12-A)8(5-A12-A)2(5-B12-A)2(5-A12-A)5-A13-2A3-A14-A2-A15-2A-B15-A-A17-2A17-AB17-B3-13C6-D11-D6-B11-B8(6-A11-A)6-A12-A2(4-A13-B)4-B13-2(A3-B14-)2(A4-B13-)2(2A3-B13-)2A3-3(A13-A4-)B12-A5-A13-B3-A14-A4-A14-A2-B15-A2-B16-2A17-AB17-B4-12C7-D10-D6-B11-B5(6-A11-A)6-B11-A6-B12-A5-B12-6(A4-A13-)A3-BA13-3(A5-A12-)A4-2(B14-A3-)B13-2A4-B11-A5-B13-A3-B14-A3-B15-A2-A15-A2-B16-2(AB17-)B4-12C7-D10-D6-B11-B6-A2(11-A6-B)2(11-2A5-B)11-2A5-A11-BA5-7(A11-B6-)A11-A6-A11-3(A5-A12-)A5-A13-B2(4-A12-2A)4-A13-3A3-A11-4A2-A14-2A2-A14-A-2A15-A2-A15-3A17-AB17-B4-11C8-D9-D8-B9-B7(8-A9-A)2(6-2A10-A)5-3A10-A6-2A10-2(A6-A11-)A7-2(A11-A6-)B11-2(A5-A12-)B5-A12-B5-2A10-B6-A11-B7-A11-B4-2A11-B5-AB12-AB4-A14-B3-A14-B17-A2-B16-2AB17-B5-10C9-2(D8-)B9-B7(8-A9-A)8-A10-A7-A9-2A5-A-A9-AB5-A-A9-2A5-2A10-2A2(5-A11-AB)6-A11-B6-A11-A6-2(A10-A7-)A10-A8-B10-2(A6-B11-)2A5-B10-A7-B11-2A4-B13-A2-BA14-B3-B14-B3-A15-B2-B15-B6-11C8-D9-D8-B9-2(A8-)2(A9-A8-)A9-2(A7-A10-)2A7-A8-3A6-2A8-A7-3A8-2(A7-2A9-)B7-2A8-A8-2A3(8-B9-A)2(B7-B9-A)2B6-B2(10-AB6-A)10-B7-A10-B7-2A9-BA5-2A10-2(AB)5-A10-B2A3-2A11-A5-B12-A5-A12-A4-A14-2A2-2B14-B6-11C8-D9-D8-A9-2(A8-)2(A9-A8-)A10-A6-A11-A6-A12-A5-A12-A4-A11-2A-A2-A12-2(2A-)A12-A2-AB2A11-2(A4-2(A-)A9-)3(2A3-A2-A10-)2A3-B2-A10-2A3-A2-A10-B4-A2-2A9-2(A3-)2A8-A-B2-A-B-AB8-2AB2-A3-2A8-A-B2-A3-2A8-2A2(3-A)B8-A-A7-AB7-A8-3AB5-A-B9-AB5-2AB9-ABA4-A13-A4-2B12-B6-12C7-D10-D7-A10-2(A8-)2(A9-A8-)A10-A6-A11-A6-A12-B5-A13-A3-B13-2(A-)A14-A2-A11-5A14-3A-2A-A12-2(2A-)2A13-3A-3A12-B2A-3A12-B-A-3A12-A-B-2AB12-A-B-3A11-BA-B-2A12-B2A-2BA11-2(A-B)-A11-B-2A-2BA13-2A-ABA10-A-B2(-A)BA10-AB2(-A)-B-A10-B2A-A2-A10-A-2A5-2A10-2A6-A8-BA9-AB6-B11-B7-13C6-D11-D6-A11-A7-A9-A8-B9-A8-2(A9-)A7-B10-A7-A11-B5-A13-A3-B15-A-A17-A14-A18-B2(-A16-A)-B18-A-B15-A2-A3(15-A2-B)15-2(A-A16-)A-B15-BA-B15-A2-B15-2A2(-A)B13-A-ABA14-2(AB)A12-A-AB-B2A10-3A6-2A8-2B7-2B8-13C6-D11-D6-A11-A7-A9-A8-B9-A8-2(A9-)A7-B10-A7-A11-B5-A13-A3-B15-A-A17-A110-A132-B17-A19-B18-B39-A15-4AB2A12-7B10-13C6-D11-D6-A11-A7-A9-A8-B9-A8-2(A9-)A7-B10-A7-A11-B5-A13-A3-B15-A-A17-A392-13C6-D11-D6-A11-A7-2(A9-A8-)2(A9-)A7-B10-A7-A11-B5-B13-A3-B15-A-A17-A391-14C5-D12-D5-2A11-A7-2(A9-A8-)2(A9-)A7-B10-A7-A11-B5-B13-A3-A15-A-A17-A391-14C5-D12-D5-A12-A6-2(A10-A7-)B10-2(A8-)B9-A8-A10-A6-A12-A4-A14-A2-B16-2A391-14C5-D12-D5-A12-A6-2(A10-A7-)B10-2(A8-)B9-A8-A10-B6-A12-A4-A14-A-AB16-A392-13C6-D11-D6-A11-A7-2(A9-A8-)B2(9-A)7-B10-A7-A2(11-B5-A13-A3-A15-A-B17-A392-13C6-D11-D6-A11-A7-2(A9-A8-)B2(9-A)7-A10-A7-B)11-B5-A13-A3-A15-2AB411-11C8-D9-D8-2(A9-)2(A8-A9-)B8-B10-A6-A11-B6-A12-B3-2A14-A-BA16-A412-11C8-D9-D8-2(A9-)A7-A10-A7-B10-B7-B11-A5-A12-B4-2A13-A2-A16-A2B430-10C9-D8-D9-A8-A10-2(A6-A11-)B6-A12-A4-A13-A3-2A14-A-A17-B433-8C11-D6-D11-A6-3(A12-A5-)A13-A2-BA14-A-AB16-A452-8C11-D6-D11-A6-A12-A4-A13-AB2-BA14-B2-BA15-AB17-A472-6C13-D4-D13-A4-A14-4A16-2A17-AB503-
