model
size = 15 30 4, scale = 0.05, origin = -y
material 
  colors = A:#7E7E7E B:#646464 C:#4B1D00 D:#6F2A00 E:#712F00 F:#884617 G:#4B4B4B H:#989898 I:#7C3B0B J:#B1B1B1 K:#945222
voxels
377-2C13-BD13-DB13-2C388-2C13-BD13-DB13-2C43-EF3(13-2C13-2D)13-2C13-ED13-EF13-IF13-DC13-CD13-EF13-IF13-EF13-DC8-A4-CD8-AG3-IF8-AB3-EK7-G2A3-EF7-B2AG2-DC7-3AB2-CD6-B2AHA2-EF6-3AHAGBEFBG2-GB2AJHABAEF8AJH2BAEF2A3B2A2HA2GBEF2B3G2B2AB3-EF7-BAB13-B4-FE4(13-2C13-2D)2(13-FE)13-CD13-DC13-K2(E13-F)I13-CD8-A4-DC8-AG3-FE8-AB3-FE7-G2A3-KE7-B2AG2-CD7-3AB2-DC6-B2AHA2-FE6-3AHAGBFEBG2-GB2AJHABAFE8AJH2BAFE2A3B2A2HA2GBFE2B3G2B2AB3-FE7-BAB13-B2-
