model
size = 21 31 21, scale = 0.05, origin = -y
material 
  colors = A:#777
voxels
363-7(8A13-)3A3-2A13-3A3-2A350-5(7A14-)7A12-8(11A10-)11A202-6(5A16-)5A13-3A5-3A5(10-2A7-2A)2(10-A)4(9-A10-A)9-2A9-A9-12A8-13A8-14A7-14A95-3(5A16-)5A14-6(2A5-2A12-)2A5-2A10-2A9-2A5(8-A11-A)7-6(2A12-A6-)3(15A6-)15A5-17A71-3(2A5-2A12-)2A5-2A10-6(2A9-2A8-)2A9-2A7-5(A13-A6-)A13-A5-10(A15-A4-)A15-2A3-18A48-3(A9-A10-)2(A9-)6(A11-A8-)A11-A6-2A13-2A5(4-A15-A)21-10(A20-)A3-18A47-3(A11-A8-)A11-A7-6(A13-A6-)A13-A5-5(A15-A4-)A15-A21-4(A20-)A149-7A5-8A25-3(A11-A8-)A11-A7-6(A13-A6-)A13-A4-2A15-2A5(2-A17-A)-A4(19-2A)19-A148-6A7-7A24-3(A13-A6-)A13-A5-6(A15-A4-)A15-A3-5(A17-A2-)A17-A-A3(19-2A)19-A190-5A9-6A3-3(A13-A6-)A13-A5-6(A15-A4-)A15-A3-5(A17-A2-)A17-A-A2(19-2A)19-A211-4A11-5A3-3(A13-A6-)A13-A5-6(A15-A4-)A15-A3-5(A17-A2-)A17-A-A19-2A19-A232-4A11-5A3-3(A13-A6-)A13-A5-6(A15-A4-)A15-A3-5(A17-A2-)A17-A-A2(19-2A)19-A211-4A11-5A3-3(A13-A6-)A13-A5-6(A15-A4-)A15-A3-5(A17-A2-)A17-A-A3(19-2A)19-A190-5A9-6A4-3(A11-A8-)A11-A7-6(A13-A6-)A13-A4-2A15-2A5(2-A17-A)-A4(19-2A)19-A148-6A7-7A25-3(A11-A8-)A11-A7-6(A13-A6-)A13-A5-5(A15-A4-)A15-A3-4(A17-A2-)A17-7(A20-)A2-20A26-3(A9-A10-)2(A9-)6(A11-A8-)A11-A6-2A13-2A5(4-A15-A)3-4(A17-A2-)A17-A20-A4(14-7A)14-6A3-18A50-3(2A5-2A12-)2A5-2A10-6(2A9-2A8-)2A9-2A7-5(A13-A6-)A13-A4-2A15-5(A3-A16-)5(A3-2A10-A4-)A3-18A52-3(5A16-)5A14-6(2A5-2A12-)2A5-2A10-2A9-2A5(8-A11-A)6-2A13-5(A5-A14-)3(A5-12A3-)A5-12A2-2A6-15A158-6(5A16-)5A13-3A5-3A5(10-2A7-2A)8-2A11-5(A7-A12-)A3(7-14A)7-13A327-5(7A14-)7A11-3A7-4(2A9-2A8-)2A4(9-12A)473-8(9A12-)9A111-
