model
size = 32 25 32, scale = 0.05, origin = -y
material 
  colors = A:#FC9 B:#C96 C:#555
voxels
40-16A752-7(16A784-)16A776-2B28A2B8-2(16A16-)10A4C2A16-16A10(16-16B)2(16-16A)2(16-5A6-5A)3(16-16A)16-11A3C2A16-12AC3A16-16A8-2B7A14-7A2B8-4(A14-A16-)10(B14-B16-)9(A14-A16-)16A8-2B7A14-7A2B8-2(A14-A16-)C14-A16-A14-A2(16-B14-B)3(16-C14-B)5(16-B14-B)7(16-A14-A)16-C14-A16-A14-A16-16A8-2B7A14-7A2B8-2(A14-A16-)C14-A16-A14-A2(16-B14-B)16-C14-C16-B14-C16-C14-C5(16-B14-B)7(16-A14-A)2(16-C14-A)16-16A8-2B7A14-7A2B8-2(A14-A16-)C14-A16-A14-A2(16-B14-B)16-C14-C16-C14-B16-C14-C5(16-B14-B)7(16-A14-A)16-C14-A16-A14-A16-16A8-2B7A14-7A2B8-2(A14-A16-)C14-A16-A14-A2(16-B14-B)3(16-B14-C)5(16-B14-B)9(16-A14-A)16-16A8-2B7A14-7A2B8-4(A14-A16-)2(B14-B16-)3(C14-B16-)5(B14-B16-)8(A14-A16-)B14-B16-16B8-2B7A14-7A2B8-4(A14-A16-)2(B14-B16-)C14-C16-B14-C16-C14-C5(16-B14-B)8(16-A14-A)16-B14-B16-16B8-2B7A14-7A2B8-4(A14-A16-)2(B14-B16-)C14-C16-C14-B16-C14-C5(16-B14-B)8(16-A14-A)16-B14-B16-16B8-2B7A14-7A2B8-4(A14-A16-)2(B14-B16-)3(B14-C16-)5(B14-B16-)8(A14-A16-)B14-B16-16B8-2B7A14-7A2B8-2(A14-A16-)A14-C16-A14-A2(16-B14-B)3(16-C14-B)5(16-B14-B)9(16-A14-A)16-16A8-2B7A14-7A2B8-2(A14-A16-)A14-C16-A14-A2(16-B14-B)16-C14-C16-B14-C16-C14-C5(16-B14-B)7(16-A14-A)16-A14-C16-A14-A16-16A8-2B7A14-7A2B8-2(A14-A16-)A14-C16-A14-A2(16-B14-B)16-C14-C16-C14-B16-C14-C5(16-B14-B)7(16-A14-A)2(16-A14-C)16-16A8-2B7A14-7A2B8-2(A14-A16-)A14-C16-A14-A2(16-B14-B)3(16-B14-C)5(16-B14-B)7(16-A14-A)16-A14-C16-A14-A16-16A8-2B7A14-7A2B8-4(A14-A16-)10(B14-B16-)9(A14-A16-)16A8-2B28A2B8-2(16A16-)2A4C10A16-16A10(16-16B)2(16-16A)2(16-5A6-5A)3(16-16A)16-2A3C11A16-3AC12A2(16-16A)6(784-16A)776-
