model
size = 32 32 26, scale = 0.05, origin = -y
material 
  colors = A:#1C1D20 B:#CF6 C:#96F D:#6F6 E:#D8D8D8 F:#96C G:#63C H:#660 I:#9F6 J:#66C K:#336 L:#339 M:#639 N:#669 O:#99C P:#222 Q:#93F R:#696 S:#693 T:#383838 U:#663 V:#007 W:#9C9 X:#333 Y:#99F Z:#330 Aa:#555 Ab:#363 Ac:#010 Ad:#6C9 Ae:#6C6 Af:#690 Ag:#888 Ah:#020 Ai:#30C Aj:#996 Ak:#63F Al:#309 Am:#777 An:#005 Ao:#030 Ap:#360 Aq:#306 Ar:#9C3 As:#60F At:#366 Au:#001 Av:#444 Aw:#666 Ax:#90F Ay:#6F9 Az:#070 Ba:#AAA Bb:#66F Bc:#6F3 Bd:#6C0 Be:#390 Bf:#00E Bg:#33C Bh:#00A Bi:#003 Bj:#699 Bk:#30F Bl:#9C6 Bm:#393 Bn:#999 Bo:#004 Bp:#009 Bq:#100 Br:#936 Bs:#006 Bt:#60C Bu:#69C Bv:#969 Bw:#BBB Bx:#00D By:#9F9 Bz:#9CC Ca:#93C Cb:#050 Cc:#33F Cd:#002 Ce:#6C3 Cf:#008 Cg:#00C
voxels
621-E5-E24-2(E5-E25-)E5-E24-2(E7-E23-)E8-E23-E7-E23-E6-E1111-10A22-10A918-10A22-10A20-2A10-2A18-2A10-2A852-10A22-10A20-2A10-2A18-2A10-2A17-A14-A16-A14-A819-10A20-2A10-2A18-2A10-2A17-A14-A16-A14-A15-A16-A14-A16-A786-10A20-2A10-2A17-A14-A16-A14-A15-A16-A14-A16-A13-A18-A12-A18-A723-6A24-10A21-A10-A19-A12-A17-A14-A16-A14-A15-A16-A13-2A16-2A12-A18-A12-A18-2A660-2A28-6A24-10A20-2A10-2A17-2A12-2A16-A14-A15-A16-A14-A16-A13-A18-A11-2A18-2A2(10-A20-A)13-3(8(BA)16-)3(16A16-)14(8(BA)16-)3(BA)B3A3(BA)16-2(BA)B7A2(BA)16-BAB11ABA16-B2A10-3A16-2A12-2A16-A14-A15-A16-A13-2A16-2A10-2(3A18-3A8-)2A20-2A8-2A20-2A10-19(20A12-)20A6-4A2-20A2-9A-20A-69A-30A3-28A5-5A-14A-5A7-4A-14A-4A8-3A2-14A2-3A7-4A3-12A3-4A6-2A22-2A7-A22-A9-18(5A12-5A10-)5A12-5A5-10A12-20A12-11A2(3-6A12-6A3-2A)3-6A12-6A3-4A-6A12-2(6A-)6A12-6A-3A-2A-6A12-6A-2A3-8A12-8A5-4A-2A12-2A-4A6-4A2-2A10-2A2-4A6-2A5-12A5-2A6-2A22-2A7-23(4A16-4A8-)4A16-4A4-A3-4A16-4A3-3A2-4A16-4A2-5A-4A16-4A-3A-7A16-7A3-6A16-6A4-5A-A14-A-5A4-3A4-2A10-2A4-3A5-2A22-2A25(6-4A18-4A)3-A2-4A18-4A2-3A-4A18-4A-9A18-7A-6A18-6A3-6A16-6A4-3A3-A14-A3-3A5-2A22-2A5-25(5A18-5A4-)5A18-5A2-A-5A18-5A-8A18-14A18-7A-7A16-7A3-3A3-A14-A3-3A5-2A22-2A5-26(4A20-4A4-)5A18-5A2-7A18-14A18-7A-7A16-7A3-3A3-A14-A3-3A5-2A22-2A5-27(4A20-4A4-)4A20-4A2-A-5A18-5A-9A16-8A2-3A3-A14-A3-3A5-2A22-2A5-28(4A20-4A4-)5A18-5A2-8A16-8A3-2A3-A14-A3-2A6-2A22-2A5-28(4A20-4A4-)5A18-5A2-8A16-8A3-2A3-A14-A3-2A7-A22-A6-27(4A20-4A4-)4A20-4A2-A-5A18-5A-A-7A16-7A5-2A2-A14-A2-2A9-A20-A7-26(4A20-4A4-)4A20-4A2-A-4A20-4A-8A18-7A2-6A16-6A7-A2-A14-A2-A11-A18-A8-25(4A20-4A4-)4A20-4A2-A2-4A18-4A2-3A-4A18-4A-5A-3A18-3A-3A3-6A14-6A9-2(A2-A12-)A18-A8-24(5A18-5A4-)5A18-5A2-A2-4A18-4A2-3A-4A18-4A-5A-3A18-3A-3A2-7A14-7A8-3A14-3A13-A-3A8-3A-A14-A16-A10-5(4A18-3AB6-)4A18-3AI6-4A18-3AD3(6-Aj3A18-4A)6-H3A18-4A6-U3A18-4A6-R3A8(18-4A6-4A)18-4A5-5A18-5A4-5A18-5A5-4A18-4A3-A2-4A18-4A2-3A-4A18-4A-9A18-7A-6A18-6A7-3A14-3A13-6A6-6A15-A14-A16-A14-A12-2(B23A8-)S23A8-Ab22AAr8-Aq22ABd8-M22ABc8-Br22AD2(8-F22AI)8-K22AI8-Z22AD8-H22AD8-S22AI8-Am22AAj8-F22AL8-C22ABh8-23ABp8-23ABq8-24A4-A3-24A3-2(2A2-26A2-)2A2-20A-5A2-2A2-26A2-4A-24A-6A-24A-3A2-28A8-20A14-6A4-6A17-2A10-2A18-A12-A46-BlAbAa16ABAB10-ApAcP16ABmBlB10-UApX16AAzAfAr10-NMBs16ABeHAf10-NAaT16AR2Af10-N2K16AJRBd10-M2G16ACBbAe10-2GF15ACBa2D10-CaGV15AYW2D10-MFAi15AAd3D10-2XAh15A4D10-2HZ15A4D10-3H15A2D2I10-AaKV15ADAdBnB10-CJG15ADBnCcJ10-3C15AIFBkBf10-3C15AWAkBkBx10-F2C15AFAxAsCg10-AF16AQAAsBp6-22AQ2ABq4A-23AC2(31AG)8A-30A3-28A5-26A10-18A16-14A19-2A8-2A20-A10-A82-NAwV2AlKCbAhAcPApAoAhZAbAr16-AnKLBoXP2AoZSAfAzAeCeBeAz16-CdTBiAuPBoXAbUAwApS3DBm16-AoAcAuTAvTAqMJGAbW4D16-Ah2AcXKT2P3KBuAdWAdN16-PAcTAtRAtLAnPSVJO2CQ16-AaAbAwAiBgQAkBgAnRAtAmO3C16-AgGBf2AkAlGLRUAm5C16-CBbBhJGVAiMRSNQ2COY16-MGAnNFAiGLRAeGQ2CWAy16-AuTZBiLGLAa2BjAxQCYAdD16-AhZHZPXAaAgJC2QYOSAe16-Av4H2UBvO2CFAyAeSD16-VAqAv2HUNCYCBaAy2DBcD16-2M2LVL3COI5D16-4CJ4CBz6D16-9CO6D16-9CYBy4DI15-11CW3DIBwAx13-AgF10CJAdIWOCAsAi10-3AAgF11COY2CBtCf2A6-6AAg15CAl5A4-7AF14C6A5-7AF11CFJ5A8-7AF7CFN5A12-8AJCFJAm5A17-12A21-AE6-EA139-
