model
size = 10 32 5, scale = 0.05, origin = -y
material 
  colors = A:#630 B:#C93 C:#278F65
voxels
80-2B6-2B264-2B8-B9-2B9-B8-2B4-B7-B235-2B4(8-2A)7-4A5-6A3-3A2C3A-2B6A2B2-10(3AB2A4-2AB3A4-)3AB2A5-AB2A7-AB38-2B9-B8-2B8-B9-2B5-B7-B310-2B6-2B230-
