model
size = 18 10 3, scale = 0.05, origin = -y
material 
  colors = A:#000
voxels
8-2A16-2A15-4A13-2A2-2A24-6A6-6A3-12A7-10A9-8A11-2A2-2A2(97-4A8-4A4-5A2-5A7-4A2-4A9-3A2-3A11-A4-A)6-
