model
size = 30 15 9, scale = 0.05, origin = -y
material 
  colors = A:#630
voxels
272-2A22-2A4-A24-A3-2A24-2A2-A26-A-2A26-3A28-A214-A20-A6-2(2A22-2A4-)A24-A2-3A24-5A26-4A26-3A28-A154-A20-A8-A20-A6-3A20-3A4-2A22-2A3-3A22-3A2-2A24-2A-3A24-5A26-4A26-3A28-A154-A20-A8-A20-A7-2A20-2A4-2(3A22-3A2-)2A24-2A-3A24-5A26-4A26-2A37-3A10-3A13-4A10-4A12-5A8-5A11-6A8-6A9-A4-2A8-2A4-A8-A4-2A8-2A4-A7-2A4-A10-A4-2A5-3A4-A10-A4-3A3-3A5-A10-A5-3A2-3A22-3A2-2A24-2A-3A24-3A97-3A10-3A13-4A10-4A12-5A8-5A11-6A8-6A9-A4-2A8-2A4-A8-A4-2A8-2A4-A7-2A4-2A8-2A4-2A5-3A4-2A8-2A4-3A3-3A5-2A8-2A5-3A2-3A5-2A8-2A5-3A10-5A2-5A19-10A21-8A23-2A2-2A49-3A10-3A13-4A10-4A12-5A8-5A11-6A8-6A9-A4-2A8-2A4-A13-5(2A8-2A18-)5A2-5A19-10A21-8A23-2A2-2A49-3A10-3A13-4A10-4A12-5A8-5A11-6A8-6A14-6(2A8-2A18-)5A2-5A19-10A21-8A23-2A2-2A79-A14-A13-A-A12-A-A15-A10-A49-5(A8-A20-)A8-A21-2A4-2A23-2A2-2A72-
