model
size = 20 23 3, scale = 0.05, origin = -y
material 
  colors = A:#EEE B:#BBB C:#007 D:#004
voxels
8-4A15-AB4A13-A2B5A9-A2-A2B5A2-A4-3A2-A2B5A2-3A-2AB3A3B12A8B11A-A7B10A2-A7B10A3-A5B10A4-A3B2ADA2C6A5-3A3DA4C3A6-A5DA6CA7-A4DA5CA8-A4DA5CA9-A3DA4CA10-A3DA4CA11-A2DA3CA13-ADA2CA14-ADA2CA15-2ACA16-4A17-2A18-2A35-A6-A29-A12-A72-2A372-A12-A363-
