model
size = 24 16 22, scale = 0.05, origin = -y
material 
  colors = A:#F6C B:#F0C C:#FF0 D:#FC6 E:#FF6 F:#F60 G:#FC0 H:#F06 I:#FFF J:#FC3 K:#CCC L:#F9F M:#FF9 N:#F9C O:#F33 P:#CF3 Q:#F09 R:#F90 S:#F96 T:#FFC U:#F30 V:#F63 W:#CF0 X:#F0F Y:#FC9 Z:#F3C Aa:#F36 Ab:#F93 Ac:#F99 Ad:#CF6 Ae:#CC3 Af:#CC6 Ag:#F6F Ah:#F00 Ai:#CCF Aj:#FCC Ak:#FF3 Al:#F03 Am:#F3F An:#CFC Ao:#F66 Ap:#FCF Aq:#CC0 Ar:#F69 As:#F39 At:#CC9 Au:#CF9 Av:#CFF Aw:#111
voxels
52-6(A14-A8-)A14-A174-7(A18-A4-)2(A18-A364-)A18-A11-2RAhTJAo17-ApAuZGAmA2Ae16-AkAfS2QVYAg16-AjORDZUEI17-6B251-A5-QIXAnZAdKAf5-A9-JPAsAoArAlNAbCG14-AAlCAeSJAWYF14-VWAcYAcOMAgAdK14-UAbAeEGAaLZXO14-DYLAnAhCAcYArD15-8B56-A7(22-2A)-5AAdG6ADAe5A-A7-NQ6AHY14-ADCWYAaRAjVE14-MHPAgAkIQAbAdAn14-LHAkZAdAsPWNI14-AcPApYAlCAlKAAo14-BAfAqAkArAcWAiMJ16-6B201-A6-AcM6-ApAo6-A7-BT6AAqF14-RAeAcAjAfDEAbApY14-QAgAeAbQAcAfWRY14-PILWEAqQKZM14-AlLAaKXGEAiSAt14-WAqGAiAgTXSRJ15-Ah2BFI2BT200-A6-AmAf6-SJ6-A7-AmCA-2A-ARO14-EYRAbAhZXAhTAa14-AfAdZWSMAgNAmC14-QXSKAnAfFDQJ14-EArRAiAsBNAqZAu14-XUTSLAkLIRE15-P2BAAp2BO200-7AQD6-DE7A7-EHA-2A-ACAn14-XVOAhHAgBJGI14-AgAdAvNPAAnAuFAo14-FNKDAfUAjEKJ14-NAAbAqCAmJVOF14-LMWIYAmNXDAe15-L2BAdE2BH207-IAp6-MAg14-VAqA-2A-AAtT14-BApPJAiArKOJH14-AnRAkAuEBIAaAE14-AjZApEAbAsAaCVT14-JSAqVAkAoVJUK14-NRApXZFUAu2D15-T2BAlAu2BC207-FS6-PT14-AuRA-2A-A2Av14-KTAnOFTXHLG14-IAmArAaAeAvSHQAl14-AaQSCApGAlPAM14-VZAcJAkAlAnAfZT14-URGAuAjMArCMAe15-O2BAmT2BAf207-ED6-FAi14-VCA-2A-ANE14-XGAiHCAiWHLAb14-SFBHGSKVAvAk14-AlKAdPFAhAiAdAjZ14-AnOAsAfKNSNAbAl14-ArDAoCODAhAWJ15-H2BDAq2BK201-6AAjM6-OAq6A8-AbAtA-2A-AAaG14-WJAjHLAjAtUCT14-KAHVAaAmNDJI14-AiVAtAdGAiAfCAuV14-SUAvNAoAaXGEB14-AhDAjAAhIAgFVAn15-C2BGAs2BX201-A5-AcP6-BAd5-A8-AiAvA-2A-AAkAh14-AtLAnUMULAlApS14-NQIDTAmAcMAcAn14-AfAAoCAeAmBTAiAs14-XZJGAgERAeAtL14-AgM2FIAfQAgNA15-Af2BLQ2BAf201-A5-AF6-AhR5-A8-MN6AAgZ14-2LAcAlXIEAjTS14-AcAvBMArAsAbAeHR14-BAjRTUCAkCET14-RAbQAePAcZPTAm14-QWPAgAaAeAlAkKQ16-2BAmL2B202-A5-UO6-OP5-A8-AiAa6AAiAl14-ECSAjXOKFBW14-AbJAhAeAgDAiNAdAb14-AkAuNCAAtSLAsY14-ZEDPUWAhAvAoAs14-8BFAp16-6B18-6B178-A2-3A2BAbXVGAkC2B3A2-A8-2BWAgUAoNY2B14-2BAgFMAhApAd2B14-2BZNAcGUX2B14-2BYLAdQAiAr2B14-2BAkAvAhDEU2B14-2BAdAjSHAbP2B16-BAb2BAkB18-6B10-7(A20-A2-)A2-A4-2CUAoAkG4-A2-A10-GYPAeZF18-FAdAaYAlK18-KXAmEJO18-O2ArAnOD18-DUBIAaH16-Aw-HPAsAoCV-Aw17-Aw2-Aw20-Aw2-Aw182-A4-AeGIAcDF4-A13-YFAaGAqK18-EKVAhIO18-AnOUAqCD18-IDMAbMH18-AoHAcJWV18-JBAdRBAd229-A5-FAjCH5-A13-FKAmAcHG18-YOAiAePAo18-YDAaLAfAh18-MHIAaCG18-At4BQ18-6B229-A4-BAaDIEB4-A13-2BAtC2B18-2BWM2B18-2BAjW2B18-6B42-Aw4-Aw211-B2-B14-A5-B2-B5-A14-B2-B20-B2-B154-
