model
size = 32 32 30, scale = 0.05, origin = -y
material 
  colors = A:#000 B:#FD98FD C:#989898 D:#EDC896 E:#FD0000 F:#FD9800 G:#0098FE H:#FFF I:#FD6DD2 J:#33FD00 K:#6633FE L:#FF9898 M:#FEFE00
voxels
428-H61-H3-H61-H534-H802-H2258-H1425-H61-H3-H61-H361-H30-H-H30-H2074-H31-H60-2H-H-2H60-H31-H1612-H61-H3-H61-H4386-3K3A4-3A7-3A2-3A4-3KA2CA3-A2CA5-A2CA-A2CA4-3KA3C22A3-4G4A10DA10CA2-5G2A3D7BA3C7A2CA-6GA2DBI5BAC2LC2(A2C)AC2LA4J2GAD5BI2BAC2L9C2LA4J3AD8BA3C2A3CAC2A2CA2J3ACADBI6BA3CHA5CHA2C3A3C2AD7BIA14C2A2C4AD3BI5BA12CA-M3A2MAD9BA4C4A4CA-4F2MAD5BI3BA3CA3BDA3CA-6FAD9BA2CA4BD2A2CA-6FAD10B2A2BI2BDA-2A2-4E2FAD2BI14BDA5-6EA2D6BI2BI5B2DA5-6EA3D13B3DA9-3EA17DA14-17A391-3K3A4-3A7-3A2-3A4-3KA2CA3-A2CA5-A2CA-A2CA4-3KA3C22A3-4G4A10DA10CA2-5G2A3D7BA3C7A2CA-6GA2DBI5BAC2LC2(A2C)AC2LA4J2GAD5BI2BAC2L9C2LA4J3AD8BA3C2A3CAC2A2CA2J3ACADBI6BA3CHA5CHA2C3A3C2AD7BIA14C2A2C4AD3BI5BA12CA-M3A2MAD9BA4C4A4CA-4F2MAD5BI3BA3CA3BDA3CA-6FAD9BA2CA4BD2A2CA-6FAD10B2A2BI2BDA-2A2-4E2FAD2BI14BDA5-6EA2D6BI2BI5B2DA5-6EA3D13B3DA9-3EA17DA14-17A181-H209-3K3A4-3A7-3A2-3A4-3KA2CA3-A2CA5-A2CA-A2CA4-3KA3C22A3-4G4A10DA10CA2-5G2A3D7BA3C7A2CA-6GA2DBI5BAC2LC2(A2C)AC2LA4J2GAD5BI2BAC2L9C2LA4J3AD8BA3C2A3CAC2A2CA2J3ACADBI6BA3CHA5CHA2C3A3C2AD7BIA14C2A2C4AD3BI5BA12CA-M3A2MAD9BA4C4A4CA-4F2MAD5BI3BA3CA3BDA3CA-6FAD9BA2CA4BD2A2CA-6FAD10B2A2BI2BDA-2A2-4E2FAD2BI14BDA5-6EA2D6BI2BI5B2DA5-6EA3D13B3DA9-3EA17DA14-17A391-3K3A4-3A7-3A2-3A4-3KA2CA3-A2CA5-A2CA-A2CA4-3KA3C22A3-4G4A10DA10CA2-5G2A3D7BA3C7A2CA-6GA2DBI5BAC2LC2(A2C)AC2LA4J2GAD5BI2BAC2L9C2LA4J3AD8BA3C2A3CAC2A2CA2J3ACADBI6BA3CHA5CHA2C3A3C2AD7BIA14C2A2C4AD3BI5BA12CA-M3A2MAD9BA4C4A4CA-4F2MAD5BI3BA3CA3BDA3CA-6FAD9BA2CA4BD2A2CA-6FAD10B2A2BI2BDA-2A2-4E2FAD2BI14BDA5-6EA2D6BI2BI5B2DA5-6EA3D13B3DA9-3EA17DA14-17A391-3K3A4-3A7-3A2-3A4-3KA2CA3-A2CA5-A2CA-A2CA4-3KA3C22A3-4G4A10DA10CA2-5G2A3D7BA3C7A2CA-6GA2DBI5BAC2LC2(A2C)AC2LA4J2GAD5BI2BAC2L9C2LA4J3AD8BA3C2A3CAC2A2CA2J3ACADBI6BA3CHA5CHA2C3A3C2AD7BIA14C2A2C4AD3BI5BA12CA-M3A2MAD9BA4C4A4CA-4F2MAD5BI3BA3CA3BDA3CA-6FAD9BA2CA4BD2A2CA-6FAD10B2A2BI2BDA-2A2-4E2FAD2BI14BDA5-6EA2D6BI2BI5B2DA5-6EA3D13B3DA9-3EA17DA14-17A2257-H1788-H31-H60-2H-H-2H60-H31-H2230-H30-H-H30-H97-H1937-H2893-
