model
size = 30 32 31, scale = 0.05, origin = -y
material 
  colors = A:#800 B:#700 C:#BBB D:#00F E:#DDD F:#400 G:#D00 H:#F00 I:#EEE J:#A00 K:#111
voxels
342-6A24-6A5(21-9A)3(24-6A)621-6A4-A19-6A4-A17-5A3-9A13-5A6-5(6A11-4A9-)2A17-3(5A6-6A13-)11A19-11A21-3A27-3A507-6A4-A19-2(A4-)A17-2A6-4A-4A13-A15-A11-2A16-2(A11-A17-)A11-A14-4A11-2A12-A17-A12-4A13-A15-A13-A10-6A13-A9-A19-2A3-6A21-A-A27-3A447-11A19-11A17-2A6-4A-4A13-2A6-4A-4A2(11-2A16-A)11-4(A18-A10-)A14-5A2(10-2A17-A)10-2A13-5A10-2A11-2A15-2A11-2A2(17-2A3-8A)19-10A20-10A380-11A19-A9-A17-2A11-4A13-A15-A11-2A16-A11-A17-A11-7(A18-A10-)A14-5A10-A13-A15-2A12-A17-A11-A17-2A10-A19-A8-A20-10A298-A21-10A20-10A18-2A10-5A13-2A11-4A11-2(2A17-A10-)10(A18-A10-)A14-5A10-2A13-5A12-2(A12-4A13-)2A10-A17-6A5-2A23-5A25-5A148-A29-A27-A2-A28-2A21-7A2-A20-A8-A18-2A10-5A13-A15-A11-2A17-12(A10-A18-)A10-2A17-A12-A15-A13-A12-4A13-A11-A17-6A5-2A23-A3-A25-5A145-3A-2A24-A-2A-A24-6A24-A-A2-A20-4A-A4-2A18-A9-2A14-4A12-3A11-2A16-A11-13(A18-A10-)2A17-A12-2(A15-A13-)A12-4A13-5A7-5A18-A5-A23-7A143-A5-A23-A-A2-A-A22-A6-A20-3A-A4-2A2(18-A10-A)14-4A12-3A11-A17-A11-13(A18-A10-)2A17-A12-3(A15-A13-)5A7-5A18-A5-A23-7A143-2(A6-A22-)A6-A20-2A8-2(A18-A10-)A14-4A12-3A11-A17-A11-13(A18-A10-)2A17-A12-3(A15-A13-)5A7-5A18-A5-A23-7A142-A2(7-A20-2A)7-A20-A9-2(A18-A10-)A14-4A12-4A10-2A17-4(A10-A18-)2(A5-5B19-)A5-5B2(20-10B)20-2(5B5-A19-)5B5-2(A18-A10-)2A17-A12-3(A15-A13-)2A11-4A15-3A7-A19-4A3-4A23-3A114-2(A9-A19-)A9-A18-A10-2(A16-2A11-)A16-A13-4A12-A16-A10-2A17-2(A10-A18-)A6-4B19-A-3B-B2(24-6B)2(28-2B)28-2(6B24-)B-3B-A19-4B6-A18-A10-2A17-A12-3(A15-A13-)2A11-4A15-A9-A19-4A3-4A23-3A114-A9-A18-A10-A18-A11-A17-A11-A15-2(2A11-A16-)A13-4A12-A16-A10-2A17-2(A10-A18-)A6-3B-A18-A-3B2(2-B)20-B3-2B-B24-B-2B-B2(24-6B)24-B-2B-B24-B-2B3-B20-2(B2-)3B-A18-A-3B6-A18-A10-2A17-A12-3(A15-A13-)2A11-4A15-A9-A19-4A3-4A23-3A113-A10-A19-2(A10-A18-)A9-2(A18-A10-)A16-2A12-3A13-A15-A11-2A17-2(A10-A18-)A6-3B-A18-A2-B3-3B-A18-A-3B2-B-2B20-2B-4B-2(2B20-2(2B2-))2B20-2B-4B-2B20-2B-B2-3B-A18-A-3B3-B2-A18-A-3B6-A18-A10-2A17-A12-3(A15-A13-)2A10-5A15-A8-A20-4A3-3A24-3A113-2(A10-A18-)A10-A19-A10-A17-A11-A17-A10-A16-2A12-3A13-A15-A11-2A17-12(A10-A18-)A10-2A17-A12-2(A15-A13-)2A14-A13-2A10-5A15-3A6-A20-10A141-A9-A19-2(A10-A18-)A9-2(A18-A10-)A16-2A12-3A13-A15-A11-2A17-12(A10-A18-)A10-2A17-A12-A15-A13-2A14-A15-A13-A15-3A6-6A18-A4-A24-6A142-A8-A20-A9-A18-A10-A18-A11-A16-A12-A17-A10-A16-2A12-3A2(13-2A)11-4(2A17-A10-)4(A18-A10-)A17-A11-3(A18-A10-)2A16-A11-2A16-2(A13-2A14-)A15-A10-4A15-3A6-6A18-6A24-6A142-A8-A20-2(A9-A19-)A9-A18-2(A11-2A16-)A11-A17-A11-A15-2(2A13-)A15-A13-A16-A12-A16-A10-2A17-5(A10-A18-)A10-A17-A11-2A17-A12-A15-A13-2A14-A15-A13-A15-A10-4A15-A9-A19-11A200-A8-A20-2(2A8-A19-)2A8-A18-A11-A17-A11-2A16-A11-A17-A11-A15-2(2A12-3A13-)A16-A12-A16-6(A10-2A17-)A10-2A16-A11-2A17-A12-2A14-A13-2A14-A2(15-A10-4A)15-A9-A19-11A200-2A6-2A22-2(A7-A21-)A7-2(A19-2A8-)4(A18-A10-)A16-2A12-3A5(13-A15-A)4(13-2A14-A)15-A13-A15-A10-4A15-A9-A19-A2(10-C18-C)2-6A2-C2(18-3C6-3C)19-C8-C111-9A23-A6-4(A21-A7-)A18-3A8-3(A18-A10-)A16-3(2A12-3A13-)2A2(12-3A14-A)12-3A5(15-A13-A)15-A11-3A15-11AC18-2A-8A2(C18-C2-6A2-)3(C18-C-C6-C-)C19-C8-C20-C8-C83-8A21-A7-A22-A6-2(A21-A7-)A18-3A8-9(A18-A10-)A18-A11-2I2(A15-A13-)A15-A4-A3-A4-A15-A13-A15-11A-3A26-C20-C8-C2(18-3C6-3C)18-2C8-2C19-C8-C20-C8-C145-A27-2A-3AD21-2A7-A21-A7-A19-2D8-J18-A3-6A-2(A18-A10-)A18-2A9-A18-A9-2A18-2A-9A2(18-4A2-3A-2A)2(18-4A6-2A)18-A4HA3-A4HA15-AHK-HI3-IH-KHA15-A4HI3-I4HA16-A3I2(-A)-3IA16-A4-2A-2A4-A15-15A351-A28-D-2D23-ADB4-BD22-G7-A19-2D-6A-D19-D-A6-A-A17-A3-6E-A18-2A9-A20-A7-2A19-A-7A22-A31-2(2A3-A24-)A-4A24-2A3-A26-3(A-A27-)A-A21-6F-A-6F15-6F3-6F379-4D25-D2G2-2G22-D7-GA19-D2-6A-A20-DA6-A-A18-D2-6E-A20-D7-D21-A7-J20-8AJ54-2(2A3-A24-)A-4A24-2A3-A26-3(A-A27-)A-A21-6F-A-6F15-6F3-6F381-D29-2D24-D3G2-3GD20-D-6B-A20-DG6-GA20-D-6E-D20-2D6-A22-2DG3-2A22-A2-3A24-A30-2(2A3-A24-)A-4A24-2A3-A26-3(A-A27-)3A355-2(E4-E24-)E4-E56-D26-GEG-2GEGD21-G-4E2-A21-GE4-E-A21-G-4E-GD22-A4-A24-D4G28-2A55-2(6A24-)2A3-A24-2A3-A26-A-A27-A-A28-A446-2(E4-E24-)E4-E23-DE4D2(ED22-DE4-)ED22-D6ED22-8D24-2D-D147-3A2(27-A-A)28-A868-2(3A27-A-A27-3A897-)A-A27-3A28-A433-
