model
size = 32, scale = 0.05, origin = -y
material 
  colors = A:#FCFCFC B:#010101 C:#080808
voxels
32-32A33B927-32A64B928-32AB30A2B30A929-32AB30A2B30A3-28A4-28A866-32AB30A2B30A3-28A4-28A5-26A6-26A803-32AB30A2B30A3-28A4-28A5-26A6-26A7-2(24A8-)24B8-24B676-32AB30A2B30A3-28A4-28A5-26A6-26A7-2(24A8-)B22AB9-22AB676-32AB30A2B30A3-28A4-28A5-26A6-26A7-2(24A8-)B22AB9-22AC10-20A12-20A614-32AB30A2B30A3-28A4-28A5-26A6-26A7-2(24A8-)B22AB9-22AC10-20A12-20A13-2(18A14-)18B15-16C488-32AB30A2B30A3-28A4-28A5-26A6-26A7-2(24A8-)B22AB9-22AC10-20A12-20A13-2(18A14-)B16AB14-C16AC487-32AB30A2B30A3-28A4-28A5-26A6-26A7-2(24A8-)B22AB9-22AC10-20A12-20A13-2(18A14-)B16AB14-C16AC16-14A18-14A425-32AB30A2B30A3-28A4-28A5-26A6-26A7-2(24A8-)B22AB9-22AC10-20A12-20A13-2(18A14-)B16AB14-C16AC16-14A18-14A19-12A20-12A53-10C299-32AB30A2B30A3-28A4-28A5-26A6-26A7-2(24A8-)B22AB9-22AC10-20A12-20A13-2(18A14-)B16AB14-C16AC16-14A18-14A19-2(12A20-)C10A21-C10AC21-10B267-32AB30A2B30A3-28A4-28A5-26A6-26A7-2(24A8-)B22AB9-22AC10-20A12-20A13-2(18A14-)B16AB14-C16AC16-14A18-14A19-2(12A20-)C10A21-C10AC21-B8AB23-8A24-8B204-32AB30A2B30A3-28A4-28A5-26A6-26A7-2(24A8-)B22AB9-22AC10-20A12-20A13-2(18A14-)B16AB14-C16AC16-14A18-14A19-2(12A20-)C10A21-C10AC21-B8AB23-8A24-B6AB25-6A26-6B141-32AB30A2B30A3-28A4-28A5-26A6-26A7-2(24A8-)B22AB9-22AC10-20A12-20A13-2(18A14-)B16AB14-C16AC16-14A18-14A19-2(12A20-)C10A21-C10AC21-B8AB23-8A24-B6AB25-6A26-B4AB27-4A28-4B78-2(32AB30A2B30A3-28A4-28A5-26A6-26A7-2(24A8-)B22AB9-22AC10-20A12-20A13-2(18A14-)B16AB14-C16AC16-14A18-14A19-2(12A20-)C10A21-C10AC21-B8AB23-8A24-B6AB25-6A26-B4AB27-4A28-B2AB29-2A30-2B15-)32AB30A2B30A3-28A4-28A5-26A6-26A7-2(24A8-)B22AB9-22AC10-20A12-20A13-2(18A14-)B16AB14-C16AC16-14A18-14A19-2(12A20-)C10A21-C10AC21-B8AB23-8A24-B6AB25-6A26-B4AB27-4A28-4B78-32AB30A2B30A3-28A4-28A5-26A6-26A7-2(24A8-)B22AB9-22AC10-20A12-20A13-2(18A14-)B16AB14-C16AC16-14A18-14A19-2(12A20-)C10A21-C10AC21-B8AB23-8A24-B6AB25-6A26-6B141-32AB30A2B30A3-28A4-28A5-26A6-26A7-2(24A8-)B22AB9-22AC10-20A12-20A13-2(18A14-)B16AB14-C16AC16-14A18-14A19-2(12A20-)C10A21-C10AC21-B8AB23-8A24-8B204-32AB30A2B30A3-28A4-28A5-26A6-26A7-2(24A8-)B22AB9-22AC10-20A12-20A13-2(18A14-)B16AB14-C16AC16-14A18-14A19-2(12A20-)C10A21-C10AC21-10B267-32AB30A2B30A3-28A4-28A5-26A6-26A7-2(24A8-)B22AB9-22AC10-20A12-20A13-2(18A14-)B16AB14-C16AC16-14A18-14A19-12A20-12A21-10C22-10C299-32AB30A2B30A3-28A4-28A5-26A6-26A7-2(24A8-)B22AB9-22AC10-20A12-20A13-2(18A14-)B16AB14-C16AC16-14A18-14A425-32AB30A2B30A3-28A4-28A5-26A6-26A7-2(24A8-)B22AB9-22AC10-20A12-20A13-2(18A14-)B16AB14-C16AC487-32AB30A2B30A3-28A4-28A5-26A6-26A7-2(24A8-)B22AB9-22AC10-20A12-20A13-2(18A14-)18B15-16C488-32AB30A2B30A3-28A4-28A5-26A6-26A7-2(24A8-)B22AB9-22AC10-20A12-20A614-32AB30A2B30A3-28A4-28A5-26A6-26A7-2(24A8-)B22AB9-22AC676-32AB30A2B30A3-28A4-28A5-26A6-26A7-2(24A8-)24B8-23B677-32AB30A2B30A3-28A4-28A5-26A6-26A803-32AB30A2B30A3-28A4-28A866-32AB30A2B30A929-
