model
size = 21 28 23, scale = 0.05, origin = -y
material 
  colors = A:#001
voxels
23-3A18-3A17-4A524-A2(17-4A)16-5A522-3A17-4A2(16-5A)18-4A499-4A2(16-5A)16-3A-2A17-4A18-3A478-3A17-4A19-2(4A17-)5A16-2A-2A17-4A19-2A500-3A18-4A17-2A-A18-4A17-4A18-4A520-3A18-4A17-2A-2A17-4A2(18-3A)479-2A18-4A18-3A18-4A17-2A-2A17-4A18-3A500-2A2(18-4A)17-4A17-2A-2A17-4A18-3A500-3A17-5A17-A2-2A16-5A2(17-4A)18-4A456-3A19-2A18-4A17-2A-2A16-2A-2A17-5A17-4A498-5A17-2A-2A16-A2-2A16-2A2-2A15-2A2-2A16-5A17-4A478-3A17-5A17-2A-2A16-A3-A16-2A2-2A16-5A16-6A16-4A435-3A18-2(5A16-)3A-2A15-2A2-2A16-2A2-2A15-6A16-5A2(18-3A)435-4A17-5A16-A3-2A2(15-2A3-A)16-2A2-2A15-6A16-5A476-5A17-2A-3A15-A2(3-2A15-2A)-3A15-2A2-2A15-6A17-5A433-4A17-6A15-6A16-2A2-2A15-A4-A15-2A3-2A15-2A2-2A16-5A17-3A18-5A412-3A18-5A16-2A2-2A15-2A3-2A14-2A3-2A15-A4-2A14-2A3-2A15-2A-3A16-5A18-2A435-4A17-5A16-2A2-2(2A15-2A3-2A14-2A3-)2A15-6A16-4A414-3A18-2(5A16-)6A15-2A3-A15-2A3-2A14-2A3-2A15-6A16-4A456-5A17-5A15-2A3-2A2(15-2A3-A)15-6A16-4A479-2A18-5A16-3A-2A2(15-6A)16-4A501-3A17-5A17-3A17-5A21-
