model
size = 14 25 14, scale = 0.05, origin = -y
material 
  colors = A:#1C1D20
voxels
18-13(6A8-)6A6(11-3A)64-13(6A8-)6A6(11-3A)76-13(2A6-2A4-)2A6-4(2A12-)2A11-3A11-2A10-4A10-3A47-13(A10-A2-)A10-3(A13-)A12-2(2A11-)2(3A11-)2A10-3A33-13(A10-A2-)A10-4(A13-)A12-2A11-3A10-3A11-3A9-4A31-A13(12-2A)12-4(A13-)2(A12-)2A11-3A10-3A11-2A10-3A18-A13(12-2A)12-5(A13-)2(A12-)2(2A11-)3A9-3A11-A6-2(A13(12-2A)12-6(A13-)2(A12-)2A11-2A9-4A10-2A5-)A13(12-2A)12-5(A13-)2(A12-)2(2A11-)3A9-3A11-A6-A13(12-2A)12-4(A13-)2(A12-)2A11-3A10-3A11-2A10-3A19-13(A10-A2-)A10-4(A13-)A12-2A11-3A10-3A11-3A9-4A32-13(A10-A2-)A10-3(A13-)A12-2(2A11-)2(3A11-)2A10-3A34-13(2A6-2A4-)2A6-4(2A12-)2A11-3A11-2A10-4A10-3A46-
