model
size = 18 32 25, scale = 0.05, origin = -y
material 
  colors = A:#BDC0BA B:#574C57 C:#AAA D:#F6C555 E:#888 F:#91989F G:#FFC408 H:#EEE I:#FCFAF2 J:#C99833 K:#3F2B36 L:#222
voxels
6-6B12-2A2C2A12-AC2BCA12-AB2D6(BA12-AB2A)BA12-AB2DBA12-AC2BCA13-A2CA353-2B6-2B11(8-EB6-BE)8-AEB4-BEA9-AE4BEA11-AE2BEA314-2B10-2B5(4-EC10-CE)2(4-AC10-CA4-EC10-CE)2(4-AC10-CA)4-EA10-AE5-2A8-2A7-2A6-2A9-3A2E3A294-B14-B10(2-A14-A)2(2-2A12-2A)3-A12-A5-A10-A7-A8-A9-3A2B3A10-3A2B3A11-2A2B2A12-2A2B2A13-A2BA15-2E189-B14-B2-A14-A-2A10(14-4A)14-2A-A14-A3-A12-A5-A10-A7-A8-A9-8A3(10-B6AB)11-BA2EAB12-B4AB13-4B152-B14-B-2A14-4A14-2AB8(A14-A2B)A14-AB2A14-4A14-2A-A14-A3-A12-A5-A10-A7-2(A8-)BA6-AB8-CA6-AC8-AB6-BA9-2(C6AC10-)2C4A2C11-A4CA13-4C116-B14-B-2A14-2A2(BA14-ABD3(A14-A2D)A14-AD)BA14-AB2A14-2A-A14-A2-A14-A3-A12-A5-A10-A6-2A8-2A7-2(B8-)CB6-BC8-CA6-AC8-2A6-2A9-8A10-8A11-AC2ECA13-C2BC14-C2BC15-2(2B16-)2B27-B14-B-2A14-2ABA14-AB2A14-4A14-2ACA14-ACBA14-ABHA14-AHBA14-ABCA14-AC2A14-4A14-2ABA14-AB2A14-4A14-2A-A14-A2-A14-A3-2A10-2A5-2A8-2A6-2A8-2A7-2B6-2B8-CA6-AC2(8-2A6-2A)9-A6-A10-AEC2ECEA11-AC2ECA12-AC2ACA13-2(C2AC14-)C2AC15-2B9-B14-B-2A14-2ABA14-ABCA14-A2CA14-ACBA14-ABH2(A14-A2H)A14-AHBA14-ABC2(A14-A2C)A14-ACBA14-AB2C14-2C-C14-C2-C14-C3-2C10-2C5-CA8-AC6-CA8-AC7-2B6-2B8-CA6-AC2(8-2A6-2A)9-A6-A10-AEC2ECEA11-AC2E4(CA12-AC2A)CA13-4C8-B14-B2-B14-B-B3(A14-A2B)A14-ABHA14-AHKA14-A2KA14-AKB4(A14-A2B)A14-AB-2(B14-B2-)B14-B3-2B10-2B4-2BA8-A2B5-BA8-AB2(6-3B)7-CA6-AC2(8-2A6-2A)9-A6-A10-AC4ECA11-A4EA12-6A3(12-C4AC)13-4B8-B14-B2-B14-B-B3(A14-A2B)A14-ABHA14-AHKA14-A2KA14-AKB4(A14-A2B)A14-AB-2(B14-B2-)BA12-AB3-2B10-2B4-2BA8-A2B5-BA8-AB2(6-3B)7-CA6-AC2(8-2A6-2A)9-A6-A10-ACB2EBCA11-CB2EBC12-CB2GBC13-2(B2GB14-)B2GB26-B14-B-2A14-2ABA14-ABCA14-A2CA14-ACBA14-ABH2(A14-A2H)A14-AHBA14-ABC2(A14-A2C)A14-ACBA14-AB2C14-2C-C14-C2-2C12-2C3-2C10-2C5-CA8-AC6-CA8-AC7-2B6-2B8-CA6-AC8-2A6-2A9-A6-A10-A6-A11-CB2EBC13-B2GB14-B2GB80-B14-B-2A14-2ABA14-AB2A14-4A14-2ACA14-ACBA14-ABHA14-AHBA14-ABCA14-AC2A14-4A14-2ABA14-AB2A14-4A14-2A-A14-A2-2A12-2A3-2A10-2A5-2A8-2A6-2C8-2C7-2B6-2B9-2(C6-C10-)ACB2GBCA11-CB2GBC13-B2GB116-B14-B-2A14-2A2(BA14-ABD3(A14-A2D)A14-AD)BA14-AB2A14-2A-A14-A2-A14-A3-A12-A5-AC2B4-2BCA7-C2B4A2BC8-C2B4A2BC9-B6IB11-B4GB12-2B2G2B169-B14-B-2A14-4A14-2AB8(A14-A2B)A14-AB2A14-4A14-2A-A14-A3-A12-A5-AC2BA2-A2BCA10-B2AB11-G-B4AB-G4-G5-B4AB5-G4-G-G4AG-G11-4G188-B14-B2-B14-B-2A10(14-4A)14-2A-4A8-4A3-3A8-3A5-2(2A8-)C2B2J2BC7-D4-4J4-D8-J4IJ11-G2I2L2IG11-GI2LIG8-D4-4G4-D201-10(B14-B2-)CB12-BC3-CBA8-ABC5-CB3A2-3ABC7-C3B2D3BC9-2CB2DB2C61-J12-J328-4(D12-D4-)D12-D5-B10-B7-F8-F9-2FB2-B2F13-2D442-3(D12-D4-)B12-B5-F10-F7-F8-F9-2FB2DB2F475-2(D12-D4-)2(B12-B5-F10-F7-F8-F9-2FB2DB2F493-D12-D4-)B12-B5-F10-F7-F8-F9-2FB2DB2F494-D10-D6-B10-B7-F8-F9-2FB2DB2F513-2(D8-)B8-B9-2FB2DB2F532-8D10-3B2D3B383-
