model
size = 3 28 3, scale = 0.05, origin = -y
material 
  colors = A:#111 B:#EEE C:#93F
voxels
75-4BC4B-24(A2-)A-3B3(CB)75-4BC4B
