model
size = 20 29 17, scale = 0.05, origin = -y
material 
  colors = A:#630 B:#0E0 C:#070 D:#0F3 E:#050 F:#080
voxels
7-5A573-9A570-11A12-5A14-5A296-D18-5(3D17-)3D114-13A9-9A11-7A15-5A14-5A16-5A14-5A335-3D114-13A8-11A9-9A13-7A12-7A14-7A13-6A15-5A16-4A115-4A18-A156-3D113-15A7-11A8-11A11-9A10-2(9A12-)7A13-7A14-6A13-6A14-2A3-2A12-7A13-7A12-A19-8A12-7A155-3D113-15A6-13A7-11A11-9A10-9A13-8A12-7A13-8A2(13-6A)14-2A-4A13-6A13-2A-4A12-2A18-8A11-9A10-9A14-2(3A18-)3(D19-)D18-3D113-7A-7A6-13A7-5A-5A11-4A-4A10-4A-4A13-3A-4A12-2A-4A13-8A2(13-A-4A)14-7A13-A-4A13-7A12-3A17-3A-4A11-9A10-9A13-5A16-5A212-15A6-6A-6A7-11A11-9A10-9A12-9A13-6A13-3A-4A2(13-6A)14-7A13-6A13-7A13-3A16-8A11-4A-4A10-4A-4A12-7A14-3AE3A53-C5-B8-B4-3(C5-B8-BC3-)C5-B8-B5C5-2(B8-B10-)9B3-15A6-13A7-11A11-9A10-9A13-8A13-4A15-4A17-3A2-A14-3A17-4A16-2(5A14-)2(8A11-8A12-)3A-3A14-3AE3A13-C2-E2-B13-C2-2E-B8-B4-4(C5-B8-BC3-)C5-B8-B5C5-B8-B10-B7-2B10-9B4-13A7-13A8-9A13-7A12-7A15-2A3-A14-A79-A19-2A17-4A15-7A13-6A14-7A3-F7-8A4-F7-7A5-F8-7A36-2E15-C14-B4-3(C14-BC3-)C14-B5C14-B19-B23-13A8-11A10-7A15-5A14-5A16-5A155-2(4A15-)6A4-F8-6A5-F8-5A7F50-3E175-11A9-11A11-5A255-4A5-F9-4A6-F9-3A-7F50-3E176-9A11-9A372-3E178-5A15-5A374-3E577-3E498-E18-3(3E17-)3E171-
