model
size = 30 31 29, scale = 0.05, origin = -y
material 
  colors = A:#22224B B:#141438 C:#700 D:#D79D2A E:#400 F:#001 G:#500 H:#FFBB32 I:#FC0 J:#F90
voxels
101-8G22-G6AG22-GAI2AIAG19-4G6A4G2(16-G12AG)16-GA3(I2A)IA2(G16-G12A)G16-4G6A4G19-GAI2AIA2(G22-G6A)G22-8G22-8F413-2(6E24-)6E20-2A2B6A2B2A16-2EB8AB2E16-3B8A3B15-5(16A14-)C14AC14-H14AH15-2(14A16-)AI10AIA16-14A16-14F407-12D18-2AB6AB2A18-3B6A3B16-16A14-3E10A3E14-D14AD12-5(20A10-)3C3A8B3A3C10-2H4A8-4A2H12-4(4A8-4A14-)4F8-4F405-14D16-3A8B3A16-14B13-6A8B6A10-5EA8BA5E10-3D3A8B3A3D9-5(7A8B7A8-)4C14B4C8-H3A14-3AH9-4(3A14-3A10-)3F14-3F401-3D2B8-2B3D12-3A2B8-2B3A12-5B8-5B10-5A2B8-2B5A8-6EB8-B6E8-4DA2B8-2BA4D7-5(6A2B8-2B6A6-)5C3B8-3B5C6-H2A18-2AH7-4(2A18-2A8-)2F18-2F399-3DB12-B3D10-3AB12-B3A10-B2AB12-B2AB9-4AB12-B4A8-E3AB12-B3AE8-4DB12-B4D7-5(5AB12-B5A6-)5CB12-B5C6-HA20-AH7-4(A20-A8-)F20-F399-2DB14-B2D10-2AB14-B2A10-BAB14-BAB8-4AB14-B4A6-2E2AB14-B2A2E6-5D14-5D5-5(5AB14-B5A4-)6C14-6C4-H2A20-2AH5-4(2A20-2A6-)2F20-2F397-2DB16-B2D8-2AB16-B2A8-3B16-3B6-4AB16-B4A4-3EAB16-BA3E4-5D16-5D3-5(5AB16-B5A2-)6C16-6C2-HA24-AH3-4(A24-A4-)F24-F395-2DB18-B2D6-2AB18-B2A6-BAB18-BAB5-3AB18-B3A4-3EB18-B3E4-4D18-4D3-5(4AB18-B4A2-)5C18-5C2-HA24-AH3-4(A24-A4-)F24-F395-DB20-BD6-AB20-BA6-2B20-2B5-2AB20-B2A4-3E20-3E4-3D20-3D3-5(3AB20-B3A2-)4C20-4C2-HA24-AH3-4(A24-A4-)F24-F395-DB20-BD6-AB20-BA6-2B20-2B4-3AB20-B3A2-4E20-4E2-2DAB20-BA2D-4A4(B20-B8A)B20-B4A5C20-5CH2A24-2AH-4(2A24-2A2-)2F24-2F393-2D22-2D4-AB22-BA4-2B22-2B3-2AB22-B2A2-3E22-3E2-2DB22-B2D-3A4(B22-B6A)B22-B3A4C22-4CHA26-AH-4(A26-A2-)F26-F393-2D22-2D4-AB22-BA4-2B22-2B3-2AB22-B2A2-3E22-3E2-2DB22-B2D-3AB22-B6AB22-B3AI2AB22-B2AI3AB22-B6A2(B22-B3A4C22-4CHA26-AH-4(A26-A2-)F26-F393-2D22-2D4-AB22-BA4-2B22-2B3-2AB22-B2A2-3E22-3E2-2DB22-B2D-3A4(B22-B6A))B22-B3A4C22-4CHA26-AH-4(A26-A2-)F26-F393-2D22-2D4-AB22-BA4-2B22-2B3-2AB22-B2A2-3E22-3E2-2DB22-B2D-3AB22-B6AB22-B3AI2AB22-B2AI3AB22-B6AB22-B3A4C22-4CHA26-AH-4(A26-A2-)F26-F393-2D22-2D4-AB22-BA4-2B22-2B3-2AB22-B2A2-3E22-3E2-2DB22-B2D-3A4(B22-B6A)B22-B3A4C22-4CHA26-AH-4(A26-A2-)F26-F394-D22-D2(6-B22-B)4-2AB22-B2A2-3E22-3E2-2DB22-B2D-3A4(B22-B6A)B22-B3A4C22-4CH2A24-2AH-4(2A24-2A2-)2F24-2F394-2(DB20-BD6-AB20-BA6-2B20-2B5-3B20-3B4-3E20-3E4-DAB20-BAD3-5(3AB20-B3A2-)4C20-4C2-HA24-AH3-4(A24-A4-)F24-F310-BA10-AB15-3A10-3A14-F2A10-2AF10-)2DB18-B2D6-2AB18-B2A6-BAB18-BAB5-2BAB18-BA2B4-4E18-4E4-D2AB18-B2AD3-5(4AB18-B4A2-)5C18-5C2-H2A22-2AH3-4(2A22-2A4-)2F22-2F310-BA10-AB15-3A10-3A14-F2A10-2AF12-DB16-BD10-AB16-BA8-2(3AB16-B3A6-)4E16-4E6-4D16-4D5-5(4AB16-B4A4-)4CB16-B4C4-H2A20-2AH5-4(2A20-2A6-)2F20-2F311-BA10-AB15-3A10-3A14-F2A10-2AF12-2DB14-B2D10-2AB14-B2A9-2(3AB14-B3A8-)4E14-4E8-4D14-4D7-5(4AB14-B4A6-)3C2B14-2B3C6-HA20-AH7-4(A20-A8-)F20-F312-BA10-AB15-3A10-3A14-F2A10-2AF13-2DB12-B2D12-2AB12-B2A10-2(4AB12-B4A8-)5E12-5E8-4DB12-B4D7-5(5AB12-B5A6-)3C2AB12-B2A3C6-H4A14-4AH7-4(4A14-4A8-)4F14-4F312-BA10-AB15-3A10-3A14-F2A10-2AF15-14D16-A12BA13-2(4A12B4A10-)4E12B4E10-3DA12BA3D9-5(5A12B5A8-)2C3A12B3A2C8-H3A14B3AH9-4(3A14B3A10-)3F2-10B2-3F15-2(10B20-)10B19-4(12B18-)12B19-10B21-8B19-BA10BAB15-3A10B3A14-2FA2B6-2BA2F16-12D18-AB8ABA16-2(16A14-)2E12A2E14-D14AD12-5(20A10-)C18AC10-2H16A2H12-4(16A14-)F2-10A2-F17-2(10A20-)10A19-4(12A18-)12A19-10A21-8A20-B10AB17-14A16-F3A6-3AF19-8D22-2B4C2B19-2(AB10ABA16-)EB10ABE16-DB10ABD14-4(18A12-)3G12A3G12-GIG12AGIG12-3H12A3H14-4(AB10ABA16-)2F10A2F18-10A19-F10AF17-2F10A2F16-F2G8A2GF16-FG10AGF16-FG2A6B2AGF16-FGA8BAGF16-FG10BGF16-2FB8AB2F17-2F8A2F19-F8AF19-3A6F3A18-3F6-3F79-10C3(20-C8AC)19-2C8A2C18-C2A6G2AC18-C2AGI2GIG2AC18-C2A6G2AC18-C10AC18-C2A6G2AC18-2CAGI2GIGA2C19-CA6GAC20-C8AC20-CA6GAC20-CAGI2GIGAC20-CA6GAC20-C8AC20-C2(2JA)2JC20-C8AC21-8C142-2(8A22-)ACA2CACA21-F8AF621-2(2J-)2J263-C-2C-C72-
