model
size = 23 13 9, scale = 0.05, origin = -y
material 
  colors = A:#FFD700 B:#EAC300
voxels
8-5A293-2A3-2A18-3B270-2A5-2A16-B3AB269-A7-A15-B5AB18-3A19-5B17-8A13-11B9-16A6-A3-15B3-A3-17A2(2-A)3-7B7-3A2-A4-2(AB)A10-3A6-ABA21-A18-A7-A15-B2A-2AB18-BAB19-2BA2B17-3BA4B13-5BA5B9-8BA7B6-B3-5BA9B3-B3-6B4A7B2(2-B)3-7A7-3B2-B4-B3AB10-3B6-BAB21-B18-A7-A15-B5AB18-3A19-5B17-8A13-11B9-16A6-A3-15B3-A3-17A2(2-A)3-7B7-3A2-A4-2(AB)A10-3A6-ABA21-A18-2A5-2A16-B3AB270-2A3-2A18-3B272-5A286-
