model
size = 17 26 11, scale = 0.05, origin = -y
material 
  colors = A:#FFC B:#FC6 C:#930 D:#C60 E:#C00
voxels
289-2D2(13-4D)13-3DC13-CD2C13-2C72-3C3-3C12(8-3A3-3A)5-E2(2-3A3-3A2(2-E))2-3A3-3A2-E2-B3(2-3A3-3A2(2-B))2-3A3-3A2-B-2D2-4AC4A2-4D2-3AC5A2-2D2C2-3AC5A2-2C4-3AC5A8-C2AC4AC8-9C7-C3AC-C3AC8(6-5A-5A)4-B2(-5A)-B2-E2(-5A)-E6(2-B2(-5A)-B)3(2-E2(-5A)-E)2-B-11A-B-2D-11A-4D-11A-2D2C-C9AC-2C3-A9-A6-C9-C5-C4AC-C4AC4(4-6A-6A)3-B6A-6AB4(2-E6A-6AE)5(2-B6A-6AB)2-E6A-6AE4(2-B6A-6AB)2(2-B13AB)-2DC11AC3DC13ACD2CA11-A2C2-C11-C4-C4AC-C4AC3-B6A-6AB3(2-E6A-6AE)5(2-B6A-6AB)2-E6A-6AE3(2-B6A-6AB)3(2-E6A-6AE)2(2-B6A-6AB)2-E6A-6AE2(2-B13AB)-2D13A3DC13AC3DA11-A2D3C11-3C-B5AC-C5A10(B2-B6A-6A)B2-E6A-6AE7(2-B6A-6AB)3(2-B13AB)-2D2(13A4D)A11-A2D3C11-3C2-2(C3AC3-)3(E5A3-5AE2(2-B5A3-5AB)2-)B5A3-5AB2-E5A3-5AE4(2-B5A3-5AB)2-E5A3-5AE2(2-B5A3-5AB)3(2-B13AB)-2D13A3DC13AC3DA11-A2D3C11-3C2(3-C2AC)4(6-4A3-4A)4-2(B-4A3-4A-B2-)E-4A3-4A-E6(2-B-4A3-4A-B)5(2-E-4A3-4A-E)3(2-B-11A-B)-2D-11A-3DC-11A-CD2C-A9-A-2C3-C9-C7-2C5-2C8(8-2A5-2A)5-E2-2A5-2A2(2-E)2-2A5-2A2-E2-B4(2-2A5-2A2(2-B))2-2A5-2A2-B2-E2-2A5-2A2-E2-B2(2-2A5-2A2(2-B))2-9A2(2-B)2-AC5ACA2-B-2D2-CAC3ACAC2-4D2-CAC3ACAC2-2D2C2-3C3A3C2-2C4-9A8-9C226-3(E13-E2-)3(B13-B2-)B13-B-2D13-4D13-2D2C13-2C340-2D2(13-4D)13-3DC13-CD2C13-2C68-
