model
size = 21 26 11, scale = 0.05, origin = -y
material 
  colors = A:#AAA B:#FC6 C:#555 D:#C60 E:#C00 F:#930
voxels
3-15C6(6-15A)5-17A4-17A3-19A-21AC7(19A2C)19AC63A-19A4-15A8-11A11-9C9-C3A7-3AC5(6-4A7-4A)6-A13-A5-A15-A4-A15-A3-2A15-2A-C2A15-2AC168-C6A7-6AC7A7-14A5(7-7A-6A7-6A4-4A7-4A8-2A7-2A11-C7-C9-C3A7-3AC5(6-4A7-4A)6-A13-A5-A15-A4-A15-A3-2A15-2A-C2A15-2AC189-C6A7-6AC7A)7-7A-6A7-6A4-4A7-4A8-2A7-2A11-C7-C9-C3A7-3AC5(6-4A7-4A)6-A13-A5-A15-A4-A15-A3-2A15-2A-C2A15-2AC168-C6A7-6AC7A7-14A7-7A-6A7-6A4-4A7-4A8-2A7-2A11-C7-C9-6C3A6C6(6-15A)5-17A4-17A3-19A-21AC7(19A2C)19AC63A-19A4-15A8-11A11-9C15-3B17-E4B16-4BE15-4B3E14-BE3B2E13-9B12-8BE11-2(BE)4B3E10-4BE3B3E9-2E8B2EB8-2E3BE2BE3BE7-5B3E7B6-6BE5BE2B5-2E13B2E4-2E2BE5B2E3B2E3-2E2B3E3B4E3B2E2-3B5E3B2E6B-D4B3E8BE3B2D5BE4BE3B3E2B3D9B2E3BE2B2DF2D15B2D2F5D9B5DF-2F15D2F4-7FD7F8-3F5D3F13-5F365-D19-2D19-3D17-5D15-3DF5D9-5DF-2F15D2F4-2F11D2F8-3F5D3F13-5F8-
