model
size = 21 14 26, scale = 0.05, origin = -y
material 
  colors = A:#930 B:#FC6 C:#C60 D:#C00 E:#600
voxels
282-3B269-5A16-5A265-5AC5A10-3A5C3A15-E19-10(3A18-)3A12-7AC7A6-2A11C2A30-E2A3-2AE9(12-3A3-3A)12-9A7-2A15C2A2-2A15C2A48-E9-E8(10-A9-A)10-11A5-A5C9B5C2A5C9-5CA67-E11-E7(8-A11-A)8-13A4-A2C15B2CA3C15-3C87-E13-E6(6-A13-A)6-15A3-2C9B2D3BD2B4C17-2C150-4(A13-A6-)15A3-C5BD4BD3B3D2B2C19-C171-E13-E2(6-A13-A)6-15A3-C4B3D8BD3B2C19-C171-E13-E2(6-A13-A)6-15A4-3B5D3B2D6B172-4(A13-A6-)15A4-2D2B3D3B4D3B2D109-E13-E6(6-A13-A)6-15A5-2D2BD5B2D3B2D69-E11-E8(8-A11-A)8-13A6-2D13B2D28-E9-E10(10-A9-A)10-11A8-6BD5BD2B72-E7-E5(12-A7-A)12-AE5-EA12-2AE3-E2A12-3A3E3A12-9A9-5B3D7B280-2D3BD2BD3BD281-2D8B2DB282-4BD3B3D283-2(BD)4B3D284-8BD285-9B286-BD3B2D287-4B3D288-4BD289-D4B29-
