model
size = 16 12 17, scale = 0.05, origin = -y
material 
  colors = A:#EEE B:#630
voxels
7-2(3B13-)3B2(189-A-A)188-2A-2A187-A3-A11-A3-A186-2A3-2A185-A5-A9-A14-2A11-4A12-A137-2(A15-)2A7-A14-2A14-A152-A15-A21-2A14-A153-A37-A153-A15-A21-A15-A153-3A2(15-A)2-2A11-2A15-A125-A15-A19-A171-A18-2A14-A155-2A34-A155-A191-A51-
