model
size = 18 31 15, scale = 0.05, origin = -y
material 
  colors = A:#111 B:#444 C:#FC0 D:#C66
voxels
149-2A4-2A258-6B4A6B8-4A15-2D16-2D229-2A4-2A263-6A12-6A6-6B6A6B8-2A14-A-2A-A209-9(2A4-2A10-)8A10-8A11-6A12-6A13-4A31-2(6A12-)6A11-3C2A3C10-C-C2AC-C10-3C2-3C190-9(2A4-2A10-)4(8A10-)8A11-5(6A12-)6A208-2A6-2A135-5(8A10-)8A11-4(6A12-)6A11-8A2(10-2A4-2A)11-A4-A154-10A9-11(8A10-)8A11-7(6A12-)A4-A190-10A8-10A9-8A9-2(10A8-)10A9-4(8A10-)8A11-6A13-4A14-4A32-4A13-2(6A12-)6A226-5(10A8-)10A9-2(8A10-)8A11-6A389-8A9-3(10A8-)10A9-8A10-8A11-6A12-6A13-4A391-6A12-6A11-3(8A10-)8A461-3(6A12-)6A500-2A16-2A538-2A16-2A397-2A16-2A2(15-3A)15-2A15-3A14-3A15-2(2A16-)2A397-2A16-2A2(15-3A)15-2A15-3A14-3A15-2A16-2A404-
