model
size = 32, scale = 0.05, origin = -y
material 
  colors = A:#111 B:#006 C:#00F D:#6F0 E:#E00 F:#CC0 G:#001 H:#0A0 I:#070 J:#EEE K:#888
voxels
-32A30E2ABK28-29(2AB29-)34A6BAEA12BAEA6B2A5B5E10B5E5B2A4B2E3-2E8B2E3-2E4B2A3B2E5-2E6B2E5-2E3B2A2B2E7-2E4B2E7-2E2B2ABAE9-EA2BAE9-EAB3A2E9-2E2A2E9-2E3ABAE8-2EA2BAE9-EAB2A2B2E6-3E4B2E7-2E2B2A3B2E5-2E6B2E5-2E3B2A4B2E3-2E8B2E3-2E4B2A5B5E10B5E5B2A6BAEA12BAEA6B2A7BA14BA7B2A30B2A2B3E6B3E16B2AB2E-2E4B2E-2E15B2A2E3-2E2B2E3-2E4B3E3B3EB2AE5-E2AE2-D2-E3B2E-2EB2E-2E2A2E3-2E2B2E3-2E3BE-H-EAE-H-E2AB2(2E-2E4B)2E-2EB2E-2E2A2B2(3E6B)3E3B3EB2A3B2(A8B)A5BA2B2A2B2(3E6B)3E3B3EB2AB2(2E-2E4B)2E-2EB2E-2E2A2E3-2E2B2E3-2E3BE-H-EAE-H-2(E2AE5-)E3B2E-2EB2E-2E2A2E3-2E2B2E3-2E4B3E3B3EB2AB2E-2E4B2E-2E15B2A2B3E6B3E16B34A30B2ABG28-2ABG3-5F10-5F5-2ABG2-2F3D2F8-2F3D2F4-2AB2G2FD3-D2F6G2FD3-D2F-2G2ABG2FD5-D2F4-2FD5-D2F2-2ABGFD7-DF4-FD7-DF2-2ABGF2(D3-)DF4-F2(D3-)DF2-2ABGFD6-D2F4-FD7-DF2-2ABG2FD4-D3F4-2FD5-D2F2-2ABG-2FD3-D2F6-2FD3-D2F3-2ABG2-2F3D2F8-2F3D2F4-2ABG3-5F10-5F5-2(2ABG28-)2AB29-2AB-3F5G-3F16-2AB2FD2FG3-2FD2F15-2A2FD-D2F2-2FD-D2F4-3F3-3F-2AF2(D-)DF2-F2(D-)DF3-2FD2F-2FD2F2A2FD-D2F2-2FD-D2F3-F3DF-F3DF2AB2(2FD2F4-)2FD2F-2FD2F2AB-2(3F6-)3F3G3FG2AB21-G7-2AB-2(3F6-)3F3-3F-2AB2FD2F4G2FD2F4-2FD2FG2FD2F2A2FD-D2F2-2FD-D2F3-F3DF-F3DF2AFD-H-DF2-FD3-DF3-2FD2(2F-)2F2A2FD-D2F2-2FD-D2F4-3F3-3F-2AB2FD2F4-2FD2F15-2AB-3F6-3F16-34A30B2ABG28-2AB4-5D10-5D5-2AB3-7D8-7D4-2ABG-3D3H3DG5-3D3H3D2-G2AB-3D5H3D4-3D5H3D2-2AB-2D7H2D4-2D7H2D2-2AB-2D3HD3H2D4-2D3HD3H2D2-2AB-2D6H3D4-2D7H2D2-2AB-3D4H4D4-3D5H3D2-2AB2-3D3H3D6-3D3H3D3-2AB3-7D8-7D4-2AB4-5D10-5D5-2(2AB29-)2ABG28-2ABG3D6-3D15-G2AB5DG3-5D14-G2A3DH3D2-3DH3D4-3D3-3DG2A2DHDH2D2-2DHDH2D3-5D-5D2A3DH3D2-3DH3D3-5D-5D2AB2(5D4-)5D-5D2AB-2(3D6-)3D2-G3DG2AB20-G8-2AB-2(3D6-)3D3-3D-2AB5DG3-5D4-5DG5D2A3DH3D2-3DH3D3-5D-5D2A2DHDH2D2-2D3H2D3-5D-5D2A3DH3D2-3DH3D4-3D3-3D-2AB5D4-5D15-2AB-3D6-3D16-34A30B2ABG28-2(2AB29-)2AB2-9G18-2AB16-11G-G4(2AB29-)6(2AB28-G)2AB29-2AB5G4-4G16-2(2AB29-)2AB28-G2AB21-G6-G2AB20-2G3-4G2AB29-2AB20-G8-2AB5G4-4G7-3G-3G2-5(2AB29-)34A30B2ABG28-3(2AB29-)5(2AB28-G)7(2AB29-)2ABG28-4(2AB29-)2AB28-G2(2AB29-)2ABG19-G8-5(2AB29-)34A30B2ABG27-B3(2AB29-)2AB28-G11(2AB29-)2ABG28-4(2AB29-)2AB28-G2(2AB29-)2ABG28-5(2AB29-)34A30B2ABG28-3(2AB29-)2AB28-G11(2AB29-)2ABG28-7(2AB29-)2ABG28-5(2AB29-)34A30B2ABG9-4(18C-2AB10-)18C-2AB28-G11(2AB29-)2AB2G27-7(2ABG28-)5(2AB29-)34A30B2ABG28-4(2AB29-)2AB28-G24(2AB29-)34A30B2ABG28-29(2AB29-)34A30B2AB5I24-2AB4I25-28(2AB29-)34A30B2AB5I2J22-2AB4I25-17(2AB29-)11(2AB4-25C)34A30B2AB5I-J22-2AB4I25-28(2AB29-)34A30B2AB6-J22-29(2AB29-)34A30B2AB7J22-29(2AB29-)34A30B2ABJ28-29(2AB29-)34A30B2ABJ9-13(9C10-2AB10-)9C10-16(2AB29-)34A30B2ABJ28-18(2AB29-)11(2AB19-5C5-)4(34A30B2ABJ28-29(2AB29-))34A30B2ABJ4-8(6C8-8C2-2AB5-)3(6C18-2AB5-)6C18-9(2AB29-)9(2AB19C10-)3(34A30B2ABJ28-29(2AB29-))34A30B2ABJ28-17(2AB29-)12(2AB13-16C)34A30B2ABJ28-29(2AB29-)34A30B2ABJ9-10(9C10-2AB10-)9C10-19(2AB29-)34A30B2ABJ28-14(2AB29-)15(2AB3-13C13-)34A30B2ABJ28-29(2AB29-)33A
