model
size = 27 32 18, scale = 0.05, origin = -y
material 
  colors = A:#222 B:#111 C:#E00 D:#EEE E:#777 F:#444 G:#AAA H:#BBB I:#DDD J:#FC6 K:#F9C
voxels
157-2(D26-)D1333-3(3B9-3B12-)3B9-3B660-3(3B9-3B12-)3B9-3B120-3B9-3B471-5(3B9-3B12-)3B9-3B255-3B9-3B309-4(3B9-3B12-)3B9-3B444-3B9-3B147-4(3B9-3B12-)3B9-3B579-3B9-3B93-3B9-3B12-3B9-3B714-3B9-3B66-3B9-3B768-3B9-3B66-3B9-3B741-3B9-3B120-3B9-3B12-3B9-3B552-4(3B9-3B12-)3B9-3B64-19A7-4(21A-G4-21AH-G3-)21A3D3-4(21A6-)2(21A3-3C2(21A6-))5(21A6-)21A7-19A143-19A7-21AH-4(G3-21A6-21A2-)D3-4(21A6-)21A3-C2-2(21A6-)21A3-C2-2(21AD5-)F19AFD5-2(E19AE6-F19AF6-)E19AE7-9(FE)F143-19A7-21A-G4-3(21A2-G3-21A6-)21A2-G3-21A2-D3-4(21A6-)2(21A3-C2-2(21A6-))2(E19AE6-F19AF6-)E19AE6-F19AF7-9(EF)E143-19A7-21AH-4(G3-21A6-21A2-)D3-4(21A6-)2(21A3-3C2(21A6-))5(21A6-)21A7-19A143-19A7-4(21A-G4-21AH-G3-)21A3D4-2(19A8-)3A13C3A8-3A2(C3D)2(2CD2C3A8-3A4(CD))2CD2C3A8-3AC3D2(CD)C3DC3A8-3A13C3A8-19A8-3A13C3A8-3AC3DCD4CD2C3A8-3A2(CD)C3D2CD2C3A8-3A4(CD)2CD2C3A8-3A3(C3D)C3A8-3A13C3A8-19A170-19B7-2(21B6-)3BCB10CBC4B6-5B10C6B6-5B10C4BCB6-19BCB3(6-21B)7-19B66-3D-3D2(2-D17-3(D-)D)2-D17-3D2(-D)-3D97-3D-D4-D17-2(D-)3D2-D17-3(D-)D2-D17-2(3D-)3D228-19B7-2(2B18-B6-)2B-J-10D-J3-B6-2B-J-D8ID-J3-B6-2B3-10D-J2-2B6-2B14-K2-2B3(6-21B)7-19B575-19B7-5(21B6-)B9(EF)EB6-B9(FE)FB6-21B7-19B598-
