model
size = 32 31 19, scale = 0.05, origin = -y
material 
  colors = A:#9CF B:#FF9 C:#FC9 D:#A00 E:#E00 F:#800 G:#001 H:#F93 I:#69C J:#B00 K:#FFF L:#EEE M:#F9C N:#0F9 O:#FCC P:#F0C Q:#0FF R:#F60 S:#966 T:#FF3 U:#3FF V:#FC3
voxels
45-7C24-12C19-4C4-7C17-3C8-5C16-3C10-4C29-2(3C30-)3C29-2(3C30-)3(2C30-)2C29-3C29-2C29-2(3C28-)2(4C27-)4C28-2C277-6C24-12C19-15C17-16C16-4C5-8C15-4C7-6C2(28-5C)2(28-4C29-4C)3(28-4C)27-4C28-2(4C27-)3(5C26-)5C27-4C28-2C246-7C23-13C17-D15C16-D16C15-D4C3D-9C14-D4C-3D3-7C13-3D3-3D5-5C12-3D4-3D6-5C11-3D14-2(5C28-4C28-)2(4C28-)4C27-5C27-4C27-2(5C26-)2(6C25-)6C26-5C27-3C234-3D2-D5-7C16-5D2-13C12-6D15C11-6D16C10-6D4C4D9C9-6D4C5D2-6C12-12D4-5C11-12D5-5C10-12D6-5C9-12D7-4C10-8D11-3C14-4D11-4(4C28-)3C28-4C27-3(5C26-)5C2(27-4C)28-2C232-J6F7D7C11-J6F5D11C9-2J5F4D14C8-J5F4D4C4D7C7-J5F4D4C6D-5C6-J5F4D4C6D3-4C6-J4F14D4-3C6-J4F14D5-3C5-2J3F14D6-3C5-J3F14D7-2C5-2J2F14D7-3C4-2J2F15D7-2C5-J2F14D8-2C5-3J13D9-2C6-2J11D11-2C30-2C29-5(3C28-)3C29-2C263-J6-14A10E-J6-6A7BA10E-JE5-5A8BA9E3-J5-5A4B5A7E5-J5-5A4B5AD6E5-J5-5A4B5A3D3E6-2J4-13A4D2FE7-J4-13A3D2FE8-JE3-14A2D2F9-JE3-14AD2FE10-JE2-12A3DFDE10-2E2-D11A3DFE11-2E2-D11A3DFE12-2J-2D10A2D2F14-2J14DE85-6A25-3(8A24-)8A25-6A271-J2C22A2C3E2-J2C4A14B4A2C3E2-JE-13A5B4AD3E4-2(E-13A5B4AD2E5-)E-13A5B4ADE6-2E-12A5B3A2-E7-E3-10A5BAD2-D8-2E2-10A5BAD2-E8-2E2-10A5BA2-E10-2E-10A5BA-2E10-2E-10A4B2A-E11-2E-10A4B2A-E12-2E-5A7B2A2-E13-2E14A2E16-14A18-14A19-4A5B3A4(20-4A6B2A)20-4A5B3A21-10A23-8A206-E2C22A2C5-E2C19B3A2C5-2E3(-13A5B4A-E6-E)-13A5B4A-E6-2E13A5B4A-E7-E2-11A5B2A3-E7-2E-11A5B2A-2E8-2E2-10A5BA2-E10-2(2E-10A5BA-E11-)2E-10A4B2A-E12-2E6A8B2A-E13-2E5A8BA2E16-7(5A8BA18-)5A8BA19-A10BA20-2A8B2A22-8A174-E2C22A2C5-E2C19B3A2C5-2E3(-13A5B4A8-E)-13A5B4A8-2E13A5B4A9-E2-11A5B2A11-2E-11A5B2A11-2E2-3(10A5BA13-2E-)10A4B2A-E12-2E6A8B2A-E13-2E5A8BA3E15-7(5A8BA18-)5A8BA19-A10BA20-2A8B2A22-8A174-E2C22A2C5-E2C2A17B3A2C5-2E3(-13A5B4A8-E)-13A5B4A9-E-12A5B3A10-E2-11A5B2A11-2E-11A5B2A12-E2-2(10A5BA13-2E-)10A5BA14-E-10A4B2A14-2E6A8B2A15-2E5A8BA3E15-7(5A8BA18-)5A8BA19-A10BA20-2A8B2A22-2A3B3A26-4A149-18A14-A16BA7(14-11A5B2A)15-3(10A5BA16-)10A4B2A16-6A8B2A17-8(5A8BA18-)5A8BA19-A10BA20-2A8B2A22-8A26-4A29-3E29-3R29-2H31-V22-18A14-A16BA7(14-11A5B2A)15-3(10A5BA16-)10A4B2A16-6A8B2A17-9(5A8BA18-)C12BC17-2C12B2C16-4C8A4C16-4C2-4A2-4C16-4C3-3E2-4C16-2C5-2R5-2C24-H54-18A14-A16BA7(14-11A5B2A)15-3(10A5BA16-)10A4B2A17-10(5A8BA18-)C12BC17-CM12BMC16-C2MB8AB2MC17-2MB2-4A2-B2M17-C-2C8-2C-C16-2C12-2C79-18A14-A16BA4(14-11A5B2A)15-5(10A5BA16-)10A5BA17-9A4B3(A18-5A8B)A16-2C5A9B2C15-C5A9BC16-C5A9BC17-3(5A8BA18-)5A8BA19-A10BA20-A10BA21-C8AC22-C8-C147-2(7A2I6AC16-)3(7A2I7A16-)7AEK7A16-6I2E2K2I4A17-5I2K2E5I18-3H2A2K2E2A3H18-3A8H3A18-2(GA)GH2AH2(GA)G18-2A3H4A3H2A19-H3A4C3AH20-12C19-6C2S6C18-CB10CBC16-7C4G7C15-C2O2CG4CG2C2OC16-C2OB3C2G3CB2OC17-AB3C4G3CBA18-AB3L4C3LBA18-AL3PL2CL3PLA18-AL2GPL2CLP2GLA19-AUG2L2A2LGUA20-2A2LC2AC2L2A22-3A2T3A180-4C8-4C16-C2BC8-C2AC3(16-4A8-4A)16-4A3-EK3-4A17-3A2-2E2K2-3A23-2K2E23-3H2-2K2E2-3H21-3H2Q3H26-H2QH25-3H4-3H21-H10-H49-2G14-2G16-2G10-2G49-2G12-2G13-3G2(3-G3-2G)16-G3-4G3-G17-3G-3K4-3K-3G17-K3NK2-K3NK20-K2GNK2-KN2GK20-KQG2K2-2KGQK21-3K4-3K211-4C8-4C16-C2BC8-C2AC16-4A8-4A16-4I8-4I17-3A8-3A18-3I8-3I18-3A8-3A785-5C6-5C16-5C6-5C944-5C6-5C16-2(C-)C6-2(C-)C938-
