model
size = 29 32 3, scale = 0.05, origin = -y
material 
  colors = A:#F93 B:#444
voxels
14-2(B28-)B25-7A19-3A7-3A14-2A13-2A11-A17-A9-A19-A7-A21-A5-A23-A4-A23-A3-2(A25-A2-)A25-A-A6(27-2A)27-A-2(A25-A2-)A25-A3-A23-A4-A23-A5-A21-A7-A19-A9-A17-A11-2A13-2A14-3A7-3A19-7A109-7A19-3A7-3A14-2A13-2A11-A17-A9-A7-A2-A8-A7-A8-A2-A9-2(A5-)10A8-A4-A6-A8-A7-A3-A7-A9-A7-2(A2-A7-A10-A6-)A-A2(8-A10-A7-2A)8-A9-A8-2A2(8-A)9-2A8-A4-4A10-2A2(8-A)9-2A8-A9-A8-A-2(A7-A10-A6-A2-)A7-A10-A6-A3-A6-A10-A5-A4-A6-A9-A6-A5-A4-11A6-2(A7-)A2-A8-A9-A6-A2-A7-A11-2A13-2A14-3A7-3A19-7A226-A2-A25-A2-A21-10A20-A8-A19-A9-A18-4(A10-A17-)A9-A18-A8-A19-A4-4A20-A8-A19-A9-A18-4(A10-A17-)A9-A17-11A22-A2-A25-A2-A100-
