model
size = 24 30 14, scale = 0.05, origin = -y
material 
  colors = A:#EEE B:#111
voxels
24-26AB3ABA4BAB2A2(BA)B5AB2A2BAB4AB2ABA2B6A3(BA)2B3A4B2(AB)5A2B2ABAB4AB2A2(BA)B5AB3AB2(A4B)A2B61AB2A4B17AB5AB17AB2A4B17AB2AB20AB2A4B36A4BAB3ABA3B10AB4AB2A2BAB2AB9A2B3A3(BA)B2AB9AB4A2B2ABAB2AB9A4BAB3ABA3B36AB3AB2ABA4B11AB3AB2ABAB14AB3A4BA2B13AB3AB2ABAB12A5BAB2ABA4B77A3-2A14-2A3-73A2(BA)3B3A2(BA)B3AB6A2B2(3AB)A3B3AB5A3B2A2BA3B2(AB)A3B5A4(3BA)3B30AB2A3BA2BABA3B2AB6AB3A2B2A3(BA)B2AB5A3BA3B2A2(BA)3BA3B53A2(4BA)B2ABAB2AB8A3(BAB2A)B7A2BAB2AB2(A4B)8A3(BAB2A)B5A4BAB2ABA4BAB2AB53A3B4AB2A4BA4B6AB5A2(B2A)BAB2AB6AB5A2(B2A)BA4B6AB5A2(B2A)BAB2AB5A3B3A3BAB2ABA4B75A3-2A14-2A702-2A14-2A6-10(2A14-2A702-)2A14-2A678-2A14-2A6-2A14-2A3-
