model
size = 25 25 19, scale = 0.05, origin = -y
material 
  colors = A:#03F B:#111 C:#96F D:#96C E:#C6F F:#F9F G:#66F H:#36F I:#008 J:#00C K:#30C L:#93F M:#60F N:#009 O:#00A P:#93C Q:#90C R:#99F S:#C9F T:#00B U:#309 V:#63F W:#66C
voxels
9-7B16-2B7-2B12-2B11-2B9-B15-B7-B17-B5-B19-B4-B19-B3-B21-B2-B21-B-B6(23-2B)23-B-B21-B2-B21-B3-B19-B4-B19-B5-BA16-B7-B15-B9-2B11-2B12-2B7-2B16-7B3(18-7A16-2A7-2A12-2A11-2A9-A15-A7-A17-A5-A19-A4-A19-A3-A21-A2-A21-A-A6(23-2A)23-A-A21-A2-A21-A3-A19-A4-A19-A5-2A16-A7-A15-A9-2A11-2A12-2A7-2A16-7A)18-7A16-2A7-2A12-2A11-2A9-A15-A7-A17-A5-A19-A4-A19-A3-A21-A2-A21-A-A23-A2(D23-C)D2(23-2C)23-CD23-C-D21-C2-A21-A3-A19-A4-A19-A5-2A16-A7-A15-A9-2A11-2A12-AC7-2A16-6CA18-7A16-2A7-2A12-2A11-2A9-A15-A7-A17-A5-A19-A4-A19-A3-A21-A2-A21-A-A23-AD23-DC23-D2(E23-C)E23-2C23-C-D21-D2-A21-A3-A19-A4-A19-A5-2A16-A7-A15-A9-2A11-2A12-AD7-2A16-4C2DA18-7A16-2A7-2A12-2A11-2A9-A15-A7-A17-A5-A19-A4-A19-A3-A21-A2-W21-A-D23-D2(I23-H)U23-HF23-SF23-2E23-E-R21-E2-D21-D3-A19-A4-A19-A5-2A16-A7-A15-A9-2A11-2A12-DE7-2A16-2ES3HD18-7A16-2A7-2A12-2A11-2A9-A15-A7-A17-A5-A19-A4-A19-A3-A21-A2-D21-D-C23-DO23-H2(J23-G)N23-GI23-EF23-L-F21-P2-C21-C3-A19-A4-A19-A5-2A16-A7-A15-A9-2A11-2A12-CP7-DA16-LE3GHD18-7A16-2A7-2A12-2A11-2A9-A15-A7-A17-A5-A19-A4-A19-A3-A21-A2-D21-D-C23-CV23-H2(J23-G)A23-LK23-LI23-K-F21-Q2-C21-E3-A19-A4-A19-A5-2A16-A7-A15-A9-2A11-2A12-EQ7-DA16-K2L2GHC18-7A16-2A7-2A12-2A11-2A9-A15-A7-A17-A5-A19-A4-A19-A3-A21-A2-D21-D-C23-CM2(23-2M)23-MT23-TO23-ON23-N-K21-K2-E21-E3-A19-A4-A19-A5-2A16-A7-A15-A9-2A11-2A12-EK7-DA16-NOT3MC18-7A16-2A7-2A12-2A11-2A9-A15-A7-A17-A5-A19-A4-A19-A3-A21-A2-D21-D-C23-CH23-V2(G23-J)L23-AL23-2K23-I-Q21-F2-E21-C3-A19-A4-A19-A5-2A16-A7-A15-A9-2A11-2A12-CF7-DA16-IKA2JVC18-7A16-2A7-2A12-2A11-2A9-A15-A7-A17-A5-A19-A4-A19-A3-A21-A2-D21-D-D23-CH23-O2(G23-J)G23-NE23-IL23-F-P21-F2-C21-C3-A19-A4-A19-A5-2A16-A7-A15-A9-2A11-2A12-CF7-DA16-FIN2JOC18-7A16-2A7-2A12-2A11-2A9-A15-A7-A17-A5-A19-A4-A19-A3-A21-A2-A21-W-D23-D2(H23-I)H23-US2(23-FE)23-E-E21-R2-D21-D3-A19-A4-A19-A5-2A16-A7-A15-A9-2A11-2A12-DR7-WA16-E2FU2ID18-7A16-2A7-2A12-2A11-2A9-A15-A7-A17-A5-A19-A4-A19-A3-A21-A2-A21-A-A23-AD23-2D23-2C3(23-EC)23-C-D21-D2-A21-A3-A19-A4-A19-A5-2A16-A7-A15-A9-2A11-2A12-AD7-2A16-C3ECDA18-7A16-2A7-2A12-2A11-2A9-A15-A7-A17-A5-A19-A4-A19-A3-A21-A2-A21-A-A23-A3(C23-D)C2(23-2C)23-D-C21-D2-A21-A3-A19-A4-A19-A5-2A16-A7-A15-A9-2A11-2A12-AD7-2A16-D2C3DA3(18-7A16-2A7-2A12-2A11-2A9-A15-A7-A17-A5-A19-A4-A19-A3-A21-A2-A21-A-A6(23-2A)23-A-A21-A2-A21-A3-A19-A4-A19-A5-2A16-A7-A15-A9-2A11-2A12-2A7-2A16-7A)18-7B16-2B7-2B12-2B11-2B9-B15-B7-B17-B5-B19-B4-B19-B3-B21-B2-B21-B-B6(23-2B)23-B-B21-B2-B21-B3-B19-B4-B19-B5-B17-B7-B15-B9-2B11-2B12-2B7-2B16-7B9-
