model
size = 29 21 29, scale = 0.05, origin = -y
material 
  colors = A:#222 B:#111 C:#FF6 D:#F9F E:#C6F F:#30C G:#00A H:#66F I:#008 J:#36F K:#60F L:#00C M:#96F N:#03F O:#93F P:#C9F Q:#33C R:#009 S:#00D T:#90C U:#93C V:#309 W:#63F X:#F6F Y:#639 Z:#00B
voxels
11-7A599-13A19-7B568-17A14-13B564-19A11-17B561-21A9-19B559-2(8A7-)7B7-7B15-7A22-7C4(22-7A)3(22-6AB)4(22-7A)2(22-6AB)4(22-7A)13-7A11-7A5-6B11-6B12-2A7-2A18-2C7-2C6(18-2A7-2A)5(18-2A7-BA)5(18-2A7-2A)18-11A11-6A13-6A5-5B13-5B2(11-A)16-C11-C12(16-A11-A)3(16-B11-A)16-A11-A16-13A9-6A15-6A3-5B15-5B9-A13-A14-C13-C4(14-A13-A)8(14-B13-A)4(14-A13-A)14-15A8-5A17-5A3-4B17-4B8-A15-A12-C15-C16(12-A15-A)12-17A7-5A17-5A3-4B17-4B8-A15-A12-C15-C16(12-A15-A)12-17A6-5A19-5A-4B19-4B6-A17-A10-C17-C13(10-A17-A)3(10-A17-B)10-19A5-5A19-5A-4B19-4B6-A17-A10-C17-C6(10-A17-A)8(10-A17-B)2(10-A17-A)10-19A5-5A19-5A-4B19-4B6-A17-A10-C17-C16(10-A17-A)10-19A5-5A19-5A-4B19-4B6-2(A8-)2(A10-C17-C16(10-A17-A)10-19A5-5A19-5A-4B19-4B6-A17-)A10-C17-C8(10-A17-A)6(10-B17-A)2(10-A17-A)10-19A5-5A19-5A-4B19-4B6-A17-A10-C17-C4(10-A17-A)4(10-B17-A)8(10-A17-A)10-19A6-5A18-4A3-4B18-3B8-A16-B11-C15-C3(12-A15-A)11(12-A15-B)2(12-A15-A)12-17A7-5A17-5A3-4B17-4B8-A15-A12-C15-C5(12-A15-A)2(12-A15-B)9(12-A15-A)12-17A7-6A15-6A3-5B15-5B9-A13-A14-C13-C16(14-A13-A)14-15A9-6A13-6A5-5B13-6B10-A11-A16-C11-C16(16-A11-A)16-13A10-7A11-7A5-6B11-6B12-2A7-2A18-2C7-2C2(18-2A7-2A)17-2AM7-2A18-IG7-JA2(18-IG7-2J)18-VG7-HJ18-DI7-2P18-DY7-HP18-2D7-MP18-2D2(7-2E18-ED)7-2E18-AE7-EA18-AM7-2A18-2A7-2A18-11A12-2(8A7-)7B7-7B15-7A22-7C2(22-7A)22-GFKQHJM22-GW2KQ2J22-2LFK2HJ22-2LF2K2H22-2LN2K2H22-FSNFKMH22-R2NZGOH22-IFNFGOE22-I2F2GOE22-DIGRGFO22-D4IFO22-3D2FTU22-5DXE2(22-7A)15-21A9-19B561-19A11-17B563-17A14-13B567-13A19-7B573-7A591-
