model
size = 27 26 27, scale = 0.05, origin = -y
material 
  colors = A:#600 B:#800 C:#400 D:#888 E:#555 F:#500
voxels
63-C26-4C23-8C19-3A5C2(19-5A3C)19-5A2BA19-3A4BA19-3A3B2A19-2A4BAB19-4B3AB19-3B3A2B19-3BA4B19-B3A3BA19-B2A2B2(3A19-A4B)3A19-A3B4A19-4B4A19-3B5A24-3A25-2A26-A98-3C2(24-A2C)6-2C16-3(3A6-3C15-)3(3A6-2AC15-)3(3A6-3B15-)3(3B6-3A15-)B2A3(6-3A15-3A)6-3A15-2BA6-3A15-B8-2(3A24-)3A26-A13-3(3C24-)2(B2A24-)4(B2A10-3C11-)2(3A10-3C11-)3A10-A2B11-3A10-2BA3(11-3A10-3A)2(11-3B10-3A)2(11-B2A10-3A)3(11-3A10-3A)11-2A11-2(3A24-)3A10-2(2C25-)2A3(25-2B)14-C10-3(2B14-2C9-)2(BA14-2C9-)BA5(14-2A9-2A)14-2A9-B15-2(2A9-2B14-)2A9-BA3(14-2A9-2A)14-2(2A25-)2A8-2(2C25-)4(2A25-)5(2B16-2C7-)2B3(16-AC7-2A)4(16-2A7-2A)2(16-2A7-2B)2(16-2A7-BA)16-2A7-2A16-2(2A25-)2A6-2(2C25-)3(2A25-)BA25-6(2B18-2C5-)2(BA18-2C5-)3(BA18-2A5-)4(2A18-2A5-)2B18-2A5-2B18-AB5-BA18-AB5-A19-AB25-2A5-2(C26-)5(B26-)A26-A6(20-C5-B)2(20-A5-B)5(20-A5-A)20-A3(5-B20-B)31-CA25-2A5(25-2B)2(25-2A)6(20-2C3-2B)2(20-2A3-2B)6(20-2A3-2A)2(20-2B3-2B)20-2B30-C26-A3(26-B)4(26-A)8(22-A3-B)6(22-A3-A)22-B3-A2(22-B3-B)14(25-2B)5(22-2B-2B)22-2B3(-2A22-AB)2(-2A22-2B)-BA22-2B-BA25-13(B26-)6(B24-B-)4(A24-B-)2(A24-A-)14(B26-)6(B24-B-)4(A24-B-)A24-A-2(A26-)13(B26-)6(B24-B-)A2(24-A-B)3(24-A-A)26-A14(26-B)5(24-B-B)24-B4(-A24-A)-11(A26-)3(B26-)A26-5(A24-B-)2(A24-A-)2(A24-AC)B24-AEB24-A-B10(26-A)3(26-B)2(26-A)5(24-B-A)2(24-A-A)24-ACA24-AE2(A24-A-)3(A26-)8(2A25-)3(2B25-)3(2A22-AB-)4(2A22-2A-)2A22-3C2A22-2AC2A22-2AE2A22-2A-2A2(25-BA)25-2A53-A26-A3(25-2C)2(25-CA)3(25-2B)25-CA22-B6(2-CA22-A)2-CA22-2C-CA22-AD-2(CA22-A2-)3(CA25-)CA53-2A25-2A5(24-2CA)3(24-3B)20-B3-2CA20-AB6(2-2CA20-2A)2-2CA20-3C-2CA20-2AE-2(2CA20-2A2-)2CA24-C2A24-B2A24-C2A53-A26-5(A25-C)A3(25-2B)20-B7(4-CA20-A)4-CA20-2C3-CA20-AE3-2(CA20-A4-)2(CA25-)2C25-CA53-A26-8(2A24-C)4(2A18-2B4-C)4(2A18-2A4-C)2A18-3C3-C2A18-2AE3-2(C2A18-2A4-)2(C2A24-)3C25-2A80-3(2A23-CD)4(2A23-CE)2A16-B6-4(CE2A16-2B5-)CE2A16-2(BA5-CEA17-)2(2A5-CE2A16-)3C4-CE2A16-2AE4-2(CE2A16-2A5-)ED2A16-A6-ED2A23-3CA24-E2A80-3(2A22-2CD)2A22-CED2A23-E2(D2A24-)7(D2A14-2B8-)2(D2A14-2A8-)D2A14-A2C7-D2A14-2AE7-3(D2A14-2A8-)D2A24-C2A24-E2A105-C-2(3A22-CD)3A22-2D2(3A22-DC)3A23-7(C3A10-3B10-)2(C2(3A10-))C3A10-3AC9-C3A10-3AE9-C2(3A10-)E2(3A10-)D2(3A10-)C3A23-E3A24-3A131-C2-2AB21-C2-3A21-F2D3(3A21-CED)6(3A6-3B13-ED)3A6-2AB3(13-ED3A6-3A)-C11-ED3A6-3A2C11-ED3A6-3AED11-2(2D3A6-3A13-)3C2A22-ED3A24-3A161-AB21-3C-A3B19-EDC-2A4B17-EDC-2A5B16-EDC-2A6B15-ED2C2A6B4(16-D2C4A4B)2(16-D2C6A2B)16-D2C7AB2(16-D2C8A)2C14-D2C8A2E15-2(EC8A17-)CD6A19-E-6A21-4A543-C21-5CE19-5C2E20-2CD2E22-2E70-
