model
size = 32 32 6, scale = 0.05, origin = -y
material 
  colors = A:#F96 B:#E00 C:#C63 D:#600 E:#930 F:#111
voxels
205-6A21-16A15-18A13-20A11-4B14A4B2(10-A2B16A2BA)2(10-2A2B14A2B2A)2(10-3A2B12A2B3A)2(10-4A2B10A2B4A)2(10-5A2B8A2B5A)2(10-2(6A2B)6A)10-7A2B4A2B7A11-6A2B4A2B6A13-6A2B2A2B6A15-5A6B5A21-2A2B2A565-D14-D16-16D2(16-16E)16-16D16-D14-D436-8A21-3A8C3A16-2A14C2A13-A18CA11-AC18-CA9-AC20-CA7-AC22-CA5-AC24-CA4-AC24-CA3-AC26-C2(A2-A28-)A-AC28-C2(2A7-D14-D7-)3(2A7-E14-E7-)2A7-D14-D7-2AC28-CA-2(A28-A2-)AC26-CA3-A26-A4-AC24-CA5-AC22-CA7-AC20-CA9-AC18-CA11-A18CA13-2A14C2A16-3A8C3A21-8A24-2(2BF)2B21-3B8A3B16-B16AB13-B18AB11-B20AB9-B22AB7-B24AB5-B26AB4-B26AB3-2(B28AB2-)B28AB-2(B30A2B30ABF30AF)B30A2B30AB-2(B28AB2-)B28AB3-B26AB4-B26AB5-B24AB7-B22AB9-B20AB11-B18AB13-2B14A2B16-3B8A3B21-2(2BF)2B56-8A20-16A15-F16AF13-B18AB11-B20AB9-F22AF7-B24AB5-F26AF4-28A3-2(B28AB2-)8(30A2-)B28AB2-B28AB3-28A4-F26AF5-B24AB7-B22AB9-F20AF11-B18AB13-B16AB15-F13AF21-8A121-6A21-16A15-18A13-20A11-22A9-24A7-26A5-13(28A4-)28A5-26A7-24A9-22A11-20A13-18A15-16A21-6A77-
