model
size = 20 25 14, scale = 0.05, origin = -y
material 
  colors = A:#FFF B:#111 C:#A00 D:#444 E:#777 F:#800 G:#888
voxels
68-4B15-2A2B2A13-2AB2GB2A12-AB4GBA11-10A10-10A13-4A17-3(2A18-)2A16-2C2A2C14-C4AC15-4A174-8A12-A6-A11-2A6-2A9-2(2A8-)A10-A7-2A10-2A6-A12-A5-A14-A3-2A14-2A2-A16-A-2A8(16-4A)16-6A12-29A3-4A3-5A-4A10-4A3-3A10-3A4-3A10-3A8-8E12-8E11-3E4-3E9-4E4-4E8-3E6-3E7-3E8-3E6-3E8-3E5-A2E10-2EA3-2AE12-E2A2-A2E12-2EA-2A7(E14-E4A)2E12-2E4A2E12-2E6A12E5A3C12A3C2A3CA3-4A3-A3CA-A2CA10-A2CA3-ACA10-ACA4-3A10-3A8-8D12-D6AD11-10D9-5D2-5D8-5D2-5D7-A4D4-4DA6-A3D6-3DA5-2A3D6-3D2A3-3A2D8-2D3A2-3AD10-D3A-3A2D10-2D5(6AD12-D)2(6A2D10-2D)6A14D24A3-12A3-2A3-A3-4A2(3-A)-A2-A10-A2-A3-A-A10-A-A4-3A10-3A8-8A12-8A11-10A9-4A4B4A8-4A4B4A7-5A4B5A6-3A8B3A5-4A8B4A3-5A8B5A2-4A10B4A-5A10B9A12B8A12B4AC3A12B3AC4A12B8A12B9A10B10A10B25A-18A6-10A13-4A74-8A12-8A11-10A9-12A8-12A7-14A6-14A5-16A3-18A2-18A-40AC18A2C18AC100A-18A6-10A13-4A74-8A12-8A11-10A9-12A8-12A7-14A6-C12AC5-16A3-18A2-18A-20AC2(18A2C)18AC100A-18A6-10A13-4A74-8A12-8A11-10A9-12A8-C10AC7-C12AC6-C12AC5-16A3-18A2-18A-20AC2(18A2C)18AC100A2-16A7-10A13-4A75-6A13-8A11-10A9-12A8-C10AC7-C12AC6-C12AC5-16A3-18A2-18A-40AC18A2C18AC80A-18A4-2C10A2C8-3C4A3C13-4A75-6A13-8A11-10A9-12A8-C10AC7-C12AC6-C12AC5-16A3-4(18A2-)C16AC5(2-18A)3-2AC10AC2A7-2C6A2C13-4A95-6A13-8A11-10A9-12A8-C10AC7-C12AC6-C12AC5-3(16A4-)A6B2A6BA4-2(2A5B)2A4-C2AB8AB2AC4(4-16A)5-14A8-2C6A2C13-4A115-6A13-8A11-B8AB9-B10AB8-12A7-2(C12AC6-)14A5-16A4-A6F2A6FA4-C6-2F6-C4-CF4-F2AF4-FC4-CAF-3F2A3F-FAC4-3AF8AF3A4-16A5-14A7-12A9-2C6A2C13-4A137-2A15-2B4A2B12-8A11-10A9-12A8-12A7-C12AC2(6-14A)8-4C2A4C14-2C12-C4-C2AC4-C6-2C-FC4ACF-2C6-A2C8A2CA7-12A8-12A10-8A12-2C4A2C174-4A14-AB4ABA11-10A10-10A9-2(12A8-)12A9-10A12-6A16-2A17-C2AC12-C-2C4A2C-C9-2C6A2C10-10A12-6A15-4A168-
