model
size = 22 28 21, scale = 0.05, origin = -y
material 
  colors = A:#E2943B B:#74673E C:#7D532C D:#AB3B3A E:#78552B F:#6A4028 G:#C7802D H:#855B32
voxels
141-4A15-10A12-10A11-12A10-12A8-16A6-16A8-12A11-10A14-6A17-4A18-4E368-8A12-2A8B2A10-12B9-A12BA7-2(16A6-)16A7-14A9-12A10-12A12-8A14-3G2A3G16-4E19-2D20-2D300-A12-A6-F2A12-2AF5-2(2A12-2A6-)2A12B2A6-4A8B4A5-5A8B5A6-3A8B3A9-12A10-12A11-10A12-G8AG15-E2AE19-2(2D20-)2D298-F2A12-2AF5-2(2A12-2A6-)2A2B8-2B2A6-2A2B8-2B2A5-3A2B8-2B3A6-3A8B3A2(8-14A)10-10A12-G8AG15-H2AH18-E2DE19-2D20-2D297-FA16-AF3-2A14-2A5-2(2A12-2A6-)2A2B8-2B2A5-3A2B8-2B3A4-3A12B3A6-A12BA8-A12BA9-12A10-G10AG13-6A17-E2DE19-2(2D20-)2D275-FA16-AF3-2(A16-A4-)A16-A5-B14-B5-2(3AB10-B3A4-)3A12B3A5-2A12B2A8-12A10-G10AG12-8A15-2A2D2A17-E2DE19-2(2D20-)2D253-FA16-AF2-FA16-AF3-A16-A4-A16-A5-B14-B5-2(2A2B10-2B2A4-)2A14B2A5-A14BA7-14A8-2G10A2G10-10A13-3A2D3A16-E2DE19-3(2D20-)2D253-FA16-AF3-2(A16-A4-)AB14-BA2(4-2A2B10-2B2A)4-2A14B2A5-A14BA7-14A8-G12AG10-10A12-4A2D4A14-2A2D2A17-E2DE19-3(2D20-)2D231-FA16-AF3-2(A16-A4-)AB14-BA4-A16-A4-2A2B10-2B2A4-2A14B2A5-A14BA7-14A8-G12AG9-12A11-4A2D4A14-2A2D2A17-H2DH18-E2DE19-2(2D20-)2D231-FA16-AF2-FA16-AF3-A16-A4-AB14-B2(A4-A16-)A4-2A14B2A5-A14BA7-14A8-14A9-12A11-4A2D4A13-3A2D3A16-H2DH18-E2DE19-2(2D20-)2D231-FA16-AF2-FA16-AF3-A16-A4-AB14-B2(A4-A16-)A4-A3-10B3-A5-A14BA6-C14AC7-14A9-12A11-4A2D4A13-3A2D3A16-H2DH18-E2DE19-3(2D20-)2D231-FA16-AF3-A16-A4-AB14-B2(A4-A16-)A4-A3-10B3-A4-2A14B2A5-C14AC7-14A9-12A11-4A2D4A14-2A2D2A17-H2DH18-E2DE19-3(2D20-)2D231-CA16-AC3-A16-A4-AB14-B2(A4-A16-)A4-A3-10B3-A4-2A14B2A5-C14AC7-14A10-10A13-3A2D3A15-2A2D2A17-E2DE18-E2DE19-3(2D20-)2D165-3(CB16-BC2-)CB16-BC3-A16-A4-AB14-B2(A4-A16-)A4-A3-10B3-A4-2A14B2A5-C14AC7-14A11-8A15-2A2D2A17-3(E2DE18-)E2DE19-3(2D20-)2D76-CA18-A2CA18-AC-C18-C3(2-A18-A)2-C18-C3-A16-A4-CB14-B2(C4-C16-)C4-A3-10B3-A4-2A14B2A5-C14AC7-14A8-A3-6A3-A13-A2EA4(18-4E)19-3(2D20-)2D76-CA18-AC2A18-2A-4(A18-A2-)C18-C3-A16-A4-C16-C48-C3-10B3-C4-2A14B2A5-C14AC7-14A8-2A3-4A3-2A8-2A10-2A124-2(2D20-)2D76-CA18-AC2A18-2A-4(A18-A2-)C18-C3-A16-A4-C16-C48-C3-10B3-C4-2A14B2A5-16A6-C14AC7-2(2A4-)2A9-A10-A147-2D20-2D55-C18-C-CA18-AC2A18-2A-4(A18-A2-)C18-C3-A16-A4-C16-C52-10A8-C16AC5-16A6-C14AC7-C3A2-2A2-3AC10-2A6-2A227-C18-C-CA18-AC2A18-2A-4(A18-A2-)C18-C3-A16-A4-C16-C52-10A9-3C10A3C6-16A7-14A9-C10AC13-6A208-CA14-AC3-C3A12-3AC-C4A12-4AC6A10-6A-6A8-6A3(2-7A6-7A)2-C6A6-6AC3-4A2C6-2C4A4-4C10-4C52-2C6A2C3(12-10A)12-3C4A3C15-C2AC18-C2AC166-2(C14-C6-)2(AC12-CA6-)2AC10-C2A6-3AC8-C3A5-5AC2-2C2-C5A4-AE3AC2-2C2-C3AEA4-2AE2AC-4C-C2AE2A4-5AC2-2C2-C5A5-3A2(2C2-)2C3A13-2C20-2C19-C2AC17-C4AC18-6(2C20-)2C142-
