model
size = 16 30 16, scale = 0.05, origin = -y
material 
  colors = A:#603
voxels
112-55A3-11A7-8A8-8A9-3(6A10-)7A9-7A8-10A5-69A192-54A5-10A7-8A9-3(6A10-)7A9-7A8-9A6-12A3-70A208-54A4-11A7-8A8-8A4(9-7A)8-9A6-85A-14A179-12A2-55A3-11A6-9A8-8A3(9-7A)8-9A7-10A5-85A-14A3-12A149-10A5-12A2-22A5-12A3-12A5-10A7-8A9-3A2-2A9-2(A15-)A5-A9-A4-2A8-3A-5A6-12A2-71A-14A3-12A5-10A119-8A7-10A5-12A2-21A7-9A6-11A5-5A-3A8-4A3-A9-A69-A8-A5-3A7-2A2-7A3-70A-14A3-12A5-10A7-8A89-6A9-8A7-10A5-12A2-20A9-7A8-9A6-5A3-2A7-2A101-2A6-2A5-5A3-5A-64A-14A3-12A5-10A7-8A9-6A59-4A11-6A9-8A7-10A5-12A2-20A9-7A9-3A-4A7-3A4-2A7-A103-A6-2A6-11A2-64A-14A3-12A5-10A7-8A9-6A11-4A29-2A13-4A11-6A9-8A7-10A5-12A2-19A10-7A9-3A2-2A8-3A2(5-2A)103-2A4-2A7-11A2-64A-14A3-12A5-10A7-8A9-6A11-4A13-2A14-2A13-4A11-6A9-8A7-10A5-12A2-19A10-7A9-3A2-3A7-3A4-3A5-2A103-A6-2A6-4A3-4A2-64A-14A3-12A5-10A7-8A9-6A11-4A13-2A14-2A13-4A11-6A9-8A7-10A5-12A2-20A9-7A8-9A7-4A3-2A6-2A103-A7-A5-4A5-3A2-64A-14A3-12A5-10A7-8A9-6A11-4A13-2A29-4A11-6A9-8A7-10A5-12A2-20A8-9A7-10A5-5A2-3A7-2A5-A8-A86-A8-2A2-6A5-69A-14A3-12A5-10A7-8A9-6A11-4A59-6A9-8A7-10A5-12A2-21A6-11A5-12A3-11A6-5A2-2A8-2A5-A63-A9-A3-4A7-10A5-69A-14A3-12A5-10A7-8A9-6A89-8A7-10A5-12A2-23A2-44A6-9A8-8A9-3A2-2A9-2A3-2A9-2A2-3A9-2A-4A8-9A7-10A4-70A-14A3-12A5-10A7-8A119-10A5-12A2-70A5-10A7-8A8-8A3(9-7A)8-9A6-12A3-70A-14A3-12A5-10A163-55A2-12A6-9A8-8A9-2(6A10-)2(7A9-)8A7-10A5-69A-14A97-
