model
size = 13 25 18, scale = 0.05, origin = -y
material 
  colors = A:#111 B:#FF0
voxels
142-4(A12-)A337-6(A12-)2(A90-4(A12-))5(A12-)A51-5(A12-)A90-4(A12-)A10-A-A2(10-3A)2(11-2A)51-5(A12-)A77-4(A12-)A23-2(3A10-)3A2(11-2A)11-A26-7(A12-)A64-3(A12-)A30-A5-2A5-2(A5-3A-A2-)A6-2A-A9-2A11-A26-7(A12-)A64-3(A12-)A27-2A-A2-B-3A2-5A2(-B-10A)5-4A9-2A11-A26-2(A12-)A25-3(A12-)A64-2(A12-)A33-B6-2A-A2-6A-32AB3-4A9-A12-A26-2(A12-)A38-2(A12-)A64-2(A12-)A33-B6-2A-A2-6A-26A2(-2A)B3-3A10-A39-2(A12-)A38-2(A12-)A64-2(A12-)A33-B7-A-A2-2A2(3-A2-7A)2(3-A)-2AB4-A38-3(A12-)A38-2(A12-)A64-2(A12-)A43-2(A2-B9-)A2-B56-3(A12-)A38-2(A12-)A64-2(A12-)A129-3(A12-)A38-2(A12-)A51-2(3(A12-)A129-2(A12-)A51-3(A12-)A38-)3(A12-)A129-2(A12-)A51-8(A12-)A142-2(A12-)A64-7(A12-)A233-6(A12-)A143-
