model
size = 32 17 12, scale = 0.05, origin = -y
material 
  colors = A:#930 B:#609 C:#F00 D:#EEE E:#60F F:#111
voxels
146-2A30-4CA475-2B30-3B2A508-A31-5A27-B5A26-2B4A440-2A6C22-6A5C20-4B4A5C19-5B4A4C19-A2E3B5AC22-2E3B4A25-4B2A315-6C19-2B5A9C15-5B2A6-4C15-2A3B9-3C14-2A3B10-4C13-7B8-C2DC14-2B3A3B4-ACD2F17-4A5B3ADF21-2A4B3A26-4B223-3C22-3A10C16-3B5A4-6C12-3B14-2C2A9-4A15-2C2A9-C3A15-2C2A9-C2AB16-C2A9-2A4B12-2CDBA10-4B3AB7-2ACFDB13-6A3B2-2B2A2DC16-2C3A6B3AC20-C2A5B2A153-4C23-4A9C16-4B6A2C-5C13-6B11-3C4-3B4-4A16-2C2-4B2A-3A18-3C-3B4AC20-A2C-2B4A2C21-AC3B3A2C2A19-2A-B5AC2A3B16-C2A-4A2-C2A2EB2A13-2CA8-2A2B3AC3A8-3AC10-2B3A4C3A3BA3B2A13-A7C3A6B16-8C3A3B21-7C2AB25-5C30-4C23-7A6C16-6B5A7C13-6B11-3C4-B2E4-4A15-3C2-3B2EB-2AC18-3C-5B3AC19-3C-4B3AC20-3C5B2AC3A17-DAC-4B3AC2A2B16-CAC-3BA2-C2A3B3A11-2ACA8-2A3B6A2B5-2B3A10-2B3A3C2(3A3B)A13-A7C2A3B2A2B16-8C3A2BA21-6C3AB25-5C90-5B4A4C16-9B2A-A4C13-4A13-3C11-A3C14-3C10-A3C15-ACA10-AC3A13-2D2A10-C3A3B10-D2FDA12-7B7-3BFDA13-2E6B2AC2A3B2A17-2A2E2B5A2B23-3B4A221-2AC20-5A5B2A3C16-7A5-2A2C15-6C8-2AC15-5C9-B2A15-6A7-2B2D16-3B3A3C3ABD2F18-3B3A2C3ADF21-2B3A2C2A-2D310-3A4B23-C6A3B21-C9A2B20-11A21-AB5E4A22-7B2A378-A31-C4A30-2A360-
