model
size = 31 32 17, scale = 0.05, origin = -y
material 
  colors = A:#FFF B:#F8F8F8 C:#C1C1C1 D:#070707 E:#060606 F:#3CF G:#7EBDFD H:#FF0 I:#FF9 J:#111 K:#001 L:#FF53A9 M:#555 N:#AAA O:#FF74CC P:#F69DFF Q:#100 R:#CCC S:#999 T:#603 U:#F3F V:#777 W:#333 X:#888 Y:#666 Z:#002 Aa:#066 Ab:#033 Ac:#3C9 Ad:#020 Ae:#063 Af:#200 Ag:#936 Ah:#C39 Ai:#096 Aj:#606 Ak:#303
voxels
8-2(15D16-15A16-)AB4AB2A3B3A16-6A5B2A2B16-2A5B3AB2A2B16-4A3BA2B2A2BA16-A3B5A4B2A16-B2AB6A2B2AB16-3AB11A16-AM11EMA16-AEAVECEBWC2MADA17-EAX3(MA)VYAE18-EAXDYJVDYDVAE18-E2A2S2(NS)NBAE18-E2ARBA4B2AE18-EAW3K2Q2KDAE18-EAJAdAaAeD2TAfQAE18-EAKAb2AcDAgAhTQAE18-EAKAbAiAaJTAjTJAE17-AEAD3KZAk2ZQAEA14-3AE2A3R4CBAE3A12-3AE2(NC)RCNC3NE2AB12-3AM11EMA2B13-3B3ASQBJX3A2BA15-AB3ABWQDR2A2BA16-ABA2B3A5BAB18-2AB8A20-11D21-9A49-D15-D14-A15-A14-D15-D2(14-A15CA)14-A15CB14-B15CB14-A15CA14-A3(15CB14-B)15CB14-A15CB14-2A13C2A14-2A13CAB15-4(A13CA16-)A13CA11-B3A-A13CA-4A6-2AB2A15C5A6-2AB2A15C3A2B6-2AB2A15C5A7-4A15C2ABA8-2ABA15C3AB9-B2A15CA2B12-A15CB15-2A11C2A17-13D19-11A22-7D18-2(D17-D12-A17-A12-)2(A17-A12-)2(B17-B12-)A17-2(B12-2A15-A)B12-BA15-AB12-2A15-AB13-A15-A14-B15-A2(14-A15-B14-B15-B)15-A13-A10-A5-A13-A5-A4-B4-2A13-2A2(4-A)25-A4-BA23-AB4-3A21-2AB5-B2A19-2AB6-2B2A17-2A2B7-A2BA16-3B10-2A15-2A14-2D11-2D17-2A9-2A20-D7-D16-2(D19-D10-A19-A10-)A19-B10-B19-A10-A19-B10-B19-B10-A19-A11-2(A17-A12-)2(A17-B12-)B17-A12-B17-A13-B15-A14-B2(15-B14-A)15-B14-B15-A8-A5-A15-A5-A2-A27-B2-B27-B2-2A25-2B3-2A23-2A4-B2A21-2AB4-4A19-3AB5-4A17-3AB7-4A15-4A11-2(D15-)A13-A17-2D9-2D14-2(D19-D10-A19-A10-)A19-A10-B19-A10-A19-B10-B19-A10-A19-A2(10-2A17-2A)10-2A17-AB11-A17-B12-B17-A12-B17-B13-2(B15-B14-)2(A15-B14-)A15-A8-A5-A15-A5-2(A2-A27-)A2-B26-AB2-BA25-2B2-B2A23-A2B3-3A21-2AB4-4A19-3AB5-4A17-3AB8-A2D15-2D2(A13-)A17-D11-D14-2(D19-D10-A19-A10-)3(A19-A10-)A19-B5(10-A19-A)2(10-A19-B)11-B17-B3(12-B17-A)13-B15-A7-A6-B15-A6-BA28-ABA28-2AB28-AB-B26-AB2-BA25-BA2-B2A23-ABA3-3A21-2AB5-4A17-3AB7-2A2D15-2DAB11-2A14-A16-D12-D13-2(D19-D10-A19-A10-)A19-B3(10-A19-A)10-A19-B2(10-B19-A)3(10-A19-B)10-A19-A10-BA17-AB10-2A17-AB11-B17-A12-B17-B12-BA15-AB2(6-A)15-A6-2A3(28-3A)28-2A-A26-BA2-2A25-AB3-BA23-2A4-3A21-ABA6-AB19-2B10-DA15-AD14-2(D13-)2(D19-D10-A19-A10-)A19-A10-A19-B4(10-A19-A)10-A2(19-B10-B)2(19-A10-A)19-A10-BA2(17-2A10-2A)17-AB11-A17-A12-2A15-2A6-A5-2A15-2A5-2A28-3A28-A2B28-2AB28-B2A28-2B-A26-AB2-BA25-AB3-2A23-2A5-B2A19-3B9-DA15-AD14-2(D13-)2(D19-D10-A19-A10-)A2(19-B10-B)2(19-A10-A)19-B3(10-A19-A)2(10-B19-A)10-B19-B4(10-2A17-2A)10-3A15-3A5-A5-2A15-2A5-2A2(28-A2B)28-B2A28-2BA28-2A-A26-2A2-2A25-AB3-2A23-2A5-3A19-2BA9-DA15-AD14-2(D13-)2(D19-D10-A19-A10-)2(B19-A10-A19-B10-)A19-B10-A2(19-A10-B)3(19-B10-A)19-B2(10-2A17-2A)10-BA17-2A11-A17-B12-2A15-2A6-A5-2A15-2A5-2A2(28-2AB)28-3B28-BA-A26-2B2-2A25-AB3-2A23-2A4-3A21-3A6-BA19-AB10-DA15-AD14-2(D13-)D19-D10-A19-A10-D19-D2(10-B19-A)2(10-A19-B10-A19-A)2(10-A19-A)10-B19-A10-B2(19-B10-A)19-B10-BA17-AB10-BA17-2A11-2(B17-A12-)BA15-2A6-B6-A15-A6-AB28-3B28-B2A28-2B-A26-AB2-BA25-2A2-B2A23-2AB3-B2A21-3A5-3A19-2AB7-2ADA15-ADAB11-2(A15-)2(D13-)D19-D10-A19-A10-D19-D10-B19-B10-A19-B2(10-B19-A)10-B19-B10-B4(19-A10-A)19-B2(10-A19-A)11-B17-A12-A17-A12-B17-B12-A17-A13-B15-A8-B5-B15-A5-A3(2-A27-B)2-2A25-2A2-3A23-3A3-3A21-2AB4-4A19-4A5-4A17-2A2B8-A2D15-2D2(A13-)A17-2D9-2D14-D19-D10-A19-A10-D19-D10-B19-A10-A19-B10-B3(19-A10-A)19-A3(10-2A17-2A)11-3(A17-A12-)2A15-2A12-2A15-2A13-A15-B2(14-A15-A)8-A5-A15-A5-2(A2-A27-)A2-2A25-2A3-2A23-2A4-3A21-3A4-4A19-3AB5-4A17-3AB7-AB2A15-2A2B11-2D13-2D16-2AD7-D2A45-2(D19-D10-A19-A10-)A19-A10-B19-G10-B19-F2(10-A19-A)11-5(A17-A12-)A17-A13-4(A15-A14-)B15-A9-A4-A15-2(A4-)A25-A4-A25-B4-2A23-AB4-B2A21-A2B5-B2A19-2AB6-B3A17-3AB7-B3A15-A2BA10-2A15-2A14-2DAD7-DA2D76-2(D17-D12-A17-A12-)A17-F12-B17-G12-A17-G12-B17-A12-B17-B12-BA15-2A12-2A15-AP12-HA15-AO12-HA15-2A13-A15-A14-B15-A14-FA13-2A14-GA2(13-2A14-2A)13-AI15-B13-A11-3A2-A13-A2-B2A2(6-3A19-A2B)6-2IA19-A2B7-HI19-2A8-AH2A15-4A9-HIA15-2AB12-A15-B15-A2DAD5-DA2DA108-2D13-2D14-2A13-2A14-2D13-2D14-AB13-2A14-AB13-AF14-2A13-AF14-BA13-2A2(14-BA13-AB)14-2A13-LP14-2A13-LO14-HI13-2O14-AH13-AO14-3A11-3A14-3A11-2AB15-GA11-2A16-GA11-AB16-FA11-2A2(16-2A11-AH)14-P2BA11-3AB11-2POA13-2A2B10-APA15-3A10-3A15-2AB11-2A15-FA13-2A13-2F15-AB2(AD)3-DAD3A16-2BDAD5-DAD2A141-13D18-2A3J3D3J2A18-13D18-6AD6A18-BA3BADA4BA18-4ABADA3BAB18-AFGABAD6A18-A2GFBAD2AB3A18-2A2FBAD2AB2AL18-2B2ABAD4A2U18-A3B2ADA2B2AL18-AHI3AD6A18-HIAI2AD2ABA2B18-6ADA2B3A18-A2B3AD2AGF2A18-2A2(BA)DAF2G2A18-FA3BADA2F2AB18-F2A3BD6A18-AB4AD4AHA18-A3B2ADAB2A2I18-3A2BADA2B3A17-LP5AD2A3B2A15-2OLUL2A3D4AB2A14-ALUL2A2(DA)D3AFGA15-4ADAD-DAD2A2G17-B2(AD)3-DAD2A195-
