model
size = 28 28 32, scale = 0.05, origin = -y
material 
  colors = A:#D00 B:#EEE C:#400 D:#700 E:#609 F:#93F G:#800 H:#93C I:#90F J:#90C K:#60C
voxels
358-2(2A25-5A23-5A24-2A670-)2A25-5A2(22-5AE)23-5A24-2A641-5A2(22-5AE)22-5AK22-5AE23-5A639-5A4(22-5AE)23-5A604-2A23-6A5-2A14-8A3-5A12-8A2(2-5AE11-9A)3-5A11-9A4-2A13-8A21-7B22-5B443-7A20-9A17-12A16-12A15-13A-4A10-5A-12AC2(8-19AF)8-20A8-14A-4A9-3A8B3A15-13B15-12B17-11B18-8B22-5B277-4A21-9A18-12A15-13A14-5A5-5A12-5A7-4A12-3A10-5A9-4A-16A7-12A-7AC7-2(10A3-8AF6-)9A4-7AC7-9A-10AC7-A13B5A9-17B11-16B12-16B13-14B15-12B17-10B20-6B197-3A21-8A16-5A2-6A13-4A7-5A11-4A-2A7-3A10-11A4-3A10-13A3-2A9-21A7-22A6-7A8-7AC4-6A10-2(7AH4-5A11-)7AD4-5A12-5AC5-2A3B10-B6A7-2(5B8-6B9-)7B5-6B10-17B12-16B13-14B15-12B18-8B143-A24-5A19-5A-4A15-8A2-4A10-13A2-3A9-15A2-2A8-16A2-3A7-6A5-6A-3A6-6A8-8A6-5A12-5AC5-4A12-7AC4-4A12-7AD4-3A13-7AI4-3A13-7AD4-3A14-5AC5-A2B14-5A6-3B13-5B7-4B12-5B7-4B11-5B8-5B10-4B10-5B8-5B10-17B12-15B15-12B18-8B115-3A22-7A19-5A-4A19-5A-3A10-2A8-5A-2A7-5A9-4A-2A6-5A11-3A-3A5-4A12-7A5-4A13-6A4-2(4A13-7AC3-)3A14-7AD3-3A14-7AI3-3A14-7AD3-3A14-7AC3-A2B15-6A4-3B15-4B6-4B14-4B6-4B13-5B7-3B13-4B8-4B11-4B10-4B9-5B10-17B12-15B15-11B20-5B89-4A23-6A22-3A-3A21-4A-2A22-3A2(-2A5-4A14-2A)-2A4-4A15-5A4-4A14-6A4-3A14-7AC3-3A14-7AC2-4A13-8AD2-3A14-8AJ2-3A15-7AD2-3A15-7AC2-A2B16-6A3-3B17-4B5-3B16-4B5-3B15-5B5-3B15-3B7-4B13-4B8-4B11-4B10-5B7-5B12-15B14-13B17-9B61-3A23-5A23-6A23-2A-2A23-2A2-2A23-2A-2A4-3A16-2A-2A3-4A16-2A-2A3-3A17-5A3-3A15-7A2-4A14-7AC2-3A15-7AC2-3A14-8AD2-3A14-8AJ2-3A15-7AD2-3A15-7AC2-3A16-6A3-3A18-4A3-3A18-3A4-3A17-4A5-3A15-4A6-3A15-3A7-4A13-4A8-5A9-5A10-7A3-7A12-15A15-11A60-3B24-2B-2B24-4B24-2(2B-2B23-)2B2-B24-B2-2B2-3B18-B2-2B2-3B16-4A2B2-4B15-6AB2-3B15-7A2(C2-3B14-8A)D2-2B15-8AG2-2B15-8AD2-2B16-7AC2-2B17-6A3-2B18-4AB3-2B19-4B3-3B17-4B4-3B17-3B6-3B15-4B6-4B13-4B8-4B11-4B10-5B7-5B12-15B14-12B19-6B35-2(4B24-)2B2(-2B24-B)2-2B23-B2-2B23-2B-2B2-3B18-2B-2B2-3B16-4A3B-3B16-6A2B2(-B)15-7AC2-3B14-8AC-3B15-8AD-3B15-8AG-3B15-8AD-3B16-7AC-3B17-6A2-3B18-4AB2-3B19-4B3-2B19-4B3-3B17-4B4-3B16-4B6-3B14-4B7-4B12-4B9-5B9-4B11-16B14-13B18-7B35-3B25-2(B-2B24-)2(B2-2B23-)2B2-B23-2B2-B2-3B19-B2-B-3B17-4A3B-3B15-8AB-3B15-7ACB-3B14-8AC-3B15-8AD2(-B)15-8AG-3B15-8AD-2B17-7AC-2B17-8A-3B18-4AB2-3B20-3B3-2B19-4B3-2B18-4B4-3B17-3B6-3B15-3B7-4B13-4B8-5B9-5B10-7B2-7B14-13B17-8B35-3B25-B-2B24-B2-B24-B2-2B23-B3-B23-2B2-B24-2(B2-)2B20-B2-B-3B17-4A-2B2(-B)15-8AB-3B15-7AC4B15-8AC-3B15-8AD-3B15-8AG-3B15-8AD-2B17-7AC-2B17-8A-2B19-4AB2-3B20-3B2-3B19-4B3-2B19-3B4-3B17-3B6-3B15-3B7-4B13-4B8-5B9-5B10-6B4-7B13-13B17-8B35-3B25-B-2B24-B2-B24-2(B2-2B23-)2B2-B23-2B2-B2-2B20-B2-B-3B17-4A3B-3B15-8AB-3B15-7AC4B15-8AC-3B15-8AD-3B15-8AG-3B15-8AD-2B17-7AC-2B17-8A-2B19-4AB2-3B20-3B2-3B19-4B3-2B19-3B4-3B17-3B6-3B15-3B7-4B13-4B8-5B9-5B10-7B3-6B14-13B17-8B34-4B24-2B2(-2B24-B)2-B24-2(B2-2B23-)2B-2B2-3B18-2B-2B2-3B16-4A3B-3B15-8AB-3B15-7AC2-3B14-8AC-3B15-8AD-3B15-8AG-3B15-8AD-3B16-7AC-3B16-8A-3B18-4AB2-3B20-3B3-2B19-4B3-3B17-4B4-3B17-3B6-3B15-3B7-4B13-3B2(9-5B)10-8B-7B14-13B17-8B34-2(4B24-)2B-2B23-2B-2B2(24-B2-B)24-B2-2B2-3B18-B2-2B2-3B16-4A2B2-3B16-6AB2-3B15-7A2(C2-3B14-8A)D-3B15-8AG-3B15-8AD-3B16-7AC-3B17-6A2-3B18-4AB3-2B19-4B3-3B18-3B4-3B17-3B5-4B15-4B6-3B14-4B8-4B11-4B9-6B7-5B12-15B14-13B18-6B35-3A24-5A23-2A-2A23-6A3(23-2A-2A)3-4A16-2A2-A3-3A16-6A3-3A15-7A2-4A14-7A2(C2-3A14-8A)D2-3A14-8AG2-2A15-8AD2-2A16-7AC2-2A17-6A3-2A18-5A3-3A18-3A4-3A17-4A4-3A17-3A6-3A15-4A6-4A13-4A8-4A11-4A10-6A5-6A12-15A15-11A60-2A24-5A22-3A-2A23-3A-2A22-3A-2A23-2A-2A5-3A15-2A2-2A4-3A16-2A-2A3-4A16-5A3-3A15-6A4-3A14-7AC2-4A14-7AC2-3A14-8AD2-3A14-8AJ2-3A15-7AD2-3A15-7AC2-3A16-6A3-3B18-3B4-3B17-4B4-4B16-4B5-3B15-4B6-4B13-4B8-4B11-4B2(9-5B)10-17B13-13B17-9B87-4A21-8A20-4A-3A21-4A-2A22-3A-3A5-5A11-4A-2A5-4A13-3A-2A5-4A13-6A4-4A14-6A4-4A13-7AC3-3A14-7AC3-3A13-8AD3-3A13-8AJ3-3A14-7AD3-3A14-7AC3-3A15-6A4-3B16-4B5-3B15-5B5-3B15-4B6-4B13-4B8-3B12-5B8-5B9-5B10-6B5-6B12-15B15-12B18-7B88-2A23-6A19-5A-4A15-9A-3A10-14A2-3A7-7A4-6A-3A2(7-5A)2-2A6-5A9-8A6-5A11-7A5-4A12-2(7AC3-4A13-)7AD3-4A13-7AI3-4A13-7AD3-3A14-7AC3-4A14-6A4-4B14-4B6-4B13-5B7-3B13-5B7-4B11-5B8-5B9-5B10-6B6-5B12-15B14-13B17-10B139-4A20-9A15-6A4-4A11-10A4-3A10-12A4-3A9-13A3-3A8-16A-3A8-21A6-6A7-10A5-5A11-7AC4-4A12-7AD4-4A12-7AI4-4A12-7AD4-4A13-5AC5-4A12-6A6-4B11-5B8-5B10-5B9-5B8-6B9-6B7-5B10-17B12-15B14-13B17-10B21-3B167-7A17-12A15-14A13-5A5-5A12-4A9-3A11-2(4A10-)12A2-6A8-21A6-13A2-7AC5-10A5-7AH5-8A7-7AH5-7A8-7AD5-6A7-A-6AC6-7A5-9A7-8B3-7B10-18B11-17B11-15B14-14B15-12B17-10B22-2B249-7A19-11A16-12A15-14A14-5A4-5A-2A10-5A5-10A8-4A3-12AC7-4A2-15AF6-4A-16AF6-20AC7-20AC8-15A-2A10-15B13-14B15-13B15-12B17-10B20-6B387-6A21-8A19-10A2-4A11-11A-5AC2(10-11A-5AF)10-11A-6A10-11A2-4A11-11A17-10B19-9B21-6B537-2A25-3ACA2(22-5AE)23-5A24-2A641-4A23-3(5AE22-)5AE23-5A639-4A23-2(5AE22-)5AK22-5AE23-5A640-2A25-5A2(22-5AE)23-5A24-2A340-
