model
size = 23 32 28, scale = 0.05, origin = -y
material 
  colors = A:#303 B:#603 C:#111 D:#03F E:#222 F:#606 G:#C09 H:#00A I:#00E J:#00D K:#001 L:#03C M:#06C N:#005 O:#002 P:#00C Q:#000 R:#006 S:#008 T:#007 U:#009 V:#039 W:#00B X:#444 Y:#60C Z:#00F Aa:#036 Ab:#FC0 Ac:#DDD Ad:#306 Ae:#EEE Af:#A00
voxels
253-C2(22-E)45-3(C22-E22-)E3(22-C)68-C2(22-E)22-C275-C2(22-E)45-3(C22-E22-)E3(22-C)68-C2(22-E)22-C299-2(E22-)C22-L22-V3(22-C)22-S22-V3(22-C)22-E2(22-C)2(22-E22-C)207-2(C22-)E45-C22-H4(22-D)22-E22-H2(22-D)22-W22-R2(22-D)22-E3(22-C)22-E22-C161-C3(22-E)2(22-C)22-E22-U4(22-D)22-C22-P2(22-D)22-L22-R2(22-D)22-O3(22-C)22-E22-C115-3(C22-)2(E22-)C22-O22-H22-E22-S4(22-D)22-Aa22-P2(22-D)22-L22-R22-D22-J22-K3(22-C)22-E115-2(E2(22-C)22-)R22-S2(22-N)22-O4(22-D)2(22-L)2(22-D)22-L22-H22-V22-T22-E3(22-C)138-2(E22-)C22-N22-O22-I22-C22-J22-C22-H22-O4(22-D)22-L22-U2(22-D)8-A13-L6-3A13-C6-3AB12-C6-4F12-P6-3F13-H8-A13-E22-C138-C22-E2(22-C)2(22-J)22-C22-O22-P22-U22-H22-K5(22-D)7-B14-N7-B14-D4-4AB13-D3-3ABABG12-N3-5ABG12-S3-2B4ABG11-W2-3B4ABG11-J3-2B3A3B11-R3-4BA2B12-C4-6B12-C82-Af21-M33-E6(22-C)22-S22-C22-J2(22-C)22-J4(22-D)6-B15-C3-3BA2B13-J2-6ABG12-C-8AXQ11-UB8AXQ11-W10AQ11-PB9AQ11-H2B8AG11-C-B7A2B11-C-2B6AB15-7A18-B2A72-2M34-E22-C2(22-E)22-T2(22-H)22-C22-Z2(22-I)22-V22-C3(22-D)5-F16-D2-3BA2B14-C2B6AB13-CB8AG12-B10AQ11-B10AQ10-B11AAc10-B11AQ10-B11AG11-B10AB11-B9AB13-B7A2B14-7A18-BA26-2M22-M59-2(C22-)R22-T3-3B16-N3-3B16-C3-3B16-O3(3-3B16-I)3-3B16-D22-C22-I2(22-D)2-4B16-D2B4A3B13-B8AF12-B10AG10-B11AG10-3(B12AG9-)B12AB9-B11AB10-B11AB11-B9AB13-B7AB15-4BA2BM111-B18-K2-3B17-T2(-5B16-J)-5B16-I-5B16-P-5B16-C2(-5B16-I)-5B2Y14-D-5B16-T2-3B17-S3-B18-D22-7F2B13-B7A2-B11-B10AAe10-B11AF10-B12A4(B8-B13A)2(B9-B12A)B10-B10AB11-2B8AB14-8A88-B21-3B19-5B18-5B17-7(7B16-)P5B17-I5B17-C-3B18-H2-B18-6A3B12-2B8A-F10-2B10A11-B11AF9-B13AB8-B13AAb8-3(B14AB7-)B13AB8-AB12AB9-13A11-B9A2B12-9B87-3B19-2(5B18-)5B17-7(7B16-)3(K5B17-)K-3B17-6A3B12-2B8A-F10-B11A11-B11AF9-B13AB8-2(B14AAd7-)2(B14AB7-)B13AB8-15A9-B13A10-B11A12-10B87-B21-3B19-5B18-5B17-7(7B16-)2(K5B17-)K-3B18-K2-B18-6A3B12-B9A-F10-B11A11-B11AF9-B13AB8-B13AAb8-3(B14AB7-)B13AB8-14AB9-B12A11-B9A2B12-9B111-B21-3B19-5B18-5B17-K3(5B17-N)5B17-C5B17-K5B2Y15-P5B17-I-3B18-C2-B19-H21-7F2B13-B7A2-B11-B10AAe10-B11AF10-B12A4(B8-B13A)2(B9-B12A)B10-B10AB11-2B8AB14-8A130-K22-T22-2(J2-3B17-)I2-3B17-P2-3B17-C2(2-3B17-I)2-3B17-D22-T22-S2(22-D)-4B17-2B4A3B13-B8AF12-B10AG10-B11AG10-3(B12AG9-)B12AB9-B11AB10-B11AB11-B9AB13-B7AB15-4BAB2M22-M60-3(C22-)R22-T22-N22-C22-O3(22-I)22-D22-C22-I2(22-D)4-F17-D-3BA2B15-2B6AF14-B8AG12-B10AQ11-B10AQ10-B11AAc10-B11AQ10-B11AG11-B10AB11-B9AB13-B7A2B14-7A18-BA49-2M22-M12-E22-C2(22-E)22-T2(22-H)22-C22-Z2(22-I)22-V22-C4(22-D)5-B16-C2-3BA2B14-C-6ABG13-W8AXQ12-B8AXQ12-10AQ12-B9AQ12-2B8AG13-B7A2B13-2B6AB15-7A18-B2A95-2M10-E6(22-C)22-S22-C22-J2(22-C)22-J4(22-D)6-B15-C6-B15-J3-2A-AB14-C2-3ABABG13-U2-5ABG13-W2-2B4ABG12-P-3B4ABG12-H2-2B3A3B12-C2-4BA2B13-C3-6B118-Af21-M9-C22-E2(22-C)2(22-J)22-C22-O22-P22-U22-H22-K5(22-D)22-N2(22-D)7-A14-N5-3A14-S5-3AB13-W5-4F13-J5-3F14-R7-A14-C22-C159-2(E22-)C22-N22-O22-I22-C22-J22-C22-H22-O4(22-D)22-L22-U2(22-D)22-L2(22-C)22-P22-H22-E22-C159-2(E2(22-C)22-)R22-S2(22-N)22-O4(22-D)2(22-L)2(22-D)22-L22-H22-V22-T22-E3(22-C)159-3(C22-)2(E22-)C22-O22-H22-E22-S4(22-D)22-Aa22-P2(22-D)22-L22-R22-D22-J22-K3(22-C)22-E182-C3(22-E)2(22-C)22-E22-U4(22-D)22-C22-P2(22-D)22-L22-R2(22-D)22-O3(22-C)22-E22-C205-2(C22-)E45-C22-H4(22-D)22-E22-H2(22-D)22-W22-R2(22-D)22-E3(22-C)22-E22-C297-2(E22-)C22-L22-V3(22-C)22-S22-V3(22-C)22-E2(22-C)2(22-E22-C)67-
