model
size = 14 12 6, scale = 0.05, origin = -y
material 
  colors = A:#111 B:#222 C:#444 D:#E00 E:#EEE F:#007 G:#AAA
voxels
29-2A2-4A2-2A-3A-2A2D2A-6A-A4DA-3A-2A2-A2DA2-2A7-2A91-2A2-4B2-2A-3A-B4-B-6A-B4-B-3A-2A-B4-B-2A5-2B2-2B8-2B2-2B7-2B4-2B5-2(B8-B4-)B8-B5-8B4-2A8-2A-ACA2-4A2-AC2(2A2CDA4-AD2C)2A2CD2A2-AFD2CA-2A-B4AB-2A5-BA2BAB7-DA4-AD5-2(D8-D4-)D8-D5-8D3-3A8-4ACA2-4A2-ACAD2CD6AD2C2D2CGB5A3CDA2CD2F3AFD2C4A-B4AB-3A4-B4AB7-DA4EAD5-2(D8ED4-)D8ED5-8D3-3A8-4ACA2-4A2-ACAD2CDAB2C2AD2C2D2CD4C2BD2CDACA-A4CA-AC2(4A2-)3A5-B2AB8-2B4E2B5-2(B8EB4-)B8EB5-8B4-2A8-2A-3A2-4A2-AC4A-A3C2A2(-AC4A-A3CBA)-ACA-2A2-4A2-2A7-2B76-
