model
size = 14 12 6, scale = 0.05, origin = -y
material 
  colors = A:#111 B:#222 C:#444 D:#EEE E:#3F6 F:#AAA G:#007
voxels
29-2A2-4A2-2A-3A-2A2E2A-6A-A4EA-3A-2A2-A2EA2-2A7-2A91-2A2-4B2-2A-3A-B4-B-6A-B4-B-3A-2A-B4-B-2A5-2B2-2B8-2B2-2B7-2B4-2B5-2(B8-B4-)B8-B5-8B4-2A8-2A-ACA2-4A2-AC2(2A2CFA4-AF2C)2A2CF2A2-AGF2CA-2A-B4AB-2A5-BA2BAB7-2A4-2A5-2(A8-A4-)A8-A5-8A3-3A8-4ACA2-4A2-ACAE2CF6AF2C2E2CFB5A3CEA2CF2G3AGF2C4A-B4AB-3A4-B4AB7-2A4D2A5-2(A8DA4-)A8DA5-8A3-3A8-4ACA2-4A2-ACAE2CFAB2C2AF2C2E2CF4C2BF2CEACA-A4CA-AC2(4A2-)3A5-B2AB8-2B4D2B5-2(B8DB4-)B8DB5-8B4-2A8-2A-3A2-4A2-AC4A-A3C2A2(-AC4A-A3CBA)-ACA-2A2-4A2-2A7-2B76-
