model
size = 24 30 16, scale = 0.05, origin = -y
material 
  colors = A:#080 B:#111 C:#555 D:#050 E:#800 F:#DDD G:#00E H:#EEE I:#777 J:#444 K:#AAA
voxels
151-4B2-4B13-2(2B3-)2B11-2B10-2B9-2B2-8E2-2B7-2B4-EK2EKE4-2B6-B16-B14-2B21-B2AB20-4A21-2A22-2A17-2F3-2A3-2F11-F2GF6-F2GF10-H2GH6-H2GH11-2H8-2H14-2B4-2B13-3B8-3B32-2B14-2B7-B14-B8-3(B-)B2-3(B-)B8-16B9-14B11-12B202-16B7-14(18B6-)18B7-2(16B8-)16B9-14B226-14B9-2B12A2B7-2B14A2B10(6-B16AB)6-B2(4A2B)4AB6-5B8A5B2(6-2B14A2B)7-2(B14AB8-)2B12A2B9-B12AB11-12B157-10B13-12B11-2B10A2B9-2B12A2B7-2B14A2B10(6-B16AB)6-B2(4A2B)4AB6-5B8A5B2(6-2B14A2B)7-2(B14AB8-)2B12A2B9-B12AB11-B10AB12-12B133-3(4B2A4B13-2(2B3A)2B11-2B10A2B9-2B12A2B7-2B14A2B10(6-B16AB)6-B2(4A2B)4AB6-5B8A5B2(6-2B14A2B)7-2(B14AB8-)2B12A2B9-B12AB11-B10AB12-12B13-5(10A14-))4B2A4B13-2(2B3A)2B11-2B10A2B9-2B12A2B7-2B14A2B5(6-B16AB)5-4(D18AD4-)D18AD5-B2(4A2B)4AB6-5B8A5B2(6-2B14A2B)7-2(B14AB8-)2B12A2B9-B12AB11-B10AB12-12B13-5(10A14-)4B2A4B13-2(2B3A)2B11-2B10A2B9-2B12A2B7-2B14A2B5(6-B16AB)5-D18AD4(4-20A)4-DB2(4A2B)4ABD5-5B8A5B6-2B14A2B3-C2-2B14A2B2-2(2C3-B14AB3-)2C3-2B12A2B3-C5-B12AB11-B10AB12-12B13-5(10A14-)4B2A4B13-2(2B3A)2B11-2B10A2B9-2B12A2B7-2B14A2B4(6-B16AB)5-2(D18AD2(4-20A)4-)DB2(4A2B)4ABD5-5B8A5B6-2B14A2B3-C2-2B14A2B2-5CB14AB3CJ4CB14AB3CJC3-2B12A2B3-C5-B12AB11-B10AB12-12B13-5(10A14-)4B2A4B13-2(2B3A)2B11-2B10A2B9-2B12A2B7-2B14A2B3(6-B16AB)5-2(D18AD2(4-20A)4-)20A4-DB2(4A2B)4ABD5-5B8A5B6-2B14A2B3-C2-2B14A2B2-CJ3CB14AB3C2J3CB14AB3CJC3-2B12A2B3-C5-B12AB11-B10AB12-12B13-5(10A14-)4B2A4B13-2(2B3A)2B11-2B10A2B9-2B12A2B7-2B14A2B3(6-B16AB)5-2(D18AD4-20A4-)2(20A4-)D18AD4-DB2(4A2B)4ABD5-5B8A5B6-2B14A2B3-C2-2B14A2B2-2(2C3-B14AB3-)2C3-2B12A2B3-C5-B12AB11-B10AB12-12B13-5(10A14-)4B2A4B13-2(2B3A)2B11-2B10A2B9-2B12A2B7-2B14A2B3(6-B16AB)2(6-18A)5-4(20A4-)D18AD5-2(B2(4A2B)4AB6-5B8A5B2(6-2B14A2B)7-2(B14AB8-)2B12A2B9-B12AB11-B10AB12-12B133-10B13-2(2B3A)2B11-2B10A2B9-2B12A2B7-2B14A2B3(6-B16AB)7(6-18A)6-)5A2B4A2B5A6-5B8A5B2(6-2B14A2B)7-2(B14AB8-)2B12A2B9-B12AB11-B10AB12-12B133-10B13-2BD2A2B2AD2B11-2BD8AD2B9-2BD10AD2B7-2BD12AD2B6-BD14ADB6-B16AB8(6-18A)6-5A2B4A2B5A6-D4B8A4BD6-2B14A2B6-2B3(AI)2A3(IA)2B7-2(B14AB8-)2B12A2B9-B12AB11-B10AB12-12B6-
