model
size = 3 24 8, scale = 0.05, origin = -y
material 
  colors = A:#331919 B:#BBB
voxels
10-3(B2-)A2-A106-2A-6A6-3(B2-)2(A2-)A3-A14-2(A2-)A10-18A21-11(2A-)21A3(B2-)2(A2-)A3-A10(-2A)-21A18-2A10-4(2A-)2A7-18A3-3(B2-)3(A2-)2A16-2(2A-)2A13-9A24-2A52-
