model
size = 21 25 20, scale = 0.05, origin = -y
material 
  colors = A:#331919 B:#111
voxels
29-7A13-7A645-5A15-3BA3B12-3(2AB)2A11-AB5AB3A9-2A3BA3B2A9-3AB5AB3A7-4A3BA3B2A10-2AB5AB4A7-3A7B3A4-19A3-19A-5A11B3A3-9AB9A-10AB8A2-10AB7A3-10AB8A3-9AB9A9-7A13-7A139-9A13-9A2(9-13A)7-13A7-15A5-15A8-15A5-15A2(3-19A)-19A3-19A-19A2-18A2(3-19A)7-11A9-11A14-5A36-5A17-5A15-5A17-5A11-13A9-13A6-15A7-2(15A5-)17A3-17A6-17A3-17A2-20A2(-41A)-19A2-20A-21A5-13A7-13A11-9A13-5A14-9A13-9A11-9A13-9A2(9-13A)2(5-17A)3-17A4-17A3-17A6-17A3-17A2-20A2(-41A)-19A2-20A-21A4-15A5-15A8-13A9-9A2(11-11A)9-11A11-11A2(7-15A)4-17A5-2(17A3-)19A-19A4-2(19A-)125A-42A2(3-17A)7-13A8-11A2(9-13A)7-13A9-13A6-15A7-15A2(3-19A)-19A2-19A-19A4-2(19A-)125A-42A2(3-17A)6-15A6-13A8-13A9-13A7-13A9-13A2(5-17A)2-19A3-19A-19A2-19A-19A4-2(19A-)125A-42A2-19A-19A5-15A6-13A2(7-15A)5-15A7-15A4-17A5-17A2-19A3-19A-19A2-3(9A-)9A4-5(9A-)2(21A-19A-)19A-11A-9A-32A2-19A-19A4-17A4-15A6-15A7-15A5-15A7-15A4-8A-8A5-8A-8A2-9A-9A3-3(9A-)9A2-19A-19A4-2(19A-)125A-42A2-19A-19A4-17A4-15A6-7A-7A7-7A-7A5-7A-7A7-7A-7A4-17A5-17A2-19A3-19A-19A2-19A-19A4-2(19A-)125A2-41A2-3(9A-)9A4-8A-8A4-7A-7A6-15A7-15A5-15A7-15A4-17A5-17A2-19A3-19A-19A2-19A-19A4-2(19A-)125A2-41A2-19A-19A4-17A4-15A6-2(15A7-15A5-)15A7-15A2(3-19A)-19A2(3-17A)6-17A3-17A2-20A2(-41A)-19A2-20A-21A2-19A-19A4-17A4-15A2(7-13A9-13A)6-15A7-15A4-17A5-17A3-17A4-17A3-17A6-17A3-17A2-20A2(-41A)-19A2-20A-21A2-19A-19A5-15A6-13A8-2(13A9-13A7-)13A9-13A2(5-17A)3-17A2(5-15A)8-15A5-15A2(3-19A)-19A3-19A-19A2-18A2(3-19A)4-17A3-17A6-15A6-13A2(9-11A11-11A)8-13A9-13A6-15A7-15A5-15A2(7-13A)10-13A7-13A4-2(19A3-19A-)19A2-18A2(3-19A)4-17A3-17A7-13A8-11A3(11-9A13-9A)2(9-13A)7-13A2(9-11A)12-11A9-11A6-2(17A5-17A3-)17A3-2(17A5-)17A6-15A5-15A8-13A9-9A14-2(5A17-5A15-)5A17-5A12-11A11-11A9-11A12-7A13-7A16-7A13-7A9-2(15A7-15A5-)15A5-2(15A7-)15A8-13A7-13A11-9A13-5A141-7A15-7A13-7A95-2(11A11-11A9-)11A9-3(11A11-)11A9-11A14-5A307-2(7A15-7A13-)7A13-2(7A15-)7A7-
