model
size = 21, scale = 0.05, origin = -y
material 
  colors = A:#C25100 B:#0029A6 C:#DF0000 D:#EFEFEF E:#000 F:#101010
voxels
156-CDB17-2CD2B15-2(3CD3B14-)3CD3B15-2CD2B17-CDB269-2CD2B15-3CD3B13-3C2A-3B11-3C3A-F3B3(10-2C4A3-2B)10-3C3A2-3B11-3C2A-3B13-3CD3B15-2CD2B204-3CD3B13-2C5A2B11-2C5-2A2B9-2C6-3A5(2B8-C10-)2B8-2C8-3B9-2C7-2B11-2C5-2B13-3CD3B161-3CD3B12-2C7A2B8-D2C9A2BD6-DC7-4ABD6-D8-5A6(D6-D12-A)D6-DC11-BD6-D2C9-2BD8-2C7A2B12-3CD3B119-3CD3B11-D2C7A2BD8-D11AD7-B13AC6-B8-5AC5-BA8-6A6(C4-BA12-2A)C5-B12-AC6-B12-AC7-D11AD8-D2C7A2BD11-3CD3B78-2CD2B13-D2C5A2BD9-B11AC7-B13AC6-B13AC5-BA8-6AC4-BA8-6AC3-4(B2A12-3AC2-)B2A12-3AC3-BA12-2AC4-BA12-2AC5-B12-AC6-B13AC7-BE10AC9-D2C5A2BD13-2CD2B57-3CD3B12-BD7ADC9-B11AC7-B13AC5-B15AC4-BA8-6AC3-B2A8-7A6(C2-B2A12-3A)C3-BA12-2AC4-BA12-2AC5-B13AC7-B11AC9-BDE5AEDC12-7D37-CDB15-D2C3A2BD10-2B9A2C7-B13AC5-B15AC4-B15AC3-2(B2A8-7AC2-)B2A12-3AC-3(B3A12-4AC)-2(B2A12-3AC2-)B2A12-3AC3-BA12-2AC4-B15AC5-B13AC7-2B9A2C10-3B3A3C15-BDC17-2CD2B13-BDC5ABDC9-B11AC7-B13AC5-B15AC3-B17A2(C2-B2A8-7A)C-5(B3A12-4AC)-2(B2A12-3AC2-)B2A12-3AC3-B15AC5-B13AC7-B11AC9-3B5A3C13-2BD2C15-3CD3B12-BD7ADC9-B11AC7-B13AC5-B15AC3-B17AC2-B2A8-7AC-B3A8-8A6(CB3A12-4A)C-B2A12-3AC2-B2A12-3AC3-B15AC5-B13AC7-B11AC9-2B7A2C12-3BD3C14-7D12-2D7A2D9-D11AD7-D13AD5-D15AD3-D17AD2-D2A8-7AD-D3A8-8A6(2D3A12-4A)D-D2A12-3AD2-D2A12-3AD3-D15AD5-D13AD7-D11AD9-2D7A2D12-7D14-3BD3C12-CD7ADB9-C11AB7-C13AB5-C15AB3-C17AB2-C2A8-7AB-C3A8-8A6(BC3A12-4A)B-C2A12-3AB2-C2A12-3AB3-C15AB5-C13AB7-C11AB9-2C7A2B12-3CD3B15-2BD2C13-CDB5ACDB9-C11AB7-C13AB5-C15AB3-C17A2(B2-C2A8-7A)B-5(C3A12-4AB)-2(C2A12-3AB2-)C2A12-3AB3-C15AB5-C13AB7-C11AB9-3C5A3B13-2CD2B17-BDC15-D2B3A2CD10-2C9A2B7-C13AB5-C15AB4-C15AB3-2(C2A8-7AB2-)C2A12-3AB-3(C3A12-4AB)-2(C2A12-3AB2-)C2A12-3AB3-CA12-2AB4-C15AB5-C13AB7-2C9A2B10-3C3A3B15-CDB37-3BD3C12-CD7ADB9-C11AB7-C13AB5-C15AB4-CA8-6AB3-C2A8-7A6(B2-C2A12-3A)B3-CA12-2AB4-CA12-2AB5-C13AB7-C11AB9-CDE5AEDB12-7D57-2BD2C13-D2B5A2CD9-C11AB7-C13AB6-C13AB5-CA8-6AB4-CA8-6AB3-4(C2A12-3AB2-)C2A12-3AB3-CA12-2AB4-CA12-2AB5-C12-AB6-C13AB7-CE10AB9-D2B5A2CD13-2BD2C78-3BD3C11-D2B7A2CD8-D11AD7-C13AB6-C8-5AB5-CA8-6A6(B4-CA12-2A)B5-C12-AB6-C12-AB7-D11AD8-D2B7A2CD11-3BD3C119-3BD3C12-2B7A2C8-D2B9A2CD6-DB7-4ACD6-D8-5A6(D6-D12-A)D6-DB11-CD6-D2B9-2CD8-2B7A2C12-3BD3C161-3BD3C13-2B5A2C11-2B5-2A2C9-2B6-3A2C5(8-B11-C)8-2B9-2C9-2B7-2C11-2B5-2C13-3BD3C204-2BD2C15-3BD3C13-3B3-3C11-3B-B3-3C3(10-2B7-2C)10-3B3-F-3C11-3B2-F3C13-3BD3C15-2BD2C269-BDC17-2BD2C15-2(3BD3C14-)3BD3C15-2BD2C17-BDC156-
