model
size = 21, scale = 0.05, origin = -y
material 
  colors = A:#C25100 B:#101010 C:#808080 D:#000
voxels
156-BCB17-2BC2B15-2(3BC3B14-)3BC3B15-2BC2B17-BCB269-2BC2B15-3BC3B13-3B2A-3B11-3B3A-4B3(10-2B4A3-2B)10-3B3A2-3B11-3B2A-3B13-3BC3B15-2BC2B204-3BC3B13-2B5A2B11-2B5-2A2B9-2B6-3A5(2B8-B10-)2(2B8-)3B9-2B7-2B11-2B5-2B13-3BC3B161-3BC3B12-2B7A2B8-C2B9A2BC6-CB7-4ABC6-C8-5A6(C6-C12-A)C6-CB11-BC6-C2B9-2BC8-2B7A2B12-3BC3B119-3BC3B11-C2B7A2BC8-C11AC7-B13AB6-B8-5AB5-BA8-6A6(B4-BA12-2A)B5-B12-AB6-B12-AB7-C11AC8-C2B7A2BC11-3BC3B78-2BC2B13-C2B5A2BC9-B11AB7-B13AB6-B13AB5-BA8-6AB4-BA8-6AB3-4(B2A12-3AB2-)B2A12-3AB3-BA12-2AB4-BA12-2AB5-B12-AB6-B13AB7-BD10AB9-C2B5A2BC13-2BC2B57-3BC3B12-BC7ACB9-B11AB7-B13AB5-B15AB4-BA8-6AB3-B2A8-7A6(B2-B2A12-3A)B3-BA12-2AB4-BA12-2AB5-B13AB7-B11AB9-BCD5ADCB12-7C37-BCB15-C2B3A2BC10-2B9A2B7-B13AB5-B15AB4-B15AB3-2(B2A8-7AB2-)B2A12-3AB-B2(3A12-4A2B)3A12-4AB-2(B2A12-3AB2-)B2A12-3AB3-BA12-2AB4-B15AB5-B13AB7-2B9A2B10-3B3A3B15-BCB17-2BC2B13-BCB5ABCB9-B11AB7-B13AB5-B15AB3-B17A2(B2-B2A8-7A)B-B4(3A12-4A2B)3A12-4AB-2(B2A12-3AB2-)B2A12-3AB3-B15AB5-B13AB7-B11AB9-3B5A3B13-2BC2B15-3BC3B12-BC7ACB9-B11AB7-B13AB5-B15AB3-B17AB2-B2A8-7AB-B3A8-8A6(2B3A12-4A)B-B2A12-3AB2-B2A12-3AB3-B15AB5-B13AB7-B11AB9-2B7A2B12-3BC3B14-7C12-2C7A2C9-C11AC7-C13AC5-C15AC3-C17AC2-C2A8-7AC-C3A8-8A6(2C3A12-4A)C-C2A12-3AC2-C2A12-3AC3-C15AC5-C13AC7-C11AC9-2C7A2C12-7C14-3BC3B12-BC7ACB9-B11AB7-B13AB5-B15AB3-B17AB2-B2A8-7AB-B3A8-8A6(2B3A12-4A)B-B2A12-3AB2-B2A12-3AB3-B15AB5-B13AB7-B11AB9-2B7A2B12-3BC3B15-2BC2B13-BCB5ABCB9-B11AB7-B13AB5-B15AB3-B17A2(B2-B2A8-7A)B-B4(3A12-4A2B)3A12-4AB-2(B2A12-3AB2-)B2A12-3AB3-B15AB5-B13AB7-B11AB9-3B5A3B13-2BC2B17-BCB15-C2B3A2BC10-2B9A2B7-B13AB5-B15AB4-B15AB3-2(B2A8-7AB2-)B2A12-3AB-B2(3A12-4A2B)3A12-4AB-2(B2A12-3AB2-)B2A12-3AB3-BA12-2AB4-B15AB5-B13AB7-2B9A2B10-3B3A3B15-BCB37-3BC3B12-BC7ACB9-B11AB7-B13AB5-B15AB4-BA8-6AB3-B2A8-7A6(B2-B2A12-3A)B3-BA12-2AB4-BA12-2AB5-B13AB7-B11AB9-BCD5ADCB12-7C57-2BC2B13-C2B5A2BC9-B11AB7-B13AB6-B13AB5-BA8-6AB4-BA8-6AB3-4(B2A12-3AB2-)B2A12-3AB3-BA12-2AB4-BA12-2AB5-B12-AB6-B13AB7-BD10AB9-C2B5A2BC13-2BC2B78-3BC3B11-C2B7A2BC8-C11AC7-B13AB6-B8-5AB5-BA8-6A6(B4-BA12-2A)B5-B12-AB6-B12-AB7-C11AC8-C2B7A2BC11-3BC3B119-3BC3B12-2B7A2B8-C2B9A2BC6-CB7-4ABC6-C8-5A6(C6-C12-A)C6-CB11-BC6-C2B9-2BC8-2B7A2B12-3BC3B161-3BC3B13-2B5A2B11-2B5-2A2B9-2B6-3A2B5(8-B11-B)8-2(2B9-)2B7-2B11-2B5-2B13-3BC3B204-2BC2B15-3BC3B13-3B3-3B11-3B5-3B3(10-2B7-2B)10-3B3-B-3B11-3B2-4B13-3BC3B15-2BC2B269-BCB17-2BC2B15-2(3BC3B14-)3BC3B15-2BC2B17-BCB156-
