model
size = 21, scale = 0.05, origin = -y
material 
  colors = A:#C25100 B:#000
voxels
156-ABA17-2AB2A15-2(3AB3A14-)3AB3A15-2AB2A17-ABA269-2AB2A15-3AB3A13-3A3-3A11-4(3A5-3A10-)3A5-3A11-3A3-3A13-3AB3A15-2AB2A204-3AB3A13-9A11-11A9-2A7-5(4A8-A8-)4A8-2A7-4A9-11A11-9A13-3AB3A161-3AB3A12-11A8-2(B13AB6-)7(BA12-B6-)B13AB6-B13AB8-11A12-3AB3A119-3AB3A11-B11AB8-B11AB7-15A6-15A5-6(3A12-2A4-)3A12-2A5-15A6-15A7-B11AB8-B11AB11-3AB3A78-2AB2A13-B9AB9-13A7-15A6-15A5-17A4-3A12-2A3-4(4A12-3A2-)4A12-3A3-3A12-2A4-17A5-15A6-15A7-AB11A9-B9AB13-2AB2A57-3AB3A12-AB7ABA9-13A7-15A5-17A4-17A3-6(4A12-3A2-)4A12-3A3-17A4-17A5-15A7-13A9-A2B5A2BA12-7B37-ABA15-B7AB10-13A7-15A5-17A4-17A3-19A2(2-4A12-3A)-5A2(12-9A)12-4A-2(4A12-3A2-)19A3-17A4-17A5-15A7-13A10-9A15-ABA17-2AB2A13-AB7ABA9-13A7-15A5-17A3-2(19A2-)4A12-3A-5A4(12-9A)12-4A-4A12-3A2(2-19A)3-17A5-15A7-13A9-11A13-2AB2A15-3AB3A12-AB7ABA9-13A7-15A5-17A3-19A2-19A-5A6(12-9A)12-4A-19A2-19A3-17A5-15A7-13A9-11A12-3AB3A14-7B12-2B7A2B9-B11AB7-B13AB5-B15AB3-B17AB2-B17AB-B6(4A12-3A2B)4A12-3AB-B17AB2-B17AB3-B15AB5-B13AB7-B11AB9-2B7A2B12-7B14-3AB3A12-AB7ABA9-13A7-15A5-17A3-19A2-19A-5A6(12-9A)12-4A-19A2-19A3-17A5-15A7-13A9-11A12-3AB3A15-2AB2A13-AB7ABA9-13A7-15A5-17A3-2(19A2-)4A12-3A-5A4(12-9A)12-4A-4A12-3A2(2-19A)3-17A5-15A7-13A9-11A13-2AB2A17-ABA15-B7AB10-13A7-15A5-17A4-17A3-19A2(2-4A12-3A)-5A2(12-9A)12-4A-2(4A12-3A2-)19A3-17A4-17A5-15A7-13A10-9A15-ABA37-3AB3A12-AB7ABA9-13A7-15A5-17A4-17A3-6(4A12-3A2-)4A12-3A3-17A4-17A5-15A7-13A9-A2B5A2BA12-7B57-2AB2A13-B9AB9-13A7-15A6-15A5-17A4-6A9-2A3-4(6A10-3A2-)7A9-3A3-6A9-2A4-17A5-15A6-15A7-AB11A9-B9AB13-2AB2A78-3AB3A11-B11AB8-B11AB7-15A6-15A5-6A9-4(2A4-5A10-)2(2A4-6A9-)2A5-15A6-15A7-B11AB8-B11AB11-3AB3A119-3AB3A12-11A8-2(B13AB6-)3(B4A5-4AB6-)B4A9-3(B6-B4A5-4A)2(B6-B13A)B8-11A12-3AB3A161-3AB3A13-9A11-11A9-6(4A5-4A8-)4A5-4A9-11A11-9A13-3AB3A204-2AB2A15-3AB3A13-3A3-3A11-4(3A5-3A10-)3A5-3A11-3A3-3A13-3AB3A15-2AB2A269-ABA17-2AB2A15-2(3AB3A14-)3AB3A15-2AB2A17-ABA156-
