model
size = 15 8 32, scale = 0.05, origin = -y
material 
  colors = A:#FCD200 B:#FF8A36 C:#EFEFEF D:#FC6900 E:#FFE770 F:#FFDE36 G:#FF9B53 H:#FFD91A I:#FFE253
voxels
3-5BF3-F94-5BG3-B9-A2F11-H3-E128-CA5-AC125-E9-F109-A9-C109-F9-A108-F11-I107-C11-A107-A11-I122-A11-I107-A11-C107-C11-F107-H11-H122-E11-H107-A11-A108-E9-E109-H9-A110-A7-E127-F5-A114-C3-C115-HF-FH116-HCF113-G3B2G2BEDB2G2-F3B2F3-DB2F91-GC3ACGBEADACG-FC2AECF3-DACF90-GC3ACA2B2ADCABFC2AECEB3-DCAB90-B2ADC2A2BACD2A2BAE-C2AB3-D2AE90-BACD2ACBGEADACGBAC-2ACB3-DACF90-GCA5DB2AD2CBGCE8-D2CE90-B2ADA2CGBAEDCA2BEA-AECG3-DCAB90-B2AD2CABG2ED2AGB2A-2CEB3-D2AG90-BA2C3ABGB3AB-BA2CE2AB3-2AB92-GC4AG2-BAB3-FE4AB3-AB2-
