model
size = 32, scale = 0.05, origin = -y
material 
  colors = A:#222 B:#7C6331 C:#EEE D:#001 E:#353535 F:#111
voxels
416-66A4(28-4A)28-2A768-7(11A21-)11A23-2A32-A348-E11(31-A)30-3(14A18-)2(2A9-3A18-)2A2-3(B-)B2(3A18-2A9-)3A20-2(2A32-)2A696-3(16A16-)2(2A12-2A16-)2A2-5(B-)2(2A16-2A12-)2A18-3(2A32-)2A662-3(17A15-)2(2A14-A15-)2A2-6(B-)2(A15-2A14-)A17-4(2A32-)A629-2(3(18A14-)2(2A15-A14-)2A2-6(B-)B2(A14-2A15-)A16-4(2A32-)2A628-)3(3(19A13-)2(2A16-A13-)2A2-7(B-)2(A13-2A16-)A15-5(2A32-)A595-)2(3(20A12-)2(2A17-A12-)2A2-7(B-)B2(A12-2A17-)A14-5(2A32-)2A594-)3(21A11-)2(2A18-A11-)2A2-8(B-)2(A11-2A18-)A13-6(2A32-)A561-3(23A9-)2(2A19-2A9-)2A2-8(B-)B2(2A9-2A19-)2A11-7(2A32-)A527-3(26A6-)2(2A21-3A6-)2A2-9(B-)B2(3A6-2A21-)3A8-8(2A32-)2A492-3(28A4-)2(2A24-2A4-)2A2-11(B-)2(2A4-2A24-)2A6-9(2A32-)2A458-3(29A3-)2(2A26-A3-)2A2-12(B-)2(A3-2A26-)A5-10(2A32-)A425-2(3(30A2-)2(2A27-A2-)2A2-12(B-)B2(A2-2A27-)A4-10(2A32-)2A424-)2(3(31A-)2(2A28-A-)2A2-13(B-)2(A-2A28-)A3-11(2A32-)A391-)3(31A-)2(2A28-A-)2A2-13(B-)2(A-2A28-)A3-11(2A32-)2A390-98A2(28-4A)2-13(B-)2(4A28-)2A2-11(2A32-)2A390-98A2(28-4A)2-13(B-)4A28-4A20-E7-2A2-2A17-E14-2A15-E16-2A12-E19-2A10-E21-2A7-E24-2A5-E26-2A2-E29-2AE31-3(2A32-)2A390-256A768-256A15-B-B29-3B28-2B-2B685-256A400-E11(31-A)15-162A3(CD)2(2CDCD)CD2CDCD5C4A3(-D)2(2-D-D)-D2-2(D-)2(F-)4A28-2A398-2(B-)B27-5B2(333-162A3(CD)2(2CDCD)CD2CDCD5C4A3(-D)2(2-D-D)-D2-2(D-)2(F-)4A28-2A430-2(F-)D)333-162A28C2(4A28-)2A385-E28-E11(2-A28-A)-78A5B79A2(28-4A)28-2A384-
