model
size = 31 32 20, scale = 0.05, origin = -y
material 
  colors = A:#111 B:#F30 C:#444 D:#F60 E:#F63 F:#F33 G:#F00 H:#603 I:#63C J:#30F
voxels
328-2(6D955-)6E23-10D85-3(6C118-)6C100-24C335-6B23-10E19-14D21-6A25-4(6A24-C6AC24-2(6A25-))6A7-C17-6AC24-6A25-6C242-6B23-10B20-12E17-16D19-8A23-4(8A22-C8AC22-2(8A23-))8A6-C16-8AC22-8A23-C6-C180-4F27-4B25-8B21-12B18-14E16-16D18-10A21-4(10A20-C10AC20-2(10A21-))10A5-C15-10AC20-10A21-2C7-C148-4G25-8F23-8B22-10B19-14B16-16E14-18D16-12A19-4(12A18-C12AC18-2(12A19-))12A4-C14-12AC18-12A19-C-2C7-C116-4H25-8G22-10F21-10B20-12B18-14B16-16E14-18D15-11A-2A17-4(14A16-C14AC16-2(14A17-))14A3-C13-14AC16-14A17-C3-C7-2C84-4I26-6H24-8G22-10F21-10B19-14B16-16B14-18E12-20D13-12A-3A15-4(16A14-C16AC14-2(16A15-))16A2-C12-16AC14-16A15-C4-2C3-6C53-2J27-6I24-8H22-10G20-12F19-12B18-14B16-16B14-18E12-20D13-2A-13A15-4(16A14-C16AC14-2(16A15-))16A2-C12-16AC14-16A15-C5-C2-2C4-C52-4J26-6I24-8H22-10G20-12F19-12B18-14B16-16B14-18E12-20D13-16A15-4(16A14-C16AC14-2(16A15-))16A2-C12-16AC14-16A15-C6-2C6-C22-2C28-4J26-6I24-8H22-10G20-12F19-12B18-14B16-16B14-18E12-20D13-16A15-4(16A14-C16AC14-2(16A15-))16A2-C12-16AC14-16A15-10C5-C22-2C29-2J27-6I24-8H22-10G20-12F19-12B18-14B16-16B14-18E12-20D13-16A15-4(16A14-C16AC14-2(16A15-))16A2-C12-16AC14-16A15-C5-2C-C5-C83-4I26-6H24-8G22-10F21-10B19-14B16-16B14-18E12-20D13-16A15-4(16A14-C16AC14-2(16A15-))16A2-C12-16AC14-16A15-C5-C2-2C4-C114-4H25-8G22-10F21-10B20-12B18-14B16-16E14-18D15-14A17-4(14A16-C14AC16-2(14A17-))14A3-C13-14AC16-14A17-C2(3-2C)2-C146-4G25-8F23-8B22-10B19-14B16-16E14-18D16-12A19-4(12A18-C12AC18-2(12A19-))12A4-C14-12AC18-12A19-C-2C5-3C178-4F27-4B25-8B21-12B18-14E16-16D18-2A-7A21-4(10A20-C10AC20-2(10A21-))10A5-C15-10AC20-10A21-2C7-C240-6B23-10B20-12E17-16D19-8A23-4(8A22-C8AC22-2(8A23-))8A6-C16-8AC22-8A23-C6-C272-6B23-10E19-14D21-6A25-4(6A24-C6AC24-2(6A25-))6A7-C17-6AC24-6A25-6C304-6E23-10D85-3(6C118-)6C100-24C100-
