model
size = 18 22 18, scale = 0.05, origin = -y
material 
  colors = A:#FF0 B:#BBB C:#EEE
voxels
7-6B31-18(2A16-)2A14-6B32-18(2A16-)2A14-6B12-6B30-18(6A12-)6A11-B6AB10-8B12-4A12-18(8A10-)8A9-B8AB8-2B6-2B10-2A2-3A9-18(10A8-)10A7-B4A2(C2A)B6-2(2B8-)2A5-2A7-18(12A6-)12A5-B12AB4-2B10-2B6-2A7-2A5-18(14A4-)14A3-B14AB2-2B12-2B4-2A9-2A3-18(16A2-)16A-B3ACAC2AC7A3B14-2B2-2A11-A3-18(16A2-)16A-B4A2(C5A)3B14-2B2-A12-A2-333A-8AB7ACAC3AC2A3B14-2B2-A12-A2-342AB16A3B14-2B2-A11-2A3-18(16A2-)16A-B3ACA2CAC7A3B14-2B2-2A9-2A4-18(16A2-)3A-9A-2A-B16A3B14-2B3-2A7-2A6-18(14A4-)3A-7A2-A3-B3A2(C2A)C4AB2-2B12-2B2(5-2A)8-18(12A6-)3A-5A2-A5-B4AC7AB4-2B10-2B7-2A3-2A10-18(10A8-)2A7-A7-B10AB6-2B8-2B9-5A12-18(8A10-)8A9-B3AC4AB8-2B6-2B28-18(6A12-)6A11-B6AB10-8B5-
