model
size = 32 32 8, scale = 0.05, origin = -y
material 
  colors = A:#222 B:#444 C:#111 D:#F60 E:#EEE F:#F93
voxels
-31E12C20-11BAC5-14C11B2A5-C12A18(C11B2A5-C5A7B)C5D8(6B2A5-C5A3B10D)8E5A9E10D22A5D13C19-12AC5-14C12AC5-C2A6DADA2D12AC5-C2AD6ADAD13AC5-C2AD2A3DADA2D12AC5-C2AD6AD15AC5-C2A11D12A22(C5-C25A)C5AC25AC5AC13A32EC11-C31-A5-2(C12-)A5-C12-D12-A5-C25-3(A5-C12-D12-)13(A5-C25-)2(A5-C13-D11-A5-C12-DA7(11-A5-C12-2A)11-A5-C12-AD11-A5-C12-DE11-E5AE12-EC11-C31-A5-2(C12-)18(A5-C25-))A5-C13-D11-A5-C12-DA7(11-A5-C12-2A)11-A5-C12-AD11-A5-C12-DE11-E5AE12-EC10-2C30-2A5-C12-C11-18(2A5-C24-)2A5-C13-D10-2A5-C12-DA7(10-2A5-C12-2A)10-2A5-C12-AD10-2A5-C12-DE10-2E5AE12-EC10-C31-A6-C12-C11-18(A6-C24-)A6-C13-5F6-A6-C8-6F8(3-F6-A6-C8-F3-2F)3DF6-A6-C8-F3DFE10-E6AE12-EC10-C31-AC5-C12-C11-18(2A5-C24-)2A5-C13-5F6-2A5-C8-5F4-D7(6-2A5-C2(8-D))6-2A5-C8-D4-F3DF6-2A5-C8-F3DFE10-2E5AE12-E
