model
size = 11 4 9, scale = 0.05, origin = -y
material 
  colors = A:#111 B:#222
voxels
5A-6A3-A-A3-2A3-A-A3-12A7(33-A9-A)22-B9-BA9-A
