model
size = 30 30 11, scale = 0.05, origin = -y
material 
  colors = A:#F9F B:#CFF C:#9FF D:#FF9 E:#036 F:#001 G:#F60 H:#0CF I:#FFF J:#EEE K:#FF0 L:#F0C M:#0CC N:#039 O:#9CF P:#0FF Q:#FCC R:#3FF S:#6FF
voxels
190-10B19-12B17-3(14B16-)14B17-12B18-12B19-10B112-6B23-3(8B22-)8B23-6B351-12C16-3C10B3C13-18B13-4(B14AB14-)2B12A2B14-2B12A2B15-2B10A2B3(16-14B)17-3B6A3B4(18-2B8A2B)18-3B6A3B19-10B21-8B142-G6-G139-14C15-C14B2C12-5B8A5B12-5B4A9B12-2B7A9B13-B14A2B13-B14AB14-B14AB12-2CB14AB2C10-2CB14AB2C13-8(B12AB16-)B12AB17-B10AB18-2B8A2B20-8B112-2G4-2G112-2H4-2H19-3C2B4C2B3C15-C14B2C12-5B8A5B12-5B4A9B12-2B9A7B7-C5-B14A2B4-C2-3C3-B14AB3-3C3-5CB14AB5C4-5CB14AB5C6-3CB14AB3C8-4CB12AB4C12-6(B12AB16-)2B11AB16-2B11AB17-B10AB18-2B8A2B20-8B112-2G4-2G22-2K4-2K22-2G4-2G22-2K4-2K21-H2GH2-H2GH18-2(2C4B)2C15-C14B2C13-4B8A5B12-5B4A9B6-2H4-2B9A7B4-6H-2CB14A2BC-7H4CB14AB4C3H-H5CB14AB5CH2-6CB14AB6C3-2C4B14A4B2C5-C3BCB12ABC3BC7-5B12A5B12-5(B12AB16-)2B11AB16-2B11AB17-B10AB18-2B8A2B20-8B110-5G2-5G20-2K4-2K22-2G4-2G22-2K4-2K21-H2GH2-H2GH18-2(2C4B)2C15-C14B2C13-4B4A9B12-5B4A9B13-B9A7B13-B13ADB13-CB13ADBC9-4CB13ADB4C6-3C2B13AO2B3C6-C4B13AO4BC7-5B12A5B10-3B12A3B14-2(B12AB16-)3(B10A2DB16-)2B9A2DB16-2B9A2DB17-B9ADB18-2B8A2B20-2B4A2B24-4B27-3B28-B23-2(G-)G2-2(G-)G110-2H4-2H19-3C2B4C2B3C15-C14BC14-2(4B4A9B13-)B9A7B13-3(B13ADB14-)B13AOB14-B13AOB15-4(B12AB16-)3(B10A2DB16-)2(2B9A2DB16-)2B9A2DB15-4B10A2B14-6B4A6B14-2(4B2-)4B14-4B3-2B3-4B14-2B12-2B16-2(G-)G2-2(G-)G137-14C15-C14BC14-C3B4A7BCB13-4B4A9B13-B7A8B3(14-B13ADB)14-B13AOB15-5(B12AB16-)3(B10A2DB16-)2(2B9A2DB16-)2B9A2DB15-BE2B8A2DEB14-B2EA3BA4BD2EB15-2ES3-B4-R2E15-B-2B8-2B-B14-2B12-2B166-12C17-C12B2C15-3B8A4B14-4B8A4B14-B13A3(DB14-2B12A)DB15-3(B12AB16-)B12AB14-2B13AD2B13-B13ADB14-B11A3DB15-2(B10A2DB16-)2B9A2DB16-2B9A2DB17-B10AB18-2B9AB19-10B20-B8-B230-10C19-8B2D3B16-3B6A2D4B15-3B8D3B2(16-4B6D4B)16-5B4D5B16-14B17-12B18-5B2M5B17-14B16-BD4B2L4BDB14-7B4F7B13-BQM2BF4BF2BMQB14-B2MD3B2F3BD2MB15-BD3B4F3BDB16-2B3J4B3J2B16-2B3LJ2BJ3LJB16-2B2FLJ2BJL2FJB17-BRF2J2B2JFAB18-2B2J4B2J2B20-8B263-6E23-8E21-3(10E20-)10E21-8E22-2(2E-)2E77-2(2F14-)2F10-2F45-2F12-2F11-3F2(3-F3-2F)14-F3-4F3-F15-3F-3I4-3I-3F15-I3NI2-I3NI18-I2FNI2-IN2FI18-IPF2I2-2IFPI19-3I4-3I130-
