model
size = 31 29 20, scale = 0.05, origin = -y
material 
  colors = A:#F00 B:#FF9 C:#700 D:#001 E:#FFF F:#F0C G:#9CF H:#0FF I:#FCC J:#EEE K:#A00 L:#3FF
voxels
36-5A6-5A15-2(A-)A6-2(A-)A859-7A23-12A18-4A4-7A16-3A8-5A15-3A10-4A28-2(3A29-)3A28-2(3A29-)3(2A29-)2A28-3A28-2A28-2(3A27-)2(4A26-)4A27-2A206-6A23-12A18-15A16-16A15-4A5-8A14-4A7-6A2(27-5A)2(27-4A28-4A)3(27-4A)26-4A27-2(4A26-)3(5A25-)5A26-4A27-2A176-7A22-13A17-15A16-16A15-4A4-9A14-4A7-7A26-3(5A27-)4A27-5A4(27-4A)26-5A26-4A26-2(5A25-)2(6A24-)6A25-5A26-3A175-7A22-8AB4A17-15A16-16A15-4A4-9A14-4A7-6A3(27-5A)27-4A28-3A28-4(4A27-)3A27-4A26-3(5A25-)5A2(26-4A)27-2A176-7A22-11A19-14A17-4A4-7A16-4A7-5A15-4A9-4A28-3(3A29-)2A29-3A5(29-2A)28-5(3A27-)3A28-2A265-3(4A27-)4A736-10(14A17-)14A18-12A19-12A20-10A116-6A24-3(8A23-)8A24-6A201-26A5-26A7-3(22A9-)22A10-20A13-5(16A15-)16A16-3(14A17-)14A18-5(12A19-)12A20-10A22-8A138-2(26A5-20A2BAB2A7-4(18A2B2A9-)18A2B2A11-18A13-18A14-4(16A15-)16A16-8(14A17-)14A18-12A19-12A21-8A107-)26A5-20A2B4A7-3(18AB3A9-)18A2B2A10-17A2BA12-18A13-18A14-4(16A15-)16A16-8(14A17-)14A18-12A19-12A21-8A111-8(18A13-)18A14-3(14ABA15-)14AGA15-14AGA16-4(14A17-)4(11A2BA17-)11AB2A18-10ABA19-12A21-8A25-4A28-3A29-A21-8(18A13-)18A14-3(14ABA15-)14AGA15-14AGA16-4(14A17-)4(11A2BA17-)11AB2A17-11AB2A16-2(16A15-)2(4A2-)4A15-4A3-2A3-4A15-2A12-2A14-8(18A13-)18A14-3(14ABA15-)14AGA16-5(14A17-)4(11A2BA17-)11AB2A17-11AB2A16-A2C11ACA15-A2C9AB2CA16-2CA3-A4-A2C16-A-2A8-2A-A15-2A12-2A14-5(18A13-)18A14-5(14ABA15-)14ABA16-3(14A17-)14A15-15AB2A14-14ABA15-12A3BA16-3(11A2BA17-)11AB2A18-12A19-C11A20-10A21-A8-A80-16A6(15-10A5BA)16-3A8B3A2(17-4A6B4A)17-5A4B5A17-14A18-5A2K5A19-12A18-4A6D4A17-AB2A6D4A15-6ADJ2DJD6A14-AIC10ACIA15-A2CB3A2D4A2CA16-AB3A2D7A17-14A17-2A3F4A2F3A17-2A2DF4AFD3A18-ALD6AD2A19-12A21-8A112-4A8C4A5(15-4A8C3BA)16-3A8C3A20-8C24-6C25-6C26-4C113-2D14-2D15-2D10-2D47-2(2D12-)3D2(3-D3-2D)15-D3-4D3-D16-3D-3E4-3E-3D16-E3CE2-E3CE19-E2DCE2-EC2DE19-EHDCE2-ECDHE20-3E4-3E142-4A8-4A15-4A8-A2BA2(15-4A8-4A)16-2(3A8-3A17-)3A8-3A698-5A6-5A15-5A6-5A847-
