model
size = 18 20 18, scale = 0.05, origin = -y
material 
  colors = A:#F00
voxels
170-3(2A16-)2A286-3(2A16-)2A304-3(2A16-)2A268-2A16-2A14-3(2A2-2A12-)2A2-2A14-2A16-2A232-2A16-2A14-3(2A2-2A12-)2A2-2A14-2A16-2A196-2A16-2A14-2A2-2A12-2A2-2A10-3(2A6-2A8-)2A6-2A10-2A2-2A12-2A2-2A14-2A16-2A160-2A16-2A14-2A2-2A12-2A2-2A10-3(2A6-2A8-)2A6-2A10-2A2-2A12-2A2-2A14-2A16-2A124-2A16-2A14-2A2-2A12-2A2-2A10-2A6-2A8-2(2A6-)3(2A10-2A4-)2A10-2(2A6-)2A8-2A6-2A10-2A2-2A12-2A2-2A14-2A16-2A88-2A16-2A14-2A2-2A12-2A2-2A10-2A6-2A8-2(2A6-)3(2A10-2A4-)2A10-2(2A6-)2A8-2A6-2A10-2A2-2A12-2A2-2A14-2A16-2A52-2A16-2A14-2A2-2A12-2A2-2A10-2A6-2A8-2(2A6-)2A10-2A4-2A10-2A2-2A3(14-4A)14-2A2-2A10-2A4-2A10-2(2A6-)2A8-2A6-2A10-2A2-2A12-2A2-2A14-3(2A16-)2A14-2A2-2A12-2A2-2A10-2A6-2A8-2(2A6-)2A10-2A4-2A10-2A2-2A3(14-4A)14-2A2-2A10-2A4-2A10-2(2A6-)2A8-2A6-2A10-2A2-2A12-2A2-2A14-2A16-2A52-2A16-2A14-2A2-2A12-2A2-2A10-2A6-2A8-2(2A6-)3(2A10-2A4-)2A10-2(2A6-)2A8-2A6-2A10-2A2-2A12-2A2-2A14-2A16-2A88-2A16-2A14-2A2-2A12-2A2-2A10-2A6-2A8-2(2A6-)3(2A10-2A4-)2A10-2(2A6-)2A8-2A6-2A10-2A2-2A12-2A2-2A14-2A16-2A124-2A16-2A14-2A2-2A12-2A2-2A10-3(2A6-2A8-)2A6-2A10-2A2-2A12-2A2-2A14-2A16-2A160-2A16-2A14-2A2-2A12-2A2-2A10-3(2A6-2A8-)2A6-2A10-2A2-2A12-2A2-2A14-2A16-2A196-2A16-2A14-3(2A2-2A12-)2A2-2A14-2A16-2A232-2A16-2A14-3(2A2-2A12-)2A2-2A14-2A16-2A268-3(2A16-)2A152-
