model
size = 21 23 12, scale = 0.05, origin = -y
material 
  colors = A:#630 B:#FF0 C:#930 D:#C3C
voxels
3-5(2A-)2A3-2A-2A3-B3-2A-2A3-7A2(-B)-7A2-7A2(B-)B7A3-2A-2A3(B-)B2A-2A8-B-B3-B-B11-B-B5-B-B9-2(B-B7-)B-B4-D4-B-B5-B-B4-3D4-B-B5-B4-5D4-B7-B2-7D2-B8-B-9D-B7-B-B2-5D2-B-B5-B-B4-3D4-B-B5-B-B4-D4-2(B-B7-)B-B9-B-B5-B-B11-B-B3-B-B13-3(B-)B9-2(2A-)3(B-)2A-2A3-8ABAB8A2-19A239-6C475-2C6-2C471-2C10-2C468-2C12-2C467-C14-C466-2C14-2C465-C16-C464-2(2C16-2C463-)2C16-2C253-441A21-
