model
size = 32 5 31, scale = 0.05, origin = -y
material 
  colors = A:#F39 B:#D00 C:#EEE D:#555 E:#C90
voxels
77-E4-E92-E61-2E2-2E61-E30-E31-E29-2E2D2E29-E31-E62-E30-E2DE30-E126-2D156-2C2D2C153-2C-2D-2C151-2C2-2D2-2C149-2C3-2D3-2C147-2C4-2D4-2C145-2C5-2D5-2C143-2C6-2D6-2C141-2C7-2D7-2C139-2C8-2D8-2C137-2C9-2D9-2C135-2C10-2D10-2C133-2C11-2D11-2C131-2C12-2D12-2C130-C13-2D13-C67-A26-A2-3A26-6A12-2D12-6A26-3A2-A26-A4-2A7-10A7-2A3-3A7-4A2-4A7-3A2-3A7-4A2D4A7-3A2-3A7-4A2-4A7-3A3-2A7-10A7-2(2A5-)2A8-2(2A5-)3A5-5A2-5A5-3A4-3A5-5A2D5A5-3A4-3A5-5A2-5A5-3A5-2A5-A10-A5-2A7-A5-A10-A5-A7-2A5-2A8-2A5-2A6-2A5-2A3-2D3-2A5-2A6-2A5-2A8-2A5-2A7-A5-A10-A5-A8-A4-A12-A4-A7-2A4-2A10-2A4-2A6-2(2A4-)2D2(4-2A)6-2A4-2A10-2A4-2A7-A4-A12-A4-A8-A3-A14-A3-A7-2A3-2A12-2A3-2A6-2A3-2A5-2D5-2A3-2A6-2A3-2A12-2A3-2A7-A3-A14-A3-A8-4A16-4A8-5A6-2B6-5A8-5A5-4B5-5A8-5A6-2B6-5A8-4A16-4A9-2A8-2B8-2A9-4A6-4B6-4A8-4A5-6B5-4A8-4A6-4B6-4A9-2A8-2B8-2A19-4B19-2A6-6B6-2A10-2A5-8B5-2A10-2A6-6B6-2A19-4B27-6B25-8B23-10B23-8B25-6B26-2B2-2B25-8B23-10B23-8B25-2B2-2B58-B4-B25-3B2-3B25-B4-B45-
