model
size = 18 32 20, scale = 0.05, origin = -y
material 
  colors = A:#B00 B:#111 C:#036 D:#A00 E:#555 F:#FC6 G:#F90 H:#06F I:#093 J:#EEE K:#777 L:#C30 M:#06C N:#F93
voxels
350-2G235-2I15-2IL15-2(ILC14-)IL2C2(13-IL3C)12-IL3C14-L453-C2(16-2C)15-3C14-4C12-I5C12-I4C13-L4C14-3C16-C17-C434-C16-2C15-3C2(12-I5C)12-L4C13-5C14-3C16-2C159-4A14-4A270-C16-2C14-4C3(12-3A3C)13-2A2C14-4A140-4A13-6A12-6A13-4A49-6B246-6A11-3(8A10-)8A11-6A13-4A103-3(6A12-)6A47-8B11-6B209-E-E2-E-E11-6A11-5(8A10-)8A83-6A11-3(8A10-)8A11-6A27-12B7-10B9-8B12-4B172-2(E-)E2-2(E-)E8-E6AE7(10-8A)64-8A9-2(10A8-)10A9-2(8A10-)8A7-14B5-12B7-10B9-8B12-4B154-2(E-)E2-2(E-)E6-E-E6AE-E7-5(10A8-)10A9-8A10-8A28-8A9-10A7-3(12A6-)12A7-10A8-10A5-4B8A4B2-16B4-12B7-10B9-8B12-4B136-2(E-)E2-2(E-)E6-E-E6AE-E7-10A6-A-10A-A4-A-10A-A6-2(10A8-)10A9-8A10-8A11-6A11-8A9-10A7-3(12A6-)12A7-10A8-10A4-5B8A23B2-14B6-10B8-10B9-8B134-2(E-)E2-2(E-)E5-AE-E6AE-EA3-2A-10A-2A2-16A3-14A4-14A5-12A6-12A7-10A9-8A11-6A11-8A9-10A7-3(12A6-)12A7-10A8-10A4-5B8A23B2-14B6-10B8-10B9-8B12-4B117-H2(E-)E2-2(E-)EH3-2CE-E6AE-E2C2-C14AC2(2-16A)3-14A4-14A5-12A7-10A9-8A11-6A11-8A9-10A7-3(12A6-)12A7-10A8-10A4-5B8A23B2-14B6-10B8-10B9-8B133-H2(K-)E2-E2(-K)H3-CMK-KAK2AKAK-KMC2-C3AK6AK3AC4(2-16A)3-14A5-12A8-8A11-6A11-3D2F3D9-3D4F3D7-4D4F4D6-5D2F5D6-12D6-3DB4DB3D7-10D8-10D5-4B8D4B2-16B4-12B7-10B9-8B12-4B115-H16-3H3(-E)2-3(E-)2HC2HE-EAE2AEAE-E2H3C3AE6AE3A3C16AC36A-16A3-14A5-12A8-8A11-6A12-2A2F2A11-2A4F2A9-3A4F3A8-4A2F4A2(8-10A)9-8A11-6A8-3B2-4D2-3B5-4BJ2BJ4B7-4B2J4B9-2(2BJ)2B12-4B133-H16-3H3(-E)2-3(E-)2HC2HE-EAE2AEAE-E2H3C-2AE6AE2A-2C-C14AC3(2-16A)3-14A5-A-8A-A8-8A13-2D15-D2FD13-A4FA11-2A4F2A10-3A2F3A2(10-8A)11-6A12-6D243-2(E-)E2-2(E-)E6-E-EAE2AEAE-E6-2AE6AE2A6-12A5-14A2(4-2A-8A-2A)5-A-8A-A10-4A51-2F14-D4FD12-A4FA12-2A2F2A12-6A12-D4AD12-2D2-2D12-D4-D243-2(E-)E2-2(E-)E8-E6-E9-10A9-8A8-A-8A-A6-A2-6A2-A6-A3-4A3-A83-2F15-N3G13-D4FD13-D2FD13-J-2D-J11-JBJ2-JBJ11-J4-J263-E6-E29-6A13-4A14-4A15-2A106-2F15-4G14-4G15-2G357-4A15-2A16-2A141-4G14-4G375-2A16-2A159-4G15-2G224-
