model
size = 6 33 28, scale = 0.05, origin = -y
material 
  colors = A:#FEE900 B:#080202 C:#FFF D:#070701 E:#040000 F:#FC0000 G:#F2EEFC H:#0B0505
voxels
81-8(A5-)A143-8(A5-)A191-A5-A182-36B144-18BA5(4B2A)4BA18B120-6BA2(4B2A)4B32A3(4B2A)4BA6B32-4E2-2E11(4-2A)2-2B2A2B73A4B2A4BA6B26-4E2-2E10(4-2A)2-2B2A2BAB2AB80A4B2A4BA6B84-6BAB2AB92A4B2A4BA6B72-6B2A3B30A2(D5A)D28A2(2C4A)2C19A4B2A4BA6B66-6B29AD2(5AF)5AD22A2C3A3C3A2CH3A2CD4A2C19A4BA6B66-6B29AD5AF5AG5AD22A2C3(3A3C)4A2C19AB4A6B66-6B23AD2(5AF)5AG5AD22A2C3(3A3C)4A2C19AB5A4BA6B60-6B23AD2(5AF)5AG5AD28A2(2C4A)2C31A3(4BA6B60-6B23AD2(5AF)5AG5AD73A)4BA6B60-6B23AD2(5AF)5AG5AD28A2(2C4A)2C31A4BA6B60-6B23AD2(5AF)5AG5AD22A2C3A3C3A2CH3A2CD4A2C19A4BA6B66-6B29AD2(5AF)5AD22A2C3(3A3C)4A2C19A4BA6B66-6B29A3(D5A)D22A2C3(3A3C)4A2C19A4BA6B72-6B41AD28A2(2C4A)2C19AB4A6B14-4E2-2E10(4-2A)2-2B2A2B91A4BA6B20-4E2-2E11(4-2A)2-2B2A2B79A4BA6B108-6B67A4BA6B120-18B31A4BA18B144-36B171-A5-A74-
