model
size = 30 32 11, scale = 0.05, origin = -y
material 
  colors = A:#555 B:#F96 C:#111 D:#444 E:#0F0
voxels
3(150-2A26(26-4A)26-2A)150-2A17(26-4A)8(26-2ABA)26-4A26-2A150-2A15(26-4A)11(26-2ABA)26-2A150-2A13(26-4A)3(26-2ABA)8(26-4A)2(26-2ABA)26-2A34-2A18-2A7-3A18-3A6-3A18-2A6-4A18-3A5-4A18-4A4-4A18-4A3-12(5A18-5A2-)B4A11(18-5A2-5A)18-5A2-B4A18-5A36-2A16-2A8-4A16-4A6-4A16-4A5-2(5A16-5A4-)5A16-5A3-10(6A16-6A2-)AB4A16-6A2-2B4A16-6A2-B5A5(16-6A2-6A)16-6A5(2-AD4A16-4ADA)2-6A16-6A2-6B16-6A36-3A14-3A9-4A14-4A7-2(5A14-5A6-)11(5A14-4AB6-)AB2(3A14-4AB6-2B)3A2(14-4AB6-5A)2(14-5A6-5A)14-5A6-AD3A14-3ADA6-DB3A14-3AB2(D6-DC3A14-3AC)D2(6-2C3A14-3A2C)6-2D3A14-3A2D6-5A14-5A6-5B14-5A10-A13-2A12-3A13-2A13(2B10-3A14-A)2B10-AB2(A14-A2B10-2B)A3(14-A2B10-3A)14-3A10-ADA14-ADA10-DBA14-ABD10-BCA14-ACB5(10-2CA14-A2C)10-CDA14-ADC10-3A14-3A10-3B14-3A13-14A15-3AD8CD3A14-4AD6CD4A14-5A2D2C2D5A14-7A2D7A3(14-16A)14-7A2D7A14-5A2D2A2D5A2(14-4AD6AD4A)3(14-5AD4AD5A)14-2(4A2D)4A14-B3AD6AD4A14-2B2AD6AD4A14-3B13A14-A3B12A14-2A3B11A14-3D2BC3ADC5D14-6C3AD6C14-6CB2AD6C14-5C2B2A2D5C14-5CBA2CAD5C14-4C2BE2CE2D4C14-3C2BA4C2AD3C14-2CD2BAC2AC3AD2C14-2D2B2(2AC)4A2D14-2A2B12A14-3B13A7-
