model
size = 22 28 22, scale = 0.05, origin = -y
material 
  colors = A:#CC9 B:#C66 C:#C90 D:#C99 E:#966 F:#C63 G:#AAA H:#936 I:#C36 J:#C93 K:#C96 L:#996 M:#F90 N:#F06 O:#CC6 P:#F33 Q:#C00 R:#099 S:#963 T:#C33 U:#E00 V:#CC3 W:#993 X:#663 Y:#399 Z:#777 Aa:#396 Ab:#990 Ac:#690 Ad:#C06 Ae:#F36 Af:#D00 Ag:#696 Ah:#444 Ai:#693 Aj:#933 Ak:#888 Al:#F60 Am:#555 An:#F00 Ao:#F30 Ap:#660 Aq:#999 Ar:#F66 As:#699 At:#C60 Au:#CC0 Av:#F63 Aw:#669
voxels
30-2AOJVA16-3AO2V16-JO3AV16-OJO3A16-D2KO2A16-3D3A16-6D2(16-5DB)16-4D2B16-2A2DBD16-3ADBD16-3A2BA16-2ADBEA16-2ABHBA16-AD2EDA16-ADEBDA16-AD2BDA19-2AD19-2A171-6C16-2CAv2PC16-2CP2NC16-3C2JC16-W2CJ2F16-Ag3CFB16-AgM3CF16-Aa5C16-RWM2CJ16-RWMJCB16-YJCB2F16-YFCF2B16-YE2FHB16-AwBH2BE16-2(E2B)16-BE2BHB16-EBE2BE16-2(BE)2B19-BEB19-2B190-3C6-3C10-2AoAl6-CJAa10-2AnAl6-CJR10-3C6-2CW10-AtJW6-3F10-SAgZ6-H2B10-SFZ6-BHB10-SZR6-2BE10-LAaR6-JBE10-S2R6-F2B10-Aa2R6-3B10-Y2R6-EBE10-Y2R6-B2E10-2YR6-B2E10-2EZ6-3I10-2BH6-I2N10-E2B6-I2N10-BEB6-E2I10-EB6-2BE19-EBE17-KD2K18-3A19-A124-C12-C8-M12-Aa8-Al12-R8-C12-W8-C12-F8-F12-H8-F12-E8-F12-B8-C12-E8-C12-H8-C12-B8-J12-B8-F12-H2(8-F12-B)8-C12-N8-C10-3N8-C10-2NAd8-C9-ENBH8-F9-EKEB18-3K19-2A17-4A18-3A99-C14-C6-C14-Ag6-V14-Aa6-C14-J6-C14-F6-P14-B6-C14-E6-P14-E2(6-C14-B)6-C14-H6-C14-E6-P14-H6-C14-B6-P14-B6-C14-I6-C13-NAe6-C13-2N6-C12-2NI6-P12-2KE6-J12-2K20-AK18-2AK19-DL17-A2K76-C16-C4-V16-C4-A16-C4-O16-C4-J16-F4-F16-H4-C16-B4-P16-B4-C16-H4-C16-B4-C16-E4-C16-H4-F16-B4-C16-B4-T16-B4-C16-K4-C15-NL2(4-C15-NI)4-P15-KB4-J15-K5-A15-L19-AL20-L16-3K2L17-K2L53-C18-C2-O2(18-C2-A)18-C2-J18-F2-F18-H2-C18-E2-P2(18-B2-C)18-H2-C18-E2-C18-I2-P18-Ae2-C18-B2-T2(18-B2-C)17-NH2-C17-NI2-C16-2I3-P16-KE3-J16-KB3-A16-E20-AcX20-Ac18-2LAb16-4L18-L33-C18-C2-O18-C2-A18-Ab2-A18-C2-J18-F2-F18-B2-C18-B2-P18-H2-C18-B2-C18-E2-C18-H2-C18-B2-P18-B2-C18-B2-T2(18-S2-C)18-I2(2-C17-2I)2-P17-IH2-J17-B3-A17-X20-Ap21-Ap18-L2Ab18-LC17-3L31-C18-C2-V18-Ab2-A18-Ac2-O18-C2-J18-F2-F18-H2-C18-B2-P18-B2(2-C18-H)2-C18-I2-C18-Ae2-P18-B2-C18-E2-T18-X2-C18-S2-C18-I2(2-C17-2I)2-P17-IB2-J17-IB2-G17-S3-G16-SC20-C2(19-2M)16-4L29-F20-2C20-AbV20-AcAu20-2C20-2F20-EC20-HT2(20-BC)20-HC20-EC20-AeF20-BC20-ST20-AiC20-SC20-IC20-EC20-IP19-H-J19-B-A19-F-A18-M2-A18-M2(19-2M)15-L4M17-2L9-F20-CF2(20-2C)20-CF20-2F20-BC20-BF20-HF20-B2(C20-E)2(F20-B)C20-LF20-XF20-AiC20-EC20-HF20-AdF19-AdBJ19-E-A19-F-G18-M2-A18-M2-G16-2M19-2M17-3C17-2LJ8-C3(20-CF)20-2C20-FC20-H2(C20-B)J2(20-HF)20-HJ2(20-BC)20-KC20-XJ20-AiF20-BF20-NJ20-AdC19-AdBJ19-B-G19-F-G18-2M-G18-M2-G16-2M19-2M18-3C16-L2J8-Aq2(20-CAh)20-CX20-CK20-FD20-BD20-H2(D20-B)D20-EA20-H2(A20-B)A20-KA20-XA20-SA20-IA20-NA20-IA19-IEA19-B-A19-F-D18-2M-G18-M2-G16-2M19-2M18-3C16-G2J8-A20-CG20-BZ20-BS20-2J20-F2(D20-B)D20-EK20-ED20-BA20-EA20-IA20-AeA20-K3(A20-B)A20-IA20-HA19-HBA19-I-D19-F-2(G18-C2-)G16-2C19-2M17-3C17-GDF8-O20-C2(A20-B)O20-JK20-FD20-H2(D20-B)K20-BD20-HA20-EA20-HA20-Ar3(A20-B)A20-E2(A20-B)A19-H-L19-Af-L19-U-G18-U2-D18-U2(19-2U)15-2G3U17-GD10-J18-C2-O18-B2-G18-B2-Z18-J2-K18-F2-D18-B2(2-D18-E)2(2-D18-B)2(2-A18-H)2(2-A18-B)2-A18-E2(2-A18-B)2-A17-BE2-A17-2B2-G17-QI2-G17-QU2-L17-Q3-G16-2Q20-Q2(19-2Q)16-3GQ30-L18-C2-X18-C2-Am18-C2-Ak18-J2-D18-B2-D18-H2(2-D18-B)2-D18-H2(2-A18-B)2-A18-H2-A18-E2(2-A18-B)2-A18-H2-A18-B2-A17-2B2-A17-BE2-A17-QI2-G17-Af3-G17-T20-T21-Aj18-G2Aj18-GD17-3G31-G18-C2-Am18-C2-Ah18-C2-G18-O2-D18-D2-D18-H2-D18-E2(2-D18-B)2-A18-H2(2-A18-E2(2-A18-B))2-A17-BH2-A17-2B2-A16-2B3-G16-QI3-D16-QU3-G16-T20-TI20-B18-GAcW16-4G18-G34-2(A16-C4-)S16-O4-Z16-A4-D16-D2(4-D16-B)4-D16-H2(4-D16-B)4-A16-E4-A16-H2(4-A16-B)4-A16-E4-A16-B2(4-A15-2B)4-A15-BE4-A15-QI4-A15-U5-G15-T19-AT20-A16-L2GAAk17-L2G55-A14-C6-A14-V6-O14-A6-W14-A6-K14-A2(6-D14-D)6-D14-K6-D14-E6-D3(14-B6-A)14-E2(6-A14-B)6-A14-E6-A13-BE6-A13-2B6-A12-3B6-A12-2QI6-D12-2Af20-AT18-GYA19-GAs17-L2G78-O12-J2(8-A12-A)8-O12-A8-K12-O5(8-D12-A)2(8-A12-A)8-A12-D8-A12-K2(8-A12-B)8-A10-3B8-A9-3BH8-A9-2BDB8-A9-2BAI18-BFA19-2G17-2GAAk18-2GD101-COA6-2AO10-O2V6-3A10-2AV6-JOA10-3A6-OJV10-K2D6-D2K10-3D6-2EA10-3D6-EDA10-3D6-E2A10-3D6-D2A10-3D6(6-3A10-3A)2(6-2AD10-3A)6-2AK10-2A6-ABE19-DIB17-2AKT18-D2A19-D120-
