model
size = 28 25 25, scale = 0.05, origin = -y
material 
  colors = A:#C66 B:#CC9 C:#C99 D:#C90 E:#996 F:#966 G:#AAA H:#999 I:#936 J:#C96 K:#993 L:#9C9 M:#963 N:#C33 O:#C36 P:#F60 Q:#696 R:#C63 S:#C93 T:#990 U:#663 V:#CC6 W:#E00 X:#888 Y:#444 Z:#F90 Aa:#699 Ab:#933 Ac:#399 Ad:#C30 Ae:#396 Af:#FFF Ag:#693 Ah:#099 Ai:#777 Aj:#D00 Ak:#CC3 Al:#690 Am:#C00 An:#666 Ao:#F06 Ap:#F36 Aq:#930 Ar:#333 As:#969 At:#F00 Au:#366 Av:#960 Aw:#C06 Ax:#360 Ay:#C03 Az:#555 Ba:#369 Bb:#660 Bc:#363 Bd:#633 Be:#F66 Bf:#C60 Bg:#F63 Bh:#C69 Bi:#F33
voxels
6-D2(T2D)KVBHBVSEG12-2(DYM)DYKMYGBVUAz12-DYMDYUDArUMYAiBGAzY12-D2MT2MD2MTUMVAiXG12-4KS3J2(S2J)2C12-4KJ11C12-3VQXC2J8C12-3BXAaJ10C12-4BEJ5C2J3C12-4BGE8C2B12-V4BEJ9B12-5B2E9B12-5BGEG8B12-6B2E8B12-C4BC2FJ7B12-JG3BCIOA7B12-FE3BCFAFC6B12-IA3BC2AFC6B12-FAC3BAIA7B12-2OJ3BANA4BGBG12-2WA3BJBiA3BE2GC12-2NJ4BJC2BC2E2G12-7BG2BC5G12-7BG2B2G2(CG)12-7B2GB4GCG10-2(2D16A2B8-)2D16AMV8-AvD16AAiK8-2K16ACJ8-EK16A2C8-QE16A2C8-AcAa2(16A2C8-2E)16A2C8-KE16A2B8-JG16A2B8-BE16A2B8-GE16A2B8-AF16A2B8-FI16A2B8-I17A2B8-F17A2B8-AF16A2B8-ON16A2B8-2W16ABC8-AbN16A2G8-AaC16A2G8-XB16AEG8-JB16A2G7-D4A12-4AV6-Y4A12-4AB6-Ar4A12-4AB6-U4A12-4AV6-K4A12-4AJ6-E4A12-4AC6-Q4A12-4AC6-Ac4A12-4AC6-Q4A12-4AC6-E4A12-4AC6-K4A12-4AB6-G4A12-4AB6-B4A12-4AB6-G4A3(12-4AB6-5A)12-4AB6-F4A12-4AB6-I4A12-4AB6-N4A12-4AB6-W4A12-4AG6-Ab4A12-4AE6-F4A12-4AG6-5A12-4AG6-J4A12-4AG5-D3A16-3AD4-M3A16-3AV2(4-M3A16-3AB)4-K3A16-3AJ4-E3A16-3AC4-Q3A16-3AC4-Ac3A16-3AC4-Q3A16-3AC4-E3A16-3AC4-K3(3A16-3AB4-E)3A16-3AB4-F3A16-3AB4-I3A3(16-3AB4-4A)16-3AB4-N3A16-3AB4-W3A16-3AB4-N3A16-3AG4-J3A16-3AE2(4-B3A16-3AG)3-D3A18-3AV2-D3A18-3AAk2(2-D3A18-3AB)2-K3A18-3AC2-E3A18-3AC2-Q3A18-3AC2-Ac3A18-3AC2-Q3A18-3AC2-E3A18-3AC2-S3(3A18-3AB2-E)3A2(18-3AB2-4A)18-3AB2-F3A18-3AB2-I3A18-3AB2-4A18-3AB2-O3A18-3AB2-W3A18-3AB2-N3(3A18-3AG2-B)3A18-3AE-D4A18-4AB2(D4A18-4AAk)D4A18-4ABK2(4A18-4ACE)4A18-4ACAc2(4A18-4ACE)4A18-4ACS3(4A18-4ABE)4A18-4ABF4A3(18-4AB5A)18-4ABF4A18-4ABN4A18-4ABW4A18-4ABN2(4A18-4ACB)4A18-4AGB4A18-4AE2(D3A20-3AB)D3A20-3ASD3A20-3AVK2(3A20-3ACE)3A20-3ACAa2(3A20-3ACE)3A20-3ACS3(3A20-3ABE)3A20-3ABF2(3A20-3ABI)3A2(20-3AB4A)20-3ABO3A20-3ABW3A20-3ABN3A20-3A2B2(3A20-3AGB)3A20-3AG2(D3A20-3AB)D3A20-3AVT3A20-3ASK3A20-3AJ2(E3A20-3AC)Q2(3A20-3ACE)3A20-3ACK3A20-3ABAe2(3A20-3ABAu)3A20-3ABX3A20-3AB2(4A20-3AC)2(I3A20-3AC)O3A20-3ACW3A20-3AJN3A20-3ABC3A20-3ABE3A20-3ACK3A20-3AGD3A20-3AV2(D3A20-3AB)T3A20-3AVK3A20-3AJ2(E3A20-3AC)Q2(3A20-3ACE)3A20-3ACK3A20-3ACAi3A20-3ABK3A20-3ABQ3A20-3ACG3A20-4AJ3A2(20-3AF4A)20-8A20-4AO3A20-3AOW3A20-3A2N3A20-3AGK3A20-3AXAl3A20-3AGT3A20-3ABD3A20-3ASM3A20-3AVU3A20-3ABM3A20-3ABK3A20-3AVE3A20-3AB3(E3A20-3AC)2(K3A20-3AC)M3A20-3ACS3A20-4AQ3A20-8A20-3AI4A20-3A2F3A20-4AI3A20-8A20-3AFO3A20-4AW3A20-3ARAq3A20-3AGT3A20-3AAcAv3A20-3AAaAd3A20-3AXT2(3A20-3AAkY)3A20-3ABM3A20-3ABK2(3A20-3ABE)2(3A20-3ACE)3A20-3AC2(K3A20-4A)Ag2(3A20-4AE)3A20-3AFAn3A20-4AAn3(3A20-3ACF)3A20-3ACN3A20-3ABW3A20-3ABN3A20-3ABAd2(3A20-3ABAj)2(3A20-3ABD)2(3A20-3AAkD)3A20-3ABK2(3A20-3ABE)3A20-3AC2(E3A20-4A)S3A20-4AK3A20-3ACAx3A20-3ACAg3A20-3ABK3A20-3ABQ3A20-3ABBc2(3A20-3ABU)3A20-3ABE3A20-3AB4A20-3ABW2(3A20-3ABAm)2(3A20-3ABAd)3A20-3ABD2(3A20-3ABU)3A20-3ASM3A20-3AVK3A20-3AC2(E3A20-3AF)K3A20-3AFE3A20-3ACS3A20-3ABAg3A20-3ABAx3A20-3ABAg3A20-3ABK3A20-3ABQ3A20-3ABBc3A20-3ABAx3A20-3ABU3A20-3ABE3A20-3ABJ5(3A20-3ABN)3A20-3ABD2(3A20-3ABU)3A20-3AVM3A20-3ASK3A20-3AJE3A20-3AFE3A20-3ACK3A20-3ABD3A20-3ABS3A20-3ABE3A20-3ABAg2(3A20-3ABQ)3A20-3ABAc3A20-3ABQ3A20-3ABAi3A20-3ABF3A20-3AB4A20-3ABF3A20-3ABI3A20-3ABF3(3A20-3ABJ)3A20-3AJD3A20-3AVD2(3A20-3ABT)3A20-3AAkK3A20-3AJ3(E3A20-3AB)S2(3A20-3ABE)3A20-3ABG3A20-3ABC3A20-3ABG2(3A20-3ABH)3A20-3ACX3A20-3ACF3A2(20-3AJ4A)20-8A20-3ANE3A20-3ARG3A20-3ASG3A20-3ARG3A20-3AWD3A20-3ASM3A20-3ABU3A20-3ABM3A20-3ABR3A20-3AVS3A20-3ABK3(3A20-3ABE)2(3A20-3A2B)3A20-3ABG3A20-3ACG3A20-3AJ2(L3A20-4A)H3A20-4AF3A20-3A2I3A20-4AI3A20-3AO4A20-3AAjR3A20-3ANR3A20-3AAd2(J3A20-3AAt)T3A20-3ADY3A20-3AAkY3A20-3ABM3A20-3ABS3A20-3AB2(D3A20-3AC)D3A20-3AJS3A20-3AFX3A20-4AL2(3A20-4AH)3A20-3AF2(H3A20-4A)L3A20-3AFH3A20-3AF4A2(20-8A)20-3AOR3A20-3AAjP3A20-3AN2(P3A20-3AW)R3A20-3AND2(3A20-3A2D)3A20-3AVD3A20-3ABS3A20-3ACQ3A20-4AK3A20-4AZ3A20-3AIN3A20-4AX3A20-4AH3A20-3AFH3A20-3AIH2(3A20-4AL)3A20-3AFL2(3A20-4AH)3A20-4AX3A20-3AF4A20-3AOR3A20-3AW2(P3A20-3AN)P3A20-3AOP3A20-4AD3(3A20-3A2D)3A20-3AVQ3A20-3ACAh3A20-3AIK3A20-3AFP3A20-4AN3A20-4AAa3A20-3AIH3A20-3AFL2(3A20-4AH)3A20-3AFH2(3A20-4AL)3A20-3AIL3A20-4AX3A20-4AF3A20-3AOR3A20-3AWP3A20-3ANAd3A20-3AOAd3A20-4AP3A20-3AKD4A18-4A2D2(4A18-4ADT)4A18-4ASQ4A18-5ABa4A18-4AI5A18-5AW4A18-5AAb4A18-4AIAa2(4A18-5AL)4A18-4AIH4A18-4AFL4A18-5AH4A18-5AL4A18-4AIH4A18-5AL4A18-5AH4A18-4A2F4A18-4AOR4A18-4AAjP2(4A18-4ANAd)4A18-4AAbP4A18-4AAb-D3A18-3AD2-D2(3A18-4A2-T)3A18-3AS2-Q3A18-3AR2-As3A18-4A2-O3A18-3AF2-At3A18-3AF2-Ab3A18-4A2-Aa3A18-4A2-H2(3A18-3AI2-Aa)2(3A18-4A2-H)3A18-3AF2(2-L3A18-4A)2-L3A18-3AF2-H3A18-4A2-F3A18-3AO2-P3A18-3AW4(2-P3A18-3AAm)3-D22AD2(4-U23A)4-M22AS4-Q22AR4-As22AI3(4-N23A)4-Aa22AI4-E22AF4-Ae22AI4-Aa22ABe4-L3(23A4-H)22AF4-L23A4-H23A4-F22AI4-P22AAj4(4-P22AW)5-T2D16A3D6-YDU16A2DA6-UDY16A2DA6-MDM16A2DS6-Q2E16A3R6-AiFO16AI2A6-3Ab17AIA6-2AnAu18AF6-2AjN16AIAF6-2AiQ16AIFA6-3K16A2IF6-3Ah18AO6-Aa2Ac18AAp6-L2H16A3J6-2LH16A2UA6-LHL16AAgMA6-3L17AOA6-2LH16A2AoO6-3H16AAwOI6-FEX17AFA6-P2R18AO6-3P16A3R2(6-P2Ad16A2ZD)6-3P16A2ZD9-2(3DT)8D12-UDUBdDZTYAeQ3D2TD12-UT2U2DMArAhAe2DT2AlD12-MT2M2DMUKS6D12-2Q2Ag4Q8R12-NAyAjAyN2AbMIA2IAIFA12-2Ab2AqAv3Al2FAF2AIA12-BaAc3AeQAgTAF2(2AI)12-2NAbMS3DFA2(I2A)12-2QAi2QK2DI2AIF2IF12-3K3TMAqAI2FIO2F12-Ah5AeAnBfAFIOA2ApA12-4AcQE2S2IAAp4A12-L2H2GHLH5AFME12-L2HL4H4AMUAgU12-LHL2HAs2AAoOJA3MAg12-HL3HBh2AAoApEI3OF12-L2H2L3HAwAo4OFI12-3H5LI6OAw12-4XH3L2(AF)2(IA)12-2RAFX3H3J4AF12-2PREF2EJGJEFUM2R12-2PBgC2GAaLEJEUBbD2Z12-2PRBCH2AhEJEAlBbD2Z12-2PJBGH2AhEJE2T3Z75-2(2Af26-2Af250-)2Af26-2Af41-
