model
size = 11 26 9, scale = 0.05, origin = -y
material 
  colors = A:#100404 B:#FFE11D
voxels
30-21(A10-)A15-5B23-2(A10-)20(2A9-)A10-A2(3-2B)11-2(A10-)A11-2(A10-)14(2A9-)A10-A2(9-2A)9-A10-A2-2B5-2B3(3(10-A)11-2(A10-)14(2A9-)A10-A2(9-2A)9-A10-A2-B7-B)3(10-A)11-2(A10-)14(2A9-)A10-A2(9-2A)9-A10-A2-2B5-2B21-2(A10-)20(2A9-)A10-A2(3-2B)33-21(A10-)A15-5B4-
