model
size = 31 29 20, scale = 0.05, origin = -y
material 
  colors = A:#30C B:#66F C:#FF9 D:#0F6 E:#001 F:#FFF G:#39F H:#EEE I:#30F J:#F0C K:#9CF L:#FCC M:#3FF
voxels
36-3B2A6-5A15-A-B-A6-2(A-)A859-7A23-12A18-4A4-7A16-3A8-3A2B15-3A10-A3B28-3B2(29-3A)28-2(3A29-)3(2A29-)2A28-3A28-2A28-2(3A27-)2(4A26-)4A27-2A206-6A23-12A18-15A16-16A15-4A5-8A14-4A7-6A2(27-5A)2(27-4A28-4A)3(27-4A)26-4A27-2(4A26-)3(5A25-)5A26-4A27-2A176-7A22-13A17-15A16-16A15-4A4-9A14-4A7-7A26-3(5A27-)4A27-5A4(27-4A)26-5A26-4A26-2(5A25-)2(6A24-)6A25-5A26-3A175-7A22-8AC4A17-15A16-16A15-4A4-9A14-4A7-6A2(27-B4A)27-5A27-4A28-3A28-2(4A27-)B2A2(B27-3A)27-4A26-2(5A25-)B4A25-5A2(26-3AB)27-2A176-7A22-11A19-14A17-4A4-7A16-4A7-3A2B15-4A9-4B28-3B29-B2(2A29-3A29-)2A29-AB3(29-2B)28-3(3A27-)2BA27-3B27-A2B28-2A265-3(4A27-)4A736-3(14A17-)3B11A17-4B10A17-4B7A3B17-4B6A4B17-3B7A4B17-10A4B17-11A3B17-14A18-12A19-12A20-10A116-4A2B24-4A4B23-5A3B23-6ABA23-8A24-6A201-26A5-26A7-2(22A9-)3AB18A9-3AB18A10-2AB14AB2A13-2(15AB15-)3(16A15-)16A16-14A3(17-B13A)18-9AB2A5(19-12A)20-10A22-8A138-26A5-20A2CAC2A7-2(18A2CAB9-)2(18A2C2A9-)18A2C2A11-18A13-18A14-4(16A15-)AB14A16-B13A3(17-B12AB)5(17-14A)18-B11A19-B11A21-8A107-26A5-20A2CAC2A7-3(18A2CAB9-)18A2C2A9-18A2C2A11-18A13-18A14-4(16A15-)AB14A16-B13A3(17-B12AB)5(17-14A)18-B11A19-B11A21-8A107-26A5-20A2C4A7-3(18AC3B9-)18A2C2A10-17A2CA12-18A13-18A14-4(16A15-)AB14A16-B13A3(17-B12AB)5(17-14A)18-12A19-12A21-8A111-18A3(13-B17A)5(13-18A)14-3(14ACA15-)14AKA15-14AKA16-3(B13A17-)14A4(17-11A2CA)17-11AC2B18-10ACB19-10A2B21-8A25-4A28-3A29-A21-5(B17A13-)3(18A13-)18A14-3(14ACA15-)14AKA15-14AKA16-4(14A17-)4(11A2CA17-)11AC2B17-11AC2B16-11A5B15-10A6B15-2(4A2-)4B15-4A3-2A3-4B15-2A12-2B14-5(B17A13-)3(18A13-)18A14-3(14ACA15-)14AKA16-5(14A17-)2(11A2CA17-)2(11A2CB17-)11AC2B17-11AC2B16-A2G7A6B15-A2G7A2BC2GB16-2GA3-A4-C2G16-A-2A8-2B-B15-2A12-2B14-3(B17A13-)2(B16AB13-)18A14-5(14ACA15-)14ACA16-3(14A17-)14A15-15AC2A14-14ACA15-12A3CA16-11A2CA2(17-11A2CB)17-11AC2B18-11AB19-G6A5B20-6A4B21-A8-B80-16A2(15-B9A5CA)15-B9A2(5CB15-10A)5CA15-10A5CA16-3A8C3A17-4A6C4A17-2B2A6C4A17-2B3A4C5A17-2B12A18-12A19-9A3B18-6A2E2A3BA17-AC8A3BA15-7A4E7A14-ALG2AEA2EAE2AGLA15-A2GC3A2E2A2B2GA16-AC3A2E7B17-2A3H2A2B2H3B17-AH3JHA2B2J3B17-AH2EJHA2BJE3B18-CME2HAB2HEAB19-2A2H2A6B21-5A3B112-4A8D4A5(15-4A8D3CA)16-3A8D3A20-8D24-6D25-6D26-4D113-2E14-2E15-2E10-2E47-2(2E12-)3E2(3-E3-2E)15-E3-4E3-E16-3E-3F4-3F-3E16-F3IF2-F3IF19-F2EIF2-FI2EF19-FBE2F2-2FEBF20-3F4-3F142-4A8-4A15-4A8-3CA2(15-4A8-4A)16-2(3A8-3A17-)3A8-3A698-5A6-5A15-5A6-5A847-
