model
size = 15 29 21, scale = 0.05, origin = -y
material 
  colors = A:#BBB B:#0F0
voxels
76-16(A14-)A164-5(A14-)2(A13-B)8(A14-)9A6-3(A14-)A134-5(A14-)A13-B7(A14-)A13-B2(A14-)A7-6A-A14-A13-B2(A14-)A119-4(A14-)A13-B9(A14-)A13-BA14-A12-A-A13-B4(A14-)A89-3(A14-)2(A13-B)11(A14-)A13-BA12-AB6(A14-)A74-2(A14-)A13-B13(A14-)A13-BA12-AB7(A14-)A44-3(A14-)A13-B12(A14-)A13-BA14-A12-A-A13-B7(A14-)A29-3(A14-A13-B)9(A14-)A13-B2(A14-)A12-A-A14-A13-B10(A14-)3(A13-B)5(A14-)A13-B7(A14-)A12-A-11(A14-)3(A13-BA14-)11(A14-)A12-A-13(A14-)A13-B14(A14-)A12-A-13(A14-)A13-B6(A14-)A13-B4(A14-)A13-B2(A14-)A12-A-A14-A13-B9(A14-)3(A13-BA14-)9(A14-)A13-BA14-A12-A-A13-B11(A14-)3(A13-B)12(A14-)A13-BA12-AB11(A14-)3(A13-BA14-)10(A14-)A13-BA12-AB13(A14-)A13-B12(A14-)A13-BA14-A12-A-A13-B7(A14-)A44-3(A14-)2(A13-B)9(A14-)A13-B2(A14-)A12-A-A14-A13-B5(A14-)A59-5(A14-)A13-B11(A14-)A12-A-6(A14-)A89-5(A14-)A13-B10(A14-)A12-A-5(A14-)A104-6(A14-)2(A13-B)8(A14-)A7-6A-4(A14-)A134-15(A14-)9A6-3(A14-)A103-
