model
size = 32 32 31, scale = 0.05, origin = -y
material 
  colors = A:#111 B:#EEE C:#700 D:#66F E:#099 F:#090 G:#AAA H:#696 I:#99F J:#C90 K:#633 L:#3CF M:#FC6 N:#609 O:#C99 P:#E00 Q:#936 R:#060 S:#033 T:#9C3 U:#555 V:#C3C W:#960 X:#63C Y:#888
voxels
238A5LA7H19A2(LA)L4AH2AH10AO3AO4A2(LA)L4AH2AH10A2O3AO12AH2AH10AOAO2AO3A5L18AO2A2O7AL2A7H21AL6AH2AH19A5L4AH2AH11A5O12AH2AH11AO11ALA3HA2H11A4O5A5L19AO11ALA7H25A2(H2A)H19A5LA2(H2A)H10A6V5A2(LA)2(H2A)H12AV6A2LAL21AV12A7H10A3V9A2LA2(H2A)H19A3L3A2(H2A)H22A2LA2(H2A)H166A4D15A2(BA)B3AQAQ962A7C2ABA8BA10B3AD14A-2A5B3AQAQ962AC5GC2ABA5B2ABA10B4AD2ADAXD3A4F9A5Q962A4CG2C2ABA5B2AB5A2B6A4DADAXD2AF4AF2A-4B422AE223AE321A3CG3C2AB6A3B5A2B11A4DAF6AFAB5A5Q416A7(E31A)E321A4CG2C2AB6A3BA10B2A4D2(6AF)2A4BAQ3AQ416AE223AE321AC5GC2ABA5B2ABA10B2(2AD)AD4AF6AFA-5A5Q962A7C2ABA5B2AB13A4DAD4AF6AFA5B422A7(E31A)E95A4(M31A)M97AC5GC2ABA8BA7BA2B7A4DA8F204AT255AE351AM161ACG5C13A7BA2B2A4D19AB166AT95AT63AT159AE255A4(M31A)M97AC5GC2A10B18A2DADA8FA5B3(AJ)192AT31AT287AE449A7C2A10B3A8B5ADAD2AD3AF10AY3(AJ)544AE191A4(M31A)M97ACGC3GC2A2B10A9B2A4DA4D4AF5AB3ABA5J416A7(E31A)E95A2(M63A)M97A3(CG)C2A2B9A2B13AD10AF4A5B198AT543A2(M63A)M97AC3GCGC2A10BA2B15A4D6AF9AJ3AJ160AT95AT63AT95A7(E31A)E321A7C2A10B2A9B3(2AD)AD7AF2A3(BA)J3AJ192AT31AT191AE127AE191A4(M31A)M97AC5GC15A8B2A2(4DA)8FA5BA5J416AE127AE191AM63AM161A3(CG)C2A2B2A6B459AE127AE223AM63AM31AM97A3(CG)C2A2B2A6BA10B2A2(4DA)8FAB5A5J192AT223AE127AE417A7C3(2A2B)A10B3AD4AD12AY4B3AJAJ160AT95AT63AT95AE319A4(M31A)M97AC5GC3(2A2B)A2(2B2A)2B2(4AD)2A8FAB5A5J192AT31AT511A2(M63A)M97ACG5C2A6B2A2BA3(2B2A)4DA4D7AF2A5B422A7(E31A)E95A2(M63A)M97AC5GC2A6B2A2BA2(2B2A)2B17AF11A3J416AE223AE321A7C13A3(2B2A)4D10AF4A5B3AJAJ416AE223AE321AC5GC2A10B13AD4AD9AF2(3AB)A5J416AE223AE321A4CG2C2A10BAO3A2O4U2A4DA4D7AF2A5B422AE223AE321A3CG3C3(2A2B)A3OAOA2UAU5AX2(AD)2A8F7A3JAJ416A7(E31A)E321A4CG2C3(2A2B)3A4O2A2U2A4D3A2-10AB3AB3(AJ)962AC5GC3(2A2B)A3OAOA2UAU2(2AD)3A2-10A5BAJA3J962A7C3(2A2B)AO3A2O4U92ARAR29ARAR27A5R54AP4A5R5AWA3WA2KAK6A3P2(3AR)13AKAK4A3P4A5R11A5K3A3P15A2NAN11A3P16AN3A2(KA)K5A3P3A2(IA)I5A5N3(AK)6AP4A2(IA)I11A5K11A5I5A5N9A5S15AN4AKAK4A3SAS3A3IAI8AN2A2(KA)K6A2S3A2(IA)I5A5NA5K3A3SAS3AIA3I19A5S13A5NA5K11A5I5AN5AKAK8AP4AI9A5NAKA3K5A3P3A5I20A3P16A3NA2(K3A)3P5A5I7A2(NA)K3AK4A3P4AI3AI5A5NA5K5A3P3A5I22AP36A5I29AI29A5I66A
