model
size = 30 31 13, scale = 0.05, origin = -y
material 
  colors = A:#FFF B:#EEE C:#111 D:#BBB
voxels
702-6D23-2D4-2D21-2D6-2D19-2D8-2D17-2D10-2D2(16-D12-D)916-D12-D16-9(D12-D916-)D12-D8-720A158-D12-D16-D12-D8-90B2(2C2B)2(C3BCB)2(CB2(C2B))2(CBC3B)3C2(B2(C2B)C)3(BC)B3C3(BC)B2C2BCB2(C2B)C2(B2C)4(BC)B2C2(BC)B3C2B2C2BC3BCB3C2B2CBC2B2(CB)C30BC4B2C2(2BC)7BC2B2(CB)4C3BC2BCBC2BC7BC2B2(CB)C2B2C2(2BC)B3C8BC2B3CB2CBC3BC2BCBC2BC7BC2B2(CB)C2B3C2B2C2B3C7B3C2(BC)B3C31B3C6BCBC3B2C2(2BC)BC2BC3BC6B3(CB)2(C2BCB)C2BC3BC6B3(CB)C2BCB3C2B3C4BC6B3(CB)2(C2BCB)CBC3B3C5BC3BC2B2C2B3C2(2BC)121B8-5(D12-D16-)D12-D38-
