model
size = 30, scale = 0.05, origin = -y
material 
  colors = A:#111 B:#FFF
voxels
-91B25(6(2-2B)2-4B)6(2-2B)2-993B12(24-2A2-2B)14(28-2B)3(28-63B-28B24-2A2-B3-2(24A6-)24A3-B2(2-24A2-2B)3(2-24A2-B3-2(24A6-)24A3-B2-24A2-2B)2-24A2-2B2-24A2-B3-24A6-24A33-B)28-3(9B2-10B2-40B-28B24-2A24(2-2B2-24A)2-2(2B28-))3(9B2-10B2-40B-28B24-2A2-B3-2(24A6-)24A3-B2(2-24A2-2B)3(2-24A2-B3-2(24A6-)24A3-B2-24A2-2B)2-24A2-2B2-24A2-B3-24A6-24A33-B28-)9B2-10B2-40B-28B24-2A24(2-2B2-24A)2-2(2B28-)9B2-10B2-40B-28B24-2A20(2-2B2-24A)2(2-2B2-10A-13A)2(2-2B2-24A)2-2(2B28-)9B2-10B2-40B-28B24-2A2-B3-2(24A6-)24A3-B2(2-24A2-2B)3(2-24A2-B3-2(24A6-)24A3-B2-24A2-2B)2-24A2-2B2-24A2-B3-24A6-24A33-B28-9B2-10B2-40B-28B24-2A2-B3-2(24A6-)24A3-B2(2-24A2-2B)2(2-24A2-B3-2(24A6-)24A3-B2-24A2-2B)2-24A2-B3-2(24A6-)24A3-B2(2-11A-12A2-2B)2-11A-12A2-B3-24A6-24A33-B28-9B2-10B2-40B-28B24-2A2-B3-2(24A6-)24A3-B2(2-24A2-2B)2(2-24A2-B3-2(24A6-)24A3-B2-24A2-2B)2-24A2-B3-24A2(6-10A-13A)3-B2(2-10A-13A2-2B)2-10A-13A2-B3-24A6-24A33-B28-9B2-10B2-40B-28B24-2A20(2-2B2-24A)2-2B2-10A-13A2-2B2-7A-A2-13A2(2-2B2-24A)2-2(2B28-)9B2-10B2-40B-28B24-2A21(2-2B2-24A)2-2B2-8A-15A2(2-2B2-24A)2-2(2B28-)3(9B2-10B2-40B-28B24-2A2-B3-2(24A6-)24A3-B2(2-24A2-2B)3(2-24A2-B3-2(24A6-)24A3-B2-24A2-2B)2-24A2-2B2-24A2-B3-24A6-24A33-B28-)3(9B2-10B2-40B-28B24-2A24(2-2B2-24A)2-2(2B28-))3(9B2-10B2-40B-28B24-2A2-B3-2(24A6-)24A3-B2(2-24A2-2B)3(2-24A2-B3-2(24A6-)24A3-B2-24A2-2B)2-24A2-2B2-24A2-B3-24A6-24A33-B28-)9B2-10B2-69B26(28-2B)28-93B25(6(2-2B)2-4B)6(2-2B)2-62B
