model
size = 32, scale = 0.05, origin = -y
material 
  colors = A:#111 B:#FFF
voxels
-130B6(6(2-2B)2-6B6(2-2B)2-70B)6(2-2B)2-6B6(2-2B)2-2181B27(28-4B)28-8(132B28-23(4B-26A-)4(4B28-))132B28-22(4B-26A-)4B-10A-15A2(-4B-26A)-2(4B28-)132B28-22(4B-26A-)4B-16A-9A2(-4B-26A)-2(4B28-)132B28-22(4B-26A-)4B-9A-16A2(-4B-26A)-2(4B28-)132B28-22(4B-26A-)4B-10A-15A2(-4B-26A)-2(4B28-)132B28-18(4B-26A-)3(4B-11A-14A-)2(4B-10A2-2A-11A-)2(4B-26A-)2(4B28-)132B28-20(4B-26A-)3(4B-12A-13A-)2(4B-26A-)10(2(4B28-)132B28-25(4B-26A-))3(4B28-)100B28-25(4B-26A-)3(4B28-)69B27-29(4B28-)69B27-28(4B28-)132B28-4B26(27-5B)28-66B
