model
size = 24 32 12, scale = 0.05, origin = -y
material 
  colors = A:#282828 B:#8E8E8E C:#010101 D:#FFF
voxels
5-3AB3A2-3AB3A7-7C2-7C7-7AC2-C7A6-7AC2-C7A7-6AC2-C6A31-8C2-8C2(6-7AC2-C7A)7-6AC2-C6A32-7C2-7C4(8-6AC2-C6A)9-5A4-5A32-8C2-8C6-C7A2C7AC5-C8A2B8AC4-8A4B8A4-3B4A2B2D2B4A3B4-2AB5A4B5AB2A4-2AB6A2B6AB2A4-2A5B6A5B2A4-2(6AB)6A4-6A8B6A4-4B5A2B5A4B4-3AB5A2B5AB3A4-3A3B3A2B3A3B3A5-4AB3A2B3AB4A7-7A2B7A8-2A12B2(2A8-2AB4A2B4AB)2A8-3B4A2B4A3B8-7A2B7A8-4A8B4A8-4AB2A2B2AB4A8-5B2A2B2A5B2(8-7A2B7A)8-4B3A2B3A4B3(8-3AB3A2B3AB3A)8-16B3(8-7A2B7A)6-AB7A2B7ABA4-A4B4A2B4A4BA3(4-4AB4A2B4AB4A)4-4A12B4A2(4-9A2B9A)4-2A16B3(2A4-2AB6A2B6AB)2A5-AB6A2B6ABA4(6-18A)6-B16AB3(6-18A)6-2B14A2B6(6-18A)6-B16AB6-18A6-B16AB5-AB16ABA2(4-20A)3-22A-192A2-20A4-2AB6A2B6AB2A5-3(18A6-)2(B16AB6-)3(18A6-)2B14A2B6(6-18A)6-B16AB6-18A6-B16AB5-20A4-20A3-22A-240A2-2AB6A2B6AB2A5-3(18A6-)B16AB4(6-18A)6-2B14A2B6(6-18A)6-B16AB6-18A6-B16AB5-20A4-20A3-22A-24AB7(22A2B)22AB24A2-2AB6A2B6AB2A5-3(18A6-)B16AB4(6-18A)6-2B14A2B4(6-B16AB)2(6-18A)6-B16AB6-18A6-B16AB5-20A4-20A3-22A-24AB7(22A2B)22AB24A2-2AB6A2B6AB2A5-3(18A6-)B16AB8(6-18A)6-B16AB2(6-18A)6-B16AB6-18A6-B16AB5-20A4-20A3-22A-B8(22A2B)22A3B20A2B2-3B6A2B6A3B5-3(18A6-)4(B16AB6-)5(18A6-)B16AB2(6-18A)3(6-B16AB)5-B18AB4-20A3-22A-B8(22A2B)22A3B20A2B2-9A2B9A5-3(18A6-)B16AB2(6-18A)2(6-B16AB)4(6-18A)6-B16AB5(6-18A)5-B18AB4-20A3-22A-24AB7(22A2B)22ABAB20ABA2-9A2B9A5-4(B16AB6-)3(18A6-)2(B16AB4(6-18A)6-)18A5-B18AB4-20A3-22A-24AB7(22A2B)22ABAB20ABA2-5A10B5A5-2(B16AB2(6-18A)6-)18A6-B16AB4(6-18A)3(6-B16AB)3(6-18A)5-B18AB4-20A3-22A-217AB20ABA2-5AB3A2B3AB5A5-B7A2B7AB2(6-8A2B8A)6-B7A2B7AB6-18B2(6-8A2B8A)2(6-B7A2B7AB)6-18B5(6-B7A2B7AB)6-2B5A4B5A2B6-18B6-8A2B8A5-2(B18AB4-)B18AB3-2B18A2B-121A2(B20AB2A)B20ABA-B20AB3-5AB3A2C3AB5A2-
