model
size = 29 16 31, scale = 0.05, origin = -y
material 
  colors = A:#222 B:#200 C:#FC3 D:#DDD E:#F93 F:#555
voxels
40-11A17-13A15-3A9B3A14-2A7B2D2B3A12-3A9BD2B3A11-2A11BDB3A4(11-2A14B2A)11-2A2BD11B2A5-2CEC4A2BF2D9B5A2-4C4A14B5A2-4C20A5-2CEC20A16-8A18-13A15-15A14-15A13-4A10-2(3A12-)2(3A11-2A13-)3A2(11-2A14-2A)11-2A14-3A10-2A14-4A3-2(CA2C6A12-5A2-)4C20A5-2CEC20A353-2A27-CAC26-3C26-2A375-2A2(27-2C)27-13(2A375-3(2A27-))2A374-4(3(2A27-)2A375-)3(A28-)A7(375-3(2A27-)2A)375-3(A28-)A376-4(A28-)
