model
size = 29 16 31, scale = 0.05, origin = -y
material 
  colors = A:#222 B:#200 C:#FC3 D:#BBB E:#F93 F:#DDD G:#555
voxels
36-11A17-13A15-3A9B3A13-3A7B2D2B2A12-3A10BDB3A11-3A11BDB4(2A11-2A14B)2A11-2A2BF11B2A8-5A2BGDF9B4ACE2C2-5A14B4A2(4C5-20A)CE2C10-8A19-13A15-15A14-4A6-5A13-3A10-4A11-3A11-4A2(11-3A13-2A)2(11-2A14-2A)10-3A14-2A9-4A14-2A8-5A12-6A2CAC2-5A12-6A2CAC5-20A4C5-20ACE2C375-2A26-CAC26-3C27-2A375-2A2(27-2C)27-13(2A375-3(2A27-))2(2A376-3(A28-)A376-2(3(2A27-)2A375-)3(2A27-))4(2A375-3(2A27-))2A2(376-3(A28-)A)
