model
size = 30 32 32, scale = 0.05, origin = -y
material 
  colors = A:#A00 B:#BBB C:#700 D:#FF0 E:#222 F:#AAA G:#888 H:#630 I:#E00 J:#EEE K:#444
voxels
424-A20-A798-4(2F28-)2F27-4(4A26-)4A687-2D147-4(A2CA26-)4A568-2(E29-)E28-2E25-8E25-2E28-E19-A9-E10-A7-3A8-E9-3A46-3(A2CA26-)AC2A27-2(G29-)G649-A20-A7-3A18-3A5-5A16-5A5-3A18-3A77-2D118-G619-A20-A7-3A18-3A5-5A16-5A3-7A14-7A3-5A16-5A6-A20-A48-2D118-G618-3A18-3A5-5A16-5A2-9A12-18A12-9A-7A14-7A5-A20-A36-26B5-3C3D4C4-4C3D3C6-2C2(DC)D3C4-3C2(DC)D2C6-C3(D2C)4-3(2CD)C17-G588-3A18-3A4-7A14-7A2-7A14-7A-9A2(12-18A)12-9A4-A20-A35-28B3-2(D24-D4-)D10C4-10CD5-2(D3C)DC-G2-C2(D3C)D547-A20-A6-5A16-5A3-7A14-7A2-7A14-7A-9A2(12-18A)12-9A-F2-A2-F14-F2-A2(2-F)5-F14-F5-F2-28B2-C26-C2-D26-D2-2C24-2C3-C11-K12-C5-10D4-10D487-A20-A7-3A18-3A5-5A16-5A3-7A14-7A2-7A14-7A-9A2(12-18A)12-9A4-A20-A35-28B2-D26-D2-C26-C2-2C24-2C3-C3-IJI5-K12-C5-D3-GJ17-D9-IJI475-A20-A7-3A18-3A5-5A16-5A3-7A14-7A2-7A14-7A-9A2(12-18A)12-9A4-A20-A35-28B2-C26-C2-D26-C2-2C24-2C3-C-I22-C5-DJ2-G18-D7-I248-4B227-A20-A7-3A18-3A5-5A16-5A3-7A14-7A2-7A14-7A-9A2(12-18A)12-9A4-A20-A35-28BF-C11-G2-G11-C2-C11-G2-G11-CF-DC10-4H10-2C3-C-J22-CF4-D2G20-D7-J247-6B226-A20-A7-3A18-3A5-5A16-5A3-7A14-7A2-7A14-7A-9A2(12-18A)12-9A4-A20-A35-28BF-C26-C2-D26-CF-2C10-4H10-2C3-C-I22-CF4-DJ21-D7-I246-8B225-A20-A7-3A18-3A5-5A16-5A3-7A14-7A2-7A14-7A-9A2(12-18A)12-9A4-A20-A35-28B2-D26-D2-C26-C2-2C24-2C3-C24-C5-D22-D59-F193-10B224-A20-A7-3A18-3A5-5A16-5A3-7A14-7A2-7A14-7A-9A2(12-18A)12-9A4-A20-A35-28B2-C26-C2-D26-D2-DC24-CD3-D-I22-D5-DJ21-D6-DI21-D6-DC20-CD7-C20-C8-C20-C133-12B223-A20-A7-3A18-3A5-5A16-5A3-7A14-7A2-7A14-7A-9A2(12-18A)12-9A4-A20-A35-28B2-D26-D2-C26-C2-2C24-2C3-C-J22-C5-D2G20-D6-CJ21-C6-2C20-2C7-C20-C8-2C18-2C9-C18-C10-C18-C74-12B223-A20-A7-3A18-3A5-5A16-5A3-7A14-7A2-7A14-7A-9A2(12-18A)12-9A4-A20-A35-28B2-C26-C2-D26-D2-2C24-2C3-C-I22-C5-D22-D6-DI21-D6-DC20-CD7-D20-D8-DC18-CD9-C18-C10-CB16-BC11-D16-D12-D16-D14-14B192-E20-E8-A20-A7-3A18-3A5-5A16-5A3-7A14-7A2-7A14-7A-9A2(12-18A)12-9A4-A20-A35-28B2(2-C26-C)2-DC24-CD3-C24-C5-D22-D6-C22-C6-2C20-2C38-C18-C10-D18-D10-CB16-BC11-D16-D12-2D14-2D13-D14BD101-4(E20-E8-)A20-A7-3A18-3A5-5A16-5A3-7A14-7A2-7A14-7A-9A2(12-18A)12-9A4-A20-A35-28B2(2-C26-C)2-2C24-2C3-D24-D5-2(D22-D6-)2C20-2C38-2(C18-C10-)DB16-BD11-D16-D12-2D-12D-2D13-D-12D-D11-7(E20-E8-)A20-A7-3A18-3A5-5A16-5A3-7A14-7A2-7A14-7A-9A2(12-18A)12-9A4-A20-A35-28B2(2-C7-G2-G4-G2-G7-C)2-2C5-6H2-6H5-2C3-D24-D5-2(D22-D6-)2C20-2C38-2(C18-C10-)DB2-12B2-BD11-D2-12D2-D12-18D13-2D12-2D221-A20-A7-3A18-3A5-5A16-5A3-7A14-7A2-7A14-7A-9A2(12-18A)12-9A4-A20-A35-28B2(2-C7-G2-G4-G2-G7-C)2-DC5-6H2-6H5-CD3-C24-C5-D22-D6-C22-C6-2C20-2C38-C3-12D3-C10-D3-2(CD)4C2(DC)3-D10-CB-B2(2CDCD)2CB-BC11-2(D-D12-)3D12-3D13-D14-D221-A20-A7-3A18-3A5-5A16-5A3-7A14-7A2-7A14-7A-9A2(12-18A)12-9A4-A20-A35-28B2-C26-C2-D26-D2-2C24-2C3-C24-C5-2(D22-D6-)DC20-CD7-D20-D8-DC2-D12-D2-CD9-C2-C12-C2-C10-C2BC12-C2BC11-2D14-2D12-2D14-2D250-A20-A7-3A18-3A5-5A16-5A3-7A14-7A2-7A14-7A-9A2(12-18A)12-9A4-A20-A35-28B2-D26-D2-C26-C2-2C24-2C3-C24-C5-D22-D6-C22-C6-2C3-D12-D3-2C7-C3-D12-D3-C8-4CD12-D4C9-2CD14-D2C10-CDC14-CDC309-A20-A7-3A18-3A5-5A16-5A3-7A14-7A2-7A14-7A-9A2(12-18A)12-9A-F2-A2-F14-F2-A2(2-F)5-F14-F5-F2-28B2(2-C26-C)2-2C6-12C6-2C3-C6-12D6-C5-2(D4-D12-D4-D6-)D4CD12-D4CD7-D3C14-3CD8-D3C14-3CD368-A20-A7-3A18-3A5-5A16-5A3-6A16-6A2-7A14-7A-9A2(12-18A)12-9A4-A20-A35-28B3-C6-2CD6CD2C6-C4-C6-CD-DC2DCD-DC6-C4-2C4-CD3-D2-D3-DC4-2C5-D4-D12-D4-D7-2(4D14-4D8-)4D14-4D428-A20-A7-3A18-3A6-3A18-3A5-5A16-5A4-5A16-5A3-2(7A14-7A2-)7A14-7A5-A20-A35-10B8-10B4-2(D4-C12-C4-D6-)D5C12-5CD7-4C14-4C548-A20-A7-3A18-3A5-4A18-4A4-5A16-5A3-7A14-7A2-7A14-7A3-5A16-5A6-A20-A8-A20-A6-7B12-7B6-2(4C14-4C8-)4C14-4C607-2(3A18-3A6-)3A18-3A5-5A16-5A3-7A14-7A3-5A16-5A6-A20-A37-4B16-4B697-A20-A7-3A18-3A6-3A18-3A5-5A16-5A4-5A16-5A5-3A18-3A7-A20-A788-A20-A7-3A18-3A6-3A18-3A5-5A16-5A5-3A18-3A7-A20-A818-A20-A7-3A18-3A6-3A18-3A7-A20-A878-A20-A7-3A18-3A543-
