model
size = 9 14 9, scale = 0.05, origin = -y
material 
  colors = A:#39F B:#909 C:#6C0 D:#0F9 E:#0C6 F:#9CF G:#6C3 H:#CF3
voxels
110-2A-2A121-5A5-B-B111-2A-3A-2A3-3B97-E13-3A3D3A-2B3-2B4-2(E8-)3(C8-)2C4(8-C)7-GFG7-C5-2ADFD2A3-B-H-B96-E13-3A3D3A-2B3-2B109-2A-3A-2A3-3B113-5A5-B-B113-2A-2A11-
