model
size = 31 23 13, scale = 0.05, origin = -y
material 
  colors = A:#EEE B:#F3F C:#008 D:#004 E:#06F
voxels
197-B-B2-B3-2B20-3B2(-B)3-B20-5(B-)B22-B2-B3-B48-2(E-)2E2-E4-E-E15-C-3(C2-)2(C-)C16-2D-2D2-D2-3D-D15-A-3(A2-)2(A-)A15-3C-2C-3C-C3-C232-17(17A14-)4A9-4A14-3A11-3A2(14-2A13-2A)76-19(A15-A14-)2A13-2A14-2A13-3A74-19(2A15-2A12-)3A13-3A12-3A13-4A72-14(3A15-3A10-)3A15-3A5-8A2(15-16A)15-8A5-3A15-3A10-4A13-4A10-4A13-5A12-A13-A43-13(4A15-4A8-)4A15-4A4-8A15-13A21-5A31-5A21-13A15-8A4-5A13-5A8-5A13-5A11-2A13-2A42-12(4A15-4A8-)4A15-4A4-8A15-13A21-5A93-5A21-14A13-9A4-5A13-5A10-3A13-3A41-12(4A15-4A8-)4A15-4A4-8A15-8A155-9A13-9A4-5A13-5A10-3A13-3A14-A13-A12-12(4A15-4A8-)4A15-4A4-8A15-13A21-5A93-5A21-14A13-9A4-5A13-5A10-3A13-3A14-A13-A12-13(4A15-4A8-)4A15-4A4-8A15-13A2-A18-5A31-5A21-13A15-8A4-5A13-5A9-4A13-4A12-2A13-2A15-2(A13-)14(3A15-3A10-)3A15-3A5-8A2(15-16A)15-8A5-3A15-3A10-4A13-4A11-3A13-3A14-A13-A45-9(2A15-2A12-)10(2A15-A13-)18A14-17A76-19(17A14-)17A100-
