model
size = 30 16 31, scale = 0.05, origin = -y
material 
  colors = A:#C6F B:#200 C:#FC3 D:#DDD E:#F93 F:#555
voxels
41-11A18-13A16-3A9B3A15-2A7B2D2B3A13-3A9BD2B3A12-2A11BDB3A4(12-2A14B2A)12-2A2BD11B2A6-2CEC4A2BF2D9B6A2-4C4A14B6A2-4C20A6-2CEC20A17-8A19-13A16-15A15-15A14-4A10-3A13-2(3A12-)2(2A13-3A12-)2(2A14-2A12-)2A14-3A11-2A14-4A4-2(CA2C6A12-6A2-)4C20A6-2CEC20A366-2A28-CAC27-3C27-2A388-2A2(28-2C)28-13(2A388-3(2A28-))2A387-4(3(2A28-)2A388-)3(A29-)A7(388-3(2A28-)2A)388-3(A29-)A389-4(A29-)
