model
size = 11 32 11, scale = 0.05, origin = -y
material 
  colors = A:#FF0505 B:#020202 C:#FFF10F D:#FFE11D
voxels
52-22(C10-)C87-5(C10-)17(2C9-)3(C10-)C37-5D56-C10-21(2C9-)3(C10-)C14-2D3-2D13-9(A10-)A13(9-2A)2(9-3(A10-)A)2-2D5-2D56-5(A10-)A14(9-2A)9-2(A10-)A9-2A9-2(A10-)A2-D7-D23-8(A10-)A15(9-2A)9-A10-A2(9-2A)9-A10-A2-D7-D56-5(A10-)A14(9-2A)9-2(A10-)A9-2A9-2(A10-)A2-D7-D12-9(A10-)A13(9-2A)2(9-3(A10-)A)2-2D5-2D54-B10-21(2B9-)3(B10-)B14-2D3-2D33-5(B10-)17(2B9-)3(B10-)B37-5D56-22(B10-)B57-
