model
size = 14 17 32, scale = 0.05, origin = -y
material 
  colors = A:#FFF B:#383838 C:#010101 D:#242424 E:#A8A8A8 F:#2F2F2F G:#303030 H:#282828 I:#888 J:#1D1D1D K:#151515 L:#111 M:#0D0D0D N:#0A0A0A O:#020202 P:#080808 Q:#CFCFCF R:#252525
voxels
18-2(5AE8-)6C9-E3F177-2(5A4E5-)9C6-7F8-2(5B9-)5G9-5H2(9-5D)9-5J9-5K9-5L9-5M9-5N9-5P9-5O7-2(5A4E5-)9C6-7F8-2(5B9-)5G9-5H2(9-5D)9-5J9-5K9-5L9-5M9-5N9-5P9-5O6-2(6A5E3-)11C4-9F6-2(7B7-)7G7-7H2(7-7D)7-7J7-7K7-7L7-7M7-7N7-7P7-7O4-2(7A5E2-)12C3-10F5-2(8B6-)8G6-8H2(6-8D)6-8J6-8K6-8L6-8M6-8N6-8P6-8O3(4-2(7A5E2-)12C3-10F4-2(9B5-)9G5-9H2(5-9D)5-9J5-9K5-9L5-9M5-9N5-9P5-9O)4-2(7A4E3-)11C4-9F5-2(8B6-)8G6-8H6-8D6-8I6-8J6-8K6-8L6-8M6-8N6-8P6-8O4-2(8A4E2-)12C3-10F5-2(8B6-)8G6-7H7-7I7-7D7-7J7-7K7-7L7-7M7-7N7-7P7-7O5-2(8A3E3-)11C4-9F6-2(7B7-)7G7-7I2(7-7D)7-7J7-7K8-5L9-5M9-5N9-P3IP9-5O6-2(8A3E3-)11C4-9F6-2(7B7-)7I7-7H2(7-7D)7-7J8-5K9-5L9-M3IM48-2(8A2E4-)10C5-8Q7-7B7-7I7-7G8-5H9-5I9-5D9-5J9-K3IK76-2(8A2E4-)10C5-8Q7-6I8-6B8-6G9-5I9-5D9-D3ID104-2(8A2E4-)10C5-8Q7-2(6B8-)6I9-5H9-5D118-2(8A2E4-)10C5-8Q7-6B8-6I8-6G9-5H9-D3ID118-2(8A2E4-)10C5-8Q7-6I8-6B8-6G9-5I9-5D118-2(8A2E4-)10C5-8Q7-2(6B8-)6I9-5H9-D3ID118-2(8A2E4-)10C5-8Q7-6B8-6I8-6G9-5H9-5D10-2D106-2(8A2E4-)10C5-8Q6-7I7-7B7-7G8-6H8-6D9-4D104-2(9A2E3-)11C4-9F6-2(7B7-)7G8-6H8-6D9-4D104-2(9A2E3-)11C3-10F2(5-9B)5-9G6-7H7-7D9-4D104-2(9A3E2-)12C2-11F4-2(9B5-)9G6-8H6-8D9-3D104-2(9A3E2-)12C3-10F4-2(9B5-)9G6-8H6-8D9-3D105-2(8A4E2-)12C2-11F3-2(10B4-)10G5-8H6-8D10-3D104-2(8A4E2-)12C2-E10F4-2(9B5-)9G6-7H8-6D10-3D104-2(8A5E-)13C2-11F3-E9B4-9B5-9G6-7H8-6R118-2(7A5E2-)12C2-E10F4-9B5-E7B6-8G7-6H9-5R118-2(7A5E2-)12C3-10F4-E8B6-7B7-E5G9-E3H133-2(7A4E3-)11C4-9F6-7B7-6B9-3E2G147-2(6A3E5-)9C5-8F7-6B9-E3B162-2(6A2E6-)8C7-6F9-3EB173-
