model
size = 26 28 18, scale = 0.05, origin = -y
material 
  colors = A:#444 B:#111 C:#555 D:#888 E:#E00 F:#222 G:#606
voxels
33-12B14-12B13-14B11-16B11-5(14B12-)3(5BE2BE5B12-)5B4-5B2(12-B)2(12-5BE2BE5B)11-6BE2BE6B9-18B7-20B4-24B-26B2-22B5-20B2(8-4B)91-10B15-12B13-14B11-16B11-8(14B12-)5B4-5B2(12-B)12-14B11-16B9-18B8-18B7-20B5-22B2-104B3-20B88-12A13-14A11-16A9-18A9-4(16A10-B14AB10-)16A11-14A10-B16AB8-18A7-B18AB6-20A5-22A3-B22AB-B3(24A2B)D22ADB2-D6ACBC2BCBC6AD5-6F8-6F61-2A10-2A11-3A10-3A9-4A10-4A7-3(B4A10-4AB6-AB3A10-3ABA6-)B4A10-4AB6-AB3A10-3ABA7-4A10-4A9-B2A10-2AB11-2A10-2A9-5B10-3A2B6-2A3B10-5A5-2BA3B10-4A2B4-3A3B10-6A3-B3A3B10-6AB2-B3A2B12-5AB-B4AB6-2A6-5A2(2B4A4B16A)3B3A4B15A2B2-B2A4BABA2BAB7AB5-2F4BCBC2BCBC4A2F2(8-4B)36-BA12-AB9-B2A12-2AB7-4A12-4A6-B3A12-3AB5-6(B4A12-4AB4-)B4A12-4AB6-B2A12-2AB9-2A12-2A11-A12-A8-5B12-2A3B4-3A2B12-5A3-2(B3A2B12-5AB2-)B3AB14-4AB2-B3A16-3AB-B3A18-3A2B2(2A9-)2A2B4A4B16A2BD3A4B15ADB2-D2A4BABA2BAB7AD5-2F4BCBC2BCBC4A2F2(8-4B)34-B2A14-2AB6-3A14-3A6-B2A14-2AB6-3A14-3A5-6(B3A14-3AB4-)2B2A14-2A2B6-2A14-2A9-B14-B33-4A14-4A4-B3A14-3AB3-2B3A14-3A2B2-2(BA)16-2(AB)2-B2A18-2AB2-BA20-AB-BA22-A2B24-2B11-2A11-2B24A6B5ABA2BAB5A5B2-3B5ABA2BAB5A3B5-2B4ACBC2BCBC4A2B2(8-4B)8-2(3A14-3A6-B2A14-2AB6-)3A14-3A5-4(B3A14-3AB4-)B3A14-3AB5-3A14-3A7-BA14-AB9-A14-A33-B3A14-3AB4-4B14-4B184-B9A6C9A2BD8ABC2BCB8ADB2-D7ABC2BCB7AD5-2D4ACBC2BCBC4A2D2(8-4B)8-2(B2A14-2AB6-3A14-3A6-)3A14-3A5-4(B3A14-3AB4-)B3A14-3AB5-B2A14-2AB7-2A14-2A9-B14-B33-4A14-4A5-2A16-2A185-B8AC6-C8A6B4AC6-C4A5B2-3B4AC6-C4A3B5-2B4AC6-C4A2B2(8-4B)9-2A14-2A7-B2A14-2AB4(6-3A14-3A)5-2(B3A14-3AB4-)B3A14-3AB5-3A14-3A6-3A14-3A7-BA14-AB9-A14-A33-4A14-4A5-2B16-2B185-B8AC6-C8A2BD7AC6-C7ADB2-D6AC6-C6AD5-2D4AB6-B4A2D2(8-4B)9-2A14-2A7-2(3A14-3A6-B2A14-2AB6-)B2A14-2AB5-2(B3A14-3AB4-)B3A14-3AB5-B2A14-2AB6-B2A14-2AB7-2A14-2A9-B14-B33-4A14-4A5-2A16-2A185-B8AC6-C8A6B4AC6-C4A5B2-3B4AC6-C4A3B5-2B4AC6-C4A2B2(8-4B)9-2A14-2A7-2(3A14-3A6-)B2A14-2AB2(6-3A14-3A)5-2(B3A14-3AB4-)B3A14-3AB5-3A14-3A6-3A14-3A7-BA14-AB9-A14-A33-4A14-4A5-2B16-2B185-B8AC6-C8A2BD7AC6-C7ADB2-D6AC6-C6AD5-2D4AB6-B4A2D2(8-4B)8-3A14-3A3(6-B2A14-2AB)6-3A14-3A5-4(B3A14-3AB4-)B3A14-3AB5-B2A14-2AB7-2A14-2A9-B14-B33-4A14-4A5-2A16-2A185-B8AC6-C8A6B4AC6-C4A5B2-3B4AC6-C4A3B5-2B4AC6-C4A2B2(8-4B)8-2(B2A14-2AB6-3A14-3A6-)3A14-3A5-4(B3A14-3AB4-)B3A14-3AB5-3A14-3A7-BA14-AB9-A14-A33-4A14-4A4-4B14-4B184-B9ABC2BCB9A2BD8ABC2BCB8ADB2-D7ABC2BCB7AD5-2D4ACBC2BCBC4A2D2(8-4B)8-3A14-3A6-B2A14-2AB2(6-3A14-3A)5-6(B3A14-3AB4-)2B2A14-2A2B6-2A14-2A9-B14-B33-4A14-4A4-4A14-4A3-2B3A14-3A2B2-2(BA)16-2(AB)2-B2A18-2AB2-BA20-AB-BA22-A2B24-2B11-2A11-2B9ABA2BAB9A6B5ABA2BAB5A5B2-3B5ABA2BAB5A3B5-2B4ACBC2BCBC4A2B2(8-4B)9-B2A12-2AB7-4A12-4A6-B3A12-3AB6-4A12-4A5-6(B4A12-4AB4-)B4A12-4AB6-B2A12-2AB9-2A12-2A11-A12-A9-4A12-4A5-5A12-5A3-B5A12-5AB2-B4A14-4AB2-B3A16-3AB2-B2A18-2AB-B2A20-2A2BA10-2A10-A2B8A8C8A2BD7ACBC2BCBC7ADB2-D6ACBC2BCBC6AD5-DB4ACBC2BCBC4ABD2(8-4B)36-3A10-3A9-B3A10-3AB7-5A10-5A6-B4A10-4AB2(6-3B2A10-2A3B6-5A10-5A)6-5A10-5A6-3B2A10-2A3B6-B4A10-4AB7-4A10-4A9-B2A10-2AB11-2(2A10-)4A10-4A7-5A10-5A5-6A10-6A3-B5A12-5AB2-B4A14-4AB2-B3A16-3AB-B3A8-2A8-3A2B24A2B8A8C8A2BD7ACBC2BCBC7ADB2-D6ACBC2BCBC6AD5-BD4ACBC2BCBC4ADB2(8-4B)37-B12AB11-B14AB9-B16AB7-20A7-2(2B14A2B8-18A8-)18A8-2B14A2B8-18A8-B16AB9-7A2E7A11-4A6E4A11-16A9-18A6-7A8-7A4-6A10-6A3-B5A12-5AB2-B4A6-2A6-4AB-B2(24A2B)D22ADB2-B7ABA2BAB7AB5-2D4ACBC2BCBC4A2D2(8-4B)64-12A13-14A11-16A9-18A9-2(B14AB10-16A10-)16A10-B14AB10-16A10-7A2G7A10-B4AGE2-EG4AB11-A3E6-3EA12-14A11-16A9-18A7-5A10-5A5-6A4-2A4-6A3-B22AB-B24A2BD22ADB2-D20AD5-2D4ACBC2BCBC4A2D2(8-4B)83-
