model
size = 21 17 21, scale = 0.05, origin = -y
material 
  colors = A:#C25100 B:#50000D C:#000 D:#005049 E:#EFEFEF
voxels
72-BDB17-2BD2B15-2(3BD3B14-)3BD3B15-2BD2B17-BDB185-2BD2B15-3BD3B13-3B3C3B11-3B5C3B3(10-2B6CE2B)10-3B5C3B11-3B3C3B13-3BD3B15-2BD2B120-3BD3B13-2B5A2B11-2B2A3C2A2B9-2B3C3-3C2B8-B3C5-3(3CB8-B2C6-)3CB8-B3C5-3CB8-2B3C3-3C2B9-2B7C2B11-2B5C2B13-3BD3B96-2B7-2B8-D2B9C2BD6-DB11CBD6-D2C9-2C5(D6-DC11-C)D6-D2C9-2CD6-DB2C7-2CBD6-D2B9C2BD8-2B7A2B12-3BD3B74-D2B7-2BD7-B2C9-2CB6-BC11-CB5-6(BAC12-CB4-)BAC12-CB5-BC11-CB6-BA12CB7-D11AD8-D2B7A2BD11-3BD3B52-2B11-2B6-BC11-CB5-BAC11-CAB4-BAC12-CB3-4(B2AC12-CAB2-)B2AC12-CAB3-BAC12-CB4-BAC12-CB5-BA12CB6-B13AB7-BC10AB9-D2B5A2BD13-2BD2B32-2B11-2B5-BAC11-CAB4-BAC11-CAB3-6(B2AC12-CAB2-)B2AC12-CAB3-BAC12-CB4-B2A12CAB5-B13AB7-B11AB9-BDC5ACDB12-7D30-3B11-3B4-BAC11-CAB3-B2AC11-C2A2(B2-B2AC12-CA)B-B2(3AC12-C2A2B)3AC12-C2AB-2(B2AC12-CAB2-)B2AC12-CAB3-B2A12CAB4-B15AB5-B13AB7-2B9A2B10-3B3A3B15-BDB2(11-3B)3-2(B2AC11-C2AB2-)B2AC12-CAB-B4(3AC12-C2A2B)3AC12-C2AB-2(B2AC12-CAB2-)B3A12C2AB3-B15AB5-B13AB7-B11AB9-3B5A3B13-2BD2B10-3B11-3B3-B2AC11-C2AB2-B2AC11-C2AB-B6(3AC12-C2A2B)3AC12-C2AB-B2AC12-CAB2-B3A12C2AB3-B15AB5-B13AB7-B11AB9-2B7A2B12-3BD3B9-D2B11-2BD3-D2AC11-C2AD2-D2AC11-C2AD-D6(3AC12-C2A2D)3AC12-C2AD-D2AC12-CAD2-D3A12C2AD3-D15AD5-D13AD7-D11AD9-2D7A2D12-7D9-3B11-3B3-B2AC11-C2AB2-B2AC11-C2AB-B6(3AC12-C2A2B)3AC12-C2AB-B2AC12-CAB2-B3A12C2AB3-B15AB5-B13AB7-B11AB9-2B7A2B12-3BD3B9-3B11-3B3-2(B2AC11-C2AB2-)B2AC12-CAB-B4(3AC12-C2A2B)3AC12-C2AB-2(B2AC12-CAB2-)B3A12C2AB3-B15AB5-B13AB7-B11AB9-3B5A3B13-2BD2B10-3B11-3B4-BAC11-CAB3-B2AC11-C2A2(B2-B2AC12-CA)B-B2(3AC12-C2A2B)3AC12-C2AB-2(B2AC12-CAB2-)B2AC12-CAB3-B2A12CAB4-B8AE6AB5-B13AB7-2B9A2B10-3B3A3B15-BDB12-2B11-2B5-BAC11-CAB4-BAC11-CAB3-6(B2AC12-CAB2-)B2AC12-CAB3-BAC12-CB4-B2A5C2-5CAB5-B6A2CE4AB7-B6AC4AB9-BDC5ACDB12-7D31-2B11-2B6-BC11-CB5-BAC11-CAB4-BAC12-CB3-4(B2AC12-CAB2-)B2AC12-CAB3-BAC12-CB4-BAC12-CB5-BA12CB6-B7AE5AB7-BC10AB9-D2B5A2BD13-2BD2B33-B11-B7-BC11-CB6-BC11-CB5-6(BAC12-CB4-)BAC12-CB5-BC11-CB6-BA12CB7-D11AD8-D2B7A2BD11-3BD3B54-2B7-2B8-D2B9-2BD6-DB11-B6(D6-DC11-C)D6-DC10-2CD6-DB9-2CBD6-D2B7C-C2BD8-2B6AC2B12-3BD3B77-7B13-B7-B11-2(B9-)2B9-2B5(8-2B10-B)8-2(2B9-)2B7-2B11-2B5C2B13-3BD3B101-B20-B57-4(2B7-2B10-)3B5-3B11-3B3-3B13-3BD3B15-2BD2B204-3(3BD3B14-)3BD3B15-2BD2B17-BDB156-
