model
size = 19 31 19, scale = 0.05, origin = -y
material 
  colors = A:#C30 B:#7C1F00 C:#922400 D:#872100 E:#222 F:#930 G:#F30 H:#D00 I:#9E2700 J:#960 K:#777 L:#A92A00 M:#B52D00 N:#555
voxels
7-5A581-11A12-3A547-5J10-13A8-9A356-N17-NEN15-5E14-5E15-3E17-E36-3B15-5B14-5F12-2J5F2J7-6A3HA5H6-4A3HA3H11-A3HA320-K17-3K15-2KE2K13-K5EK12-7E13-5E14-B3EB13-3BE3B11-3B3-3B10-2B5-2B10-2F5-2F9-J2F5-2FJ5-17A4-13A8-9A280-I17-3I15-5I13-2I3C2I13-5D13-7D12-2D3-2D12-D5-D12-B5-B11-B7-2(B9-)B8-B9-B8-F9-F7-JF9-FJ4-13G4A3-12G3A6-10GA260-C18-C16-5C14-5C13-2C3-2C12-D5-D11-3(D7-D10-)B7-2(B9-)B7-2(B11-B6-)F11-F5-JF11-FJ3-17A3-15A6-11A11-5A242-2CI2C14-2C-2C13-C5-C12-C5-C11-C7-C10-D7-2(D9-)2(D8-D9-)D8-B9-B7-3(B11-B6-)F11-F4-2JF11-FJ2-9A10G2-7A8G5-6A7G9-3A4G223-3I14-CI3-IC12-C5-C11-2(C7-C10-)C7-C2(9-D)2(8-D9-D)7-D11-D3(6-B11-B)5-B13-B4-F13-F3-JF13-FJ-19A-17A4-13A9-7A15-A4(18-M)4(18-L)18-I17-3I15-I3-I13-C5-C12-C5-C11-C7-C10-C7-2(C9-)C2(8-D9-D)7-2(D11-D6-)B11-B6-B11-B5-2(B13-B4-)F13-F3-JF13-FJ-19A-17A4-13A9-7A14-3A4(16-3M)4(16-3L)2(16-3I)15-I3-I13-I5-I11-2(C7-C10-)C7-2(C9-)C2(8-D9-D)7-2(D11-D6-)B11-B6-B11-B5-2(B13-B4-)F13-F3-JF13-FJ-19A-17A4-13A9-7A15-A4(18-M)4(18-L)18-I17-3I15-I3-I13-C5-C12-C5-C11-C7-C10-C7-2(C9-)C2(8-D9-D)7-2(D11-D6-)B11-B6-B11-B5-2(B13-B4-)F13-F3-JF13-FJ-19A2-15A5-13A9-7A223-3I14-CI3-IC12-C5-C11-2(C7-C10-)C7-C2(9-D)2(8-D9-D)7-D11-D3(6-B11-B)5-B13-B4-F13-F3-JF13-FJ2-17A3-15A6-11A11-5A242-2CI2C14-2C-2C13-C5-C12-C5-C11-C7-C10-D7-2(D9-)2(D8-D9-)D8-B9-B7-3(B11-B6-)F11-F5-JF11-FJ3-2G12A3G3-G12A2G6-11A260-C18-C16-5C14-5C13-2C3-2C12-D5-D11-3(D7-D10-)B7-2(B9-)B7-2(B11-B6-)F11-F5-JF11-FJ3-11A6H4-9A4H8-7A2H280-I17-3I15-5I13-2I3C2I12-I5DI12-7D12-2D3-2D12-D5-D12-B5-B11-B7-2(B9-)B8-B9-B8-F9-F7-JF9-FJ5-6A9H6-4A7H11-A4H282-C17-3C15-2CI2C14-C-K-C13-C-KEK-C12-K5EK12-E-3D2E13-5D14-5B13-7B11-3B3-3B10-2B5-2B10-2F5-2F9-J2F5-2FJ7-H2A6HA3H8-A6HAH337-K17-3K15-2KE2K13-K5EK12-7E13-5E15-3E17-E17-3B15-5B14-5F12-2J5F2J9-10AH12-3A359-N17-NEN15-5E14-5E15-3E17-E92-5J14-5A577-
