model
size = 32 28 32, scale = 0.05, origin = -y
material 
  colors = A:#777 B:#444 C:#CF0 D:#EEE
voxels
75-2(4B2D4B22-)3(2B6D2B22-)2B6D2B21-2DB6DB2D2(20-DAB6DBAD)19-2DA8BA2D3(18-4A6B4A)22-6B598-5(4AD4BD4A18-)5D4B5D9(18-DBD8BDBD)18-DB4D2B4DBD336-8(6AD4BD6A14-)18A14-18A15-16A17-4(14A18-)2(6A2B6A18-)D4BD2BD4BD335-8(7AD4BD7A12-)20A13-6(18A14-)2(8A2B8A14-)2AD4BD2BD4BD2A240-2(4AD4BD4A18-)4AD4BD4A14-8(8AD4BD8A10-)9(22A10-)4AD12AD4A10-4AD2(2B3D)2BD4A11-3AD2(2B3D)2BD3A175-2(4AD)4A18-14A14-22A10-22A9-16(24A8-)5AD12AD5A9-4AD12AD4A10-A3BD12BD3BA11-3AD12BD3A110-D3A3D2B3D3AD16-D14AD16-16A13-22A10-22A9-8(D22AD8-)8(24A8-)5AD12AD5A8-5AD12AD5A9-A3BD12BD3BA11-3AD12BD3A13-2AD12BD2A79-2(D14AD16-)D14AD13-4D14A4D10-4D14A4D9-D22AD6-5(2AD22AD2A4-)2AD22AD2A6-8(D22AD8-)24A2(8-5AD12AD5A)9-A3BD12BD3BA11-3AD12BD3A13-2AD12BD2A16-D12BD49-2(D14AD16-)16A13-22A10-22A7-7(28A4-)28A5-6(26A6-)D24AD6-26A2(6-6AD12AD6A)7-2A3BD12BD3B2A9-4AD12BD4A12-2AD12BD2A16-D12BD49-2(16A16-)16A13-22A10-22A7-7(28A4-)28A5-6(26A6-)D24AD6-26A2(6-6AD12AD6A)6-3A3BD12BD3B3A8-4AD12BD4A11-3AD12BD3A13-3D12B3D47-2(16A16-)16A13-22A10-22A7-28A4-28A2-224A-5(30A2-)3D24A3D3-28A4-28A5-26A6-3A20B3A8-22A11-20A13-D16BD19-8B19-2(18A14-)18A12-22A10-22A7-28A2-288A-4(30A2-)D28AD3-2(28A4-)28A5-3A20B3A8-22A11-20A13-D16BD19-8B19-2(18A14-)18A12-22A10-22A7-28A2-32AB6(30A2B)2(30AB32A-4(30A2-)D28AD3-2(28A4-)28A5-3A20B3A8-22A11-20A13-D16BD19-8B19-2(18A14-)18A12-22A10-22A7-28A2-32AB30ABC4(30A2C)30ACB)30ABD30AD-4(D28AD2-)D28AD3(3-2(28A4-)28A5-3A20B3A8-22A11-20A13-D16BD19-8B19-2(18A14-)18A12-22A10-22A7-28A2-32AB30ABC4(30A2C)30ACB30AB32A-4(30A2-)30A)3-2(28A4-)28A5-3A20B3A8-22A11-20A13-D16BD19-8B19-2(D16AD14-)18A12-22A10-22A7-28A2-32AB30ABC4(30A2C)30ACB30AB32A-4(30A2-)30A3-2(28A4-)28A5-3A20B3A8-9A4B9A11-8A4B8A13-5D2A4B2A5D19-2D4B2D19-2(D16AD14-)D16AD12-D20AD10-D20AD7-4D20A4D2-AD28ADAB6(30A2B)30AB32A-4(30A2-)30A3-2(28A4-)28A5-3A20B3A8-9A4B9A11-8A4B8A13-7A4B7A19-AD4BDA19-2(D16AD14-)18A12-22A10-22A7-28A2-AD28AD257A-4(30A2-)30A3-2(28A4-)28A5-3A20B3A8-9A4B9A11-8A4B8A13-7A4B7A19-AD4BDA19-2(18A14-)18A12-22A10-22A7-28A3-D28AD-A3(D28AD2A)D28ADA2D28A2DCD28ADC32A-5(30A2-)30A3-2(28A4-)28A5-3A20B3A8-9A4B9A11-8A4B8A13-7A4B7A19-AD4BDA19-2(18A14-)18A12-22A10-22A8-9(26A6-)26A4-4(30A2-)30A3-2(28A4-)28A5-3A20B3A8-9A4B9A11-8A4B8A13-7A4B7A19-AD4BDA21-2(14A18-)14A14-22A10-22A8-9(26A6-)26A5-3D22A3D6(4-2D24A2D)5-D24AD6-D2A20B2AD8-9A4B9A11-8A4B8A13-7A4B7A19-AD4BDA21-2(14A18-)14A14-22A10-22A8-10(26A6-)2D22A2D7(6-26C)6-D2A7BD4BD7B2AD8-8AD4BD8A11-7AD4BD7A13-6AD4BD6A47-2(16A16-)2(B14AB16-)B14AB12-5B14A5B8-B22AB7-3(B24AB6-)5(26A6-)2D22A2D7(6-26C)6-2DA7BD4BD7BA2D8-8AD4BD8A11-7AD4BD7A13-6AD4BD6A47-2(16A16-)2(B14AB16-)B14AB12-5B14A5B8-B22AB7-3(B24AB6-)3(26A6-)26A7-24A8-D22AD7(8-24C)8-DA7BD4BD7BAD9-8AD4BD8A11-7AD4BD7A13-6AD4BD6A47-2(16A16-)2(B14AB16-)B14AB12-4B16A4B3(8-B22AB)4(8-24A)3(8-D22AD)7(8-24C)8-2D7BD4BD7B2D9-D7AD4BD7AD11-7AD4BD7A79-2(14A18-)14A17-B14AB16-B14AB12-4B16A4B2(8-2B20A2B)8-B22AB3(8-24A)2(8-D22AD)9-2(22A10-)7(22C10-)D7BD4BD7BD11-7AD4BD7A13-5A2D4B2D5A81-2(12A20-)12A19-B12AB18-B12AB16-3B12A3B13-2B16A2B12-2B16A2B11-2(22A10-)3(D20AD10-)3(22A10-)7(22C10-)D7BD4BD7BD11-6A2D4B2D6A113-4A2D4A22-10A21-3(B10AB20-)B10AB18-3(16A16-)16A14-2D16A2D2(12-20A)11-3(22A10-)7(22C10-)9D4B9D176-4A2D4A21-3(B10AB20-)B10AB19-3(14A18-)14A17-D14AD2(16-16A)17-14A2(18-14C)393-
