model
size = 14 10 32, scale = 0.05, origin = -y
material 
  colors = A:#444 B:#EEE C:#111 D:#E00
voxels
31-8A5-3(2A6C2A4-)2B6C2B4-2A6C2A5-8A18-4AB2AB4A-3A8C5A4(10C4A)10C5A8C3A3(2-3AB2AB3A18-3AB2AB3A2-98A)2-3AB2AB3A18-4B2A4B2-4B7A7B9A4(4B10A)4B6A5B2-4B2A4B18-AB6ABA2-98A2-10A18-AB6ABA2-B12A2B12AB28A3B9A5B8A6B8A3B2-10B2(18-AB6ABA2-B12A2B12AB28A3B9A2B28A2-10A)18-AB6ABA2-14AB10A3B28A3B9A2B28A2-10A18-AB6ABA2-14AB10A3B28A3B9A2B28A2-2(2A2B)2A18-AB6ABA2-14AB10A3B28A3B9A2B19AB2AB5A2-2(2A2B)2A18-A3B2A3BA2-14A2(B10A3B28A3B9A2B19AB2AB5A2-3AB2AB3A18-3AB2AB3A2-5AB2AB5A)B10A3B28A3B9A2B19AB2AB5A2-3AB2AB3A18-3AB2AB3A3-4AB2AB4A-3B8A3B28A3B9A2B14A-4AB2AB4A3-3AB2AB3A32-3AB2AB3A3-2B8A2B2(2-12A)2-2B9AB2-12A4-3(2(2AB)2A48-2(2AB)2A5-B8AB2(4-10A)4-B8AB4-10A5-)8A7-6C35-A2B2A2BA5-B8AB2(4-10A)4-B8AB4-10A5-8A7-6C9-D3B22-A2B2A2BA5-B8AB2(4-10A)4-B8AB4-10A5-8A7-6C35-8A5-B8AB2(4-10A)4-B7A2B4-2B6A2B5-B6AB7-6C9-2D2B22-8A5-B8AB4(4-10A)5-8A7-6C35-8B5-B8AB4(4-10A)5-8A7-6C9-3DB22-2(2AB)2A5-4(10A4-)10A5-8A7-6C35-2(2AB)2A5-3(10A4-)B8AB4-2B7AB5-B6AB7-6C9-D3B22-2(2AB)2A5-3(10A4-)B8AB4-10A5-8A7-6C35-2(2AB)2A5-3(10A4-)B8AB4-10A5-8A7-6C9-3DB22-3B2A3B5-3B6AB2(4-B8AB4-10A)5-8A7-6C35-8A5-2(B8AB4-)10A4-B8AB4-10A5-8A31-
