model
size = 15 6 22, scale = 0.05, origin = -y
material 
  colors = A:#444 B:#222 C:#EEE D:#111
voxels
2-3AC2AC3A4-4(A8DA5-)A8DA5(49-2(3(2B-)2B4-)3(2B-)2B)49-3(2B-)2B2(2-4B3(-2B))2-2B4(-2(10A5-)C8AC5-10A2(4B-3AC2AC3A)4B)-2(10A5-)C8AC5-10A4B-3AC2AC3A4B-2(2A2C)2A4B-2(10A5-)C8AC5-2(10A2B3-)2(2A2C)2A2B3-2(2(10A5-)C8AC5-3(10A2B3-))2(10A5-)C8AC5(5-10A)3(5-C8AC)5-10C6(5-10A)5(5-C8AC)5-4C2A4C3(5(5-10A)5-3AC2AC3A)4-
