model
size = 15 29 15, scale = 0.05, origin = -y
material 
  colors = A:#C20000 B:#F9FAEE C:#FFF D:#000 E:#110101
voxels
289-2(7A8-)3AB3A8-7A8-B6A9-5A353-A7BA5-9ABA4-11A4-B10A5-8AB6-9A7-7A10-ABA323-A9BA3-2(13A2-)13A3-11A4-11A5-9A7-7A10-3A307-A11BA5(2-13A)3-11A5-B7AB7-7A130-3C8(12-3B)11-5B9-7B8-7B4-A3B2A3C2A3BAB5A3C12A2C21AB15A-13A2-13A3-11A5-9A8-5A115-5C8(10-5B)9-2(7B8-)7B4-A3B6CA3B5A6C9A5C12A3C12AC14AC8A-13A3-11A5-9A7-AB3ABA113-7C11(8-7B)4-A3B6CA3B5A6C9A6C10A5C11A2C13A2C7A-13A2-B12A3-11A6-7A10-2(E-E12-)4(C-C12-)C-C10-7C2(8-7B)6-B-7B-B4-B3(-7B-C4-C)-7B-C4-2C7B2C6-2(7B8-)7B4-A2B8C3B4A8C7A8C8A6C10A4C11A4C6A-13A2-13A3-11A6-3AB3A10-E-E100-7C11(8-7B)4-A2B8C3B4A8C7A8C4AB3A6C10A4C11A4C6A-13A2-12AB3-11A6-B6A114-5C8(10-5B)9-C6B8-7B8-4B3C4-A2B7CA3B5A6C4AB4A6C10A5C11A2C13A2C7A-13A3-11A5-9A7-6AB115-3C5(12-3B)12-3D11-D3BD10-5B10-2(BD)B9-2BDBD2B8-4B3C4-A3B6CA3B6A5C10A5C11A4C19AB-13A2-13A3-11A5-9A8-2AB2A291-A5B2C4BA2(2-5A3C5A)2-7AC5A2(2-13A)3-B10A5-9A7-7A306-A9BA3-2(13A2-)13A3-11A4-11A5-9A7-6AB10-3A309-A7BA5-11A4-10AB4-B10A5-9A6-9A7-7A10-B2A325-7A8-AB5A2(8-7A)8-5ABA9-5A65-
