model
size = 11 23 28, scale = 0.05, origin = -y
material 
  colors = A:#EEE B:#111 C:#444 D:#C39 E:#39F F:#222
voxels
168-5C5-2C3-4(C5-C4-)C5-C3-C6-4C162-5C6-C3-2(C5-)3(C4-C5-)C4-6C170-6A5-3A2-A5-A4-2(A5-)3(A4-A5-)A5-5A170-6A3(5-A4-A)2(5-A)4-2A3-2A5-A3-2A5-5A7-3A160-6A3(5-A4-A)2(5-A)4-2A3-2A5-6A5-5A7-3A171-4A-3(A5-A4-)2A4-3A-3A5-6A5-5A7-3A182-5A6-A4-A5-2A2-3A4-3A-3A5-6A5-5A7-3A184-3A7-5A6-A2-3A5-2A-3A5-6A5-5A7-3A18-20(5A6-)5A26-6(3A3-3A2-)12(B2A3-3A2-)3(3A3-3A2-)9A2-9C-2A4(7-4A)7-2ABA12(7-4A)7-2ABA3(7-4A)7-2A2C7-2CA4(9-2A)4(9-AB)9-BA2(9-2A)4(9-AB)2(9-2A)9-AB3(9-2A)9-AC9-CA4(9-2A)2(9-AB9-BA9-2A)9-AB9-2A9-AD2(9-2A)2(9-AB9-2A)2(9-2A)9-AC9-CA2(9-2A)2(9-BA)4(9-2B)9-BA9-2A9-AB3(9-AD)2(9-2A9-AB)3(9-2A)9-AC9-CA4(9-2A)9-AB2(9-2A)9-AF2(9-BA)9-2B9-BA9-BD2(9-2A)2(9-AB9-2A)2(9-2A)9-AC9-CA4(9-2A)9-AB2(9-2A)9-AF2(9-2A)9-AB9-BA9-AE2(9-2A)2(9-AB9-2A)2(9-2A)9-AC9-CA4(9-2A)4(9-AB)2(9-2A)9-2B3(9-AE)2(9-2A9-AB)3(9-2A)9-AC9-CA4(9-2A)2(9-AB2(9-2A))9-AB9-BA9-AE2(9-2A)2(9-AB9-2A)2(9-2A)9-AC9-CA4(9-2A)4(9-AB)3(9-BA)2(9-2B)2(9-AB)2(9-2A)9-AB3(9-2A)9-AC9-C2A4(7-4A)7-2ABA12(7-4A)7-2ABA3(7-4A)7-2A2C7-2C-6(3A3-3A2-)12(B2A3-3A2-)3(3A3-3A2-)9A2-9C4-20(5A6-)5A194-3A7-5A5-7A4-3A-3A4-7A5-5A7-3A171-A10-A-4A5-6A5-7A4-3A-3A4-7A5-5A7-3A171-6A5-A4-A5-6A5-7A4-2A2-3A4-7A5-A-3A2(7-3A160-6A3(5-A4-A)5-2(A4-2A4-)A4-2A5-A2-2A)7-3A160-6A5-3A2-2(A5-A4-)3(2A4-A4-)2A4-A3-2A5-5A15-
