model
size = 13 18 15, scale = 0.05, origin = -y
material 
  colors = A:#FF0 B:#FFEC1A
voxels
18-A-A10-ABA9-2(BA)9-2B2A8-2ABAB8-BAB2A8-A3BA8-BA2BA9-2(AB)8-2(BA)B8-BAB2A8-2A2BA9-3B62-2A2BA7-4AB2A5-B7A5-B6AB5-B5A2(2B5-6A)2(BA5-B5A)2(2B5-6A)2(2B5-B5A)BA5-B5A2B5-BA3BAB7-ABA2B34-2ABA3B5-2A3BA3B3-2ABA2BA4B2-2(A2B)A3BA2-2ABA2B2(AB)A2-2ABA2BABA2B2-BA5BA3B2-2(AB)A2B2(AB)2-2B2(AB)2ABAB2-AB2A2B2ABAB2-2A3B3ABAB2-2(2B2A)BAB2(2-4A2B2AB2A)2-6ABAB2A2-6AB2ABA3-A2B2ABA2B5-AB4AB121-3(10AB2-)2(B9AB2-11A2-)11A3-AB4AB2A120-10AB2-11AB-B9AB2-10AB2-B10A2-B9AB2-B10A2-11A2-B2AB7A118-11ABA-11AB-B10AB-2(10AB2-B10A2-)11A2-2(B2A)B4A105-A12-B12-A11-B-11AB-10AB2-B10A2(2-11A)2-B10A2-B3AB5AB118-B11-2A11-B-11AB-12A-B10A2-B9AB2-11A2-B10A2-B3AB6A105-B12-B11-BA11-AB11AB-B10AB-11A2-B9AB2(2-11A)2-2(B4A)B105-2(B12-)B11-2B12A-B10A2-11A2-10AB2(2-11A)2-2(B4A)B105-A12-B12-A12-B11AB-B9AB3(2-B10A)2-B9AB2-6AB3AB118-A12-B13-B9AB2-10AB2-B10A2-10AB2-11A2-B10A3-5AB3A109-8A4-AB7AB2-2B2A3B3AB2-B10A2-2B8AB2-2B9A2(2-B10A)3-3ABAB3A5-4AB2A111-5AB7-6A6-2B5A6-B5AB6-5ABA6-B4ABA6-7B6-3A2B2A11-BA125-A2B10-2AB10-B2A9-4B9-A3B9-2A2B57-
