model
size = 32 25 26, scale = 0.05, origin = -y
material 
  colors = A:#EEE B:#BBB C:#AAA D:#DDD E:#888 F:#777 G:#555 H:#100 I:#800 J:#111 K:#FC3 L:#F60 M:#A00 N:#700 O:#F30 P:#F93 Q:#222 R:#B00
voxels
424-3AD28-A-AD2C29-DC-E29-2C-F85-B31-2B31-BO30-OCE480-2AD29-2A-CE28-ADCEF29-CEF697-3AD28-A-AD2C29-DC-E29-2C-F85-B31-2B31-BO30-OCE509-CEG29-C-G90-A-A8-E20-A-A9-I20-2AD30-AD31-2L517-2A23-C-B4-A24-C-B26-3A29-A-A29-3A6-BC-K20-2A6-BC30-BC-I27-AB29-A31-AG30-AG32-F384-A-D27-3A-DB2C19-BCD5-2ADB18-2AB-D2-2A22-A-2A28-A-A30-A7-BC-P29-CEK29-C-P27-AB29-G33-F29-A2(-F30-I)K352-A-BC26-2A-DB2C18-2ABD2-3A-AD-C17-A-ABD2-2A6-I18-A4-AB6-PI15-3A4-A3(BC30-)B61-GA30-A-G29-2AG30-AGF30-2K353-DB29-ADBC19-4A-FG2-2ADB-L16-2(2A-)F-C5-CL17-2A3-FGC29-FGC696-2ADCEFG25-4AE8-C19-2(A-)FG30-FG700-C29-3A29-ADAEFG356-2A30-2A186-A28-4A26-2(6A3-4A19-)6A3-4A28-4A13-A5-2A8-2A13-2A4-ADAEFG20-2A22-B7-2A30-2A22-B8-A233-2A3-3A23-3A3-3A23-2A4-A25-2A4-A24-3A3-2A24-4A2-2A25-3A2-2A23-6A-3A20-8A-5A19-14A18-15A17-16A10-2A5-18A7-2A3-A-15ABCA6-2A5-D-14AB4C4-2A14-4A2-A2B2CB4-2A20-AB2CB5-2A20-ABA2B5-2A20-A4B5-5A18-3B7-A2B20-B146-A5-A25-A30-A31-A30-3A2(30-2A)28-5A25-15A18-15A17-17A15-17A10-2A3-16AB3A6-22AB2Q2A10-17AB6C17-8AB7E22-2AB4H6-A18-2A5B6-3A17-A5B7-2A2O15-A4B7-BI390-2A26-15A17-17A16-17A10-2A3-17A10-2A-18AB4A9-3AD14AB3JA10-D16A8B8-B7-8AB7AC21-2AB5H24-2AB4N7-2A17-AB4M7-2AO16-A5B426-16A16-17A16-16AB15-16AB11-2A2-16AB4A6-21AB4J2A4-A3-D16AB6HA2-2A12-8A8BH-2A18-2A6B5-A18-2A5B6-A19-AB4R26-A5B205-2A12-2A15-2A12-2A16-A12-3A17-A10-3A18-2A8-3A19-3A7-3A18-5A5-4A16-16A2(16-17A)15-17A10-2A-18AB4A9-18AB3JA10-D16A8B8-B7-8AB7AC21-2AB5H24-2AB4N26-AB4M26-A5B204-4A11-2A15-2A12-2A16-A12-2A18-A10-2A19-2A8-2A20-3A7-2A19-5A5-3A17-7A3-5A18-15A17-17A15-17A10-2A3-16AB3A6-22AB2Q2A6-A3-17AB6C3-2A12-8AB7E2-2A18-2AB4H25-2A5B26-A5B7-2A17-A4B7-BI197-2A159-2A29-4A25-7A4-3A19-14A18-15A17-16A10-2A5-18A7-2A3-A-15ABCA6-2A5-D-14AB4C4-2A14-4A2-A2B2CB4-2A20-AB2CB5-2A20-ABA2B5-2A20-A4B5-5A18-3B7-A2B20-B401-2A27-2(6A3-4A19-)6A3-4A28-4A13-A5-2A8-2A13-2A4-ADAEFG20-2A22-B7-2A30-2A22-B8-A614-C29-3A29-ADAEFG729-2ADCEFG25-4AE8-C19-2(A-)FG30-FG643-DB29-ADBC19-4A-FG2-2ADB-L16-2(2A-)F-C5-CL17-2A3-FGC29-FGC641-A-BC26-2A-DB2C18-2ABD2-3A-AD-C17-A-ABD2-2A6-I18-A4-AB6-PI15-3A4-A3(BC30-)B61-GA30-A-G29-2AG30-AGF30-2K351-A-D27-3A-DB2C19-BCD5-2ADB18-2AB-D2-2A22-A-2A28-A-A30-A7-BC-P29-CEK29-C-P27-AB63-F29-A2(-F30-I)384-2A23-C-B4-A24-C-B26-3A29-A-A29-3A6-BC-K20-2A6-BC30-BC-I27-AB29-2(A31-)A475-CEG29-C-G90-A-A8-E20-A-A9-I20-2AD30-AD31-2L152-
