model
size = 32 17 20, scale = 0.05, origin = -y
material 
  colors = A:#F33 B:#F63 C:#F93 D:#111 E:#DDD F:#F66 G:#F96 H:#F30 I:#F99 J:#FC9 K:#C96 L:#444 M:#100 N:#FC3 O:#888 P:#FC6
voxels
39-A507-2A12-A-2A12-3A13-3A90-CA19-2A8-3B20-A8-2A339-2AB12-A-2A12-3AF11-5A13-A12-3A16-B12-AB18-2A8-BCJB18-2A8-2BIB18-2A8-3A20-A316-3A13-A-2A12-2A13-5A12-2A12-3A16-B12-AB17-3A8-BCJB17-3A8-2CIB17-3A8-3AB18-2A8-3A170-2(D31-)D86-2(3A29-)A49-2A8-BCJB17-3A8-2CIB17-3A8-3AB17-3A8-4A69-IB28-AFCBK27-BC2AC-D25-BC2AHLFE25-3A-LFE26-A2-LCE30-D168-A10-CJB17-3A8-2CIB16-4A8-3AB17-3A8-4A17-2A10-3A3-2BJ2G26-HBFIBGB25-2AFCBKCAD23-ABC2AC2BE23-ABC2AHBFE23-AB5AFE24-5ABCE25-3A-LCE30-D135-3A29-4A7-3AB16-7A3-5AB16-16AC16-17AC2B4AC9-15AHBFIBMBCJ17-8AFCBKCDI2A18-4ABC2AC2BE2A18-4ABC2AHBFE22-2AB5AFD22-AB5ABCE23-6ABCE30-D135-4A6-2A19-16A16-17A15-17A16-26A6-26A2G11-19AMA18-14A18-12A20-4AB5AFD22-AB5ABCD23-6ABCE30-D135-12A18-17A16-17A15-20A13-27AC4-27AGA5-25AB2A16-13AC2A16-15A17-4AB5AFEH20-2AB5ABCE23-6ABD167-12A18-17A15-19A14-20A12-B27AD4-27AGCA4-25ABCA16-13A2C17-16A16-4AB5ADAH21-AB5ABD2A22-6AB168-12A18-18A14-2(20A13-)B26AD4-27AGCA4-25ABCA16-13A2CA16-16A16-4AB5AFAH21-AB5ABC2A22-6AB168-12A18-17A15-2(19A14-)B26AD5-26AGCA5-24ABCA16-13A2C17-16A16-4AB5ADAH21-AB5ABDA23-6AB169-BAB6-2A18-6AB10A15-A-16A15-19A14-B26AC5-B17AFI6AGA10-12AFC6ABCA15-5ABC7A2CA15-5ABC9A17-4AB5AFEH20-2AB5ABCE23-6ABD169-B27-5AB7-4A15-6ABA3-AC2BABA15-17A16-AB24A8-B14AHBFIBMBCJ2G16-7AFCBKCDIMB17-5ABC2AC2BE2A17-5ABC2AHBFE20-4AB5AFD22-AB5ABCD23-6ABCE30-D144-3A18-2B2A3-A2-CBA3-B16-4A2-A2-3A3-F16-4A-BAO-PG3-3B16-2A2-B3A-A3-7B5A20-6ABNBMBCJ19-7ACBKCDI2A17-9AC2BE2A17-9AHBFE22-8AFD22-7ABCE23-6ABCE30-D20-2A30-JA86-2A-NBGB20-2B3-3ACBKA19-4A2-5ACB19-A-2A2-5AH21-3AB-3A2-BA5-3BC2G10-2AB6-A6-2ABNBAB24-4ACBKCD12-2A9-6AC2BE22-6AHBFE23-7AFE23-6ABCE24-5ALCE30-D11-3A5-A-2A20-2B5-5A20-2B4-ACA23-2B4-AG25-2ABNBMB25-3ACBKA20-2AB2-3A-ACB19-5A-3A-AHB20-A-3A5-A22-4AB12-4B14-2AB12-4A14-2A11-5A-D25-4A-LAE24-4A-LAE25-3A-LAE30-D43-4A4-A-2A20-3A4-5A20-2A4-ACA23-2B4-AG24-3ABNBMB26-2ACBAC21-A4-4AC21-2A2B2-2A2-H22-3AB29-3A2(31-AB)49-2(D31-)D75-4A4-A-A21-3A5-3A87-2B-2A27-CBGA28-2A26-2(B30-2A)B255-2A30-2A504-
