model
size = 17 28 31, scale = 0.05, origin = -y
material 
  colors = A:#063 B:#010 C:#111 D:#CF0 E:#100 F:#690 G:#9C0 H:#C60 I:#CC0 J:#EEE K:#F90 L:#C90 M:#633 N:#990 O:#222 P:#FF0 Q:#F96 R:#960 S:#390 T:#360 U:#330 V:#444 W:#DDD X:#888 Y:#AAA Z:#200 Aa:#660 Ab:#020
voxels
89-9A7-3(11A6-)10A2(8-9A)11-4A332-2(11A6-)11A5-13A5-3(11A6-)11A7-9A10-6A12-4A282-9A7-11A5-5(13A4-)13A5-12A5-11A7-9A9-8A10-6A13-2A248-11A5-7(13A4-)13A5-12A5-11A7-10A8-8A10-6A12-4A214-9A7-11A5-13A4-13A3-2(15A2-)15A3-2(13A4-)14A3-14A4-12A5-11A7-10A8-8A10-6A11-6A13-2A180-11A5-13A4-13A3-6(15A2-)13A2(2B3-12A)2B4-12A5-12A6-10A8-8A9-8A10-6A12-4A146-9A7-11A5-13A3-5(15A2-)2(13A2B2-)13AE3-13A3B2-14A3-14A4-12A5-11A7-10A-C5-10A-C6-8A10-6A11-6A13-2A112-11A5-13A4-13A3-4(15A2-)2(13A2B2-)13AN3-13A3B2(-16A)2-14A3-12A-A4-10AC2(6-10A2C)5-10A8-8A9-8A10-6A110-11A5-13A3-4(15A2-)13A2B2-13AF2(3-13AE)2-14A3B2(-16A)2-14A3-11AC5-11ACW5-10ACY5-10A3C5-10A7-10A8-8A9-8A12-2A95-11A5-13A3-2(15A2-)15A-2(14A3B)14A2(2D2-13A)E2-14A3B17A-16A-13A2-A2-11AC2M3-11AC2K3-11ACHK4-10ACVC4-11A2C5-10A7-10A8-8A11-4A13-4A61-9A7-11A5-13A3-15A2-15A-31A3B14A2D-14A2G-14AZ2-14A2D-14A2S-14A3B-16A-12ACJ-A-12AC2R3-11ACNH3-11ACLH4-10ACOC4-11A2C4-12A6-10A7-10A8-7A12-4A14-2A45-9A6-13A4-13A3-15A2-15A-31A3B3(14AE2-)2(14A2I-)14A3B17A-12ACJ-A-12AC2H2-12AC2P3-11AC2L3-11A2OC4-2(12A5-)12A6-10A7-8A11-6A12-4A14-2A28-9A6-13A3-2(15A2-)15A-14A3B14A2F-14A2D-14A2F-3(14AE2-)14A3B17A-16A-12ACJ3-12AC2Q3-11ACMC3-12AC4-14A4-12A5-12A6-10A7-9A10-6A11-6A12-4A26-11A5-13A3-15A2-15A-31A3B14A2G2(-14A2D)-14A2Aa-2(14AE2-)2(14A3B)17A-12ACJ3-12ACXC3-12AC4-14A3-14A4-2(12A5-)12A6-9A9-8A10-6A12-4A26-11A5-13A3-15A2-15A-31A3B14AN2-14AU2(2-14AE)2-14A2F-14A2D-14A2G-14A3B17A-12A3C2-13AC-A-16A2-2(14A3-)14A4-2(12A5-)10A2(9-8A)10-6A12-4A9-11A5-13A3-15A2-15A-31A3B14AT3(2-14AE)2-14A2I-14A2D-14A2G-14A3B17A3(-16A)2-2(14A3-)14A4-2(12A5-)10A2(9-8A)10-6A12-4A9-11A5-13A3-15A2-15A-31A3B14A2G2(-14A2D)-14A2U-2(14AE2-)14AAb2-14A3B17A-16A-14A-A-16A2-2(14A3-)14A4-12A5-12A6-9A9-8A10-6A11-6A12-4A9-11A5-13A3-15A2-15A-31A3B14A2F-14A2D-14A2I-3(14AE2-)2(14A3B)17A-12A3C2-13AC4-2(14A3-)14A4-2(12A5-)12A6-9A9-8A10-6A11-6A13-2A11-9A6-13A3-2(15A2-)15A-31ATDB3(14AE2-)14A2F-14A2D-14A3B17A-16A-12ACJ3-12ACXC3-12AC4-14A3-14A4-12A5-12A6-10A7-9A9-8A10-6A12-4A27-9A6-13A4-13A3-15A2-15A-31A3B14A2D-14A2T-14AZ2-14A2D-14A2F-14A3B17A-13A2-A-12ACJ3-12AC2Q3-11ACMC3-12AC3(5-12A)6-10A7-9A10-6A11-6A12-4A27-9A7-11A5-13A3-15A2-15A-31A3B14A2S2(-14A2D)-14AE2-14A3B17A-16A-12ACJ-A-12AC2H3-11AC2P3-11AC2L4-10A3C4-12A5-12A6-10A7-10A8-7A11-6A12-4A14-2A44-11A5-13A3-2(15A2-)15A-31A3B14AI2(3-13AE)2-14A3B17A-16A-12ACJ-A2-11AC2R3-11ACNH3-11ACLH4-10ACOC4-11A2C5-10A7-10A8-8A9-7A12-4A14-2A61-11A5-13A3-5(15A2-)13A2B2-13AE3-13AN2-14AG3-13A3B-16A2-14A3-11AC2M3-11AC2K4-10ACHK4-10ACVC5-10A2C5-10A8-8A9-8A11-4A13-4A77-11A5-13A4-13A3-5(15A2-)2(13A2B2-)13AE3-13A3B-16A2-14A3-11AC6-10ACW5-10ACY6-9A3C5-10A8-8A9-8A10-6A13-2A96-9A7-11A5-13A3-7(15A2-)13A3B-13A3B2-12A2B3-14A4-12A5-10AC7-9A2C6-10A2C6-8A10-6A11-6A13-2A129-11A5-13A4-13A3-6(15A2-)15A3-14A3-12A2B4-12A5-12A6-10A8-8A2-C6-8A2-C7-6A12-4A163-9A7-11A5-13A4-13A3-2(15A2-)15A3-2(13A4-)14A3-14A4-12A5-11A7-10A8-8A10-6A11-6A13-2A197-11A5-7(13A4-)13A5-12A5-11A7-10A8-8A10-6A12-4A231-9A7-11A5-5(13A4-)13A5-12A5-11A7-9A9-8A10-6A13-2A265-2(11A6-)11A5-13A5-3(11A6-)11A7-9A10-6A12-4A317-7A9-9A7-2(11A6-)11A7-9A8-9A11-4A261-
