model
size = 27 4 25, scale = 0.05, origin = -y
material 
  colors = A:#DDD B:#111 C:#E00 D:#777
voxels
9-A4CAB2(20-A2(C2A))20-A4CAB18-AB7-2B16-AB7-AB16-2B7-AB16-AB7-2B14-BA11-AB12-2B2(11-AB12-BA)11-AB11-A15-A10-A15-B2(10-A15-A)9-2(A17-A8-)A17-B8-A17-A7-4(2A18-B6-)3(A19-A6-)A19-A5-5(A21-C4-)2(A21-A4-)A21-C3-B23-C2(2-B23-A)2-B2(23-C2-A)23-C2-B2(23-C2-A)23-A2-B2(23-A2-A)23-A4(2-B23-B)2-A23-A2-A23-B2(2-A23-A)2(2-C23-A)2-C23-B2-C23-A2-C2(23-B2-A)23-B2-C23-B3-C2(21-A4-A)5(21-A4-C)21-A5-4(A19-A6-)3(B19-A6-)B19-A7-2(A17-A8-)B17-A8-A17-A9-A15-A2D3A5-B15-A2D2A6-A15-A2D3A5-A15-A2D4A5-BA11-AB3D9-BA11-2B2(3D9-BA11-AB)3D11-2B2(7-BA16-BA)7-2B16-2B7-BA18-BA4C2(A20-2(2AC))A20-BA4CA11-
