model
size = 19 31 21, scale = 0.05, origin = -y
material 
  colors = A:#FFF B:#FC6 C:#C60 D:#FC9 E:#EEE F:#930 G:#FFC H:#F93 I:#200 J:#100 K:#FC3 L:#300 M:#500 N:#400 O:#F90 P:#600 Q:#C30 R:#700 S:#800 T:#C93 U:#630 V:#F96 W:#C63 X:#FCC Y:#444 Z:#F33 Aa:#C33 Ab:#F00 Ac:#AAA Ad:#B00 Ae:#F60 Af:#C96 Ag:#960 Ah:#900 Ai:#963 Aj:#CCC
voxels
187-I464-N18-2P41-M23-A18-L18-3J44-L3-L14-L7-2L370-2L3-L13-2M2(3-M)9-P8-P9-R3-3F2-PA11-5F-F2(2A10-5C2-)2AL10-3C3-3J18-J18-I6-2(S3-)2S9-2(M3-)2M9-2F7-F10-F7-F10-2F6-F38-L274-2M7-L8-NR2-5S-RN6-L3-3F5-PL6-N2-8C2A8-H-7HA-Z7-9BAd-Ad7-9BM-M7-9B3J4-M3-7D-3J4-N4-5D4-J3-2I-Q8-Q-2I3-2I-F8-F-2I3-2IN10-NI6-2I9-2I8-2C3-C2-C38-Q8-U-2(U3-)U236-2L2(3-L)9-L2-5S-L8-N2-7Q-N9-9C2A7-10KA-Z6-10DZNM6-10GM2J6-10EJ2Y6-10EY2J7-9A3J4-F3-7E8-LS3-5X9-LM10-ML6-N10-N8-IR7-RI8-FPB3-B2-P47-F-F3-F12-2R2(3-R)9-L4-L203-2I-5P2I11-7F11-9C9-11BA6-11G2AAa5-11A2Aa2-NPF-11A2NJ-PF2-11A3J5-11A3JIPFC2-10AJ3-PSC3-9A11-7E13-5E49-C2R5-2R6-RCNPBFW-B2-KP-P16-N8-UI-I3-B2-I28-C4-C13-C4-C14-U3-U33-U2-O16-F-C37-B54-I4-I11-I-7SI10-9C9-11H7-13D6-13A6-11AAb-Ab5-11AAb-S5-11AS7-11AI2J5-11E2J7-11G9-6BC2B11-5HPNCR15-NIQL15-IU17-F2-B9-P8-P18-O9-B-CO2-B-O10-B-F2-B-F11-LIM4-M11-CIN2-C13-CU3-C17-C131-3M12-M8FM9-11O7-13B6-13G6-13A5-14A6-10A-2Ac5-11A-3J5-11A2J6-13A6-13E5-B-11H3-NP-PK-4C2BPBCR4-2(NO)B3-CBONCQL6-CO4-OC-F10-PF4-FP10-CIM-CK-MIC2K11-Q2-NIQ9-F2-BF2BMUF12-3B2-B13-2K2C-K2C11-2C2Q-C2Q11-UC2F-U14-2M-Ag2M12-LN111-2L-3PIP-L9-P8CP9-11H7-13D6-13E5-14A5-13AE5-12AAj2J4-12A3J4-14A2(6-13A)7-11G7-2K4D2K3D9-B2-5B8-K3-K2-2B10-T4-T2-2BT9-F-2CFK-C2FK8-M-2QM2-QCM9-L-2FL-BFCWK2-W14-T12-2BKB-BF12-2KCK-VM12-2CUC-TL12-CAgC-BF14-NW2-W15-C18-Ai-B70-L2-5R-L10-9C9-11H7-13D6-13EI4-2(14A5-)12A7-15A4-15A5-13A6-13E7-11G9-9D12-5D11-K2-W16-T3-B11-RCBFB-BK3-2K-P4-VQCMV-KC2V9-T2-LT-CU2T16-2V16-B15-2B-KBV13-2K-CKT15-C2B14-UC4B14-F3B16-TAfB2(16-3B)32-L2-5R-L10-9C9-11H7-13D6-13EI4-2(14A5-)12A7-15A4-15A5-13A6-13A7-11D9-9B6-B5-5B8-B3-2B19-V19-B16-VBK6-B9-TKC-2B3-B12-V17-B18-KBV16-CKT13-B-C2B17-2O17-CAe16-TCB17-2B37-W13-2I2-2RI2-I9-R8CR9-11O7-13D6-13G6-13E5-13AE5-12AAj2J4-12A3J5-2(13A6-)13A7-11D4-P-2K-5DBDBCR5-O4-B-C3BCQL5-B3-2B13-V4-2V19-B12-B3-VBK-2B9-K3-TKCW3K13-B18-KB2-F12-2VCK-VM12-2TUC-TL12-BAgC-BF14-NW2F16-3C16-T18-2F52-2I2(3-I)9-P-7QP10-9C9-11B7-13D6-13E6-13A6-11A2Ac6-11A3J5-11A2J6-13E7-11E9-9G9-K-3DK3D7-C18-W2-KW-WB15-T15-B2-F2(BK)2B2K7-K2-MVBKC2KB8-C2-LTBCU2C3-K8-T2B2-T13-2FC2-F2C11-MCQ2-M2Q12-CF2-L2F11-CM2-FM13-LNC18-F24-Ai68-I4-I11-N2-5F-N11-7Q11-9H9-11B7-11GAG6-11GA-Ab2-P2-11DAb-S5-11ES7-11AI2J-PF3-10AJ4-S4-9E11-7G9-2K2-2X2KX27-B3-B2-2B-B8-B4-B2-3B2-B6-K3CKB2C2K-KP-P4-C3QCB2Q2CBONO5-U-2FUC2FCU-OC10-PF16-CIM2-C-MIC9-QIN2-Q13-FUM2-F12-2MP18-UFO-B14-F2CAe16-TAf18-B52-2I2(3-I)9-2I6-2I12-5S13-7C11-9H2A7-10BA2Aa6-10BAa4-PF2-10DN2J6-10D3J2-Q3-10D3J2-FC3-9D5-SC4-7D8-B4-5B9-2(P8-)BO17-BCO-B2-OC-B9-BPFCB2-F-B2R7-RIMPF2-MILK2(PN)4-CI2NC2-NI2CNIN5-C-MIC3-UC-2I9-F3-F4-F9-M3-M14-N7-N10-M38-CFO-B15-2CAe16-TAfC16-F72-2L2(3-L)9-2(L8-)N3-5F2-N10-7C-2A8-9OZ-Z7-9HMNM7-9H3J7-9H3Y7-9B3J8-7K-3J4-F4-5O48-N10-N8-IR7-RI8-FP7-P8-RC8-CR7-LQ8-QL8-C-C7-C13-P14-I26-I180-2I3-I13-2L7-M8-NP8-PN6-LP10-PL5-2N4-3F3-AN5-NM3-5C2-Z-Z4-M4-5H2-Ad-Ad9-5O2-MYM4-P5-3O3-3J4-M11-3J4-N12-2J42-INF8-FNI6-2IF7-F2I8-2R3-R2-R38-N293-2L3-L13-P18-P9-A5-2I-R8-R2A17-2A4-L12-2A17-3J42-LS10-SL5-LM10-ML7-2Ah7-Ah10-2(R3-)R10-2P358-L18-2N3-N3-M9-2M2(3-M)19-A18-L17-R3J44-2(F18-)2N3-N14-I397-2N17-2N65-I65-L18-2I18-I416-I468-
