model
size = 10 19 28, scale = 0.05, origin = -y
material 
  colors = A:#F09 B:#9F9 C:#FF0 D:#111
voxels
113-4B6-4B67-2B187-4B186-4B7-2B176-6B5-4B175-6B5-4B174-8B4-4B6-4B164-8B4-4B6-4B36-4(4A6-)4A84-8B3-6B5-4B26-4A5-4(6A4-)6A5-4A73-10B2-6B5-4B16-4A4-4(8A2-)8A3-6A4-6A5-4A63-10B2-6B5-4B2(6-4A)4-5(8A2-)3(8A3-6A4-6A5-4A53-10B2-6B5-4B2(6-4A)4-8A2-8A-30A-)8A3-6A4-6A5-4A53-10B2-6B5-4B2(6-4A)4-8A2-8A-20A-8A2-3(8A3-6A4-6A5-4A53-10B2-6B5-4B2(6-4A)4-5(8A2-))8A3-6A5-4A63-10B2-6B5-4B2(6-4A)5-6A3-2(8A2-)8A3-6A4-6A5-4A73-10B2-6B5-4B2(6-4A)5-6A4-6A3-8A2-8A3-6A5-4A83-10B2-6B5-2(4B6-)4A6-4A5-2(6A4-)6A5-4A93-10B2-6B5-2(4B6-)4(4A6-)4A103-10B2-6B5-3(4B6-)4A134-8B3-6B5-3(4B6-)4B135-6B4-6B5-8(4B6-)4B7-2B78-2B7-11(4B6-)4B34-5(3C2-)3C34-8(4B6-)4B5-6B6(4-B)3-5(3C2-)3C104-4B6-4B55-D4-D12-
