model
size = 32, scale = 0.05, origin = -y
material 
  colors = A:#39F B:#993 C:#111 D:#39C E:#06C F:#006 G:#06F H:#039
voxels
47-2A221-H2AH4(28-E2AE)28-C2AC28-C2-C25-4C2-4C21-5C2-5C19-6C2-6C18-5C4-5C18-4C6-4C18-3C8-3C18-2C10-2C627-2B8-2B20-2B8-2B19-3B8-3B3(18-4B6-4B)17-5B6-5B16-5B6-5B15-6B6-6B13-7B6-7B12-7B6-7B13-6B6-6B15-5B6-5B16-5B6-5B17-2(4B6-4B18-)4B6-4B19-3(2B8-2B20-)2B8-2B21-B8-B277-2B8-2B19-3(4B6-4B18-)4B6-4B17-5B6-5B3(16-6B4-6B)15-7B4-7B13-8B4-8B11-9B4-9B10-9B4-9B11-8B4-8B13-7B4-7B15-2(6B4-6B16-)6B4-6B17-4(4B6-4B18-)4B6-4B19-3B6-3B117-2B6-2B21-4B4-4B19-5B4-5B18-5B4-5B17-6(6B4-6B16-)6B4-6B15-7B4-7B13-9B2-9B11-10B2-10B9-11B2-11B7-2(12B2-12B6-)12B2-12B7-11B2-11B9-10B2-10B11-9B2-9B13-8B2-8B15-5(6B4-6B16-)6B4-6B17-B2AB6-B2AB18-3B8-3B83-5B2-5B19-6B2-6B18-BA4B2-4BAB16-3BA4B2-4BA3B14-8B2-8B13-9B2-9B11-10B2-10B9-3(11B2-11B8-)11B2-11B7-2(12B2-12B6-)8(26B6-)12B2-12B7-2(11B2-11B8-)11B2-11B9-10B2-10B11-3BA5B2-5BA3B13-2BA4B4-4BA2B15-B3AB6-B3AB17-3B8-3B55-4B24-12B19-14B18-BA10BAB16-3BA10BA3B13-B8A2B8AB11-B9A2B9AB9-B8A6B8AB8-B8A6B8AB7-2(B9A6B9AB6-)9(2B8A6B8A2B6-)2(2B22A2B6-)3(2(2B10A)2B6-)2(2B10A)2B7-B10A2B10AB9-2B7A4B7A2B12-B5AB4-B5AB15-B3AB6-B3AB17-3B8-3B24-2B28-6B23-12B19-14B18-BA10BAB16-3BA10BA3B13-B18AB10-2B20A2B8-B22AB7-2(B24AB6-)26A6-26A5-11(28A4-)28A5-26A6-26A7-24A9-9A4B9A12-6AB4-B6A15-5A6-5A17-3A8-3A23-4B27-6B24-2B6A2B20-2B10A2B18-B12AB16-3B12A3B13-B18AB10-2B20A2B8-B22AB7-B24AB2(6-26A)5-28A4-28A3-4(30A2-)30A-64A-2(30A2-)30A3-28A4-28A5-26A7-24A9-9A4B9A12-7A4-7A15-5A6-5A16-4A8-4A20-8B24-8B23-2B6A2B20-2B10A2B18-B12AB16-3B12A3B13-B18AB10-2B20A2B8-B22AB7-26A6-26A5-28A4-28A3-4(30A2-)30A-128A-2(30A2-)30A3-28A5-25AD7-D23A9-10A2B10A12-7A4-7A15-5A6-5A16-4A8-4A20-8B23-10B22-2B6A2B20-2B10A2B18-B12AB16-3B12A3B13-B18AB10-2B20A2B8-24A7-26A6-26A5-28A4-28A3-3(30A2-)30A-192A-30A2-30A3-28A5-26A7-24A9-10A2B10A12-7A4-7A14-6A6-6A15-4A8-4A19-2(10B22-)2B6A2B20-2B10A2B18-B12AB16-3B12A3B13-B18AB10-24A8-24A7-26A6-26A5-28A4-28A3-2(30A2-)30A-256A-30A3-28A5-26A7-24A9-D21A11-8A4-8A13-6A6-6A15-4A8-4A20-8B23-10B22-2B6A2B20-2B10A2B18-B12AB16-3B12A3B13-20A10-24A8-24A7-26A6-26A5-28A4-28A3-2(30A2-)30A-256A-30A3-28A5-25AD7-24A9-22A10-AD7A4-9A12-6A6-6A15-4A8-4A20-8B24-8B23-2B6A2B20-2B10A2B18-B12AB16-18A13-20A10-24A8-24A7-26A6-26A5-28A4-28A3-2(30A2-)30A-256A-30A3-28A5-26A7-24A8-24A9-9A4-9A12-D5A6-6A15-4A8-4A21-6B26-6B24-2B6A2B20-2B10A2B18-14A16-18A13-20A10-24A8-24A7-26A6-26A5-28A4-28A3-2(30A2-)30A-256A-30A3-28A5-26A6-25AD7-24A9-9A4-9A12-6A6-6A15-D3A8-4A21-6B26-6B24-2B6A2B20-14A18-14A16-18A13-20A10-24A8-24A7-26A6-26A5-28A4-28A3-3(30A2-)30A-192A-30A2-30A3-28A5-26A7-24A8-24A9-9A4-9A12-6A6-6A15-AD2A8-4A22-4B27-B4AB24-10A20-14A18-14A16-18A13-20A10-24A8-24A7-26A6-26A5-28A4-28A3-4(30A2-)30A-96A-3(30A2-)30A3-28A5-26A7-23AD9-22A10-9A4-9A12-6A6-6A15-2ADA8-4A23-2B28-6A24-10A20-14A18-14A16-18A13-20A10-24A8-24A7-26A6-26A5-2(28A4-)28A3-3(30A2-)30A-96A-2(30A2-)30A3-28A4-28A5-26A7-24A9-22A11-8A4-8A13-5AD6-6A15-3AD8-4A53-6A24-10A20-14A18-14A16-18A13-20A10-24A8-24A7-2(26A6-)26A5-3(28A4-)28A3-2(30A2-)30A-32A-30A2-30A3-2(28A4-)28A5-26A6-26A7-24A9-22A11-7AD4-8A13-6A6-6A15-4A8-4A53-6A24-10A20-14A18-14A16-18A13-20A10-2(24A8-)24A7-3(26A6-)26A5-28A4-28A3-5(30A2-)30A3-28A5-2(26A6-)26A7-24A8-23AD9-9AD12A12-7A4-7A14-6A6-6A15-4A8-4A53-6A24-10A20-14A18-14A16-18A13-20A10-4(24A8-)24A7-26A6-26A5-2(28A4-)28A3-3(30A2-)30A3-28A4-28A5-26A7-2(24A8-)24A9-22A10-2(10AD)12-7A4-7A14-6A6-6A15-4A8-4A53-6A24-10A21-12A19-14A16-18A13-20A11-22A9-3(24A8-)24A7-2(26A6-)26A5-6(28A4-)28A5-26A6-26A7-24A8-24A9-22A10-22A11-10AD9A13-7A4-7A15-5A6-5A16-4A8-4A53-6A24-10A21-12A19-14A16-18A13-20A11-2(22A10-)22A9-2(24A8-)24A7-9(26A6-)26A7-2(24A8-)D23A9-22A11-19AD12-11AD8A13-7A4-7A15-5A6-5A16-4A8-2ADA53-6A24-10A21-12A20-12A17-18A13-20A12-20A11-2(22A10-)22A9-13(24A8-)D23A9-22A11-2(20A12-)19AD13-7A4-7A15-5A6-5A17-3A8-ADA54-6A24-10A21-12A20-12A17-18A13-2(20A12-)20A11-2(22A10-)22A9-11(24A8-)24A9-D21A11-3(20A12-)19AD13-7A4-D6A15-5A6-5A17-3A8-D2A54-6A24-10A21-12A20-12A18-16A14-3(20A12-)20A11-22A10-22A9-10(24A8-)24A9-22A11-3(20A12-)19AD12-20A13-7A4-7A15-5A6-D4A18-A10-A55-6A24-10A21-12A20-12A18-16A15-18A13-3(20A12-)20A11-22A10-22A9-8(24A8-)24A9-22A11-20A12-D19A2(12-20A)12-19AD12-20A13-11AD6A16-3A8-3A86-6A24-10A21-12A20-12A19-14A17-16A16-16A14-2(20A12-)20A11-10(22A10-)22A11-2(20A12-)D19A2(12-20A)12-19AD12-20A13-10AD7A116-6A24-10A22-10A21-12A19-14A18-14A17-16A16-16A14-2(20A12-)20A11-8(22A10-)22A11-3(20A12-)D19A2(12-20A)12-19AD13-9AD8A148-6A24-10A22-10A21-12A19-2(14A18-)14A17-16A15-18A13-14(20A12-)D19A12-20A12-18ADA13-8AD9A180-6A24-2(10A22-)10A20-4(14A18-)14A16-18A13-12(20A12-)20A13-D17A14-18A15-6AD7A2D182-4A27-6A25-8A23-10A22-10A21-4(12A20-)12A18-16A16-16A15-6(18A14-)4(C16AC14-)18A15-D15A16-16A17-5AD7AD215-4A27-2(6A26-)A4GA26-6F3(26-6A)24-10A21-12A19-2(14A18-)14A17-3A3C4A3C3A16-2AC10AC2A16-AC6AD5ACA3(16-C7AD6AC)16-C6A2D6AC16-C6ADAD5AC16-2C3A2D3AD3A2C17-2A2D6AD3A18-2D9A2DA19-3AD7AD234-
