model
size = 30 30 9, scale = 0.05, origin = -y
material 
  colors = A:#DDD B:#636 C:#111 D:#6F6 E:#9CF F:#FF6 G:#06C H:#F60 I:#F33 J:#BBB
voxels
130-A839-2C2(28-2A)28-A29-A27-3A28-A720-C29-A29-2A28-2A27-3A14-2C10-4A14-2A10-3A14-2A12-A2-2A10-3A13-4A9-2A17-A-A7-A20-3A5-A24-2A2-A27-2A29-A590-A28-A-A14-2C9-A-A16-2A9-3A15-2A12-2A13-2A9-B3-4A-2A6-4A15-6A4-3A18-6A2-3A20-9A24-5A26-4A27-4A23-2I3-2A24-2I29-2I28-2IA28-I3A26-2I2A27-2I28-3I28-I-I278-2B29-2B28-2B3-3A23-3B-5A22-2B-8A19-2B-13A3-A11-3B-11A2-A13-2B2-11A20-11A22-9A22-8A23-7A21-H2B6A22-H2BH4A22-2H2B4A23-H2B4A4-2A17-2HB4A3-3A18-H10A19-2H6ACA21-HB6A23-HBHAH26-3H29-H158-B29-2B28-3B4-A22-4B-5A21-3B-7A19-4B10A17-3B12A15-2(3B14A14-)2B-14A17-15A17-14A16-2F12A18-F11A19-F10A20-F8A20-F2B7A3-2A15-2FB7A2-4A15-FB7A-5A15-2F12A16-2FB10A15-5FB8A19-3F6AJ22-2FAFBF2J24-F-F2-2J2(29-J)13-2C28-3C27-A20-2B6-A20-3B5-2A20-4B4-2A21-4B-5A21-3B-7A19-4B10A17-3B12A15-2(3B14A14-)2B-2(14A17-)D14A16-2D12A18-D11A19-D10A19-DB8A20-D2B7A3-2A15-2DB7A2-4A15-DB7A-5A15-2D12A16-2DB10A15-5DB8A19-3D7A22-2DADBD-J24-D-D77-2C28-3C3(27-2A)16-2C4-B5-2A16-3C3-2B4-2A17-C2A3-2B2-3A18-2A3-4B5A15-2A5-3B8A12-A7-2B13A6-2A8-2B-11A5-2A13-11A3-3A14-11A-3A15-3E11A17-3E10A18-3E8A20-EBE7A21-E2BE4A22-E3B4A23-E2B4A4-2A17-E2B4A3-3A18-E10A19-2E6ACA21-2E6A23-3EAE26-3E243-2C11-A16-3C9-2A16-2CA9-2A19-A7-3A18-A9-4A16-A10-5A13-A13-3A12-2A17-3A7-2A18-3A6-2A20-3A3-3A22-2A-4A24-2A-2A22-G29-2(3G28-)3G2(27-4G)27-3G28-3G29-G127-
