model
size = 9 32 15, scale = 0.05, origin = -y
material 
  colors = A:#F00 B:#F06 C:#F03 D:#0E0 E:#001 F:#33F
voxels
94-D278-D7-3D7-D278-D286-4A4-6A3-A2D3A3(3-4DCA)3-A2DACA3-2ADACA3-3AD2C3-3A7-DAD6-D2A5-ADAC5-2(AC)A6-AC3(6-3C)5-5C5-3C7-C59-2B3-2B-3B3-7B-8B-4B2-7A3-6A3(2-7A)2-24A2(C8A)C2(5ADAC-)6A2C2(2-7A)3-AC2A5-5A4(4-5C)5-3C40-2B3-2B-3B2(3-6B)3-7B-8B-4B9AC7A3(D8A)4(DC7A)2C7AC27AC7A2-C5AC3-5A4-2AC2A5(4-5C)3-E5-E19-B7-4B3(3-6B)3-7B-8B-4B8ABC8AC26A3(C8A)C7A4(C8A)C9A-7A3-2(5A4-)3(5C4-)5C5-3C30-3B4(3-6B)3-7B-8B-3B2(-8A)5(-D7A)-2(D8A)C43A2-7A4-2(3A6-)3C5-2(5C4-)5C5-FCF22-2B3-2B2-2B3-2B-3B3-6B3-3B37-6AB6(-8A)-17AC8A3(C-7A)2-7A2-6AC4-2(3A6-)3A7-D8-D32-2B3-2B2-2B3-2B66-2AB2A11(4-5A)3-7A2-C5AC3-2CACA15-A7-A-A7-D8-D32-2B3-2B94-DAD5-2(2DA2D4-)3(2(AD)A4-)3(2DA2D4-)2(AD)A3-2ADAD2A2-2ADAD2A32-A8-D8-E32-2B3-2B182-2A3-2A2-CA3-2A84-E3-E183-2A3-2A2-C5-A246-2(A3-)2A3-2A2-2(2A3-)A3-A247-E3-E4-2(A3-)2(2A3-)A3-A101-
