model
size = 23 12 29, scale = 0.05, origin = -y
material 
  colors = A:#111 B:#444 C:#CA1515 D:#EEE
voxels
6-2(11A12-)3A5-3A12-4A3-4A14-7A17-5A151-3(5A5-5A8-)6A3-6A10-11A12-11A15-5A127-2(4A9-4A6-)3A11-3A6-3A11-3A8-A11-A10-2(A11-)11A15-5A103-3(3A13-3A4-)3A13-3A6-A13-A8-2A11-2(2A9-)2A12-9A16-5A80-3(3A13-3A4-)3A13-3A5-2A13-2A6-3A11-3A7-2(3A9-)13A12-9A77-2(3A15-3A2-)2A17-2A3-A17-A4-A17-A5-3A11-3A6-4A9-2(4A7-)4A10-11A15-5A56-2(2A17-2A2-)A19-A2-A19-A3-A17-A4-A17-A5-4A9-4A6-5A7-5A8-13A12-9A53-3A17-6A17-3A-A19-A2-A19-A3-A17-A4-A17-A5-A15-A6-5A7-5A8-13A12-9A53-2A2(19-4A)19-2A-A19-A2-2A17-2A3-A17-A4-2A15-2A5-3A11-3A8-5A3-5A12-9A17-3A33-2A3(19-4A)19-2A-2A17-2A2-2A17-2A3-2A15-2A4-4A11-4A6-6A3-6A10-11A15-5A32-3(2A3(19-4A)19-2A-2A17-2A2-2A17-2A3-2A15-2A4-4A11-4A6-4A7-4A10-11A14-7A18-3D10-)3A17-6A17-5A19-2A-A19-A2-2A17-2A3-A17-A4-2A15-2A5-3A11-3A2(7-4A)10-11A15-5A33-2(2A17-2A2-)A19-A2-A19-A3-A17-A4-A17-A5-A15-A6-3A11-3A8-4A5-4A12-9A17-3A34-2(3A15-3A2-)2A17-2A2-2A17-2A3-2A15-2A4-2A15-2A5-A15-A6-3A11-3A8-13A12-9A55-2(2A15-2A4-)A17-A4-A17-A5-A15-A6-A15-A7-3A9-3A8-3A9-3A10-11A14-7A56-3(4A11-4A4-)4A11-4A5-3A11-3A6-3A11-3A7-2(3A9-)2A9-2A11-11A14-7A56-AB3A9-3ABA4-5A9-5A5-3A11-3A6-3A11-3A7-2(2A11-2A8-)2(3A9-)13A11-11A16-3A58-2(AB)11A2(BA)4-AD15ADA6-3A4-A4-3A8-3A4-A4-3A9-2(2A4-A4-2A10-)2A4-A4-2A11-11A13-9A78-4(AB)3A4(BA)4-AD15ADA8-4A3C4A12-2(3AC)3A12-2AC3ACAC2A12-3(2AC)2A12-2ACAC3AC2A13-2AC3AC2A15-7A79-3(AB)2A3B2A3(BA)4-AD15ADA12-3C19-C3-C17-C3-C-C16-2(C2-)C16-C-C3-C17-C3-C19-3C81-2A2(BA)B5A2(BA)B2A4-2AD13AD2A235-2A2(BA)5B2(AB)2A6-AD13ADA236-3ABAB5ABAB3A6-2AD11AD2A237-3ABA5BAB3A8-2AD9AD2A239-3AB5AB3A10-2AD7AD2A241-3A5B3A12-2A7D2A243-9A14-9A237-
