model
size = 29 14 28, scale = 0.05, origin = -y
material 
  colors = A:#FF6905 B:#0A0000 C:#FFF D:#F6D644 E:#F2AB14 F:#F28214 G:#F29114 H:#FDF4B9 I:#B9E7FD J:#F23914 K:#4AA7F6 L:#1352F1 M:#FAEB88 N:#1224B0 O:#F26D14 P:#030303 Q:#912407
voxels
14-3B24-B3-B24-2B-2B24-JB-BJ24-JQBQJ23-OJ3QJO22-O2JQ2JO4(22-2OJQJ2O)23-OJQJO24-2AJ2A25-3A109-11B18-2(C2B)3C3(2B18-4(CB)C)2B18-3(CB)3CBC18-11B219-3B9-3B14-3C3(9-BCB14-CBC)9-BCB14-3C9-3C14-3B9-3B216-2B5(13-2B12-BC)13-CB12-2B13-2B214-2B2(15-2B10-CB)15-2B10-2B2(15-BC10-CB)15-BC10-2B15-2B212-2B17-2B8-BC17-2B8-2C17-2B8-CB17-2C8-2C17-CB8-BC17-2C8-2B17-2B210-2B19-2B2(6-CB19-2C)6-BC19-2C6-2C19-2C6-CB19-2C6-2B19-PB208-2(2B2(21-2B4-BC)21-2B4-)2B21-2B206-2B3(23-2B2-CB)2(23-2C2-CB)23-2C2-2B23-2B204-2B25-2B2C25-2CBC25-4C25-2CBC25-2B2C25-4B25-2B203-B27-BC27-2B27-BC27-CB27-2C27-CB27-B203-B6(27-2B)27-B203-B27-BC2(27-2C)27-BC27-2C27-CB27-B203-B27-BC2(27-2B)27-CB27-2B27-CB27-B203-B27-BC5(27-CB)27-B203-B6(27-2B)27-B203-B27-BC27-CB3(27-BC)27-CB27-B203-B27-BC27-CB27-BC27-2B27-BC27-CB27-B203-B27-BC2(27-2C)27-CB27-2C27-CB27-B203-B6(27-2B)27-B121-8B3-8B7-7B3-2B-2B3-7B2-4B9-B-B9-5B2P10-3B10-2PB-P2(B11-)2B-BPB23-3B-PB23-BP-BPB23-BPB-PB23-BP-BPB23-BP2BPB23-BP5B21-BP2B-7B13-7B4-5B13-5B8-8B3-8B7-4BA7B-7BA4B2-3BLKIH6-B-B6-HIKL4B2(2ALKIH6-3B6-HIKL2A2B)2ALKIH7-B7-HIKL5(2A2B2ANLKI15-IKLN)2A3BANLKI15-IKLNA2B-3B3A4B7-4B4A2B4-8B7-8B8-8B3-8B7-4B4A4B-4B4A4B2-3B4ADEG3-B-B3-GED4A4B2(6ADEG3-3B3-GED6A2B)6ADEG4-B4-GED5(6A2B6AHDE9-EDH)6A3B5AHDE9-EDH5A2B-3B6A9B7A2B4-23B8-8B3-8B7-4B6A2B-2B6A4B2-3B7AF2AB-B2AF7A4B9AF2A3B2AF9ABN9AFA-3B-AF9A2N9AFA2-B2-AF4(9A2N9AGF5-FG)9ANB9AGF5-FG9A3B8AGF5-FG8A2B-3B8A5B9A2B4-23B8-8B3-8B7-4B6A2B-2B6A4B3-2B10AB-B10A2B2-K12AB12AK2-K10AJ3AJ10AK2-L10AJQAQJ10AL2-L10A2JQ2J10A3(L2-L11AJQJ11A)L2-L12AJ12AL2-B12AJ12AB2-3B22A2B4-23B8-8B3-8B7-4B6A2B-2B6A4B4-B10AB-B10AB4-I11AB11A2(I4-I23A)I5(4-K23AK)4-KI21AIK4-BI21AIB5-23B8-8B3-8B8-3B2D4A2B-2B4A2D3B6-H2MD6AB-B6AD2MH6-H2MD7AB7AD2MH6-H2MD15AD2MH6(6-IHMD15ADMHI)7-HM2D13A2DMH8-H2M2D11A2D2MH8-21B13-4B3-4B17-EGFA2B-2BAFGE15-2EGF2AB-B2AFG2E14-2EGF3AB3AFG2E14-2EGF7AFG2E5(14-DEGF7AFGED)14-DEG2F5A2FGED15-EG2F5A2FGE17-EGF5AFGE18-11B9-
