model
size = 29 27 25, scale = 0.05, origin = -y
material 
  colors = A:#9CF B:#0C0 C:#400
voxels
9-3(7A22-)7A687-3(11A18-)11A683-3(15A14-)15A680-3(4A7-6A12-)4A7-6A582-3B93-3(3A11-5A10-)3A11-5A582-B28-B64-3(3A13-5A8-)3A13-5A581-B26-5B62-3(2A15-4A8-)2A15-4A610-B28-B34-3(2A17-4A6-)2A17-4A115-B493-B25-7B31-3(2A17-4A6-)2A17-4A56-2(B28-)2B522-B33-3(2A19-4A4-)2A19-4A26-B28-B436-C28-C111-9B29-3(2A19-4A4-)2A19-4A27-2(B28-)2B28-B347-C27-3C26-3C27-C85-2B33-3(2A19-4A4-)2A19-4A492-2(C28-)C57-B28-B33-3(2A19-4A4-)2A19-4A25-3(3B26-2B28-2B26-)2(3B26-)2B28-2B2(26-2B28-2B27-3B)26-2B28-2B61-3(2A19-4A4-)2A19-4A25-14(3B26-)2(3B27-2(3B26-))3B61-3(2A19-4A4-)2A19-4A25-2(3B27-2B26-2B27-)3B27-2B26-3B26-2B27-3B27-2(2B26-2B28-)3B27-2B26-2B28-3B27-2B26-2B62-3(2A19-4A4-)2A19-4A521-2(C28-)C27-B28-B35-3(2A17-4A6-)2A17-4A493-C27-3C26-3C27-C52-9B24-B4(6-2A17-4A)522-C28-C114-B7-3(2A15-4A8-)2A15-4A638-B25-7B4-3(3A13-5A8-)3A13-5A638-B37-3(3A11-5A10-)3A11-5A610-B26-5B36-3(4A7-6A12-)4A7-6A611-B68-3(15A14-)15A611-3B69-3(11A18-)11A687-3(7A22-)7A680-
