model
size = 13 23 15, scale = 0.05, origin = -y
material 
  colors = A:#CA7A2C B:#ECB88A C:#724832 D:#EEE E:#6C6A2D F:#111
voxels
146-2(2C3-)117C-11C132-3(11B2-)9(11B2C)11BC-11C119-11B3(2-B9AB)-C8(B10A2C)11BC-11C119-11B4(2-B9AB)-CB9AB-C6(B10A2C)2(11BC-11C119-11B4(2-B9AB)-C7(B10A2C))11BC-11C119-11B3(2-B9AB)-CB9AB-C7(B10A2C)11BC-11C119-11B2(2-B9AB)2-11B2(2-8(B10A2C)11BC-11C119-11B3(2-B9AB))2-B9AB2-7(B10A2C)11BC-11C119-11B4(2-B9AB)-C7(B10A2C)11BC-11C119-11B3(2-B9AB)2-B10AC-7(B10A2C)11BC-11C119-11B2-4(B10AC-)7(B10A2C)11BC-11C119-11BC-3B5C3B2(C-11B)2C5DB4DB2CB3EDBD3EB2CBEFEDBDEFEB2CB3EDBD3EB2C2(BD)2BDB2DB4(2C11B)C-11C13-C12-C11(11-2C)11-3(4C9-)4C2(-C)2-C2-8C-3C-28C-11C14-
