model
size = 13 7 27, scale = 0.05, origin = -y
material 
  colors = A:#F9BF45 B:#C99833
voxels
39-A11-A65-A2(11-2A)11-A52-A11-A13-A2(11-A52-A2(11-2A))11-A52-A11-A13-A11-A52-2A2(9-4A)9-2A53-2(A9-A2-)A9-A54-2(2A7-2A2-)2A7-2A55-2A6-A2(4-2A5-2A)57-2(7A6-)7A61-2(A12-)A77-5(A90-)A89-3A88-A-A88-ABA63-B24-ABA24-B51-B11-ABA11-B38-2(B12-)B11-ABA11-2(B12-)B38-2(B12-)B51-2(B25-)B64-B45-
