model
size = 9 29 5, scale = 0.05, origin = -y
material 
  colors = A:#7DFF09
voxels
22-14(A8-)A7-5(3A6-)A-A5-2A-2(2A3-)2A-2A2(5-4A)5-2A13-2(A8-)A220-A6-4A5-2A4-A247-2A5-2A4-2(A8-)A220-A6-4A5-2A22-A7-3A6-3A5-5A3-7A2-3A-3A5(2-2A3-2A)-3A3-5A13(5-4A)5-2A9-
