model
size = 17 32 18, scale = 0.05, origin = -y
material 
  colors = A:#CF3
voxels
17-5(A16-)2A7(16-A)13-A2-2A11-2A2-15A2-2A269-5(A16-)2A7(16-A)13-A2-2A11-2A2-15A2-2A286-5(A14-A-)2A13-6(A-3A12-)5A11-7A9-21A-14A3-2A13(16-A)267-A3-A12-A2-4A10-2A-5A2(-2A)-3A224-A16-A270-3A11-2A2-A3(-2A)2(-A)241-A16-2(A253-3A11-2A2-A3(-2A)2(-A)258-)A253-3A11-2A2-A3(-2A)2(-A)3-15(A16-)A253-3A11-2A2-A3(-2A)2(-A)258-2(A253-3A11-2A2-A3(-2A)2(-A)3-15(A16-))A253-3A11-2A2-A3(-2A)2(-A)258-A253-3A11-2A2-A3(-2A)2(-A)3-15(A16-)2(A253-3A11-2A2-A3(-2A)2(-A)258-)A253-3A11-2A2-A3(-2A)2(-A)241-A16-A233-A3-A12-A2-4A10-2A-5A2(-2A)-3A224-A16-A31-5(A14-A-)2A13-6(A-3A12-)5A10-8A9-21A-14A3-2A13(16-A)48-
