model
size = 28 16 26, scale = 0.05, origin = -y
material 
  colors = A:#F90 B:#D00 C:#EEE
voxels
39-6A411-6ABAB3A435-14A15-4A6B2A16-3A6B3A16-3A2B2A2B3A350-8ABAB5A13-2(A12-A14-)5AB8A14-5A5B4A14-4A6B4A15-3A2B2A2B3A16-3A6B3A17-3A6BA210-18A11-A-4A6B2A-A12-A-3A6B3A-A12-A-3A2B2A2B3A-A13-2(A12-A14-)14A14-14A16-10A18-5ABAB2A182-2(3A12-3A10-)3A12-3A11-6AB9A12-6A5B5A12-5A6B5A13-4A2B2A2B4A14-4A6B4A15-4A6B2A17-5ABAB2A182-3(2A14-2A10-)2A14-2A11-4(2A12-)16A12-16A13-14A15-12A17-10A154-A16-A3(10-2A14-2A)3(10-3A12-3A)11-4A8-4A13-3A8-3A14-14A16-10A154-A16-A3(10-2A14-2A)11-A14-A6(12-2A)13-3A8-3A15-12A17-10A154-A16-A4(10-2A14-2A)2(10-3A12-3A)11-2A12-2A13-A12-A14-14A16-10A154-A16-A5(10-2A14-2A)10-18A9-2C16A2C7-4C14A4C5-3C2-14A2-3C3-3C5-10A5-3C2-2C22-2C-2C24-2C-2C22-2C3-C22-C35-A16-A4(10-2A14-2A)11-A14-A11-C16AC9-2C16A-C7-4C14A4C5-3C2-14A2-3C3-3C5-10A5-3C-3C22-5C24-5C22-3C-2C22-2C3-C22-C7-A16-A3(10-2A14-2A)11-A14-A4(12-2A)10-2C2A12-2A2C7-4CA12-A4C5-3C2-14A2-3C3-3C5-10A5-3C2-2C22-2C-2C24-2C-2C22-2C3-C22-C35-A16-A2(10-2A14-2A)11-2(A14-A12-)5(2A12-)2A13-3A8-3A15-12A17-10A154-A16-A10-2A14-2A11-2(A14-A12-)3(2A12-)2A13-A12-A14-3A8-3A15-2A8-2A17-3ABAB4A182-2A14-2A11-2(A14-A12-)A14-A13-2(A12-A14-)14A14-14A16-10A18-3ABAB4A183-2A12-2A13-2(A12-A14-)5AB8A14-5A5B4A14-5A6B3A15-4A2(2B2A)16-4A6B2A17-2A6B2A212-14A15-3A6B3A16-4A6B2A16-4A2(2B2A)351-2(5ABAB6A434-)14A434-14A435-12A436-12A437-10A439-8A430-
