model
size = 27 8 32, scale = 0.05, origin = -y
material 
  colors = A:#222 B:#777 C:#111 D:#063 E:#444 F:#555 G:#888 H:#D00
voxels
81-81A108-81A82-2A20-3A2-2E20-EAE-17A5-22A5-6A2B24A4-2C4-7B14-2C49-2A20-3A2-2E20-3E-17A5-22A5-6A2B24A4-2C2-11B12-CH4-7C15-C75-17A5-22A5-32A6-15B14-11C89-17A5-22A5-6AB25A5-17B11-15C87-17A5-22A5-4AC27A4-19B9-17C86-17A5-22A5-6AB25A3-21B7-19C85-17A5-22A5-32A3-21B7-19C85-17A5-22A5-4AC27A2-23B5-21C84-17A5-22A5-32A2-23B5-8C5D8C84-17A5-22A5-32A-25B3-8C7D8C83-17A2(5-22A)5-5A-25B3-7C3DG5D7C83-17A2(5-22A)5-5A-25B3-7C2DG6D7C83-17A2(5-22A)5-5A-25B3-7C4DC4D7C83-17A2(5-22A)5-5A-25B3-7C6DG2D7C83-17A2(5-22A)5-5A-25B3-7C5DG3D7C83-17A2(5-22A)5-5A-25B3-8C7D8C83-17A2(5-22A)5-5A2-23B5-8C5D8C84-17A2(5-22A)5-5A2-23B5-21C84-2(17A2(5-22A)5-5A3-21B7-19C85-)17A2(5-22A)5-5A4-19B9-17C86-17A5-22A5-8AB13A5-5A3-A-17B8-A2-15C13-4BF69-17A2(5-22A)5-5A6-15B14-11C17-B-3F67-17A5-22A5-6AE15A5-5A8-11B18-7C23-4F64-55AE20A3C2A10-7B5-3C45-4F61-55AE19A5CA21-5C23-3C21-3F2C57-55AE19A2(2CA)21-5C23-3C22-7C54-53AC21A5CA21-5C23-3C24-3C3-2A22-A2-2E22-E-55AE2A8C10A3C2A8-B13-3C57-2A21-2A2-2E21-2E-81A81-
