model
size = 27 6 22, scale = 0.05, origin = -y
material 
  colors = A:#222 B:#444 C:#555 D:#777 E:#111 F:#009 G:#C60 H:#03F I:#080
voxels
27-270A27-82AD26A-7AG15AIA4-E-E8-E2-E3-E4-26AE108A27-135A27-107AE5A4CAFAG14A6-B7-4(B-)B2-E-135A27-110AD24A27-107A2(D2A)4CAFAG14A5-B8-4(B-)B2-E-110AD24A27-110AD24A-3B23-107A2(D2A)4CAFAG14A8-B5-4(B-)B2-E-110AD24A27-135A27-107AD5A4CAFAG14A8-B5-4(B-)B2-E-2(135A27-)107AD10AFAG14A4-2(E-)E5-4(B-)B2-E-135A27-53AD66AF3ACA2C3D4A25-E-110AH12AI2A2C3D4A4-3(E-)E16-53AD66AF3ACA2C3D2AHA27-
