model
size = 24 22 28, scale = 0.05, origin = -y
material 
  colors = A:#111 B:#555 C:#444 D:#222 E:#EEE F:#001 G:#060 H:#06F I:#C0C J:#D00 K:#36F L:#FFD000 M:#0CF N:#C3C O:#500 P:#00E Q:#C60 R:#960 S:#777 T:#888 U:#09C V:#400
voxels
2-22A69(-23A)-8(21AB2-21AD2-)6(23A-)21AD2-21AB2-21A6(D3-C19AB3-C19A)D3-C19AB2-6(23A-)8(21AB2-21AD2-)3(23A-)22AC2(-23A)-21AD2-21AB2-21A6(D3-C19AB3-C19A)D3-C19AB2-6(23A-)21AB2-21AD6(2-21AK)6(2-21AG)2-21AB2-21AD2-3(23A-)22AC2(-23A)-21AD2-21AB2-21A2(R3-C19A)4(D3-C19AB3-C19A)2(U3-C19A)D3-C19AB2-4(23A-)2(B22A-)B20AB2-B20A2(D2-21AB2-21A)D2-21AE2-22A2-21AP3(2-21AD2-21AB)2-21AD2-3(23A-)22AC2(-B22A)-B20AD2-B20AB2-21AD3-C19AB3-C19AD2(3-C19AF)3-C20A2(3-C19AP)3-C20A2(3-C19AB3-C19AD)3-C19AB2-23A-72AB46A-B20AB2-B20AD2-21AB2-21AD2-21AT2(2-21AE)2-22A2(2-21AJ)2(2-21AE)2(2-21AB2-21AD)2-4(23A-)2(B22A-)B20AD2-B20AB2-21AD3-C19AE3-C19AT2(3-C19AF)3-C20A2(3-C19AJ)3-C20A2(3-C19AE)3-C19AB3-C19AD3-C19AB2-4(23A-)B22A-23A-B20AB2-B20AD2-21AL2-21AF2-21AS2(2-21AE)2-22A2(2-21AN)2(2-21AE)2-22A2-21AE2-21AB2-21AD2-4(23A-)2(B22A-)B20AD2-B20AB2-21AJ3-C19AF3-C19AS2(3-C19AF)3-C20A2(3-C19AN)2(3-C20A3-C19AE)3-C19AD3-C19AB2-4(23A-)B22A-23A-B20AB2-B20AD2-21AJ2-21AF2-22A2(2-21AE)2-22A2(2-21AG)2(2-21AE)2-22A2-21AE2-21AB2-21AD2-4(23A-)2(B22A-)B20AD2-B20AB2-21AL3-C19AF3-C20A2(3-C19AF)3-C20A2(3-C19AG)2(3-C20A3-C19AE)3-C19AD3-C19AB2-6(23A-)21AB2-21AD2-21AB2-21AE2-22A2(2-21AE)2-22A2(2-21AM)3(2-21AE)2-21AD2-21AB2-21AD2-6(23A-)21AD2-21AB2-21AD3-C19AB3-C20A2(3-C19AF)3-C20A2(3-C19AM)2(3-C20A)3-C19AD3-C19AB3-C18A2D3-C19AB2-5(23A-)C22A-O20A2(B2-21AD2-21A)B2(2-21AE)2-22A2(2-21AL)2-21AE2(2-21AD2-21AB)2-21AD2-6(23A-)21AD2-21AB2-21A2(D3-C19AB3-C19A)D3-C20A3-C19AL3(3-C19AB3-C19AD)3-C19AB2-5(23A-)C22A-O20AB2-21AD2(2-21AQ)4(2-21AB2-21AD)2(2-21AH)2-21AB2-21AD2-6(23A-)21AD2-21AB2-21A6(I3-C19A)6(H3-C19A)D3-C19AB2-5(23A-)C22A-O20A7(B2-21AD2-21A)B2-21AD2-6(23A-)21AD2-21AB2-21A6(D3-C19AB3-C19A)D3-C19AB2-3(23A-)22AV2(-23A)-8(21AB2-21AD2-)6(23A-)8(21AD2-21AB2-)23(23A-)23A
