model
size = 30 31 12, scale = 0.05, origin = -y
material 
  colors = A:#A0A0A0 B:#CE3925 C:#FFF D:#EEE E:#AAA F:#656765 G:#DCDCDC H:#FFFFFB I:#F05E1C J:#F75C2F K:#9B9B9B L:#FBE251 M:#ED784A N:#CC543A O:#B54434 P:#FFB11B Q:#F6C555 R:#BDC0BA S:#D19826
voxels
454-FD4BD5(AF)D2BDAF7-A2D2B2D11A2D3A7-2A4D2A9-4A10-6A11-2A12-4A27-2A180-B2(29-H)504-AD4BD5(FA)D2BDFA7-A2D2B2D11A2D3A7-2A4D2A9-4A10-6A11-2A12-4A27-2A180-B2(29-H)533-FG6D10G4D2GF5-10A12C3A6-8D5E10D7-E6D2F2(EK)E2F6DF7-2F4D4F2(EK)E2F4D9-A2F2D2FA3F2(EK)E4F10-2A4F3AF-2EK2E15-6ABA3-2EK2E15-4ABA5-3E17-5A5-E21-2A88-H29-H395-N8-N11-N7-BOB6-BOB9-BOB7-B8-B36-FAG6CECG6CE8CA2-4A22C2A3-2DA22BD4-2EA22-F4-2FA20-F2A4-ADA19-F2A5-ADA9-F5-6E6-A2D5A-5A3-2AR10-A3D12ARA12-ADK2D8AREA14-2ADK3D5AE17-2A6D2AER18-3A4D3A20-3A2D5A21-4A-3AR22-2A2-3A303-J10-J9-J8-BI8-IB9-BI7-M2B6-2BM9-M2B6-3BN4-N3B8-4BN5-3B6-3B10-2(B8-)B5-A3CG5EG8EC5EGE2CFA-A25C2A-DA25BD2-EA25-F2-FA25-A2-2A24-2A2-2A18-3D4E3-2A16-2D3H7-2A14-2D2H10-2A12-2D2H12-2A11-D2H14-2A9-2DH16-A9-D2H26-2(DAH27-)2D212-Q29-S10-L9-L8-PM8-MP9-PM7-MI-N4-N-IM9-MI-N5-3IB4-B3I9-3IB2(4-O3BO)7-O3BO4-N4B4-4BN6-BN4B3-5B6-5B7-3B6-2B8-2B4-FCD2EG2CGCE4(GC)EGC2GCEGDC2A28CAK5BD2B2(DB)2(3DB)D2B3D2BDK28-2FA27-AFA26-4A23-4E-2A20-2AH5-BA18-AH8-2A16-AH11-A14-AH13-A11-2AH15-A9-DAH17-A9-DA18-R8-DAH27-2D28-2D33-2(L29-)L28-LQ8-L19-QP8-L11-L7-SLQ7-QL9-LQ6-PLQS7-PQ9-QP6-PJIQJ5-QIS9-SIQ5-PJIMJ5-MIJP7-PJIM4-P2(JI)J4-2(JI)J7-2(JI)2(J3-6B)6-5B3-BO5B2-5BOB5-BO4B2(4-5B)7-5B4-4B6-4B3-ACDGEC2GCGE4(CG)ECG2CGEGDCFA28C2A2B2(2DB)D3B2(2D2B)D2BDBD2BDK28-FK28-AF28-2A24-4E-A21-2AH5-B19-AH8-A17-AH10-R15-AH12-D12-2AB15-A9-DAH17-A9-DA18-R8-HAH18-R8-HD28-2D84-2(L8-L20-)L7-LP19-LQ7-LQ8-L10-QP7-QP8-QL9-SIQ6-PIQ7-PQ8-PJIM5-PSIQ6-QIS8-2(JI)J4-PJIM6-MIJP6-6B4-JIJ-J4-2(JI)J6-BO5B3-5B4-5B7-5B3-BO4B4-4BOB6-4B5-5B4-5B3-FCDGEC2GCGE4(CG)ECG2CGEGDC2A28C2A2B2DBDB2DB2(D3B)DBD2B3D2BDK28-FK28-AF28-2A24-4E-A21-2AH5-B19-AH8-A17-AH10-R15-AH12-D12-2AB15-A9-DAH17-A9-DA18-R8-HAH18-R8-HD28-2D182-Q20-L8-L20-PM7-QM9-L9-MI-N5-PM8-MP9-3IB5-MI-N4-N-IM8-O3BO5-3IB4-B3I8-N4B2(4-O3BO)6-5B4-BN4B4-4BNB7-2B7-3B6-3B4-ACD2EG2CGCE4(GC)EGC2GCEGDCFA28CAK5BD2B2(DB)2(3DB)2D2(BD)2BDK28-2FA27-AFA26-4A23-4E-2A20-2AH5-BA18-AH8-2A16-AH11-A14-AH13-A11-2AH15-A9-DAH17-A9-DA18-R8-DAH27-2D28-2D263-J29-BI7-J10-J9-M2B6-BI8-IB9-3BN5-M2B6-2BM9-3B5-4BN4-N4B9-2(B8-)B5-F3CG5EG8EC5EGE2C2A-A25C2A-DA25BD2-EA25-F2-FA25-A2-2A24-2A2-2A18-3D4E3-2A16-2D3H7-2A14-2D2H10-2A12-2D2H12-2A11-D2H14-2A9-2DH16-A9-D2H26-2(DAH27-)2D354-N28-BOB7-N8-N11-B7-BOB6-BOB35-AF7CECG6CE8CF2-4A22C2A3-2DA22BD4-2EA22-F4-2FA20-F2A4-ADA19-F2A5-ADA9-F5-6E6-A2D5A-5A3-2AR10-A3D12ARA12-ADK2D8AREA14-2ADK3D5AE17-2A6D2AER18-3A4D2AE20-3A2D4AE21-4A-EAER22-2A2-AEA472-AG6D10G4D2GA5-10A12C3A6-8D5E10D7-E6D2F2(EK)E2F6DF7-2F4D4F2(EK)E2F4D9-A2F2D2FA3F2(EK)E4F10-2A4F3AF-2EK2E15-6ABA3-2EK2E15-4ABA5-3E17-5A5-E21-2A88-H29-H80-
