model
size = 30 21 21, scale = 0.05, origin = -y
material 
  colors = A:#343434 B:#393939 C:#CBC8BC D:#777 E:#111 F:#E83015 G:#2EA9DF H:#7DB9DE I:#FBE251 J:#EEE K:#444 L:#D52E19
voxels
30-3(29A-)29A2-28A9-7A12B12-5A12B13-5A11B14-5A10B15-5A9B16-5A8B17-5A7B18-5A6B19-5A5B20-5A4B21-5A3B22-5A2B24-4AB26-2A47-29A-2A26-3A3(28-2A)27-2A-7C18-2B4-7C16-2B8-4C15-2B11-2C14-2B13-C13-2B14-C12-2B15-C11-2B16-C11-B17-C10-B18-C9-B19-C8-B20-C7-B22-A5-B24-4AB45-29A2-E27-AD28-AC2(28-2A)27-2A2C24-3B2-4C20-2B7-4C16-2B11-2C14-2B13-C13-2B14-C12-2B15-C11-2B16-C11-B17-C10-B17-AC9-B18-AC8-B20-C7-B21-C6-B23-5AB45-29A2-E27-AD28-AC2(28-2A)27-2A2C24-3B2-4C20-2B7-4C16-2B11-2C14-2B13-C13-2B13-FC12-2B14-LC11-2B16-C11-B17-C10-B17-AC9-B18-AC8-B20-C7-B21-C6-B23-5AB45-29A2-E27-AD28-AC2(28-2A)27-2A2C24-3B2-4C20-2B7-4C16-2B11-2C14-2B13-C13-2B13-FC12-2B14-F2(C11-2B16-C11-B17-C10-B17-AC9-B18-AC8-B20-C7-B21-C6-B23-5AB45-29A2-E27-AD28-AC2(28-2A)27-2A2C24-3B2-4C20-2B7-4C16-2B11-2C14-2B13-C13-2B14-C12-2B15-)C11-2B16-C11-B17-C10-B18-C9-B19-C8-B20-C7-B21-C6-B23-5AB45-29A2-E27-AD28-AC2(28-2A)27-2A2C24-3B2-4C20-2B7-4C16-2B11-2C14-2B13-C13-2B14-C12-2B15-C11-2B16-C11-B14-4A10-B15-4A9-B19-C8-B20-C7-B21-C6-B23-5AB25-3A17-29A2-E27-AD28-AC2(28-2A)27-2A2C24-3B2-4C20-2B7-4C16-2B11-2C14-2B13-C13-2B14-C12-2B15-C11-2B13-4A11-B15-3A10-B16-3A9-B16-4A8-B20-C7-B21-C6-B23-5AB25-A-A17-29A2-E27-AD3(28-2A)27-2A2C24-3B2-4C20-2B7-4C16-2B11-2C14-2B13-C13-2B14-C12-2B12-4A11-2B14-3A11-B17-G10-B18-G9-B17-3A8-B17-4A7-B21-C6-B23-5AB25-A-A17-29A2-E27-AD3(28-2A)27-2AIC24-3B2-3IC20-2B7-3IC16-2B11-IC14-2B13-I13-2B11-4A12-2B13-3A11-2B16-H11-B17-G10-B18-G9-B19-G8-B18-3A7-B18-3AC6-B23-5AB25-A-A17-29A2-E27-AD3(28-2A)27-2AFC24-3B2-3FC20-2B7-3FC16-2B11-FC14-2B13-F13-2B11-4A12-2B13-3A11-2B16-H11-B17-H10-B18-G9-B19-G8-B18-3A7-B18-3AC6-B23-5AB25-A-A17-29A2-E27-AD3(28-2A)27-2A2C24-3B2-4C20-2B7-4C16-2B11-2C14-2B13-C13-2B14-C12-2B12-4A11-2B14-3A11-B17-H10-B18-H9-B17-3A8-B17-4A7-B21-C6-B23-5AB25-3A17-29A2-E27-AD3(28-2A)27-2A2C24-3B2-4C20-2B7-4C16-2B11-2C14-2B13-C13-2B14-C12-2B15-C11-2B13-4A11-B15-3A10-B16-3A9-B16-4A8-B20-C7-B21-C6-B23-5AB45-29A2-E27-AD3(28-2A)27-2A2C24-3B2-4C20-2B7-4C16-2B11-2C14-2B13-C13-2B14-C12-2B15-C11-2B16-C11-B14-4A10-A8-2A5-4A10-11A8-C9-12A8-C8-13A8-C7-3A9-2A9-9A42-29A2-E27-AD3(28-2A)27-2A2C24-3B2-4C20-2B7-4C16-2B11-2C14-2B13-C13-2B14-C12-2B15-C11-2B16-C11-B8-A8-C11-10A8-3(C29-)C9-12A9-10A10-A30-29A2-E27-AD3(28-2A)27-2A2C24-3B2-4C20-2B7-4C16-2B11-2C14-2B13-C13-2B12-KJC12-2B13-AJC11-2B16-C11-B8-A8-C11-10A7-H2(C28-G)C29-C9-12A9-10A10-A30-29A2-E27-AD3(28-2A)27-2A2C24-3B2-4C20-2B7-4C16-2B11-2C14-2B13-C13-2B12-KJC12-2B13-KJC11-2B16-C11-B8-A8-C11-10A7-H2(C28-G)C29-C9-12A9-10A10-A30-29A2-E27-AD3(28-2A)28-A2C24-3B2-4C20-2B7-4C16-2B11-2C14-2B13-C13-2B14-C12-2B15-C11-2B16-C11-B8-A8-C10-11A7-2(HC28-)HC29-C9-12A9-10A10-A30-29A-2A27-3(2A28-)2A27-2A-7C18-2B4-7C16-2B8-4C15-2B11-2C14-2B13-C13-2B14-C12-2B15-C11-2B16-C10-2B17-C9-A9-2A8-C9-12A8-C8-13A8-C7-14A9-A5-4A9-2A10-8A72-3(29A-)29A2-28A9-7A12B12-5A12B13-5A11B14-5A10B15-5A9B16-5A8B17-5A7B18-5A6B19-5A5B20-5A4B21-5A3B22-5A2B24-4AB26-2A47-
