model
size = 9 30 9, scale = 0.05, origin = -y
material 
  colors = A:#222 B:#111 C:#D0D0D0 D:#1B813E E:#555 F:#2F2F2F G:#E83015 H:#FD0 I:#EEE J:#5DAC81 K:#F7D94C L:#BDC0BA M:#656765 N:#868686 O:#D0104C P:#2EA9DF Q:#DDD R:#7BA23F
voxels
2-2(KB)K3-20(7B2-)7B3-5B66-3(BK)B-BACA3CA2BCBE3B2(C2BCBEBGB)2(C2BC2(BE)B)2(C2BCBGBEB)C2BC3BEBC2BA5CA2B2AO4A2BABOBQBA2BA2O3BA2BAQ2B2PA2BA3BP2(BA2BABL2EL2(A2B)2E)BA2BABLEFLA2B7AB-7B64-A7B5A3C4AF2EN-C3A2(E2(FG)4A)2(EF)E4A2(EH)2(E4A2(GH))E3AC-2(NE)C3A2(CN)C13A8(5D4A)5D2AB7AB-3BA3B5-M58-2AB3AB6A3C3AC-E3-C2AC-ECG2C2(2AC2(-F)-C)2(2AC2(-H)-C)2AC-H-F-C2A2C2-F-C3A5C101A3B3A3B3-FAF7-F49-2A5B13ACA3C2A-3(7A2-3(AC)A2-)6(7A2-)7A-63A2-M3AM5-FAF7-4(A8-)B5-7A-9A-7A12-3(2(I-)I13-)R3-G13-3(J4D4-)5J3-7A-54A3-FAF7-F51-5A3-A2FM2FA137-7A-45A4-M221-7A-36A236-2(EA)E2-2A2(FE)F11A-7A64-
