model
size = 16 13 16, scale = 0.05, origin = -y
material 
  colors = A:#CE9D6D B:#A27A55 C:#BBB D:#EEE
voxels
-7A2C13A24(2C14A)2C7AB6A2C6ABA14-2A4(14-DA)2(5(14-2A)14-AB6A2C6A2B6A2C6ABA14-2A14-DA14-C2(A14-D)A)2(5(14-2A)14-AB6A2C6A2B6A2C6ABA14-2A14-D2(A14-C)A14-DA)5(14-2A)14-AB14A2B6A2C6ABA14-2A4(14-DA)5(14-2A)14-AB14A8B2C7BA10(14-2A)14-A23B2C7BA10(14-2A)14-A17B2(6A2C6ABA10(14-2A)14-AB14A2B)3(6A2C6ABA10(14-2A)14-AB6A2C6A2B)6A2C6ABA10(14-2A)14-AB6A2C6AB
