model
size = 11 28 11, scale = 0.05, origin = -y
material 
  colors = A:#EEE B:#CAAD5F C:#86C166 D:#AAA E:#555 F:#BBB G:#F05E1C
voxels
26-3C7-2(5C6-)19(5A6-)5C6-5C7-3D29-5D5-3(7C4-)3(7A4-)7(2A3B2A4-)5(EA3BAE4-)2(2A3B2A4-)2(7A4-)2C3B2C4-2C3-2C5-D3AD7-3D8-3F6-2D3A2D3-3(9C2-)3(9A2-)6(3A3B3A2-)2(E2A3B2AE2-)3(3A3B3A2-)2(E2A3B2AE2-)3A3B3A2(2-9A)2-2C5B2C2-2C5-2C3-DA3FAD5-D3-D6-F3-F4-2DA3DA2D2-9C-22C3A2(5C6A)5C3AE3A3B3A2E3A3B3AE4A2(3B8A)3B4AE3A3B3A2E3A3B3AE4A2(3B4AC3A)2(3B3AC4A)3B4AE3A3B3A2E3A3B3AE4A3C8A3C4A2C7B4C7-2C-DA5FAD3-D5-D4-F5-F3-DA5DAD-5C2(2B9C)2B4C3A2C2BC3AF2A2C2BC2AF3A2C2BC3AE3A3B3A2E3A3B3AE4A2(3B8A)3B4AE3A3B3AE4A2(3B4AC3A)3B3AC4A3B3A2C3A2(3B3AC4A)3B4AE3A3B3AE4A3B8A3B4A2C7B4C7-2CDAF2-4FAD-D3-6F2-F5-F3-DA5DAD-5C2(2B9C)2B4CF2A2C2BC2AFG2A2C2BC2AGF2A2C2BC2AFE3A3B3A2E3A3B3AE4A2(3B8A)3B4AE3A3B3AE4A3B4AC2(3A3B3A2C)3A3B3AC4A3B4AC3A3B3AC4A3B4AE3A3B3AE4A3B8A3B4A2C7B4C7-2CDAF2-5FD-D3-F-2(F2-)F5-F3-DA5DAD-5C2(2B9C)2B4C3A2C2BC3AF2A2C2BC2AF3A2C2BC3AE3A3B3A2E3A3B3AE4A2(3B8A)3B4AE3A3B3AE4A3B8A2(3B3A2C3A)3B4AC3A3B3A2C3A3B8A3B4AE3A3B3AE4A3B8A3B4A2C7B4C7-2CDAF2-4FAD-D3-6F2(3-F)4-2DA3DA2D2-4C2B3C-5C2B9C2B4C3A2(2C2BC6A)2C2BC3AE3A3B3A2E3A3B3AE4A2(3B8A)3B4AE3A3B3A2E3A3B3AE4A3B8A2(3B3A2C3A)3B8A3B4AE3A3B3A2E3A3B3AE4A3C8A3C4A2C7B4C7-2C-DA5FAD3-D5-D6-3F6-2D3A2D3-3(4C2B3C2-)3(9A2-)6(3A3B3A2-)2(E2A3B2AE2-)3(3A3B3A2-)2(E2A3B2AE2-)3(9A2-)2C5B2C2-2C5-2C3-DA3FAD5-D3-D17-5D5-3(3C2B2C4-)3(7A4-)7(2A3B2A4-)5(EA3BAE4-)2A3B2A3(4-7A)4-2C3B2C4-2C3-2C5-D3AD7-3D30-3C7-2(5C6-)19(5A6-)5C6-5C7-3D15-
