model
size = 32 16 20, scale = 0.05, origin = -y
material 
  colors = A:#960 B:#930 C:#F96 D:#FF9
voxels
89-6A2(25-7A)25-6A345-3C28-5A26-6A26-5A413-3CAD26-5AD4-2(27A5-)26B381-3C7-12A9-5A5-27A5-26A6-19A13-15B339-10C21-12A9-4A6-26A6-2(19A13-)13B-B18-13B308-10C12-4C5-12A10-6A2(3-29A)3-28A4-15B18-13B19-12B277-10C12-4CAD3-12A10-6A2(D2-29A)3-29A3-28B5-13B19-12B21-10B246-10C12-4C5-12A10-6A2(3-29A)3-28A4-15B18-13B19-12B21-10B23-6(7B25-)7B24-10C21-12A10-5A2(4-28A)4-20A12-15B18-13B19-12B21-10B22-7(9B23-)10C13-4C4-12A11-6A2(2-30A)2-29A3-15B18-13B19-12B21-10B22-7(9B23-)10C13-4CAD2-12A11-6A2(D-30A)2-30A2-29B4-13B19-12B21-10B22-7(9B23-)10C13-4C4-12A11-6A2(2-30A)2-29A3-15B18-13B19-12B21-10B22-7(9B23-)10C21-12A11-5A2(3-29A)3-22A10-15B18-13B19-12B21-10B22-7(9B23-)10C13-4C4-12A11-6A2(2-30A)2-29A3-15B18-13B19-12B21-10B22-7(9B23-)10C13-4CAD2-12A11-6A2(D-30A)2-30A2-29B4-13B19-12B21-10B22-7(9B23-)10C13-4C4-12A11-6A2(2-30A)2-29A3-15B18-13B19-12B21-10B23-6(7B25-)7B24-10C21-12A11-5A2(3-29A)3-23A9-15B18-13B19-12B21-10B246-10C14-4C3-12A12-6A2(-31A)-30A2-15B18-13B19-12B301-4CAD-12A12-6A2(D31A)-30A2-29B4-13B332-4CAD25-6A2(D31A)-30A2-29B323-
