model
size = 20 3 30, scale = 0.05, origin = -y
material 
  colors = A:#30C
voxels
43-2A22-6A14-6A15-4A13-2(10A10-)10A9-2(3A6-3A8-)3A6-3A7-2(2A10-2A6-)2A10-2A5-2(2A12-2A4-)2A12-2A3-5(2A14-2A2-)2A14-2A-2A16-4A16-2A-A16-A-2A12(16-4A)2(16-2A-A)16-A6(2-2A14-2A)3-2(2A12-2A4-)2A12-2A5-2(2A10-2A6-)2A10-2A7-2(3A6-3A8-)3A6-3A9-2(10A10-)10A11-7A13-7A15-4A14-2A4-A14-A4-A15-A2-A14-2A4-A13-A5-A18-A14-A5-A13-A5-A18-A20-2A10-3A5-2A17-3A12-A6-2A9-2A6-3A9-A7-2A12-A6-A10-2A6-3A9-2A8-A29-2A7-2A9-2A37-3A8-A9-A38-3A8-A25-
