model
size = 32 31 13, scale = 0.05, origin = -y
material 
  colors = A:#888 B:#111
voxels
107-B7-B22-2B7-2B23-B5-B26-B3-B28-B-2(B30-)B-B28-B3-B26-B5-B23-2B7-2B22-B3-2B2-B24-7B25-B5-B26-5B26-B4-2B25-B2-B3-B23-B7-B23-B2(-2B)-B23-2(B2-)B-B24-B6-B25-B4-B27-4B216-9(11A21-)4ABAB4A21-2(3AB)3A21-2AB5AB2A21-AB7A2BA20-ABA5BAB2A20-3A6B3A20-8AB3A19-4A5B5A18-8A3B3A17-4AB6A2B3A16-3AB7A2B3A15-4AB3(A2B)4A14-4AB3(A2B)4A13-6AB6A2B5A12-6A2B4A2B6A13-6A6B6A15-16A19-10A149-5(A10-A20-)A10-A12-8(A7-A10-A7-A4-)A6-2A10-2A2(6-A4-A6-A12-A)6-A4-A5-A14-A5-2(A4-)2A14-2A2(4-A)4-2A14-2A2(4-A)3-3A14-3A3-A7-2(4A14-4A10-)4A14-4A11-4A12-4A13-5A8-5A15-16A18-12A23-6A86-3(A12-A18-)A12-A11-A6-A12-A6-A4-A6-A12-A6-A3-9(3A5-A12-A5-3A2-)2(3A4-A14-A4-3A2-)2(3A3-A16-A3-3A2-)2(3A-3A16-3A-3A2-)3A-3A16-3A-3A3-6A16-6A4-6A16-6A7-4A14-4A11-5A10-5A13-4A10-4A15-16A18-12A23-6A53-2(A14-A16-)A14-A9-3(4A3-A14-A3-4A2-)A-2A3-A14-A3-2A2(-A)2-9(2A3-A14-A3-2(2A2-))2A2-A16-A3(2-2A)2-A16-A2-2A2-3A-5A16-5A-2A-A2(-2A)16-2(2A-)2(A2-A-2A22-2A-)A3-3A22-3A4-4A20-4A4-5A18-5A6-6A12-6A9-6A10-6A11-5A10-5A14-5A6-5A18-3A6-3A23-A4-A20-2(A16-A14-)A16-A8-2(A2-)2(A16-5(A2-))A16-2(A2-)A-A9(3-A2-A16-A2-A3-2A)3-2A-A16-A-2(2A3-)2A-A16-A-2A3-2A4-3A16-3A4-2A30-A-2(A28-A2-)A28-A3-2(A26-A4-)3A22-3A5-3A20-3A7-2A20-2A9-5A12-5A11-5A10-5A15-2A10-2A20-3A4-3A2(18-2(A16-A14-)A16-A8-2(A2-)2(A16-5(A2-))A16-2(A2-)A-A9(3-A2-A16-A2-A3-2A)3-2A-A16-A-2(2A3-)4A16-4A3-2(2A30-)A-2(A28-A2-)A28-A3-2(A26-A4-)3A22-3A5-3A20-3A7-2A20-2A9-2A18-2A11-5A10-5A13-4A10-4A18-A8-A)18-2(A16-A14-)A16-A8-2(A2-)2(A16-5(A2-))A16-2(A2-)A-A9(3-A2-A16-A2-A3-2A)3-2A-A16-A-2(2A3-)2A-A16-A-2A3-2A4-3A16-3A4-A-3(A28-A2-)A28-A3-2(A26-A4-)3A22-3A5-3A20-3A7-2A20-2A9-5A12-5A11-5A10-5A15-2A10-2A20-3A4-3A19-2(A14-A16-)A14-A9-4(A-2A3-A14-A3-2A-A2-)A-2A3-A14-A3-2A2(-A)2-8(2A3-A14-A3-2(2A2-))2A2-A16-A2-2A2-2(A-)2A2-A16-A2-2A-A2-A-5A16-5A-A2-A2(-2A)16-2(2A-)A2-A-2A22-2A-A2-A-A24-A-A3-3A22-3A2(4-4A20-4A)6-3A18-3A9-4A14-4A11-6A8-6A14-6A4-6A18-4A4-4A23-6A21-2(A14-A16-)A14-A10-2A3(4-A14-A2(4-2A))4-A14-A4-2A3-10(3A4-A14-A4-3A2-)3A3-A16-A3-3A2-4A2-A16-A2-4A2(2-7A16-7A)2-4A-2A16-2A-4A3-5A18-5A4-6A16-6A7-4A14-4A11-4A12-4A13-18A15-16A18-12A23-6A54-15(A12-A18-)A12-A17-A14-A16-A14-A15-3(2A14-)2A13-3A14-3A11-2(4A14-4A10-)5A12-5A11-5A10-5A13-6A6-6A15-16A18-12A22-8A86-14(12A20-)12A19-14A18-14A17-16A16-16A15-2(18A14-)18A13-20A12-20A13-18A15-16A19-10A139-
