model
size = 32 29 32, scale = 0.05, origin = -y
material 
  colors = A:#007 B:#111 C:#900 D:#CC0
voxels
42-12A22-8A24-8A822-12A20-12A22-8A25-6A822-3A8-3A19-12A22-8A25-6A27-4A790-4A8-4A18-3A6-3A22-8A25-6A27-4A29-2A758-5A8-5A16-4A6-4A19-4A4-4A21-3(10A22-)10A503-2(8A24-)8A146-6A8-6A14-5A6-5A18-4A4-4A21-4A2-4A4(22-10A)440-2(6A25-8A25-)6A114-7A8-7A12-6A6-6A16-5A4-5A19-5A2-5A21-3(10A22-)10A23-8A378-4A27-2(6A25-8A25-)6A27-4A82-8A8-8A10-7A6-7A14-6A4-6A18-5A2-5A20-12A21-2(10A22-)10A23-8A25-6A347-4A27-2(6A25-8A25-)6A27-4A29-2A50-2(9A8-)8A6-8A12-7A4-7A16-6A2-4ACA19-12A20-12A21-10A22-10A23-8A25-6A27-4A316-4A27-2(6A25-8A25-)6A27-4A29-2A49-10A8-10A2(6-9A)10-8A4-8A14-7A2-4AD2A18-2(12A20-)12A21-10A23-8A25-6A27-4A29-2A285-4A27-2(6A25-8A25-)6A27-4A29-2A48-11A8-11A4-10A6-10A8-9A4-9A12-8A2-4AC3A16-14A19-2(12A20-)12A21-10A23-2(8A24-)8A282-4A27-2(6A25-8A25-)6A27-4A29-2A47-12A8-12A2-2(11A6-)10A4-10A10-9A2-9A14-16A18-3(12A20-)12A21-10A22-10A23-2(8A24-)8A218-4A27-6A25-2(8A24-)8A25-6A27-4A29-2A47-8AB3A8-3AB8A-12A6-12A2(4-11A)8-10A2-10A12-18A16-14A19-3(12A20-)12A21-2(10A22-)10A23-8A26-5(4A28-)4A26-8A23-5(10A22-)10A26-2A47-9AB2A8-2AB9A-12A6-12A3-12A4-12A6-6AC4A2-11A10-20A14-16A18-6(12A20-)12A21-10A6(22-A-6A-A)8(22-10A)43-5AB4ABA8-AB4AB5A-12A6-12A3-8AC3A4-12A5-7AD4A2-4AC7A8-5AC16A12-18A16-14A19-10(12A20-)4(12A21-10A21-)12A20-12A21-10A25-B3A14-11AB8-B11A-12A6-12A3-12A4-12A5-7AC4A2-4AD7A7-24A10-20A14-16A18-10(12A20-)4(12A21-10A21-)12A20-12A21-10A25-2(BA)14-11AB8-B11A-12A6-12A3-12A4-12A5-12A2-4AC7A7-24A9-22A12-18A16-14A19-9(12A20-)4(12A21-10A21-)12A20-12A21-10A25-B3A14-11AB8-B11A-12A6-12A3-12A4-12A5-12A2-12A7-24A9-22A12-18A16-14A19-9(12A20-)4(12A21-10A21-)12A20-12A21-10A25-2(BA)14-2(5AB)8-B11A-9AC2A6-12A3-12A4-12A5-12A2-12A7-24A10-20A14-2AC13A18-10(12A20-)4(12A21-10A21-)12A20-12A21-10A25-B3A14-10ABA8-AB4AB5A-9AD2A6-12A3-8AC3A4-12A5-12A2-12A8-22A12-3AC14A16-14A19-5(12A20-)12A21-10A6(22-A-6A-A)8(22-10A)43-9AB2A8-2AB9A-9AC2A6-12A3-12A4-12A6-11A2-11A10-15AC4A14-13AD2A18-3(12A20-)12A21-2(10A22-)10A23-8A26-5(4A28-)4A26-8A23-5(10A22-)10A26-2A47-8AB3A8-3AB8A-12A6-12A2(4-11A)8-10A2-10A12-18A16-12ACA19-2(12A20-)12A21-10A22-10A23-2(8A24-)8A218-4A27-6A25-2(8A24-)8A25-6A27-4A29-2A47-12A8-12A2-2(11A6-)10A4-10A10-4AC4A2-9A14-16A18-2(12A20-)12A21-9A3(24-8A)282-4A27-2(6A25-8A25-)6A27-4A29-2A48-11A8-11A4-10A6-10A8-5AC3A4-9A12-3AD4A2-8A16-AC12A19-12A20-12A21-10A23-8A25-6A27-4A29-2A285-4A27-2(6A25-8A25-)6A27-4A29-2A49-10A8-10A2(6-9A)10-8A4-8A14-2AC4A2-7A18-12A20-12A21-10A22-10A23-8A25-6A27-4A316-4A27-2(6A25-8A25-)6A27-4A29-2A50-2(9A8-)8A6-8A12-7A4-7A16-6A2-6A19-12A21-2(10A22-)10A23-8A25-6A347-4A27-2(6A25-8A25-)6A27-4A29-2A51-8A8-8A10-7A6-7A14-6A4-6A18-5A2-5A21-3(10A22-)10A23-8A378-4A27-2(6A25-8A25-)6A27-4A83-7A8-7A12-6A6-6A16-5A4-5A20-4A2-4A4(22-10A)440-2(6A25-8A25-)6A115-6A8-6A14-2AC2A6-5A18-4A4-4A21-4A2-4A3(22-10A)503-2(8A24-)8A147-5A8-5A16-4A6-4A21-2A4-2A25-6A27-4A29-2A759-4A8-4A18-3A6-3A22-8A25-6A27-4A791-3A8-3A20-10A23-8A25-6A813-
