model
size = 25 8 23, scale = 0.05, origin = -y
material 
  colors = A:#FFA5A5 B:#FFD240 C:#8E695F D:#FFF E:#FF7F7E F:#FEDFC3 G:#3A5D95
voxels
34-6A19-6A169-6A19-2A3-A139-2(11A8B6-)11A7B7-11A7B106-3(16A5B4-)16A4B5-15A5B22-2B55-17A2(5B3-2A3C12A)5B3-17A5B3-16A6B20-4B22-2B29-18A2(5B2-3A5C10A)5B2-14AD3A6B-14A2BA6B16-2B-6B16-2B2-4B22-2B4-18A2(5B2-2A6C10A)5B2-11A4D3A6B-11A2DADBA7B11-FD2A2B-6B16-2B2-4B21-3B3-19A2(5B-2A8C9A)5B-12A4D3A6B12A4DBA7B11-FD2A2B-7B15-2B-6B19-5B2-19A2(5B-A9C9A)5B-15AD3A6B16ABA7B11-FG2A2B-7B15-2B-6B19-5B2-19A2(5B-A9C9A)5B-19A6B3AE11A2BA7B3-E3-A7-2B-7B15-2B-2(7B18-6B-19A2(5B-A9C9A)5B-8AC10A6B2A3E13A-6B2-3E2-4A8-6B7-2A9-)7B18-7B19A2(5B-A9C9A)6B19A6B3AE11A2BA-6B3-E3-A7-2B2-6B15-2B-7B18-7B19A2(5B-A9C9A)6B15AD3A6B15A2BA-6B11-FD2A2B2-6B15-2B-7B18-7B19A2(5B-2A8C9A)6B12A4D3A6B12A2DADBA-6B11-FD2A2B2-6B15-2B-7B18-7B-18A2(5B2-2A6C10A)6B-11A4D3A6B-11A4DBA-6B11-FG2A2B2-5B16-2B-6B19-6B2-18A2(5B2-3A5C10A)6B-14AD3A6B-14A2BA-5B16-2B2-4B17-2B-5B20-5B4-17A2(5B3-2A3C12A)6B2-17A6B2-16A-5B20-4B2(20-5B)5-4(16A5B4-)15A-4B21-4B2(20-5B)2(6-11A8B)6-11A3BA4B6-11A8B2(21-4B)21-3B21-4B37-6A19-2A3-A3-B2(24-2B)23-3B22-3B21-4B37-6A19-6A80-B24-2B22-3B174-B23-2B3-
