model
size = 16 24 30, scale = 0.05, origin = -y
material 
  colors = A:#D7C4BB B:#EEE C:#9E7A7A D:#0F4C3A E:#F7D94C F:#B19693 G:#4F726C
voxels
326-4E61-2C13-4C364-4C12-A2-A2(12-4C)331-6C2(10-A4-A)10-6C330-6C10-A4-A9-A6-A8-2C4-2C10-4B314-A6C2(A8-A6-)A8-C6-C9-6B313-A6C2(A8-A6-)A7-B8-B7-A6-A9-6B296-B8C4(B6-B8-)B7-8B295-B8C4(B6-B8-)B7-B6-B9-6B279-3(A10-A4-)A10-A5-B8-B6-B8-B7-8B278-A10-A4-C10-A4-A10-C2(4-A10-A)5-B8-B7-B6-B9-6C263-A10-A3-A12-A2-C12-A3-A10-C2(4-A10-A)5-B8-B7-2A4-2A10-4C247-3(A12-A2-)C12-C2-C12-C3-A10-A4-A10-A5-B8-B7-8A245-3(A12-A2-)2(C12-C2-)A12-A2-A12-A3-A10-A5-BA6-AB8-6C230-A12-A-B2(14-2B)14-BC14-C-2(A12-A2-)A12-A3-A10-A5-2B2A2-2A2B10-2C216-A12-A-B3(14-2B)14-BC14-C-A12-A2-A12-A3-A10-A4-2A8-2A6-3B2A3B213-A12-A-B4(14-2B)14-BC14-C-A12-A2-A12-A3-A10-A5-4B2-4B10-2C200-A12-A-B4(14-2B)2(14-BC)14-C-A12-A2-A12-A3-2B8-2B6-3B2A3B197-A12-A-B5(14-2B)14-BC14-C-A12-A2-A12-A3-2B8-2B6-8A197-2A11-A-B6(14-2B)14-BC14-C-A12-A3-B10-B5-3A4-3A9-4A184-A10-A3-A12-A-B5(14-2B)14-B-C12-A2-A12-A3-B10-B5-3A4-3A9-4A93-2D14-3D12-4D13-2D41-3A6-3A3-A12-A2-A12-A-B4(14-2B)14-B-A12-A2-A12-A3-B10-B5-2A6-2A8-CA2-AC12-2B30-2G13-2(4D12-)D2-D11-2D3-D10-D4-D10-2D2-2D11-4D13-2D10-10A5-A10-A3-A12-A2-A12-A-B2(14-2B)14-B-2(A12-A2-)A12-A3-B10-B5-2A6-2A8-C4-C11-A2-A12-4B12-G2-G2(12-D2-D)11-3(D4-D10-)D4-D11-D2-D12-4D12-4B9-3A4-3A5-A10-A3-5(A12-A2-)A12-A3-A10-A4-2B8-2B2(6-A)9-C4-C10-C4-C11-B2-B12-G2-G2(12-D2-D)11-3(D4-D10-)D4-D11-D2-D12-4D26-8A6-2A8-2A4-A10-A3-B12-B2-B12-A2-A12-A2(2-B12-B)3-A10-A5-B8-B7-A6-A9-C4-C10-C4-C11-B2-B12-G2-G12-D2-D2(12-4D)11-2(D4-D10-)D4-D11-D2-D12-4D28-4B9-3A4-3A5-2A8-2A4-A10-A3-BA11-B2-B12-B3-2(A10-A4-)A10-A5-B8-B7-A6-A9-C4-C11-F2-F12-B2-B12-4G12-4D43-D4ED10-D4-D11-2(D2-D12-)4D43-6B9-2B4-2B7-A8-A5-3(A10-A4-)A10-A5-A8-A7-A6-A8-A6-A9-C4-C11-F2-F12-4B76-4E2(12-D2-D)13-2D77-4A10-8A7-2(2A6-)2(A8-A6-)A8-A7-A6-A8-A6-A9-C4-C11-F2-F12-4F92-4E12-E2-E12-4E123-6C9-3C2A3C2(8-2C4-2C)9-C4-C10-2C2-2C11-4C13-2F109-4E13-2E158-2C13-2(4C12-)4C13-2C141-4E13-2E55-
