model
size = 32 3 32, scale = 0.05, origin = -y
material 
  colors = A:#EEE B:#222 C:#DDD D:#707C74 E:#1E88A8 F:#E83015 G:#7BA23F H:#E03C8A I:#DDD23B J:#E2943B K:#D0104C
voxels
-63A15(F-)2F32A2H15(-H)2(64AH30BH)34A-3A-2A14E9AHB5C24BH7A13D14A-3A-2AE12AE9AHB5C24BH7A2(D5A)D14A2-A2-2AEA4G3AF3AE9AEB5C24BE7A2(D5A)D21AEAG6AF3AE9AEB5C24BE7A2(D5A)D14A2-A2-2AEAG6AF3AE9AEB5C24BE7A2(D5A)D14A-3A-2AEAG6AF3AE9AEB5C24BE7A2(D5A)D14A2-A2-2AEAG4A5FAE9AEB5C24BE7A19D15AE12AE9AGB5C24BG19AD5AD8A2-A2-2AEA4GAF3AFAE9AGB5C24BG19AD5AD9A2(-2A)EAG4AF2A2FAE9AGB5C24BG19AD5AD8A2-A2-2AEAG4A3(FA)E9AGB5C24BG19AD5AD15AEAG4A2F2AFAE9AGB5C24BG19AD5AD8A-A3-2AEAG4AF3AFAE9AGB5C24BG19A7D8A2(-A)-2AE12AE9AIB5C24BI19AD5AD8A3-A-2AEA4G3AF3AE9AIB5C24BI19AD5AD15AEAG2AG3AF3AE9AIB5C24BI19AD5AD8A5-2AEAG2AG3AF3AE9AIB5C24BI19AD5AD15AEAG2AG3AF3AE9AIB5C24BI19AD5AD8A3-A-2AEAG2AG3AF3AE9AIB5C24BI7A19D8A2(-A)-2AE12AE9AJB5C24BJ7A2(D5A)D14A5-2AEAG4AF3AFAE9AJB5C24BJ7A2(D5A)D21AEAG4AF3AFAE9AJ30BJ7A2(D5A)D14A5-2AEA3G2A3(FA)E9AJB5C18B6CJ7A2(D5A)D14A3-A-2AEAG4A2(2FA)E9AJB5C18B6CJ7A2(D5A)D17A2-2AEA4GAF3AFAE9AFB5C18B6CK7A13D14A3-A-2AE12AE9AFB5C18B6CK34A5-2A14E9AFB5C18B6CF64AF30BF32A
