model
size = 28 27 30, scale = 0.05, origin = -y
material 
  colors = A:#08082F B:#002 C:#1D1D56 D:#400 E:#F90 F:#FF1C1C G:#500 H:#FC3 I:#FC6
voxels
65-10E48-E4-E23-E2-E51-H4-H22-H4-H51-E2-E25-2E24-H4-H22-H4-H24-2E25-E2-E51-H4-H22-H4-H51-E2-E23-E4-E188-10E48-E4-E23-E2-E51-H4-H22-H4-H51-E2-E25-2E24-H4-H22-H4-H24-2E25-E2-E51-H4-H22-H4-H51-E2-E23-E4-E214-14E17-3(8C20-)4(2D4C2D20-)2(8C4(20-2D4C2D)20-)2(8C20-)8C183-5E8-5E13-2(3A6B3A16-)5(AHA6BAHA2(16-3A6B3A)16-)AHA6BAHA2(16-3A6B3A)19-3(F4-F22-)F4-F72-E16-E11-2(5A6-5A12-AD3A6-3ADA12-)2(AD3A6-3ADA12-5A6-5A12-)5A6-5A2(12-AD3A6-3ADA)2(12-5A6-5A)12-AD3A6-3ADA12-5A6-5A2(12-AD3A6-3ADA)12-5A6-5A12-AD3A6-3ADA12-5A6-5A101-F4-F72-E16-E11-39(2A12-)2A13-3(F12-F14-)F3-F4-F3-F37-3E18-3E653-F12-F14-2F10-2F37-2E20-2E5-21(2A18-2A6-)2A18-2A66-2F10-2F36-2E22-2E4-2(2A18-2A6-)2(IA18-AI6-2A18-2A6-)2(GA18-AG6-)2A18-2A6-IA18-AI2(6-2A18-2A)6-IA18-AI6-2A18-2A2(6-GA18-AG)6-2A18-2A6-IA18-AI4(6-2A18-2A)3(6-F20-F)32-E24-E3-21(3A18-3A4-)3A18-3A114-2E24-2E2-2(2A20-2A4-)2(IA20-AI4-2A20-2A4-)2(GA20-AG4-)2A20-2A4-IA20-AI2(4-2A20-2A)4-IA20-AI4-2A20-2A2(4-GA20-AG)4-2A20-2A4-IA20-AI4(4-2A20-2A)114-2E24-2E-3(C2A20-2AC2-)4(D2A20-2AD2-)C2A20-2AC6(2-D2A20-2AD)2-C2A20-2AC4(2-D2A20-2AD)3(2-C2A20-2AC)3-2(F22-F4-)2F20-2F30-2E24-2E-CB22-BC-ECB22-BCE-CB22-BC2-DB22-BD-HCB22-BC2HCB22-BCH-DB22-BD2-CB22-BC2-DB22-BD-H3(DB22-BD2H)DB22-BDH-DB22-BD2-CB22-BC2-DB22-BD-HDB22-BD2HDB22-BDH-DB22-BD2-CB22-BC-ECB22-BCE-CB22-BC113-2E24-2E-CB22-BC2-CB22-BC2(-ECB22-BCE-3(DB22-BD2-)DB22-BD)2(2-DB22-BD)-ECB22-BCE-3(DB22-BD2-)DB22-BD-ECB22-BCE-CB22-BC2-CB22-BC113-2E24-2E-7(CB22-BC2-)2(CB22-BC-ECB22-BCE-3(CB22-BC2-))4(CB22-BC2-)CB22-BC113-2(2E24-2E-8(CB22-BC2-)2(CB22-BC-ECB22-BCE-CB22-BC2-)7(CB22-BC2-)CB22-BC3-3(F22-F4-)3F18-3F2-)2E24-2E-7(CB22-BC2-)2(CB22-BC-ECB22-BCE-3(CB22-BC2-))4(CB22-BC2-)CB22-BC113-2E24-2E-CB22-BC2-CB22-BC2(-ECB22-BCE-3(DB22-BD2-)DB22-BD)2(2-DB22-BD)-ECB22-BCE-3(DB22-BD2-)DB22-BD-ECB22-BCE-CB22-BC2-CB22-BC113-2E24-2E-CB22-BC-ECB22-BCE-CB22-BC2-DB22-BD-HCB22-BC2HCB22-BCH-DB22-BD2-CB22-BC2-DB22-BD-H3(DB22-BD2H)DB22-BDH-DB22-BD2-CB22-BC2-DB22-BD-HDB22-BD2HDB22-BDH-DB22-BD2-CB22-BC-ECB22-BCE-CB22-BC113-2E24-2E-3(C2A20-2AC2-)4(D2A20-2AD2-)C2A20-2AC6(2-D2A20-2AD)2-C2A20-2AC4(2-D2A20-2AD)3(2-C2A20-2AC)3-2(F22-F4-)2F20-2F30-2E24-2E2-2(2A20-2A4-)2(IA20-AI4-2A20-2A4-)2(GA20-AG4-)2A20-2A4-IA20-AI2(4-2A20-2A)4-IA20-AI4-2A20-2A2(4-GA20-AG)4-2A20-2A4-IA20-AI4(4-2A20-2A)115-E24-E3-21(3A18-3A4-)3A18-3A115-2E22-2E4-2(2A18-2A6-)2(IA18-AI6-2A18-2A6-)2(GA18-AG6-)2A18-2A6-IA18-AI2(6-2A18-2A)6-IA18-AI6-2A18-2A2(6-GA18-AG)6-2A18-2A6-IA18-AI4(6-2A18-2A)3(6-F20-F)33-2E20-2E5-21(2A18-2A6-)2A18-2A66-2F10-2F37-3E18-3E653-F12-F14-2F10-2F68-E16-E11-39(2A12-)2A13-3(F12-F14-)F3-F4-F3-F68-E16-E11-2(5A6-5A12-AG3A6-3AGA12-)2(AG3A6-3AGA12-5A6-5A12-)5A6-5A2(12-AG3A6-3AGA)2(12-5A6-5A)12-AG3A6-3AGA12-5A6-5A2(12-AG3A6-3AGA)12-5A6-5A12-AG3A6-3AGA12-5A6-5A101-F4-F72-5E8-5E13-2(3A6B3A16-)5(AIA6BAIA2(16-3A6B3A)16-)AIA6BAIA2(16-3A6B3A)19-3(F4-F22-)F4-F74-14E17-3(8C20-)4(2G4C2G20-)2(8C4(20-2G4C2G)20-)2(8C20-)8C150-
