model
size = 21 30 30, scale = 0.05, origin = -y
material 
  colors = A:#B00 B:#222 C:#A00 D:#FF3 E:#CACACA
voxels
448-7B600-11B618-4B2A3BA3B616-4B2(AB)3A4B614-5BABA3BA5B612-7B2AB2A7B610-21B609-7B7A7B7-3AC3A595-5B3A5-3A5B2(5-3A)13-2AC2A16-2AD2A554-4B2A9-2A4B4-2A9-2A10-2A5-2A12-9A14-A3DA16-5D512-3BA13-A3B3-A13-A7-2A9-2A8-4A5-4A10-9A12-2C5A2C14-A3DA491-2B2A13-2A2B2-2A13-2A6-A11-A8-2(2A9-)3A5-3A10-3C5A3C11-9A14-2AD2A470-2BA15-A2B2-A15-A5-A13-A6-2A11-2A2(7-3A)8-4C5-4C9-11A12-7A15-2AC2A449-B2A15-2AB-2A15-2A4-A13-A6-2A11-2A7-2A9-2A8-3C7-3C9-4A3-4A11-9A13-7A16-ACA429-BA17-AB-A17-A3-A15-A4-2A13-2A5-2A11-2A6-D2A9-2AD7-4A5-4A9-11A11-4AC4A14-2AC2A428-BA17-AB-A17-A3-A15-A4-2A13-2A5-DA11-AD6-D2A9-2AD7-D2A7-2AD9-4ACAC4A11-3A3C3A13-2A3C2A427-BA17-AB-C17-C3-C15-C4-DA13-AD5-DA11-AD6-D2A9-2AD7-D2A7-2AD9-D4AC4AD11-CA5CAC13-7C15-5B15-B5-B13-B7-B11-2(B9-)B11-B7-B13-B5-B15-B3-B17-B-B12(19-2B)A17-AB-A17-A3-A15-A4-2A13-2A5-DA11-AD6-D2A9-2AD7-D2A7-2AD9-4ACAC4A11-3A3C3A13-2A3C2A427-BA17-AB-A17-A3-A15-A4-2A13-2A5-2A11-2A6-D2A9-2AD7-4A5-4A9-11A11-4AC4A14-2AC2A428-B2A15-2AB-2A15-2A4-A13-A6-2A11-2A7-2A9-2A8-3C7-3C9-4A3-4A11-9A13-7A16-ACA429-2BA15-A2B2-A15-A5-A13-A6-2A11-2A2(7-3A)8-4C5-4C9-11A12-7A15-2AC2A449-2B2A13-2A2B2-2A13-2A6-A11-A8-2(2A9-)3A5-3A10-3C5A3C11-9A14-2AD2A14-9B447-3BA13-A3B3-A13-A7-2A9-2A8-4A5-4A10-9A12-2C5A2C14-A3DA14-B7EB468-4B2A9-2A4B4-2A9-2A10-2A5-2A12-9A14-2AD2A16-A3DA14-BE2A2(EA)B489-5B3A5-3A5B2(5-3A)13-5A16-2AD2A18-A16-BA3EAEAB510-7B7A7B7-7A17-A20-A16-BA3EAEAB532-19B11-A20-A16-BE2A2EAEB554-17B12-A16-B7EB576-15B9-9B599-12B193-
