model
size = 30 32 16, scale = 0.05, origin = -y
material 
  colors = A:#7C6962 B:#E3DAC3 C:#4AA8DB D:#FDEF14 E:#6D483A F:#FF432E G:#222 H:#444
voxels
527-2F28-2C473-2(6B24-)6B887-20A9-22A7-19(24A6-)24A7-22A9-20A190-4(5A10-)20A8-20(24A6-)24A7-22A9-20A24-3C163-2(5A10-)20A8-21(24A6-)24A7-22A9-20A23-5C26-3D27-3F103-2(5A10-)20A8-8(24A6-)5(27A3-)8(24A6-)24A7-22A9-20A22-7C24-5D25-5F26-3C27-3D43-2(5A10-)20A8-7(24A6-)24A3-150A3-8(24A6-)24A7-22A9-20A22-7C24-2DF2D25-2FC2F26-3C27-3D28-F14-2(5A10-)20A8-7(24A6-)24A3-150A3-8(24A6-)24A7-22A9-20A22-7C24-5D25-5F26-3C27-3D43-2(5A10-)20A8-7(24A6-)24A3-150A3-8(24A6-)24A7-22A9-20A23-5C26-3D27-3F103-2(5A10-)20A10-20A8-6(24A6-)24A3-150A3-8(24A6-)24A7-22A9-20A24-3C163-2(5A10-)20A10-20A9-6A10B6A7-5(6A12B6A6-)6A12B6A3-10A10B76A18B11A20B5A3-A22BA6-A6B10H6B6(A6-A22B)A6-2A20B2A7-2A18B2A9-20A190-5(5A10-)5A45-5(10B20-)10B10-3A4(24-6A)24-3A10-10E27-2C20-12E18-12E46-2(3G10-3G14-)3G10-3G282-5(5A10-)5A76-3(8B22-)8B41-3A4(24-6A)24-3A47-2D466-5(5A10-)5A215-2(2A26-2A30-)2A26-2A47-2F496-3(2(A-)A10-)2(A-)A412-2C958-2D28-2D431-
