model
size = 32 32 18, scale = 0.05, origin = -y
material 
  colors = A:#960 B:#FC0 C:#FF3 D:#F90 E:#100
voxels
73-2(2C4B26-)2C4B27-C5B27-4B200-2A28-3A26-6A25-7A25-6A26-6A27-3A29-3A401-5B2C4A1010-B2D4B-2CBA59-3CB28-3C2B26-B3C2B28-2C233-2A28-4A26-6A25-6A27-5A27-3A30-2A429-2BDB9-2B55-B2C5B23-2B2C5B24-B2C5B26-C4B29-B107-2A29-3A26-5A25-7A24-7A25-7A24-8A23-9A24-7A25-2A-4A26-A-5A25-A-5A27-6A2(27-5A)28-3A29-2A202-2BD5-C8B21-B2C7B21-2(2B2C6B22-)2B2C7B24-C8B24-8B2-2B21-7B-2B22-9B4-A19-7B4-3A19-5B5-3A19-3B4-6A24-7A24-B7A23-2B8A20-11A21-2(12A20-)10A23-9A23-10A23-2A-7A22-2A-7A23-2A-6A24-A-6A2(25-A-5A)26-A-2A29-A107-2B5-2C8B5-B2CA11-B3C7B6-B3C10-2B3C6B5-3B13-2B3C8B2-4B13-2B3C8B-5BC15-2C8B2-4BC15-2C8B-5B17-C2(14BA15-2C)13B3A15-C13B4A16-9B6A18-6B8A19-5B8A21-3B8A20-14A18-13A18-12A20-9A24-11A21-12A2(B20-11A)B20-A-9AB2E20-9A3(B23-8A)26-6A28-A2-B31-B38-2B4-B2C9B3-4B2CA9-2B2C8B4-4B2C10-2B2C9B2-5BC10-3B2C9B-6B11-3B2C9B-6B3(14-2C16B)14-2C15B2A13-2C14B5A12-C14B4A14-11B6A16-10B7A16-7B9A17-6B10A16-2B14A17-B11A19-13A20-13AB18-13ABD17-13A2(B19-12A)2(BD19-11A)B2E18-11AB21-10AB23-8AB24-8A25-5AB29-A-2A37-2B3-2B2C9B3-4B2CA4-B3-3B2C9B2-5B2C9-3B2C9B2-5BC10-3B2C9B-6B11-3B2C16B12-2B3(2C16B13-B)2C15B3A11-B2C14B5A11-2C14B5A12-12B7A14-11B8A14-8B10A15-7B10A15-3B14A16-2B12A2(18-14A)2(2B17-13A)B18-13A2BD16-13A2(2BD17-12A)B2E2(18-11A2BD)19-10A2B21-11A24-7A26-5A38-2B2-2B2C5B8-5BCA4-B2-3B2C10B3-5BC8-3B2C10B2-6B9-3B2C10B2-5B11-2B3(2C17B12-B)2C17BA11-B2C16B4A9-B2C15B6A9-2C15B6A10-13B9A11-12B9A12-9B10A14-8B10A14-4B13A16-3B12A18-14A2B16-14A2B17-13A2B3C14-13ABCB2C14-13A2(2BD2C15-12A)B2E2C16-11A2BDB17-11A2BDB18-10A2BD19-10A2BD20-11A22-10A23-2A2-4A37-2BD3B2C6B8-4BA5-2BD3B2C10B3-5BC8-3B2C10B3-4B10-3B2C11B-5B10-3B2C17B11-2B2(2C17B12-B)2C17B2A10-B2C16B4A9-B2C15B6A9-2C15B5A2(11-13B8A)13-9B4AB5A14-8B8A16-4B11A18-3B13A16-B14A2B16-14A2BDBC13-14A2BDC15-13A2BDB2C14-12A2BDB2C13-13A2BDB2C14-12A2BDBC16-11A2BDBC17-10A2BDB18-10A2BD20-9A2BD21-10A22-10A23-9A25-4A7-2BD3B2C6B19-B2(D3B2C10B16-)D3B2C11B16-3B2C12B16-2B2C14B14-2B2C17BA11-B2C17B2A10-B2C16B5A8-B2C15B5A10-2C15B5A11-13B9A10-13B9A12-9B4AB6A13-8B9A15-4B10A18-4B11A18-B13A3B16-13A3BDBC13-13A3BDC15-3(12A3BDB2C13-)12A3BDB2C14-11A3BDBC16-10A3BDB17-10A3BD19-9A3BD19-12A23-10A24-7A25-6A6-BD3B2C6B10-2BA6-BD3B2C10B6-2B8-D3B2C10B17-3B2C11B3-2B11-3B2C12B2-2B12-2B2C16B12-2B2C17B2A10-B2C17B3A9-B2C16B4A9-B2C15B6A9-2C15B6A2(10-13B9A)12-9B4AB6A13-8B9A15-4B11A17-4B13A16-B14A2B16-14A2BDBC13-14A2BDC15-13A2BDB2C14-12A2BDB2C13-13A2BDB2C14-12A2BDBC15-12A2BDBC16-11A2BDB17-11A2BD19-10A2BD19-12A21-12A22-9A25-5A10-2B2C5B8-5BA8-3B2C10B3-5BC8-3B2C10B2-5B10-3B2C11B-5B2(11-2B2C17B)2(12-B2C17B)3A9-B2C16B5A8-B2C15B6A9-2C15B6A2(10-13B9A)12-9B11A13-8B10A14-4B13A15-4B12A17-B14A2B16-14A2B17-13A2B3C14-13ABCB2(2C14-13A2BD)2C14-13AB2E2C15-12A2(2BDB17-11A)2BD19-10A2BD20-11A22-10A23-8A27-2A12-2B2C7B6-5BCA8-2B2C10B2-6BC9-2B2C10B2-6B10-2B2C10B2-5B3(12-B2C17B)13-2C17BA12-2C16B4A10-2C15B6A10-2C14B6A10-13B9A11-12B8A13-9B10A14-8B10A14-4B14A14-4B12A18-14A2B16-14A2B17-13A2BD16-13ABC17-13A2BD16-13A2(2BD17-12A)B2E2(18-11A2BD)19-10A2B21-11A24-7A25-7A42-2B2C9B3-4B2CA8-3B2C8B3-5B2C9-3B2C9B2-5BC10-3B2C9B-6B12-2B2C9B-6B13-B3(2C16B14-)2C15B2A13-2C14B5A11-BC14B5A12-12B7A13-12B7A16-7B9A15-8B10A14-4B14A15-3B11A19-13A20-13A2B17-13ABD17-13AB19-12A2B18-12ABD19-11AB2D18-11AB2E18-11A2B20-10A2B21-9A2B21-10A25-5AB29-A-2A44-2C9B4-3BCA10-2B2C8B4-4B2C10-2B2C8B3-5B12-2B2C9B2-5B13-B2(2C9B-6B14-)2C15B15-2C15B16-C15BA15-C14B4A13-2C13B5A13-11B8A15-7B8A18-6B8A17-7B8A17-3B14A16-2B13A18-12A20-11A2-B18-12A2BD17-13AB19-12A2(B20-11A)B2E18-11AB21-A-2(8AB23-)8AB25-6A28-2A-B31-B47-C8B20-B3C7B21-B3C6B22-B3C6B5-2B16-3C8B2-4B17-C2(8B-5B18-)2(14BA17-)13B3A17-8B-3B3A19-4B-2B6A19-4B-8A20-4B7A23-2B8A20-11A21-12A19-13A20-10A22-10A23-10A22-11A22-10A23-9A24-8A2(25-7A)26-4A29-3A113-C8B21-2(B2C6B23-)B2C6B24-2C6B25-C5B28-3B-2B3-2B23-5B-3B23-5B-2B24-6B5-2A20-3B6-3A21-2B3-5A25-7A25-6A25-7A22-10A4(23-9A)25-7A26-7A24-9A26-6A26-4A-A26-4A28-4A29-2A137-
