model
size = 22 29 24, scale = 0.05, origin = -y
material 
  colors = A:#111 B:#777 C:#F93 D:#100 E:#666 F:#999 G:#EEE H:#FC0 I:#FC6 J:#FFF K:#FC3 L:#D00 M:#800 N:#300 O:#F90 P:#DDD Q:#0F0F0F R:#AAA S:#555 T:#900 U:#C00 V:#200 W:#BBB X:#A00 Y:#500 Z:#966 Aa:#001 Ab:#000 Ac:#996 Ad:#333 Ae:#FC9 Af:#CC6 Ag:#CCC Ah:#C90 Ai:#700 Aj:#E00 Ak:#600 Al:#400
voxels
478-3(2C20-)2C548-3(2C20-)2C431-4A91-2C19-3C18-3(4CO17-)4CO18-3C20-2C344-2B20-2A18-6A18-2A20-2A26-2C19-3C18-4C2K15-5C2Af15-5C3Z14-5C3Ac14-5C2Ae16-4C2K17-3C20-2C278-2B20-2B19-4B18-4A16-8A16-4A18-4A19-2A3-3C14-2A2-4C2K15-5C3S4(14-5C3D)14-5C3R15-4C2K17-3C234-2B20-2B19-4B18-4B17-6B16-6A14-10A14-6A16-6A2-2C13-4A-4CAh12-4A5C2R12-2A-5C3D11-2A6C4D12-6C4A12-6C4G12-6C4W13-5C3Aa14-5C2P16-4CAh19-2C211-4B18-4B17-6B16-6B15-8B14-8A12-12A12-8A14-8A-2C12-6A4CH11-5A5C3Ad10-4A5C3D10-3A6C4D12-6C4A2(12-6C4J)13-5C3Q14-5C3F15-4CH19-2C168-2B20-2B18-6B16-6B15-8B14-8B13-10B12-10A10-14A10-10A12-10A2C11-7A4CH10-6A5C3Q9-5A5C3A9-4A2(6C4D10-2A)6C4P12-6C4G13-5C3A14-5C3F15-4CH19-2C124-2B20-2B19-4B18-4B16-8B14-8B13-10B-3D8-10B-3D7-12B3D7-12A3D5-14A3D7-12A10-11A2C10-8A4CH9-7A5C2F9-6A5C2BG8-5A2(6C4D9-3A)6C4D10-2A6C4A10-2A-5C3D14-5C2Ag16-4CH19-2C123-4B18-4B17-6B16-6B14-10B-3D8-10B-3D7-12B3N7-12B3Ai6-13B3D6-13A3B4-15A3D6-14A8-14A9-10A3C9-9A4C2I8-7A5C3A7-7A2(5C3D9-5A)2(5C3D10-4A)5C3E15-4C2I17-3C102-2B20-2B18-6B16-6B15-8B2-3D9-8B2-3D7-12B3U7-12B3V6-13B3N6-13B3T5-14B3D5-14A3E3-16A3D5-16A6-16A7-12A2C8-11A3C9-9A4C2I7-8A5C2B9-6A5C3A8-6A5C3Ab9-5A5C2F10-6A4C2I12-2A3-3C14-2A4-2C58-2B20-2B19-4B18-4B16-8B14-8B13-10B-3D8-10B-3U6-13B3L6-13B3Al5-14B3V5-14B3T4-15B3D4-15A3E2-17A3D2(4-18A)5-16A6-13A2CA7-11A3C8-10A4CO2(9-8A4CH)10-7A4CO10-8A3C13-4A3-2C13-4A19-2A20-2A19-4B18-4B17-6B16-6B14-10B12-10B-3D7-12B3X7-12B2(3L5-14B)3Ak4-15B3D4-15B3M3-16B3D3-16A3E2-17A3D3-20A2-20A3-18A4-18A5-16A6-13A2CA8-11ACA9-11A2(CA10-10A)14-6A16-6A17-4A18-4A19-2B20-2B19-4B18-4B16-8B14-8B2-3D8-10B-3M8-10B-2(3L6-13B)3Y5-14B3D5-14B3M4-15B3D4-15A3E2-17A3D2(4-18A)5-16A6-16A7-14A8-12A2(CA10-10A)CA11-8A-CA11-8A16-4A18-4A19-2A20-2A64-2B20-2B18-6B16-6B15-8B2-3D9-8B2-3U7-12B3Aj7-12B3Y6-13B3D6-13B3M5-14B3D5-14A3E3-16A3D5-16A6-16A7-14A8-12A2C9-10A3C9-9A2(4CO10-7A)2(4CO11-6A)-3C14-2A4-2C14-2A151-4B18-4B17-6B3-3D10-6B3-3D8-10B-3X8-10B-3V7-12B3N7-12B3T6-13B3D6-13A3E4-15A3D6-14A8-14A9-11A2C9-10A3C10-8A4C2K8-7A5C2Af10-5A5C3Z9-5A5C3Ac10-4A5C2Ae11-4A-4C2K17-3C20-2C146-2B20-2B19-4B18-4B16-8B2-3D9-8B2-2(3D8-10B-)3N7-12B3D7-12A3S5-14A3D7-12A10-12A11-9A3C10-8A4C2K9-6A5C3S8-6A2(5C3D10-4A)2(5C3D11-2A-)5C3R15-4C2K17-3C190-2B20-2B18-6B16-6B15-8B14-8B2-3D8-10B-3D8-10A-3D6-13A3D8-10A12-10A2C11-7A4CAh10-6A5C2R10-5A5C3D9-4A6C4D10-2A6C4A10-2A6C4G12-6C4W13-5C3Aa14-5C2P16-4CAh19-2C211-4B18-4B17-6B16-6B15-8B14-8A12-12A12-8A14-8A-2C12-6A4CH11-5A5C3Ad10-4A5C3D10-3A6C4D12-6C4A2(12-6C4J)13-5C3Q14-5C3F15-4CH19-2C212-2B20-2B19-4B18-4B17-6B16-6A14-10A14-6A16-6A2-2C13-4A-4CH12-4A5C3Q11-2A-5C3A11-2A2(6C4D12-)6C4P12-6C4G13-5C3A14-5C3F15-4CH19-2C256-2B20-2B19-4B18-4A16-8A16-4A18-4A3-2C14-2A2-4CH13-2A-5C2F15-5C2BG13-3(6C4D12-)6C4A13-5C3D14-5C2Ag16-4CH19-2C300-2B20-2A18-6A18-2A20-2A25-3C18-4C2I15-5C3A4(14-5C3D)14-5C3E15-4C2I17-3C365-4A69-2C19-3C18-4C2I15-5C2B15-5C3A14-5C3Ab14-5C2F16-4C2I17-3C20-2C460-2C19-3C18-4CO2(17-4CH)17-4CO18-3C20-2C70-
