model
size = 32 26 23, scale = 0.05, origin = -y
material 
  colors = A:#63C B:#661DE1 C:#6615E9 D:#EEE E:#660EF0 F:#222 G:#60F H:#F3C I:#F36
voxels
591-B30-2B29-3B29-2B30-B674-2B29-2AB28-3A28-4A28-2(3A29-)2A610-2B2(29-3A)2(28-3A28-4A)28-3A578-A2B29-3A28-3A29-3A2(28-4A27-4A)28-4A28-3A515-A2(B29-2A)2(29-3A)28-4A2-A25-3A3-A24-4A3-2(A23-4A4-)A23-3A5-A375-3B28-B4A22-2AB2(-6A18-7A)-6A-AB15-14A-2A15-17A2(16-16A)-A15-10A-3A2-A16-4A-2(3A2-)AD24-4A2-AD24-3A3-A2D22-4A3-AD23-4A3-A216-C30-3B29-4B17-4B6-5B17-3BA6-4A2B15-2B6AB2-B3A2B15-9A2B5AB3(15-17A)-A13-17A-A13-19A14-18A-A12-18A-I13-17A-AH13-16A-A2D13-15A-A2DF18-3A2-4A-A2DF22-5A-A2D23-4A2-AD30-A75-4E8-5E15-3C9-5C15-3C9-4C16-4C8-4C16-5B7-5B15-5B6-6B15-9B2-6B14-B8A2B7A14-B9A2B6A14-B17A10-2D2-18A8-4D2-18A8-2D4-18A14-18A2(15-17A)2(-A)11-21AHA10-20A2DA2(10-19A2DF)12-17A3D18-11A2DF23-6A2D29-A75-4E8-5E15-3C9-5C15-3C9-4C16-5C7-5C15-5B7-5B14-10B2-6B14-18B4(14-18A)8-3D3-18A7-A2D4-18A6-2AD5-19A4-4A2(5-27A)6-21AI3A7-21A2D2A8-20A2DFA9-19A3DA10-18A2DFA15-13A2DF21-8A2D29-A75-4E8-5E15-3C9-5C15-3C9-4C16-5C7-4C16-5B7-5B14-10B3-5B14-18B6(14-18A)5-4AD4-19A2-6AD3(4-28A)5-21AH5A5-21A2D3A7-20A2DF2A8-19A2DF2A10-17A2D2A16-12AD2A24-7A32-2G30-2E20-3E7-2E8-2C9-4C7-3E7-2C10-3C8-3C6-3C9-2C9-3C5-5B8-2B10-3C4-10B15-3B4-11B3-B11-3B3-12A-3A10-3A3-16A10-3A2-17A10-3A2(2-18A8-4A)-20A3-8A-31A-2(30A2-)30A3-28A4-22AD5A5-21A2D4A6-20A2D3A9-18AD4A14-17A17-14A31-3G3(29-3E)3-2(2C25-3C2-)2B26-3C-2B7-4B15-3B-2B3-9B15-3BAB2-11A14-4AB-14A12-21A11-22A9-24A7-26A3-72A-2(30A2-)29A4-28A5-27A6-25A8-24A14-17A16-15A31-2G30-3E19-3E7-3E19-3C7-3E7-2C10-3C8-3C2-C3-2C10-2C9-3C2-2B-4B21-3C-2B-5B-4B15-3B-2B-11B15-3BAB-12A14-5A-16A10-22A10-23A8-4A-19A8-4A-20A3-8A-31A-2(30A2-)30A3-28A4-22AD5A5-21A2D4A6-20A2D3A9-18AD4A14-17A17-14A72-4E8-5E15-3C9-5C15-3C9-4C16-5C7-4C16-5B7-5B14-11B2-5B14-18B5(14-18A)14-19A4-5A4-20A-7AD3-29A3-2(28A4-)22AH5A5-21A2D3A7-20A2DF2A8-19A2DF2A10-17A2D2A15-13AD3A23-7A73-4E8-5E15-3C9-5C15-3C9-4C16-5C7-5C15-5B7-5B14-10B2-6B14-18B4(14-18A)8-2D4-18A7-2AD4-18A6-2AD5-19A4-3AD2(5-27A)6-21AI3A7-21A2D2A8-20A2DFA8-20A3DA10-18A2DFA15-13A2DF20-9A2D29-A75-4E8-5E15-3C9-5C15-3C9-4C16-4C8-4C16-5B7-5B15-5B6-6B14-11B-6B14-2B8AB7A2(14-18A)10-2D2-18A8-4D2-18A8-AD4-18A7-2A5-18A7-A7-17A15-17A3-A11-21AHA10-20A2DA9-20A2DF10-19A2DF12-17A3D17-12A2DF23-6A2D29-A152-2C29-3C29-3B19-2B7-5B17-4B6-5B17-2B2A6-4A2B15-9A-6AB15-16AB3(15-17A)2(-A13-17A)-A14-18A-A12-18A-I13-17A-AH12-17A-A2D13-15A-A2DF17-10A-A2DF22-5A-A2D23-4A2-AD30-A312-AB29-3AB27-5A18-2(3A-)6A18-7A-6A18-3(14A-2A15-)17A16-16A-A14-16A-A16-13A2(2-AD24-4A)2-A2D22-4A3-AD23-4A3-A508-2(2A29-3A29-)3A28-4A2-A25-3A2(3-A24-4A)3-2(A23-4A4-)A538-2(3A29-3A28-)4A28-3A28-4A27-2(4A28-)3A545-AB29-A2B28-3A29-3A28-4A27-2(4A28-)3A29-2A609-B30-AB29-ABA2(28-3A29-3A)29-2A672-B30-AB29-2AB29-AB30-B114-
