model
size = 27 31 20, scale = 0.05, origin = -y
material 
  colors = A:#D00 B:#400 C:#700 D:#A00 E:#800 F:#B00 G:#E00 H:#500 I:#100 J:#FFF K:#EEE L:#DDD M:#111 N:#CCC O:#010 P:#020 Q:#999 R:#6CC S:#063 T:#066 U:#033 V:#333 W:#777 X:#BBB Y:#399 Z:#696 Aa:#699 Ab:#3CC Ac:#099 Ad:#9CC
voxels
477-3(CEDG23-)CEDG725-3(CA2G23-)CA2G699-2G23-CE3GB21-CE3GC20-HCE3GBJ19-HCE3GCJ20-CE3GB21-CE3GB23-2G619-GH23-EDGHGB20-CEDGHG2C19-CEDGHG2Q18-HCEDGHG3N17-HCEDGHG3L18-CEDGHG2N19-CEDGHG2W20-EDGHGC23-GH190-3B24-3B370-EDHCGB20-CEDHCG2C18-2CEDHC4G17-2CEDHCG3J2(17-2CEDHCG3K)2(17-2CEDHCG3J)18-CEDHCG2E20-EDHCGB135-G26-B25-3B24-3B171-F4AF20-DF4AFD20-F4AF113-FACG21-EDFACG2B18-CEDFACG3C17-CEDFACG3J16-HCEDFACG4L15-HCEDFACG4S15-HCEDF2CG4O15-HCEDF2C4GX16-CEDF2CG3J17-CEDF2CG3J18-EDF2CG2B21-F2C2(G81-)B25-3B21-3M118-D2F4A2FD16-ED2F4A2FDE14-CED2F4A2FDEC14-ED2F4A2FDE16-D2F4A2FD58-3B22-DF3BG20-EDF3B2C18-CEDF3B3E16-HCEDF3B4K15-HCEDF3B4T2(15-HCEDFACG4I)15-HCEDFACG4Q15-HCEDFACG4Z16-CEDFACG3J18-EDFACG2Q20-DFACGC80-G131-4M23-3B64-DF6AFD15-CEDF6AFDEC12-2(HCEDF6AFDECH11-)HCEDF6AFDECH12-CEDF6AFDEC2-3B10-DF6AFD4-3B23-5B20-2D5BG18-E2D7B16-CE2D5B3E15-CE2D5B3K15-CE2D5B3U14-HCE2DF3B5I13-HCE2DF3B5I14-CE2DFACG4I15-CE2DFACG4P15-CE2DFACG4J16-E2DFACG3Q18-2DFACG2B22-AC28-G158-4M23-3B24-B15-4A7-B11-EDF6AFDE13-C2EDF6AFD2EC10-2(HC2EDF6AFD2ECH9-)HC2EDF6AFD2ECH3B7-C2EDF6AFD2EC5B3E5-EDF6AFDE2-5B12-4A6-5B20-D7B18-ED8B16-CED9B15-CED7B2K14-HCEDF5B4Ac2(13-HCEDF5B4I)13-HCEDFA3B5I14-CEDFA2CG4Aa15-CEDFA2CG4K16-EDFA2CG3C18-DFA2CG2B21-A2CG186-3M65-8A16-EDF8AFDE2-2(B8-HCEDF8AFDECH)8-BHCEDF8AFDECH3B6-HCEDF8AFDECH4B5-HCEDF8AFDECH4B7-EDF8AFDE-5B10-8A3-7B19-D7B-L16-ED8BL15-CED9B15-CED7B2F14-HCED7B3K13-HCEDF5B4R13-HCEDF5B4Y13-HCEDF5B3GX14-CEDFA3B4K15-CEDFA2CG4W16-EDFA2CG3B18-DFA2CG2B21-A2CG253-F8AF15-EDF8AFDE11-HCEDF8AFDECH8-BHCEDF8AFDECHB7-BHCEDF8AFDECH3B5-BHCEDF8AFDECH4B5-HCEDF8AFDECH4B7-EDF8AFDE7B8-F8AF2-7B19-D7B-K16-ED8BK15-CED9B14-2(HCED10B13-)HCED7B3E13-HCEDF5B4G13-HCEDF5B4E13-HCEDFA8B14-CEDFA2CG4B16-EDFA2CG3B18-DFA2CG2B20-FA2C2G252-F8AF15-EDF8AFDE11-HCEDF8AFDECH8-BHCEDF8AFDECHB7-BHCEDF8AFDECH3B5-BHCEDF8AFDECH4B5-HCEDF8AFDECH4B7-EDF8AFDE-5B9-F8AF2-7B19-D7B-K16-ED8BK15-CED7B2C14-2(HCED7B3C13-)HCEDF5B3VE13-HCEDF9B13-HCEDF5B3VE13-HCEDFA8B14-CEDFA2CG4B16-EDFA2CG3B18-DFA2CG2B20-FA2C2G253-8A16-EDF8AFDE11-HCEDF8AFDECH9-HCEDF8AFDECH8-BHCEDF8AFDECHB8-HCEDF8AFDECH3B6-HCEDF8AFDECH4B3E4-EDF8AFDE-5B10-8A4-5B20-D7B-L16-ED8BL15-CED9B15-CED7B2C14-HCEDF5B4N2(13-HCEDF5B4L)13-HCEDFA3B5K14-CEDFA2C4GX15-CEDFA2CG4C16-EDFA2CG3B18-DFA2CG2B21-A2CG186-3M67-4A19-DF8AFD3-B9-CEDF8AFDEC-B8-2(HCEDF8AFDECH9-)HCEDF8AFDECH10-CEDF8AFDEC-3B9-DF8AFD3-3B13-4A6-5B20-DF5BG18-EDF7B16-CEDF5BE2C15-CEDF5B3L14-HCEDF5B4R13-HCEDFA3B5P13-HCEDFA3B5O13-HCEDFA2CG5N14-CEDFA2CG4K15-CEDFA2CG4N16-EDFA2CG3C18-DFA2CG2B21-A2CG186-4M23-3B24-B26-B12-F8AF15-EDF8AFDE12-2(CEDF8AFDEC11-)CEDF8AFDEC12-EDF8AFDE15-F8AF31-3B21-2DF3B2G18-E2DF6B16-CE2DF3B4F15-CE2DF3B4K15-CE2DF3B4T14-HCE2DFACG5I13-HCE2DFACG5I14-CE2DFACG3CX15-CE2DFACG4U15-CE2DFACG4J16-E2DFACG3C18-2DFACG2B22-AC25-A52-2B25-3B79-4M23-3B91-DF6AFD16-EDF6AFDE14-2EDF6AFD2E14-EDF6AFDE16-DF6AFD83-DFAC2G20-EDFACG2B18-CEDFACG3E16-HCEDFACG4K15-HCEDFACG4S3(15-HCEDFACG4I)15-HCEDFACG4P16-CEDFACG3J18-EDFACG2E20-DFACGB77-A25-3B24-3B79-3M147-6A20-F6AF20-6A113-FACG21-EDFACG2B18-CEDFACG2QE17-CEDFACG3J16-HCEDFACG4Ab15-HCEDFACG4O15-HCEDFACG4I15-HCEDFACG4O16-CEDFAC3GX17-CEDFACG3J18-EDFACG2F21-FACG105-2B24-3B428-EDFAGB20-CEDFAG2C18-2CEDFAG2KE17-2CEDFAG3J17-2CEDFAG3L17-2CEDFAG3Ad17-2CEDFAG3L17-2CEDFCG3J18-CEDFCG2L20-EDFCGC590-DF23-E2DFGB20-CE2DFG2B19-CE2DFG2L18-HCE2DFG3J17-HCE2DFG3J18-CE2DFG2J19-CE2DFG2L20-E2DFGB23-DF619-2D23-CE2DGB21-CE2DGC20-HCE2DGBJ19-HCE2DGFJ20-CE2DGB21-CE2DGC23-2D249-
