model
size = 31 31 13, scale = 0.05, origin = -y
material 
  colors = A:#FC0 B:#F96 C:#FF0
voxels
14-ACA27-BC-CB25-AC3-CA23-BC5-CB21-BC7-CB20-AB7-BA20-BC7-CB20-AB2-BCB2-BA20-BC2-CAC2-CB20-AB2-BCB2-BA14-3(BA)B9A3(BA)B7-3(BC)B2(A4-)A3(BC)B5-AC6-A3-3B3-A6-CA3-BC7-A2-B3CB2-A7-CB-AC5-BCBA-BC3ACB-ABCB5-CAC6-CAC2AB2(CA)CB2ACAC6-CAC5-BCBA-BC3ACB-ABCB5-CA-BC7-A2-B3CB2-A7-CB3-AC6-A3-3B3-A6-CA5-3(BC)B2(A4-)A3(BC)B7-3(BA)B9A3(BA)B14-AB2-BCB2-BA20-BC2-CAC2-CB20-AB2-BCB2-BA20-BC7-CB20-AB7-BA20-BC7-CB21-BC5-CB23-AC3-CA25-BC-CB27-ACA494-A896-2(5A25-2ABAB2A25-)5A832-2AB2A25-7A24-2B3A2B24-7A25-2AB2A896-A3843-A896-2AB2A25-7A24-2B3A2B24-7A25-2AB2A832-2(5A25-2ABAB2A25-)5A896-A494-ACA27-BC-CB25-AC3-CA23-BC5-CB21-BC7-CB20-AB7-BA20-BC7-CB20-AB2-BCB2-BA20-BC2-CAC2-CB20-AB2-BCB2-BA14-3(BA)B9A3(BA)B7-3(BC)B2(A4-)A3(BC)B5-AC6-A3-3B3-A6-CA3-BC7-A2-B3CB2-A7-CB-AC5-BCBA-BC3ACB-ABCB5-CAC6-CAC2AB2(CA)CB2ACAC6-CAC5-BCBA-BC3ACB-ABCB5-CA-BC7-A2-B3CB2-A7-CB3-AC6-A3-3B3-A6-CA5-3(BC)B2(A4-)A3(BC)B7-3(BA)B9A3(BA)B14-AB2-BCB2-BA20-BC2-CAC2-CB20-AB2-BCB2-BA20-BC7-CB20-AB7-BA20-BC7-CB21-BC5-CB23-AC3-CA25-BC-CB27-ACA14-
