model
size = 19 16 19, scale = 0.05, origin = -y
material 
  colors = A:#200 B:#633 C:#00E D:#EEE E:#555 F:#050 G:#888
voxels
6-4(7A12-)5(2A3C2A12-)A5CA5(12-7A)6-19A4-2E7A2E3(8-2B7A2B)2(8-2B2A3C2A2B)8-FBA5-ABF156-A17-A3-3E7A3E3(6-3B7A3B)2(6-3B2A3C2A3B)6-F2BA5-A2BF155-A17-A2-4E7A4E3(4-4B7A4B)4-4B2A3C2A4B4-4B2A3-2A4B4-F2BFA5-AF2BF154-A17-A-5E7A5E3(2-5B7A5B)2-5B2A3C2A5B2-5B2A3-2A5B2-3BF9-F2BF153-A17-A-5E7A5E3(2-5B7A5B)2-5B2A3C2A5B2-5B2A3-2A5B2-FBF11-F2B153-A17-7A7G3(12A7D)12A2D3C2D12A2F3-2F10A11-5A8(17-2A)17-7A7G2(12A7D)12AC6D12AF6C12AF5-F9A13-4A6(17-2A)16-3A15-4A17-7A7G2(12A7D)6A7C6D6AC6-13C4(17-2C)17-CA3(17-2A)16-3A15-4A17-7A7G2(12A7D)6A7C6D6AC6-13C8-F8-4(2C17-)3(CA17-)CA16-3A15-4A17-7A7G2(12A7D)6A7C6D6AC6-13C4(17-2C)17-CA3(17-2A)16-3A15-4A17-7A7G2(12A7D)7A12D7A11CD7A2C4F5-F7AFB13-4A6(17-2A)16-3A15-4A17-7A7G2(12A7D)7A7D3C2D7A6DF3-FD7A3D4F3-2F7A2BF11-5A8(17-2A)17-A-5E7A5E2(2-5B7A5B)2-5B2A3C2D5B2-5B2A3-FD5B2-5B2A3-2F5B2-3B11-F2B153-A17-A-5E7A5E2(2-5B7A5B)2-5B2A3C2D5B2-5B2A3-FD5B2-5B2A3-2F5B2-F2BF9-F2BF153-A17-A2-4E7A4E2(4-4B7A4B)4-4B2A3C2D2(4B4-4B2A3-FD)4B4-F3BA5-F3BF154-A17-A3-3E7A3E2(6-3B7A3B)6-3B2A3C2D2(3B6-3B2A3-FD)3B6-F2B2A3-F3BF155-A17-A4-2E7A2E2(8-2B7A2B)8-2B2A3C2D2(2B8-2B2A3-FD)2B8-FB2A3-3BF156-A17-A6-3(7A12-)6(2A3C2A12-)2ACAC2A12-2(A2C)A4(12-7A)6-19A
