model
size = 29 14 27, scale = 0.05, origin = -y
material 
  colors = A:#FF6905 B:#0A0000 C:#FEFEFE D:#F6D644 E:#FDF4B9 F:#FAEB88 G:#F28214 H:#F2AB14 I:#F29114 J:#B9E7FD K:#4AA7F6 L:#1352F1 M:#F3BC27 N:#1224B0 O:#FF5705 P:#F23914 Q:#FF3A05 R:#ED2707 S:#030303 T:#FE3C00
voxels
96-11B18-2(C2B)3C3(2B18-4(CB)C)2B18-3(CB)3CBC18-11B219-3B9-3B14-3C3(9-BCB14-CBC)9-BCB14-3C9-3C14-3B9-3B216-2B5(13-2B12-BC)13-CB12-2B13-2B214-2B2(15-2B10-CB)15-2B10-2B2(15-BC10-CB)15-BC10-2B15-2B212-2B17-2B8-BC17-2B8-2C17-2B8-CB17-2C8-2C17-CB8-BC17-2C8-2B17-2B210-2B19-2B6-CB19-2C6-2C19-2C6-BC19-2C6-2C19-2C6-CB19-2C6-2B19-2B208-2(2B2(21-2B4-BC)21-2B4-)2B21-2B206-2B3(23-2B2-CB)23-BC2(2-CB23-2C)2-2B23-2B204-2B25-2B2C25-2CBC25-4C25-2CBC25-2B2C25-4B25-2B203-B27-BC27-2B27-BC27-CB27-2C27-CB27-B203-B6(27-2B)27-B203-B27-BC2(27-2C)27-BC27-2C27-CB27-B203-B27-BC2(27-2B)27-CB27-2B27-CB27-B203-B27-BC5(27-CB)27-B203-B6(27-2B)27-B203-B27-BC27-CB3(27-BC)27-CB27-B203-B27-BC27-CB27-BC27-2B27-BC27-CB27-B203-B27-BC2(27-2C)27-CB27-2C27-CB27-B203-B6(27-2B)27-B121-8B3-8B7-7B3-2B-2B3-7B2-4B9-B-B9-5B2S10-3B10-S2B-C2(B11-)2(BC-BSB23-3B-CB23-)BC-BSB23-4BSB23-7B21-BS2B-7B13-7B4-5B13-5B8-8B3-8B7-4BA7B-7BA4B2-3BLKJE6-B-B6-EJKL4B2(2ALKJE6-3B6-EJKL2A2B)2ALKJE7-B7-EJKL5(2A2B2ANLKJ15-JKLN)2A3BANLKJ15-JKLNA2B-3B3A4B7-4B3A3B4-8B7-8B8-8B3-8B7-4B4A4B-4B4A4B2-3B4ADHI3-B-B3-IHD4A4B2(6ADHI3-3B3-IHD6A2B)6ADHI4-B4-IHD5(6A2B6AEDH9-HDE)6A3B5AEDH9-HDE5A2B-3B6A9B6A3B4-23B8-8B3-8B7-4B6ATB-2B6A4B2-3B7AG2AB-B2AG7A4B9AG2A3B2AG9ABN9AGA-3B-AG9A2N9AGA2-B2-AG4(9A2N9AIG5-GI)9ANB9AIG5-GI9A3B8AIG5-GI8ATB-3B8A5B8A3B4-23B8-8B3-8B7-4B6A2B-2B6A4B3-2B10AB-B10A2B2-K12AB12AK2-K10AP3AP10AK2-L10APRARP10AL2-L10A2PR2P10A3(L2-L11APRP11A)L2-L12AP12AL2-B12AP12AB2-3B21AT2B4-23B8-8B3-8B7-4B6A2B-2B6A4B4-B10AB-B10AB4-J11AB11A2(J4-J23A)J5(4-K23AK)4-KJ21AJK4-BJ21A2B5-23B8-8B3-8B8-3B2D4A2B-2B4A2D3B6-E2FD6AB-B6AD2FE6-E2FD7AB7AD2FE6-E2FD15AD2FE6(6-JEFD15ADFEJ)7-EF2D13A2DFE8-E2F2D11A2D2FE8-21B10-7B3-7B12-2MHIGA2B-2BAGIH2M11-D2MHIGAOB-BOAGIH2MD9-F2DMHIGAO3BOAGIHM2DF8-2FDMHIGAOQBQOAGIHMD2F5(8-EFDMHIGAOQRQOAGIHMDFE)8-EFDMHI2GAOQOA2GIHMDFE9-FDMHI2GAOQOA2GIHMDF11-FDMHIGAOQOAGIHMDF12-17B6-
