model
size = 5 24 14, scale = 0.05, origin = -y
material 
  colors = A:#111 B:#222 C:#612000 D:#E00 E:#0C0
voxels
22-6(B4-)B162-5(BA)B3A5(BA)B95-3(AB)3AB5AB3AB5A95-2(BA)B5AB3AB5A2(BA)B17-6(B4-)B47-3(AB)3AB5A2(BA)B22-B14-2(B4-)B52-2(BA)B5AB3A3(BA)22-B9-2(B4-)B52-2(B3AB5A)2(BA)B21-3B3-B4-B57-2(B3AB5A)B3A3(BA)7-C4-C3-3C-5B-3B3-A2(2(4-D)4-B)2(4-D4-B)4-D2-2(5AB3AB)5A2(BA)B6-2(3C2-)3C-5B-BCB3-A2(2(4-D)4-B)2(4-D4-B)4-D2-2(B3AB5A)5(BA)7-C12-5B-BEB3-A2(4-D4-B)3(4-B4-D)4-B2-5AB3A3(BA)22-C13-3B3-B4-B57-B3AB5A2(BA)B22-3(C4-)B9-2(B4-)B52-B3A3(BA)37-B14-2(B4-)B52-2(BA)B20-
