model
size = 25 30 19, scale = 0.05, origin = -y
material 
  colors = A:#E00 B:#FF0 C:#CF3 D:#EEE E:#080 F:#251505 G:#CF0 H:#AAAAB9 I:#BBB J:#960 K:#939 L:#CC6 M:#AAA N:#040 O:#888 P:#FCF
voxels
6-24(7D18-)7D141-11D2(14-2D7A2D)14-2DA3-A-4(A2D14-2DA5-)A8(2D14-2DB5-B)2D14-2DH5-H2D14-2DA5-A4(2D14-2DH5-H)2D14-2DH5CH2D14-2D7F2D14-2D7-2D138-E11DA2(12-E12A)12-EA4-3A2-2A12-EA4-2A3-3(2A12-EA9-)2A6(12-EB9-BA)2(12-EB6-4BA)12-EB7-2CHA12-EA7-4A12-EH7-2C3(HA12-EH8-C)HA12-EH7CBCHA12-E4FJ2FJ3FA12-E11-A136-2E11D2A2(10-E14A)10-E9A2-3A10-E8A4-3(2A10-E7A5-)2A2(10-E7B5-BA)4(10-EB2-4B5-BA)10-EB2-10BA10-EB2-4B-B-3BA10-EH2-4C2-3CHA10-EA2-4A2-5A10-EH2-4C2-3C3(HA10-EH2-4C2-G2C)HA10-EH8CG2CHA10-E5FJ7FA10-E6-L6-A134-3E11D3A2(8-E7A-8A)8-E13A-2A8-E10A4-3(2A8-E8A6-)2A6(8-E8B6-BA)8-E9B-5BA8-E9B2-4BA8-EH8C-4CHA8-E9A-6A8-EH13C4(HA8-EH9CG3C)HA8-E2(4FJ)FJ3FA8-E6-L-L6-A42-M90-3E11D3A2(8-E16A)5(8-E12A3-A)5(8-E12B3-A)8-E12B2-BA8-E8B-B-2B-BA8-E9B2-4BA8-E9C-5CA8-E9A-4A-A8-E14C4(BA8-E10CG3C)BA8-E2F2J4F2J2FJ2FA8-E5-2(L-)L5-A42-OI19-I4-I63-4E11D4A2(6-E18A)3(6-E13A3-2A)6-E5A2GAC4A3-2A6-E5A2G2C4A3-2A6(6-E3B3A3C4B3-BA)6-E3B3A3C-5B-BA6-E3B3A3CB2-5BA6-EH8CB-6BA6-E10A-7A6-EH4C4D7C3(HA6-EH4C4D2CG4C)HA6-EH10CG4CHA6-E2(3FJFJ)2(FJ)FA6-E5-3(L-)L5-A16-O24-I20-OMO3-I62-4E11D4A5(6-E18A)6-E-6GAC4A3G2A6-E-6G2C4A3G2A4(6-E-2B3A3C8BA)2(6-E-2B3A3C7B-A)6-E-2B3A3C-B-4B-A6-E-2B3A3CB3-3B-A6-E-8C2(B-)3B-A6-E-9A-A-3A-A6-E-4C4D7C2(-A6-E-4C4D2CG4C)-A6-E-4C4D2CG5CA6-E-10C2G4CA6-E2(3FJ)9FA6-E4-4(L-)L4-A15-3M21-2M-2I19-2MI2-MI18-M5-M36-4E11D4A5(6-E18A)6-E-6GAC4A4GA6DE-6G2C4A4GA6D4(E-2B3A3C8BA5-D)2(E-2B3A3C7B-A5-D)E-2B3A3C-6B-A5-DE-2B3A3CB3-3B-A5-DE-8C2(B-)3B-A5-DE-4A5C-C-3C-H6DE-4C4D7C-H6D2(E-4C4D2CG4C-A6-)E-4C4D2CG5CA6-E-10C2G4CA6-E2F2J2FJ3FJ6FA6-E3-5(L-)L3-A15-3I68-I44-4E11D4A5(6-E18A)6-E-6GAC4A4GA6DE-6G2C4A4GA6D4(E-2B3A3C8BA5-D)4(E-2B3A3C7B-A5-D)E-8C7B-A5-DE-4A4C4D3C-H6DE-4C4D7C-H6D2(E-4C4D2CG4C-A6-)E-4C4D2CG5CA6-E-10C2G4CA6-EFJ6F2J4FJ2FA6-E2-6(L-)L2-A15-2IM21-2I-2I19-2I2-3I16-O-I4-2I18-I17-4E11D4A5(6-E18A)6-2(E-4GAG4CGA4GA6D)2(E-2B6A8BA5-D)E-2B2A2-2A8BA5-DE-2B2A6-6BA5-DE-2B2A6-B-3B3(-A5-DE-2B2A4C7B)-A5-DE-8C7B-A5-DE-4A4C3D2(3KC-H6DE-11C)2(3KC-A6-E-11C)3K2CA6-E-11C3K2CA6-E6FJ10FA6-E3-5(L-)L3-A40-3I21-MI-2I16-3MPM3-2I14-2M-2I5-I11-4E11D4A5(6-E18A)6-2(E-4GAG4CGA5G6D)2(E-2B6A8BA5-D)E-2B2A2-2A8BA5-DE-2B2A6-6BA5-DE-2B2A6-B2-2B3(-A5-DE-2B2A4C7B)-A5-DE-8C7B-A5-DE-4A4C3D2(3KC-H6DE-11C)2(3KC-A6-E-11C)3K2CA6-E-11C3K2CA6-E8FJ3FJF2JFA6-E4-4(L-)L4-A40-3I42-M2I43-4E11D4A7(6-E3G2C13A)5(6-E3B6A8BA)3(6-E3B2A4C8BA)6-EH8C8BA6-E5A3C10A5(6-EH11C3KCHA)6-E2(5F2J)FJFA6-E5-3(L-)L5-A40-3I21-MI-2I16-5M3-2I14-2M-2M5-I12-3E11D3A7(8-E2G2C12A)3(8-E2B6A7BA)2(8-E2B4A2N7BA)3(8-E2B2A4C7BA)8-E8C7BA8-E4A3C9A5(8-E15CA)8-EJF2JFJ3FJ2F2JFA8-E5-2(L-)L5-A110-O2-IM18-3E11D3A7(8-EG12A-2A)2(8-E2B6A5B-BA)8-EB-6A5B-BA8-EB-2A4N5B-BA8-EB-2A2(CN)2(5B-BA8-EB-2A4C)5B-BA8-E2B2A4C5B-BA8-EH-6C5B-BA8-EA-11A-2A3(8-EH-11C-HA)2(8-EHB11C-HA)8-E2F2(JF)J2F3J3FA8-E6-L-L6-A85-I24-M3-I19-2E11D2A7(10-E14A)10-E13BA10-E3B8-2B3(A10-E13B)3(A10-E7B-5B)A10-EH6C-5BA10-E7A-6A5(10-EH6C-4CHA)10-E4FJFJ2F2J2FA10-E6-L6-A86-I28-I20-E11DA12-E2A8-2A6(12-E12A)8(12-E11BA)12-EH5C5BA12-E12A5(12-EH9CHA)12-E6FJ4FA12-E11-A115-2I21-11D6(14-2DA3-3A2D)14-2DA2-4A3(2D14-2DB2-4B)2D14-2DB-5B4(2D14-2D7B)2D14-2DH3C3B2D14-2D7A5(2D14-2DH5CH)2D14-2D7F2D14-2D7-2D91-2(I24-)24(7D18-)7D93-M43-
