model
size = 25 30 19, scale = 0.05, origin = -y
material 
  colors = A:#FF0 B:#E00 C:#000 D:#CF3 E:#EEE F:#00C G:#251505 H:#BBB I:#CF0 J:#8F5F00 K:#CC6 L:#939 M:#1C0900 N:#AAA O:#AAAAB9 P:#00F Q:#888 R:#FCF
voxels
6-24(4A3B18-)4A3B141-6A5B2(14-8A3B)14-3A3-A-14(3B14-3A5-)4(3B14-2AO5-)3B14-2AO5D3B14-2A3G2MGM2B14-2A7-2B138-7A6B2(12-A3E8AB)12-AE4-3A2-AB12-AE4-2A3-A9(B12-AE9-E)B12-AE6-4EB12-AE6-2A3B12-AE7-D3B12-AE7-3CB12-AF7-D3(2CB12-AF8-)2CB12-AO7DA2CB12-AGJGMJ2MJ2GMB12-A11-B136-8A7B2(10-A4E9AB)10-A4E5A2-2AB10-A4E4A4-A3(B10-A4E3A5-E)2(B10-A4E3B5-E)4(B10-AE2-E3A5-E)B10-AE2-E4A5EB10-AE2-E3A-A-4B10-AE2-E3D2-D4B10-AE2-E3C2-4CB10-AF2-4D2-D3(3CB10-AF2-4D2-I)3CB10-AO8DI3CB10-AJ4GJ2G2MG2MB10-A6-K6-B134-9A8B2(8-A5E2A-7AB)8-A5E8A-AB8-A5E5A4-3(AB8-A5E3A6-)AB2(8-A5E3B6-2B)4(8-A5E3A6-2B)8-A5E4A-6B8-A5E4A2-5B8-A5E4D-D5B8-A5E4C-5CB8-A4F7D3(4CB8-A4F6DI)4CB8-AO9DI4CB8-AG3MJ4GJGMG2MB8-A6-K-K6-B42-N90-C8A8B2(8-C15AB)5(8-C12A3-B)2(8-C12B3-B)2(8-C5B5A2B3-B)8-C5B4A3B3-B8-C5B4A3B2-2B8-C5B3A-B2(-2B)8-C5B4A2-5B8-C5B4D-D5B8-10C-4C-B8-C4F7D3(4CB8-C4F6DI)4CB8-C10DI4CB8-C2G2J4G2JGM2GMB8-C5-2(K-)K5-B42-QH19-H4-H63-19C2(6-2C15ABC)5(6-2C12A3-BC)2(6-2C12B3-BC)2(6-2C5B3D2A2B3-BC)2(6-2C12B3-BC)6-2C8B-5B-BC6-2C5B3DA2-5BC6-2C5B3DA-A5BC6-11C-5CBC6-2C4F4E3D3(4CBC6-2C4F4E2DI)4CBC6-2C10DI4CBC6-CJ2MJGJ3GJGJMJ2GBC6-C5-3(K-)K5-C16-Q24-H20-QNQ3-H62-19C5(6-C17AC)6-2(C-16AEC5B)2(C-2B2AB3D4A4BC5-B)2(C-5B3D2A6BC5-B)2(C-15B-C5-B)C-8B-B-4B-C5-BC-5B3DA3-3B-C5-BC-5B3D2(A-)3B-C5-BC-9C-C-3C-BC5BC-3FD4E3D4C-EC5B2(C-3FD4E2DI4C-C6-)C-3FD4E2DI6C6-C-10DI6C6-CJMGJ3GJ7GJMC6-C4-4(K-)K4-C15-3N21-2N-2H19-2NH2-NH18-N5-N36-19C5(6-C6A8B3EC)6-C-5AIBD4B4IEC5AC-5AI2D4B4IEC5A2(C-2B2AB3D4A4BC5-A)2(C-5B3D2A6BC5-A)2(C-15B-C5-A)C-8B-6B-C5-AC-5B3DA3-3A-C5-AC-5B3D2(A-)3A-C5-AC-5C4D-D-3D-BC5AC-3FD4E7D-EC5A2(C-3FD4E2DI4D-C6-)C-3FD4E2DI5DC6-C-10D2ID3EC6-C2G2J2GJ3GJ5GMC6-C3-5(K-)K3-C15-3H68-H44-19C5(6-C6A2B10C)6-C-5AIBD4B3I2E7C-5AI2D4B3I2E7C2(-2B2AB3D4A3BEC5-2C)2(-5B3D2A5BEC5-2C)3(-15B-C5-2C)2(-5B3D7A-C5-2C)-5C3D4E3D-E7C-3FD4E7D-E7C2(-3FD4E2DI4D-C6-C)-3FD4E2DI5DC6-C-10D2ID3EC6-CGJ6G2J4GJ2MC6-C2-6(K-)K2-C15-2HN21-2H-2H19-2H2-3H16-Q-H4-2H18-H17-19C5(6-C6A2B10C)6-C-5AI4DIB3I2EC5AC-15A2EC5A2(C-2B2AB7A3BEC5-A)C-4B2-2B2A2(5BEC5-AC-4B6-)B-3B2(-C5-AC-15B)2(-C5-AC-5B3D7A)-C5-AC-5C3D3E2(3LD-EC5AC-3F8D)2(3LD-C6-C-3F8D)3L2DC6-C-11D2L3EC6-C6GJ9GMC6-C3-5(K-)K3-C40-3H21-NH-2H16-3NRN3-2H14-2N-2H5-H11-19C5(6-C6A8B3EC)6-C-5AI4DIBI4EC5BC-15A2EC5B2(C-2B2AB7A3BEC5-B)C-4B2-2B2A2(5BEC5-BC-4B6-)B2-2B2(-C5-BC-15B)-C5-BC-4B4D7A-C5-BC-3B5D7A-C5-BC-5C3D3E2(3LD-EC5BC-3F8D)2(3LD-C6-C-3F8D)3L2DC6-C-11D2L3EC6-C2M6GJ3GJGJMGC6-C4-4(K-)K4-C40-3H42-N2H43-19C7(6-C16AEC)2(6-C3B10A3BEC)6-C9B2A5B4(EC6-C16B)EC6-C5B4D7AEC6-C4B5D7AEC6-7C2D8B2(EC6-C4F8D3LD)2(OC6-C4F8D3LD)OC6-CO11D2L3EC6-CGJ3G2J5GJM2GMC6-C5-3(K-)K5-C40-3H21-NH-2H16-5N3-2H14-2N-2N5-H12-C8A8B8-C12A3PB8-C12AP2EB8-C12A3P3(B8-C15A)B8-C13A2E2(B8-C2B10A3E)B8-C8B2A6B4(8-C16B)8-C4B4D2A6B8-C3B5D2A6B8-6C2D9B4(8-CE2F12DB)8-C13D2EB8-CM3JGJ3GJ2G2JGB8-C5-2(K-)K5-B110-Q2-HN18-9A8B5(8-12A2E-EB)4(8-2A3E7A2E-EB)8-2A-2E4B2A3B4(-2B8-2A-2E9B)-2B8-2A3B4D2A3B-2B8-2A-B5D2A3B-2B8-2A-11C-C3(B8-2A-F10D-O)B8-2A2F10D-OB8-3A11D-EB8-A3(JG)J2GJMJ3GB8-A6-K-K6-B85-H24-N3-H19-8A7B5(10-11A3EB)10-A3E7A3E2(B10-A3E6A4E)B10-A3E8-2EB10-A3EB5A2(4EB10-A3E6B)2(4EB10-A3E4B-B)4EB10-A2B5A-A4EB10-A2B5D-A4EB10-A7C-5C4(B10-A2F5D-4DO)B10-AO6D-4DEB10-A4GJGJ2G2M2GB10-A6-K6-B86-H28-H20-7A6B12-3A8-E4(B12-10A2E)B12-2AE7A2EB12-2AE6A2(3EB12-2AE6B)3EB12-2AEB5A4(3EB12-2AE6B)3EB12-9A3EB12-2A5D2A3EB12-2A10CB4(12-2A8D3B)12-2A9DOB12-AJ5GJM3GB12-A11-B115-2H21-6A5B6(14-3A3-2A3B)14-3A2-3A3B3(14-3A2-6B)14-3A-E4(6B14-3A2E)6B14-3A8B14-3A5C5(3B14-3A5D)3B14-2A6GM2B14-2A7-2B91-2(H24-)24(4A3B18-)4A3B93-N43-
