model
size = 25 30 19, scale = 0.05, origin = -y
material 
  colors = A:#E00 B:#00C C:#FF0 D:#CF3 E:#EEE F:#251505 G:#000 H:#BBB I:#CF0 J:#CC6 K:#939 L:#960 M:#AAAAB9 N:#1C0900 O:#AAA P:#888 Q:#FCF
voxels
6-8(7B18-)9(7E18-)7(7A18-)7A141-3(11B14-)3B3-B-4(3B14-3B5-)3B7(14-2EA5-A2E)14-2EA5-C2E14-2EA5-M2E2(14-3A5-3A)3(14-2AM5-M2A)14-2AM5DM2A14-2A3F2N2F2A14-2A7-2A138-3(13B12-)2B4-3B2-2B12-2B4-2B3-3(2B12-2B9-)2B6(12-EA9-AE)12-EA6-4AE12-EA6-2C2AE12-EA7-D2AE2(12-2A7-4A)3(12-AB8-2GA)12-AM7DC2GA12-A3FNL2NL2FNA12-A11-A136-3(15B10-)10B2-3B10-9B4-3(2B10-8B5-)2B2(10-E7A5-AE)4(10-EA2-A3C5-AE)10-EA2-A4C5AE10-EA2-A3C-C-3AE10-EA2-A3D2-D3AE2(10-2A2-4A2-5A)3(10-AB2-4D2-I3GA)10-AM8DI3GA10-A5FL2F2NF2NA10-A6-J6-A134-17B2(8-B7C-3C5B)8-B11C2B-2B8-B10C4-3(2B8-B8C6-)2B2(8-E8A6-AE)4(8-E5A3C6-AE)8-E5A4C-5AE8-E5A4C2-4AE8-E5A4D-D4AE8-10A-6A8-17A3(8-A4B6DI4GA)8-AM9DI4GA8-AF3NL4FLFNF2NA8-A6-J-J6-A42-O90-17B2(8-B11C5B)5(8-B11CB3-B)2(8-E12A3-E)2(8-E5A5C2A3-E)8-E5A4C3A3-E8-E5A4C3A2-AE8-E5A3C-A-2A-AE8-E5A4C2-4AE8-E5A4D-D4AE8-10A-4A-A8-17A3(8-A4B6DI4GA)8-A10DI4GA8-A2F2L4F2LFN2FNA8-A5-2(J-)J5-A42-PH19-H4-H63-19B2(6-2B11C6B)5(6-2B11CB3-2B)2(6-E13A3-AE)2(6-E6A3D2C2A3-AE)2(6-E13A3-AE)6-E9A-5A-AE6-E6A3DC2-5AE6-E6A3DC-C5AE6-7A4G-6GA6-7A3E3D3(5GA6-A5B4E2DI)5GA6-AM10DI5GA6-AF2NLFL3FLFLNL2FNA6-A5-3(J-)J5-A16-P24-H20-POP3-H62-19B5(6-2B16CB)6-B-16CA7B-16CA6BE2(-2A2CA3D4C4AE5-2E)2(-5A3D2C6AE5-2E)2(-15A-E5-2E)-8A-A-4A-E5-2E-5A3DC3-3A-E5-2E-5A3D2(C-)3A-E5-EA-5A4G-G-3G-8A-5A3E3D4G-8A2(-3BD4E2DI4G-A6-A)-3BD4E2DI5GA6-A-10DI5GA6-AFNFL3FL8FNA6-A4-4(J-)J4-A15-3O21-2O-2H19-2OH2-OH18-O5-O36-19B5(6-2B5C8A3EB)6-B-5CIAD4A4IA7B-5CI2D4A4IA6BE2(-2A2CA3D4C4AE5-2E)2(-5A3D2C6AE5-2E)2(-15A-E5-2E)-8A-6A-E5-2E-5A3DC3-3C-E5-2E-5A3D2(C-)3C-E5-EA-5A4D-D-3D-8A-5A3E7D-8A2(-3BD4E2DI4D-A6-A)-3BD4E2DI5DA6-A-10D2ID3EA6-A2F2L2FL3FL5FNA6-A3-5(J-)J3-A15-3H68-H44-19B5(6-2B5C8A3EB)6-B-5CIAD4A4IA7B-5CI2D4A4IA6BE2(-2A2CA3D4C4AE5-2E)2(-5A3D2C6AE5-2E)3(-15A-E5-2E)-5A3D7C-E5-2E-5A3D7C-E5-EA-5A3D4E3D-8A-5A3E7D-8A2(-3BD4E2DI4D-A6-A)-3BD4E2DI5DA6-A-10D2ID3EA6-AFL6F2L4FL2NA6-A2-6(J-)J2-A15-2HO21-2H-2H19-2H2-3H16-P-H4-2H18-H17-19B5(6-2B5C8A3EB)6-B-5CI4DIA4IC7B-17C6BE2(-2A2CA7C4AE5-2E)-4A2-2A2C2(6AE5-2E-4A6-)A-3A2(-E5-2E-15A)2(-E5-2E-5A3D7C)-E5-EA-5A3D3E3KD-8A-5A6D3KD-8A2(-3B8D3KD-A6-A)-3B8D3K2DA6-A-11D2K3EA6-A6FL9FNA6-A3-5(J-)J3-A40-3H21-OH-2H16-3OQO3-2H14-2O-2H5-H11-19B5(6-2B5C8A3EB)6-B-5CI4DIAI3EA7B-16CA6BE2(-2A2CA7C4AE5-2E)-4A2-2A2C2(6AE5-2E-4A6-)A2-2A2(-E5-2E-15A)-E5-2E-4A4D7C-E5-2E-3A5D7C-E5-EA-5A3D3E3KD-8A-5A6D3KD-8A2(-3B8D3KD-A6-A)-3B8D3K2DA6-A-11D2K3EA6-A8FL3FLFLNFA6-A4-4(J-)J4-A40-3H42-O2H43-19B5(6-2B15CEB)2(6-2B8C9B)2(6-E3A10C4AE)6-E9A2C6A4(E6-E17A)E6-E5A4D8CE6-E4A5D8CE6-7A2D8AGA6-7A6D3(3KDMA6-A4B8D)3KDMA6-AM11D2K3EA6-A5F2L5FLN2FNA6-A5-3(J-)J5-A40-3H21-OH-2H16-5O3-2H14-2O-2O5-H12-17B7(8-4B5C8B)2(8-E2A10C4E)8-E8A2C5A4(E8-E15A)E8-E4A4D2C5AE8-E3A5D2C5AE8-6A2D9A4(8-AE2B12DA)8-A13D2EA8-ALF2LFL3FL2F2LFA8-A5-2(J-)J5-A110-P2-HO18-17B7(8-4B5C5B-2B)2(8-E2A9C2E-2E)8-EA-6A2C3A4(-AE8-EA-11A)-AE8-E4A4D2C3A-AE8-EA-A5D2C3A-AE8-2A-3A6G2A-2A8-2A-A8D2A-2A8-2A-A10D-MA8-AE-B10D-MA8-AE2B10D-MA8-AMC11D-EA8-A2F2(LF)L2FLNL3FA8-A6-J-J6-A85-H24-O3-H19-15B7(10-3B5C7B)10-EA9C4E10-EA2C8-3E10-E4A5C4AE10-E2AC10AE10-E13A2(E10-E7A-5A)E10-E2A5C-C4AE10-E2A5D-C4AE10-5A3G-2G4A10-3A5D-2D4A10-3A2(5D-4DMA10-A2B)5D-4DMA10-AM6D-4DEA10-A4FLFL2F2N2FA10-A6-J6-A86-H28-H20-13B12-2BC8-2B6(12-2B5C6B)2(12-E9A3E)12-E3A5C3A4(E12-E11A)E12-EA7C3AE12-EA5D2C3AE12-4A6G2(3A12-2A8D)2(3A12-AB8D)3A12-AM9DMA12-A6FLN3FA12-A11-A115-2H21-11B6(14-3B3-5B)14-3B2-6B3(14-2EA2-4A2E)14-2EA-5A5(2E14-2E7A)2E14-3A6G5(2A14-2AM5DM)2A14-2A7F2A14-2A7-2A91-2(H24-)8(7B18-)9(7E18-)7(7A18-)7A93-O43-
