model
size = 25 30 19, scale = 0.05, origin = -y
material 
  colors = A:#E00 B:#EEE C:#FF0 D:#CF3 E:#000 F:#251505 G:#BBB H:#960 I:#CC6 J:#1C0900 K:#00C L:#CF0 M:#AAA N:#939 O:#888 P:#AAAAB9 Q:#FCF
voxels
6-7B8(18-7A)7(18-7B)7(18-7A)18-7B18-7E141-11B2(14-11A)14-3A3-A-5(3A14-3A5-)3A7(14-3B5-3B)6(14-3A5-3A)14-11A14-2BJ2HJH2J2B14-2E7-2E138-13B2(12-13A)12-2A4-3A2-2A12-2A4-2A3-4(2A12-2A9-)2A5(12-2B9-2B)12-2B6-5B12-2B6-2B2AB3(12-2A7-4A)3(12-2A8-3A)12-10AE2A12-B2(2JH)JHJFJB12-E11-E136-15B2(10-15A)10-10A2-3A10-9A4-4(2A10-8A5-)2A10-8B4(5-2B10-2B2-4B)5-2B10-2B2-11B10-BA2-A3C-C-3AB10-2A2-A3D2-5A10-2A2-A3E2-5A10-2A2-A3D2-5A10-2A2-4D2(2-5A10-2A2-4A)2-5A10-11AE3A10-BF2H2FH2F2JF2JB10-E6-I6-E134-17B2(8-8A-8A)8-14A-2A8-11A4-4(2A8-9A6-)2A8-5B4A4(6-AB8-5BA3C)6-AB8-5BA4C-5AB8-B5A4C2-4AB8-6A4D-6A8-6A4E-6A8-6A5D6A8-4AK6D6A2(8-17A)8-12AE4A8-BF3JH4F2(HF)HJB8-E6-I-I6-E42-M90-17B2(8-17A)6(8-13A3-A)8-5B8A2(3-B8-5BA5C2A)2(3-B8-5BA4C3A)2-AB8-5BA3C-A-2A-AB8-B5A4C2-4AB8-6A4D-6A8-6A4E-4A-A8-6A5D6A8-4AK6D6A2(8-17A)8-12AE4A8-B2F2H4F2HFJ2FJB8-E5-2(I-)I5-E42-OG19-G4-G63-19B2(6-19A)6(6-14A3-2A)6-6B8A2(3-AB6-6BA3D2C2A)2(3-AB6-6B8A)3-AB6-6B4A-5A-AB6-B6A3DC2-5AB6-7A3DC-7A6-7A4E-7A6-7A3B2D7A6-5AK4B2D7A2(6-19A)6-13AE5A6-BFHJHFH3FHF3(HJ)B6-E5-3(I-)I5-E16-O24-G20-OMO3-G62-19B3(6-9A9CA)2(6-9A8C2A)6-A-5A11CB6EA-4A12CB6EA-5A3D2C7A5-EB-2A2CA3D4C4A2(B5-EB-5A3D2C6A)2(B5-EB-15A-)B5-EB-8A-A-4A-B5-EB-5A3DC3-3A-B5-EA-5A3DC-A-3A-A5-EA-5A4E-A-3A-A6EA-5A3B2D5A-A6EA-3AD4B2D5A-A6-A-A2KD4B2D5A-A6-A-3KD4B2D7A6-A-10DLE5A6-BFJFH3FH8FJB6-E4-4(I-)I4-E15-3M21-2M-2G19-2MG2-MG18-M5-M36-19B3(6-15A3BA)2(6-15A2B2A)6-A-5ALAD4A4LB6EA-4ACL2D4A4LB6EA-5A3D4C5A5-EB-2A2CA3D4C4A2(B5-EB-5A3D2C6A)2(B5-EB-15A-)B5-EB-8A-6A-B5-EB-5A3DC3-3C-B5-EA-5A3DC-A-3A-A5-EA-5A4D-A-3A-A6EA-5A3B2D5A-A6EA-3AD4B2D5A-A6-A-A2KD4B2D5A-A6-A-3KD4B2D7A6-A-10D2L5A6-BHF2H2FH3FH5FJB6-E3-5(I-)I3-E15-3G68-G44-19B3(6-A6C8A3BA)2(6-A6C8A2B2A)6-A-5ALAD4A4LB6EA-4ACL2D4A4LB6EA-5A3D4C5A5-EB-2A2CA3D4C4A2(B5-EB-5A3D2C6A)3(B5-EB-15A-)B5-EB-5A3D7C-B5-EA-5A3D2C5A-A5-EA-5A3D2B5A-A6EA-5A3B2D5A-A6EA-3AD4B2DL4D-A6-A-A2KD4B2DL4D-A6-A-3KD4B2DL5DA6-A-10D2LD3BA6-BFH6F2H4FH2JB6-E2-6(I-)I2-E15-2GM21-2G-2G19-2G2-3G16-O-G4-2G18-G17-19B3(6-A6C8A3BA)2(6-A6C8A2B2A)6-A-5AL4DLA4LB6EA-4A12CB6EA-5A7C5A5-EB-2A2CA7C4AB5-EB-4A2-2A2C2(6AB5-EB-4A6-)A-3A2(-B5-EB-15A)-B5-EB-5A3D7C-B5-EA-5A3D2C5A-A5-EA-5A3D2B5A-A6EA-5A5D5A-A6EA-3A8D3ND-A6-A-A2K8D3ND-A6-A-3K8D3N2DA6-A-11D2N3BA6-B6FH9FJB6-E3-5(I-)I3-E40-3G21-MG-2G16-3MQM3-2G14-2M-2G5-G11-19B3(6-A6C8A3BA)2(6-A6C8A2B2A)6-A-5AL4DLAL3BA6EA-4A12CB6EA-5A7C5A5-EB-2A2CA7C4AB5-EB-4A2-2A2C2(6AB5-EB-4A6-)A2-2A2(-B5-EB-15A)-B5-EB-4A4D7C-B5-EA-5A3D2C5A-A5-EA-5A3D2B5A-A6EA-5A5D5A-A6EA-3A8D3ND-A6-A-A2K8D3ND-A6-A-3K8D3N2DA6-A-11D2N3BA6-BH7FH3FHFHJFB6-E4-4(I-)I4-E40-3G42-M2G43-19B4(6-A11C7A)6-A5C13A6-19A6-6A11CBA6-6A8C5A6-B3A10C4AB6-B9A2C6A4(B6-B17A)B6-B5A4D8CB4(6-19A)6-3A2K8D6A6-2A3K8D6A6-2A11D6A6-B5F2H5FHJ2FJB6-E5-3(I-)I5-E40-3G21-MG-2G16-5M3-2G14-2M-2M5-G12-17B4(8-10AC6A)4(8-17A)8-B2A10C4B8-B8A2C5A4(B8-B15A)B8-B4A4D2C5AB4(8-17A)8-2A2K8D5A8-AB2K8D5A8-A11D5A8-BHF2HFH3FH2F2HFB8-E5-2(I-)I5-E110-O2-GM18-17B4(8-10AC3A-2A)4(8-14A-2A)8-B2A9C2B-2B8-BA-6A2C3A4(-AB8-BA-11A)-AB8-B4A4D2C3A-AB4(8-2A-11A-2A)8-2A-K8D2A-2A8-AB2K8D2A-2A8-APC9D2A-2A8-B2F2(HF)H2FHJH3FB8-E6-I-I6-E85-G24-M3-G19-15B4(10-9AC5A)4(10-15A)10-BA2C8-3B10-B4A5CA4B10-B2AC7A4B10-B10A2(4B10-B7A-2A)4B10-B2A5C-CA4B4(10-8A-6A)3(10-4A4D-2D4A)10-B4FHFH2F2J2FB10-E6-I6-E86-G28-G20-13B12-3A8-2A3(12-8AB4A)4(12-13A)6(12-13B)12-BA7CA3B5(12-13A)2(12-3A7D3A)12-B2FH3FHJ3FB12-E11-E115-2G21-11B4(14-3A3-AB3A)2(14-3A3-5A)2(14-3A2-6A)2(14-3B2-6B)14-3B-7B3(14-11B)14-2BA8B5(14-11A)2(14-2AP6B2A)14-2BF3(HJ)2B14-2E7-2E91-2(G24-)7B8(18-7A)7(18-7B)7(18-7A)18-7B18-7E93-M43-
