model
size = 25 30 19, scale = 0.05, origin = -y
material 
  colors = A:#EEE B:#FF0 C:#E00 D:#CF3 E:#00F F:#000 G:#06F H:#00C I:#251505 J:#30F K:#BBB L:#CC6 M:#CF0 N:#939 O:#960 P:#1C0900 Q:#AAAAB9 R:#AAA S:#888 T:#FCF
voxels
6-12(3A4E18-)4(7E18-)8(3A4E18-)3A4E141-11A2(14-7A2B2A)14-3A3-A-8(B2A14-3A5-)B2A14-3E5-B2(2E14-3E5-J)2E14-3E5-B2E14-3A5-B2A14-2AF5(5-B2A14-2AQ)4D2B2A14-2A3I2P2I2A14-2A7-2A138-3(13A12-)2A4-3A2-2A12-2A4-2A3-7(2A12-2A9-)2A12-EA9-BE12-EJ9-JE12-EJ6-A2BJE12-EA6-A3BE12-2A7-4A12-AF7-3FA12-AH7-D3(2FA12-AH8-)2FA12-AQ7DB2FA12-A3IPO2PO2IPA12-A11-A136-15A2(10-AB13A)10-AB8A2-3A10-9A4-5(2A10-8A5-)2(2A10-2A2-4A5-)2A10-2E2-4A5-BE10-2E2-2J2A5-JE10-2E2-2J6A2JE10-2E2-4A-A-2ABE10-2A2-4A2-3ACA10-AF2(2-4F)A10-AH2-4D2-D3(3FA10-AH2-4D2-M)3FA10-AQ8DM3FA10-A5IO2I2PI2PA10-A6-L6-A134-17A2(8-A7B-7BA)8-A13B-BA8-11A4-4(BA8-9A6-)3(CA8-9A6-)CA8-3E6A6-BE8-3E4J2A6-JE8-3E4J3A-2A3JE8-3E7A2-2A2BE8-10A-3A2CA8-A9F-5FA8-A4H7D3(4FA8-A4H6DM)4FA8-AQ9DM4FA8-AI3PO4IOIPI2PA8-A6-L-L6-A42-R90-17A2(8-A15BA)8-A12B8(3-A8-13A)3-A8-3E10A3-E8-3E4J5AJ2-JE8-3E4J2A2(-A)J-JE8-3E7A2-2A2BE8-10A-3A2CA8-A9F-4F-A8-A4H7D3(4FA8-A4H6DM)4FA8-A10DM4FA8-A2I2O4I2OIP2IPA8-A5-2(L-)L5-A42-SK19-K4-K63-19A2(6-A17BA)6-A13B5(3-BA6-14A)3(3-CA6-14A)3-CA6-A3E10A3-BA6-A3E4J5AJ3-JA6-A3E4J2A-3A2J-JA6-A3E7A2-2A3BA6-11A-3A3CA6-A10F-6FA6-A5H4A3D3(5FA6-A5H4A2DM)5FA6-AQ10DM5FA6-AI2POIO3IOIOPO2IPA6-A5-3(L-)L5-A16-S24-K20-SRS3-K62-19A3(6-A17BA)2(6-15A3BA)6-A2(-13A3BC7A)4(-13A3CA5-2A)-2E11A2C-A5-2A-2E9A4J-A5-2A-2E6A2(-A)3J-A5-2A-2E7A3-A2C-A5-2A-9A2(-A)2C-A5-2A-9F-F-3F-C7A-3HD4A3D4F-G7A2(-3HD4A2DM4F-A6-A)-3HD4A2DM5FA6-A-10DM5FA6-AIPIO3IO8IPA6-A4-4(L-)L4-A15-3R21-2R-2K19-2RK2-RK18-R5-R36-19A5(6-A17GA)6-A-17G7A-5BM2D4C4MG7A2(-2C2BC3D4B4CA5-2A)2(-5C3D2B6CA5-2A)-15C-A5-2A-11C4J-A5-2A-8C-3C3J-A5-2A-5C3DB3-3B-A5-2A-5C3D2(B-)3B-A5-2A-5F4D-D-3D-C7A-3HD4A7D-G7A2(-3HD4A2DM4D-A6-A)-3HD4A2DM5DA6-A-10D2MD4A6-A2I2O2IO3IO5IPA6-A3-5(L-)L3-A15-3K68-K44-19A5(6-A17GA)6-A-16G8A-5BM2D4C4M8A2(-2C2BC3D4B4CA5-2A)2(-5C3D2B6CA5-2A)3(-15C-A5-2A)2(-5C3D7B-A5-2A)-5F3D4A3D-C7A-3HD4A7D-C7A2(-3HD4A2DM4D-A6-A)-3HD4A2DM5DA6-A-10D2MD4A6-AIO6I2O4IO2PA6-A2-6(L-)L2-A15-2KR21-2K-2K19-2K2-3K16-S-K4-2K18-K17-19A5(6-A6B8C4A)6-A-5BM4DMC4MB7A-17B7A2(-2C2BC7B4CA5-2A)-4C2-2C2B2(6CA5-2A-4C6-)C-3C-A5-2A-12C3J-A5-2A-11C4J2(-A5-2A-5C3D7B)-A5-2A-5F3D3A3ND-C7A-3H8D3ND-G7A2(-3H8D3ND-A6-A)-3H8D3N2DA6-A-11D2N4A6-A6IO9IPA6-A3-5(L-)L3-A40-3K21-RK-2K16-3RTR3-2K14-2R-2K5-K11-19A5(6-A6B8C4A)6-A-5BM4DMCM11A-16B8A2(-2C2BC7B4CA5-2A)-4C2-2C2B6CA5-2A-4C6-6CA5-2A-2B2C6-C2-2C-A5-2A-12C3J-A5-2A-2B9C4J-A5-2A-2B2C4D7B-A5-2A-3C5D7B-A5-2A-5F3D3A2(3ND-G7A-3H8D)2(3ND-A6-A-3H8D)3N2DA6-A-11D2N4A6-A8IO3IOIOPIA6-A4-4(L-)L4-A40-3K42-R2K43-19A7(6-A16B2A)2(6-A3C10B4CA)6-A9C2B6CA6-A17CA6-A3B8C6BA6-A4B8CB4JA6-A5J7C5JA6-A3B2C4D8BA6-A4C5D8BA6-A6F2D8CF4(A6-A4H8D3NDQ)A6-AQ11D2N4A6-A5I2O5IOP2IPA6-A5-3(L-)L5-A40-3K21-RK-2K16-5R3-2K14-2R-2R5-K12-17A8-A12B3EA8-A12BE3A8-A12B3E3(A8-A15B)A8-A13B3A2(8-A2C10B4A)8-A8C2B5CA8-A15CA8-E2B8C5BE8-E4J7CB3JE8-E4J7C4JE8-E2B2C4D7BE8-A3C5D2B5CA8-A5F2D8C4(A8-2A2H12D)A8-A13D3A8-AOI2OIO3IO2I2OIA8-A5-2(L-)L5-A110-S2-KR18-17A7(8-A11B2A-2A)2(8-A2C9B2A-2A)8-AC-6C2B3C-CA8-AC-11C-CA8-EB-8C3B-BE8-EJ-2J7CBJ-JE8-EJ-2J7C2J-JE8-E2B2C4D5B-BE8-AC-C5D2B3C-CA8-AF-11F-F3(A8-2A-H10D-Q)A8-2A2H10D-QA8-AQB11D-2A8-A2I2(OI)O2IOPO3IA8-A6-L-L6-A85-K24-R3-K19-15A4(10-A6BG3B4A)4(10-2A5BG3B4A)10-2A2B8-3A10-2A3C2BG2B3C2A10-2ACB3CG5C2A10-EB5C4G3BE10-E3J4C-2CB2JE10-E3J4C-2C3JE10-EBC5B-5BE10-2AC5D-B3C2A10-A7F-5F4(A10-A2H5D-4DQ)A10-AQ6D-4D2A10-A4IOIO2I2P2IA10-A6-L6-A86-K28-K20-13A12-A2B8-2A6(12-A5BG3B3A)2(12-A5CG3C3A)12-A3C2BG2B2C2A12-A5CG4C2A12-E3B2C4G2BE12-E2JB6CBJE12-E2JB6C2JE12-EC10BE12-AC5D2B3CA12-A11F4(A12-AH8D2C)A12-AQ9DQA12-A6IOP3IA12-A11-A115-2K21-11A2(14-2AB3-3B2A)4(14-3A3-3B2A)14-3A2-G3B3(2A14-3A2-G3C)2A14-3A-CG3C2A14-2EB2C4G2E14-2E7J2E14-2EB6C2E14-2EA5CB2E14-3A6C2A14-3A6F2A14-3A4(5DQ2A14-2AQ)5DQ2A14-2A7I2A14-2A7-2A91-2(K24-)12(4E3A18-)4(7E18-)8(4E3A18-)4E3A93-R43-
