model
size = 25 30 19, scale = 0.05, origin = -y
material 
  colors = A:#E00 B:#EEE C:#FF0 D:#CF3 E:#DDD F:#00F G:#000 H:#06F I:#00C J:#251505 K:#30F L:#BBB M:#CC6 N:#CF0 O:#939 P:#960 Q:#1C0900 R:#AAAAB9 S:#AAA T:#888 U:#FCF
voxels
6-5(7A18-)6AF18-5A2F18-4A3F18-3A4F18-2A5F18-A6F3(18-7F)18-B6F18-2B5F18-3B4F18-4B3F18-5B2F18-6BF5(18-7B)141-2A7E2(2A14-2A5B2C)2A14-2AB3-B-CAF8(14-2AB5-C2F)14-A2F5-C2(2F14-2BF5-K)2F14-2BF5-C2F14-3B5-C2F14-2BG4(5-C2F14-2BR)5-CBF14-2BR4D2C2B14-2B3J2Q2J2B14-2B7-2B138-A11E2(A12-2A10B)F12-2A4-3B2-BF12-2A4-2B3-8(BF12-2A9-)CF12-BK9-KF12-BK6-B2CKF12-2B6-B3CF12-2B7-3BF12-BG7-3GF12-BI7-D3(2GF12-BI8-)2GF12-BR7DC2GF12-B3JQP2QP2JQB12-B11-B136-A13EA2(10-3A11BF)10-3A7B2-2BF10-3A6B4-5(BF10-3A5B5-)3(BF10-2A2-4B5-)CF10-BF2-2K2B5-KF10-BF2-2K6B2KF10-BF2-4B-B-2BCF10-2B2-4B2-3BAF10-BG2(2-4G)F10-BI2-4D2-D3(3GF10-BI2-4D2-N)3GF10-BR8DN3GF10-B5JP2J2QJ2QF10-B6-M6-B134-A15E2(F8-4A4C-7C)F8-4A10C-CF8-4A7B4-4(CF8-4A5B6-)4(AF8-4A5B6-)CF8-B2F4K2B6-KF8-B2F4K3B-2B3KF8-B2F7B2-2B2CF8-10B-3B2AF8-B9G-5GF8-B4I7D3(4GF8-B4I6DN)4GF8-BR9DN4GF8-BJ3QP4JPJQJ2QF8-B6-M-M6-F42-S90-A15E2(F8-4A12C)F8-4A9C9(3-F8-4A9B)3-F8-B2F4K5BK2-KF8-B2F4K2B2(-B)K-KF8-B2F7B2-2B2CF8-10B-3B2AF8-B9G-4G-F8-B4I7D3(4GF8-B4I6DN)4GF8-B10DN4GF8-B2J2P4J2PJQ2JQF8-B5-2(M-)M5-F42-TL19-L4-L63-A18E2(6-5A13CE)6-5A9C5(3-CE6-5A9B)3(3-AE6-5A9B)3-AE6-A3F10B3-CE6-B3F4K5BK3-KE6-B3F4K2B-3B2K-KE6-B3F7B2-2B3CE6-11B-3B3AE6-B10G-6GE6-B5I4B3D3(5GE6-B5I4B2DN)5GE6-BR10DN5GE6-BJ2QPJP3JPJPQP2JQE6-B5-3(M-)M5-E16-T24-L20-TST3-L62-19E3(6-E17CE)2(6-E14B3CE)6-E2(-13B3CA7E)4(-13B3AE5-2E)-2F11B2A-E5-2E-2F9B4K-E5-2E-2F6B2(-B)3K-E5-2E-2F7B3-B2A-E5-2E-9B2(-B)2A-E5-2E-9G-G-3G-A7E-3ID4B3D4G-H7E2(-3ID4B2DN4G-E6-E)-3ID4B2DN5GE6-E-10DN5GE6-EJQJP3JP8JQE6-E4-4(M-)M4-E15-3S21-2S-2L19-2SL2-SL18-S5-S36-19E5(6-E17HE)6-E-17H7E-5CN2D4A4NH7E2(-2A2CA3D4C4AE5-2E)2(-5A3D2C6AE5-2E)-15A-E5-2E-11A4K-E5-2E-8A-3A3K-E5-2E-5A3DC3-3C-E5-2E-5A3D2(C-)3C-E5-2E-5G4D-D-3D-A7E-3ID4B7D-H7E2(-3ID4B2DN4D-E6-E)-3ID4B2DN5DE6-E-10D2ND3BE6-E2J2P2JP3JP5JQE6-E3-5(M-)M3-E15-3L68-L44-19E5(6-E17HE)6-E-16HB7E-5CN2D4A4NB7E2(-2A2CA3D4C4AE5-2E)2(-5A3D2C6AE5-2E)3(-15A-E5-2E)2(-5A3D7C-E5-2E)-5G3D4B3D-A7E-3ID4B7D-A7E2(-3ID4B2DN4D-E6-E)-3ID4B2DN5DE6-E-10D2ND3BE6-EJP6J2P4JP2QE6-E2-6(M-)M2-E15-2LS21-2L-2L19-2L2-3L16-T-L4-2L18-L17-19E5(6-E6C8A3BE)6-E-5CN4DNA4NC7E-17C7E2(-2A2CA7C4AE5-2E)-4A2-2A2C2(6AE5-2E-4A6-)A-3A-E5-2E-12A3K-E5-2E-11A4K2(-E5-2E-5A3D7C)-E5-2E-5G3D3B3OD-A7E-3I8D3OD-H7E2(-3I8D3OD-E6-E)-3I8D3O2DE6-E-11D2O3BE6-E6JP9JQE6-E3-5(M-)M3-E40-3L21-SL-2L16-3SUS3-2L14-2S-2L5-L11-19E5(6-E6C8A3BE)6-E-5CN4DNAN4B7E-16CB7E2(-2A2CA7C4AE5-2E)-4A2-2A2C6AE5-2E-4A6-6AE5-2E-2C2A6-A2-2A-E5-2E-12A3K-E5-2E-2C9A4K-E5-2E-2C2A4D7C-E5-2E-3A5D7C-E5-2E-5G3D3B2(3OD-H7E-3I8D)2(3OD-E6-E-3I8D)3O2DE6-E-11D2O3BE6-E8JP3JPJPQJE6-E4-4(M-)M4-E40-3L42-S2L43-13E7(6A6-E12C)2(6A6-E3A9C)6A6-E9A2C7A6-E18A6-E3C8A2C5A6-E4C8AC4KB6-E5K7A5KB6-E3C2A4D8CB6-E4A5D8CB6-E6G2D8AG4(B6-E4I8D3ODR)B6-ER11D2O4B6-E5J2P5JPQ2JQB6-E5-3(M-)M5-B40-3L21-SL-2L16-5S3-2L14-2S-2S5-L12-F11E7(5A8-F11C)2(5A8-F2A9C)5A8-F8A2C6A8-F16A8-F2C8A2C4A8-F4K7AC3KB8-F4K7A4KB8-F2C2A4D7CB8-F3A5D2C5AB8-F5G2D8A4(B8-FB2I12D)B8-F13D3B8-FPJ2PJP3JP2J2PJB8-F5-2(M-)M5-B110-T2-LS18-F11E5A7(8-F11C2A-2A)2(8-F2A9C2A-2A)8-FA-6A2C3A-2A8-FA-11A-2A8-FC-8A2CA-2A8-FK-2K7ACK-KB8-FK-2K7A2K-KB8-F2C2A4D5C-CB8-FA-A5D2C3A-AB8-FG-11G-G3(B8-FB-I10D-R)B8-FB2I10D-RB8-FRC11D-2B8-F2J2(PJ)P2JPQP3JB8-F6-M-M6-B85-L24-S3-L19-A10E4(4A10-F6CH3C)4(4A10-FB5CH3C)4A10-FB2C8-3A10-FB3A2CH2C5A10-FBAC3AH7A10-FC5A4HC3A10-F3K4A-2AC2KB10-F3K4A-2A3KB10-FCA5C-5CB10-FBA5D-C3A2B10-F7G-5G4(B10-F2I5D-4DR)B10-FR6D-4D2B10-F4JPJP2J2Q2JB10-B6-M6-B86-L28-L20-A9E3A12-A2C8-2A6(12-F5CH3C3A)2(12-F5AH6A)12-F3A2CH2C4A12-F5AH6A12-F3C2A4HC2A12-F2KC6ACKB12-F2KC6A2KB12-FA10CB12-FA5D2C3AB12-F11G4(B12-FI8D2A)B12-FR9DRB12-B6JPQ3JB12-B11-B115-2L21-2A7E2(2A14-2AC3-3C)2A14-FA4(B3-3C2A14-2F)B2-H3C2A3(14-2FB2-H5A)14-2FB-AH5A14-2FC2A4HFA14-2F7K2B14-2FC6A2B14-2FB5AC2B14-2FB6A2B14-2FB6G2B14-2FB2(5DR2B14-2FR)5DR2B14-FB2(R5DR2B14-2B)7J2B14-2B7-2B91-2(L24-)5(7A18-)F6A18-2F5A18-3F4A18-4F3A18-5F2A18-6FA3(18-7F)18-6FB18-5F2B18-4F3B18-3F4B18-2F5B18-F6B5(18-7B)93-S43-
