model
size = 19 30 25, scale = 0.05, origin = -y
material 
  colors = A:#E00 B:#EEE C:#CF3 D:#FF0 E:#000 F:#00C G:#251505 H:#BBB I:#CF0 J:#CC6 K:#939 L:#960 M:#AAAAB9 N:#1C0900 O:#AAA P:#888 Q:#FCF
voxels
6-12(7A12-)12(7B12-)7B105-6(11A8-)6(3A5-3A8-)5(2BA5-A2B8-)2BE5-E4(2B8-2BF5-F)2B8-2BM5-M2B8-2B7G2B8-2B7-2B102-12(13A6-)5(B11AB6-)B11E4(B6-3B9F)B6-BM9CMB6-BGL3GLG2N2GB6-B11-B100-10(15A4-)2(2A-12A4-)3(BA-11AB4-)B13AB4-BA-11AB4-BE-11E3(B4-BF-11F)B4-B13FB4-BMD10CMB4-B7GL2(GN)GB4-B6-J6-B62-2H18-OPO-O11-10(17A2-)2(14A-2A2-)5(B13A-AB2-)B13E-E4(B2-B13F-F)B2-BM13CMB2-B2G2L4G4LN2GB2-B6-J-J6-B64-3O16-O-O11-3(17A2-)7(15A-A2-)2(14A2-A2-)B3(13A2(2-B))2D11A2(2-B)6C7A2(2-B)13E4(2(2-B)10C3F)2(2-B)15CB2-B3GL7GLN2GB2-B5-2(J-)J5-B64-OHOPH27-21A-51A5(-18A)-5A-12A2(-9A2-7A)-2AB6A2-7A2(-A2B15A)-A2BA2D4C8A-A2BA6C8A-A2B15E-E4(2BM7C4B3C-M)2BM15CM2B3GLGL5GLGL3G2B5-3(J-)J5-B50-PH5-OH4-OHO11-2H2-HO-H10-20A2-17A-18A6(-14A2-2A)-A-12A2(2-2A-5A2-7A)2-AB6A2-4A2(3D2-2B12A)3D2-2BA2D9C3D2-2BA14C2-2B4E6C5E4(2-2B8C4B3C)2-2B17C2B2GLG2L2(GL)5GNG2B4-4(J-)J4-B47-H-2O12-O-QH-O9-3H2O-2H9-20A2-8A2(D8A-9A)2(D4A2-2A-9A)D4A2-2A-5A2C2AD4A2-2A-5A2D2CD4A2-2A-5A2D3C4A2-2A-A-3A2D3C4A2-2A-7A3C4A2-8A2-3C4A2-AB6A2-4A2(3D2-2B12A)3D2-2BA2D9C3D2-2BA14C2-2B4E6C5E4(2-2B8C4B3C)2-2B17C2B3GL6GL3G2LG2B3-5(J-)J3-B28-H-O13-O-OH-OP12-O-O29-20A2-8A2(D2A-5A-9A)2(D5A-2A-9A)D4A2-2A-5A4CD4A2-8A2D2CD4A2-8A2D3C4A2-4A-3A2D3C4A2-10A3C4A2-8A2-3C4A2-AB6A2-4A2(3D2-2B12A)3D2-2BA2D9C3D2-2BA14C2-2B4E2A4C5E4(2-2B8C4B3C)2-2B17C2B2GL3GLGL6G2N2B2-6(J-)J2-B9-2HO13-4H-O13-H-H2-H45-21A-8A3(D18A)D5A-12AD2A4-8A2C2AD2A4-8A2D2AD2A4-8A5D2A4-4A-3A2(5D2A4-8A)2-3D2A4-AB6A2-4AD4-2B2A-9AD4-2B2A-6A4-2D2-2BAD-11D3-2BAD-9D2C3-2B2E-E2A3BC4E4(3-2B2C-11C)3-2B2C-14C2BGL6GL2G2L2G2N2B3-5(J-)J3-B9-2HOP12-3H3-HPO61-21A-8A2(D18A)D5A-12AD3A3-12AD2A4-8A2C2AD2A4-8A2D2AD2A4-8A5D2A4-4A-3A2(5D2A4-8A)2-3D2A4-AB6A2-5A2(4-2B13A)-2A-2BA8D5-2D-2BA8D8-2B4E2A3B8-4(2B14C3-)2B17C2BGNG2L4GL2G2LNLG2B4-4(J-)J4-B9-OHO13-4H2(-H)11-H-2H3-H43-21A-8A2(D18A)D3A2-2(13AD2A3-)9A2I2AD2A3-9A2D2AD2A3-9A5D2A3-5A-3A5D2A2(3-16A)3-2AB2(13A3-A2B)10A-A-4A2B5A4D6-2D2B5A7D4CM2B4E2A3BC7E2BM15C3(M2BM7C7I-)M2BM7C7IDM2B2G2N7GL2GN2G2B5-3(J-)J5-B28-H-H13-H-2H-OH12-H-2H29-17A2-A-8A2(D6A2-10A)D3A2-3(A2-10AD2A3-)A2-6A2D2AD2A3-A2-6A5D2A3-A2-2A-3A5D2A2(3-A2-13A)3-A2-B5A2-5A3-B2-B12A3-B2-B15A2(B2-B4A4D2-5A)B2-B3E2A2KB2-5E4(B2-BA3C3K2C6E)B2-B4C3K2I6EB2-BGNLG2L4G3N2GB2-B5-2(J-)J5-B48-H-H13-H-2H-O13-H-H11-17A2(2-10AD6A)2-10AD2-4A2(2-10AD4-2A)2-6A4ID4-2A2-6A2D2ID4(4-2A2-11A)4-2A2-B5A-4A4-AB2-B10A4-AB2-B15A2(B2-B4A5D6A)B2-B3E2A2K4(2C6EB2-BA3C3K)2C6EB2-BM3C3K2C6EB2-B3GLN5GL2G2NB2-B6-J-J6-B98-15A2(4-2A-2A4BD5A)3(4-2A-2A4BD3-2A)4-2A-2AB3ID3-2A4-2A-2A2D2ID4(3-2A4-2A-7A)3-2A2(4-BA-7A3-AB)4-BA-8A-2A2(B4-BA-A5D5A)B4-BE-2A2K4(2C5EB4-BM-C3K)2C5EB4-2B-6B5EB4-B2G2(LG)L4G2NB4-B6-J6-B100-13A2(6-4A4BD4A)3(6-4A4BD2-2A)6-4AB3ID2-2A6-4A2D2ID4(2-2A6-9A)2-2A6-B8A2-A2(B6-B8A-2A)2(B6-B2A5D4A)B6-BE2A4C2E-E4(B6-BM6C4E)B6-8B4EB6-B3GNGN3G2NB6-B11-B102-11A5(8-3A4BD3A)8-3AB3ID3A8-3A2D2ID3A4(8-11A)3(8-2BA5-A2B)2(8-2BD5-A2B)8-2BE4(5-E2B8-2BM)4C2E2B8-7B2E2B8-2BNG5N2B8-2B7-2B105-6(7A12-)2(2AD4A12-)4(7A12-)5(7B12-)B5AB12-BAM3AB6(12-7B)222-5(5A14-5A185-5B14-5B337-)7(5A14-)5(5B14-)5B216-
