model
size = 25 30 19, scale = 0.05, origin = -y
material 
  colors = A:#E00 B:#070 C:#FF0 D:#EEE E:#CF3 F:#251505 G:#BBB H:#000 I:#960 J:#CC6 K:#CF0 L:#1C0900 M:#AAA N:#939 O:#00F P:#888 Q:#00C R:#FCF S:#AAAAB9
voxels
6-8(7B18-)8(7D18-)8(7A18-)7A141-3(11B14-)3B3-B-4(3B14-3B5-)3B2(14-2DA5-A2D)5(14-3D5-3D)14-2DA5-C2D6(14-3A5-3A)14-11A14-2AF3LI2L2A14-2A7-2A138-3(13B12-)2B4-3B2-2B12-2B4-2B3-3(2B12-2B9-)2B6(12-DA9-AD)12-DA6-2D2AD12-DA6-DC2AD3(12-2A7-4A)3(12-2A8-3A)12-13A12-A2FILI3LIFLA12-A11-A136-3(15B10-)10B2-3B10-9B4-3(2B10-8B5-)2B2(10-D7A5-AD)4(10-DA2-A3C5-AD)10-DA2-A4C5AD10-DA2-A3C-C-3AD6(10-2A2-4A2-5A)10-15A10-A5FI2FLIF2LA10-A6-J6-A134-17B2(8-8B-8B)8-14B-2B8-11B4-3(2B8-9B6-)2B2(8-D8A6-AD)4(8-D5A3C6-AD)8-D5A4C-5AD8-D5A4C2-4AD2(8-10A-6A)5(8-17A)8-2A3LI4FIFLF2LA8-A6-J-J6-A42-M90-17B2(8-B9C7B)5(8-B9C3B3-B)2(8-D12A3-D)2(8-D5A5C2A3-D)8-D5A4C3A3-D8-D5A4C3A2-AD8-D5A3C-A-2A-AD8-D5A4C2-4AD8-10A-6A8-10A-4A-A5(8-17A)8-A2F2I4F2IFLFILA8-A5-2(J-)J5-A42-PG19-G4-G63-19B2(6-2B9C8B)5(6-2B9C3B3-2B)2(6-D13A3-AD)2(6-D6A3E2C2A3-AD)2(6-D13A3-AD)6-D9A-5A-AD6-D6A3EC2-5AD6-11A-7A6-5A6H-7A6-5AQ4D3E2(5HA6-5AQ4D2EK)4H2A6-5AQ4D2EK4H2A6-5A7EK4H2A6-AF2LIFI3FIFILI2FLA6-A5-3(J-)J5-A16-P24-G20-PMP3-G62-19B5(6-2B16CB)6-B-16C8B-16C7BD2(-2A2CA3E4C4AD5-2D)2(-5A3E2C6AD5-2D)2(-15A-D5-2D)-8A-A-4A-D5-2D-5A3EC3-3A-D5-DA-5A3E2(C-)3A-A5-2A-3A6H-H-3H-8A-3AE4D3E4H-8A2(-3AE4D2EK4H-A6-A)-3AE4D2EK4H2A6-A-3A7EK4H2A6-AFLFI3FI8FLA6-A4-4(J-)J4-A15-3M21-2M-2G19-2MG2-MG18-M5-M36-19B5(6-2B5C8A3DB)6-B-5CKAE4A4K8B-5CK2E4A4KA6BD2(-2A2CA3E4C4AD5-2D)2(-5A3E2C6AD5-2D)2(-15A-D5-2D)-8A-6A-D5-2D-5A3EC3-3C-D5-DA-5A3E2(C-)3C-A5-2A-3A2H4E-E-3E-8A-3AE4D7E-8A2(-3AE4D2EK4E-A6-A)-3AE4D2EK4E2A6-A-3A7E2KE2D2A6-A2F2I2FI3FI5FLA6-A3-5(J-)J3-A15-3G68-G44-19B5(6-2B5C8A3DB)6-B-5CKAE4A4K8B-5CK2E4A4KA6BD2(-2A2CA3E4C4AD5-2D)2(-5A3E2C6AD5-2D)3(-15A-D5-2D)-5A3E7C-D5-DA-5A3E7C-A5-2A-5A3E4D3E-8A-5A3D7E-8A2(-5A3D2EK4E-A6-A)-5A3D2EK4E2A6-A-5A5E2KE2D2A6-AFI6F2I4FI2LA6-A2-6(J-)J2-A15-2GM21-2G-2G19-2G2-3G16-P-G4-2G18-G17-19B5(6-2B5C8A3DB)6-B-5CK4EKA4K8B-17C6BD2(-2A2CA7C4AD5-2D)-4A2-2A2C2(6AD5-2D-4A6-)A-3A2(-D5-2D-15A)-D5-2D-5A3E7C-D5-DA-5A3E7C-A5-2A-5A3E3D3NE-8A-5A6E3NE-S7A2(-5A6E3NE-A6-A)-5A6E3NE2A6-A-5A6E2N2D2A6-A6FI9FLA6-A3-5(J-)J3-A40-3G21-MG-2G16-3MRM3-2G14-2M-2G5-G11-19B5(6-2B5C8A3DB)6-B-5CK4EKAK3D8B-16C7BD2(-2A2CA7C4AD5-2D)-4A2-2A2C2(6AD5-2D-4A6-)A2-2A2(-D5-2D-15A)-D5-2D-4A4E7C-D5-DA-5A3E7C-A5-2A-5A3E3D2(3NE-8A-5A6E)2(3NE-A6-A-5A6E)3NE2A6-A-5A6E2N2D2A6-A8FI3FIFILFA6-A4-4(J-)J4-A40-3G42-M2G43-19B7(6-2B15CDB)2(6-D3A10C4AD)6-D9A2C6A4(D6-D17A)D6-D5A4E8CD6-7A3E3C6A6(6-19A)6-2A4F2I5FIL2FLA6-A5-3(J-)J5-A40-3G21-MG-2G16-5M3-2G14-2M-2M5-G12-17B8-9B4C3OB8-9B4CO2DB8-9B4C3O3(B8-9B7C)B8-9B5C2DB2(8-D2A10C4D)8-D8A2C5A4(D8-D15A)D8-D4A4E2C5AD7(8-17A)8-AIF2IFI3FI2F2IFA8-A5-2(J-)J5-A110-P2-GM18-17B7(8-14B-2B)2(8-D2A9C2D-2D)8-DA-6A2C3A4(-AD8-DA-11A)-AD8-D4A4E2C3A-AD5(8-2A-11A-2A)2(8-14A-2A)8-A2F2(IF)I2FILI3FA8-A6-J-J6-A85-G24-M3-G19-8(15B10-)DA9C4D10-DA2C8-3D10-D4A5C4AD10-D2AC10AD10-D13A2(D10-D7A-5A)D10-D2A5C-C4AD7(10-8A-6A)10-2A3FIFI2F2L2FA10-A6-J6-A86-G28-G20-13B12-3B8-2B6(12-13B)2(12-D9A3D)12-D3A5C3A4(D12-D11A)D12-DA7C3AD7(12-13A)12-A6FIL3FA12-A11-A115-2G21-11B6(14-3B3-5B)14-3B2-6B3(14-2DA2-4A2D)14-2DA-5A4(2D14-2D7A)2D7(14-11A)14-3A6F2A14-2A7-2A91-2(G24-)8(7B18-)8(7D18-)8(7A18-)7A93-M43-
