model
size = 25 30 19, scale = 0.05, origin = -y
material 
  colors = A:#E00 B:#009 C:#CF3 D:#EEE E:#FF0 F:#251505 G:#00C H:#000 I:#BBB J:#CF0 K:#CC6 L:#960 M:#939 N:#1C0900 O:#AAA P:#AAAAB9 Q:#00F R:#888 S:#FCF
voxels
6-9(7A18-)9(7B18-)6(7D18-)7D141-3(11A14-)3A3-A-5(3A14-3A5-)3A9(14-3B5-3B)4(14-2DP5-P2D)14-2DP5CP2D14-2D3F2N2F2D14-2D7-2D138-3(13A12-)2A4-3A2-2A12-2A4-2A3-4(2A12-2A9-)2A5(12-2B9-2B)12-2B6-AD3B12-2B6-5B2(12-2B7-4B)12-DG7-C3(2HD12-DG8-)2HD12-DP7CE2HD12-D3FNL2NL2FND12-D11-D136-3(15A10-)10A2-3A10-9A4-4(2A10-8A5-)2A10-5B3A4(5-2B10-2B2-B3E)5-2B10-2B2-B4EAD4B10-2B2-B2E2(B-)4B2(10-2B2-4B2-5B)10-DG2-4C2-C3(3HD10-DG2-4C2-J)3HD10-DP8CJ3HD10-D5FL2F2NF2ND10-D6-K6-D134-17A2(8-8A-8A)8-14A-2A8-11A4-4(2A8-9A6-)2A8-6B3A4(6-2B8-6B3E)6-2B8-6B4E-A5B8-6B2E2B2-5B2(8-10B-6B)8-D4G7C3(4HD8-D4G6CJ)4HD8-DP9CJ4HD8-DF3NL4FLFNF2ND8-D6-K-K6-D42-O90-3(17A8-)6(13A3-A8-)6B6A2(B3-B8-6B5EA)2(B3-B8-6B4E2A)B2-2B8-6B3E-A2(-2B)8-6B2E2B2-5B8-10B-6B8-10B-4B-B8-D4G7C3(4HD8-D4G6CJ)4HD8-D10CJ4HD8-D2F2L4F2LFN2FND8-D5-2(K-)K5-D42-RI19-I4-I63-3(19A6-)6(14A3-2A6-)7B6A2(B3-2B6-7B3C2EA)2(B3-2B6-7B6A)B3-2B6-7B3A-2A3B-2B6-7B2C2B2-6B2(6-11B-7B)6-D5G4D3C3(5HD6-D5G4D2CJ)5HD6-DP10CJ5HD6-DF2NLFL3FLFLNL2FND6-D5-3(K-)K5-D16-R24-I20-ROR3-I62-19A5(6-5A13EA)6-A2(-3A13E8A)-3AEA3C4E5A5-2B-5B3C3E2(6B5-2B-5B3C2EA)6B2(5-2B-5B6A4B-B)5-2B-5B3A-A-4B-B5-2B-5B3CE3-3B-B5-2B-7BC2(E-)3A-B5-2B-7B2H-H-3H-7BD-3GC4D3C4H-A7D2(-3GC4D2CJ4H-D6-D)-3GC4D2CJ5HD6-D-10CJ5HD6-DFNFL3FL8FND6-D4-4(K-)K4-D15-3O21-2O-2I19-2OI2-OI18-O5-O36-19A5(6-5A2E8A3DA)6-A-3A2EJAC4A4J8A-3A2EJ2C4A4J8A-3AEA3C4E5A5-2B-5B3C3E2(6B5-2B-5B3C2EA)6B2(5-2B-5B6A4B-B)5-2B-5B3A-2A4B-B5-2B-5B3CE3-3B-B5-2B-7BC2(E-)3E-B5-2B-7B2C-C-3C-7BD-3GC4D7C-A7D2(-3GC4D2CJ4C-D6-D)-3GC4D2CJ5CD6-D-10C2JC4D6-D2F2L2FL3FL5FND6-D3-5(K-)K3-D15-3I68-I44-19A5(6-5A2E8A3DA)6-A-3A2EJAC4A4J8A-3A2EJ2C4A4J8A-3AEA3C4E5A5-2B-5B3C3E2(6B5-2B-5B3C2EA)6B3(5-2B-5B6A4B-B)5-2B-5B3C3E4B-B5-2B-7BC7E-B5-2B-7BC4D3C-7BD-3GC4D7C-A7D2(-3GC4D2CJ4C-D6-D)-3GC4D2CJ5CD6-D-10C2JC4D6-DFL6F2L4FL2ND6-D2-6(K-)K2-D15-2IO21-2I-2I19-2I2-3I16-R-I4-2I18-I17-19A5(6-5A2E8A3DA)6-A-3A2EJ4CJA4JE7A-3A14E7A-3AEA7E5A5-2B-5B6E6B5-2B-4B2-2A2E2(A6B5-2B-4B6-)A-3B2(-B5-2B-5B6A4B)-B5-2B-5B3C3E4B-B5-2B-7BC7E-B5-2B-7BC3D3MC-7BD-3G8C3MC-P7D2(-3G8C3MC-D6-D)-3G8C3M2CD6-D-11C2M4D6-D6FL9FND6-D3-5(K-)K3-D40-3I21-OI-2I16-3OSO3-2I14-2O-2I5-I11-19A5(6-5A2E8A3DA)6-A-3A2EJ4CJAJ3D8A-3A13E8A-3AEA7E5A5-2B-5B7E5B5-2B-4B2-2A2E2(2A5B5-2B-4B6-)A2-2B2(-B5-2B-5B7A3B)-B5-2B-5B3C5E2B-B5-2B-7BC4E3B-B5-2B-7BC3DM3B-7BD-3G8C3MC-A7D2(-3G8C3MC-D6-D)-3G8C3M2CD6-D-11C2M4D6-D8FL3FLFLNFD6-D4-4(K-)K4-D40-3I42-O2I43-19A7(6-5A12EDA)6-5A9E5A6-7B7E5B6-7B3A2E2A4(5B6-7B7A)5B6-7B3C5E4B6-5B5C4E5B6-5B2H2C5A5B4(6-D4G8C3MCPD)6-DP11C2M4D6-D5F2L5FLN2FND6-D5-3(K-)K5-D40-3I21-OI-2I16-5O3-2I14-2O-2O5-I12-17A8-12AE3QA8-12AEQ2DA8-12AE3Q3(A8-12A4E)A8-12A2E2DA8-12AE3DA8-4B9E4B8-4B5A2E2A4(4B8-4B9A)4B8-4BA4C2E3A3B8-4B5C2E2A4B8-4B2H2C5A4B4(8-2D2G12CD)8-D13C3D8-DLF2LFL3FL2F2LFD8-D5-2(K-)K5-D110-R2-IO18-17A8(8-14A-2A)8-14B5(-2B8-2B-11B)-2B8-14B-2B8-2B-B5C2E2AB-2B8-2B-B9HB-2B3(8-2D-G10C-PD)8-2D2G10C-PD8-DPE11C-2D8-D2F2(LF)L2FLNL3FD8-D6-K-K6-D85-I24-O3-I19-9(15A10-)4B8-3B3(10-15B)3(10-8B-6B)10-3B5C-E2A3B10-3B5H-3H3B4(10-D2G5C-4CPD)10-DP6C-4C2D10-D4FLFL2F2N2FD10-D6-K6-D86-I28-I20-13A12-3A8-2A7(12-13A)7(12-13B)2(12-2B9A2B)4(12-D11AD)12-DP9CPD12-D6FLN3FD12-D11-D115-2I21-11A6(14-3A3-5A)2(14-3A2-6A)2(14-3B2-6B)14-3B-7B6(14-11B)5(14-2D7A2D)14-2D7F2D14-2D7-2D91-2(I24-)9(7A18-)9(7B18-)6(7D18-)7D93-O43-
