model
size = 25 30 19, scale = 0.05, origin = -y
material 
  colors = A:#FF0 B:#009 C:#06C D:#E00 E:#CF3 F:#251505 G:#EEE H:#00C I:#000 J:#BBB K:#CC6 L:#960 M:#939 N:#CF0 O:#1C0900 P:#AAA Q:#AAAAB9 R:#888 S:#FCF
voxels
6-12(7A18-)12(7C18-)7C141-11A2(14-7A2D2A)14-3A3-A-6(D2A14-3A5-)2(G2A14-3A5-)G2A6(14-2CG5-G2C)4(14-2CQ5-Q2C)14-2CQ5EQ2C14-2C3F2O2F2C14-2C7-2C138-13A2(12-2A8D3A)12-2A4-3D2-2A12-2A4-2D3-7(2A12-2A9-)2A2(12-CB9-BC)2(12-CB6-2G2BC)2(12-CB7-G2BC)12-CH7-E3(2IC12-CH8-)2IC12-CQ7EA2IC12-C3FOL2OL2FOC12-C11-C136-15A2(10-3A8D4A)10-3A7D2-3A10-3A6D4-4(2A10-3A5D5-)2A10-3A2B3D2(5-2A10-2A2-B3A)5-2A2(10-CB2-B3A5-BC)10-CB2-B4ADG3BC10-CB2-B2A2(B-)3B2(C10-CB2(2-4B))C10-CH2-4E2-E3(3IC10-CH2-4E2-N)3IC10-CQ8EN3IC10-C5FL2F2OF2OC10-C6-K6-C134-17A2(8-4A4D-3D5A)8-4A8D2A-2A8-4A7D4-4(2A8-4A5D6-)2A8-4A2B3D2(6-2A8-4A2B3A)6-2A2(8-C5B3A6-BC)8-C5B4A-D4BC8-C5B2A2B2-4B2(C8-C9B-5B)C8-C4H7E3(4IC8-C4H6EN)4IC8-CQ9EN4IC8-CF3OL4FLFOF2OC8-C6-K-K6-C42-P90-17A2(8-4A8D5A)6(8-4A8DA3-A)8-4A2B6D2(A3-A8-4A2B5AD)A3-A8-C5B4A2DB3-C8-C5B4A2DB2-BC8-C5B3A-D-2B-BC8-C5B2A2B2-4BC8-C9B-5BC8-C9B-4B-C8-C4H7E3(4IC8-C4H6EN)4IC8-C10EN4IC8-C2F2L4F2LFO2FOC8-C5-2(K-)K5-C42-RJ19-J4-J63-19A2(6-5A8D6A)6(6-5A8DA3-2A)6-5A2B6D2(A3-2A6-5A2B3E2AD)A3-2A2(6-C6B6DB3-BC)6-C6B3D-2D3B-BC6-C6B2E2B2-5B2(C6-C10B-6B)C6-C5H4G3E3(5IC6-C5H4G2EN)5IC6-CQ10EN5IC6-CF2OLFL3FLFLOL2FOC6-C5-3(K-)K5-C16-R24-J20-RPR3-J62-6(19A6-)A2(-24A)-4AD2(3E9A5-2A-3A2B)3E2AD6A5-2A-3A2B3E2AD6A5-AC2(-5B6D4B-C5-2C)-5B3D-D-4B-C5-2C-5B3EA3-3B-C5-2C-7BE2(A-)3D-C5-2C-7B2I-I-3I-B7C-3HE4G3E4I-D7C2(-3HE4G2EN4I-C6-C)-3HE4G2EN5IC6-C-10EN5IC6-CFOFL3FL8FOC6-C4-4(K-)K4-C15-3P21-2P-2J19-2PJ2-PJ18-P5-P36-19A5(6-7A6D6A)6-A-5ANDE3D13A-5AN2E3D13A-4AD2(3E9A5-2A-3A2B)3E2AD6A5-2A-3A2B3E2AD6A5-AC2(-5B6D4B-C5-2C)-5B3D-2D4B-C5-2C-5B3EA3-3B-C5-2C-7BE2(A-)3A-C5-2C-7B2E-E-3E-B7C-3HE4G7E-D7C2(-3HE4G2EN4E-C6-C)-3HE4G2EN5EC6-C-10E2NE3GC6-C2F2L2FL3FL5FOC6-C3-5(K-)K3-C15-3J68-J44-19A5(6-7A6D6A)6-A-5ANDE3D13A-5AN2E3D13A-4AD2(3E9A5-2A-3A2B)3E2AD6A5-2A-3A2B3E2AD6A5-AC3(-5B6D4B-C5-2C)-5B3E3A4B-C5-2C-7BE7A-C5-2C-7BE4G3E-B7C-3HE4G7E-D7C2(-3HE4G2EN4E-C6-C)-3HE4G2EN5EC6-C-10E2NE3GC6-CFL6F2L4FL2OC6-C2-6(K-)K2-C15-2JP21-2J-2J19-2J2-3J16-R-J4-2J18-J17-19A5(6-7A6D6A)6-A-5AN4EN13A-24A-4AD12A5-2A-3A2B12A5-2A-3AB2-2D2AD6A5-2A-3AB6-D6A5-AC-4B6-D-3B2(-C5-2C-5B6D4B)-C5-2C-5B3E3A4B-C5-2C-7BE7A-C5-2C-7BE3G3ME-B7C-3H8E3ME-Q7C2(-3H8E3ME-C6-C)-3H8E3M2EC6-C-11E2M3GC6-C6FL9FOC6-C3-5(K-)K3-C40-3J21-PJ-2J16-3PSP3-2J14-2P-2J5-J11-19A5(6-7AD11A)6-A-5AN18A-24A-4AD12A5-2A-3A2B12A5-2A-3AB2-11A5-2A-3AB6-7A5-AC-4B6-D2-2B2(-C5-2C-5B7D3B)-C5-2C-5B3E5A2B-C5-2C-7BE4A3B-C5-2C-7BE3GM3B-B7C-3H8E3ME-D7C2(-3H8E3ME-C6-C)-3H8E3M2EC6-C-11E2M3GC6-C8FL3FLFLOFC6-C4-4(K-)K4-C40-3J42-P2J43-12(19A6-)3(C6B7D4BC6-)C6B3E5A3BC6-C4B5E4A4BC6-C4B2I2E5D4B4(C6-C4H8E3MEQ)C6-CQ11E2M3GC6-C5F2L5FLO2FOC6-C5-3(K-)K5-C40-3J21-PJ-2J16-5P3-2J14-2P-2P5-J12-12(17A8-)3(C3B9D3BC8-)C3BD4E2A3D2BC8-C3B5E2A2D3BC8-C3B2I2E5D3B4(C8-CG2H12E)C8-C13E2GC8-CLF2LFL3FL2F2LFC8-C5-2(K-)K5-C110-R2-JP18-17A9(8-14A-2A)2(8-2A-11A-2A)3(8-CB-11B-GC)8-C13B-GC8-CB-B5E2A2DB-GC8-CB-B9IB3(-GC8-CG-H10E)-GC8-CG2H10E-GC8-CQA11E-GC8-C2F2(LF)L2FLOL2FLC8-C6-K-K6-C85-J24-P3-J19-9(15A10-)4A8-3A2(10-15A)10-CG12B3(C10-CG6B-5B)C10-CGB5E-A2D2BC10-CGB5I-3I2B4(C10-CGH5E-4EQ)C10-CG6E-4EGC10-CL3FLFL2F2O2FC10-C6-K6-C86-J28-J20-13A12-3A8-2A10(12-13A)4(12-CG10BC)2(12-CG9DBC)4(12-CG10DC)12-CG9EQC12-CL5FLO3FC12-C11-C115-2J21-11A6(14-3A3-5A)4(14-3A2-6A)14-3A-7A6(14-2C7B2C)5(14-2C7D2C)14-2C7F2C14-2C7-2C91-2(J24-)12(7A18-)12(7C18-)7C93-P43-
