model
size = 25 30 19, scale = 0.05, origin = -y
material 
  colors = A:#0A0 B:#E00 C:#EEE D:#FF0 E:#CF3 F:#F60 G:#00C H:#251505 I:#CF0 J:#AAAAB9 K:#BBB L:#CC6 M:#939 N:#960 O:#1C0900 P:#AAA Q:#F30 R:#040 S:#888 T:#FCF
voxels
6-24(7C18-)7C141-2A7C2(2F14-2A7B)2F14-2AB3-B-4(B2F14-2AB5-)B8(2F14-2AD5-D)2F14-2AJ5-J2F14-2AB5-B4(2F14-2AJ5-J)2F14-2AJ5EJ2F14-2A3H2O2H2F14-2A7-2F138-3A7C3F2(12-A11BF)12-AB4-3B2-BF12-2A4-2B3-4(BF12-AG9-)5(DF12-AG9-)D2(F12-AG6-4D)F12-AG7-2EJF12-AG7-3BF12-AG7-2E3(JF12-AG8-E)JF12-AJ7EDECF12-A3HON2ON2HOF12-A11-F136-4A7C4F2(10-AC11BCF)10-AC8B2-BCF10-4A5B4-3(BF10-A3G4B5-)B2(F10-A3G4D5-D)4(F10-AG2-4D5-D)F10-AG2-10DF10-AG2-4D-D-3DF10-AG2-4E2-3EJF10-AG2(2-4B)F10-AG2-4E2-3E3(JF10-AG2-4E2-I2E)JF10-AJ8EIE2CF10-A5HN2H2OH2OF10-A6-L6-F134-5A7C5F2(8-A2C5B-5B2CF)8-A2C11B-CF8-5A6B4-3(QF8-A4G4B6-)6(QF8-A4G4D6-)QF8-A4G5D-4DQF8-A4G5D2-3DQF8-A4G5E-4EQF8-A4G5B-4BQF8-A4G10E3(QF8-A4G6EI3E)QF8-AJ9EIE3CF8-AH3ON4HNHOH2OF8-A6-L-L6-F42-P90-5A7C5F2(8-A2C11B2CF)8-A2C10B3-F8-5A4(8B3-F8-A4G)5(8D3-F8-A4G)8D2-QF8-A4G4D-D-2D-QF8-A4G5D2-3DQF8-A4G5E-4EQF8-A4G5B-4B-F8-A4G10E3(QF8-A4G6EI3E)QF8-A10EIE3CF8-A2H2N4H2NHO2HOF8-A5-2(L-)L5-F42-SK19-K4-K63-6A7C6F2(6-A3C11B3CF)6-A3C10B3-CF6-6A8B3-CF6-7A7B3-CF6-7AIBE4B3-BF6-7AI2E4B3-B6(F6-7A3E4D3-D)F6-7A3E-5D-DF6-7A3ED2-3DQDF6-7A3ED-4DQDF6-7A4B-4BQBF6-7A3C6E3(QJF6-7A3C2EI3E)QJF6-AJ10EI2E3CF6-AH2ONHN3HNHNON2HOF6-A5-3(L-)L5-F16-S24-K20-SPS3-K62-6A7C6F3(6-A3C11B3CF)6-3AC11B3CF6-7A8B3CF6-A-5AIBE8BF6-A-5AI2E4B3IB4(F6-A-5A3E8D)2(F6-A-5A3E7D-)F6-A-5A3E-D-4D-F6-A-5A3ED3-3D-F6-A-5A3E2(D-)3D-F6-A-5A4B-B-3B-F6-A-5A3C7E2(-F6-A-5A3C2EI4E)-F6-A-5A3C2EI5EF6-A-10E2IE3CF6-AHOHN3HN8HOF6-A4-4(L-)L4-F15-3P21-2P-2K19-2PK2-PK18-P5-P36-6A7C6F3(6-A3C11B3CF)6-3AC11B3CF6-7A8B3CF6-A-5AIBE4B4IB6CA-5AI2E4B4IB6C4(A-5A3E8DF5-C)2(A-5A3E7D-F5-C)A-5A3E-6D-F5-CA-5A3ED3-3D-F5-CA-5A3E2(D-)3D-F5-CA-5A4E-E-3E-J6CA-5A3C7E-J6C2(A-5A3C2EI4E-F6-)A-5A3C2EI5EF6-A-10E2IE3CF6-A2H2N2HN3HN5HOF6-A3-5(L-)L3-F15-3K68-K44-6A7C6F3(6-A3C11B3CF)6-3AC11B3CF6-7A8B3CF6-A-5AIBE4B4IB6CA-5AI2E4B4IB6C4(A-5A3E8DF5-C)5(A-5A3E7D-F5-C)A-5A3E4C3E-J6CA-5A3C7E-J6C2(A-5A3C2EI4E-F6-)A-5A3C2EI5EF6-A-10E2IE3CF6-AHN6H2N4HN2OF6-A2-6(L-)L2-F15-2KP21-2K-2K19-2K2-3K16-S-K4-2K18-K17-6A7C6F3(6-A3C11B3CF)6-3AC11B3CF6-7A8B3CF6-2(A-5AI4EIB4IB6C)2(A-5A3B8DF5-C)A-4A2-2B8DF5-CA-4A6-6DF5-CA-4A6-D-3D4(-F5-CA-5A3E7D)-F5-CA-5A3E3C2(3ME-J6CA-5A6E)2(3ME-F6-A-5A6E)3M2EF6-A-11E2M3CF6-A6HN9HOF6-A3-5(L-)L3-F40-3K21-PK-2K16-3PTP3-2K14-2P-2K5-K11-6A7C6F3(6-A3C11B3CF)6-3AC11B3CF6-7A8B3CF6-A-5AI4EIBI10CA-5AI4EIB5I6C2(A-5A3B8DF5-C)A-4A2-2B8DF5-CA-4A6-6DF5-CA-4A6-D2-2D4(-F5-CA-5A3E7D)-F5-CA-5A3E3C2(3ME-J6CA-5A6E)2(3ME-F6-A-5A6E)3M2EF6-A-11E2M3CF6-A8HN3HNHNOHF6-A4-4(L-)L4-F40-3K42-P2K43-6A7C6F3(6-A3C2E9B3CF)6-3AC2E9B2(3CF6-7A8B)3CF6-7A11B5(F6-7A3B8D)4(F6-7A3E8D)F6-7A2E9B4(F6-7A6E3MEJ)F6-AJ11E2M3CF6-A5H2N5HNO2HOF6-A5-3(L-)L5-F40-3K21-PK-2K16-5P3-2K14-2P-2P5-K12-5A7C5F3(8-A2C2E9B2CF)8-2AC2E3(11BF8-A3GE)11B3(F8-A3G5B7D)2(F8-A3G3B2R7D)3(F8-A3GB4E7D)F8-A3G5E7DF8-A3GB3E8B4(F8-A3G12E)F8-A13E2CF8-ANH2NHN3HN2H2NHF8-A5-2(L-)L5-F110-S2-KP18-5A7C5F3(8-A2C11B-CF)8-2AC11B3(-BF8-A3G10B)-B2(F8-A3G5B5D-D)F8-AG-G5B5D-DF8-AG-GB4R5D-DF8-AG-GB2(ER)2(5D-DF8-AG-GB4E)5D-DF8-A3GB4E5D-DF8-AG-G5E5D-DF8-AG-G10B-B3(F8-AG-G10E-J)F8-A3G10E-JF8-AJD11E-CF8-A2H2(NH)N2HNON3HF8-A6-L-L6-F85-K24-P3-K19-4A7C4F3(10-AC11BCF)10-4A10BF10-A2G11BF10-A2G9C2BF10-A2G11BF10-A2G11DF10-A2GD8-2D3(F10-A2G11D)3(F10-A2G5D-5D)F10-A2G5E-5DF10-A2G5B-5B4(F10-A2G5E-4EJ)F10-AJ6E-4ECF10-A4HNHN2H2O2HF10-A6-L6-F86-K28-K20-3A7C3F12-A2B8-B2(F12-A11B)F12-3A9BF12-AG10BF12-AG9CBF12-AG10B8(F12-AG8D2B)F12-AG5E3D2BF12-AG10B4(F12-AG8E2B)F12-AJ9EJF12-A6HNO3HF12-A11-F115-2K21-2A7C6(2F14-2AB3-3B)2F14-2AB2-4B3(2F14-2AD2-4D)2F14-2AD-5D4(2F14-2A7D)2F14-2AJ3E3D2F14-2A7B5(2F14-2AJ5EJ)2F14-2A7H2F14-2A7-2F91-2(K24-)24(7C18-)7C93-P43-
