model
size = 13 32 10, scale = 0.05, origin = -y
material 
  colors = A:#121212 B:#0A0A0A C:#000 D:#002 E:#008 F:#1E1E1E G:#323232 H:#555 I:#777 J:#366 K:#336 L:#800 M:#630 N:#669 O:#63C P:#309 Q:#030 R:#0B0 S:#080 T:#050
voxels
40-3(2F-)2F15-3(2G-)2G15-3(IH-)IH15-2J-2K-2M-2L287-14B5(A3(B2A)3B3(2AB)2A3B3(2AB)A2B)A3(B2A)2B-11B183-2B3(2AB)A5(2B37A)2B12ABA3(B2A)B-14(2B11-)BA3(B2A)2B12A5(B13AB24A)3B3(2AB)A-14(2B11-)4(B2A)B13A5(B11AB26A)-3(2AB)2A183-2B3(2AB)A5(2B37A)2B12A-A3(B2A)B183-BA3(B2A)2B12A5(B13AB24A)B-3(B2A)BA183-4(B2A)B13A5(B11AB26A)-3(2AB)2A183-2B3(2AB)A3(2B37A)2B11C2ACQCEO2ENEJC2ACTCDE2DEDEC2BCSCEOENPJKC2ACRC7DC2A11C2B11CA-A3(B2A)B183-14B9(11A2B)6(11-2B)11AB-11B183-
