model
size = 30 28 26, scale = 0.05, origin = -y
material 
  colors = A:#292959 B:#0F0F32 C:#FFBB32 D:#555 E:#960 F:#007 G:#200 H:#002 I:#004 J:#FC3 K:#66F L:#500
voxels
101-8E1162-2(8A22-)8C770-2(12A18-)2C8A2C20-8A22-8A708-2(4A8-4A14-)2C2A8F2A2C16-12A18-12A21-6C678-3A12-3A7-3K2-3A12-3A2-3K3(-K)-2CA12FA2C2(-K)-6K3-14A3-6K2(-K)3-14A3-3(K-)3K6-2C6A2C6-3K13-6A24-6A613-3D-3A14-3A-3D-5D3A14-3A10D2CA4F6-4FA2C10D2-5A6I5A2-10D2-16A2-10D3-2C10A2C3-5D-4D5-10A5-4D11-10A22-6C225-4L16-4L304-3D22-3D-5D2A16-2A10D2A16-2A5D4-DCA3F10-3FACD8-D-4A10I4A-D8-D-18A-D8-D2-C14AC2-D5-4D3-14A3-4D3-3D3-14A3-3D12-3C4A3C23-4A137-2G18-2G8-2G18-2G7-L2GL16-L2GL7-8(2G18-2G8-)2G18-2G5-2D-2G18-2G-2D-4D2G18-2G8D2A18-2A4D4-2A18-2A8-CA3F12-3FAC9-4A3I6-3I4A10-7A6H7A11-C16AC10-D2-16A2-D6-3D2-16A2-3D10-2C10A2C18-10A134-2G18-2G8-2G18-2G7-L2GL16-L2GL7-8(2G18-2G8-)2G18-2G4-D3-2G18-2G3-4D-2G18-2G-3D3-D2A18-2AD7-2A18-2A8-CA2F14-2FAC9-3A3I8-3I3A10-6A8H6A11-C16AC13-16A14-16A15-C12AC17-12A192-4L16-4L304-C26-C2-2E2B20-2B2E4-AB20-BA6-CA3F14-3FAC7-4A2I10-2I4A8-6A10H6A10-C16AC13-16A14-16A15-C12AC17-12A460-3(C26-C2-)2E2B20-2B2E4-AB20-BA6-CA2F16-2FAC7-3A2I12-2I3A8-5A12H5A9-C18AC11-18A12-18A13-2C12A2C16-12A22-4J86-4J314-2(C26-C2-)C26-C3-B24-B4-E2B20-2BE5-AB20-BA6-CA2F16-2FAC7-3A2I12-2I3A8-5A12H5A9-C18AC11-18A12-18A13-C14AC15-14A20-6J25-4J26-4J25-6J283-2(C26-C2-)C26-C3-2(B24-B4-)E2B20-2BE5-AB20-BA6-CA2F16-2FAC7-3A2I12-2I3A8-5A12H5A9-C18AC11-18A12-18A13-C14AC15-14A20-6J25-4J26-4J25-6J253-2(C26-C2-)C26-C3-3(B24-B4-)E2B20-2BE5-AB20-BA6-CA2F16-2FAC7-3A2I12-2I3A8-5A12H5A9-C18AC11-18A12-18A13-C14AC15-14A20-6J25-4J26-4J25-6J223-2(CB24-BC2-)CB24-BC3-4(B24-B4-)E2B20-2BE5-AB20-BA6-CA2F16-2FAC7-3A2I12-2I3A8-5A12H5A9-C18AC11-18A12-18A13-2C12A2C16-12A22-4J86-4J73-3C24-6C24-3C-2(2C24-2C2-)2C24-2C3-7(B24-B4-)E2B20-2BE5-AB20-BA6-CA3F14-3FAC7-4A2I10-2I4A8-6A10H6A10-C16AC13-16A14-16A15-C12AC17-12A190-EB24-BE3-3(B24-B4-)E24-E5-7(B22-B6-)E2B18-2BE7-AB18-BA8-CA2F14-2FAC9-3A3I8-3I3A10-6A8H6A11-C16AC13-16A14-16A15-C12AC17-12A190-EB24-BE3-3(B24-B4-)E24-E5-7(B22-B6-)E2B18-2BE7-AB18-BA8-CA3F12-3FAC9-4A4I4-4I4A10-8A4H8A12-C14AC15-14A16-14A17-C10AC19-10A191-E2B22-2BE3-3(2B22-2B4-)2E22-2E6-7(B20-B8-)E2B16-2BE9-AB16-BA10-CA3F10-3FAC11-4A10I4A12-18A13-C14AC15-14A16-14A18-3C4A3C23-4A195-EB22-BE5-3(B22-B6-)E22-E7-7(B20-B8-)E3B14-3BE9-2AB14-B2A10-2CA4F6-4FA2C12-5A6I5A14-16A15-2C10A2C18-10A20-10A22-6C224-E2B20-2BE5-3(2B20-2B6-)2E20-2E8-7(B18-B10-)E3B12-3BE11-2AB12-B2A12-C2A12F2AC13-16A14-16A17-2C6A2C22-6A24-6A255-E2B18-2BE7-3(2B18-2B8-)2E18-2E10-7(B16-B12-)E4B8-4BE13-2A2B8-2B2A14-2C2A8F2A2C16-12A18-12A21-6C316-E2B16-2BE9-3(2B16-2B10-)2E16-2E2(12-2B)6(14-2B12-2B)14-2E12B2E16-2A8B2A18-2C8A2C20-8A22-8A346-E4B10-4BE11-3(4B10-4B12-)3EB10-B3E15-7(2B8-2B18-)2E8B2E20-8A22-8C407-2E4B6-4B2E14-3(4B6-4B16-)3EB6-B3E19-7(8B22-)8E469-3E8B3E19-3(8B22-)8E641-
