model
size = 13 16 18, scale = 0.05, origin = -y
material 
  colors = A:#020 B:#111 C:#FFF D:#6C0 E:#E00 F:#FF0 G:#360
voxels
13-2A3-3A3-2A-A3-ABA3-A7-B12-B11-2(3B10-)2(B-B10-)3B11-B140-5A7-7A5-2(9A4-)2(4A-4A4-)4A-4A5-3A-3A7-2A-2A56-3A10-8A5-9A4-4A5-A3-3A7-A2-5(2A9-A-)3A7-A2-4A5-A3-9A9-3A36-A-A6-7A6-8A5-3A5-A4-2A7-A3-4(A9-A2-)A9-A3-A7-2(A5-)A7-5A9-3A9-A3-A8-2AG2A186-3A-A3-A-3A-2A-A3-A-2A2(183-13A-11A)5-5B8-BF3B160-13A-11A4-7B6-2BCEC2B159-13A-11A3-9B4-2B2CE2C2B158-13A-11A3-9B4-B3CE3CB158-13A-11A3-9B4-B2(D2C)DB158-13A-11A3-9B4-2(B3C)B158-13A-11A3-9B4-2B2CB2C2B158-13A-11A4-7B6-2BCBC2B159-13A-11A5-5B8-5B160-13A-11A183-2(4A-3A-)3A-3A183-
