model
size = 19 26 16, scale = 0.05, origin = -y
material 
  colors = A:#FF0 B:#E00 C:#306 D:#60C E:#303 F:#3CC G:#111 H:#609 I:#EEE J:#888
voxels
2-G-G20-A5-C13-C3-A15-A-C35-A-A15-A3-A13-A5-A12-A5-A6-C5-3(A-)A5-C-A3-3A3-2AC3-A3-C6(-A)-C8-A5-A6-3(A5-)A-C2(3-A-A)3-2(C3-A-)A3-C-A10-3A13-A-A3-A-A9-3A2(-I)-3A7-A-2A5-4A6-2(A5-)A6-2A2-J-A-J2-2A7-2A2-3A2-2A9-3A3-3A4-G5-G7-G3-G-G3-G9-G-G165-B31-B94-B358-B11-B27-B7-B94-B27-3(B3-)B310-2(B3-)B126-B39-B322-B7-B27-B7-B94-B10-B16-B7-B3-B318-B20-B18-B94-B10-B-B5-B12-B318-3(B3-)B8-B5-B-B10-B7-B105-3B5-B-B6-2B6-B3-B310-2(B3-)B2-2B6-B-B5-3B123-3B6-3B7-3B4-2B276-A-A5-A-A7-3(A3-)A5-A3-2B2(A-)4BA5-3B5-4B6-A2-E2-A-A2-E2-A5-A2(-4E)-A7-2(A-)2(E-)A-A8-2(A-)2(E-)A-A7-A3-AE-EA3-A5-A2-4E-4E2-A6-3B5-3B6-A-3B2(-A)-3B-A5-3(A3-)A7-A-A5-A-A236-A-A5-A-A7-3(A3-)A5-A-3B2(-A)-3B-A6-3B5-3B6-A5-A-2(A5-)3(A3-)A7-5(A-)A8-A-A5-A-A7-3(A3-)A5-A2-E2-A-A2-E2-A6-3B5-3B6-A-3B2(-A)-3B-A5-3(A3-)A7-A-A5-A-A294-E7-E51-A-A51-E7-E371-3E3-3E12-2(E3-E14-)EA-AE50-E7-E316-D-C-D14-D3-D2(14-E-C-E14-E3DE)14-EDCD2(E14-E3-)E12-3E3-3E298-CDC15-5D14-2(DC)D14-2(D-)D14-E3DE14-2(D-)D2(14-5D)87-11A7-13A2(6-C2(A4D)AC)7-2A2D3A2D2A9-3A3-3A146-A-A15-A3DA13-2(A5DA12-)3(AD)A12-2A3D2A12-3(AD)2(A12-A5D)A13-5A15-3A16-3A13-A-5A-A9-3A5F3A7-AF2A5F4A6-2(A5F)A6-C2(A4F)AC7-2A2F3A2F2A9-3A3-3A68-C5-A13-A3-C15-C-A35-C-H15-4CH13-7C12-7C6-A5-7C5-A-C3-3A3C3A3-C3-A-H-3(AC)A-C-A8-A5CA6-C5-A5CA5-C-A3-H-A3CA-H3-A3-C-A3-ACA3-A-C10-3A13-A-A3CA-A9-3A2(CF)C3A7-AC2A5C4A5-C2(A5C)AC5-2A2CFCACF2C2A7-2A2C3A2C2A9-3A3-3A62-
