model
size = 32 32 28, scale = 0.05, origin = -y
material 
  colors = A:#E00 B:#001 C:#EEE D:#00F
voxels
525-6B91-4B91-6B699-4A27-6A25-3(8A24-)8A25-6B27-4A700-4A26-8A23-10A21-12A20-12A19-3(14A18-)14A19-2AB9A20-12A21-10A23-8A26-4B541-2A27-8A22-12A19-14A18-14A17-2(16A16-)16A15-18A14-18A15-2(16A16-)16A17-14A18-14A19-3AB8A22-8A27-2A444-6A24-10A20-14A17-16A16-16A15-18A14-18A13-5(20A12-)20A13-18A14-18A15-16A16-16A17-14A20-10A24-6B377-8A22-12A19-14A17-16A15-18A13-20A12-20A11-7(22A10-)22A11-20A12-20A13-18A15-16A17-14A19-2AB9A22-8A312-8A22-12A19-14A16-18A14-18A13-20A11-22A10-22A9-7(24A8-)24A9-22A10-22A11-20A13-18A14-18A16-14A19-12A22-8A249-6A23-12A19-14A16-18A13-20A12-20A11-22A9-2(24A8-)24A7-5(26A6-)26A7-2(24A8-)24A9-22A11-20A12-20A13-18A16-14A19-12A23-6A188-2A26-10A20-14A16-18A13-20A11-22A10-22A9-24A8-24A7-3(26A6-)26A5-28A4-28A5-3(26A6-)26A7-24A8-24A9-22A10-22A11-20A13-18A16-14A20-10A26-2A155-8A21-14A17-16A15-18A13-20A11-22A9-24A7-2(26A6-)26A5-7(28A4-)28A5-2(26A6-)26A7-24A9-22A11-20A13-18A15-16A17-14A21-8A122-4A24-12A18-16A15-18A13-20A11-22A9-24A7-26A6-26A5-3(28A4-)28A3-3(30A2-)30A3-3(28A4-)28A5-26A6-26A7-24A9-22A11-20A13-18A15-16A18-12A118-8A21-14A17-16A14-20A11-22A9-24A8-24A7-26A5-2(28A4-)28A3-7(30A2-)30A3-2(28A4-)28A5-26A7-24A8-24A9-22A11-20A14-16A17-14A116-10A20-14A16-18A13-20A11-22A9-24A7-26A6-26A5-28A4-28A3-9(30A2-)30A3-28A4-28A5-26A6-26A7-24A9-22A11-20A13-18A16-14A87-4A24-12A18-16A15-18A12-22A9-24A8-24A7-26A5-28A4-28A3-11(30A2-)30A3-28A4-28A5-26A7-24A8-24A9-22A12-18A15-16A85-6A23-12A18-16A14-20A11-22A9-24A7-26A6-26A5-28A4-28A3-11(30A2-)30A3-28A4-28A5-26A6-26A7-24A9-22A11-20A14-16A22-5B27-5B25-8A21-14A17-16A14-20A11-22A9-24A7-26A6-26A5-28A3-2(30A2-)30A-31A2(-B30AB-2(30A2-)30A)2(2-30A)3-28A5-26A6-26A7-24A9-22A11-20A14-16A84-8A21-14A16-18A13-20A11-22A9-24A7-26A5-28A4-28A3-2(30A2-)30A-31A3(-B30AB-30A)4(2-30A)3-28A4-28A5-26A7-24A9-22A11-20A13-18A22-3B29-3B26-8A21-14A16-18A13-20A11-22A9-24A7-26A5-28A4-28A3-2(30A2-)30A-31A3(-B30AB-30A)4(2-30A)3-28A4-28A5-26A7-24A9-22A11-20A13-18A83-8A21-14A17-16A14-20A11-22A9-24A7-26A6-26A5-28A3-2(30A2-)30A-31A2(-B30AB-2(30A2-)30A)2(2-30A)3-28A5-26A6-26A7-24A9-22A11-20A14-16A22-5B27-5B26-6A23-12A18-16A14-20A11-22A9-24A7-26A6-26A5-28A4-28A3-11(30A2-)30A3-28A4-28A5-26A6-26A7-24A9-22A11-20A14-16A86-4A24-12A18-16A15-18A12-22A9-24A8-24A7-26A5-28A4-28A3-11(30A2-)30A3-28A4-28A5-26A7-24A8-24A9-22A12-18A15-16A115-10A20-14A16-18A13-20A11-22A9-24A7-26A6-26A5-28A4-28A3-9(30A2-)30A3-28A4-28A5-26A6-26A7-24A9-22A11-20A13-18A16-14A117-8A21-14A17-16A14-20A11-22A9-24A8-24A7-26A5-2(28A4-)28A3-7(30A2-)30A3-2(28A4-)28A5-26A7-24A8-24A9-22A11-20A14-16A17-14A119-4A24-12A18-16A15-18A13-20A11-22A9-24A7-26A6-26A5-3(28A4-)28A3-3(30A2-)30A3-3(28A4-)28A5-26A6-26A7-24A9-22A11-20A13-18A15-16A18-12A150-8A21-14A17-16A15-18A13-20A11-A4BAB2ABAB3ABA4BA9-2(2AB)AB2ABAB2A2BA2(B2A)7-3ABA2BA4B4(AB)A2B3A6-3AB4AB2ABA2B2ABAB6A6-3A2(4BA)B3ABA4B3A5-7(28A4-)28A5-2(26A6-)26A7-24A9-22A11-20A13-18A15-16A17-14A21-8A155-2A26-10A20-14A16-18A13-20A11-A4-A-2A-A-3A-A4-A10-2(A-2A-)A-2A2-A-2A-A9-2A-A2-A4-4(A-)A2-2A8-2A-4A-2A-A2-2A-A-5A7-3A2(4-A)-3A-A4-3A3(6-26A)5-11A6B11A4-28A5-26A6-3A4C4A4B4A4C3A6-2AC4DC10AC4DC2A6-2ACD2BDC10ACD2BDC2A7-ACD2BDC2A6B2ACD2BDCA8-AC4DC10AC4DCA9-A4C12A4CA10-22A11-20A13-18A16-14A20-10A26-2A572-6B83-4C4-4B4-4C11-2(C4DC10-)2(CD2BDC10-)CD2BDC2-6B2-CD2BD2(C10-C4D)C11-4C12-4C755-6B91-4B91-6B333-
