model
size = 27 30 19, scale = 0.05, origin = -y
material 
  colors = A:#888 B:#555 C:#AAA D:#DDD E:#111 F:#F9C G:#444 H:#996 I:#F66 J:#C03 K:#EEE
voxels
524-G53-G755-G53-G611-3B4-3B17-3A4-3A17-3A4C3A17-10A2(17-9AF)7(17-10A)3(23-4A)395-3B4-3B17-3A4-3A17-3A4C3A17-10A2(17-9AF)2(17-10A)17-9AD17-7A2E2(D17-9A)D17-10A2(23-3AB)23-4A395-3B4-3B17-3A4-3A17-3A4C3A5(17-10A)3(17-9AH)17-9AD17-10A2(23-3AB)23-4A395-3B4-3B17-3A4-3A17-3A4C3A5(17-10A)2(17-9AE)17-9AK17-9AD17-10A2(23-3AB)23-4A395-3B4-3B17-3A4-3A17-3A4C3A3(17-10A)2(D16-10A)D16-3(9AE17-)9AD17-10A3(23-4A)449-10C3(17-10A)3(D16-10A)4(17-10A)528-2B10C15-2B9AJ2(15-2B10A)D2(14-2B10AI)14-5(2B10A15-)2B25-7B20-7B452-2B10C15-2B9AJ3(15-2B10A)2(I14-2B10A)4(15-2B10A)15-2B25-7B20-7B452-2B10C15-2B9AJ2(15-2B10A)D2(14-2B10AI)14-5(2B10A15-)2B25-7B20-7B454-10C3(17-10A)3(D16-10A)4(17-10A)476-3B4-3B17-3A4-3A17-3A4C3A3(17-10A)2(D16-10A)D16-9AD17-9AK2(17-9AD)17-10A3(23-4A)395-3B4-3B17-3A4-3A17-3A4C3A5(17-10A)3(17-9AH)17-9AD17-10A2(23-3AB)23-4A395-3B4-3B17-3A4-3A17-3A4C3A5(17-10A)2(17-9AE)17-9AK17-9AD17-10A2(23-3AB)23-4A395-3B4-3B17-3A4-3A17-3A4C3A17-10A2(17-9AF)2(17-10A)17-9AE17-7A3E17-9AE17-9AD17-10A2(23-3AB)23-4A41-12(B25-)B21-5B15-3B4-3B17-3A4-3A17-3A4C3A17-10A2(17-9AF)7(17-10A)3(23-4A)539-G53-G755-G53-G231-
