model
size = 30 6 10, scale = 0.05, origin = -y
material 
  colors = A:#111 B:#EEE C:#222 D:#00E E:#444 F:#777
voxels
5-22C307-22C11-D14-D13-D-D12-D-D13-D14-D41-22B6-2C22A2C39-F14-F69-8BD3B2D12B3-C26AC38-2(F14-)E14-E38-5B3E2B2(2D3B)3E5B-C5ABAB12ABAB5AC67-3(E14-)E8-5BEBE4B2D3B2D2(BE)5B-C28AC67-3(E14-)E8-5B2(EB)2D3B2D4BEBE5B-C28AC37-2(F14-)E14-E38-5B3E2(3B2D)2B3E5B-C5ABAB12ABAB5AC37-F14-F69-12B2D3BD8B3-C26AC8-D14-D13-D-D12-D-D13-D14-D41-22B6-2C22A2C2-
