model
size = 32, scale = 0.05, origin = -y
material 
  colors = A:#800 B:#BBB C:#AAA D:#0B0 E:#EEE F:#001
voxels
176-B220-B4-B29-B85-2(B18-)B6-B124-B26-B8-C475-B188-B4-B28-B86-B18-B11-3(B6-)B144-C8-C27-B255-C114-C8-B6-B8-C115-B156-B4-B19-2B16-2B21-B55-B16-B19-B6-B151-B4-B3-B120-B4-C125-B179-B7-B6-B7-B116-B124-B4-B21-B14-B55-B24-B14-B11-B8-B6-B8-B115-B21-C4-B8-B4-C83-B4-B125-B244-3(B6-)B101-C15-B92-B4-B22-B12-B23-3A28-5A23-B3-5A4-B13-B7-B5A-B7-B17-5A28-3A31-B22-B16-B18-B8-B56-B4-B114-B10-B9-C299-B5-B6-B5-B102-B15-B14-B45-6A24-B9A22-3A3-4A22-2A5-3A21-3A5-3AB15-B4-2A6-A-A5-B15-3A5-3A22-3A3-4A19-B3-8A3-B21-6A24-B2-3A3-B24-A4-A114-B10-B9-B364-B4-B6-B4-B86-2A16-B11-6A11-B11-3A6-2A21-A9-A20-2(2A10-A19-)A12-A15-B2-A11-2A2-B15-A11-A19-2A10-AB19-2A8-A21-3A6-2A22-3A3-4A24-6A51-B18-B11-B10-B9-B57-C252-B78-B30-C8-B3-B6-B3-B21-5A26-3A2-3A22-3A6-2A13-B6-A11-A7-B11-A11-2A18-A12-A17-A13-2A16-A14-A15-BA14-AB15-A13-2A16-A14-A17-A11-2A18-A11-A19-2A10-A14-B2(5-3A)14-B2-B6-5A7-B22-B67-B120-C4-B189-B80-C9-10A9-B10-B3A5-3A-B18-3A8-3A18-A11-2A16-2A13-3A10-B3-2A14-2A3-B9-3A14-2A2(13-2A16-A)13-A17-2(A13-2A16-)A3(14-2A)13-3A11-B2-BA13-3A13-2B-A11-2A-B17-3A5-3A22-10A24-6A-B120-B4-B252-B29-5A24-3A5-3A13-B6-A11-2A6-B10-A14-A16-2(A14-)2A16-A13-A17-A11-B-A17-A2-B9-4(A19-A11-)2A18-A11-A-A16-A12-BA17-A14-A16-A15-A14-A29-A20-A9-A22-2A5-3A24-5A59-B4-B92-B191-2A27-3A2-3A21-3A8-3A17-A14-A11-B3-A16-A3-B10-A16-A13-A17-A12-3(A19-A11-)A20-A5-5B21-A4BC5-2(A19-A11-)AB2(17-A13-A)17-A14-A16-A15-A14-A29-A20-2A8-A23-A-6A25-B4-B53-B14-B23-B7-B158-B30-B23-6A-B21-3A6-2A20-A11-2A17-A14-A15-A16-A11-B-A17-A2-B9-2(A19-A11-)6(A20-A10-)2(A19-A11-)A19-A12-2A16-A15-A14-A17-A12-A18-A11-A20-11A52-B12-B24-B67-B25-4(B4-B26-)6A23-3A6-2A20-A11-A17-2A13-3A13-2A16-A13-A17-A12-A19-A11-A20-A10-A20-A9-6(A22-A8-)B21-A8-B-A20-A7-B2-A27-B3-A19-A6-B5-2A16-A2(14-2A)15-A13-2A17-A-2A6-2AB20-B2-6A2-B25-B58-B8-B109-C28-C3-B26-B5-B8-8A8-B7-B5-2A8-A6-B9-B3-A11-2A3-B11-B2A14-2AB12-A17-A12-2(A19-A11-)A20-A9-A22-A8-A22-A4-4B5(A22-A8-)A22-A9-A20-A10-A21-E9-A20-2E10-A18-2A12-A16-A15-A14-A17-3A8-3A21-8A55-B7-B186-3A26-3A3-4A20-2A10-A19-A12-A15-3A14-2A13-A17-A12-A19-A11-A20-A9-3(A22-A8-)A22-A7-2(A24-A6-)A24-A7-2(A22-A8-)A22-A9-A21-E9-A21-2F9-A18-3E10-A17-A10-C3B2A14-2A16-2A10-2A20-3A3-4A23-B-3A2-B114-3(B32-)B3-5A24-B2A5-3A20-2A10-A18-A13-2A14-2A16-A12-2(A19-A11-)A20-A9-2(A22-A8-)A22-A7-A24-A6-2(A24-2D5-)A25-D5-A24-A7-A22-A8-A22-A2(9-A21-E)9-A19-2A11-A17-A14-A16-A15-A-A10-A-A17-B-2A5-3A-B17-B4-5A5-B15-B16-B13-B18-B11-C20-C114-6A23-3A6-2A20-A11-2A17-2(A14-)2A16-A7-B4-A19-A7-B3-A20-A7-B2-A20-A8-B2(A22-A8-)A23-A6-A24-2D5-A30-BA29-B-A24-2D2-C2-A24-A7-2(A22-A8-)A22-A9-A20-A10-A19-A12-A17-A14-A16-A15-2A11-3A18-3A5-3A24-2A-2A29-B31-C60-2(B32-)B30-6A23-3A6-2A20-A11-2A17-2(A14-)2A16-A12-A19-A11-A20-A10-A20-A9-2(A22-A8-)A23-A6-A24-2D5-2(A31-)A24-2D5-A24-A7-A22-A8-A22-A7-BA22-A6-B2-A20-A6-B3-A19-A6-C5-A17-A14-A16-A15-2A8-A2-3A18-3A4-AB2A24-5A3(B32-)C35-2(B30-)B21-5A4-B19-3A5-3AB19-A11-A18-A13-2A14-2A16-A12-A19-A10-BA19-A11-A20-A9-2(A22-A8-)A23-A6-A24-2D5-2(A31-)A24-2D5-A24-A7-2(A22-A8-)A22-A9-A20-A10-A19-A12-A17-A14-A16-A15-A12-A-A17-B3A5-3A-B17-B2-B-5A5-B15-B2-2(B13-)B2-B15-B11-C2-B17-B115-3A26-3A3-4A20-2A10-A18-A13-2A14-2A16-A12-A19-A9-B-A19-A11-A20-A9-2(A22-A8-)A22-A6-2BA23-A3-B2-A24-2D3-B-A24-2D4-BA24-2D6-A22-2A7-A22-A8-A22-A2(9-A21-E)9-A19-2A11-A17-A10-4BA16-A15-3A10-3A19-3A3-4A25-3A176-C28-C3-B26-B5-B8-8A8-B7-B5-2A8-A6-B9-B3-A11-2A3-B11-B2A14-2AB12-A17-A9-B2-2(A19-A11-)A20-A9-3(A22-A8-)3(A22-2A7-)A22-A8-A22-A9-A20-A10-A21-E9-A21-2F9-A18-3E11-A16-A15-A14-A18-2A8-3A21-8A29-B123-3(B4-B26-)B4-B23-B2-6A23-3A6-2A20-A11-A17-2A13-3A13-A17-A8-B4-A17-A12-A19-A11-A20-A10-A20-A9-6(A22-A8-)B21-A8-B-A20-A7-B2-A20-2E5-B3-A20-2E4-B5-A18-2A12-A16-A15-A13-2A19-2A6-3A20-B2-6A2-A59-B184-B35-3A26-3A3-4A20-2A10-A18-A13-2A15-A16-A7-B5-A17-A11-BA19-A-B9-3(A20-A10-)A20-A9-2(A22-A8-)A22-A9-3(A20-A10-)A19-A11-2A18-A13-A16-A15-A14-A30-A19-B3A3-5A24-3A24-B12-B58-B120-B98-6A23-3A5-3A20-A11-2A17-A14-A11-B3-A16-A3-B9-2A16-A12-2(A19-A11-)A19-2A2(10-A20-A)5-5B21-A5B5-2(A20-A10-)AB19-A10-A19-A11-2A18-A12-2A16-A15-A14-A29-2AB18-A10-A2-B17-3A-7A4-B19-B4-B7-B32-B12-B14-B4-C10-C15-C25-B56-B162-5A24-3A5-3A13-B6-A11-2A6-B10-A14-A15-B2(A14-)2A16-A13-A17-A11-B-A17-A2-B9-4(A19-A11-)2A18-A13-A16-A12-BA17-A14-A16-A15-A14-A29-2A19-A9-A22-2A5-3A24-5A59-B4-B119-B214-B9-10A9-B10-BA9-A-B18-A11-2A15-B2-A12-A16-2A14-2A10-B3-A16-A3-B9-5(A17-A13-)A17-2(A14-A16-)A11-B2-BA14-2A2-B10-2B-A11-2A-2A16-A9-A22-2A6-2A23-B6A24-B30-B66-B4-B269-B30-C8-B3-B6AB3-B19-2A5-3A21-2A8-A16-B3-A11-A12-B5-A13-2A5-B10-A14-A15-2(2A14-)4(A16-A14-)A16-A15-A14-A16-A13-2A17-A12-A13-B4-2A10-A5-B7-B2-B4-2A2-2A-3A4-A2-B16-6A-B184-B4-C244-B4-B6-B4-B52-5A26-8A13-B2-B5-11A9-B10-4A6-3A19-2A10-2A18-2A10-2A17-3A10-3A16-2A12-2A14-B-2A11-3A-B14-2A11-3A16-3A10-3A17-3A8-3A18-4A6-3A19-2A-2A3-3A-A20-3A-7A24-2A2-A20-B9-B8-A11-B14-B5-B363-B5-B6-B5-B86-B15-C30-C3-B41-6A24-B8AB22-3A3-4A22-2A5-3A21-3A6-2AB15-B4-2A8-A5-B15-3A6-2A22-2A-A3-3A19-B3-8A3-B21-6A24-B2-3A3-B24-A4-A93-B20-B14-B5-B298-3(B6-)B85-B81-C39-B2-B4-B22-B12-B23-3A28-5A23-B3-6A3-B13-B7-B6AB7-B17-6A26-A-3A53-B16-B18-B8-B56-B4-B93-B20-B14-B5-B233-B7-B6-B7-B84-B120-B35-B4-B21-B14-B56-B23-B14-B11-C8-B6-B8-B51-B85-B4-B8-B4-B83-B4-B129-B174-C8-C6-B8-B83-B188-B4-B19-2B16-B23-B54-B16-B19-B6-B92-B58-B8-C120-B4-C129-C75-
