model
size = 29 28 5, scale = 0.05, origin = -y
material 
  colors = A:#FF0 B:#111 C:#FC0 D:#FF3 E:#FF6
voxels
5-B17-B10-2B15-2B10-BA2B11-2BAB10-B3AB9-B3AB11-BD2AB7-BADAB12-B4A2B3-2BA2DAB13-BA2E2A3B3ACAB14-BAEB7ABEAB14-B3ABA3BAB3AB15-BADA2(B3A)B14-2B2AD3ACAC4A2B11-B7A2D2(2AE)2AB9-B3AE4AC6A2D2AB7-B5A3B2AD2E3B5AB6-BACD3(AB)3A3(BA)2EAB5-B2A2E7AD6A2CD2AB3-BACD2A2E3BAE2AC3B7AB-10BA2E2AD2CA10B10-B2ECAECAB20-B7AB21-BADCADB22-B2AD2AB23-BADAB24-B2EAB25-BAB26-BAB27-B28-B18-C2A15-3A8-4AC11-C3AE8-6A9-2C3AE8-C6A7-3C4A9-8A3-5C3A10-8AC10A11-17A12-16AE12-C16A12-16AC11-19A9-21A7-22AC5-24AE4-C23AE3-27A-28AC29ACAC4AC11AEA5CAEA10-9A20-8AE21-6AC22-6AC23-5A24-5A25-3A26-3A27-C18-3B15-3B8-5B11-5B8-6B9-6B8-7B7-7B9-8B3-8B10-19B11-3(B15AB12-)B15AB11-2B15A2B9-2B16A3B7-3B16A4B5-4B16A5B4-4B16A5B3-5B16A6B-2B20A9B20A21B4A11B10-4B4AB20-4B4AB21-7B22-7B23-5B24-5B25-3B26-3B27-B18-3A15-3A8-3ACA11-C4A8-C5A9-5AC8-C6A7-7A9-7AC3-AC6A10-18AC11-17A12-C16A12-C15AC12-C15AD11-19A9-C19AC7-23A5-25A4-C23AC3-27A-59ACD2CDAEC10ADACADCDACA10-9A20-9A21-7A22-C6A23-5A24-D3AC25-3A26-DAC27-A19-B17-B10-2B15-2B10-BA2B11-2BAB10-B3AB9-B2ADB11-BACAB7-B2ADB12-B2ADA2B3-2B4AB13-BCE3A3B2AC2AB14-B4AC7ACB14-BAD3A3B5AB15-3(B3A)B14-2B3AD5ACA2E2B11-B2AC2AEADACA2D4AB9-B8AE6AD3AB7-B2AC2A3B2AD2A3B2AC2AB6-B2E2A2(BA)B3A2(BA)B2AEAB5-BA2EC2AD9A2DACADAB3-B6AEA2BACADBA2B7AB-10B9A10B10-B2DADEACB20-B4AD2AB21-B2C3AB22-B2CACAB23-B3AB24-BADAB25-BAB26-BAB27-B28-B14-
