model
size = 22 30 5, scale = 0.05, origin = -y
material 
  colors = A:#200505 B:#372F7C C:#2F6ED4 D:#309 E:#2A6A9C F:#6868FF G:#545759 H:#2C0D09
voxels
23B20C2BC5E3C10EC2B20C24B20C2BC8E7C3EC2BCE6CE11C2BC8E3C7EC2BCE6CE11C2BCE6CE4C6EC2BCE6CE11C2BC8E3C7EC2BCE6CE11C2BC8E2C8EC2B20C24B8C13GB8C3G10-B2C6E3G10-B8C2G11-B2C5E2(3G11-B7C)2G12-B6C3G12-B4C2E2G13-B6C2G13-B2C4E2G13-B5C2G14-5B2G15-B20CBC16(20A2C)4B16AG7(C4B16A-)4(C4B10A7-)B4CG16-BC5E8C5ECBC20ACE2(20A2E)20AEC4(20A2C)20ACE7(20A2E)4B16AG5(E4B16A-)C2(4B16A-E)4B10A7-E2(4B10A7-C)4B10A7-BC3EG16-B20CBC2(20B2(2CB5AB6AB5AB)2C)B5AB6AB5AB2(2C20B3(2CB5AB6AB5AB))2C19BG2C4B2AB6AG5A-GC4B2AB6A-5A2-C4B2AB2A4H-5H2-C8B13-C4B2ABA5H-5H2-C4B2AB6A-5A2-C4B2AB6H-5H2-C6BG14-C4B2A-6H8-C4B2A-6A8-C4B2A-6H8-C4BG16-B4CG16-23B20C2BC17DFC2BC2D4F4D4F2DFDC2BCD2(F4DF2D)FC2BCDF4DF2DF4D2(FD)C2BCD2(F4DF2D)FC2BC16DFDC2BC4D3F3D5F2DFC2BCF3DF7DF3DFDC2BCDF10D3F2DFC2BCF3D3FDF7DFDC2BCDF4DFDF3D3F2DFC2BCF3D5F3D3(FD)C2BCDF10D3F2DFC2BCF3D5F7DFDC2BCDF2DFDF5D3F2DFC2BCF3D3F13GBCDF5DG12-BCF4DF2G12-BCDF2D2FG13-BCF4DFG13-BCDF3D2G13-BCF4DG14-BCDF2D2G14-BCF3DG15-BCDF2DG15-BCF2D2G15-B4CG16-5BG16-
