model
size = 22 30 5, scale = 0.05, origin = -y
material 
  colors = A:#200505 B:#372F7C C:#2F6ED4 D:#309 E:#2A6A9C F:#D4AF37 G:#6868FF H:#545759 I:#2C0D09
voxels
23B20C2BC5E3C10EC2B20C24B20C2BC8E7C3EC2BCE6CE11C2BC8E3C7EC2BCE6CE11C2BCE6CE4C6EC2BCE6CE11C2BC8E3C7EC2BCE6CE11C2BC8E2C8EC2B20C24B8C13HB8C3H10-B2C6E3H10-B8C2H11-B2C5E2(3H11-B7C)2H12-B6C3H12-B4C2E2H13-B6C2H13-B2C4E2H13-B5C2H14-5B2H15-B20CBC16(20A2C)4B16AH2(C4B7A9F-)3(C4B6A10F-)2(C4B5A11F-)3(C4B3A13F-)C4BA15F-B4CH16-BC5E8C5ECBC20ACE2(20A2E)20AEC4(20A2C)20ACE7(20A2E)4B16AH5(E4B16A-)C2(4B16A-E)4B10A7-E2(4B10A7-C)4B10A7-BC3EH16-B20CBC2(20B2(2CB5AB6AB5AB)2C)B5AB6AB5AB2(2C20B3(2CB5AB6AB5AB))2C19BH2C4B2AB6AH5A-HC4B2AB6A-5A2-C4B2AB2A4I-5I2-C8B13-C4B2ABA5I-5I2-C4B2AB6A-5A2-C4B2AB6I-5I2-C6BH14-C4B2A-6I8-C4B2A-6A8-C4B2A-6I8-C4BH16-B4CH16-23B20C2BC17DGC2BC2D4G4D4G2DGDC2BCD2(G4DG2D)GC2BCDG4DG2DG4D2(GD)C2BCD2(G4DG2D)GC2BC16DGDC2BC4D3G3D5G2DGC2BCG3DG7DG3DGDC2BCDG10D3G2DGC2BCG3D3GDG7DGDC2BCDG4DGDG3D3G2DGC2BCG3D5G3D3(GD)C2BCDG10D3G2DGC2BCG3D5G7DGDC2BCDG2DGDG5D3G2DGC2BCG3D3G13HBCDG5DH12-BCG4DG2H12-BCDG2D2GH13-BCG4DGH13-BCDG3D2H13-BCG4DH14-BCDG2D2H14-BCG3DH15-BCDG2DH15-BCG2D2H15-B4CH16-5BH16-
