model
size = 32 4 32, scale = 0.05, origin = -y
material 
  colors = A:#EEE B:#AAA C:#BBB D:#C60 E:#555
voxels
-288B4(2(30A2B)30A34B)2(30A2B)10ADA2D2AD13A34B2(30A2B)9AD7AD12A34B2(30A2B)20A3D7A34B2(30A2B)3A4BDB12A2CD3C3A34B2(30A2B)3A4BDB7A2D3A2CD3C3A34B2(30A2B)3A2BD3BD11A6C3A34B2(30A2B)3ABD4B12A6C3A34B2(30A2B)3A3BD2B12A6C3A34B2(30A2B)3A2BD3B12A2CD3C2(3A34B2(30A2B)3A5ED12A6B)3A34B2(30A2B)3A6E10ADA6B3A34B2(30A2B)3A2ED3E10ADABD4B3A34B2(30A2B)3A2ED3ED11ABD4B3A34B2(30A2B)3A2ED3E12AD5B3A34B2(30A2B)9AED4E2CD3CD8A34B2(30A2B)9A2EDE2D6C9A34B2(30A2B)7ADA6E3CDCD2A2D5A34B2(30A2B)7ADA6E2CD3C3A3D3A34B2(30A2B)9A6ECD4C3A3D3A34B2(30A2B)9A2D2E2D6C4ADAD2A34B2(30A2B)27AD2A34B2(30A2B)26AD3A34B2(30A2B)27AD2A2(34B2(30A2B)30A)B
