model
size = 31 26 31, scale = 0.05, origin = -y
material 
  colors = A:#0FF B:#03F C:#F0C D:#009 E:#FF0 F:#0E0 G:#3CC
voxels
323-5D25-D5-D26-DCD28-DCD26-D5-D25-5D614-7B21-D2-B5DB-2D19-3D5B2D23-2B3D2B2-C21-2B3D2B2-C19-3D5B2D20-D2-B5DB-2D21-7B24-7E516-F3B7-3BF17-3B7-3B16-3D2B7-B3D17-B2D7-D2B-D15-C3B7-2BC17-C3B7-2BC18-B2D7-D2B-D14-3D2B7-B3D17-3B7-3B18-3E7A3E21-7A24-7C24-3C-3C391-2(2B13-)2(FBF13-)2(2B13-)3D13-DB13-D2B13-B2D13-BC13-2B14-BC13-2B13-D2B13-B2D12-3D13-DB14-2BG12-2B15-E3A7-3AE17-3A7-3A19-2C7A2C20-2C7A2C22-3C-3C24-3C-3C297-B17-B11-FB17-BF10-2F17-2F2(11-B17-B12-B17-B11-2D17-2D)11-B17-B12-BG15-GB12-2EA13-A2E13-E2A11-2AE16-C2A7-2AC18-C2A7-2AC19-2C7A2C20-2C7A2C22-3C-3C254-B9-2(F-B18-BF8-)F-B18-BF10-B18-B9-D-B18-BD9-2D18-2D10-B18-B11-B18-B10-2D18-2D8-D-B18-BD10-B18-B10-E2A15-2AE11-2A15-2A13-E2A11-2AE14-E2A11-2AE16-C2A7-2AC18-C11AC19-5C-5C200-B21-B7-F2B20-BF3(6-2FB20-2F)7-2B20-B7-2DB20-2D7-BD20-B7-C2B20-BC6-C2B20-BC7-BD20-B7-2DB20-2D7-2B20-B8-EA19-AE9-2A17-2A12-2(A15-A14-)E2A11-2AE14-E4A7-4AE16-3C7A3C21-7C139-6(B23-B6-)B23-B5-2D23-2D5-3(B23-B6-)B23-B5-2D23-2D5-BG21-GB7-EA19-AE9-A19-A2(10-EA17-AE)12-A15-A14-3A11-3A14-E-C11AC-E18-4C-4C138-B23-B5-4(2F23-2F4-)2F23-2F5-B23-B5-2D23-2D4-DB23-BD5-B23-B6-B23-B5-DB23-BD4-2D23-2D5-B23-B6-EA21-AE7-A21-A2(8-EA19-AE)9-EA17-AE11-3A13-3A12-E2-13A2-E15-C2(-4C)-C104-8(B25-B4-)2(B25-B3-2D25-2D3-B25-B4-)B25-B4-EA23-AE5-2A21-2A7-EA19-AE8-EA19-AE9-EA17-AE11-2A15-2A12-E-15A-E14-3C4(-C)-3C103-B25-B3-6(2F25-2F2-)2F25-2F3-2(B25-B3-2D25-2D3-B25-B4-)B25-B4-EA23-AE5-A23-A2(6-EA21-AE)7-EA19-AE9-2A17-2A11-E17AE14-3C-7C-3C103-8(B25-B4-)2(B25-B3-2D25-2D3-B25-B4-)B25-B4-EA23-AE5-A23-A2(6-EA21-AE)7-EA19-AE9-2A17-2A11-E6A5-6AE14-5C5A5C21-2C-2C324-2D25-2D64-B27-B2-B27-B-2D27-2D-B27-B2-EA25-AE3-A25-A2(4-EA23-AE)5-EA21-AE7-2A19-2A9-E6A7-6AE12-3C-C7AC-3C20-5C417-B27-B2-B27-B-2D27-2D-B27-B2-EA25-AE3-A25-A2(4-EA23-AE)5-EA21-AE7-2A19-2A9-E5A9-5AE12-4C9A4C18-4C-4C415-B27-B2-B27-B-2D27-2D-B27-B2-EA25-AE3-A25-A2(4-EA23-AE)5-EA21-AE6-E2A19-2A9-E5A9-5AE12-4C9A4C18-3C3-3C415-B27-B-2D27-2D-2(B27-B2-)EA25-AE3-A25-A2(4-EA23-AE)5-EA21-AE6-E2A19-2A9-E5A9-5AE12-C2-C9AC2-C19-C5-C416-B27-B-2D27-2D-2(B27-B2-)EA25-AE3-A25-A2(4-EA23-AE)5-EA21-AE6-E2A19-2A9-E5A9-5AE12-4C9A4C18-3C3-3C415-B27-B-2D27-2D-2(B27-B2-)EA25-AE3-A25-A2(4-EA23-AE)5-EA21-AE7-2A19-2A9-E5A9-5AE12-4C9A4C18-4C-4C353-2D25-2D33-B27-B2-B27-B-2D27-2D-B27-B2-EA25-AE3-A25-A2(4-EA23-AE)5-EA21-AE7-2A19-2A9-E6A7-6AE12-3C-C7AC-3C20-5C46-8(B25-B4-)B25-B3-2D25-2D3-B25-B3-2C25-2C2-2C25-2C3-B25-B3-2D25-2D3-B25-B4-EA23-AE5-A23-A2(6-EA21-AE)7-EA19-AE9-2A17-2A11-E6A5-6AE14-5C5A5C21-2C-2C46-2(B25-B4-)B25-B3-3(2F25-2F2-)2F25-2F3-B25-B4-B25-B3-2D25-2D3-3(B25-B4-)B25-B3-2D25-2D3-B25-B4-EA23-AE5-A23-A2(6-EA21-AE)7-EA19-AE9-2A17-2A11-E17AE14-3C-7C-3C72-B25-B4-B25-B3-5(2F25-2F2-)2F25-2F2(3-B25-B4-B25-B3-2D25-2D)3-2(B25-B4-)EA23-AE5-2A21-2A7-EA19-AE8-EA19-AE10-A17-A12-2A15-2A12-E-15A-E14-3C4(-C)-3C42-B23-B6-B23-B5-7(2F23-2F4-)2F23-2F5-2(B23-B5-2D23-2D5-B23-B6-)B23-B6-EA21-AE7-A21-A2(8-EA19-AE)10-A17-A12-3A13-3A12-E-C13AC-E15-C-2C2(-C)-2C-C43-10(B23-B6-)2(B23-B5-2D23-2D5-B23-B6-)BG21-GB7-EA19-AE9-A19-A2(10-EA17-AE)12-A15-A13-E3A11-3AE14-2C11A2C19-C-5C-C386-D23-D38-B21-B7-DB21-B7-2D21-2D7-B21-B8-EA19-AE9-2A17-2A12-2(A15-A14-)E2A11-2AE14-E4A7-4AE16-3C7A3C22-2C-2C452-B19-B10-B19-B9-2D19-2D9-B19-B10-E2A15-2AE11-2A15-2A13-E2A11-2AE14-E2A11-2AE16-C2A7-2AC18-C11AC19-C2(-3C)-C481-B17-B12-B17-B11-2D17-2D11-BG15-GB12-2EA13-A2E13-E2A11-2AE16-C2A7-2AC18-C2A7-2AC20-C7AC21-C-7A-C22-3(C-)C484-2(2B13-)3D13-3D12-D2B13-2BD2(13-2B)15-E3A7-3AE17-3A7-3A19-2C7A2C21-C7AC24-2C-2C25-3(C-)C517-3B7-3B16-3D2B7-2B3D16-2(3B7-3B18-)3E7A3E21-7A24-7C25-2C-2C581-2D7B2D19-2DC7BC2D19-DC7BCD21-D7BD23-7E677-3D26-2(D-DCD-D24-)D-3D-D291-
