model
size = 23 8 18, scale = 0.05, origin = -y
material 
  colors = A:#000 B:#2609BB C:#A93AF6 D:#7A1FF5 E:#510BDF F:#BE4FF7 G:#0B0894 H:#CB73F9
voxels
2-2(9A3-9A-)2AHF2CDEBA3-AHF2CDEB3AH2FC2DEB2A-2A2FC2DEBG2AHF2CD2EBGA-AHF2CD2EBG2AHFC2DE2BGA-AHFC2DE2BG2AHFCD2EB2GA-AHFCD2EB2G3AFCDE2BG2AB2AFCDE2BG2A92-B2(21-2B3(21-B161-B))10(21-B161-B)21-B23-
