model
size = 23 8 18, scale = 0.05, origin = -y
material 
  colors = A:#000 B:#F85D00 C:#F88C18 D:#F15E05 E:#F14805 F:#F12C05 G:#F8B524 H:#F10505 I:#FAC75A
voxels
2-2(9A3-9A-)2AIG2CDEFA3-AIG2CDEF3AI2GC2DEF2A-2A2GC2DEFH2AIG2CD2EFHA-AIG2CD2EFH2AIGC2DE2FHA-AIGC2DE2FH2AIGCD2EF2HA-AIGCD2EF2H3AGCDE2FH2AB2AGCDE2FH2A92-B2(21-2B3(21-B161-B))10(21-B161-B)21-B23-
