model
size = 10 8 5, scale = 0.05, origin = -y
material 
  colors = A:#FC0 B:#500 C:#FFF D:#400 E:#30F F:#009 G:#001
voxels
3-BD-BD7-2A8-2A15-A9-2A29-2B2A6-C4A5-C4A3-C5A4-4A6-FE2A7-2A20-6A4-4A-A2-C5A-A-C5A-2A2G4A2-A2-5A2-2A2-3A4-A3-A9-2B2A6-C4A5-C4A3-C5A4-4A6-FE2A7-2A19-BD-BD7-2A8-2A15-A9-2A26-
