model
size = 31, scale = 0.05, origin = -y
material 
  colors = A:#36C B:#E00 C:#010 D:#EEE E:#B00 F:#C90 G:#CF3 H:#DDD
voxels
385-5B25-7B24-7B23-9D23-7A24-7A25-5A677-5B24-9B21-11B20-3B5A3B19-3B7A3B18-3B7A3B17-4D7A4D17-13A18-13A19-11A20-11A21-9A24-5A522-5B24-9B21-3B5A3B19-2B9A2B17-2B11A2B16-2B11A2B15-2B13A2B14-2B13A2B13-3D13A2D2(14-17A)15-15A16-15A17-13A19-11A21-9A24-5A428-7B22-3B5A3B19-2B9A2B17-2B11A2B15-2B13A2B14-B15AB13-2B15A2B2(12-B17AB)11-2D17AD3(12-19A)13-17A14-17A15-15A17-13A19-11A22-7A362-13D18-3B7A3B17-2B11A2B15-2B13A2B13-2B15A2B12-B17AB11-2B17A2B3(10-B19AB)9-2D19AD4(10-21A)11-19A12-19A13-17A15-15A17-13A18-13D299-9A20-13A16-2D13A2D14-B15AB13-B17AB11-B19AB10-B19AB9-3(B21AB8-)B21AB7-2D21AD4(8-23A)9-21A10-21A11-19A13-17A14-2D13A2D16-2B9A2B20-9B240-7A21-13A17-15A15-17A12-2D17A2D10-B19AB9-2(B21AB8-)B21AB7-2(B23AB6-)B23AB5-2D23AD3(6-25A)7-2(23A8-)23A9-21A10-2D17A2D12-B15AB15-B13AB17-3B7A3B21-7B180-5A23-11A18-15A15-17A13-19A11-21A9-D21AD8-B21AB7-2(B23AB6-)B23AB5-2(B25AB4-)D25AD2(4-27A)5-2(25A6-)25A7-23A8-D21AD9-B19AB11-B17AB13-B15AB15-2B11A2B18-3B5A3B23-5B148-9A20-13A16-17A13-19A11-21A9-23A8-23A7-D23AD6-B23AB5-3(B25AB4-)B25AB3-2D25AD4(4-27A)5-25A6-D23AD7-B21AB8-B21AB9-B19AB11-B17AB13-2B13A2B16-2B9A2B20-9B117-5A23-11A18-15A14-19A11-21A9-23A8-23A7-25A6-25A5-D25AD2(4-B25AB)3-2(B27AB2-)D27AD2(2-29A)3-2(27A4-)D25AD5-B23AB6-B23AB7-B21AB8-B21AB9-B19AB11-2B15A2B14-2B11A2B18-3B5A3B23-5B86-9A20-13A16-17A13-19A11-21A9-23A7-25A6-25A5-27A4-27A3-D27AD3(2-B27AB)-2D27AD3(2-29A)2-D27AD3-B25AB4-B25AB5-B23AB6-B23AB7-B21AB9-B19AB11-B17AB13-2B13A2B16-2B9A2B20-9B83-11A18-15A15-17A12-21A9-23A8-23A7-25A5-27A4-27A3-29A2-29A-2D27A2D-B27AB2-B27AB-2D27A2D-29A2-29A-2D27A2D-B27AB2-B27AB3-B25AB4-B25AB5-B23AB7-B21AB8-B21AB9-3B16A2B12-B15AB15-2B11A2B18-11B54-5A23-11A18-15A14-19A11-21A9-23A7-25A6-25A5-27A4-27A3-2(29A2-)29A-D29ADB29ABD29AD31AD29AD-2(B27AB2-)B27AB3-B25AB4-B25AB5-B23AB6-B23AB7-B21AB9-3B17AB11-2B15A2B14-2B11A2B18-3B5A3B23-5B25-7A21-13A16-17A13-19A11-21A9-23A7-25A5-27A4-27A3-2(29A2-)29A-62AD2(29A2D)29ADB29A2B29AB-2(B27AB2-)B27AB3-B25AB4-B25AB5-B23AB7-B21AB9-3B17AB11-B17AB13-2B13A2B16-3B7A3B21-7B24-7A21-13A16-17A13-19A11-21A9-23A7-25A5-27A4-27A3-2(29A2-)29A-31AD4(29A2D)29ADB29AB-2(B27AB2-)B27AB3-B25AB4-B25AB5-B23AB7-B21AB9-3B17AB11-B17AB13-2B13A2B16-3B7A3B21-7B24-7D21-3D7A3D16-2D13A2D13-D17AD11-D19AD9-D21AD7-D23AD5-D25AD4-D25AD3-D2(27AD-2D)27A3D6(29A2D)29A3D27A4D27AD2-D27AD2-2D25AD4-D25AD4-2D23AD6-2D21AD8-2D19AD10-2D17AD12-3D13A2D15-4D7A4D19-9D23-7F21-3F7A3F16-2F13A2F13-F17AF11-F19AF9-F21AF7-F23AF5-F25AF4-F25AF3-2(F27AF2-)F27AF-F29AFD4(29A2D)29AD31A-2(29A2-)29A3-27A4-27A5-25A7-23A9-21A11-19A13-17A16-13A21-7A24-7F21-3F7A3F16-2F13A2F13-F17AF11-F19AF9-F21AF7-F5AC11BC5AF5-F4A3C11B3C4AF4-F2A6C9B6C2AF3-F2A23C2AF2-FA25CAF2-F27CF-FA27CA2F29CFD29C2(2D29A)DG29AGD29AD-2(29A2-)29A3-27A4-27A5-25A7-23A9-21A11-19A13-17A16-13A21-7A25-5F23-3F5A3F18-2F11A2F14-2F15A2F11-F19AF9-F4AC11BC4AF7-F3A2C-11E-2C3AF6-FA2C3-11E3-2CAF5-FAC6-9E6-CAF4-FC23-CF3-FC25-C2(F2-F27-)F-D29-D31-D29CDG29B2G29BG-G27AG-2D27A2D-29A3-27A4-27A5-25A6-25A7-23A9-21A11-19A14-15A18-11A23-5A54-11F18-2F11A2F15-F15AF12-2F17A2F9-F4A4C5B4C4AF8-F2A2C13-2C2AF7-FA2C3-11E3-2CAF5-FAC6-9E6-CAF4-FC7-9E7-CF3-FC25-CF2-F27-F2-D27-2D62-2D27C2D-2(G27BG2-)2(G27AG2-)D27AD3-27A4-27A5-25A7-23A8-23A9-21A12-17A15-15A18-11A83-9F20-2F9A2F16-2F13A2F13-F17AF11-F3A6CB6C3AF9-F2A2C13-2C2AF7-FA2C3-11E3-2CAF6-FC5-11E5-CF5-FC7-9E7-CF4-F8-9E8-F3-D27-D94-2D27CD2(2-G27BG)2(2-G27AG)3-G25AG4-D25AD5-25A6-25A7-23A9-21A11-19A13-17A16-13A20-9A86-5F23-3F5A3F18-2F11A2F14-2F15A2F11-F3A13C3AF9-F2A2C13-2C2AF8-F2C17-2CF7-FC5-11E5-CF6-F7-9E7-F5-D8-9E8-D127-D27CD2(2-G27BG)3-2(G25AG4-)G25AG5-G23AG6-D23AD7-23A8-23A9-21A11-19A14-15A18-11A23-5A117-9F20-2F9A2F16-2F13A2F13-F2A13C2AF11-FA2C13-2CAF9-2FC17-C2F8-F5-11E5-F7-D6-11E6-D14-9E107-D23-D5-DB23CBD2(4-G25BG)2(4-G25AG)5-G23AG6-G23AG7-G21AG8-D21AD9-21A11-19A13-17A16-13A20-9A148-5F23-3F5A3F18-2F11A2F15-FAB11CBAF13-F2C13-2CF11-FC17-CF9-D21-D14-11E21-9E107-D23-D5-DB23CBD2(4-G25BG)5-2(G23AG6-)G23AG7-G21AG8-G21AG9-G19AG10-2D17A2D12-17A15-15A18-11A23-5A180-7F21-3F7A3F17-F3B7C3BF15-2F13-2F12-2D-D13-D-2D46-11E21-9E138-D23CD2(6-G23BG)6-G23AG7-2(G21AG8-)G21AG9-G19AG11-G17AG13-G15AG14-2D13A2D16-13A21-7A240-9F20-2FC7BC2F16-2D2H2(-3H)-2H2D16-2D2(-3D)-2D50-11E21-9E78-D19-D10-H19-H9-DA19CAD2(8-GA19BAG)2(8-G21AG)9-G19AG10-G19AG11-G17AG13-G15AG15-G13AG17-2G9A2G18-13D297-13D112-11E21-8E80-D17-D12-H17-H11-DA17CAD2(10-GA17BAG)10-G19AG10-2G17A2G11-G17AG12-GC15ACG13-GC13ACG15-2G11A2G17-3G7A3G20-9G455-11E22-6E52-2(D13-D16-)H13-H14-DCA13CACD2(12-GBA13BABG)12-2G15A2G12-CG15AGC12-CGC13ACGC12-4C11A4C13-3CG9AG3C17-3G5A3G22-7G457-9E21-11E23-4E54-2(2D9-2D18-)2H9-2H16-2D2A9C2A2D2(14-2G2A9B2A2G)14-3C11A3C14-CG2C9A2CGC14-2CGC9ACG2C14-4C2G5A2G4C15-C2-9G2-C21-5G458-2(9E22-)9E54-3(3D-3D24-)3H-3H21-3D3AC3A3D2(18-3G3AB3A3G)19-3G5A3G18-C2-9G2-C15-3C-9G-3C14-2CD3-5G3-2CD454-5E25-4ED2E24-5EDE24-7E210-7D2(24-7G)25-5G385-
