model
size = 17 31 24, scale = 0.05, origin = -y
material 
  colors = A:#100 B:#E00 C:#C03 D:#111 E:#222 F:#BBB G:#933 H:#B00 I:#C33 J:#633 K:#963 L:#696 M:#C66 N:#D00 O:#500 P:#C96 Q:#363 R:#C00 S:#A00 T:#396 U:#993 V:#333 W:#C36 X:#F03 Y:#09F Z:#C63 Aa:#CC6 Ab:#330 Ac:#800 Ad:#903 Ae:#400 Af:#936 Ag:#09C Ah:#099 Ai:#066 Aj:#366 Ak:#069 Al:#900 Am:#555
voxels
276-4B12-B4-B10-B6-B9-2(B7-)2B2(7-B)8-2B2(6-B9-B)6-B8-2B2(7-B)8-2B5-2B9-3B2-2B12-4B303-4B12-B4-B10-B6-2(B8-B7-)2B6-2B8-2(B6-B9-)B6-2B8-2(B7-)B8-2B5-2B9-2B2-3B11-4B66-2(4C13-)4C14-3C15-C115-3A12-7A10-7A9-8A9-3A4-2A7-3A6-A7-2A2(7-A)9-A5-2A9-2(A5-A10-)3(A6-A9-)A6-2(A8-)A6-A10-A4-A12-4A47-CN4-N2C8-2C4-2C9-GC4-2C9-2AdC3-2C9-2G2C-C2G10-V2C2V2C9-6D2C9-6AAmC8-9A8-2(7A10-)2A3-3A8-A5-3A8-A6-2A7-A7-2A7-A8-2A5-A9-3A5(4-A10-2A)4-2(A10-A5-)A10-A6-2(A8-)A6-2A8-A5-2A10-5A46-X9-X6-C8-C7-J8-J7-E8-E7-A8-D7-2A7-D7-A8-D6-2A8-A5-2A9-A5-2A7-3A5-2A7-2A6-2A8-A6-2(A9-2A5-)A9-2A4-A11-2A2(3-A12-A)4(2-A13-A)2-A12-A4-A11-A4-A10-A6-A9-A6-2(A8-)A5-2A10-2A2-A14-2A29-2(B10-B5-)2(I10-I5-)A10-J2(5-A10-D)5-A10-A4-A11-2A3-A11-A4-A10-2A3-A11-2A3(3-A12-A)3-A13-5(A-A14-)A-2(A13-A2-)A12-A4-A11-A4-A10-A6-2(A8-)A6-A10-A3-2A12-3A28-X11-X4-W11-W4-G11-G4-E11-E4-A12-D4-A11-2(D3-A12-)3(A2-A13-)2(K2-A13-)E2(-A14-A)-F14-A-2(F15-A)F15-2A15-D2(A14-Q-)A13-A2-A13-A3-A11-A4-A10-A6-A8-2A7-A6-A9-A5-A11-5A26-B13-B3-I12-I3-G11-G4-J12-J3-A12-D3-A12-A2-A14-A-A14-2(2A15-)K2(A15-P)A15-ZA5(15-AF)15-2A15-TA15-LA14-L-A14-Q-A13-A3-A11-A4-A11-A5-A9-A6-2(A8-)A6-A10-A3-2A12-3B10-N13-N2-N13-N3-I12-I3-E12-E3-A12-D3-A12-A-2A14-3(2A15-)K2(A15-P)A15-MA15-AF4(15-2A)15-AF2(15-LA)14-L-A14-Q-A13-A3-A12-A3-A11-A5-A9-A6-2(A8-)A6-A10-A4-A12-4B9-G13-G2-E13-E3-E12-E3-A12-D3-A13-D2-A13-3A14-3(2A15-)EA15-ZA15-MA15-JA15-AF4(15-2A)15-AF15-VA15-LA14-T-A14-D2-2(A12-A3-)A11-A5-A10-A5-A8-2A7-A6-B10-A4-B11-B13-B14-B-I14-I2-D12-D3-2(A13-D2-)A13-3A14-7(2A15-)AF4(15-2A)15-AF2(15-2A)14-A-A14-A2-2(A12-A3-)A11-A5-A10-A5-A9-B7-A7-B8-2B30-Af14-Af-D14-D2-D2(13-D2-A)13-A-A14-JA15-GA15-JA2(15-2A)2(15-KA)15-EA6(15-AF)15-EA15-AjA14-Q-A14-A2-A12-A3-A12-Ai3-A12-Ah4-A10-Ak5-A9-B7-A16-2B30-N14-N-E14-E2-D2(13-D2-A)13-A-A14-2(MA15-)WA15-2A15-K2(A15-P)A15-MA15-2A4(15-AF)15-2A15-TA15-LA14-L-A14-Q2-A12-A3-A12-Ag3-A12-Y4-A10-Y5-A9-B7-A16-2B30-G14-G-D14-D2-D2(13-D2-A)13-A2-A13-M2A14-MA15-WA15-2A15-K2(A15-P)A15-MA6(15-2A)15-TA15-LA14-L-A14-Q2-A12-A3-A12-Ag3-A12-Y4-A10-Y5-A9-B7-A16-2B30-N14-N-M14-M2-E13-E2-D13-D2-A13-A2-A13-J2A14-GA15-JA2(15-2A)2(15-KA)15-EA6(15-2A)15-EA15-AjA14-Q-A14-A2-A12-A3-A12-Ai3-A12-Ah4-A10-Ak5-A3-6AB7-A16-2B30-G14-G-J14-J2-E12-E3-D2(13-D2-A)13-3A14-11(2A15-)AF3(15-2A)14-A-A14-A2-2(A12-A3-)A11-A5-A10-A5-A9-B7-A7-B8-2B30-R13-R2-R14-R2-I12-I3-Ae13-Ae2(2-A13-A)-A14-3(2A15-)AbA15-ZA15-MA15-JA15-AF15-Ab2(F15-U)F15-AbF15-2A15-VA15-LA14-T-A14-D2-2(A12-A3-)A11-A5-A10-A5-A9-A7-A6-2B9-A3-2B11-B2(13-R)3-I12-I3-J12-J3-E12-E3-A13-D3-A12-A-2A13-3(A-A14-)K2(-A14-P)-A14-M2A14-AF15-U2(F15-Aa)F15-UF15-AF2(15-LA)14-L-A14-Q-A13-A3-A12-A3-A11-A5-A9-A6-A3-A4-A8-2(A-)A2-A10-2A-A-B12-4B10-S12-S3-H12-H2(3-G12-G)4-E11-E4-D11-D3-D12-D3-A12-A2-A14-A-A14-K2(-A14-P)-A14-ZA15-2A15-U2(A15-Aa)A15-UA15-2A15-T2(A14-L-)A14-Q-A13-A3-A11-A4-A11-A5-A9-A6-2(A8-)2(A2-)2A10-2(A-)A13-3B2(11-H)4-I12-I3-H11-J5-2(O11-O4-)E11-E2(3-A12-A)2(2-A13-A)2(2-A13-K)2-A13-E2(-A14-A)2(-A14-K)-A2(15-2A)14-D2(-A14-Q)-A13-A2-A13-A3-A11-A4-A10-A6-2(A8-)A6-A9-A5-A11-5A28-N10-N5-R10-R5-I10-I5-J10-J6-E9-E6-D9-D4-2A10-A4-A11-A2(3-A11-2A)3(3-A12-A)3-A11-2A3-A12-A2-A13-A2-5(A14-A-)2(A13-A2-)A12-A4-A11-A5-A9-A6-2(A8-)A6-A10-A3-2A12-3A30-2(S9-S6-)H8-H7-2G7-G8-G7-G8-E7-E6-2D8-D5-3A7-2A5-2(3A6-2A6-)2(2A8-2A5-)2A7-3A5-A9-A6-A9-2A4-A11-A4-A12-A3-A12-4(A2-A13-)A2-A12-A4-A10-A5-A10-A6-A8-A7-2(A8-)A5-2A10-2A-2A14-A32-3H3-3H8-HC5-2H8-2H2C2-IH10-H4CHC10-HCOC2HO10-OH5O8-9E9-7A10-6A11-6A10-2(8A9-)A5-A9-A6-2A8-A6-2A7-A7-3A6-A8-3A2(4-A10-2A)3(4-A11-A)4-2(A10-A5-)A9-A7-2(A8-)A6-A9-2A4-A12-4A50-C2Al13-2C3Ac14-2C162-2(7A10-)7A9-2A4-2A9-A6-2A8-A7-2A6-A9-A6-A9-2A2(5-A10-A)5-2(A9-A6-)A9-A7-2(A8-)A6-A10-A4-A12-4A42-
