model
size = 17 31 24, scale = 0.05, origin = -y
material 
  colors = A:#100 B:#E00 C:#EEE D:#C03 E:#111 F:#222 G:#933 H:#B00 I:#C33 J:#633 K:#963 L:#696 M:#500 N:#D00 O:#C66 P:#363 Q:#C96 R:#C00 S:#A00 T:#396 U:#993 V:#333 W:#F03 X:#C36 Y:#09F Z:#C63 Aa:#CC6 Ab:#330 Ac:#800 Ad:#400 Ae:#903 Af:#936 Ag:#09C Ah:#099 Ai:#066 Aj:#366 Ak:#069 Al:#900 Am:#555
voxels
276-4B12-B4-B10-B6-B9-2(B7-)2B2(7-B)8-2B2(6-B9-B)6-B8-2B2(7-B)8-2B5-2B9-3B2-2B12-4B269-3B13-2B-3B10-B5-2B8-2B7-3(B6-B9-)2B4-B11-B4-2(B10-B5-)2B9-B6-B8-2B6-2B7-B8-2B5-B10-3B2-B13-3B49-2(4D13-)4D14-3D15-D115-3A12-6A10-3A3-A10-2A5-A9-A7-2A2(6-A9-A)5-A10-A5-3(A11-A4-)A10-A5-A10-A6-A9-A6-2(A8-)A6-A10-A4-2A11-4A47-DN4-N2D8-2D4-2D9-GD4-2D9-2AeD3-2D9-2G2D-D2G10-V2D2V2D9-6E2D9-6AAmD8-9A8-2(7A10-)2A3-3A2(8-A6-2A)7-A8-A7-A9-A5-6(A11-A4-)2(A10-A5-)A10-A6-2(A8-)A7-A8-A5-2A10-5A46-W9-W6-D8-D7-J8-J7-F8-F7-A8-E7-A2(E7-)A8-E6-2A8-A5-2A9-A5-2A7-3A5-2A7-2A6-2A8-A6-2(A9-2A5-)A9-2A4-A11-2A2(3-A12-A)4(2-A13-A)2-A12-A4-A11-A4-A10-A6-A9-A6-2(A8-)A5-2A10-2A2-A14-2A29-2(B10-B5-)2(I10-I5-)A10-J2(5-A10-E)5-A10-A4-A11-2A3-A11-A4-A10-2A3-A11-2A3(3-A12-A)3-A13-5(A-A14-)A-2(A13-A2-)A12-A4-A11-A4-A10-A6-2(A8-)A6-A10-A3-2A12-3A28-W11-W4-X11-X4-G11-G4-F11-F4-A12-E4-A11-2(E3-A12-)3(A2-A13-)2(K2-A13-)F3(-A14-A)-A3(15-2A)15-E2(A14-P-)A13-A2-A13-A3-A11-A4-A10-A6-A8-2A7-A6-A9-A5-A11-5A26-B13-B3-I12-I3-G11-G4-J12-J3-A12-E3-A12-A2-A14-A-A14-2(2A15-)K2(A15-Q)A15-ZA6(15-AC)15-TC15-LC14-L-A14-P-A13-A3-A11-A4-A11-A5-A9-A6-2(A8-)A6-A10-A3-2A12-3B10-N13-N2-N13-N3-I12-I3-F12-F3-A12-E3-A12-A-2A14-3(2A15-)K2(A15-Q)A15-O4(C15-A)C2(15-2A)2(15-LA)14-L-C14-P-A13-A3-A12-A3-A11-A5-A9-A6-2(A8-)A6-A10-A4-A12-4B9-G13-G2-F13-F3-F12-F3-A12-E3-A13-E2-A13-3A14-3(2A15-)FA15-ZA15-OA15-JC6(15-2A)15-VA15-LA14-T-C14-E2-2(A12-A3-)A11-A5-A10-A5-A8-2A7-A6-B10-A4-B11-B13-B14-B-I14-I2-E12-E3-2(A13-E2-)A13-3A14-6(2A15-)2(AC15-)5(2A15-)AC15-AC14-A-C14-A2-2(A12-A3-)A11-A5-A10-A5-A9-B7-A7-B8-2B30-Af14-Af-E14-E2-E2(13-E2-A)13-A-A14-JA15-GA15-JA2(15-2A)2(15-KA)15-FA6(15-AC)15-FC15-AjC14-P-A14-A2-A12-A3-A12-Ai3-A12-Ah4-A10-Ak5-A9-B7-A16-2B30-N14-N-F14-F2-E2(13-E2-A)13-A-A14-2(OA15-)XA15-2A15-K2(A15-Q)A15-OA6(15-2A)15-TA15-LA14-L-A14-P2-A12-A3-A12-Ag3-A12-Y4-A10-Y5-A9-B7-A16-2B30-G14-G-E14-E2-E2(13-E2-A)13-A2-A13-O2A14-OA15-XA15-2A15-K2(A15-Q)A15-OA6(15-2A)15-TA15-LA14-L-A14-P2-A12-A3-A12-Ag3-A12-Y4-A10-Y5-A9-B7-A16-2B30-N14-N-O14-O2-F13-F2-E13-E2-A13-A2-A13-J2A14-GA15-JA2(15-2A)2(15-KA)15-FA6(15-2A)15-FA15-AjA14-P-A14-A2-A12-A3-A12-Ai3-A12-Ah4-A10-Ak5-A3-6AB7-A16-2B30-G14-G-J14-J2-F12-F3-E2(13-E2-A)13-3A14-6(2A15-)2(AC15-)5(2A15-)AC15-AC14-A-A14-A2-2(A12-A3-)A11-A5-A10-A5-A9-B7-A7-B8-2B30-R13-R2-R14-R2-I12-I3-Ad13-Ad2(2-A13-A)-A14-3(2A15-)AbA15-ZA15-OA15-JC15-AC15-Ab2(C15-U)C15-AbC15-AC15-VC15-LC14-T-C14-E2-2(A12-A3-)A11-A5-A10-A5-A9-A7-A6-2B9-A3-2B11-B2(13-R)3-I12-I3-J12-J3-F12-F3-A13-E3-A12-A-2A13-3(A-A14-)K2(-A14-Q)-A14-O2C14-AC15-U2(C15-Aa)C15-UC15-A2(C15-L)C14-L-C14-P-A13-A3-A12-A3-A11-A5-A9-A6-A3-A4-A8-2(A-)A2-A10-2A-A-B12-4B10-S12-S3-H12-H2(3-G12-G)4-F11-F4-E11-E3-E12-E3-A12-A2-A14-A-A14-K2(-A14-Q)-A14-ZC15-AC15-U2(A15-Aa)A15-UA15-2A15-T2(A14-L-)A14-P-A13-A3-A11-A4-A11-A5-A9-A6-2(A8-)2(A2-)2A10-2(A-)A13-3B2(11-H)4-I12-I3-H11-J5-2(M11-M4-)F11-F2(3-A12-A)2(2-A13-A)2(2-A13-K)2-A13-F2(-A14-A)2(-A14-K)-A2(15-2A)14-E2(-A14-P)-A13-A2-A13-A3-A11-A4-A10-A6-2(A8-)A6-A9-A5-A11-5A28-N10-N5-R10-R5-I10-I5-J10-J6-F9-F6-E9-E4-2A10-A4-A11-A2(3-A11-2A)3(3-A12-A)3-A11-2A3-A12-A2-A13-A2-5(A14-A-)2(A13-A2-)A12-A4-A11-A5-A9-A6-2(A8-)A6-A10-A3-2A12-3A30-2(S9-S6-)H8-H7-2G7-G8-G7-G8-F7-F6-2E8-E5-3A7-2A5-2(3A6-2A6-)2(2A8-2A5-)2A7-3A5-A9-A6-A9-2A4-A11-A4-A12-A3-A12-4(A2-A13-)A2-A12-A4-A10-A5-A10-A6-A8-A7-2(A8-)A5-2A10-2A-2A14-A32-3H3-3H8-HD5-2H8-2H2D2-IH10-H4DHD10-HDMD2HM10-MH5M8-9F9-7A10-6A11-6A10-2(8A9-)A5-A9-A6-2A8-A6-2A7-A7-3A6-A8-3A2(4-A10-2A)3(4-A11-A)4-2(A10-A5-)A9-A7-2(A8-)A6-A9-2A4-A12-4A50-D2Al13-2D3Ac14-2D162-2(7A10-)7A9-2A4-2A9-A6-2A8-A7-2A6-A9-A6-A9-2A2(5-A10-A)5-2(A9-A6-)A9-A7-2(A8-)A6-A10-A4-A12-4A42-
