model
size = 16 31 31, scale = 0.05, origin = -y
material 
  colors = A:#FFF B:#63C C:#66C D:#CCF E:#96C F:#EEE G:#FC3 H:#DDD I:#FC6 J:#99C K:#99F L:#C9F M:#FF9 N:#FC9 O:#FFC P:#BBB
voxels
292-5A11-6A10-6A11-4A426-4A12-5(7A9-)7A10-6A376-6A10-6(9A7-)9A8-8A8-7A345-7A8-7A2N5(6-10A)2(7-9A)8-8A8-7A329-3A-2A2N7-7A2I6-4(11A5-)2(10A6-)10A7-9A8-8A9-5A44-7A9-6A11-5A3(10-6A)10-2(5A11-)4A74-7A7-8A2M6-8A2G6-8A2I6-8A2G6-8A3I5-2(12A4-)2(5A-6A4-)12A4-2(11A5-)11A6-9A8-7A41-11A5-10A7-9A3(6-10A)6-9A7-9A3(5-11A)5-10A6-3(11A5-)8A4I4-8A4G4-8A2(5G2-9A)5I2-9A5M2-6A2-A5F2-5A3-6A2-6A-6A3-13A4-11A5-11A6-9A8-7A11-3A25-13A3-13A5-11A9(3-13A)3-12A4-13A3-13A2-9A5I2-9A6G-2(9A7G)9A7I9A7M6A2-A6O-5A3-7A-5A3-6A2-6A-7A2-13A4-11A6-10A6-8A10-5A24-7(14A2-)2(8A6F2-)2(14A2-)15A-40A7M2(9A7G9A7I)37A3-12A4-7A-5A3-7A-6A-7A2-13A4-12A5-10A6-9A8-6A23-8A5(-7A)-31A-40A7C9A7B9A7K9A7H57A7O6A-2A7H6A2-A7H5A3-A7N5A4-7I5A2(3-13A)2(-15A)3-7A-5A3-6A2-6A-7A4-11A5-10A6-9A8-7A10-5A7-7A2-A-13A-A-5A-7A-A-13A-A-15A-5A-15A-24A7C2(9A7B)9A7E9A7H9A7D9A7L9A7E6A-2A7B6A2-A7B5A3-A7H5A4-7N4A2(4-12A)2-14A2-15A3-13A3-7A-6A-7A3-13A3-12A5-10A7-8A9-5A7-6A4-12A4-2(13A3-)2(6A-6A3-)13A2-14A2-7C7A2-7B7A2-7C7A2-7E6A4-3(6B5A5-)3(6B4A6-)6C4A7-5F4A7-8A8-8A7-10A6-10A5-12A3-7A-6A-7A3-13A3-12A5-10A7-3A13-2A11-5A6-3(11A5-)2(5A-5A5-)11A4-12A4-6C2(6A4-6B)6A5-5B5A6-5B5A7-4B4A7-5B4A7-5E2(4A7-5B)3A8-5B3A9-4E3A9-4F3A8-8A8-9A6-10A5-12A3-7A-6A-7A3-13A3-12A5-10A6-3A14-A12-5A6-10A6-2(11A5-)5A-5A2(5-11A)5-10A6-5C2(4A7-5B)2(4A8-4B)4A8-4C4A8-4L5(3A9-4B)3A9-4C3A9-4H3A8-9A6-10A6-11A4-6A-5A3-6A3-13A3-12A5-10A6-3A14-A12-5A7-9A7-2(10A6-)4A-5A2(6-10A)6-9A7-4C2(4A8-4B)3A10-3B3A10-3E3A10-3D3A10-3C5(3A10-3B)2(3A9-4B)4A7-5L4A7-9A6-11A4-6A-5A3-6A3-5A-7A3-12A5-4A3-3A6-3A14-A12-5A7-9A7-10A2(6-4A-5A)6-10A6-9A7-8A8-4C2(4A8-4B)3A10-3J3A10-3F2(3A10-3C3A10-3B)3(3A10-3B)3A9-4B3A9-4E4A7-5B4A7-5C4A6-6D5A5-5A-5A3-2(6A3-5A2-)5A5-4A3-3A6-3A14-A12-5A2(7-9A)2(7-4A-4A)2(7-9A)7-8A8-4C4A8-4B4A8-4P3A9-4F3A9-4E2(3A9-4B)3A9-4J3A9-4B3(3A10-3B)3A9-4B3A9-4J4A7-5E4A7-5B4A6-6B5A5-5C-5A3-2A4P3-5A2-2A4F3-5A2-5A5-4A3-3A6-3A14-A12-5A2(7-9A)2(7-4A-4A)2(7-9A)7-8A2(8-4D4A)8-4F4A8-4E3(4A8-4B)4A8-4L4A8-4B4A9-2(3B3A10-)3B2(3A9-4B)4A7-5D4A7-5B4A6-6B5A4-A5B-5A3-2A4B3-5A-3A4B3-9A3K5-4A3-A2F6-3A14-A13-4A6-2(11A5-)2(5A-5A5-)5(10A6-)5J3(5A7-4B)4A8-4B4A8-4D3(4A8-4B)3(3A9-4B)3A8-5E4A6-6D4A6-6B5A4-A5B-5A2-3A2(4B3-9A)3B5-8A2C6-3A14-A13-5A2(5-11A)2(5-5A-5A)4(5-11A)5-5J6A5-3(5B5A6-)2(5B4A7-)5D3(4A7-5B)2(3A9-4B)2(3A8-5B)4A6-6D4A5-A6K5A3-2A5B-6A-3A2(4B3-9A)3J5-8A2H6-3A14-A13-5A4-3(13A3-)2(6A-6A3-)2(13A3-)6D7A3-2(6B6A3-A)3(6B5A4-A)6C4A6-6H4(4A6-6B)4A7-5B3A8-5B3A7-6B4A6-6E4A5-A6F5A3-2A5P-6A-3A4L3-9A4F3-12A5-10A7-3A13-2A12-7A2(-6A-8A)-7A4(-15A)-9A6E2(-9A6B)3(10A6B)10A6K10A6D6A-3A6B6A2-2A6B5A3-2A2(6B5A4-A)6B4A6-2(6B4A5-A)6C5A3-2A6F5A3-6A2-6A-7A3-12A4-11A6-9A8-7A10-5A9-2(13A3-)13A2(2-14A)2(3-13A)3-8A5C3-8A2(5B2-9A)5B-10A5B2-9A5B2(-10A5D)-5(10A6B)10A6C5A3-2A6D4A4-2A6F5A3-7A-6A-7A2-13A4-12A5-10A6-9A8-6A25-12A4-12A5-11A4(4-12A)4-8A4C4-8A4(4B3-9A)3B4-9A4F3-9A5D3(-10A5B)-10A5E-10A5D-15A-6A2-2(7A-5A3-)6A2-6A-7A2-13A4-11A6-10A6-8A10-5A26-11A5-10A7-9A3(6-10A)6-9A7-7A2C3(6-8A2B)6-8AB7-8A2J6-10A6-8A3D4-9A3B4-9A3K4-9A4H3(2-14A)2(2-6A)2-5A3-6A2-6A-6A3-13A4-11A5-11A6-9A8-7A11-3A29-7A9-6A11-5A3(10-6A)10-2(5A11-)4A74-7A8-9A7-8AF2(7-9A)6-11A5-2(12A4-)2(5A-6A4-)12A4-2(11A5-)11A6-9A8-7A313-3A-4A7-9A6-4(11A5-)2(10A6-)10A7-9A8-8A9-5A314-7A8-9A5(6-10A)2(7-9A)8-8A8-7A328-6A10-6(9A7-)9A8-8A8-7A345-4A12-5(7A9-)7A10-6A394-5A11-6A10-6A11-4A151-
