model
size = 21 32 19, scale = 0.05, origin = -y
material 
  colors = A:#6FC B:#900 C:#C90 D:#630 E:#C93 F:#003 G:#C96 H:#966 I:#C66 J:#933 K:#888 L:#777 M:#963 N:#C63 O:#C60 P:#AAA Q:#99C
voxels
364-2(A20-)2A20-A188-2C19-2C313-B19-3B19-2A18-3A18-2A7-2D10-3A6-DI10-3A5DI2G10-DAD2-5DI11-D7-D12-6B14-8B12-3B4-B56-2C2E17-C2EC18-2C19-2C187-3B18-3B17-4B17-3B18-5B16-2(4B17-)2B2AB17-4A14-8A12-12A2DG5-13A2DG5-4A11DG5-9A6DG5-12A-DG7-11A10-10A2B9-5A6B11-CE5CE14-2E2CEC15-6C15-CE4C15-E2C-CE11-3C9-3C141-B18-3B2(16-5B)16-4(6B15-)2A4B14-7A13-9A10-9A6DG5-AD11A3(DF6-13A)DF6-9A6DG5-13A8-12A9-12AB9-2E6ACEC10-FC2-4ACF10-CEC6-E2C9-ECE6-C3E8-CEC6-4C7-3C8-4C7-2E8-2E103-B18-3B14-B-5B14-7B14-4(8B13-)8B9-4A2B3A3B9-12A9-13A8-13A2DG4-14ADF2(5-14A2F)5-14ADF5-14A2DG4-16A5-14A7-14A8-2C8AEC10-C8ACF9-EC8-E2C2(8-CE8-2CE)7-3C8-4C7-C10-C83-2B15-B2-3B14-7B2(12-9B)12-B2A6B10-2AB2A6B9-3AB3A5B8-4A2B5A2B7-A-3A5B3AB7-13A2B6-14A8-15A5-14A2DG4-14ADF2(5-14A2F)4-15A2F4-15A2DG3-17A5-2(15A2B4-)CE10ACE8-C10A2C8-C-8A-2C8-C11-C8-E11-C8-C11-C83-B19-2B2(15-6B)12-B-8B11-10B11-B3A6B9-2A3B2A5B7-4A4BA5B6-5A5B4ABJ5-5A8BABH5-15AB5-16A6-15A5-14ADA5-14ADFG4-14A2(2F4-15A)DF4-15ADFG3-17A4-17AB3-17A2B2-2C12AEC6-C12AC7-2C11AE12-5A3-C20-C83-B17-B2-B17-4B15-6B15-7B14-7B11-10B11-B5A4B9-2A3B3A4B7-4A3B5A2B6-5A8B2A2Q4-5A3B3A3BA2L4-15A2B4-16AB4-2(16A5-)14ADA4-2(15ADFG3-)15A2DG3-15ADA3(4-17A)B2-3C12AE2C5-C12AC8-C11AC-E4-E3-7A3-E-E18-C60-2B19-3B17-4B17-5B2(15-6B)11-10B11-11B10-B5A5B8-2A2B4A5B6-4A2B8A2B4-5A10B2K4-5A2B4A4B2M4-14AB2H4-16AB4-16A5-19A-19A2-18A3-15ADA5(4-17A)B2-3C13AEC5-C13AE5-E-12AC-2C2-2EC-9A3-CEC2-3C4-4A5-2C3-3C13-E2C36-3B2(17-4B)17-2(5B16-)5B11-10B11-11B10-B6A4B8-2AB6A4B6-4AB9A2B4-5A9BA2K4-5AB6A3B2M4-14AB2H4-16AB4-16A5-19A-19A2-18A3-15ADA5(4-17A)3-3C13AEC5-F13AF5-2C12A4C2-2EC-9A3-ECE2-3C2-7A4-2C3-2CE13-E2C4-E13-EC16-2B19-3B17-4B17-5B2(15-6B)11-10B11-11B10-B5A5B8-2A2B4A5B6-4A2B8A2B4-6A8BA2P4-5A2B4A4B2L4-14A3B4-16AB4-2(16A5-)14ADA4-2(15ADFG3-)15A2DG3-15ADA3(4-17A)3-3C13AEC5-E13AC7-C11A-CE4-EC-9A3-EC5-E3-5A5-C6-C13-C61-B17-B2-B17-4B2(15-6B)15-7B11-10B11-B5A4B9-2A3B3A4B7-2(4A3B)6-6A7B2A2J4-5A3B3A3BA2H4-15AJB4-16A6-15A5-14ADA5-14ADFG4-14A2(2F4-15A)DFN3-15ADFG3-3(17A4-)2C12A2C6-C12AC7-C12AE10-7A3-E20-C104-B19-2B2(15-6B)12-B-8B11-10B11-B3A6B9-2A4BA5B7-4A4BA5B6-6A4B4AB6-5A8BABI5-15AB5-16A6-15A5-14A2DG4-14ADF5-14A2FO4-14A2FN3-15A2F4-15A2DG3-17A2(5-16A)B4-C12A2C6-C12AE8-C11AE8-E2-6A3-C20-C124-B16-B2-2B15-2B-3B13-2(9B12-)B2A6B10-2A2B2A5B9-3A2B2A5B8-5A2B3A3B8-4A5B3AB8-4A2B6AB8-12A9-13A8-13A2DG4-14ADF5-14A2FN4-14A2FO4-14ADF5-14A2DG4-16A2(5-15AB)6-E10ACE8-C10AEC8-CE8A-2E2(8-2C9-CE)7-3C9-3C144-B13-B-2B2(-B)4(13-8B)13-A7B13-3BA4B13-5A3B12-7A13-9A10-9A6DG5-AD11ADFN5-2(13ADF6-)13ADFO5-9A6DG5-13A8-2(13AB7-)2C8A2C10-E8ACF9-E2C7-2C9-ECE7-3C8-2C8-3C7-3C8-4C7-C10-C160-5B16-5(6B15-)6B17-3A17-4A14-8A12-12A2DG5-13A2DG5-4A11DG5-9A6DG5-12A-DG6-12A10-2(11AB9-)CE6A3C10-FC-5ACF11-2E2(6-2C11-EC)6-3E8-3C8-E2C8-2E8-2C161-B20-B19-3B18-2(4B17-)4B18-3B17-3B19-2A18-3A18-2A7-2D10-3A6-DI10-3A6D2G10-DAD2-5DI11-D7-D16-2B17-5B17-4B11-2ECE4C14-ECE2CE15-CE3CE15-5CE16-5C17-2C396-2(A20-)DA20-A67-B18-3B14-5C37-E3C17-E3C18-2(2C19-)E2C627-2C19-2C32-
