model
size = 19 23 17, scale = 0.05, origin = -y
material 
  colors = A:#C96 B:#C60 C:#111 D:#930 E:#960 F:#630 G:#FF0 H:#C90
voxels
311-2(DB)D14-5D281-3A15-5(5A14-)5A12-DB5ABD10-2D5B2D12-5B206-A16-5A14-5A13-7A11-5(9A10-)9A8-DB9ABD6-2D9B2D8-9B12-5B167-3A14-7A11-9A10-9A9-6(11A8-)11A7-B11AB6-D11BD7-11B9-9B128-A17-3A15-5A12-9A10-9A9-11A7-6(13A6-)13A5-D13AD4-D13BD5-13B7-11B11-5B110-3A15-5A13-7A11-9A9-11A7-7(13A6-)13A5-B13AB4-D13BD5-13B7-11B10-7B90-3A15-5A13-7A11-9A9-11A8-11A7-13A6-13A5-4(15A4-)15A5-13A4-D15AD2-D15BD3-15B5-13B8-9B70-3A15-5A13-7A11-9A10-9A9-11A8-11A7-13A5-6(15A4-)15A3-B15AB2-D15BD3-15B5-13B8-9B12-5B52-2A-2A13-3A-3A11-4A-4A10-4A-4A9-3(5A-5A8-)5A-5A6-7A-7A2-G8A-8AG9A2(-18A)-9A2-7A-7A4-7A-7A2-CD7AB7AD2CD15BDC-C15BC3-C13BC5-2C9B2C8-9C12-5C33-5A13-7A11-9A10-9A9-11A8-C9AC7-C11AC6-C11AC5-2C11A2C2(4-C13AC)4(4-15A)3-B15AB2-D15BD3-15B5-13B8-9B12-5B54-A15-7A11-9A10-9A9-C9AC7-C10AC7-C11AC5-3(C13AC4-)3(15A4-)15A5-13A4-D15AD2-D15BD3-15B5-13B8-9B88-5A12-C7AC9-C9AC7-C10AC7-5(C11AC6-)4(13A6-)13A5-B13AB4-D13BD5-13B7-11B10-7B70-5C12-2C5A2C9-C9AC7-C10AC7-6(C11AC6-)4(13A6-)13A5-D13AD4-D13BD5-13B7-11B11-5B53-3C14-2C3A2C11-C7AC9-3(C9AC8-)3(C8A2C8-)C9AC6(8-11A)7-B11AB6-D11BD7-11B9-9B70-3C14-7C11-5(9C10-)3C3F3C10-9C10-C7AC3(10-9A)10-CH5ACH10-2E5A2E10-9A8-DB9ABD6-2D9B2D8-9B12-5B262-3A108-DB5ABD10-2D5B2D12-5B394-2(DB)D14-5D102-
