model
size = 31 3 31, scale = 0.05, origin = -y
material 
  colors = A:#555 B:#2B1E00
voxels
12-7A55-7A21-13A49-13A16-5A7-5A45-5A7-5A13-6A7-6A18-7B18-6A7-6A11-7A7-7A15-11B15-7A7-7A9-8A7-8A12-15B12-2(8A7-)9A7-9A10-17B10-9A7-9A2(5-11A)8-19B8-11A5-11A4-11A5-11A7-21B7-11A5-11A2(3-13A)6-21B6-13A3-13A2-13A3-13A5-23B5-13A3-13A2-14A-14A5-23B5-2(14A-)2A5-8A-8A5-2A3-25B3-2A5-8A-8A5-4A7-13A7-2A3-25B3-2A7-13A7-4A9-9A9-2A3-25B3-2A9-9A9-4A11-2A-2A11-2A3-12B-12B3-2A11-2A-2A11-4A9-9A9-2A3-25B3-2A9-9A9-4A7-13A7-2A3-25B3-2A7-13A7-4A5-8A-8A5-2A3-25B3-2A5-8A-8A5-2A2(-14A)5-23B5-14A-14A2-13A3-13A5-23B5-13A3-13A2-13A3-13A6-21B6-2(13A3-)11A5-11A7-21B7-11A5-11A4-11A5-11A8-19B8-2(11A5-)9A7-9A10-17B10-2(9A7-)8A7-8A12-15B12-8A7-8A9-7A7-7A15-11B15-7A7-7A11-6A7-6A18-7B18-6A7-6A13-5A7-5A45-5A7-5A16-13A49-13A21-7A55-7A12-
