model
size = 31 5 30, scale = 0.05, origin = -y
material 
  colors = A:#111 B:#888
voxels
69-7(B-)B47-7(B-)B53-2(B-)B57-2(B-)B56-2(7A21-B-B7AB-B21-)7A21-2(4A5-4A16-B-4A5-4A-B16-)4A5-4A16-4(3A11-3A14-)3A11-3A13-2(2A15-2A11-B2A15-2AB11-)2A15-2A11-4(2A17-2A10-)2A17-2A9-2(2A19-2A7-B2A19-2AB7-)2A19-2A7-5(2A21-2A6-)2(A23-A5-BA23-AB5-)A23-A5-5(2A23-2A4-)2(A25-A3-BA25-AB3-)5(A25-A4-)A25-A3-2(2A25-2A-B2A25-2AB-)2A25-2A2(6(2-A27-A)2(-BA27-AB-A27-A))5(2-A27-A)2-2(2A25-2A-B2A25-2AB-)2A25-2A3-5(A25-A4-)2(A25-A3-BA25-AB3-)A25-A5(4-2A23-2A)2(5-A23-A5-BA23-AB)5-A23-A5(6-2A21-2A)2(7-2A19-2A7-B2A19-2AB)7-2A19-2A9-4(2A17-2A10-)2A17-2A9-A-A16-2A9-2ABA16-2AB8-2A-A16-2A9-2ABA16-2AB9-A-A16-2A11-4(A-17A12-)A-17A2(13-16A14-B16A-B)13-16A9-
