model
size = 10 32 11, scale = 0.05, origin = -y
material 
  colors = A:#03C B:#888 C:#EEE D:#444 E:#FF0 F:#111
voxels
4-8(2A8-)2A267-A2-A6-A2-A5-2A2-2A4-2A2-2A5-A2-A7-5(2A8-)2A14-A3(8-2A)8-A202-2A2-2A4-2A2-2A3-8(3A2-)8A2-8A-21A-6A-2A2-4A2-2(2A3-)2(2A8-)A250-A2-4A2-2(2A-6A-)51A-8A2-8A3-6A5-4A6-4A195-6A2-A-6A-71A-8A2-8A3-6A5-3(4A6-)4A135-D4-D24-6A4-6A2-80A-8A3-6A5-3(4A6-)4A7-2A136-4(D4-)6A4-6A2-60A-2(8A2-)8A3-6A5-3(4A6-)E2AE7-2A135-D-D2-D-D14-4A5-6A4-6A3-5(8A2-)8A3-2(6A4-)A4EA5-E2AE6-4A4-2C4A2C2-3C2E2(3C2-)3C122-D-D2-D-D145-2B8-2B16-F4-F276-2(2B8-)2B288-2(2B8-)2B44-
