model
size = 28 32 32, scale = 0.05, origin = -y
material 
  colors = A:#BBB B:#444 C:#111 D:#0E0
voxels
46-4D28(24-D2AD)24-4D51-C4D28(CB21-CD2AD)CB21-C4DCB75-2BCB2CBC2B28(18-2B7AB)18-2B6C2B73-2BDB4DBD28(2B16-2B8A)2B16-12B71-2B2(CB)2C3(BC)9(14-B3A6-3AC)19(14-3BA6-3AC)14-4B6-3BC16-11B43-2(BD)B5D2(BD)C2(13-B2A7-4AD)8(13-B2A9-2AD)3(13-B-A2(9-2AD13-B2A)9-2AD)9(13-B2A9-2AD)13-3B9-B2C15-11B18-8C17-3(CB)2C3(BD)C2(13-CA8-4AD)20(13-CA11-AD)6(13-CA-10BAD)13-CB-10B2C15-11B18-9C15-3(DB)5D2(BD)C2(12-DA9-5A)3(12-DA12-2A)3(12-DA12-AC)12-DA12-2A12-DA12-AC2(12-DA12-2A)5(12-DA12-AC)12-DA12-2(2A12-D2A11-)2(AC12-D2A11-)2(AC12-D2A-10B2A12-D2A-10B)2(2A12-D2A-10B)2A12-DCB-10B2C15-11B18-9C15-2(DB)DCB2C3(BD)C2(12-A10-5A)3(12-A13-2A)3(12-A13-AC12-A13-2A)3(12-A13-2A)12-A13-AC3(12-2A)12-AC2(12-2A)12-3A11-2A12-3A11-AC2(12-3A11-2A)12-3A-10B2A12-3A-10BAC4(12-3A-10B2A)4-9DCB-10B2C15-11B18-9C15-2(DB)DCB2C3(BD)C2(12-A10-5A)3(12-A13-2A)12-A13-AC12-A13-2A3(12-A13-AC)2(12-A13-2A)3(12-A13-AC)2(12-2A12-AC)2(12-2A)12-3A11-2A3(12-3A11-AC)2(12-3A-10BAC)4(12-3A-10B2A)3-10DCB-10B2C15-11B18-9C15-3(DB)5D2(BD)C2(12-DA9-4AD)16(12-DA12-AD)4(12-D2A11-AD)6(12-D2A-10BAD)2-3D7-DCB-10B2C15-11B18-9C16-3(CB)2C3(BD)C2(13-CA8-4AD)17(13-CA10-2AD)3(13-C2A9-2AD)6(13-C2A9B2AD)-3D9-C12B2C15-11B18-9C16-2(BD)B5D2(BC)2(14-2B2A6-3AC)7(14-2B2A7-2AC)19(14-B3A7-2AC)-3D10-4B7-2BC16-11B18-8C18-2(BC)B2CBC2(DB)9(15-3BA5-3AB)19(15-2B2A5-3AB)-2D12-4B5-4B16-10B46-BDB4D2BCB8(17-2B6A3B)17-2B7A18(2B17-B8A)2B2-3C12-B8A2B2-3C12-11B3-2C69-BCB2CB27(C2B19-BC4A)C2B3-3C13-BC4AC2B3-A2C13-B6C2B4-2C26-2C42-C4D27(C22-CD2AD)C5-A2C14-CD2ADC5-A2C14-C4DC5-A2C26-2C42-C4D27(CB21-CD2AD)CB4-A2C14-CD2ADCB4-A2C14-C4DCB4-A2C26-2C40-2BCB2CBC2B27(18-2B7AB)3-3C12-2B7AB3-A2C12-2B6C2B4-2C26-2C39-2BDB4DBD27(2B16-2B8A)2B2-3C11-2B8A2B2-3C11-12B3-2C66-2B2(CB)2C3(BC)9(14-B3A6-3AC)19(14-3BA6-3AC)-2D11-4B6-3BC16-10B44-2(BD)B5D2(BD)C2(13-B2A7-4AD)8(13-B2A9-2AD)3(13-B-A2(9-2AD13-B2A)9-2AD)8(13-B2A9-2AD)13-B2A9-2A4D10-3B9-B2C15-11B18-8C17-3(CB)2C3(BD)C2(13-CA8-4AD)20(13-CA11-AD)6(13-CA-10BAD)-3D9-CB-10B2C15-11B18-9C15-3(DB)5D2(BD)C2(12-DA9-5A)3(12-DA12-2A)5(12-DA12-AC)6(12-DA12-2A)12-DA12-AC12-DA12-2(2A12-D2A11-)AC2(12-D2A11-2A)12-D2A-10B2A12-D2A-10BAC4(12-D2A-10B2A)2-3D7-DCB-10B2C15-11B18-9C15-2(DB)DCB2C3(BD)C2(12-A10-5A)5(12-A13-2A)12-A13-AC4(12-A13-2A)3(12-A13-AC)2(12-2A12-AC)2(12-2A)2(12-3A11-2A12-3A11-AC)12-3A-10B2A12-3A-10BAC4(12-3A-10B2A)3-10DCB-10B2C15-11B18-9C15-2(DB)DCB2C3(BD)C2(12-A10-5A)3(12-A13-2A)5(12-A13-AC)5(12-A13-2A)3(12-2A)12-AC2(12-2A)12-3A11-2A3(12-3A11-AC)2(12-3A-10BAC)4(12-3A-10B2A)4-9DCB-10B2C15-11B18-9C15-3(DB)5D2(BD)C2(12-DA9-4AD)16(12-DA12-AD)4(12-D2A11-AD)6(12-D2A-10BAD)12-DCB-10B2C15-11B18-9C16-3(CB)2C3(BD)C2(13-CA8-4AD)17(13-CA10-2AD)3(13-C2A9-2AD)6(13-C2A9B2AD)13-C12B2C15-11B18-9C16-2(BD)B5D2(BC)2(14-2B2A6-3AC)7(14-2B2A7-2AC)19(14-B3A7-2AC)14-4B7-2BC16-11B18-8C18-2(BC)B2CBC2(DB)9(15-3BA5-3AB)19(15-2B2A5-3AB)15-4B5-4B16-11B45-BDB4D2BCB8(17-2B6A3B)17-2B7A19(2B17-B8A)2B17-11B74-BCB2CB28(C2B19-BC4A)C2B19-B6C2B59-
