model
size = 31 30 22, scale = 0.05, origin = -y
material 
  colors = A:#BBB B:#444 C:#111 D:#0E0 E:#222
voxels
36-23C9-22D10-3D17AD11-2D17AD12-19D752-23C9-22D10-3D17AD11-2D17AD12-19D781-2C23BC6-25C7-24C8-23C9-22C10-21C747-2C3B10(AE)A2BC3-2B25AB4-2B24AB5-2B23AB6-2B22AB7-2B21AB8-23B714-C3B5(EA)2(EC2(EA))EA2BC-6C21A3B2-5C21A3B3-4C21A3B4-3C21A3B5-2C21A3B6-C21A3B7-19C5B20-C4D20(CB24-CD2AD)CB24-C4DCB4-CBAEA3E2(AE)2(C2(EA)E)CEAE2BC-BA11-14A3B2-B11-14A3B3-BA9-14A3B4-B9-14A3B5-B4A4-14A3B6-B21A3B7-3B18A3B10-10B21(7AB21-2B)6C2B3-CB3E2(AE)C8(EA)ECEBC-BA11-7A5-3A2B2-B11-7A5-3A2B3-2B9-7A5-3A2B4-B9-7A5-3A2B5-4BA4-7A5-3A2B6-3B12A5-3A2B7-2B12A5-3A2B9-9B3A5-A2B17-2D20(2B2A5-A2B19-)4B5-3B2-CB13(AE)ABC-BA12-5A7-2A2C2-A12-5A7-2A2C3-2A10-5A7-2A2C4-A10-5A7-2A2C2(5-5A)7-2A2C6-14A7-2A2C7-13A7-2A2C8-A5B6A7-2AC15-3D3A19(7-2AC17-3BA)7-2AC17-4B7-2BC-CB6(EA)2(EC2(EA))EAEBC-BA25-2AD2-A25-2AD3-2A23-2AD4-A23-2AD5-5A18-2AD6-8A14-2AD7-9A12-2AD8-A4B3A12-2AD11-5DA11-2AD16-B2A3(9-2AD16-B-A2(9-2AD16-B2A))9(9-2AD16-B2A)9-2AD16-3B9-BCDCBAEA3E2(AE)2(C2(EA)E)C2(EA)BC-BA26-AD2-C26-AD3-2C24-AD4-C24-AD5-3C21-AD6-2C5A16-AD7-C8A13-AD8-2CA2D3A13-AD10-D5CA12-19(AD16-CA11-)AD16-CB11-CDCB3E2(AE)C8(EA)ECEBC-BA26-AC2-D26-AC3-2D24-AC4-D24-AC5-3D21-AC6-7D16-2A7-6D3A13-AC8-C2A2D3A13-AC9-D2C3D2A3(12-AC15-DA)12-2A5(15-DA12-AC)15-DA12-2A5(15-D2A11-AC)2(15-D2A11-2A15-D2A11-AC)15-D2A11-AC15-DCB11-3CB13(AE)ABC-BA26-2A2-C26-2A3-2C24-2A4-C24-2A5-3C21-AC6-2C5D16-2A7-C5D3A13-AC8-C2A2D3A13-2A8-D2CD4A2(13-2A15-A)2(13-AC15-A13-2A15-A)13-2(2A15-2A12-)AC15-2A12-4(2A15-3A11-)AC2(15-3A11-2A)2(15-3A11-AC15-3A11-2A)15-DCB11-3CB6(EA)2(EC2(EA))EAEBC-BA26-AC2-C26-AC3-2C24-AC4-C24-AC5-3C21-AC6-2C5D16-2A7-C5D3A13-AC8-C2A2D3A13-AC8-D2CD4A3(13-AC15-A)13-2A3(15-A13-AC)2(15-2A12-AC)15-2A12-2A5(15-3A11-AC)15-3A11-2A3(15-3A11-AC)15-3A11-2A15-DCB11-3CBAEA3E2(AE)2(C2(EA)E)C2(EA)BC-BA12-2A12-AD2-D12-2A12-AD3-2D10-2A12-AD4-D10-2A12-AD5-3D7-2A12-AD6-7D2-2A12-AD7-6D4A12-AD8-C2A2D4A12-AD9-D2C4D10(A12-AD15-D)10(2A11-AD15-D)CB11-CDCB3E2(AE)C8(EA)ECEBC-BA12-3A10-2AD2-C12-3A10-2AD3-2C10-3A10-2AD4-C10-3A10-2AD5-3C7-3A10-2AD6-2C6A-3A10-2AD7-C10A10-2AD8-2CA2D5A10-2AD10-D6C11(A10-2AD16-C)9(2A9-2AD16-C)2B9-BCDCB13(AE)ABC-BA11-6A7-2A2C2-A11-6A7-2A2C3-2A9-6A7-2A2C4-A9-6A7-2A2C5-5A4-6A7-2A2C6-14A7-2A2C7-13A7-2A2C8-A5B3D3A7-2AC12-7D2A19(7-2AC17-B3A)7-2AC17-4B7-2BC-CB6(EA)2(EC2(EA))EAEBC-BA11-7A5-4AB2-A11-7A5-4AB3-2A9-7A5-4AB4-A9-7A5-4AB5-5A4-7A5-4AB6-15A5-4AB7-14A5-4AB8-A5BA2D4A5-3AB15-4D3A19(5-3AB18-2B2A)5-3AB18-4B5-4B-CBAEA3E2(AE)2(C2(EA)E)C2(EA)BC-BA11-15A2B2-B11-15A2B3-2B9-15A2B4-B9-15A2B5-4BA4-15A2B6-3B20A2B7-12B10A2B9-10B8A2B17-3D20(B8A2B20-)11B2-CB2(EC2(EA))6(EA)EC2BC-B26A3B2-B25A3B3-B24A3B4-B23A3B5-B22A3B6-B21A3B7-13B5ACBA3B10-10B21(C4AC2B22-B)6C2B3-C3B12(AE)2BC-19C8A3B2-18C8A3B3-17C8A3B4-16C8A3B5-15C8A3B6-14C8A3B7-19C5B21-4D20(27-D2AD)27-4D7-2C26BC3-28B4-27B5-26B6-25B7-24B8-23B717-26C6-25C7-24C8-23C9-22C10-21C746-
