model
size = 17 20 17, scale = 0.05, origin = -y
material 
  colors = A:#FF0 B:#FF3 C:#AAA D:#FF6 E:#444
voxels
278-ADBAB333-ADA3-3B61-5A12-2ADAD14-A231-BAB7-ADA58-2A3-2A10-2A3-2A11-3B2A14-B214-A2-6C3-B57-2A5-2A8-BA5-AB9-7A11-AD3A211-2A-C6-C2-AB55-2A7-2A6-2A7-AB7-B7AB9-D2ADBAD210-D4-5C4-D54-2A9-2A4-2A9-AB5-AB9A7-B8A11-ABA194-2A2(-C)5-2(C-)2A53-2A9-2A4-2A9-AB5-B10A7-D7AB10-DA-AD149-A-D14-D-B14-A-A7-A-C4-A-B4-C-B7-D-A15-B27-2(2A9-2A4-)11ABA5-AD7A2D9-2(A-)A14-A16-B2(16-A)16-B16-A16-D16-A15-3A41-B-C5-E5-C-A8-A15-A2B15-D10-2A9-2A4-2A9-2A5-D9AB7-7ADA10-2A-2A149-D-A14-B-D14-A-A7-A-C4-A-A4-C-A7-A-D15-B27-2A9-2A4-2A9-2A5-2BA6B2A7-BD7A11-A2D194-2A2(-C)5-2(C-)DA54-2A7-2A6-2A7-AB7-BA6BD9-D2AB3A210-B4-5C-C2-A56-2A5-2A8-BA5-AD9-AB5A11-2BDAD211-BA-C6-C2-2A57-2A3-2A10-BA3-AB11-B3AB14-D214-A2-6C3-D59-5A12-B3AB14-A231-D2A7-3A329-3B3-ABA333-B2ABD57-
