model
size = 27 18 23, scale = 0.05, origin = -y
material 
  colors = A:#84492C B:#000 C:#A17A43 D:#FEEA41 E:#A9523A F:#94453E G:#FFF H:#8E695F I:#1E1729
voxels
249-B-3B26-B24-B-B29-2A49-B26-B292-B-3B20-2BAB3A15B5-6BIB4A19-I3B2(A2-A19-4B)23-3B24-4B216-B20-8B18-9B17-2BA3BA7B12-B2AB3AB7A5B7-B18A-B6-B18A-4B3-B18A9-2B9A4-3A12-4A4B5-A14-4B185-2B4-B3-B14-12B14-B8AB16-B9AB16-B10A8B7-12B8AB6-14BA4BAB6-B2E2A9D2H3FAB6-B4A6D3A2H3FA7-B4A5G10A8-2B7A2B4-2A13-5AB22-4B23-2B107-B7-B-B15-2B3-7B13-8B3A10B5-B8A6B11-B9A6B10-B7A3-2A-6B7-12B8A4B3-14BA4BA2B4-B4E10D2H3FA2B4-B16A3FAB6-B20A7-B9AB2-6A10-4A2GAB20-2A3GB22-4B104-2B-12B12-8B4A3B10-2B3A3B6A2B10-B14A2B8-2B15A2B7-B8A3-6A3B6-14B7AB5-14B6CAB5-B-3E8DH6CAB5-B13A7CA6-B20A7-B7A-2AB8A9-4AFGA3B-6A11-2A2BGB22-6B76-B-7B17-3B7A3B13-2B6A-5A2B9-2B15A5B4-B17A8-2B17A7-B8A4-7A7-14B6A6-15B5CA6-B6E7DH5CA7-B13A5CA8-B18A9-B6A2-2AB8A9-4AFGAB-2(B3A)12-A2BG-2B20-2B-2B52-6B19-2B6A3B15-2B10AB13-2B6A-5AB10-2B15A5B4-B17A7-2B18A6-B20A7-14BC3A-A6-15B4C5A3-B6E6D2H4C5A3-B14A4C5A4-2B21A6-B6A2-11A8-B4A2GA2-B8A11-A3G2(2-2B)4A11-6B51-6B18-3B6A3B15-2B10AB13-B7A-5AB10-2B15A8-2B17A7-B19A6-B20A6-15BC3A-A6-15B4C5A3-B6E6D2H4C6A-B15A4C6A2-3B15AF5A5-3B2-3A2-2AB9A11-3A3-B8A12-6B2-AB5A12-6B6-2A42-6B18-3B6A3B15-2B10AB13-B7A-5AB10-2B15A8-2B17A7-B20A5-B21A4-16B3CA-4A3-15B4C-5A2-B6E6D2H4C-5A-B15A4C-5A2-3B15AF-5A4-3B2(2-5A)-5A5-B5-3B6AF-4A11-4B5AB6A11-6B5-A-2A17-2B20-B-3B2AB18-3B6A3B15-2B10AB13-B7A-5AB10-2B15A8-2B17A7-B20A5-B21A4-16B5C4A3-15B5C5A2-B6E6D2H5C5A-B15A5C5A2-3B15A2F5A4-3B5-15A5-2B3-4B2D3AH2F4AB10-2B-B5AB3A-AB11-3B-B3A3-A2-A17-2B20-B-3B2AB18-3B6A3B15-2B10AB13-B7A-5AB10-2B15A8-2B17A7-B20A5-B21A4-16B4C-4A2-BE14B5C5A2-B6E6D2H5C5A-B15A5C5A2-3B15A2F5A4-3B5-15A5-2B3-2B-B4D2H3F3AB10-4B5AB3A-AB11-5B3A3-A2-A17-2B22-3B2AB18-3B6A3B15-2B10AB13-B7A-5AB10-2B15A8-2B17A7-B20A5-B21A4-16B4C-4A3-15B5C4A3-B6E6D2H5C5A-B15A5C4A3-3B15A2F4A5-3B3-16A7-B3-4B4A2H4F2A12-3B5AB6A12-5B5-A-2A15-B25-6B18-3B6A3B14-3B10AB13-B7A-5AB10-2B15A8-2B17A7-B20A5-B21A5-15B5C4A5-13B5C4A4-B4E7D2H5C4A3-B14A5C5A3-2B15A2F4A6-2B19A7-B3-3AB-2B2AH4F2A11-3B-2B2-AB3AF2A11-5B7-2A42-6B18-3B6A3B15-2B10AB11-3B7A-5AB10-2B15A8-2B17A7-B19A6-B20A7-2(14B5C3A5-)B4E7D2H5C3A5-B13A5C3A6-B15A2F3A7-B19A8-B7A3B8A11-A3GB5-2B4A11-4B53-6B20-B6A3B15-2B10AB12-2B7A-5AB10-2B15A8-2B17A2(7-B19A)8-13B4C4A6-13B5C3A5-B3E9DH5C3A5-B13A5C3A6-B15A2F3A7-B5AF12A10-4A-2A3B3AB3A12-A2BGB22-B-2B80-7B18-2B7A3B13-2B6A-5AB10-2B15A5B3-2B17A2(7-B19A)8-13B3C4A7-13B5C2A6-B2E-9DH5C3A5-B15A3CA8-B16AFA9-B9AB-7A10-3AF3AB3-6A11-2A2BGB22-B-2B82-B24-9B15-8B4A3B9-3B12A-B9-B15A2(10-B16A)9-BAB2A9B2C4A7-BAB2A9B3C3A8-2B2A9D3C3A8-2B2A7D8A9-B2A6G9A10-2AGA2-3AB2-6A10-7AB5-3A12-2A3GB22-5B138-4B13-21B5-B12A7B6-B13A2B11-B13A3B9-3BA9BC4A5B4-3BA9B5CA10-B10A5CA10-B14ACA11-14AFA11-4AB2A2B4-3A12-3ABAB-B20-4B23-3B166-B-B15-12B2(14-13B)15-6B5A4B11-7B9A11-B15A11-B4AB10A12-B2AB-4A4-2A13-3B-4B5-A14-2B-B26-B24-2B245-2B2(22-3B2A)10B8-7B2AB17-7B3A18-5BA-A19-4B-B22-B3-B23-3B24-B273-2A25-2A24-3A24-A2-A483-2A147-
