model
size = 32 23 15, scale = 0.05, origin = -y
material 
  colors = A:#888 B:#222 C:#444 D:#555 E:#777 F:#111 G:#BBB H:#050 I:#FFC
voxels
98-24B8-2B2-2B4E15B7-6B4E15B7-2B2-21B3(7-25B)2(7-B3-B-19B7-25B)7-B3-B-19B7-24B296-25A6(6-B24AB7-24AB)6-26B232-2F30-2F29-25A6-26B5-11(28B4-)28B5-26B200-2F30-2F29-25A6-27B6(4-28B)3(4-E27B4-28B)5-27B262-25A6-27B12(4-28B)5-27B262-25A6-12(27A4-E)27A5-27A221-F31-F8-25A6-2(27A4-E)5(27A5-C26A4-E)27A5-27A8-2D15-2D13-D16B2D162-F31-F8-25A6-2(27A4-E)5(27A5-C26A4-E)27A5-27A8-2D15-2D13-D16B2D203-25A6-26A5-E27A5(4-E27A5-C26A)4-E27A5-27A262-25A6-A8C4A11CD6-EA7C2A2C5A8C6-EA7CA2C6A8C7-C4A6C6A2(CA)C2AD6-E7A4C6A2(CA)4C7-C7A3C6A2(CA)C2AD6-E9A3C5A2(CA)C2AD7-C9A2C5A2(CA)C2AD6-E10A2C5A8C7-C10AC5A7CD6-E11A10C3AD7-C10A9C4AD6-E27A5-27A199-2F30-2F29-25A6-A8C4A11CD6-EA7C2A2C5A8C6-EA7CA2C6A8C6-E5A6C6A2(CA)C2AD6-E7A4C6A2(CA)4C6-E8A3C6A2(CA)C3AD2A3-E9A3C2(5A2(CA)C3AD2A3-E10A2C)5A8C6-E11AC5A7CD6-E11A10C3AD6-E11A9C4AD6-E27A5-27A199-2F30-2F29-25A6-A8C4A11CD7-A7C2A2C5A8C7-A7CA2C6A8C7-5A6C6A3(CA)-D7-7A4C6A2(CA)4C7-8A3C6A2(CA)C3AD2A4-9A3C5A2(CA)C2AD2-I4-10A2C5A2(CA)C3AD2A4-10A2C5A8C7-11AC5A7CD7-11A10C3AD7-11A9C4AD7-27A5-2A21-4A262-23AD7-A8C4A11CD7-D7C2D2C5A8C11-4CD2CD5A8C13-5CD5ACAC-C18-3CD5AC-CA4C16-2CD5ACAC-C4D2A14-2C5AC-CAC2DAD2A14-2C5ACAC-C4D2A15-C5A8C18-C5A7CD19-9C2DGD19-2C3A3CDG2D25-C14-F23-6(2D31-)D98-23C9-11C5D8C8-10C6D8C12-6C6D2(C-)C17-4C6D2(C-)4C15-3C6D2(C-)C19-3C5D2(C-)C2-B-B15-2C5D2(C-)C20-2C5D8C18-C5D7C19-10C22-9C29-C14-F221-F133-13B3-G-G16-10B22-5B-B-2B26-6B26-2B2FHB27-B2FHB3(27-5B)333-F
