model
size = 20 3 30, scale = 0.05, origin = -y
material 
  colors = A:#996 B:#03C C:#EEE D:#6FF E:#C69 F:#303 G:#E00 H:#FC6 I:#3F3 J:#111 K:#C09 L:#FF0 M:#6F6
voxels
43-2E22-F5B14-F5B15-4B13-2(3F6BL10-)3F6BL9-2(3F6-B2L8-)3F6-B2L7-2(2F10-2L6-)2F10-2L5-2(IF12-2G4-)IF12-2G3-5(2I14-2G2-)2I14-2G-2(2I16-2G)-I16-G-3(2I16-2G)3(2(2H16-LM)2H16-2M)2H2(16-2J-H)16-J3(2-2H14-2J)3(2-2K14-2J)3-2(2K12-2J4-)2K12-2J5-2(2K10-2D6-)2K10-2D7-2(K2A6-3D8-)K2A6-3D9-2(4A6D10-)4A6D11-E5AC13-E5AC15-4A14-EA4-C14-A4-C15-A2-C14-2E4-C13-E5-C18-C14-E5-C13-E5-C18-C20-2C10-3E5-2C17-3C12-E6-2C9-2E6-3C9-E7-2C12-E6-C10-2E6-3C9-2E8-C29-2E7-2C9-2E37-3E8-C9-E38-3E8-C25-
