model
size = 23 31 17, scale = 0.05, origin = -y
material 
  colors = A:#FC0000 B:#2500DF C:#DF0082 D:#54FC00 E:#005049 F:#00DFCD G:#FCD200 H:#00897E I:#8200DF J:#00DF70 K:#FC6900 L:#006C63 M:#EFEFEF
voxels
23-B21-B23-H21-H23-B21-B23-H20-BH92-B21-B23-H21-H23-B21-B346-H19-H25-B19-B25-H19-H25-B19-B94-H19-H25-B19-B25-H19-H35-J312-16(B17-B4-)B8-J8-B36-J290-2(B15-B6-)14(H15-H6-)B15-B6-B2-J9-J2-B2(9-J)17-J291-7(B13-B8-)B5-3A3(5-B8-B5-AFA)5-B8-B5-3A5-3(B8-B13-)B8-B2-J7-J2-B8-B13-B15-J18-J7-J475-2A3-2A16-FA3-AF16-2A3-2A18-3J15-B4-JBJ4-B10-B4-JBJ4-B7-K2-B4-JBJ4-B2-K7-B4-3J4-B10-2(B5-)B7-K2-B11-B2-K4-K2(5-J)5-2(K4-K17-)K50-K17-K354-A7-A37-A7-A15-J5-J14-2(B9-)K2-B2-J3-J2-B2-K9-B2-J3-J2-B9-K2(2-B)3-2(B2-)K9-B2-J3-J2-B9-C2-B2-J3-J2-B2-3(C6-C15-)C2(29-K15-K)331-A9-A12-F9-F12-A9-A13-4(B7-B14-)B7-B11-K2-B7-B2-K8-C13-C2(8-K13-K)8-C13-C8-K13-K262-F11-F10-F11-F103-2(A9-A12-)A9-A13-4(B7-B14-)B7-B35-K11-K2(10-C11-C)10-K11-K240-F11-F10(10-A11-A)10-AC9-CA11-8(C9-C12-)C9-C218-F11-F33-A11-A10-F11-F33-F11-F2(10-A11-A)4(10-F11-F)10-A-C7-C-A12-6(C7-C14-)C7-C12-D-C7-C-D10-E-C7-C-E10-E11-E2(10-A11-A)10-D11-D125-12(A11-A10-)A2-C5-C2-A13-2(C5-C16-)C5-C14-3(D-C5-C-D12-)3(E-C5-C-E12-)E9-E2(12-A9-A)12-L9-L12-M9-M80-F11-F10-F11-F102-F11-F10-F11-F57-2(A9-A12-)A9-A13-D7-D3(14-E7-E)14-D7-D12-F-E7-E-F12-3(E7-E14-)2(D7-D14-)2(A7-A14-)D7-D14-D7-D312-A9-A12-F9-F12-A9-A14-3(ED3-DE16-)2(2D3-2D16-)2D3-2D14-I-2D3-2D-I14-7(2D3-2D16-)2D3-2D314-A7-A37-A7-A17-3G20-3G16-I3-3G3-I11-2I3-3G3-2I11-F2-5G2-F15-2(GE)G16-F-2(GE)G-F16-2(GE)G17-2GEGE2G2(16-2(G2E)G)3(16-3EG3E)2(16-3AG3A)16-GL3GLG17-M3GM247-2A3-2A16-FA3-AF16-2A3-2A18-3I17-2I-3I-2I14-FI5FIF14-4IF4I14-2IF3IF2I15-I5-I501-3A3(20-AFA)20-3A401-
