model
size = 32 25 16, scale = 0.05, origin = -y
material 
  colors = A:#FFC408 B:#E83015 C:#FFB11B D:#111 E:#F00 F:#C7802D G:#F05E1C H:#F7D94C I:#EFBB24 J:#FBE251 K:#F4A7B9 L:#DDA52D M:#E98B2A N:#F9BF45 O:#E2943B P:#CA7A2C Q:#E9CD4C R:#C18A26 S:#DDD23B T:#444 U:#C99833 V:#7D532C W:#BA9132 X:#F6C555 Y:#D75455 Z:#D9AB42
voxels
486-2C3A2CH4-G2C2ACHC11-CHCA2CH3C2-2CLA2CGCHC10-3CI2CMCAC2-2(CV2CH)10-A2HGICAHAC2-L2CVICIH2C10-HCICAC2LA4-A4C3IG502-E32-E29-ED59-D5-DE24-ED-E4-E21-2E-E2D3-DE18-BD2-ED2ED23-3B2D-DB2-2E18-2D11-2ED-E15-3D45-DE30-ED311-B-D31-2D27-D-B31-2BD28-2DBD27-3ED25-D-E3-DE22-2B-ED3ED2BD19-2D-3BDB2-DE2B19-E6B3-3E15-B-2B2D5BE4-E17-7BDBDEB2D-D13-D2B3EB-2B4-BEYDE13-BDEDBE8-D33-D2(BE)28-D2BD214-D31-2D31-D30-2BE28-5B26-D3B-D26-3D4B27-E3B24-ED-4BD23-DE-4E2B2D20-2B-E8B19-8B2E4B19-7BE-D4B14-12BE-DEBDB12-DE4B-4B2D4BEBD12-D6B7-D5BE11-2D5B7-BDE2DEB13-E3DB8-6BD25-D2BDB2D213-B30-3B29-D2B28-D4B27-6B25-7B25-E6B25-D6BD23-EB-3B-B2-B20-5B-5B20-2BD9BD17-16B16-D9BY6B12-D13BE5B12-D7BD-4D7B11-D7B6-7B11-D6B7-7BD11-2D3BD8-7B181-B30-3B30-2B29-4B27-4BD27-6B25-D6B23-DB2-5B23-BD8B22-2E3B-5B21-3BE5BD2B19-D-7B-B15-AO2D16BDJUI8-H2D17B2DAI8-IDBD17BDAJ8-Z20B2DA8-I9B4D8BDA8-N8BD4-D7B2D8-2D6BD6-DBD4B2D144-AC2ADSC2A22-3CHTDTAC2A18-5AHTDBDTO3AQ15-N2AG2ATD3BDTON3A14-C4A2D4B2D2OAGA14-5ADBD4BDAH3A14-C3A2D6B2D2H2A12-UNJ2G2D8BDAHGACA10-GNGAND9B2DNAH2A10-NGAGD11BDNAUHI10-2AN2D11B2D2AUJ9-2ANAD13BD3AG9-AUOA2D12B2D2A2H8-ANO2D14B2D3A8-24A8-A22-A104-A22-A7-8A8-A7-2A8-8D6-8D173-3A10-3A15-A16-Q14-C16-G2(14-C16-C)12-C2A17-A2(C10-H20-)A10-A20-A9-3A20-C8-2A21-C8-HA21-A8-2A21-O166-2A24-SA6-G7A8-7AG9-2AOGJ2A8-3AG2AC11-JAOAJG8-2CA2SG110-J2A10-2AJ15-2(A16-C14-)A16-A14-C16-A12-3A17-AG10-C20-Q10-C20-A10-C20-C9-C2A20-C8-CA21-A8-CA21-I8-2A21-I165-3A24-2AS4-JA22-2A7-A22-A9-G2A16-2AC11-AWIGAI8-AHIGHA78-J2A10-2AC15-A16-C14-A16-J14-C16-A14-C16-C12-C2A17-A2(G10-C20-)A10-A20-C9-C2A20-C8-GA21-A8-CA21-C8-2A21-I164-GA28-AH-4A22-4A3-3A22-AJA5-6A15-3AJA7-ASC2PIJ10-AHAC2AH76-J2A10-2AJ15-H16-A14-A16-C14-H16-A14-A16-N12-C2A17-AJ10-C20-G10-A20-A10-A20-G9-C2A20-2(C8-CA21-)P8-CA21-I164-2A28-2A-4A22-3AG3-C2A22-2AC5-G5A15-4AC7-WA2P2IA10-IHIACIA76-J2A10-3A15-A16-A14-H16-Q14-A16-J14-A16-C12-H2A17-AC10-A20-C10-C20-A10-C20-G9-C2A20-G2(8-2A21-C)8-2A21-I164-2A28-2A-4A22-3AI3-3A22-2AH5-C5A15-4AG7-QACAGAC10-IP2(HA)H76-3A10-3A15-A16-A14-H16-C14-A16-Q14-2A15-J12-3A17-2C10-C20-C10-C20-A10-C20-G9-G2A20-G8-2A21-A8-2A21-C8-CA21-A165-3A24-3A4-2A22-AJ7-A19-2A-C9-4A14-3AI11-2ACH2A8-I2PGHC18-3A2DAGA23-ALADBEDAGA19-4AXLDEBD2AL2AC15-CF3CF2A2DALFC2FCF14-6AFDEBDF5AQ14-H5AFDBEDF6A14-3CFCF2A2D2AFC2FCF12-21AJ2(10-C20-A)10-A20-C9-H2A20-G8-CA21-A8-CA21-O8-CA21-A166-HA24-AI6-J4AHA9-8A9-GCRARCA8-2AG2A2C11-A2C3A8-ACGHGA173-LCG2CG6-LCAC2A14-LAL2HA6-AGCLAC44-C7AFDEBDF8A10-C7AFDBEDF7AI10-2(CFM)C2FA2D2AF3C3FA10-C8ADBED8AF9-AF8ADEBD8AFG8-2(2CF)2(CF)A2DH3FCF2CFAG8-C23A8-2A21-C8-A22-O104-A22-A7-2A16-8A8-2AGC3A8-4AC2A331-CLAC2AC6-CA2CACA12-ACHLHAC6-AHACG2C44-5CACA4-HCGLCHAG12-CAGCA3C4-2(CA)GC2L42-CAMF2(CM)2FAR2CFCMFM2CF2C8-AF8K2FCF8KFC2(8-FK8AKFAK8AKF)8-F10A2-10AF8-F9A4-9AF8-AFMF2M2FM6-2M2(2FM)X8-C2ARAC2RA6-2A2(CHA)C132-
