model
size = 6 29 21, scale = 0.05, origin = -y
material 
  colors = A:#CB2929 B:#E82C2C C:#AE2A2A
voxels
44-2A3-4(4A2-)4A3-2A124-2A3-2(4A2-)4A3-2(2A4-)2A3-2(4A2-)4A3-2A100-2A3-4(4A2-)2(C2AC2-)4(B2AB2-)C2AC2(2-4A)3-2A76-2A3-2(4A2-)6(B2AB2-)4(C2AC2-)B2AB2-C2AC2(2-4A)3-2A64-2A3-4A2-4A-36A-C2AC4(2-B2AB)2-C2AC2-B2AB3-2A3-4A2-4A63-2A3-4A-6A36-7AC2ACA-3(C2AC2-)2(B2AB2-)B2AB3-2A3-4A3-2A122-AB2ABA-2(B2AB2-)B2AB3-2A4-2A3-B2AB2(2-4A)127-AB2ABA-5(B2AB2-)C2AC2-4A3-2A128-AB2ABA-3(B2AB2-)C2AC2(2-B2AB)2-4A127-6A-2(B2AB2-)C2AC2(2-B2AB)2-C2AC2-4A133-6A-C2AC2(2-B2AB)2-C2AC2-B2AB2-4A3-2A128-6A-2(B2AB2-)C2AC2-4A2-B2AB2(2-4A)127-12A-C2AC2-B2AB2-4A3-2A3-B2AB2-4A127-12A-5(B2AB2-)B2AB3-2A122-12A-5(B2AB2-)4A2-4A121-12A-B2AB3-2A3-B2AB2-B2AB3-2A4-2A3-4A3-2A111-4A-6A-2(4A2-)B2AB3(2-4A)3-2A3-4A2-4A3-2A104-6A-4A9(2-C2AC)2-4A3-2A98-6A-11(B2AB2-)B2AB3-2A87-4A3-15(2B4-)2B76-2A98-
