model
size = 9 31 9, scale = 0.05, origin = -y
material 
  colors = A:#FFF B:#CC0 C:#FF9 D:#FF0 E:#DDD F:#CC3 G:#FF3 H:#FF6
voxels
2-5A103-5B2(4-BG3B)2(4-5B)4-3BGB2(4-5B)4-BG3B4-2BG2B4-5B4-BG2BG4-2H2GH4-5A2(4-2EA2E)4-2(EA)E4-5E4-5A3-7A94-3B4-2(B4F2B2-)BA4FG2-B2(5FB2-G)5FB2-BA4FB2-B5FB2-BC4FG2-B2FC2FB2-BC4FB2-B2FC2FB2-G5DH6(2-A5-A)-9A3-3A78-3B5-4BF2-2B2(5A4B)6(6A3B)2(6C3B)6CBGB6C2GB6DHA7-AE3(7-2E)7-EA7-10A2-5A68-3A5-B3AB3-B5AB-2B5A3B6A3B2(7AGB)7ABG2(7A2B)7ABG2(7C2B)7CGB7CBH7DHA7-AE7-2E7-EA7-AE7-EA7-10A2-5A6-6(A8-)A7-3A5-B3AB3-B5AB-4B-5B3A-2A3B6(7A2B)2(7C2B)2(7CBG)7DHA2(7-2A)7-AE7-2E7-EA7-10A2-5A68-3A5-B3AB3-B5AB-2B5A3B6A2BG7ABG2(7A2B)7AGBF6ABG7A2B7CGB7CBG7C2B7CGH7DGA7-AE7-2E7-EA7-AE7-EA7-10A3-3A78-3B5-F3AF2-BF5D3BA5DBGBF5DA2BA4D2A2BA3D3A2BA3DADA2BA2D2ADA2B2(A2D)A2BCD2CBDC2B2(CD)BDC2BC5DC2BC4DBCBG7DHA7-AE3(7-2E)7-EA7-A-7A94-3B4-4BDF2(B2-4B2D)B2-4BDAB2-4B2A2(B2-4BAD)B2-4B2DB2-G4BDG2-5BDB2-4B2DB2-4BD2B2-G5DH6(2-A5-A)3-5A103-3(5B4-)3BGB4-G2BGB2(4-5B)4-2BG2B4-3BGB4-5B4-BG3B4-G3BG4-2H2GH4-5A2(4-2EA2E)4-2(EA)E4-5E4-5A2-
