model
size = 14 30 9, scale = 0.05, origin = -y
material 
  colors = A:#FFF B:#000 C:#847E87
voxels
-C10-C2-12B-B12CBC14(12B2C)12BCB12CBCB10-B2(2C12-)CB5(12-2B)12-3B10-2B-12B15-14BC12ACB14(12A2B)AB10AB-12B3-10B156-14BC12ACB14(12A2B)11A2B-2B8A2B3-10B156-14BC12ACB14(12A2B)11A2B-B9A2B3-10B156-14BC12AC14AB195A-12A3-10A156-14BC12ACB14(12A2B)11A2B-B10AB3-10B156-14BC12ACB14(12A2B)11A2B-B9A2B3-10B143-C10-C-BA10BABC12ACB13(12A2B)11A2B-B10AB3-10B171-12B-15C7(BC8BCB2C)BC3B2A3BCB2CBC8BC2(B2CB10C)B3(2C12B)C-C10BC3-10C156-
