model
size = 12 35 13, scale = 0.05, origin = -y
material 
  colors = A:#F06
voxels
247-2A9-3A2(8-4A)7-2(4A8-)2A316-A2(8-4A)7-A2-2(2A6-A3-)A6-A4-A5-A4-A6-A3-A6-2A2-A7-4A8-3A268-2A9-3A8-4A7-2(A4-A6-)A3-2(A6-A4-)2(A5-A4-)A6-A4-A5-A3-2A6-A2-A7-A2-A8-3A244-3A8-2A2-2(A7-A3-)3(A6-A4-)A5-A4-A6-A4-A5-2A3-A6-2A-2A6-5A2(6-A2-2A)7-A2-A8-A-A9-3A57-3A8-5A7-5A8-4A8-3A100-3A8-5A5(7-A3-A)2(6-A4-A)6-A3-A7-4A8-3A9-A20-2(2A9-)3A2(9-A-A)9-2A45-5A4(7-A3-A)8-3A63-2(4A8-)8(A3-A7-)4A8-3A87-2A2(9-A-A)10-2A33-5A5(7-A3-A)8-4A25-2(4A8-)A3-A7-2(A4-A6-)A4-4(A7-A3-)A7-5A8-3A122-A11-2(2A10-)2A22-4A2(7-A3-A)7-A4-A6-A4-2A5-A4-2A6-A3-3A6-8A6-2A3-A6-2A4-A6-3(A5-)3(A6-A4-)2(A7-A3-)A8-4A169-2A10-2A22-3A8-A3-A7-2(A4-A6-)2(A5-)A6-A4-2A3(6-A5-A)2(5-A)6-2(A5-)2(A6-A4-)A7-A3-A7-5A8-3A182-2A10-A-A10-2A21-4A7-A4-A6-2(A5-)A6-A4-A7-A3-3(A7-A4-)A6-2(A5-)A6-A5-A6-A4-A6-2A2-A9-3A219-2A10-2A33-4A7-A4-A6-2(A5-)A6-A5-A6-A4-A7-A4-2(A6-A5-)A5-A6-A4-A7-5A8-3A233-A11-2A44-5A7-2A2-2A6-2A4-A5-2A4-2A5-A5-2A5-A4-2A6-2A2-2A7-5A8-4A269-2A58-2A10-2(4A8-)5A8-4A10-2A304-
