model
size = 9 35 10, scale = 0.05, origin = -y
material 
  colors = A:#F06
voxels
20-A7-4(3A6-)3A7-2A8-A398-A7-7(3A6-)2A214-A8-2(3A6-)A-2A4(5-A2-A)4-A3-A4-3(A2-A5-)3A7-A178-3A6-4A5-A-2A5-3(A3-A4-)A3-3(A5-A2-)A4-A3-A4-3(A2-A5-)2(A-A6-)2A142-2A6-2(4A5-)A3-A4-A3-A5-4(A3-A4-)A3-A5-A2-A5-2A-A5-4A5-2(3A6-)2A2(6-3A)6-A-A6-2(2A7-)2A86-A8-2A7-2(4A5-)2A2-A4-A3-3(A4-)2(A3-A4-)2(A4-)2(A3-A4-)2A2-A5-3A6-3A8-A59-4(2A7-)2A8-A23-A7-2(3A6-)2(4A5-)A-2A5-A2-2A4-A3-3(A4-)A3-2(A4-)2(A3-A4-)2(A4-A3-)A5-2A-A6-3A7-2A113-2A7-2A8-2A7-2A3-3A6-A-A5-3(A3-A4-)A4-A3-2(A4-)2(A3-A4-)A4-A3-2(A4-)A3-A4-A3-A5-A2-2A4-5A5-3A8-A165-3A5-5(A3-A4-)A4-A3-2(A4-)2(A3-A4-A3-A5-)4A5-3A193-3A6-A-A5-4(A3-A4-)A3-A5-A2-2A4-2A-2A2(5-4A)6-3A210-
