model
size = 25 30 20, scale = 0.05, origin = -y
material 
  colors = A:#F60 B:#111 C:#888 D:#222 E:#777 F:#AAA G:#555 H:#A00 I:#DDD J:#080
voxels
3-8B20-16B7-3B3-13A5-3B4-2A2B3AB2ABAB4-2B6-A2(B2A)2B2(AB)3-2B7-A2BAB2A4BAB2-2B8-4AB2ABA2BAB2-2B8-A3B3AB2ABAB2-2B8-12AB2-2B8-AB2AB3A2B2AB2-2B8-A3(B2A)BAB2-2B8-A4B2A2B2(AB)2-2B8-AB2AB5ABAB2-2B8-2A2B3A3B2AB2-2B8-5ACF5AB2-2B8-4A2C2F4AB2-2B8-3A3C3F3AB2-2B8-3A3C3F4A2-2B8-2A2C4A2F3A2-2B8-AC3AGC3AFAB2-2B8-3A3G3C3AB2-2B8-A5G5CAB2-2B8-2AC3G3CF2AB2-2B8-3A2CGC2F3AB2-2B8-3A3C3F3A2(B2-2B8-4A2C2F4A)B2-2B8-5ACF5AB2-2B8-5ACFAD3AB3-10B7AD3A9-16B7-3B3-13A5-3B4-2A2B3AB2ABAB4-2B6-A2(B2A)2B2(AB)3-2B7-A2BAB2A4BAB2-2B8-4AB2ABA2BAB2-2B8-A3B3AB2ABAB2-2B8-12AB2-2B8-AB2AB3A2B2AB2-2B8-A3(B2A)BAB2-2B8-A4B2A2B2(AB)2-2B8-AB2AB5ABAB2-2B8-2A2B3A3B2AB2-2B8-5ACF5AB2-2B8-4A2C2F4AB2-2B8-3A3C3F3AB2-2B8-3A3C3F4A2-2B8-2A2C4A2F3A2-2B8-AC3AGC3AFAB2-2B8-3A3G3C3AB2-2B8-A5G5CAB2-2B8-2AC3G3CF2AB2-2B8-3A2CGC2F3AB2-2B8-3A3C3F3A2(B2-2B8-4A2C2F4A)B2-2B8-5ACF5AB2-2B8-5ACFAD3AB3-10B7AD3A5-8B11-E9-5B10AB7-3B3-B11AB5-3B4-B12A4-2B6-B12A3-2B7-14(B12A2-2B8-)7(B13A-2B8-)B12AD-2B8-B13A-2B8-B12A3-11B6AD2AB5-8B21-5B10AB7-3B3-12AB5-3B4-13A4-2B6-14A2-2B7-10(14A-2B8-)13AD-2B8-14A-2(2B8-13A2-)7(2B8-14A-)2B8-13AD-2B8-14A-2B8-B12A3-11B6AD2AB5-8B25-B10AB13-12AB12-13A12-2(14A11-)14AJ10-8(14A11-)13AD11-14A11-2(13A12-)2(14A11-)3(13A2E10-)2(14A11-)13AD11-14A11-B12A12-AB6AD2AB38-B10AB13-12AB12-13A12-5(14A11-)13AE11-14AD10-13AE2(11-14A)11-13AB11-13AD11-14A11-2(13A12-)14A11-13A2E10-3(13AB11-)13A2E10-14A11-13AD11-14A11-B12A12-AB6AD2AB38-B10AB13-12AB12-13A12-11(14A11-)13AB11-14A11-2(13A12-)14A11-13A2E10-3(13AB11-)13A2E10-14A11-13AD11-14A11-B12A12-AB6AD2AB38-B10AB13-12AB12-13A12-14A11-2(14AD10-)2(14A11-)14AD10-2(13AE11-)3(14A11-)13AD11-14A11-2(13A12-)14A11-13A2E10-3(13AB11-)13A2E10-14A11-13AD11-14A11-B12A12-AB6AD2AB38-B10AB13-12AB12-13A12-2(14A11-)14AE10-8(14A11-)13AD11-14A11-2(13A12-)2(14A11-)3(13A2E10-)2(14A11-)13AD11-14A11-B12A12-AB6AD2AB18-B19-B10AB13-12AB12-13A12-3(14A11-)13ABE10-4(13AB11-)3(14A11-)13AD11-14A11-2(13A12-)7(14A11-)13AD11-14A11-B12A12-AB6AD2AB18-B19-B10AB13-12AB12-13A12-2(14A11-)2(13AB11-)13ABE10-4(13AB11-)2(14A11-)13AD11-14A11-2(13A12-)7(14A11-)13AD11-14A11-B12A12-AB6AD2AB18-B19-B10AB13-12AB12-13A12-14A5(11-13AB)D10-4(13AB11-)14A11-13AD11-14A11-2(13A12-)7(14A11-)13AD11-14A11-B12A12-AB6AD2AB18-B19-B10AB13-12AB12-13A12-14A3(11-13AB)3(11-13AH)3(11-13AB)11-14A11-13AD11-14A11-2(13A12-)7(14A11-)13AD11-14A11-B12A12-AB6AD2AB18-B19-B10AB13-12AB12-13A12-14A3(11-13AB)2(11-13AH)I10-13AH3(11-13AB)11-14A11-13AD11-14A11-2(13A12-)2(14A11-)3(13A2E10-)2(14A11-)13AD11-14A11-B12A12-AB6AD2AB18-B19-B10AB13-12AB12-13A12-14A3(11-13AB)3(11-13AH)3(11-13AB)11-14A11-13AD11-14A11-2(13A12-)14A11-13A2E10-3(13AB11-)13A2E10-14A11-13AD11-14A11-B12A12-AB6AD2AB38-B10AB13-12AB12-13A12-14A9(11-13AB)11-14A11-13AD11-14A11-2(13A12-)14A11-13A2E10-3(13AB11-)13A2E10-14A11-13AD11-14A11-B12A12-AB6AD2AB38-B10AB13-12AB12-13A12-2(14A11-)7(13AB11-)2(14A11-)13AD11-14A11-2(13A12-)14A11-13A2E10-3(13AB11-)13A2E10-14A11-13AD11-14A11-B12A12-AB6AD2AB38-B10AB13-12AB12-13A12-3(14A11-)5(13AB11-)3(14A11-)13AD11-14A11-2(13A12-)2(14A11-)3(13A2E10-)14A11-13AB11-13AD11-14A11-B12A12-AB6AD2AB34-5B10AB7-3B3-12AB5-3B4-13A4-2B6-14A2-2B7-10(14A-2B8-)13AD-2B8-14A-2(2B8-13A2-)7(2B8-14A-)2B8-13AB-2B8-14A-2B8-B12A3-11B6AD2AB5-8B21-5B10AB7-3B3-B11AB5-3B4-B12A4-2B6-B12A3-2B7-14(B12A2-2B8-)7(B13A-2B8-)B12AD-2B8-B13A-2B8-B12A3-11B6AD2AB5-8B15-
