model
size = 13 35 23, scale = 0.05, origin = -y
material 
  colors = A:#F06
voxels
30-3(4A9-)3A10-3A11-A237-3(2A11-)A98-4A8-A4-A7-A4-2A5-2A4-A2(6-2A3-2A)6-3A-2A8-5A9-2A186-2A10-3A2(9-A2-A)9-A-A9-2A-A9-4A9-3A60-3A8-2A3-A7-2(A5-)2(A6-A5-)2(A5-)2(A6-)A5-A6-A4-A7-2A2-2A8-4A10-A136-A11-2A2(10-A-A)10-3A9-A-2A8-A2-A9-A2-A8-A3-A8-A2-A10-3A46-5A7-A4-2(A6-)A5-A6-2(A4-A7-)A4-3(A6-A5-)A5-A6-2A4-A7-2A-2A9-2A110-2A2(10-A-A)10-2A11-2A23-A11-3A9-A-2A8-A3-A8-2(A2-A9-)3A34-5A7-A4-2(A6-)A5-A6-3(A4-A7-)A4-3(A6-A5-)A5-A6-A5-A7-A2-2A9-2A97-2(2A11-)A73-2A10-A2-2(A8-A3-)A8-A2-A10-3A22-3A8-2A3-A7-2(A5-)A6-A5-A6-A4-A7-A4-A6-A5-A6-A4-A7-A5-A6-2(A5-)A6-A5-A6-A4-A8-5A82-2(2A11-)2A97-3A9-3(A3-A8-)4A33-5A8-2A3-A7-A4-2(A6-A5-)2(A5-A6-)3(A4-A7-)A4-2(A6-)A5-A6-A4-A8-4A70-2A11-2A122-4A3(8-A3-A)9-3A36-3A9-4A8-5A7-2A2-2A3(6-A5-A)4(5-A6-A)2(5-A)7-2A-3A9-A196-4A3(8-A3-A)9-3A74-2A9-5A7-A4-2A6-2(A5-)5(A6-A5-)2A4-A8-4A194-3A9-3(A3-A8-)4A98-4A8-A4-2A6-2(A5-)4(A6-A5-)A5-A7-A3-2A8-3A182-3A8-2A3-2(A7-A4-)A8-4A111-4A8-A4-A6-A5-2(A6-)2(A5-A6-)2(A5-)A6-A5-A7-2A-2A10-A169-3A9-2(A3-A8-)A3-A9-4A113-A9-3A-A8-A4-A6-A5-2(A6-)2(A5-A6-)2(A5-)A6-2A4-A8-4A167-3A9-3(A3-A8-)5A125-2A9-2A2-2A3(6-A5-A)2(6-A)2(5-A)6-A5-A7-A2-2A9-2A156-3A9-3(A3-A8-)5A137-4A8-A4-6(A6-A5-)A7-5A141-2A10-A2-2A3(8-A3-A)8-5A138-2A9-2A2-A7-5(A5-A6-)A5-A7-A3-2A8-3A128-5A4(8-A3-A)9-4A150-3A9-A3-A7-5(A5-A6-)A5-A7-A3-2A8-4A89-2A10-4A9-4(A3-A8-)A3-A9-3A164-3A9-A3-2A3(6-A5-A)2(6-A)2(5-A)2(7-A4-A)8-5A9-4A9-3A10-3(4A9-)A2-2A4(7-A4-A)8-A3-A8-3A-A11-A166-A9-3A-A8-A4-2(A6-A5-)2(2(A6-)A5-)A6-A5-A6-A4-A7-2A3-A8-A3-2A8(7-A4-A)8-A3-A9-3A191-2A9-2A2-A8-A4-2(A6-A5-)2(2(A6-)A5-)3(A6-A5-)7(A7-A4-)A8-A3-A8-5A216-2A9-3A-A8-A4-A7-A4-2(2(A6-)A5-)3(A6-A5-)6(A7-A4-)A8-A3-A8-3A-A11-A231-A10-4A8-2A3-A7-A4-A7-5(A5-A6-)A5-4(A7-A4-)A8-A3-A8-4A12-A269-3A9-5A8-2A2-A8-A3-2A5(7-A4-A)7-2A3-A8-5A8-4A9-4A322-2A10-3A9-2(5A8-)5A2(9-4A)10-3A110-
