model
size = 23 32 9, scale = 0.05, origin = -y
material 
  colors = A:#444 B:#555 C:#111 D:#EEE E:#C69 F:#C6C
voxels
346-4B19-3B20-3B43-3(6A17-)3(5A18-)4A502-3(B5A17-)6A17-3(7A16-)3(5A18-)4A20-5(2B21-)2B365-6AB16-3(6A17-)3(7A16-)3(4AD18-)4A20-2BE18-2C2B2C19-3(2BE20-)2B365-6AB16-2(6A17-)6AD3(16-7A)16-2(4AC18-)4AD18-4A20-2BE18-2C2B2C18-C2BC19-4C409-D4(6A17-)7A16-7AF15-7A16-3(4A19-)4A41-2C2-2C18-4C19-4C410-6AB16-2(6A17-)6AD3(16-7A)16-2(4AC18-)4AD18-4A20-2BE18-2C2B2C18-C2BC19-4C86-13(B21-)B20-2B15-6AB16-3(6A17-)3(7A16-)3(4AD18-)4A20-2BE18-2C2B2C19-3(2BE20-)2B365-4B2A2(17-3B3A)17-6A17-3(7A16-)3(4A19-)4A20-5(2B21-)2B365-4B19-3B20-3B43-3(6A17-)3(4A19-)4A156-
