model
size = 28 32 13, scale = 0.05, origin = -y
material 
  colors = A:#F60 B:#111 C:#FFC D:#630 E:#EEE F:#F03 G:#888
voxels
423-2(3B4-3B18-)2(3A4C3A18-)5(10A18-)6A4B3(18-10A)24-4A2(24-4D)466-3B4-3B18-BAB4-BAB6(18-10A)18-9AB18-9AE18-9AB2(18-10A)24-3AC24-3DC24-4D466-3B4-3B18-BAB4-BAB2(18-9AC)4(18-10A)18-9AE18-9AB18-9AE2(18-10A)24-3AC24-3DC24-4D466-3B4-3B18-BAB4-BAB2(18-9AC)4(18-10A)18-9AB18-9AE18-9AB2(18-10A)24-4A2(24-4D)466-3B4-3B18-3B4-3B5(15-12AC)2(15-13A)15-2C10AB3(16-C11A)16-C6A21-6C2(A26-C)A496-12AC15-12AF15-12AC15-2(13A2C13-)15A13-13A15-C11AB3(16-C11A)16-C6A21-6C2(A26-C)A496-12AC15-12AF15-12AC15-2(14AC13-)14AB13-13A15-C11AB3(16-C11A)16-C6A21-6C2(A26-C)A496-12AC15-12AF2EG12-12AC15-13A2C13-14AC13-15A13-13A15-C11AB3(16-C11A)16-C6A21-6C2(A26-C)A443-3B4-3B18-3B4-3B5(15-12AC)2(15-13A)15-2C10AB3(16-C11A)16-C6A21-6C2(A26-C)A443-3B4-3B18-BAB4-BAB2(18-9AC)4(18-10A)18-9AB18-9AE18-9AB2(18-10A)24-4A2(24-4D)466-3B4-3B18-BAB4-BAB2(18-9AC)4(18-10A)18-9AE18-9AB18-9AE2(18-10A)24-3AC24-3DC24-4D466-3B4-3B18-BAB4-BAB6(18-10A)18-9AB18-9AE18-9AB2(18-10A)24-3AC24-3DC24-4D70-13(B26-)B23-4B17-2(3B4-3B18-)2(3A4C3A18-)5(10A18-)6A4B3(18-10A)24-4A2(24-4D)43-
