model
size = 32 17 9, scale = 0.05, origin = -y
material 
  colors = A:#601313 B:#322121 C:#412626 D:#130D0D E:#9CF F:#5A2F2F G:#6D3232 H:#7C3434
voxels
229-2B18-2B9-3B18-3B8-2B20-2B7-2B22-2B5-2B24-2B4-B26-B3-2B26-2B296-2B14-2B13-3B14-3B11-4B14-4B9-4B16-4B7-4B18-4B5-4B20-4B3-4C22-4C2-3C24-3C2-2C26-2C-2G28-2GH30-H169-2A10-2A17-3A10-3A15-4A10-4A14-2(3A12-)5A12-5A9-2AE2A14-2AE2A7-5B16-5B6-4C18-4C5-4C20-4C3-4F22-4C2-3G24-2GH-3H26-3H139-A8-A21-2A8-2A19-3A8-3A18-3A8-3A17-3A10-3A15-4A10-4A13-4A12-4A11-4B14-4B9-4C16-4C7-4C18-4C5-F3C20-4C3-4G22-4G2-3H24-3H108-B2C4-2CB22-3A4-3A22-2AC4-C2A21-3A6-3A20-AEA6-AEA19-3A8-3A17-3AC8-C3A15-4A10-4A13-5B10-5B11-4C14-4C9-4C16-4C7-4C18-4C5-4F20-4F79-C4-C25-2B4-2B24-3B2-3B2(24-AEB2-BEA)23-2AC4-C2A21-A2EC4-C2EA20-AEB6-BEA19-2AEB6-BE2A17-3AB8-B3A15-5B8-5B13-5C10-5C11-5C12-5C10-4C14-4C9-2F20-2F49-2(D4-D26-)2D2-2D2(26-D4-D)25-ADB2-BDA24-ADC2-CDA23-A2ED2-D2EA22-A2B4-2BA21-AEB6-BEA19-2AEB6-BE2A17-4B8-4B16-3C10-3C15-3C12-3C13-3F14-3F211-2(D4-D26-)2D2-2D25-AED2-DEA23-AED4-DEA22-AB6-BA21-AEB6-BEA20-2B8-2B19-2C10-2C374-2D2-2D25-AD4-DA23-2D6-2D22-B8-B203-
