model
size = 31 30 26, scale = 0.05, origin = -y
material 
  colors = A:#D00 B:#E00 C:#777 D:#555 E:#EEE F:#500 G:#B00 H:#400 I:#A00 J:#800 K:#700 L:#222 M:#111 N:#444 O:#888
voxels
199-2(L-)L27-3L29-L741-3ICI25-7I24-IDIN3I24-L3I2NI25-NI2NC27-3I214-3I27-C2NIN25-I2N3IL24-3INIDI24-3C4I25-IC3I333-2(3D5C3D20-)3C5B3J2(20-2J7B2C)20-3L6B2J20-LJD4B2C2J20-N3J3B2C2J21-3J5CJ23-JL3C2J86-2J3CLJ23-J5C3J21-2J2C3B3JN20-2J2C4BDJL20-2J6B3L20-2C7B2J20-5C4B2J20-2CJ5B3C22-7A25-K4A27-2GI239-2(2D2C7-2C18-)2F11B2F16-2F11BDF16-2F11B2F16-2F11BFN16-2F11B2F17-2C10BD18-2F9B2F19-DF7B2F21-FD3FL3F22-FD7F21-2F7BFD19-2F9B2F18-D10B2C17-2F11B2F16-NF11B2F16-2F11B2F16-FD5C6B2F16-2F2C9B2F18-11A20-4K7A21-2A3G2AGJ22-2A3G2AIJ24-5F175-2(DC10-4C15-)2(HB10-4BH14-)HB10-4BN14-HB10-4BH14-HB10-4BL14-H3C8-3B2H15-H2B8-3BH16-2H2B2H2C3H2B2H17-3H7-3H18-2HB7-B2H17-2H2B3H2C2H2B2H16-H3B7-3BH15-2H3B7-B3CH14-L2B9-4BH14-H2B9-4BH14-N2(2B9-4BH14-H)2B9-4BH15-15A17-5K8A18-13A19-8AI2A20-AJ2KF2A2F2A22-2KF4A26-F2A113-2(D14-3C13-)3(K14-3BK12-)N14-3BD12-K14-3BD12-C14-3BC13-J13-2BJ14-J13-2BC15-IA11-AI16-IB11-BI15-C2B11-2BJ14-J2B11-2BJ13-C3B11-3BC12-D3B11-3BK12-D3B11-3BN3(12-K3B11-3BK)13-17A14-17A15-15A16-13AFA17-2A3JF5AGF19-A3JF5AF21-3JF5A24-GFG2A81-C16-2C12-C16-2C11-4(FB16-2BF10-)FB16-2BF11-2(K16-BK12-)KB15-CK13-JI2(14-C)B14-J13-KCBA13-2(BK12-K2B14-)BK11-4(F3B14-2BF10-)F3B14-2BF11-19A13-2(17A14-)17A15-12A3G17-11A2G19-11A21-2A3G4A25-2GA51-C17-C12-C17-C11-6(FB17-BF10-)FB17-BN11-KB16-K12-ND16-K2(12-KB16-H)11-N6(2B17-F10-F)2B17-F11-2(19A12-)2I17A13-I16A14-13A4G15-12A3G17-13A19-3A3G5A22-AGIG3A47-2(3C18-C9-)5(D2B18-BD8-)D2B18-BD9-FB18-F10-FBJ17-F2(11-K18-H)10-FBJ17-F10-FB18-F9-5(D2B18-BD8-)D2B18-BD9-21A10-21A11-2(19A12-)14A5G13-13A4G15-H14A17-4A3G5AJ19-F2AGIG4AJ23-GIKAG17-2(3C18-C9-)6(D2B18-BD8-)D2B18-BD9-FBJ17-F10-FK2(18-F10-FB)J17-F9-6(D2B18-BD8-)D2B18-BD9-2(21A10-)3F17AH10-3F18A11-2F12A5G13-F12A4G14-17A15-13AJA18-10AJ21-4A5J15-2(2C19-C9-)DB19-BD7-2(H2B19-2BH6-)H2B19-2BH7-2(DB19-BD8-)DB19-2D8-DBD18-2D9-FD18-D10-DK18-F9-2DK18-BD8-2D-I17-2(BD8-DB19-)BD7-2(H2B19-2BH6-)H2B19-2BH7-DB19-BD8-23A9-21A2(10-3F18A)11-2F12A5G12-2F12A2G3I13-15A2I15-13AJI17-F11AJ20-2A4K3J15-2C19-2C8-2C19-2C7-H2B19-2BH5-2(GH2B19-2BHG4-)GH2B19-2BHG5-H2B19-2BH7-DB19-BD2(8-DB19-2D)9-D19-D10-D19-D9-3D18-BD8-2D19-BD8-DB19-BD7-H2B19-2BH5-2(GH2B19-2BHG4-)GH2B19-2BHG5-H2B19-2BH7-23A8-23A9-21A10-2I19A10-KI13A6G11-F13A2G3I13-15A2I14-14A3K16-F11AK19-H2J4K3JA14-2C19-2C8-2C19-2C7-H2B19-2BH5-GH2B19-2BHG2-2GIH2B19-2BHI3G-GH2B19-2BHG-2(2G2-H2B19-2BH2-)2(2G3-DB19-2D3-)2(2G4-D19-D4-)2G3-3D18-BD3-2G3-2D19-BD3-2(2G2-H2B19-2BH2-)2G-GH2B19-2BHG-3GIH2B19-2BHI2G2-GH2B19-2BHG5-H2B19-2BH7-2(23A8-)23A9-21A10-J15A4FH11-F14A4F12-F14A4F13-14A3F15-2F11A2F18-3J2A5JI14-2C19-2C8-2C19-2C7-H2A19-2BH3-3GH2A19-2BH3G3IH2A19-2BH4I2GH2A19-2BH2G2(2I2-H2B19-2BH2-)2(2I3-DB19-2D3-)2(2I4-D19-D4-)2I3-3D18-BD3-2I3-2D19-BD3-2(2I2-H2B19-2BH2-)2I2GH2B19-2AH2G4IH2B19-2AH3I3GH2B19-2AH3G3-H2B19-2AH7-2(23A8-)23A9-21A10-J15A4FH11-15A4F12-15A4F13-14A3F15-8A5I2F18-3I3A5I14-2C19-2C8-2C19-2C7-H2B19-2BH5-GH2B19-2BHG2-2GIH2B19-2BHI3G-GH2B19-2BHG-2(2G2-H2B19-2BH2-)2(2G3-DB19-2D3-)2(2G4-D19-D4-)2G3-3D18-BD3-2G3-2D19-BD3-2(2G2-H2B19-2BH2-)2G-GH2B19-2BHG-3GIH2B19-2BHI2G2-GH2B19-2BHG5-H2B19-2BH7-2(23A8-)23A9-H20A10-16A4FA11-15A4F12-15A4F13-14A2FH15-A2G5A5I2F18-3IA2G4IJ14-2C19-2C8-2C19-2C7-HDB19-2BH5-2(GHDB19-2BHG4-)GHDB19-2BHG5-HDB19-2BH7-DB19-BD2(8-DB19-2D)9-D19-D10-D19-D9-3D18-BD8-2D19-BD8-DB19-BD7-H2B19-BDH5-2(GH2B19-BDHG4-)GH2B19-BDHG5-H2B19-BDH7-23A8-23A9-21A10-H20A10-16A4FA11-15A4F13-G13A3F14-G13A3F16-G6A5IF19-3IA2G4IJ14-2(2C19-2C8-)DB19-BD7-2(HDB19-2BH6-)HDB19-2BH7-2(DB19-BD8-)DB19-2D8-DBD18-2D9-2D18-D10-2D18-D9-4D17-BD8-2D-D17-2(BD8-DB19-)BD7-2(H2B19-BDH6-)H2B19-BDH7-DB19-BD8-20A3G9-F18A2(2G10-19A)GH11-15A4F12-15A4F13-2I12A3F15-I12A2F17-4J3A5IF20-2J3A4I15-2(2C18-3C8-)2DB6(17-C2D8-2DC)17-C2D9-3(DC17-CD10-)DC17-CD9-6(2DC17-C2D8-)2DC17-B2D9-19A2G10-F18A2(2G10-19A)2G11-15A4F13-14A3F14-G13A2FH15-3A3K7A2F18-J3K6HA21-3K6H15-2(2C18-3C8-)2DB5(17-C2D8-2DC)17-C2D9-DC17-CD10-DC17-CD11-C17-C12-C17-C11-DC17-CD10-DC17-CD9-5(2DC17-C2D8-)2DC17-B2D9-19A2G10-19A2H11-2(18AG12-)H14A4F13-14A3F15-13A2F17-HA3K7GF19-A3K6HG23-K4H18-2(C18-2C10-)DB6(17-CD10-DC)17-CD11-3(C17-C12-)C17-C11-6(DC17-CD10-)DC17-BD11-19A12-18AH12-2I16AI13-I16A14-14A3F15-12AK2F17-11AKF19-A3K6GK22-2K5H48-2(C16-4C10-)D3B13-2BCD10-DC2B13-2BCD10-DCD2(B13-BECD10-DCE)B13-BECD11-2(CEB13-2EC12-)CEB13-2EC2(13-2E)14-2E13-BE13-2(C2E13-BEC12-)C2E13-BEC11-2(DCEB13-BECD10-)DCEB13-BDCD10-DC2B13-2BCD10-DC2B13-3BD11-19A13-17A14-I16A14-2HJ14A15-HJ11A2F17-11AKF19-7AI2AK21-3K3AI2A25-3H51-2(4C11-4C12-)2(4C11-3BC12-)CD3(2B11-2BEC12-CE)2B11-3EC13-EBM11-M2E14-EBM11-B2E15-EB11-BE16-EB11-ME15-2EB11-MBE14-2EM11-MBE13-C3E3(11-2BEC12-CE2B)11-2BDC12-C2BC11-4C12-C3B11-4C13-17A14-17A15-14AH16-2J12AH17-JG10AF19-8AH2A21-AH4AIHA24-K3AI82-5C7-5C14-4CD7-D4C2(14-5C7-5C)2(14-5E7-4BE)14-E4B7-4BE14-2E3B7-2B3E15-EM2B7-2BME16-E3B7-3BE17-B3M5-3MB18-2(BM)5-2(MB)17-E4B5-4BE16-EM2B7-2BME15-3E2B7-3B2E14-E4B7-4BE2(14-E4B7-5E)2(14-5C7-5C)15-11A4G17-10A3G18-H9A3G19-9A2G20-2I2KAH3A2G22-3AH2AH26-3A115-15C16-3C9D3C16-7CD7C16-C2(D5C)DC3(16-7ED7E)17-E4BED6E18-5B3E5B19-2M2B3E2B2M2(20-MOMB3EBMOM)20-2M2B3E2B2M19-5B3E5B18-6EDE4BE17-3(7ED7E16-)7CD7C16-7CD7C18-11A20-8A3J21-2A2GA2H2G22-2A2GA2HAK24-KGH2A178-2C7B2C20-C2D5B2DC20-2C7D2C20-5CD5C20-5ED5E20-3E5L3E20-4E3L4E20-5EL5E21-3B3E3B23-MB3EBM23-C7-C22-C7-C23-MB3EBM23-3B3E3B21-5EL5E20-4E3L4E20-3E5L3E20-4E3D4E2(20-11D)22-4A3I25-3AIJ27-2KH399-5L27-3L29-L697-
