model
size = 3 31 14, scale = 0.05, origin = -y
material 
  colors = A:#630 B:#222 C:#930 D:#C96 E:#777
voxels
84-6B70-8(E2-)E68-8(B2-)B71-7(B2-)B77-5(B2-)B77-4(B2-)2(B83-3(B2-))B83-B-6B-B4-3A3C14(DC)D4C39A12B3-3ACA2C5(ACDADC)AC39A10BAB3-3A3C14(DC)D4C39A10BAB60-21A10BAB75-6A12B3-
