model
size = 5 32 28, scale = 0.05, origin = -y
material 
  colors = A:#FC3 B:#630 C:#BBB D:#800 E:#400 F:#AAA G:#500 H:#C00 I:#F00 J:#633
voxels
127-5(C4-)C129-5(C4-)C124-3(C4-)2(F4-)3(C4-)C114-2(C4-)7(F4-)C114-2(C4-)F6(4-A)4-F124-7(A4-)A134-5(A4-)A144-3(A4-)3(A149-2(A4-))A148-3A2-3A3-A143-3(3A2-)3A7-3A2-3A68-B3-11(3B2-)3(3A2-)3A3-B3-2(3A2-)3E2(2-DGD2-GDG)2-DGD2-EDG2-DED2-GDE2-DGD2-GDG2-3E13(2-3B)2-3A-H3A2I3AH-3A3-B3-2(3A2-)3E2-GDE2-DED2-GDG2-DED2-E2(DG2-DED2-G)DE2-DED2-E-E5(2-3B)2-BJB7(2-3B)2-3A-I3A2H3AI-3A3-B3-3A2-3A68-B3-11(3B2-)3(3A2-)3A3-B138-3(3A2-)3A147-3A2-3A3-3(A149-2(A4-))A144-3(A4-)A134-5(A4-)A124-7(A4-)A114-2(C4-)F6(4-A)4-C114-2(C4-)7(F4-)C119-3(C4-)F2(4-C)4-F2(4-C)7-
