model
size = 32 31 31, scale = 0.05, origin = -y
material 
  colors = A:#999096 B:#7C887E C:#9BADB7 D:#222034 E:#000 F:#403E3F G:#A08D83 H:#726870 I:#45283C J:#BAB79F K:#91967F L:#D3D2CD M:#FF9200 N:#F00 O:#FFE200 P:#C1F5F7 Q:#00B2FF R:#00F8FF
voxels
-2A2E22-2E2A-2A28-3A30-AE3(30-2E)30-E768-A30-2A30-A928-A30-A960-A30-A579-5(I24-I6-)I24-I195-A30-A675-3(I24-I6-)2(I24-I163-A30-A739-I24-I6-)2(I24-I6-I24-I131-A30-A771-)I24-I6-2I22-2I131-A30-A771-2I22-2I7-I22-I132-A30-A771-3I20-3I7-2I20-2I132-A30-A772-3I18-3I9-2I18-2I133-A30-A773-3I16-3I11-2I16-2I134-2A28-2A39-4I10-4I14-4I10-4I685-3I2-2I6-2I2-3I13-8I2-8I16-6I2-6I20-2I6-2I76-2A4-4H10-4B4-2A7-2(5H10-5B12-)2H-2H10-2B-2B12-5H10-5B12-H4F10-4F2(B12-H5F8-5F)2(B12-H6F6-6F)B12-H18FB12-B18FB13-5B8F6B13-5(5B8F5B14-)BF3B8F3BFB3(14-5B8F5B)14-18B15-3(16B16-)2G2-8B2-2B16-2G2(14B17-G)13B19-3B2H7B11-3A24-3A3-4AI4J11-L2BI4A5-3A-4J10-3LB-3A8-AB4J10-3L2HA11-B2J-J10-L2-2H12-BJ2-JB8-BL2-2H12-BJ3-B8-2B2-2H12-BJ3-2B6-2B4-B12-B2(4-3B)4-2(B12-B5-8B5-)2(B12-2B17-)B13-B16-2B13-3(B16-B14-)3(H16-B14-)2(B16-B14-)2B15-B2(14-2B)15-2(B14-B16-)2B13-B16-2B12-2B17-B12-2H17-B2J2-B3L2-J2H19-3J2H3L3JB82-2J12-2L16-3J10-3LH14-4J10-3LH14-2J-JB8-B3LH14-2J-JB8-2B-B2H12-B2J2-2B6-2B3-2B12-2G2(4-2B)4-BH12-2G5-6B5-BH12-2G7-2B7-BH12-2G16-BH12-2B16-2B13-B16-2G13-3(B16-G14-)2(H16-G14-)HB15-G2(14-2K14-2B)14-2K14-2J15-L14-2J15-2L12-BJ16-2L12-2H16-2B12-2H17-2B10-K2H17-9B3J2H18-B3J2B3L3J2H20-2J2H3-3J147-3J11-2L16-3J10-3L16-3JB8-5B14-4J2B6-6B14-GK2-3B4-3B2-2B14-GK3-8B3-2J14-GK4-6B4-2J14-GB14-2J3(14-2B)2(14-2G14-2H)3(14-2G14-2B)14-GH14-3B13-GH15-KB12-2LH15-KB12-2B16-K2B10-2BJ16-2LB10-2BJ16-2L2B8-2GBJ17-LG3KB3-B3GH18-2BG2KG3HB3GH18-2B3KG3HB3GH19-B3K3GB3JK275-2B11-B17-K3B8-B3H16-KB3J6-2B3H16-3G2JB4-3B3H16-3G2J9B2J16-2G2-8B2-2J16-2G12-2B16-2G2(12-BG16-2H)12-BG16-2B12-LG16-3B11-2(LG16-3B10-B)LG17-B2H8-2BL18-B2HB6-4B18-B2H3B3G5B19-2H2BJ3G4B20-2G2B2JB2L3G21-G2K2JB2L2G25-G3H439-2G10-2H18-2G2J6-L2BJ14-D2C-2G4BG2B2L2BJ-2CD10-3C-2(2GB)G2B2L3G-3C10-4C2GB2G4K2L3G4C9-5C2H2B3K-3K3G5C8-5C2H2B-4K-K3G2(5C8-5C3J8-2KL)5C8-5C-2JB7-2K-5C8-5C-2JB6-3K-5C9-4C-2HB2K3G4K-4C10-3C3-H3B3G3B3-3C11-2C4-3B3G2B4-2C617-2D3-D14-D3-2D6-2D3A2D4-2G2B4-2D3A2D6-2D4AD3-3G2KL3-D4A2D6-D5A2D-2G3K3H-2D5AD6-D5A2D2B2K2G3HG2D5AD6-D5A2DB3H2G3HK2D5A2(D6-DA3-A2DB3H2G2J2K2DA3-A)D6-D2A2-A2D-B2L2K2JK-2DA2-2AD6-2DA-2AD2-B2L3G2K2-D2A-A2D6-2D4AD12-D4A2D6-3D2A2D12-2D2A3D7-2(5AD12-D5A8-)5A14-5A9-3A16-3A487-2D5-D12-D5-2D2(4-C2A4-AD10-DA4-2AC)3(4-C7AD10-D7AC)2(4-CA6-D10-D6-AC)3(4-CA5-AD10-DA5-AC)5-DA4-AD10-DA4-AD6-2A4-2A10-2A4-2A6-8A10-8A6-7A12-7A7-2A-3A12-3A-2A361-P2(31-O)20-O10-M20-M7-D2-N4-D2E6-2ED4-N2-D3-ECA6-D2E6-2ED6-4(ACE2-ECA5-2ACE6-EC2A5-)A4(CE2-EC7-ACE6-ECA7-)2(CE2-ECA6-DE8-ED6-A)CE2-ECA6-AE8-EA6-ACE2-EC3A2-3AE8-E3A2-3ACE4-8AE8-E8A6-7A12-7A8-3A16-3A298-P20-P10-Q20-Q9-RO2Q17-QOR8-MO2M17-MOM8-MN20-NM6-D-2N2M2-D10-D3-M2N-D3-2C7-AC8-CA7-4(2C2-2CA5-2AC8-C2A5-A)2C3-3(3(C8-)C4-)3(C7-AC8-CA7-C4-)C7-A10-A7-C4-C2A4-2A10-2A4-2AC4-C3A2-3A10-3A2-3AC5-3A-4A10-4A-3A7-5A14-5A9-3A16-3A11-2D16-2D237-P30-PQ18-P11-2O17-QO10-4O16-MO10-2MNM17-M7-D2-4N-D2E6-2ED3-MN2-D3-EC7-ACE6-ECA7-4(CE2-ECA5-2ACE6-EC2A5-A)4(CE2-EC8-CE6-EC8-)2(CE2-EC7-ACE6-ECA7-)CE2-EC7-AE8-EA7-CE2-EC2A4-2AE8-E2A4-2ACE3-C2A3-3AE8-E3A3-2AC5-3A2-A-A10-A-A2-3A7-2A-2A14-2A-2A9-3A16-3A11-2D16-2D12-N18-N223-P30-PQ13-R16-2O13-M16-3O12-M16-MNM7-2D3-N2-D10-D2-3N-2D3-4(2CA5-2AC8-C2A5-A2C2-)2CA5-2AC8-C2A5-A2C3-2(3(C8-)C4-)3(C7-AC8-CA7-C4-)C7-DC8-CD7-C4-CA6-A10-A6-AC4-C2A3-3A10-3A3-2AC4-C3A-4A10-4A-3AC5-8A10-8A8-4A14-4A10-3A16-3A350-R2(31-M)9-D5-ACD8-DCA2-N2-D4-EC2A4-ACD8-DCA4-2ACE2-EC2A2-3ACD8-DC3A2-2A2(CE2-EC7ACD8-DC7A)CE2-EC2A3-2ACD8-DC2A3-2A2(CE2-EC7-CD8-DC7-)3(CE2-ECA6-CD8-DC6-A)2(CE2-ECA5-ACD8-DCA5-A)CE4-2(7A12-7A6-)7A12-7A9-2A16-2A457-3D2-2D12-2D2-3D5(6-D5AD12-D5AD)2(6-D5-D12-D5-D)2(6-DA4-D12-D4-AD)2(6-DA3-AD12-DA3-AD)6-D2A2-AD12-DA2-2A2(D6-D5AD12-D5A)D7-5A14-5A489-4D14-4D9-2(A4C14-4CA8-)9(5C14-5C8-)5C14-5C9-3C16-3C10-3C16-3C554-6(ECE16-ECE10-)7(E-E16-E-E10-)E-E16-E-E554-7(E-E16-E-E10-)E-E16-E-E357-
