model
size = 15 11 10, scale = 0.05, origin = -y
material 
  colors = A:#111
voxels
4-9A2(8-3A10-7A7-9A5-11A3-13A-45A-13A3-11A)5-9A25-7(A52-A2(13-2A)13-A-A11-A53-)A52-A2(13-2A)13-A-A11-A31-
