model
size = 9 14 18, scale = 0.05, origin = -y
material 
  colors = A:#111 B:#BBB C:#90F D:#0C0 E:#03F F:#F60 G:#E00 H:#FF3
voxels
4-3A5-3B7(6-3A)6-3H6-3A6-3F6-3A6-3G5-5B2(4-5A)5-3A6-3A85-7B2(2-7A)3-5A4-5A5-3A76-7B4(2-7A)3-5A74-9B18C-7C2-7C3-5C74-9B18A-7A2-7A3-5A74-9B18E-7E2-7E3-5E74-9B18A-7A2-7A3-5A74-9B18D-7D2-7D3-5D2(74-9B18A-7A2-7A3-5A)5-3A66-9B18A-7A2-7A3-5A4-5A5-3A57-9B18A-2(7A2-)7A3-5A4-5A5-3H6-3A6-3F6-3A6-3G6-3A3-9B18A-4(7A2-)6A4-5H4-5A4-5F4-5A4-5G4-5A3-7B7(2-7A)2-7H2-7A2-7F2-7A2-7G2-7A2-7B7(2-7A)2-7H2-7A2-7F2-7A2-7G2-7A3-5B7(4-5A)4-5H4-5A4-5F4-5A4-5G4-5A4-5B7(4-5A)4-5H4-5A4-5F4-5A4-5G4-5A2-
