model
size = 19 14 9, scale = 0.05, origin = -y
material 
  colors = A:#F9F B:#EEE C:#FCF D:#111
voxels
5-10A9-6B2(4A14-B)4A112-2B4(17-BC)5-16A3-4B10-2(2A17-)A13-B4A55-2B5(17-BC)17-2B4-18A-B15-2A17-2A16-2A17-2A12-B5A16-2B17-BC17-2B99-18A2B16-AB16-2A16-AD17-AD12-B5A16-BC17-2B118-19AB16-AB2(16-2A)17-2A12-B5A155-18A2B16-AB16-2A16-AD17-AD12-B5A16-BC17-2B118-18A-B15-2A17-2A16-2A17-2A12-B5A16-2B17-BC17-2B100-16A3-4B10-2(2A17-)A13-B4A55-2B5(17-BC)17-2B9-10A9-6B2(4A13-2B)4A112-2B4(17-BC)4-
