model
size = 28 18 31, scale = 0.05, origin = -y
material 
  colors = A:#FFCE0C B:#272727 C:#EEE
voxels
10-8B48-8B2(20-8A)382-12B18-8B18-12B16-2A8B2A16-2A8-2A17-2(10A18-)10A19-8A21-6A23-4A214-4B8-4B14-2B8-2B14-4B8-4B12-2A2B8-2B2(2A12-)2A14-3A6-3A2(16-12A)17-10A19-8A21-6A23-4A24-4A157-3B12-3B11-2B12-2B11-3B12-3B10-A2B12-2BA10-A16-A11-2(2A12-)5A6-5A13-4A6-4A14-14A15-12A17-10A19-8A22-4A24-4A128-2B16-2B9-B16-B9-2B16-2B2(8-AB16-BA)9-A16-A10-3A2-A9-3A10-3A12-3A11-2(2A12-)4A8-4A13-3A8-3A15-12A17-10A20-6A23-4A99-2B18-2B7-B18-B7-2B18-2B6-AB18-BA6-A20-A7-A2B14-2BA2(8-3A14-3A)9-2A14-2A10-3A12-3A11-2A12-2A13-4A6-4A15-12A17-10A20-6A23-4A71-B20-B7-B18-B7-B20-B5-AB20-BA4-A22-A5-A20-A6-3AB14-B3A7-2(2AB14-B2A8-)3AB12-B3A9-2AB12-B2A11-3A10-3A12-5A6-5A14-12A17-10A21-4A24-4A43-2(B20-B6-)B20-B5-AB20-BA4-A22-A5-A20-A3(6-2A18-2A)7-2A16-2A8-2A16-2A9-2A2B10-2B2A11-3A10-3A13-14A15-12A18-8A22-4A42-2(B22-B4-)B22-B3-AB22-BA2-A24-A3-A22-A2(4-2A20-2A)5-A20-A6-2A18-2A7-A18-A8-3A14-3A9-3AB10-B3A11-5A6-5A13-14A16-10A20-6A23-4A42-B22-B4-B22-B3-2B22-2B2-AB22-BA3-A22-A3(4-2A20-2A)5-2A18-2A6-2A18-2A7-2A16-2A8-3A2-B8-B2-3A9-5A8-5A11-5A6-5A14-12A18-8A22-4A42-B22-B4-B22-B3-2B22-2B-AB24-BA-A24-A3-3(A22-A4-)2A20-2A5-A20-A6-3A16-3A7-3A14-3A9-4AB8-B4A11-4AB6-B4A13-5A4-5A16-10A21-4A70-B22-B3-2B22-2B-AB24-BA-A24-A2(2-2A22-2A)3-A22-A2(4-2A20-2A)5-2A18-2A7-2A16-2A8-AC2A12-4A9-4A-B6-B-4A12-4AB4-B4A15-12A19-6A69-B22-B4-B22-B2-AB24-BA-A24-A2(2-2A22-2A)3-A22-A2(4-2A20-2A)5-2A18-2A6-3A16-3A7-AC2A12-4A9-4A10-4A11-4A2(2-B)2-4A14-12A18-8A96-B22-B2-2(AB24-BA-A24-A3(2-2A22-2A)2(2-3A20-3A)3-3A18-3A4-2ACA16-4A5-2AC2A12-5A7-5A10-5A9-5A3-2B3-5A11-16A14-12A120-)AB24-BA-A24-A2(2-2A22-2A)3-A22-A2(4-2A20-2A)5-2A18-2A6-3A16-3A7-AC2A12-4A9-4A10-4A11-4A2(2-B)2-4A14-12A18-8A122-AB24-BA-A24-A2(2-2A22-2A)3-A22-A2(4-2A20-2A)5-2A18-2A7-2A16-2A8-AC2A12-4A9-4A-B6-B-4A12-4AB4-B4A15-12A19-6A123-AB24-BA-A24-A3-3(A22-A4-)2A20-2A5-A20-A6-3A16-3A7-3A14-3A9-4AB8-B4A11-4AB6-B4A13-5A4-5A16-10A21-4A125-AB22-BA3-A22-A3(4-2A20-2A)5-2A18-2A6-2A18-2A7-2A16-2A8-3A2-B8-B2-3A9-5A8-5A11-5A6-5A14-12A18-8A22-4A125-AB22-BA3-A22-A2(4-2A20-2A)5-A20-A6-2A18-2A7-A18-A8-3A14-3A9-3AB10-B3A11-5A6-5A13-14A16-10A20-6A23-4A125-2AB20-B2A4-A20-A3(6-2A18-2A)7-2A16-2A8-2A16-2A9-2A2B10-2B2A11-3A10-3A13-14A15-12A18-8A22-4A154-AB20-BA5-A20-A6-3AB14-B3A7-2(2AB14-B2A8-)3AB12-B3A9-2AB12-B2A11-3A10-3A12-5A6-5A14-12A17-10A21-4A24-4A154-2AB18-B2A5-2A2B14-2BA7-4A14-3A8-3A14-3A9-2A14-2A10-3A12-3A11-2A12-2A13-4A6-4A15-12A17-10A20-6A23-4A183-2AB16-B2A7-2A16-A9-4A12-3A10-3A12-3A11-2(2A12-)4A8-4A13-3A8-3A15-12A17-10A20-6A23-4A211-3A2B12-2B3A9-2(2A12-)4A8-4A13-3A8-3A14-3A8-3A15-12A17-10A19-8A22-4A24-4A240-4A2B8-2B4A11-3A8-3A15-12A16-12A17-10A19-8A20-8A21-6A23-4A269-5A8B5A13-12A17-10A18-10A19-8A20-8A21-6A325-16A15-10A19-8A21-6A23-5A24-2A356-14A18-6A23-4A25-2A414-10A21-4A471-6A375-
