model
size = 31 31 21, scale = 0.05, origin = -y
material 
  colors = A:#000 B:#FFF
voxels
850-3(5A26-)5A830-4(2A5-2A22-)9A827-4(A9-A20-)3A5-3A825-4(A11-A18-)3A7-3A792-5(A13-A16-)3A9-3A790-5(A15-A14-)3A11-3A788-5(A17-A12-)3A13-3A755-6(A19-A10-)3A15-3A753-6(A21-A8-)3A17-3A751-6(A23-A6-)3A19-3A749-6(A25-A4-)3A21-3A747-6(A27-A2-)3A23-3A745-A5(29-2A)29-4A25-3A5(713-A6(29-2A)29-3A27-2A)682-A28-A-A6(29-2A)29-3A27-2A651-2(A28-A-)A6(29-2A)29-3A27-2A18-A29-3A27-4A26-6A24-7A23-9A21-10A20-12A18-13A17-15A15-8AB7A14-8ABAB7A12-8A2(BA)B6A11-8AB5AB6A9-8AB2ABAB2AB5A8-8ABA2(B2A)BAB5A7-7AB4ABA2(B4A)6-7A2(BA)2(B2A)2(BA)B4A5-6AB3AB7A2(B3A)4-6A3(BA)2(B2A)3(BA)B3A3-2(5AB)2ABAB2AB5AB2A2-5A2(BA)B4AB8A2(BA)B2A-4AB3AB4AB5AB4AB3ABA-3A3(BA)B2AB7AB2A3(BA)B3AB5AB2A2(B4A)B2AB5A3(BA)2(2(B4A)BA)BA2(B3A2(B4A))B3A2(BA)B2AB4AB5AB4AB2ABAB5AB2AB4AB7AB4AB2AB3A2(B4A)B9A4(B4A)B11AB4AB3A
