model
size = 11 28 11, scale = 0.05, origin = -y
material 
  colors = A:#F60 B:#C60 C:#070
voxels
297-C9-C287-C7-C2-C7-C91-2(7B4-7A4-)7B126-C3-C5-2C3-2C4-C5-C49-2(5A6-)5B6-5A6-5B5-7B2(4-7A4-B5AB)5-5B6-5A6-5B83-2C-2C5-3C-3C4-C5-C28-2(3A8-)3B7-2(5A6-)B3AB6-5A6-5B5-7B2(4-7A4-B5AB)5-B3AB6-5A6-B3AB7-3A8-3A52-C-C7-2C-2C6-C3-C40-2(3A8-)3B7-2(5A6-)B3AB6-5A6-5B5-7B2(4-7A4-B5AB)5-B3AB6-5A6-B3AB7-3A8-3A9-3(C10-)C75-2(3A8-)3B7-2(5A6-)B3AB6-5A6-5B5-7B2(4-7A4-B5AB)5-B3AB6-5A6-B3AB7-3A8-3A52-C-C7-2C-2C6-C3-C72-2(5A6-)5B6-5A6-5B5-7B4-7A4-B5AB4-7A4-7B5-5B6-5A6-5B83-2C-2C5-3C-3C4-C5-C114-2(7B4-7A4-)7B126-C3-C5-2C3-2C4-C5-C300-C7-C2-C7-C298-C9-C
