model
size = 16 32 12, scale = 0.05, origin = -y
material 
  colors = A:#960 B:#100 C:#050 D:#080 E:#F90 F:#630 G:#F60 H:#FF0 I:#0D0 J:#777 K:#0A0 L:#FC0 M:#963 N:#0C3
voxels
2-2L5BA5B8-6F10-2(HIA)10-ACICEH10-AJA2EHA9-AJGE3A9-I4CAI9-A2C2D2A9-IACAGJ10-2ADAGC9-GACD2AC9-2ACD2AH9-AGA2DC9-3AD2JA9-A2G2J2C9-AGAJIAC9-2GHG2IC9-JEHGA2I8-EAE2D3A8-2AGJ4A5-I2-2AMJ2MAD5-H2-E2MI3DA5-A2-A2CA2DA2H4-D2-AEC2D2AGE4-DI-AE2D2IAHA4-DI2-AD2CIE2H4-CA2-A2E2CE2A4-2D2-A2GE2(GA)4-AD2-HAGE2AGA4-2C2-3ACACKE4-A2C3A2CK4A3-2L5BK5B324-ADE3A9-AD2IE4AH6-2D2IDC2DCAH5-H3E2A2CHAD5-4DA2CH3A5-HGAD2C2HE3A4-3A4EAE2CA4-2A3G4AEAH4-GA2C4A2G2A4-5A2G4AE4-4BA2-6B3-4BK2-6B308-3A2H2A8-11A5-11AD4-11AC2(4-11AD)2(4-12A)4-2(13A3-)12AE2(3-13B)9-6F10-ACA3C10-GA2EGE10-4CGE11-CE2A12-G2AD10-GE2GAD9-3A4D10-3A3D11-A2I2D11-ADI2D11-JIA2C10-G2J2CA10-GI2CJA10-A3CJD8-2A4CJD7-DC2A2DGJD7-CDA4DJH7-AD4AGJHC5-11A4-11A5-12A2(4-11AD)4-12A4-11AC4-2(13A3-)12AE3-13A2(3-12BA)8-F6-F8-A6-A7-2A6-A7-AG6-E7-A2C4-AE7-GAG4-AE7-G2A4-E8-3A4-E7-G3A4-A7-2G2A4BA7-AGJ6A7-AG6AEA5-AG9A5-10AE5-G8AEA2(5-10AC)2(3-H11AC)3-13A3-12AC7(3-13A)E2(2-14A)2-13B3-14B6-F8-F6-A8-C6-H8-G5-2A8-A5-2A14-IA7-A6-CA7-E2(6-2A7-A)5-3A7BA5-11A5-12A4-12AF3-12AF2-13AF2-12ACF-D13AF-13B3(AF14-)F6(15-A)2(15-E)15-A2(15-B)6-F8-F6-A8-A6-A8-C5-2A8-H2(5-HA8-C)5-CA8-C5-IA8-D5-EA8-J4-C2A8BA2(4-12A)F3-12AE3-13A2-13AG2-13AH-15A14BAD14-AF14-AG14-F15-E2(15-A)15-C15-A2(15-C)2(15-A)2(15-B)6-F8-F6-H8-G6-A8-C5-2A8-G5-2A8-C5-2A8-D2(5-CA8-C)5-CA8-I4-C2A8BA4-C10AH4-C11AF3-13A3-H12A2-13AC2-13AE-14AC14BAD14-AF14-2A14-F15-A15-E2(15-D)15-C3(15-K)15-E2(15-B)6-F8-F6-H8-A6-A8-G5-HA8-C5-2A8-J5-2A8-C5-EA8-C5-CA8-J5-CA8-I4-C2A8BE4-C11A4-E11AF2(3-12AC)2-13AE3-12AC-14AC14BAG14-AF14-AE14-F15-A15-J15-D3(15-A)15-C2(15-K)15-C15-A6-F8-F2(6-A8-G)2(5-2A8-A)5-2A8-H2(5-EA8-A)5-CA8-A4-H2A8BE2(4-E11A)F3-E12A3-E11AC2-E12AC2-14A-14AH14BAE14-AF14-2A14-F3(15-D)15-E2(15-C)2(15-A)15-K2(15-B)6-F8-F2(6-C8-A)5-2C7-FC5-2A7-FN2(5-HA7-FC)5-EA7-C6-2A7-E5-E2A7BA5-H10A5-10A2C4-10A2CF3-I9A2CF2-E12AF2-13AF-14AF14B3(AF14-)F2(15-A)15-D15-A15-J15-E15-A15-K15-A2(15-B)7-F6-F8-C6-A8-A6-A8-H6-A7-2A6-C7-2I6-I7-2A6-J6-A2I6-C6-2IA6-E6-ICA6BH6-CI7AH6-2(C7AC6-I)2(8AC6-I)8AH6-9AH4-11AEA3-13A3-AI11A3-12AE3-13A3-AC11A3-12AE3-2AI10A2(3-13A)3-12AE3-13A3-12AE2(3-2L5BA5B)2-
