model
size = 12 18 11, scale = 0.05, origin = -y
material 
  colors = A:#111 B:#C96 C:#222 D:#DDD E:#F96 F:#99F G:#C3C H:#060 I:#FF0
voxels
54-7(C9-C-)C-I7-2(C-)B7-CAC9-CAC48-10(A9-A-)A2B7-A-AB4-7A5-3A2(CA)B4-3A2(CA)5-3A2(CA)6-A4CA24-3(A9-A-)2(A7-2(C-))A5-A2(-C)-A5-A2(-C)2A5-A2(-C)A6-A-2CA3B4-A-2C2A3B2-2A-2C2A2B3-ABA2(2C2AD3-2A2B)2C2AF3-2A2B2C2AB5-A3C2A79-3(A9-A-)A-C4B3-2(A-)CA4B2-A-A2C2A3B2-A-A2C2A-2B-A2BA2C2AH3-A3B2C2AD3-A3B2C2AF3-A3B2C2AB4-2A3CBA9-CA66-2(A11-)A4-3B4-A3-C5B2-A3-CA3BG2-A-B2CA4B2-A2B2C5B-A3B2C2B2(D3-A3B2CBE)B3-A3B2C3B4-2A3CBA8-2CA67-2(A11-)A3-3B5-A2-C5B3-A2-CA3BG2-2AB2CA4B2-A2B2C6BA3B2C4B2-2(A3B2C2EB3-)A3B2C3B4-2A3CBA8-2CA93-C-3B6-A2C5B2-2(A-)C4BG2-A-A2C5B2-3A2C5B-AB2A2C2BD3-AB2A2CBED3-A3B2CBEB3-A3B2C3B4-2A3CBA8-2CA78-2(A11-)A3-C2A2B3-A3-C2A3B2-A2-2C2A3B2-A-A2C2A-2B-AB2A2C2AH3-AB2A2C2AD3-A3B2C2AF3-A3B2C2AB4-2A3CBA9-CA68-C11-3(C9-A-)C-3A2B3-A-C-3A3B2-A-C3A-2B3-2(2AC4AD4-)ABC4AF4-ABC4AB5-A2C3A145-B9-AB6-2C3A7-2C3AB5-2(A2C3A6-)A2C3A156-I11-B7-3A9-3A41-
