model
size = 32 26 32, scale = 0.05, origin = -y
material 
  colors = A:#D2D2D2 B:#FEBFC7 C:#CAD2E9 D:#FFF E:#990027 F:#FF7200
voxels
40-B12A20-11A23-8A26-4A700-2(4A28-)4A761-2(10A22-)10A25-4A28-4A694-2(5B8A3B16-)5B8A3B19-2B8A22-2B8A25-4A29-2A629-2(7B8A5B12-)7B8A5B13-6B8A4B14-6B8A4B18-2B8A23-B7A27-2A596-2(8B8A6B10-)8B8A6B11-7B8A5B12-7B8A5B14-5B8A3B17-4B8A2B21-B7A26-4A562-2(8C9A3E4B8-)8C9A3E4B9-7C9A3E3B10-7C9A3E3B11-6C9A3E2B13-5C9A3CB16-3C9A2C20-C9A26-2A530-2(B8C9A2E6C6-)B8C9A2E6C7-8C9A2E5C8-8C9A2E5C9-7C9A2E4C11-6C9A5C14-4C9A3C17-3C9A2C22-6A28-2A498-4(B8C9ABE6C6-)B8C9ABE6C8-7C9ABE4C10-7C9AB5C12-5C9AB3C15-4C9AB2C19-C9A24-6A495-2(2B8C9A2E6CB4-)2B8C9A2E6CB5-B8C9A2E6C6-B8C9A2E6C7-8C9A2E5C9-7C9A6C11-6C9A5C13-5C9A4C17-2C9AC21-C9A493-2(2B8C9A2E6CB4-)2B8C9A2E6CB5-B8C9A2E6C6-B8C9A2E6C7-8C9A2E5C8-8C9A2D5C10-6C9A6C11-6C9A5C15-3C9A2C19-2C9AC356-C27-4DC103-2(2B8C9A2E6CB4-)2B8C9A2E6CB5-B8C9A2E6C6-B8C9A2E6C7-8C9A2E5C8-8C9A2D5C9-7C9A6C11-6C9A5C14-4C9A3C17-3C9A2C20-C9AC259-C32-C31-C25-2D4-C27-4DC70-2(3B8C9A2E6C2B2-)3B8C9A2E6C2B3-2B8C9A2E6CB4-2B8C9A2E6CB5-B8C9A2E6C7-8C9ADE5C9-7C9A6C10-7C9A6C12-5C9A4C15-4C9A3C19-C9A2C21-9A154-A2D6A31-AB31-3B2(31-B)25-D5-BD30-B27-4DB38-2(3B8C9A2E6C2B2-)3B8C9A2E6C2B3-2B8C9A2E6CB4-2B8C9A2E6CB5-B8C9A2E6C6-B8C9ADE6C7-8C9A7C9-7C9A6C12-5C9A4C15-4C9A3C18-2C9A3C19-C9AC23-7A3(D26-3B2-)D25-2A2D6A31-AB31-3B2(31-B)3(D30-B)27-4D7-2(22B6C2B2-)22B6C2B3-2B8C9A2E6CB4-2B8C9A2E6CB5-B8C9A2E6C6-B8C9ADE6C7-8C9A7C9-7C9A6C11-6C9A5C13-5C9A4C16-3C9A3C19-C9AC22-9AD24-2B2A2B2(2D24-6B)2D23-3A2D7A2(30-3A)2(31-A)2(D30-A)D26-4DA38-3(23B9A)23B7A2-23B7A3-22B6A5-21B5A7-8C16A8-8C16A10-6C14A13-5C13A15-4C12A19-C10AD21-9A2D21-3B4A2B2(2D21-9B)2D21-4A2D7A30-3A30-2A32-2(A31-)AD30-A27-4DA38-2(23B9A)23B11A21B7A2-2A21B7A3-A21B6A4-A21B6A5-26A7-24A9-22A11-20A14-16A19-11AD21-9A2D21-2B6AB2(2D21-9B)2D21-14A29-3A30-2A31-D32-A31-A27-4DA70-2(23B9A)23B11A21B7A2-2A21B7A3-A21B6A4-A21B6A5-16AF9A7-15AF8A9-14AF7A11-13AE6A14-11AE4A19-8AE2AD21-7AEA2D21-2B6AB2(2D21-9B)2D21-14A29-3A30-2A31-D32-A31-A27-4DA70-23B2(9A7B-15B)11A21B7A2-2A21B7A3-A21B6A5-21B5A7-24A8-24A10-20A13-18A15-16A19-11AD21-9A2D21-3B4A2B2(2D21-9B)2D21-13A30-3A30-2A32-2(A31-)AD30-A27-4DA38-23B2(7A2-7B-15B)7A3-A21B6A4-A21B6A5-21B5A6-21B5A7-8C16A9-7C15A11-6C14A13-5C13A15-4C12A19-C10A22-9AD23-3B2A2B2(2D23-7B)2D23-11AC30-A2C30-3C2(31-C)2(D30-C)D26-4DC38-23B2(7A2-7B-15B)7A3-2B8C18A4-2B8C18A5-B8C17A6-B8C17A7-8C16A9-7C15A12-5C13A15-4C12A17-3C11A20-C10A22-B7A3(D25-6B)D25-10A31-AC31-3C2(31-C)3(D30-C)27-2D2C7-22B4E2(4B2-22B4C)4B3-2B8C7A3E5C3B4-2B8C10A5C3B5-B8C10A5C2B7-8C10A5CB9-7C10A5C10-7C10A5C12-5C10A3C15-4C10A2C18-2C10A22-9A27-4B28-2(2B30-)2B29-9A31-AC31-2D2(C31-)C25-D5-CD30-C27-4DC39-23B2E3B4-23B2C3B4-2B3C12B2EB5C3B5-B8C4-A2-3E5C2B6-B8C10A5C2B7-8C10A5CB8-8C10A5CB9-7C10A5C11-6C10A4C14-4C10A2C17-3C10AC20-C10A23-7A262-C31-C25-2D4-C27-4DC71-23B2E3B4-23B2C3B4-B4C12B2AB5C3B5-9C7-3A5C2B6-9C10A5C2B7-8C10A5CB8-8C10A5CB9-7C10A5C11-6C10A4C15-3C10AC19-2C10A22-9A26-3A296-C27-4DC103-2(24B4C4-)B3C13B2AB3CB4C5-9C4-A2-3A7C6-9C10A7C7-8C10A6C8-8C10A5C11-6C10A4C13-5C10A3C17-2C10A21-C9A24-6A464-2(23B3C6-)3C13B2A2(B3C)6-9C4-A2-3A7C6-9C10A7C7-8C10A5C10-7C10A5C12-5C10A3C15-4C10A2C19-C9A24-6A496-24B2C6-24B2C7-2C21B2C7-4C4B4-B-9BC8-4C19BC9-3C19B10-7C10A4C14-4C10A2C17-3C10AC22-6A26-5A498-2C22B8-2C22B9-C22B9-3C4B4-B-9B10-3C19B11-2C18B12-6C10A3C17-2C10AC20-C9A24-5A531-2(21B11-)21B2(12-20B)13-18B14-3B2(10A23-)8A562-3(19B13-)19B14-18B15-16B19-9A25-5A596-2(4B12A3B13-)4B12A3B14-3B12A2B16-2B12A20-11A24-5A629-3B12A2B16-2B11A21-11A22-10A23-7A686-
