model
size = 27 25 32, scale = 0.05, origin = -y
material 
  colors = A:#EDE8FF B:#FFF C:#1E1729 D:#9AA9BC E:#CAD2E9
voxels
356-4BD5B19-8B21-4BE22-5B22-3BD532-10B19-8B21-4BD22-2BD2B22-4B556-3B10A3B13-3B8A3B15-D2B5A2B17-3B5A2B17-2BD4A3B20-4B23-4B503-15A3B9-B14A2DB9-2(3B10A3B11-)3B10ABDB14-3B4A3B17-E2B4A2BE20-4B24-DB169-2(A26-)8(A11-A14-)A10-2(18AB8-)3(16A2B9-)3B10A4B9-4B10A3BD13-3B4ABDE18-3B2A3B22-2B441-AB7-19AB7-18AB8-18AE8-18AB8-17AB8-B16A2B9-3B10A3B12-3B8A3B16-3B2A3B21-3BD413-2AB5-9A3C9AB5-2(9A3C8AB6-)9A3C8AD6-2(9A3C7AB7-)B8A3C5ABE8-3B6A3C3AD2B11-DBD4A3CA2B16-4BAC3BD20-E2B387-3AB10-2AC3-2C8AB10-3(2AC3-2C7AB11-)2A2(C3-2C6AB6-8A)C3-2C5AB7-B7AC3-2C3A2B9-2B5AC3-2CABE12-4B2AC-2C2BAB14-3E2BAC2B24-E360-3AB10-2AC5-C7AB10-3(2AC5-C6AB11-)2AC5-C6AB7-6AC5-C5A2B7-6AC5-C4AB9-6AC5-C3A2B7-B7AC5-C2AB10-E2B4AC3-2C3B13-E2B3A3C2B22-3B358-3A3(B10-2AC6-C6A)D10-2AC6-C6AB10-2(2AC6-C5AB11-)2AC6-C4AB8-6AC6-C3AB6-B8AC6-C2AD8-3B5AC5-C3B10-2EB3ADA5CB21-2A3B356-4AB19-C6AB19-3(C5AB10-2AC7-)C4AB11-2AC7-C4AD11-2AC7-C3AE8-6AC7-C2A2B4-B9AC7-CABD6-3B6AC6-C2BA8-2EB3AD2A6CB20-3ABDB355-4AB8-A3-C7-C5AB8-A3-3(C7-C4AB9-4A)2(C7-C3AB10-4A)C7-C2AB10-5AC7-C2AB4-D10AC7-CAB6-2B8AC6-C2B8-2(E4A)6CB19-2AD2A2B354-5AB7-2(A3-C7-C5AB8-)2(4AC7-C5AB8-)2(4AC7-C4AB9-)4AC7-C3AB9-5AC7-C2AB4-B10AC7-CAB5-2B9AC7-C2B6-EB7AEA7CD18-6A2B353-2(5AB7-A3-C8-C)2(4AB8-4AC8-C)4AD8-4AC8-C3AB9-4AC8-C3AD9-4AC8-C2AB9-5AC8-C2AB3-11AC8-CAB4-DB9AC7-C2B6-EB3AE5A7CB18-AE4A2B353-2(C4AB7-A3-AC8-)3(C3AB8-5AC8-)2(C2AB9-5AC8-)CAB9-6AC8-CAB3-12AC8-CB4-B11AC7-CB6-B6AD4A7CB17-3ADADE2B352-2(C4AB7-A3-AC8-)C4AB7-5AC8-C4AD7-5AC8-C4AB7-2(5AC8-C3AB8-)5AC8-C2AB8-6AC8-CAB3-12AC8-CB4-B11AC7-C2B5-B3AD7A7CB17-8AE352-2(C4AB7-A3-BC8-)3(C4AB7-3A2BC8-)2(C3AB8-3A2BC8-)C2AB8-4A2BC8-C2AB2-10A2BC8-CAB3-10A2BC8-CB4-BAE7A2BA8CB16-B3A2(DA)2B351-2(C4AB7-A3-BC8-)3(C4AB7-3A2BC8-)C3AB8-3A2BC8-C3AD8-3A2BC8-C2AB8-4A2BC8-C2AE2-10A2BC8-CAB3-10A2BC8-CB4-B9A2DA8CB16-D7A2B351-C4AD2(7-A3-AC8-C4AB)2(7-5AC8-C4AB)7-2(5AC8-C3AB8-)5AC8-C2AB8-6AC8-CAB3-12AC8-CB4-B11AC7-CBD5-BAD3AD5A7CB17-3ADE3AB352-2(C4AB7-A3-AC8-)3(C3AB8-5AC8-)2(C2AB9-5AC8-)CAB9-6AC8-CAB3-12AC8-CB4-B11AC7-CB6-BAE5AD3A7CB17-6AE2B352-2(5AB7-A3-C8-C)2(4AB8-4AC8-C)4AD8-2(4AC8-C3AB9-)4AC8-C2AB9-5AC8-C2AB3-11AC8-CAB4-2B9AC7-C2B7-B2AD4AEA7CB18-5AD2B353-5AB7-A3-C7-C5AB8-A3-C7-C5AD2(8-4AC7-C5AB)8-4AC7-C4AB9-4AC7-C4AD9-4AC7-C3AB9-5AC7-C2AB4-B10AC7-CAB5-2B9AC7-CBA7-B9A7CB18-3AD2A2B353-4AB8-A3-C7-C5AB8-A3-3(C7-C4AB9-4A)2(C7-C3AB10-4A)C7-C2AB10-5AC7-C2AB4-B10AC7-CAB6-2B8AC6-CBD8-EB3ADEADA6CB19-5A2B352-2(6AB8-A10-C)2(5AB9-3AC7-C)5AD9-2(3AC7-C4AB10-)3AC7-C3AB10-4AC7-C2A2B4-B9AC7-CAB7-D2B6AC6-C3B8-2EB6A6CB20-2AE2BD353-5A2(B9-A9-C6A)2(B9-3AC6-C6A)B9-2(3AC6-C5AB10-)3AC6-C4AB10-4AC6-C3AB6-B8AC6-C2AB8-3B5AC5-C3B9-3EB5A5CB21-2A3B354-5AB9-3AC5-C7AB9-4(3AC5-C6AB10-)3AC5-C5A2B10-3AC5-C4AB8-7AC5-C3A2B7-B7AC5-C2AB10-2BD4AC3-2C2BE10-4E2B3A3C2B22-3B356-5AB5-7AC3-2C8AB5-3(7AC3-2C7AB6-)2(7AC3-2C6AB7-)7AC3-2C5AD8-7AC3-2C3ABD9-2B5AC3-2CA2B12-4B2AC-2C2BAB13-4E2BAC2B24-B354-8AB6-8A3C9AB6-3(8A3C8AB7-)2(8A3C7AB8-)8A3C5A2B9-2B6A3C3A3B12-DB4A3CA3B15-4BAC4B20-E2B381-7AB7-19AD7-18AB8-18AD8-18AB8-17AB9-16A2B9-3B10A3B12-3B8ABEB16-3B2A3B21-4B395-2(18AB8-)3(16A2B9-)D2B10A4B10-3B10A3BD13-3B4A2BD18-3B2A3B22-2B114-11(A26-)A10-16A3B7-3B14A3B9-2(3B10A3B11-)3B10ABDB14-3B4A3B17-3B4AE2B20-2BAB24-BA156-4(E26-)6(A26-)A22-3B10A3B13-3B8A3B15-2(3B5A2B17-)3B4A3B20-4B23-2BAB176-
