model
size = 28 29 19, scale = 0.05, origin = -y
material 
  colors = A:#6C9 B:#FF1AAB C:#09FFEA D:#6F9 E:#CF0 F:#6CF G:#0F0 H:#0D0 I:#FFF J:#6F6 K:#F03 L:#222 M:#888 N:#EEE O:#555
voxels
118-17(2CD2C6-2BD2B12-)2CD2C6-2BD2B320-2CD2C6-2BD2B460-2CD2C6-2BD2B292-2CD2C6-2BD2B12-2CD2C6-2BD2B460-2CD2C6-2BD2B12-2(2CD2C6-2BD2B264-2CD2C6-2BD2B516-)2CD2C6-2BD2B236-2CD2C6-2BD2B12-2CD2C6-2BD2B516-2CD2C6-2BD2B12-2CD2C6-2BD2B208-2CD2C6-2BD2B572-2CD2C6-2BD2B208-5D6-5D572-5D6-5D208-5D6-5D36-6(2A20-2A4-)2(DA20-AD4-)DA20-AD288-5D6-5D152-16A12-16A9-22A6-22A5-5(24A4-)6A12-6A5-4A2-10G2-4A6-4A-2G8K2G-4A5-D4A-G10KG-4AD5-4A-GK8GKG-4A6-4A-12G-4A6-4A2-N2LN2GN2LN2-4A6-5A-NILN2GNILN-5A6-5A-10G-5A7-4A2-2G4-2G2-4A8-5A4-2A4-5A9-18A11-2(16A12-)16A13-14A15-12A98-16A12-16A9-22A6-22A5-5(24A4-)6A12H6A3-FJ4A2H10A2H4AJF2-FJ4AH12AH4AJF3-D4AH12AH4AD5-2(4CHC11AH4C6-)4C2H10A2H2(4C6-4COH10AHO)4C7-4C2H2A4H2A2H4C8-5C4H2A4HA4C9-4C11A3C11-2(3C11A2C12-)3C11A2C13-2C11AC15-12A17-2(A8-A18-)5(JC)15-16A12-16A9-22A6-22A5-5(24A4-)24A2-IFJ22AJFI-FJ22AJF3-D22AD5-4(5E12A5E6-)5E12A5E7-4E12A4E8-4E12A4E9-3E12A3E11-2(2E12A2E12-)2E12A2E13-E12AE15-12A17-2(A8-A18-)5(EJ)15-16A12-16A9-22A6-22A5-5(24A4-)24A3-FJ22AJF2-FJ22AJF3-D22AD5-4(5B12A5B6-)5B12A5B7-4B12A4B8-4B12A4B9-3B12A3B11-2(2B12A2B12-)2B12A2B13-B12AB15-12A17-2(A8-A18-)5(JB)15-16A12-16A9-22A6-22A5-5(24A4-)24A5-22A6-22A5-D22AD5-4(22A6-)22A7-20A8-20A9-18A11-2(16A12-)16A13-14A15-12A155-14A11-20A6-6(24A4-)2(D22AD4-)D22AD6-3(20A8-)L18AL9-I16AI11-I14AI12-I14AI13-I12AI15-I10AI16-I10AI17-I8AI18-6I2M2I24-2M183-13(20A8-)20A9-18A11-16A12-16A13-14A15-12A16-12A17-10A18-10A239-4F8A4F11-2F14A2F9(10-F16AF)10-2D14A2D11-2D12A2D13-2D10A2D15-D10AD16-2D8A2D17-D8AD18-2D6A2D19-D6AD20-8D272-8A19-10A17-12A15-2A3C4A3B2A13-3A3C4A3B3A12-3AC8EB3A12-3A2E6L2E3A12-3AEL6ELE3A12-3A2E6A2E3A12-16A12-2F9AM2A2F13-2FL7IML2F15-2F8A2F17-10F47-8A20-8A21-A4DA22-6A384-2(3C4-3B18-)C3E2B3EB18-2E6-2E18-E-6E-E18-2E6-2E54-M27-M374-
