model
size = 28 29 19, scale = 0.05, origin = -y
material 
  colors = A:#F4A7B9 B:#CB1B45 C:#DB4D6D D:#FFF E:#F8C3CD F:#533D5B G:#FEDFE1 H:#884C3A I:#6A4028 J:#9F353A K:#904840 L:#B9887D M:#986DB2 N:#6A4C9C O:#F19483 P:#9E7A7A Q:#F596AA R:#E03C8A S:#F7D94C T:#64363C U:#854836 V:#994639 W:#AB3B3A X:#B54434 Y:#F75C2F Z:#D7C4BB Aa:#B55D4C Ab:#F17C67 Ac:#CC543A Ad:#B5495B Ae:#D0104C Af:#BF6766 Ag:#9A5034 Ah:#EB7A77 Ai:#724832 Aj:#D75455 Ak:#EEA9A9 Al:#A35E47 Am:#554236 An:#A96360 Ao:#005CAF Ap:#C46243 Aq:#D05A6E Ar:#86473F As:#B19693 At:#8E354A Au:#E16B8C Av:#734338 Aw:#CB4042 Ax:#954A45 Ay:#DC9FB4 Az:#E87A90 Ba:#268785 Bb:#888 Bc:#222 Bd:#C73E3A Be:#E83015
voxels
118-17(2AB2A6-2AB2A12-)2AB2A6-2AB2A320-2AB2A6-2AB2A460-2AB2A6-2AB2A292-2AB2A6-2AB2A12-2AB2A6-2AB2A460-2AB2A6-2AB2A12-2(2AB2A6-2AB2A264-2AB2A6-2AB2A516-)2AB2A6-2AB2A236-2AB2A6-2AB2A12-2AB2A6-2AB2A516-2AB2A6-2AB2A12-2AB2A6-2AB2A208-2AB2A6-2AB2A572-2AB2A6-2AB2A208-5B6-5B572-5B6-5B208-5B6-5B36-GA20-AL4-HA20-AAq4-QA20-AAv4-BA20-AK4-AlA20-2A4-2A20-2A4-AcA20-AAj4-JA20-AAt4-AbA20-AAx288-5B6-5B152-16A12-6AKAyAkQ6A9-9AAwAbAhX9A6-9AAsCAnY9A5-O4A2IAg2AVOAdH2AAvUE4AK4-5AAmAzAf2AZAzAdQ2AKAyT5A4-5AAfXD2AAhXAuAm3AAiAp5A4-5AArAxGAgAfAnXYAhAmIAqAzT5A4-HAUAcAgBdAaKYAhGUAqAyAgBdJAeAkGKVAAt4-2AH18-Ak2A4-2AG3Ao2-2S-Ba-3N2-2R-O2A4-2AO2-Ao2(-S)-Ba2(-N)2(-R)-U2A4-AfAAr2-Ao2(-S)-Ba2(-N)2-2R-LAL5-AW2-Ao2(-S)-Ba2(-N)2(-R)-AlA6-AAu2-Ao2-2S-Ba2(-N)2-2R-BA6-AI18-AdA6-AVAwXAfAsAzXCAaOAiAgAiQJAqAkAbLZA6-4AAnEAe2AAbUBT2AAeAkAv4A7-3A2PAp2AJLAlE2ACAjH3A8-3AGTC2ABeAlAfQ2AAbIAi3A9-2AHIAy2AZBWAw2AApAiB2A11-6AG2AdAc6A12-6AArZEK6A12-6ABeQJD6A13-14A15-12A98-16A12-16A9-22A6-22A5-U22AJ3(4-24A)4-Ad22AO4-24A3-E24AE2-E24AE3-HJAw18AAaAcH5-BAt18ALB6-BI18AAsB6-BO18AYB6-BAtKAfE13AAcAeJB6-BAm2DW12AU2VAjB7-BZGL12AEAaAkB8-BAApAq12ATZOB9-BAbAv12AApAhB11-2(2B12A2B12-)2B12A2B13-B12AB15-12A17-2(A8-A18-)2(AB)2A2(BA)15-16A12-16A9-22A6-22A5-H22AAl3(4-24A)4-W22AU4-24A2-DE24AED-E24AE3-E22AT5-4(22A6-)22A7-20A8-20A9-18A11-2(16A12-)16A13-14A15-12A17-2(A8-A18-)2(AB)2A2(BA)15-16A12-16A9-22A6-22A5-H22AP3(4-24A)4-Ay22AAr4-24A3-E24AE2-E24AE3-G22AAt5-BDZAxW12A4CB6-B2AAaAu12A4CB6-BAuAePI12A4CB6-BAlAgArV12A4CB6-BQGAuE12A4CB7-BKGT12A3CB8-BC2Ae12A3CB9-BVAc12A2CB11-BY12ACB12-BP12ACB12-BI12ACB13-B12AB15-12A17-2(A8-A18-)2(AB)2A2(BA)15-16A12-16A9-22A6-22A5-V22AAj3(4-24A)4-An22AJ3(4-24A)4-Y22AJ5-4(22A6-)22A7-20A8-20A9-18A11-2(16A12-)16A13-14A15-12A155-14A11-20A6-X22AX4-Y22AX4-H22AU4-Q22AI4-Am23A4-24A4-Ag22AAa4-Ad22AAm4-At22AAs6-3(20A8-)Bc18ABc9-D16AD11-D14AD12-D14AD13-D12AD15-D10AD16-D10AD17-D8AD18-6D2A2D24-2Bb183-GAgCGTAsAxAnLBAhApQEYAnLAiPAf8-O18AAn8-Ar18AP8-W18AG8-Au18AH8-I18AQ8-V18AB8-E18AAl8-T18AAi8-Ae18AAc8-Ac18AJ8-Y18AAb8-P18AP8-IO16AAqAz9-WK14ABeAj11-Aw14AAj12-AsAk12ACAv13-WAd10AAxAb15-E10AAa16-AaAm8AKP17-J8ABd18-2LHAjWAhLKEZ239-16A11-10(18A10-)18A11-16A13-14A15-12A16-12A17-10A18-10A19-8A20-8A272-8A19-10A17-12A15-14A13-6(16A12-)16A13-2ABc7DABc2A15-12A17-10A47-8A20-8A21-A4CA22-6A360-2F25-4F24-4F23-2F2-2F22-F-2M-F23-4M24-4M25-2M30-Bb27-Bb162-4C208-
