model
size = 15 30 10, scale = 0.05, origin = -y
material 
  colors = A:#777 B:#555 C:#888 D:#222 E:#F30 F:#0F0 G:#9F0 H:#F60 I:#F90 J:#444 K:#3F3 L:#B00 M:#6F0
voxels
120-3(3B-)2(6B2(-3B)-)3B63-2AC6A2(6-2AH4E2A)6-2AHI3E2A6-2AH2ELE2A6-2AH4E2(2A6-2AHIELE2A6-2AHI3E)2(2A6-2AHI3E)2A6-2AC6A168-31AC14AC28A360-29A3(2C13A)C14AC-A11BA2-13A2-6BA6B2-5ABAB5A6-2(AB)A6-5ABAB5A2-6BA6B2-13A2-6BA6B2-5ABAB5A6-2(AB)A6-4(5ABAB5A2-)13B106-30AC13AC60A-2(13A2-)B11AB2-13A3-G2F5A2GF3-2(13A2-B11AB2-)13A3-2GF5AFMK3-4(13A2-)B11AB106-15AC13AC75A-C11AC2-12AC2-BA9-AJ2-2A9-AC3-F9-F3-2A9-AC2-JA9-AJ2-CA9-AC2-BA9-AJ2-2A9-AC3-F9-M3-3(CA9-AC2-)2A9-AC2-BA9-AB-3(3AD)3(6A2(D3A)D)6A2(B3A)B138A-13A2-C12A2-JA9-AB2-2A9-2A3-G9-F3-2(2A9-2A2-BA9-AB2-)2A9-2A3-F9-K3-4(2A9-2A2-)BA9-AB-3(3AD)198A-2(13A2-)BA9-AB2-2A9-2A3-F9-G3-2(2A9-2A2-BA9-AB2-)2A9-2A3-G9-G3-4(2A9-2A2-)BA9-AB-3(3AD)198A-2(13A2-)BA9-AB2-2A9-2A3-F9-G3-2(2A9-2A2-BA9-AB2-)2A9-2A3-G9-K3-4(2A9-2A2-)BA9-AB-3(3AD)198A-2(13A2-)B11AB2-13A3-3GF4AG2F3-13A3(2-B11AB)2-13A3-3G7FG3-4(13A2-)B11AB-C4(2A2(D3A)D2A2C)2A2(D3A)D4AC75AC2AC10ABJ2BJ8B2(2ABC2AC7AB)A-3(BC10AB2-)AC10AC17-4(AC10AC2-)AC10AC17-AC11A2-AC10A2(C2-AC2AC7A)C2-13B-
