model
size = 13 25 15, scale = 0.05, origin = -y
material 
  colors = A:#555 B:#C0C C:#DDD D:#C0F E:#BBB F:#222 G:#EEE H:#111
voxels
9-E12-A11-2A11-2(A12-)A324-A10-3A322-2(A324-)A322-5A7-2(7A6-)7A5-9A4-9A5-7A20-5A7-4(7A6-)7A7-5A137-7A3(6-A5BA)5-2(A7BA4-)3A3B3A7-3C8-2A3B2A5(6-A5DA)5-9A3(4-2A5-2A)2(5-A)72-C3-C7-7A3(6-A5BA)5-2(A7BA4-)3A3B3A7-3C8-2A3B2A5(6-A5DA)5-2AD3ADA5-2(A-A3-A-A4-)A-A3-A-2(A5-)A72-C3-C7-AB3ABA3-2E-A5BA-4E-A5BA-2E-C-A5BA-C2-CA7BAC2-C9BC3-C2A3B2AC7-3C8-2A3B2A6-A5DA6-7A3(6-A5DA)6-7A124-C3-C7-7A3-FE-A5BA-EF2E-A5BA-2E3-A5BA5-2A5B2A4-3A3B3A4-9A18-3(7A6-)2(GHGAGHG6-)2G3A2G97-3C-3C6-3C-3C20-C3-C9-3C9-2CE2C2(8-C3EC)8-5C9-3C34-2F3A2F5-2F5A2F135-2(3C-3C6-)3C-3C7-C3-C8-G3-G127-H139-2(3C-3C6-)3C-3C292-3C-3C6-3C-3C305-FCF-FCF302-
