model
size = 12 6 28, scale = 0.05, origin = -y
material 
  colors = A:#111 B:#EEE
voxels
14-5A56-6A65-8A63-10A62-11A9(60-12A)B2(10-2B)10-3B8-2B-10B-12AB2(10-2B)10-3B8-2B-10B2(-13A2(10-2A)10-3A8-2A-10A)2(-12AB2(10-2B)10-3B8-2B-10B)-2(13A10-2A10-3A8-2A-10A13-)2(12AB10-2B10-3B8-2B-10B13-)12A60-2(11A61-)10A63-8A63-
