model
size = 19 6 9, scale = 0.05, origin = -y
material 
  colors = A:#111 B:#555 C:#888
voxels
5-10A9-2BC2B5A2(14-B4A)43-16A3-BC2B10-2(2A17-)A13-C4A23-18A-B15-2A17-2A16-2A17-A13-C4A4-19AC2(3(16-2A)17-A13-B4A4-19AB)3(16-2A)17-A13-C4A4-18A-B15-2A17-2A16-2A17-A13-B4A5-16A3-2BCB10-2(2A17-)A13-B4A28-10A9-2BC2B5A2(14-B4A)42-
