model
size = 13 27 13, scale = 0.05, origin = -y
material 
  colors = A:#6FF B:#CFF C:#DDD D:#E00 E:#EEE F:#BBB
voxels
56-3(5A8-)2(5B8-)4(5A8-)2(5B8-)5A8-5A138-5A2(8-5B)8-5A6-3(2AB3-B2A4-)2(3B3-3B4-)4(3A3-3A4-)2(3B3-3B4-)3A3B3A4-3A3C3A7-3C125-7A2(6-7B)6-A5BA4-3(8A-2A2-)2(3B5A-AB2-)4(8A-2A2-)2(2B6A-2B2-)2A7B2A2-2A7C2A4-7C9-F112-9A2(4-2BA6B)4-3A5BA3-3(11A2-)2(3B7AB2-)4(11A2-)2(2B8AB2-)A9BA2-A9CA3-9C120-11A2(2-2B2A3B3AB)2-4A3B4A-A2(B9AB2A)B9ABA2B9A4B9A2BA3(B12A)B11A2B9A4B9A2BA10B4A9C2A2-9C2(5-F)108-11A2(2-2B2ABAB3AB)2-4A3B4A-A2(B12A)B11A2B9A4B9A2BA3(B12A)B11A2B9A4B9A2BA11B2A11CA-11C119-5A-5A2(2-2B2AB-B3AB)2-4AB2(AB4A-)2(7AB4A-)6A2B4A-4A4B4A-4A2BA3(B4A-7A)B4A-6A2B4A-4A4B4A-4A2BA11B2A5C-5CA2(-5C)7-4(D12-E12-)D7-11A2(2-2B2A3B3AB)2-4A3B4A-A2(B12A)B11A2B9A4B9A2BA3(B12A)B11A2B9A4B9A2BA11B2A11CA-11C4-F5-F100-E7-11A2(2-2B2A3B3AB)2-4A3B4A-A2(B9AB2A)B9ABA2B9A4B9A2BA3(B12A)B11A2B9A4B9A2BA10B4A9C2A2-9C112-D8-9A2(4-B6A2B)4-9A3-3(11A2-)2(3B7AB2-)4(11A2-)2(2B6A3B2-)A9BA2-A9CA3-9C8-F103-E9-7A2(6-7B)6-A5BA4-11A2(2-9ABA)2(2-3B6A2B)4(2-11A)2(2-2B6A3B)2-A8B2A2-2A7C2A4-7C113-D10-5A2(8-5B)8-5A6-3(2AB3AB2A4-)2(3B3A3B4-)4(9A4-)2(2B5A2B4-)3A3B3A4-3A3C3A7-3C115-E62-3(5A8-)2(5B8-)4(5A8-)2(5B8-)5A8-5A134-
