model
size = 27 19 23, scale = 0.05, origin = -y
material 
  colors = A:#84492C B:#000 C:#A17A43 D:#FEEA41 E:#037C30 F:#A9523A G:#94453E H:#8E695F I:#FFF J:#01512E K:#259A3E L:#1E1729 M:#BA5F42
voxels
249-B-3B26-B24-B-B29-2A49-B26-B319-B-3B20-2BAB3A15B5-6BLB4A19-L3B2(A2-A19-4B)23-3B24-4B243-B20-8B18-9B17-2BA3BA7B12-B2AB3AB7A5B7-B18A-B6-5B14A-4B3-5B14A9-4B7A4-3A12-4A3BA5-A14-4B212-2B4-B3-B14-12B14-B8AB16-B9AB16-B10A8B7-12B8AB6-14BA4BAB6-B2F2A9D2H3GAB6-B4A6D3A2H3GA7-B4A5I10A8-2B7AB2A3-2A12-6AB22-5B22-2BJEB131-B7-B-B15-2B3-7B13-8B3A10B5-B8A6B11-B9A6B10-B7A3-2A-6B7-12B8A4B3-14BA4BA2B4-B4F10D2H3GA2B4-B16A3GAB6-B20A7-B18A9-5A3EB19-3AI3EB21-2BEKJB129-2B-12B12-8B4A3B10-2B3A3B6A2B10-B14A2B8-2B15A2B7-B8A3-6A3B6-14B7AB5-14B6CAB5-B-3F8DH6CAB5-B13A7CA6-B20A7-B7A-2AB8A8-5A3EB9A9-4AB3E-2AMA17-2BJ2EB103-B-7B17-3B7A3B13-2B6A-5A2B9-2B15A5B4-B17A8-2B17A7-B8A4-7A7-14B6A6-15B5C3A4-B6F7DH5C3A5-B13A5C3A6-B20A7-B6A2-2AB8A8-5A4E-9A8-4AB2E-E10A11-2BKEJB78-6B19-2B6A3B15-2B10AB13-2B6A-5AB10-2B15A5B4-B17A7-2B18A6-B20A7-14BC3A-A6-15B4C6A2-B6F6D2H4C6A2-B14A4C6A3-2B21A6-B6A2-12A7-B4A3E2-10A7-4AI2E2-10A11-2BJEKB78-6B18-3B6A3B15-2B10AB13-B7A-5AB10-2B15A8-2B17A7-B19A6-B20A6-15BC3A-A6-15B4C6A2-B6F6D2H4C6A-B15A4C6A2-3B15AG6A4-3B5A2-2AB10A6-5A2E3-10A7-3A2B4E11A11-BEJEB78-6B18-3B6A3B15-2B10AB13-B7A-5AB10-2B15A8-2B17A7-B20A5-B21A4-16B3CA-4A3-15B4C-5A2-B6F6D2H4C-5A-B15A4C-5A2-3B15AG-5A4-4B6A2-5A-5A5-B3AB-4E5AG-5A6-3A-B4E11A11-BKEKBA5-A47-2B20-B-3B2AB18-3B6A3B15-2B10AB13-B7A-5AB10-2B15A8-2B17A7-B20A5-B21A4-16B5C4A3-15B5C5A2-B6F6D2H5C5A-B15A5C5A2-3B15A2G5A4-6B2-15A5-B3A-4B2D3AH2G5A6-3A-2B-B12A11-3B-B3A4-A20-2A24-2B20-B-3B2AB18-3B6A3B15-2B10AB13-B7A-5AB10-2B15A8-2B17A7-B20A5-B21A4-16B4C-4A2-BF14B5C5A2-B6F6D2H5C5A-B15A5C5A2-3B15A2G5A4-6B2-15A5-B3A3B-B4D2H3G4A6-3A-4B12A11-5B3A4-A20-2A24-2B22-3B2AB18-3B6A3B15-2B10AB13-B7A-5AB10-2B15A8-2B17A7-B20A5-B21A4-16B4C-4A3-15B5C5A2-B6F6D2H5C5A-B15A5C5A2-3B15A2G5A4-4B19A6-3A5B4A2H3G3A7-3AB-3B12A12-4BA5-A45-B25-6B18-3B6A3B14-3B10AB13-B7A-5AB10-2B15A8-2B17A7-B20A5-B21A5-15B5C4A5-13B5C5A3-B4F7D2H5C5A2-B14A5C5A3-2B15A2G4A6-2B7AB11A7-7AB-B3AH3G3A7-3A2B2E-B11A11-BKEJB78-6B18-3B6A3B15-2B10AB11-3B7A-5AB10-2B15A8-2B17A7-B19A6-B20A7-2(14B5C4A4-)B4F7D2H5C4A4-B13A5C4A5-B15A2G4A6-B8AB11A7-B6AEBE10A7-4AI3EB10A11-2B3EB78-6B20-B6A3B15-2B10AB12-2B7A-5AB10-2B15A8-2B17A2(7-B19A)8-13B4C4A6-13B5C3A5-B3F9DH5C3A5-B13A5C3A6-B15A2G3A7-B5AG2AB9A9-5A-AE2B8A9-4AB3EB9A12-B-JEJB105-7B18-2B7A3B13-2B6A-5AB10-2B15A5B3-2B17A2(7-B19A)8-13B3C4A7-13B5C2A6-B2F-9DH5C3A5-B15A3CA8-B16AGA9-B8AB9A9-4AG2AEB9A9-4AB3EB2AMA17-B-KJEB107-B24-9B15-8B4A3B9-3B12A-B9-B15A2(10-B16A)9-BAB2A9B2C4A7-BAB2A9B3C3A8-2B2A9D3C3A8-2B2A7D8A9-B2A6I9A10-2AIA2-2AB9A9-7AEB8A11-3AI3EB21-2B2EKB164-4B13-21B5-B12A7B6-B13A2B11-B13A3B9-3BA9BC4A5B4-3BA9B5CA10-B10A5CA10-B14ACA11-14AGA11-4AB2ABA4-3A11-4ABAB22-2B2EB22-2BJEB191-B-B15-12B2(14-13B)15-6B5A4B11-7B9A11-B15A11-B4AB10A12-B2AB-4A4-2A13-3B-3BA5-A14-2B-B26-B24-2B272-2B2(22-3B2A)10B8-7B2AB17-7B3A18-5BA-A19-4B-B22-B3-B23-3B24-B300-2A25-2A24-3A24-A2-A510-2A174-
