model
size = 29 16 32, scale = 0.05, origin = -y
material 
  colors = A:#444 B:#00E C:#E00 D:#60C E:#F3F F:#F30 G:#FF0 H:#EEE I:#200 J:#DDD K:#111 L:#00F
voxels
330-3E432-3E460-2CA2C26-D431-2C3A2C24-3D375-D27-3D24-C5DC23-5D26-D317-3E25-2CA2C23-2C3A2C22-C5AC22-2C3A2C23-2CA2C25-3C259-B26-C3BC23-3BA2BC22-2B3ABC21-2B5ABC21-2B3A2B22-7B23-5B26-B289-B27-B2A4-D20-B3AB2-3D20-3B2-B4D25-3D27-D282-3E25-B2A2C2-3E18-B4A4CA2C17-B5A2C3A2C16-6BC5AC22-2C3A2C23-2CA2C25-3C50-G173-D26-2EA2E23-B5A6E17-B11AC15-B12AC16-6B7AD21-B5AC22-B5AC23-2CA2C26-D21-3G171-3D24-2E3A2E22-B6A6E15-B12AC15-B13AD14-6B8AD20-B7AD21-B5AC22-2C3A2C24-3D19-5G169-5D23-E5AE21-B7A6E15-2(B13AD14-)6B8A2(D20-B7A)D21-C5AC23-5D19-3G171-3D24-2E3A2E22-B6A6E15-B12AC15-B13AD14-6B8AD20-B7AD21-B5AC22-2C3A2C24-3D20-GFG27-F115-B27-DAD25-E2ABE20-B2-B3ABA6E13-3B-B3AB7AC2-D8-5B4AB7AC-3D8-3B-2B2A2B7AB4D8-B4-BAB-B5AC-3D15-B2-B5AC2-D20-2CA2C26-D19-7F23-2FA2F25-3F55-3B25-2BA2B23-2B3A2B18-3E-B5AB-3B13-2BA2B7AE3A2E-3E6-HB3AB13A2CA2C5-H18AC3A2C4-HB3AB18AC5-JBA4B4AB5ABC3A2C6-3C2-C3AB-B3AB-2CA2C13-3D2(3-3C)38-G2-7F2-G19-F5AF23-2FA2F26-F26-B3AL23-B5AB19-D2-B5AB2-D14-2EA2E7A2BA2B11-B17A6E5-H23AC4-K23AC4-H12AB3AB7AD3-H12A-BAB-B5AC5-2CA3C5A2(B2-)B5AC7-D3-2DA2D7-2CA2C14-D11-D9-4G7F4G18-F5AF22-2F3A2F24-FAF24-B5AB22-B5AB18-4D7A4D12-2E15A2B10-B18A6E3-I24AC3-I25AD2-I25AD3-H12A5B7AD3-2C3AC7A5-B5AC6-3D-2D3A2D5-2C3A2C12-3D9-3D7-4G9F4G16-F7AF21-F5AF23-F3AF23-B5AB21-B7AB16-4D9A4D11-E17AB9-I19A6E3-C25AD2C26AD2-C25AD2-I14A3B8AD3-C12AB3-B7AD4-6D5AD5-C5AC11-2(5D7-)4G7F4G18-F5AF22-2F3A2F24-FAF24-2B4AB22-B5AB18-4D7A4D12-2E15A2B10-B18A6E3-I24AC3-I25AD2-I25AD3-H12A5B7AD3-2C3AC7A5-B5AC6-3D-2D3A2D5-2C3A2C12-2(3D9-)G2-7F2-G19-F5AF23-2FA2F26-F26-2B2AB23-B5AB19-D2-B5AB2-D14-2EA2E7A2BA2B11-B17A6E5-H23AC4-K16AB6AC4-H12AB3AB7AD3-H12A-BAB-B5AC5-2CA3C5A2(B2-)B5AC7-D3-2DA2D7-2CA2C14-D11-D13-7F23-2FA2F25-3F55-3B25-2BA2B23-2B3A2B18-3E-B5AB-3B13-2BA2B7AE3A2E-3E6-HB3AB13A2CA2C5-H18AC3A2C4-HB3AB18AC5-JBA4B4AB5ABC3A2C6-3C2-C3AB-B3AC-2CA2C13-3D2(3-3C)43-GFG27-F115-B27-DAD25-E3AE20-B2-B5A6E13-3B-B11AC2-D8-5B12AC-3D8-3B-2B3AB7AB4D8-B4-3B-B5AC-3D15-B2-B5AC2-D20-2CA2C26-D21-3G171-3D24-2E3A2E22-B6A6E15-B12AC15-B13AD14-6B8AD20-B7AD21-6AC22-2C3A2C24-3D19-5G169-5D23-E5AE21-B7A6E15-2(B13AD14-)6B8A2(D20-B7A)D21-C5AC23-5D19-3G171-3D24-2E3A2E22-B6A6E15-B12AC15-B13AD14-6B8AD20-B7AD21-B5AC22-2C3A2C24-3D21-G173-D26-2EA2E23-B5A6E17-B11AC15-B12AC16-6B7AD21-B5AC22-B5AC23-2CA2C26-D224-3E25-B3AB2-3E18-B5AB2CA2C17-BA3C6A2C16-6B6AC22-BC3A2C23-2CA2C25-3C224-E26-2EA2E23-B5AC22-B5AC2-D18-B2(A2C)A4D18-L2AD3A5D17-6BA-3D19-5B3-D22-B259-3E25-2CA2C23-2C3A2C22-C5AC22-2C3A2C23-2CA2C25-3C317-D27-3D24-C5DC23-5D26-D402-2C3A2C24-3D431-2CA2C26-D132-
