model
size = 13 16 11, scale = 0.05, origin = -y
material 
  colors = A:#F96 B:#BBB C:#DDD D:#EEE E:#F99 F:#E00 G:#039
voxels
124-4(A12-)A128-5C21-3A10-B2A6-2(4B2A7-)5BA7-5DA90-DC11-4C2(11-AC)8-2ABA6-3A3BE4-2(2B4AC6-)2B4ABAE4-2D4ADA91-C13-C12-C11-BC5-3A2-2BC4-5A-BA3-3B4AG5-3B4AC5-3B6AE3-3D4A2DA7-2A14-2(2C11-)3C10-4C9-6C7-2CD3C7-4C11-2B5-3A3-BC4-5A-2BC3-4AFAFBA3-2(3B4AC5-)3B6AE3-3D4A2DA6-4A13-2(2C11-)3C10-4C9-6C7-2CD3C7-4C11-2B5-AFA3-BC4-5A-B2C3-4A3FB2A2-3(3B7A3-)3D4A2DA6-4A13-2(2C11-)3C10-4C9-6C7-2CD3C7-4C11-2B5-3A3-BC4-5A3BC3-6AFBA3-2(5B2AC5-)5B4AE3-3D4A2DA6-4A79-2D13-C11-2C11-BC5-3A-3BC4-5A-BA3-5B2AG5-5B2AC5-5B4AE3-3D4A2DA7-2A79-D11-D4C12-C10-2AC9-B2A6-3A-BAE4-2(4B2AC6-)4B2ABAE4-2D4ADA114-5C23-A10-B2A6-2(4B2A7-)5BA7-5DA142-4(A12-)A31-
