model
size = 28 29 19, scale = 0.05, origin = -y
material 
  colors = A:#888 B:#FC0 C:#FFF D:#222 E:#FC3 F:#FF3
voxels
118-17(2AB2A6-2AB2A12-)2AB2A6-2AB2A320-2AB2A6-2AB2A460-2AB2A6-2AB2A292-2AB2A6-2AB2A12-2AB2A6-2AB2A460-2AB2A6-2AB2A12-2(2AB2A6-2AB2A264-2AB2A6-2AB2A516-)2AB2A6-2AB2A236-2AB2A6-2AB2A12-2AB2A6-2AB2A516-2AB2A6-2AB2A12-2AB2A6-2AB2A208-2AB2A6-2AB2A572-2AB2A6-2AB2A208-5B6-5B572-5B6-5B208-5B6-5B36-5(BA20-AB4-)2A20-2A3(4-BA20-AB)288-5B6-5B152-16A12-6A4B6A9-9A4B9A6-9A4B9A5-B4A3B2A4B2A3B4AB2(4-5A3B2A4B2A3B5A)4-5A14E5A4-B4A2E11BE4AB4-3A2B2E11BE2B3A4-3AB16-B3A4-3AB-2D2-2D-3D2(-D)-B3A4-B2AB2-5(D-)3D-B2AB5-2AB2-D2-2D-3D2(-D)-B2A6-2AB16-B2A6-2A18B2A2(6-4A14B4A)7-3A3B2A4B2A3B3A8-3A3B2A4B2A3B3A9-2A3B2A4B2A3B2A11-2(6A4B6A12-)6A4B6A13-14A15-12A98-16A12-16A9-22A6-22A5-B22AB3(4-24A)4-B22AB4-24A3-F24AF2-F24AF3-4B13A2BA4B5-3B14ABA3B6-3B16A3B2(6-5B12A5B)7-4B12A4B8-4B12A4B9-3B12A3B11-2(2B12A2B12-)2B12A2B13-B12AB15-12A16-12A17-2(A8-A18-)2(AB)2A2(BA)15-16A12-16A9-22A6-22A5-B22AB3(4-24A)4-B22AB4-24A2-CF24AFC-F24AF3-B22AB5-4(22A6-)22A7-20A8-20A9-18A11-2(16A12-)16A13-14A15-12A17-2(A8-A18-)2(AB)2A2(BA)15-16A12-16A9-22A6-22A5-B22AB3(4-24A)4-B22AB4-24A3-F24AF2-F24AF3-B22AB5-4(5B12A5B6-)5B12A5B7-4B12A4B8-4B12A4B9-3B12A3B11-2(2B12A2B12-)2B12A2B13-B12AB15-12A17-2(A8-A18-)2(AB)2A2(BA)15-16A12-16A9-22A6-22A5-2(B22AB3(4-24A)4-)B22AB5-4(22A6-)22A7-20A8-20A9-18A11-2(16A12-)16A13-14A15-12A155-14A11-20A6-5(B22AB4-)24A3(4-B22AB)6-3(20A8-)D18AD9-C16AC11-C14AC12-C14AC13-C12AC15-C10AC16-C10AC17-C8AC18-6C2A2C24-2A183-20B12(8-B18AB)8-2B16A2B9-2B14A2B11-B14AB12-2B12A2B13-2B10A2B15-B10AB16-2B8A2B17-B8AB18-10B239-16A11-10(18A10-)18A11-16A13-14A15-12A16-12A17-10A18-10A19-8A20-8A272-8A19-10A17-12A15-6AB7A13-2(6A3B7A11-5B2(2AB)2A5B11-)6A3B7A12-7AB8A12-16A13-2AD7CAD2A15-12A17-10A47-8A20-8A21-A4BA22-6A388-B26-2(3B18-5B2(2-B)2-5B17-)3B26-B31-A27-A162-4B208-
