model
size = 28 32 25, scale = 0.05, origin = -y
material 
  colors = A:#2C0824 B:#1D0110 C:#23021D D:#2A071D E:#000
voxels
64-DA8-CA16-AC8-AC16-3C-2A-2B-BD16-B2DCBA-2D2BD16-B2A2(BDBC)D17-C2B2DB2A-CA17-BAD-CACD-AC17-BDA-ADB2DAC16-D3A-CD2CADC16-BACD-DAD2CAB16-ACAB-BCBDBAB16-A2(B-)DB2AD2B16-AC-2DC2(ACD)16-AD-ABADB-3D16-4ABCDC-ABD17-DC3DAD-CA18-AD2(AC)DBCA18-3ADBABCDB20-ADA2BA23-C2-A300-CA8-2D16-DB8-CBC14-DAC8-ADB14-A2D8-BDA14-ADC8-BCA15-CD8-DCA15-3B-D2(2-B)2A15-DBC-BD2C-ABDB15-AB2(DA)2BD2CA16-CA2BADCBCA2B16-A2CBCB3D2CD16-2B2ADBDCBADB15-C2ADA2(DB)3ABA14-BC2DBD2A2C2ADC14-BAD3C2D3CABD14-B2D2ACDA2CBACD14-AC2(BCD)2CABAD14-B2D2A3BDCABCA14-2C3(AC)2ACADC14-CADBC2ACACD2AD14-BCDBDA2BDBC3D15-AC3B2C2ACBD17-2A2BADC2AC18-A2-BDACA-D241-DC8-BC15-BD2(A2-)B2-2CB14-BDA2-BD-A2-ABC14-BDB2-2B2(-2D)A14-2DA-BAD-DA-2CA15-B4CDB2C-DBA15-DAC2A3D2ABA15-CACDBCD2A2BA2D13-2BCBCD2CABC3ACB11-CDCADBDAD3BDBC2BA10-DCBD2CADBC2(AB)A2DB10-2DCACDAB4ADACBAD11-DB2ACACDAD2ACB2CB11-C3ABA2DBC2D2CADC11-3A2DBADBA2BC2AD11-C2A2CA4CA2BDADB11-2B2(2DB)CDACDBACBC10-2ABDBC3DB2DC2BDBA10-2AB2DBDADC2BDACA2C11-C5B2CBCBD2CAB12-DBCDABADABCA3CA13-2D2B2DCB2(C2B)14-BCDA2(DB)CA2(DB)14-C2BDBACBDCA2CA15-2C2A2(2CD)2C20-DABA188-AD-ADB-BC-2A13-C2-CA-CA2BCD-AC2-A10-2A-2B-AD2C2(AC-)AC10-DC-BD-A2DABA-AB-BDB8-2DC-BD-C2ADCD-2B-DCD8-2DA2(-DB)CDBA-DB-CA10-CDA2DBAC3D2BA2D2A10-A5BAB3ADCB2(DA)C9-B2DC3AC2BA2C2A2CDB8-BCDA3CB2DAC3DA2(CB)8-ADACD2CDCA3DCD2CDAD8-D2CBAD2BC2ABCAC2BDCA8-3D2ADCACDCBCD2BABDC8-DB4C2DA2DC2(AD)BDAD8-CAD2BD2A2(DA)BADA2CBD8-2AD2BDAC2ADACBDB2DCA8-BACAB2ACDBADAB2(AC)AB8-C4D2(BC)2BAD2A2CDAD9-C2D2(BD)2C2D2CA2BCA10-A2C2(BA)DBCBD2(ADB)10-B2CDABA2(DC)2B2DC2B10-2DCB2(ABD)CA2(CD)CA11-ABCAD2CBD2CD2ABD12-DBC2ADB2C2B3ADB13-2C2(DA)2B2ADABA14-2CDCA2DCBCADCA16-B-DBACAB-2A153-2D4-2DB-BD4-2B10-DB4-ADBABD4-2B10-DB4-2DADBC4-DCB8-CAC2A2-2ABC2D2-DBC2B8-CABAC-2A3B2CD-2CBCA8-CDABD2(3BAC)ABD2C8-BADB2CBCDCADC3ABDAD8-CB2ABD3BDBADC2DB3D8-ADABCA3BDC4ACB2CA8-D2BACA2(2BC2A)C2BC7-BABDBA2BDC2(AB)CD3A2CD6-DA2B2ACBA2CDACDCB2CD2C6-DCABD2BDAD2ACB3CA2BAB6-CA4D3BCA3B2DCA3B7-ABDBADABACB2DBC3B2DC7-DCBADCADBCDA2(CD)B2D3B6-B2CD2CA2D2(AB)2AC2BADCA6-ABCDCBAB3CAC2AC2BABCB6-2AB3DBCB2CB2(CA)C2(DB)D7-2DADCDB2ACBA2B2ABDB2C7-3C2AD2C2BDAB2C3DCA8-BA2BDCBA2C3AD3B2AB9-2CA3C3BDCB2C4A10-3DA3CB2C2ADA2DAC11-BCB3CB2C4ABDB12-2BAD2BAC2B3ACDC13-AB3C2DCBDADBC16-2A2DA3C-CA125-AB3-B-A2-D-D3-DA10-2AB2DA2DCBDCA2C3B10-BDACADCAC3AB3CDA9-B2ADC3BDBA2BC2(2BD)8-CBCD2ACDB2CBABCBDCDA8-2(DB)2A2BADACBCDCBA2B8-AB2ADB2D2(CD)ABDACBAD8-CDB2DBCA2BCBC2A2BD2A8-B3DB2A2BDBA2DCBAB2C8-CACDBAB2D2AB2A2(2CD)7-3D2(AC)DBDA2C2DBCBD3A6-DADBCA2DB3CAD3BADBDA6-DBD2CABCA3CAD2CDACB2A6-ADBCD2B2DBAD2BD3AB2CB6-D2B2(AB)5DA2B3(CB)D6-2DC2D2(BA)C2BCABDC2DABD6-ACAD2BCBCACD3ADA2CA2B6-A5D2CB2(AD)B2A4BCD6-2DCBC2BC2D2CDCA2(CB)C2D6-2ADA2DCA4B2C2A3DA2C6-2(BD)2(AD)ACB2A3D2B2CDA6-2A2BC2DCDBCA3DAC2A2DC7-B4ACDACABADB2DACDB8-2D2ADC2ACA2DA2C2ABAB9-2(AD)CDAC3DCDACABD11-BC2BCACBDB3CD2A12-CAC2D3ACA3D2AB13-CAD3BDBC3ACD15-BD-A2DADA-BC21-BA74-CDAC-A6-B-3AB10-B4DCA-BA-2B2AC2B9-DAD2C2BD-AD-2CAD2A2D7-CB2C2BC3A2BD2B3CADAC6-CA2BD3CBA2BCBACA2BABA6-2C2ACD4BC2BCBD2BACDAB5-2(AC)DB2CBDBA3D2BDBDCD5-DA3CDAB3DBADC2(AD)2(CB)C4-CDACBDC2ADCAB2(DA)BCDC2AB4-C4ACB4CACBADC2B2A2DA4-DABAD2ADAD2BCB2(CD)2ADB2D4-2ABCDBD2(AC)3ACBC2DBCA2D4-3DCD2ABAD2CADCA2DCD2ABC4-ACBAB4DAD2AB2CDB2CBA2C4-CBDCD2A2D2A2BDA2CDCD4C4-DADB2CBCB2D2(CA)CDB2C3BD4-ADAB2(AC)D2BCA2(DC)DB2D3A4-2(AC)DBCADB2A2(DC)AD3ADCB4-C2ADCDA3DCADC2A2D2A2(CD)4-ABCAD2CDBD2BA3DBD2AD2BA5-2ADBCDB2CBA2CDACDB2(DA)6-2BACD2BAB2DC2BD3CDB2A6-BCDAB3CACDCB2CABDAC2A7-BC2BABDA2DADBD2CDACD8-DCACDB2C2AC3BCABCAD8-DACDBADAB3(CD)2A3D10-BDAB2AB3AD2BDAC13-2CDC2ABACBA2DC14-2(BDA)BC3(DB)15-2B-2ADBDA-CD21-DA45-CB-CB10-AD-BC7-2DA-2D3(-AB)-2B-3D6-ABC-CBCDC-DB-CAB2CBDBA5-CABC-2DCD2(AB)2(2DC)3BDC4-2ADADCBDB2CAD2(AB)2C2BCBD4-2(BDBC)D2(AB)CA2CAC2(AD)C4-D3ABD2B2(CB)2A2DABCAC2BD4-CADC2BC2DA2B3ABCA3B3A4-4DA2(DC)ACDC2DCBA3DABA4-CDCBCABA2BDACD2(BC)ADA2DA4-ACABD2A2(BA)2CB3D4C2AD4-3B2ACB2AD2A2C2(BC)A2BDAD4-BDCB2DCACB2ACDAC2(2DA)2BD3-D2BCBDA3C2BDBCA3C3A2BD3-B2ABDCADABDCBA2CDBADC2BC4-D3BCABC3A2BAD2ABADA2CA4-BC2B2DBCABD2ADA2D2A2BCBD4-CDA2C2DCA2D2A5C2BDABC4-DAC3DB2A2(DC)ACABC2ADACA4-B2DBCA2CADBCBA2BA3DC2BA4-BAC3B2A2(D2AB)DA2DCD2A4-A2D2BAB2ADC2ACB3C2DC2BD5-BDBADAB3DADACA2BDB3C6-CD2(BC)DABD2ABDA2DCAB2A6-CBCDB2D2(AB)2AB3CB3AD7-A2CA2BD3ADA2BACB2AD9-AC2BC3BAB2DACAD2CA10-B2CDA2DCA2DB4A13-A2DBADCA2CABCB15-AD-DAD2BC-3B19-DB2A44-2BC14-ADA5-2BACAB14-CBACAD-B2CD3ACD-B6-2(D-)2BCD2A3C2D2CD2C3DA2-AB2DB-BDCA2CACDCBDC2BA2BC2BACADB2C2AC2A3DA2D2BACDAB2C2ADA2B2ADC2DCDC2(AB)4CA2BC4BA3D4CABDA2C2D2CACABCB4ACA4D2B2CAB3D2BD3BA2BA4CDCBC2DBCB2ACADABDB3CA2BD2A3D3BABADB2CBC2ABD2ADC2DCBD2B2DBCAB2ABC4ADCADB2CB2A2D3C2(AD)ACBAC-2C2A2BADA2DBCD2C2BDB2D2BDAC-2D3(AB)C2BD2BACBACD2BADCB2-D2B2CBA2BC2B2C2ACD2CACD2AD2-B2DCD2B2C2BABA3BCBACDCB2A3-2D4AC2A2(CB)ADCBDA2DBDAC3-BAC2BCDCA2(D2A)4BADCBD4-DCBAD2CADBA2DC2B2CBD2A2B4-BC2(DA)BC2BA2DA3B2ACA2BC4-ABDC2A2DCA3DBD2AC3DBDA4-2BC3BABDB3CBD2ACDB3DA4-ADCAD2CB2ADACBCD2C2DBADB5-C3ADB4CABDBABC2AD2BC5-2(BAC)2ABC3B3ADB2DCA7-CDCAB3DBCABDACB2AD2A7-C2BDACABACBD2(AB)C2AD9-D2(AB)3AC2(AB)CDB2A12-ADBC3BDADC3B14-C2ACADA2(CD)BAB15-DA-ADCADA-DC21-DC15-2C-DC14-BA-ABC2-A2(BC)B14-BCB2AD-BA4CB14-B3ACDBDAB2ABC14-2ADCBD2AD2BCBCD-2CD2CACADA-BAD2B2CA2DAB2DA2BD2A2CADC2ABADB2(CD)ACBCA2DCABCAC3AC2DADABACABADB2DBCDCACDCBAD2BD2(AC)B2C3B2(CD)C2ADAB2(DA)2B2(DAC)AB3DC4A2DB4CACBA3D2B2DBDCABADCABC3BDBCD2BCAC5AB2AC2BADC2BABD2(BA)DAD3CABDC2B2D2B3CBCBACDABDBA2DC2A2(BCA)3B2CDBCBDBACD2CBC2BDCAC3ADC2BC3AB2C2DB3DC2ACABDB2DBDCB3CAC2A4CBDC3ABC2(DA)2BABDAB-BDCACDAB2DADAB2CA2B2AD2C2B2-3AB2(DC)2B2C2B3(AD)C2D2BC2-B2C4AB2CD2CB3A2(C2A)CBC3-B2C2DADCB3DCD3B3C2BDA4-AD2BACD4BDCAC2BDC2BADC4-DCDA2C2(BC)BABD2CDC2DBADA4-2CBCA3DACB2A2BDB2C2B2DA4-CD2(2A2C)DA2BDC2DA4CA5-2B2CDA2CD2A2CBA2DBACAB6-ADCBD2B2(AC)BC2DC3DCBA7-ACDABAD2CDACDADBD2AB9-4ADA3DBDBABD2AC11-BAB2DC2(DA)D2B2CD13-CA5B2(DC)ABA15-DC-ABD2CB-AC21-CD15-DB20-BC3-C2D-A16-A-DAB2-BAB-D16-A-DAD2-BDA-2C17-A2B2-3A-AB14-D2-BDC2-2BDCDB5DCBADCAD2A2CDA2D2-B2DCABC2(DB)C2DBAD3CB2D2AD2-A2(BC)2DA2DB2ADCDA3C2BCDAD2-2D3BCBAD2B4CADBABCDBD2B2-2DB2ABCD2A2(BC)DBAB2CA2BCBD2-CBACAD2ABC2BCADAB4DADCAD2-C2BAC3DBDA2(BAC)BD2C2BD2A2-2CBDCDADC3BA2B2(CB)AB3A2C2-C2BDBC2BCA2(B3C)A2CDAC2D2-2D2CDB2D2CB2(A2D)ACA2DCABA2-A2C2(AB)ACADA2DBACBA4BAD2A-CADAB2D2(BC)DCD2ACACD2CBDCA2-B2(DC)B2CDCBD2ABC3DCBC2DAD2-2(A2D)CA2DC3A3(CA)3BADB2-BDC2DA2BACA2DBCDB2CBDCA2DA2-C3DACD2BDADCB2CB4ABDCBC3-2C2DCBCA3(CB)DACDCBACDB4-BDA2(BD)2(ABC)A2C2BD2CA2B4-3CB2(DC)2DABDBA2BCDAC2DB5-D2BCADAB2ADBDCB2(CA)BCA6-2CBACA4BD2CD3CBACBD7-DB2DCA3D2C3B2(2CD)9-B4C2(ACB)ADAC2DB10-DBC2BC2(AD)B2DA2C2B12-ACBADBC2ACD2CA15-DCABCBD2BADA19-BABDAC68-CACB18-3BA2-CACB18-BCBD2-2BCB18-B2DC2-2(AC)8-2C8-3DA2-C2A2C2D2CADCBDBA4C2(DA)CA2-DCB2(CA)DBCDB2(ABC)BCB2ADBD2-2D2(CDA)CBDABD3CBAC2BA2BC2-2AC2B2A2CDADB2CA3CDAC2ABD2-DA2DBCAB2(DA)D3CB3A2CDACD2-ABD2CB2C2DCBA2BCBAD2ACDCAB2-DC3(BA)2D2(AB)D2C2BACBDBCA2-C2A3C2BD2A2BADA3DCDAC2DC2-3ABADB2CB2(CA)D4CD2CDCBC2-AD2BCB2(CD)A2(DC)2DCD2BA2BCA2-A2B2CADBDABC2A3CA2(DB)ABCB2-B2CBCA2C2A2DBACA4DA2BCDB2-4CBCAC2B2D2A2BCDC2DA2CAC2-C2D2BA2BD2BA2DACBABDABADBA2-2(DB)2C3DAC2BADB2CAC2DCDBA2-5BA2B2DADCDACAD2ACDC3A3-ADCB2A2B2D2BAB2DCDBAC2DA5-BCD2ACD2B2CA2DCAB2D2ADA5-C2DCD3ABCAC2ACDB4CB6-CBC2DBA2DADACBA2BCBDAD7-DACADC2D2ADCDBD2BACDC8-2ABD2ADACADB2C2DBD10-2CBAC2(DA)CD2A2BD2C12-2BADC2ABD5A15-4DB2CAC2BD19-CDB2AB41-B2D19-DC3-BDBC18-2C2B2-2BDC18-DABC2-2DBD18-ACDC2-CB2D18-A2BA2-ABACA3-CBA2BCA2D4-2ABDA2-2CBC2D2(A2C)DADBD3CAC3BA2-2CAB2(DA)C2(DA)DC2(BD)2(CBA)C2-2ABA2BD2C2AB3AD2AD2BDA3B2-2DAD3AB2CB2DBCD2AB2ACADCA2-CABD2A3B2A2CDAB3A2CBCBDB2-BDCA2DABAD2C2A2DAC4DBACD2-AB2DBDBCAC2DBAC2BAB2DCDBCA2-BC2B2DC2BDB2ADBCA2CBDC4B2-3DBABCDB2DABCA2BDABDBAB2A2-DCDBACD2(AB)DBDCDBDA3CABDB2-ACABCDADBAC2AB2DBC5BABC2-DC2ABDCBAD2BC2(AB)3CB2DCAB3-2B3A3DBA2CD2B3A2(DC)BCB2-2DCBDBCD2A2C2BCAB2CADBCADA2-CDBA3B2(2DB)DC2BA2(BD)ADBC3-2BD2(CA)CDBD2BDAD3C4BD4-C2ADAC3DBDCACDA2C2BDBAB5-B4ACBDBAB2CDBC2ACADC6-2A2CA2BC2DB2CADCDBDA2C7-ACBCDCBC2D2BDAC2D3AC8-A3D2BCB2ABDACBACD10-A2(2DADC)ACA2(DC)12-2CBC2B2ABD2CBD15-BDAC2ACBDACA17-D-4CA2DB40-B20-C5-D2C18-3C3-BDAB18-ABDBC2D3A19-A2BAB2AB21-DBDCBA10-CB10-DBCA2B-3B2DCBADBCABC2A3CA-A2CDBACADBAD2ABDBCB2D2AD2BCAD2BCDB2(AD)ACDBA2BCDCBDABDB2CDCBC2AB2ACADB3EC3EADCACD3AC2(ADB)D2C2A4ED2EABD2(CA)CBC2D2BC2BDADB2(EC)3EDBCADACABDA-ABCBAD2B2(ACEB)3ADCBDBAB2-A2CDADB2A3EBEDE3ADC2ABDB2-2ACBD3AC2ED4EAD2AC2(AB)C2-2CDCB2D2B2(3EB)CDAB4CB2-CBAB2ADC2AB2ACDCA2BDBAB3D2-ACBD2BACB2ABA3CDAB2A2D2CB2-CACDBABDA2CD2A2CBDACBD3BD3-BCB2CB4ABD3C3DB2ADCA4-DCD2CDBDAC5A2DB3CDCA4-A3C2DCD2B2D2BD2C2BD3BC4-2BDC3BDBCAB2D3(AD)2BDB5-2(CA)BABDC2ACDAC2(DB)ABC7-DCBC3DCA2CA3C2BCB2D7-B2C3BD2BCA2B2D2A2DC8-BCBAC4B3(CD)3ACB10-ADBACADBA2BAB2AC13-2DBDABAD2BDBCDA14-CAC2A2CDBACB17-C-B2CABDAC93-DCD22-B2ABAD22-BACADC22-CADBAC22-BAD2BAC20-ADABDADB-AC14-A2-BCA2C2AC2DB14-ABC2(D4C)A14-D2BA2BC2DA2(CD)14-CB2CBD2B2DC2AD14-D3CBCADCDB2CB14-3ABCAB-CBDCAC14-D3CBC2-ADABCA14-ADBDAC3-DBDCD14-DB3DA3-C3DC14-D3BAD2-C2BADC14-BACDBC3-DBA2BAC2B3DBAB2AD2B3ABC3-2AB2DAC2BDCABC2BACABDC2B4-2(AB)2ADCDB2(AD)B2CBCB4C5-A2BDAD2CDBCB3DA2CBCADC4-AB3ABCABDAB4DA4CBAB5-CADC2AD4A2B2DC2(DB)DC7-2CDACD2BAB2CDA2BC2BA8-CBC2BDCDBCBACADCD2AB8-CDBDCA2C2BA2BD2CBACB10-C2D2AD2CD2A2BD2A12-A2CADBCD2AC2(AD)A14-3C2ACA2BCBC17-BACBDBA3C93-CDA2D18-2DCD-D2(CA)18-ADC2ACABDC17-2BABCADBCD2C16-CBC2BABA2BDB16-B2(CDBD)2CB16-AD2ABA4BCAD14-ADA2BDB2ADB2DB14-2CBDCDBCAC2(DB)14-DCBDCAB2ACD3C14-AC2D2A2C2B3DB14-ACBABCA-3ABAD14-ABADBD2-2(BAD)14-2BCABA3-2BCAC14-ADCDBA3-3DAB14-CBCAB4-D2BDC14-C3DB4-DCDBDA12-2BDA2B4-B2(CA)4BABDA3CBC2(AD)BC4-CA3D2B2D2BDBC2(DA)3CDAC4-ACDACA3B2A3B3(CA)CBAD5-BDBC2DBABCD2CDA2(CD)2AB6-B2(DBCA)DCABCA5DCA7-D2CA2BADBD3CBACADBD8-C2(DA)BDCDA2C2A3DABC9-DBDCDA2DCBDADC4BA10-DCABA2C2(BD)CB2DA13-ABCADC2AD3(AC)14-BCA5BDBAC18-2AC2(DB)A68-CAB19-AD4-CDB18-B2A4-DA2B16-CBCA3-CA2DA16-D2BD3-BCABA16-ADCD4-ABACB14-3BAD4-ABDBC14-D3AC3-BC3AD14-AD2(BA)2-CB3CD14-DB3DC2-3D3A14-3BD2B2-DBDCDB14-2CBDAC3-CABCA14-DBCACB2-BADBAB14-ACBCAD2-3ACAC14-C2(BA)D2-3AC2B14-C2AD2C3-DAC2B14-BACAB4-AB2DC14-D2(CB)4-3BDAB12-BD2BAD5-CDBCB12-2BABD6-DB2C2BADACBDCABAD2BDAD6-CBABCBDCB2CBCABCDCABDB6-CDACDB3DCDAB3DCDCADC7-5B4CA2BCBDB2(CD)8-2BDCBCA3C2(BD)A2BCDA9-2ADABD2A2CDB3ADAC10-2(DB2C)DABADBC3B12-CDCB2(CA)CBA2BCD13-D2A2DCDC2D2CDB16-4D2B2DBA19-2(D2B)AB68-CDC19-2C4-2DA18-CBD4-BAC18-BAB4-3BA16-A2BA4-A3BD14-ACB2D4-ADACD14-3CBC4-D3AC14-C2D2A4-3C2D14-ABDAC3-2ADCAD14-2ADBCA2-3D2BA14-DBA2DA2-B2ABAB14-D2BCAB3-BDABD14-2BAB2D3-2ADBD14-ADABD4-ABD2C14-C2D2A4-2DBDC14-2A2BCA3-CDBCA14-BC2DA4-BC2DC14-3ABD5-CABDB12-C2DCD6-BCACB12-AB2CB6-3A2C3DC2ACBD2B2ABADB6-CB2ADBCDC2DAC2A2BDC2DC6-C2DB2C2DBA2BCAC2A2C2DB7-CADCBD2BDCD2BCDBC2DC8-2BDBDC2DAC3BABCACDC9-C2D2A2(CA)CBDAD2BAD10-2(DC)ABADBCD2ACDBAB12-3CDC2B2(CD)A2C14-CBD2BC2(AD)BADA16-B2CBC2DABA20-DCDBD2A98-CA16-DA7-C2D16-CBC6-CB2D14-D3A6-A2CD14-A2DB6-ADBA14-CABC6-3DC14-A3B5-DC3B14-CB2A5-2BACD14-CADCB4-BA2BA14-B2D2B4-CDC2A14-DACAD4-2CDAC14-D2(AB)4-B2CAD14-2DACD4-CBDCA14-A2CAD5-D2BC14-2A2C5-CD2CA14-ADCAC4-ABDBA14-DC2AC5-BCACD12-2B2CDA5-BA2BC12-DCDAC7-A3BD2CB2DABA2CBC3DB7-DCBDB2(AC)2B3AB5D8-2BC2AD2BAC2ACBCDBDCB8-CBDAC2DB2DC3DC2BC2D9-DA2DADC2AD2CDAD2CAB9-AC2A3BC2DCDBD3CB11-2B3C4ABD3CBDA12-B2DBCDACADB2AB15-DADC2(BA)CDAC17-DBADB2ADBD20-2(BD)CA99-BA16-2C7-C2D16-2AB6-C2AB15-2DB6-DB2C14-2DAB6-CDAD14-DABD6-2CDC14-A2DA6-D3A14-2DCD6-C2AC14-C2DC6-ADAB14-BCDA6-C3A14-A3C6-B2AB14-C2AC6-C2DC14-CDBA6-ABDB14-CABD6-2B2D14-DA2B6-D2AD14-BA2C6-BACD14-DBCD6-A4C12-2DADA6-DA2CD12-CBCDA7-AC2B2CDCBCA4CDC3A8-2CADBCBD2BA2(CAB)D2B8-2DA2CB3DAD2(BA)3BDA8-2CDB3DABA2DBC2D2ABC9-2(DA)DB2(ADCD)2(BC)11-A2CDCDBD2ACDC2BC12-2BABCABA3BA3CA14-BDA2DCABD2CD17-CBCAC2A2CB19-2D3AD2C21-BACA2C99-2C25-DCB17-B7-CBC16-DCA6-CAB16-DBC6-DCA16-CA7-BDC16-AB8-DA16-AD8-BCB14-D2B8-2BA14-CAB7-CDAC14-DAB7-DCAB14-2BAC7-CDB14-BACD7-B2D14-BDB8-DAC14-2BDC7-2CB14-ACD8-B2A14-BCA8-DADB12-C2AB8-A3C12-2DBA8-B3ABC2D2(BC)BAC2DC2A9-2CD3CDA2CDBAC2DBD10-A2BC2D3A2CB3ACBA10-D3AB3CABDCAC3AB11-2(DC)D2BAD2A2D2AC12-A2CADC3B2A2B2CB13-DBAB2CD2ADCBDCD14-DA2(DB)2DBACB18-BDBCADBA20-2CA2BCDB380-A14-B12-C14-D12-C14-AD11-D14-CB11-D14-DA10-AB14-BC11-C14-AB11-AD12-3A10-DBA12-A2C10-B5CDAB2ADCAC2ADA9-BDABD3CBDCBA2C3B11-3CDB2CABADACBD2A11-3ACACD2(BA)CDC2BC12-3CA2CDABD2BAB14-CACD2C2B2DBDAD15-C2ADB2(CD)BAB17-D2AC2BC2AB19-A2DA2CAC21-ABADBC578-B2C7-2BCA14-CABCB2A3CDCB2D13-2(CB)A3CB2CADCA13-ABDAC2BCADABDB14-C2DC3A3C2(DB)15-C2(A2C)2ACBCD15-2ABAB2CD2CA2D15-2AC2(DB)CD2AC17-2(B2A)3CB19-BCDBCADA21-BC2(BA)607-B2ABCDBDCADC17-DCADCB3DBC17-2BA3DBC3B18-BC2ADA2(BD)17-2BDBDA2CBA18-CB2CA4DBA17-2ACDCB3CAD17-BADAC2BCBD20-CB2(AC)22-BC3BA24-CD611-DB2-DB-C21-A2-DC-B21-2(CB-)A21-BD-DB-D20-CAC-BA2B20-2B2(D-)BC20-CBCD2ABD22-BDAC25-2DA25-CB97-
