model
size = 19 24 7, scale = 0.05, origin = -y
material 
  colors = A:#400 B:#111 C:#500 D:#700 E:#800 F:#444 G:#777 H:#555 I:#222 J:#F30 K:#C60 L:#888 M:#D00 N:#E00 O:#AAA P:#BBB Q:#200 R:#A00 S:#B00 T:#F60
voxels
41-A11-A5-2A11-2A3-F2A11-2AF8(2-3A11-3A)2-F2A11-2AF3-2A11-2A4-3A9-3A5-13A6-HF9AFH5-3HF7AF3H4-GH3-5C3-HG5-G11-G101-2A-B5-B-2A5-F2A2B5-2B2AF4-3A2B5-2B3A3-4A2B5-2B4A2(2-K3A2B5-2B3AK)5(2-4A2B5-2B4A)3-3A9B3A4-F3A7B3AF4-L13AL5-F11AF5-HGF9AFGH3-H3GF7AF3GH2-O2G3-5C3-2GO3-OGH9-HGO5-OG9-GO7-K9-K8-2(E9-)F7-F9-2A-5B-2A7-L2A7B2AL6-C2A7B2AC5-CF2A7B2AFC3-KCD2A7B2ADCK3-CD2A7B2ADC2-2I2(CD2A7B2ADC4I)CD2A7B2ADC2I-ICDA9BADCI3-CDA2N5B2NADC4-CD2A7B2ADC4-CD3A5B3ADC5-D11AD6-D11AD7-11A7-HF9AFH5-GLHF7AFH2(LG4-)3C4-GL5-L11-L66-F5AF10-FC7ACF9-L7AL9-F3C3A3CF8-4C3A4C5-K2-3DJ3BJ3D2-K5-E2DJ3AJ2DE8-3E5A3E5-K2-M2E5A2EM2-K5-2EJ5AJ2E2(8-E2-N3AN2-E)8-EMN5ANME8-EJ7AJE8-2E7A2E8-ME7AEM8-3D5A3D9-4CA4C12-5A16-C92-A3FA13-FACFCAF12-2ACAC2A12-CMCACMC12-3CA3C12-JH3-HJ7-K4-2JCAC2J4-K2-K3-EJDQAQDJE3-K6-EJDCACDJE12-DCACD14-DCACD11-M2ADCACD2AM9-MRDCACDRM11-SDCACDS12-EDCTCDE12-2DCAC2D12-D2CA2CD12-3CA3C14-3A112-I16-G-I-G71-O3-O14-P3-P16-A17-CAC16-DED17-C18-A91-GI3-IG12-G5-G281-E18-D275-
