model
size = 17 28 17, scale = 0.05, origin = -y
material 
  colors = A:#633 B:#630 C:#9CF D:#600 E:#603 F:#CC0
voxels
7-2(3B473-3B14-)3B150-3A13-5A11-7A9-7(9A8-)9A9-7A11-5A13-3A15-A83-3B14-3B114-7A10-7A9-9A7-2(11A6-)11A5-3(13A4-)13A5-2(11A6-)11A7-9A9-7A11-5A13-3A15-A66-3B14-3B97-7A10-A5CA8-3A6C2A5-2(4A6C3A4-)3A7C3A3-4A7C4A2(2-F3A7C3AF)2-4A7C4A3-2(3A7C3A4-)3A7C3A5-2A7C2A7-9A9-7A11-5A13-AFA82-3B14-3B49-F16-F12-9A7-3A5C3A9-5C11-E3DE2D9-9D8-6DE2D7-3(DE)5D6-11D6-D2E6DED6-5D2(E2D)7-9D8-EDE3D2ED8-9D9-2(DE)3D11-E4D13-2DE133-3(3B14-)BCB14-BCB10-11A5-3A6C4A7-2DE4D260-2B13-2B-2B11-2B3-2B9-2B5-2(2B7-)2B5-2B9-2B3-2B11-5B12-B3-2(B12-B3C)B9-2A6C3A5-2A7C4A6-6DE2D259-2B13-2B-2B11-2B3-2B9-2B5-2(2B7-)2B5-2B9-2B3-2B11-2B2-B12-B3-B11-F5CF10-F5CF8-2A6C3A5-2A7C4A6-2D2(ED)E2D259-2B13-2B-2B11-2B3-2B9-2B5-2(2B7-)2B5-2B9-2B3-2B11-5B12-B3-2(B12-B3C)B9-5A3C3A5-6A3C4A6-9D351-3(3B14-)BCB14-BCB11-9A7-11A8-3D2E2D335-3B14-3B49-F16-F13-7A9-9A10-EDE2D319-3B14-3B98-5A11-7A12-DED303-3B14-3B116-3A13-5A302-3B14-3B150-AFA286-3B14-3B456-3B466-
