model
size = 32, scale = 0.05, origin = -y
material 
  colors = A:#289898 B:#2F8E95 C:#25949A D:#2B979D E:#27949A F:#111 G:#FFF H:#29859A I:#DDD J:#222 K:#EEE L:#444 M:#999 N:#333 O:#777 P:#AAA
voxels
4-2(26B5-)B26AB3-B28AB-B3(30A2B)13A4B13A2B12AB4FB12A2B10ABJ7FB10A2B9ABFBA4FABFB9A2B9AF10AF9A2(2B30A)2B6A4B10A4B6A2B5A6FB6A2B5FB4A2B3AB2FGI4FB4AB2FGI5F3A2B2ABF2GJ6F3ABFKGIJ5FB2A2BABF2G9FBAFK2GJ7FBA2BAFI2G9FABF2GI9FA2BAF3GFLGN5F2JF2GMFGL6FA2BAF3GF2GK5F2JI2GIF2GK5FA2BAF3GOF3G3FK2JI3GF3G5FA2BAF4GJF2G2FNG2JI3GMFLG2FJGFA2BAFI4GI3FIGF2BF4GI3FM2GFA2B2AFK8GKF2AFI9GF2A2B2AFPK6GKFB3AFI7GKF2A2B3A2FIK2GKIFB4ADFIK3GI2F3A2B5A6F8A6F5A2B30AB-29AB3-27AB7-22B8-26B5-B5E16B4E2B3-B6E16C6EB2-B2E4C16D4C2EB-2B2EC3D16A3DC2E4B2ECD18A3DC2E5BECD20ADC2E5BCD21A2DCE5B14(CD22ADC6B)CD22ADC5B2(2ECD20ADC2E4B)2EC3D16A3DC2E2B-B2E4C16D4C2EB2-B6E16C6EB3-2B4E16B5EB5-26B8-22B8-26B5-H26AH3-H28AH-B25(30A2B)30AB-H28AH3-H26AH5-26B5-B5E16B5EB3-H28AH-E30ABE3(30A2E)2(30AEB)15(30A2B)5(30ABE)30AEB30AB-H28AH3-2B4E16B5EB3-B6E16C6EB-2(E30AB)E4(30A2E)30AEC15(30A2C)30ACE4(30A2E)2(30AEB)30AB-B6E16C5E2B2-B2E4C16D4C2EB-E30ABE30A2E30AEC3(30A2C)30ACD15(30A2D)30ADC3(30A2C)30ACE30A2E30AEB30AB-B2E4C16D4C2EB-2B2EC4D15A3DC2E2BE30ABE30A2E30AEC30ACD2(30A2D)30AD512AD2(30A2D)30ADC30ACE30A2E30AEB30A3B2EC3D16A3DC2E4B2ECD20ADC2E2BE30ABE30A2E30AEC30ACD30AD640AD30ADC30ACE30A2E30AEB30A3B2ECD20ADC2E4B2ECD20ADC2E3B30ABE30A2E30AEC30ACD30AD640AD30ADC30ACE30A2E30AEB30A3B2ECD20ADC2E5B15(CD22ADC4B30A2B30ABC30ACD30AD704AD30ADC30ACB30A2B30A4BCD22ADC6B)CD22ADC4B30ABE30ABC30ACD30AD704AD30ADC30AEB30A2B30A4BCD22ADC5B2(2ECD20ADC2E3B30ABE30A2E30AEC30ACD30AD640AD30ADC30ACE30A2E30AEB30A3B2ECD20ADC2E4B)2EC3D16A3DC2E3B30ABE30A2E30AEC30ACD2(30A2D)30AD31AD480AD2(30A2D)30ADC30ACE30A2E30AEB30A3B2EC3D16A3DC2E2B-B2E4C16D4C2EB-B30ABE30A2E30AEC3(30A2C)30ACD15(30A2D)30ADC3(30A2C)30ACE30A2E30AEB30AB-B2E4C16D4C2EB2-B6E16C6EB-B2(30ABE)4(30A2E)30AEC15(30A2C)30ACE5(30A2E)30AEB30AB-B6E16C6EB3-B5E15B6EB3-H28AH-B30ABE4(30A2E)30AEB16(30A2B)4(30A2E)30A2B30AB-H28AH3-2B4E16B5EB5-26B5-H3B23AH3-HB3E24AH-2B4E25A3B2E2C3(25A3B2ECD)25A3(4BCD26A)2(4BC27A)11(4BCD26A)2(3B2ECD25A)3B2EC2D24A3B2E3C24A3B5E24AB-HB4E23AH3-H4B22AH5-26B3-
