model
size = 30 32 30, scale = 0.05, origin = -y
material 
  colors = A:#100 B:#FFF C:#093 D:#FF3 E:#FC3 F:#FF0 G:#F93 H:#0A0 I:#F90 J:#FC0 K:#C30 L:#F63 M:#066 N:#001 O:#096 P:#AAA Q:#CCC R:#EEE S:#555 T:#777 U:#C60 V:#FF6 W:#111 X:#010
voxels
42-G2E2DH25-2BAB26-2(BA)864-A-A2LBE25-3AB26-2ABA892-CN5A2EALA20-BQ4ADG22-6A2D24-2ALF26-CHAD26-HRAB294-2(2AP)AM24-2AGL26-2F2E440-3C10-3A16-CB8-KB18-NA8-KA18-D3C4-D2EA20-2C4-2D22-2C4-DL24-HABD26-H2AB26-2(AB)26-4A172-EI3ABAPAF2A20-AB2A2-GA22-BTA3-GF22-3AJE2IK407-CA13-2AF13-2C12-AF14-3C11-2A14-3A11-BA14-3DC8-E2AB15-2DCA7-FAB17-GO2H4-BFBA19-M2H4-3A21-2H4-AB22-BA4-BA22-4AB2AB24-B3A26-4A25-ABAS2A24-2A2(BA)20-2KAFA-A3-2F2H17-GF3A3-3AM18-EB4A2-3AC18-G6A-IKEC22-KJGI26-FDEI348-H18-F11-C16-2(D12-A-2A13-)J12-BA2B11-A-B12-3D12-3A13-3DA10-2A14-3DA8-2A2B15-2EH8-B2A17-EH8-BA18-J3A2-A2-2AB19-DBA2-A-B2A21-LA2-A-BA22-DA2-A-2A21-2FA2-A-2A18-3IA4-A3-F3H15-E3A8-AH17-E2A8-C18-E2A8-C19-ABA4-2IE21-AFA3-IE22-3AGD2GL315-HA18-AE9-H16-E-E10-M16-G-G10-B16-J-J10-A16-D-D10-F16-A-D10-2E15-3A11-G16-A12-3G12-3A13-2G12-2A14-2K11-3A14-3IA9-3B15-3I8-3A17-IG8-BA18-IA7-3A15-KI2KA7-AC4H13-GA11-2AH15-G11-AH16-E2A9-AC17-E2A8-A18-E2A7-2A18-D4A3-2GEB22-2AGE26-3AB26-2(AB)226-A22-E7-B2(20-K8-A)20-G8-F20-E8-G20-F9-E18-X10-E18-A10-EA16-AB11-E16-B12-I2A14-A12-IA15-A12-2IA12-3A13-2I12-2A14-2K12-2B12-2E2A13-AHA11-EA14-2A12-2E14-2H12-2D14-2H14-D12-A16-B12-A16-3A-2A5-3A18-2B2A3-DFA21-ABA3-DF22-3A3-AV24-4A26-2ABA165-2A22-AU5-A-A20-U6-B2(-A20-I6-F)-A20-J7-DA19-F8-D2A18-A8-G-A18-A9-E18-A10-D18-A10-L2-A15-A10-I17-2A11-K16-B12-K16-A12-L16-A10-2G2A14-3AD9-EA16-AB11-F16-A12-FA14-2A13-BA13-B14-2A13-A14-4A10-BA15-3A8-2A17-3A8-HC17-4A5-A-HC20-B2A3-BA22-4A2-AB24-BWBA26-4A105-JA23-K5-B22-I6-B22-J6-A22-I6-2A21-G6-DA21-J7-D20-B8-D20-A8-DA18-2A9-J18-A10-J18-B10-G18-A10-EA16-2A11-E16-A12-G16-J9-3J17-3AG7-JA18-AF9-F18-A10-F18-D11-FA14-2A12-2A14-2A2(12-3A)14-B12-B16-B12-C16-3A10-C17-BA8-BH18-2A8-AB20-BA4-BA22-4A2-BA24-B3A74-2G24-LK3-D2(24-K4-B)24-E5-C22-E6-C22-F6-C22-B7-J20-A8-J20-B8-L20-B8-DA19-A9-E18-A10-G18-D10-E18-B10-J18-G7-3GA18-AFDE5-J2A19-AE6-2FA19-AD6-2FA19-DE8-F18-E10-N18-A10-2B16-2A12-A14-2A13-B14-HB2(13-A)H15-A12-B16-2A9-3A18-B8-A20-BA6-AB21-2A4-2A24-4C26-4C14-2L25-G3-G24-G4-A24-D4-C24-E5-C22-D6-M22-A6-O22-F6-MA21-A7-J20-B8-J20-A8-D20-B8-G19-2A9-D18-D10-F18-G9-F19-AF6-2JA19-AFDK5-JA20-AI6-BA20-AE6-2A20-AL7-2A19-F9-B19-F9-2A16-2AV10-2A15-A13-2(A14-)A13-2A15-A12-A16-BA11-B17-A10-A18-A10-A19-A8-A21-2C4-2C22-2C4A2C12-G26-KE-A26-A2-A26-D3-2(C24-D4-)C23-2A5-C22-B6-H22-A6-J22-A6-H22-B6-DA21-A7-D20-B8-D20-D8-F20-G8-FA19-G5-3A-A20-DAI3-JA21-2AI4-2A21-2AI4-B2A20-ADG6-2(2A19-D8-)2A18-2A10-A16-A12-B16-A12-A16-A13-2(B14-)A14-A15-A12-B16-2A10-AB17-EC9-A18-2C8-C19-2C7A2C10-2N26-KE-B26-2B-A26-A3-C24-F4-C24-A4-C24-B5-O22-A6-M2(22-B6-H)22-A6-A22-A7-D21-A7-B21-D6-FA21-L6-FA21-E4-2A23-2AI3-2A22-AI4-BA22-AI4-4A20-GE6-BA19-G8-2A19-A8-2A18-2A10-B16-A12-A16-B12-2A15-B13-3(A14-)A15-B12-A16-B12-A17-F10-A18-C9-C19-C9AC10-2A26-2AB27-4A26-2A-C26-A2-C25-2A2-C26-A3-H24-B2(4-H24-A)4-B24-A5-A22-B6-B22-A6-A22-D6-A22-G6-F22-E4-2A24-DE2-A24-2AG2-B24-2AE3-A-A21-AD5-2A21-G6-2A20-2A7-A19-2A9-B2(18-A10-A)17-2A11-B16-A12-A15-2A13-B2(14-A)13-2A15-12A-A16-C11AC17-C11AC9-2B26-2AQ27-AB2A26-2A-C26-A2-C25-AH2-C25-AR3-2(H24-A4-)H24-B4-A24-A5-4(A22-A6-)A22-K4-2A23-ABJ2-B25-AJ2-T24-A-F3-A23-AG5-BA21-A6-2F21-A7-A20-B9-A18-A10-B18-A10-A18-B11-A16-A12-A15-2A13-2(A14-)A13-AB15-11A2CA16-C11AC17-C11AC9-2A26-GBA27-4A26-2A-A26-A2-C26-C2-HA25-H3-2(H24-H4-)A24-A4-A24-A5-2(A22-A6-B22-B6-)A22-A4-3A23-2A2-2A25-A2-F26-F3-A23-2A5-2A21-A6-2F21-A7-A20-A9-2(A18-A10-)A18-A11-A16-A12-2A15-A13-2(B14-)2A13-A15-11A2CA16-C11AC17-C11AC9-2A26-GAB27-4A26-2A-A26-C2-H26-C2-R26-C3-2(A24-H4-)B24-H4-A24-A5-B2(22-A6-A)22-B6-A22-A6-B22-A4-2P24-2A2-2A25-B2-2F25-T3-J22-A-A5-2J20-2A6-2D20-AB7-GA19-B9-A18-A10-A18-B10-BA17-A11-A16-A12-2A15-B13-W14-A14-BA13-A15-A-9A2CA16-C11AC17-C11AC9-2A26-GA-A26-B2-B25-2A2-2(2A24-C3-)2A24-C5-B3(22-H6-A)22-B6-2A21-A7-A20-B8-A20-A7-2S20-2A6-2A20-AF4-3D23-2A3-G23-2A4-E23-AB4-2E20-4A6-G19-2A8-E19-2A8-2DA17-2A9-AG16-B12-A16-A12-A15-2A13-A2(14-B)14-A15-A12-B16-A11-2A17-A10-A18-C10-C18-C9A2C10-B26-AN-B26-B2-A25-2A3-F24-C4-A24-C4-BA23-C5-A22-O6-B22-M6-B22-H6-A22-H6-BA20-2A7-A20-D8-A20-B8-A20-F8-B19-AF5-3F20-A-F2A3-L2A21-2A4-E2A21-AB4-2IA-A18-3A6-2(I2A17-2A8-)2GA17-AB10-E16-B2(12-B16-A)13-3(A14-)A15-A12-B16-AC10-2B17-B10-A18-CA9-C18-C9A2C10-E26-G2-2A2(24-A4-D)24-C5-D22-C6-A22-C6-BA21-C6-2A20-AH7-A20-J8-B20-H8-A20-D8-BA19-D8-BA18-D9-2A18-F9-2A19-F6-2D2A19-AFA5-GA20-2AJ5-GA20-3A5-I3A18-ABA6-I2A17-AB9-IA17-A10-G2A15-2A11-DA14-2A13-D14-B14-2A13-A15-B12-B16-A11-2A17-B10-A18-G10-A19-D8-A20-C7-AC20-C7A2C11-2E24-AL3-L24-G4-D-A22-A4-D-A22-C5-2A21-C6-B22-M6-AB21-O7-A20-M2(8-A20-J)8-A19-AD9-A18-G10-A18-D10-A18-F10-B18-F7-DFDA18-A3J5-LA19-2AJ6-2E19-A2B6-IE2A17-3A8-JA17-A10-DA17-B10-G2A15-BA12-F14-A14-B14-A14-2A13-A15-B12-A16-ABA9-2B17-DK8-A20-GA6-2A21-GE4-2A22-2CA2-A2C22-2C4A2C13-E23-AG5-B22-D6-2A21-B6-FA21-B6-2A20-AC6-BA20-AC7-B2(20-C8-A)B18-AJ9-B18-L10-3A16-D10-B18-E10-2A16-AG11-B16-E12-A16-J9-FDPA17-3G7-GA18-AJ9-F18-F10-J18-F11-2A14-AF12-FA14-AN12-3A12-3B14-B12-A16-A12-B16-A10-3A17-AB8-2A18-AD8-2A20-ED4-AB22-FE2-3AB24-GKDB2(26-4C)15-EB22-AJ5-B20-A-B6-A20-A-B6-F20-A-A6-2A19-A-A7-A19-AD8-B19-AD8-A20-D9-B18-D10-A18-2(J10-2A17-)G11-A16-E12-B16-E12-A16-G10-DP2A14-2A2J9-2A16-AJ11-F16-F12-2A14-AF13-2A12-2F14-FA12-2A14-2A12-2A16-BA8-2A18-AB8-BA18-2A-A6-BA20-2A4-AB22-DA2-2ABA24-EB2A26-GD2A106-B22-A7-A20-A8-A20-B2(8-A20-F)8-A20-D9-A-A16-D10-A-A16-G10-BA17-E11-A16-D12-A16-L12-B15-AI12-3A12-A2K13-2A12-2K14-AF12-2L12-P2A14-A2G11-2A14-AE12-FA14-2F12-3A13-2F14-A12-B16-A11-2A16-3A9-AB18-ABA4-ABF21-2A4-2A22-AB3-ABA24-B2AB26-4A167-2A18-2A9-A-A16-B10-B-A16-A10-A-A16-A10-H-A16-F10-R-A16-G10-AHA15-2E11-H16-E12-AHA12-A2E13-AB12-2E14-3A11-2I14-ABD9-A3I15-ABD8-K2I17-2F8-KI18-F-A7-AK15-4A-A7-2A2KE13-B2A11-AE15-BA11-E16-2A2-A8-D17-4A7-D18-B3A6-2B18-3AB3-2A2FA22-2A2B26-AB2A26-3AB228-A18-H11-A16-H12-A13-MA-M12-A13-BA-B12-C-A11-4A12-HCA12-A2F13-2H10-A3E14-2HMA8-A3G15-2HJ8-3G17-2H8-EG18-AD2(A2-)2AIK19-DGE-A2-IJI21-DA-A2-2I22-FA-A2-AI21-2FA-A2-A2I17-4A3-A4-A3K15-3A7-2A2G17-BA7-2AG18-B4A4-2AE19-2AFA3-DGD21-BNA2-A2F22-AB3ADAF317-B2E13-AH13-QB12-2C14-2A12-2A14-2C12-BA14-4C4-A3-D3B15-3CMC2(2-A)3D17-2(OC)2-A-DGED18-MHMC2-A-DGD21-2J2-A-EG22-JL2-2A2E22-2DJLIKJI24-G3I25-GEK2I25-2EK3I24-JGLK2I20-2A2F3-A-A4I17-AJ2A3-3AGE18-B3A2-4ALE18-3AF-3AEGDE22-FBDE26-2ABE350-AQBA3-3EAH2A2C16-3AB-5A2C18-2C2AE6AC18-4C5ABDA20-CM4AFD22-CO4AED24-CDGE26-JD2E26-LJDE26-DJLI172-2A2EGLK2IEGK20-AB2-2AGE22-2A3-A2E22-2A2FBDED411-BABG4AH2C20-6AMA22-2C4ABA24-CA2F26-C2DG26-C2DE294-2J2EFEGE24-3FE26-3FD433-
