model
size = 3, scale = 0.05, origin = -y
material 
  colors = A:#99F
voxels
4A-5A-A3-A-5A-4A
