model
size = 20 26 24, scale = 0.05, origin = -y
material 
  colors = A:#EEE B:#BBB C:#111 D:#D00 E:#00E
voxels
92-4B2(16-4C)17-10(B19-)B13-7B457-2E18-2E434-2D18-2D42-2A18-2A190-3(14A6-)3(3A8-3A6-)2(3A-2D5-3A6-)3A8-2(3A6-3A5-2E-)3A6-3A8-2(3A6-3A-2A5-)3A6-3A8-2(3A6-3A5-2A-)2(3A6-3A8-)3A4(6-14A)65-22(16A4-)16A63-22(18A2-)18A61-2(460A3-14A43-)2(460A3-14A8-10A25-)3(460A3-14A8-10A13-4A8-)2(460A3-14A8-10A25-)460A3-14A43-460A3-14A44-22(18A2-)18A63-22(16A4-)16A65-22(14A6-)14A128-16(11B9-)11B189-16(11B9-)11B196-4B16-C2BC16-4C231-B244-4B16-C2BC16-4C231-B172-
