model
size = 31 32 17, scale = 0.05, origin = -y
material 
  colors = A:#FFDF01 B:#FFB302 C:#FFF D:#FED901 E:#FFBA01 F:#FFCF00 G:#FEC300 H:#F8F8F8
voxels
8-5(15B16-)2B2E3BE2B2EB2E16-EB3EB5E2B2E16-15E16-13E2G16-GE2GEGE2G3E3G2(16-15G)16-G2F5GF6G17-3FG4FG2FGF18-11FGF18-13F18-3FD9F18-DF3D3FDFD2F18-6DF5DF18-12DA18-DA10DA17-ADA10D2A14-6ADA3DA2D5A12-6AD3AD8A12-19A13-17A15-15A16-15A18-11A20-11A21-9A49-3(B15-B14-)B15AB6(14-E15AE)2(14-G15AG)14-G15AF2(14-2F13A2F)15-F3(13AF16-D)13AD16-D13AD11-A3D-D14A-4A3(6-25A)7-23A8-23A9-21A12-17A15-15A17-13A19-11A22-7A18-4(B17-B12-)B5(17-E12-E)2(A15-AG12-G)A15-AG12-FA15-AG13-4(F15-F14-)D15-D14-A15-D15-A13-D10-D5-A13-A5-2(D4-)2A13-2A4-D4-A25-A4-2A23-2A4-3A21-3A5-3A19-3A6-4A17-4A7-4A16-3A10-2A15-2A14-2A11-2A17-2A9-2A20-A7-A16-4(B19-B10-)4(E19-E10-)E19-E11-3(G17-G12-)G2(17-F12-F)17-F13-3(D15-F14-)D15-D14-A15-D8-D5-D15-A5-D2-D27-A2-A27-A2-2A25-2A3-2A23-2A4-3A21-3A4-4A19-4A5-4A17-4A7-4A15-4A11-2(A15-)A13-A17-2A9-2A14-5(B19-B10-)4(E19-E10-)E2(A17-AG10-G)A17-AG11-2(F17-F12-)F17-F13-D15-F3(14-D15-D)14-A15-D8-A5-D15-D5-D2(2-A27-A)2-A26-2A2-2A25-2A2-3A23-3A3-3A21-3A4-4A19-4A5-4A17-4A8-3A15-3A2(13-A)17-A11-A14-4(B19-B10-)2(B19-E10-)3(E19-E10-)G19-E2(10-G19-G)10-F19-G2(10-F19-F)11-2(F17-F12-)D17-D12-D17-D13-A15-D7-A6-D15-A6-DA28-ADA28-3A28-2A-A26-2A2-2A25-2A2-3A23-3A3-3A21-3A5-4A17-4A7-4A15-4A11-2A14-A16-A12-A13-5(B19-B10-)E19-B3(10-E19-E)2(10-E19-G)2(10-G19-G)10-F19-G10-F19-F10-FA17-AF10-DA17-AF11-D17-F12-D17-D12-DA15-A2(D6-)D15-A6-2D2(28-ADA)28-3A28-2A-A26-2A2-2A25-2A3-2A23-2A4-3A21-3A6-2A19-2A10-2A15-2A14-2(A13-)4(B19-B10-)2(E19-B10-)4(E19-E10-)G19-E2(10-G19-G)10-G2(19-F10-F)2(A17-AF10-D)A17-AD11-D17-D12-2A15-AD6-D5-2A15-2A5-2A28-ADA3(28-3A)28-2A-A26-2A2-2A25-2A3-2A23-2A5-3A19-3A9-2A15-2A14-2(A13-)5(B19-B10-)E19-B3(10-E19-E)3(10-G19-G)3(10-F19-F)10-FA17-AF10-F2(A17-AD10-D)A17-AD10-3A15-2AD5-A5-2A15-2A5-2D28-A2D3(28-3A)28-2A-A26-2A2-2A25-2A3-2A23-2A5-3A19-3A9-2A15-2A14-2(A13-)5(B19-B10-)4(E19-E10-)E3(19-G10-G)19-G2(10-F19-F)10-F2(A17-AF10-D)A17-AD11-D17-D12-2A15-AD6-A5-2A15-2A5-DA3(28-3A)28-2A-A26-2A2-2A25-2A3-2A23-2A4-3A21-3A6-2A19-2A10-2A15-2A14-2(A13-)5(B19-B10-)E19-E10-E19-B2(10-E19-E)10-E2(19-G10-G)2(19-G10-F)2(19-F10-F)A17-AF10-FA17-AD11-2(D17-D12-)2A15-A2(D6-)A15-A6-2D28-ADA28-2AD28-2A-A26-2A2-2A25-2A2-3A23-3A3-3A21-3A5-3A19-3A7-4A15-4A11-2(A15-)2(A13-)4(B19-B10-)E19-E10-E19-B3(10-E19-E)10-G19-E2(10-G19-G)10-G2(19-F10-F)19-F11-3(F17-D12-)D17-D13-A15-D8-A5-D15-A5-D2(2-D27-A)2-A27-A2-2A25-2A2-3A23-3A3-3A21-3A4-4A19-4A5-4A17-4A8-3A15-3A2(13-A)17-2A9-2A14-5(B19-B10-)E19-B2(10-E19-E)10-E19-2(G10-EA17-A)G10-GA17-AG11-G2(17-F12-F)17-F2(12-HA15-AH)13-2(D15-D14-)D15-A8-D5-A15-A5-D2(2-A27-A)2-2A25-2A3-2A23-2A4-3A21-3A4-4A19-4A5-4A17-4A7-4A15-4A11-2A13-2A16-3A7-3A45-4(B19-B10-)E19-B3(10-E19-E)10-H19-H11-H17-H12-E2(17-G12-G)17-G2(12-F17-F)13-3(C15-C14-)D15-D14-D15-A9-D4-A15-2(A4-)2(D25-A4-)2A23-2A4-3A21-3A5-3A19-3A6-4A17-4A7-4A15-4A10-2A15-2A14-4A7-4A76-4(B17-B12-)2(E17-E12-)H17-H2(12-C17-C)2(12-CA15-AC)12-CA15-AH12-HA15-AH13-C15-H14-C15-C3(14-CA13-2C)14-CA13-AC14-2A13-2A10-3A2-A13-A2-3D6-2DA19-2AD2(6-3A19-3A)7-2A19-2A8-4A15-4A9-3A15-3A12-2(A15-)5A5-5A108-4(2B13-2B14-)2E13-BE14-HC13-CH7(14-2C13-2C)2(14-3C11-3C)15-2C11-2C16-H2(A11-2C16-C)A11-AC16-CA11-AC14-3DA11-3AD11-2(DA)13-2A2D2(10-3A15-3A)11-2A15-2(2A13-)2A15-6A3-6A16-5A5-5A141-2(13B18-)4B5C4B18-3B7C3B18-2EH7CH2E5(18-13C)18-5B2(CB)4C18-4(EC)E4C18-4(GC)5G18-4(FC)F3CF18-D3C2(DC)D3CD18-A3C2(AC)5A4(18-13C)18-DAH7CH2A17-2D2AH5CH4A15-6AH3CH6A14-17A15-15A17-6A-6A195-
