model
size = 17 11 27, scale = 0.05, origin = -y
material 
  colors = A:#070707 B:#050505 C:#0D0D0D D:#0F0F0F E:#0B0B0B F:#0A0A0A G:#0E0E0E H:#090909 I:#080808 J:#0C0C0C K:#101010
voxels
5-7B178-2B7-2B6-2A7-2A6-3I5-3I7-3H3-3H8-9F9-7E12-3J77-BAC7-CAB4-2A9-2A4-I3A5-3AI4-2H2A5-2A2H5-F9AF6-2E7A2E7-3J3A3J10-5C58-B2C9-2CB2-2AC9-C2A2-I2A9-2AI2-H2A9-2AH3-F3A5-3AF4-E3A5-3AE5-J9AJ7-2C5A2C10-5G40-BAC11-CAB2AC11-C2AI2AC9-C2AI-HAC9-C2A2-FAC9-CAF2-EAC9-CAE3-J11AJ5-C9AC7-3G3A3G11-3D24-BC13-CBA15-AIA13-AIHA13-AHF2A-C7-C-2AF-EA-C7-C-AE2-J2AC7-C2AJ3-C3A5-3AC5-2G7A2G8-7D22-BC13-CBA15-AIA13-AIHA13-AHF2A11-2AFE2A11-2AE-J2A-C5-C-2AJ3-2(C2AC5-)GAC5-CAG7-3D3A3D11-3K7-BC13-CBA15-AI15-IH15-HFA13-AFEA13-AE-J2A9-2AJ2-C2A9-2AC3-2GA-C3-C-A2G6-2D5A2D10-5K6-3(BC13-CBA15-AI15-IH15-HFA13-AFEA13-AEJ3A9-3AJ-C2A9-2AC3-G2A2-3C2-2AG5-2D7A2D8-7K5-)BC13-CBA15-AI15-IH15-HFA13-AFEA13-AE-J2A9-2AJ2-C2A9-2AC3-2GA-C3-C-A2G6-2D5A2D10-5K6-BC13-CBA15-AIA13-AIHA13-AHF2A11-2AFE2A11-2AE-J2A-C5-C-2AJ3-2(C2AC5-)GAC5-CAG7-3D3A3D11-3K7-BC13-CBA15-AIA13-AIHA13-AHF2A-C7-C-2AF-EA-C7-C-AE2-J2AC7-C2AJ3-C3A5-3AC5-2G7A2G8-7D22-BAC11-CAB2AC11-C2AI2AC9-C2AI-HAC9-CAH2-FAC9-CAF2-EAC9-CAE3-J11AJ5-C9AC7-3G3A3G11-3D24-BA2C9-2CAB-2AC9-C2A2-I2A9-2AI2-H2A9-2AH3-F3A5-3AF4-E3A5-3AE5-J9AJ7-2C5A2C10-5G40-2B2A2C5-2C2A2B2-2A9-2A4-I3A5-3AI4-2H2A5-2A2H5-F9AF6-2E7A2E7-3J3A3J10-5C57-3B3A5C3A3B3-3A5-3A6-3I5-3I7-2H5-2H8-3F3A3F9-7E12-3J75-5B7A5B5-7A11-5I12-5H13-3F110-2(15B172-)15B173-13B174-13B175-11B177-9B180-5B176-
