model
size = 20 12 31, scale = 0.05, origin = -y
material 
  colors = A:#FD8B68 B:#6E40E5 C:#E824A4 D:#5BCDE6 E:#69F96C F:#FA9E58 G:#FF7877 H:#F9FF75
voxels
7-CH4C232-2B6-2B10-DB6-BD10-EB6-BE10-HB6CBH11-B6CB13-6C130-2B2A6-2A2B6-2D2A6-2A2D7-E2A6-2AE8-H10AH8-2F8A2F9-GB6ABG11-8B15-2C91-B2A10-2AB4-D2A10-2AD5-EA10-AE6-HA10-AH6-F2A8-2AF7-G2A6-2AG9-C8AC11-8G15-2G71-BA12-AB4-DA12-AD4-EA12-AE4-HA12-AH4-FA12-AF5-GA10-AG7-CA8-AC9-G8AG11-8F67-BA14-AB2-DA14-AD2-EA14-AE2-HA14-AH3-FA12-AF4-GA12-AG5-CA10-AC7-G2A6-2AG9-2F6A2F12-6H48-BA14-AB2-DA14-AD2-EA14-AE2-HA14-AH2-FA14-AF3-GA12-AG4-CA12-AC5-G2A8-2AG7-2F8A2F10-H6EH46-B2(A16-A2B)A16-AB-2(BA14-AB2-)BA14-AB3-CA12-AC5-GA10-AG7-F3A4-3AF9-H2E4A2EH13-4D28-C3(A16-A2C)A16-AC-CA14-AC2-BA14-AB3-CA12-AC5-GA10-AG7-F2A6-2AF9-HE6AEH12-D4BD27-2(C3(A16-A2C)A16-AC-CA14-AC2-BA14-AB3-CA12-AC4-C2A10-2AC5-GF2A6-2AFG8-HE6AEH12-D4BD16-2C9-)C3(A16-A2C)A16-AC-CA14-AC2-BA14-AB3-CA12-AC5-GA10-AG7-F2A6-2AF9-HE6AEH12-D4BD27-B2(A16-A2B)A16-AB-2(BA14-AB2-)BA14-AB3-CA12-AC5-GA10-AG7-F3A4-3AF9-H2E4A2EH13-4D29-BA14-AB2-DA14-AD2-EA14-AE2-HA14-AH2-FA14-AF3-GA12-AG4-CA12-AC5-G2A8-2AG7-2F8A2F10-H6EH47-BA14-AB2-DA14-AD2-EA14-AE2-HA14-AH3-FA12-AF4-GA12-AG5-CA10-AC7-G2A6-2AG9-2F6A2F12-6H48-BA14-AB3-DA12-AD4-EA12-AE4-HA12-AH4-FA12-AF5-GA10-AG7-CA8-AC9-G8AG11-8F67-BA14-AB3-D2A10-2AD5-EA10-AE6-HA10-AH6-F2A8-2AF7-G2A6-2AG9-C8AC11-3G2A3G15-2G70-B3A10-3AB3-3D2A6-2A3D6-E2A6-2AE8-H3A4-3AH8-2F8A2F9-2G6A2G11-8C15-2C90-B5A6-5AB3-5D6A5D7-2E6A2E10-3H4A3H11-8F13-6G128-B16AB3-16D9-6E15-4H169-B16AB3-D3BD10BD203-B16AB3-2(DBCB)CB4CBD203-B16AB3-DBC3B2(CB)C2BCBD203-B16AB3-D5(BC)2BCBD203-BD14ADB4-4(BC)B4CB205-D14AD5-5(BC)4B205-D14AD5-B5C2(BC)B3D205-2D12A2E6-10B2D207-2D10A2E8-10D209-3E6A3E11-6E213-8H226-
