model
size = 26 32 25, scale = 0.05, origin = -y
material 
  colors = A:#777 B:#FFB11B C:#222 D:#444 E:#555 F:#FCFAF2 G:#8A6BBE
voxels
14-20(C25-)C311-C519-C311-C4-19(C25-)C20-C4-C306-C4-C514-C4-C301-2(C4-)C15-19(C25-)2(C4-)C301-3(C4-)19(C25-)C10-3(C4-)C296-3(C4-)C504-3(C4-)C119-3(2D3-D20-)2D3-D93-3(C4-)C504-3(C4-)C116-14B12-14B15-2D3-D20-2D2-2(3D23-)3D40-3(C4-)C504-3(C4-)C116-14B12-14B14-8A19-2D2-3D23-3D18-9A17-9A13-3(C4-)C504-3(C4-)C15-3(C25-)C22-3BC10B12-14B14-11A15-9A16-D2(9A17-)2A5E2A13-3(C4-)C504-C9-C4-C116-14B12-14B13-12A15-10A15-D10A15-12A14-3A6E3A11-3(C4-)C504-C9-C4-C20-3(C25-)C16-A8BC5B11-D14B11-2D12A12-3D10A15-D10A15-12A14-2A2E4D2E2A11-3(C4-)C504-C14-C116-14B12-14B13-12A2(D14-10A-)D13-12AD13-A2E2D2C2D2EA11-3(C4-)C504-C14-C10-2(C25-)C3-9E13-C3-9E12-DC-14B9-DE-14B10-E2-12A2(D14-10A-)D13-12AD13-AE2D4C2DEA11-3(C4-)C519-C25-C15-7C3-2(C14-9E2-)C10-2E13BC10-2E12B3D12-12A2D13-10A16-10A15-12A14-AED6CDEA11-3(C4-)C536-G3-G20-2C3-2C18-3E3F3E15-2(14B12-)14B13-12AD14-10A2D14-10A15-12A14-AED6CDEA11-3(C4-)C561-2C3-2C18-3E3F3E15-2(14B12-)14B13-12AD14-10A2D14-10A15-12A14-AE2D4C2DEA11-3(C4-)C536-G3-G20-2C3-2C18-3E3F3E13-2(2D14B10-)2D14B11-D-12AD14-10A2D14-10A15-12A14-A2E2D2C2D2EA11-3(C4-)C162-3CB21-2C2-2B19-2C4-2B17-2C6-2B15-2C23-2C24-8(C25-)10C25-C4-7C14-C3-9E13-2(2D14B10-)2D14B11-2D12A13-2D10A16-10A15-12A14-2A2E4D2E2A11-3(C4-)C15-3(C25-)2(B25-)B440-9E15-3(14B12-)D12AB12-2D-8A-2B15-8A16-10A16-3A6E3A11-C9-C4-C610-2(13B13-)13B15-10AB25-B41-9A17-10A12-C9-C4-C20-3(C25-)2(B25-)B459-2(12B14-)12B17-3D122-C14-C584-D25-A25-4A25-3D23-3D122-C14-C10-3(C25-)2(B25-)B690-4(C25-)2(B25-)B651-
