model
size = 9 48 9, scale = 0.05, origin = -y
material 
  colors = A:#E9CD4C B:#58B2DC C:#E87A90 D:#EBB471 E:#FFF
voxels
138-3CA2(4-5A)4-A3B6-4B4-5B4-B3(3A6-)3A16-C7-3C312-3C2A2-2C4-2(A2-A5-)A2-A4-2B2-AE4-B2-B5-B2-B4-2A2-2B2(3-2A2-2A)3-2A2-A5C4-2C-2CB2-2B3-B2(4-5B)3(4-5A)4-4CA4-4CB4-4B6-4B4-4BA4-4B3(6-3A)6-2A7-3A6-3B6-2B143-2CD4-2C3-A2-C6-2(2A7-)BA6-E2-A6-2B7-AB6-A2-B3(5-A2-A)5-B2-A3(5-B2-B)5-B2(2-A5-A)2-A2(5-C2-C)5-B2-3(B4-)B2-B5-A2-B2(4-A)3-A4-2(A3-)2A3-A4-A2-2A4-A3-A4-A3-B4-B2-2B4-3B17-12(D8-)2D6-C2-2A3-C5-A-C6-2(2A7-)BA7-BC7-2B2(7-AB)3(7-2A)6-B2-C6-BA6-B-B6-4(A2-B5-)2(C2-A5-)B2-A2(5-B2-C)2(5-A2-B)2(5-C2-B)5-B2-B5-B3-A4-B2-A5-B2-A4-C4-4C15-3D12(6-D-D)6-D2-2A3-C5-A-C6-2(2A7-)BA7-BC7-2B2(7-AB)3(7-2A)7-B-C6-BA7-2B6-4(A2-B5-)2(C2-A5-)B2-A2(5-B2-C)2(5-A2-B)2(5-C2-B)5-B2-B3(5-B2-A)4-C3-2C3-C5-4C6-12(D8-)DCD6-D2-A4-C4-A-2C5-2(2A7-)BA7-BC7-2B2(7-AB)7-C3(A7-B)-C6-BA6-B-B6-4(A2-B5-)2(C2-A5-)B2-A2(5-B2-C)2(5-A2-B)2(5-C2-B)5-B2-B3(5-B2-A)4-C3-2(C4-)5C124-C2A5-C3-A-3C4-2(2A7-)BA2(7-BC)7-AC6-A-B6-C2(2-B5-B)2(2-A5-B)3(2-A5-A)2(2-B5-A)2-B2(5-C2-A)5-B2-A2(5-B2-C)A4-A2-B4-C3-B5-C3-B4-C3(3-B)4-B4-A3-B4-4AB4-A3-A4-C3-A5-4A124-CA7-C-B5-C2-B2-3C3-2(B2-A5-)A2-A5-A2-2A4-A2-B4-2A2-B5-C2-2B3-2B2-2B3-B3-2A3-2B2-2A3-2B3-5A3-2A2(3-A)C3-C2(4-5C)3(4-5B)2(4-5A)5-4A4-B3C5-B4C5-3BC5-3B5-4B6-3A15-3A6-3A143-2B7-2B5-2C2B4-A2C2B2(4-5A)5-4A4-4B5-4BC5-2(3B6-)3A6-3A15-3A6-3A165-
