model
size = 26 32 14, scale = 0.05, origin = -y
material 
  colors = A:#EEE B:#BBB
voxels
36-7A796-11A18-7A175-6A20-4(8A18-)8A17-10A2(14-12A)14-13A13-13A12-14A12-15A11-15A10-4(17A9-)16A14-9A117-15A14-2(11A15-)11A16-10A17-8A16-2(9A17-)11A15-3A4-4A16-2A6-2A15-3A6-2A14-4A6-2A13-2(5A6-3A12-)4A8-2(2A12-2A10-)3A3(11-2A)11-3A9-2A4-A7-3A9-2A13-2A8-3A13-2A7-3A15-2A6-3A15-3A5-3A14-4A5-7A7-7A6-19A9-15A15-7A66-3A10-3A11-3A9-2A12-3A9-2A13-3A2-2A-A2-2A13-7A3-3A14-4A-7A13-6A-5A14-2A2-8A14-2A6-5A13-3A8-2A12-4A8-A13-4A8-2A12-3A9-2A12-2A10-2A12-2(A12-2A11-)A12-2A10-2A12-2A9-2(3A13-2A8-)3A14-2(A8-2A15-)A58-2A20-A3-3A17-3A4-4A13-4A6-7A5-7A9-15A14-9A38-3A12-3A10-6(2A11-)3A10-2A11-3A9-3A11-3A8-4A11-2A9-4A2(11-2A10-3A)11-2A10-2A12-A11-3A2(11-A12-2A)11-A3(13-A10-2A)12-3A8-2A2(15-A9-A)15-A25-A108-4A19-2A3-3A17-3A3-5A13-4A6-6A7-6A9-15A14-9B12-2A14-3A7-3A12-3A9-2A12-3A10-2(A13-A11-)2A12-A2(11-2A)11-A12-2A11-A13-A3(11-A12-2A)3(11-A13-A)10-2A13-A10-A14-2A3(9-A15-A)9-A14-2A134-3A21-2A-2A20-2A3-3A-A15-3A4-4A13-4A7-5A7-4A13-3B5-3B11-2(2A14-3A7-)2A14-2A9-A14-2(2A10-A13-)9(A11-A13-)A10-A14-2A4(9-A15-A)9-A14-2A134-2A22-2A-2A21-A3-3A17-3A4-B4A11-4AB7-5A7-4A13-3B5-3B11-2(2A15-2A7-)2A15-2A8-A15-A9-A15-A10-A13-2A10-8(A13-A11-)A13-A10-2(2A13-2A9-)A15-A8-2A2(15-A9-A)15-A134-3A21-2A-3A19-2A3-4A15-4A5-B5A7-5AB10-4A5-4A15-2B5-2B12-2(2A15-2A7-)2A2(15-A9-A)14-A10-A14-10(A11-A13-)2(A10-2A13-)2A8-3A13-2A8-2A14-2A2(8-2A15-A)83-2A25-3A17-4A2-4A15-4A4-6A9-6A7-6AB3-B6A13-2B5-2B38-2A15-2A7-2A14-2A8-2A14-2A9-A14-A10-A14-5(A11-A13-)A2(11-A12-2A)6(11-2A)3(11-A13-A)10-2A13-A10-2A13-2A9-2A13-2A2(8-2A15-A)32-2A25-3A16-3A4-4A13-4A6-5A9-5A8-B5A4-6AB12-3A2B-2B3A64-2A13-3A7-3A13-2A9-2A13-A10-2A13-A11-2A12-A2(11-A12-2A)7(11-2A)10-3A3(11-2A)11-A13-A2(11-A12-2A)3(11-2A)11-BA11-AB2(11-2A)11-A12-2A10-2A13-2A9-2A13-2A8-BA14-2AB7-2A14-3A7-3A13-3A7-4A11-5A7-4A9-5A9-B5A3-5AB13-11A17-A2B-2B67-3A11-3A10-2(2A11-)2(3A9-3A11-)2A10-3A3(11-2A)6-A3-3A11-3A5-A3-3A12-2A5-A3-3A12-A6-A3-2A12-2A9-3A12-2A10-2A13-2A9-2A13-3A7-3A13-2ABA5-AB2A13-AB8-ABA13-BA9-AB13-A10-2A12-2A-8A-3A2(11-2A-8A2-2A)10-BA2-8A3-2B9-2A2-8A3-2A9-3A-8A2-3A9-12A-4A9-18A10-2(B5A)B14-5AB5A18-AB-BA94-15A13-4ABAB3AB15-AB2A-B-2ABA15-2ABA3-AB2A15-2(3AB)3A15-B3ABAB3AB15-A2(B3A)BA15-2AB5AB2A15-2(3AB)3A15-4ABAB4A15-2(B4A)B15-AB4A3-BA16-AB5ABA18-AB3ABA20-2(AB)A19-4AB4A16-11A14-2A9B2A13-AB4-A4-BA13-B2(A4-)AB12-B2A4-A4-2AB11-2A5-A4-3A10-4A4-A4-4A9-5A3-B3-5A10-6ABAB6A13-2(3AB)3A16-AB2A-2ABA146-11A16-B2A2(3-3A18-3A-3A20-5A19-2A-3A-2A17-3A)-A-3A18-3A-3A19-7A20-5A22-3A24-A99-4AB4A16-11A14-13A12-2(15A11-)7A-7A12-5A3-5A188-
