model
size = 26 32 13, scale = 0.05, origin = -y
material 
  colors = A:#EEE
voxels
7-11A18-7A175-6A20-4(8A18-)8A17-10A2(14-12A)14-13A13-13A12-14A12-15A11-15A10-4(17A9-)16A14-9A117-15A14-2(11A15-)11A16-10A17-8A16-2(9A17-)11A15-3A4-4A16-2A6-2A15-3A6-2A14-4A6-2A13-2(5A6-3A12-)4A8-2(2A12-2A10-)3A3(11-2A)11-3A9-2A12-3A9-2A13-2A7-4A13-2A7-3A15-2A6-3A15-3A5-3A14-5A4-7A7-7A6-19A9-15A15-7A66-3A10-3A11-3A9-2A12-3A9-2A13-3A2-2A4-2A13-7A3-3A14-4A-7A13-12A14-2A2-8A14-2A6-5A13-3A8-2A12-4A8-A13-4A8-2A12-3A9-2A12-2A10-3A3(11-A12-2A)9-3A12-2A9-2(3A13-2A8-)3A14-A8-2A15-A7-3A15-A6-2(2A24-)2A20-A3-3A17-3A4-4A13-4A6-7A5-7A9-15A14-9A38-3A12-3A10-6(2A11-)3A10-2A11-3A9-3A11-3A8-4A11-2A9-4A2(11-2A10-3A)11-2A10-2A12-A11-3A2(11-A12-2A)11-A2(13-A10-2A)13-A9-3A13-2A8-2A3(15-A9-A)15-A83-A21-3A-3A19-2A3-3A17-3A3-5A13-4A6-6A7-6A9-15A14-9A28-2A8-3A2(13-2A9-2A)13-A10-2A13-A11-2A12-A10-3A11-3A9-2A12-3A9-2A13-A3(10-2A12-2A)2(11-A13-A)2(10-2A13-A)10-A14-2A3(9-A15-A)9-A14-2A134-3A21-2A-2A20-2A3-3A-A15-3A4-4A13-4A7-5A7-4A13-3A5-3A27-2(2A8-2A14-)2A9-A14-3(2A9-2A13-)3(2A9-A14-)2(A10-2A13-)2(A11-A13-)A10-2A13-A10-A14-2A4(9-A15-A)9-A14-2A134-2A22-2A-2A21-A3-3A17-3A4-5A11-2(5A7-)4A13-3A5-3A28-2(A8-2A15-)2(A9-A15-)A2(9-A14-2A)9-A15-A2(9-A14-2A)9-2A13-2A10-2(A13-A11-)A2(13-A10-2A)13-2A9-2A13-2A2(8-2A15-A)2(9-A15-A)25-A108-3A21-2A-3A19-2A3-4A15-4A5-6A7-6A10-4A5-4A15-2A5-2A29-2(A8-2A15-)2(A9-A15-)A2(9-A14-2A)2(9-2A13-2A)9-2A13-A10-2A5(13-A11-A)13-A10-2A2(13-2A8-3A)13-2A8-2A14-2A2(8-2A15-A)83-2A21-2A2-3A17-3A3-4A15-4A4-6A9-6A7-7A3-7A13-2A5-2A55-A2(8-2A14-2A)3(9-A14-2A)2(9-2A13-2A)10-2(A13-A11-)2(A12-2A11-)6(2A11-)2(A13-A11-)A2(13-A10-2A)13-2A9-2A13-2A2(8-2A15-A)32-2A25-3A16-3A4-4A13-4A6-5A9-5A8-6A4-7A12-5A-5A65-A13-2A8-3A13-2A9-2(2A13-A10-)3A12-A2(10-2A12-2A)7(11-2A)10-3A4(11-2A)12-A11-A12-10(2A11-)A12-2A10-2A13-2A9-2A13-2A8-2A14-2A7-3A14-2A8-3A13-3A8-3A11-3A-A7-4A9-3A11-6A3-6A13-11A17-6A68-2(2A11-3A9-3A11-)3A9-3A11-2A10-3A3(11-2A)10-3A11-3A9-3A12-2A9-3A12-A10-2A12-2A9-3A12-2A2(10-2A13-A)11-A13-2A10-A2(13-2A9-2A)13-A2(10-2A12-2A)3(11-2A)10-2A13-A10-2A13-2A9-3A11-3A9-4A9-3A11-4A7-4A12-13A14-11A18-5A94-7A-7A12-2(5A3-5A13-)5A3-4A14-3(3A6-4A13-)4A5-3A14-4A5-4A13-4A6-2A14-4A5-3A14-4A6-2A14-4A6-3A13-3A7-3A13-2A9-2A14-A9-2A13-2(2A9-A14-)2A9-2A13-2A9-2A12-3A9-3A11-2A10-3A11-3A9-3A11-4A7-4A12-13A14-11A16-9A145-13A16-2(7A19-)7A18-9A17-9A18-5(7A19-)7A18-9A16-10(11A15-)11A16-9A190-
