model
size = 20 12 31, scale = 0.05, origin = -y
material 
  colors = A:#505064 B:#1E1E23 C:#28282D D:#FF8C00 E:#FFED00 F:#008026 G:#004DFF H:#FFF I:#750787 J:#E40303
voxels
7-CE4C232-2C6-2C2(10-BC6-CB)10-BCIGFEDJCB11-CIGFEDJC13-IGFEDJ130-2C2A6-2A2C6-2B2A6-2A2B7-B2A6-2AB8-B10AB8-2B8A2B9-BC6ACB11-8C15-2B91-2CA10-A2C4-B2A10-2AB5-2(BA10-AB6-)B2A8-2AB7-B2A6-2AB9-B8AB11-8B15-2B71-CA12-AC4(4-BA12-AB)5-BA10-AB7-BA8-AB9-B8AB11-8B67-CA14-AC3(2-BA14-AB)3-BA12-AB4-BA12-AB5-BA10-AB7-B2A6-2AB9-2B6A2B12-6B48-4(CA14-AC2-)CA14-AC3-CA12-AC4-CA12-AC5-B2A8-2AB7-2B8A2B10-8B46-3(JA16-AI)-2(JA14-AI2-)JA14-AI3-CA12-AC5-BA10-AB7-B3A4-3AB9-3B4A3B13-4B28-4(DA16-AG)-DA14-AG2-DA14-AG3-CA12-AC5-BA10-AB7-B2A6-2AB9-2B6A2B12-6B27-4(EA16-AF)-EA14-AF2-EA14-AF3-CA12-AC4-B2A10-2AB5-2B2A6-2A2B8-2B6A2B12-6B16-2H9-4(FA16-AE)-FA14-AE2-FA14-AE3-CA12-AC4-B2A10-2AB5-2B2A6-2A2B8-2B6A2B12-6B16-2H9-4(GA16-AD)-GA14-AD2-GA14-AD3-CA12-AC5-BA10-AB7-B2A6-2AB9-2B6A2B12-6B27-3(IA16-AJ)-2(IA14-AJ2-)IA14-AJ3-CA12-AC5-BA10-AB7-B3A4-3AB9-3B4A3B13-2BHB29-4(CA14-AC2-)CA14-AC3-CA12-AC4-CA12-AC5-B2A8-2AB7-2B8A2B10-4BH3B47-JA14-AI3(2-BA14-AB)3-BA12-AB4-BA12-AB5-BA10-AB7-B2A6-2AB9-2B6A2B12-B4HB48-2J14-2I3-3(BA12-AB4-)BA12-AB5-BA10-AB7-BA8-AB9-B8AB11-2BH5B67-2J14-2I3-J2A10-2AI5-2(BA10-AB6-)B2A8-2AB7-B2A6-2AB9-B8AB11-2B3H3B15-2B70-3JD10-G3I3-2JB2A6-2AB2I6-B2A6-2AB8-B3A4-3AB8-2B8A2B9-2B6A2B11-5BH2B15-2H90-3J3D6-3G3I3-2JD2B6A2BG2I7-2B6A2B10-3B4A3B11-2B4H2B13-4BHB128-3J3D3E3F3G3I3-2J3D6B3G2I9-6B15-BH2B169-3J3D3E3F3G3I3-J4H3E3F3H2I203-3J3D3E3F3G3I3-JH3D2E2H2FH2GHI203-3J3D3E3F3G3I3-JH3DEHE2(FH)2GHI203-3J3D3E3F3G3I3-J3HDEHEFHF3H2I203-3J3D3E3F3G3I4-H3DE4HFH2GH205-2J3D3E3F3G2I5-H3DEHE2(FH)2GH205-2J3D3E3F3G2I5-H3DEHEFHF3HI205-2J3D3E3F3G2I6-3DEHEFHF3G207-J3D3E3F3GI8-2D3E3F2G209-3D3E3F3G11-3E3F213-D3E3FG226-
