model
size = 16 26 16, scale = 0.05, origin = -y
material 
  colors = A:#FFF B:#E00 C:#00F
voxels
150-4A10-8A7-2(10A6-)6AB3A6-3A4B3A6-3AB2AB3A6-3AB6A6-3AB2AC3A2(6-10A)6-3A4-3A2(6-2A)185-4A10-8A7-9A7-10A5-3(12A4-)12A3-5(14A2-)14A3-2(4A4-)3A6-3A103-6A9-8A7-10A6-10A5-2(4A4-)2A8-2A3-2A9-3A2-2A10-2A3(2-A12-A)-2A12-3A3(14-2A)14-A66-2A8-2A38-8A8-8A7-10A2(6-2A)5-2A8-2A2(4-A10-A)3-2(A12-A2-)A12-A-A7(14-2A)14-A98-2A8-2A22-A6-A7-A8-A5-A9-A5-A10-A4-A10-A3-2(A12-A2-)A12-A-A7(14-2A)14-A146-2A8-2A5-A7-2A5-A10-A4-A10-A3-2(A12-A2-)A12-A-A8(14-2A)14-A162-2A8-2A5-A8-A5-A10-A4-A10-A3-A12-A2-2(A12-A-A9(14-2A)14-A162-2A8-2A4-2A8-A5-A10-A3-2(A12-A2-))A12-A-A9(14-2A)14-A162-2A8-2A5-A8-A5-A10-A4-A10-A3-A12-A2-A12-A-A9(14-2A)14-A162-2A8-2A5-2A6-2A5-A10-A4-A10-A3-2(A12-A2-)A12-A-A8(14-2A)14-A162-2A8-2A2(6-A)7-A8-A5-A10-A4-A10-A3-A12-A2-A12-A-A9(14-2A)14-A130-2A8-2A22-3A2-3A7-2(2A6-)A8-A6-A8-A5-A10-A4-A10-A3-A12-A2-A12-A-A8(14-2A)14-A114-2A8-2A24-4A11-6A9-8A7-4A2-3A7-2A6-2A5-2A8-2A4-A10-A3-A12-A2-A12-A-A8(14-2A)14-A82-2A8-2A89-2A12-6A9-8A7-2A6-2A5-2A8-2A4-A10-A3-A12-A2-A12-A-A7(14-2A)14-A50-2A8-2A151-6A9-8A7-3A4-3A5-2A8-2A3-10(2A10-2A2-)2A10-2A3-2A8-2A66-
