model
size = 29 21 21, scale = 0.05, origin = -y
material 
  colors = A:#111 B:#00E C:#BBB D:#F60 E:#D00 F:#555 G:#AAA H:#444 I:#0F6
voxels
507-A27-3A27-A579-A577-5C24-5A24-5D24-5A515-9C20-9A20-2D5-2D20-2A5-2A511-13C16-6AC6A16-2D9-2D16-2A9-2A508-15C14-3(3AC)3A14-D13-D14-A13-A507-15C14-15A14-D13-D14-A13-A506-17C12-2AC11AC2A12-D7-I7-D12-A15-A505-17C12-17A12-D7-G7-D12-A15-A504-2C5E2(CE)8C8-23A8-D8-G8-D10-A17-A10-8B4F7B9-2B17-2B7-2B19-2B5-2B21-2B4-B23-B3-2(2B23-2B2-)2B23-2B-2B6(25-4B)25-2B-2(2B23-2B2-)4B2CE5C2(EC)E4CEC4B3-BAC19ACAB5-2BD8-G8-D2B8-A17-A10-6BH2F2H2FH5B9-2B17-2B7-2B19-2B5-2B21-2B4-B23-B3-2(2B23-2B2-)2B23-2B-2B6(25-4B)25-2B-2(2B23-2B2-)4B2C2E4C2E2C6EC4B3-BAC2ACE5AB5A2C2ACAB5-2BD8-F8-D2B8-A8-F5GI2-A10-8B4F7B9-2B17-2B7-2B19-2B5-2B21-2B4-B23-B3-2(2B23-2B2-)2B23-2B-2B6(25-4B)25-2B-2(2B23-2B2-)4B2CE5CECE6CEC4B3-BAC19ACAB5-2BD17-D2B8-A17-A503-2C5E2(CE)8C8-23A8-D17-D10-A17-A504-17C12-17A12-D15-D12-A15-A505-17C12-2AC11AC2A12-D15-D12-A15-A506-15C14-15A14-D13-D14-A13-A507-15C14-3(3AC)3A14-D13-D14-A13-A508-13C16-6AC6A16-2D9-2D16-2A9-2A511-9C20-9A20-2D5-2D20-2A5-2A515-5C24-5A24-5D24-5A12-
