model
size = 20 25 29, scale = 0.05, origin = -y
material 
  colors = A:#B80000 B:#101010 C:#A80000
voxels
281-2(B15-B3-)B15-B423-2B14-B3-3(2B14-2B2-)2B14-B383-B15-B3-B15-5(2B2-2B14-)B343-2B14-B3-BA14-2(2B2-B15-)4(2B2-2B14-)B343-2B14-B3-BA14-2B2-BA14-2(2B-BA15-)2B-BAB2(14-2B2-2B)14-2B342-2B14-2B2-BA14-4(2B-BA15-)2(2B2-2B14-)2B3-B14-B323-2B14-2B2-BA14-2(2B-BA15-)2B-BA16-B2(-BA15-2B-BAB2(14-2B2-2B)14-B323-2B14-2B-B2A14-2B-BA15-2B2(-BA16-B))-BA16-B-BA15-2(2B2-2B14-)B323-2B14-2B-B2A14-2B-BA15-2B-BA16-B-BA16-A2BA16-B-BA15-2B2-2B14-2B2-2B13-2AB322-2B14-2B-BA15-2B-BA16-B-B3(A16-A2B)A15-2B-BAB14-2B2-2B13-2AB3-2A12-2A303-2B14-2B-BA15-2B-B4(A16-A2B)A15-2B-BAB14-2B2-2B13-2AB3-2A11-3A4-4A8-3A7-4A4-4A9-9A227-2B14-B3-2B14-2B-BA15-2B-B4(A16-A2B)A15-2B-BAB14-2B2-2B13-2AB2-B2A11-3A4-4A8-3A6-5A4-4A9-AB8A12-6B208-2B14-2B2-2B14-2B-BA15-2B-B4(A16-A2B)A16-B-BAB14-2B2-2B13-2AB2-B2A11-3A4-3A9-3A2(6-4A)7-11A11-B5AB208-2B14-2B-BAB14-2B-BA15-2B-B4(A16-A2B)A16-B-BAB14-2B2-2B13-2AB2-B2A12-2A4-3A9-4A5-4A6-4A7-11A11-B5ABA207-2B14-2B-BAB14-2B-BA15-2B-B4(A16-A2B)A15-2B-BAB14-2B2-2B13-2AB2-B2A12-2A4-3A10-3A5-3A7-4A7-11A11-3B3ABA187-2B14-B3-2B14-2B-BAB14-2B-BA15-2B-BA16-B-B3(A16-A2B)A15-2B-BAB14-2B2-2B13-2AB2-B2A12-2A4-3A10-3A5-4A6-4A7-12A10-6ABA49-2A10-2A6-2A10-2A5-3A10-2(2A5-2A11-)3A4-2A12-2A4-B2(13-2A3-2B)14-2(2B-BA15-)2B-B4(A16-A2B)A15-2B-BAB14-2B2-2B13-2AB2-B2A12-2A4-3A9-4A5-4A6-4A7-12A10-6ABA31-2A6-2A8-3(4A6-)4A5-4A7-4A2(5-4A8-3A)5-3A10-3A4-2A11-3A3-B2A12-2A3-2B13-2AB-BAB14-6(2B-BA15-)2B-BAB14-2B2-2B13-2AB2-B2A11-3A4-3A9-4A5-4A6-4A7-11A11-6ABA12-8A11-10A9-11A9-12A8-5A2-5A8-4A4-4A8-3A5-4A7-3A7-4A5-3A9-4A3-B2A11-3A3-2B13-2AB2-2B14-2B-BAB14-4(2B-BA15-)2B-BAB14-2B2-2B14-2B2-B2A12-2AB2-B2A11-3A4-3A9-3A6-4A5-5A7-11A11-7B3(14-6A)3(13-7A)C10-5A2-4A8-4A6-3A6-4A8-3A5-2A11-3A3-B2A12-2AB2-2B13-2AB2-2B14-2B-BAB14-3(2B-BA15-)2B2-2B14-2B2-2B13-2AB2-B2A12-2A4-3A10-3A4-4A8-3A6-5A4-4A9-10A12-6A132-A2C4B2C10-4A4-4A6-4A7-4A5-3A10-3A3-B2A12-2A3-2B13-2AB6(2-2B14-2B)2-2B13-2AB2-B2A12-2A4-3A10-3A5-3A8-3A7-4A3-5A9-10A13-4A133-AC-BC2B2C10-3A-8A7-4A5-5A5-4A8-3A5-3A10-3A3-B2A12-2A3-2B13-2AB4(2-2B14-2B)2-2B13-2AB2-B2A12-2A4-2A11-3A4-3A9-3A2(6-4A)7-12A9-9A152-2CB5C11-9AC8-6A2-5A7-4A6-4A5-3A9-4A4-3A10-3A2(3-B2A12-2A)2(3-2B13-2A)2(3-B2A12-2A)4-2A11-3A4-3A9-4A5-3A7-4A6-5A3-5A8-11A11-7A153-2C4B2C12-8A10-11A8-6A2-5A7-4A6-4A5-4A8-3A5-3A10-4(3A4-2A11-)3A4-3A10-3A4-3A9-4A5-3A7-4A6-5A4-4A8-12A9-9A15-2A177-4A13-9A10-11A8-6A-6A7-4A5-5A5-4A7-4A5-4A8-3(3A5-3A9-)3A5-4A8-3A2(6-4A)6-5A3-5A8-12A9-9A13-5A216-4A14-8A11-10A9-12A7-5A3-5A7-4A5-4A2(7-4A6-3A)7-4A5-4A7-5A3-5A8-12A8-11A10-9A13-5A275-6A12-9A11-10A10-10A2(9-11A)2(10-10A)10-9A12-7A16-2A336-6A4(13-7A)14-6A16-2A129-
