model
size = 32 13 26, scale = 0.05, origin = -y
material 
  colors = A:#D8D7DC
voxels
44-8A376-8A405-14A22-6A27-4A342-5A6-5A18-3A6-3A21-A-A4-A-A22-3A-2A-3A23-8A26-4A245-3A12-3A16-2A10-2A18-2A10-2A19-2A8-2A20-A-A6-A-A21-2A-A2-A-2A24-6A211-2(3A14-)2(A14-A16-)A14-A17-2A10-2A19-2A8-2A22-A6-A24-2(2A-)2A177-3A16-3A12-2(A16-A14-)2A14-2A15-A14-A16-A14-A17-2A10-2A19-3A6-3A22-8A144-3A18-3A10-A18-A12-A18-A45-A16-A47-2A12-2A17-2A10-2A20-A8-A24-A-2A-A113-2A20-2A9-2A18-2A11-2(A18-A12-)2A16-2A13-A16-A15-A14-A16-2A12-2A19-A8-A22-4A2-4A25-4A56-2A8-2A14-2A20-2A9-2(A20-A10-)2A18-2A43-2A16-2A46-A14-A17-2A10-2A19-3A6-3A22-2(2A-)2A23-2A6-2A21-2A8-2A13-3A20-3A4-5A20-5A38-A20-A11-A18-A12-A18-A13-A16-A2(14-2A)15-A14-A18-2A8-2A21-A-6A-A22-A8-A46-2A22-2A2(3-A)22-A3-A5-2(A20-A10-)A20-A43-A18-A13-A16-A15-A14-A17-2A10-2A20-3A4-3A25-4A49-2A22-2A2(3-A)22-A3-A4-A22-A41-A20-A10-2A18-2A11-A18-A46-A14-A18-A10-A20-A-A6-A-A23-A-2A-A2(48-2A22-2A2(3-A)22-A3-A4-A22-A9-2(A20-A10-)A20-A11-A18-A13-A16-A15-A14-A17-A12-A19-3A6-3A23-6A)48-2A22-2A2(3-A)22-A3-A4-A22-A41-A20-A10-2A18-2A11-A18-A46-A14-A18-A10-A20-A-A6-A-A23-A-2A-A48-2A22-2A2(3-A)22-A3-A5-2(A20-A10-)A20-A43-A18-A13-A16-A15-A14-A17-2A10-2A20-3A4-3A25-4A49-3A20-3A4-5A20-5A38-A20-A11-A18-A12-A18-A13-A16-A2(14-2A)15-A14-A18-2A8-2A21-A-6A-A22-A8-A47-2A20-2A9-2(A20-A10-)2A18-2A43-2A16-2A46-A14-A17-2A10-2A19-3A6-3A22-2(2A-)2A23-2A6-2A21-2A8-2A14-2A20-2A9-2A18-2A11-2(A18-A12-)2A16-2A13-A16-A15-A14-A16-2A12-2A19-A8-A22-4A2-4A25-4A56-2A8-2A14-3A18-3A10-A18-A12-A18-A45-A16-A47-2A12-2A17-2A10-2A20-A8-A24-A-2A-A114-3A16-3A12-2(A16-A14-)2A14-2A15-A14-A16-A14-A17-2A10-2A19-3A6-3A22-8A146-2(3A14-)2(A14-A16-)A14-A17-2A10-2A19-2A8-2A22-A6-A24-2(2A-)2A179-3A12-3A16-2A10-2A18-2A10-2A19-2A8-2A20-A-A6-A-A21-2A-A2-A-2A24-6A213-5A6-5A18-3A6-3A21-A-A4-A-A22-3A-2A-3A23-8A26-4A247-14A22-6A27-4A334-
