model
size = 26 27 23, scale = 0.05, origin = -y
material 
  colors = A:#100 B:#C93 C:#FF9 D:#FC6 E:#FC3 F:#963 G:#FC9 H:#CC9 I:#CC6 J:#FFC K:#993 L:#FFF M:#F93 N:#630 O:#330 P:#660 Q:#C63 R:#111 S:#001 T:#CCC U:#DDD V:#777 W:#C60 X:#996 Y:#FF6 Z:#C96 Aa:#FCC Ab:#CC3 Ac:#222 Ad:#555 Ae:#444 Af:#F96
voxels
401-4A21-2E3AX20-2BD2AB19-AUBK2AGQ17-10A17-9A17-E2AKFY3A461-ATDC21-2A3BO19-4AKB2A18-8A17-2A2E3AXBD15-3A2BD2ABAJA14-3AUBK2AGQDA13-14A12-2AF10AF12-ADAbE2A3-3AAfD12-AJA8-ADJ380-L4AH20-6A19-BA4-2A17-EH5-O2A16-P8-2A14-2A8-2A13-DA10-AD2(12-I)11-FG12-AF10-12A2-2A10-2A-F2-4A2(2-A)10-2A-Ab8-A2-A10-A-2A9-D-A10-3A11-YA353-6A19-A6-A17-A8-A15-B10-B13-2A11-3(A12-)B12-B11-F14-F2(10-A14-A)10-A3-A5-2A3-A9-CA2-AE2AKFY3A3-C8-A2-JF9-D2-A8-A-2A11-Y2A8-2A14-2A326-6A19-A6-A17-B8-B15-C10-C13-E6-K5-E12-A5-2A5-A11-AB13-3(A10-A14-)A9-B5-A10-B8-B16-B8-D4-G2ACBFAc2A3-D7-BA-2AG4AUB4AY2-A6-3A14-3A7-A317-6A19-8A17-MB2ATDC2AM15-ZEH2A3BO2AZ13-BA3-2A-A3-AB12-2A3-A2-A4-A12-A2(5-2A)3(10-A14-A)9-M16-M8-B16-B8-I16-I7-B18-A6-A2-14A2-A6-2AD14-ABA401-P4A-B3A-A14-A3-2A4-2A12-BA10-A-B10-BJ12-AB10-A14-A9-A16-A6-AAe18-2A4-KE18-AK4-AE4-F13-2A4-A20-A5-A18-A6-2ADL3ADF3AFBE4AB15-3A331-FB2A2-C3A15-KEH2A3BO2AD13-2A4-AK4-AW11-3A11-2A9-IHB13-AM7-AB16-ZC5-I2A16-BEI4-2A18-2A4-A20-A3-A22-B2-A22-G2-2A21-G3-A20-A4-A2-DL3A6-BE3A2-A5-NA5-AD3-M5-2A245-2AIJ2-ABDP16-10A14-2AN10AV12-AJ4-TD4-2B11-2A12-EF9-2A14-2A8-A16-A8-C17-B5-HA19-H4-S20-S4-A20-A2-2A22-V2(2A24-)3A23-4A21-2A2-C4-A10-A4-A5-J3A-2A6-2A-DJ2A166-5A2-5A13-G3AHC3AFLB2A12-C3ABDB2AAaEC2A12-GA3-JNA3-P2A12-2A9-3A11-A14-A10-A14-B9-J16-J8-D16-D8-A16-A7-A18-B5-A20-A3-M22-A-2A22-2ABA22-ABCA22-2C-B22-P-2A2(22-4A)H20-3A3-I5A8-AHBI2A88-BIB2A2-H3AC13-AFCL2AMGCR2AHQ12-2AB4A2B3ASI11-16A10-A14-A10-A14-K2(10-A14-A)9-A16-A8-B16-B8-L16-L8-Q16-Q8-A17-A6-A19-A4-A20-A3-M22-A-2A22-2ALA22-2L-A22-E2-A22-D2-A22-A-2A22-4A22-BH2-4ABHA8-6AB34-7AO6A12-APZQ2ABIB2AIBA11-FABWB2AFCL2AMGCF11-AF10AHQ12-12ASI11-16A10-A14-A10-A14-K10-O15-O2(8-A16-A)8-X16-X8-B16-B8-G17-G6-A18-A5-A20-A4-R20-R2-AM22-4A22-2A-A22-F2-A22-Aa2-A22-B2-A22-A-2A22-A-BA22-FE2-3ANFEP8-5ANF9-C3A3B2AAb2EA13-5AV4AO2A13-A10-2A11-7(3A10-)4A8-A16-A8-C16-C2(8-B16-B)2(8-A16-A)7-2A17-2(A6-A18-)A5-H20-H4-C20-C2-BA22-AB2A22-2A-A22-A2-B22-A2-N2(22-A2-A)22-A-4A3-J10-A4-AJK4-2AJ-A8-A-4A9-2G11-G12-2B11-B12-2A11-2A10-3A11-2A9-3(4A11-3A8-)A16-A8-D16-D8-B16-B8-K16-K2(8-A16-A)7-2(A18-A6-)A18-A5-BA18-B5-GA18-2G3-2A21-AB2A22-4A22-2A-D22-A2-J22-A2-A22-A-2A7-A6-A7-4AGC-5A6-3AGC-4A4-A3-2A6-2A3-A10-2(M12-)A12-IA10-2A12-2A10-AG12-2A9-BEC12-AKB8-NCG12-2AN8-3A12-3A8-A16-A8-T16-T8-B16-B3(8-A16-A)8-D17-D6-K18-K6-A18-A6-I18-I5-MW18-M5-AL18-2A3-A22-3AE22-2ABM22-AB-I22-N-2A8-6A8-4A7-A6-A7-O3AFEC5A6-3AFEC4A32-A12-A11-2A12-IA10-2A12-2A10-CG12-AC9-DEC12-AKD8-JCG12-2AJ8-3A12-3A5(8-A16-A)8-E16-E2(8-B16-B)2(8-A16-A)7-W18-A6-L18-A4-2A20-2A-CE22-ACDM22-ADJB8-IJN2A9-AJ3A6-3A2-2A7-6AAc4ANA6-3AV4AOA2-ABR2AE11-ABR2A34-A2(12-A11-2A)12-A11-HG12-AH9-BEC12-AKB8-ICG12-2AI8-3A12-3A8-3A12-V2A4(8-A16-A)8-E16-E8-B16-B8-U16-U3(8-A16-A)7-LA16-2A6-2A16-2A5-4A14-AMBA4-2ABE5-DB2A5-K2BC4-2ARC3-AI4-BD3-AIDA5-7A6-7A87-LF10-H13-2A10-S13-2A10-A12-AGA5(10-3A)9-4A10-4A8-2A15-A8-B16-B8-H16-H6(8-A16-A)8-B16-B8-LA15-L9-4A9-AIA10-4A9-3A10-FG2A2-C3A2-4A11-C3AB4-AaEC2A12-G2A8-P2A118-C8-A16-B8-A16-A8-A14-G2A8-3A12-C2A8-3A12-G2A8-3A11-4A8-4A10-A14-A10-A14-B10-A14-F2(10-A14-A)10-H14-A10-2(B15-A9-)A14-A10-2A13-B11-A12-QB11-4A2-2A3-AS14-3A2-2A3-2A14-3AHC3AFLBA172-L2AMGCRA18-4A2B2A18-8A16-10AB2A13-10AC2A13-10AP2A12-15A11-A13-A10-A14-B10-A14-F2(10-A14-A)10-H14-A10-B14-B10-B14-A10-2A11-AAdA11-A-A8-ACI13-F2A6-2AH15-B4A2B3A16-10A277-AHC3AFL18-ABDB2AAaE18-AIJN2ABD15-14A12-2AN8-2AV12-AJF9-2B12-AK10-DE12-2A10-AW12-2A10-2A12-BA10-2A12-J2A4-A3-J2A12-G3AU-2A-GQD2A13-AOA2-2A2-3A14-B-A2(2-2A)C14-FC-A2-A-3AH14-ABA6-2AS15-2A6-2A355-2(8A18-)B2ATAC3A16-E3-2B3-A16-P3-AK3-A16-2(2A2-)2A16-2(2A2-)BD17-2A-D3AL20-B2-A21-2A2-2A17-BIA-A2-A-3A14-F-L2AMGCRA-A17-2A2-BA412-2A24-TD21-H2A2-BOA18-3A2-B2A19-2A2-2A20-2E2-AX20-2B2-AB20-UB2-AG20-2A2-2A19-B2A2-H2A25-A243-
