model
size = 29 32 20, scale = 0.05, origin = -y
material 
  colors = A:#222 B:#C36 C:#933 D:#C63 E:#33C F:#693 G:#A83800 H:#C39 I:#E47329 J:#090 K:#06C L:#339 M:#396
voxels
35-6(5A7-5A12-)6A5-6A12-6A5-6A11-7A5-7A3(10-8A3-8A)10-9A-9A10-19A11-3H11A3G12-3B11AG2C12-3B4K7AG2C13-2B4E3A5IC15-B4E3AI4D17-4E3AI3D19-3E4J2(2D20-3E3FJ)2D19-2(4E3FJ3D18-)A3E4F3D19-EBE4F2D20-2EFEFDF2D22-2(EF)I26-2F28-F232-2A20-3A4-3A18-4A4-4A17-5A2-5A17-6A-5A17-13A14-16A13-3H11A2G2(13-3B11AGC)14-2B4K3A5I16-B3EK3AI4D17-4E4J3D18-4E4F3D19-3E3-F2D370-4A25-4A24-6A21-9A19-11A18-12A16-13A16-14A15-14A13-17A12-2(18A11-)4H11AGCG2(11-4B12A2C)11-4B8A4I2C12-3B3E5A4DC14-2B4E4A4DC15-B4E4F4D16-B4E4F4D18-3EF-2F2D21-2E3-FD255-4A25-7A2(18-11A)18-13A3(15-3A8-3A)14-4A8-3A14-4A8-4A12-5A8-5A10-3(6A8-6A9-)5HA8-2AGC2G3(9-5BA8-3A3C)9-5BE8-3D3C11-3B2(E8-3DC14-2B)E8-3DC15-B4E4F4D17-4E4F3D19-3E4F2D22-E4F25-LFD165-3(13A16-)2A2(9-4A13-3A)2(9-5A11-4A)9-6A9-5A9-6A8-5(6A9-7A7-)2H4A9-2AGC3G3(7-6B9-3A4C)7-6BE8-3D4C8-5BE8-3D4C9-4BE8-3D3C11-3BE8-3D2C12-3BE8-3D2C13-2BE8-3DC15-B4E4F4D17-2EJE4F3D19-JHE5FC22-E2FIL133-2(3A11-)4A11-3A10-5A11-5A8-3(5A11-6A7-)8(5A11-7A6-)2H3A11-AGC4G3(6-5B11-2AC-3C)6-5B11-2D-4C6-6B10-2D-4C7-5B10-2D4C8-5BE9-2D4C9-4BE9-2D3C11-3BE9-2D2C13-2BE8-3DC15-J2E7-2DJ16-BH3E4F2DFD17-2EME4FJ2D19-2E2FML2FD23-2FL74-3A14-5A6-4A15-4A6-4(4A15-5A5-)8(4A15-6A4-)3HA15-6G4-4B15-A5C5-4(3B15-A4C6-)5B13-A4C7-5B11-DA3C8-5B11-DA3C9-4BE10-DA2C10-4BE9-2DA2C11-3B2E7-4DC13-KB2E7-3DC15-H4E4F4D16-B4E4F2DMD18-JFE3FC2D21-2ED2F2D23-E2(FL)14-2A19-3A5-13(2A19-4A4-)2H19-4G4-2B19-A3C4-2B19-A-2C4-2B19-4C5-3(B19-3C6-)2B18-3C7-B18-2C8-B18-2C9-B16-AC11-B15-C13-2B10-3D14-2B3E5-2D-DC15-B3E5-2D-D16-B3E5-3DG18-2E5-2D20-HE5-2D12-A21-3A3-9(2A21-4A2-)4(3A20-4A2-)3H20-4G3-3(2B20-3C4-)2B20-3C5-2(B20-2C6-)2B18-3C6-2B18-3C7-2B16-A2C9-B16-AC10-2B15-AD11-A2B10-D3C13-2B2E7-2D2C14-HB2E7-2D2C15-B2E7-2DC16-B2E7-3D17-2E7-2D10-A22-4A-2A9(22-7A)22-5A-3(A22-4A2-)H22-4G2(2-B22-4C)3-B21-2(3C4-2B20-)3C5-B20-2C2(6-2B18-3C)6-2B18-2C8-2B17-2C9-2B16-C10-4B10-A4C11-K2BA9-A2CD13-2BA9-A2C14-KBA9-ACD14-2BA9-A2C16-A9-D9-A11(25-4A)25-5A24-3A-A24-2A2-H24-2G2-2B23-2C2-2B22-A2C2-2B22-3C3-2(2B21-2C4-)2B20-3C5-B19-2(3C6-2B18-)3C7-B18-2C8-2B17-2C9-KB13-3CD10-4BA9-A4C11-3BA9-A2CD12-3BA9-A3C13-2BA9-2AC15-BA9-AC8-A12(26-3A)26-4A25-2A2H25-2G-2B24-C2(2-2B23-2C)2-3B21-3C3-2B21-2C4-2B20-3C4-2B19-4C5-2(2B18-3C6-)2B18-3C7-2B17-2C8-2B17-2C9-2B-B11-4C10-AB-B11-3C12-B-B11-3C13-2B11-AC14-2B11-2C7-A12(26-3A)26-4A25-2A2H25-2G3B24-2C3B23-3C-2B23-2C2-2B22-3C2-3B21-3C3-2B20-3C4-2B19-4C4-3B18-4C5-2(2B18-3C6-)3B16-ACD8-2B15-4C9-3B13-3C10-3B13-3C11-HB13-2C13-B13-C14-K13-C7-2A25-11(3A26-)2(4A25-)2A2H25-2G3B24-2C3B23-3C-2B23-2C2(2-3B21-3C)3-2B20-3C4-2B19-4C4-3B18-4C5-2(2B18-3C6-)3B16-A2C8-HB15-3CD9-3B13-3C10-K2B13-2CD11-2B13-2C13-B13-D14-H13-C8-A24-2A2-A24-2A-2A11(24-5A)24-3A-H24-2G2-B24-2C2(2-B23-3C)2-2B22-3C3-B22-2C4-2B20-3C5-2(2B18-3C6-)2B18-3C7-2B17-2C8-2B16-3C8-2B15-3C10-3B2(A11-4C11-2B)A11-3C13-BA11-2C14-2A11-CD8-6(2A22-3A2-)2A22-3A-3A4(22-7A)22-4A-2(2A22-3A2-)2H22-3G2-2B22-3C3-2(B22-2C4-)2B21-2C4-2B19-4C5-2B18-3C6-2B18-3C7-2(2B17-2C8-)2B17-2C9-2B15-2C10-AB13-D3C10-H3BA9-AD3C11-K2BA9-ADCD12-3BA9-AD2C13-2BA9-ADC15-HA9-AC10-5(2A20-3A4-)2A20-3A3-8(3A20-4A2-)3H20-4G3-2B20-2(A2C4-3B19-)3C5-2(2B18-3C6-)3B17-3C7-2B16-2(A2C8-3B15-)A2C9-3B14-AC10-3B13-2CD11-3B10-AD2C12-2B-2A7-2A-2C12-3B2A7-2AD2C13-KBEA7-2ADC14-2BEA7-2ADC16-EA7-2D12-2(A20-2A6-)A20-2A5-4(2A20-3A4-)2A20-3A3-5(3A20-4A2-)3A20-4A3-2H20-3G4-2B20-A2C4-3B19-A2C5-2B19-2(2C6-2B18-A)2C7-2B17-AC8-2B16-2AC8-3B15-A2C9-2B15-AC10-3B14-AC11-2B13-2C12-K2B10-AD2C13-2B2(2A7-2ADC14-HB)2E7-2A2D15-BFE7-AGD18-J7-D13-2(22A7-)3(23A6-)23A5-7(25A4-)25A5-3H14A6G2(6-6B11A6C)7-5B11A5C2(8-5B8A4D4C)9-2(4B8A4D3C10-)4B2(8A4D2C12-3B)8A4D2C13-2B8A5D14-2B8A4DC14-2B8A3DGC14-KB8A5D15-2BE6A4D18-E6ADF21-E5AF15-3(20A9-)4(21A8-)21A7-6(23A6-)6H11A6G7-2(5B11A5C8-)5B4E7A5C9-2(4B4E4A4D3C10-)4B4E4A4D3C11-2(3B4E4F4D2C12-)3B4E4F4D2C13-2B4E4F4DC14-2B4E4F4DC15-BJ3E4F4D17-B3E4F2DF18-E2FE4F2DF20-2EC3FC22-E2FJ2FD23-BIFIL12-
