model
size = 32, scale = 0.05, origin = -y
material 
  colors = A:#A07561 B:#111 C:#825D4F D:#956857 E:#FFF F:#EEE G:#DC9FB4 H:#FFFFFB I:#3A3226
voxels
6-22B9-22A8-A2C9A3C9A2C5-2C2B7A2C3B2C7A2BC3-C4B6AC2B3G2BC6A3BC2-4B6ACB7GBC6A3B-4BA4D2AB2G6HGB2A3D2A6B2A5DAB2H5B2HBA5DA6B2A5DAI2B5A2BIA5D2A5B27A5B4A5C9A5C4A5B3AC5BC7AC5BC3A5B2AC7BC5AC7BC2A5B2A2BFE5B5A2BFE2(5B2A)B4EBF2B5AB4EBF2B2A5B2AB4E4B5AB4E4B2A5B2ABF2EF4B5ABF2EF4B2A5B2ACB3F3B7AB3F3BC2A5B4A5B9A5B4A5B27A5B19A2C6A5B8A5B2C2A4B6A5BC3A3C2A7B2A4B4AC6B3A4B2A7B2A3BC3AC7BC2A4BAC8BC3BCAC9BC2A30BC56B-30B2-30B3-28B5-26B8-22A8-26A5-4A20C4A3-6C19B5C2-30B-704B-30B2-30B3-28B5-26B8-22B8-26A5-28A3-30A-7C19A6C33B7(30A2B)30A290B30A2B30A161B-30B3-28B5-26B5-28A3-30A-32AC30ACB29A3B7(30A2B)30A290B30A2B30A193B-30B3-28B3-30A-64AC30ACB29A3B7(30A2B)30A290B30A2B30A225B-30B2-30A-64AC30ACB29A3B11(30A2B)3(26A6B)4(30A2B)30A225B-30B-96AC30ACB29A3B11(30A2B)3(26A6B)4(30A2B)3(30A257B96AC30ACB29A3B18(30A2B))30A2B5(3(25A7B)25A2(9B23A)70B96AC30ACB29A3B19(30A2B))3(25A7B)25A2(9B23A)70B96AC31AB12(30ACB19(30A2B)3(25A7B)25A2(9B23A)70B128AC)30ACB19(30A2B)3(25A7B)25A2(9B23A)70B-30A-96AC30ACB19(30A2B)3(25A7B)25A2(9B23A)38B-30B2-30A-96AC30ACB19(30A2B)3(25A7B)25A2(9B23A)38B-30B3-28A3-30A-64AC30ACB19(30A2B)3(25A7B)25A2(9B23A)6B-30B3-28B5-26A5-28A3-30A-32AC30ACB19(30A2B)3(25A7B)25A9B23A6B-2B23A5B3-28B5-26B3-
