model
size = 31 30 9, scale = 0.05, origin = -y
material 
  colors = A:#777 B:#956D95 C:#222 D:#0FC E:#C0FF61 F:#555 G:#8BFFD0 H:#8CCCCC I:#CC8FB7 J:#3CF K:#399 L:#EEE M:#DCEFDC
voxels
12-3A-3A23-2A2(-A)-2A21-4A-A-4A20-5(A-)A19-5A3-5A18-A-2A2(-A)-2A-A18-2(2A-)A2(-2A)18-3A-5A-3A18-2(2A-)A2(-2A)18-6A-6A19-2A-5A-2A20-A2(-3A)-A21-3A-A-3A22-A-5A-A23-3A-3A25-2(A-)A19-2C2DE2-5A2-E2D2C11-2C2D2EG7-G2E2D2C9-2C2D2E2GH5-H2G2E2D2C8-2C2D2E2G2H3-2H2G2E2D2C7-3(2C2D2E2G2HI3-I2H2G2E2D2C6-)2C2D2E2G2HI3-I2H2G2E2D2C5-2C2D2E2G2H2I3-2I2H2G2E2D2C3-2C2D2E2G2H3I3-3I2H2G2E2D2C-2C2D2E2G2H3I5-3I2H2G2E2D4C2D2E2G2HI9-I2H2G2E2D4C2D2E2GH13-H2G2E2D2C-2C2DE19-E2D2C72-9(A11-A18-)2A10-A19-A9-A20-2AF5-F2A21-A2F3-2F2(A22-AB5FB)A23-2(7B24-)3B-3B23-A7BA22-A3B-3B2(A22-A7B)A21-AM8BA2(20-11B)20-A4B-4BA20-3A-3B-3A22-7B269-A11-A18-A11-A49-2A10-A18-2A9-2A19-2(2A7-2A20-)2A7-2A21-4(A7-A22-)A7-A21-3(2A7-2A20-)2A8-A82-A9-A20-3A5-3A20-3FJ3-J3F298-A11-A18-A11-A49-2A9-2A18-2A9-2A19-2A8-A2(20-2A7-2A)21-2(A7-A22-)A7-A21-2(2A7-2A20-)A9-A175-A9-A20-2FJ5-J2F298-2(A11-A49-)2A9-2A19-A9-A20-2A8-A20-2A7-2A21-2(A7-A22-)A7-A21-2A7-2A20-2A8-A20-A9-A175-3A5-3A20-FDJ5-JDF298-A11-A18-A11-A49-2A9-2A18-2A9-2A19-A9-A20-2A8-A20-2A7-2A21-3(A7-A22-)A7-A21-2A7-2A20-2A8-A20-A9-A113-3A5-3A20-FDJ5-JDF298-A11-A18-A11-A49-2A9-2A18-2A9-2A19-2(2A7-2A20-)2A7-2A21-5(A7-A22-)A7-A21-4(2A7-2A20-)ALA5-3A20-ADJ5-JDA236-4(A11-A18-)2(2A9-2A18-)ALA7-ALA19-F2A5-3A20-FLA5-AMA21-6(2A5-2A22-)2A6-3(A22-A7-)A22-3A3-3A22-FDJ3-JDF22-DJ5-JD176-C9-C20-C9-C19-4(AC9-CA18-)A2C7-2CA18-A3C5-3CA19-B3C3-3CB20-2B7C2B21-2(BC)K2(CB)22-3BCKC3B23-2(2BCKC2B24-BC3KCB24-)C2KD2KC24-FC3DCF24-CF3DFC23-2FCDJDC2F22-FC2DJ2DCF22-CFD3JDFC22-F2DJ-J2DF24-J3-J137-
