model
size = 14 17 20, scale = 0.05, origin = -y
material 
  colors = A:#E00
voxels
146-2(A13-)A12-3A12-2A13-A168-A13-A2(11-3A)164-A2-A10-2(A2-2A9-)2(5A9-)5A10-2A109-A13-A4(12-2A)12-4A10-5A9-5A11-2A206-6A8-6A217-2A4-2A6-2A4-2A215-2A6-2A4-2A6-2A214-A8-A4-A8-A213-2A8-2A2-2A8-2A212-A10-A2-A10-A211-2A10-4A10-2A3(210-A12-2A12-A)210-2A10-4A10-2A211-A10-A2-A10-A157-A13-A8-A4-A8-A3-2(2A8-2A2-)2A8-2A3-A8-A117-A13-9(A6-)A5-2A6-2A4-2A6-2A5-A6-A37-A13-2A11-4A10-4A9-5A9-6(6A8-)6A7-8A6-8A7-6A8-5A11-2A54-3(A13-)2A4(11-3A)10-4A10-5A8-7A9-4A11-2A12-2A6-
