model
size = 20 17 11, scale = 0.05, origin = -y
material 
  colors = A:#222 B:#967249 C:#3A3226 D:#855B32 E:#7D532C F:#111 G:#EEE H:#787D7B I:#E03C8A
voxels
26-8A11-2(10A10-)10A11-8A14-4A211-6(14A6-)14A7-12A10-3A2-3A169-14A6-2A10B2A5-3(2A-10B-2A4-)3A10B3A4-5A6B5A4-7A2B7A5-6A2-6A7-4A4-4A10-2A4-2A129-14A5-2(2A12B2A4-)2A12B2A3-2A-12B-2A2(2-3A12B3A)2-4A10B4A2-6A6-6A2-7A4-7A3-6A4-6A2(6-3A)107-14A5-2A12B2A4-2A12B2A3-2(2A-12B-2A2-)2A-12B-2A-3A2(-12B-6A)14-8A10-5A2-2(5A6-)3A6-3A10-2A4-2A12-2A4-2A13-2A2-2A14-5A16-4A11-14A5-2A12B2A4-2A12B2A3-2(2A-12B-2A2-)2A-12B2(-2A)2-12B2-5A-12B-6A14-7A12-4A2-2(5A6-)3A6-3A10-2A4-2A12-2A4-2A13-2A2-2A14-5A16-4A11-14A5-2(2A12B2A4-)2A12B2A3-2(2A-13B2A2-)3A12B3A2-4A10B4A2-5A2-6B5A2-7A4B7A3-6A4-6A2(6-3A)10-2A4-2A89-14A6-2A10B2A5-3(2A-10B-2A4-)3A10B3A4-4A8B4A4-6A4B6A5-5A4B5A7-4A4B4A10-2A4-2A129-3(14A6-)2(5A4-5A6-)14A6-14A7-2ACDB2GBDC2A10-CD4BDC12-CBA2BABC12-CE4BEC12-3C2-3C114-4A13-10A9-2(12A8-)12A9-10A11-8A12-CDB2GBDC12-CD4BDC12-CBA2BABC12-CE4BEC12-3C2-3C195-2I17-H2FH15-DH2FHD13-CDB2GBDC12-CD4BDC12-CBF2BFBC12-CE4BEC12-3C2-3C106-
