model
size = 28 25 20, scale = 0.05, origin = -y
material 
  colors = A:#D00 B:#111
voxels
90-A14-A11-2AB12-B2A10-2BA12-A2B9-A2BA12-A2BA8-B2AB12-B2AB8-B2A2B10-2B2AB2(8-A2B2A10-2AB2A)8-B2A2B10-2B2AB9-2A2B2(10-2B2A)2-2A2B2A2-2A2B10-4(2B2A)2B2(10-4(2A2B)2A)10-4(2B2A)2B11-B3(2A2B)2AB12-A3(2B2A)2BA13-3(2B2A)2B15-A2(2B2A)2BA322-BA-2(2B2A)2B-AB12-B3(2A2B)2AB2(12-A3(2B2A)2BA)2(12-B3(2A2B)2AB)2(12-A3(2B2A)2BA)13-2(3(2A2B)2A14-)3(2B2A)2B16-2(2A2B)2A18-2(2B2A)2B267-B14-B11-2AB12-B2A10-4(2A2B)2A2(2(10-2B14A2B)2(10-18A))10-2B14A2B11-B14AB13-2B10A2B14-2B10A2B15-A2(2B2A)2BA18-B2A2B2AB131-B8-B15-A2BA8-A2BA12-A2BA8-A2BA11-2(2B2AB8-B2A2B10-)3AB2A6-2AB3A9-B6A2B2A2B6AB2(2(8-20A)2(8-B18AB))9-18A10-B16AB11-16A12-16A13-2A2B6A2B2A15-A2B6A2BA17-2(2A2B)2A70-2B2AB8-B2A2B9-A2B2A2B6-2B2A2BA2(8-B6A6-6AB)2(8-6AB6-B6A)8-B6A2B2A2B6AB7-AB18ABA2(2(6-B20AB)2(6-22A))7-20A9-3(18A10-)2B14A2B10-2B14A2B11-A3(2B2A)2BA13-3(2B2A)2B39-2(A4-AB)A4-A7-2B2(4-ABA)4-2B2(6-2A4-2AB4-B2A4-2A)2(6-BA2(4-3A)4-AB)6-2A4-4A2-4A4-2A6-2A4-4A2B4A10(4-2A6-2A4-10A)4-2A2(6-AB4-10A4-BA)7-B4-10A4-B8-BA3-10A3-AB8-2A3-10A3-2A9-18A11-B3(2A2B)2AB8-2(2B6-3A2-3A6-2B4-)2(2A6-A2B2-2BA6-2A4-)2(2B6-3A2-3A6-2B4-)2(2A6-3A2-3A6-2A4-)2B6-3A2B3A6-2B4-2B6-8A6-2B4-2A6-8A6-2A4-2A20-2A2(4-2B20-2B)2(4-2A20-2A)4-2B20-2B5-B20-B6-A20-A6-2A18-2A2(6-2B18-2B)6-2A18-2A7-3A14-3A9-2B14-2B6-2(2(3A6-2AB2-B2A6-3A2-)2(B2A6-3A2-3A6-2AB2-))2(3A6-8A6-3A2-)B2A6-8A6-2AB2-B2A20-2AB2(2-3A20-3A)2(2-B2A20-2AB)3-2A20-2A4-2A20-2A5-2(B20-B6-)2(A20-A6-)2BA16-A2B7-BA16-AB8-2A16-2A4-2(3A9-B2-B9-6A9-B2-B9-3A2BA9-A2-A9-A4BA9-A2-A9-A2B)3A9-4A9-6A9-4A9-3A2BA9-4A9-A4BA22-A2B3A22-6A22-3A-2(BA22-AB2-)2(2A22-2A2-)2B22-2B2-3B20-3B3-2A20-2A4-2A20-2A5-2BA16-A2B7-BA16-AB8-2A16-2A2(4-2(BA10-A2-A10-A2BA10-A2-A10-AB2A10-B2-B10-4A10-B2-B10-2A)B2(A10-A2B)A10-4A10-AB2A2(10-4A)24-2ABA24-A2BA24-AB2A24-2A-A24-A2(2-B24-B)2(2-3A20-3A)2-2BA20-A2B3-BA20-AB5-2A18-2A7-A18-A8-B18-B)2(4-2(2A10-B2-B10-4A10-B2-B10-2ABA10-A2-A10-A2BA10-A2-A10-AB)2A3(10-4A)10-2ABA10-4A10-A2BA24-AB2A24-4A24-2A2B24-2B-B24-B2(2-A24-A)2(2-B2A20-2AB)2-3A20-3A3-2A20-2A5-2B18-2B7-B18-B8-A18-A)4-2(BA10-A2-A10-A2BA10-A2-A10-AB2A10-B2-B10-4A10-B2-B10-2A)B2(A10-A2B)A10-4A10-AB2A2(10-4A)24-2ABA24-A2BA24-AB2A24-2A-A24-A2(2-B24-B)2(2-3A20-3A)2-2BA20-A2B3-BA20-AB5-2A18-2A7-A18-A8-B18-B4-BA10-A2-A10-A2BA10-A2-A10-AB2A10-B2-B10-4A10-B2-B10-2ABA9-2A2-2A9-A2BA9-A4-A9-AB2A9-A4-A9-4A9-A4-A9-2ABA9-A-2B-A9-A2BA9-2A2B2A9-AB2A2(10-4A)24-2ABA24-A2BA24-AB-4(B24-B2-)3A20-3A2-3A20-3A3-BA20-AB4-BA20-AB5-2A18-2A7-2A16-2A8-BA16-AB4-3A8-A4-A8-6A8-A4-A8-3AB2A8-B4-B8-2A2B2A8-B4-B8-2AB3A8-A4-A8-6A8-A4-A8-3AB2A8-A4-A8-2A2B2A8-A4-A8-2AB3A8-A4-A8-6A8-A4-A8-3A2BA8-6A8-A2B-BA22-AB2(2-2A22-2A)2(2-BA22-AB)2(2-AB22-BA)2-2BA20-A2B3-BA20-AB2(4-2A20-2A)5-2B18-2B7-B3A12-3AB9-2BA12-A2B5-2(3A8-A4-A8-6A8-A4-A8-3AB2A8-B4-B8-2A2B2A8-B4-B8-2AB)3A8-A4-A8-6A8-A4-A8-3A-BA8-6A8-AB2-BA22-AB2(2-2B22-2B)2-2A22-2A3-A22-A3-2B22A2B2-2B22A2B3-24A4-24A5-22A6-22A7-B18AB9-18A11-B3(2A2B)2AB7-2(2(2B6A2B6-2B6A2B2-)2(10A6-10A2-))2(2B9A4-9A2B2-)10A2B2A2B10A2-26A2-2B22A2B3-B22AB2(4-24A)4-B22AB5-22A2(6-2B18A2B)7-A2B14A2BA8-A2B14A2BA9-4(2A2B)2A10-4(2A2B)2A36-6AB8-B6A5-B6AB8-B6AB2(4-8A8-8A)2(4-B6AB8-B6AB)2(4-9A6-9A)2(4-B6A2B6-2B6AB)4-9A6-9A4-9A2B2A2B9A4-B22AB5-22A2(6-2B18A2B)7-2(20A8-)B18AB9-18A10-2B14A2B11-B14AB13-3(2B2A)2B68-2BA12-A2B9-A2B2A10-2A2BA7-2B2A2B10-2B2A2B6-2B2A2BA8-A2B2A2B2(6-6AB8-B6A)2(6-2B2A2BA8-A2B2A2B)2(6-6AB8-B6A)6-2B5A8-5A2B6-2B5A2-B2AB2-5A2B7-5A2B6A2B5A8-20A8-B18AB9-2(18A10-)B16AB11-16A12-16A13-3(2A2B)2A15-A2(2B2A)2BA92-
