model
size = 31 32 17, scale = 0.05, origin = -y
material 
  colors = A:#F8F8F8 B:#00C C:#E00 D:#888 E:#F99 F:#CF0 G:#777 H:#60F I:#FC3 J:#070707
voxels
8-3(15A16-)2(15B16-)15A2(16-15C)5(16-15A)17-7(13A18-)13A17-15A14-2(19A12-)19A13-17A15-15A16-15A18-11A20-11A21-9A49-3(A15-A14-)2(17B14-)17A2(14-C15AC)7(14-17A)15-4(15A16-)15A11-4B-15A-4B3(6-25A)7-23A8-23A9-21A12-17A15-15A17-13A19-11A22-7C18-3(A17-A12-)2(B17-B12-)A17-A2(12-C17-C)12-A17-A4(12-2A15-2A)13-5(A15-A14-)2(A15-)A13-A10-B5-A13-A5-B4-A4-2A13-2A2(4-A)25-A4-2A23-2A4-3A21-3A5-3A19-3A6-4A17-4A7-4A16-3A10-2A15-2A14-2A11-2A17-2A9-2A20-C7-C16-3(A19-A10-)2(B19-B10-)A19-A2(10-C19-C)10-A19-A11-5(A17-A12-)A17-A13-4(A15-A14-)A15-A8-B5-A15-A5-B2(2-A27-A)2-2A25-2A3-2A23-2A4-3A21-3A4-4A19-4A5-4A17-4A7-4A15-4A11-2(A15-)A13-A17-2C9-2C14-3(A19-A10-)2(B19-B10-)A19-A2(10-C19-C)10-A19-A3(10-2A17-2A)11-2(A17-A12-)A17-A13-4(A15-A14-)A15-A8-B5-A15-A5-B2(2-A27-A)2-A26-2A2-2A25-2A2-3A23-3A3-3A21-3A4-4A19-4A5-4A17-4A8-3A15-3A2(13-A)17-C11-C14-3(A19-A10-)2(B19-B10-)A19-A2(10-C19-C)7(10-A19-A)11-3(A17-A12-)A17-A13-A15-A7-B6-A15-A6-BA2(28-3A)28-2A-A26-2A2-2A25-2A2-3A23-3A3-3A21-3A5-4A17-4A7-4A15-4A11-2A14-A16-C12-C13-3(A19-A10-)2(B19-B10-)A19-A2(10-C19-C)7(10-A19-A)2(10-2A17-2A)11-2(A17-A12-)2A15-2A6-B6-A15-A6-BA3(28-3A)28-2A-A26-2A2-2A25-2A3-2A23-2A4-3A21-3A6-2A19-2A10-2A15-2A14-2(C13-)3(A19-A10-)2(B19-B10-)A19-A2(10-C19-C)7(10-A19-A)3(10-2A17-2A)11-A17-A12-2A15-2A6-B5-2A15-2A5-BA4(28-3A)28-2A-A26-2A2-2A25-2A3-2A23-2A5-3A19-3A9-2A15-2A14-2(C13-)3(A19-A10-)2(B19-B10-)A19-A2(10-C19-C)7(10-A19-A)4(10-2A17-2A)10-3A15-3A5-B5-2A15-2A5-BA4(28-3A)28-2A-A26-2A2-2A25-2A3-2A23-2A5-3A19-3A9-2A15-2A14-2(C13-)3(A19-A10-)2(B19-B10-)A19-A2(10-C19-C)7(10-A19-A)3(10-2A17-2A)11-A17-A12-2A15-2A6-B5-2A15-2A5-BA3(28-3A)28-2A-A26-2A2-2A25-2A3-2A23-2A4-3A21-3A6-2A19-2A10-2A15-2A14-2(C13-)3(A19-A10-)2(B19-B10-)A19-A2(10-C19-C)7(10-A19-A)2(10-2A17-2A)11-2(A17-A12-)2A15-2A6-B6-A15-A6-BA2(28-3A)28-2A-A26-2A2-2A25-2A2-3A23-3A3-3A21-3A5-3A19-3A7-4A15-4A11-2(A15-)2(C13-)3(A19-A10-)2(B19-B10-)A19-A2(10-C19-C)7(10-A19-A)11-3(A17-A12-)A17-A13-A15-A8-B5-A15-A5-B3(2-A27-A)2-2A25-2A2-3A23-3A3-3A21-3A4-4A19-4A5-4A17-4A8-3A15-3A2(13-A)17-2C9-2C14-3(A19-A10-)2(B19-B10-)A19-A2(10-C19-C)10-A19-A3(10-2A17-2A)11-3(A17-A12-)2A15-2A12-2A15-2A13-2(A15-A14-)A15-A8-B5-A15-A5-B2(2-A27-A)2-2A25-2A3-2A23-2A4-3A21-3A4-4A19-4A5-4A17-4A7-4A15-4A11-2A13-2A16-3A7-3A45-3(A19-A10-)2(B19-B10-)A19-A2(10-C19-C)10-A19-A11-5(A17-A12-)A17-A13-4(A15-A14-)A15-A9-B4-A15-A4-B2(4-A25-A)4-2A23-2A4-3A21-3A5-3A19-3A6-4A17-4A7-4A15-4A10-2A15-2A14-4A7-4A76-3(A17-A12-)2(B17-B12-)A17-A2(12-C17-C)12-A17-A4(12-2A15-2A)13-2(A15-A14-)4(2A13-2A14-)2A13-2A10-3B2-A13-A2-3B3(6-3A19-3A)7-2A19-2A8-4A15-4A9-3A15-3A12-2(A15-)5A5-5A108-3(2A13-2A14-)2(2B13-2B14-)2A13-2A2(14-2C13-2C)5(14-2A13-2A)2(14-3A11-3A)15-4(2A11-2A16-)2A11-2A14-2(4A11-)4A13-4A2(10-3A15-3A)11-2A15-2(2A13-)2A15-6A3-6A16-5A5-5A141-2(2A2D5E2D2A18-)AG2D5E2DGA18-BG2D5E2DGB18-BG3D3E3DGB18-AG9DGA2(18-3E7D3E)2(18-AEA7DAEA)18-3A3DA3D3A18-4A2DA2D4A18-4A2(D3ED4A18-AI2A)2DE3D3A18-AIE7D2EA18-2E3F3D3F2E18-2EFJF3DFJF2E18-2E3F3D3F2E18-3E7D3E18-4E5D4E17-A4EA3HA4EA15-2A4EA3HA4E2A14-3A2E3AH3A2E3A15-15A17-6A-6A195-
