model
size = 31 32 17, scale = 0.05, origin = -y
material 
  colors = A:#606 B:#D00 C:#060606 D:#FFF
voxels
8-12(15A16-)15A17-6(13A18-)4A5D4A18-3AD5AD3A17-4AD5AD4A14-2(19A12-)6A2D3A2D6A13-5A2D3A2D5A15-15A16-15A18-11A20-11A21-9A49-3(A15-A14-)11(17A14-)17A15-4(15A16-)15A11-4A-15A-4A3(6-25A)7-23A8-23A9-21A12-17A15-15A17-13A19-11A22-7A18-9(A17-A12-)3(2A15-2A12-)2A15-2A13-5(A15-A14-)2(A15-)A13-A10-A5-A13-A5-2(A4-)2A13-2A2(4-A)25-A4-2A23-2A4-3A21-3A5-3A19-3A6-4A17-4A7-4A16-3A10-2A15-2A14-2A11-2A17-2A9-2A20-A7-A16-8(A19-A10-)A19-A11-5(A17-A12-)A17-A13-4(A15-A14-)A15-A8-A5-A15-A5-2(A2-A27-)A2-2A25-2A3-2A23-2A4-3A21-3A4-4A19-4A5-4A17-4A7-4A15-4A11-2(A15-)A13-A17-2A9-2A14-9(A19-A10-)2(2A17-2A10-)2A17-2A11-2(A17-A12-)A17-A13-4(A15-A14-)A15-A8-A5-A15-A5-2(A2-A27-)A2-A26-2A2-2A25-2A2-3A23-3A3-3A21-3A4-4A19-4A5-4A17-4A8-3A15-3A2(13-A)17-A11-A14-14(A19-A10-)A19-A11-3(A17-A12-)A17-A13-A15-A7-A6-A15-A6-2A2(28-3A)28-2A-A26-2A2-2A25-2A2-3A23-3A3-3A21-3A5-4A17-4A7-4A15-4A11-2A14-A16-A12-A13-15(A19-A10-)2A17-2A10-2A17-2A11-2(A17-A12-)2A15-2A2(6-A)15-A6-2A3(28-3A)28-2A-A26-2A2-2A25-2A3-2A23-2A4-3A21-3A6-2A19-2A10-2A15-2A14-2(A13-)15(A19-A10-)2(2A17-2A10-)2A17-2A11-A17-A12-2A15-2A6-A5-2A15-2A5-2A4(28-3A)28-2A-A26-2A2-2A25-2A3-2A23-2A5-3A19-3A9-2A15-2A14-2(A13-)15(A19-A10-)4(2A17-2A10-)3A15-3A5-A5-2A15-2A5-2A4(28-3A)28-2A-A26-2A2-2A25-2A3-2A23-2A5-3A19-3A9-2A15-2A14-2(A13-)15(A19-A10-)2(2A17-2A10-)2A17-2A11-A17-A12-2A15-2A6-A5-2A15-2A5-2A3(28-3A)28-2A-A26-2A2-2A25-2A3-2A23-2A4-3A21-3A6-2A19-2A10-2A15-2A14-2(A13-)15(A19-A10-)2A17-2A10-2A17-2A11-2(A17-A12-)2A15-2A2(6-A)15-A6-2A2(28-3A)28-2A-A26-2A2-2A25-2A2-3A23-3A3-3A21-3A5-3A19-3A7-4A15-4A11-2(A15-)2(A13-)14(A19-A10-)A19-A11-3(A17-A12-)A17-A13-A15-A8-A5-A15-A5-3(A2-A27-)A2-2A25-2A2-3A23-3A3-3A21-3A4-4A19-4A5-4A17-4A8-3A15-3A2(13-A)17-2A9-2A14-9(A19-A10-)2(2A17-2A10-)2A17-2A11-3(A17-A12-)2A15-2A12-2A15-2A13-2(A15-A14-)A15-A8-A5-A15-A5-2(A2-A27-)A2-2A25-2A3-2A23-2A4-3A21-3A4-4A19-4A5-4A17-4A7-4A15-4A11-2A13-2A16-3A7-3A45-8(A19-A10-)A19-A11-5(A17-A12-)A17-A13-4(A15-A14-)A15-A9-A4-A15-2(A4-)2(A25-A4-)2A23-2A4-3A21-3A5-3A19-3A6-4A17-4A7-4A15-4A10-2A15-2A14-4A7-4A76-9(A17-A12-)3(2A15-2A12-)2A15-2A13-2(A15-A14-)4(2A13-2A14-)2A13-2A10-3A2-A13-A2-3(3A6-3A19-)3A7-2A19-2A8-4A15-4A9-3A15-3A12-2(A15-)5A5-5A108-13(2A13-2A14-)3A11-3A14-3A11-3A15-4(2A11-2A16-)2A11-2A14-2(4A11-)4A13-4A2(10-3A15-3A)11-2A15-2(2A13-)2A15-6A3-6A16-5A5-5A141-7(13A18-)3(AC)2(A2C)A18-A2C2ACA2(C2A)18-3(AC)2(2AC)A18-A2C2AC2(A2C)A18-13A18-6AB6A18-5A3B5A18-4A5B4A18-3A7B3A18-2A9B2A18-2A4BA4B2A18-2(3A2B)3A18-13A18-5A3C5A17-7AC7A15-8AC8A14-7A3C7A15-15A17-6A-6A195-
