model
size = 14 17 26, scale = 0.05, origin = -y
material 
  colors = A:#EEE B:#111 C:#DDD
voxels
18-3(6C8-)6A8-6A161-3(8C6-)8B6-2(2BA)2B7-2(2B2(AB)8-)BA2BAB9-A2BA11-2A106-2(C4(A-)C4-)C8AC4-B8AB4-10B5-5(8B6-)8B8-4B11-2B63-2(C5(A-)C2-)C10AC2-B10AB2-12B3-5(B8-B4-)B8-B5-8B7-6B8-6B9-4B34-2(C5(-A)C2-)C10AC2-B10AB2-12B3-5(B8-B4-)B8-B5-5(B6-)B45-C2(6(-A)2C)12ACB12A15B-5(B10-B2-)B10-B3-B8-B4-B8-B58-C2(6(A-)2C)12ACB12A17B4(10-B-2B)10-B2-B10-B3-B8-B4-B8-B58-C2(6(-A)2C)12ACB12A17B4(10-B-2B)10-B2-B10-B3-B8-B4-B8-B58-C2(6(A-)2C)12ACB12A17B3(10-B-2B)10-B2-B9-2B2-B9-B4-2(B7-B5-)B7-B45-C2(6(-A)2C)12AC14A16B2(10-B-2B)10-B2-B9-B3-B9-B4-B7-B6-B5-2B6-2(B5-B7-)2B3-2B8-B3-B19-2(C5(A-)AC-)C11AC-13A-A11BA-AB9-A2-2B9-B3-B9-B3-2B7-2B4-B7-B2(6-B5-2B)6-2B3-2B8-B3-B9-5B10-3B11-3B6-C2(5(-A)2(-C))11AC-B11AB-A11BA-AB9-A2-AB9-A3-B9-B3-2B7-2B4-B7-B6-B5-2B6-2B3-2B7-2B3-2B8-5B10-3B11-3B20-2(C5(A-)AC-)C11AC-B11AB-13B-2B9-B2(3-A9-A)3-2B7-B5-B7-B6-B5-B7-2B3-2B8-5B9-5B10-3B34-C2(5(-A)2(-C))11AC-B11AB-13B-2B9-B3-B9-B3-A9-A4-A7-A5-B7-B6-7B8-5B9-5B10-3B48-2(C5(A-)AC-)C11AC-13A-13B-2B2(9-B3-B)9-B4-A7-A5-B7-B6-7B8-5B10-3B62-C2(5(-A)2(-C))11AC-13A-A11BA2-A9-A2(3-B9-B)4-B7-B5-B6-B7-7B9-3B76-2(C5(A-)AC-)C11AC-B11AB-A11BA2-A9-A3-AB8-A4-2B6-B5-2B5-B7-B4-2B8-5B89-C2(5(-A)2(-C))11AC-B11AB-13B2-B9-2B3-A8-A4-AB6-A6-B5-B7-6B103-C2(6(A-)2C)12ACB12A15B-B10-B3-B8-B5-A5B-A6-7B8-5B104-2(C5(A-)AC-)C11AC-B11AB-13B2-B9-B3-2B7-B5-6B-B7-6B10-2B105-C2(5(-A)2(-C))11AC-B11AB-13B2-B9-B4-B7-B6-7B8-4B118-2(C5(A-)AC-)C11AC-B11AB-13B2-B9-B4-B7-B6-7B9-2B119-C2(5(-A)2(-C))11AC-B11AB-13B2-B9-B4-2B5-2B7-4AB132-2(C5(-A)C2-)C10AC2-B10AB2-12B3-B7-2B5-6AB145-2(C4(A-)AC3-)C9AC3-B9AB3-11B4-2A4B2AB7-4A148-2(C3(A-)2C5-)C6A2C5-8AB5-A6BAB6-6A158-
