model
size = 18 8 12, scale = 0.05, origin = -y
material 
  colors = A:#595959 B:#9F5B17
voxels
5-A8-A4-2(2A3-2A2-)ABA-ABA2-ABA-ABA3-2(2(AB)A4-)A3BA4-A3BA3-A5BA2-A5BA-3A3B6A3B3A2-2AB2A4-2AB2A40-2(A12-A4-)A12-A130-A12-A4-9(A12-A130-)A12-A38-
