model
size = 9 8 27, scale = 0.05, origin = -y
material 
  colors = A:#EEE B:#444 C:#500 D:#200 E:#700 F:#DDD G:#888 H:#222
voxels
57-3C6-BDB59-5C4-2(BD)B57-7C2-3(BD)B10-2A2(5-4A)5-2A19-7C2-3(DB)D-2A5-3A2(7-2A)7-3A5-2A10-7C2-3(BD)B-2A5-3A7-AC7BCA2-3B2-3A2-B2-2A4-B5-2CHBH2C2-3(DB)D-2A5-3A2(7-2A)3-B3-3A2-B2-2A4-B5-2C3B2C2-3(BD)B10-2A2(5-4A)5-2A4-B8-B5-2CHBH2C2-7E56-2C3F2C2(2-7E56-C5FC)2-7E56-3(CF)C2-3(DB)D56-C5FC2-3(BD)B56-2C3D2C2-3(DB)D56-2C3A2C2-3(BD)B56-2(GC)3G2-3(DB)D56-GCG3CG2-3(BD)B56-C2GC3G2-3(DB)D56-2(GC)G2C2-3(BD)B10-2A2(5-4A)5-2A4-B8-B5-GCHBH2G2-3(DB)D-2A5-3A2(7-2A)3-B3-3A2-B2-2A4-B5-2C3B2C2-3(BD)B-2A5-3A7-AC7BCA2-3B2-3A2-B2-2A4-B5-2CHBH2C2-3(DB)D-2A5-3A2(7-2A)7-3A5-2A10-7C2-3(BD)B10-2A2(5-4A)5-2A19-7C2-3(DB)D56-7C2-3(BD)B57-5C4-2(BD)B59-3C6-BDB3-
