model
size = 13 16 14, scale = 0.05, origin = -y
material 
  colors = A:#111 B:#EEE
voxels
16-9(5A8-)5A9-4A9-3A10-A53-2A9-4A7(8-5A)8-4A9-2A11-A50-8A4(4-9A)3-2(9A4-)9A5-8A6-7A6-6A8-5A8-4A9-2(3A10-)2A18-A12-A2-2A8-A2-A9-A2-A2(8-A3-B)8-2A2-B8-2A2-6A3-A4-8A7-3A2-A79-2A11-3(2A-A9-)3(2A-B9-)2A-5A5-A3-9A6-6A9-2A68-2(2A11-)2(2A-A9-)2(2A-B9-)2A-3A7-2A-4A6-A2-4A6-A3-9A8-4A68-2(A12-)2(2A11-)AB2(9-2A-A)9-2A-3A6-2A2-4A5-2A3-3A5-A5-8A67-2(A12-)2(2A11-)2A9-2A-A9-2(2A-)2A5-2A-5A3-3A2-5A3-3A3-4A3-2A5-8A67-2(A12-)2A11-2A3(9-2A-A)9-A2(2-7A-3A)3-6A-3A4-8A67-A12-A10-2(2A-A9-)2A-B2(9-2A-A)9-2(A2-9A-)A3-10A4-7A66-2A11-2A2-A8-2A-2(A9-A2-)2(B9-A2-)A8-A2(3-10A)4-9A6-6A66-2A11-A2-2A8-2(A2-A9-)A2-B9-A2-2(B8-A3-)3A-6A4-2A-6A6-7A8-2A68-A11-2A2(2-A9-A)2-A3(8-A3-B)A7-A3-5A-2A-A4-4A-2A-A6-4A-A71-A2(5-2A4-2A)3-A-2(2A4-2A5-)2(2A3-3A5-)A4-3A5-A5-3A2-3A6-2A2-3A2(8-5A)8-2(4A9-)3A10-2A7-
