model
size = 31 32 13, scale = 0.05, origin = -y
material 
  colors = A:#200 B:#2A0000 C:#270D00 D:#C9C971 E:#B9B95F F:#9A9A9A G:#616151 H:#ABABAB I:#555 J:#7F7E6E
voxels
687-B-A15-B-A10-ACB2C-C7-B-B4C11-C2A-A9-C-2BC13-A-B11-B-B16-A11-A17-BA11-AB818-AC2A15-3AC8-C-2ACB3C5-A3B3AFC9-CB3A-B7-C-C2A2C12-AB-A9-C-CA15-CB11-2A16-BC11-2A786-CB21-BA6-A-C19-C-C5-HB-A4-2BCB3-CB2C4-AFCH4-F-BHA3-A-C5-AFC3-AFC-F4-F2-5AFA7-AH4AB2-F4-2F2-2A2-CB7-BA-FAC2-HF5-FH2-2DED9-2E2D3-H655-CB25-2B-AC27-AB2A27-BC-F-B23-A-A2-FH2C21-A-FH2-2H-C21-A-2F2-HACA6-A2CB-B3C6-A2BH5-BA5-A-A3-2BA5-2A8-A-A2CAB2A5-A2CBCBAHB9-A-4D-C5-BFHDED-A11-E3DED7-D3-2D-F11-2(ED)9-4D109-ABA7-2AB16-2AB11-A2B12-2AB15-2AB9-2B19-BA8-B21-B7-2A21-2A2(6-A23-B)5-BA23-B2(A4-B25-)A3-2B25-2A2-B27-A2-A27-B-BA27-2AB29-BA29-BC2B25-ACA31-C29-B3CB23-CB2A2-BCB21-B-C4-CFB21-A-B4-BHA7-ACA-2BA7-AFA5-2A7-BF2(C-)C7-AB7-2A2(CB)3CA3-3(2CA)C8-B-2(DE)DH-B3-B3FDE2DFB9-E-2(IG)ED5-D-2(GI)2DF10-D4-E7-E4-D108-B-A7-A-A16-A-A11-A-B11-BA-B15-B-2A8-BA19-BA7-3A19-3A6-2A21-2A6-AB21-2B5-2(2A23-AB4-)AB23-2A3-2(AB25-2A2-)2A25-BA-AB27-2A2B27-4A27-3A29-AB29-C31-C29-2ABCA23-ACAB-CHA23-AFC3-BA23-2A4-BA9-CB2CA8-AHC4-CBA8-BC-2C8-ABC5-AHA2CB4AB3-A3C2ACACHC7-BED3EDHFB3-2D2E2DEDHC8-E-2G2(IG)2D3-D-3GIGIDF9-D6-D5-D6-DF30-H29-2F25-FH17-B-A7-A-B16-B-A11-A-A12-B-A15-A-A9-2A19-2A8-AB19-2A7-2A21-BA6-2A21-2A6-B23-B5-BA23-2A4-2B23-2A4-A25-A3-2A25-2A2-AB25-2A2-A27-A-BA27-2ABA27-B2A29-BA29-A31-A29-C2ACA23-ABAC-CHC23-AHA3-2A23-AC4-2A9-2AC2B9-2A4-CA9-AB-BC8-3A4-2BACBC2A3CAB-2(2CB)ABACFAB5-B-DE5DE-D-2D2(ED)E4DA6-DE4G2(IG)D3-D5GIGI2D7-E8-D3-D8-D59-HF25-F2-F16-2BA7-ABA16-3A11-3A12-ABA15-A2B10-A19-A9-B21-A8-B21-A7-2(A23-A6-)B23-A5-2(A25-A4-)B25-A3-A27-A2-B27-B2-A27-A-A29-BA29-AC29-C31-B29-BACBC23-BCAB2-CBC21-C-A4-2A9-BC-2B9-AB4-BA10-2(BA)8-AHC4-CA9-AC-2A8-ACA4-3A2(BA)3CBFB-BH3BCBACAH2C4-2C-3FHF3H-FE2-EDE5D-CA5-DEJGJ2GIGI2D-ED6GIGDE7-D8-D3-D8-E59-F25-F4-H564-C29-2BA27-2A2-ABC21-BCA4-3B21-A-A4-BA8-A2C-BAC7-A-B5-A8-2(A-)AFA7-2A5-ACA8-AC-2A8-ABA4-2C-2A2C4A-FA-HC2ACABCAH2C5-B-3(HF)H2-2(D-)D3E3DE-C6-2DGJ4GIGD3-E7GI2E7-D8-E3-D8-D54-F4-H25-H4-H628-3A21-AC5-A-FC19-B2-C4-B-A6-ACAB-3CA6-A-A4-3A6-A2HB-C-HA6-ACB5-BA7-AC3-B7-A-B6-C-7A-CB-2B7AH-A6-A2-2(2FH)-BA-CBA3FEDE-HA7-DEGJ4GDE3-EDJ5GDE9-E6-D5-D6-D56-F2-F27-H2-H630-2CB19-2CA5-AB-FA4-A7-C4-A2-HC4-C2-A4-A-BA3-CB-A3-2A-HA4-2BCA4-AFBCB-BCBA4-A2BCB4-2C2BA4-AB5-A5-4AC5-2C2-4A-B5-6A2-2B6-2B2-2DED-A5-2BAHED-D2B8-2D4G2E5-ED4GED11-D4-D7-D4-E58-2H29-HF632-B2A2B13-A4C7-BA2-2A2CA7-AB3A2-2B5-2BCF4A2-CA3-AB-4A-HCBC4-A-BCB3ACA7-B5ACB-A8-2B2ABA7-2C2A2C9-B-2C4-CA5-AC4-AC-A7-BA4-AB7-BC3-D2B10-E5D7-EDE3D13-D2ED9-E2DE726-CA15-CA11-BCABA10-2(B2C)10-2BC2BAC7-CAC2ACA12-ABC11-BAC15-AC11-CB15-2B2A9-2CAB12-CA2BA11-BACBC12-2(DE)9-2E2D131-
