model
size = 31 32 17, scale = 0.05, origin = -y
material 
  colors = A:#252525 B:#000 C:#131313 D:#090909 E:#100 F:#242424 G:#1A1A1A H:#202020 I:#FFF J:#777 K:#888 L:#060606 M:#666 N:#111 O:#999 P:#333 Q:#AAA R:#CCC S:#F8F8F8 T:#C1C1C1
voxels
8-2(15B16-)2B10I3B2(16-DI3EM5EI3D)16-CI3EM5EI3C16-CI3EJ5EI3C16-GI3EJ5EI3G16-HI3EJ5EI3H16-FI3EJ5EI3F16-AI2ELM5EI3A16-I3EQR5EI3A16-I3EKQ5EI3A17-4EO6EIA18-4EMJ6EI18-5EOL5EI18-2M4EK6E18-NLJN2EOP5E18-2EOJENLJ5E18-EJG2E2KRM4E18-MJ3EKGJQTJ2E17-2J3EJQ2GJSJ3E14-IGK3EPRJ2ENKP3EIF12-HSN2ELKJL7EI2H12-2GI2EKLPKL6EI2G13-2CIJM2ELOKL3EI2C15-2CI4EOGMJLI2C16-3DI2E2J2ENI3D18-2D2IK3EL2D20-4BI3EI2B21-4B3I2B49-2(B15-B14-)17B2(14-17D)2(14-17C)14-17G14-17H14-F15AF14-17A2(14-14A2FA)14-IE13AFA14-IE15A15-E14A16-N13AI16-I13AE16-N13AE11-3AI-E13AE-I3A6-2AIE-E13AE-I3A6-2AINE15AEI3A6-3F19A3F6-3H17A5H7-2G19A2G8-23C9-21C12-17D15-15D17-13B19-11B22-7B18-3(B17-B12-)2(D17-D12-)2(C17-C12-)G17-G12-H17-H12-FA15-AF3(12-2A15-2A)2(13-2A)14-2A2(13-2A14-IA)13-2A14-GA13-AI14-IA13-AI9-A4-EA13-AE2(4-A)4-NA13-AE2(4-A)4-2A13-2A4-A4-F25-F4-HA23-AH4-2GA21-A2G5-CAC19-CAC6-2CA2C15-2CA2C7-4D15-4D10-2D15-2D14-2B11-2B17-2B9-2B20-B7-B16-3(B19-B10-)2(D19-D10-)2(C19-C10-)G19-G10-H19-H10-FA17-F5(12-A17-A)13-3(A15-A14-)A15-A8-2(A5-A15-A5-A2-)A27-A2-F27-F2-H26-AH3-GA23-AG4-CAC21-CAC4-C2AC19-C2AC5-D2AD17-D2AD7-4D15-4D11-2(B15-)B13-B17-2B9-2B14-3(B19-B10-)2(D19-D10-)2(C19-C10-)G19-G10-H19-H10-FA17-AF2(10-2A17-2A)11-2(A17-A12-)A17-A13-3(A15-A14-)A15-A8-2(A5-A15-A5-A2-)A27-A2-F27-F2-H27-H2-G27-G2-CAC23-CAC3-CAC21-CAC4-D2AD19-D2AD5-2DAD17-DA2D8-3B15-3B2(13-B)17-B11-B14-3(B19-B10-)2(D19-D10-)2(C19-C10-)G19-G10-H19-H10-F19-F5(10-A19-A)11-3(A17-A12-)A17-2(A6-)A15-A6-2A6-A15-A6-2A28-2AF29-FH28-AH-G27-G2-2C25-2C2-CAC23-CAC3-DAD21-DAD5-DA2D17-2DAD7-4B15-4B11-2B14-B16-B12-B13-3(B19-B10-)2(D19-D10-)2(C19-C10-)G19-G10-H19-H10-F19-F5(10-A19-A)2(10-2A17-2A)11-A17-A12-A17-A6-A5-2A15-2A5-2A6-A15-A6-2A28-2AF29-FH28-AHG28-AG-C26-2C2-2C25-2C3-2D23-2D4-3D21-3D6-2B19-2B10-2B15-2B14-2(B13-)3(B19-B10-)2(D19-D10-)2(C19-C10-)G19-G10-H19-H10-F19-F5(10-A19-A)3(10-2A17-2A)11-A17-A6-A5-2A15-2(2A5-)2A15-2A5-2A28-2AF29-FH28-AHG29-GC28-2C-C26-2C2-2D25-2D3-2D23-2D5-3B19-3B9-2B15-2B14-2(B13-)3(B19-B10-)2(D19-D10-)2(C19-C10-)G19-G10-H19-H10-F19-F5(10-A19-A)4(10-2A17-2A)5-A4-2AF15-3A4-2A5-2A15-2A5-2A28-2AF29-FH28-AHG29-GC28-2C-C26-2C2-2D25-2D3-2D23-2D5-3B19-3B9-2B15-2B14-2(B13-)3(B19-B10-)2(D19-D10-)2(C19-C10-)G19-G10-H19-H10-F19-F5(10-A19-A)3(10-2A17-2A)11-A17-A6-A5-AF15-2(2A5-)2A15-2A5-2A28-2AF29-FH28-AHG28-AG-C26-2C2-2C25-2C3-2D23-2D4-3D21-3D6-2B19-2B10-2B15-2B14-2(B13-)3(B19-B10-)2(D19-D10-)2(C19-C10-)G19-G10-H19-H10-F19-F5(10-A19-A)2(10-2A17-2A)11-A17-A12-A17-A6-A5-AF15-2A5-2A6-A15-A6-2A28-2AF29-FH28-AH-G27-G2-2C25-2C2-CAC23-CAC3-DAD21-DAD5-DAD19-DAD7-4B15-4B11-2(B15-)2(B13-)3(B19-B10-)2(D19-D10-)2(C19-C10-)G19-G10-H19-H10-F19-F5(10-A19-A)11-3(A17-A12-)A17-A7-2(A5-A15-A5-A2-)A27-A2-F27-F2-H27-H2-G27-G2-CAC23-CAC3-CAC21-CAC4-D2AD19-D2AD5-2DAD17-DA2D8-3B15-3B2(13-B)17-2B9-2B14-3(B19-B10-)2(D19-D10-)2(C19-C10-)G19-G10-H19-H10-FA17-AF2(10-2A17-2A)11-3(A17-A12-)2A15-2A12-2A15-2A13-A15-A14-A15-A8-2(A5-A15-A5-A2-)A27-A2-F27-F2-H27-H3-GA23-AG4-CAC21-CAC4-C2AC19-C2AC5-D2AD17-D2AD7-4D15-4D11-2B13-2B16-3B7-3B45-3(B19-B10-)2(D19-D10-)2(C19-C10-)G19-G10-H19-H11-F17-F5(12-A17-A)13-3(A15-A14-)A15-A9-A4-A15-3(A4-)A15-2(A4-)A25-A4-F25-F4-HA23-AH4-2GA21-A2G5-CAC19-CAC6-2CAC17-CA2C7-4D15-4D10-2D15-2D14-4B7-4B76-3(B17-B12-)2(D17-D12-)2(C17-C12-)G17-G12-H17-H12-FA15-AF12-A16-2(2A12-2A15-)2A13-2(A15-A14-)2A13-FA14-AF2(13-FA14-2A)13-FA10-3A-2A13-FA-3A6-3A2-A13-F2-3A6-3A19-3A6-2FA19-A2F6-2HA19-A2H7-2G19-2G8-4C15-4C9-3C15-3C12-2(D15-)5D5-5D108-3(2B13-2B14-)2(2D13-2D14-)2(2C13-2C14-)2G13-2G14-2H13-2H14-2F13-2F3(14-2A13-2A)14-3A11-F2A14-AIA11-FIA15-3(IA11-FI16-)IA11-FI14-2AIA12-I2A12-2AIA11-FI2A11-4A13-4A10-3F15-3F10-2HF15-A2H11-2G15-2G2(13-2C)15-6C3-6C16-5D5-5D141-3(13B18-)2(13D18-)2(13C18-)13G18-13H18-13F4(18-13A)18-2I2A4IA2(I3A18-2AIAI4A)I3A18-2I2AI4AI3A18-2AIAI4A2(IA)18-2AIAI4A2IAI18-2I2AI4AI3A17-15A15-17F14-17H15-7G-7G17-5C3-5C195-
