model
size = 30 22 30, scale = 0.05, origin = -y
material 
  colors = A:#8F77B5 B:#FBE251 C:#888 D:#444 E:#F7D94C F:#B1AABE G:#255359 H:#4A225D
voxels
493-4A27-2A597-4A27-2A625-8A23-6A25-4A592-3A6-3A19-10A21-8A24-4A559-4A10-4A13-5A6-5A16-9AG2A20-8A556-3A14-3A2(10-5A)11-7A4-7A15-12A22-4A527-A20-A8-4A14-4A9-6A8-6A12-16A18-3A2E3A524-2A20-2A7-2A18-2A8-4A14-4A10-6A6-6A14-4A6B4A521-2A20-2A6-3A18-3A7-3A16-AGA9-5A10-5A12-3A10B3A20-4A496-A22-A6-2A20-2A7-2A18-2A9-3A14-3A11-2A14B2A17-2(2AE)2A493-2A22-2A5-2A20-2A6-3A18-3A7-4A14-4A10-2A5B-2B-5B2A15-3AFE2AEF3A491-A24-A4-2A22-2A5-3A18-3A7-3A16-3A10-A5B2-2B2-5BA15-3AF4AF3A83-2(2D28-)2D345-2A24-2A3-2A22-2A4-3A20-3A5-4A7-2B7-4A8-2A6B-2A-6B2A13-3AH6AH3A52-2D3(28-2C)345-A26-A2-2A24-2A3-3A20-3A5-3A6-6B6-3A8-A4B-B6AB-4BA13-A2F8A2FA52-2C28-2C404-2A26-2A-2A24-2A2-3A22-3A3-4A6-6B6-4A6-2A3B3-6A3-3B2A11-A2E10A2EA51-2(2C28-)12(2D28-)2D14-2A12-2D12-5A11-2D11-3A-3A10-2D10-3A3-3A6-3B2A3B5-4A6-A6B8A5BEA11-16A21-2A58-13(2C28-)2C14-2A12-2C12-5A11-2C11-3A-3A10-2C10-3A3-3A6-3B2A3B5-4A6-A6B8A5BEA11-16A21-2A464-2A26-2A-2A24-2A2-3A22-3A3-4A6-6B6-4A6-2A3B3-6A3-3B2A11-A2E10A2EA488-A26-A2-2A24-2A3-3A20-3A5-3A6-6B6-3A8-A4B-B6AB-4BA13-A2F8A2FA489-2A24-2A3-2A22-2A4-AGA20-AGA5-4A7-2B7-4A8-2A6B-2A-6B2A13-3AH6AH3A490-A24-A4-2A22-2A5-3A18-3A7-3A16-3A10-A5B2-2B2-5BA15-3AF4AF3A491-2A22-2A5-2A20-2A6-3A18-3A7-4A14-4A10-2A5B-2B-5B2A15-3AFE2AEF3A492-A22-A6-2A20-2A7-2A18-2A9-3A14-3A11-2A14B2A17-2(2AE)2A494-2A20-2A6-2A19-3A7-3A16-AGA9-5A10-5A12-3A10B3A20-4A496-2A20-2A7-2A18-2A8-4A14-4A10-6A6-6A14-4A6B4A522-A20-A8-3A16-3A9-6A8-6A12-7A2-7A18-3A2B3A526-3A14-3A2(10-5A)11-7A4-7A15-12A22-4A529-4A10-4A13-5A6-5A16-9AG2A20-8A560-3A6-3A19-10A21-8A24-4A564-8A23-6A25-4A133-
