model
size = 11 10 14, scale = 0.05, origin = -y
material 
  colors = A:#222 B:#673115 C:#2A2A2A D:#7A7A7A E:#9D9DA3 F:#BB5016
voxels
14-5A140-A108-3A95-5A7-2AC94-7A6-2AC83-7A5-5A7-2AC82-9A4-6A6-3AC8-BF60-8A2-11A2-7A5-5AC6-B2AF59-9A-11A-9A3-6AE5-B3AE8-AC49-9A-11A-8AD3-7A5-B4AE6-4A8-AC37-10A-11A-8AD3-6AD5-B4AD6-4A7-3A8-AC28-9A-11A2-4A4B4-6B6-4A7-3A8-2A9-AC28-9A2-8A50-2(2A9-)2C8-5A6-5A73-2A9-AC5-
