model
size = 12 15 32, scale = 0.05, origin = -y
material 
  colors = A:#EEE
voxels
16-2(5A7-)5A138-7(5A7-)5A8-3A45-3A31-8(7A5-)7A6-3(5A7-)5A29-5(9A3-)2(2A4-3A3-)7(3A3-)2A4-3A3-2A5-2A3-2A28-5(9A3-)7(2A5-2A3-)2A5-2A26-5(11A-)3(2A7-2A-)2A7-A2-2(2A3(7-A3-A)7-A26-5(11A-)2(A8-2A-)2(2A7-2A-))2(2A7-2A2-2(A7-A3-)A7-A26-5(11A-)2(A8-2A-)2(2A7-2A-))2A3(7-A3-A)7-A26-5(11A-)2(A8-2A-)2A7-2A-2A7-A2-2A3(7-A3-A)7-A26-5(10A2-)4(3A5-2A2-)3A3(5-2A3-2A)5-2A4-3(A5-)A3-5(10A2-)4(3A5-2A2-)3A3(5-2A3-2A)5-2A4-7A5-7A3-5(10A2-)4(3A5-2A2-)3A2(5-2A3-2A)5-2A3-9A4-7A5-7A3-5(10A2-)3(3A5-2A2-)3A2(5-2A3-2A)5-2A3-8A2(5-7A)15-5(10A2-)2(3A5-2A2-)3A2(5-2A3-2A)5-2A3-8A5-7A39-5(10A2-)2(3A5-2A2-)3A5-2A3-2A5-A4-8A5-7A51-5(10A2-)3A5-2A2-3A5-2A3-2A5-A4-8A5-7A63-4(10A2-)3A5-2A2-3A5-2A3-2A5-2A3-8A5-7A75-4(11A-)3A5-2A2-3A5-2A3-9A3-8A87-4(11A-)3A5-3A2-9A3-9A5-5A88-4(11A-)11A2-9A3-8A99-47A-11A2-9A4-6A100-48A-10A2-9A5-5A100-48A-10A3-7A7-3A101-36A-11A-10A4-6A112-3(11A-)11A2-9A4-5A113-3(11A-)11A2-8A6-4A113-3(10A2-)10A3-8A124-3(9A3-)9A4-6A125-2(8A4-)8A5-7A137-2(7A5-)7A6-5A135-
