model
size = 21 31 9, scale = 0.05, origin = -y
material 
  colors = A:#E00 B:#111 C:#FCC D:#222
voxels
483-11B2(9A12B)9A23B2(9A12B)9A11B483-11B9A2(2B19A)2B20AB4(19A2B)9A11B462-11B9A2B19AB21A2(B20A)B3(19A2B)9A11B9-3(3C18-)4(3D18-3C18-)10(3C18-)3C9-9B3-8A2(2B19A)B21AB18A2B20AB21AB19A2B9A11B9-3C2(18-C-C)4(18-D-D18-C-C)11(18-C-C)9-9B3-10B19A2B19ABAB18A2B18A3B18A-A2(B20A)21B8-2(CB)C2(16-5C)17-4(3D18-3C18-)10(3C18-)3C9-B8A3-10B19A2B19AB21A2B18AB20AB21AB19A12B9AB9-2(3C18-)3C408-B10A11B19AB21A2(B20A)B2(19A2B)19A12B9AB462-B10A11B2(19A2B)20AB3(19A2B)19A12B9AB483-B3(10A11B)10A21B2(9A12B)9AB21-
