model
size = 31 31 17, scale = 0.05, origin = -y
material 
  colors = A:#C00 B:#111
voxels
8-12(15A16-)15A17-2(13A18-)AB3ABA5BA18-2(2AB)5ABA18-3A3B4AB2A18-2(2AB)3AB3A18-AB3AB2AB4A18-AB3ABAB5A17-3A4BA5B2A14-2(19A12-)19A13-17A15-15A16-15A18-11A20-11A21-9B18-3(A15-A14-)11(17A14-)17A15-4(15A16-)15A11-6B13A6B3(6-25A)7-23A8-23A9-21A12-17A15-15A17-13A19-11B16-9(A17-A12-)3(2A15-2A12-)2A15-2A13-5(A15-A14-)2(A15-)A13-A10-B5-B13-B5-B4-A4-2A13-2A2(4-A)25-A4-2A23-2A4-3A21-3A5-3A19-3A6-4A17-4A7-4A16-3A10-2A15-2A14-2A11-2A17-2B9-2B14-8(A19-A10-)A19-A11-5(A17-A12-)A17-A13-4(A15-A14-)A15-A8-B5-B15-B5-B2(2-A27-A)2-2A25-2A3-2A23-2A4-3A21-3A4-4A19-4A5-4A17-4A7-4A15-4A11-2(A15-)2(B13-)9(A19-A10-)2(2A17-2A10-)2A17-2A11-2(A17-A12-)A17-A13-4(A15-A14-)A15-A8-B5-B15-B5-B2(2-A27-A)2-A26-2A2-2A25-2A2-3A23-3A3-3A21-3A4-4A19-4A5-4A17-4A8-3A15-3A2(13-B)13-14(A19-A10-)A19-A11-3(A17-A12-)A17-A13-A15-A7-B6-B15-B6-BA2(28-3A)28-2A-A26-2A2-2A25-2A2-3A23-3A3-3A21-3A5-4A17-4A7-4A15-4A11-2B14-B12-15(A19-A10-)2A17-2A10-2A17-2A11-2(A17-A12-)2A16-A2(6-B)16-B5-BA3(28-3A)28-2A-A26-2A2-2A25-2A3-2A23-2A4-3A21-3A6-2A19-2A10-2B16-B11-15(A19-A10-)2(2A17-2A10-)2A17-2A11-A17-A12-2A16-A6-B5-2B16-B5-BA4(28-3A)28-2A-A26-2A2-2A25-2A3-2A23-2A5-3A19-3A9-2B16-B11-15(A19-A10-)4(2A17-2A10-)3A16-2A5-B5-2B16-B5-BA4(28-3A)28-2A-A26-2A2-2A25-2A3-2A23-2A5-3A19-3A9-2B16-B11-15(A19-A10-)2(2A17-2A10-)2A17-2A11-A17-A12-2A16-A6-B5-2B16-B5-BA3(28-3A)28-2A-A26-2A2-2A25-2A3-2A23-2A4-3A21-3A6-2A19-2A10-2B16-B11-15(A19-A10-)2A17-2A10-2A17-2A11-2(A17-A12-)2A15-2A2(6-B)15-B6-BA2(28-3A)28-2A-A26-2A2-2A25-2A2-3A23-3A3-3A21-3A5-3A19-3A7-4A15-4A11-B15-B12-14(A19-A10-)A19-A11-3(A17-A12-)A17-A13-A15-A8-B5-B15-B5-B3(2-A27-A)2-2A25-2A2-3A23-3A3-3A21-3A4-4A19-4A5-4A17-4A8-3A15-3A2(13-B)13-9(A19-A10-)2(2A17-2A10-)2A17-2A11-3(A17-A12-)2A15-2A12-2A15-2A13-2(A15-A14-)A15-A8-B5-B15-B5-B2(2-A27-A)2-2A25-2A3-2A23-2A4-3A21-3A4-4A19-4A5-4A17-4A7-4A15-4A11-2A13-2A16-3B7-3B14-8(A19-A10-)A19-A11-5(A17-A12-)A17-A13-4(A15-A14-)A15-A9-B4-B15-2(B4-)2(A25-A4-)2A23-2A4-3A21-3A5-3A19-3A6-4A17-4A7-4A15-4A10-2A15-2A14-4A7-4A19-B7-B2(17-A)8(12-A17-A)4(12-2A15-2A)13-2(A15-A14-)3(2A13-2A14-)2A13-2A15-A13-A11-3B2-B13-B2-3B3(6-3A19-3A)7-2A19-2A8-4A15-4A9-3A15-3A12-2(A15-)5A5-5A20-A5-A24-B5-B19-13(2A13-2A14-)3A11-3A14-3A11-3A15-4(2A11-2A16-)2A11-2A14-2(4B11-)4A13-4A2(10-3A15-3A)11-2A15-2(2A13-)2A15-15A16-15A21-2(5A26-)5B22-15(13A18-)A5BAB3ABA18-AB5A2(B2A)18-2AB4ABAB3A18-2(3AB)2AB2A18-4AB2AB3ABA18-5ABAB3ABA17-2A5BA4B3A15-17A14-17A15-15A17-13A19-11A21-9A104-
