model
size = 28 30 32, scale = 0.05, origin = -y
material 
  colors = A:#555 B:#222 C:#E83015 D:#FFB11B E:#FCFAF2 F:#111 G:#261E47 H:#005CAF
voxels
12-6B61-B7(7-2B2-2B3-3B3-2B2-2B)11-7(2B3-3B3-2B15-)13B15-13B17-9B273-6B73-11(2(B2DB2-)B2DB12-)4B2-B2DB2-4B18-4B24-4B438-5(B2-)B11-18B11-11(2(4B2-)4B12-)2(4B2-)4B18-4B24-4B409-2(18B10-)3(2B3A2C4A2C3A2B10-)2B3A2C4A2C3A2B11-7(B3A2C4A2C3AB12-)B3A2C4A2C3AB13-5C4A5C14-5C4A5C19-4B17-B16-B10-2B14-2B289-3(20B8-)2(3B14A3B8-)3B13A4B8-B17A8(C10-C16A)C2(10-2C14A2C)10-7C4A7C10-B16CB10-2B14C2B16-6B294-22D6-22B7-2(3B14A3B8-)3B13A4B8-B17AC10-C15AE11-C15A6(E12-C14A)E12-C15AG10-C16AC9-B18AB8-B17A2B8-3BA3C6A3CA3B8-4B3-6B3-4B16-4C239-2(22B6-)22B7-2(3B14A3B8-)3B13A4B8-B17AC10-C15AE11-C16A7(G11-C15A)G10-C16AC9-B18AB9-E16AE10-2EA3C6A3CA2E12-B3-2B2E2B3-B19-C2-C267-22D6-22B7-2(3B14A3B8-)3B13A4B8-B17AC10-C15ACG10-C16AG11-C14AH12-C15AG11-4(C14AE12-)C14AE11-C16AC9-B18AB9-E16AE10-2EA3C6A3CA2E12-B3-2B2E2B3-B19-C2-C239-2(22B6-)22B7-2(3B14A3B8-)3B13A4B8-B17AC10-C15ACG10-C16AG11-C14AH12-C15AG11-4(C14AE12-)C14AE11-C16AC9-B18AB8-B17A2B8-3BA3C6A3CA3B8-4B3-6B3-4B16-4C267-22D6-22B7-2(3B14A3B8-)3B13A4B8-B17AC10-C15AE11-C16A7(G11-C15A)G2(10-C16AC)10-B16AB10-2B4C6A4C2B16-6B265-3(24B4-)5B14A5B4-5B14A5B6-3B13A4B8-B17AC10-C15AE11-C15A6(E12-C14A)E12-C15AG2(10-C16AC)11-C14AC13-14C287-91B14A7B-6B14A6B5-B18AB9-D16AC9-2(C17A2C8-)6(2C16A2C8-)2C17A2(C8-C18A)C9-C16AC10-2C14A2C12-14C259-92B12A8B-6B14A6B4-2(2B18A2B6-)4(B20AB6-)B20AB7-C19AB7-4(C18AC8-)C18AC9-C16AC10-2C14A2C12-14C287-28D36B12A8B-6B14A6B4-2(2B18A2B6-)4(B20AB6-)B20AB7-C19AB7-5(C18AC8-)2(B18AB8-)3B14C3B266-8B10-10D8B10D35B14A7B-6B14A6B5-B18AB9-D16AD9-11(C18AC8-)2(B18AB8-)3B4C6A4C3B15-6B235-9B-8B-18BD8BD44B14A7B-6B14A6B5-B18AB9-D16AD9-9(C18AC8-)C18AC7-B20AB2(6-2B18A2B)6-4BA3C6A3CA4B6-5B3-6B3-5B15-4C208-9B-2B4-2B-18BD2B4E2BD44B14A7B-6B14A6B5-B18AB9-D16AD9-9(C18AC8-)2(C18AC7-B20AB7-2(E18AE8-)3EA3C6A3CA3E11-B3-2B2E2B3-B19-C2-C218-2B4-2B10-10D2B4E2B10D36B12A8B-6B14A6B3-2(3B18A3B4-)2B2(20A2B5-B)3(20AB6-B)20AB7-C19AB7-2(C18AC8-))C18AC7-B20AB7-2(E18AE8-)3EA3C6A3CA3E11-B3-6B3-B19-4C208-9B-2B4-2B-18BD2B4E2BD44B14A7B-6B14A6B5-B18AB9-D16AD9-9(C18AC8-)C18AC7-B20AB2(6-2B18A2B)6-4BA3C6A3CA4B6-5B3-6B3-5B182-6B22-6B11-9B-8B-18BD8BD44B14A7B-6B14A6B5-B18AB9-D16AD9-C18AC7-2(B20AB6-)B20AB7-7(C18AC8-)2(B18AB8-)3B14C3B127-6B50-6B21-2(8B20-)8B10-10D8B10D35B14A7B-6B14A6B5-B18AB9-D16AD9-C18AC7-B20AB5-2B20A2B5-B20AB7-6(C18AC8-)C18AC9-C17AB9-2C16AB11-3C8A3C3B14-4(8C20-)C6BC22-4C22-8B19-2B6-2B18-2B6-2B37-28D35B14A7B-6B14A6B5-B18AB9-D16AD9-C18AC7-B20AB5-2B20A2B5-B20AB7-6(C18AC8-)C18AC9-C16AC10-2C14A2C12-2C10A2C16-4(C8BC18-)C8BC20-C4BC20-3B4F3B17-2B8-2B16-2(2B8-)91B14A7B-6B14A6B5-B18AB9-D16AD9-C18AC7-B20AB5-2B20A2B5-B20AB7-6(C18AC8-)C18AC9-C16AC10-2C14A2C12-2C10A2C16-3(C8BC18-)C8BC17-12B18-C6BC18-3B6F3B15-2B10-2B14-2B10-2B7-91B14A7B-6B14A6B5-B18AB9-D16AD9-C18AC7-B20AB5-2B20A2B5-B20AB7-6(C18AC8-)C18AC9-C16AC10-2C14A2C12-2C10A2C16-3(C8BC18-)C8BC17-12B17-C8BC17-2B8F2B15-2B10-2B14-2B10-2B35-28D35B14A7B-6B14A6B4-2(2B18A2B6-)B20AB6-B20AB5-2B20A2B5-3(B20AB6-)B19AC7-B19A3(C8-C18A)C9-C16AC10-2C14A2C12-2C10A2C16-C3B2E3B3(C18-C8B)C17-12B17-C8BC17-2B8F2B15-2B10-2B14-2B10-2B35-28D35B14A7B-6B14A6B4-2(2B18A2B6-)B20AB6-B20AB5-2B20A2B5-B20A2(B6-2B19A)B6-2B18AC7-B19A3(C8-C18A)C7-2B18A2B8-2C14A2C12-2C10A2C16-C3B2E3B3(C18-C8B)C17-12B17-C8BC17-2B8F2B15-2B10-2B14-2B10-2B8-3(25B3-)CA2B18A2B2(C3-C23A)2(C4-C22A)C4-2(C21AC5-)2C20AC7-2(B18AB8-)B18AB7-C19A3(C8-C18A)C7-BC18ACB8-C16AC10-4C10A4C14-3(C8BC18-)C8BC17-12B17-C8BC17-2B8F2B15-2B10-2B14-2B10-2B36-25D3-25B3-CA2B18A2B2(C3-C23A)2(C4-C22A)C4-2(C21AC5-)2C20AC7-2(B18AB8-)B18AB7-C19A4(C8-C18A)C9-C16AC10-4C10A4C14-3(C8BC18-)C8BC17-12B18-C6BC18-3B6F3B15-2B10-2B14-2B10-2B8-3(25B3-)CA2B18A2B2(C3-C23A)C4-C22AC4-2(C21AC5-)C21AC6-2C18A2C8-2(C16AC10-)C16AC8-2C4(18AC8-C)18AC9-C16AC10-4C10A4C14-4(C8BC18-)C8BC20-C4BC20-3B4F3B17-2B8-2B16-2B8-2B39-2B2-2B3-3B3-2B2-2B5-25B3(3-C23AC)4-C22AC4-2(C21AC5-)C21AC6-2C18A2C8-7(C16AC10-)C16AC11-2C12A2C12-4C8A4C16-4(8C20-)C6BC22-4C22-8B19-2B6-2B18-2B6-2B40-2B2-2B3-3B3-2B2-2B5-8B3D3B3D8B3(3-2(2C2A)3DB2A3D2(2A2C))4-C2A2C2A3DB2A3D2(2A2C)4-2(C2A2C2A3DB2A3D2A2C2AC5-)5C2A3DB2A3D2A5C6-4C2A3DB2A3D2A5C9-5(C2A3DB2A3D2A2C12-)2(C13A2C12-)3C9A4C14-12C16-12C131-6B50-6B21-8B20-8B10-
