model
size = 13 21 30, scale = 0.05, origin = -y
material 
  colors = A:#571212 B:#F7D94C C:#FFFC56 D:#DDD23B E:#350606 F:#36563C
voxels
16-3A-3A6-2A3-2A151-AEA2(10-3A)89-A12-E258-3A11-A85-C9-C149-3A10-AEA97-B9-B2-D9-D2-C9-C123-3A10-EAE110-B9-B2-D9-D2-C9-C110-3A10-3A110-C9-C2-B9-B2-D9-D2-C9-C84-2(3A10-)AEA123-C9-C-2B9-2B-D9-D84-2(3A10-)EAE97-C9-C2-B9-B2-D9-D-2C9-2C-B9-B2-D9-D71-3A10-A-A10-3A97-D9-D2-C9-C2-B9-B-2D9-2D2C9-2C-B9-B2-D9-D58-2(3A10-)AEA110-2D7-2D2-C9-C-2B9-2B2D9-2D-C9-C2-B9-B71-3A10-EAE98-C7-C3-2B7-2B2-2D7-2D-2C9-2C2B9-2B2D9-2D-C9-C2-B9-B58-2(3A10-)AEA85-D7-D3-2C7-2C2-2B7-2B-2D9-2D2C9-2C2B9-2B-D9-D2-C9-C58-3A9-5A8-E3AE9-AEA84-2D7-2D2-2C7-2C-3B7-3B2D9-2D2C9-2C-B9-B2-D9-D2-C9-C57-2(5A8-)E3AE9-AEA71-2B7-2B2-2D7-2D-3C7-3C3B7-3B2D9-2D2C9-2C-B9-B2-D9-D70-2(5A8-)E3AE9-AEA58-2C7-2C2-2B7-2B-3D7-3D3C7-3C2B9-2B2D9-2D-C9-C2-B9-B83-3(5A8-)2(EA)E44-2B7-2B2-2C7-2C-3B7-3B3D7-3D3C7-3C2B9-2B-D9-D2-C9-C2-B9-B56-2A3-2A20-5A7-7A6-7A7-2AE2A31-2D7-2D2-2B7-2B2-2C7-2C-3B7-3B3D7-3D3C7-3C2B9-2B-D9-D2-C9-C17-5(2A3-2A6-)7A6-E5AE6-2A3-2A6-2AEAE2A30-2B7-2B2-2D7-2D2-2B7-2B-3C7-3C3B7-3B3D7-3D2C9-2C-B9-B2-D9-D17-5(2A3-2A6-)E5AE2(6-A5-A)6-3AE3A8-A-A19-2C7-2C2-2B7-2B2-2D7-2D2-2B7-2B-3C7-3C3B7-3B3D7-3D2C9-2C-B9-B17-2A3-2A6-2A3-2A19-2A3-2A6-EA3-AE6-5A-A6-E5-E6-A5-A6-7A7-AE-EA18-2D7-2D2-2C6-3C2-2B6-3B2-2D7-2D-3B7-3B3C7-3C3B7-3B2D9-2D2C9-2C16-2A3-2A6-2A3-2A19-2(2A3-2A6-)7A2(6-A5-A)6-E5AE7-5A18-3B5-3B2-3D5-3D2-3C5-3C2-2B7-2B2-2D7-2D-3B7-3B3C7-3C2B9-2B2D9-2D68-2A3-2A6-7A6-2A3-2A6-E5-E6-2A2-3A7-2AE2A7-2(A5-)2C5-2C3-3B5-3B2-3D5-3D2-2C7-2C2-2B7-2B-3D7-3D3B7-3B2C9-2C2B9-2B82-5A7-EA3-AE6-A5-A6-EA3-AE7-2(AE)A7-2A3-2A5-3A3-3A4-2(3C3-)3B5-3B2-2D7-2D2-2C7-2C2-2B7-2B-2D9-2D2B9-2B2C9-2C82-5A7-2A3-2A6-A5-A6-2A3-2A6-7A6-3A-3A5-E3A-3AE4-3A3-3A4-2C5-2C3-2B7-2B2-2D7-2D2-C9-C2-B9-B-2D9-2D2B9-2BC11-C57-3A8-7A6-A4-2A6-A5-A6-A4-2A2(6-7A)6-3A-3A6-2A3-2A81-2D9-2D2B9-2B56-5A7-3A-3A5-EA5-AE4-2A5-2(2A4-)3A5-4A-2A7-5A8-2A-2A35-2(3A10-)3A31-C11-C2D9-2D2(3-2A)2(6-2A3-2A)6-EA3-AE6-7A5-E2A3-2AE4-2A5-2A4-A6-2A4-EA5-AE5-2A3-2A7-5A8-5A9-2(3A10-)EAE10-A-A10-EAE10-3A47-2(2A3-2A6-)EA3-AE6-2A3-2A6-7A5-2A2(-A)-2A4-A6-2A4-E6-AE4-2(2A5-)2A3-2A7-E2-AE8-2A-2A9-A-A2(10-3A)10-EAE10-A-A10-3A9-2(2A-2A8-)A3-A7-3A-3A6-E2A-2AE6-2A3-2A6-EA3-AE6-AE3AEA5-9A4-E3A-3AE4-2A5-2A4-EA4-2AE5-2A3-2A7-5A8-E3AE9-EAE4(10-3A)9-5A8-2A-2A33-E2A-2AE6-3A-3A45-3AE3A2(6-AE3AEA6-2AEAE2A)7-5A10-A24-3(3A10-)FAF10-3A44-
