model
size = 31 31 17, scale = 0.05, origin = -y
material 
  colors = A:#036 B:#FF0 C:#FF3 D:#039
voxels
8-3AC7AC3A16-2AC2A5B2AC2A16-2AC6AB2AC2A16-2AC3A4B2AC2A16-2AC6AB2AC2A16-2AC2A5B2AC2A16-2AC9AC2A16-2AC2A5B4(2AC2A16-2AC6AB)2AC2A16-2AC9AC2A17-AC2AB3AB2ACA18-AC2A5B2ACA18-AC2AB3AB2ACA18-AC3ABAB3ACA18-AC4AB4ACA18-AC9A2(CA18-AC2AB3AB2A)CA17-2AC2A5B2AC2A14-2(4AC2AB3AB2AC4A12-)4AC9AC4A13-3AC3ABAB3AC3A15-2AC2A2(BA)B2AC2A16-2AC2A2(BA)B2AC2A18-C2AB3AB2AC20-C2AB3AB2AC21-C7AC18-14(17A14-)17A15-4(15A16-)15A11-4A-15A-4A3(6-25A)7-23A8-23A9-21A12-17A15-15A17-13A19-11A16-9(A17-A12-)3(2A15-2A12-)2A15-2A13-5(A15-A14-)2(A15-)A13-A10-A5-A13-A5-2(A4-)2A13-2A2(4-A)25-A4-2A23-2A4-3A21-3A5-3A19-3A6-4A17-4A7-4A16-3A10-2A15-2A14-2A11-2A17-2A9-2A14-8(A19-A10-)A19-A11-5(A17-A12-)A17-A13-4(A15-A14-)A15-A8-A5-A15-A5-2(A2-A27-)A2-2A25-2A3-2A23-2A4-3A21-3A4-4A19-4A5-4A17-4A7-4A15-4A11-2(A15-)2(A13-)9(A19-A10-)2(2A17-2A10-)2A17-2A11-2(A17-A12-)A17-A13-4(A15-A14-)A15-A8-A5-A15-A5-2(A2-A27-)A2-A26-2A2-2A25-2A2-3A23-3A3-3A21-3A4-4A19-4A5-4A17-4A8-3A15-3A3(13-A)14(19-A10-A)19-A11-3(A17-A12-)A17-A13-A15-A7-A6-A15-A6-2A2(28-3A)28-2A-A26-2A2-2A25-2A2-3A23-3A3-3A21-3A5-4A17-4A7-4A15-4A11-2A14-A12-9(A19-A10-)A3(19-D10-D)19-A10-D19-D10-A19-A2(10-2A17-2A)11-2(A17-A12-)2A16-2(A6-)A22-2A3(28-3A)28-2A-A26-2A2-2A25-2A3-2A23-2A4-3A21-3A6-2A19-2A10-2A16-A11-9(A19-A10-)D2(19-D10-A19-A10-A)19-D10-A19-A3(10-2A17-2A)11-A17-A12-2A16-A6-A5-2A16-A5-2A4(28-3A)28-2A-A26-2A2-2A25-2A3-2A23-2A5-3A19-3A9-2A16-A11-9(A19-A10-)A19-D10-D19-A10-D19-D10-A19-A10-A19-D10-A19-A4(10-2A17-2A)10-3A16-2A5-A5-2A16-A5-2A4(28-3A)28-2A-A26-2A2-2A25-2A3-2A23-2A5-3A19-3A9-2A16-A11-9(A19-A10-)D2(19-D10-A19-A10-A)19-D10-A19-A3(10-2A17-2A)11-A17-A12-2A16-A6-A5-2A16-A5-2A3(28-3A)28-2A-A26-2A2-2A25-2A3-2A23-2A4-3A21-3A6-2A19-2A10-2A16-A11-9(A19-A10-)A19-D10-D19-A3(10-D19-D)10-A19-A2(10-2A17-2A)11-2(A17-A12-)2A15-2A2(6-A)15-A6-2A2(28-3A)28-2A-A26-2A2-2A25-2A2-3A23-3A3-3A21-3A5-3A19-3A7-4A15-4A11-A15-A12-14(A19-A10-)A19-A11-3(A17-A12-)A17-A13-A15-A8-A5-A15-A5-3(A2-A27-)A2-2A25-2A2-3A23-3A3-3A21-3A4-4A19-4A5-4A17-4A8-3A15-3A3(13-A)8(19-A10-A)19-A3(10-2A17-2A)11-3(A17-A12-)2A15-2A12-2A15-2A13-2(A15-A14-)A15-A8-A5-A15-A5-2(A2-A27-)A2-2A25-2A3-2A23-2A4-3A21-3A4-4A19-4A5-4A17-4A7-4A15-4A11-2A13-2A16-3A7-3A14-8(A19-A10-)A19-A11-5(A17-A12-)A17-A13-4(A15-A14-)A15-A9-A4-A15-2(A4-)2(A25-A4-)2A23-2A4-3A21-3A5-3A19-3A6-4A17-4A7-4A15-4A10-2A15-2A14-4A7-4A19-A7-2(A17-)8(A12-A17-)A4(12-2A15-2A)13-2(A15-A14-)3(2A13-2A14-)2A13-2A15-A13-A11-3A2-A13-A2-3(3A6-3A19-)3A7-2A19-2A8-4A15-4A9-3A15-3A12-2(A15-)5A5-5A20-A5-A24-A5-A19-13(2A13-2A14-)3A11-3A14-3A11-3A15-4(2A11-2A16-)2A11-2A14-2(4A11-)4A13-4A2(10-3A15-3A)11-2A15-2(2A13-)2A15-15A16-15A21-2(5A26-)5A22-16(13A18-)4A5B4A18-3AB5AB3A18-2AB2A2B3AB2A18-AB2AB6ABA18-2(AB)2AB4ABA17-2ABAB7AB2A15-3A11B3A14-12A2B3A15-10A2B3A17-8A2B3A19-5A3B3A21-9A104-
