model
size = 32 29 31, scale = 0.05, origin = -y
material 
  colors = A:#500 B:#BBB C:#888 D:#222 E:#111 F:#555 G:#EEE H:#CF3 I:#777 J:#A00 K:#E00 L:#B00
voxels
235-4A2-4A21-2A-2A2-2A-2A20-A3-A2-A3-A20-2A-2A2-2A-2A21-3A4-3A12-2(A27-A3-)A27-A11-13C661-4A2-4A21-2AJ2A2-2AJ2A20-AJ-JA2-AJ-JA20-2AJ2A2-2AJ2A21-3A4-3A12-2A25-2A3-A27-A3-A6-15C6-A3-A27-A653-4A2-4A21-5A2-5A20-2AL2A2-2AL2A20-5A2-5A21-3A4-3A12-3A23-3A3-A5-17C5-2(A3-A27-)A653-4A2-4A21-2(5A2-5A20-)5A2-5A21-3A4-3A12-4A2-17C2-4A3(3-A27-A)4-2(A25-A5-)A25-A392-4(2E18-2E10-)2E18-2E16-4A2-4A21-2(5A2-5A20-)5A2-5A21-3A4-3A12-5A-17C-5A3(3-A27-A)4-2(A25-A5-)A25-A6-A23-A7-A23-A297-2E18-2E2(10-2B18-2B)11-B18-B11-2(2B18-2B10-)2E4-4A2-4A4-2E15-2(5A2-5A20-)5A2-5A21-3A4-3A12-6A17C6A3(3-A27-A)4-2(A25-A5-)A25-A6-A23-A7-A23-A8-A256-2E18-2E10-3(2B18-2B11-B18-B11-)2B4-4A2-4A4-2B10-2E3-5A2-5A3-2E15-5A2-5A20-5A2-5A21-3A4-3A12-7A15C7A3(3-A27-A)4-2(A25-A5-)A25-A6-A23-A7-A23-A8-A21-A10-A19-A203-2E18-2E2(10-2B18-2B)2(11-B18-B11-2B18-2B)10-2B4-4A2-4A4-2B10-2E3-5A2-5A3-2E15-5A2-5A20-5A2-5A21-3A4-3A12-8A13C8A3(3-A27-A)4-2(A25-A5-)A25-A6-A23-A7-A23-A8-A21-A10-A19-A12-A17-A14-A15-A31-A109-2E18-2E11-B18-B12-B5-AK4-KA5-B11-2B5-2A4-2A5-2B9-24C9-2B3-C10-C3-2B11-B3-C10-C3-B12-B3-C4A2-4AC3-B11-2E3-5A2-5A3-2E15-2(5A2-5A20-)C3A4-3AC11-9A11C9A3(3-A27-A)4-2(A25-A5-)A25-A6-A23-A7-A23-A8-A21-A10-A19-A12-A17-A14-3(A15-)A31-2A31-4A31-5A5-2E18-2E10-2B18-2B10-2B2-14D2-2B11-B18-B11-2B2-EC10-C3-2B11-B18-B11-2B18-2B10-2B4-4A2-4A4-2B10-2E3-5A2-5A3-2E15-5A2-5A20-5A2-5A21-3A4-3A12-10A9C10A3(3-A27-A)4-2(A25-A5-)A25-A6-A23-A7-A23-A8-A21-A10-A19-A12-A17-A14-3(A15-)A14-2A15-2A11-3A17-4A4-5A22-5A5-2E18-2E10-2B18-2B11-B2-14D2-B11-2B18-2B11-B2-EC10-C3-B11-2B18-2B11-B18-B11-2B4-4A2-4A4-2B10-2E3-5A2-5A3-2E15-5A2-5A20-5A2-5A21-3A4-3A12-11A7C11A3(3-A27-A)4-2(A25-A5-)A25-A6-A23-A7-A23-A8-A21-A10-A19-A12-A17-A14-3(A15-)A14-2A15-2A11-3A17-4A4-5A22-5A37-2E18-2E10-2B2-14D2-2B10-2B18-2B11-B2-EC10-C3-B11-2(2B18-2B10-)2E4-4A2-4A4-2E15-2(5A2-5A20-)5A2-5A21-4A3-3A12-12A5C12A3-A27-A3-G27-A3-A27-A4-2(A25-A5-)A25-A6-A23-A7-G23-A8-A21-A10-A19-A12-A17-A14-3(A15-)A14-2A15-2A11-3A17-4A4-5A22-5A69-2E2-14D2-2E10-2E18-2E10-2E2-EC10-C3-2(2E10-2E18-)2E16-4A2-4A21-2(5A2-5A20-)5A2-5A21-3A4-3A12-29A3-A11-C-A-C11-A3-G11-C3-C11-G3-A11-C3-C11-A4-A10-5F10-A5-G10-5F10-A5-A10-5F10-A6-A9-5F9-A7-G23-G8-A21-A10-A19-A12-A17-A14-3(A15-)A14-2A15-2A11-3A17-4A4-5A22-5A73-14D50-EC10-C85-4A2-4A21-2(12A20-)5A2-5A21-3A4-3A12-29A3-2(A13-)A3-G27-G3-A27-A4-A25-A5-G25-G5-A25-A6-A23-A7-G23-G8-A21-A10-A19-A12-A17-A14-3(A15-)A14-2A15-2A11-3A17-4A4-A4G22-4GA73-14D50-EC10-C85-4A2-4A21-2(12A20-)12A21-3A4-3A12-29A3-2(A13-)A3-G27-G3-A27-A4-A25-A5-G25-G5-A25-A6-A23-A7-G23-G8-A21-A10-A19-A12-A17-A14-3(A15-)A14-2A15-2A11-3A17-4A4-5A22-5A73-14D50-EC10-C85-4A2-4A21-2(12A20-)12A21-3A4-3A12-29A3-2(A13-)A3-G27-G3-A27-A4-A10-5F10-A5-A25-G5-A25-A6-A23-A7-G23-G8-A21-A10-A19-A12-A17-A14-3(A15-)A14-2A15-2A11-3A17-4A4-2A2GA22-A2G2A73-14D50-EC10-C85-4A2-4A21-2(12A20-)12A21-3A4-3A12-29A3-2(A13-)A3-A27-G3-A27-A4-A10-5F10-2(A5-A25-)A6-A23-A7-A23-G8-A21-A10-A19-A12-A17-A14-3(A15-)A14-2A15-2A11-3A17-4A4-5A22-5A73-14D50-EC10-C54-8A22-3(12A20-)12A21-3A4-3A12-29A3-2(A13-)2(A3-A27-)A4-A10-5F10-2(A5-A25-)A6-A23-A7-A23-A8-A21-A10-A19-A12-A17-A14-3(A15-)A14-2A15-2A11-3A17-4A4-A4G22-4GA73-14D50-EC10-C54-8A22-3(12A20-)12A21-3A4-3A12-29A3-A11-C-A-2(C11-A3-A11-C3-)C11-A4-2(A9-7F9-A5-)A9-7F9-A6-A8-7F8-A7-A8-7F2(8-A)7-7F7-A10-A6-7F6-2(A12-A17-A14-3(A15-)A14-2A15-2A11-3A17-4A4-5A22-5A73-14D50-EC2-6A2-C22-8A23-10A21-3(12A20-)12A21-3A4-3A12-29A3-2(A13-)2(A3-A27-)A4-A10-5F10-2(A5-A25-)A6-A8-F5-F8-A7-A23-A8-A21-A10-A19-)A12-A17-A14-3(A15-)A14-2A15-2A11-3A17-4A4-5A22-5A69-2E2-14D2-2E10-2E18-2E10-2E2-EC2-6A2-C3-2E10-2E5-8A5-2E10-2E4-10A4-2E15-3(12A20-)12A21-3A4-3A12-29A3-2(A13-)2(A3-A27-)A4-A10-5F10-2(A5-A25-)A6-A8-F5-F8-A7-A23-A8-A21-A10-A19-A12-A17-A14-3(A15-)A14-2A15-2A11-3A17-4A4-5A22-5A37-2E18-2E10-2B2-14D2-2B10-2B18-2B11-B2-EC2-6A2-C3-B11-2B5-8A5-2B10-2B4-10A4-2B10-2E3-12A3-2E15-2(12A20-)12A21-3A4-3A19-16A23-A93-5F403-2E18-2E10-2B18-2B11-B2-14D2-B11-2B18-2B11-B2-EC2-6A2-C3-B11-2B5-8A5-2B11-B4-10A4-B11-2B3-12A3-2B10-2E3-12A3-2E15-12A20-12A21-3A4-3A20-14A21-2I-A501-2E18-2E10-2B18-2B10-2B2-14D2-2B11-B18-B11-2B2-EC10-C3-2B11-B18-B11-2(2B18-2B10-)2E18-2E80-3A27-C12AC21-2I-A-2I28-4(I31-)I28-2K3I2K306-2E18-2E11-B18-B12-B5-8A5-B11-2B18-2B9-24C9-2B3-C10-C3-2B11-B3-C10-C3-B12-B3-C10-C3-B11-2E3-C10-C3-2E15-2(C10-C20-)C3-3A4-C20-C10AC22-2I-A-2I498-2E18-2E2(10-2B18-2B)11-B5-8A5-B11-2B5-8A5-2B11-B18-B11-2(2B18-2B10-)2E18-2E112-C8AC26-A155-9A337-2E18-2E10-2B18-2B11-B18-B11-2B18-2B11-B5-8A5-B11-2B5-8A5-2B11-B5-8A5-B11-2B5-A6-A5-2B10-2E5-8A5-2E17-8A23-10A56-6A151-11A400-2E18-2E2(10-2B18-2B)11-B18-B11-2(2B5-8A5-2B10-)2E5-A6-A5-2E17-E6GA55-10A22-10A148-13A463-4(2E18-2E10-)2E5-8A5-2E17-G-G2-G-G119-9A23-9A24-3HA3H21-3(AG)3A3(GA)17-15A629-A6GA184-3H-3H25-3H-3H493-
