model
size = 25 32 26, scale = 0.05, origin = -y
material 
  colors = A:#B1BBC5 B:#8D5BA4 C:#83509B D:#4F1869 E:#4C1566 F:#C9B6B6 G:#7C838D H:#625571 I:#777A7F J:#D9C2C5 K:#863584 L:#462667 M:#737189 N:#3C2B58 O:#9B95B1 P:#525B6A Q:#726B9E R:#5C6689 S:#562B7D T:#636478 U:#933485 V:#97E2A7 W:#815DA5
voxels
43-CB24-B190-2(2A23-)2A228-B23-BC23-2C23-CB22-C-2(B24-)B21-B-BC21-2BC419-4A20-6A18-3(8A17-)8A18-6A20-4A571-4A19-8A16-E3A-5A15-EA5-3A15-E7-2A14-2D8-2A13-DE7-3A13-ED7-2ABC13-DA6-A3B14-3A2-2AC2BC14-6AB2C2B15-4A3CBC17-4B3C18-2C3BC20-CB2C371-2A22-4A20-6A18-2A4-2A16-E8-A14-3(D10-A13-)E11-A11-D12-B11-D12-C12-D10-CB12-2E8-3B12-DE7-2CBC14-A5-WC2BC14-3AB2-2BCBC15-A2CBCB3CB16-2(BC)3BC18-C2BCB2C293-2A21-6A18-2(8A17-)A6-A16-E8-A14-E10-A13-D11-A11-E3(12-A11-D)12-C11-D12-C11-E12-B11-D12-B11-E12-2B11-2E8-B2C2B11-E9-B2CB12-A8-B2CB13-CB6-2C2B14-2BC-C2B3C16-4CB2CB215-6A18-D7A16-2E8A15-DE8A14-2D10A13-ED10A12-DEDA6-4A11-E2D9-2A11-ED11-2A10-ED12-A10-D13-A2(9-AD13-B)2(9-AE13-B)9-AE2(13-C10-D)13-CBC8-E12-3CB8-2E12-BCB9-2D11-3C10-EC10-3B12-BC7-BCB14-B5-2B2C16-2C2BCB2C188-DE8A14-EDA-8A13-D10-A13-E10-A12-E11-A12-E-E9-2A11-EDE9-2A11-2E12-A9-AED12-A9-AE14-2C7-AD14-2B7-A15-C2B6-A15-2BC6-A15-3B6-A15-CBC6-A15-2BC6-AD14-2BC6-AE16-B7-E15-B8-D15-C8-E15-C9-E14-B10-D2(B12-)B10-C14-4CB5C17-B2C2B141-D7A15-2E2-7A14-D3-6A-A13-D10-A12-2D10-2A11-E11-2A11-3(E13-A9-A)15-2B7-A2(15-A2B5-2A)15-ACB5-2A15-ACBC4-2A15-AB2C4-2A15-ABCB5-A15-ACBC5-A17-CB5-AD16-B6-A2(D15-2B7-)D15-CB7-E15-B9-E14-B10-D2(C12-)2(BC2BC)2B15-2C4BCB114-D7A16-D9A14-E3-8A12-DA3-6A-A12-D2(A11-)EA12-A2-B6-A14-A2-B6-A15-C2(-B6-A15-B)2CB4-2A15-AB2C3-3A15-A2CB3-3A16-AC2(B4-A17-A-)2(B4-A19-C4-A19-)B5-A17-2B5-A16-3C5-AD15-2C7-E15-BC7-E16-C7-D15-CB8-2D13-C11-3BC4B3C2BC13-3C2B2C2BC18-2(CB)43-4A20-6A17-DE8A15-D2-4A2-A13-2D4-A5-A12-2A11-A2(11-2A)2-B6-3A13-A2C6-A15-2BC6-A15-4B4-2A15-B2CB3-3A15-2C2B2-4A16-ACB2-3A17-A-C2-3A19-C3-2A19-C4-A19-CB3-A19-BC3-A19-CB3-A19-2B3-A19-B4-A19-C5-A17-2C5-A17-2B5-AE15-2B7-D16-C7-E16-C8-D15-B9-E7B2C4BC12-2B2CB2C2BCBC16-2(BC)2B17-4A20-6A18-E5A-A15-DE2-4A2-A14-E10-2(A12-)A11-A12-2A3-2B4-2A12-3A-B2C4-2A14-A-CB5-A15-A-BC3-3A15-A2C3-4A15-ABC3-3A17-AB3-A-A18-CB2-A3-2(17A-B2-2A2-)17A-BC-2A2-17A-2C3-A-17A-BC3-A-E2D14A2-2(C3-A20-)C3-A19-C2(5-A18-B)5-A17-CB5-AD16-B7-D16-C7-2E15-C9-D4C2B2CBC3BC11-C3B3CB4C2B14-3B2(CB)C14-D7A17-E7A16-D6A-2A14-DA2-4A2-2A13-A10-2A11-A12-2A10-A12-3A2-2C4-2A12-3A2-C4-3A14-A-BC3-3A15-A2C2(3-A-A17-AB)3-A20-C4-A19-OB3-A2-17AOC3-A2-17AJC2(B-A3-17A2-)B-2A2-17A2-2B2-A-DED14A2-2C2-2(A20-C3-)A19-CB3-A19-C5-A18-B5-A18-C5-AD16-BC5-AD16-C7-2D15-C9-DBCB3C2BC4B2C9-E2(C2B)CB3CB2C13-BC4BC3B12-E9A15-ED8A15-ED5A-2A14-2A2-4A2-2A13-A10-2A11-A12-2A10-A12-3A2-C4-3A12-3A2-C3-4A14-A5-3A17-2(2A3-A19-)2A4-A19-B4-A18-A-B3-A2-17A-2B2-A2-17A-BC2-A2-17A2(B-)A3-17A2-CBA3-17A2-2B2A2-E2D14A2-BC2-A20-CB2-2(A20-C3-)A19-2B4-A18-B5-A18-C5-AE17-C5-AE16-2B6-DE15-C8-2DBDC2BCB2CBC2B2C9-DC5B4(CB)12-2B2CB5CBC11-2(D9A15-)6A2-2A14-AE8-2A13-2(A11-)A12-2A10-A12-3A7-3A12-3A6-4A14-A5-3A17-A4-2A2(18-2A4-A)19-CB3-2A18-2CB2-A2-17ABCB2-A2-17A-BC2-A2-17AJ-BC-A2-17A2-2CA3-17A2-2C2A2-2DE14A2-2B2-A20-BC2-A20-2B2-A20-B3-A19-2C4-A18-B5-A18-C5-AE17-B5-AD16-CB6-E16-C8-2EBEB3CBC5BCB9-D3CBC4BCB3C12-2C3(BC)3BC11-2(10A15-)6A-3A14-A10-A13-2(A11-)A12-2A10-A12-3A7-3A12-3A6-4A14-A5-4A15-A6-2A2(17-A6-A)18-BC4-A18-2CB3-A-17A-CB3-A-17A2-2C-A2-17AF-CB-A2-17A2-2B2A2-17A2-2C-2A-E16A2-CB2-A20-BC2-A20-2C2-A19-2B4-A18-CB4-A18-B5-A18-C5-AD17-B5-AD16-2C6-D16-B8-2DCE2CBC2(B2C)BCB9-E2BCB3C2BC3BC12-2CB2C4B3C11-2(10A15-)A-4A2-2A14-A10-A13-2(A11-)A12-2A10-A12-3A8-2A12-3A7-3A14-2(A7-2A15-)A7-A17-A2-B3-A17-AC-B3-A17-AB2C3-A-17A2-C3-A-17AF-C3-A-2(17A2-2B-A2-)17A2-2B2-A-E16A2-2C2-A20-CB2-A20-B4-A19-C4-A18-2B4-2(A18-B5-)AE17-B6-E16-2C6-E16-B8-2EBC2B2C5B3CB9-E2C4B2C2B4C12-CB2(3C2B)11-2(10A15-)A-4A3-A14-A10-A13-2(A11-)A12-2A10-A2(12-3A8-2A)14-2(A8-A15-)A2-B4-A17-A-CB3-A17-AB2C3-A17-A2-C3-A-17AF-B3-A-17AF-2(C3-A-17A2-)CB2-A-17A2-2B2-A-D16A2-2B2-A20-C3-A20-B4-A19-C4-2(A18-B5-)AD2(17-C6-E)16-B7-D16-B8-2D4B2CB2C4B2C9-DB3CB4C3BCB12-2BCBC3B2(CB)11-2(10A15-)A-4A3-A14-A10-A13-2(A11-)A12-2A10-A12-3A9-A12-3A8-2A14-A8-A15-A2-C5-17A2-B5-17A3-B3-A17-AB-C3-A17-AF-C3-A-16AFJ-3(B3-A-17A2-)2(C3-A-17A2-)B3-A20-C4-A19-C4-2(A18-B5-)A18-C6-A17-C6-A16-B7-A16-C7-E16-B8-2DC2B2(CB)3C4BC10-C2(B2C)BCB3CB12-2CBC2(B2C)2B11-2(10A15-)A-4A3-A14-2A9-A13-2A10-A12-2(A11-)A12-AF10-A12-2A3-C5-2A14-A2-B5-A15-A2-B5-17A2-C5-17A3-C4-A15-A2(-B)4-A15-AB2-C3-A-16AF-2C3(3-A-17A-CB)2(3-A-17A2-B)4-A18-CB4-A18-2(C5-2A17-)C6-A17-B6-A17-C6-A16-C7-E16-B7-D16-C8-2EBCB3C3B4CBC11-2B2C2B6CB12-5B2(CB)2C13-8A17-2A4-2A16-6A3-A15-A8-A14-A10-A13-2(A11-)F12-J4-B6-A12-AF3-C6-A12-2A3-C5-A15-A2-B5-17A-2C5-17A-2B5-A15-AB-B5-A16-J-B5-18A-B4-19A-C4-A-17A-2C3-A-17A-2B4-18A-2B4-15A3C2B5-A18-C5-A18-B5-2A17-C2(6-A17-B)6-A16-B7-E16-C7-D16-C8-D15-B9-D4B2CB7C12-2CBCB2C2BC3B13-C2B2(CB)2C15-6A18-3A2-3A17-5A2-A16-A8-A15-A9-A13-A10-A5-B7-J10-A5-C6-J12-F4-B6-A12-AF3-B6-A12-2A2-2B6-15A3-B5-16A-3B5-2A14-AF2B5-A17-3(2C5-18A)2B5-18ABC5-18A2B5-15ACB2CB5-2A15-3C5-2A15-CBC6-A15-C2B6-A15-CBC6-A16-B7-D16-C7-E16-C8-D15-B9-EB12-CB11-2BCBC2BCB3CB12-3CB3C5B15-2CBC3B18-2A21-6A18-5A-2A17-A5-2A16-A7-2A15-A7-2A6-C7-FA8-AF5-C7-2F8-JF4-C7-2FA9-JF3-C7-J11-3J2-2C6-F12AJA-BCB6-15A-C2B6-G12-2AB-CB5-I13-2A2-BC4-IE17AC5-IE14AF2AB5-IE17AC5-GE17AB6-G17AB7-14A2BCB7-A15-2B7-A15-CB7-A15-2C7-E15-2B7-D15-2B7-ED14-CB8-ED13-2B9-D13-BC10-B2(12-C)B2(C2B)C4B12-2BCB2CBC3B17-2B2CB19-2A22-4A20-6A19-6A18-2(8A5-B11-)8A4-3B10-8A4-C-C9-J6ALAJ3-C-B8-2F6ALAFJ2-B-CB7-8AL3A2-C2B8-8AL3A2-3C7-G2I6AL3A2-2CB6-IE2AG9A-3BC5-GED14A2CB5-IED11AS2A2CB5-G2E11AFC2BCB5-I2E13A2CBC6-GE13A4B7-I13A4C7-GA12-C-B8-DE12-B-B8-DED2A9-C2-C7-EDE2A12-B8-2D2A12-B9-DA12-CB10-2C11-2B10-CA2(11-C)A11-B12-5B3CB3C13-C2B2CBC4B17-2BCBC54-B23-2C23-B15-2K7-C14-4K6-B-B12-4K6-B-C12-4A7-CB11-AF2AJA6-2C9-J8AJ4-2C9-10A4-CB9-10A-B2-CB7-4G6A3-C2-C7-GD3EG4A4-B2-C6-G2ED2EI4A3-3C-C6-IDED3EG3A3-BCB-B6-I2D2(ED)G4A2-2C2-C6-G2EDE2DG2APQTQ-B-2B7-G2EUDG3APV2R-B2CB8-3GI5A3N-C-BC8-GEI9AB-2B2C7-E2D8A-C4-B8-ED6A2-C5-C9-D2A2C4-B5-B10-AC6F6-C10-CB11-2C11-C2(11-B12-B)C9-B15-9C17-4B2CB19-3B29-2C23-BC23-CB23-C24-2C2(24-C)39-2A22-2(4A21-)4A16-4I-4A5-C9-I4HG-2A5-2C8-I6HI2A4-2B9-IHM4HI2A4-CB9-I2HM3HG2A4-2B9-IHM4HG2A4-2B10-G4HG-2A4-2C11-2(GI)2-2(2A4-CB17-)2A2-C2B2CBC14-2A-2B4C2B15-BCB3C-3B13-3B2C2B3-2B13-5CB4-B14-C3-2C4-C14-B3-BC3-CB14-2B6-2C16-BC2B3CB19-2B2C52-CB24-2B23-BC23-2B114-2A22-4A21-4A22-4(2A23-)2A202-B2-B20-CB-3C20-B3CB16-B2C-4CB16-CB-C2-CB18-C3-2B20-B2C60-
