model
size = 26 30 22, scale = 0.05, origin = -y
material 
  colors = A:#EEE B:#9B90C2 C:#B28FCE D:#66327C E:#986DB2 F:#6E75A4 G:#DB4D6D H:#DA8FBE I:#F8C3CD J:#E9CD4C K:#66BAB7 L:#A5DEE4 M:#0D5661 N:#B69451 O:#FBE251 P:#0089A7 Q:#A8497A R:#DDD
voxels
402-HN23-J2NJ22-J2NJ23-2J797-B14-B89-F12-F635-B14-B10-2B12-2B63-3(F12-)F635-2B12-2B10-2B12-2B63-2(F12-)2F10-2F636-2(B12-)2B10-2B13-B10-B39-2(F12-)2F10-2F610-4(B12-)2B10-2B13-2B8-2B39-2F10-2F12-2F10-2F39-2(H10-H14-)GD8-DG14-GD8-DG15-D8-D15-4(C10-C14-)C10-C325-2B10-2B12-2B10-2B8-F3-BIB8-BAB3-F9-2B8-2B13-2F10-2F12-2F10-2F13-3(H10-H14-)2(GD8-DG14-)GD8-DG15-C8-C41-2C8-2C14-2C8-2C2(10-C3-C)6-2(C3-C10-)C10-C14-C10-C63-D15-D9-B15-B9-2B13-2B116-B10-B14-B10-B9-B4-B10-2(B4-)F4-2B8-2B4-F10-B8-B14-2F10-2F12-2F10-2F13-2(H10-H14-)2(GD8-DG14-)2C8-2C14-2C8-2C92-3C6-3C10-D3-3C6-3C3-D6-C3-C10-C3-C5-2C3-C10-C3-2C2(4-C)10-C4-C7-C13-C36-D15-D9-BE13-EB9-BD13-DB10-F13-F11-F13-F65-B10-B14-B10-B9-2B3-2B8-2B3-2B4-FB3-2B8-2B3-BF9-F2B6-2BF14-F10-F14-H10-H2(14-GH8-HG)14-CID6-DAC14-3C6-3C170-3C6-3C10-D3-3C6-3C3-D5-CHC2-2C8-2C2-CHC4-3C2-C10-C2-3C4-EC-2C11-2C2-CE4-EC-2E11-2E2-CE6-D2E11-2ED9-D2E11-E2D10-BD11-DB11-F13-F11-FB11-BF38-2(B11-B13-)2B10-B10-2B-BIB8-2B2-2B6-FB2-BIB6-BAB2-BF10-F2B6-2BF14-F10-F14-2H8-2H14-GH8-HG14-DHD6-DAD15-CD6-DC224-3C4-3C12-D2-CAC6-CAC2-D7-2C2-2C8-2C2-2C6-5C10-5C6-EDAE11-E2-CE6-4E11-2ED2E8-DE11-ED11-BD11-DB11-FB12-F11-FAB10-BF12-B11-2(B13-2B10-)B13-BIB8-2B10-2B-BAB8-2B2-2B6-FB-B2AB6-BAB-2BF8-2F-IB6-B-A2F12-FH8-HF14-2H8-2H14-GH7-DAG15-2D6-2D17-C6-C226-2C4-2C17-CAC4-CAC12-H2D-2C6-2C-2DH7-C3A2C8-2C3IC6-E3AE10-E2DIE6-E3AE10-E3IE7-2DAE10-E3D9-3D10-DB8-BD-BAB10-BF2-DB4-F3-2B10-B4-F8-2(2B10-B13-)BIB8-2B11-B-BAB8-2B-2B8-F-B2AB6-2B2-BF8-FB4AB4-B2A2BAF9-FBA3B4-2B2A2F12-2H8-2H14-GH8-2G15-GD6-DG16-3D4-3D276-3C4-3C16-CAC4-CAC12-CHDCAC6-CACDHC8-C3AE8-E3IC2(8-E3AE8-EI2-E)8-DI2AD8-2DF-D6-B2D2AB10-B-3DB4-4FAB10-B-4F5-2F-2B10-B2-2F9-BIB8-2B12-B2AB8-2B12-B3AB6-2B2-B10-F3AB6-2B2-F10-F2A3B4-2BA2BF8-E2-2B9-BIF6-2D3E2-HB8-GH2-3E2D-2D2E2-GAD6-D2G2-2E2D4-2C3-DAD4-DAD3-2C6-3(2C4-)2C6-2H16-2H6-2GD14-D2G7-2D14-2D8-D16-D169-2C4-2C17-CAC4-CAC15-D2AC4-C2AD12-2C2AC6-CA-2C10-C2AE8-E2-C9-2E-AE8-E2-2E9-D2AD8-2DID8-2D3A2B6-3B-A2D6-B4AB8-BAB2AB6-FAB2AB8-2B-BAF7-FB2AB8-2B-BF9-B2AB8-B-2B10-B-2AB6-2B-BF10-F-2A2B4-BAB-BF8-4BAB-B4-B2A5B5-DA3-HB7-BAB2-2FD4-DEC3-B7-BG3-IED6-C3-DBD4-DAD3-C8-C2(4-2D)4-C8-H15-GH8-G15-2G8-GD14-DG247-3C2-3C17-D2AC2-C2AD14-HG2AC4-C2AGH12-C-AE6-E2AC12-C-AE6-EA-C12-E2AD6-DA-E10-DE3AB6-BA-IED8-B3AB8-3BAB8-F-2AB8-B2-AF8-F4AB6-BI-BAF9-B3AB6-2B-AF10-F4AB4-BAB-AF10-B5AB2-B3ABAB8-2D2B2A2B4-B3ABA2D6-DE2-IAB6-3B-BED7-E2-BABD4-DB3-BE8-C2-B3D4-3DB-BC8-C-ID2-C4-C2-DGBC8-H2GD10-DGAH8-2GD12-D2G299-D6CD16-2GDAC2-CAD2G14-H2AE4-E2AH14-C2AE4-EA-C14-E2AD4-D2AE12-2E-2AB4-B3A2E10-D3AB6-2(BA)D10-B2-AB6-BI-2B10-F2-AB6-BI-AF10-FA-2AB4-BA2-AF10-BA-3AB2-B2A-BAB10-D5AB2-B5AD10-EB3AB4-B4AE10-E-B2AB4-B2A-IE10-C3-2AD2-D2A3IC10-CIA3D4-3DAIC10-H2G10-2GH10-G14-G327-6C20-CA2KAC18-2GAC2-CA2G16-HAE4-EAH15-C-AD4-D2AC13-E3AB4-B3AE12-E2AB6-B2AE12-D-AB6-B-BD12-B-2AB4-BA-2B12-BA-2AB2-B2A-IB12-DA-2AB2-B4AD12-E4AB2-B4AE12-E4AG2-G4AE12-CA-2AG2-GA-2AC12-CHA3D2-3DAHC12-H2G8-2GH406-6C19-2GA2KA2G17-H2AE2-E2AH15-2C2AD2-D2A2C14-E3AB2-B3AE14-E2A2B2-2B2AE13-2E2AB4KB2A2E12-DE3AB2KBA-BED12-DQ3AB2-B4AD2(12-E4AB2-B4AE)12-E4AG2-G4AE12-2C3AD2-D3A2C14-2GD4-D2G436-2C23-C2AC20-2GA2KA2G18-H2A2K2AH17-2C2A2K2A2C16-E3A2K3A2(E16-E8A)E15-2E3A2B3A2E14-2E2AB2-B2A2E14-EC2AB2-B2ACE14-2CH2G2-2GH2C15-H2G4-2GH384-2C24-2C23-4C22-C2AC23-2AC22-G2AG21-G4AG20-J4AJ19-CL4ALC3(18-E6AE)18-CJA2JAJC18-CH4JHC437-2C22-M4LM20-KM2LMK20-2K2M2K21-4K22-K2AK22-I3A22-4A21-JO2AOJ20-JR2A2J20-H4AH20-O4AO21-I2JI22-4J439-2M128-2M23-N2LN22-4L23-2L23-J2A22-J4AJ21-P2AP22-4J23-2J298-
