model
size = 17 11 28, scale = 0.05, origin = -y
material 
  colors = A:#131313
voxels
74-5A113-7A178-2(2A7-2A6-)3A5-3A7-3A3-3A8-9A9-7A12-3A77-3A7-3A4-2A9-2A2(4-4A5-4A)5-11A6-11A7-9A10-5A58-3(3A9-3A2-)3A9-3A3-4A5-4A4-2(4A5-)11A7-9A10-5A40-3A11-6A11-7A9-4A-2(3A9-3A2-)3A9-3A3-13A5-11A7-9A11-3A24-2A13-3A15-3A13-4A13-5A-A7-A-3A-2A-A7-A-2A2-4A7-4A3-2(4A5-)11A8-7A22-2A13-3A15-3A13-4A13-5A11-6A11-2(3A-)A5-A-3A3-2(4A5-)3A5-3A7-9A11-3A7-2A13-3A2(15-2A)15-3A13-4A13-2A-3A9-3A2-3A9-3A3-3A-A3-A-3A6-9A10-5A6-3(2A13-3A2(15-2A)15-3A13-4A13-6A9-4A-3A9-3A3-2(3A2-)3A5-11A8-7A5-)2A13-3A2(15-2A)15-3A13-4A13-2A-3A9-3A2-3A9-3A3-3A-A3-A-3A6-9A10-5A6-2A13-3A15-3A13-4A13-5A11-6A11-2(3A-)A5-A-3A3-2(4A5-)3A5-3A7-9A11-3A7-2A13-3A15-3A13-4A13-5A-A7-A-3A-2A-A7-A-2A2-4A7-4A3-2(4A5-)11A8-7A22-3A12-5A11-7A9-4A-2(3A9-3A2-)3A9-3A3-13A5-11A7-9A11-3A24-2A13-2A-2(3A9-3A2-)3A9-3A3-4A5-4A4-2(4A5-)11A7-9A10-5A40-2A13-2A2-2A9-2A2(4-4A5-4A)5-11A6-11A7-9A10-5A57-2A13-2A2-2A9-2A2(5-3A)7-9A8-9A9-7A12-3A76-A13-A3-2A9-2A6-2A5-2A10-5A13-3A110-4(A13-A3-2A9-2A6-2A5-2A10-5A126-)A13-A3-2A9-2A6-2A5-2A10-5A144-2A9-2A6-2A5-2A10-5A145-A9-A7-2A5-2A10-5A163-2A5-2A10-5A125-
