model
size = 28 12 18, scale = 0.05, origin = -y
material 
  colors = A:#111 B:#369 C:#336 D:#036 E:#339 F:#366
voxels
6-2BFC4AC6ACAD9-10(18A10-)B2E5BED3C2D3C11-11(16A12-)16A10-11(20A8-)20A7-11(5A12-5A6-)5A12-5A5-11(4A16-4A4-)4A16-4A3-11(4A18-4A2-)4A18-4A-5A11(18-10A)18-9A83(20-8A)20-9A11(18-10A)18-5A-11(4A18-4A2-)4A18-4A3-11(24A4-)24A5-10(22A6-)2B18ADA6-AB20A3-
