model
size = 30 25 11, scale = 0.05, origin = -y
material 
  colors = A:#8A9BA0 B:#3C2F41
voxels
8-3(14A16-)14A257-12A17-2(14A16-)14A15-5(16A14-)16A15-14A16-14A46-A12-A2(16-2A10-2A)2(16-14A)17-5(12A18-)12A17-2(14A16-)2A10-2A15-2A12-2A9-4A-2A12-2A-4A4-7A12-7A3-7A14-7A2-7A14-7A3-6A14-6A6-4A14-4A9-4A12-4A11-3A12-3A14-14A17-12A17-4(A12-A16-)8(2A10-2A16-)A12-A15-2A12-2A10-2A2-2A12-2A2-2A5-6A14-6A4-A2-3A14-3A2-A2-2A26-5A24-3A-4A20-4A3-4A18-4A6-3A16-3A9-2(4A12-)3A10-3A16-3A6-3A17-12(A12-A16-)A12-A15-2A12-2A10-3A-A14-A-3A7-4A14-4A64-2A26-2A-3A22-3A3-3A20-3A6-3A16-3A9-3A14-3A12-3A10-3A16-2A8-2A17-12(A12-A16-)A12-A15-2A12-2A10-3A-A14-A-3A7-4A14-4A64-2A26-2A-2A24-2A3-3A20-3A6-2A18-2A9-3A14-3A12-3A10-3A16-A10-A17-12(A12-A16-)A12-A15-2A12-2A10-2A2-A14-A2-2A7-4A14-4A64-3A24-3A-3A22-3A3-4A18-4A6-3A16-3A9-3A14-3A12-3A10-3A16-2A8-2A17-12(A12-A16-)A12-A15-2A12-2A10-2A2-A14-A2-2A7-4A14-4A34-3A24-7A22-4A2-3A20-3A5-4A16-4A8-3A14-3A11-3A12-3A13-5A6-5A16-4A4-4A17-12(A12-A16-)A12-A15-2A12-2A10-2A2-A14-A2-2A6-5A14-5A4-2A24-2A2-3A22-3A3-4A18-4A5-4A16-4A7-4A14-4A10-3A12-3A13-7A2-7A15-14A19-8A19-12(A12-A16-)A12-A15-2A12-2A2(14-A)9-2(6A14-6A4-)5A16-5A5-5A14-5A8-3A14-3A11-3A12-3A13-16A15-14A21-4A51-4A6-4A11(16-2A10-2A)16-A12-A15-2(2A12-2A14-)2A12-2A13-2(2A14-2A12-)3A12-3A13-2A12-2A14-16A15-14A107-8(12A18-)2AB9A18-12A18-2A3(BA)2B2A17-14A16-3A2(2BA)2B3A16-14A16-3ABA2B2(AB)3A15-3(16A14-)16A15-14A16-14A128-
