model
size = 20 32 15, scale = 0.05, origin = -y
material 
  colors = A:#D1AE1C B:#DAB624 C:#D2AF1D D:#D7B424 E:#996D0A F:#EACE3E G:#C6A309 H:#D7B422 I:#F6DA4A J:#D7B321 K:#CDAF2B L:#1F1C08 M:#FDE53B N:#E5C12D O:#EDD125 P:#D8B621 Q:#D0AE19 R:#F6D937 S:#D9BC30 T:#F2D231 U:#E7C629 V:#FBDF40 W:#C4A202
voxels
7-6E55-4E15-6E75-4E15-6E192-2C6-2C9-2A2C4-2CAD8-ADA2C2-ACA2D8-2ADCA2-2CADA8-DADC4-CD2A9-2A6-AD149-FKD6BIDG9-DEGDKDG3H11-HGFBIQOF11-GKF4EPED9-FAN6EGPM10-NJAMGEDH12-FDIFOAM13-KEKODFGF12-PA4EKR11-HI6EAE11-GFDSDE2F13-3HPHJ15-HFIE17-JD18-AF18-FM17-ARGE17-FP19-E13-3CE4-E3C7-4DCE2-EA2DCA6-2A2-2C2EAD2-AD6-A4-C2EA4-A6-2A2-2C2EAD2-AD7-3ACA2-2CDAD9-2AC4-CAD127-FGFD8-D2GS6-F2B6-2BG8-FN2B4-2BHF8-K4B2-4BP7-O12BD7-IF8BFN8-PI7BGFH8-QH8BHE8-AIB2-2B2-BFI8-AH9BF8-GE8BMH9-GR6BHR10-FTF5BJF10-IKER2BFJUD11-DIE2BFAF12-EJA2BJFE12-KMB2-BAR11-DAMP2BAFDJ10-10E9-C3B4E3BC7-DA-2A3EC2A-AD6-D3-D5A3-A6-A3-A2D2AD3-2A5-A3-2AD3A3-DA5-4A2D2E2D4A7-2ADAC2E3A2D10-ACA2-2CA107-CFG-2DM4-OED-GSD3-JI-DBG4-3H-EH4-DP-NBG4-OFH-HE4-HOKGBH4-FEDPAI3-MNBFANEIJH3GPMBFK3-JEIFN2BMGBDHFNDG4-HD2IFDIFOAMGFH2O4-HMQHKEK2-FGFHEGD4-EQAIAQ4-NRFIEG4-IG12-GF4-EK12-HM5-IH10-FH6-A2B8-BJF6-EDB8-BDE7-GI8-PJ9-G8-H10-A8-A10-D8-J9-E10-E8-CB8-2C7-3A8-2DA6-DAD8-D2A5-AD2A8-3DA4-3A10-3A5-A12-A6-3D8-2DA7-3ACAC2ADA2D8-2DA2CDCAC2DA11-CA2-2C68-H16-D2-I16-F2-QB14-EA2-AB14-IE2-I2B13-2F2-HB14-GA2-D15-O4-H14-K4-E14-G4-IB12-GF4-IB12-HD4-AB12-HG5-AB10-JF6-HB10-DE6-HB10-JI7-F10-F8-G10-M8-R10-D8-E10-E8-C10-C7-DA10-DA6-2A10-AD5-AD12-2A4-2A2(12-2D4-DA)12-2A5-2AD8-2DA6-2(AD)CD2-DCA2DA7-2D2(AC)ADC3A10-A2C2-ACA47-I16-M2-Q16-G2-B16-K2-G16-H2-VB14-BE2-G16-J2-G16-G2-Q16-G3-I14-H4-G14-E4-EB12-BJ4-AB12-BD4-FB12-BE5-N12-Q6-DB10-BI6-E11-F7-H11-H7-F11-F8-E10-E7-C12-C6-A12-D2(6-D12-A)6-A12-A5-AD12-2D4-DA12-2D4-2A12-2A4-2AD10-A2D5-7AC4A2D7-D3AC2-C4A10-AC4-CD26-EB16-BE-A16-D2-P16-F2-Q16-N-EB16-BE-P16-A2-D16-D2-I16-F2-E16-N3-B14-BI3-G14-A4-OB12-BI4-DB12-BK5-J12-M6-G12-T6-D11-D7-P2(11-E7-E)12-E6-C12-C2(6-A12-A)6-A12-D5-2A12-AD4-2D12-DA4-2A12-2A4-D14-D4-AD12-2D4-ADA3-7C3A5-2D2AC4-C3DA7-2DAC4-C2AD9-2AC4-CAD5-EB16-B2EA16-KE-D16-B2-A16-F-EB16-B2EF16-ME-D16-K2-B16-B2-F16-F2-J16-J3-M14-M4-FB12-BF4-OB12-BO5-FB10-BF6-GB10-BG6-S11-S7-H11-H7-F11-F7-E12-E6-C12-C2(6-A12-A)5-2A2(12-AD4-DA)12-DA4-A14-A4-D2(14-A4-A)D4-7C-2A4-ADA3C7-DAD5-2(AD)C4-C2ADA7-AD2C4-2C2A4-EB16-B2EA16-DE-I16-I2-S16-E-EB16-B2EB16-BE-D16-O2-F16-I2-N16-E2-IB14-BH3-A14-G4-IB12-BO4-KB12-BD5-MB10-BJ6-T2B8-2BK6-D-B8-BD7-E11-M7-D11-E7-E12-E6-C12-C6-A12-A5-AD12-2A4-AD2(12-DA4-2A)12-2A4-A14-A4-AD12-2A5-A12-A6-A4-7C-D6-2A3C7-DA5-2DADC6-C4A5-D2AC6-CADA3-EB16-B2EH16-GE-J16-Q2-E16-I-EB16-B2EB16-BE-GB14-BA2-GB14-BQ2-HB14-BI2-EB14-BG3-JB12-BE4-DB12-BA4-E2B10-2BF5-Q3B6-3BN6-I-2B6-2BD7-F-2B6-2BE7-H-B8-BH7-F-B8-BE7-E11-E7-C12-C6-A12-A5-AD12-2D2(4-AD12-2A)4-D14-A4-A14-A5-D12-A6-A12-A6-D4-7C-A6-2A3C7-AD7-DAC6-CDA7-DADC6-CD2A3-EB16-HE-D16-R2-F16-J2-M16-A-EF16-NE-AB14-2J2-KB14-HP2-IB14-HA2-RB14-EJ3-F14-M4-DH12-KI4-GHF10-HJA5-2(FJ)6-TFBA7-2DUJFDJREKID8-JPFA2FAEIDIG8-IHEFJMFAJEG9-QARAEGRAMKA9-AJDEAEFPMADR8-12E8-C10-C7-A12-D6-A12-D5-DA12-DA4-DA12-2A4-D14-D5-D12-D6-A12-A6-D12-D6-A4-7C-A6-2A3C7-2A7-DAC6-CDA8-DAC6-CAD5-DS2GDEOG2-HM2DFGFC3-HE2B2HGDKD5BJ4-E3B3LB3L4BD3-HI3B2LB4L4BHF2-F4B3L2(BL)6BN-A5BL3BL6BH2-G4B2(LB)3L5BF3-D3B4LB2L4BH4-G3B3LB3L4BE4-F12BAGI5-WH10BG9-RHJ4BHJG12-B2EFEF132-10C9-D3ADCD3ADA8-2(3AD)2ADA8-2(2A2CAD)7-AD10C2A5-2D12CDA4-DA12CAD5-D2(12CA6-A)12CA6-2A10C2A5-ADA2D6C2AD2A5-3A2C4-2CD2A5-IAPDE6-DGKOH4-FD3B2GHJIE2BNFN4-G14BJ4-O14BH3-I15BHA3-G14BE4-F14BI4-DE13BI5-GBK9BGIA5-KGHJI4BFIEFN7-2DUGFDOBEKID12-PFAE174-DCA2-2CD11-AD2C2(DC)DA9-DADCAC2DCD2A8-D2AC3ADCADA7-2A2(D3CA)2D5-D2A4CAD4C2DA4-2A5C2D5CAD4-AD12C2A4-2(2A5C)2A4-2AD4CDA4C3A5-3ADA4C2D2AD7-D2AC4-C3A8-GKHMGDKDGEDF8-FMFOQIBFKHNJ7-EPDEFIEFNHDGKO6-IMPGKGHJIENAFO6-BNFHDEGMAJNFIE6-OHFGMAOFIDFIGD6-GEHFGFDOKEKHQM7-IFR2NJFMQAIAQ9-AED2GTIGH13-EDSDF253-ACD2-2CA11-2D2CDCAC2A9-DADCAC2DC3A7-2(DA)CAD2(CA)D2A6-2(DA)CDC2AC2D2A6-2D2ACD2CACD3A6-4ACD4C4A7-D2A6C3A8-3A2C2-2C3A9-DA6-2A492-CA2-2C14-2C2-AC14-CD2-2C14-2C2-AC87-
