model
size = 21 29 21, scale = 0.05, origin = -y
material 
  colors = A:#D65500 B:#EE2424 C:#EA5D00 D:#F60 E:#700 F:#A00 G:#853500 H:#500 I:#AD4500 J:#C24D00 K:#800 L:#EE1212 M:#D00 N:#993D00 O:#040 P:#050 Q:#070 R:#080 S:#0A0
voxels
177-2D18-5(4D17-)4D18-2D397-2C18-4C16-6C15-2C2B2C6(15-C4BC)15-2C2B2C15-6C16-4C18-2C292-2A18-4A16-2A2M2A15-A4LA14-A6BA13-A2B2-2B6(A13-AB4-B)A13-A2B2-2BA13-A6BA14-A4LA15-2A2M2A16-4A18-2A229-2J17-2J2K2J15-J4FJ13-AJ2M2-2MJA10-CAJL4-LJAC9-CAL6-LAC9-CAB6-BAC8-5(DCAB6-BACD7-)DCAB6-BACD8-CAB6-BAC9-CAL6-LAC9-CAJL4-LJAC10-AJ2M2-2MJA13-J4FJ15-2J2K2J17-2J187-2I17-2I2E2I14-J2K2-2KJ11-2AJF4-FJ2A8-CA2F6-2FAC7-C3M6-3MC7-C2L8-2LC6-DCLB8-BLC6(D5-D3B8-3B)D5-DCLB8-BLCD6-C2L8-2LC7-C3M6-3MC7-CA2F6-2FAC8-2AJF4-FJ2A11-J2K2-2KJ14-2I2E2I17-2I165-4N15-2I4E2I10-2AJ2K4-2KJ2A7-A2KF6-F2KA6-CKF10-FKC5-CF12-FC5-CM12-MC5-CL12-LC4-DL14-L4(D3-DB14-B)D3-DL14-LD4-CL12-LC5-CM12-MC5-CF12-FC5-CKF10-FKC6-A2KF6-F2KA7-2AJ2K4-2KJ2A10-2I4E2I15-4N144-2G15-I-NG2HGN-I10-J2I2E2-2E2IJ8-A2EK6-K2EA6-AE12-EA5-AK12-KA5-AF12-FA4-CF14-FC3-CM14-MC3-CL14-L4(C3-CB14-B)C3-CL14-LC3-CM14-MC3-CF14-FC4-AF12-FA5-AK12-KA5-AE12-EA6-A2EK6-K2EA8-J2I2E2-2E2IJ10-I-NG2HGN-I15-2G123-4G13-2ING4HGN2I9-IH2E4-2EHI8-JE10-EJ7-JK11-EA5-AK12-KA5-AF12-FA4-AF14-FA3-AM14-MA3-AL14-L4(A3-AB14-B)A3-AL14-LA3-AM14-MA3-AF14-FA4-AF12-FA5-AK12-KA6-JK10-KJ7-JE10-EJ8-IH2E5-EHI9-2ING5HN2I13-5G120-7G12-NG7HN9-2IHE7-H2I7-IE10-2EJ6-IK11-EJ5-JK13-KA4-JF13-FA3-AF15-FC2-AM15-FC2-AL15-MC2-AB15-LC2-AB15-B2(C2-AB15-L)C2-AL15-MC2-AM15-FC2-AF15-FC3-JF13-FA4-JK13-KA5-IK11-EJ6-IE10-2EJ6-2IHE2-3E2-H2I9-NG2H3G2HN13-2G3-2G59-OP19-OP36-8G12-G8HGN9-NH8-2HI7-JE11-EJ5-JE13-EA4-JK13-KA3-CF15-KC2-CF15-FC2-AM15-FC-DM17-F2DL17-M2(2DL17-L)2DL17-M2DM17-FD-AM2(15-FC2-CF)15-KC3-JK13-KA4-JE13-EA5-JE11-EJ7-NH2-5E-2HI9-G2H5GHGN11-2G5-G38-OP18-OBP18-OLP18-2OQ15-9G10-IG8HBNI7-J2H9-2HJ5-AE13-HA4-AE13-EA3-CK15-EC2-CF15-KC2-CF15-FC-DF17-F2DM17-F2DL17-M2(2DL17-L)2DL17-M2DM17-F2DF17-FD-CF15-FC2-CF15-KC2-CK15-EC3-AE13-EA4-AE13-HA5-J2H-2E3-E-3HJ7-IGH2G3HGHGNI10-G2-3O-G16-2O2(P18-OB)P18-OLP18-2OR15-9G10-IN8HBNI7-J2H9-2HJ5-AE13-HA4-AE13-EA3-CK15-EC2-CF15-KC2-CF15-FC-DF17-F2DM17-F2DL17-M2(2DL17-L)2DL17-M2DM17-F2DF17-FD-CF15-FC2-CF15-KC2-CK15-EC3-AE13-EA4-AE13-HA5-J2H2-E3-E-3HJ7-IN2HG3HGHGNI10-2G-OPO-G16-3P2(19-PQ)19-RS36-8G12-G8HGN9-IH8-2HI7-JE11-EJ5-AE13-EA4-AK13-KA3-CF15-KC2-CF15-FC2-CM15-FC-DM17-F2DL17-M2(2DL17-L)2DL17-M2DM17-FD-CM2(15-FC2-CF)15-KC3-AK13-KA4-AE13-EA5-JE11-EJ7-IHE-4E2-2HI9-2GH4G2HGN12-G4-2G119-6G13-NG6HGN10-IHE6-EH2I7-JE10-2EJ6-JK11-EJ5-AK13-KA4-AF13-FA3-CF15-FC2-CM15-FC2-CL15-MC2-CB15-LC2-CB15-B2(C2-CB15-L)C2-CL15-MC2-CM15-FC2-CF15-FC3-AF13-FA4-AK13-KA5-JK11-EJ6-JE10-2EJ7-IHE2-2E2-EH2I9-NG2H2G2HGN13-2G2-2G121-4G15-NG4HGN11-2I2E4-2E2I8-J2E8-2EJ7-JK10-KJ7-JF11-KJ6-JM11-FJ5-AM13-FA4-AL13-MA4-AB13-L4(A4-AB13-B)A4-AB13-LA4-AL13-MA4-AM13-FA5-JM11-FJ6-JF11-KJ6-JK10-KJ7-J2E8-2EJ8-2I2E4-2E2I11-NG4HGN15-4G123-2G15-2ING2HGN2I11-I3E2-3EI10-JE8-EJ8-AK10-KA6-AK12-KA5-AF12-FA5-AM12-MA5-AL12-L6(A5-AB12-B)A5-AL12-LA5-AM12-MA5-AF12-FA5-AK12-KA6-AK10-KA8-JE8-EJ10-I8EI11-2IN4GN2I159-I2-3I-I12-J2IN2EN2IJ10-AE3K2-3KEA8-A2K7-F2KA7-AF10-FA6-CF11-MFC5-CM10-2LMC5-C2L11-L6(C5-CB12-B)C5-CL12-LC5-CM12-MC5-CF12-FC6-AF10-FA7-AK-2F4-2F-KA8-AE3K2-3KEA10-J2IN2EN2IJ12-I2-2I2-I162-4I15-2IA2-A2I12-A8-2(A10-)A8-C12-C51-8B-BL8-2B11-B6-3(DB12-BD5-)DB13-D5-DB13-D6-2(CL10-LC7-)C3ML4-L3MC7-C3F2M2-2M3FC8-AKJI4FIJKA9-2AJIJ2KJIJ2A12-I-2J-I328-10BC8-D4B4-4BD7-DB2-B4-B2-B2(D7-D12-)D8-4B4-3B9-D4B4-4B8-DC4B2-4BCD8-C2L6B2LC9-C2AJ4LJ2AC9-C2A2J2M2J2AC10-A2-J2AJ2-A15-2A351-C2-A2BA2-C10-DC2A4B2ACD9-D2-A4BA2-D13-4B17-4B14-C2A4B2AC10-DC2A4B2ACD10-C3A2B3AC11-C2A4C2AC14-4C18-2C397-2D18-4D17-4D18-2D18-2(4D17-)4D18-2D283-
