model
size = 13 24 28, scale = 0.05, origin = -y
material 
  colors = A:#181818 B:#62593B C:#101102 D:#FC0 E:#6F6936 F:#6AB3CC
voxels
18-3B10-3C569-CDC10-CDC8-7B6-7B7-5B8-5C230-CDC10-CDC20-3(9B4-)9C7-DCD10-3A11-A64-A11-3(3A10-)3A9-3(5A8-)C3AC9-CDC10-CDC33-9B4-BE5BEB4-BED3C2EB4-9C5-DC3ACD2(6-7A)8-5(3A10-)3A9-2(5A8-)4(A3-A8-)C3-C57-11B2-2BE5B2EB2-2BEB3C3EB2-3CB7C3-2CB3A3C4-ACF3A2CA4-ACA3-ACA5-4(2A3-2A6-)8(2A3-A7-)2C3-C56-16BE2BA5E4BC2B2C4EBCA2C2B7C-D2C2B3A2CD2-A2C5A2CA3-AC5-CA4-2(2A5-)3(2A3-2A6-)8(A5-A6-)C5-C55-17BABA5E4B2CB2C4EBC4AB2A2B2AC-3CAB3A3C2-A2C5A2CA3-2A5-2A4-2(2A5-)2A3-2A10(6-A5-A)6-C5-C55-17B3A5E4B5C4EBC7A2B2AC-D2C5A2CD2-A2C5A2CA3-2(2A5-)12(A5-A6-)C5-C55-4B6-19B5C4EBC7ABC2AC-3C5A3C2-2AC5AC2A4-13(A5-A6-)C5-C55-2B10-17B5C4EBC7ABC2AC-D2C5A2CD2-2AF5AF2A4-13(A5-A6-)C5-C68-13BC2A5C3EB2C7ABC2AC-2AC5AC2A4-7A13(6-A5-A)6-C5-C68-13BCAB7C2BC-D2C5A2CD2-2AC5AC2A4-7A4(6-A5-A)5(6-7A)4(6-2A3-2A)6-CA3-AC7-A3-A56-13BC2A6C3BC-3C5A3C2-2AC5AC2A4-7A4(6-A5-A)2(6-7A)2(6-2A3-2A)6-AC3-C4(A6-AF3AF)A6-C5AC8-3A57-13BCAD6C3BC-D2C5A2CD2-2AC5AC2A4-A5CA6-AC2F2CA6-A5CA2(6-7A)2(6-2A3-2A)7-AD-DA8-A-D-A8-AD-DA8-D3-D8-AD-DA8-A-D-A8-AD-DA8-D3-D69-13BC2A6C3BC-3C5A3C2-2AC5AC2A4-4(7A6-)2A3-2A7-A3-A8-D3-D173-13BCAD10C-D2C5A2CD2-2AC5AC2A4-3(7A6-)2AD-D2A7-A-D-A9-D-D174-13BC11B2C2A10C-A2C5A2CA3-AC5ACA5-2(7A6-)2A3-2A7-D3-D199-13BC11BC-D9CD2-A2C5ACFA3-AC5AFA5-7A6-7A7-5A212-13BC11BC-11C2-AFC4A2CFA3-AC4A2CA4-2AC3AC2A6-A3FA9-3A213-13BC11BC-D9CD2-A2C4A3CA2-AFC4A2CFA3-2AC3AC2A6-5A225-13BC11BC-11C2-A2C4A3CA2-2AC4A2C2A4-AC3ACA7-5A225-13BC11BC-D9CD2-A2C4A3CA3-AC4A2CA5-AC3ACA7-5A225-13B6CBC4BC-3CA7C3-AC4A2CA4-AC4A2CA5-AC3ACA7-5A226-11B2-5CBCB3C3-D7CD4-A3C2A2CA5-A2C2ACA6-2AC4A8-3A227-11B2-5CBCB3C4-7C6-A5CA6-2A3C2A7-5A240-9B4-4CBCB2C6-D3CD8-A3CA9-3A255-7B6-3CB3C8-CDC10-3A265-
