model
size = 14 13 26, scale = 0.05, origin = -y
material 
  colors = A:#1A1A1A B:#111 C:#A8A8A8
voxels
18-2(6B8-)6A8-6A119-2(8B6-)8A6-8A7-2(6A8-)6A9-4A11-2A64-4(B-)2B4-B8AB2(4-10A)5-4(8A6-)8A7-6A9-4A34-5(B-)2B2-B10AB2(2-12A)3-4(A8-A4-)A8-A5-2(A6-)8A7-6A9-4A6-2B5(-B)2-B10AB2(2-12A)3-5(A8-A4-)A8-A5-3(A6-)A17-2B5(-B)-2B12AB28A-5(A10-A2-)A10-A3-A8-A30-6(B-)3B12AB28A4(-A10-2A)-A10-A2-A10-A3-A8-A30-2B5(-B)-2B12AB28A5(-A10-2A)-A10-A3-A8-A30-6(B-)3B12AB28A4(-A10-2A)-2A9-A3-A9-A4-A7-A5-A7-A16-2B5(-B)-2B12AB28A3(-A10-2A)2-A9-A3-A9-A4-A7-2A2(5-A)8-A3-A10-3A6-2B4(-B)-2B-B11AB2(-13A)2(2-A9-2A)2-A9-A4-A7-2A4-A7-A6-A5-A8-A3-A10-3A20-7(B-)B11AB2(-13A)2(2-A9-2A)2-A9-A4-A7-2A4-A7-A6-A5-A8-5A33-2B4(-B)-2B-B11AB2(-13A)2-A9-2A2-A9-A3-A9-A4-A7-2A4-A7-A6-C5-C8-5C33-7(B-)B11AB2(-13A)2-A9-2A2-A9-A3-A9-A4-A7-A5-A7-A6-7A9-3A34-2B4(-B)-2B-B11AB2(-13A)2-A9-2A2-A9-A3-A9-A4-A7-A5-A7-A6-7C46-7(B-)B11AB2(-13A)2-2(A9-A3-)A9-A4-A7-3(A6-)7A46-2B4(-B)-2B-B11AB2(-13A)2-A9-A3-A8-2A4-A6-2A6-A5-2A6-2C4-C9-4C47-7(B-)B11AB2(-13A)-2A9-A3-A8-A5-A6-2A6-A5-A8-6A59-6(B-)3B12AB28A-A10-A3-A8-A5-A-6A7-C5AC8-5C60-2B4(-B)-2B-B11AB2(-13A)2-A9-A4-A7-2A5-A-6A7-6A10-2A62-7(B-)B11AB2(-13A)2-A9-A4-A7-A6-7A9-4A75-2B4(-B)-2B-B11AB2(-13A)2-A9-A4-A7-A6-7A10-2A76-7(B-)B11AB2(-13A)2-A9-A4-2A5-2A7-5A89-2B5(-B)2-B10AB2(2-12A)3-2A7-A6-7A103-2B3(-B)-2B3-B9AB2(3-11A)4-9A8-4A105-2B2(-B)-2B5-2B6AB2(5-9A)7-6A116-
