model
size = 16 28 16, scale = 0.05, origin = -y
material 
  colors = A:#EEE B:#393 C:#222 D:#111 E:#444
voxels
19-2A8C6-2C8B6-C6B2AB6-7BA2B6-2(2B3A)6-BA2(B3A)6-A4B5A6-A2B3A4B6-2B2A3(BA)6-2BA2B2A3B6-2B2(A3B)6-3BA3B3A6-C9B6-AC8B6-2A8C6-10A2(9-2A3-2A8-2(A-)4A)9-2A3-D7-10A6-10A22-10E24(6-10A)6-8A24-10E2(6-10A)21-21(12A4-)12A5-10A6-10C5-E10AE2(4-12A)5-10A4-21(14A2-)14A3-13A3-C10AC3-E12AE2(2-14A)3-12A2-368A-C12AC-E14AE32A-14A-368A-C12AC-E14AE32A-6A-7A-368A-C12AC-E14AE32A-14A-95A4(C15A)C208A-C12AC-E14AE32A-14A-79AC5(15AB)15AC192A-C12AC-E14AE32A-14A-63AC7(15AB)15AC176A-C12AC-E14AE32A-14A-47AC9(15AB)15AC62A4(D-14A)D-32A-C12AC-E14AE32A-14A-47AC6(15AB)4(C14AB)C14AC16A3(C15A)C13AD-64A-C12AC-E14AE32A-14A-31AC6(15AB)16AC30A2(B15A)BC14AC16AC29AD-14AD-C13A2(D-14A)D-32A-C12AC-E14AE32A-14A-31AC15AB16AC15A2(C14AB)2(C15A)C14A3(B15A)BC14AB15A2C29AD-14AD-C13A2(D-14A)D-32A2-C11AC2-14AE32A-5A5-4A2-13AC2(2-13AB)2(2-C12AB)2(2-B9A3BA2-B9A4B)3(2-C9A4B)2(2-C12AB)2-13AC2-C13A2-C6AD4A2(DA2-C11A)2(DA2-12A)D3-14A3-13A3-C10AC3-E12AE2(2-14A)3-12A4-11AC4-7A5B4-C3(6A5B4-B)5(6A4BA4-B)11A4-C11A2(4-11AB)4-11AC4-12A4-2(A3D2A3DAD5-A2D2(AD)3AD5-)A3D2A3DAD5-12A4-12A5-10C5-E10AE2(4-12A)5-10A3-
