model
size = 14 13 26, scale = 0.05, origin = -y
material 
  colors = A:#4B4B4B B:#FFF C:#693FDE D:#8F4BDE E:#3D3BDE F:#A758ED G:#3535C9 H:#BD43ED
voxels
18-6B8-6G2(8-6E)119-8B6-8G2(6-8E)7-2(6C8-)6D9-4D11-2F64-4(B-)2B4-G8AG2(4-E8AE)5-2(8C6-)2(8D6-)8F7-6F9-4H34-5(B-)2B2-G10AG2(2-E10AE)3-2(C8-C4-)2(D8-D4-)F8-F5-2(F6-)8H7-6H9-4H6-2B5(-B)2-G10AG2(2-E10AE)3-2(C8-C4-)2(D8-D4-)F8-F4-F8-F5-3(H6-)H17-2B6(-B)G12AGE12A2E12AE-2(C10-C2-)2(D10-D2-)F10-F2-F10-F3-H8-H30-6(B-)2BG12AGE12A2E12AE2(-C10-2C)2(-D10-2D)-F10-F2-F10-F3-H8-H30-2B6(-B)G12AGE12A2E12AE2(-C10-2C)2(-D10-2D)-F10-2F-F10-F3-H8-H30-6(B-)2BG12AGE12A2E12AE2(-C10-2C)2(-D10-2D)-2F9-F3-F9-F4-H7-H5-H7-H16-2B6(-B)G12AGE12A2E12AE2(-C10-2C)-D10-2D2-D9-D3-F9-F4-F7-2F2(5-H)8-H3-H10-3H6-2B4(-B)-2B-G11AG2(-E11AE)2(2-C9-2C)2-D9-D4-D7-2D4-F7-F6-F5-F8-H3-H10-3H20-7(B-)G11AG2(-E11AE)2(2-C9-2C)2-D9-D4-D7-2D4-F7-F6-F5-F8-5H33-2B4(-B)-2B-G11AG2(-E11AE)2-C9-2C2-C9-C3-D9-D4-D7-2D4-F7-F6-B5-B8-5B33-7(B-)G11AG2(-E11AE)2-C9-2C2-C9-C3-D9-D4-D7-D5-F7-F6-7F9-3H34-2B4(-B)-2B-G11AG2(-E11AE)2-C9-2C2-C9-C3-D9-D4-D7-D5-F7-F6-7B46-7(B-)G11AG2(-E11AE)2-2(C9-C3-)D9-D4-D7-D6-F5-2F7-5F47-2B4(-B)-2B-G11AG2(-E11AE)2-C9-C3-C8-2C4-D6-2D6-D5-2D6-2B3-2B9-3B48-7(B-)G11AG2(-E11AE)-2C9-C3-C8-C5-D6-2D6-D5-D8-5F60-6(B-)2BG12AGE12A2E12AE-C10-C3-C8-C5-D-6D7-B4D2B8-4B61-2B4(-B)-2B-G11AG2(-E11AE)2-C9-C4-C7-2C5-D-6D7-2D2A2D10-2F62-7(B-)G11AG2(-E11AE)2-C9-C4-C7-C6-7D9-4D75-2B4(-B)-2B-G11AG2(-E11AE)2-C9-C4-C7-C6-7D10-2D76-7(B-)G11AG2(-E11AE)2-C9-C4-2C5-2C7-5D89-2B5(-B)2-G10AG2(2-E10AE)3-2C7-C6-7C103-2B3(-B)-2B3-G9AG2(3-E9AE)4-9C8-4C105-2B2(-B)-2B5-2G6AG2(5-2E6AE)7-6C116-
