model
size = 19 24 19, scale = 0.05, origin = -y
material 
  colors = A:#9CF B:#3FF C:#2BDCDC D:#29D4D4 E:#2FEDED F:#27CCCC G:#24BEBE H:#EA8B2D I:#F3F J:#FFF K:#F93
voxels
197-2(5D14-)4(5C14-)5E299-5D14-5D12-2(2D5A2D10-)4(2C5A2C10-)2E5A2E12-5E14-5E223-5F14-5F12-2D5A2D10-2D5A2D8-2(2D9A2D6-)4(2C9A2C6-)2E9A2E8-2E5A2E10-2E5A2E12-5E14-5B166-5F12-2F5A2F10-2F5A2F8-2D9A2D6-2D9A2D5-2(D13AD4-)4(C13AC4-)E13AE5-2E9A2E6-2E9A2E8-2E5A2E10-2B5A2B12-5B128-5F12-2F5A2F9-F9AF8-F9AF7-D11AD6-D11AD5-2(D13AD4-)4(C13AC4-)E13AE5-E11AE6-E11AE7-E9AE8-B9AB9-9B107-5G13-F5AF10-2F7A2F7-F11AF6-F11AF5-D13AD4-D13AD3-2(D15AD2-)4(C15AC2-)E15AE3-E13AE4-E13AE5-E11AE6-B11AB7-11B11-5B72-3G14-2G3A2G11-F7AF9-F9AF7-F11AF6-F11AF5-D13AD4-D13AD3-2(D15AD2-)4(C15AC2-)E15AE3-E13AE4-E13AE5-E11AE6-B11AB7-11B10-7B52-3G15-G3AG12-2G5A2G9-F9AF7-F11AF5-F13AF4-F13AF3-D15AD2-D15AD-D17A2D17ADC3(17A2C)17ACE17AE-E15AE2-E15AE3-E13AE4-B13AB5-13B8-9B13-3B17-G16-2GA2G13-G5AG11-G7AG9-F9AF7-F11AF5-F13AF4-F13AF3-D15AD2-D15AD-D17A2D17ADC3(17A2C)17ACE17AE-E15AE2-E15AE3-E13AE4-B13AB5-13B8-9B12-5B15-3G15-G3AG13-G5AG11-G6A-G9-F7A-AF7-F8A-2AF5-F9A-3AF4-F9A-3AF3-D10A-4AD2-D10A-4AD-D11A-5A2D11A-5ADC3(11A-5A2C)3H8A-2A3HCE4H7A-A4HE-2E2H7A-A3HE2-2E3H6A-4HE3-E3H6A-3HE4-B3H6A-3HB5-2BH6B-H2B8-9B12-5B16-G16-2GA2G13-G5AG11-G7AG9-F9AF7-F11AF5-F13AF4-F13AF3-D15AD2-D15AD-D17A2D17ADC3(17A2C)17ACE17AE-2E14AE2-2E14AE3-E13AE4-B13AB5-13B8-9B12-5B34-3G15-G3AG12-2G5A2G9-F9AF7-F11AF5-F13AF4-F13AF3-D15AD2-D15AD-D17A2D17ADC3(17A2C)17ACE17AE-E15AE2-E15AE3-E13AE4-B13AB5-13B8-9B13-3B54-3G14-2G3A2G11-F7AF9-F9AF7-F11AF6-F11AF5-D13AD4-D13AD3-2(D15AD2-)4(C15AC2-)E15AE3-E13AE4-E13AE5-E11AE6-B11AB7-11B10-7B89-5G13-F5AF10-2F7A2F7-F11AF6-F11AF5-D13AD4-D13AD3-2(D15AD2-)4(C15AC2-)E15AE3-E13AE4-E13AE5-E11AE6-B11AB7-11B11-5B109-5F12-2F5A2F9-I9AI8-I9AI7-D11AD6-D11AD5-2(D13AD4-)4(C13AC4-)E13AE5-E11AE6-E11AE7-J9AJ8-J9AJ9-9B145-5F12-2I5A2I10-FI5AIF8-DI9AID6-DI9AID5-2(D13AD4-)4(C13AC4-)E13AE5-EJ9AJE6-EJ9A2E8-2E5AJE10-2J5A2J12-5B166-F3IF14-FI3F12-ID5AID10-DI5AID8-DI9AID6-2D9A2D4(6-2C9A2C)6-EJ9AJE8-EJ5AJE10-EJ5A2J12-E3JE14-2(BJ)B223-D3ID14-3DID12-ID5A2I10-2D5A2D4(10-2C5A2C)10-2J5A2J12-2EJ2E14-2EJ2E299-D3ID14-5D14-2(CK)C14-2CK2C14-2(CK)C14-5C14-2EJ2E140-
