model
size = 29 18 15, scale = 0.05, origin = -y
material 
  colors = A:#3FF B:#F93 C:#26C1C1 D:#2BD9D9 E:#23B0B0 F:#2FEFEF G:#177A7A H:#1F9D9D I:#E78A2E J:#CF7C29 K:#FCC L:#141414
voxels
10-13G16-12H17-10E20-6E24-3C400-G6(A-)AG14-H12A2H14-E10A3E15-2E6A4E14-3C-2C3A2C17-5C-5C18-5C24-5D25-3D289-G7(A-)A2G11-H6A3(BA)B2A2H9-3E5A11B9-4E5A12B7-2C3AC3A4B2J2I5B6-2C5AC2A3B2J2I6B6-2C5A3C4J2I3B-2B7-2D5A2D-3J2I5B10-2D3A2D2-J3I7B10-5D3-J2I8B11-4F4-I10B12-3F3-11B12-3A3-7B-2B14-2A4-7B17-A4-8B16-A4-8B22-6B24-4B15-G9(A-)G8-2H18AH5-3E19A2E4-3E17A5E4-2C18A5C4-C19A5C4-C14A3-2A5C4-D9AD3A5-2A4D4-2D7AD10-2A3D5-2D5A2D10-2A3D6-2F4A2F10-3A2F8-2F3AF10-3A2F9-5A14-A10-4A2(26-3A)27-2A52-G10(A-)G4-3H21AH3-E24AE3-E19A5-E3(3-C19A5-C)3-D14A2-3A5-D3-D9AD2(2A5-)D3-D9A9-A5-D4-F8A9-A5-F6-F5A10-A5-F9-3A11-A4-A10-2A16-A11-A28-A79-3G11(A-)G2-H25AH3-K24AE2-E4A21-E2C5A21-3C13A13-C2-C16A9-C2-L17A8-D2-L13A2-3A7-D2-D9ADA5-2A7-D3-F8A7-2A7-F4-F6A9-A7-F6-3A12-A6-A28-A118-G3A11(-A)G3-K24AH2-E25A3E5A21-E2-K4A21-C2-K12A13-3C15A11-C2-D16A9-D2-D17A8-D2-D12A2-4A7-D2-F9AF5-3A7-F3-F8A7-2A7-F5-5A10-A7-A21-A6-A28-A89-G4A10(-A)-G3-K24AH2-E25A2E6A21-EC6A21-2C14A13-2C16A11-C2-D16A9-D2-D17A8-D2-D12A2-4A7-D2-F10A5-3A7-F3-F8A7-2A7-F5-5A10-A7-A21-A6-A28-A89-G3A11(-A)G3-K24AH2-E25A3E5A21-E2-K4A21-C2-K12A13-3C15A11-C2-D16A9-D2-D17A8-D2-D12A2-4A7-D2-F9AF5-3A7-F3-F8A7-2A7-F5-5A10-A7-A21-A6-A28-A90-3G11(A-)G2-H25AH3-K24AE2-E5A20-E2C6A20-3C13A13-C2-C16A9-C2-L17A8-D2-L13A2-3A7-D2-D11A5-2A7-D3-F8A7-2A7-F4-F6A9-A7-F6-3A12-A6-A28-A122-G10(A-)G4-3H21AH3-E24AE3-E19A5-E3(3-C19A5-C)3-D14A2-3A5-D3-D9AD2(2A5-)D3-D9A9-A5-D4-F8A9-A5-F6-F5A10-A5-F9-3A11-A4-A10-2A16-A11-A28-A83-G9(A-)G8-2H18AH5-3E19A2E4-3E17A5E4-2C18A5C4-C19A5C4-C14A3-2A5C4-D9AD3A5-A5D4-2D7AD10-5D5-2D5A2D10-5D6-2F4A2F10-3A2F8-2F3AF10-3A2F9-5A14-A10-4A2(26-3A)27-2A54-G7(A-)A2G11-H6A3(BA)B2A2H9-3E5A11B9-4E5A12B7-2C3AC3A4B2J2I5B6-2C5AC2A3B2J2I6B6-2C5A3C4J2I3B-2B7-2D5A2D-3J2I5B10-2D3A2D2-J3I7B10-5D3-J2I8B11-4F4-I10B12-3F3-11B12-3A3-7B-2B14-2A4-7B17-A4-8B16-A5-7B22-6B24-4B17-G6(A-)AG14-H12A2H14-E10A3E15-2E6A4E14-3C-2C3A2C17-5C-5C18-5C24-5D25-3D291-13G16-12H17-10E20-6E24-3C391-
