model
size = 32 32 22, scale = 0.05, origin = -y
material deform = 1, fade = true, lighting = smooth, roughness = 0.3, metalness = 0.6
  colors = A:#555 B:#222 C:#FCFAF2 D:#FFB11B E:#111 F:#444
voxels
26-B1171-2(4B2(28-B2-B)28-4B188-)4B2(28-B2-B)28-4B315-6B18-5B3-6B3-5B14-2(B3-2B2C2B3-B18-)B3-6B3-B14-5B3-6B3-5B114-2(6B26-)2B2C2B18-2B6-2B2C2B2(6-2B10-2B6-6B)6-3(2B10-2B18-)2(2B10-2B6-6B6-)2(2B10-2B6-2B2C2B6-)2(2B10-2B6-6B6-)3(2B10-2B18-)2B78-14A18-14A15-3B14A3B12-3B14A3B11-4B14A4B11-2(3B14A3B12-)3B14A3B11-4B14A4B11-3B14A3B12-3B4(14A18-)14A14-2B2-14A2-2B5-352A-30A3-28A7-2B18-2B46-14A16-18A14-18A13-B18AB12-B18AB11-2B18A2B11-2(B18AB12-)B18AB11-2B18A2B11-B18AB12-B4(18A14-)18A12-2B18A2B5-352A-30A3-28A7-2B18-2B10-2B18-2B12-2(18A14-)18A13-B18AB12-B18AB11-2B18A2B11-2(B18AB12-)B18AB11-2B18A2B11-B18AB12-B4(18A14-)18A12-2B18A2B6-9(30A2-)30A-32A-30A3-28A5-26A8-2B18-2B12-2A14-2A13-3A14F3A3(12-20A)11-4(B20AB10-)B20AB11-5(20A12-)20A11-B20AB6-9(30A2-)30A-32A-30A3-28A5-26A8-2B4A2-6A2-4A2B12-2A14-2A13-3AF12BF3A14(12-20A)11-B20AB7-8(28A4-)28A3-30A-32A-30A3-28A5-26A8-2B4A10-4A2B12-2A14-2A13-3AFB10EBF3A14(12-20A)11-B20AB7-8(28A4-)28A3-30A-32A-30A3-28A5-26A8-2B4A-8F-4A2B12-2A14-2A13-3AFB10EBF3A14(12-20A)11-B20AB8-6(26A6-)26A5-28A4-28A3-30A-32A-30A3-28A5-26A8-2B4A-F6BF-4A2B12-2A14-2A13-3AFB10EBF3A5(12-20A)2(11-B20A)7(12-20A)11-B19A2B11-3(B18AB12-)B18AB10-24A7-26A6-26A5-28A4-28A3-30A-32A-30A3-28A5-26A8-2B4A-FB4EBF-4A2B12-2A14-2A13-3AFB10EBF3A2(11-B20A)3(12-20A)11-B20AB10-B20AB11-6(20A12-)20A2(11-B19A2B11-3(B18AB12-)B18AB10-24A7-26A6-26A5-28A4-28A3-30A-32A-30A3-28A5-26A8-2B4A-FB4EBF-4A2B12-2A14-2A13-3AFB10EBF3A2(11-B20AB10-B20AB11-2(20A12-)20A)4(12-20A))11-B20AB8-6(26A6-)26A5-28A4-28A3-30A-32A-30A3-28A5-26A8-2B4A-F6BF-4A2B12-2A14-2A13-3AFB10EBF3A2(11-B20AB10-B20AB11-2(20A12-)20A)4(12-20A)11-B20AB7-8(28A4-)28A3-30A-32A-30A3-28A5-26A8-2B4A-8F-4A2B12-2A14-2A13-3AF12BF3A11-B20AB10-B20AB11-2(20A12-)20A10-2B20AB9-2B20AB11-6(20A12-)20A11-B20AB7-8(28A4-)28A3-30A-32A-30A3-28A5-26A8-2B4A10-4A2B12-2A14-2A13-3A14F3A11-B20AB10-B20AB11-2(20A12-)20A10-2B20A2B8-2B20A2B10-6(20A12-)20A11-B20AB6-9(30A2-)30A-32A-30A3-28A5-26A8-2B4A2-6A2-4A2B12-18A14-18A12-2B18A2B10-2B18A2B12-2(18A14-)18A11-3B18A3B8-3B18A3B11-6(18A14-)18A12-2B18A2B6-9(30A2-)30A-32A-30A3-28A5-26A8-2B18-2B14-14A16-8A2D8A12-2B7A4D7A2B10-2B8A2D8A2B12-7A4D7A14-8A2D8A14-7A4D7A11-3B6A6D6A3B8-3B6AD4CD6A3B11-5A2D4C2D2(5A14-5A8C)2(5A14-5A2C4A2C)2(5A14-5A8C)5A12-2B5A2C4D2C5A2B5-12A2C4D5(2C24A2CD2AD)2C21A3D2CD2AD2C3D2(18AD4CD2AD4CD)18A6D2A6D41A-30A3-28A8-B19-B10-2B18-2B46-6A2-6A14-4B5A4-5A4B10-4B6A2-6A4B14-5A4-5A18-6A2-6A18-5A4-5A13-5B4A6D4A5B8-5B4AD4CD4A5B13-3A2D4C2D2(3A18-3A8C)2(3A18-3A2C4A2C)2(3A18-3A8C)3A14-2B2-3A2C4D2C3A2-2B5-12A2C4D5(2C24A2CD2AD)2C21A3D2CD2AD2C3D2(18AD4CD2AD4CD)18A6D2A6D41A-30A3-28A8-B19-B10-2B18-2B74-5B12-5B10-5B12-5B105-6B3-6D3-6B8-6B3-D4-D3-6B16-2D4-2D90-4A28-4A83-2B7-4D8-B10-2B7-4D5(7-2B10-2B7-D2-D)7-2B10-2B2-3D2(2-D)2-3D2(2-2B10-2B2(2-D4-D))2-2B10-2B2(2-6D)2-5(2B10-2B18-)2B75-3(4B12-)4B107-5B12-5B10-5B12-5B234-2B30-13(2B18-2B10-)2B18-2B30-2B5-
