model
size = 17 28 17, scale = 0.05, origin = -y
material deform = 1, fade = true, lighting = smooth, roughness = 0.3, metalness = 0.6
  colors = A:#111 B:#9CF C:#777
voxels
7-2(ACA473-ACA14-)ACA150-3A13-5A11-7A9-7(9A8-)9A9-7A11-5A13-3A15-A83-ACA14-ACA114-7A10-7A9-9A7-2(11A6-)11A5-3(13A4-)13A5-2(11A6-)11A7-9A9-7A11-5A13-3A15-A66-ACA14-ACA97-7A10-A5BA8-3A5B3A5-2(4A6B3A4-)3A7B3A3-3(4A7B4A2-)4A7B4A3-2(3A7B3A4-)3A7B3A5-2A7B2A7-9A9-7A11-5A13-3A82-ACA14-ACA49-C16-C12-9A7-3A5B3A9-A3BA11-C5AC9-C7AC8-C7AC7-3(C9AC6-)C9AC7-2(C7AC8-)C7AC9-C5AC11-C3AC13-3C133-2(ACA14-)3A2(14-ABA)10-11A5-3A6B4A7-C5AC260-2A13-2A-2A11-2A3-2A9-2A5-2(2A7-)2A5-2A9-2A3-2A11-5A12-A3-A12-5A12-A3BA9-3A5B3A5-2A7B4A6-C7AC259-2C13-2C-2C11-2C3-2C9-2C5-2(2C7-)2C5-2C9-2C3-2C11-CA2-C12-A3-A11-CB3ABC10-C5BC8-2A6B3A5-2A7B4A6-C7AC259-2A13-2A-2A11-2A3-2A9-2A5-2(2A7-)2A5-2A9-2A3-2A11-5A12-A3-A12-5A12-A3BA9-5A3B3A5-6A3B4A6-C7AC351-2(ACA14-)3A2(14-ABA)11-9A7-11A8-C5AC335-ACA14-ACA49-C16-C13-7A9-9A10-C3AC319-ACA14-ACA98-5A11-7A12-3C303-ACA14-ACA116-3A13-5A302-ACA14-ACA150-3A286-ACA14-ACA456-ACA466-
