model
size = 32 28 21, scale = 0.05, origin = -y
material deform = 1, fade = true, lighting = smooth, roughness = 0.3, metalness = 0.6
  colors = A:#903 B:#A00028 C:#000
voxels
494-2B2AB26-2B2ABA25-BA5BA24-A2B2(AB)A24-2(2AB)2A25-B3ABA27-3BA638-B28-2A3BAB24-2B2(2-B)A22-B2A2(2BA)B22-A-2ABA2B-B22-A-2(A2B)-2B21-A-2(2BA)-2A21-BA2-B2A-BAB21-ABA2B2(AB)A23-B2ABA2B2A24-4B2AB26-4BA489-B6-B10-B2ABA9-B6-A8-2B2AB3A8-A14-8A-A22-3A2B4A-B20-B-B7A-2A19-A-7AB-BA19-B-B6AB2-B19-A-8A2-A19-B2-5A2B2-A19-B-B6AB-B20-BA2-2(BA)3-A21-AB7-B22-B2(2A2B)A334-A22-A-A6-B-A20-A-A6-B-BA19-B-B6-A2BA9-B8-2A-A6-2ABA6-A4BA6-2(BA)6-2ABA5-2A-3B-A5-3AB6-2B-B4-B2(3C-)B4-2(AB)6-AB-A4-A4CB2CA-A3-A-2A7-2A2B2-A2(BC)B3C2B-A2-A-2A7-AB3-A-ABC3BC2BA-A4-A9-B3-A-A3C2(BC)2B2-A3-A9-B3-A-B2CB4C2B2-A3-A13-B-2(B3C)BA-B18-B-2A7BA2-A17-B-A9B-B18-B2-BA6B2-A19-A2-5AB2-2B20-B8-BA22-2ABAB2AB176-B22-B8-A22-A8-A21-2A8-BA20-BA7-ABA20-BAB6-2A-A18-B-2B7-B-B7-2BAB7-B-B8-A-A6-2BA-2B6-B-B8-B-A5-B2-BAB-BA4-A-A8-A-A4-B-AB3-A-AB3-B-A7-2(B-)A2-A8-2AB3-B2-A6-A-B-A2-2B8-B-B2-2A-B7-B2-B-2A10-B2(A-)B-A7-B-2A-BA10-B-4AB8-B-B2A-A10-A2-2B2A8-BA2BA-A10-B2-B3A9-B2(A-)A10-A-2A-B10-B2-A-B10-B-A2-A13-B-A10-A-B17-A-2A7-A2-B17-B2-B6-B2-B19-B2-2(2AB)2-A21-A2B4-ABA25-2(AB)146-B31-2B20-2A5-BA-BA20-A-3B2-BAB-A20-A-ABA2-2A3-B7-2AB2A6-A3-BA2-BA3-A6-2(2AB)6-A3-2B2-3B2-B6-2(B2A)6-A2-ABA2-3A2-A5-4B2ABAB4-A2-3A2-BA2(B3-)A-2A3-2A-A3-A2-ABA2-3A3-A2-A-A6-2AB2-B3-ABA2-B2A3-A2-2B9-AB-B3-2BA2-AB-A2-A-2B10-B-BA2-A-2B2-BA2-2(B-)BA11-BA3-A-AB2-2A2-A2-2A12-A4-A-A4-A2-B3-A12-A3-B2-A7-2A2-B12-A3-B10-A-B2-A11-A2-2A10-3A2-B11-A-3B11-AB2-B11-4BA12-2A-A10-B2-B16-A-A8-A2-A17-2B-BA4-BA2-B20-B2-4A2-BA22-A4BA2B47-AB25-B4-2B24-BA4-AB24-BA3-2AB23-B2A3-3B23-A2B2-B-BA22-B2(2-A)2-B22-A2-B2-A3-A7-2B4-B6-A3-B2-A3-A6-2B4-2B6-B3-B2-B3-A6-AB5-BA5-B3-A2-2(A4-)B-A5-2A4-A4-B2-A4-B3-A-B7-2B3-A4-B2-A4-A3-BA9-2B2-B4-A2-A5-B-AB10-B-BA5-B2-A-A3-BA-B11-B-A3-B-B2-A-AB2-3B12-B2(-B3-A)BA4-A13-A4-A-A3-3A4-A13-A3-2(A2B4-)A13-B3-2AB5-B2A3-B12-B3-4A5-2A-B-2A12-B2-B-2B7-A-B2AB12-A-2B-B11-B2-A11-B-BA14-A-A10-B-B17-A-AB7-A-A19-B2-2(AB)2AB-A21-A3B6A78-AB24-2A3-2BA23-A-A3-B-A23-AB4-A-A22-A-A4-B-B22-B-A4-B-B21-A2-2(A3-)B20-B3-A-A4-B14-A5-B4-2B4-B5-BA7-B5-A4-A2(B4-)B-B8-B2(4-A)B5-B3-2A8-B-B2-2(A5-B)2-2A10-2A2-B5-AB5-B2-BA11-BA-2(A5-B)-AB12-2B-A5-B-B4-A-2B13-B-A4-B2-B5-2A14-2A5-A3-B5-A14-A5-A4-B5-B14-2(B5-)A4-A14-A4-A6-B-A2-2A13-B2-A-B7-BA-2AB12-A3-BA9-2B2(3-B11-B)2A-B10-B-2AB15-B-B8-B-BA17-2A-2B4-2B2-A20-2(BA)2B3ABA24-A2BA49-B25-A4-2B25-2A2-B-B24-B-B2-B-A24-B-2BAB2-A22-B2-4A2-A22-B2-B2A3-B22-A3-2B3-B7-A7-B6-B3-2B4-A5-A8-A5-B4-2A5-A3-B-B7-2B4-A4-2B5-A2-A-A9-2B2-B5-2B5-A2-2B11-A2-A5-AB5-A2-A12-AB-A5-AB5-A-2A13-B-2(A5-B)-A14-AB6-BA6-2B14-B7-A-A6-A14-A6-AB-B6-A14-A6-B2-2B5-B14-B5-2A3-A6-A13-2(B5-)A5-A13-B4-A7-3B3-B11-A4-A11-BA-B10-A2-3B14-B-BA6-BA2-2B16-BA2-2B4A3-B20-BA6-A2B23-2ABA2B111-2B25-B3-2BA24-ABA2-B-B24-A-A2-B2-A22-B2-A2-B2-A22-A2-A-B3-B7-A7-2B5-A2-B-A3-B6-AB7-BA5-B2-B-2(B4-)2B9-A5-B3-2A4-A3-BA10-BA3-A4-AB4-A3-BA11-B3-B4-3A2(3-A)12-2B2-B4-A-B4-B-AB13-B2-B3-BA-B4-B-B14-2AB4-B2-A4-ABA15-BA4-A2-AB3-A-A14-B-B3-BA2-3B4-B14-A-B3-AB3-2A4-B14-B4-BA4-2B4-A14-B4-BA5-2A3-A14-B3-2A8-B3-A12-B3-2A10-2B2-B10-A2-AB14-A2-A8-A2-AB16-BA-AB2A2BAB2-A20-2(B2A)B3AB198-A5-2B24-2B4-BA24-AB4-2B24-AB3-B-A17-B6-B-2(B2-)A16-A5-B2(2-A)2-B5-BA9-B5-2(A2-)B2-B22-A2-B2-A2-B22-A2-B3-B2-B21-A2-A3-2(B2-)B14-2B-B2-A4-B2-A-BA14-AB-B2-A4-A2-A-AB14-BA-A2-B5-B-A-2A15-2(B-)A7-2(B-)B15-2(B-)B7-B-2AB14-2(A-)B8-A3-B14-2(B-)B9-2A-B14-B-AB11-A2-B12-B2-BA12-A2-A11-B-AB14-A2-A8-BA-2A16-B2-B2A2-A2B2-2A18-A2BA-AB-A3BA22-3A2B177-B24-B6-A24-B5-2A24-2A4-2B24-BA4-AB24-2B4-B2A23-2B4-BAB22-A2B4-BAB22-3A5-2A22-A2B5-2B3-BA13-B3-2B6-2A3-A14-2B2-AB6-3A-BA15-A2-AB6-2AB-BA15-B2-BA7-2B-AB14-2B-2A9-A2-A14-2(BA)10-AB2A14-2A2B12-2(2A14-)B-A12-A-B14-BA-B11-A-B15-B2-A8-BA-BA16-B2-BA6B2-BA18-2AB6-B3A20-2A2(BA)2B373-A15-A14-2A15-A3(14-AB)14-BA14-AB14-A-A13-BA14-A-A13-AB14-B-B13-2B14-A-B13-BA14-B-A13-BA14-A-B13-B-A13-3B13-B-A12-A-A14-AB-B10-B2-A15-B2-2A6-BA2-2A16-A3-5BA3-2A18-2A9-AB20-A3B4A2B339-B14-AB14-2B14-2A2(14-BA)14-2A14-BA14-2A14-2B2(14-AB)14-2B14-2A14-A-A13-2B14-B-B13-2A14-B-A13-BA14-A-A13-B-B13-A-A12-A2-B13-B2-A11-B-B14-A3-B9-B2-A15-A3-A6-2A2-A17-B3-2(2BA)4-A18-B10-BA20-2AB7A340-A13-A16-2B13-2B15-2A13-BA15-2B12-A-A15-AB13-BA14-A-B13-BA14-B-B2(13-2A14-A-A)12-B-A15-BA12-B-B15-2B12-B-B15-A-B11-A-A14-A2-B10-2B-B15-B2-BA7-B-2B17-B3-BAB-3A3-A17-A6-A5-A19-2A9-A22-A4BA3B276-A12-B18-B12-A18-AB11-BA17-B12-AB16-2A12-AB16-AB12-AB16-B-B11-A-B15-A-B11-A-A2(15-B-B11-A-B)15-A-B10-A-B16-A-B10-A2-B15-A-B10-A2-A15-B-B10-B-B16-B2-B8-4B17-B2-2B4-2B-2B18-A4-2(AB)4-A19-AB9-A22-4B2A3B321-A18-B12-B18-A11-AB18-BA10-2B18-AB10-AB18-2A10-A-B17-2A10-B-B17-BA10-A-B17-BA10-B-A17-AB10-A-A17-2A10-A-B17-A-B9-B-A17-B-BA7-A2-B17-A-2A6-AB-B18-BA-2A5-B2-A19-B3-BAB2A2-A20-BA8-2B21-ABA5-2A25-2B2AB387-B18-A3(12-A18-B)12-A18-AB10-AB18-A-B8-B-A18-B-A9-2B18-A-AB7-B-A18-B2-B7-A-A19-A-A7-A-B19-B2-A4-BA-B21-A2-2ABAB2-B21-B8-A23-AB5-A26-3B3A566-2AB7-3A18-BA-B7-2B19-AB-B6-BAB19-BA2-B5-B-A20-B2-2B2-A2B-A20-BA-2ABAB2A-A21-B2-2A2B2-2B22-B7-A23-BA4-BA25-2A2(BA)632-BA3B4-A22-B3AB2A2BAB21-2B-B3ABAB22-B2A-2B2-AB23-2A4-BAB23-A2B3-2B25-BAB3AB26-2(AB)700-BA29-ABA2BA27-4AB27-3AB29-3B206-
