model
size = 31 32 31, scale = 0.05, origin = -y
material deform = 1, fade = true, lighting = smooth, roughness = 0.3, metalness = 0.6
  colors = A:#FFB11B B:#777 C:#F7C242 D:#444 E:#FCFAF2 F:#555 G:#96632E
voxels
832-2(3B28-)3B2(30-B)840-18B7-3B4-B23-3BD3-B23-3B4-B23-3B3-18B9-B840-18B7-3B3-18B7-3BD2-2(18B7-3B3-)13B-14B18-D642-5(2D29-)2D22-7B2D9B7-3B4-6B2D9B7-2B-D3-6B2D9B7-2B5-6B2D9B7-2B4-13B-14B365-D30-D89-C63-2C29-2C78-2D39-5D109-2D22-3B4-2D16-3B4-2(2B4-2D16-2B5-)2B4-2D16-2B4-3B24-B265-10A21-10A11-9A-10A11-9AC2(10A11-9A-)2(10A13-7A-)4AC5A2(13-7A-10A)13-7A3(-2A7-A11-5A4C)-3A6-A11-5A4C-3A5D-A11-2(5A4C-3A18-)9A-3A21-2D22-3B4-2D16-3B4-2(2B4-2D16-2B5-)2B4-2D16-2B4-3B24-B274-A30-2(A11-A7-A10-)2(A11-A9-A8-)5(A21-A8-)3(A11-A4-4C-A8-)A9-2DA4-4C-A2-5D-A9-D-A4-4C-A18-D-A4-4C-A20-9A-3A2-2C17-2D10-2C10-3B4-2D16-3B4-2B4-2D16-2B5-2B4-2D16-2B-D3-2B4-2D16-2B4-3B24-B274-A30-2(A19-A10-)A17-3C-A8-A11-A5-4C4(A8-A11-A5-3C-)A8-A11-A9-4(A8-A11-A4-4C-)A2-5D-A11-A4-4C-A8-A9-D-A4-4C-A8-A11-9A-10A14-2D4A2-4A2C2A8-3B4-2D14A2-3B4-2B4-2D14A2-2B5-2B4-2D2AC11A2-2B5-2B4-2D14A2-2B4-3B22-3B274-A30-2(A19-A10-)A17-5(3C-A8-A11-A5-)4C5(A8-A11-A8-C)A2-5D-A11-2(A8-CA8-A9-D-)9AC10A9-D4-2D2(4A2C)2A8-3B4-2D14A2-3B4-2B4-2D14A2-2B2(5-2B4-2D14A2-DB)4-3B9-3C10-2DB15-3C256-A30-A19-A10-A19-A-A8-A17-2(3C-A8-A11-A5-)2(3C-A5-5C10-A5-)3C-A8-A11-A5-4C4(A8-A11-A8-C)A4D4-A11-A8-CA7D-2(A11-A8-CA4D4-)A11-9AC10A12-8A2C8A8-3B2-18A2-3B4-2B2-18A2-2B5-2B2-18A2-DB-D3-2B2-18A2-DB4-3B4-5A3C6A4-2DB15-3C256-A30-A19-A10-A19-A-A8-A17-2(3C-A8-A11-A5-)3C-A5-5C8-2CA5-3C-A5-5C10-A5-3C-A8-A11-A5-4C4(A8-A11-A8-C)A4D4-A11-A8-CA7D-2(A11-A8-CA4D4-)A11-9AC10A12-8A2C8A8-3B2-18A2-3B4-2(2B2-18A2-2B5-)2B2-18A2-2B4-3B4-14A4-3B10-14A5-2D191-3C28-3C18-A30-A17-3A10-A13-3C-3A10-A17-2(3C-A8-A11-A5-)2(3C-A5-3CA11-A5-)3C-A8-A11-A5-4C4(A8-A11-A8-C)A4D4-A11-A8-CA7D-2(A11-A8-CA4D4-)A11-9AC10A12-8A2C8A8-3B2-18A2-3B4-2(2B2-18A2-2B5-)2B2-18A2-2B4-3B4-14A5-DB10-14A5-2D69-2(A30-)A28-2CA28-CAC28-3C4(18-A11-A)2(5-3C-A8-A11-A)2(5-3C-A5-3CA11-A)5-3C-A8-A11-A5-4C4(A8-A11-A8-C)A4D4-A11-A8-CA7D-2(A11-A8-CA4D4-)A11-9AC10A12-8A2C8A8-3B2-18A2-3B4-2(2B2-18A2-2B5-)2B2-C17A2-DB4-3B2-2C14A4-DGB10-14A4-3D69-2(A30-)3(A28-2C)4(A18-A11-)A5-3C10-2(A11-A5-3C-A5-3C)A11-A5-3C-A3C2-3CA11-A5-3C-A3C5-A10-CA5-4CA3C5-3(A11-A8-CA8-)A11-A8-CA4D4-A11-A8-CA7D-2(A11-A8-CA4D4-)A11-9AC10A12-8A2C8A8-3B2-18A2-3B4-2(2B2-18A2-2B5-)2B2-C17A2-DB4-3B2-2C14A4-D2B10-14A4-2D70-5(A30-)3(A16-3A11-)A15-2(C3A10-2A5-3A7-)2C2A10-2A5-3A-A5-2C2A11-A5-3A-AC-7A11-9A-9(10A11-9AC)10A12-8A2C8A8-3B2-18A2-3B4-2(2B2-18A2-2B5-)2B2-18A2-2B4-2B5D14A4-3B10-14A76-A7-A22-A7(7-A21-2A)7-A21-10A-7AC13-E8A-7AC12-10A-10A11-2(9A-9A12-)4(9A-10A11-)9A-10A3D8-9A-10A4D7-2(9A-10A11-)9A-2A2-6A11-2C17A8-3B-2C17A2-3B4-2(2B2-18A2-2B5-)2B2-18A2-2B4-3B4-14A4-D2B10-14A4-2D70-A2(7-A21-2A)7(7-A22-E)9-A20-E9-A19-2A9-A8-A11-A9-A4-3C13-A9-A20-4(A9-A8-A11-)2(A9-A8-A3D8-)2(A9-A8-A11-)9A-10A11-2C17A8-3B-2C17A2-3B4-2B2-17A4DB5-2B2-18A2-2B5-2B2-17A2C-2B4-3B4-14A3C-3B10-14A76-A7-A21-2A2(7-A22-E)7-A22-F7-A22-E4(7-A21-2A)2(9-A19-2A)9-A8-A11-A9-A4-3C13-A9-A20-A9-A8-A11-A8-C4(A8-A11-A9-)2(A8-A2-D8-A9-)A8-A2-D8-9A-10A12-18A8-3B2-18A2-3B4-2B2-17A4DB5-2B2-18A2-2B5-2B2-17A2C-2B4-B6-14A3C-3B10-14A24-A18-2C10-A18-2CA7-A-A19-2A2(7-A-A20-E)7-A-A20-F7-A-A20-E4(7-A-A19-2A)2(9-A2-4C13-2A)9-A2-4C2-A11-A9-A2-5C13-A9-A2-4C14-2(A9-A2-4C2-A11-)5(A9-A8-A11-)A9-A8-A2-D8-9A-10A2-D9-18A3-D4-3B2-18A2-3B4-2(2B2-18A2-2B5-)2B2-18A2-2B4-B6-14A4-3B10-14A24-A18-2C10-A18-2CA2(7-A-A19-2A)7(7-A-A20-E)9-A2-4C14-E9-A2-4C13-2A9-A2-4C2-A11-A9-A2-4C11-3DA9-A2-4C11-2(D2-A9-A2-4C2-A8-)2(D2-A9-2(A8-))3DA8-C3(2(A8-)D2-A9-)2(A8-)D2-9A-10A8-D3-18A8-3B2-18A2-3B4-2B2(2-18A2-2B5-2D)2-18A2-2B4-B2D4-14A4-3B10-14A24-A30-2(A20-A7-A-)7(A19-2A7-A-)A19-2A9-A2-4C14-E9-A2-4C13-2A5(9-A2-4C2-A11-A)5(9-A8-A11-A)9-A8-A11-9A-10A12-18A8-3B2-18A2-3B4-2(2B2-18A2-2B5-)2B2-18A2-2B-B2DB6-14A4-4B3D6-14A7-2D15-A30-9(A20-A7-A-)A19-2(2A9-A2-4C13-)2A2(9-A2-4C2-A11-A)9-A2-4C2-A10-C2(A9-A2-4C2-A11-)6(A9-A8-A11-)9A-10A12-18A8-3B2-18A2-3B4-2(2B2-18A2-2B5-)2B2-18A2-2B-B2DB6-14A4-4B3D27-2D15-A8-A21-9(A8-A11-A7-A-)A8-A11-A9-A2-4C2-A11-A8-C2(A2-4C2-A11-A9-)A2-6C3(A11-A9-A2-4C2-)6(A11-A9-A8-)A10-C9A-10A10-C-18A8-3B2-18A2-3B4-2(2B2-18A2-2B5-)2B2-18A2-2B-B2DB24-3BD-2D26-2D16-A8-A21-9(A8-A11-A7-A-)A8-3(A11-A9-A2-4C2-)A11-A9-A2-6C3(A11-A9-A2-4C2-)6(A11-A9-A8-)A10-C9A-10A10-C-18A8-3B2-18A2-3B4-2B2-11AD6A2(2-2B5-2B2-18A)2-2B4-B24-3BD29-2D16-A8-A21-2(A8-A11-A7-A-)2(A9D10-9DA-A8-A11-A7-A-)A9D10-9D2(A-10A11-A7-)A-10A3(11-A9-3A4C3A)11-A9-3A6CA3(11-A9-3A4C3A)6(11-A9-10A)10-C9A-10A10-C27-3B22-3B4-2B13-D8-2(2B5-2B22-)2B4-B24-D2B28-2D18-10A21-9(10A11-9A-)2(10AC10-9A-)5(10A11-A-7A-)7(10A11-9A-)10A33-D4-3B22-3B4-2B11-3D8-2B2(5-2B23-B)4-B24-2DB28-2D119-C30-2C16-C12-C17-C8-3D-C57-3D46-2C11-3D2-2C10-9A10-2C10-9A24-2(7A8D16-)7A9DC14-7A8D16-7A2(8D14-9A)6-C15-3(9A22-)9A28-C51-28B4-13BDB-6B2-2B5-17B8-B5-12BD5B7-B4-B3-9BD2-3B6-2DB28-2D319-C30-C-C61-2(14D17-)2(2D10E2D17-)14D17-14D144-C30-C51-28B3-16B-6B3-DB3-18B8-DB3-19B7-D2(B3-)9B2D-3B7-DB16-2D490-10E21-10E291-19B7-2B4-2(B24-D5-)B24-D4-2D11B2D4B7-DB16-2D848-2B10-6D13-2B13-3D14-B30-B3-2D25-B3-2D876-3D28-3D110-
