model
size = 21 32 21, scale = 0.05, origin = -y
material deform = 1, fade = true, lighting = smooth, roughness = 0.3, metalness = 0.6
  colors = A:#222 B:#FFF C:#0A0 D:#FF3 E:#093 F:#FF0 G:#FC3 H:#F93 I:#FC0 J:#F90 K:#010 L:#100 M:#C30 N:#066 O:#555 P:#F63 Q:#9C0 R:#001 S:#C60 T:#AAA U:#EEE V:#111 W:#A00 X:#FF6 Y:#6C3 Z:#3F0 Aa:#690
voxels
342-3A3-2AB11-AB5AB3A10-3(B2A)2B10-2ABO2(AB)3A10-2AB2A2B2(AB)10-2B6AB2A10-3ABABK4A11-A2B4ABA13-3A2BAB15-5A413-B2A2B4A11-C7ABAB8-2(CE)AB3AB4AB6-2CE4AB6AB5-C2E14A4-ABC13AB3-19A-O2A2B13ABAK-B17AB2-15AB2AB2-2AB11A2BABA-AB2AKDB14A-ABADI11A2BA3-J2I2D2(BA)B3AB2AB10-B3AB329-B4AB2AK9-E3(AB)2AOB2A2B6-E14A5-3C14A4-NCA2(4-3A)4-EC13-2A4-2B13-2A3-B2A13-2AB-4A13-4AB2A15-2AB3A15-6A15-2A2B3A2(13-8A)13-3AB-BDB2A9-5A4-IDJD6ABKABA8-DJD2AB2A2BA12-DIA2B2A15-D3AK36-2B2(AB)A14-3AB3A14-AB3A2B14-2(BA)B2A14-3A2(BA)14-2ABA2BA14-B6A14-B2AB3A14-B3A2BA13-B2AB3ABA11-5A2(B2A)8-B6A-4AB2A5-E4A2-A-A2-5A4-C2A4-A-A4-3A3-EA15-AB2-EA15-2A2-KA15-2A-3A15-6A15-3AB2A15-2AB3A2(15-6A)15-3AB2A15-2AB2A2(17-2ADA)17-2A-3I2L9-3ABA5-HAa9AAaA9-GS8AB11-2I5ABA13-D6C12-10AB10-9ABA10-B10A10-E9AB10-2C9A10-CE7ABA9-2E9ABA8-C9AB2A6-2CBAO10AKA4-C5A-3A-2AB3A4-5A2-3A2-2A2BA4-3A11-2AO4-CA13-AB3-EA15-2A2-2A15-2A-2A17-A-BA17-AB2A3(17-4A)17-A2BA17-2ABA17-4A17-2AKA17-AKFA17-ABGA17-2AGA17-AB-MJM2A9-3ABA5-M4A3-5A9-G10A11-M7AC10-13A8-B11AB8-13A8-12AB8-E12A7-CE13A6-E13AB6-N14A5-C5A-3A-6A4-2DA11-2AB4-2F13-2A3-BAB13-2AB2-DA15-2A2(2-A17-A)-2A17-AO2A17-4A2(17-2ABA17-AB2A)17-4A17-AB2A17-4A17-2AFA17-2AIA17-2AJA17-2A-3J2A9-4AB5-S-2A5-2A-A8-S2(-4A)-A9-HB2A3-3AC2(9-2A)8-3A2-A-A2-3A8-3A2-A-A2-2AB7-B3A2-A-A2-4A6-4A2-A-A2-4A6-C3A2-A-A2-3AB6-EY2A7-2AYA6-E2A9-3A5-BA-A9-A-2A4-DA13-2A3-HA15-AB2-FA15-2A2-H17-A-IA17-AI2A17-AB2A17-2AB19-BA2(19-2A)19-3A3(17-4A)17-2ABA17-ABIA17-2AHA17-2AJA17-AB-2IJ2A9-2AB2A5-J-A7-A-B8-M-3A3-3A-A9-G2A5-2AC8-D13-B6-DA11-2A6-2A11-2A6-3A9-2AB6-AWA9-AWB6-B2A9-3A6-CA11-2A5-C2A11-2AB4-G2A11-3A3-GA15-2A2-DA15-2A2-G17-A-GA17-AGHA17-AHA19-AF19-FA19-AB19-BA19-2A19-AOA17-2ABA17-A2BA17-AB2A17-2ABA17-ABFA17-2AGA17-ABGA17-2A-J2MA11-4A4-MA11-2A7-P-A7-A-B9-HA7-AC8-I2(13-A6-A)13-A6-2A11-2A6-BA11-2A6-2A11-2A5-XA13-2A4-FA13-AK4-FA13-AB3-PA15-2A2-G17-B2-J17-A-MA17-AMFA17-AFH19-HF19-FA2(19-2A)19-2K19-K2(BA17-AB2A17-2A)FA17-AF2A17-2ADA17-ABGA17-AB-3D13-ABA4-HA11-2A7-G-A7-A-B9-IA7-AC8-A13-C6-A2(13-B6-B)13-A5-2A13-AB4-BA13-AB4-2A13-2A4-DA13-2A3-D2A13-3A2-HA15-2A2-J17-A-JA17-A2JA17-AJHA17-A2H19-HD19-DA19-2A19-AB19-2B19-B2A17-2ABA17-AB2A17-4A17-2ABA17-ABKA17-AKDA17-2ADFD15-2A4-D13-A7-G11-A8-G-A7-A-A9-2A7-AC8-B2(13-C6-A)13-A5-2(2A13-2A4-)2A13-AB4-BA13-2A4-BA13-AB3-GA15-AB2-H17-A2-J17-A-JA17-A2JA17-AJGA17-AGP19-PF19-FB19-BA2(19-2A)19-3A17-4A17-2ABA17-A2BA17-AB2A17-2ABA17-AB3A16-2A-3F13-3A4-A13-B7-B2-A5-A2-A9-B-A5-A-B10-B2A5-2AC8-A13-N6-A13-C5-2A13-AC4(4-2A13-2A)4-OA13-2A3-HA15-AB2-D17-B2-G17-A2-H17-A-GA17-A2GA17-AGH19-HD19-DL19-LO19-OA19-2A19-2BA17-AB2A2(17-4A)17-2ABA17-AB2A17-2AB2A15-3A-3A13-2AB4-2A11-2A7-2A2-A3-A2-2A9-A-A5-A-A11-2A5-AN8-BA2(13-AC4-2A)13-AC4-VA13-AC4-BA13-AB4-2A13-2A4-BA13-2A4-2A13-2A3-3A13-3A2-HA15-AB2-D17-A2-I17-B2-I17-A-FA17-AF2A17-2AT19-TB19-BA2(19-2A)19-ABA17-AB2A17-2ABA17-AB2A17-5A15-6A15-2AB-AB2A11-3AB4-I4A5-5A7-M4A3-4AB9-SJ2A3-3AD10-SMAG3-2AGF12-G5-C9-CA13-AC5-3(2A11-AC6-)2A11-2A6-2A11-2A5-3A11-2AB4-3A11-3A4-3A11-2AK4-3A11-3A3-F2A13-3A2-3A13-3A2-2A15-2A2-FA15-2A-2A17-4A17-3A19-AB19-BA19-AB19-B2A17-2AK2A15-6A15-3AC3A13-3A2B6A7-7A-BAD5A3-5AB2A4-D5A3-5AB7-HJ3A3-3AIA9-JIAD3-BAHD12-MH3-2AG13-P5-B31-2A11-AC6-DA11-AE6-2A11-AB6-BA11-AQ6-2A11-AN6-2A11-AE6-BA11-2A6-2A11-2A5-3A11-2A5-AZA11-AZ5-B2A11-2A4-E3A11-2A-Q2-E2A13-2AI2-EA15-AF-EA17-A2CA17-AC2A2(17-4A)17-2ABA17-AB2A17-5A15-7A13-5AB4A9-4AFA2-7A3-6AB5-6A3-5ABA6-GI3A3-5A10-J2G3-2AI13-M5-A74-DA9-AE8-BA9-AE8-2A9-2A2(8-2A9-AQ)8-2A9-AN8-2A9-2A7-B2A9-ABA6-3A9-2AB6-B2A9-3A6-3A9-3A6-2A11-2E5-EA13-EF3-EA15-EI2-E17-F-NC17-NE2C17-HCBC17-IB2A17-D3A17-HABA17-D2(BA)14-AB2AB4A11-3AFH-B5A6-3ABA2F3-2AKA2BF3-AC3A2B5-D2FIFA3-UCD3A8-IHGD3-CEDB114-DA9-AC8-2A9-AE8-2A9-2A2(8-2A9-AQ)8-2A9-AN8-BA9-2A8-2A9-AB3(8-2A9-2A)7-B2A9-2AE5-2EC11-2AF3-2E15-EF2-EC15-EF2-C18-GIC17-2H2C17-2IBA17-DHDA16-DHGRAB15-2DFAB2A14-BAG-6A7-5AF3-K6A3-4ABAF5-AKA2BF3-5AB8-FIFA3-UCDA12-GD3-CE117-FG7-AE10-2A7-AB10-BA2(7-2A10-2A)7-AB10-CA7-2A10-2E7-BN10-2E7-2A10-AB7-2A9-A2D7-BAB8-AFG7-GBA8-2A9-2A6-2E2A9-2A2E4-EL13-2E3-EL15-EF2-C17-N2-C17-D-EC17-2I-A17-D2-2A15-DH-R3A13-R2DF-B4A9-2(AB)G3-5A2BA-AB6A4-7A3-AC2AB2A6-KA2BFBLBACABA10-IFB3-UCD138-GDI2(AB)CA12-AD5AED12-9A12-6AV2B12-BAB2A2B2A12-CB7A13-NX3ABA14-CF5A14-GF3ABA14-GP3AHA14-DG3ADF12-BFGJ3AIABA8-EC5A-5A2E5-EL13-LE4-C15-E3-CL15-2C2-C17-H2-CA15-HI2-2A15-2D2-3A13-A2D2-4A11-2A2D3-7A3-6AB4-8A-8A5-B5A3-4ABA8-A2BFBLBACAK161-ABA18-AKA2(18-B2A)18-2AB18-B2A18-A2(BA18-D)GH18-2HD18-2JG18-2JH13-CDHGMA-AI3AE7-C2A3-3A3-ALE5-CL6-A6-LE4-EL13-LE3-CL15-ID3-BA13-CH4-KA13-BD3-5A9-2A2DH3-B6A3-5ARD4-8A-5ABAB5-AB13A8-AB3AB2AC2A431-HGM2JGI2A10-CAIHFH2G2F2AE7-EAK2A2HPH3AK2E5-2C3A2FDFDT2A2CNC4-C2(AB)3ABLB2AEC2I4-B4AB3AO2(AB)2CD4-2(3AB)7ABH4-AB5AB3A2B2A2D5-AB3AB2A2B2ABAR7-3(AB)6AB9-BA2B3(AB)A194-
