model
size = 6 30 24, scale = 0.05, origin = -y
material deform = 1, fade = true, lighting = smooth, roughness = 0.3, metalness = 0.6
  colors = A:#EEE
voxels
125-9(A5-)2(A119-10(A5-))A119-A9(4-2A)5-A119-A4-2A7(3-3A)4-2A5-A119-A4-2A3-3A5(2-4A)3-3A4-2A5-A119-A4-2A3-3A2-4A3(-5A)2(2-4A3-3A4-2A21(5-A)4-2A3-3A2-4A-11A-5A)2-4A3-3A4-2A5-A21(4-2A)3-3A2-4A-11A-5A2-4A3-3A4-2A5-A22(3-3A)2-4A-11A-5A2-4A3-3A4-2A5-A23(2-4A)2(-11A-5A2-4A3-3A4-2A5-A23(-5A))-11A-5A2-4A3-3A4-2A5-A23(2-4A)-11A-5A2-4A3-3A4-2A5-A22(3-3A)2-4A-11A-5A2-4A3-3A4-2A5-A21(4-2A)2(3-3A2-4A-11A-5A2-4A3-3A4-2A21(5-A)4-2A)2(3-3A2-4A-11A-5A2-4A3-3A4-2A5-A119-A4-2A)3-3A2-4A3(-5A)2-4A3-3A4-2A5-A119-A4-2A3-3A5(2-4A)3-3A4-2A5-A119-A4-2A7(3-3A)4-2A5-A119-A9(4-2A)5-A
