model
size = 3, scale = 0.05, origin = -y
material deform = 1, fade = true, lighting = smooth, roughness = 0.3, metalness = 0.6
  colors = A:#99F
voxels
4A-5A-A3-A-5A-4A
