model
size = 15 32 29, scale = 0.05, origin = -y
material deform = 1, fade = true, lighting = smooth, roughness = 0.3, metalness = 0.6
  colors = A:#222 B:#43341B C:#9B6E23 D:#D0104C E:#EFBB24
voxels
4-3(7B8-7C8-)7B382-9B2(6-2C5-2C6-2B5-2B)6-2C5-2C6-9B8-2(5A10-)4A12-2A193-2A12-7(4A11-)4A8-10B2(5-2C7-C5-2B7-B)5-2C7-C5-4B2-4B7-2(2A2-3A8-)6A9-6A10-4A87-2A12-2(4A11-)5A3(9-6A)8-8A6(7-3A2-3A)7-8A6-10B2(5-C8-C5-B8-B)5-C8-C5-3B4-3B6-2(2A4-2A7-)2A4-2A8-2A2-3A8-6A10-4A10-6(6A9-)2A2-2A8-3A2-3A7-3A3-3(2A7-2A4-)2A7-A6-2A6-A4(6-2A5-2A)6-2A5-10A5-10B5-CB7-2(C5-B8-B5-C8-)C5-2(2B6-)2(A6-A7-)2A5-A7-2A4-2A8-3(2A2-2A9-)A4-A9-A5(4-2A7-2A)4-2A7-2(A6-)4(2A6-2A5-)2(2A7-A5-)3(A8-A5-)10A5-10B2(5-C8-C5-B8-B)5-C8-C5-2(2B6-)3(A6-A7-)6(2A4-2A7-)2A5-4(A7-A6-)2(2A5-2A6-)2A8(5-A8-A)5-10A5-10B2(5-C8-C5-B8-B)5-C8-C5-2(2B6-)3(A6-A7-)2A5-9(A7-A6-)A2(6-2A)5-2A7-9(A5-A8-)A5-10A5-10B5-2C7-C5-B8-B5-C8-C5-B8-B5-2C7-C5-2(2B6-)2(A6-A7-)2A5-A5(7-2A4-2A)7-2A5-4(A7-A6-)A2(6-2A)5-2A6-2A5-2A7-8(A5-A8-)A5-10A6-9B2(5-2C7-C5-2B7-B)5-2C7-C5-2(2B6-)2(A6-A7-)2A5-A8-A4-2A8-2(2A3-A9-)A4-A9-A6(4-2A7-2A)5-A7-A4(6-2A5-2A)7-5(A5-A8-)A5-10A6-9B2(6-C7-C6-B7-B)5-BC7-C5-2(2B6-)2(A6-A7-)2A5-A8-A4-2A8-3A-2A9-6A9-E4DE3(9-6A)9-EDA2DE9-6A9-2A2-3A7-3A2-3A3(7-2A4-2A)7-2(2A5-)6(2A6-2A5-)10A5-10B2(5-2C7-C5-2B7-B)5-2C7-C5-2(2B6-)2(A6-A7-)2A5-A8-A4-2A8-6A11-3A71-4D2(11-4A)10-6A9-E4DE9-6A9-7A2(7-AEA2-AEA2(7-3A2-3A))7-AEA2-AEA7-8A6-10B2(5-C8-C5-B8-B)5-2C7-C5-2(2B6-)2(A6-A7-)2A5-A8-A4-2A8-3A-2A10-5A130-4D26-4A2(11-4D2(11-4A))11-4D11-4A8-11B2(4-C8-2C4-B8-2B)4-C8-2C4-2B6-3B5-2(A6-A7-)2A5-A8-A4-2A8-ADA-ADA8-E-3D-E174-2(4D41-)4D22-12B2(3-2C9-C3-2B9-B)3-2C9-C3-4B5-3B2(5-2A)6-A2(6-2A)5-2A7-A5-A8-3A-3A10-3A292-12B2(3-C10-C3-B10-B)3-C10-C3-4B5-3B2(5-2A)6-A7-A6-2A5-2A6-2A5-A8-3A-3A9-5A291-13B2(2-C10-2C2-B10-2B)2-C10-2C2-3B7-3B4-2(A7-A6-)A2(6-2A)5-2A7-2A3-2A9-5A290-14B2(-2C11-C-2B11-B)-2C11-C-4B7-3B4-3(A7-2A5-)2A5-2A6-3A3-3A7-E5DE289-14B2(-C12-C-B12-B)-C12-C-4B7-3B3-2A7-2A4-2A8-A2(4-2A7-2A)4-2(3A5-)4A-4A7-7A274-15B2(C12-2CB12-2B)C12-2C3B9-3B-3(2A9-2A2-)2A9-2A3-2A7-2A4-2(3A5-)9A8-5A260-15B2(C13-CB13-B)C13-C2B11-2B-3(A11-A2-)2A9-2A2-2A9-2A3-2A7-2A5-3A3-3A7-2(7A259-15B2(C13-CB13-B)C13-C2B11-2B-4(A11-A2-)2A9-2A3-2A7-2(2A5-)3A6-)7A259-15B2(C13-CB13-B)C13-C2B11-2B-3(A11-A2-)2A10-A2-2A9-2A3-2A7-2(2A5-)2A7-7A259-15B2(2C11-2C2B11-2B)2C11-2C3B9-3B-2A9-2A2-2A10-A2(2-2A9-2A)3-2A8-2A3-3A6-2A5-3A3-3A7-7A260-13B2(2-C11-C2-B11-B)2-C11-C2-2B9-3B2-A9-2A2-2A9-2A3-A9-2A3-2A7-2A4-2A7-2A5-3A3-4A6-8A8-5A261-13B2(2-2C9-2C2-2B9-2B)2-2C9-2C2-3B7-3B3-3(2A7-2A4-)2(3A5-)3A3-3A6-9A8-5A277-11B4-2C7-2C4-B9-B4-C9-C4-B9-B4-2C7-2C4-4B3-4B5-3(3A3-3A6-)9A7-7A9-5A293-9B2(5-3C)2(4-3B5-3B4-3C5-3C)5-9B8-3(5A10-)5A12-2A310-3(7B8-7C8-)7B379-
