model
size = 20 12 31, scale = 0.05, origin = -y
material deform = 1, fade = true, lighting = smooth, roughness = 0.3, metalness = 0.6
  colors = A:#731251 B:#191919 C:#E824A4 D:#FFF E:#FC0
voxels
7-CE4C232-2C6-2C2(10-BC6-CB)10-BC6DCB11-C6DC13-6D130-2C2A6-2A2C6-2B2A6-2A2B7-B2A6-2AB8-B10AB8-2B8A2B9-BC6ACB11-8C15-2B91-C2A10-2AC4-B2A10-2AB5-2(BA10-AB6-)B2A8-2AB7-B2A6-2AB9-B8AB11-3B2A3B15-2B71-CA12-AC4(4-BA12-AB)5-BA10-AB7-BA8-AB9-B8AB11-8B67-CA14-AC3(2-BA14-AB)3-BA12-AB4-BA12-AB5-BA10-AB7-B2A6-2AB9-2B6A2B12-6B48-CA14-AC4(2-BA14-AB)3-BA12-AB4-BA12-AB5-B2A8-2AB7-2B8A2B10-8B46-C2(A16-A2C)A16-AC-2(CA14-AC2-)CA14-AC3-BA12-AB5-BA10-AB7-B3A4-3AB9-3B4A3B13-4B28-D3(A16-A2D)A16-AD-DA14-AD2-CA14-AC3-BA12-AB5-BA10-AB7-B2A6-2AB9-2B6A2B12-6B27-2(D3(A16-A2D)A16-AD-DA14-AD2-CA14-AC3-BA12-AB4-B2A10-2AB5-2B2A6-2A2B8-2B6A2B12-6B16-2C9-)D3(A16-A2D)A16-AD-DA14-AD2-CA14-AC3-BA12-AB5-BA10-AB7-B2A6-2AB9-2B6A2B12-6B27-C2(A16-A2C)A16-AC-2(CA14-AC2-)CA14-AC3-BA12-AB5-BA10-AB7-B3A4-3AB9-3B4A3B13-4B29-CA14-AC4(2-BA14-AB)3-BA12-AB4-BA12-AB5-B2A8-2AB7-2B8A2B10-8B47-CA14-AC3(2-BA14-AB)3-BA12-AB4-BA12-AB5-BA10-AB7-B2A6-2AB9-2B6A2B12-6B48-CA14-AC3-3(BA12-AB4-)BA12-AB5-BA10-AB7-BA8-AB9-B8AB11-8B67-CA14-AC3-B2A10-2AB5-2(BA10-AB6-)B2A8-2AB7-B2A6-2AB9-B8AB11-3B2A3B15-2B70-C3A10-3AC3-3B2A6-2A3B6-B2A6-2AB8-B3A4-3AB8-2B8A2B9-2B6A2B11-8B15-2B90-C5A6-5AC3-5B6A5B7-2B6A2B10-3B4A3B11-8B13-6B128-C16AC3-16B9-6B15-4B169-C16AC3-16B203-C16AC3-2BC3B2(CB)4C2B203-C16AC3-2BC3B2(CB)2(C2B)203-C16AC3-2B4(CB)2(C2B)203-2C14A2C4-4(BC)B4CB205-C14AC5-5(BC)4B205-C14AC5-B5C2(BC)4B205-2C12A2C6-12B207-2C10A2C8-10B209-3C6A3C11-6B213-8C226-
