model
size = 32 32 31, scale = 0.05, origin = -y
material deform = 1, fade = true, lighting = smooth, roughness = 0.3, metalness = 0.6
  colors = A:#555 B:#222 C:#FCFAF2 D:#111 E:#444 F:#FFB11B
voxels
207-2(2C30-2C254-)2C30-2C381-4B2(28-B2CB)28-4B188-4B2(28-B2CB)24-B3-4B3-B20-B10-B18-F2B10-2BF81-FB31-B3-4B24-B3-2(B2CB28-)4B252-4B59-6B24-F-6B-F24-2B2C2B26-2B2C2B24-10B24-6B119-F2-6B2-F20-12B23-2B2C2B26-2B2C2B23-12B23-6B122-6B2-BF22-6B2-B20-5B2C2B2-B23-2B2C2B22-2B2-6B2-2B18-B3-6B3-B17-FB12-BF151-2B29-4B29-2B28-6B24-10B24-2B2C2B26-2B2C2B24-F-6B-F24-6B28-2(2B30-)2B28-2(6B26-)2(2B2C2B26-)6B26-6B28-2(2B30-)2B28-2(6B26-)2B2C5B23-2B2C2B23-12B23-6B28-2B158-2B29-4B29-2(2B28-2(6B26-)2(2B2C2B26-)6B26-6B28-2(2B30-))2B28-2(6B26-)2(2B2C2B26-)6B26-6B28-2B189-4B92-2(4B2(28-B2CB)28-4B188-)4B2(28-B2CB)28-4B252-4B59-2(2(6B26-)2(2B2C2B26-)6B26-6B122-)2(6B26-)2(2B2C2B26-)6B26-6B188-2B29-4B83-5B4-4B4-5B14-2(B4-B2CB4-B18-)B4-4B4-B14-5B12-5B147-4B28-B2CB19-2B7-B2CB7-2B10-2B7-4B7-5(2B10-2B18-)2B10-2B7-4B2(7-2B10-2B7-B2CB)7-2B10-2B7-4B7-3(2B10-2(2B8-))2B10-2B18-2B52-2B24-14A18-14A15-3B14A3B12-3B14A3B11-4B14A4B11-2(20A12-)20A11-4B14A4B11-3B14A3B12-3B2(14A18-)14A15-3B14A3B15-14A14-2B2-14A2-2B7-10(28A4-)28A5-26A7-24A9-2(2B8-)2B46-14A16-18A14-18A13-B18AB12-B18AB11-2B18A2B11-2(20A12-)20A11-2B18A2B11-B18AB12-B2(18A14-)18A13-B18AB13-18A12-2B18A2B6-9(30A2-)30A3-28A4-28A5-26A3(8-2B)10-2B18-2B12-2(18A14-)18A13-B18AB12-B18AB11-2B18A2B11-2(20A12-)20A11-2B18A2B11-B18AB12-B2(18A14-)18A13-B18AB13-18A12-2B18A2B5-288A-30A2-30A3-28A4-28A5-26A3(8-2B)12-2A14-2A13-3A14E3A3(12-20A)11-4(B20AB10-)B20AB11-5(20A12-)20A11-B20AB5-320A-30A2-30A3-28A5-26A8-2(6B2-)6B12-2A14-2A13-3AE12BE3A14(12-20A)11-B20AB6-8(30A2-)30A-64A-30A3-28A5-26A7-4B7-2B7-4B11-2A14-2A13-3AEB10DBE3A10(12-20A)2(11-B20A)2(12-20A)11-B20AB7-8(28A4-)28A3-30A-32A-30A3-28A5-26A8-6B-8E-6B12-2A14-2A13-3AEB10DBE3A10(12-20A)11-B20AB10-B20AB11-20A12-20A11-B20AB11-5(20B12-)20B10-24A7-26A5-28A3-30A-32A-30A3-28A4-B26AB4-6B4-E6BE4-6B9-2A14-2A13-3AEB10DBE3A5(12-20A)11-B20AB10-B20AB11-2(20A12-)20A11-B20AB10-B20AB11-20A12-20A11-B19A2B11-4(B18AB12-)20B12-20B10-24A7-26A5-28A3-30A-32A-30A3-28A5-26A7-7B-EB4DBE-7B11-2A14-2A13-3AEB10DBE3A2(11-B20AB10-B20AB11-2(20A12-)20A)10-2B20A2B8-2B20A2B10-20A12-20A11-B19A2B11-4(B18AB12-)20B12-20B10-24A7-26A5-28A3-30A-32AB30A3B28A2B-2B26A2B3-6B4-EB4DBE4-6B9-2A14-2A13-3AEB10DBE3A2(11-B20AB10-B20AB11-2(20A12-)20A)10-2B20A2B8-2B20A2B10-20A12-20A11-B19A2B11-4(B18AB12-)20B12-20B10-24A7-26A5-28A3-30A-32A-30A3-28A5-26A7-7B-EB4DBE-7B11-2A14-2A13-3AEB10DBE3A2(11-B20AB10-B20AB11-2(20A12-)20A)10-2B20A2B8-2B20A2B10-20A12-20A11-B20AB11-5(20B12-)20B10-24A7-26A5-28A3-30A-32A-30A3-28A4-B26AB4-6B4-E6BE4-6B9-2A14-2A13-3AEB10DBE3A2(11-B20AB10-B20AB11-2(20A12-)20A)10-2B20A2B8-2B20A2B10-20A12-20A11-B20AB7-8(28A4-)28A3-30A-32A-30A3-28A5-26A8-6B-8E-6B12-2A14-2A13-3AE12BE3A11-B20AB10-B20AB11-2(2(20A12-)20A10-2B20A2B8-2B20A2B10-)20A12-20A11-B20AB6-8(30A2-)30A-64A-30A3-28A5-26A7-4B7-2B7-4B11-2A14-2A13-3A14E3A11-B20AB10-B20AB11-2(2(20A12-)20A10-2B20A2B8-2B20A2B10-)20A12-20A11-B20AB5-320A-30A2-30A3-28A5-26A8-2(6B2-)6B12-18A14-18A12-2B18A2B10-2B18A2B12-2(2(18A14-)18A11-3B18A3B8-3B18A3B11-)18A14-18A12-2B18A2B5-288A-30A2-30A3-28A4-28A5-26A3(8-2B)14-14A16-18A12-2B18A2B10-2B18A2B12-2(18A14-)18A11-3B6A6F6A3B8-3B6AF4CF6A3B11-5A2F4C2F2(5A14-5A8C)5A11-3B5A2C4B2C5A2B9-3B5A2C4B2C5A2B12-5A8C5A14-5A8C5A12-2B5A2C4B2C5A2B6-11A2C4B5(2C11A2-11A2CB2AB)2C11A2-8A3F2CB2AB2C3B2(8A2-8AF4CB2AB4CB)8A2-8A6B2A6B8A3-28A4-28A5-26A9-B8-2B9-B10-2B18-2B20-2B24-14A15-3B6A2B6A3B12-3B6A2B6A3B15-2(4A6B4A18-)4A6B4A14-4B4A6B4A4B10-4B4A6B4A4B14-6A2B6A2(18-4A6B4A)15-3B4A6B4A3B12-3B4A6B4A3B15-4A6B4A18-6A2B6A14-2B2-4A6B4A2-2B7-4(11A6B11A4-)13A2B13A5(4-11A6B11A)4-13A2B13A5-12A2B12A7-24A10-B8-2B9-B10-2B18-2B52-2B22-5B3-2B3-5B14-3B5-2B5-3B20-6B26-6B25-3B2C3B18-4B3-6B3-4B12-4B3-6B3-4B21-2B28-6B26-6B20-3B2-3B2C3B2-3B14-3B-10B-3B20-6B28-2B20-2B6-6B7-B10-2B6-6B6-2B10-2B4-4B2C4B4-2B10-2B2-14B2-2B10-2B6-6B6-2B10-2(2B8-)2B10-2B6-6B6-2B10-2B4-10B4-2B10-2B2-6B2C5B3-2B10-2B-16B-2B10-2B5-8B5-3(2B10-2(2B8-))2(2B10-2B18-)2B179-4B28-B2-B28-4B124-4B28-B2-B26-B-4B-B81-2B30-2B7-4B7-2B10-2B5-B-B2-B-B5-2B10-2B4-2B-4B-2B4-3(2B10-2B18-)2B10-2B5-B-4B-B5-2B10-2B3-3B-B2-B-2B4-2B10-2B2-2(4B-)4B2-5(2B10-2B18-)2B30-2B785-B6-B23-2B6-2B196-B783-3B8-3B21-B6-B854-3(B10-B20-)B10-B19-4B6-4B19-B-B6-B-B20-B10-B20-F10-F915-3B8-3B233-
