model
size = 32 32 18, scale = 0.05, origin = -y
material deform = 1, fade = true, lighting = smooth, roughness = 0.3, metalness = 0.6
  colors = A:#222 B:#FFB11B C:#777 D:#444 E:#555 F:#FCFAF2
voxels
353-12(2B30-)2B112-4C26-3D29-3D429-12(2B30-)2B385-2(9A23-)4A2(-A)24-3A28-4A28-3A29-2A27-14(3A29-)3A75-3(D3-2D26-)D3-2D115-3B25-9B23-2(B9A22-)B4A2(-A)22-2B3A27-B4A26-3B2A26-4BA27-3A2B27-3AB28-3A10(30-2A)2(29-3A)3-D66-14B18-14B23-D3-2D25-3D2-2D25-3D29-3D55-3B25-9B23-2(B9A22-)B4A2(-A)22-2B3A27-B4A26-3B2A26-4BA27-3A2B27-3AB28-3A10(30-2A)29-3A2-3B24-3A2-3B29-3B2-3A28-14B18-14B22-8C24-3D2-2D25-3D28-9C23-9C79-2(9A23-)4A2(-A)24-3A28-4A28-3A29-2A27-12(3A29-)3A-A27-3A-A3B11-A12-3A-A3B11-A5-D6-2(A-)A3B2-A-A6-A12-2(A-)A4-2BF7BA3B18-14B19-11C2(23-9C)D22-9C23-2C5E2C332-10(2B30-)2B29-AB2(A-)3B23-5A2(4B15-3B6-4A)3B2-3A11-3B5-2(A-)A4-14B18-14B19-12C21-10C22-10CD20-12C20-3C6E3C327-11(2B30-)2B3(-A)22-2(A-ABA-4A3B6-A10-2B)A-ABA-4A4B5-A12-2(A-)2A2(-A)2-7BA8BC3-2(A-)A9-14BD3-2(A-)A10-12C2D19-10C3D19-10CD20-12C20-2C2E4D2E2C93-9A23-9A24-2(A-)4A29-3A29-4A29-3A30-2A32-11(3A29-)4A2(-A)19-3BA-3A2(-4A3B16-3B5A)-4A4B16-2B6A2(-A)2-17B-2B5A9-15B3-2(A-)A9-D12C19-2(D-10C20-)D12C20-C2E2D2A2D2EC31-2B-B27-9B2(22-9AB)23-2(A-)4AB28-3A2B27-4AB28-2A2B29-A4B27-2B3A28-B3A29-9(2A30-)2A3(-A)22-A-2A3(-A)2-B17-2B4A3(-A)B-B4-9E2-4B4A3(-A)2-B4-9E-2BA2B4A3(-A)4-15BADB5A9-15BED3(-A)9-D12C2-E16-2(D-10C20-)D12C20-CE2D4A2DEC31-2B-B27-9B2(22-9AB)23-2(A-)4AB28-3A2B27-4AB28-2A2B29-A4B27-2B3A28-B3A29-9(2A30-)2A28-A-2A14-7A5-2B4A13-9E2-4B4A10-A2-9E-5B4A10-A13B2E2B5A9-2D12B2E2-2(A-)A9-D12C21-10C22-10C21-12C20-CED6ADEC93-9A23-9A24-2(A-)4A29-3A29-4A29-3A30-2A32-11(3A29-)4A2(-A)19-3BA-4A2(-A)2-B5-2A3-2A4-3B6A2(-A)B-B4-3E3F3E2-4B6A2(-A)2-B-18B6A2(-A)4-15B3-5A9-16B2-2(A-)A9-D12C19-2D10C22-10C21-12C20-CED6ADEC327-11(2B30-)2B3(-A)22-A-ABA-4A3B5-2A3-2A5-2BA-ABA-4A3B4-3E3F3E5-BA-ABA-4A18B3-B2(A-)2A2(-A)2-16B4-2(A-)A9-14B4-2(A-)A9-D12C19-2D10C22-10C21-12C20-CE2D4A2DEC331-10(2B30-)2B29-ABA-A28-4A3B5-2A3-2A4-3B6-4A3B4-3E3F3E3-3B6-4A18BD3B5-2(A-)A2-16BD17-14B2D16-D12C-D17-2D10C22-10C21-12C20-C2E2D2A2D2EC78-2(9A23-)4A2(-A)24-3A28-4A28-3A29-2A27-12(3A29-)3A-A-3B23-5A4B4-7A13-4A4B3-9E4-D7-4A3B-14BD8-2(A-)A4-14BD17-14B2D17-12C2D19-10C2D20-10C21-12C20-2C2E4D2E2C17-3B25-9B23-2(B9A22-)B4A2(-A)22-2B3A27-B4A26-3B2A26-4BA27-3A2B27-3AB28-3A10(30-2A)-A27-3A-A3B24-3A-A3B4-9E11-2(A-)A3B-14B9-2(A-)A4-2(14B18-)B12CD18-2B-8C-2D21-8C24-10C20-3C6E3C17-3B25-9B23-2(B9A22-)B4A2(-A)22-2B3A27-B4A26-3B2A26-4BA27-3A2B27-3AB28-3A10(30-2A)29-3A2-3B24-3A2-3B29-3B2-3(13B19-)B10C21-B65-9C22-10C79-2(9A23-)4A2(-A)24-3A28-4A28-3A29-2A27-14(3A29-)3A3-D36-11B21-12B20-12B26-3D140-
