model
size = 24 32 14, scale = 0.05, origin = -y
material deform = 1, fade = true, lighting = smooth, roughness = 0.3, metalness = 0.6
  colors = A:#2EA9DF B:#E3916E C:#F7D94C D:#FFFFFB E:#FCFAF2 F:#111 G:#E87A90 H:#EEE I:#CB1B45 J:#00AA90 K:#E9CD4C L:#90B44B
voxels
701-14B658-14B754-14B767-B10-14B754-14B130-4(2A2C6A2C2A10-)2A2C2A2(DA)2(2C2A10-2A2CA3D2A)2C2A10-2A2CAD2ADA2(2C2A10-2A2C6A)2C2A10-2A2C2AD3A2C2A10-2A2C2A3DA2C2A10-2A2CADA2DA2C2A10-2A2C3AD2A2C2A10-2A2C6A2C2A10-2A2C2A2(DA)2C2A10-2A2CA3D2A2C2A10-2A2CA2D3A2C2A10-2A2C2A3DA2(2C2A10-2A2C6A)2C2A10-2A2C3A2DA2C2A10-2A2C2A2D2A2C2A10-2A2CAD2ADA2C2A10-2A2C3AD2A2C2A10-2A2C6A2C2A10-14A10-14B23-B23-2B2-2B19-4B30-2A2C6A2C2A3(10-H12-A10-F12-A)10-H7(12-A10-A)2(12-D10-A)2(12-F2(10-A12-D)10-A)3-F8-D10-A3-F8-F10-A3-2F7-D10-A4-F7-A10-A9-2G-A9-B2-E10-B9-B13-B8-B14-2(2B2-)B16-4B-2B27-2A2C6A2C2A3(10-H12-A10-F12-A)10-H7(12-A10-A)2(12-D10-A12-F10-A)2(12-D10-A)2(12-F10-A)3I9-2(D10-A12-)D10-A3-3J6-A10-A8-3G-A9-B-3E3-K2-2G-B9-B2-E10-B8-B14-2(2B2-)B16-4B-2B27-2A2C6A2C2A3(10-H12-A10-F12-A)10-H5(12-A10-A)8-2L2-2(A10-A12-)D2(10-A12-F)10-A12-D10-A12-F3(10-A12-D)10-A3I9-D10-A-I10-F10-A12-D10-A3-3J6-A10-A4-J3-3G-A9-B2-E3-3K-2G-B9-B7-K5-B8-B14-2(2B2-)B16-4B-2B27-2A2C6A2C2A3(10-H12-A10-F12-A)10-H4(12-A10-A)8-2L2-A10-A9-L2-2(A10-A12-)6(D10-A12-)F10-A2-I9-D10-A3I9-2(D10-A10-2G)D10-A3-3J4-2GA10-A8-4GA9-B7-K5-B8-2B13-B7-2B14-2B2-2B-2B16-4B-2B27-4(2A2C6A2C2A10-)2A2CA4EA2C2A10-2A2CA2EAEA2C2A10-2A2C2(AE)2A2C2A10-2A2C6A2C2A10-2A2C4AEA2C2A10-2A2CAE2AEA2C2A10-2A2C2A2E2A2C2A10-2A2C6A2C2A10-2A2CAEA2EA2(2C2A10-2A2C2A2E2A)2C2A10-2A2C4AEA2C2A10-2A2C6A2C2A10-2A2CAE2AEA2C2A10-2A2C3AE2A2C2A10-2A2C2A2(EA)2C2A10-2A2CA2E3A2(2C2A10-2A2C6A)2C2A10-2A2C2A3EA2C2A10-2A2C2(AE)2A2(2C2A10-2A2C6A)2C2A10-14B23-B23-2B2-2B19-4B678-2(14B754-)14B10-14B77-
