model
size = 18 31 6, scale = 0.05, origin = -y
material deform = 1, fade = true, lighting = smooth, roughness = 0.3, metalness = 0.6
  colors = A:#FBE251 B:#E16B8C C:#2EA9DF D:#FCFAF2 E:#E9A368 F:#E9CD4C
voxels
278-4B12-2B4-B9-2B2(7-B)4-3B2-B7-B2-2B3-3(B2-B5-)2(B2-)2B2(2-B)4-2(B2-)2B2(2-B)5-B2-B3-B2-B-B5-B2-B3-2(B2-)B5-B2-3B3-B2-B5-B6-2B2-B7-B3-2B3-B9-3B4-B15-2B12-4B267-4B12-2B4-B9-2B2(7-B)4-3B2-B7-B2-2B3-3(B2-B5-)2(B2-)2B2(2-B)4-2(B2-)2B2(2-B)5-B2-B3-B2-B-B5-B2-B3-2(B2-)B5-B2-3B3-B2-B5-B6-2B2-B7-B3-2B3-B9-3B4-B15-2B12-4B231-A16-4A12-3A4CA9-2A2C2D2ACA7-A2C7ACA6-C4A3C4A5-C3A2C2DAC2ACA3-AC2AC6AC2ACA2-C2AC3A2C2(2AC)A2-2(C2A)C2DC2ACADA2-4(C2A)CADA2-A2(C2A)2CAC2ACDA2-AC2AC5AC2ACAF3-AC2A2(C3A)C2A4-C3A3C3AC2A6-C6A2C2A8-C3A2C3A10-3C4A12-5A32-7(2E16-)4(2E15-A)2E13-3A2D3A9-4A2D4A7-5A2D5A5-6A2D6A3-7A2D7A2-7A2D7A-8A2(2D16A)2D5AD17AD38A-5A-4A-5A2-16A3-14A5-12A7-10A9-8A12-4A15-9(2E16-)2(EA16-)EA13-3A2D3A9-4A2D4A7-5A2D5A5-6A2D6A3-7A2D7A2-7A2D7A-8A2(2D16A)2D5AD17AD38A-5A-4A-5A2-16A3-14A5-12A7-10A9-8A12-4A213-A16-4A12-3A4CA9-2A2C2D2ACA7-A2C7ACA6-C4A3C4A5-C3A2C2DAC2ACA3-AC2AC6AC2ACA2-C2AC3A2C2(2AC)A2-2(C2A)C2DC2ACADA2-4(C2A)CADA2-A2(C2A)2CAC2ACDA2-AC2AC5AC2ACAF3-AC2A2(C3A)C2A4-C3A3C3AC2A6-C6A2C2A8-C3A2C3A10-3C4A12-5A24-
