model
size = 31 32 17, scale = 0.05, origin = -y
material deform = 1, fade = true, lighting = smooth, roughness = 0.3, metalness = 0.6
  colors = A:#E00 B:#D00 C:#B00 D:#800 E:#A00 F:#700 G:#400 H:#500 I:#200 J:#900
voxels
8-12(15A16-)15A17-7(13A18-)13A17-15A14-2(19A12-)19A13-17A15-15A16-15A18-11A20-11A21-9A49-3(B15-B14-)11(17B14-)17B15-4(15B16-)15B11-4B-15B-4B3(6-25B)7-23B8-23B9-21B12-17B15-15B17-13B19-11B22-7B18-9(C17-C12-)3(2C15-2C12-)2C15-2C13-5(C15-C14-)2(C15-)C13-C10-C5-C13-C5-2(C4-)2C13-2C2(4-C)25-C4-2C23-2C4-3C21-3C5-3C19-3C6-4C17-4C7-4C16-3C10-2C15-2C14-2C11-2C17-2C9-2C20-C7-C16-8(E19-E10-)E19-E11-5(E17-E12-)E17-E13-4(E15-E14-)E15-E8-E5-E15-E5-2(E2-E27-)E2-2E25-2E3-2E23-2E4-3E21-3E4-4E19-4E5-4E17-4E7-4E15-4E11-2(E15-)E13-E17-2E9-2E14-9(D19-D10-)2(2D17-2D10-)2D17-2D11-2(D17-D12-)D17-D13-4(D15-D14-)D15-D8-D5-D15-D5-2(D2-D27-)D2-D26-2D2-2D25-2D2-3D23-3D3-3D21-3D4-4D19-4D5-4D17-4D8-3D15-3D2(13-D)17-D11-D14-14(F19-F10-)F19-F11-3(F17-F12-)F17-F13-F15-F7-F6-F15-F6-2F2(28-3F)28-2F-F26-2F2-2F25-2F2-3F23-3F3-3F21-3F5-4F17-4F7-4F15-4F11-2F14-F16-F12-F13-15(H19-H10-)2H17-2H10-2H17-2H11-2(H17-H12-)2H15-2H2(6-H)15-H6-2H3(28-3H)28-2H-H26-2H2-2H25-2H3-2H23-2H4-3H21-3H6-2H19-2H10-2H15-2H14-2(H13-)15(G19-G10-)2(2G17-2G10-)2G17-2G11-G17-G12-2G15-2G6-G5-2G15-2G5-2G4(28-3G)28-2G-G26-2G2-2G25-2G3-2G23-2G5-3G19-3G9-2G15-2G14-2(G13-)15(I19-I10-)4(2I17-2I10-)3I15-3I5-I5-2I15-2I5-2I4(28-3I)28-2I-I26-2I2-2I25-2I3-2I23-2I5-3I19-3I9-2I15-2I14-2(I13-)15(G19-G10-)2(2G17-2G10-)2G17-2G11-G17-G12-2G15-2G6-G5-2G15-2G5-2G3(28-3G)28-2G-G26-2G2-2G25-2G3-2G23-2G4-3G21-3G6-2G19-2G10-2G15-2G14-2(G13-)15(H19-H10-)2H17-2H10-2H17-2H11-2(H17-H12-)2H15-2H2(6-H)15-H6-2H2(28-3H)28-2H-H26-2H2-2H25-2H2-3H23-3H3-3H21-3H5-3H19-3H7-4H15-4H11-2(H15-)2(H13-)14(F19-F10-)F19-F11-3(F17-F12-)F17-F13-F15-F8-F5-F15-F5-3(F2-F27-)F2-2F25-2F2-3F23-3F3-3F21-3F4-4F19-4F5-4F17-4F8-3F15-3F2(13-F)17-2F9-2F14-9(D19-D10-)2(2D17-2D10-)2D17-2D11-3(D17-D12-)2D15-2D12-2D15-2D13-2(D15-D14-)D15-D8-D5-D15-D5-2(D2-D27-)D2-2D25-2D3-2D23-2D4-3D21-3D4-4D19-4D5-4D17-4D7-4D15-4D11-2D13-2D16-3D7-3D45-8(E19-E10-)E19-E11-5(E17-E12-)E17-E13-4(E15-E14-)E15-E9-E4-E15-2(E4-)2(E25-E4-)2E23-2E4-3E21-3E5-3E19-3E6-4E17-4E7-4E15-4E10-2E15-2E14-5E5-5E76-9(C17-C12-)3(2C15-2C12-)2C15-2C13-2(C15-C14-)3(2C13-2C14-)2C13-2C15-C13-C11-3C2-C13-C2-3(3C6-3C19-)3C7-2C19-2C8-4C15-4C9-3C15-3C12-2(C15-)6C3-6C108-4(2B13-2B14-)2B5-J-5J-2B14-2B2(2-J)-J3-J-2B14-2B2(2-J)-J5-2B14-2B2-9J2-2B14-2B2(2-J)-J5-2B14-2B2-4J-J5-2B14-2B13-2B14-2B2-8J3-2B14-2B13-2B14-3B11-3B14-3B-9J-3B15-2(2B5-J5-2B16-)2B2-7J2-2B16-2B5-J5-2B16-2B2(2-J)5-2B14-4B2-7J2-4B11-4B3-J2-J6-4B2(10-3B15-3B)11-2B15-2B13-2B5-2B6-2B15-15B16-7B-7B141-4(13A18-)5A-A5-A18-2(2A-)A-3A-A18-2(2A-)A-5A18-2A9-2A18-2(2A-)A-5A18-2A4-A-5A18-13A18-2A8-3A2(18-13A)18-2A9-2A2(18-6A-6A)18-3A7-3A18-6A-6A18-3A-2A-6A18-3A7-3A17-4A-2A-7A15-17A14-17A15-15A17-13A195-
