model
size = 23, scale = 0.05, origin = -y
material deform = 1, fade = true, lighting = smooth, roughness = 0.3, metalness = 0.6
  colors = A:#400 B:#500 C:#700 D:#800 E:#A00 F:#B00 G:#D00 H:#E00 I:#200 J:#F39
voxels
8-7I520-2I7A2I14-7A495-2I2A7B2A2I10-11A14-7B471-2IA3B5C3BA2I8-13A11-11B15-5C448-2IA2B2C5D2C2BA2I6-15A9-13B12-9C16-5D425-IAB2C2D5E2D2CBAI5-17A7-15B9-13C12-9D16-5E401-IA2BCD2E5F2EDC2BAI3-19A5-17B8-13C11-11D13-9E16-5F378-IABCD2EF5GF2EDCBAI3-19A5-17B7-15C9-13D11-11E14-7F17-5G354-IA2BCDEF7HFEDC2BAI-21A3-19B6-15C9-13D11-11E13-9F15-7G16-7H330-IABCDEFG7HGFEDCBAI-21A3-19B5-17C7-15D9-13E11-11F13-9G15-H5-H330-IABCDEFG7HGFEDCBAI-21A3-19B5-17C7-15D9-13E11-11F13-9G15-H-3H-H330-IABCDEFG7HGFEDCBAI-10AJ10A3-9BC9B5-8CD8C7-7DE7D9-6EF6E11-5FG5F13-4GH4G15-3(H-)H19-2(I22-)2(A22-)2(B22-)C17-11C17-D19-7E16-F5-F16-7G16-H5-H16-7H8-IABCDEFG7HGFEDCBAI-21A3-19B5-17C7-15D9-13E11-11F13-9G15-H-3H-H330-IABCDEFG7HGFEDCBAI-21A3-19B5-17C7-15D9-13E11-11F13-9G15-H5-H330-IA2BCDEF7HFEDC2BAI-21A3-19B6-15C9-13D11-11E13-9F15-7G16-7H331-IABCD2EF5GF2EDCBAI3-19A5-17B7-15C9-13D11-11E14-7F17-5G355-IA2BCD2E5F2EDC2BAI3-19A5-17B8-13C11-11D13-9E16-5F379-IAB2C2D5E2D2CBAI5-17A7-15B9-13C12-9D16-5E402-2IA2B2C5D2C2BA2I6-15A9-13B12-9C16-5D426-2IA3B5C3BA2I8-13A11-11B15-5C450-2I2A7B2A2I10-11A14-7B474-2I7A2I14-7A499-7I514-
