model
size = 27 27 32, scale = 0.05, origin = -y
material deform = 1, fade = true, lighting = smooth, roughness = 0.3, metalness = 0.6
  colors = A:#CC6
voxels
498-2A24-4A22-6A21-6A22-4A24-2A375-6A20-8A5(18-9A)19-7A21-5A428-3A22-8A17-11A16-12A14-5A4-4A14-4A6-3(4A13-3A7-)4A13-4A5-5A13-5A3-5A15-11A17-10A18-7A344-8A17-12A14-6A-7A13-4A6-4A12-3A9-4A11-2(3A10-)3A11-3A3(10-3A12-2A)10-2(3A11-)3A9-4A11-4A8-3A13-4A5-5A13-13A16-10A19-6A237-6A19-10A16-12A14-4A6-4A12-3A10-2(2A12-)2A10-3A12-3A2(9-2A14-2A)9-A2(15-2A8-2A)15-2A8-3A14-2A8-3A13-3A9-3A12-3A9-2(3A11-)4A8-4A12-5A4-5A14-12A17-7A183-5A20-10A16-4A4-4A14-3A8-3A12-3A10-2(2A12-)2A10-2A13-3A9-2A14-2A9-A2(16-A8-2A)16-2A7-2A16-2A7-A17-2A6-2A17-2A6-3A16-2A7-2A15-3A7-3A14-2A9-3A12-3A9-4A10-3A11-5A5-5A14-12A18-6A130-3A21-10A16-4A3-5A14-3A8-2A13-3A10-2(2A12-)2A10-2A13-3A9-2A14-2A8-2(2A16-2A7-)2A16-2A6-2A17-2A6-2A18-A6-3(2A18-2A5-)2A17-3A5-3A16-2A7-2A15-3A7-3A13-3A9-4A10-3A11-6A4-5A14-11A125-9A17-5A-6A14-3A8-2A14-2A10-2A12-2A11-3A10-2A13-3A8-3A14-2A8-2A16-2A7-2A16-2A6-2A18-A6-2(2A18-2A5-)A2(19-2A4-2A)2(20-A4-2A)19-2A4-3A18-2A5-2A17-3A5-3A15-3A7-3A13-3A2(9-4A)11-15A17-6A74-7A18-12A14-3A7-3A14-2A10-2A12-2A11-3A10-3A12-3A9-2A14-2A8-2A16-2A7-A17-2A6-2(2A18-2A5-)A19-2A4-2A20-A4-2(2A20-2A3-)3(A21-2A3-)2A20-2A3-2A19-2A5-2A17-3A5-3A15-3A7-3A13-3A9-7A4-6A14-10A70-11A15-4A5-4A14-2A10-2A12-2A11-3A10-3A12-2A10-2A14-2A8-2A16-2A7-2A16-2A6-2A18-2A5-2A18-2A4-2A20-A4-2(2A20-2A3-)A21-2A2(2-2A22-A)3-A2(22-A2-2A)21-2A3-2A20-2A3-2A19-2A5-2A17-3A6-2A15-3A2(8-5A)11-13A45-6A18-12A14-2A9-3A12-2A11-3A10-3A12-2A10-2A14-2A8-2A15-2A8-2A16-2A6-2A18-A6-2A18-2A4-2A20-A4-2A20-2A3-A21-2A7(2-2A22-A)2-2A21-2A3-2A20-2A3-3A18-2A5-3A16-2A7-4A11-4A10-14A43-9A16-5A4-4A13-3A10-2(2A12-)2A10-2A14-2A9-A15-2A8-2A16-2A7-A17-2A6-2A18-2A5-A19-2A4-2A20-2A3-A21-2A2(2-2A22-A)2-3(A23-2A-)3(A23-A2-)2A22-A2-2A21-2A3-2A19-3A4-2A17-3A6-3A12-5A8-16A42-10A15-3A7-4A12-2A11-3A11-A13-2A10-2A14-2A9-A16-A8-2A16-2A6-2A18-A6-2A18-2A4-2A20-A4-2A20-2A3-A22-A2-2A22-A2-2(A23-2A-)A24-A3(-A23-2A)-2(A23-A2-)2A22-A3-2A20-2A3-3A18-2A5-3A14-4A8-17A17-3A21-10A15-10A-3A12-2A3-5A4-2A11-A4-5A5-A10-2A4-5A5-2A9-A5-5A6-A8-3A3-7A3-4A7-20A6-22A4-23A4-2A7-6A7-2A3-A8-5A9-A2-2A9-4A9-A2-A10-4A9-4A11-A12-2(3A24-)A-A24-A3(-A23-2A)-2A22-A2-2A21-2A3-2A19-2A5-3A15-4A6-9A-9A14-7A26-3A15-5A3-6A12-2A-3A3-3A-3A11-A2-3A3-3A2-2A10-2A2-3A3-4A2-2A2(9-7A3-8A)10-5A5-5A36-2(9A4-)10A3-11A3-2A5-4A2-4A5-2A2-2A6-4A2-3A7-A2-A7-9A7-4A8-8A8-2A9-7A9-3A10-3A11-2(3A24-)A-A24-A2(-A23-2A)-2A21-2A3-2A20-A5-2A17-3A6-7A5-7A12-10A43-3A7-3A13-4A7-4A12-2(4A7-5A11-)4A8-4A116-7A8-7A4-8A7-9A2-2A5-2A7-3A5-A2-A6-3A6-2A6-4A7-2A5-3A7-2A8-4A-5A7-2A9-8A8-2A10-5A10-3(3A24-)A-A23-2A-2A21-2A3-2A20-2A3-3A17-3A6-5A8-6A12-11A307-7A10-7A2-2A4-2A9-2A4-2A2-A6-2A8-2A5-4A6-2A8-2A5-3A7-3A6-2A7-2A8-3A3-4A7-2A9-8A8-2A11-3A11-2A25-3A24-A-A23-2A-2A21-2A2-2A21-2A3-3A17-3A6-5A9-5A12-12A280-5A12-3A6-6A11-6A3-2A4-2A10-2A3-2A2-2A4-2A10-A5-A-2A5-2A9-2A5-3A7-2A8-2A6-2A7-3A6-2A7-2A8-4A-4A8-2A10-6A9-3A24-3A23-2A-A23-2A-2A21-2A2-2A21-A4-3A17-3A6-5A10-4A12-12A254-3A13-3A7-5A12-4A5-2A3-A12-A-3A2(4-A)11-2A3-2A2-2A4-A11-2A3-2A-2A5-2A10-A5-4A5-2A9-2A5-3A7-2A7-3A6-2A8-3A4-3A7-3A8-8A8-3A23-2A-A23-2A-2A22-A2-2A21-2A3-2A19-2A4-3A17-3A6-5A10-4A12-13A200-2A14-2A2(8-3A13-3A)7-2A-2A12-A-2A5-2A2-2A12-A2-2A4-2A2-2A12-A2-2A3-2A4-A11-2A3-2A2-A5-A11-2A4-A-2A5-2A10-A5-4A6-2A8-2A5-4A6-3A6-2A6-4A8-8A7-2A-A10-3A10-2A-A23-A2-2A21-2A3-2A20-2A3-2A19-2A5-3A16-2A7-6A10-3A12-13A173-3A2(12-3A8-4A)12-3A8-A-2A12-A-A7-2A-2A12-A-2A6-A2-2A12-A-2A5-2A2-2A12-A2-2A3-2A4-A12-A3-2A2-2A4-A11-2A3-2A2-A5-2A10-A5-A-2A6-A9-2A5-A-2A6-3A6-2A6-A2-A8-8A7-A2-A10-3A10-A2(2-2A21-2A)3-2A19-2A5-2A18-2A5-3A16-2A8-5A9-4A13-12A146-3A13-A10-3A12-3A2(8-2A-A12-A-A)8-A2(2-A12-A-A7-2A)2-A12-A-2A5-2A3-A12-A-3A4-2A3-A11-2A2-2A3-2A4-A11-2A2-3A2-2A4-2A9-2A4-2A2-2A5-2A8-2A4-2A2-A6-2(3A5-)2A2-A8-8A6-2A2-2A10-2A9-2A2-2A21-2A3-A21-A4-2A19-2A5-2A17-2A7-2A15-3A8-5A9-4A13-11A147-3A24-A-A12-3A9-A2(-A12-3A8-2A)-A12-3A8-A2(2-A12-3A7-2A)2-A11-5A5-3A2-A11-2A-2A5-2A3-2A10-A2-3A4-2A3-2A9-2(2A3-)2A5-2A7-2A5-A3-2A6-3A4-3A5-A3-2A7-7A7-A3-2A21-A4-A21-A4-2A19-2A4-2A18-3A5-2A17-2A7-2A15-2A9-5A8-4A14-11A121-2A3(24-3A)12-2A10-3A12-3(2A9-2A-2A11-)2A9-2A-2A10-4A7-2A2-2A9-2A-2A7-2A2-2A9-2A-3A5-3A3-2A7-3A2-3A4-2A4-3A5-3A2(4-2A)5-9A5-2A4-A8-6A6-2(2A4-2A19-)2A4-2A18-3A5-2A17-2A6-3A15-2A8-4A12-3A9-7A4-6A14-10A149-2(2A25-)2A24-3A24-2(4A23-)4A22-5A10-3A9-2A2-A9-4A9-2A2-2A8-5A7-2A3-3A6-2A-4A6-2A4-4A-5A2-2(3A5-)7A2(5-2A)18-2A5-2A18-2(2A6-2A17-)2A6-2A16-2A8-3A13-3A9-5A9-3A12-14A17-6A313-2A24-4A23-4A10-2A10-6A8-3A10-2A-15A9-2A4-13A7-2A7-3A5-3A3(7-2A16-2A)8-2A15-2A8-2A14-3A8-4A11-3A11-5A6-4A15-11A417-3A24-13A-2A10-4A9-4A10-4(2A14-2A9-)3A13-2A10-3A11-3A10-4A9-3A13-5A4-4A17-8A448-12A13-4A8-4A2(11-3A11-2A)11-3A12-A2(11-3A11-2A)12-3A9-3A13-3A7-3A15-5A2-4A19-6A450-11A15-3A8-2A13-3A9-2A13-3A10-2A2(13-2A9-3A)13-2A9-2A14-3A7-3A15-3A5-3A17-9A21-4A452-10A16-2A7-2A16-2A8-2A2(15-2A7-3A)15-2A7-2A16-2A6-3A16-3A5-3A17-3A3-3A19-7A478-9A18-10A2(16-2A6-3A)17-A6-2A18-2A5-2A18-2A4-3A18-3A3-2A20-7A21-5A506-2(8A19-)2(2A4-2A19-)3A2-3A20-3A-3A20-6A22-5A92-
