model
size = 22 31 19, scale = 0.05, origin = -y
material deform = 1, fade = true, lighting = smooth, roughness = 0.3, metalness = 0.6
  colors = A:#222 B:#444 C:#AAA D:#555
voxels
4-7(3AB6A-3A8-)17(14A8-)14A9-12A118-7(A3-B6-B3-A6-)17(A14-A6-)A13-2A6-2A12-2A7-14A94-23(A16-A4-)2A15-2(A4-A16-)A4-2A13-3A5-16A71-23(A16-A4-)2A15-2(A4-A16-)A4-A14-3A4-A16-A5-16A11-6A14-10A7-13(A18-A2-)10(2A16-2A2-)A-A15-2(2A2-A17-)2A2-A15-2A-A2-A15-A2-A3-A16-A5-5A6-5A8-2(2(3A6-)12(A18-A2-)11(2A16-2A2-)A-A15-2(2A2-A17-)2A2-A15-2A-A2-A15-2(A2-)A18-A3-3A2-A6-A2-3A7-)2(3A6-3A5-A11(20-2A)4(-A16-A-2A)-A16-2(A-)7(2A16-2A2-)A-A15-2(2A2-A17-)2A2-A15-2A-A2-A15-2(A2-)A18-A3-3A2-A6-A2-3A7-)3A6-3A5-A11(20-2A)4(-A16-A-2A)-A16-2(A-)7(2A16-2A2-)A-A15-2A2-A17-2A2-A15-2A-A2-2(A15-2(A2-))A18-A3-3A2-A6-A2-3A7-3A6-3A5-A12(20-2A)3(-A16-A-2A)-A16-2(A-)7(2A16-2A2-)A-A15-2A2-A17-2A2-A15-2A-A2-2(A15-2(A2-))A18-A3-3A2-A6-A2-3A7-2(3A6-)12(A18-A2-)11(2A16-2A2-)A-A15-2A2-A17-2A2-A15-2A-A2-A15-2(A2-)A18-A2-4A2-A6-A2-4A2(6-3A)10-2(3A6-)13(A18-A2-)10(2A16-2A2-)A-A15-2A2-A17-2A2-A15-2A-A2-A15-2(A2-)A18-A3-3A2-A6-A2-3A7-3A6-3A10-2(3A6-)5(A18-A2-)B18-B10(2-A18-A)7(2-2A16-2A)2-A-A15-2A2-A17-2A2-A15-2A-A2-A18-A3-3A2-A6-A2-3A7-3A6-3A10-3A6-3A29-5(A16-A4-)B16-B14(4-A16-A)4-A16-B2(4-A16-A)4-2A15-A4-A16-A4-A14-3A4-3A2-A6-A2-3A7-3A6-3A10-3A6-3A51-5(A16-A4-)B16-B14(4-A16-A)4-A16-B2(4-A16-A)4-A15-2A4-A14-3A5-2A2-A6-A2-2A8-3A6-3A10-3A6-3A74-2A11-3A4(6-2A12-2A)6-BA12-AB14(6-2A12-2A)6-2A12-2B3(6-2A12-2A)6-2A2-A6-A2-2A8-3A6-3A10-3A6-3A98-4(3A6-3A10-)2(3A6-BDA3(10-3A6-3A)10-)9(3A6-3A10-)4(A-A6-A-A10-)3A6-3A210-C87-C241-A6-A14-A6-A13-2A6-2A11-2(3A6-3A10-)3A6-3A137-
