model
size = 9 27 9, scale = 0.05, origin = -y
material deform = 1, fade = true, lighting = smooth, roughness = 0.3, metalness = 0.6
  colors = A:#777 B:#000 C:#FFF D:#222 E:#555 F:#FED901 G:#FFBA01 H:#FFCF00 I:#FFDF01 J:#FEC300 K:#FFB302 L:#444 M:#070 N:#888 O:#E00
voxels
184-E7-3D5-EAL2A5-LAL7-A62-D8-G7-3G2(6-3J)6-3H6-3C6-CH2(C6-2F)C6-3C6-3F2(6-3I)6-3D6-L2A5-E2ALE3-2D3A2D2-7A2-AE4AL3-NL2AL5-A2E25-K7-3K6-3G5-2DB2D4-2GC2G4-GC2BG2(4-J3BJ)3(4-H3BH)4(4-F3BF)2(4-I3BI)4-DBABD4-E3AL3-7A2-D5AD-9A-E6A2-L6A3-E4A6-L8-K7-KBK5-K3BK4-G3BG4-D3BD4-G3BG3-G2C2BCG2(2-J4BCJ)3(2-H4BCH)4(2-F4BCF)2(2-I4BCI)2-DB3ABD2-E5AE2-6AL-D7ADE7A2E7AL-7A2-E5AE4-EAE6-3K5-2(K3BK4-)G3BG3-D5BD2-G3C2BG2-G2C2BCG2(2-J4BCJ)3(2-H4BCH)4(2-F4BCF)2(2-I4BCI)2-D5AD2-E6A-E8AD7ADE7A2(E8A)E-6AL3-3EAE6-K7-KBK5-K3BK4-G3BG4-D3BD4-G2CBG3-G2C2BCG2(2-J5CJ)2-H5C2(H2-H4BC)H4(2-F4BCF)2(2-I4BCI)2-DB3ABD2-E5AE2-7A-D7AD9AE7AE-E5AE2-L4A2E4-EAE16-K7-3K6-3G5-2DB2D4-2GC2G4-G3CG2(4-J3CJ)4-H3CH4-HCBCH4-HCOCH4-FCBCF4-FCMC2(F4-F3C)F2(4-I3CI)4-DBABD4-5A3-E6A2-D5AD-8AE-E6A2-E5AL3-3ALE6-E44-D8-G7-3G2(6-3J)2(6-3H)6-HDH6-FDF6-FMF2(6-3F)2(6-3I)6-3D6-AEA5-E3AE3-2D3A2D2-7A2-E5AE3-AE2AE5-L2A196-E7-3D5-E3AL5-EAE7-E22-
