model
size = 32 32 14, scale = 0.05, origin = -y
material deform = 1, fade = true, lighting = smooth, roughness = 0.3, metalness = 0.6
  colors = A:#101010 B:#B80000
voxels
494-6A3(23-9A)24-7A25-6A28-3A347-8A21-13A18-17A13-20A11-22A9-10A3-11A7-9A8-9A5-9A11-7A5-8A13-7A3-8A15-7A2-7A17-6A2-6A18-6A-6A19-6A-6A20-12A20-3(11A21-)2(12A20-)6A-5A19-6A2-6A17-7A2-7A15-8A3-7A13-8A4-9A10-8A6-9A8-9A7-10A4-10A9-22A11-20A13-17A17-13A21-8A59-5A25-9A21-13A17-16A15-19A12-21A10-8A2-13A8-7A9-9A6-7A11-8A6-6A13-8A4-7A14-7A4-6A16-6A3-7A16-4(6A3-6A17-)2(6A4-5A17-)6A5-5A15-7A5-6A13-7A6-7A11-8A6-9A8-8A8-10A4-10A8-23A11-20A13-17A17-14A20-10A25-4A187-6A24-10A21-13A17-16A15-18A14-5A8-6A12-5A10-5A11-5A12-4A11-4A14-4A10-4A14-4A9-4A15-4A2(9-4A16-3A)2(9-4A15-4A)9-5A14-4A10-4A13-5A10-2(5A11-)7A7-6A13-8A3-7A16-16A18-12A21-10A24-7A341-13A19-3A-2A4-3A18-15A17-4A7-5A15-4A10-4A13-2(4A12-)A-2A12-4A12-3A14-A-A11-4A14-3A10-2A-A15-4A9-4A15-4A10-4A14-3A12-3A14-A-A12-3A13-4A12-4A11-4A13-5A9-5A14-6A6-5A16-12A-2A18-3A-5A-3A19-13A403-13A19-3A7-3A18-12A-2A17-5A4-7A15-4A9-5A13-2A-2A10-2A-A13-2(4A12-)A-A14-A-A11-4A14-A-A10-5A14-A-2A9-5A14-A-2A11-3A14-A-A12-A-A13-2A-A3(12-4A)11-2A-A14-5A8-2A-2A14-6A6-2A-2A16-3A-8A-2A18-4A6-3A19-13A403-A4B2(3AB)19-4A4-5A19-2A-6A3-2A17-5A3-5A-2A15-2A-2A8-2A-2A14-A-2A10-4A13-2(4A12-)A-2A12-2A-A12-A-A14-A-A10-3A-A14-A-2A9-3A-A14-A-2A11-A-A14-A-A3(12-4A)11-2A-2A13-A-2A10-2A-A14-5A8-2A-2A15-2A-3A4-3A-2A17-14A18-6A2-5A19-13A404-B2AB3ABA-AB19-4A4-5A19-2A-5A3-3A17-2A-2A3-5A-2A15-2A-2A7-3A-2A14-A-2A10-4A13-2A-A2(12-A-2A)12-2A-A12-A-A14-A-A11-2A-A14-A-2A10-2A-A14-A-2A11-A-A13-2A-A2(12-4A)13-A-A11-2A-2A13-A-2A10-A2-A14-2A-2A8-2A-2A15-7A3-3A-2A17-3A-6A-3A18-13A20-2A2-4A2-2A404-BA2B3AB24-3A3-3ABAB19-2A-5A3-3A17-2A-3A-5A2-2A15-2A-2A6-4A-2A14-A-2A9-5A13-2A-2A10-2A-2A12-A-2A12-4A12-A-2A12-2A-A11-2A-A13-2A-2A10-2A-A13-2A-2A11-A-2A12-2A-A12-4A12-A-2A13-A-A11-2A-2A13-4A9-2A-2A14-6A6-3A-2A15-16A18-3A-5A-3A19-12A24-5A-A406-6A25-B3A-2A2(BA)20-2A2-3A3-2ABA17-2A-8A2-3A15-2A-3A4-4A2-A15-A2-2A7-3A-2A13-2A-2A10-2A-A13-2A-A11-2A2(-2A12-A)3(2-A12-A-2A12-A)-2A12-2A-A11-2A-2A13-A-2A10-2A-A14-5A8-2A-2A15-6A4-3A2-A17-2A-8A-3A18-3A7-2A21-10A24-5A411-4A25-B6ABAB21-3A7-2AB18-2A2-6A3-3A15-2A2-9A3-2A14-2A-4A2-6A-2A14-A-4A6-3A-2A13-2A-3A8-3A-2A12-A2-2A10-2(2A-2A12-A2-A11-)2A2-A12-A2-2A9-3A-2A12-2A-2A9-3A-A14-5A6-4A-2A14-2A-4A3-5A-2A14-3A-10A2-2A15-3A2-6A2-3A17-3A8-3A19-11A24-5A413-2A26-3B3A2BA21-AB2A6-A2B18-3A10-3A15-2A4-4A5-2A15-2A3-8A3-2A14-2A2-10A2-2A13-2A2(2-5A)2-A13-A2-5A4-4A2-A13-A2-3A7-3A2-2A12-A2-3A7-3A3-A12-A2-3A7-3A2-2A12-2A2-3A4-4A3-A14-2A-11A2-2A14-2A2-8A4-2A15-2A3-5A4-2A16-2A11-3A17-3A7-3A21-10A24-5A442-8A22-4A4-4A18-5A7-3A16-4A11-2A15-2(2A14-)2A5-4A5-2A13-2A5-6A5-2(A13-2A3-9A4-)2A12-A4-4A-4A2(4-2A12-2A3-9A)4-A14-2A3-6A5-2(2A14-)2A15-2A12-2A17-2A10-2A18-4A6-3A21-9A26-3A444-6A25-9A21-13A17-16A15-3(18A14-)18A13-12A-6A13-6A2-4A-6A13-7A-3A-7A14-6A4-8A14-8A-9A15-16A16-16A17-14A19-12A22-8A236-
