model
size = 22 32 30, scale = 0.05, origin = -y
material deform = 1, fade = true, lighting = smooth, roughness = 0.3, metalness = 0.6
  colors = A:#D9BEB5 B:#30B2C7 C:#72B1CE D:#51AEB7 E:#48B4C5 F:#5CC4D5 G:#A65DC6 H:#9A52AB I:#D8B1B1 J:#EAE0D7 K:#D2B1B0 L:#CE9399 M:#E5D7CA N:#5AA2DD O:#5F5051 P:#C48C99 Q:#D69AA2
voxels
362-DC19-EDCD17-DE2DBC16-EF2DFD16-DFEC2F16-B2DCBF16-2(CB)EF16-F2DF2B17-BCED19-EC242-E702-EC702-F703-C20-BE701-BDE20-CF679-ECD19-BDC20-F657-DBD19-2FC19-2FE284-4A17-6A16-6A15-4(8A14-)8A15-6A192-FCB18-2F-B18-CD2E20-C220-2A18-6A16-4ACA15-A2D2ABCA13-2AFD2A2F2A11-2AD2C2A2CB2A10-2AFBC2AECF2A10-2AC6-C2A11-A7-BA12-AB6-EA13-3A2-3A17-2K171-2BC18-CF-EC17-C3-B18-DB2E175-2A17-8A12-5A2-5A9-4AE4-E4A7-5AD4-B5A6-4A7-5A7-2A10-2A3(8-A12-A)8-2A10-2A9-A9-BA11-3A4-3A15-K2LK170-2CB18-DC-CF17-D3-F17-DE-2E19-B111-2A18-6A14-10A10-3A7-F3A7-3A10-3A6-AF12-DA5-AB14-BA4-A15-EA5-2(A14-A6-)A14-A7-2(A12-A8-)AC10-BA9-3A6-3A13-KLPQLK168-BD2C18-C3-B17-EFDCE17-CB-2E19-B88-4A17-6A14-3AF2-F3A12-AB6-EA9-3A10-3A6-A14-A5-AC14-DA3-AF15-E2A3-A16-A4-2A14-BA5-2(A14-A6-)A13-BA7-A12-A8-AE10-CA9-3A6-3A13-4LPL148-F19-BD-DC17-D3-2D16-B2D2CB16-2FDCEC84-6A15-8A13-4A2-4A11-2AF6-C2(2A9-)C2A6-2A14-2A4-A15-DA2-2AB15-2E2A-AF16-CA2-AC16-FA3-A16-A4-2A14-2A5-A14-A6-A14-A7-2(A12-A8-)4A6-4A11-7A148-2B18-2F2-CD16-DF2-EC16-DC2-EFE15-2E2CDE62-6A15-8A12-4A4-4A10-2A7-D2A9-2A10-2A7-2A12-2A5-A15-2A3-AF16-2A-AD17-DE2AD17-DFA-A17-FA3-2(A16-A4-)A16-A5-A14-I6-I14-I7-I12-I8-2IA8-A2I11-8A146-2CEC18-D3-2C16-C4-D15-B4-2D15-EC2EF43-2A17-3A-F3A13-AB6-CA2(10-2A)7-2AF9-FB2A6-A2E10-FEA6-AF12-BA5-A15-2A3-AB16-2A-AD17-CF2AB17-2BA-A18-A3-2(A16-A4-)A16-A5-I14-I6-I14-I7-I12-I8-2IA8-A2I11-4AK3A17-A108-F19-CE3D17-E4-F15-F5-F15-FD3-FE16-DCFD42-4A15-4A2-4A12-A7-EA2(10-2A)7-AC12-2A2(6-A13-CA)5-A15-DA3-AF16-CA-AB18-D2AE18-DA-A18-A2-A17-CA3-A16-A4-A16-A5-I14-I6-I14-I7-I12-I8-2IA8-A2I11-3A-K3A17-2A106-E2B17-EDE-3B15-C5-BF14-E5-EB14-E2C2-EF17-CBD21-A19-2AC3A14-2AD4-D2A11-A9-FA9-A12-A7-AF12-2A6-A14-A5-2A14-2A4-A15-CA3-A17-BA-AF18-C2AD18-B2AD18-DA-A17-DA3-A16-A4-A16-I5-2(I14-I6-)I14-I7-AJA8-AJA10-JMAK2-KAMJ16-2A85-DB17-BD2(EB)C15-C5-DB14-B6-B14-DF4-FC16-BCDBF19-C21-BC18-FB2-2B14-2B6-BD11-A10-B8-2A12-2A5-AB14-2A4-A15-B2(A4-A16-)A3-2(A18-A2-)A18-A-A20-A-A18-A2-A18-A3-A16-I4-I15-2I5-I14-I6-A14-A7-J2A8-2AJ9-DNJMD2-FM2NJ14-4A83-C2BE16-EBE2-DEF14-D6-B14-C6-C14-2DC3-CD16-CFECF41-DF18-2B-2CB14-DB6-CE11-C10-C8-BF12-CB5-BC14-2B4-C15-2B4-C16-C3-AF16-C3(A2-A18-)A-A20-2AD18-BA-A18-A2-A17-EA3-A15-EA5-A14-A6-A14-A7-J2A8-2AJ9-NOJMD2-CMNOJ14-4A62-CF18-FDEBFB15-CE4-2D14-E6-D14-ED5-B15-BFE2-BE17-B2D42-BC18-CB-BCF14-BC6-BC11-C10-B8-2B12-CB5-DB14-2B4-E15-CE4-B16-D3-E17-CB2(2-A18-A)-AC18-B2A20-2AB18-BA-A18-A2-A18-A3-A15-CA5-A14-A6-A14-A7-J2A8-2AJ9-4JC2-F4J14-4A61-2EDC16-2DE2-DFB14-B6-F14-D7-F13-2BF4-FE15-DE2-CB18-2E42-BC18-CB-2BC14-BC6-BC11-B9-BF8-BC12-EB5-BC14-BC4-B15-CF4-E16-B3-B17-2B2-B18-D2-D18-C-AD19-2(2A20-)2AD18-BA-A18-A3-A15-DA5-A14-A6-A14-A7-3A8-3A9-3J2A2-2A3J15-2A60-2(BD)FDCD14-D6-EC13-B7-D13-C7-E15-EC3-CE17-BC2F16-HGFB2G16-H2GHGH15-2GH2-G2H14-2H4-HG13-CB6-GB11-C9-BE8-CB12-2B5-EC14-2B4-B15-CB4-B16-E3-C18-B2-E18-B-AB18-B3(2A20-)2AC18-DA-A18-A3-A16-A4-A15-EA5-A14-A7-A2K8-2KA11-A2K2-2KA17-2A42-BD16-2DCF2-2BE13-B7-FB12-B7-2D12-B7-EF15-E3-DC16-DBDCB15-HGD3-2G14-G5-2H13-2G6-2G12-GH6-HG12-FB6-GB11-EB7-FEB9-F11-BE7-D13-CB5-D15-ED4-F16-E3-D18-E2-C18-F-AF18-C4(2A20-)A-F18-D2-D17-EB3-D15-BE4-CE14-CB6-EB10-CF9-D2FCB2-3BDF11-D2(BC)FCDEC14-BFBEFD18-FED16-CED3-FDB12-D8-D12-E8-C13-B6-ED15-2E2-B16-BF3-E15-HG4-HG14-G6-G13-H7-2G12-G7-HG12-GH6-HG12-F7-BC10-2C10-BC7-B13-CF5-E15-CE4-D16-D3-D17-DB2-F18-E2-D18-E-BE18-DCE20-DB20-2CF18-2C2D18-DC-E18-B2-F17-FB3-FB14-ED4-2DC12-BEF6-EF10-2D10-F2C4-CFB14-D2F2EC17-ECE2F16-2D4-EF13-FDF5-E13-2FE5-DF12-CDB4-2FD13-CE3-B16-E4-F15-H5-GH13-HG6-GH12-H7-GH12-G7-2H12-H7-2G12-D7-FC10-FB10-DF7-D13-2B5-D15-BD4-F16-E3-F17-F3-D18-F2-B18-E2-F18-C-2C18-2EBD18-CD-F18-B2-F18-C2-B17-2C2-2B16-2E3-F16-E4-FE14-BE6-BD9-CFB10-EDEF2-F2CD15-B2ED19-2(DC)E16-ECBDEFB15-EF2-FBEF13-CF4-FEB13-CB4-CE14-BC3-2C15-BE-FEC15-GH4-2H13-GH6-GH12-H7-2G12-H7-HG12-HG6-2G12-DE6-CB10-ED10-BF7-DC12-BE5-EB14-CE4-B15-BE4-B16-F3-D17-2C2-B17-FC2-B18-D2-B18-C2-F18-E2-B17-DB2-B17-2B3-B15-FE4-D15-CB4-CB14-CE5-DB12-CD8-DBDFCEDBF2CE14-F3D63-F21-D3FE17-BF2DE17-2ECB17-2CDEF16-2BCFEF15-GH4-2H14-H6-G13-HG6-2G12-2H6-HG12-2H6-2G13-F6-B12-DB8-EC9-2F10-2F7-FD12-ED5-2C14-CE4-C15-2D4-E15-EB4-D15-CD3-EB16-2F2-E17-BD3-D15-DC4-F15-2C4-F15-2D4-EB14-2C4-DE14-DC5-F2E10-3C7-CBFB6-CEBF12-EBCEBD172-CE19-BC2F17-2G3HG15-2H3-G2H14-G6-G14-H6-H14-HG4-HG15-2B2-BC14-FDE5-2E11-C9-DC9-BD10-FC7-DE12-FB5-FD14-BF4-DC14-2C4-D15-2B4-D15-FB4-D15-BD4-DC14-2C4-BD14-2C5-C13-2B6-FD12-BC6-2DE10-3E7-CF9-ECF10-EBCDCF2C2D235-2HGH17-G2H3G16-HG3HG16-G4HG16-6G17-BC2D16-BFD2E2BD13-BF6-EB11-BF7-2BD9-FC10-FD7-DF12-EF6-FD12-EB6-BE12-EB6-CB12-BD6-ED12-EC6-CFC10-2DC7-CE10-BD8-FEF8-2EC8-3EC6-2EFD9-2BED2BD3EDC11-D2CE2CBCFC13-FD2EFDBD389-BDBCEF15-2FCEDEBE13-B2EF-BEDFC11-DED6-CEC10-CFC6-BCD10-BEC6-E2C10-DCF6-DED10-BE2C5-3F11-BCF4-F2D12-2DEC2-DECB13-2DF-2E2D15-BF2C2D140-
