model
size = 20 32 13, scale = 0.05, origin = -y
material deform = 1, fade = true, lighting = smooth, roughness = 0.3, metalness = 0.6
  colors = A:#5E432C B:#533D28 C:#594127 D:#000 E:#7E664A F:#C7B494 G:#7F6954 H:#928167 I:#9F8B72 J:#3E302D K:#362B25 L:#3A2826 M:#352726 N:#3E2F28 O:#352724 P:#372825 Q:#E0CBAC R:#3A2B24 S:#BDA58B T:#3A2921 U:#3C2D26 V:#372928 W:#6B5943 X:#382A27 Y:#DCC5A3 Z:#E9D2B3 Aa:#3A2C29 Ab:#CCB798 Ac:#DBC4A4 Ad:#412B1D Ae:#A0886C Af:#3B2D2A Ag:#D6BF9D Ah:#3B2C27 Ai:#332A25 Aj:#493625 Ak:#DFC8A8 Al:#3D2B29 Am:#DEC7A8 An:#352623 Ao:#CAB797 Ap:#A79378 Aq:#3E2D25 Ar:#3C2E2B As:#33291F At:#382922 Au:#C2AB8B Av:#E7D0AE Aw:#3B2B2C Ax:#EAD3B3 Ay:#E2CBAB Az:#DAC3A4 Ba:#F8E1C2 Bb:#DCC5A5 Bc:#D5C2A2 Bd:#372C2A Be:#574435 Bf:#F0D9B9 Bg:#E4CDAE Bh:#3A2D27 Bi:#3B2C29 Bj:#362B29 Bk:#342A28 Bl:#D2BB9C Bm:#D7C0A1 Bn:#D7C2A3 Bo:#3B2C25 Bp:#D4BD9D Bq:#DEC7A7 Br:#453528 Bs:#937F66 Bt:#392E2A Bu:#59493C Bv:#B49C80 Bw:#3B2E28 Bx:#E2CBAC By:#342923 Bz:#3A2C2B Ca:#CBB495 Cb:#303C32 Cc:#59463C Cd:#3B2E26 Ce:#382E24 Cf:#D1BA9B Cg:#41342C Ch:#89735C Ci:#BBA888 Cj:#3E2C2A Ck:#D6BFA0 Cl:#826E56 Cm:#847058 Cn:#C7B295 Co:#3D3123 Cp:#B69F7F Cq:#DDC6A6 Cr:#392B28 Cs:#D3BC9C Ct:#392723 Cu:#AC9478 Cv:#DBC4A5 Cw:#97836B Cx:#3C3020 Cy:#392929 Cz:#3F3029 Da:#F2DBBB Db:#D9C2A3 Dc:#F4DDBE Dd:#3C2D2A De:#C3B090 Df:#4F3E34 Dg:#C8B594 Dh:#3B2D2D Di:#B09C83 Dj:#C1AA8A Dk:#D2BF9E Dl:#AD9579 Dm:#46342A Dn:#3C2B21 Do:#E1CAAB Dp:#EAD3B4 Dq:#ECD5B6 Dr:#CFB899
voxels
6-BC4ACB12-B2C3B2A13-C2ABCB15-CA2B17-CA553-C2B6-B2A8-2CAC4-A2CA8-4BA2-ABACB9-2ABCAB2A2C10-B4C2BA2C10-C2B2C2(AB)C11-BA2(CB)2C12-2B3C2BC13-C2ACAB15-3AC390-KAcHA8-BKAdBf6-BKAd6-AcHA26-BCB10-3C4-3C10-2AB5-2A10-2B6-BCA8-BCA6-A2B8AB2C7-9AC2B8-3B6A3B8-A3B-4A2BA9-CB4AB3C10-C2ACBC2ABC11-ACB3CBC12-BAB2(CA)B13-BACA2CA14-CACB309-AgBUELEG4-EGAwBJIP4-GAwBJI4-BUELE24-2A14-BA2-2BA12-A-A3-2A12-AC4-CA12-CA4-ABC11-2C4-2AB10ABAC5-CB2A2(3DA)BC6-2B2A4DA2D3A6-BAC2(AD)A3DACA7-2B2A3(DA)2C8-B2A3DADBD2B8-BAC2DC4DCA9-2A3DA3DB10-BA6CAC11-CACB2CBA13-2A2C2A14-A3BAB16-AB157-KAcHA15-ELUELE14-2GTGEA14-AnAkAjZLR8-IATQENV-GA-NVAoAaYAbAf3-NVAoAaYAbB2-IATQENV5-MOAuAt6-JAvAhB3-2B16-AB-C15-2B2-AC14-BA2-2B14-CB2-AB14-CB3-AB12-BC4-AC12-CA4-2C12-2B4-CA12-AB5-BC10-2C6-BA10-2C6-3A8-A-A7-BA8-CA8-ABA6-2BA9-CB6-AB10-2BC4-CBC10-2(AC)-ABACA11-BCB2CABA13-2BC3A14-B5C14-2(CA)BC15-2(CA)16-4A16-CTQC14-ACGUELCA12-ACKAcHANB11-2BACUELECA12-2BTGEB13-BAnAkAjZLRA8-SAtAuOMBNAHAcMBAhAvJBe4-MBAhAvJBeI2-QSAtAuOMB4-ENEQTA4-AbYAaAoVN2-AB16-C2BC16-2B2A16-BC-A16-B2-2C14-BC2-2A14-AC2-2B14-BA3-C14-B4-C14-A4-2AB11-2A4-A2B11-2C5-3B8-BAB6-A2B8-2BA6-CA2B6-2B2A7-A2B6-3B8-ABDB4-3BC8-B-ADB-2BDC-B9-BA2DB2DA2B10-3B4D3A10-BAB4DB2C10-ACA4D2CA10-3C4DB2A10-2AB4DCBA10-ABC4D2CB10-2C5D2BA9-2CBC5DC2B8-2(BA)C2DCB3A8-3A3B2(CB)2A7-2ACAlAnAkAjZERAxABA5-2ArAmRWAJDoDpBnDqAzOBgCAr3-AiG5-EZAjAk5-GAi4-ELEUBAg2-PIJHAwG3-B18-2A18-2CA16-BACB16-3CA16-BC-B16-C2-B16-A2-CB14-2C2-2C14-CA3-3B12-C4-3B11-BA4-2C2B8-2B2C4-2A2B8-4B5-4B6-3BA6-A3B6-3BC7-C2AB4-3BC8-2A2DB-2BADBC8-BC3AB4A2C9-9AC10-BC6ABC2(10-B9A)10-C8AC10-B8AB9-AC8A2C8-AC10A8-C10AC7-12ACA6-14A5-EA2(CB)C2ABD2ADAE3-BcHBzCaZBDr4FBqPBAdAsIBc3-FNAHAcKB2-SBfAdKBAdAo2-B18-2B18-CB18-ACA16-2BCA16-AC-B16-B2-C16-A2-C16-C2-BA14-CA2-2C14-2B3-A14-A4-B14-B4-AB12-BC4-2C12-AC5-C12-A6-BA10-AC7-5A4-3A8-CA8-BA8-2C8-2A9-A8-C9-2(AC8-)CA8-CB8-2B3(8-CB)8-A10-B8-A10-A7-2B10-BC6-C11-2C6-A12-A5-HA4-MEMAbD2-DAH3-Bb-2C2-CbCcBGCcCb2-AB-Bb3-GELEUBAg2-PIJBAwGE2-C18-3C17-B2C16-2C2B16-BC-C16-A2-C16-C2-B16-A2-BC14-CB2-CA14-BA3-C14-C4-B14-A4-B13-2B4-2C12-BA4-2B12-BA5-C12-A6-2A10-CA7-C2A6-2AC8-2C8-AB8-BA8-BC9-A8-B9-BC8-BA8-2C8-CB8-2A8-CB8-B10-B8-C10-A8-B10-B7-CB10-BC6-B11-CB6-C12-C5-FB8-D2-DBF3-Ba-2A2-CH2-HB2-2B-Ba3-VHEQTA4-AbYAaAoVF2-BA16-CBAB16-2B-B16-A2-2C14-2A2-AC14-2C2-BC14-CB2-2B14-2B2-BC14-BC3-2C12-CA4-AB12-AB4-CB12-2B4-BA12-AC5-B12-A6-2C10-2B6-AB10-BC7-CB8-AB8-2BA6-A2(2C8-)CB9-A8-C10-B8-B2(10-B8-C)10-C8-A9-2C8-2B8-CB8-BA8-CA8-2A7-AB10-AC6-2C10-BC6-2C11-C5-G3C3B2-CB2-2CG3-WHACABH4-HBC-AGW4-MOAuAt6-JAvAhB4-BC14-2C2-C2B12-2CA2-2BC12-ACA2-ABA12-A2B3-CB12-2C4-CB12-CA4-BC12-CA4-B2C10-C2A4-B2A10-BAB5-AB10-2C6-2A10-CB6-AC10-BC6-3C8-ACB6-2AC8-2CA7-2(AB8-)C-B6-B-B9-BC6-CA10-2A6-CB10-BA6-BC10-CB6-BC10-AB6-AB10-BA6-BC10-BC6-2C10-CB6-AC10-BC6-CA9-B2ACA2-3B2A7-CAC2AC2-ACB3C6-B3ABA2-CB2ABC6-C2BF2B2-BCFC2B6-B2FBAB2-BCB2FC5-AsI2FA6-B2FAsI24-2(CB)9-3B4-2ACA8-BCAB5-BAC8-ACA6-A2B8-3B6-B2C8-A2B6-CBA7-B2AC6-BA2C6-3AC6-CA2B6-AC2A7-A2C6-C2B8-2BC6-C2B8-3BA4-BCBA8-2(AB)4-B2AB8-2C2B4-2ABC9-ABC4-ACB10-ACAF2-F3B10-2BBtF2-FAiAC11-CEAe2-F2C12-AAlX-DBlBdB12-BBuBoD-DkDlA12-BDmY2-BvPB12-BDnAa-DBsBwC12-CSBdD-AmBeB12-BABx2-AfAbB12-CBAg-DPIC12-B2KD-SBfC13-RAe2-ApJ14-IAy-DXE13-QGAD-ByEX11-EAlAn4-RAxE9-AmRW6-AzOBg7-BzCa10-AdE27-BhCdBiCeAe2-BjBkCCfAe9-ApCgChBj2-BlCiCjCk10-ClBmCmBn2-CnBCoBm10-CpCqBkBh2-CCrAfCs10-AgOCtM2-CuAhAqC10-CvBoCwC2-JBpAxCx11-CyWAy2-XAeCz12-BpPAi2-AjDaAq12-AkAqAr2-DbDcAp12-EAsA2-DdAqY12-DeAzBq2-DfBJ13-AfDg2-BrW14-AlDh2-ZBa14-DiP2-BiBb14-DjAm2-BsBc14-BtF2-BrAi14-E20-X3-Bd14-Bu23-Bv16-Aa3-Bw14-S3-Am16-Bx2-Af20-I14-K3-S19-Ap16-Ay3-E13-QG3-By-X12-AlAn17-R8-OBg44-
