model
size = 27 32 25, scale = 0.05, origin = -y
material deform = 1, fade = true, lighting = smooth, roughness = 0.3, metalness = 0.6
  colors = A:#6CC B:#111 C:#F69 D:#F39 E:#F99 F:#FFF G:#C99 H:#F93 I:#EEE J:#F36
voxels
442-A5-A17-13A13-15A12-15A11-16A10-19A7-20A2(8-19A)9-3A11-3A447-2A3-2A17-13A13-14A13-15A12-15A11-17A9-19A6-22A5-6A11-6A2(4-5A13-5A)4-4A14-5A4-5A13-5A3(4-6A11-6A)2(5-5A11-6A)253-10A16-12A15-13A12-16A11-17A10-17A9-19A8-4A11-4A7-2(5A11-5A6-)4A12-5A5-4A15-4A4-3A17-3A2(5-A19-2A)112-2(2A19-2A4-)6A11-6A4-A2-3A11-3A-2A5-5A11-6A7-2A13-2A66-13A14-13A2(13-14A)13-15A11-17A10-4A8-2(5A9-)4A9-4A11-4A7-3A14-4A2(6-3A15-3A)5-3A17-2A5-2(3A17-A-A4-)2A18-3A4-2A19-2A4-A20-2A247-3A17-2A5-A2-3A11-3A2-A5-2A2-A11-A2-2A8-2A13-2A37-4A9-4A10-3A10-4A2(10-3A11-3A)9-4A11-3A9-3A13-A-A8-2A15-2A7-A-A15-3A6-2A16-3A5-A-A17-2A5-2A19-2A4-2A17-E-2A4-2A19-2A3-2(2A20-A-A2-)2A21-2A3-A21-A301-3A17-3A4-A2-3A11-3A2-A5-4A12-5A34-2A14-3A4(8-2A15-2A)7-2A16-A-A2(6-2A17-2A)5-2(2A19-2A4-)A20-2A3-4(2A21-2A2-)A22-2A354-3A-A13-5A4-5A13-A-3A7-2A13-2A8-2A16-2A7-3(2A17-2A6-)2A17-2A5-2A18-2A5-2(2A19-2A4-)2A19-2A3-3(2A21-2A2-)A23-A-2A23-4A23-2A-A23-A354-2A19-2A4-5A13-5A6-3A13-3A7-2A17-2A6-A18-2A2(6-A19-A)5-2A19-A5-2A19-2A4-A20-2A4-A21-A3-2(2A21-2A2-)A23-A2-A23-A-2A23-4A23-3A24-2A407-2(5A13-5A4-)2(2A19-A5-)3(2A19-2A4-)A20-2A4-A21-A3-2(2A21-2A2-)A23-A2-A23-A-2A23-4A23-3A24-3A25-A407-3A17-3A4-5A13-5A2(4-2A19-2A)4-A20-2A2(4-A21-A)4-A20-2A3-2A21-A3-2A21-2A2-A22-2A2-A2(23-A-2A)23-3A24-3A25-2A25-A407-3A17-3A4-5A13-5A4-A20-2A4(4-A21-A)3-2A20-2A3-2A21-2A2-A22-2A2(2-A23-A)-2A23-4A23-3A2(25-2A)25-A407-4A15-4A4-5A13-5A4(4-A21-A)3-2A21-A3-2A20-3A2-2A21-2A2-A22-2A2-A23-A-2A2(23-4A)23-3A2(25-2A)25-A407-2(5A13-5A4-)3(A21-A4-)A2(21-A3-2A)20-3A2-2A21-2A2-A22-2A2-A23-A-2A23-4A23-3A24-3A2(25-2A)25-A380-2A19-2A4-A-3A13-3A-A5-4A13-4A5-A20-2A4(4-A21-A)3-2A20-2A3-2(2A21-2A2-)A23-A2-A23-A-2A23-4A23-3A24-3A2(25-2A)25-A353-5A13-5A4-3A-A13-A-3A7-2A13-2A7-2A19-2(A5-A20-)A5-2(A21-A4-)A20-2A4-A21-A3-2A21-2A2-A22-2A2-A2(23-A-2A)23-4A23-3A2(25-2A)25-A326-2A19-2A4-A-3A13-3A-A4-5A13-5A31-4(2A19-A5-)A20-2A2(4-A21-A)3-2A21-A3-2(2A21-2A2-)A2(23-A-2A)23-4A23-3A2(25-2A)25-A272-2A19-2A4-A-3A13-3A-A4-3A-A13-A-3A7-2A13-2A35-3(A18-A7-)A18-A6-2A19-A5-2(2A19-2A4-)A20-2A3-2A21-A3-2(2A21-2A2-)A22-2A-2A23-A-2A23-4A23-3A24-3A2(25-2A)25-A191-2A19-2A4-A-3A13-3A-A4-3A-A13-A-3A6-3A13-3A61-5(2A17-A7-)A2(18-A6-2A)2(19-2A4-2A)19-2A3-2A21-A3-2(2A21-2A2-)A22-2A-2A23-A-2A23-4A23-3A4(25-2A)25-A55-2A21-A4-3A17-3A4-A-4A11-4A-A4-3A-2A11-A2-3A7-2A13-2A90-4(2A15-2A8-)3(2A16-A8-)2A16-2A6-A18-2A5-3(2A19-2A4-)A20-2A3-2(2A21-2A2-)2A21-2A-2A23-A-2A5(23-4A)23-2A-2A21-2A2-A-2A17-2A-A3-2A-3A11-3A-2A4-6A11-6A7-2A13-2A118-2(2A13-2A10-)2A13-2A9-3A14-4(2A8-2A15-)2A7-2A17-A7-2A17-2A6-2A17-2A5-2A19-A5-2(2A19-2A4-)A20-2A3-4(2A21-2A2-)A22-2A-2A22-2A2(-A)21-2A2-2A21-2A2-A-2A17-2A-A3-2A-4A9-4A-2A6-4A11-4A171-3A11-3A3(10-2A13-2A)9-2(3A13-3A8-)2A14-3A3(8-2A15-2A)7-2(2A17-2A6-)2A17-2A5-2A18-2A5-2A19-2A4-2A19-2A3-2A20-2A2(3-2A21-A)3-2(2A21-2A2-)A-A19-2A4-3A17-3A4-2A-4A9-4A-2A6-5A9-5A199-5A5-5A11-2(5A7-5A10-)3(4A9-4A10-)4A10-3A9-5A10-4A8-3A12-4A8-A-A13-3A2(8-2A15-2A)7-2A17-A7-2A17-2A6-2A17-2A5-2A18-A-A4(4-2A19-2A)4-3A17-3A4-4A15-3A6-5A11-5A7-3A-A8-2A-3A11-2A9-2A203-13A13-4(15A12-)15A11-2(17A10-)17A9-4(19A8-)19A7-7A3BA3B7A6-7A2BA4B5A-A6-7A3B2(AB)7A6-8AB3AB8A6-7A2(BA)3B7A6-7A4BA2B7A6-7A3BA3B7A7-19A9-17A12-13A233-7A19-9A17-2(11A16-)4A3-4A15-13A14-3A-5A-3A14-13A13-15A11-17A10-17A11-15A12-15A11-17A10-17A9-4(19A8-)18A10-17A11-8A2CD4A14-11A317-2(3A24-)3A23-5A21-7A20-7A19-3(9A18-)9A17-11A16-6ADCD2A16-5A2(DC)DA15-5ACEGEFHCA14-4ADCHEFGEDC14-4A2DGFHIGDC14-4ACJ3(FE)D15-4ACEFEGHD18-3AD4C23-2CD280-
