model
size = 20 29 7, scale = 0.05, origin = -y
material deform = 1, fade = true, lighting = smooth, roughness = 0.3, metalness = 0.6
  colors = A:#F7A8B8 B:#FFF C:#55CDFC D:#4B4B4B
voxels
C21(18-2C)18-3C16-2C-CA14-AC2-2CA12-A2C3-2CA10-A2C5-2CA8-A2C84-6(A16-A2-)A16-A-2A10(16-4A)16-2A-3(A16-A2-)2A14-2A2-3A12-3A3-3A10-3A5-ACA8-ADA7-2C8-2C106-3(B14-B4-)B14-B3-13(2B14-2B2-)2B14-2B3-2(A14-A4-)2A12-2A4-3A10-3A5-ADA8-ADA7-CBC6-CBC9-C8-C128-A12-A5-15(BA12-AB4-)2A12-2A4-2A12-2A5-A12-A6-2A10-2A6-ADA8-ADA7-CDC6-CDC9-C8-C128-2(A12-A6-)4(AC10-CA6-)7(AB10-BA6-)2A10-2A3(6-AB10-BA)6-2A10-BA6-AC10-2A6-2A10-2A6-ACA8-ADA7-3C6-3C9-C8-C169-2(C10-C8-)BA8-AB8-CA8-AC6(8-2C)8(8-CB8-BC)2(8-2B)8-CB8-BC8-A2B6-2BA8-CAC6-CAC2(8-2C)329-6(A8-A10-)AB6-BA4(10-CB6-BC)11-C6-C46-
