model
size = 27 13 20, scale = 0.05, origin = -y
material deform = 1, fade = true, lighting = smooth, roughness = 0.3, metalness = 0.6
  colors = A:#111 B:#CF3
voxels
42-4A22-6A2(21-2A2B2A)21-6A22-4A185-4A22-6A2(21-2A2B2A)21-6A22-4A212-4A22-6A12-9B2(6A2B17-2B)6A2B17-3B4A3B18-8B20-6B199-2B7A9-A2B13-4A5-5A14-2(12A15-)12A16-10A18-3A2B3A22-2B146-B7A13-AB11-B2A9-4A12-2(4A5-5A13-)4A5-5A14-3A5-4A16-2A5-3A18-8A22-2B118-B8A13-AB11-BA11-3A3(11-B2A9-4A)12-2A9-3A14-A9-2A16-2A5-3A18-3A2B3A115-B7A15-AB9-2A13-3A2(9-3A11-4A)10-BA11-3A11-BA11-3A12-A11-2A14-2A7-3A16-10A19-2A2B2A88-B8A15-AB9-2A13-3A3(9-3A11-4A)10-BA11-3A11-BA11-3A12-2A9-3A14-12A17-3A2B3A87-B7A17-AB7-BA15-2AB7-B2A13-3AB8-2(2A13-3A9-)2A13-3A10-B13-2A12-A11-2A14-12A16-10A20-4B62-B7A17-AB7-BA15-2A2(B7-B2A13-3A)B8-2A13-3A9-2A13-3A10-B13-2A12-A11-2A14-12A16-10A19-6B2(61-B7A17-2A7-2A15-3A2(7-B2A13-3AB)8-2A13-3A9-2A13-3A10-B13-2A11-BA11-3A12-14A15-10A19-2B2A2B)61-B7A17-AB7-BA15-2A2(B7-B2A13-3A)B8-2A13-3A9-2A13-3A10-B13-2A12-A11-2A14-12A16-10A19-6B61-B8A15-2AB7-B2A13-3AB7-B3A11-4AB8-2(3A11-4A9-)3A11-4A10-BA11-3A12-2A9-3A14-12A16-10A20-4B62-B8A15-AB9-2A13-3A3(9-3A11-4A)10-BA11-3A11-BA11-3A12-3A7-4A14-12A17-3A2B3A88-B8A13-2AB9-3A11-2(4A9-)5A9-4A9-5A10-B2A9-4A11-B2A9-4A12-2A9-3A14-3A5-4A16-10A19-2A2B2A89-B8A13-AB11-B2A9-4A3(11-B4A5-6A)12-4A5-5A14-3A5-4A16-10A18-3A2B3A116-B9A9-3AB11-B4A5-6A12-2(14A13-)14A14-12A16-10A18-8A22-2B120-2B9A5-3A2B13-14A14-2(12A15-)12A16-10A18-3A2B3A22-2B105-4A22-6A12-9B2(6A2B17-2B)6A2B17-3B4A3B18-8B20-6B142-
