model
size = 27 24 27, scale = 0.05, origin = -y
material deform = 1, fade = true, lighting = smooth, roughness = 0.3, metalness = 0.6
  colors = A:#001 B:#004 C:#002 D:#FF0 E:#60F F:#700 G:#A00 H:#00F I:#0D0 J:#3F6
voxels
10-7B638-13B634-15B631-19B628-21B627-G20B13-7D9(20-7A)20-2A3G2A20-3A2G2A2(20-7A)3(20-6AG)3(20-7A)93-8B7-8B10-2D7-2D16(16-2A7-2A)16-2A7-2G16-2A7-AG16-2A7-2A70-11C9-7B11-7B8-D11-D16(14-A11-A)2(14-A11-G)14-A11-A68-13C8-6B13-6B7-D13-D17(12-A13-A)12-A13-G12-A13-A66-15C7-5B15-5B6-D15-D8(10-A15-A)10-A15-H10(10-A15-A)64-17C5-6B15-6B5-D15-D19(10-A15-A)64-17C5-5B17-5B4-D17-D12(8-A17-A)8-F6(17-A8-A)17-A35-6C3EC2E7C31-5B17-5B4-D17-D12(8-A17-A)8-F6(17-A8-A)17-A35-8C3E8C31-5B17-4BJ4-D17-D12(8-A17-A)8-F6(17-A8-A)17-A35-9CJE8C31-5B17-5B4-D17-D12(8-A17-A)8-F6(17-A8-A)17-A35-9CJ9C31-5B17-5B4-D17-D11(8-A17-A)3(8-F17-A)8-A17-H8-F3(17-A8-A)17-A35-19C31-6B15-6B5-D15-D11(10-A15-A)10-F15-A10-A2(15-A10-F)15-H10-F15-H3(10-A15-A)10-17C60-5B15-5B6-D15-D2(10-A15-A)10-A14-2A3(10-A14-AI)2(10-A14-2A)2(10-F14-2A)10-A14-2A2(10-A14-AH)10-F14-AH10-F14-2A10-A14-AH3(10-A14-2A)10-17C60-6B13-6B7-D13-D4(12-A13-A)12-A13-I4(12-A13-A)2(12-F13-A)12-A13-A2(12-F13-H)12-A13-A12-A13-H3(12-A13-A)12-15C61-7B11-7B8-D11-D8(14-A11-A)2(14-E11-A)4(14-F11-A)14-A11-A14-F3(11-A14-A)11-A14-13C63-8B7-8B10-2D7-2D8(16-2A7-2A)2(16-2E7-2A)6(16-2A7-2A)16-FA2(7-2A16-2A)7-2A16-11C65-5BE15B13-7D8(20-7A)20-2E5A20-4E3A20-2AE4A20-3E4A20-E6A6(20-7A)20-7C67-5BE15B628-4BE14B631-2BE12B634-13B638-7B631-
