model
size = 32 17 30, scale = 0.05, origin = -y
material deform = 1, fade = true, lighting = smooth, roughness = 0.3, metalness = 0.6
  colors = A:#080808 B:#A9A9A9 C:#ADADAD D:#AEAEAE E:#A8A8A8 F:#FBFBFB G:#B8B8B8 H:#B7B7B7 I:#ACACAC J:#F3F3F3 K:#A7A7A7 L:#BABABA M:#BBB N:#F4F4F4 O:#9C9C9C P:#090909 Q:#FAFAFA R:#9D9D9D S:#A6A6A6 T:#AAA U:#EBEBEB V:#F5F5F5 W:#A3A3A3 X:#A4A4A4 Y:#EFEFEF Z:#F7F7F7 Aa:#F0F0F0 Ab:#EEE Ac:#F6F6F6 Ad:#FDFDFD Ae:#989898 Af:#CACACA Ag:#CCC Ah:#D7D7D7 Ai:#F2F2F2 Aj:#A2A2A2 Ak:#D9D9D9 Al:#7A7A7A Am:#9B9B9B An:#9F9F9F Ao:#ABABAB Ap:#C9C9C9 Aq:#D6D6D6 Ar:#F8F8F8 As:#C0C0C0 At:#D4D4D4 Au:#6F6F6F Av:#B5B5B5 Aw:#F1F1F1 Ax:#747474 Ay:#6A6A6A Az:#959595 Ba:#919191 Bb:#C7C7C7 Bc:#C5C5C5 Bd:#656565 Be:#A1A1A1 Bf:#AFAFAF Bg:#5D5D5D Bh:#6B6B6B Bi:#6E6E6E Bj:#585858 Bk:#575757 Bl:#CFCFCF Bm:#E3E3E3 Bn:#626262 Bo:#9E9E9E Bp:#787878 Bq:#111 Br:#B2B2B2 Bs:#868686 Bt:#2D2D2D Bu:#5B5B5B Bv:#CECECE Bw:#999 Bx:#DCDCDC By:#E5E5E5 Bz:#E8E8E8 Ca:#E4E4E4 Cb:#ECECEC Cc:#777 Cd:#949494 Ce:#8D8D8D Cf:#FCFCFC Cg:#D1D1D1 Ch:#F9F9F9 Ci:#E7E7E7 Cj:#B0B0B0 Ck:#4D4D4D Cl:#808080 Cm:#595959 Cn:#616161 Co:#757575 Cp:#A0A0A0 Cq:#717171 Cr:#646464 Cs:#969696 Ct:#636363 Cu:#9A9A9A Cv:#414141 Cw:#B3B3B3 Cx:#8B8B8B Cy:#707070 Cz:#B9B9B9 Da:#B6B6B6 Db:#CBCBCB Dc:#C4C4C4 Dd:#FEFEFE De:#C3C3C3 Df:#E1E1E1 Dg:#E2E2E2 Dh:#D2D2D2 Di:#E6E6E6 Dj:#858585 Dk:#0F0F0F Dl:#1D1D1D Dm:#191919 Dn:#1B1B1B Do:#343434 Dp:#8F8F8F Dq:#A5A5A5 Dr:#888 Ds:#828282 Dt:#151515 Du:#2C2C2C Dv:#181818 Dw:#171717 Dx:#5E5E5E Dy:#3D3D3D Dz:#5F5F5F Ea:#737373 Eb:#515151 Ec:#7D7D7D Ed:#232323 Ee:#8A8A8A Ef:#5C5C5C Eg:#B1B1B1 Eh:#3E3E3E Ei:#282828 Ej:#5A5A5A Ek:#DADADA El:#D8D8D8 Em:#E9E9E9 En:#EAEAEA Eo:#D0D0D0 Ep:#373737 Eq:#555 Er:#DEDEDE Es:#666 Et:#676767 Eu:#F50804 Ev:#7C7C7C Ew:#727272 Ex:#A01010 Ey:#909090 Ez:#D3D3D3 Fa:#929292 Fb:#333 Fc:#DFDFDF Fd:#C2C2C2 Fe:#535353 Ff:#EDEDED Fg:#FFF Fh:#DBDBDB Fi:#E0E0E0 Fj:#D5D5D5 Fk:#878787 Fl:#505050 Fm:#4E4E4E Fn:#525252 Fo:#0C0C0C Fp:#3B3B3B Fq:#565656 Fr:#BFBFBF Fs:#BEBEBE Ft:#818181 Fu:#838383 Fv:#2B2B2B Fw:#121212 Fx:#2E2E2E Fy:#070707 Fz:#0E0E0E Ga:#383838 Gb:#424242 Gc:#1F1F1F Gd:#313131 Ge:#1E1E1E Gf:#0D0D0D Gg:#1C1C1C Gh:#1A1A1A Gi:#404040 Gj:#797979 Gk:#8C8C8C Gl:#7F7F7F Gm:#141414 Gn:#161616 Go:#242424 Gp:#BDBDBD Gq:#202020 Gr:#606060 Gs:#7B7B7B Gt:#696969 Gu:#2F2F2F Gv:#212121 Gw:#686868 Gx:#494949 Gy:#2A2A2A Gz:#292929 Ha:#262626 Hb:#272727 Hc:#3A3A3A Hd:#767676 He:#6D6D6D Hf:#0A0A0A Hg:#444 Hh:#6C6C6C Hi:#8E8E8E Hj:#C6C6C6 Hk:#C1C1C1
voxels
135-2(2E14-)BCE12-D2C558-HfEq14-EqA13-Es2Bw14-BHhEt12-EwEB14-BEEw22-A30-2Fb29-As2FeFa28-De2AtFd29-2At214-AHcCu12-Cp2A14-AAuB12-BAuA14-AKC12-CSA14-EpS14-SEp13-Es-B14-B-Et13-EB5-Ba2ACe5-BE20-AzBaA-CeAz26-AzFa2-CeAz26-Dc4-Fd26-De4-As26-BcCg2-DcAs27-DhAkFhAt29-AkAq119-ABuS10-Ae2A15-A2-S10-E2-Ej14-Ae-B12-B-Bw14-S-B12-B-Ej14-SB14-2E14-EB5-Ay2AHg5-BE20-Ay4-Ay25-2(Ba6-Ey24-)De6-As24-Bc6-Bb25-Bc4-As26-At4-At27-2AkFhDi118-2A2Au8-Cy2AGr15-Ae3-C8-C3-Bw14-2B2C10-2C2B15-E14-E53-2Ay2ACcAy25-Cc6-Cc24-Ce6-Ba24-Ba6-Hi24-Hk6-Bc24-Bc6-Bb2(24-Ci6-U)25-Di4-Ab27-Dh2AhDh55-2A10-ADv17-B2-R8-Au2-E16-B2-C8-C2-W17-2D10-2D56-2A28-2Aj2-2Aj25-2(Cd6-Az24-)As6-As24-Hj6-Bc24-Ff6-Ff24-N6-N24-N6-V25-J4-U27-Di2AkU56-GfCv8-GgGh19-B2-W6-Cr2-K18-D2-C6-C2-D18-2DH8-H2D55-Ax2AAx27-Aj4-W25-2(Cd6-Ev24-)Bb6-Bb24-Bb6-Bb23-Ac8-Ac23-N6-N24-N6-N25-J4-Aw26-2Y2Ak2Ab48-B3E14-Ge3-2ECqE6-B2E3-2I2Eh6-2Cv-I3-2EB12-I3-Ae4-O3-I19-GHD6-DHG56-Ax2AAx27-O4-O25-Ax6-Ax24-Aj6-Cc2(24-Cg6-Ez)23-V8-Ac23-Z6-Ar24-Z6-Ar25-N4-J26-2N2Fj2J16-FpACmDm2R14-2Cm2Do2A4-WEa4-R2I12-XTK4-EaT2-2B2-E2BI-ICw2Bg4-2BjEgAo-T2BE2-BC2-2BCE4-C3-Bg4-Bj3-I4-E3B11-G2(2-2B)2-G21-2GH4-H2G26-2A28-OS2-RO25-R6-R24-Aj6-Aj24-Cg6-Dc24-Fc6-Fc24-Ar6-Ar24-Ad6-F24-F6-Q25-Ac4-V27-Aa2CiJ19-DlDmFoDkA12-4PDn5-Bi3AGcDl4-2P8-2Ao4-DnGd2ADzCuC3-ROSDH3-EeDw4-BjGq3-HCSOR3-5C5-Af4-B2-K4-M5-4C10-G3-B2-K3-G21-2GMG2-HM2G26-2A28-2S2-RK26-T4-C25-Br6-Cz24-Cz6-Bx24-Ac6-V24-F6-Q24-Ad6-Ad24-F6-Ad25-V4-V27-Aa2UJ20-2BqDk2A10-3P2Bq6-BiAGa3-2DxBp2-2Ct6-2Bh2-CtBjGb3-2ADyC2-R2-CyCrC4-Cx4-Gp4-TAmCy2-W2-2CDH6-AfDb3-X2AAn3-DbM6-HDC11-Ag3-IA3-Ag23-AfBl-AgA-BlM26-Eo2-Eo28-Av2-Av27-T4-C26-M4-Bl25-Ai6-J24-Q6-Q24-F6-Ad24-Fg6-Fg25-Ch4-Ch26-ArAiDgDfAiV77-FwFx7-Bg2BtDvFy4-DwBh2BtAu7-AFzBi-T5-Am2Ao3-Ef2-Ef3-2AoAm5-T-Bi2CD6-GL4-2A4-LG6-D2C11-Bz8-Bz23-Ca6-Ca25-Ca4-Ca27-Ag2-Bl27-M4-M26-Ab4-Y25-Q6-V24-Dd6-Dd25-Ad4-Dd26-Ch4-F26-V4-V27-Z2FiN79-Fv10-Dt6-Dt10-Du-BuR9-Cx-EdP2-GnGo-Ee9-CuDy2B9-Ag3-PA3-Ag9-2B11-Ag8-Ag23-Em6-Em25-By4-By27-Er2-Er27-Ab4-Y26-J4-Ai26-Ac4-Q26-Ad4-Cf26-F4-Cf26-Q4-Q27-ZDfDgV117-2DICsA8-ACsIBC7-2O5-2DHL-AEdGm2-2PA-L3H5-2O2E6-GHL4-2P4-L2G6-2E10-BvEl8-ElBv22-Bm6-Bm25-En4-En26-U4-U26-Aw4-J26-Ar4-J2(26-Ad4-Cf)26-Q4-Ch27-AcDfDgAc116-2O2A12-2A2Be12-O3-2A8-2A3-O12-D5-CkEc4-EcGl5-H13-2MBv4-Ha2EiHb4-DbAfM17-EkBz8-BmEk22-Bz6-Bx25-Y4-Cb26-N4-Ai26-Z4-V26-Z4-Q2(26-F4-F)27-Z2YJ147-Ae4A12-Fn2A2Am10-Ae3-FuBn10-CnDs3-B10-2D3-2AnBfBg4-BdBf2An3-2D12-M3AfAv2-GxGyGzCx2-Af4M17-ByBm8-BmBy22-U6-U25-Y4-Aa26-N4-Ac25-2F4-2F24-2F4-2F25-Z4-Ar27-Aw2-Z29-2Ai148-Bd2AFl14-Fm2ABd9-E3-Cr14-Bp3-E8-2BHAvIAm3-Ds4AGk3-AmAvGH2B16-Da6-Da24-Aq6-Aq25-Y4-Y26-N4-N25-2F4-2F24-EuF4-FEu24-ExQ4-QEx24-FZ4-NF26-YCbAaAi178-BoBdABp16-Fk2ABn8-Bo2-Bp5-A4-A5-An2-X8-BIAvI4-X-A2EbA-X4-3IC16-L6-G24-Bx6-Aq25-Aw2(4-Aw26-Q)4-Q25-2F4-2F24-2F4-2F26-Ab2-Aa29-2Cb179-3A18-DjABn8-Bo-X5-2ABs2-BsAFt5-X-X8-D-D4-K2-Br2-Bf2-K4-D-D8-2LD5-C2-CzDa2-C5-D2L16-Bx3ApBvBl2Aq25-AaAp2-AbAa27-J2-J27-FJ2-JF26-FJ2AaJF27-JUAbJ29-UAb211-2ACl5-2A4-2A6-ACl8-Bn-Be4-Bo2-Cq2-Co2-X4-Cp-Cl7-W2-B4-K2-Br2-I2-K4-B2-W6-BHGS4-2EDG2-HD2K4-SG2H50-ApAq2(30-AhAp)2(30-2Ah)250-2AAl4-AlACk14-CnADr5-Co-Al4-Al-Cp5-DrACn6-Be2-D4-E-D4-D-Bk4-D2-An6-BLDB4-2EB4-3E4-EDLC430-2A6-2A14-2AFr4-W2-Dq4-X2-T4-Fs2A6-Be-Cw4-B2-D4-H2-D4-Cj-Gj6-B2L4-EBD6-DBE4-DLC430-ACj6-CkA14-ADj5-W-Cj6-Br-Al5-2Bs5-R2-Cw4-W2-D4-D2-Al4-Cs2-R5-BDG4-E-D6-D-E4-2DT13-EBD6-DBE21-B8-E398-Dp6-2ABf6-DAAl6-Dp5-K-T5-Bu-D6-D-Gi5-I-E4-3B5-K-G6-H-K5-3B11-C2-D6-D2-B18-EBCD6-DCBE396-Ae24-Fq5-ET6-2AG6-D2A6-TE11-Gw2-G6-H2-Bi18-X2-D6-D2-Cq18-B2-C6-C2-E18-Bk2C8-2CE435-2A8-GvA19-Ae-Eg8-Bf-Dz17-Bk2-D8-C2-Bk17-BCB8-BCB465-Bu2ADq8-W2AHe16-Bk2-D8-C2-K16-EDCB8-2BDE464-BhAHd10-BdABh16-D-D10-C-D16-2GC10-B2G432-2A12-GuDu15-C2-D10-C2-C14-CH-D10-C-HC16-G12-G432-BAGs12-CoGtC14-C-C12-C-C15-HC12-CG360-
