model
size = 19 31 25, scale = 0.05, origin = -y
material deform = 1, fade = true, lighting = smooth, roughness = 0.3, metalness = 0.6
  colors = A:#EEE B:#FAD689 C:#E87A90 D:#66BAB7
voxels
351-2A16-4A15-4A16-2A510-4A14-3(6A13-)6A14-4A472-2A15-6A13-6A12-8A11-8A12-6A13-6A15-2A453-4A14-6A12-3(8A11-)8A12-6A13-5A15-2A243-10(B18-)B-4A13-B6A10-10A2(8-11A)9-10A11-7A12-6A13-6A14-4A166-3(B18-)B192-2A11-10A8-11A8-2(12A7-)12A8-10A11-8A12-6A13-6A15-2A110-2(B18-)B139-5(C18-)C9-2A7-C7-10A-C7-12A6-14A5-14A2(6-13A)8-10A10-8A12-6A14-6A15-4A16-2A51-B18-B101-4(C18-)C103-4A14-6A3-2A7-2(14A5-)15A4-2(15A5-)14A7-8A-2A9-8A12-7A2(13-6A)14-4A31-B82-2(C18-)C179-4A2-2A10-12A6-14A5-15A4-16A3-17A3-16A4-15A6-13A7-11A9-8A11-8A10-A-6A13-6A15-2A13-B63-C18-C203-4A11-2A-6A8-12A7-13A5-15A4-17A3-16A3-17A2-17A3-15A7-12A8-9A10-8A10-9A12-6A14-4A12-B63-C204-2A15-6A13-6A9-11A7-13A6-15A4-16A2-3(18A-)18A2-16A7-11A7-10A11-8A12-6A14-4A12-B63-C53-7(D18-)D16-4A14-6A12-8A11-8A9-10A8-14A3-17A2-56A-18A-17A4-14A7-10A11-7A13-6A15-2A13-B18-B44-C34-D18-D149-4A14-6A12-8A11-9A10-10A5-14A4-17A-18A-56A2-17A3-14A8-9A11-8A14-4A50-B18-B25-C15-D2-C15-D169-2A15-6A13-7A11-10A9-10A5-15A3-16A2-3(18A-)18A2-16A4-13A9-9A11-6A89-2(B18-)B3-D2-2(C11-B6-)C11-B18-B134-4A14-8A11-9A9-11A5-14A2(3-16A)2(2-17A)3-15A4-15A6-12A9-9A12-2A134-D40-C18-3(C11-B6-)C11-5(B18-)B2-6A10-B-8A8-12A6-13A4-15A3-16A3-2(15A4-)15A5-13A9-10A10-4A-2A149-D116-5(C18-)C17-2A15-6A8-11A7-13A2(5-14A)4-15A4-14A6-12A9-10A11-2A-4A167-D247-4A10-11A6-13A6-14A4-15A4-14A6-13A6-11A10-7A187-D18-D222-4A3-4A7-13A6-4(14A5-)13A7-11A11-4A207-D18-D185-2A15-6A2-4A7-13A5-15A4-15A2(5-14A)7-11A9-9A12-2A227-4(D18-)D108-4A14-6A3-2A7-2(14A5-)15A4-15A5-13A7-12A10-4A-2A318-5(D18-)D13-4A-D12-6AD11-8A-4A6-2(14A5-)14A6-13A7-6A-4A446-2A15-6A13-6A12-8A2-2A7-8A-4A7-6A2-4A7-6A3-2A10-2A472-4A14-3(6A13-)6A14-4A510-2A16-4A15-4A16-2A182-
