model
size = 9 8 27, scale = 0.05, origin = -y
material deform = 1, fade = true, lighting = smooth, roughness = 0.3, metalness = 0.6
  colors = A:#C6C B:#777 C:#111 D:#FC3 E:#CCF F:#FF9 G:#AAA H:#F3F I:#FC9 J:#F96 K:#F09 L:#F39 M:#CC9 N:#FC0 O:#FF0 P:#F0F Q:#FFF R:#F0C S:#FF6 T:#F3C U:#FFC V:#F63 W:#FCC X:#F36 Y:#F66 Z:#F00 Aa:#CC0 Ab:#F9C Ac:#F6C Ad:#F93 Ae:#FC6 Af:#FF3 Ag:#F60 Ah:#F9F Ai:#CF9 Aj:#CC6 Ak:#CF3 Al:#FCF Am:#CCC An:#CFF Ao:#F90 Ap:#F06 Aq:#CF0 Ar:#F6F As:#F30 At:#F99 Au:#CFC Av:#F33 Aw:#F03 Ax:#F69 Ay:#CF6 Az:#CC3
voxels
57-WAhT6-PAcJ59-AkAlJAnAh4-AnAaAiAmX57-USLDAfAqR2-HPAhAcAlWL10-2A2(5-4A)5-2A19-LAgPAnAxAAn2-YIArWJRN-2A5-2AAx7-RAs7-AoAk7-K2A5-2A10-EAoAfJRFJ2-XAiAlAtAyMZ-2A5-2AAc7-Y9BAi2-3B2-N2A2-B2-2A4-B5-YNGWGEH2-AgUQAd2ME-2A5-2AF7-NM7-AwD3-B3-F2A2-B2-2A4-B5-YSGAfGTH2-ZVArWYFH10-2A5-4A5-H3A5-2A4-B8-B5-AlUGAqGDL2-Af2AmAdAoAgO56-NAjJApZPAe2-AwPAoApAbYM56-KVIArTMN2-TAsSQIDK56-Av5CS2-XAhTPAvDAu56-QCAdCAuCAa2-LAkAqAbQIAd56-AtCAqCICAh2-AaKAmTFAgX56-FCAbHOCAq2-AjAgAeK2DW56-Ac5CE2-AsWSAmDVR56-RQXCSAeF2-LXOVUApM56-An2CK2CE2-NAwAkAcFAkM56-JAmVAnAfFT2-ZEAyWTAtF56-HAbAeDQAcD2-EAjOAiVFAg10-2A2(5-4A)5-2A4-B8-B5-H2(AtG)XP2-HRUELHY-2A5-2AAj7-KO7-AcI3-B3-T2A2-B2-2A4-B5-LAdGApGAbM2-OAfOSUAkD-2A5-2AE7-J9BAb2-3B2-L2A2-B2-2A4-B5-AeEGAyGAaAw2-MJAhLIAlD-2A5-2AQ7-EX7-JV7-Z2A5-2A10-NAs2PAoVI2-KEAxArKRI10-2A2(5-4A)5-2A19-SDAvRAbArY2-AuAvAeAfAlUAg56-AaOAeAuUAiAd2-AdFApAiQAjD57-AjZAaEAa4-ONQSZ59-AzAsAh6-IHK3-
