model
size = 10 13 32, scale = 0.05, origin = -y
material deform = 1, fade = true, lighting = smooth, roughness = 0.3, metalness = 0.6
  colors = A:#C00 B:#E40003 C:#D90000 D:#111 E:#222 F:#444
voxels
32-6B5-A2CA136-A2BA5-A4CA4-2C2B2C4-BC2BCB5-B2CB6-A2CA7-2A58-2A6-CB2-BC4-B-2B-B4-AB2-BA4-AC2-CA4-C-2B-C5-A2-A6-B2-B7-2B46-BA2CAB3-B6-2(B2-)2A2-B3-2B2-2B4-BA2-AB4-AB2-BA5-C2AC6-C2-C7-2C37-A2BA5-B4-B3-B6-B2-B-A2CA-B2-AC4-CA3-CA2-AC4-AC2-CA5-4B6-B2-B7-2B18-2B8-2C7-A2-A2(4-2B)2-C6-C2-A-C2BC-A2-CB4-BC3-AC2-CA4-CA2-AC5-A2BA6-A2CA17-2D8-2A7-C2-C6-A2-A4-BA4-AB2-C-4C-C2-AB4-BA2-CB4-BC3-2C2-2C4-BC2-CB5-B2-B6-B2-B17-2D8-2B7-4A6-B2-B2(4-2B)2-C-B2CB-C2-AC4-CA2-B-C2-C-B3-2C2-2C4-AB2-BA5-A2-A56-4A4-BA4-AB2-C-4A-C2-AC4-CA3-BA2-AB4-BA2-AB5-B2-B6-C2-C55-2B2C2B3-B2-2A2-B2-A-C2-C-A2-2A4-2A3-BA2-AB4-2A2-2A5-A2-A64-3A2C3A2-C-4A-C2-CB4-BC2-AC4-CA3-CA2-AC4-CA2-AC5-A2-A64-C6AC2-A-A2BA-A2-2C4-2C3-BA2-AB4-CB2-BC4-BC2-CB64-BA2BAB3-A-4B-A2-AB4-BA3-2(C4-)AC2-CA4-2B2-2B73-ACB2ABCA2-B-A2BA-B2-2C4-2C3-2(C4-)CB2-BC4-BC2-CB64-AC2BCA3-C2-2A2-C2-A-B2-B-A2-AB4-BA3-2(C4-)B4-B73-ACB2CBCA2-B-A2CA-B2-BC4-CB2-CA4-AC3-2(B4-)C4-C73-ABC2BCBA2-B-C2-C-B2-BA4-AB2-2C4-2C3-C4-C73-CAB2CBAC2-B-A2BA-B2-2B4-2B2-A6-A2-2A4-2A2-2C4-2C71-ACAB2CB2(AC)-2A2C2A-C-3(B6-B2-)A6-A71-B3D2A3D2B-B4-B-BCA6-AC-C6-C2-B6-B81-C8D2C-C4-C-2CB6-BC2A6-2A-B6-B81-CDBD2ADBDC2B6-2BC8-CBA6-2(AB)6-BA80-CADB2ABDA2CBA4-AB2C8-3C6-2CBA6-AB2-DE2FED72-C3D2B3DCA2(2CB)2CAC8-CBA6-AB2A6-2A-FE4-EF71-B2(2DC)2DBCA2C2A2CA2C8-C2A6-2ABA6-AB-D6-D71-B3D2C3DBAB2A2B2AB2A8-3A6-3AC6-CA-D6-D71-2CB4AB3C-2C2B2C-CBC6-C2BA6-A2B-C4-C-B-ED4-DE71-C2(2AB)2A2CBAB2ABABCAC6-CA2C6-2C-AB4ABA3-DE2DED73-B2A2B2AB-A2(2BC)2BABA6-ABA-A4-2(A-)2A4B2A91-2AC4AC2A2(B-)2C2(-B)A2-A2CA2-A-2AB2CB2A92-CAB2CBAC-C2(2-B)2-C-AB4-BA3-2C2B2C94-AC2BCA3-2B4-2B3-B4-B5-A2CA83-
