model
size = 31 32 17, scale = 0.05, origin = -y
material deform = 1, fade = true, lighting = smooth, roughness = 0.3, metalness = 0.6
  colors = A:#F0F B:#F93 C:#F06 D:#66F E:#45FF45 F:#FF0 G:#3FF H:#EEE I:#111
voxels
8-DGEGDACBCADGEGD16-ADGDACBFBCADGDA16-CADACBFEFBCADAC16-BCACBFEGEFBCACB16-FBCBFEGDGEFBCBF16-EFBFEGDADGEFBFE16-GEFEGDACADGEFEG16-BGEGDACBCADGEGB16-FEGDACBFBCADGEF16-EGDACBFEFBCADGE16-GDACBABFBABCADG16-DAC2(BADA)BCAD16-ACBADCBFBCDABCA17-BCDCBFDFBCDCB18-FBCBFDADFBCBF18-EFBFDACADFBFE18-GEFDACBCADFEG18-DGEACBEBCAEGD18-ADACBEFEBCADA18-DACBEFBFEBCAD18-ACBDGEFEGDBCA17-ACBCADGEGDACBCA14-DACBFBCADGDACBFBCAD12-ACBGEFBCADACBFEGBCA12-CBADGEFBCACBFEGDABC13-BCADGEFACAFEGDACB15-BCADGACBCAGDACB16-2(FBC2ACB)F18-BACBFEFBCAB20-ACBFEGEFBCA21-BFEGDGEFB49-A15-A14-C15-C14-B15-B14-FBCACBFEGEFBCACBF14-EFBCBFEGDGEFBCBFE14-GEFBFEGDADGEFBFEG14-BGEFEGDACADGEFEGB14-CBGEGDACBCADGEGBC14-BFEGDACBFBCADGEFB14-FEGDACBFEFBCADGEF14-EGDACBFEGEFBCADGE14-GDACBFEGDGEFBCADG14-FACBFEGDADGEFBCAF14-EFBFEG2(DA)DGE2(FB)14-GEFEG3(DA)DGEFEB15-GEF2(DA)C2(AD)FEG16-DGEFDACBCADFEGD16-ADGEACBGBCAEGDA16-CADACBGFGBCADAC16-BDACBGFDFGBCADB11-CADG-DACBDBGFGBDBCAD-GDAC6-BCA2DACBCADBGBDACBCA2DACB6-FBCDACBFBCADBDACBFBCADCBF6-EFDACBGEFBCADACBFEGBCADFE7-DACBADGEFBCACBFEGDABCAD8-AC2BCADGEFACAFEGDAC2BCA9-BEFBCADGACBCAGDACBFEB12-E2(FBC2ACB)FE15-EFBACBFEFBCABFE17-EACBFEGEFBCAE19-CBFEGDGEFBC22-EGDADGE18-C17-C12-B17-B12-F17-F12-E17-E12-G17-G12-B17-B12-C17-C12-A17-A12-C17-C12-BF15-FB12-FE15-EF12-FG15-GF12-EF15-FE13-E15-B14-G15-B14-D15-D14-A15-A14-C15-C14-2(B15-)B13-B10-B5-D13-D5-B4-F4-DA13-AD4-F4-E25-E4-GE23-EG4-DGD21-DGD5-DAC19-CAD6-ACBE17-EBCA7-BDGE16-GDB10-DG15-GD14-GE11-EG17-AC9-CA20-F7-F16-B19-B10-F19-F10-E19-E10-G19-G10-B19-B10-C19-C10-A19-A10-D19-D10-A19-A11-B17-B2(12-F17-F)12-E17-E12-G17-B12-D17-B13-D15-D14-A15-A14-C15-C14-B15-B14-F15-F8-F5-E15-E5-F2-E27-E2-G27-G2-DG25-GD3-DG23-GD4-ADA21-ADA4-DACB19-BCAD5-CBDG17-GDBC7-CADG15-GDAC11-2(D15-)D13-D17-CB9-BC14-B19-B10-F19-F10-E19-E10-G19-G10-B19-B10-C19-C10-A19-A10-D19-D10-A19-A10-CB17-BC10-BF17-FG10-EF17-FE11-E17-E12-G17-B12-D17-B13-D15-D14-A15-A14-C15-C14-B15-B14-F15-F8-F5-E15-E5-F2-E27-E2-G27-G2-D26-GD2-AD25-DA2-CAD23-DAC3-DAC21-CAD4-ACBD19-DBCA5-BCAD17-DACB8-CAD15-DAC2(13-D)17-C11-C14-B19-B10-F19-F10-E19-E10-G19-G10-B19-B10-C19-C10-A19-A10-D19-D10-A19-A10-C19-C10-B19-G10-E19-E10-G19-G10-D19-B10-A19-B11-A17-A12-C17-C12-B17-B12-F17-F13-F15-F7-E6-E15-E6-EG28-EGD28-GDA28-DA-A26-DA2-CA25-AC2-BDA23-ADB3-ACB21-BCA5-BCAD17-DACB7-BCAD15-DACB11-AD14-A16-C12-A13-B19-B10-F19-F10-E19-E10-G19-G10-B19-B10-C19-C10-A19-A10-D19-D10-A19-A10-C19-C10-B19-G10-E19-E10-G19-G10-D19-D10-A19-A10-CA17-AC10-BC17-CB11-B17-B12-F17-F12-EF15-F2(E6-)E15-E6-EG28-EGD28-GDA28-DAC28-AC-C26-AC2-BD25-DB3-AC23-CA4-CBC21-CBC6-BC19-CB10-CA15-AC14-2(A13-)B19-B10-F19-F10-E19-E10-G19-G10-B19-B10-C19-C10-A19-A10-D19-D10-A19-A10-C19-C10-B19-G10-E19-E10-G19-G10-D19-D10-A19-A10-CA17-AC10-BC17-CB10-FB17-BF11-F17-F12-EF15-FE6-E5-GE15-EG5-EG28-EGD28-GDA28-DAC28-ACB28-CB-B26-DB2-DA25-AD3-CB23-BC5-FBC19-CBF9-CA15-AC14-2(A13-)B19-B10-F19-F10-E19-E10-G19-G10-B19-B10-C19-C10-A19-A10-D19-D10-A19-A10-C19-C10-B19-G10-E19-E10-G19-G10-D19-D10-A19-A10-CA17-AC10-BC17-CB10-FB17-BF10-EF17-FE10-GEF15-FEG5-E5-GE15-EG5-EG28-EGD28-GDA28-DAC28-ACB28-CB-B26-DB2-DA25-AD3-CB23-BC5-FBC19-CBF9-CA15-AC14-2(A13-)B19-B10-F19-F10-E19-E10-G19-G10-B19-B10-C19-C10-A19-A10-D19-D10-A19-A10-C19-C10-B19-G10-E19-E10-G19-G10-D19-D10-A19-A10-CA17-AC10-BC17-CB10-FB17-BF11-F17-F12-EF15-FE6-E5-GE15-EG5-EG28-EGD28-GDA28-DAC28-AC-C26-AC2-BD25-DB3-AC23-CA4-CBC21-CBC6-BC19-CB10-CA15-AC14-2(A13-)B19-B10-F19-F10-E19-E10-G19-G10-B19-B10-C19-C10-A19-A10-D19-D10-A19-A10-C19-C10-B19-G10-E19-E10-G19-G10-D19-D10-A19-A10-CA17-AC10-BC17-CB11-B17-B12-F17-F12-EF15-F2(E6-)E15-E6-EG28-EGD28-GDA28-DA-A26-DA2-CA25-AC2-BDA23-ADB3-ACB21-BCA5-BCA19-ACB7-BCAD15-DACB11-2(A15-)2(A13-)B19-B10-F19-F10-E19-E10-G19-G10-B19-B10-C19-C10-A19-A10-D19-D10-A19-A10-C19-C10-B19-G10-E19-E10-G19-G10-D19-D10-A19-A11-A17-A12-C17-C12-B17-B12-F17-F13-F15-F8-F5-E15-E5-F2-E27-E2-G27-G2-D27-D2-AD25-DA2-CAD23-DAC3-DAC21-CAD4-ACBD19-DBCA5-BCAD17-DACB8-CAD15-DAC2(13-D)17-CB9-BC14-B19-B10-F19-F10-E19-E10-G19-G10-B19-B10-C19-C10-A19-A10-D19-D10-A19-A10-CB17-BC10-BF17-FG10-EF17-FE11-E17-E12-G17-G12-D17-D12-AD15-DA12-CA15-AC13-C15-C14-B15-B14-F15-F8-F5-E15-E5-F2-E27-E2-G27-G2-DG25-GD3-DG23-GD4-ADA21-ADA4-DACB19-BCAD5-CBDG17-GDBC7-CADG15-GDAC11-DG13-GD16-ACB7-BCA45-B19-B10-F19-F10-E19-E10-G19-G10-B19-B10-C19-C10-A19-A10-D19-D10-A19-A11-B17-B2(12-F17-F)12-E17-E12-G17-G12-D17-D13-D15-D14-A15-A14-C15-C14-B15-B14-F15-F9-B4-E15-E4-B4-F25-F4-E25-E4-GE23-EG4-DGD21-DGD5-DAC19-CAD6-ACBE17-EBCA7-BDGE15-EGDB10-DG15-GD14-GEAC7-CAEG76-C17-C12-B17-B12-F17-F12-E17-E12-G17-G12-B17-B12-C17-C12-A17-A12-C17-C12-BF15-FB12-FE15-EF12-FG15-GF12-EF15-FE13-E15-E14-G15-G14-DG13-GD14-AD13-DA14-CA13-AC14-BC13-CB14-FB13-BF10-CAD2-D13-D2-DAC6-BCA19-ACB6-FBC19-CBF6-EFD19-DFE7-DA19-AD8-AC2B15-2BCA9-BEF15-FEB12-2(E15-)EFBAC5-CABFE108-AD13-DA14-CA13-AC14-BC13-CB14-FB13-BF14-EF13-FE14-GE13-EG14-BG13-GB14-CB13-BC14-BF13-FB14-FE13-EF14-EG13-GE14-GD13-DG14-FA13-AF14-EFB11-BFE14-GEF11-FEG15-GE11-EG16-DG11-GD16-AD11-DA16-CA11-AC16-BD11-DB14-GEDA11-ADEG11-A2DA13-A2DA10-CDA15-ADC10-DAC15-CAD11-CB15-2(BC13-)CB15-BCADGA3-AGDACB16-FBC2A5-2ACBF141-GEGDACBCADGEG18-DGDACBFBCADGD18-ADACBFEFBCADA18-CACBFEGEFBCAC18-BCBFEGDGEFBCB18-FBFEGDADGEFBF18-EFEGDAFADGEFE18-GEGDAFBFADGEG18-EGDACFBFCADGE18-GDACFBCBFCADG18-DACEFBCBFECAD18-ACGEFBCBFEGCA18-CGEFB3HBFEGC18-BGEFBHIHBFEGB18-FGEFB3HBFEGF18-EFGEFBCBFEGFE18-G2(EF)BCB2(FE)G18-DGEAFBCBFAEGD18-ADAC2(BF)BCADA18-DACBEFBFEBCAD18-ACBDGEFEGDBCA17-ACBCADGEGDACBCA15-ACBFBCADGDACBFBCA14-CBGEFBCADACBFEGBC15-ADGEFBCACBFEGDA17-ADGEFA-AFEGDA195-
