model
size = 31 32 17, scale = 0.05, origin = -y
material deform = 1, fade = true, lighting = smooth, roughness = 0.3, metalness = 0.6
  colors = A:#AAA B:#369 C:#070707 D:#699 E:#69C F:#336 G:#060606 H:#366 I:#333 J:#39C K:#669 L:#9CC M:#CC9 N:#6CC O:#777 P:#9C9 Q:#999 R:#666 S:#36C T:#399 U:#888 V:#CC6 W:#FFC X:#339 Y:#C1C1C1 Z:#F8F8F8 Aa:#CCC Ab:#996 Ac:#036 Ad:#111 Ae:#033 Af:#FF9 Ag:#FC9 Ah:#FFF Ai:#663 Aj:#FC6 Ak:#696 Al:#9C6 Am:#99C
voxels
8-5CIC7GC16-6C9G16-5C2IC2GC4G16-2C2G3C2GC5G16-CG2CGCAd2GC3G2C16-2(2CG)3CGAdC3G16-GCGAd2C2GCGC2FCAc16-2CIG2COGCGI2TRH16-2CI3CG2C2GDBDK16-2CICI2CGCGAdHT2J16-G2I3CGC3GITDQ16-IOIC2G2CGCAdITDAl16-FO2I6CAdCBSD17-RCICG2CICGC2B18-BOI4CI2CI2B18-BO6CICFSB18-SF3CI4CR2D18-BIC3I2CIRV2Aj18-HO6CIRVAgAf18-BHCI5CO3V18-2FC4I3CHUD17-3HF3I4CH2JE14-3H3BOI2COHCD4NE12-FA3BERCICONHRL2N2E12-3A3LOCICONTDN3ED13-3DENOCAeCRNDULE2D15-DLEDR2CR2N4ED16-NENLQOCRJEN2APN18-ADEDCO2BS2B20-3BSFCF3XB21-2K2BCFBXB49-G15-Ae14-C15-Ae14-I15-G14-I15AG14-C2(15AG14-G)15AF14-C2(15AB14-F)15AD14-F15AP14-B15AV14-H15AP14-2H13AXB14-2B13ABF15-B13AS16-J13AD16-B13AV16-B13AAj16-B13AV11-4B-B13AB-4B6-2HBEB15A2E2BE6-2AcH19A2EL6-3F19AD2E7-2R19A2D8-20ADED9-2DN15ADNE12-N15AN15-2E11A2B17-D11AX19-XK7A2B22-BAbBCH2B18-G17-C12-C17-Ae12-C2(17-C12-I)17-G12-G17-C12-G17-H12-O17-B12-F17-R12-GA15-AB12-CA15-AP12-FA15-AP12-BA15-AP13-B15-B14-H15-F14-K15-B14-D15-B14-B15-D14-B15-Ab15-J13-U10-B5-J13-B5-B4-H4-BJ13-2B4-E4-C25-L4-FA23-AE4-2BA21-AED5-D2A19-2AJ6-4A17-2ADN7-2PNA16-NEN10-2E15-BD14-JA11-AC17-BX9-2B20-X7-B16-2(C19-G10-)C19-C10-G19-G10-C19-G10-G2(19-F10-C)19-B10-G19-K11-2(C17-D12-)I17-M12-F17-V12-H17-D12-D17-H13-Q15-B2(14-A15-S)14-D15-B14-B15-S8-B5-B15-B5-F2-F27-D2-F27-E2-HA25-AN3-HA23-AD4-K2A21-2AB4-J3A19-3AN5-4A17-3AD7-A2DA15-A2DE11-B15-H15-B13-X17-2X9-2B14-2(C19-C10-)G19-C10-C19-G10-G19-C10-C19-F10-I19-F10-C19-B10-I19-J10-CA17-AD10-OA17-AB10-BA17-AP11-B17-V12-Q17-V12-Aa17-R13-Aa15-F14-Z15-B14-M15-S14-A15-B14-B15-B8-F5-B15-B5-B2-F27-D2-B27-L2-B26-AE2-AkA25-AJ2-U2A23-2AB3-B2A21-2AQ4-E3A19-3AD5-M3A17-2A2E8-2DB15-H2B13-B13-F17-B11-B14-G19-G3(10-C19-C)10-G19-F10-C19-F10-G2(19-B10-C)19-B10-I19-B10-U19-B10-B19-J10-Q19-D10-Aa19-Ab10-Z19-Ak11-W17-H12-W2(17-B12-M)17-B13-B15-D7-B6-B15-D6-DF28-ADH28-ALB28-AL-P26-AE2-MA25-AB2-Ab2A23-2AB3-J2A21-2AY5-Q3A17-3AD7-3DA15-AJBJ11-2B14-X16-B12-B13-C19-G2(10-C19-C)10-G19-C10-C19-F10-I3(19-B10-C)19-Ac10-R19-B10-D19-D10-K19-B10-A19-D10-W19-Ab10-W19-K2(10-AfA17-AB)11-Ag17-B12-M17-D12-DA15-AD2(6-B)15-D6-YB28-ABAc28-ALK28-ALV28-AE-Ag26-AD2-MA25-AB3-DA23-AN4-2EA21-A2D6-2Q19-JD10-TB15-2J14-B13-X13-C19-G10-C19-F10-G19-C2(10-C19-F)3(10-C19-B)10-O19-Ac10-D19-B10-D19-K10-U19-B10-A19-D10-Ah19-Ab10-M19-B10-Z2(A17-AB10-W)A17-AD11-M17-A12-2A15-AB6-B5-DA15-AB5-MB28-ASB28-ANK28-ALV28-AEM28-AE-P26-AT2-EA25-AS3-JA23-AE5-3D19-D2E9-DS15-2E14-2(S13-)C19-I10-C19-R10-C19-Ai10-C19-G10-G19-H10-C19-I10-C19-H10-I19-H10-H19-Ac10-D19-C10-D19-B10-D19-H10-L19-D10-Z19-Ab10-W19-Q10-AfA17-AB10-AfA17-AD10-WA17-AD10-MA17-AD10-3A15-2AE5-B5-2A15-AE5-LK28-2AK28-ADK28-ABV28-ABM28-AB-D26-AE2-EA25-AE3-DA23-2A5-TPJ19-E2M9-2J15-DP14-J13-D13-C19-C10-G19-C10-C19-O10-C19-Ae10-C19-F10-I19-I10-C19-O10-O19-H10-F19-F10-E19-C10-L19-F10-Q19-B10-L19-D10-W19-P10-Ah19-A2(10-AgA17-AD)10-WA17-AD11-Z17-A12-2A15-AD6-B5-2A15-AD5-EK28-ALK28-AEV28-A2B28-AB-M26-AS2-DA25-AS3-DA23-AE4-3A21-2AY6-PM19-2M10-MD15-2M14-J13-P13-4(C19-F10-)I19-I10-C19-O10-C19-C2(10-B19-F)10-D2(19-C10-P)19-U10-E2(19-P10-Z)19-M2(10-WA17-AD)11-W17-E12-Z17-L12-2A15-A2(B6-)E15-B6-2B28-AAmB28-AYB28-AB-Q26-AJ2-MA25-AH2-H2A23-2AH3-D2A21-2AS5-P2A19-3A7-2MDA15-2AYA11-D15-L15-A13-Q13-C19-I10-C19-C10-C19-F2(10-C19-O)10-C19-H10-F19-F10-X19-B10-B19-F10-D19-C10-L19-C10-P19-Q10-A19-L10-Z19-P10-Ah19-M11-2(W17-D12-)Z17-E12-Aa17-E13-E15-D8-B5-E15-D5-B2(2-B27-Y)2-B27-J2-QA25-AJ2-K2A23-2AH3-H2A21-2AB4-F3A19-3AS5-DB2A17-2ADA8-MDB15-BAY13-T13-E17-2Q9-AE14-C19-I10-C19-C10-C19-H10-I19-F10-C19-F10-G19-H10-F19-F10-B19-B10-B19-C10-BA17-AC10-LA17-AG10-MA17-AR11-D17-L12-Y17-L12-W17-Y12-2A15-AD12-AaA15-2A13-W15-J14-Aa15-D14-E15-E8-B5-Aa15-E5-B2-B27-Q2-B27-U2-BA25-AJ3-BA23-AB4-F2A21-2AF4-F3A19-3AB5-Ac3A17-3AE7-BHFA15-AB2D11-2B13-2B16-3D7-T2J45-G19-C10-C19-H10-C19-F10-C19-Ae10-O2(19-B10-C)19-F10-F19-B10-B19-F11-B17-F12-E17-H12-M17-K12-P17-A12-A17-Z12-Z17-D13-2(Aa15-B14-)L15-D14-E15-D14-J15-B9-J4-J15-B4-D4-J25-U4-D25-D4-KA23-AE4-BJA21-A2B5-B2A19-2AE6-FK2A17-2A2B7-F2BA15-AD2B10-FB15-TB14-BTBK7-EJ2B76-C17-H12-I17-I12-O17-I12-C17-H12-C17-D12-C17-B12-C17-F12-F17-B12-B17-H12-BA15-AF12-DA15-AH12-MA15-AB12-MA15-AU13-Q15-M14-A15-Ab14-2A13-AB14-DA13-AX14-JA13-AK14-JA13-AB14-EA13-AK10-JLD2-A13-K2-UDQ6-ELA19-A2D6-EYA19-AED6-D2A19-ABD7-KD19-LA8-DQDA15-A2LA9-2DE15-QLD12-D15-A15-4BT5-D2LDK108-CG13-CO14-IC13-2I14-2F13-HC14-CF13-IF14-GC13-JR14-CG13-BF14-IF13-BF14-2F13-2B14-BF13-2B14-2B13-2F14-2D13-UK14-2P13-UK14-2M13-MA14-2DA11-A2M14-ABA11-A2D15-2(BA11-AB16-)BA11-AK16-JA11-AB16-EA11-AK14-LADA11-ABKU11-2LEA13-A2BD10-YNA15-AEB10-AEA15-AED11-ED15-AL13-ED13-NL15-2DADED3-2DBD2E16-KQDKD5-B2DAD141-2(CG)2AiROICR2B18-CI2COCROHO2HE18-F4ICRUOHBFB18-3B2HFCIOHFCI18-OH3FHFO4HB18-2CIH2K3HF2HB18-2F2H6FBHB18-2FCAdC5FH2B18-3FH2DKBH3FH18-2B2DK3BK2DKH18-T2BKJAPD2BK2U18-PQ2A3DVM2AAbA18-MP2MA2P2MAPMV18-2DAQD2AMA2BDM18-2DQ3BSJET3B18-BKD5BDJ3B18-2BHKDAK5BK18-3BDAD3BK2BK18-TJ2EN3ED2QRK18-2ENEJ3EDQU2K18-EN2L2D2BFH3B17-LENE6BE3DK15-4EBHDBTEB3ENLE14-2EBEBDEDTJ3EN2LN15-DEJQPE2DEJEDALE17-DAYA2E-ELE2DL195-
