model
size = 31 32 17, scale = 0.05, origin = -y
material deform = 1, fade = true, lighting = smooth, roughness = 0.3, metalness = 0.6
  colors = A:#070707 B:#C93 C:#FC3 D:#630 E:#963 F:#FC0
voxels
8-15A16-2AD4AE4AD2A16-D2AE7AE2AD16-AD3(2AB)2ADA16-2AD2AC3AC2AD2A16-3AE3AC3AE3A16-D3AB5AB3AD16-AE2(3AC)3AEA16-2A2(B4A)B2A16-E2(2AC)2B2AC2AE16-AB4ACEB4ABA16-2AC2A2C3B2AC2A16-C3A3CE3B3AC17-3A2CECE2B3A18-2A2CEB2CE2B2A18-A2CE2BEFCE2BA18-2FE3BC3FE2F18-A5BE5FA18-2A4BC4F2A18-2A4BE4F2A18-3A3BC3F3A17-AC2A3BE3F2ACA14-2AB4A2B3F4AB2A12-AE6ABEF6AEA12-D3AC3AB2F3AC3AD13-2AB5AC5AB2A15-E3AC5AC3AE16-3AB3AF3AB3A18-E9AE20-2AF2AB2AF2A21-B7AB49-A15-A14-D15-D14-A15-A2(2(14-17A)14-D15AD)2(14-17A)14-B15AB2(14-17A)14-C15AC15-4(15A16-)C13AC11-4A-15A-4A6-3AE17AE3A6-2AD19AD2A6-AD21ADA7-23A8-AD19ADA9-21A12-D15AD15-15A17-D11AD19-11A22-3AE3A18-D17-D3(12-A17-A)12-D17-D2(12-A17-A)12-D17-D12-A17-A12-2A15-2A12-EA15-AE2(12-2A15-2A)13-4(A15-A14-)F15-C14-2(A15-)A13-A10-A5-A13-A5-2(A4-)2A13-2A2(4-A)25-A4-2A23-2A4-ADA21-ADA5-3A19-3A6-AD2A17-2ADA7-4A16-3A10-DA15-AD14-2A11-2A17-2A9-2A20-A7-A16-3(A19-A10-)D19-D2(10-A19-A)10-D19-D2(10-A19-A)11-4(A17-A12-)B17-B12-A17-A13-2(A15-A14-)B15-B2(14-A15-A)8-A5-B15-B5-2(A2-A27-)A2-2A25-2A3-2A23-2A4-D2A21-2AD4-4A19-4A5-D3A17-3AD7-4A15-4A11-2(A15-)D13-D17-AE9-EA14-9(A19-A10-)DA17-AD2(10-2A17-2A)11-2(A17-A12-)A17-A13-2(A15-A14-)E15-E2(14-A15-A)8-A5-A15-A5-2(A2-A27-)A2-A26-2A2-2A25-2A2-3A23-3A3-3A21-3A4-4A19-4A5-4A17-4A8-3A15-2AD2(13-A)17-A11-A14-12(A19-A10-)E19-E2(10-A19-A)11-3(A17-A12-)A17-A13-A15-A7-A6-A15-A6-2A2(28-3A)28-2A-A26-2A2-2A25-2A2-3A23-3A3-3A21-3A5-4A17-4A7-4A15-4A11-2A14-A16-A12-A13-15(A19-A10-)2A17-2A10-2A17-2A11-2(A17-A12-)2A15-2A2(6-A)15-A6-2A3(28-3A)28-2A-A26-2A2-2A25-2A3-2A23-2A4-3A21-3A6-2A19-2A10-2A15-2A14-2(A13-)15(A19-A10-)2(2A17-2A10-)2A17-2A11-A17-A12-2A15-2A6-A5-2A15-2A5-2A4(28-3A)28-2A-A26-2A2-2A25-2A3-2A23-2A5-3A19-3A9-2A15-2A14-2(A13-)15(A19-A10-)4(2A17-2A10-)3A15-3A5-A5-2A15-2A5-2A4(28-3A)28-2A-A26-2A2-2A25-2A3-2A23-2A5-3A19-3A9-2A15-2A14-2(A13-)15(A19-A10-)2(2A17-2A10-)2A17-2A11-A17-A12-2A15-2A6-A5-2A15-2A5-2A3(28-3A)28-2A-A26-2A2-2A25-2A3-2A23-2A4-3A21-3A6-2A19-2A10-2A15-2A14-2(A13-)15(A19-A10-)2A17-2A10-2A17-2A11-2(A17-A12-)2A15-2A2(6-A)15-A6-2A2(28-3A)28-2A-A26-2A2-2A25-2A2-3A23-3A3-3A21-3A5-3A19-3A7-4A15-4A11-2(A15-)2(A13-)12(A19-A10-)E19-E2(10-A19-A)11-3(A17-A12-)A17-A13-A15-A8-A5-A15-A5-3(A2-A27-)A2-2A25-2A2-3A23-3A3-3A21-3A4-4A19-4A5-4A17-4A8-D2A15-2A2(D13-)D17-2A9-2A14-9(A19-A10-)DA17-AD2(10-2A17-2A)11-3(A17-A12-)2A15-2A12-2A15-2A13-E15-E2(14-A15-A)8-A5-A15-A5-2(A2-A27-)A2-2A25-2A3-2A23-2A4-D2A21-2AD4-4A19-4A5-D3A17-3AD7-4A15-4A11-2A13-2A16-3A7-3A45-3(A19-A10-)D19-D2(10-A19-A)10-D19-D2(10-A19-A)11-4(A17-A12-)B17-B12-A17-A13-2(A15-A14-)B15-B2(14-A15-A)9-A4-A15-2(A4-)2(A25-A4-)2A23-2A4-ADA21-ADA5-3A19-3A6-AD2A17-2ADA7-4A15-4A10-DA15-AD14-AD2A7-2ADA76-D17-D3(12-A17-A)12-D17-D2(12-A17-A)12-D17-D12-A17-A12-2A15-2A12-EA15-AE2(12-2A15-2A)13-2(A15-A14-)2(2A13-2A14-)CA13-AC2(14-2A13-2A)10-3A2-A13-A2-2(3A6-3A19-)3A6-ADA19-ADA7-2A19-2A8-AD2A15-2ADA9-3A15-3A12-2(D15-)2AD2A5-2AD2A108-2A13-2A14-DA13-AD14-AD13-DA2(14-2A13-2A)14-DA13-AD14-AD13-DA14-2A13-2A14-DA13-AD14-AE13-EA14-2A13-2A14-BA13-AB14-AC13-CA14-3A11-3A14-C2A11-2AC15-4(2A11-2A16-)CA11-AC14-AB2A11-2ABA11-AE2A13-2AEA10-D2A15-2AD10-3A15-3A11-DA15-AD2(13-2A)15-D3ABA3-AB3AD16-3AEA5-AE3A141-13A18-AD4AE4ADA18-2AE7AE2A18-D3(2AB)2AD18-AD2AC3AC2ADA18-2AE3AC3AE2A18-3AB5AB3A18-E2(3AC)3AE18-AB4AC4ABA18-2AC2AB2C2AC2A18-B4ABEC4AB18-AC2A2B3C2ACA18-3A3BE3C3A18-3A2BECE2C3A18-2A2BECEBE2C2A18-A2BE3C2BE2CA18-2CE3CE3BE2C18-A6C5BA18-2A4CE4B2A18-2A5C4B2A18-3A3CE3B3A17-AC3A3C2B3ACA15-AB5ACEB5ABA14-E3AC2A2CB2AC3AE15-2AB4AC4AB2A17-E3ACA-AC3AE195-
