model
size = 31 32 17, scale = 0.05, origin = -y
material deform = 1, fade = true, lighting = smooth, roughness = 0.3, metalness = 0.6
  colors = A:#9D001A B:#7F0015 C:#B31023 D:#820015 E:#950018 F:#8D0017 G:#E7153C H:#870016 I:#CF5179 J:#D92B4B K:#710012 L:#770013 M:#43000B N:#48000B O:#4E000C P:#2F0007 Q:#56000C R:#C680BF S:#7C0014 T:#350008 U:#3A0009 V:#5E000F W:#320008 X:#660010 Y:#270006 Z:#2A0006 Aa:#2F000F Ab:#1C0004 Ac:#0F0002 Ad:#060001 Ae:#6F54A5 Af:#C99C87 Ag:#EFC5B0
voxels
8-15Ad16-15Ac16-15Ab16-15Y16-15Z16-15P16-15W16-15T16-15U16-15M16-15N16-15O16-15Q17-13V18-13X18-13K18-13L18-13S2(18-13B)18-13D17-15H14-19F12-19E12-19A13-17C15-15G16-7JAfAg6J18-5I2Ag4I20-4RAfAg5R21-3Ae2Ag4Ae49-Ad15-Ad14-Ac15-Ac14-Ab15-Ab14-17Y14-17Z14-17P14-17W14-17T14-17U14-17M14-17N14-17O14-17Q14-17V14-17X15-15K16-15L16-15S2(16-15B)11-4D-15D-4D6-5HAa13HAa5H6-25F6-25E7-23A8-23C9-21G12-17J15-15I17-13R19-11Ae22-7A18-Ad17-Ad12-Ac17-Ac12-Ab17-Ab12-Y17-Y12-P17-Z12-P17-P12-W17-W12-T17-T12-U17-U12-2M15-2M12-2N15-2N12-2O15-NO12-2Q15-2Q13-V15-V14-X15-X14-K15-K14-L15-L14-S15-S14-2(B15-)B13-B10-D5-D13-D5-D4-H4-2H13-2H4-H4-F25-F4-2E23-2E4-3A21-3A5-CAaC19-CAaC6-2GAaG17-GAa2G7-4J16-3J10-2I15-2I14-2R11-2R17-2Ae9-2Ae20-A7-A16-Ad19-Ad10-Ac19-Ac10-Ab19-Ab10-Y19-Y10-P19-Z10-P19-P10-W19-W10-T19-T10-U19-U11-M17-M12-N17-N12-O17-O12-Q17-Q12-V17-V12-X17-X13-K15-K14-L15-L14-S15-S2(14-B15-B)8-D5-D15-D5-D2-H27-H2-F27-F2-2E25-2E3-2A23-2A4-CAaC21-CAaC4-G2AaG19-G2AaG5-J2AaJ17-J2AaJ7-4I15-4I11-2(R15-)Ae13-Ae17-2A9-2A14-Ad19-Ad10-Ac19-Ac10-Ab19-Ab10-Y19-Y10-P19-Z10-P19-P10-W19-W10-T19-T10-U19-U10-2M17-2M10-2N17-2N10-2O17-2O11-Q17-Q12-V17-V12-X17-X13-K15-K14-L15-L14-S15-S2(14-B15-B)8-D5-D15-D5-D2-H27-H2-F27-F2-E26-2E2-2A25-2A2-CAaC23-CAaC3-GAaG21-GAaG4-J2AaJ19-J2AaJ5-2IAaI17-IAa2I8-3R15-3R2(13-Ae)17-A11-A14-Af19-Ad10-Ag19-Ac10-Ab19-Ab10-Y19-Y10-P19-Z10-P19-P10-W19-W10-T19-T10-U19-U10-M19-M10-N19-N10-O19-O10-Q19-Q10-V19-V10-X19-X11-K17-K12-L17-L12-S17-S12-B17-B13-B15-B7-D6-D15-D6-DH28-2HF28-2FE28-2E-A26-2A2-2C25-2C2-GAaG23-GAaG3-JAaJ21-JAaJ5-IAa2I17-2IAaI7-4R15-4R11-2Ae14-Ae16-A12-A13-Af19-Ad10-Af19-Ac10-Ab19-Ab10-Y19-Y10-P19-Z10-P19-P10-W19-W10-T19-T10-U19-U10-M19-M10-N19-N10-O19-O10-Q19-Q10-V19-V10-X19-X10-2K17-2K10-2L17-2L11-S17-S12-B17-B12-2B15-2B2(6-D)15-D6-DH28-2HF28-2FE28-2EA28-2A-C26-2C2-2G25-2G3-2J23-2J4-3I21-3I6-2R19-2R10-2Ae15-2Ae14-2(A13-)Ad19-C10-Af19-Ac10-Ag19-Ab10-Y19-Y10-P19-Z10-P19-P10-W19-W10-T19-T10-U19-A10-M19-A10-N19-C10-O19-C10-Q19-Q10-A19-V10-A19-X10-2K17-2K10-2L17-2L10-2S17-2S11-B17-B12-2B15-2B6-A5-2D15-2D5-2A28-HCF28-FCE28-2EA28-3A28-CA-A26-GC2-AJ25-JC3-AI23-2I5-2AR19-2AC9-2Ae15-AeC14-2(A13-)A2(19-A10-Af)19-A10-A19-Y10-A19-Z10-A19-C10-C19-A10-T19-A10-U19-U10-A19-M3(10-A19-A)10-V19-A10-C19-X10-AK17-2K10-AL17-LC10-CS17-SA10-CB17-BA10-AAaB15-BAaA5-D5-AD15-DA5-DC28-HCA28-F2A28-E2A28-2AC28-2C-G26-2G2-CJ25-JA3-2I23-IA5-C2A19-2RA9-CA15-2A14-2(A13-)C19-C10-C19-Ac10-Ab19-C2(10-C19-A)10-P19-A10-A19-W10-A19-T10-A19-U10-C19-M10-C19-N10-O19-O10-Q19-Q10-V19-V10-X19-A10-2K17-KA10-2L17-LA10-AS17-SC11-A17-C12-2B15-2B6-D5-2D15-2D5-DH28-2HF28-2FE28-2EA28-2A-C26-2C2-2G25-2G3-2J23-2J4-3I21-3I6-2R19-2R10-2Ae15-2Ae14-2(A13-)Ad19-Ad10-Ac19-Ac10-Ab19-Ab10-Y19-Y10-Z19-Z10-P19-P10-W19-W10-T19-T10-U19-U10-M19-M10-N19-N10-O19-O10-Q19-Q10-V19-V10-X19-X10-2K17-2K10-2L17-2L11-S17-S12-B17-B12-2B15-2B2(6-D)15-D6-DH28-2HF28-2FE28-2E-A26-2A2-2C25-2C2-GAaG23-GAaG3-JAaJ21-JAaJ5-IAaI19-IAaI7-4R15-4R11-2(Ae15-)2(A13-)Ad19-Ad10-Ac19-Ac10-Ab19-Ab10-Z19-Y10-Aa19-Z10-P19-P10-W19-W10-T19-T10-U19-U10-M19-M10-N19-N10-O19-O10-Q19-Q10-V19-V10-X19-X11-K17-K12-L17-L12-S17-S12-B17-B13-B15-B8-D5-D15-D5-D2-H27-H2-F27-F2-E27-E2-2A25-2A2-CAaC23-CAaC3-GAaG21-GAaG4-J2AaJ19-J2AaJ5-2IAaI17-IAa2I8-3R15-3R2(13-Ae)17-CA9-2A14-Ad19-Ad10-Ac19-Ac10-Ab19-Ab10-Y19-Y10-Z19-Z10-P19-P10-W19-W10-T19-T10-U19-U10-2M17-2M10-2N17-2N10-2O17-2O11-Q17-Q12-V17-V12-X17-X12-2K15-2K12-2L15-2L13-S15-S2(14-B15-B)8-D5-D15-D5-D2-H27-H2-F27-F2-2E25-2E3-2A23-2A4-CAaC21-CAaC4-G2AaG19-G2AaG5-J2AaJ17-J2AaJ7-4I15-4I11-2R13-2R16-2AeA7-A2Ae45-Ad19-Ad10-Ac19-Ac10-Ab19-Ab10-Y19-Y10-Z19-Z10-P19-P10-W19-W10-T19-T10-U19-U11-M17-M12-N17-N12-O17-O12-Q17-Q12-V17-V12-X17-X13-K15-K14-L15-L14-S15-S2(14-B15-B)9-D4-D15-2(D4-)H25-H4-F25-F4-2E23-2E4-3A21-3A5-CAaC19-CAaC6-2GAaG17-GAa2G7-4J15-4J10-2I15-2I14-3RC7-A3R76-Ad17-Ad12-Ac17-Ac12-Ab17-Ab12-Y17-Y12-Z17-Z12-P17-P12-W17-W12-T17-T12-U17-U12-2M15-2M12-2N15-2N12-2O15-2O12-2Q15-2Q13-V15-V14-X15-X14-2K13-2K14-2L13-2L14-2S13-2S14-2B13-2B15-B13-B11-3D2-D13-D2-3D6-3H19-3H6-3F19-3F6-3E19-3E7-2A19-2A8-4C15-4C9-3G15-3G12-2(J15-)4IA5-A4I108-2Ad13-2Ad14-2Ac13-2Ac14-2Ab13-2Ab14-2Y13-2Y14-2Z13-2Z14-2P13-2P14-2W13-2W14-2T13-2T14-2U13-2U14-2M13-2M14-2N13-2N14-2O13-2O14-2Q13-2Q14-3V11-3V14-3X11-3X15-2K11-2K16-2L11-2L16-2S11-2S2(16-2B11-2B)14-2(4D11-)4H13-4H10-3F15-3F10-3E15-3E11-2A15-2A2(13-2C)15-5GA3-A5G16-4JA5-A4J141-13Ad18-13Ac18-13Ab18-13Y18-13Z18-13P18-13W18-13T18-13U18-13M18-13N18-13O18-13Q18-13V18-13X18-13K18-13L18-13S2(18-13B)18-13D17-15H15-17F14-8EA8E15-7A-7A17-4CA3-A4C195-
