model
size = 31 32 17, scale = 0.05, origin = -y
material deform = 1, fade = true, lighting = smooth, roughness = 0.3, metalness = 0.6
  colors = A:#100 B:#66F C:#9F0 D:#CF0 E:#06C F:#0C0 G:#0F6 H:#30C I:#360 J:#396 K:#3CC L:#F90 M:#FCF
voxels
8-2(2(BA)B4A3(BA)16-3(AB)2A3(BA)B16-)2(BA)B4A3(BA)16-3ABAB2ABAB3A3(B16-2(BA)B4A3(BA)16-3(AB)2A3(BA))B16-2(BA)B4A3(BA)17-2(2ABAB)3A3(18-2(AB)4A2(BA)B18-2(BA)B2A3(BA))18-2(AB)4A2(BA)B17-3ABAB2AB5AB14-3(BA)B4ABAB5A12-3A2(BA)B2AB3A2(BA)B12-2A2(BA)B4A2(B3A)13-6AB2AB7A15-15A16-5AB2AB6A18-11A20-3AB2AB4A21-9A49-A15-B14-B15-A14-A15-B5(14-2(BA)B6A3(BA)14-ABA3B4A3B2(AB))14-2ABAB6ABAB3A14-ABA3B4A3BAB2A15-2(2(AB)6A2(BA)B16-BA3B4A3BABA16-)2(AB)6A2(BA)B11-3AB-BA3B4A3BABA-4A6-BAB3ABAB6A2(BA)B5A6-3A2(BA)3B4A3B4(AB)6-2A3(BA)B6A3(BA)B3A7-2A2(BA)3B4A3B2(AB)3A8-3A2(BA)B6A2(BA)B4A9-3ABA3B4A3BAB4A12-2ABAB6A3(BA)15-2A3B5A2B3A17-2AB6AB3A19-11A22-7A18-4(B17-A12-A17-B12-)B17-A12-AB15-AB12-2B15-BA12-AB15-AB12-AB15-2A13-2(B15-A14-A15-B14-)B15-A14-A2(15-B)13-A10-A5-B13-B5-2(A4-)2B13-BA4-B4-A25-A4-2B23-2B4-2AB21-B2A5-A2B19-2BA6-2A2B17-2B2A7-3AB16-3A10-2A15-2A14-AB11-BA17-2A9-2A20-A7-A16-A19-A10-B3(19-A10-A)2(19-A10-B19-A10-A)19-A11-A17-B12-A17-A12-B17-B12-A17-A12-A17-B12-B17-A13-2(A15-B14-B15-A14-)A15-A8-A5-A15-B5-A2-A27-A2-B27-B2-AB25-2A3-2B23-2B4-A2B21-B2A4-A3B19-3BA5-A3B17-AB2A7-3AB15-B3A11-2(A15-)A13-A17-2A9-2A14-4(B19-B10-A19-A10-)B19-B10-AB17-2A10-2B17-2B10-AB17-2A11-B17-B12-A17-A12-A17-B13-2(B15-A14-A15-B14-)B15-A8-A5-A15-A5-A2-B27-B2-A27-A2-B26-2B2-AB25-2A2-A2B23-2BA3-A2B21-B2A4-A3B19-3BA5-2A2B17-2B2A8-3A15-3A2(13-A)17-A11-A14-6(A19-A10-B19-B10-)A19-A10-B19-A10-A19-A11-A17-B12-B17-A12-A17-B12-B17-A13-A15-B7-A6-B15-B6-2A28-2AB28-2BA28-2A-B26-2B2-AB25-2A2-A2B23-2BA3-A2B21-B2A5-4B17-4B7-2(AB)15-4A11-2A14-A16-A12-A13-7(B19-B10-A19-A10-)B19-B10-AB17-2A10-AB17-AB11-B17-A12-A17-B12-AB15-2A2(6-A)15-A6-A2(B28-2BA28-2A)-B26-2B2-AB25-2A3-2B23-2B4-2AB21-B2A6-2A19-2A10-2A15-2A14-2(A13-)2(A19-A10-A2(19-B10-A19-A10-B)19-B10-)A19-A10-A19-B10-A19-A10-2B17-2B2(10-AB17-2A)11-B17-A12-AB15-AB6-A5-2B15-2B5-2A28-3A28-ABA28-2AB28-2BA28-2A-A26-2B2-AB25-2A3-AB23-BA5-3A19-3A9-2A15-2A14-2(A13-)7(B19-B10-A19-A10-)B19-B10-AB17-2A10-2B17-2B10-AB17-2A10-AB17-AB10-3B15-2B2(A5-)AB15-AB5-AB28-2BA28-3A28-ABA28-2AB28-BA-A26-2A2-2B25-2B3-AB23-2A5-3A19-BAB9-2A15-2A14-2(A13-)3(A19-A10-B19-B10-)A19-A10-B19-A3(10-A19-A10-B19-B)10-A19-A10-2B17-2B10-AB17-2A10-2B17-2B11-A17-A12-2B15-2B6-A5-2B15-2B5-2A28-2AB28-2BA28-3A28-AB-A26-2A2-AB25-2B3-AB23-2A4-2AB21-A2B6-AB19-2A10-2A15-2A14-2(A13-)7(B19-B10-A19-A10-)B19-B10-2B17-BA10-AB17-AB11-A17-A12-A17-B12-AB15-2A2(6-A)15-B6-AB28-B2A28-2AB28-BA-A26-AB2-2B25-2B2-A2B23-B2A3-A2B21-2BA5-A2B19-B2A7-3AB15-B3A11-2(A15-)2(A13-)7(A19-A10-B19-B10-)A19-A11-B17-B12-A17-A12-A17-B12-B17-A13-B15-B8-A5-B15-B5-A2-A27-A2-B27-B2-A27-A2-2B25-BA2-A2B23-3A3-A2B21-3B4-A3B19-2B2A5-A3B17-2B2A8-3A15-2AB2(13-A)17-2A9-2A14-2(B19-B10-A19-A10-)A19-B10-A19-A10-B19-B10-A19-A10-A19-B10-AB17-2A10-2B17-2B10-AB17-2A11-A17-B12-A17-A12-B17-B12-AB15-2A12-2B15-2B13-B15-A14-A15-B14-B15-A8-A5-A15-B5-A2-A27-B2-A27-A2-AB25-AB3-AB23-AB4-3B21-2BA4-A3B19-2B2A5-A3B17-2BAB7-A3B15-B3A11-2A13-2A16-3A7-3A45-4(A19-A10-B19-B10-)A19-A11-B17-A12-A2(17-B12-B)17-A12-A17-B12-A17-A13-B15-B14-A15-A14-A15-B14-B15-A14-A15-B9-A4-B15-2(A4-)B25-A4-A25-B4-2B23-BA4-A2B21-B2A5-A2B19-BAB6-2A2B17-2(BA)7-3AB15-2(BA)10-2A15-2A14-4A7-4A76-4(B17-A12-A17-B12-)B17-A12-AB15-AB12-2B15-BA12-AB15-AB12-AB15-2A13-2(B15-B14-)2(2B13-BA14-AB13-AB14-)2B13-BA10-2AB2-B13-B2-3A6-A2B19-BAB6-BAB19-ABA6-2AB19-BAB7-AB19-AB8-2A2B15-2(BA)9-BAB15-3A12-2(A15-)5A5-5A108-2(AB13-AB14-2A13-2A14-AB13-AB14-2B13-BA14-)2(AB13-AB14-2B13-BA14-)AB13-AB14-3B11-2BA14-A2B11-BAB15-2(AB11-AB16-2B11-BA16-)AB11-AB14-A3B11-2BAB11-2(AB)13-2(AB)10-BAB15-ABA10-A2B15-BAB11-AB15-2A2(13-AB)15-6A3-5AB16-5A5-5A141-2(BA)B2A3(BA)18-2(AB)A2B3(AB)18-2(BA)B2C3(BA)18-ABADC2DCD2(AB)18-BADCD2CDCDABA18-E2CDC2DCD2CEB18-2ADCD2CDCD3A18-F2CDC2DCD2CFB18-2ADCD2CDCD3A18-G2CDC2DCD2CGB18-2ADCD2CDCD3A18-H2CDC2ACD2CHB18-2(2ADCD)3A18-I2CDC2ACD2CIB18-2(2ADCD)3A18-J2CA4CA2CJB18-5A2C5AB18-K2CA4CA2CKB18-2ACDC2DCDC3A18-L2(CD)2C2(DC)LB18-2ACDC2DCDC3A17-BM2(CD)2C2(DC)MBA15-2(BA)CDC2DCDC2(AB)A14-2(AB)2AD2CD2ABAB2A15-2(AB)6AB3AB17-6A-3AB2A195-
