model
size = 31 32 17, scale = 0.05, origin = -y
material deform = 1, fade = true, lighting = smooth, roughness = 0.3, metalness = 0.6
  colors = A:#609 B:#570084 C:#7C00BB D:#411484 E:#F0C F:#5D1DBE G:#F3F H:#39C I:#0FF J:#0C3 K:#E900FF L:#5134C4 M:#0F6 N:#FF6CFF
voxels
8-3EJM4E5KE16-2BJ2BM5B4D16-2BJ2BM4B2DH2D16-2BJ5B2DH4D16-3J2M2B2DB2DH2D16-A2JM6BHBH2D16-A2JMA5BHDH2D16-3J2M2A6BDB16-2BJ4A2D2HBHIA16-DJ2M4DHABH2AI16-DJ2M3DH7A16-2BMB3DH7A16-4B2D2B2(H2A)I17-3B2D3A2HA2I18-3B2D6A2B18-4ED6A2B18-AGADG5A3B18-2(EA)G4ABM2B18-4AG2A2B2(MB)18-E3G2A4BMBA18-13A17-7AH7A14-F5AH2AH2FH3AF2A12-3AH8F3AH3F12-4FH2F5H2AH3AF13-AF3A2H2(AH)I5A15-F3A2HAHA2I4C16-2(2AH)4I2CI2C18-2A9C20-2CH2(2CI)2C21-4CI4C49-K15-K2(14-B15-D)3(14-16BD)14-17B14-13B2(4A14-D12B)4A2(14-D2B13AI)14-3B13AB14-3B12A2B14-3B13AB15-2B12A2(B16-E13A)B16-E14A16-15A11-3KE-15A-3EK6-AE21AEA6-FEF20AEA6-2FE19AEAF7-FE19AEF8-FAE17AE2A9-FEF15ACEA12-G15AE15-13A2C17-C11AC19-C9AC22-2E4KE18-K17-K12-B17-B12-B17-D12-D3(17-D12-B)17-B2(12-D17-A)12-D2(B15-2A12-A)B15-2A12-2B15-AB13-3(B15-B14-)2(A15-A14-)2(A15-)A13-A10-K5-A13-A5-K4-A4-2A13-2A4-A4-F25-A4-FA23-AF4-AFA21-2AF5-3A19-2AF6-FE2A17-2AJA7-FGFA16-CJA10-AG15-GA14-GA11-AG17-GA9-AG20-G7-E16-K19-K2(10-B19-B)10-D19-B2(10-B19-D)3(10-D19-A)11-4(A17-A12-)B17-B12-B17-H13-B2(15-H14-A)2(15-A14-A)15-A8-K5-A15-A5-K2-E27-E2-F27-A2-FA25-AF3-2A23-AF4-3A21-2AF4-F3A19-4A5-E3A17-3AJ7-G3A15-3AJ11-2(C15-)C13-C17-2G9-EK14-K19-E10-B2(19-B10-D)19-A4(10-D19-E)10-D19-A10-EA2(17-2A10-2A)17-2A11-A17-A12-B17-H12-A17-B13-2(A15-H14-A15-A14-)A15-A8-E5-A15-A5-E2-E27-A2-A27-A2-F26-AF2-FA25-AF2-F2A23-2AF3-F2A21-2AF4-4A19-4A5-4A17-4A8-A2C15-3A13-L13-C17-G11-K14-E19-E10-D19-D10-D19-B10-D19-E10-E3(19-A10-D)19-A10-B19-E10-E19-A10-B2(19-A10-A)19-B10-E19-H10-A19-B11-2(A17-A12-)A17-I12-A17-A13-A15-A7-E6-A15-A6-EA2(28-3A)28-2A-A26-AE2-2A25-AF2-F2A23-2AE3-3A21-2AF5-L3A17-4A7-A2CA15-4A11-2L14-C16-G12-K13-E19-E10-D19-D10-E19-B10-E19-E2(10-E19-A)2(10-E19-E10-E19-A)10-B19-B10-B19-E10-E19-B10-A19-I10-G19-B10-2A17-AI10-2A17-2A11-A17-I12-A17-A12-2A15-2A6-E6-A15-A6-EA28-3A2(28-2AH)28-AE-A26-AE2-FA25-AG3-2A23-AG4-3A21-3A6-2L19-2A10-2L15-2C14-G13-K13-E19-E10-D19-D10-D19-B10-D19-A10-D19-E10-E19-A10-D2(19-A10-E19-A10-B19-E10-B)19-B10-G19-B10-B19-I10-BA17-AI10-2A17-AI10-HA17-2A11-A17-A12-2A15-2A6-E5-2A15-2A5-2E28-AEA2(28-2AH)28-2AI28-AE-I26-AG2-IA25-AG3-2A23-AG5-2CL19-C2A9-2L15-2C14-G2(13-E)19-E10-D19-D10-G19-D2(10-D19-A)10-D19-E10-E19-A10-B19-A10-E19-A10-B19-G10-G19-G10-B2(19-A10-A)2(19-B10-B)A17-2A10-HA17-2A10-2A17-2A10-IA17-2A10-3A15-3A5-E5-2A15-2A5-EA3(28-3A)28-AGF28-AG-F26-AG2-IC25-CG3-2C23-CA5-2CL19-C2A9-2L15-2C14-G2(13-E)19-E2(10-D19-D)10-G19-A10-D19-E10-E19-A10-E19-E10-A19-A10-A19-G3(10-G19-A)2(10-A19-A)10-B19-B10-HA17-2A10-2A17-2A10-IA17-AJ11-A17-J12-2A15-2A6-E5-2A15-2A5-EA28-3A2(28-2AH)28-AG-F26-AF2-FC25-AG3-HC23-CA4-2CA21-C2A6-CL19-2A10-2L15-CA14-G13-E13-G19-E2(10-D19-D)10-D19-E10-G19-A10-D19-E10-E2(19-E10-A)19-G2(10-B19-A)10-G2(19-A10-A)19-A10-B19-B10-BA17-AB10-IA17-AJ11-A17-A12-I17-A12-2A15-AJ6-E6-A15-A6-2E28-AEA28-2AH28-2A-H26-2A2-HC25-AF2-H2C23-3A3-HCA21-2CA5-CAC19-2CA7-2CLC15-2C2A11-L15-C15-2(G13-)G19-E10-B2(19-D10-D)19-E2(10-D19-A)10-D19-E10-G19-A10-B19-G2(10-B19-A)10-G2(19-A10-A)19-B10-B19-B11-B17-J12-B17-A12-I17-A12-A17-J13-A15-C8-E5-A15-C5-E2(2-A27-A)2-C27-A2-FC25-2A2-F2C23-2AF3-2CA21-CAF4-2CAC19-2CAF5-4C17-2C2A8-ICL15-2CA13-L13-C17-2N9-2G14-G19-E10-B2(19-D10-D)19-A10-D19-E10-D3(19-G10-B)19-3(A10-2A17-C)A11-2(A17-A12-)B17-2(B12-BA15-C)J13-A15-C14-A15-A14-A15-J8-E5-A15-C5-G2-A27-A2-A27-F2-AC25-2A3-FC23-AF4-FCA21-CAF4-2CAC19-2CAF5-CA2C17-3CA7-2(HC)15-C3A11-CL13-2C16-L2N7-2GC45-G19-E10-B2(19-D10-D)19-B4(10-D19-A)10-B19-A11-3(A17-A12-)I17-A12-A17-G12-B17-B13-B15-B14-B15-C2(14-A15-J)14-A15-A9-G4-A15-C4-G4-E25-E4-A25-F4-2A23-AF4-2FC21-C2F5-F2C19-2CF6-2A2C17-2C2A7-AHAC15-C3A10-HA15-2A14-3LN7-G3C76-G17-E2(12-D17-D)12-D17-B12-M17-A12-D17-D3(12-B17-B)12-2A15-CA2(12-2A15-CE)12-IA15-CE13-A15-E14-A15-2(B14-BA13-C)2(A14-2A13-C)A15-A13-C11-3G2-A13-C2-3G6-AGC19-CNA6-AGC19-CNF6-FGC19-CNF7-FG19-NF8-AFGC15-CN2A9-2AG15-G2A12-2(A15-)ACG2N5-3G2C108-2G13-GE14-2D13-BD14-DJ13-2D14-JD13-HD14-BM13-DH14-MB13-DH14-BM13-HB2(14-2B13-2B)14-BA2(13-2E14-HB)13-BE14-BH13-BG14-IBA11-C2G14-IBA11-C2N15-2(BA11-CA16-)2(2A11-CA16-)2A11-CF14-3AC11-CF2A11-3AC13-C2FA10-2FC15-C2F10-2FC15-CAF11-2F15-2(2A13-)2A15-2A3CN3-G4CA16-2G2CN5-G2C2G141-13G18-7D6B18-2D2B2DG3D2BH18-JD4BGB3DHD18-BJ4BE2ABI2D18-M2B2ABE3AIBI18-3BAGAE3ABIA18-AB2(GA)E3A3B18-AG6EAB3A18-BG5AEAB2AG18-BNA3GAE5B18-BN2(GA)GE5B18-BN2AG2AE5B18-4B4A5B18-2B10AN18-B2AH6AH2A18-B3AIAH2FH3A18-3AI2A4FH2A18-4AFI2FI3FA18-4A9F18-4A2I2F2I3F17-AE4AIA2FI4F15-AGAE6A5FAF14-2AG4ACGC3AFJ2A15-4A2CG-G2CAMAJ17-2A2CG3-G2CAM195-
