model
size = 31 32 32, scale = 0.05, origin = -y
material deform = 1, fade = true, lighting = smooth, roughness = 0.3, metalness = 0.6
  colors = A:#FFF B:#90C C:#777 D:#BEBEBE E:#070707 F:#B00 G:#E00 H:#2F2F2F I:#A00 J:#D00 K:#F66 L:#FFC M:#800 N:#636 O:#C9C98D P:#639 Q:#959559 R:#6F6
voxels
263-F-F309-P5-P418-15A16-7ADAD5A16-6ADE7A16-7ADAD5A16-4AD4AED4A16-4A2(DA)D6A16-4AEDHDEDAD3A16-4A2DED2ED4A16-3AD6ED4A16-4ADH2EHEHD3A16-5AD2EHED4A16-4AD6ED3A16-4ADH4EHD3A17-4AD2EHEHD2A18-3AD5ED3A18-3ADH4EHD2A18-2AD5E2HEDA18-3ADH3E2HD2A18-2AD4E2HED2A18-A3DEH3E2D2A18-AD2L2OLE2D3A17-2ADL2Q2L2D5A14-4ADOQ3OD8A12-4ADHEOHED8A12-4AD5ED8A13-3AD5LD7A15-2A7D6A16-15A18-11A20-11A21-9A49-3(A15-A14-)11(17A14-)17A15-4(15A16-)15A11-4C-15A-4C3(6-25A)7-23A8-23A9-21A12-17A15-15A17-13A19-11A22-7C18-9(A17-A12-)3(2A15-2A12-)2A15-2A13-5(A15-A14-)2(A15-)A13-A10-C5-A13-A5-C4-A4-2A13-2A2(4-A)25-A4-2A23-2A4-3A21-3A5-3A19-3A6-4A17-4A7-4A16-3A10-2A15-2A14-2A11-2A17-2A9-2A20-C7-C16-8(A19-A10-)A19-A11-5(A17-A12-)A17-A13-4(A15-A14-)A15-A8-C5-A15-A5-C2(2-A27-A)2-2A25-2A3-2A23-2A4-3A21-3A4-4A19-4A5-4A17-4A7-4A15-4A11-2(A15-)A13-A17-2C9-2C14-9(A19-A10-)2(2A17-2A10-)2A17-2A11-2(A17-A12-)A17-A13-4(A15-A14-)A15-A8-C5-A15-A5-C2(2-A27-A)2-A26-2A2-2A25-2A2-3A23-3A3-3A21-3A4-4A19-4A5-4A17-4A8-3A15-3A2(13-A)17-C11-C14-14(A19-A10-)A19-A11-3(A17-A12-)A17-A13-A15-A7-C6-A15-A6-CA2(28-3A)28-2A-A26-2A2-2A25-2A2-3A23-3A3-3A21-3A5-4A17-4A7-4A15-4A11-2A14-A16-C12-C13-15(A19-A10-)2A17-2A10-2A17-2A11-2(A17-A12-)2A15-2A6-C6-A15-A6-CA3(28-3A)28-2A-A26-2A2-2A25-2A3-2A23-2A4-3A21-3A6-2A19-2A10-2A15-2A14-2(C13-)15(A19-A10-)2(2A17-2A10-)2A17-2A11-A17-A12-2A15-2A6-C5-2A15-2A5-CA4(28-3A)28-2A-A26-2A2-2A25-2A3-2A23-2A5-3A19-3A9-2A15-2A14-2(C13-)15(A19-A10-)4(2A17-2A10-)3A15-3A5-C5-2A15-2A5-CA4(28-3A)28-2A-A26-2A2-2A25-2A3-2A23-2A5-3A19-3A9-2A15-2A14-2(C13-)15(A19-A10-)2(2A17-2A10-)2A17-2A11-A17-A12-2A15-2A6-C5-2A15-2A5-CA3(28-3A)28-2A-A26-2A2-2A25-2A3-2A23-2A4-3A21-3A6-2A19-2A10-2A15-2A14-2(C13-)15(A19-A10-)2A17-2A10-2A17-2A11-2(A17-A12-)2A15-2A6-C6-A15-A6-CA2(28-3A)28-2A-A26-2A2-2A25-2A2-3A23-3A3-3A21-3A5-3A19-3A7-4A15-4A11-2(A15-)2(C13-)14(A19-A10-)A19-A11-3(A17-A12-)A17-A13-A15-A8-C5-A15-A5-C3(2-A27-A)2-2A25-2A2-3A23-3A3-3A21-3A4-4A19-4A5-4A17-4A8-3A15-3A2(13-A)17-2C9-2C14-9(A19-A10-)2(2A17-2A10-)2A17-2A11-3(A17-A12-)2A15-2A12-2A15-2A13-2(A15-A14-)A15-A8-C5-A15-A5-C2(2-A27-A)2-2A25-2A3-2A23-2A4-3A21-3A4-4A19-4A5-4A17-4A7-4A15-4A11-2A13-2A16-A2C7-2CA45-8(A19-A10-)A19-A11-5(A17-A12-)A17-A13-4(A15-A14-)A15-A9-C4-A15-A4-C2(4-A25-A)4-2A23-2A4-3A21-3A5-3A19-3A6-4A17-4A7-4A15-4A10-2A15-2A14-2A2C7-2C2A76-9(A17-A12-)3(2A15-2A12-)2A15-2A13-2(A15-A14-)4(2A13-2A14-)2A13-2A10-3C2-A13-A2-3C3(6-3A19-3A)7-2A19-2A8-4A15-4A9-3A15-3A12-2(A15-)2A3C5-3C2A108-13(2A13-2A14-)3A11-3A14-3A11-3A15-4(2A11-2A16-)2A11-2A14-2(4A11-)4A13-4A2(10-3A15-3A)11-2A15-2(2A13-)2A15-2A4C3-4C2A16-2A3C5-3C2A141-4AI8A2(18-2AI10A)18-8AI4A18-5AF7A18-5AJAF5A18-5AJAJ5A18-3AFAGAJ5A18-3AJAGKGF4A18-3AJKGF2GAM2A18-3AGFI2MIF3A18-2AKJM3GMGK2A18-2AIGFGAGMGK2A18-2A2GIGA2(GI)2A18-2A2KJIFKIGI2A18-3AGFJGFGJ3A18-3AGKGJ2G4A18-2AI2(AK)G5A17-15A16-9AD3ADA16-9A3(DA)15-10A5D2A14-12AD4A14-10A2DA2D2A15-7AC7A17-4A2C-2C4A457-G30-J29-GF-F27-F2I2F26-FIBIF26-FJF2K926-BFB28-JBF28-FBF836-G2(30-F)28-F2B28-3B28-2BF927-2(4B27-)BJ2B896-J30-2(J2B28-)3B928-2(4B27-)3BF926-2(5B26-)5B927-2(4B27-)4B927-2(3B28-)3B863-6(7B24-)7B799-7B24-2BHBH2B24-2B3H2B4(24-7B)799-7B24-2B-M-2B24-2B3-2B4(24-7B)25-N3-N25-2N3-2N737-7B27-M58-3(7B24-)7B55-N5-N673-3F29-F30-F7B23-3F2I28-A3-A25-7B24-2(BER)B24-2(B2E)B24-7B55-P5-P441-
