model
size = 32 31 31, scale = 0.05, origin = -y
material deform = 1, fade = true, lighting = smooth, roughness = 0.3, metalness = 0.6
  colors = A:#000 B:#FF0 C:#FFFF3A D:#FFFF64 E:#06C F:#F60 G:#3F85CC H:#691800 I:#0060C1 J:#1F0600 K:#ED5A00 L:#FFFF8B M:#000D17 N:#D00 O:#FF772D
voxels
77-G4-G475-O67-O29-O378-G97-7E25-7E313-7F25-7F55-O42-O499-4E5I4E19-4E5I4E307-4F5K4F17-O-4F5K4F79-O463-G49-3E2I7G2I3E15-3E2I7G2I3E303-3F2K7H2K3F15-3F2K7H2K3F590-2E2I2G7M2G2I2E13-2E2I2G7M2G2I2E301-2F2K2H7J2H2K2F13-2F2K2H7J2H2K2F65-O456-G65-2EI2G2M7A2M2GI2E11-2EI2G2M7A2M2GI2E299-2FK2H2J7A2J2HK2F11-2FK2H2J7A2J2HK2F10-O534-G40-2EIG2M11A2MGI2E9-2EIG2M11A2MGI2E297-2FKH2J11A2JHK2F9-2FKH2J11A2JHK2F461-2(15L17-)15D17-15D12-2EIGM15BMGI2E7-2EIGM15AMGI2E295-2FKHJ15AJHK2F7-2FKHJA13BAJHK2F13-13D19-D4ND6ND19-2CN3CN2C2(NC)18-3C6N2(CN)2C15-5CNCN4CN6C13-5C3NC6N4C13-6BN4BN7B14-3B3NB2NB4N3B16-2(3BN)2(BN)3B17-3B5NB3N3B19-11B21-11B22-9B51-4(L15-)D15-D11-G3-D15-D11-EIGMB15-BMGIE7-EIGM17AMGIE295-FKHJ17AJHKF7-FKHJA8B8AJHKF12-15D17-15D5-O6-4C-15C-4C7-5CB13CB5C2(7-25C)8-23B9-23B10-21B13-17B16-15B18-13B20-11B23-7B19-2(L17-L13-)D17-D13-D17-D9-2EIGB17-BGI2E5-2EIGM17AMGI2E293-2FKHJ17AJHK2F5-2FKHJB16AJHK2F10-D15-D16-D13-D11-C5-C13-2(C5-)C4-2C13-2C4-C5-C25-C5-2C23-2C5-3B21-3B6-3B19-3B7-4B17-4B8-4B16-3B11-2(2B15-)2B11-2B18-2B9-2B21-B7-B17-L19-L11-L19-L4-G6-D19-D11-D19-D8-EIGB19-BGIE5-EIGM19AMGIE293-FKHJ19AJHKF5-FKHJAB17AJHKF10-D15-D7-O7-D15-D9-C5-C15-C5-2(C3-C27-)C3-2C25-2C4-2B23-2B5-3B21-3B5-4B19-4B6-4B17-4B8-4B15-4B12-B15-B16-B13-B18-2B9-2B15-L19-L11-L19-L7-G3-D19-D11-D19-D8-EIGB19-BGIE5-EIGM19AMGIE293-FKHJ19AJHKF5-FKHJAB17AJHKF10-3(D15-)D9-C5-C15-C5-2(C3-C27-)C3-C26-2C3-2B25-2B3-3B23-3B4-3B21-3B5-4B19-4B6-4B17-4B9-3B15-3B14-B13-B18-B11-B15-2(L19-L11-)D19-D11-D19-D7-2EGMB19-BMG2E3-2EGM21AMG2E291-2FHJ21AJH2F3-2FHJAB17ABAJH2F8-D17-D14-D15-D8-C6-C15-C6-C3(-C28-2C)2-B26-2B3-2B25-2B3-3B23-3B4-3B21-3B6-4B17-4B8-4B15-4B12-2B14-B17-B12-B14-2(L19-L11-)D19-D3-G7-D19-D7-EIGMB19-BMGIE3-EIGM21AMGIE291-FKHJ21AJHKF3-FKHJAB17ABAJHKF8-D17-D13-2D15-2D6-OC6-C15-C6-C3(-C28-2C)-B28-2B2-B26-2B3-2B25-2B4-2B23-2B5-3B21-3B7-2B19-2B11-2(2B15-)B13-B14-2(L19-L11-)D19-D11-D19-D7-EIGMB19-BMGIE3-EIGM21AMGIE291-FKHJ21AJHKF3-FKHJAB17ABAJHKF8-D17-D13-2D15-2D5-O-C5-2C15-2C5-C3(-C28-2C)2(-B28-2B)2-B26-2B3-2B25-2B4-2B23-2B6-3B19-3B10-2(2B15-)B13-B14-L19-L5-G5-L19-L2(11-D19-D)4-G2-EIGMB19-BMGIE3-EIGM21AMGIE291-FKHJ21AJHKF3-FKHJ2B17A2BJHKF2-O4-2D17-2D11-DBD15-DBD6-C5-2C15-2C5-C3(-C28-2C)2(-B28-2B)2-B26-2B3-2B25-2B4-2B23-2B6-3B19-3B10-2(2B15-)B13-B14-2(L19-L11-)D19-D11-D19-D7-EIGMB19-BMGIE3-EIGM21AMGIE291-FKHJ21AJHKF3-FKHJAB17ABAJHKF8-D17-D13-2D15-2D7-C5-2C15-2C5-C3(-C28-2C)-B28-2B2-B26-2B3-2B25-2B4-2B23-2B5-3B21-3B7-2B19-2B11-2(2B15-)B13-B14-2(L19-L11-)D19-D11-D19-D7-EIGMB19-BMGIE3-EIGM21AMGIE291-FKHJ21AJHKF3-FKHJAB17ABAJHKF8-D17-D13-2D15-2D7-C6-C15-C6-C3(-C28-2C)2-B26-2B3-2B25-2B3-3B23-3B4-3B21-3B6-3B19-3B8-4B15-4B12-B15-B16-B13-B14-2(L19-L11-)D19-D7-G3-D19-D7-2EGMB19-BMG2E3-2EGM21AMG2E291-2FHJ21AJH2F3-2FHJAB17ABAJH2F8-D17-D14-D15-D9-C5-C15-C5-3(C3-C27-)C3-2B25-2B3-3B23-3B4-3B21-3B5-4B19-4B6-4B17-4B9-3B15-3B14-B13-B18-2B9-2B15-L19-L11-L19-L3-G7-D19-D11-D19-D8-EIGB19-BGIE5-EIGM19AMGIE293-FKHJ19AJHKF5-FKHJAB15ABAJHKF10-3(D15-)D9-C5-C15-C5-2(C3-C27-)C3-2C25-2C4-2B23-2B5-3B21-3B5-4B19-4B6-4B17-4B8-4B15-4B12-2B13-2B17-3B7-3B47-2(L19-L11-)D19-D11-D19-D8-EIGB19-BGIE5-EIGM19AMGIE293-FKHJ19AJHKF5-FKHJAB15ABAJHKF10-3(D15-)D10-C4-C15-C4-C-O3-2(C25-C5-)2C23-2C5-3B21-3B6-3B19-3B7-4B17-4B8-4B15-4B11-2(2B15-)4B7-4B79-2(L17-L13-)D17-D13-D17-D9-2EIGB17-BGI2E5-2EIGM17AMGI2E293-2FKHJ17AJHK2F5-2FKHJ2B13A2BJHK2F10-2D13-2D8-O6-2D13-2D11-3C2-C13-C2-3(3C7-3C19-)3C8-2B19-2B9-4B15-4B10-3B15-3B13-B15-B16-5B5-5B112-2L13-2L15-2L13-2L10-G4-2D13-2D15-2D13-2D11-EIGM2B13-2BMGIE7-EIGM17AMGIE295-FKHJ17AJHKF7-FKHJA2B11A2BAJHKF12-2D11-2D17-2D11-2D15-4C11-4C12-4C13-4C2(11-3C15-3C)12-2B15-2B14-2B13-2B16-6B3-6B17-5B5-5B146-2(13L19-)13D19-13D13-2EIGMA13BAMGI2E7-2EIGM15AMGI2E295-2FKHJ15AJHK2F5-O-2FKHJA13BAJHK2F13-2(13D19-)13C18-15C16-17C15-17C16-15B18-6B-6B293-G40-2EIG2M11A2MGI2E9-2EIG2M11A2MGI2E297-2FKH2J11A2JHK2F9-2FKH2J11A2JHK2F586-2EI2G2M7A2M2GI2E11-2EI2G2M7A2M2GI2E299-2FK2H2J7A2J2HK2F11-2FK2H2J7A2J2HK2F72-O515-2E2I2G7M2G2I2E13-2E2I2G7M2G2I2E301-2F2K2H7J2H2K2F13-2F2K2H7J2H2K2F12-O19-O491-G65-3E2I7G2I3E15-3E2I7G2I3E303-3F2K7H2K3F15-3F2K7H2K3F99-O493-4E5I4E19-4E5I4E307-4F5K4F19-4F5K4F49-O514-G33-7E25-7E313-7F25-7F22-O45-O19-O450-G5-G476-O28-O400-
