model
size = 28 32 28, scale = 0.05, origin = -y
material deform = 1, fade = true, lighting = smooth, roughness = 0.3, metalness = 0.6
  colors = A:#145799 B:#210087 C:#0088AB D:#111 E:#FFF F:#FF6999 G:#400 H:#FF003F
voxels
532-5A6D6B6D5A10C2D4B2D10C11A6B11A11C6B11C11A6B11A728-2(11A6B11A11C6B11C)11A6B11A253-8(10A6B10A2-10C6B10C2-)10A6B10A2-10C6B10C-2(11A6B11AC10A6B10AC)A10C6B10CA253-A9C6B9CA2-C9A6B9A8(C2-A24BA2-C24B)C-2(2A24B2ACA24BAC)AC9A6B9ACA253-AC8A6B8ACA2-C9A6B9A8(C2-A24BA2-C24B)C-2(2A24B2ACA24BAC)ACA8C6B8CACA130-B27-2B26-2B65-ACA7C6B7CACA2-C9A6B9A8(C2-A2B7A6B7A2BA2-C2B7A6B7A2B)C-2A2B7A6B7A2B2ACA2B7A6B7A2BAC2A24B2ACA24B3(AC)7A6B7A2(CA)102-2(B28-)B27-B24-3B37-2(AC)6A6B6A2(CA)2-C9A6B9A8(C2-A2B7A6B7A2BA2-C2B7A6B7A2B)C-2A2B7A6B7A2B2ACA2B7A6B7A2BAC2A24B2ACA24B3(AC)A6C6B6C2(AC)A102-2B2(28-B)27-B26-B24-3B9-2(AC)A5C6B5C2(AC)A2-C9A6B9A8(C2-A2B7A6B7A2BA2-C2B7A6B7A2B)C-2A2B7A6B7A2B2ACA2B7A6B7A2BAC2A24B2ACA24B4(AC)5A6B5A3(CA)73-B28-3B2(28-B)27-B26-B23-4B8-3(AC)4A6B4A3(CA)2-C9A6B9A8(C2-A2B7A6B7A2BA2-C2B7A6B7A2B)C-2A2B7A6B7A2B2ACA2B7A6B7A2BAC2A24B2ACA24B4(AC)A4C6B4C3(AC)A73-2B28-3B2(28-B)27-B20-2B4-B23-4B7-3(AC)A3C6B3C3(AC)A2-C9A6B9A8(C2-A2B7A6B7A2BA2-C2B7A6B7A2B)C-2A2B7A6B7A2B2ACA2B7A6B7A2BAC2A24B2ACA24B5(AC)3A6B3A4(CA)44-B2(28-3B)2(28-B)18-2B7-B20-2B4-B23-4B6-4(AC)2A6B2A4(CA)2-C9A6B9A8(C2-A2B7A6B7A2BA2-C2B7A6B7A2B)C-2A2B7A6B7A2B2ACA2B7A6B7A2BAC2A24B2ACA24B5(AC)A2C6B2C4(AC)A43-3(3B28-)B17-2B8-B19-2B6-B21-2B3-B24-3B6-4(AC)2A6B2A4(CA)2-C9A6B9A8(C2-A2B7A6B7A2BA2-C2B7A6B7A2B)C-2A2B7A6B7A2B2ACA2B7A6B7A2BAC2A24B2ACA24B6(AC)A6B5(AC)A43-4B28-3B48-B3(28-2B)2-B25-2B6-2(26B2-)15(3B20A3B2-)3B20A3B-4B20A8B20A88B12-3B29-4B50-2(B28-)2(2B28-)B36-2(26B2-)15(3B20A3B2-)3B20A3B-4B20A8B20A88B12-5B24-B3-2B23-3(B28-)2B28-B65-2(26B2-)15(3B20A3B2-)3B20A3B-4B20A8B20A88B11-6B23-3B26-3B3(28-B)94-2(26B2-)15(3B20A3B2-)3B20A3B-4B20A8B20A88B11-6B2(24-3B)24-2(B26-)B103-2(26B2-)15(3B20A3B2-)3B20A3B-4B20A8B20A88B11-5B21-2B3-3(B26-)B25-2B25-B76-2(26B2-)15(3B20A3B2-)3B20A3B-4B20A8B20A88B12-3B21-4B57-B26-B25-2B24-2B25-B49-4(AC)2A6B2A4(CA)2-C9A6B9A8(C2-A2B7A6B7A2BA2-C2B7A6B7A2B)C-2A2B7A6B7A2B2ACA2B7A6B7A2BAC2A24B2ACA24B6(AC)A6B5(AC)A37-4B21-3B60-B25-2B24-2B21-B2-2B24-2B22-4(AC)2A6B2A4(CA)2-C9A6B9A8(C2-A2B7A6B7A2BA2-C2B7A6B7A2B)C-2A2B7A6B7A2B2ACA2B7A6B7A2BAC2A24B2ACA24B5(AC)A2C6B2C4(AC)A38-2(3B22-)3B24-B27-B8-2B17-B6-2B20-B3-2B23-3B21-3(AC)A3C6B3C3(AC)A2-C9A6B9A8(C2-A2B7A6B7A2BA2-C2B7A6B7A2B)C-2A2B7A6B7A2B2ACA2B7A6B7A2BAC2A24B2ACA24B5(AC)3A6B3A4(CA)39-B24-3B22-3B24-B26-B27-B7-2B19-B4-2B22-4B20-3(AC)4A6B4A3(CA)2-C9A6B9A8(C2-A2B7A6B7A2BA2-C2B7A6B7A2B)C-2A2B7A6B7A2B2ACA2B7A6B7A2BAC2A24B2ACA24B4(AC)A4C6B4C3(AC)A65-2B23-3B24-B26-B27-B28-B4-2B22-4B19-2(AC)A5C6B5C2(AC)A2-C9A6B9A8(C2-A2B7A6B7A2BA2-C2B7A6B7A2B)C-2A2B7A6B7A2B2ACA2B7A6B7A2BAC2A24B2ACA24B4(AC)5A6B5A3(CA)66-B24-3B24-B26-B27-2(B28-)4B18-2(AC)6A6B6A2(CA)2-C9A6B9A8(C2-A2B7A6B7A2BA2-C2B7A6B7A2B)C-2A2B7A6B7A2B2ACA2B7A6B7A2BAC2A24B2ACA24B3(AC)A6C6B6C2(AC)A92-2B25-B26-B27-2(B28-)3B18-ACA7C6B7CACA2-C9A6B9A8(C2-A2B7A6B7A2BA2-C2B7A6B7A2B)C-2A2B7A6B7A2B2ACA2B7A6B7A2BAC2A24B2ACA24B3(AC)7A6B7A2(CA)93-2(B26-)B27-B28-3B46-AC8A6B8ACA2-C9A6B9A8(C2-A24BA2-C24B)C-2(2A24B2ACA24BAC)ACA8C6B8CACA121-B2(26-2B)75-A9C6B9CA2-C9AB4GB9AC2-A9B6G9BA2-C8BF6AF8BC2-A8B8F8BA2-C9B6F9BC2-A9B6A9BA2-C24BC2-A3B5A8B5A3BA2-C2B2A5E6B5E2A2BC2-ABA7EA4BA7EABA2-CBA3D4EA4BA3D4EABC2-ABA4D3EA4BA4D3EABA2-CBA2E3D2EA4BA2E3D2EABC2-ABA2E3D2EA4BA2E3D2EABA2-C2B2A3D2A6B2A3D2A2BC2-A3B5A8B5A3BA2-C24BC-2(2A24B2ACA24BAC)AC9A6B9ACA253-10A6B10A2-10C6B10C2-9AD6BD9A2-8CD-6D-D8C2-8AD8-D8A2-9CD2-2E2-D9C2-5A2H3A6D3A2H5A2-4C3H3C6B3C3H4C2-5A5D6B5D5A2-3C2D5-D4BD5-2D3C2(2-2AD7-D4BD7-D2A2-2CD7-D4BD7-D2C)2-2AD7-D4BD7-D2A2-3C2D3-2D6B2D3-2D3C2-5A3D2A6B2A3D5A2-10C6B10C-2(11A6B11AC10A6B10AC)A10C6B10CA252-
