model
size = 14 17 26, scale = 0.05, origin = -y
material deform = 1, fade = true, lighting = smooth, roughness = 0.3, metalness = 0.6
  colors = A:#EEE B:#111 C:#DDD
voxels
18-3(6C8-)6A8-6A161-3(8C6-)8B6-2(2BA)2B7-2(2B2(AB)8-)BA2BAB9-A2BA11-2A106-2(C4(-A)C4-)C8AC4-B8AB4-10B5-5(8B6-)8B8-4B11-2B63-2(C5(-A)C2-)C10AC2-B10AB2-12B3-5(B8-B4-)B8-B5-8B7-6B8-6B9-4B34-2(C5(A-)C2-)C10AC2-B10AB2-12B3-5(B8-B4-)B8-B5-5(B6-)B45-C2(6(A-)2C)12ACB12A15B-5(B10-B2-)B10-B3-B8-B4-B8-B58-C2(6(-A)2C)12ACB12A15B5(-B10-2B)-B10-B3-B8-B4-B8-B58-C2(6(A-)2C)12ACB12A15B5(-B10-2B)-B10-B3-B8-B4-B8-B58-C2(6(-A)2C)12ACB12A15B4(-B10-2B)-2B9-B3-B9-B4-2(B7-B5-)B7-B44-C2(6(A-)2C)12AC14A14B3(-B10-2B)2-B9-B3-B9-B4-B7-B5-2B2(5-B7-B)5-B7-2B3-2B8-B3-B19-2(C5(A-)AC-)C11AC-13A-A11BA2-A9-BA2-B9-2B2-B9-B3-2B7-2B4-B7-B5-2B5-B6-2B5-B7-2B3-2B8-B3-B9-5B10-3B11-3B6-C2(5(-A)2(-C))11AC-B11AB-A11B2(A2-A9-B)A2-B9-B3-2B7-2B4-B7-B5-2B5-B2(7-2B3-2B)8-5B10-3B11-3B20-2(C5(A-)AC-)C11AC-B11AB-13B2-B9-2B2-A9-A3-A9-A4-B7-2B4-B7-B6-B5-B7-2B3-2B8-5B9-5B10-3B34-C2(5(-A)2(-C))11AC-B11AB-13B2-B9-2B2-B9-B3-A9-A4-A7-A5-B7-B6-7B8-5B9-5B10-3B48-2(C5(A-)AC-)C11AC-13A-13B2-B9-2B2-B9-B3-B9-B4-A7-A5-B7-B6-7B8-5B10-3B62-C2(5(-A)2(-C))11AC-13A-A11BA2-A9-A2(3-B9-B)4-B7-3(B6-)7B9-3B76-2(C5(A-)AC-)C11AC-B11AB-A11BA2-A9-A3-A8-BA4-B6-2B6-B5-2B6-2B4-B8-5B89-C2(5(-A)2(-C))11AC-B11AB-13B-2B9-B3-A8-A5-2(A6-B)5-B8-6B101-C2(6(-A)2C)12ACB12A15B-B10-B3-B8-B5-A-5BA7-7B8-5B102-2(C5(A-)AC-)C11AC-B11AB-13B2-B9-B4-B7-2B5-B-6B7-6B10-2B104-C2(5(-A)2(-C))11AC-B11AB-13B2-B9-B4-B7-B6-7B9-4B117-2(C5(A-)AC-)C11AC-B11AB-13B2-B9-B4-B7-B6-7B10-2B118-C2(5(-A)2(-C))11AC-B11AB-13B2-B9-B4-2B5-2B7-B4A131-2(C5(A-)C2-)C10AC2-B10AB2-12B3-2B7-B6-B6A145-2(C4(A-)AC3-)C9AC3-B9AB3-11B4-B2A4B2A8-4A147-2(2C3(-A)C5-)2C6AC5-B8A5-BA6BA7-6A158-
