model
size = 32 23 24, scale = 0.05, origin = -y
material deform = 1, fade = true, lighting = smooth, roughness = 0.3, metalness = 0.6
  colors = A:#D00 B:#111 C:#EEE
voxels
37-C3-C12-C3-C11-2(C-)C10-2(C-)C13-C3-C8-C3-C623-C3-C6-C3-C15-2(C-)C8-2(C-)C13-C3-C10-C3-C146-B2-2B2-B500-C3-C6-C3-C12-C2-2(C-)3(C2-)2(C-)C2-2(C10-C3-)C110-BA-2(2B2A)2B-AB16-B2AB8AB2AB2(16-A3(2B2A)2BA)2(16-B3(2A2B)2AB)2(16-A3(2B2A)2BA)17-2(3(2A2B)2A18-)3(2B2A)2B20-2(2A2B)2A22-2(2B2A)2B147-C3-C6-C3-C12-2C3(-C)-2C2-2C3(-C)-2C2(10-C3-C)2(14-B)15-2AB12-B2A14-4(2A2B)2A2(14-2B14A2B)2(14-18A)2(14-2B15AB)2(14-18A)14-2B14A2B15-B14AB17-2B12A18-2B10A2B19-A2(2B2A)2BA22-B2A2B2AB116-A3-C6-C3-A13-C-CAB-A-C4-C-A-BAC-C11-C2B2AB8-B2A2BC13-2B2AB8-B2A2B14-3AB2A6-2AB3A13-B6A2B2A2B6AB2(2(12-20A)2(12-B18AB))13-18A14-B16AB15-16A16-16A17-2A2B6A2B2A19-A2B6A2BA21-2(2A2B)2A77-2C4-A3-A6-A3-A4-2C7-C-3A-2AC4-C2A-3A-C11-6AB-C2-C-B6A12-6AB6-B6A12-B6A2B2A2B6AB11-AB18ABA2(2(10-B20AB)2(10-22A))11-20A13-3(18A14-)2B14A2B14-2B14A2B15-A3(2B2A)2BA17-3(2B2A)2B44-2C7-A6-A7-2C8-A5-2AB4-B2A5-A10-BA4-3AC2-C3A4-AB10-BA2(4-3A)4-AB2(10-2A4-4A2B4A4-2A)10(10-2A4-10A4-2A)2(10-AB4-10A4-BA)11-B4-10A4-B12-BA3-10A3-AB12-2A3-10A3-2A13-18A15-B3(2A2B)2AB41-3C2A7-2B2-2B7-2A3C5-2B6-2AC2-C2A6-2B8-2B6-3A2-3A6-2B2(8-2A6-3A2-3A6-2A)8-2B6-3A2B3A6-2B8-2B6-8A6-2B8-2A6-8A6-2A8-2A20-2A2(8-2B20-2B)2(8-2A20-2A)8-2B20-2B9-B20-B10-A20-A10-2A18-2A2(10-2B18-2B)10-2A18-2A11-3A14-3A13-2B14-2B21-A2-A27-AC2-CA13-3C3A7-AB2-BA7-3A3C3-3A7-AB2-BA7-3A6-B2A6-3A2-3A6-2AB6-B2A6-8A6-2AB6-3A6-8A2(6-3A)6-8A6-3A6-B2A6-8A6-2AB6-B2A20-2AB2(6-3A20-3A)2(6-B2A20-2AB)7-2A20-2A8-2A20-2A9-2(B20-B10-)2(A20-A10-)2B18-2B11-B18-B12-A18-A20-C2-C14-2C2BA9-A2-A9-A2B2C2-2(3A9-B2-B9-3A4-)2BA9-A2-A9-A2B4-2BA9-4A9-A2B2(4-3A9-4A9-3A)4-2BA9-4A9-A2B4-2BA22-A2B2(4-3A22-3A)5-2(BA22-AB6-)2(2A22-2A6-)2B22-2B6-3B20-3B7-2A20-2A8-2A20-2A9-2B18-2B11-B18-B12-A18-A6-2C2A10-B2-B10-2A2C2-2A10-C2-C10-2A2(4-BA10-A2-A10-AB)4-2A10-B2-B10-2A4-2A10-4B10-2A4-BA10-A2BA10-AB4-BA10-4A10-AB4-2A10-4A10-2A4-2A24-2A2(4-BA24-AB)4-2A24-2A5-A24-A2(6-B24-B)2(6-3A20-3A)6-2BA20-A2B7-BA20-AB9-2A18-2A11-A18-A12-B18-B20-B2-B14-2C2A10-B2-B10-2A2C2-BA10-C2-C10-AB4-BA10-A2-A10-AB4-2A10-B2-B10-2A4-2A10-4B10-2A4-BA10-A2BA10-AB4-BA10-4A10-AB4-2A10-4A10-2A4-2A24-2A2(4-BA24-AB)4-2A24-2A5-A24-A2(6-B24-B)2(6-3A20-3A)6-2BA20-A2B7-BA20-AB9-2A18-2A11-A18-A12-B18-B20-A2-A28-C2-C14-2C2A10-B2-B10-2A2C2-2A10-B2-B10-2A4-BA10-A2-A10-AB4-BA10-4A10-AB2(4-2A10-4A10-2A)4-BA10-4A10-AB4-BA24-AB2(4-2A24-2A)4-2B24-2B5-B24-B2(6-A24-A)2(6-B2A20-2AB)6-3A20-3A7-2A20-2A9-2B18-2B11-B18-B12-A18-A20-C2-C14-2CBA10-A2-A10-AB2C2-2(2A10-B2-B10-2A4-)BA10-A2-A10-AB4-BA10-4A10-AB2(4-2A10-4A10-2A)4-BA10-4A10-AB4-BA24-AB2(4-2A24-2A)4-2B24-2B5-B24-B2(6-A24-A)2(6-B2A20-2AB)6-3A20-3A7-2A20-2A9-2B18-2B11-B18-B12-A18-A6-2CA11-B2-B11-A2C2-2A10-C2-C10-2A2(4-BA10-A2-A10-AB)4-2A10-B2-B10-2A4-2A10-4B10-2A4-BA10-A2BA10-AB4-BA10-4A10-AB4-2A10-4A10-2A4-2A24-2A2(4-BA24-AB)4-2A24-2A5-A24-A2(6-B24-B)2(6-3A20-3A)6-2BA20-A2B7-BA20-AB9-2A18-2A11-A18-A12-B18-B20-B2-B14-2C2A10-B2-B10-2A2C2-BA9-AC2-CA9-AB4-BA9-A4-A9-AB4-2A9-A4-A9-2A4-2A9-A-2B-A9-2A4-BA9-A-2B-A9-AB4-BA9-2A2B2A9-AB4-2A10-4A10-2A4-2A24-2A2(4-BA24-AB)5-4(B24-B6-)3A20-3A6-3A20-3A7-BA20-AB8-BA20-AB9-2A18-2A11-A18-A12-BA16-AB19-B4-B26-BC2-CB13-2C3A8-A4-A8-3A2C2-3A8-A4-A8-3A2(4-B2A8-A4-A8-2AB)4-3A8-A4-A8-3A4-3A8-6A8-3A4-2BA8-6A8-A2B5-BA22-AB2(6-2A22-2A)2(6-BA22-AB)2(6-AB22-BA)6-2BA20-A2B7-BA20-AB2(8-2A20-2A)9-2B18-2B11-BA16-AB13-2BA12-A2B20-BC2-CB13-2CB-A8-B4-B8-A-B2C2-2(3A8-A4-A8-3A4-)2(B2A8-B4-B8-2AB4-)3A8-A4-A8-3A4-3A8-6A8-3A5-BA8-6A8-AB6-BA22-AB2(6-2B22-2B)6-2A22-2A7-A22-A7-2B2A4-10A4-2A2B6-2B2A4-10A4-2A2B7-3A4-10A4-3A8-3A4-10A4-3A9-2A4-10A4-2A10-2A4-10A4-2A11-B4-10A4-B13-18A15-B3(2A2B)2AB9-C11-C4-C11-C3-C-A22-A-C5-2(2B7-B6-B7-2B6-)2A7-A6-A7-2A6-3A2(6-A)6-3A6-2BA6-2A4-2A6-A2B6-2BA6-2(2AB)2A6-A2B6-3A6-A2B2A2BA2(6-3A)6-8A6-3A6-2BA6-8A6-A2B7-BA6-8A6-AB2(8-2A6-8A6-2A)8-B22AB9-22A2(10-2B18A2B)11-A2B14A2BA12-A2B14A2BA13-4(2A2B)2A14-4(2A2B)2A39-2C3-A7-2C2-2C7-A3-2C2-C-3A-A3-C6-C3-A-3A-C5-CB6AB8-B6ABC7-2(B6AB8-)2(9A6-9A8-)B6A2B6-2B6AB8-BA5-2B2A2-2A2B5-AB8-2A5-2(2A2B)2A5-2A8-9A2B2A2B9A8-B22AB9-22A2(10-2B18A2B)11-2(20A12-)B18AB13-18A14-2B14A2B15-B14AB17-3(2B2A)2B73-2(C4-B3-B4-C2-)C-C2B-A2B-C6-C-2BA-2BC-C5-C-6AB8-B6A-C8-6AB8-B6A2(10-2B2A2BA8-A2B2A2B)2(10-6AB8-B6A)2(10-2B5A8-5A2B)11-5A2B6A2B5A12-20A12-B18AB13-2(18A14-)B16AB15-16A16-16A17-3(2A2B)2A19-A2(2B2A)2BA111-C3-C4-C2-C4-C3-C7-3(C-)ABC-C6-C-CBA3(-C)5-C3-2BA-C8-C-A2B3-C9-2(A2BA12-)2(B2AB12-)B2A2B10-2B2AB2(12-A2B2A10-2A2BA)12-B2A2B10-2B2AB13-2A2B10-2B2A14-2(2B2A2-2A)2B14-4(2B2A)2B2(14-4(2A2B)2A)14-4(2B2A)2B15-B3(2A2B)2AB16-A3(2B2A)2BA17-3(2B2A)2B19-A2(2B2A)2BA143-C3-C12-C3-C6-C2-4(C-)C6-4(C-)C2-C4-2(C3-)C8-2(C3-)C648-C3-C12-C3-C9-4(C-)C6-4(C-)C11-C3-C8-C3-C647-
