model
size = 22 30 32, scale = 0.05, origin = -y
material deform = 1, fade = true, lighting = smooth, roughness = 0.3, metalness = 0.6
  colors = A:#222 B:#444 C:#E00 D:#800
voxels
30-6A16-3(AB)17-2(BA)18-4A2(18-2(BA))17-2(6A16-)6A17-4A19-2A63-A2-A2(18-4A)19-2A523-8A13-11A7(10-12A)11-10A14-6A390-6A13-12A9-3A8-3A7-3A11-7(2A6-2A12-)2A7-2A10-2A9-3A6-3A11-10A13-8A323-6A12-4A6-4A7-2A12-2A6-A14-A5-7(A16-A4-)A16-A5-A14-A6-2A12-2A7-2A10-2A9-2A8-2A11-10A16-2A278-14A7-A14-A5-3(A16-A4-)A16-A3-4(A18-A2-)A18-A3-A17-A3-A16-A4-A16-A5-A14-A6-2A12-2A7-2(2A10-)4A2-4A15-4A234-12A8-2A12-2A5-2(A16-A4-)A16-A3-8(A18-A2-)A18-A3-A17-A3-A16-A4-A16-A5-A14-A7-2(2A10-)10A230-14A6-2A14-2A4-A16-A3-12(A18-A2-)A18-A3-A16-A4-A16-A5-2A12-2(2A8-)2A12-8A208-16A5-A16-A3-9(A18-A2-)A19-A-4(A18-A2-)A18-A3-A16-A5-A14-2A6-2(2A10-)3A4-3A15-4A188-16A5-A16-A3-6(A18-A2-)A18-A-A5(20-2A)20-A-2(A18-A2-)A18-A3-A16-A5-2A12-2(2A8-)2A12-8A186-16A4-2A16-2A2(2-A18-A)2-A19-11(2A20-)A-A18-A2-A18-A3-A16-A5-A14-A7-2(2A10-)10A184-18A3-2(A18-A2-)A18-A-A11(20-2A)20-A-2(A18-A2-)A18-A3-2A14-2A6-2A11-A10-3A4-4A14-4A165-8A2-8A3-2(A8-2A8-A2-)A8-2A8-A-A2(9-2A)11(20-2A)20-A-A18-A2-A18-A3-A16-A5-2A12-2(2A8-)2A12-8A163-7A4-7A3-5(A7-A2-)A7-A-A8-A2-A8-2(2A9-)11(2A20-)A-A18-A2-A18-A3-A16-A5-2A12-2(2A8-)2A12-8A163-2(7A4-)A5-A4-A5-A3-A6-A4-A6-A2-A6-A4-A6-A-A8-A2-A8-2(2A9-)11(2A20-)A-A19-A-A18-A3-A16-A5-A14-A7-2(2A10-)10A162-2(7A4-)3(A5-A4-)A5-A3-A6-A4-A6-A-A8-4A8-13(2A20-)A-A18-A3-A16-A5-A14-A7-2(2A10-)10A163-6A4-6A5-2A5-A2-A5-2A4-A6-A2-A6-A4-A6-4A6-A2-2A18-3A12(20-2A)20-A-A18-A3-A16-A5-A14-A7-2(2A10-)10A167-2A4-2A11-3A2(2-A)2-3A7-3A4-2A4-3A5-A16-A2-2A18-3A12(20-2A)20-A-A18-A3-A16-A5-A14-A7-2(2A10-)10A189-3A2-3A10-A2-A3-2A3-A2-A5-A-2A10-2A-A2-2A18-3A11(20-2A)20-A-A19-A-A18-A3-A16-A5-A14-A7-A12-A9-12A74-A14-A4(6-2A12-2A)6-2A3-2A2-2A3-2A5-A-2(A2-)2A2(2-A)-A4-2(A-)A8-2(A-)A2-2A3-A10-A3-3A11(20-2A)20-A-A18-A2-A18-A3-A16-A5-A14-A7-A12-A9-12A52-6(2A12-2A6-)2A12-2A5-A-A3-6A3-A-A4-3A-2A6-2A-2(3A2-)A10-A2-4A20-A-A18-A2-A19-9(2A20-)A-A18-A2-A18-A3-A16-A5-A14-A7-A12-A9-12A52-2(2A12-2A6-)3(A-A10-A-A6-)2(2A12-2A6-)2A4-4A4-2A9-3A4-3A6-2A-3A10-2(3A-)A16-2(A-)3(A18-A2-)A18-A-A5(20-2A)20-A-2(A18-A2-)A18-A3-A16-A5-A14-A7-2(2A10-)10A32-A12-A7-5(A-A10-A-A6-)A-A11-2A6-2A12-2A6-2A3-6A3-2(2A6-2A-)2A3-2A2(-A)10-2(A-)3A-A16-2(A-)11(A18-A2-)A18-A3-A16-A4-A16-A5-A14-A7-2(2A10-)10A32-2A10-2A7-2(A-A10-A-A6-)A2-A8-A2-3(A6-A-A10-A-)A6-2A12-2A6-2A2-8A2-2A6-A-2A8-2A-A3-3A16-5A18-2A2-3(A16-A4-)A16-A3-7(A18-A2-)A18-A3-A16-A4-A16-A5-2A12-2(2A8-)2A12-8A33-2A10-2A7-4(A2-A8-A2-A6-)2(A-A10-A-A6-)2A2-2A4-2A2-2A6-2A-A2-4A2-A-2A3-3A2-A10-A2-4A20-3A18-2A2-5(A16-A4-)A16-A3-4(A18-A2-)A18-A3-A16-A4-A16-A5-A14-A7-A12-A9-4A4-4A14-4A13-2(2A10-2A8-)6(A-A8-)A2-A6-A2-A8-A-2A6-2A-A8-4A6-4A10-A-6A-A8-4A10-4A3-A18-3A20-A-2(A18-A2-)A3-2C9-C2(3-A)-C2D8-2DC-5(A4-A16-)A3-A18-A2-A18-A3-A16-A4-A16-A5-A15-A5-2A12-2A8-A10-A11-10A32-2A10-2A4(8-A-A)3(8-A2-A6-A2-A)8-2A-A6-A-2A9-A2-A4-A2-A10-A3-4A3-A7-3A12-4A3(2-A18-A)2-A2-3C8-3C2(2-A)2(2-C)6-2C-C2-A3-2A3-C6-C3-2A4-A-C2D8-2DC-7(A4-A16-)A5-A14-A6-A14-A7-2(2A10-)3A4-3A15-4A35-2(3A8-)2(A-B8-B-B8-)A2-A6-A2-A8-A2-B6-B2-B9-B-B6-B-2B10-2A6-2A11-A2-A4-A2-A10-A3-4A3-A7-3A12-3A3-A18-A2-A18-A3-A-3C8-3C-A4-2A3-C6-C3-2(2(2A4-)2(C4-))2A4-A-C2-C6-C2-C-A4-A2-2C8-2C2-5(A4-A16-)A5-A14-A6-A14-A7-A12-A9-3A6-3A13-6A57-2A8-2A10-2B8-BA10-B-B6-B-A10-A-A6-A-2(A10-B2-B4-B2-)A11-A-A4-A-A11-A2-A4-A2-A11-A2-4A2-A9-3A10-3A5-3A12-3A4-A16-A4-2A3C8-3C2A9-C6-C15-C4-C16-C4-C10-2A2(4-C)4-2A4-A-4C6-4C-A4-A16-A5-3(A14-A6-)A14-A7-A12-A8-2A10-2A9-2A8-2A12-8A78-3A6-3A2(10-B-A6-B-A)10-A2-A4-A2-A10-B2-A4-B2-A11-B-A4-B-B2(12-A-A4-A-A)12-A2-4A2-A12-A8-A11-2(2A8-)2A12-2A6-A3C8-3CA10-C6-C15-2(C4-C16-)C4-C11-AC2-C6-C2-CA6-A-2A8-2A-A6-A14-A7-A12-A2(8-2A10-2A)9-2A8-2A11-3A4-3A13-8A100-3A6-3A10-B-B6-B-A10-B2-B4-B2-A11-A-A4-A2-A11-A3(2-B)12-A2-B3-B-B2(12-A-A4-A-A)12-A2-4A2-A12-A8-A13-A6-A11-2(3A8-)2(2A10-)2A6-2C14-A4-C16-A4-C17-A2-A17-A4-A12-4A6-4A8-2A10-2A9-2A8-2A11-2A6-2A12-4A2-4A13-8A16-4A125-3A4-3A12-A-2B2-2B-B12-A2-4B2-B12-A2-4A2-A13-B2-2B3-B13-B-B2-B-B14-A-A2-A-A14-A-2(A2-)A13-A2-2A3-A13-2(A6-A14-)A2-2A2-A13-2(2A2-)2A12-2(2A2-)2A14-A4-A16-A4-A17-A2-A18-A2-A17-6A14-10A13-8A15-6A18-2A171-8A14-B2-2B2-A14-BA4-BA14-2A4-2A14-BA4-BA14-BA-2B-BA14-A-A2-A-A14-A2-2A2-A14-A6-A15-A4-A16-6A3(16-2A2-2A)17-3A-A17-A2-A18-A2-A19-2A274-
