model
size = 23 32 14, scale = 0.05, origin = -y
material deform = 1, fade = true, lighting = smooth, roughness = 0.3, metalness = 0.6
  colors = A:#EEE B:#DDD C:#400 D:#606 E:#CCC F:#AAA G:#BBB H:#888 I:#666 J:#999 K:#500 L:#333 M:#C9C N:#969 O:#F0C P:#444 Q:#555 R:#603 S:#777 T:#633 U:#F0F V:#C69 W:#636 X:#939 Y:#CCF Z:#303 Aa:#F90 Ab:#010 Ac:#090 Ad:#040 Ae:#6800D1 Af:#936 Ag:#0C3 Ah:#C99 Ai:#C90 Aj:#F93 Ak:#C63 Al:#963 Am:#C6C
voxels
309-KSK20-HEH20-FBF387-5A16-2A5-2A13-A9-A12-A9-2(A11-)A9-A13-A8-A13-A7-A15-A6-A15-A5-3(A17-A4-)A17-A3-2(A19-A2-)A19-A-A21-2A21-A-6(A19-A2-)A19-A3-A17-A4-A17-A5-A15-A6-A15-A7-A13-A2(9-2A)12-9A38-7A15-B7-B13-A9-2(A11-)A9-B13-B7-B15-B6-B15-B5-2(A17-A4-)A17-A3-A19-A2-B19-B2(2-A19-A)2(2-B19-B)7(2-A19-A)3-2(A17-A4-)A17-A5-A15-A7-A13-A9-2(A11-)2A7-2A14-7A40-B3AB17-B5-B15-B7-B12-2(2B9-)B13-B7-B15-B5-2(B17-B4-)G17-G4-Y17-Y3-5(B19-B2-)I19-I2(2-B19-B)2-F19-F3(2-B19-B)3-B17-B2(4-A17-A)5-A15-A6-A15-A7-A13-A2(9-2A)12-9A62-2(QJ)Q17-B5-B14-BA7-A2(B11-)B9-B13-B7-B15-B5-2(I17-I4-)G17-G4-Y17-Y3-B19-B2-F19-F4(2-I19-I)2-Q19-Q2-I19-I2-F19-F3-M17-M4-G17-G2(4-B17-B)4-A17-A5-E15-E6-A15-A7-A13-A9-2(A11-)3A5-3A15-5A65-JQJ18-BE3-EB14-BA7-A2(B11-)B9-B13-B7-F15-F6-P15-P5-I17-I4-G17-G4-Y17-Y4-B17-B3-F19-F2-M19-M2-N19-N2-S19-S2-I19-I2-Q19-Q2-I19-I3-N17-N4-M17-M4-G17-G4-E17-E5-J15-J6-F15-F6-E15-E7-F13-F9-2(B11-)BG7-GB14-7A87-JQJ18-BEH-HEB14-2A7-2A2(11-B)9-B13-B8-F13-F7-P15-P6-Q15-Q5-G17-G4-Y17-Y4-B17-B4-V17-V4-T17-T4-K17-K4-C17-C2(4-K17-K)4-P17-P4-O17-O4-U17-U4-GE15-EG5-G15-G6-J15-J7-J13-J8-JB11-BJ9-JF9-MJ11-AGM5-BMB14-3BZN2B131-BE3HEB14-2A7-2A2(11-B)10-B11-B9-F13-F8-P13-P7-Q15-Q6-J15-J6-A15-A5-B17-B4-U17-V4-T17-U4-K17-K4-C17-C4-K17-K4-KC15-CK4-OC15-CO5-K15-K6-N15-N6-E15-E6-GI13-IG7-S13-S9-2(E11-)F9-B13-RZ5-2Z16-GN2DG155-BE3HEB15-A7-A13-B9-B2(11-Ad)10-Ab11-Ab9-P13-P8-G13-G7-J15-J6-Ag15-Ag6-A15-A6-V15-V2(6-C15-C)76-C13-C7-KC13-CK6-O15-O6-UF13-FU7-IN11-DI9-ED9-AeN11-AB7-MB13-X3DR3DAe16-XNRDM178-BE3HEB15-A7-A14-G7-G13-F9-F12-L9-2(L11-)L10-S11-S9-H13-H8-Ac13-Ac7-AU13-UA6-2V13-2V6-2C13-2C7-2C11-2C101-C11-C9-R13-R8-F2E9-MEF9-NAeD7-3D12-Z2DAj2AaAfDZ15-XRTAkTRD223-BE3HEB16-A5-A15-Ad7-Ad14-Ab7-Ab14-L7-L13-G9-G12-I9-I11-JB9-BJ10-AgA9-AAg10-2Ac9-2Ac10-2O9-2O10-KR9-RK11-3C5-3C38-C3-C18-KM-XK17-CBN-DBC14-2CD5-D2C11-CTM7-WTC11-EMXDAk2AiRDAmM12-Ae3D3AaAlR2D268-E3HE17-A5-A16-B5-B16-G5-G16-L5-L15-PG5-GP14-A7-A14-B7-B14-2A5-2A14-OA5-AO14-O7-O14-TAf5-AfT16-W3-W18-CH-HC19-W-B20-MDX20-NAeD19-DXAeDX17-Z4DRZ16-XDTAjTRD18-3Aa295-2AB2A18-AdBFBAd18-2(AbG)Ab18-5L18-PSFSP17-2AJBJ2A16-EBFLFBE17-SLCLS18-H3CH17-U5-U16-Af5-Af17-W3-W19-H-H20-WMB572-FLF20-LCL20-3C19-EK-KE18-Ah3-Ah18-WF-FW19-HAH378-
