model
size = 32 32 18, scale = 0.05, origin = -y
material deform = 1, fade = true, lighting = smooth, roughness = 0.3, metalness = 0.6
  colors = A:#B00 B:#A00 C:#700 D:#800 E:#D00 F:#C90 G:#050 H:#040 I:#C60 J:#070 K:#DDD L:#C03 M:#EEE N:#F03 O:#C33 P:#930 Q:#3C3 R:#666 S:#500 T:#C93 U:#CC6 V:#AAA W:#444 X:#3C0 Y:#F33 Z:#6C3 Aa:#400 Ab:#CCF Ac:#9C9 Ad:#0D0 Ae:#BBB Af:#630 Ag:#960 Ah:#CC0 Ai:#600 Aj:#FC3 Ak:#999 Al:#F93 Am:#6C6 An:#C63 Ao:#663 Ap:#360 Aq:#0B0 Ar:#390 As:#C30 At:#F63 Au:#333 Av:#CCC Aw:#888 Ax:#F30 Ay:#C36 Az:#C99 Ba:#555 Bb:#C9C Bc:#CC9 Bd:#F60 Be:#FCC Bf:#633 Bg:#933 Bh:#0A0
voxels
206-UBcU29-ITI29-FAhF1171-2G29-G2H29-3H28-3HG29-2HGH29-2G170-2G29-G3H28-3HG27-3HGH28-2HGH29-2G497-GJ30-D2A29-B2A27-GABCA27-JEDCE28-AE2AD28-2EBA28-GBDE104-GJ30-D3AG27-B2ADH25-GABCAEG25-JEDCEACD25-AE2ADBJ26-2EBAJ27-GBDE400-J31-B22-H7-AEA20-3HG5-DABD18-G4HG3-2AB2A18-3G2HG2-2(DA)EA19-2HGH3-5AD27-4A2E27-C2(AD)27-3A2E28-B-2A8-J19-J11-B30-AEA29-DABD2B25-2AB4A24-2(DA)EACD22-GJ5A2DAD24-4A2E2A25-C2(AD)ECJ24-3A2E-A2J24-B-2A28-J362-JG5-ABE21-AEA4-3ACEA17-G2ED2BDG-EAD2AE17-BEA2C2AJ-3AEAC17-DBAE3A3-2BDCE17-EADAEDA2-AD-ADA18-JBCGHG3-BD-C2A18-JD5-BCDED2A25-2BEC2AC26-2B2ADCE25-BEA-2A6-ABE3-2B23-3ACEA4B22-EAD2AEA-AB22-3AEA2CAEC23-2BDCEAB2C22-AD-ADACDCA23-BD-C2A2EB22-BCDED2ACDA22-2BEC2ACE2A23-2B2ADCEA24-BEA-2A83-3(M17-M13-)M17-M12-M19-M11-M19-MG10-M19-MJ9-M21-AD8-M20-4A8-M19-2A2(DA)5-CE18-4ABAEB2-A-CA17-AD2AEABA4-A2C16-2(AE)D2AD4-B2AE16-A2(ED)CABA3-B2CD18-E2ADABE3-B-CQD16-ACAD4A4-2B-B16-2J4-2J5-2BAm16-JQ5-GJ7-X15-2G14-M2G12-G3H13-G3H5-CED3-3HG13-3HG3-A-C2A2B3HGH12-3HGH2MAzOA2CAC2-2HGH13-2HGH3-B2AECB3-2G15-2G4-B2CD-E26-B-C-DAB26-2B-3B27-2B148-M17-M13-M17-M12-M19-M11-K19-K2(11-M19-M)2(11-K19-K)A-AEA6-M19-BDB4A5-M19-D-BADAB5-M18-EMADEACE5-M17-A2(DC)2AE5-BM17-4AECEA4-2DAc18-2A2(CA)B4-C-DB17-CEDBA-2B6-Z15-A-DE2CEA2B6-Ac17-ABA2C2B7-Am15-GJQ14-GJ13-D3AG12-D3AG10-B2ADH12-B2ADH8-GABCAEG10-GABCAEG7-MJEDCEACD9-JEDCEACDAzOLBAyBe2-AE2ADBJ10-AE2ADBJB-2D-B3-2EBAJ12-2EBAJ3-C-DB3-GBDE13-GBDE11-B207-Ae17-Ae13-Ab17-Ab12-5(K19-K11-)R19-R11-K19-K11-K19-3B-A7-V18-BVC2A8-K17-2B2CA3C6-K17-B-AcDECAE6-Ac18-BD-C2AD7-Am17-BAEBCB8-Z15-J-2B3-B8-AcJ14-B-Ac4-J9-B13-AEA-AEAJG8-AEA-AEA8-DABD2BAJ9-DABD2BAJ6-2AB5A9-2AB5A6-2(DA)EACDA8-2(DA)EACDAONLNGJ5A2DAD6-GJ5A2DAD7-4A2E2A9-4A2E2A8-C2(AD)ECJ9-C2(AD)ECJ7-3A2E-A2J8-3A2E-A2J7-B-2A13-B-2A11-J16-J158-Ae17-Ae13-Ab17-Ab12-K19-K11-V19-V4(11-R19-R)11-Ba19-Ba11-R19-R11-V19-VCD10-Bb17-Bb2-DB9-Z17-Q-D11-X17-Ad-B11-Am17-Q13-Z17-Z14-Z12-ABEX2-2B9-ABE3-2B6-3ACEA4B7-3ACEA4B5-EAD2AEA-AB7-EAD2AEA-AB5-3AEA2CAEC7-3AEA2CAEC4-YO2BDCEAB2C8-2BDCEAB2C2(NL)2(-AD)ACDCA7-AD-ADACDCA6-BD-C2A2EB8-BD-C2A2EB5-BCDED2ACDA7-BCDED2ACDA5-2BEC2ACE2A7-2BEC2ACE2A6-2B2ADCEA9-2B2ADCEA7-BEA-2A11-BEA-2A155-Ae17-Ae13-Ab17-Ab13-T17-T12-2(I19-I11-)Ah19-Ah4(11-F19-F)12-I17-I13-F17-F13-Z17-Q13-X17-Ad14-Aq15-Ad15-Q15-X15-Z15-X16-X13-ApCED14-CED2(10-A-C2A2B)6-2L-A2CAC12-A2CACO5LY2-B2AECB11-B2AECB9-B2CD-E11-B2CD-E9-B-C-DAB10-B-C-DAB9-2B-3B11-2B-3B10-2B15-2B220-W17-W13-Ab17-Ab13-T17-T13-F17-F2(13-I17-I)13-Ag17-Ag3(13-P17-P)13-I17-I13-F17-F13-ZQ15-2Q14-Ad15-X15-Aq15-Ad16-Ad13-Bh17-AqAo11-BgAr18-OL9-2L20-3L5-LNL23-7L4-B16-B13-2D15-2D2(13-C-DB)284-2(W15-)2(Ak15-)K15-K14-T17-T13-F17-F2(13-I17-I)13-Ag17-Ag13-P17-2(P13-PS15-S)P14-2(S15-)2(I15-)2(Q15-)AdAr13-AoX16-X13-Ap18-Ap11-Bf20-O9-L22-LY5-YN25-NAxAn2O406-W13-W16-2(W15-)2(K15-)2(Aj15-)4(F15-)P15-P112-C13-C16-2S13-2S2(15-I)15-QAc13-VQ16-ArO11-LAo18-OL9-NL20-2L7-ON22-LOAlAt2Al2AnO25-YAsTAtY439-W11-W18-Aw13-Aw17-T13-T16-AjF13-FAj15-2F13-2F15-FI13-IF16-SAa11-AaS146-Ai11-Ai18-Af13-Af17-AcAyL9-LOV18-O2L7-N2L21-2LYAtBdAn2NL24-OAxIAlF2Y503-R9-R20-AkK9-KAk19-2U9-2U2(19-2F9-2F)19-2I9-2I20-AaAfI5-IAfAa88-AgF-FAg26-AaAsI-IAsAa23-AiAaC5-CAaAi20-AiAfP7-PAfAi20-5FN5F21-NAhFTNLNTFAhN534-SC5-CS23-M7-M23-K7-K2(23-2F5-2F)23-F7-F23-IF5-FI25-F3-F27-2F-2F28-I-I29-FAhF29-IFI28-5I26-I5FI25-3F-3F570-2(CA)C26-M5CM25-AvKVAuVKAv26-U3KU27-U3KU26-F5-F25-F5-F26-F3-F28-F-F29-IFI797-VAuV2(29-3K)28-TU-UT27-I3-I27-2F-2F28-3F751-
