model
size = 32 23 24, scale = 0.05, origin = -y
material deform = 1, fade = true, lighting = smooth, roughness = 0.3, metalness = 0.6
  colors = A:#FFF B:#111 C:#EEE
voxels
238-4A27-6A25-8A23-4(10A22-)10A23-8A26-4A347-6B25-8B24-8B25-6B27-B2CB570-8B23-2B6-2B2(22-B8-B)23-B6-B24-2B4-2B26-4B506-8A22-2A8-2A19-2(2A10-2A18-)2A10-2A17-2(4A8-4A16-)6A4-6A17-2B10A2B18-3B8A3B18-4B6A4B19-4B4A4B23-2B2A2B26-2B2A2B27-B2AB250-8A22-2A8-2A18-2A12-2A15-2A14-2A13-2(3A14-3A12-)2(2A16-2A12-)2A16-2A13-2(2A14-)AB14-BA15-B14-B16-2B12-2B17-2BCB6-BC2B20-2C6-2C23-2B4-2B24-3B2A3B25-6A28-2A153-12A18-2A12-2A15-A16-A13-A18-A11-5(A20-A10-)2A18-2A11-A18-A12-2A16-2A13-A16-A15-B14-B17-2B10-2B19-2B8-2B20-AB8-BA21-2A6-2A23-3A2-3A26-4A91-6A22-4A6-4A16-2A14-2A12-2A18-2A10-A20-A9-4(A22-A8-)A22-A9-A20-A10-A20-A11-A18-A12-A18-A13-A16-A15-B14-B16-AB12-BA17-A12-A18-2A10-2A19-2A8-2A21-10A87-8A20-4A8-4A14-2A16-2A11-A20-A9-3(A22-A8-)A22-A7-A24-A7-3(A22-A8-)2A20-2A9-A20-A11-A18-A12-2A16-2A13-A16-A2(14-2A)15-A14-A17-A12-A19-2A8-2A22-8A55-10A19-3A10-3A14-2A16-2A11-A20-A9-A22-A8-A22-A7-6(A24-A6-)A24-A7-A22-A8-2A20-2A9-A20-A10-2A18-2A11-A18-A13-A16-A15-A14-A17-2A10-2A20-10A53-12A17-3A12-3A13-A18-A11-A20-A9-A22-A7-9(A24-A6-)A24-A7-A22-A9-A20-A10-A20-A11-A18-A13-A16-A15-2A12-2A18-5A2-5A25-2A25-12A17-3A12-3A13-A18-A11-A20-A9-A22-A7-2(A24-A6-)A24-A5-4(A26-A4-)A26-A5-2(A24-A6-)A24-A7-A22-A9-A20-A10-A20-A11-2A16-2A2(14-A)17-4A6-4A22-6A23-12A17-2(3A12-)2A18-2A10-A20-A9-3(A22-A7-A24-A6-A24-A5-6(A26-A4-)A26-A5-A24-A6-A24-A7-A22-A8-A22-A9-A20-A11-A18-A13-2A14-2A16-3A8-3A21-8A22-12A17-2(3A12-)2A18-2A9-A22-A8-)A22-A7-A24-A6-A24-A5-5(A26-A4-)A26-A3-B28-B2-2B26-2B-3B26-7B24-8B24-9B22-11B20-6B-6B18-6B2-8B4A6-4A8B4-4B6-6A6-4B13-12A17-3A12-3A13-A18-A11-A20-A9-A22-A7-2(A24-A6-)A24-A5-4(A26-A4-)A26-A3-B28-B-B6(30-2B)8-A12-A8-B-B6-B-3A6-3A-B6-B3-6B5-6A5-6B13-10A19-3A10-3A14-2A16-2A11-A20-A9-A22-A8-A22-A7-2(A24-A6-)A24-A5-3(A26-A4-)A26-A3-B28-B-B6(30-2B)8-A12-A8-B-B6-B-12A-B6-B3-6B16-6B14-8A21-3A8-3A16-2A14-2A13-A18-A11-A20-A9-A22-A8-A22-A7-5(A24-A6-)A24-A4-2B26-2B2-B28-B-B4(30-2B)30-3B7-2A10-2A7-2B-2B4-2B2-10A2-2(2B4-)4B18-4B45-12A18-2A12-2A15-A16-A13-A18-A11-A20-A10-A20-A9-A22-A8-A22-A7-4(A24-A6-)A24-A5-3B22-3B3-4B22-4B2(2-2B26-2B)2-2B4-B16-B4-2B2-8BA12-A8B3-7B-3A6-3A-7B5-4B6-6A6-4B78-10A20-2A10-2A17-A14-A15-A16-A13-A18-A12-A18-A11-A20-A10-A20-A9-4(A22-A8-)A22-A9-A20-A10-B20-B8-4B18-4B6-4BA16-A4B6-4B-A14-A-4B12-2A10-2A20-10A120-6A24-2A6-2A20-2A10-2A17-2A12-2A15-2(2A14-)A16-A13-A18-A12-A18-A11-5(A20-A10-)A20-A11-A18-A13-A16-A2(14-2A)16-A12-A19-4A4-4A24-4A154-8A23-2A6-2A21-A10-A19-A12-A17-A14-A15-2(2A14-)A16-A13-2A16-2A4(12-A18-A)12-2A16-2A13-A16-A15-A14-A17-2A10-2A19-3A6-3A23-6A218-6A24-3A4-3A21-2A8-2A19-2A10-2A18-A12-A17-2A12-2A16-A14-A15-7(2A14-)2A15-A14-A16-2A12-2A17-3A8-3A20-4A2-4A24-6A283-4A26-8A23-3A4-3A21-3A6-3A20-2A8-2A19-5(2A10-2A18-)3A8-3A19-4A4-4A22-8A27-2A175-
