model
size = 24 25 30, scale = 0.05, origin = -y
material deform = 1, fade = true, lighting = smooth, roughness = 0.3, metalness = 0.6
  colors = A:#FFFFFB B:#F5F5F5 C:#D5D9D3 D:#FFFDE0 E:#FCFAF2 F:#EEE G:#B3C9EF H:#DCDCDC I:#C1DCDA J:#EAE7C8 K:#FBF5D4
voxels
416-2(4B20-)4B502-4B20-2(5B19-)4B521-8B14-2(5BA2-2AB13-)5B4A2B17-6B472-4D17-4B3A7B10-2B3A5-2A2B10-BA2-A6-A3B9-B5A4-4AB10-4B10A13-7B19-3B403-2C19-3D2A8D10-BD2A2-8A2B8-B2A10-A2B7-BA12-2AB7-B2A12-A2B7-B4A5-5A2B9-2B3A-3A5B11-3B4AB18-4B92-I119-G47-H71-G45-5C3-2C11-3D2(4A2D)9-BA11-2A2B6-B2A12-AB7-2A14-AB6-2A14-AB7-3A12-AB7-2B2A6-6AB9-B3A2-4A-2A12-2B3EBE113-G30-G37-I26-G54-H16-H30-G13-H2-G46-12C10-2D2A2-AD2A2-2A2D7-BA13-A2B6-2A14-AF5-BA15-2AB4-B2A15-AB5-BA15-AB6-B2A8-6AB7-2BA5-6AF10-B2E3AB2E18-3B196-G3-G115-H37-12C10-2DA2-2AD2A3-A2D7-BA14-AF5-BA15-2AB3-B2A16-AB3-B2A17-B4-B2A16-B5-B2A13-2AB6-BAB7-6AF9-BE2A-AB2EB16-5E353-12C10-2D4A3D5A2D7-BA13-2A3F2-2BA15-3AF2-BA18-AF2-BA18-B3-B2A17-B4-B2A14-2AB5-B3A8-4AF9-BE5AB2EB15-6E94-G47-H167-H43-11C10-16D7-BA13-2A3F2-2BA18-A2BA19-2A2BA19-AB2-2A17-AB4-BA15-2AB5-B2A9-4AF7-2BE6ABA3E13-B2E3AEB19-3B18-H131-G11-G35-H59-2(G35-)12C10-2DJ5D4A6D5-B3A12-3AF2-2BA18-A2BA20-A2B20-AB-B2A17-2AB3-BA15-2AB4-2A12-4AB5-2E8AB3AEB10-2B2E5A2EB16-4EB19-G119-G71-G117-12C10-3D4ADA2-3A4D5-B2A15-AFB-2BA18-A2B2A19-A2BA20-B-B2A18-AB3-A17-AB4-A13-5AB4-EA4-A6-AEB2EB6-4E8AB15-B7E197-G119-G8-13C9-2D3A2-ADA4-A4D4-B2A15-2AFB-BDA18-AB-BA19-A2B2A19-B-B2A18-AB2-2A18-B4-A17-AB4-EA11-2AB2EB6-7B4-3B13-B8E325-15C8-D2A4-3A4-2A2D4-2BA15-2A2F2-2(BA19-AB-)BA18-AB2-B19-AB2-BA18-B4-BA16-AB4-B2A11-AB2EB6-6B5-3B13-6EA2EB90-G51-G19-H95-G3-G61-15C8-2(DA5-A)D5-2BA15-A3F2-B19-2A2BA20-A2BA19-AB2-B19-B3-BA17-AB4-BA16-AB5-B2A9-2AB2EB7-5B5-3B13-9EB37-H95-G190-15C8-DA5-AD2A2-A-AD5-2BA11-2A2-AFB2-B14-A5-AB-B13-2A5-AB-BA19-AB-BA18-AB3-BA16-2AB3-B2A14-2AB6-B2A10-AB2EB7-5B5-3B14-8E50-G119-G47-H71-G34-15C8-DA4-2A2DA4-AD5-2BA15-AFB2-BA18-A2(B2-BA19-)B2-BA18-AB2-BA17-AF4-B2A13-2AF6-BE2A9-2A2B9-5B4-4B14-B7E112-I143-G47-I20-3CK11C7-2DA3-2A3D2A2-2AD5-B2A15-AFB2-B2A17-AB2-2(BA19-AB-)BA18-AB2-BA17-AF4-BA14-2AF5-BE2A9-3AEB8-14B13-2B6E326-14C8-2D2A-2A5D4A2D5-BDA15-AFB3-BA18-AB-BD2(19-AB-BA)18-AFB2-B17-AF4-B15-2AF5-BEA4-2A2-B4AEB8-14B12-5B2E2B327-12C9-3D3A2D3A7D5-B2A14-2AFB3-BA18-A2(B-BA20-)B-BA18-AFB2-B16-2AF4-BA14-2AB5-BEA4-4AB3A-EB8-14B12-9B146-H95-I71-H12-11C10-7D2A-2A6D5-BA14-2ADFB3-B19-AB-B2A19-B-BA20-B2-B18-AFB2-B16-A2F4-BA14-AB7-B2A3-A3EBA3-B9-6B3A5B14-6B88-H14-H32-G4-G57-G8-G4-H47-G9-G32-G14-H9-9C11-6D2A3-2A4D6-B13-3AD2FB3-B18-2AB2-BA18-AB2-BA19-B2-BA16-2AFB2-BA14-2A2F4-B2A12-2AB7-BE5A3EBA2-EB10-B3EB3A3EB17-3B111-G95-I47-G75-8C11-6D2A4-A2D8-B4A10-A3FB4-BA14-4AB3-BA18-AB3-BA17-AB3-BA14-2AF2B3-BA12-2ABF6-B2A7-A2-2AB9-BE2A5EB2AEB12-2B6AEB140-G119-I47-G44-7C12-6D2A2-2A2D8-B4A9-2AB7-BA14-A3FB4-BA14-3AB4-BA15-2AB4-BA13-2AFB6-BA10-2A2F8-B4A4-4AB11-2B6EB3E16-B3A358-4C15-5D4A3D9-2B2A8-2ADB8-3A12-A2B6-BA14-AFB5-B2A13-2AB6-BA11-2AFA7-B2A8-3AF10-B3A4-3AB15-B4E2B18-B3A92-G55-G47-G15-G55-H71-G36-11D12-A5-A-3ADFB8-B2A12-AB7-BA14-2B7-BA12-2AB8-BA9-2AFA9-B2A6-3AB12-3A4-2AB16-B4EBE18-B3A377-10D13-A5-3A2D2FB9-BA12-AB8-BA13-B8-BA11-BAB9-BA7-2BAFB11-B2A5-3B14-BAB3-2B17-BE4B20-2A114-I47-H95-G120-5D17-BA2-3AD5B11-BA5-2A6B8-B2A10-3B8-BA9-5B9-B2A6-4B12-B3A3-2B17-3B-3B18-5B424-7B17-2B5AF4B11-2B2A4-A4B11-2B3A3-A4B11-3B6A2B15-2B4A2B18-5B20-3B451-B4AB17-2BA2-AB17-2B4AB18-6B19-4B108-
