model
size = 20 32 15, scale = 0.05, origin = -y
material deform = 1, fade = true, lighting = smooth, roughness = 0.3, metalness = 0.6
  colors = A:#4B4B4B B:#7C7C7C C:#C2C2C2 D:#4C4C4C E:#595959 F:#404040 G:#CACACA H:#000 I:#777 J:#8F8F8F K:#757575 L:#787878 M:#424242 N:#C1C1C1
voxels
7-6A55-4A15-6A75-4A15-6A192-2A6-2A9-4A4-4A2(8-5A2-5A)8-4A4-4A9-2A6-2A149-BG7AEAC9-AJCAGAC3A11-ACBAD2AB11-CI2ABEDBEA9-B8ACAF10-3AFCE2A12-BADB2AF13-GEG2ABCB12-2AFB4A11-AF7AI11-CBAKAE2B13-6A15-JBIE17-2A18-AB18-BF17-2ACJ17-BI19-A13-4A4-4A7-6A2-6A6-2A2-3AB2A2-2A6-A4-ABFA4-A6-2A2-3AC2A2-2A7-5A2-5A9-3A4-3A127-BCBA8-A2CK6-B2A6-2AC8-B3A4-3AB8-G4A2-5A7-14A7-DB8ABA8-AD7ACBA8-11AJ8-ADA2-2A2-ABD8-11AB8-CE8AFA9-C9A10-BLB6AB10-DGE3ABAMA11-ADI2ABAB12-E5ABI12-GFA2-3A11-2AF4AE2A10-4ADAG3A9-6AF5A7-2A-8A-2A6-A3-6A3-A6-2(A3-6A3-2A5-)14A7-5ABI5A10-3A2-3A107-ABC-2AF4-AEA-CKA3-AD-2AC4-3A-EA4-2A-2AC4-ABA-AE4-2AGC2A4-BE3AD3-F2AB2AJD2A3CAFABG3-AEDB3AFC3AB2AC4-2A2DBADB2AFCB3A4-AF2AGEG2-BCBAJCA4-E2AD2A4-2ABDEC4-DC12-CB4-IG12-AF5-2A10-BA6-3A8-2AB6-I2A8-2AE7-CD8-2A9-C2(8-A10-A)8-A9-A10-A2(8-2A)7-3A8-3A6-3A8-3A5-4A8-4A4-3A10-3A5-A12-A6-3A8-3A7-12A8-12A11-2A2-2A68-A16-A2-D16-B2-2A14-EA2-2A14-DI2-D2A13-2B2-2A14-CA2-A15-A4-A14-G4-E14-C4-DA12-CB4-DA12-2A4-2A12-AC5-2A10-AB6-2A10-AE6-2A10-AD7-B10-B8-C10-F3(8-A10-A)7-2A10-2A6-2A10-2A5-3(2A12-2A4-)2A12-2A5-3A8-3A6-6A2-6A7-12A10-3A2-3A47-D16-F2-A16-C2-A16-G2-C16-A2-2A14-AJ2-C16-A2-C16-C2-A16-C3-D14-A4-C14-J4-EA12-2A4-2A12-2A4-BA12-AE5-A12-A6-2A10-AD6-E11-B7-A11-A7-E11-B8-A10-A7-4(A12-A6-)A12-A5-3(2A12-2A4-)3A10-3A5-14A7-5A2-5A10-2A4-2A26-2A16-2A-A16-A2-A16-B2-A16-A-2A16-2A-J16-A2-A16-A2-D16-B2-E16-A3-A14-AD3-C14-A4-2A12-AD4-2A12-AG5-A12-F6-C12-L6-A11-A7-A11-I7-I11-J7-4(A12-A6-)A12-A5-3(2A12-2A4-)A14-A4-2A12-2A4-3A3-10A5-5A4-5A7-4A4-4A9-3A4-3A5-2A16-4A16-GA-A16-A2-A16-B-2A16-3AB16-FA-A16-G2-A16-A2-B16-B2-A16-A3-F14-F4-BA12-AB4-2A12-2A5-BA10-AB6-CA10-AC6-K11-K7-A11-A7-B11-B7-3(A12-A6-)A12-A5-3(2A12-2A4-)3(A14-A4-)2A4-7A-2A4-6A7-3A5-5A4-5A7-2(4A4-)2A16-4A16-2A-D16-D2-K16-E-2A16-4A16-2A-A16-A2-B16-D2-A16-E2-DA14-2A3-A14-C4-DA12-2A4-GA12-2A5-FA10-2A6-L2A8-2AG6-A-A8-2A7-I11-F7-J11-I7-2(A12-A6-)A12-A5-4(2A12-2A4-)A14-A4-2A12-2A5-A12-A6-A4-7A-A6-5A7-2A5-5A6-5A5-4A6-4A3-2A16-4A16-CA-A16-A2-I16-D-2A16-4A16-2A-2(CA14-2A2-)2A14-AD2-JA14-AC3-2A12-AE4-2A12-2A4-E2A10-2AB5-2(4A6-)D-2A6-3A7-B-2A6-2AE7-A-A8-2A7-B-A8-AE7-A11-A7-A12-A6-A12-A5-3(2A12-2A4-)A14-A4-A14-A5-2(A12-A6-)A4-7A-A6-5A7-2A7-3A6-3A7-4A6-4A3-2A16-2A-A16-A2-B16-A2-F16-A-AB16-2A-2A14-2A2-GA14-2A2-DA14-2A2-2A14-EA3-B14-F4-2A12-GD4-CAB10-3A5-2(BA)6-LB2A7-2AMAB3AEGDA8-2ABA2BAIDADC8-DAIBAFB2AEC9-4AJC2AFGA9-3AEAIBAF3A8-12A8-A10-A7-A12-A6-A12-A5-2(2A12-2A4-)A14-A5-3(A12-A6-)A4-7A-A6-5A7-2A7-3A6-3A8-3A6-3A5-AK2CAEAC2-AF2ABCBA3-AE4ACAG7A4-E4A3HA3H4A3-AD4A2HA4H4AB2-B5A3H2(AH)6A-7AH3AH6A2-C5A2(HA)3H4AB3-5A4HA2H4A4-C4A3HA3H3AE4-B13ACD5-N11AC9-9AC12-AEIBJB132-10A9-2(12A8-)12A7-14A5-16A4-16A5-3(14A6-)14A5-16A5-5A4-5A5-D3AE6-ACG2A4-B4A2C2ADJ3ABA4-C15A4-16A3-D17A3-C14AE4-B14AD4-AE13AD5-CAG9ACDA5-GC2AD4ABDEBA7-2AMCB3AEGDA12-ABAI174-3A2-3A11-10A9-12A8-12A7-14A5-4(16A4-)16A5-14A7-4A4-4A8-CGAFCAGACJAB8-BFB2ADABG3A7-E2AEBDEB3ACGA6-DFACGC2ADJ2ABA6-2AB2AECF3ABDE6-2ABCF2ABDABDCA6-CJABCB2AGEG2AF7-DB4ABF2AD2A9-AEA2CLDCA13-EAKAB253-3A2-3A11-10A9-12A7-3(14A6-)14A7-12A8-5A2-5A9-2A6-2A492-3(2A2-2A14-)2A2-2A87-
