model
size = 32 30 30, scale = 0.05, origin = -y
material deform = 1, fade = true, lighting = smooth, roughness = 0.3, metalness = 0.6
  colors = A:#222 B:#EE2424 C:#111 D:#D65500 E:#EA5D00 F:#63F G:#F60 H:#EE1212 I:#500 J:#853500 K:#A00 L:#700 M:#AD4500 N:#D00 O:#800 P:#C24D00 Q:#993D00
voxels
652-2(8A24-)8C629-14A2(18-14C)881-16A15-3(2C14-)2C877-20A2(12-C18-C)371-5A27-4A349-2G29-2(4G28-)4G20-2(22A10-)C20-C10-C20-C273-A4-A26-6A2(26-A4-A)27-4A221-2E29-4E27-6E26-2E2B2E4(26-E4BE)18-24A2(8-C22-C)272-7A3(25-A5-A)25-2A3-A28-3A125-2D29-4D27-2D2N2D26-D4HD25-D6BD24-D2B2-2B4(D24-DB4-B)D16-26A2(6-C24-C)271-7A3(24-A6-A)25-A4-2A26-4A93-2P28-2P2O2P26-P4KP24-DP2N2-2NPD21-EDPH4-HPDE20-EDH6-HDE20-EDB6-BDE19-3(GEDB6-BDEG18-)GEDB6-BDEG13-26A5-C26-C4-C26-C208-2A28-6A25-3(A6-A24-)A6-A25-A5-A26-5A60-2M28-2M2L2M25-P2O2-2OP22-2DPK4-KP2D19-ED2K6-2KDE18-E3N6-3NE18-E2H8-2HE17-GEHB8-BHE4(G16-G3B8-3B)G28-3BG11-28A4-C26-C3-C28-C142-5A26-2A2-3A24-A6-A24-3(A7-A23-)A6-A25-A4-2A26-4A60-4Q26-2M4L2M21-2DP2O4-2OP2D18-D2OK6-K2OD17-EOK10-KOE16-EK12-KE16-EN12-NE16-EH12-HE15-GH14-H4(G14-GB14-B)G9-30A2-C10-7F11-C2-C10-6F12-C14-5F27-5F26-6F26-7A24-2A5-A24-A6-A24-4(A7-A23-)A6-A25-A4-2A26-4A29-2J26-M-QJ2IJQ-M21-P2M2L2-2L2MP19-D2LO6-O2LD17-DL12-LD16-DO12-OD16-DK12-KD15-EK14-KE14-EN14-NE14-EH14-H4(E14-EB14-B)E9-30A2-C9-A7-F10-C2-C9-F6-2F10-C12-2(2F5-2F23-)F6-2F23-F7(7-A23-A)6-A25-2A3-A28-3A28-4J24-2MQJ4IJQ2M20-MI2L4-2LIM19-PL10-LP18-PO11-LD16-DO12-OD16-DK12-KD15-DK14-KD14-DN14-ND14-DH14-H4(D14-DB14-B)D9-30A2-C8-2(A9-)C-C9-A8-F11-C10-3(F8-F22-)F4(8-A22-A)8-2(A23-A7-)A24-A5-A26-5A58-7J23-QJ7IQ20-2MIL7-I2M18-ML10-2LP17-MO11-LP16-PO13-OD15-PK13-KD14-DK15-KE13-DN15-KE13-DH15-NE13-DB15-HE13-DB15-B2(E13-DB15-H)E13-DH15-NE7-10A11-11AC2(9-A)10-2C2(9-F)10-C10-3(F9-F21-)F2(9-A21-A)8-A22-A8-A23-A7-A23-A6-A25-A4-2A26-4A58-8J23-J8IJQ20-QI8-2IM18-PL11-LP16-PL13-LD15-PO13-OD14-EK15-OE13-EK15-KE13-DN15-KE12-GN17-KG11-GH17-N2(G11-GH17-H)G11-GH17-NG11-GN17-KG6-9A12-11AC8-2(A10-)2C8-2(A10-)C9-F10-F20-F10-3(F21-F9-)A21-A8-A22-A8-A23-A7-A23-A6-A25-6A89-9J21-MJ8IBQM18-P2I9-2IP16-DL13-ID15-DL13-LD14-EO15-LE13-EK15-OE13-EK15-KE12-GK17-KG11-GN17-KG11-GH17-N2(G11-GH17-H)G11-GH17-NG11-GN17-KG6-9A13-10AC8-A11-A9-2C8-A11-A9-C9-A2(10-F20-F)10-2(F21-F9-)A21-A8-A23-A7-A23-A6-A25-A5-A25-F5A89-9J21-MQ8IBQM18-P2I9-2IP16-DL13-ID15-DL13-LD14-EO15-LE13-EK15-OE13-EK15-KE12-GK17-KG11-GN17-KG11-GH17-N2(G11-GH17-H)G11-GH17-NG11-GN17-KG6-9A13-10AC2(8-A11-A9-2C)8-A11-A9-C9-F10-F20-F10-2(F21-F9-)F21-F8-A23-A7-A23-A6-A25-6A27-5F28-2F30-2F27-8J23-J8IJQ20-MI8-2IM18-PL11-LP16-DL13-LD15-DO13-OD14-EK15-OE13-EK15-KE13-EN15-KE12-GN17-KG11-GH17-N2(G11-GH17-H)G11-GH17-NG11-GN17-KG12-EN15-KE7-9A13-10AC8-A11-A9-2C8-A11-A9-C9-F10-F20-F10-F21-F9-F21-F8-F23-F7-F23-F6-A25-A4-A25-F6CF26-F2CF29-2F60-6J24-QJ6IJQ21-MIL6-LI2M18-PL10-2LP17-PO11-LP16-DO13-OD15-DK13-KD14-EK15-KE13-EN15-KE13-EH15-NE13-EB15-HE13-EB15-B2(E13-EB15-H)E13-EH15-NE13-EN15-KE7-9A13-10AC8-A11-A9-2C8-2(A10-)C9-A10-A21-F9-F21-F8-F23-F7-F23-F6-F25-F4C2F24-2F4C2F24-F6CF27-2C93-4J26-QJ4IJQ22-2M2L4-2L2M19-P2L8-2LP18-PO10-OP18-PK11-OP17-PN11-KP16-DN13-KD15-DH13-ND15-DB13-H4(D15-DB13-B)D15-DB13-HD15-DH13-ND8-9A12-11AC8-A11-A9-2C8-A10-2A9-C10-A9-A21-F8-F23-F7-F23-3F2-3F25-F4C2F25-F4CF25-2F4CF156-2J26-2MQJ2IJQ2M22-M3L2-3LM21-PL8-LP19-DO10-OD17-DO12-OD16-DK12-KD16-DN12-ND16-DH12-H6(D16-DB12-B)D16-DH12-HD16-DN12-ND9-10A11-11A-C8-2(A9-)C2-C8-A8-2A9-C12-F7-A23-2F5-F25-2F2-2F26-FC2FCF249-M2-3M-M23-P2MQ2LQ2MP21-DL3O2-3OLD19-D2O7-K2OD18-DK10-KD17-EK11-NKE16-EN10-2HNE16-E2H11-H6(E16-EB12-B)E16-EH12-HE16-EN12-NE10-9A10-11A2-C2(8-A)10-C2-C9-A6-A11-C13-A4-2A26-5F28-3F284-4M26-2MD2-D2M23-D8-D21-D10-D19-E12-E84-8B-BH19-2B11-B17-3(GB12-BG16-)GB13-G16-GB13-G17-EH10-HE18-EH10-HE11-10A8-12A2-C9-2A5-A11-C2-C10-6A12-C14-4A569-10BE19-G4B4-4BG18-GB2-B4-B2-B2(G18-G12-)G19-4B4-3B20-G4B4-4B19-GE4B2-4BEG19-E2H6B2HE12-30A3-C10-6A10-C4-C26-C588-E2-D2BD2-E21-GE2D4B2DEG20-G2-D4BD2-G24-4B28-4B25-E2D4B2DE21-GE2D4B2DEG21-E3D2B3DE22-E2D4E2DE25-4E18-26A5-C26-C4-C26-C560-2G29-4G28-4G29-2G29-2(4G28-)4G29-2G83-26A2(6-C24-C)871-24A2(8-C22-C)873-22A3(10-C20-C)875-20A2(12-C18-C)878-16A15-3(2C14-)2C880-14A2(18-3C8-3C)265-
