model
size = 32 22 32, scale = 0.05, origin = -y
material deform = 1, fade = true, lighting = smooth, roughness = 0.3, metalness = 0.6
  colors = A:#FFF B:#000 C:#19104B D:#32526E E:#DE0000 F:#333162 G:#00FF4C H:#FE0 I:#0008FF J:#D1D1D1 K:#4B4B4B
voxels
367-2(5(2B30-)2B510-)2B6(30-2A)30-2B446-2B8(30-2A)30-2B158-2(2B30-)2B158-2B10(30-2A)30-2B126-2B2(30-2A)3(30-2B)62-2B2(30-2A)30-AB3(30-2A)30-BA30-AB2(30-2A)30-2B123-8F27-2B4(30-2A)2(30-2B)2(30-2A)6(30-2B)2(30-2A)30-2B121-2F8-2F22-8C27-2B7(30-2A)30-AB3(30-2A)30-BA30-AB2(30-2A)30-2B120-F12-F19-3C6-3C23-6D28-2B8(30-2A)30-BA5(30-2A)30-2B119-F14-F17-2C10-2C20-2D6-2D24-6C28-2B5(30-2A)3(30-BA)5(30-2A)30-2B118-F16-F15-C14-C17-2D10-2D20-2C6-2C24-6D28-2B7(30-2A)2(30-AE)3(30-2A)30-2B117-F18-F13-2C14-2C16-D12-D19-C10-C21-2D6-2D24-6C28-2B3(30-2A)2(30-BA)3(30-BE)30-AE2(30-2A)30-2B117-F18-F13-C16-C15-D14-D17-C12-C19-2D8-2D22-C6-C25-6D28-2B3(30-2A)30-AE30-B2(E30-A)E30-BE2(30-2A)30-2B94-2I2(20-F)11-2C16-2C2(14-D)17-C12-C19-D10-D21-C8-C23-2D4C2D27-2B2(30-2A)2(30-AE)30-B2(E30-A)E30-BA2(30-2A)30-2B94-2I2(20-F)11-C18-C13-D16-D15-C14-C17-D12-D19-C10-C21-2D6C2D26-2B2(30-2A)30-BA4(30-BE)30-AE2(30-2A)30-2B94-2I2(20-F)11-C18-C13-D16-D15-C14-C17-D12-D19-C10-C21-D3C2D3CD26-2B4(30-2A)4(30-AE)2(30-2A)30-2B94-2I18-2BF20-F2B6-BABC18-CBAB6-B2ABD16-DB2AB7-B2ABC14-CB2AB8-B3ABD12-DB3AB8-B4ABC10-CB4AB9-B4AB2(CD)2C2(DC)B4AB8-3B5A10B5A3B5-B26AB3-B28AB-2(B4AB2ABAB2A)B4A2B2(4AB2ABAB2AB)4A2B4ABA2BA4B4A4BA2BAB4A2B2(4AB)2AB2AEAB2A2(B4A)2B3A3B3A2(B2A)EAB2AB3A3B3A2B4AB5A2B6A2B5AB4AB-B28AB3-B26AB5-26B19-J31-J26-4HKJ4G14-2BF20-F2B6-BABC18-CBAB6-B2ABD16-DB2AB7-B2ABC14-CB2AB8-B3ABD12-DB3AB8-B4ABC10-CB4AB9-B4AB2(CD)2C2(DC)B4AB8-3B5A10B5A3B5-B26AB3-B28AB-B3A3B5AE6AE5A3B3A2B4AB5A3E4A3E5AB4A2B4AB4A5E2A5E4A2(B4A2B4AB3A6EA7E3A)B4A2B3A3B3A2EA2E2A2EA2E3A3B3AB-B28AB3-B26AB5-26B18-J31-J27-4HJK4G16-F20-F11-C18-C13-D16-D15-C14-C17-D12-D19-C10-C21-D3C2D3CD26-2B4(30-2A)4(30-AE)2(30-2A)30-2B94-2E2(20-F)11-C18-C13-D16-D15-C14-C17-D12-D19-C10-C21-2D6C2D26-2B2(30-2A)30-BA4(30-BE)30-AE2(30-2A)30-2B94-2E2(20-F)11-2C16-2C2(14-D)17-C12-C19-D10-D21-C8-C23-2D4C2D27-2B2(30-2A)2(30-AE)30-B2(E30-A)E30-BA2(30-2A)30-2B94-2E21-F18-F13-C16-C15-D14-D17-C12-C19-2D8-2D22-C6-C25-6D28-2B3(30-2A)30-AE30-B2(E30-A)E30-BE2(30-2A)30-2B94-2E21-F18-F13-2C14-2C16-D12-D19-C10-C21-2D6-2D24-6C28-2B3(30-2A)2(30-BA)3(30-BE)30-AE2(30-2A)30-2B118-F16-F15-C14-C17-2D10-2D20-2C6-2C24-6D28-2B7(30-2A)2(30-AE)3(30-2A)30-2B119-F14-F17-2C10-2C20-2D6-2D24-6C28-2B5(30-2A)3(30-BA)5(30-2A)30-2B120-F12-F19-3C6-3C23-6D28-2B8(30-2A)30-BA5(30-2A)30-2B121-2F8-2F22-8C27-2B7(30-2A)30-AB3(30-2A)30-BA30-AB2(30-2A)30-2B123-8F27-2B4(30-2A)2(30-2B)2(30-2A)6(30-2B)2(30-2A)30-2B126-2B2(30-2A)3(30-2B)62-2B2(30-2A)30-AB3(30-2A)30-BA30-AB2(30-2A)30-2B126-2(2B30-)2B158-2B10(30-2A)30-2B382-2B8(30-2A)30-2B446-2B6(30-2A)30-2B175-
