model
size = 30 31 19, scale = 0.05, origin = -y
material deform = 1, fade = true, lighting = smooth, roughness = 0.3, metalness = 0.6
  colors = A:#4C1566 B:#4F1869 C:#97E2A7 D:#87EB95
voxels
9-2BA2B4A2BA18-BA3B4A2BA18-B2ABA2B5A19-2B2A3BA2B20-2B2A2B2(AB)20-2(4BA)21-BA3BA2B22-2(3BA)23-3ABAB25-3AB27-BA618-2B4AB8-B2AB3A8-2B2(AB)3ABA4BAB3ABA8-A3BA-BAB3A3BA-BA2BA8-BA3BA-2A2(2BA)-3AB2A8-3AB2(2A2B)4A2B2ABA8-A2B3AB4A2B2A4BABA8-4A2B3A2B2(2ABAB)A9-2BABA7B7AB10-3BA2B2AB4A6BA11-2B2(AB)4A2(2B2A)12-3A2B3A4BAB2A2B13-B2AB4A2(2BA)BA14-2(AB)3(2AB)A2B15-5B2(2AB)A2B16-B3ABA2BAB4A17-2(BA)2B5AB19-2B3A2B2AB22-ABA2BA25-2ABA376-B3A16-B2AB6-5A14-2BA2B6-B2A3BA10-2AB4A6-2(B3A)8-3BABA2B6-2B3A4B2A2B2(AB)3AB3A7-2B2(AB)2ABA3BAB2A2(BA)B8-B2ABAB-6A2B-B5A8-AB3AB-3A2BA2B-2BAB2A8-A2B2ABA2BA4BA3BAB2A8-2A2B5A2BAB2(2A2B)A8-ABA2B2A2BA2B6AB2AB8-BA3B3A2B2A3B2A2BABA8-B2A2(4BA)B3A5B9-A2B3A2BA2(B2A)B4A10-5B3A2B3A2(BA)3B10-2A2BA5BA2B3A2(BA)11-5AB3A4B3A2B12-2BAB4A9BA13-2(2BA)2(BA)2BAB2A14-2A6B2AB3ABA15-AB2A2B2A3(BA)19-2A3BABA24-2ABA255-A2B20-B2A4-2BAB18-B2AB4-2ABAB16-A4B5-B3A16-B3A6-2(AB)A14-AB2AB6-A2B3A12-3B3A6-3BA4B8-B2ABA3B6-B5A2B2A3B3A2BA3BAB6-3A2(BA)2(2B2A)B3ABA2BA6-5B4ABA5B2A2B2(AB)6-4B4AB3A2(BA)B6AB6-A4BAB2A8B2(AB)3A6-3A2B7A2BABA5B2A6-A3B2AB2A5B7AB2A6-AB3ABA5BA3BABA4BA7-2(AB)3ABA2B2(AB)A3B3A8-B2(AB2A2B)3AB2ABAB8-2B2ABA6BAB3A2B3A9-A5BA2B8A2BA10-AB4A3BA2B2A3BA2B11-3A2B3A2(BA)2BAB2A12-A3B2A2B3A5BAB14-B3A2B2A3B3A19-2B2ABA2B222-3BA20-2BAB2-3A2B18-B4A2-2(AB)2A16-A2B3A3-AB2AB16-2(AB)A4-BA2B2A14-3BA2B4-B3ABAB12-A3BA2B4-A4B4A8-4A3B2A4-B3AB2A4B2A2BA4B2(2AB)4-4B2A3BA2B2A2B6AB3A4-4A2BA2B3A3(BA)4B2A2B4-BA2B2(2AB)4AB5A2B2(AB)4-A2BAB2A3B4ABAB2AB5AB4-B2ABA5BAB3ABA6BABA5-A3B2(AB)A4B2(A2B)2ABAB6-B5A2B3ABAB2ABAB3A2B6-2A2B3A5BABA3B3AB2A6-AB2ABA3B4ABA2B3(AB)A6-A2BAB2AB4A2(2BA)3(BA)7-4A5B2ABA2BAB3ABA8-A2B2(A3B)2(2ABAB)A9-A4B2A2BAB3AB5A10-B2A2B2A3B2A2B6A11-2B5A3BAB2(A2B)14-B2(A2B)A4BAB18-B2A3BA3B23-B3A164-5(A26-A2-)2(A26-B2-A26-A2-)2A24-AB3-2(B24-B4-)A24-B3(4-B24-A)4-A24-A5-A22-A6-B22-A7-B20-B8-B20-B9-A18-A10-B18-B11-2AB2A2BA2B2AB5A13-2(BA)3BA2B2(2AB)16-ABA4B2ABAB19-B2A3B2ABA21-AB2A4B22-5AB2A23-D3CDC25-2C2D13-AB26-2B2A26-3AB26-B2AB26-3AB26-AB-2(B26-B2-B26-A2-)A2(26-B2-B)26-A2-B26-B3-B24-B2(4-A24-A)4-B24-B4-A24-B5-A22-B6-A22-A6-A22-B7-B20-B9-A18-A11-B16-A12-B16-B13-AB-3B7A-BA15-2AB2A5B2(AB)16-2(AB)A7BAB16-2(B3A)2B2A2B18-3CBA2B3D20-3(CD)C2DC10-2B26-4B26-A3B26-AB2A26-2(BA)26-A2BA26-A3B26-2B-A26-B2(2-B26-A2-A26-A)2-A26-B2-A26-A2-B26-A2-A26-B3-2(A24-A4-)A24-A5-A22-B6-B22-A7-A20-A8-B20-B9-B18-A11-B16-A12-B16-A13-3A10-ABA14-3B10-B2A14-B2A10-2BA15-CD10-CD16-2C10-DC8-BA26-A3B26-2B2A26-2ABA26-2BAB26-4A26-3AB26-2(AB)26-AB2A26-2A-2(B26-B2-)3(A26-B2-)B26-A2-A26-B3-B24-B2(4-A24-A)5-A22-B6-A22-A6-B22-B7-B20-B9-A18-A10-A18-B11-A16-A12-B16-B12-A16-A12-A16-B13-3(D14-)C7-2B26-BA2B26-2A2B26-3BA26-AB2A26-B2AB26-2(AB)26-3AB26-2BAB26-2B2A26-2B-A2(26-B2-B)26-A2-A26-B2(2-B26-A)2-A26-B3-2(A24-A4-)A24-A5-A22-A6-B22-A7-B20-A8-A20-B9-A18-A11-2(B16-B12-B16-A12-)C16-C12-C16-D6-AB26-A2BA26-2B2A26-B2AB26-3AB26-2(AB)26-BA2B26-3BA26-AB2A26-2A-B2(26-A2-A)26-A2-B26-A2-A26-B2-A26-A2-B26-B2-A26-A3-A24-B4-B24-B4-A24-B5-B22-B6-A22-B7-A20-B8-A20-A9-A18-B10-A18-B11-A16-B12-A16-A12-A16-B12-D16-D12-C16-D6-BA26-4A26-AB2A26-4A26-2A2B26-AB2A2(26-2ABA)26-AB-B26-B2-A2(26-B2-B)26-A2-A2(26-B2-B)26-B2-A26-B3-A24-B4-B2(24-A4-A)24-A5-A22-B6-B22-A7-A20-B8-A20-B9-A18-A10-B18-B11-B16-A12-A16-A12-2A14-AB13-2(C14-)D14-D7-2A26-B3A2(26-3BA)26-2(AB)26-2A2B26-2B-2(A26-A2-)2(B26-A2-)A26-B2-B26-A2-A26-A3-2(B24-B4-)A24-A4-A24-B2(4-B24-A)5-2(A22-B6-)A22-B7-A20-B8-A20-B9-B18-B10-B18-A11-B16-A12-A16-B12-2B14-2A13-3(C14-)D7-BA26-4B26-2(AB)26-B2AB26-BA-B26-A2-B26-B2(2-A26-A)2-B26-A3-2(A24-B4-)A24-A4-B24-B2(4-A24-A)4-B24-A4-B24-B5-B22-A6-B22-B6-A22-A6-A22-B7-B20-B8-A20-B9-B18-B10-A18-B11-B2(16-B12-A)16-A13-2(B14-)D3(14-C)8-A2(26-A2-B)26-A3-B24-A4-A24-B4-A24-A4-A24-B2(4-B24-A)2(4-A24-B)5-B22-A6-B22-B3(6-A22-A)6-B22-A6-B22-B7-B20-B8-A20-A2(8-B20-B)9-B18-B10-A18-B11-2(A16-B12-)B16-B13-BAB10-B2A14-A2B10-3A15-DC10-CD16-2(2C10-)2B22-2B4-AB22-2A4-2A22-2A5-2(B22-A6-)B22-B6-B22-A6-2B20-AB6-AB20-2B6-2B20-AB6-2A20-2B7-2(B20-A8-)A20-B8-A20-A8-B20-A8-2A18-AB8-2B18-2A8-BA18-AB9-B18-B10-A18-A10-AB16-BA11-A16-B12-B16-B13-2(B14-)A2(14-B)14-A14-BA12-BA15-2(BA)6-2BAB18-2D6-CD20-DC6-DC13-AB2A3B10-B2A4B6-BA4BAB8-4ABA2B7-AB3A2(4BA)5B2A8-2A2B4A2B3AB2(A3B)8-3A5BAB2A3BA4BAB8-AB5ABAB4A2B2A2BAB8-2A2B2A3B3A2B2(A3B)9-3(2BA)BAB2A4BAB10-AB5ABAB2A7BA10-2AB5AB2AB4A3BA10-2ABA2BA5B4A2(BA)10-B3A2(B2A)2B2A4BAB10-2BA5BA2(B2A)BAB2A10-BA3B3AB2A2B2A4BA10-AB3AB4A8BAB10-B4A2B2A2B9A11-2(4AB)3A2BA2B12-2BA2B2ABAB2ABA4B12-A2B2AB3AB2A3BABA12-3A2(2B2ABA)B2A12-2B6ABAB3A3BA13-2A2B2(A5B)14-2(BA)2BABA4B3A14-2B2A2BA5B2A2B15-4B4A2(BA)2B16-4A2BABA5B16-AB3AB2(A2B)AB17-A3B2A2B3AB19-2BABA2B3A22-6C24-3C3D17-2(2B3A10-)B5A8-AB4A11-A3B5A2(BA)4BA12-2(2A3B)2(2A2B)12-2AB3A6B2(2AB)12-B6AB2(A2B)2(AB)12-2(AB)2(2A2B)2(A2B)13-3B3A2(3B2A)14-4BAB2A2BA3B2A14-ABA3B2(AB)4A2B14-2A3B2(AB)2ABA2BA14-2B3ABAB5A3B14-BAB2A2BA3BA2B2A14-AB3ABAB4A2B2A15-2A2BA4BA3BA16-2A4(BA)4B16-2B2(AB)2A3B3A16-AB2ABAB3A4B16-B2ABA2B3(AB)A16-AB2(A2B)6A16-2(AB)3A3BA2BA17-4A5BA2B18-2B2A3B2A2BA18-2B6A2B2A19-ABA2B2AB2A20-5A2(BA)B21-BA2B4A24-A3B27-2B82-5BADC2A2(BA)16-4ABA2CB5A16-3(AB)2-AB2A2B17-2AB2ACD2BABA18-2A3B2-2A3B18-ABA2BCDAB3A19-3AB2-2A2B20-2(AB)CD2(AB)20-2ABA2-A3B20-A3BDC4B21-3A2-3B22-B2A2C2AB22-ABA2-A2B22-ABADCBAB22-2AB2-A2B23-ABCD2B24-2A2-BA24-ABDCAB24-BA2-BA24-AB2D2B24-BA2-2B24-AB2D2B25-A2-A27-DC58-CD58-2C104-
