model
size = 29 32 27, scale = 0.05, origin = -y
material deform = 1, fade = true, lighting = smooth, roughness = 0.3, metalness = 0.6
  colors = A:#D00 B:#111 C:#EEE D:#E00
voxels
8-3(C3-)C15-8(C-)C11-4(C3-)C191-2B2A2BA21-3B2A2B2A20-3A2B2A2BA19-3A2(2B2A)B16-BA3(2B2A)B13-2BA3(2B2A)2B13-AB3A6-A2B2A12-A2BA9-2(2B2A11-)A2B11-2B2A12-2B2(12-AB13-2A)11-2BA13-2B11-2B14-2B12-A14-2A12-AB13-2A11-BAB13-2B11-B3A12-2B13-A2B10-B2A14-ABA9-B2A15-B3A6-2AB17-BA2B2A2B3A21-5B13-C-19C6-C4-8(C-)C11-4(C3-)C47-A2B2AB22-AB2A2B2A20-A2(2B2A)B2(19-B2(2A2B)A)19-9A2B17-10A2B2(17-B11A)2BA13-AC11A3CB12-7A2B2ABA3CB11-B6A6-A3CA10-2B4A9-2BCA10-AC3A11-BCB10-AC3A12-AB10-B3A13-ACA9-BA2B13-ACA9-2A2B13-A2B10-AB14-A2B10-2B14-ACA10-2BA13-ACA10-ABA13-AB11-2ACA12-AB13-B2A10-3A14-B2A9-3A15-4A6-3A18-9A2B19-2B2A2B14-21C6-C3-2(C-)9C2(-C)3-C7-C3-9C3-C17-BA2B2A2B20-B2(2A2B)A19-9A2B17-10A2B17-B11A17-B8A-2A16-6A2-2A3-A15-4A9-A14-2(BA)10-2BA12-BAB11-3B11-4A11-A2CA10-3A12-A2CA10-B2A12-A2CB9-2BA13-2BCB9-3A14-BCA9-3A15-3A8-2BA15-2AB8-2B16-2AB2(8-3A15-3A)9-3B14-2AB10-2BA13-2AB10-ABA13-2A11-AC2(2A12-)2B2A10-2AB14-B2A9-2AB15-4A6-3A18-11A19-2B2A2B11-C-21C-C6-C2-C-13C-C2-C8-C2-12C-C15-AB7A-2A17-5A2-2A2-A17-B3A4-A3-A16-B3A8-A16-2A10-2B13-3A11-2B2A11-B2A12-A2B10-2BA13-A2B10-3A13-2AB10-3A13-2A2B2(8-BDA14-4A)7-ABD15-2A2B7-A2D15-2A2B2(7-B2D16-3A)2(7-A2D16-2AB)7-B2D16-3A8-BD16-3A8-3A15-2AB10-AB14-2AB10-2BA13-3A10-BC2A12-3A11-4A12-2B12-4A9-2AB15-B3A6-4A16-B11A19-2A2B2AB11-5C15-3C-C-11C11-C2-C9-5C10-2C12-A3DA10-2B11-AB2AD11-2B10-5BD11-2AB9-5B12-2A2B2(8-2AB2A12-4A)2(8-2BAB16-B)8-3A17-2B7-3A17-2A2(7-B2D17-AB)2(6-2A2D17-2A)2(6-2B2D17-AB)6-2A2D17-2A7-A2D17-2A7-B2D17-ACB6-B2D17-ACB7-3A16-ACA7-2A-B15-ACA9-B-A14-AB10-BCA14-AB11-3A13-2A12-ACA12-A14-2B2A7-3AB16-B9ACB19-2A2B2A3B10-3C16-4C5-6C14-2C4-9C14-C9-BA3D14-A9-BC3D14-A9-2(AC3D14-2B8-)BC3D14-2A8-BCD16-3A2(7-ACD17-BA)2(7-BCD17-2A)2(6-AC2D17-AB)2(6-BC2D17-2A)2(6-AC2D17-AB)6-BC2D17-2A6-BC2D17-3A2(6-A2D17-ACB)6-B2D17-ACA7-B2D16-ACA8-2AB15-A2B9-ACA14-AB11-B-A13-2A12-B-A12-2A13-A-2A7-4A15-AC-3A3-2ACB17-BA2(2B2A)B10-2C18-4C-6C18-C8-2C18-C8-BD18-A8-B2(D17-2A8-A)D17-2A8-BD17-AB7-2BD17-A2B2(6-2AD18-2A)2(6-2BD18-AB)6-2(ACD18-ACA5-)2(BCD18-ACB5-)2(ACD18-ACA5-)BCD18-ACB5-BC2D17-ACB5-2A2D17-ACA6-A2D17-ACA6-B2D17-ACB7-B2D16-ACB8-2AB15-3A9-ACA14-2A11-2BA13-AB12-3B12-AB13-2A2B7-2B2A15-A4B4-3B18-BA2(2B2A)7-5C19-5C4-2(2C18-C8-)AD18-B8-AD18-B2(7-BCD18-A)7-ACD18-B7-ACD18-2B2(6-BCD18-2A)6-ACD18-AB6-ACD18-A2B2(5-BCD18-ACA)2(5-ACD18-ACB)2(5-BCD18-ACA)5-ACD18-ACB5-2A19-ACB5-BCD18-ACA6-B2D17-ACA6-A2D17-ACB6-A3D16-ACB8-3B15-ACA9-B2A14-ACA26-AB28-B93-2C19-3C2-6C18-5C3-3C18-C7-A2D18-A7-AD19-A7-2(BD19-AB6-)2(AD19-2A6-)2(BD19-AB6-)AD19-2A6-AD19-ACA2(2(5-BD19-ACB)2(5-AD19-ACA))5-BD19-ACB5-BCD18-ACB6-A2D17-ACA6-AC2B16-ACA7-3B17-AB8-2B17-AB27-A122-2C19-3C5-3C18-C4-5C19-5C3-2(2(BD19-2A6-)2(AD19-AB6-))2(2(BD19-ACA5-)2(AD19-ACB5-))2(BD19-ACA5-)AD19-ACB5-ACB18-ACB2(6-2B18-ACA)7-A19-2(AB27-)A122-2C19-3C2-5C19-5C3-2C19-C7-2(2(BD19-AB6-)2(AD19-2A6-))2(2(BD19-ACB5-)2(AD19-ACA5-))2(BD19-ACB5-)AD19-ACA5-AD19-ACA2(6-B19-ACB)7-A19-2(2A27-)B119-5C19-5C3-2(2C19-C7-)2(2(AD19-AB6-)2(BD19-2A6-))2(2(AD19-ACB5-)2(BD19-ACA5-))2(AD19-ACB5-)BD19-ACA5-BD19-ACA2(6-A19-ACB)6-2B19-2(2A27-)B122-2C19-3C2-5C19-5C3-2C19-C7-2(2(AD19-2A6-)2(BD19-AB6-))2(2(AD19-ACA5-)2(BD19-ACB5-))2(AD19-ACA5-)BD19-ACB5-BD19-ACB2(6-A19-ACA)6-2B19-2(AB27-)A122-2C19-3C5-2C19-C4-5C19-5C3-2(2(BD19-2A6-)2(AD19-AB6-))2(2(BD19-ACA5-)2(AD19-ACB5-))2(BD19-ACA5-)AD19-ACB5-AD19-ACB2(6-B19-ACA)7-A19-2(AB27-)A122-2C19-3C2-5C19-5C3-2C19-C7-2(2(BD19-AB6-)2(AD19-2A6-))2(2(BD19-ACB5-)2(AD19-ACA5-))2(BD19-ACB5-)AD19-ACA5-AD19-ACA2(6-B19-ACB)7-A19-2(2A27-)B119-5C19-5C3-2(2C19-C7-)2(2(AD19-AB6-)2(BD19-2A6-))2(2(AD19-ACB5-)2(BD19-ACA5-))2(AD19-ACB5-)BD19-ACA5-BD19-ACA2(6-A19-ACB)6-2B19-2(2A27-)B122-2C19-3C2-5C19-5C3-2C19-C7-2(2(AD19-2A6-)2(BD19-AB6-))2(2(AD19-ACA5-)2(BD19-ACB5-))2(AD19-ACA5-)BD19-ACB5-BD19-ACB2(6-A19-ACA)6-2B19-2(AB27-)A122-2C19-3C5-3C18-C4-5C19-5C3-2(2(BD19-2A6-)2(AD19-AB6-))2(2(BD19-ACA5-)2(AD19-ACB5-))2(BD19-ACA5-)AD19-ACB5-ACB18-ACB2(6-2B18-ACA)7-A19-2(AB27-)A122-2C19-3C2-6C18-5C3-3C18-C2(7-B2D18-B)7-2(AD19-2A6-)2(BD19-2B6-)2(AD19-2A6-)BD19-AB6-BD19-A2B2(2(5-AD19-ACA)2(5-BD19-ACB))5-A2D18-ACA5-ACD18-ACA6-B2D17-ACB6-BC2B16-ACB7-3A17-2(2A27-)B119-5C19-5C4-2(2C18-C8-)2D18-B8-2D18-B2(7-B2D18-A)7-A2D18-B7-A2D18-2B2(6-B2D18-2A)6-A2D18-AB6-A2D18-A2B2(2(5-B2D18-ACA)2(5-A2D18-ACB))5-B2D18-ACA6-B2D17-ACA6-ACB17-ACB6-2ACB16-ACB8-3B15-3A9-B2A14-3A26-AB27-2B94-2C17-5C-7C16-C9-3C16-2C2(8-ACD16-BA)2(8-BCD16-DB)8-ACD16-DA7-A2CD16-D2A2(6-B2CD16-2DB)2(6-A2CD17-2A)6-2(2(B2CD17-ACB5-)2(A2CD17-ACA5-))2BCD17-ACB6-BCD17-ACB6-ACB17-ACA7-ACD16-ACA8-B2D15-A2B9-BCA14-AB11-A-D13-2A12-3A12-2A13-2B2A7-2A2B15-2B3A5-AB19-B2(2A2B)11-3C16-4C6-4C14-3C4-8C14-C2(10-2B2D14-D)10-2(AC2D14-2DB8-)BC2D15-DA8-BC2D15-D2A2(7-ACD16-DCB)2(7-BCD17-2A)6-2(2ACD17-ACB5-)2(B2CD17-ACA5-)2(A2CD17-ACB5-)2BCD17-ACA5-2BCD17-ACA2(6-ACD17-ACB)6-3B17-ACA7-BCD16-ACA8-A2D15-A2B9-ACA14-AB11-B-D13-2A12-B-A12-2A13-A-2A7-3AB15-2A-3A3-3AB17-BA2(2B2A)B10-3C15-4C-C-13C9-2C-C8-C-6C8-2C12-2(BD)2-D8-A12-B2DBD11-2A11-A2B2D11-2BA9-2A2B2D11-DB2A2(8-2B3D14-2B)2(8-2A2D15-DA)8-2B2D16-AB7-2BD17-AB7-2AD17-2A7-ACD17-2A2(6-B2CD17-AB)2(6-A2CD17-2A)2(7-BCD17-AB)7-ACD17-ACA6-ACD17-ACA7-BAD16-A2B7-BA-D15-A2B9-D-D14-2A10-3D14-2A11-2BD13-AB12-BCA10-3A14-4A7-4A16-AC5A-3AB17-BA2B2A5B8-23C6-C-20C2-C6-C-C5-9C-C15-2AB7D2B17-2A2-6D2B16-AB3-6D2A16-AB10-AB14-DB3D9-2AB11-2DB2A10-2AB11-2B2D11-DB2A10-2BD12-DB2A10-3D12-2D2B10-3D12-2D3B9-2B13-4DA8-B2D13-2DADA7-2AD15-D-DB7-2AD17-AB2(7-2BD17-2A)7-2AD17-AB7-3A17-AB7-3B17-2A8-2B17-2A8-2AD16-AB10-3D14-AB10-B2D14-2A10-B3D13-2A11-A2CA12-AB12-4A9-3A15-B3A6-4A16-B8A2BA19-2A2B2AB11-23C4-5(C-)9C2(-C)3-C4-C2-C3-C-7C3-C18-BDA2B2AB20-2(2B2A)B19-B2(2A2B)A19-B2(2A2B)2A17-2AB7D2B17-2A8D2B17-B9D2AB15-AB3D6-2AB15-B2AD7-3D14-AB2A8-4DB12-A2D11-2DCB10-B3D11-2DAB10-A2D12-2D2A9-2A2D13-D2A2(9-2BD16-B)9-2(2AD16-2A8-)2BD16-AB9-BD16-AB9-A2D15-2A10-3D14-2A10-B2D14-AB10-B3D13-B12-3A11-A-A14-3A9-3A15-B4A5-3B17-B9A22-A2B2A14-20C8-2C9(-C)7-5(C3-)C134-B2A2B2A21-2(2B2A)B19-B2(2A2B)A19-B2(2A2B)2A17-2A2B6DCB17-2A2B7DB16-A2B10D2B2A12-A2B10D3CB11-3B4D6-D3CA11-3B2D9-4A11-2A2D11-2AB11-2A2D12-AB11-2(2BA13-3A10-)3A13-2AB10-2A14-ACB10-2B14-ACA10-2BA13-ACA10-ACA13-A2B10-4A12-AB13-2B11-3A14-B2A9-3A15-5A5-3B17-2AC6AB21-2B2A2B17-3(C3-)C11-10(C-)C11-4(C3-)C222-2B2A2B22-B2A2B2AB20-2(2B2A)B19-B3(2A2B)A15-B3(2A2B)2A13-2A3B6-3A2B13-2A2B8-2A2B12-A2B11-3A12-A2B12-2A2(12-BA13-2B)12-2A13-2A12-A14-2A12-B14-2B12-BA13-2B12-2A13-2A12-2AB12-2A13-2B11-A2B14-B2A9-A2B15-3A2B5-2BA17-2(2A2B)AB21-2B2A2B9-
