model
size = 12 15 32, scale = 0.05, origin = -y
material deform = 1, fade = true, lighting = smooth, roughness = 0.3, metalness = 0.6
  colors = A:#400 B:#EEE C:#111 D:#444 E:#777 F:#555 G:#BBB H:#DDD
voxels
15-5B7-5C7-5A140-5B7-5C7-A3DA7-AD3A7-A3DA7-3ADA7-A3DA7-5A8-3A33-CDC9-3C31-7B5-7C7(5-7A)6-2(5A7-)3ACA7-5C29-9B3-9C3(3-9A)10(3-3A)2(4-2A3-3A)4-2C3-2C28-9B3-9C3(3-9A)7(3-2A5-2A)3-2C5-2C26-11B-3C5A3C3(-11A)3(-2A7-2A)2(2-A7-2A)2-2(A7-A3-)C7-C26-11B-3C5A3C3(-11A)-2A7-2A3(-2A7-AB)2(2-A7-2A)2-A7-A3-C7-C26-11B-3C5A3C-11A2(-10AB)2(-2A7-AB)-2A7-AG-2A7-AH-2A7-AB2-A7-2A2-A7-A3-C7-C26-11B-3C5A3C2(-11A)-10A3(B-2A7-A)C-2A7-2A-2A7-AB2-A7-2A2-A7-A3-C7-C26-11B-3C5A3C-11A2(-10AB)4(-2A7-AB)2-A7-AB2-A7-2A2-A7-A3-C7-C26-11B-3C5A3C2(-11A)-10A3(B-2A7-A)C2-A7-2A2-A7-AB2-A7-2A2-A7-A3-C7-C27-2B2-B2-3B2-4CA5C2-10A2(2-9AB)2(2-A7-AB)2-A7-AG2-A7-AH2-A7-AB2-A7-2A2-A7-A3-C7-C27-4B-5B2-2C2AC2A3C3(2-10A)2-A7-2A3(2-A7-AB)2(2-A7-2A)2-A7-A3-C7-C4-2(A5-)7A4-2B5-3B2-10C2-10A2(2-F9A)5(2-2A5-3A)2-2(2A5-2A3-)C7AC4-7A5-7A4-6B-3B2-2C4A4C3(2-10A)2-FA4(5-3A2-2A)5-2A3-2A5-2A4-8A4-2A3E2A5-A2(E-)EA5-A5EA4-3B3-4B2-2C2(A3C)2-10A2(2-F9A)3(2-2A5-3A)2-2A5-2A3-2A5-2A4-8A4-7B40-6B-3B2-2C4A4C3(2-10A)2-FA2(5-3A2-2A)5-3A3-A5-2A4-8A4-7A52-2B5-3B2-10C2-10A2(2-F9A)2(2-2A5-3A)3-A5-2A4-8A4-7B64-4B-5B2-2C2AC2A3C3(2-10A)2-2A5-3A2-2A5-2A4-8A4-7A75-3B2-B2-3B-5CA5C2(-11A)2-10A2-2A5-3A2-9A4-8A86-11B-3C5A3C3(-11A)2-9A3-9A4-7B87-11B-3C5A3C3(-11A)2-9A4-8A97-12B4C5A3C12A2(-11A)2-9A5-6A98-12B4C5A3C24A-10A3-9A5-5A99-12B4C5A3C24A-10A4-7A7-3A100-12B4C5A3C23A2-10A4-6A111-11B-4C5A2C2(-11A)2-9A6-5A111-11B-4C5A2C2(-11A)3-8A6-4A113-10B2-6C2A2C2(2-10A)3-8A123-9B3-6C2AC2(3-9A)5-6A125-8B4-8C4-8A4-7A137-7B5-7C5-7A6-5A136-
