model
size = 31 31 17, scale = 0.05, origin = -y
material deform = 1, fade = true, lighting = smooth, roughness = 0.3, metalness = 0.6
  colors = A:#939 B:#111 C:#060 D:#FF0
voxels
8-A8B5AC16-5AC2AC5AC16-AB4A3CB3ACA16-AB3CB2ACB3ABA16-B2A2B2(2AC)4A16-B3A2(C2A)CA3B16-AC3AB4ACB2AC16-4ACB3ACAB3A16-3ACABC2AC2BACA16-2AC3AB2A2B2ACA16-AC4ABAB3AC2A16-6ABAB2A2C2A16-6A2B2CAC3A17-AC3A2B2A2C2A18-2ACABCB2AC3A18-2AC2(AB)3AB2A18-3A2B4ABC2A18-2ABCB3AB4A18-A4(B2A)18-AB8ABAC18-B3A2(2DA)BAC17-7AD3A2BCA14-7A5DA2B4C12-2C5A2(D3A)B3A12-5AC3(AD)3ABC2A13-4AC3(AD)3ABCA15-2AC2A2(DA)D2ACAB16-ACAB2ADAD2AC2AB18-7A2C2A20-3A2BAC4A21-9A18-2(A15-A14-)C15-A10(14-17A)14-B16A14-17A15-4(15A16-)15A11-2A2C-14AC-C3A6-2AC17ACA2CA6-AC20AC2A6-A2C22A7-23A8-20AC2A9-21A12-17A15-15A17-13A19-11A16-A2(17-A12-C)6(17-A12-A)17-A12-BA3(15-2A12-2A)15-2A13-B5(15-A14-A)2(15-A)13-A10-A5-A13-A5-2(A4-)2A13-2A4-B4-A25-A4-2A23-2A4-3A21-3A5-3A19-C2A6-4A17-C3A7-4A16-3A10-2A15-2A14-2A11-2A17-2A9-2A14-4(A19-A10-)B4(19-A10-A)19-A11-4(A17-A12-)B17-A12-A17-A13-4(A15-A14-)A15-A8-A5-A15-A5-2(A2-A27-)B2-2A25-2A3-2A23-2A4-3A21-3A4-4A19-C3A5-4A17-4A7-4A15-4A11-2(A15-)2(A13-)4(A19-A10-)B4(19-A10-A)19-A3(10-2A17-2A)11-A2(17-A12-B)17-A13-4(A15-A14-)A15-A8-A5-A15-A5-2(A2-A27-)A2-A26-2A2-2A25-2A2-3A23-3A3-3A21-C2A4-4A19-4A5-4A17-3AB8-3A15-3A3(13-A)2(2(19-A10-A)19-A10-B)2(19-A10-B)19-B6(10-B19-A)11-3(A17-A12-)A17-A13-A15-A7-A6-A15-A6-AB2(28-3A)28-2A-B26-2A2-BA25-2A2-3A23-C2A3-3A21-3A5-4A17-3AB7-4A15-4A11-2A14-A12-5(A19-A10-)2(C19-A10-)A19-C10-C19-A10-A19-B3(10-A19-A)10-A19-B10-C19-A10-BA17-2A10-2A17-2A11-2(A17-A12-)2A16-A6-C6-A22-2A3(28-ABA)28-AB-A26-2A2-BA25-2A3-2A23-AB4-3A21-3A6-2A19-2A10-2A16-A11-3(A19-A10-)B19-A10-A19-B10-A19-A10-B19-C5(10-A19-A)10-A19-B10-C19-A10-A19-A10-BA2(17-2A10-2A)17-2A11-A17-A12-2A16-A6-C5-2A16-A5-AB28-ABA3(28-3A)28-AB-A26-AB2-2A25-AB3-2A23-2A5-3A19-3A9-2A16-A11-2(A19-A10-)B2(19-A10-A)2(19-B10-A)19-B10-B19-A10-A19-B10-A2(19-A10-C)19-B3(10-A19-A)10-2A17-2A10-BA2(17-2A10-2A)17-AC10-3A16-AC5-A5-2A16-A5-AB28-2AC28-3A28-ABA28-3A28-AB-A26-AB2-2A25-2A3-2A23-2A5-3A19-3A9-2A16-A11-3(A19-A10-)A19-B3(10-A19-A)10-A19-B10-B19-A10-A19-B2(10-C19-A)3(10-B19-A)10-2A17-2A10-BA17-2A10-2A17-AB11-A17-A12-2A16-A6-B5-2A16-A5-BA28-2AC28-3A28-ABA28-AB-A26-2A2-2A25-2A3-2A23-2A4-3A21-3A6-2A19-2A10-2A16-A11-A5(19-A10-B)19-A10-C19-A10-A19-B10-C19-A10-B3(19-A10-A)19-B10-A2(19-A10-B)A17-2A10-BA17-AB11-B17-A12-A17-A12-2A15-2A6-B6-A15-A6-2A28-2AC28-3A28-AB-A26-2A2-2A25-2A2-3A23-3A3-3A21-3A5-3A19-3A7-4A15-4A11-A15-A12-2(A19-A10-)B19-C10-C19-C10-A19-A10-C2(19-A10-A)19-C10-A2(19-A10-B)4(19-A10-A)19-A11-2(A17-A12-)B17-A12-A17-A13-A15-A8-B5-A15-A5-A2-A27-A2-C27-A2-A27-B2-2A25-2A2-3A23-3A3-3A21-3A4-4A19-4A5-4A17-3AB8-3A15-3A3(13-A)3(19-A10-A)19-C2(10-A19-A)10-C19-A10-C19-C10-A19-A2(10-2A17-2A)10-BA17-2A11-3(A17-A12-)2A15-2A12-2A15-AB13-2(A15-A14-)A15-A8-A5-A15-A5-A2-A27-A2-B27-A2-2A25-2A3-2A23-2A4-3A21-2AB4-4A19-4A5-4A17-4A7-4A15-3AB11-2A13-2A16-ABA7-3A14-2(A19-A10-)A19-C3(10-A19-A)10-A19-C10-A19-A10-C19-C11-C2(17-A12-A)17-A12-B2(17-A12-A)17-B13-4(A15-A14-)A15-A9-A4-A15-2(A4-)A2(25-A4-B)A23-2A4-ABA21-2AB5-3A19-3A6-4A17-2ABA7-3AC15-4A10-2A15-CB14-A2BA7-2ABA19-A7-2(A17-)2(A12-B17-)2(A12-A17-)2(C12-A17-)2(A12-A17-)C4(12-2A15-2A)13-2(A15-A14-)2(2A13-AB14-)2A13-2A14-CA13-2A15-A13-A11-3A2-A13-A2-2(3A6-3A19-)3A6-B2A19-3A7-BA19-2A8-AB2A15-AB2A9-ABC15-2AB12-B15-A15-2B3A5-3A2B20-A5-A24-A5-A19-2(2A13-2A14-)BA13-2A14-AB13-2A14-2B13-2A14-AB13-2C4(14-2A13-2A)14-2A13-BA14-AB13-2A14-2A13-2A2(14-3A11-3A)15-2(2A11-AB16-)2(2A11-2A16-)CA11-2A14-BACA2(11-4A)13-4A2(10-3A15-3A)11-2A15-2B2(13-2A)15-14AC16-B11ABAC21-CA2(B2A26-AC)3A22-13A18-4AC8A18-5AC2B5A18-ABAC2ACA2B3A18-BABC3AC2A2BA18-2B2AC3ACA3C18-A2BAC2BA2C3A18-A3BACA2BABAC18-2ABABC2A2B2AC18-2A2BAC4A2BC18-3A3BCB3ACB18-3ABABCA2BACA18-B2A3BACA3BA18-B3ABABC2AB2A18-AB3ABAC3ABA18-AB3AB2AC3AB18-2AB3ABACB3A18-2AB3AB2AC3A18-2AB7AB2A18-4A2(2DA)CBA18-C5AD3ACAB17-2AC2A5DACABA15-3AC2AD3AD2ACABA14-2ABAC3(AD)2AC2AB15-2ABC3(AD)ABACA17-4A3(DA)BAC19-4ADAD3AB21-9A104-
