model
size = 12 15 32, scale = 0.05, origin = -y
material deform = 1, fade = true, lighting = smooth, roughness = 0.3, metalness = 0.6
  colors = A:#EEE
voxels
15-2(5A7-)5A140-7(5A7-)5A8-3A45-3A31-8(7A5-)7A6-3(5A7-)5A29-5(9A3-)2(3A4-2A3-)5(3A3-)3(3A4-2A3-)2A28-5(9A3-)7(2A5-2A3-)2A5-2A26-5(11A-)2(2A7-2A-)2A3(7-2A2-A)2(7-A3-A)7-A26-5(11A-)2(2A8-A-)2A7-2A-2A2(7-2A2-A)2(7-A3-A)2(7-A26-5(11A-)2(2A8-A-)2(2A7-2A-)2A7-2A2-2(A7-A3-)A)7-A26-5(11A-)2(2A8-A-)2A7-2A-2A2(7-2A2-A)2(7-A3-A)7-A26-5(11A-)2(2A8-A-)2A3(7-2A2-A)2(7-A3-A)7-A27-5(10A2-)5(2A5-3A2-)2(2A5-2A3-)2A5-2A4-3(A5-)A4-5(10A2-)5(2A5-3A2-)2(2A5-2A3-)2A5-2A4-7A5-7A4-5(10A2-)5(2A5-3A2-)2(2A5-2A3-)9A4-7A5-7A4-5(10A2-)4(2A5-3A2-)2A5-2A3-2A5-2A4-8A4-7A5-7A16-5(10A2-)3(2A5-3A2-)2A5-2A3-2A5-2A4-8A4-7A40-5(10A2-)2(2A5-3A2-)2A5-3A3-A5-2A4-8A4-7A52-5(10A2-)2A5-3A2-2A5-3A3-A5-2A4-8A4-7A64-5(10A2-)2A5-3A2-2A5-2A4-8A4-7A75-3(11A-)11A2-10A2-2A5-3A2-9A4-8A86-4(11A-)11A2-9A3-9A5-5A88-4(11A-)11A2-9A4-8A97-36A2(-11A)2-9A5-6A98-48A-10A3-9A5-5A99-48A-10A4-7A7-3A100-47A2-10A4-6A111-3(11A-)11A2-9A6-5A111-3(11A-)11A3-8A6-4A113-3(10A2-)10A3-8A123-3(9A3-)9A5-6A125-3(8A4-)7A137-2(7A5-)7A6-5A136-
