model
size = 26 31 9, scale = 0.05, origin = -y
material deform = 1, fade = true, lighting = smooth, roughness = 0.3, metalness = 0.6
  colors = A:#FFF B:#DFDFDF C:#F6F6F6 D:#C1C1C1 E:#F3F3F3 F:#F9F9F9
voxels
306-2A23-3A22-B2A25-5A21-B2A50-A24-3A7(22-4A)22-3A23-3A306-3A23-5AE20-6AE19-4A2-A20-2A3-2A19-A3-4A19-2A5-A18-2A3-2A20-5A20-B2A-2A20-2A3-A20-A2(4-A19-2A)5(4-2A18-2A)3-2A19-2A3-2A20-5A120-A24-CA23-2AC22-2A-3A21-6AE13-3A3-7A2E11-4A5-2A3-A2E9-5A4-2A6-BA8-4A5-A7-B17-A7-A18-A7-A17-A8-A17-A7-A18-A5-A20-A4-2(A19-A5-)4(A18-A6-)5(A17-A7-)A18-A5-A20-5A23-A15-2A24-CA2C22-2CA-A21-AC2-A12-A8-A3-2C10-2A7-A2-A3-E9-AD7-2A6-2E7-A4-2AD-2A8-2F10-A2-6A7-2BA7-A4-3A-2(A8-)2(A3-)A8-A9-3A5-A8-A17-A7-A17-A8-A16-A8-A17-A6-2(A19-A5-)4(A18-A6-)7(A17-A7-)A18-A5-A20-5A4-AD4-7A12-3CD2-D3C4-A11-2A2D2-A3C4-A11-3A2D2-3C5-B10-A-AD2-D3A5-B10-A-5D2A7-2E8-2AD2A2D2A9-2F6-A2-2A3-A11-AB5-2A2-A7-A8-2A7-2A4-2A-2(A8-)2A2-A3-A8-A9-3A5-A8-A16-A8-A17-A8-A16-2A7-A18-A5-A19-A5-3(A18-A6-)9(A17-A7-)A18-A5-A20-5A4-A2DAD8A12-A3-2D8-A11-A3-2D9-A10-A4-2D8-B10-A3-2D9-B10-A15-2B8-A17-F8-2A16-2A7-5A6-A7-3A9-A3-2A-A8-A10-ACA3-2(C8-A17-)C7-A17-C8-A16-CA7-A18-C5-A19-C5-A18-C2(6-A18-A)6-9(A17-A7-)A18-A5-A20-5A4-D11A14-A11-2A11-BC2(13-B10-BA)2(13-A11-B)13-2ABF9-2A10-B3-2BA7-2A3C6-2A5-2B11-2CA2BA-B6-ABA17-B7-2(B17-B7-A)17-2(B7-A18-)B5-B2(19-B5-A)19-C5-2(A18-A6-)5(B17-A7-)2(A17-A7-)A17-A6-A19-A5-A20-5A6-8A17-6A2-4A14-C3A6-2AB2(13-C3A7-2A)B12-C3A7-2AB12-2C3A5-2AB15-2BAC6A-B2A14-4BC2A2-2(4AB21-B)4A2B19-B2A3-B20-B4-AB18-BA3-3B20-B4-AB19-B4-B21-B3AB20-5AB20-B3-AB20-C4-B19-C5-B19-A5(5-A19-B)4-2A2(19-2A2-3A)20-5A22-A40-2A22-6A20-2(7A19-)7A20-5A137-2AB22-3AB21-4A24-3AB22-3AB74-3A22-2(5A21-)5A2(20-6A)2(21-5A)21-4A23-2A24-2A57-
