model
size = 18 14 8, scale = 0.05, origin = -y
material deform = 1, fade = true, lighting = smooth, roughness = 0.3, metalness = 0.6
  colors = A:#FCF B:#0FF C:#001 D:#111 E:#222 F:#0F6 G:#EEE H:#F90 I:#396
voxels
26-G2BG250-2B17-4B2(17-2B)2(17-B)9-4A5-B8-4A4-B99-4B16-B87-4A13-6A12-6A13-4A84-2B4-B12-5B13-6B12-6B30-B4AB4(12-6A)13-4A66-B6-B10-2B4E2B11-6B12-B4DB13-4D13-B4AB5(12-6A)11-2AB2-B2A10-AB4-BA10-B6-B10-B-D2-D-B10-2B4E2B11-2B2A2B12-B3AIB10-3C4D10-2C-B2ABAB8-2C2-6A7-2C3-6A6-2C4-AC4A5-2C5-6A5-C6-6A5-C59-B6-B10-2B4E2B11-6B12-B4DB13-C2GD13-6B2(12-AB2ABA)12-AC2ACA12-AH2AHA12-6A66-B4-B13-4B31-6B30-6B12-2B2-2B12-6B12-BC2FCB12-B4FB12-6B59-
