model
size = 9 8 27, scale = 0.05, origin = -y
material deform = 1, fade = true, lighting = smooth, roughness = 0.3, metalness = 0.6
  colors = A:#C39 B:#0CC C:#AAA D:#BBB E:#EEE F:#222 G:#444 H:#500 I:#63F J:#636 K:#D00 L:#800 M:#200 N:#939 O:#A00 P:#639 Q:#400
voxels
57-3B6-CDC59-5B4-2(CD)C57-7B2-3(CD)C10-2A2(5-4A)5-2A19-7B2-3(DC)D-2A5-3A2(7-2A)7-3A5-2A10-7B2-3(CD)C-2A5-3A7-AN7CNA2-3C2-3A2-C2-2A4-C5-2BFGF2B2-3(DC)D-2A5-3A2(7-2A)3-C3-3A2-C2-2A4-C5-2BCGC2B2-3(CD)C10-2A2(5-4A)5-2A4-C8-C5-2BFGF2B2-7E56-B5JB2-7E56-3(BP)B2-7E56-B5IB2-7E56-7B2-3(DC)D56-2(B2M)B2-3(CD)C56-3BQ3B2-3(DC)D56-B5HB2-3(CD)C56-7B2-3(DC)D56-B3LBLB2-3(CD)C56-3(BO)B2-3(DC)D56-BKB3KB2-3(CD)C10-2A2(5-4A)5-2A4-C8-C5-2BFGF2B2-3(DC)D-2A5-3A2(7-2A)3-C3-3A2-C2-2A4-C5-2BCGC2B2-3(CD)C-2A5-3A7-AN7CNA2-3C2-3A2-C2-2A4-C5-2BFGF2B2-3(DC)D-2A5-3A2(7-2A)7-3A5-2A10-7B2-3(CD)C10-2A2(5-4A)5-2A19-7B2-3(DC)D56-7B2-3(CD)C57-5B4-2(CD)C59-3B6-CDC3-
