model
size = 22 31 15, scale = 0.05, origin = -y
material deform = 1, fade = true, lighting = smooth, roughness = 0.3, metalness = 0.6
  colors = A:#4F1869 B:#4C1566 C:#97E2A7 D:#87EB95
voxels
359-B2A2-B2A12-3B2A2BAB2AB10-AB4A2BAB2A9-2BABA3BA2BABA8-5B3ABA2BAB7-2(AB)3ABA3B2(AB)6-B2AB6A2(B2A)5-AB2ABA2B2-B2ABA2BA4-B5AB4-3B2(AB)4-BA3B8-3A2B4-A2B12-2BA4-2B14-2B254-BA18-3(BA)14-3B2ABA2BA12-4(AB)2A11-B2ABAB2A3BA10-3BAB4A3B9-ABA2B2(AB)A3BA8-2BABA3BAB2A2B7-B3A6BAB3AB6-B2ABA3B5AB2A5-2A2BAB2A3(BA)B3A4-2(3ABAB)5AB3-3B8ABAB2A2BAB2-BAB2AB4AB2A2B2A3B2-5ABA2B2AB4ABA2B2-BA2B3A2BA4B2A3BA2-A3B2(AB)A3B4ABA2B2-2(BA)2B2A4B6ABA2-3B2ABA6-2B2AB2A3-4A10-A2BA4-2A14-BA55-C3D16-4B4A14-B3AB2AB13-A2B3A2(BA)12-2B2(2AB)AB11-7BA4B10-2A2B4AB3A9-2(AB2AB)4A8-3A2B4AB3AB7-2B2A2BA4B5A6-B4A3BA2BA3BA6-2BAB4AB2A2BA2B5-B5A3B2ABA2B3A4-B4A4BAB3A3BA4-2BA3BAB3A3B2(AB)3-2A2BA6B5AB2AB2-BA3B3A5B2A2BABA2-AB9A2(B2A)3B2-2A5BA2B2AB3A3BA2-A4BABA2(4B2A)2-2A3BABA2BABA3B2ABA2-2AB3A2B2ABAB2A2B3A2-3AB3A4BA2B2A2(BA)2-3AB2A2B3A3B5AB2-BA2B2(AB)2ABA5BABA2-B3AB7ABA2B2ABA2-A2BABA2B4A3BA4B2-3(AB)8-2BAB2A2-3ABA10-3ABA3-2B14-2A29-2D2CDCD3CDC10-2(BA)3BA4B9-B3AB2A2B3ABA8-3ABA3BABA3B8-BA2BA3B2(A2B)7-2B2A2BA6B2AB6-3A2B2AB7AB6-AB4A2B5A2BA5-4BA3BA4BAB3A4-4B4A2B2A2B3AB4-ABA3B3A3B4A2B3-2BA2B4A4B2A2BA2B2-3BA2B5A3BABA2BA2-B8AB2A2B2A3BA2-A3B2A2B3AB7AB2-2ABA2B2AB2A3(2BA)2-2BA6B3AB2A3BAB2-B3A4B6(AB)2-3AB3A2BAB2ABA4BA2-B18-B2-A18-A90-A18-B2-B18-A2-A3B12-2A2B2-2(AB)12-2B2A2-2(BA)12-4B3-AB14-2B6-D12-C8-A12-B7-AB12-2A6-2B12-2A6-BA12-2B6-BA12-AB6-2A12-BA5-B2A12-ABA4-3B12-2AB4-A16-A3-BA16-BA2-BA16-AB2-2B16-BA2(2-BA16-2A)2-AB16-AB2-BA16-2A2(2-A18-A)178-A18-B2-B2AB12-2B2A2-A2BA12-3AB2-AB2A12-3BA4-D14-C6-B14-B6-A14-B5-2A14-2B4-BA14-AB4-2B14-2B4-2A14-BA4-2B14-2B3-BAB14-AB2(A2-B18-)B2-B18-B-2B18-B2AB18-4A18-2B2A18-BA-B18-A2-B18-A222-A18-B2-2BAB12-2A2B2-AB2A12-AB2A3-D16-D4-B16-A4-A16-A4-B16-A3-BA16-AB2-AB16-BA2-BA16-2B2-B18-AB-A18-2ABA18-ABA20-2A2(20-2B)2(20-BA)20-B-B18-B244-A18-B2-2BAB12-BA2B3-ABA12-B2A4-C16-C4-A16-A4-A16-B4-B16-A3-2A16-2B2-BA16-BA2-2B16-2A2-B18-2(BA)18-4B18-4A18-3B20-2A20-AB20-2A2(20-BA)20-A221-A18-A2-2(AB)12-2ABA3-AB14-2A6-A12-B6-C16-D4-B16-A4-A16-B4-B16-A3-2B16-2B2-2A16-AB2-BA16-2A2-AB16-AB-2A18-2ABA18-2(BA)18-4B18-2A3(B20-A)B2(20-2A)20-BA20-B155-B18-A2-2B2A12-3BA3-AB14-AB5-2A12-2A28-C14-C6-B14-B6-A14-A5-2B14-2A4-AB14-AB4-2A14-2A3-2AB14-2BA2-3B14-B2(AB2-2A16-)2A-AB18-A2BA18-A3B18-2A2B18-BAB2(20-2B20-BA)20-2A20-AB20-2B20-A-A2(18-A2-B)18-B2-B2A14-B2A2-B3A12-2B2A3-BA14-BA6-A12-B51-2D12-2C6-2A12-2A2(6-AB12-BA)6-2A12-AB5-A2B12-2AB4-ABA12-BAB4-2AB12-3A4-AB14-2B3-A2B14-2AB2(2-A2B14-A2B)2-2B16-AB-2B18-2(AB)18-2ABA18-3A3(20-BA)20-2B20-2A20-B2A18-2BAB18-AB-BAB14-BAB3-B-B12-A-A4-3B12-BAB6-B12-A74-DC5D3CDC2D8-3BA4BAB2ABA8-2ABAB2A2B2A3B8-2B3AB2A2B3AB7-BAB3A3BAB2A3B6-2A2B2AB2A2B3ABA6-A2B3AB2A2B4AB6-2A2B3A5BAB2A5-4AB2(A2B)2AB2A2B4-2(2B3A)B2A4BA4-3ABA4B2A3B2ABA3-A2B2ABAB4AB2AB4A2-AB6A2B3AB2(A2B)2-4BA2BAB4A2B3A2B2-B4A3(BA)2B3A2B2A-2BA2B2A3B5A2B4AB2A2(BA)2BAB2A3(4BA)6B3AB3A2B2(A3B)AB2A2B4A3BA2(B2A)2B3(AB)2A2BA3B2(AB)5A2(BA)3BA4B2(AB)4A2B4A2(BA)B3A2(BA)4BAB2A2BAB2A3BA2BA-2(2AB)5AB2A5BA3-B-B3AB4-5B-A5-ABA2B6-A4B122-CD2C17-2A3BA15-3BA2BAB13-B6A2BA11-3B3A3(BA)9-3A4B3ABA2B7-2A2(BA)2B2(AB)A2BA6-B3A2BA4B5A6-2(AB)7A3B2A6-BAB4ABA4BA2B5-B3ABA2B2A2B4ABA4-2A2B2(3AB)AB4A4-2B2ABAB5A2(2BA)3-ABA10BAB3A2B2-A2BA4B3A3B4ABA2-A3B2A2BABA3B2(A2B)2-2AB3A2B2A3B4A2BA2-3(AB)2ABA2B2A2BA3B-5A2BAB2ABA2B7ABA3B2A7B2(A3B)AB2A2BA3BAB6A4B-B3AB2AB3A2B5A2B3-2B2A7B2AB4A5-A3B2AB2-A2B2(AB)6-3B2A6-2(BA)B167-2B19-3BA17-3(AB)15-B5A2B13-A2B2A4BA12-A2(B2A)BAB12-B2ABA2B2AB11-3A3BA3B2A10-2(2BA)3(BA)9-BA2B2A3BA4B8-3B5A2B2A2B8-2AB2A3BAB2ABA8-BA4B5A2BA7-3BAB2A2B4AB2A6-2AB7A3B2AB6-AB2ABAB3A5BA6-2B3(AB)8A6-2B2A4B4ABA2B7-A2B2A2BA2(B2A)9-BA6BA2BA11-A3B2(AB)2A13-2BA2-3B303-AB19-2A2B18-A3B18-2B2A17-2(B2A)16-2BAB2A16-BA3BA15-3B4AB13-B2AB3ABAB12-A2B3A2B2A12-BA3B2AB2A12-2(AB)A5B13-2(AB)3AB15-A5B16-B5A17-2(AB)229-
