model
size = 16 6 16, scale = 0.05, origin = -y
material deform = 1, fade = true, lighting = smooth, roughness = 0.3, metalness = 0.6
  colors = A:#FCFAF2 B:#F6C555 C:#FFF D:#111 E:#FFD556
voxels
-C5BD2ED2(5B2-)5B3-B3ACB2-B4AB-B4AC4BC4A2(2B14A)B48-2(A14-C96-)2(A14-C80-)10(C14-C80-)C14-C
