model
size = 10 32 17, scale = 0.05, origin = -y
material deform = 1, fade = true, lighting = smooth, roughness = 0.3, metalness = 0.6
  colors = A:#4C1566 B:#4F1869 C:#97E2A7 D:#87EB95
voxels
225-DC7-DCD5-2D4C4-3D2CD3-2C2DCDC3-2C2D7-2C79-BA7-2A2B6-2(AB)137-ABA6-A2BAB5-4ABD4-2ABA-C3-C-C2D-2C2-D-4C-D2-CD3C2DC2-C-AC6-D-C7-3D7-2D20-2(CD8-)2D8-2D7-2(A2-A6-)2B2A6-B3A6-2(AB)7-AB8-A39-2(2B8-)2A7-A2BA6-2BAB6-2A2BA5-A4B5-D3B-A3-DC2-BA-D2-DC3-B2D2-CD3-B-D2(-C)4-2D2(-C)5-D-C-D5-C2(-D)2(7-D-D)8-C11-DC8-2C8-CD7-C-DC6-A2-B6-A2BA6-A2-B6-B2-A6-2B2A6-A2-B6-2(BA)6-4A6-BA2B6-2A2B6-A2-A6-2B-B6-2(BA)5-A-BA-A4-BA2-2B4-BA2-B-A3-BA3-AB3-D4-A-B-CD5-2C-CD5-2D-2C5-A-C2D7-DCD7-D2C6-B2CD6-C-D-C7-C-D8-CD39-C3D6-3BA5-AB2-A5-2B2-A5-BA2-B6-A-2B6-A3B6-B-AB6-2B2A6-2BAB6-A2B-A5-BAB-A4-A-B3A4-BA2-2A4-2B2-2B4-AB3-BA3-2A3-AB2-CB5-AB-2C5-BA-CD5-D-DCD5-CD2(2C7-ADC7-A)D2C6-2C2(2D8-)DC39-5C5-2(AB)A5-2A2(2-B5-2A2-A5-AB)2-A6-B2-2A2(5-A2-BA)4-2A2-2A4-2B2-2A4-AB3-4(B4-)2A3-B4-BA3-2A4-B2-CB5-BA-CD5-D-2CD6-ACD7-B2(DC7-A)2C7-ACD7-A3C6-2D2(CD8-)2C29-CD3C5-DCD2C5-B2-BA5-B3-B5-B3-2B4-2B2-2A4-AB2-2B4-BA2-2B4-2A2-2A4-2B2-BA4-2A2-AB4-2A2-2B4-AB2-2B4-2B3-B4-A4-2B3-B4-BA3-A5-B3-A5-A3-A5-BA2-D5-C-3D5-B-2CD6-AD2C6-ACDC6-ADCD6-AC2D6-ACDC6-2(CD)8-D-C7-D2C28-3D2C5-2BA-A5-B2-BA5-B3-2B2(4-2B2-2A)4-AB2-2B4-2(B-)2B4-AB2-2A4-AB2-AB4-B2(-A)B4-2(A-)AB4-BA2-2A4-BA2-BA4-2A3-2B3-AB3-2B4-B3-2A3-AB3-2B3-2A3-BAB2-C5-CDC-D5-B-DCD5-ABC2D5-BA3D6-ADCD6-BDCD6-A2D-D5-3C-C7-D-D8-2C8-3CD5-A2(DC)D4-A-2A-A5-A2-AB5-A3-2(AB4-BA2-)A6-2A-A6-3AB6-4A6-4B6-A2BAB5-A-A2B5-A-B2A5-2BABA5-B2ABA5-A4B5-2ABAB5-ABA2B5-B4A4-3A-3A3-2B3AB-D2-2CD-2B-AC-2D3-A-BC-DC3-B-AD-DC4-BA2C-C4-B-2C-D4-B-2D-C4-D2C2(-C)7-C2(D8-)2C2D2C2(4-A4-B)4-A-2B3A4-BA2-BA4-BA2-B6-4B6-A-BA6-AB2A7-BA8-AB8-BA8-2A8-BA8-2B8-BA8-2A8-AB8-BA8-2AB7-BA2B6-B2ABC4-2CA2-2D3-D3B-2D3-DABA-BD2-D-3BA-D2-C-2ACA-D2-C-D3C-C2-C-C3-2D2-CD8-D18-2(C2D)4(4-A)B3-A4-AB4-B-2AB5-A-3B6-2B2A6-2BA149-3D6-D2-C5-DC2-DC4-DC3DC3-2C2D-D2C2-C2D3-2C2-DC5-D31-6C4-A4-2B3-B4-2A3-A4-A5-A2-2A6-3B179-DC8-DC74-3D2CDC3-B5-B3-A4-A5-2(BA)7-2B276-2C2DC2D3-B5-A4-ABA2B294-C2D3CD4-B2A-B6-AB2A295-2CDCD5-BA2-A7-BA297-D2C7-2AB305-
