model
size = 31 32 31, scale = 0.05, origin = -y
material deform = 1, fade = true, lighting = smooth, roughness = 0.3, metalness = 0.6
  colors = A:#E83015 B:#222 C:#FFB11B D:#444 E:#FCFAF2 F:#555 G:#F7C242 H:#96632E
voxels
832-2(3C28-)3C2(30-C)840-18C7-3C4-C23-3CD3-C23-3C4-C23-3C3-18C9-C840-18C7-3C3-2C16B7-3CD2-2(2C16B7-3C3-)13C-14C18-D642-5(2D29-)2D22-7C2D9C7-3C4-B5C2D9C7-CB-D3-B5C2D9C7-CB5-B5C2D9C7-CB4-13C-14C365-D30-D89-B63-2B29-2B78-2D39-5D109-2D22-3C4-2D16-3C4-2(BC4-2D16-CB5-)BC4-2D16-CB4-3C24-C265-10A21-10A11-9A-10A11-9AB2(10A11-9A-)2(10A13-7A-)4AB5A2(13-7A-10A)13-7A3(-2A7-A11-5A4B)-3A6-A11-5A4B-3A5D-A11-2(5A4B-3A18-)9A-3A21-2D22-3C4-2D16-3C4-2(BC4-2D16-CB5-)BC4-2D16-CB4-3C24-C274-A30-2(A11-A7-A10-)2(A11-A9-A8-)5(A21-A8-)3(A11-A4-4B-A8-)A9-2DA4-4B-A2-5D-A9-D-A4-4B-A18-D-A4-4B-A20-9A-3A2-2B17-2D10-2B10-3C4-2D16-3C4-BC4-2D16-CB5-BC4-2D16-CB-D3-BC4-2D16-CB4-3C24-C274-A30-2(A19-A10-)A17-3B-A8-A11-A5-4B4(A8-A11-A5-3B-)A8-A11-A9-4(A8-A11-A4-4B-)A2-5D-A11-A4-4B-A8-A9-D-A4-4B-A8-A11-9A-10A14-2D4A2-4A2B2A8-3C4-2D14A2-3C4-BC4-2D14A2-CB5-BC4-2D2AG11A2-CB5-BC4-2D14A2-CB4-3C22-3C274-A30-2(A19-A10-)A17-5(3B-A8-A11-A5-)4B5(A8-A11-A8-B)A2-5D-A11-2(A8-BA8-A9-D-)9AB10A9-D4-2D2(4A2B)2A8-3C4-2D14A2-3C4-BC4-2D14A2-C2(B5-BC4-2D14A2-D)B4-3C9-3B10-2DC15-3B256-A30-A19-A10-A19-A-A8-A17-2(3B-A8-A11-A5-)2(3B-A5-5B10-A5-)3B-A8-A11-A5-4B4(A8-A11-A8-B)A4D4-A11-A8-BA7D-2(A11-A8-BA4D4-)A11-9AB10A12-8A2B8A8-3C2-18A2-3C4-BC2-18A2-CB5-BC2-18A2-DB-D3-BC2-18A2-DB4-3C4-5A3B6A4-2DC15-3B256-A30-A19-A10-A19-A-A8-A17-2(3B-A8-A11-A5-)3B-A5-5B8-2BA5-3B-A5-5B10-A5-3B-A8-A11-A5-4B4(A8-A11-A8-B)A4D4-A11-A8-BA7D-2(A11-A8-BA4D4-)A11-9AB10A12-8A2B8A8-3C2-18A2-3C4-2(BC2-18A2-CB5-)BC2-18A2-CB4-3C4-14A4-3C10-14A5-2D191-3B28-3B18-A30-A17-3A10-A13-3B-3A10-A17-2(3B-A8-A11-A5-)2(3B-A5-3BA11-A5-)3B-A8-A11-A5-4B4(A8-A11-A8-B)A4D4-A11-A8-BA7D-2(A11-A8-BA4D4-)A11-9AB10A12-8A2B8A8-3C2-18A2-3C4-2(BC2-18A2-CB5-)BC2-18A2-CB4-3C4-14A5-DC10-14A5-2D69-2(A30-)A28-2BA28-BCB28-3B4(18-A11-A)2(5-3B-A8-A11-A)2(5-3B-A5-3BA11-A)5-3B-A8-A11-A5-4B4(A8-A11-A8-B)A4D4-A11-A8-BA7D-2(A11-A8-BA4D4-)A11-9AB10A12-8A2B8A8-3C2-18A2-3C4-2(BC2-18A2-CB5-)BC2-B3A2E12A2-DB4-3C2-2B2A2-6A2E2A4-DHC10-2A2-6A2-2A4-3D69-2(A30-)3(A28-2B)4(A18-A11-)A5-3B10-2(A11-A5-3B-A5-3B)A11-A5-3B-A3B2-3BA11-A5-3B-A3B5-A10-BA5-4BA3B5-3(A11-A8-BA8-)A11-A8-BA4D4-A11-A8-BA7D-2(A11-A8-BA4D4-)A11-9AB10A12-8A2B8A8-3C2-18A2-3C4-2(BC2-18A2-CB5-)BC2-B3A2E12A2-DB4-3C2-2B2A2-6A2E2A4-D2C10-2A2-6A2-2A4-2D70-5(A30-)3(A16-3A11-)A15-2(B3A10-2A5-3A7-)2B2A10-2A5-3A-A5-2B2A11-A5-3A-AB-7A11-9A-9(10A11-9AB)10A12-8A2B8A8-3C2-18A2-3C4-2(BC2-18A2-CB5-)BC2-18A2-CB4-2C5D14A4-3C10-14A76-A7-A22-A7(7-A21-2A)7-A21-10A-7AB13-E8A-7AB12-10A-10A11-2(9A-9A12-)4(9A-10A11-)9A-10A3D8-9A-10A4D7-2(9A-10A11-)9A-2A2-6A11-2B17A8-3C-2B17A2-3C4-2(BC2-18A2-CB5-)BC2-18A2-CB4-3C4-14A4-D2C10-14A4-2D70-A2(7-A21-2A)7(7-A22-E)9-A20-E9-A19-2A9-A8-A11-A9-A4-3B13-A9-A20-4(A9-A8-A11-)2(A9-A8-A3D8-)2(A9-A8-A11-)9A-10A11-2B17A8-3C-2B17A2-3C4-BC2-17A4DB5-BC2-18A2-CB5-BC2-17A2B-CB4-3C4-14A3B-3C10-14A76-A7-A21-2A2(7-A22-E)7-A22-F7-A22-E4(7-A21-2A)2(9-A19-2A)9-A8-A11-A9-A4-3B13-A9-A20-A9-A8-A11-A8-C4(A8-A11-A9-)2(A8-A2-D8-A9-)A8-A2-D8-9A-10A12-18A8-3C2-18A2-3C4-BC2-17A4DB5-BC2-18A2-CB5-BC2-17A2B-CB4-C6-2A2E6A2E2A3B-3C10-2A2-6A2-2A24-A18-2B10-A18-2BA7-A-A19-2A2(7-A-A20-E)7-A-A20-F7-A-A20-E4(7-A-A19-2A)2(9-A2-4B13-2A)9-A2-4B2-A11-A9-A2-5B13-A9-A2-4B14-2(A9-A2-4B2-A11-)5(A9-A8-A11-)A9-A8-A2-D8-9A-10A2-D9-18A3-D4-3C2-18A2-3C4-2(BC2-18A2-CB5-)BC2-18A2-CB4-C6-2A2E6A2E2A4-3C10-2A2-6A2-2A24-A18-2B10-A18-2BA2(7-A-A19-2A)7(7-A-A20-E)9-A2-4B14-E9-A2-4B13-2A9-A2-4B2-A11-A9-A2-4B11-3DA9-A2-4B11-2(D2-A9-A2-4B2-A8-)2(D2-A9-2(A8-))3DA8-C3(2(A8-)D2-A9-)2(A8-)D2-9A-10A8-D3-18A8-3C2-18A2-3C4-BC2(2-18A2-CB5-2D)2-18A2-CB4-C2D4-14A4-3C10-14A24-A30-2(A20-A7-A-)7(A19-2A7-A-)A19-2A9-A2-4B14-E9-A2-4B13-2A5(9-A2-4B2-A11-A)5(9-A8-A11-A)9-A8-A11-9A-10A12-18A8-3C2-18A2-3C4-2(BC2-18A2-CB5-)BC2-18A2-CB-C2DC6-14A4-4C3D6-14A7-2D15-A30-9(A20-A7-A-)A19-2(2A9-A2-4B13-)2A2(9-A2-4B2-A11-A)9-A2-4B2-A10-B2(A9-A2-4B2-A11-)6(A9-A8-A11-)9A-10A12-18A8-3C2-18A2-3C4-2(BC2-18A2-CB5-)BC2-18A2-CB-C2DC6-14A4-4C3D27-2D15-A8-A21-9(A8-A11-A7-A-)A8-A11-A9-A2-4B2-A11-A8-G2(A2-4B2-A11-A9-)A2-6B3(A11-A9-A2-4B2-)6(A11-A9-A8-)A10-B9A-10A10-B-18A8-3C2-18A2-3C4-2(BC2-18A2-CB5-)BC2-18A2-CB-C2DC24-3CD-2D26-2D16-A8-A21-9(A8-A11-A7-A-)A8-3(A11-A9-A2-4B2-)A11-A9-A2-6B3(A11-A9-A2-4B2-)6(A11-A9-A8-)A10-B9A-10A10-B-18A8-3C2-18A2-3C4-BC2-11AD6A2(2-CB5-BC2-18A)2-CB4-C24-3CD29-2D16-A8-A21-2(A8-A11-A7-A-)2(A9D10-9DA-A8-A11-A7-A-)A9D10-9D2(A-10A11-A7-)A-10A3(11-A9-3A4B3A)11-A9-3A6BA3(11-A9-3A4B3A)6(11-A9-10A)10-B9A-10A10-B27-3C22-3C4-BC13-D8-2(CB5-BC22-)CB4-C24-D2C28-2D18-10A21-9(10A11-9A-)2(10AB10-9A-)5(10A11-A-7A-)7(10A11-9A-)10A33-D4-3C22-3C4-BC11-3D8-C2(B5-BC23-)B4-C24-2DC28-2D119-B30-2B16-B12-B17-B8-3D-B57-3D46-2B11-3D2-2B10-9A10-2B10-9A24-2(7A8B16-)7A10B14-7A8B16-7A2(8B14-9A)6-B15-3(9A22-)9A28-B51-28C4-B12CDC-6C2-CB5-B16C8-B5-B11CD5C7-B4-C3-9CD2-3C6-2DC28-2D319-B30-B-B61-2(14B17-)2(2B10E2B17-)14B17-14B144-B30-B51-19C7B2C3-2C14B-6B3-DC3-2C16B8-DC3-2C17B7-D2(C3-)9C2D-3C7-DC16-2D490-10E21-10E291-19C7-2C4-2(C24-D5-)C24-D4-2D11C2D4C7-DC16-2D848-2C10-6D13-2C13-3D14-C30-C3-2D25-C3-2D876-3D28-3D110-
