model
size = 20 32 24, scale = 0.05, origin = -y
material deform = 1, fade = true, lighting = smooth, roughness = 0.3, metalness = 0.6
  colors = A:#F06 B:#F93 C:#3FF D:#FF0 E:#66F F:#6F6 G:#F0F H:#222
voxels
241-3C16-5E15-5G16-4A349-4A16-5B14-6D15-5F16-5C15-5E16-4G17-2A493-7A13-3B2-2B13-3D3-2D12-4F2-2F12-4C2-2C13-4E2-E14-6G15-5A16-4B17-3D451-8A12-2B4-2B12-2D5-2D11-2F5-2F11-3C5-C11-4E4-E13-3G3-G14-3A2-A15-3B-B16-4D17-3F18-2C411-7A13-B5-2B12-D5-2D12-F6-2F11-C6-2C11-3E4-2E12-3G4-G13-3A3-A14-3B2-B15-3D-D16-4F16-4C15-5E15-5G15-4A17-2B333-7A13-B5-B13-D5-2D12-F5-2F12-2C4-2C12-2E4-3E12-2G3-3G13-2A3-2A14-2B2-2B14-3D-2D15-3F-F14-4C-C14-3E2-E14-2G2-2G14-5A15-4B17-3D18-2F293-7A13-B5-B13-D5-D13-2F4-F13-2C4-C14-2E3-E14-2G3-2G14-2A2-2A15-B2-2B15-2D2-2D14-2F2-2F14-2C2-2C13-2E3-2E13-2G3-2G13-2A2-2A14-3B-2B14-5D16-4F17-2C274-7A13-3B3-B13-2D3-2D13-3F2-2F14-2C2-2C14-3E-2E15-2G-2G15-3A-A16-2B-2B15-2D-2D15-F2-2F15-C2-2C14-2E2-2E14-G3-2G14-A3-2A14-B3-2B14-2D-2D15-5F16-3C18-2E254-7A13-4B-2B12-5D-2D12-5F-F13-4C2-C14-3E2-E14-4G-2G13-7A13-5B-B13-5D-D12-5F2-F12-5C2-C12-5E2-E12-4G2-2G12-4A2-2A13-3B2-2B14-2D2-2D14-5F14-C-4C14-E2-3E14-G19-2A18-2B18-2D19-F156-9A11-3B4-2B11-3D4-D12-2F5-F12-3C4-C12-3E4-E13-2G4-G13-2A4-2A11-3B4-2B11-3D4-2D11-3F5-F11-2C6-C11-2E6-E11-2G5-2G11-3A4-A12-4B3-B12-4D2-2D13-4F-2F13-6C14-6E14-2G-3G14-3A17-3B18-D176-10A10-2B6-2B10-2D6-D11-2F6-F11-2C6-C11-3E5-E11-3G5-G11-3A5-A11-3B5-B11-2D6-2D10-2F6-2F10-2C6-2C9-3E6-2E9-3G6-2G9-3A6-2A9-3B6-B10-4D4-2D11-3F4-2F11-5C2-C13-7E13-6G15-2A-2A15-2B195-10A10-2B7-B10-2D7-D10-2F7-F10-2C7-C10-2E7-E10-2G7-G10-2A7-A11-B7-B11-D7-D11-F7-2F8-3C7-2C8-3E7-2E8-2G8-G9-2A8-A9-2B8-B10-2D7-D10-2F6-2F10-3C5-C12-5E-2E13-6G15-5A17-2B192-11A9-2B8-B9-2D8-D9-2F8-F9-2C8-C9-2E8-E10-G8-G10-2A7-A11-B7-B11-D7-D9-3F7-F8-4C7-C8-2E9-E8-2G9-G8-2A9-A9-2B7-2B9-2D7-2D9-2F7-2F9-3C5-2C11-3E3-3E12-4G-2G14-5A2-A12-5B-2B15-D3-D19-F149-11A9-2B7-2B9-2D8-D9-2F8-F9-2C8-C10-E8-E10-2G6-2G10-2A6-2A11-B6-2B11-D6-2D9-3F7-F8-2C9-C8-E10-E8-G10-G8-2A9-A2(8-2B)9-2D7-D10-HF7-F10-2C6-3C10-2E4-4E11-2G3-4G11-2A2-5A11-9B13-3D2-2D169-10A10-2B7-2B9-2D7-2D9-2F7-2F10-C7-2C10-E7-2E10-2G6-2G11-A6-A12-B6-B12-D6-2D9-3F6-2F2(8-2C)8-E9-2E7-2G9-2G7-2A9-2A8-2B8-B9-2D7-2D10-F7-2F10-2C6-2C10-3E4-3E11-2G3-4G11-3A-5A12-5B-2B15-D174-10A10-2B6-2B10-2D6-2D11-F6-2F11-C6-2C11-2E5-2E11-2G5-2G12-A5-2A12-B5-2B12-D5-2D10-3F5-2F9-2C7-2C2(8-2E)2(8-2G)2(8-2A)2(8-2B)8-3D7-2D9-2F7-F11-C7-C11-2E4-3E12-2G2-4G12-6A15-4B195-8A12-B5-2B12-D5-2D12-2F4-2F12-2C4-2C12-3E3-2E13-3G2-2G13-7A13-7B13-7D11-9F10-2C5-3C9-2E7-2E9-G9-2G8-A9-2A8-2(B9-)3D6-2D10-2F6-2F10-3C4-3C11-2E2-5E11-2G-4G13-6A14-4B16-3D178-7A13-7B13-7D13-7F14-6C14-6E15-5G16-4A52-7F11-4C4-2C9-3E7-2E2(8-2G)2(8-2A)8-2B7-3B9-2D6-3D9-2F6-2F11-4C-4C13-6E13-5G15-A-2A16-B-B16-4D16-3F18-2C141-4A16-4B16-4D17-3F18-2C19-E94-6F10-11C8-3E7-2E2(8-2G)8-2A7-3A8-3B5-4B9-2D3-5D11-3F-3FHF12-8C14-4E15-3G17-3A17-3B16-4D16-3F17-3C17-2E18-2G315-11C8-3E3-6E8-2G7-3G8-2A6-4A9-2B5-3B11-2D3-3D13-6F16-4C95-3D17-3F17-3C16-3E17-3G17-2A18-2B275-7C12-3E3-5E9-2G5-4G9-3A4-4A10-3B3-3B12-8D14-5F175-2E18-2G18-2A17-3B17-2D236-3F16-7C13-2E3-3E12-G5-2G12-2A4-2A13-7B14-6D256-B18-2D18-F217-3F16-6C14-E3-3E13-G4-2G13-3A-3A14-6B16-2D517-2F16-5C15-2E-3E14-2G2-3G13-6A16-3B335-
