model
size = 32 17 32, scale = 0.05, origin = -y
material deform = 1, fade = true, lighting = smooth, roughness = 0.3, metalness = 0.6
  colors = A:#C33 B:#FCF C:#C30 D:#EEE E:#C03 F:#111 G:#C9F
voxels
52-A629-A31-2A481-A29-BA32-A417-B30-2A28-B-A29-C2A480-A29-CA511-B31-3A29-2A542-CA543-B30-2A5-A31-A504-2A5-2A30-2A11-A31-A323-B2A21-2A5-2A-AB19-A-A4-BA-2A21-BA4-A3-A5-B7-G7-A3-B2A9-2A6-2(A11-)3A4-2A11-A17-A25-A-A279-B30-2A20-3A9-A21-A4-A3-A22-A7-C2A19-2A9-2A19-A10-ACA3-3A3-A-A19-A2(3-3A)19-A3-3A4-A21-C2-3A26-A2-C280-A82-B2AB10-2A16-4A10-2A13-A-2A13-2A-A2-3A3-3A18-2(3A-)2A-2A20-7A26-A-4A28-A2-A359-BA-2(A13-)4A13-2A10-A-3A16-3A-4A-5A19-5A-3AEA21-3A3-AC3A22-C2-A-3ACA25-2A5-A31-A29-A291-A17-A11-3A17-7A5-3A18-8A3-A20-4A-2A-4A21-6A-4A24-A-C5A-A20-3DA-E4A22-DFDA28-3DA28-3A231-A30-A-A17-E2A8-A21-12A21-11A21-13A2(20-12A)20-C3A-6AE20-3A4-E3A21-3A5-2A254-A20-A10-A21-7A4-A21-11A21-C12A19-14A19-4A-7A20-4A-7A21-3A2-6A27-E2AE286-AC19-8A2-2A20-13A20-14A19-13A18-13A20-C11A20-4A-7A29-A256-A18-2A11-A18-CA-5A2-4A20-12A21-11A21-10AE-A18-13A20-2AC9A20-2AC3-3ACAE20-2AE5-2A130-2A29-3A28-3A29-A19-2A7-A-2A18-4A6-A2-C19-3A2-7A20-2(3A-)A-3A19-2(A-)2A2-A25-4AE-A2-A22-3D2(A2-)A22-DFDA2-C2-3A20-3DA28-3A105-B31-3A27-B3A28-2A16-3A10-3A18-A8-4A19-2A7-3A18-A-5A-4A21-A-A2-2A2-A-A22-2A-CAE-C26-A267-3A10-B19-A11-A2-B29-A-A30-2A2-2A25-2AC2-2A3-2A21-CAE3-5A22-A4-4A27-A31-A237-B8-B21-3A7-A2-B19-A8-A-2A4-A5-A20-2A2(4-A)25-A4-2A24-2A4-AE26-A3-A30-A268-B30-2A7-B22-2A5-BACA4-B23-5A3-2AB4-2A19-C3-A-A4-2A23-2A4-2A25-A4-AE352-B9-2A19-2B23-3A4-2A14-3A6-3A4-2A24-A4-2A31-C320-B56-B6-A10-A19-3A22-3A4-A25-C5-A14-BA30-A31-A30-BA30-A31-A221-B20-A10-2A19-2A22-2A466-A20-A30-2A22-2A30-2A455-B30-2A21-B31-2A30-A457-A22-B7-2A21-2A30-CA424-B30-2A24-A6-A22-2A31-A455-A511-A491-
