model
size = 32 32 17, scale = 0.05, origin = -y
material deform = 1, fade = true, lighting = smooth, roughness = 0.3, metalness = 0.6
  colors = A:#0C0C0C B:#000 C:#EEE
voxels
193-4(4A22-4A2-)4A22-4A802-4A22-4A2-4A22-4A-3A2(B24-B6A26-6A)B24-B3A-4A22-4A2-4A22-4A706-4A22-4A-3A4(26-6AB24-B6A)26-3A-4A22-4A642-4A22-4A-3A5(26-6AB24-B6A)26-3A-4A22-4A578-4A22-4A-3A3(26-6AB24-B6A)26-6AB24-B3AC2A26-2A2C2AB24-B2AC3A26-6AB24-B6A26-3A-4A22-4A546-4A22-4A-3A2(B24-B6A26-6A)B24-B6A26-3AC2AB24-B2A2C2A26-2AC3AB24-B3AC2A26-2AC3AB24-B6A26-6AB24-B3A-4A22-4A514-4A22-4A-3A2(B24-B6A26-6A)B24-B3AC2A26-2A2C2AB24-B2AC3A26-6AB24-B6A26-3AC2AB24-B2AC3A26-6AB24-B6A26-6AB24-B3A-4A22-4A5-B22-B453-4A22-4A-3A26-6AB24-B6A26-3AC2AB24-B2A2C2A26-2AC3A2(B24-B6A26-6A)B24-B3AC2A26-2AC3AB24-B6A26-6AB24-B6A26-3A-4A22-4A4-2B22-2B7-2(B22-B8-)B22-B9-3(B20-B10-)B20-B11-B18-B12-B18-B13-B16-B15-B14-B17-2B10-2B20-2B6-2B24-6B14-4A22-4A-3AB24-B6A26-3AC2AB24-B2AC3A3(26-6AB24-B6A)26-3AC2AB24-B2AC3A26-6AB24-B6A26-6AB24-B3A-4A22-4A4-2B22-2B7-2(B22-B8-)B22-B9-3(B20-B10-)B20-B11-B18-B12-B18-B13-B16-B15-B14-B17-2B10-2B20-2B6-2B24-6B14-4A22-4A-3A26-6AB24-B6A26-3AC2AB24-B2A2C2A26-2AC3A2(B24-B6A26-6A)B24-B3AC2A26-2AC3AB24-B6A26-6AB24-B6A26-3A-4A22-4A4-2B22-2B7-2(B22-B8-)B22-B9-3(B20-B10-)B20-B11-B18-B12-B18-B13-B16-B15-B14-B17-2B10-2B20-2B6-2B24-6B14-4A22-4A-3A2(B24-B6A26-6A)B24-B3AC2A26-2A2C2AB24-B2AC3A26-6AB24-B6A26-3AC2AB24-B2AC3A26-6AB24-B6A26-6AB24-B3A-4A22-4A5-B22-B485-4A22-4A-3A2(B24-B6A26-6A)B24-B6A26-3AC2AB24-B2A2C2A26-2AC3AB24-B3AC2A26-2AC3AB24-B6A26-6AB24-B3A-4A22-4A546-4A22-4A-3A3(26-6AB24-B6A)26-6AB24-B3AC2A26-2A2C2AB24-B2AC3A26-6AB24-B6A26-3A-4A22-4A578-4A22-4A-3A5(26-6AB24-B6A)26-3A-4A22-4A642-4A22-4A-3A4(26-6AB24-B6A)26-8A22-5A705-4A22-4A2-4A22-4A-3A2(B24-B6A26-6A)B24-B3A-4A22-4A2-4A22-4A802-4(4A22-4A2-)4A22-4A673-
