model
size = 12 19 12, scale = 0.05, origin = -y
material deform = 1, fade = true, lighting = smooth, roughness = 0.3, metalness = 0.6
  colors = A:#1C1D20
voxels
15-13(6A6-)6A54-13(6A6-)6A64-13(2A6-2A2-)2A6-2A4-3(6A6-)6A16-13(A8-A2-)A8-A3-3(A6-A4-)A6-A5-6A3-A13(10-2A)10-A-3(A8-A2-)A8-A3-2A4-2A4(2-A13(10-2A)10-A-3(A8-A2-)A8-A3-A6-A)2-A13(10-2A)10-A-3(A8-A2-)A8-A3-2A4-2A3-13(A8-A2-)A8-A3-3(A6-A4-)A6-A5-6A4-13(2A6-2A2-)2A6-2A4-3(6A6-)6A15-
