model
size = 14 31 14, scale = 0.05, origin = -y
material deform = 1, fade = true, lighting = smooth, roughness = 0.3, metalness = 0.6
  colors = A:#1C1D20
voxels
76-2A10-20(6A8-)6A10-2A110-2A10-20(6A8-)6A10-2A108-6A7-8A6-2A4-2(2A5-)3A17(4-2A6-2A)4-2A5-3A5-2A4-2A6-8A7-6A78-6A7-2A4-2A5-3(3A4-)3A3-A8-3A16(2-A10-A)2-A9-2A2-A8-2A4(4-3A)5-2A4-2A7-6A63-8A5-3(3A4-)3A3-3A6-3A2-A9-2A17(2-A10-A)2-A9-2A2-3A6-3A3-3(3A4-)3A5-8A49-6A7-2A4-2A5-3A4-3A3-3A6-3A2-2A8-2A-A11-3A17(12-2A)11-A2-2A8-2A2-3A6-3A3-3A4-3A5-2A4-2A7-6A24-2A10-6A6-2(3A4-)2A6-2A3-2A8-2A2-A10-A-A18(12-2A)12-A-A10-A2-2A8-2A3-2A6-2A2(4-3A)6-6A10-2A11-4A8-8A5-2A6-2A3-2A8-2A2-A10-A-A20(12-2A)12-A-A10-A2-2A8-2A3-2A6-2A5-8A8-4A10-4A8-8A5-2A6-2A3-2A8-2A2-A10-A-A20(12-2A)12-A-A10-A2-2A8-2A3-2A6-2A5-8A8-4A11-2A10-6A6-2(3A4-)2A6-2A3-2A8-2A2-A10-A-A18(12-2A)12-A-A10-A2-2A8-2A3-2A6-2A2(4-3A)6-6A10-2A24-6A7-2A4-2A5-3A4-3A3-3A6-3A2-2A8-2A-A11-3A17(12-2A)11-A2-2A8-2A2-3A6-3A3-3A4-3A5-2A4-2A7-6A49-8A5-3(3A4-)3A3-3A6-3A2-A9-2A17(2-A10-A)2-A9-2A2-3A6-3A3-3(3A4-)3A5-8A63-6A7-2A4-2A5-3(3A4-)3A3-A8-3A16(2-A10-A)2-A9-2A2-A8-2A4(4-3A)5-2A4-2A7-6A78-6A7-8A6-2A4-2(2A5-)3A17(4-2A6-2A)4-2A5-3A5-2A4-2A6-8A7-6A46-
