model
size = 12 20 32, scale = 0.05, origin = -y
material deform = 1, fade = true, lighting = smooth, roughness = 0.3, metalness = 0.6
  colors = A:#FF9 B:#FFF C:#0B0000 D:#F00 E:#FF3 F:#FFC G:#FCF H:#FE0000 I:#FF0 J:#100 K:#F30 L:#FCC M:#FF6
voxels
14-2(6B6-)6D6-6D7-5D174-2(6B6-)6D6-LD2LDL6-LDL2DL6-3(DL)D5-4LDLD5-6D6-6D7-B2DB2(8-4D)9-3D9-3C78-8B2(4-2B)4-D6BD4-DG4-GD4-DL4-LD4-D2(G4-LD4-K)2A2-2AD4-BA4GAB5-BA3G2B2(5-DG3A2D)5-2DG2A2D5-2C3A2C5-7C7-2C55-9B3-B6-2B3-DB-3A2BD3-D2-3A-GD3-D-5ALD3-D-4A-LD3-K2-3A-LD3-K6-AD3-B6-AB3-BA4-2GB2(3-HA4-GAD)3-D2G3-2GD3-C4A-2AC3-C7AC4-7C51-10B2-2B-5A-B2-DB-5ABD3-D6A-D3-D3A-2A-D3-D2(6A-D3-K)-5A-B3-B-4A2-B3-D2-3A-GB3-H-4A2-AD2-H-4A2(2-D)A-4A-GD2-C3A2CA2-AC-C2A4C2AC3-2C4-3C50-10B2-B-7AB2-DB7A2(D2-D-A5-A)D2-K-A4-2AD2-K2A4-2AB2-B-2A2-3AB2-B-6A-AB-D7A-G2(D-H7A2-)D-HG2A2-2A-AD-HGA3-CA-GC-CAC4-C2AC2-2C5-2C50-10B2-B-7AB2-DB7A2(D2-D-A5-A)2(D2-K-A5-A)B2-B-A5-AB2-B-A4-2A-B-H-A4-2AG3(D-H-A4-A2-)D-HGA4-2A-D-C-A5-2AC-3C5-3C49-10B2-2B7AB2-KB7AD2-2(KGA6-AD-)K2A6-AD2-BA6-B2-B2A5-2A2(B-)A5-A-B4(-H-A5-A-D)-HGA5-A-D-C2A5-2AC-3C5-3C50-10B2-B7A2B2-K7AD3-K2(A6-AD2-B)3(A6-AB2-B)A6-AB-H2A6-AD-H-A5-2A2(D-H-A5-A-)D-HGA5-A-D-CGC5-AGD2-2C5-2AC2-2C5-2C10-C28-10B2-B8AB2-K8AD2-KA6-AD5(2-BA6-AB)3(-H2A6-AD)2-HA6-AD2-HA5-A-D2-HC5-2AD2-CAC3-C2AC2-CAC3-CAC4-3C3-C6-C4-C16-10B2-B8AB2-K8AD2(2-BA6-AB)2-BA6-2AC-3(BA6-AB2-)2(HA6-AD2-)HA5-A-D2-HA5-2AD2-H2A4-AGD2-HA2C3-2AD2-C2A3C2AC4-CA3C2AC4-C2A2F2C6-6C7-C2-C5-10B2(2-B8AB)2-2(BA6-AB2-BA6-2AC-)2(BA6-AB2-)BA6-AD2-CA5-AD3-H-A4-AGD2-H7AFD2-HI6AC3-CF2A2C2AC3-CF6AC4-CA-4AC5-C-3AC6-C4AC7-4C5-10B2-B-7AB2-B8A2(B2-BA7-MC-BA7-)2(MC-BA7-)B2-BA5-AD3-CIA4-AD3-CF6AD4-C6AC3-C7AC3-C3A3-AC3-CF2A2-2AC4-2C4AC6-C2AFAC7-5C8-3C5-10B2-2B2A5-B2-B8A2(B2-B8-AC-B8-)MC-B8-MC-BA7-B2-CFA4-AC3-CF6AC4-C5A2(IC4-CI4A)IC4-2CI2AI2C4-2C4I2C6-2(KA)8-2(FK)29-10B2-2B7-B2-BA7-2(B2-B8-)AC-B8-B2-B8-AC-BA7-B3-J6-AC3-CA4-AC4-C6AC4-C2I3AIC5-CB3IB6-B4CB7-4C8-4C53-11B-B8-2B-3(B8-B2-)B8-AC-B8-B2-2B7-B3-CB5-AC3-C2A3-AC4-CF5AC5-CB2AI2C7-3B89-11B-BA7-AB2(-B9-D)-2(B8-B2-)BA7-B2-JAB5-AB3-CA4-2AC3-C6AC5-CI3AIC6-5C100-11B-B9-B3(-B9-D)-B8-B2-2B7-B2-JAB5-AC3-C2A3-2AC3-C6AC5-BCIAIBC7-3C101-11B-B9-B3(-B9-D)-B8-AD-JB5-BAJ3-JA2-B-2AC3-C6AFC4-B4AIC5-C4BC112-11B-B9-B-B2(9-D-D)9-D-J8-AD-JAB5-AJ3-C2A3-2AC3-CI5AC5-B6C122-13BFA8-BDFA8-D-D8-BD-C9-D-C8-AD-C-A4-2AJ3-C6AFC3-2CI3AIC6-B3CB123-13BAB8-BD10-D-D9-D-D8-FD-C7-AC2-CF2A2-3AC3-CI5AIC4-2C3I2C7-3B124-13BA9-BD10-D-D9-D-D8-FD-CE6-AC2-CF6AEC3-2CI3AIC6-B3CB135-13B10-BD10-2DF8-FD-D8-D3-C2E2-3EC3-CF5E2C4-BC2IB2C7-3B136-13B10-BD10-2DF8-FD-D6-2ED2-C7EC4-2J3E2C7-B3CB147-13B10-BD10-2DF8-D2-DE5-EFD2-2C6EC5-6J8-3B148-13B9-2BD9-D-DF8-D2-DFE3-2EFD3-C3E-E2C5-5J160-11B-B9-B-D9-D-DF7-FD2-D2E3-2ED4-2C3E2C7-3J161-11B-B8-2B-D8-BD-DF7-D3-D7ED4-2C2E3C7-2J162-10B2-2B7-B2-DB2(7-D3-D)F5E2D4-D5C173-9B3-B6-2B3-D6-FD3-D6-D4-DF5ED5-2D3CD173-2(8B4-)DB4-FD4-DFB3-FD5-DFE2F2D6-4D173-
