model
size = 26 6 16, scale = 0.05, origin = -y
material deform = 1, fade = true, lighting = smooth, roughness = 0.3, metalness = 0.6
  colors = A:#010101 B:#0C0C0C
voxels
2-9A6-9A-8A8-8A-A8-A6-A8-2A9-A4-A2(9-2A)2-2(2A9-)A-2A-A9-A26-A24-2A2(24-A156-A)4(24-A130-A)5(24-A104-A24-2A)24-A78-A2(24-2A)24-A78-A9-B4-B9-2A10-B2-B10-2A24-A78-A24-2A9-B4-B9-2A24-A26-
