model
size = 32 32 25, scale = 0.05, origin = -y
material deform = 1, fade = true, lighting = smooth, roughness = 0.3, metalness = 0.6
  colors = A:#EEE B:#111
voxels
8-21(16A16-)16A10-2A4-16A4-2A4-5A-16A-5A5-26A7-24A9-22A11-20A13-18A17-12A23-6A51-19(20A12-)20A8-2A2-20A2-2A3-4A-20A-4A3(2-30A)3-28A5-26A7-24A8-24A9-22A16-10A48-18(5A12-5A10-)5A12-5A6-3A-5A12-5A-3A-10A5(12-20A)12-10A-2A-6A12-9A3-8A12-8A5-7A12-7A7-7A10-7A13-14A20-10A15-23(4A16-4A8-)4A16-4A4-8A16-16A16-11A-4A16-4A-3A-7A16-7A3-6A16-6A5-6A14-6A11-3A10-3A18-A10BA13-24(4A18-4A6-)4A18-4A3-7A18-9A-4A18-4A-9A18-7A-6A18-6A3-6A16-6A9-3A12-3A16-AB10-BA11-25(5A18-5A4-)5A18-5A2-7A2(18-14A)18-7A2-6A16-6A7-4A14-4A13-AB12-BA10-26(4A20-4A4-)5A18-5A2-7A18-14A18-7A-7A16-7A5-5A14-5A12-AB12-BA10-27(4A20-4A4-)4A20-4A2-7A18-15A16-8A3-6A14-6A11-AB12-BA10-28(4A20-4A4-)5A18-5A2-8A16-8A2-7A14-7A10-AB12-BA10-5(28(4A20-4A4-)5A18-5A2-8A16-8A-7A16-7A8-AB14-BA9-)28(4A20-4A4-)5A18-5A2-8A16-8A2-6A16-6A9-AB14-BA9-27(4A20-4A4-)4A20-4A2-7A18-15A16-8A3-6A14-6A11-AB12-BA10-27(4A20-4A4-)4A20-4A2-7A18-7A-7A16-7A5-5A14-5A12-AB12-BA10-26(4A20-4A4-)4A20-4A2-6A20-13A18-7A2-6A16-6A6-5A14-4A13-AB12-BA10-25(4A20-4A4-)4A20-4A2-7A18-9A-4A18-10A-3A18-3A-3A3-6A14-6A2(12-A)18-AB10-BA11-24(5A18-5A4-)5A18-5A2-7A18-14A18-10A-3A18-3A-3A2-7A14-7A8-3A14-3A15-2AB8-B2A44-23(4A18-4A6-)4A18-4A3-7A18-14A18-4A-9A18-7A-6A18-6A7-3A14-3A13-5AB6-B5A75-17(24A8-)24A5-30A-163A-24A-6A-24A-3A2-13A2B13A8-8AB2-B8A14-5AB4-B5A109-17(22A10-)22A9-24A6-27A4-3(30A2-)30A3-28A5-26A10-18A16-6A2-6A19-2A8-2A114-17(16A16-)16A15-18A13-20A10-24A6-28A4-28A5-26A8-22A12-18A17-5A2-5A21-2A6-2A282-3(2B30-2B158-)2B30-2B271-
