model
size = 31, scale = 0.05, origin = -y
material deform = 1, fade = true, lighting = smooth, roughness = 0.3, metalness = 0.6
  colors = A:#B00 B:#EEE C:#111 D:#FF3
voxels
385-5A25-4(7A24-)7A25-5A677-5A24-9A21-11A20-11A19-4(13A18-)13A19-11A20-11A21-9A24-5A522-5A24-9A21-11A19-13A17-15A16-15A15-4(17A14-)17A15-15A16-15A17-13A19-11A21-9A24-5A428-7A22-11A19-13A17-15A15-17A14-17A13-6(19A12-)19A13-17A14-17A15-15A17-13A19-11A22-7A364-9A20-13A17-15A15-17A13-19A12-19A11-8(21A10-)21A11-19A12-19A13-17A15-15A17-13A20-9A301-9A20-13A17-15A15-17A13-19A11-21A10-21A9-8(23A8-)23A9-21A10-21A11-19A13-17A15-15A17-13A20-9A240-7A21-13A17-15A15-17A13-19A11-21A9-2(23A8-)23A7-6(25A6-)25A7-2(23A8-)23A9-21A11-19A13-17A15-15A17-13A21-7A180-5A23-11A18-15A15-17A13-19A11-21A9-23A8-23A7-2(25A6-)25A5-4(27A4-)27A5-2(25A6-)25A7-23A8-23A9-21A11-19A13-17A15-15A18-11A23-5A148-9A20-13A16-17A13-19A11-21A9-23A8-23A7-25A6-25A5-8(27A4-)27A5-25A6-25A7-23A8-23A9-21A11-19A13-17A16-13A20-9A117-5A23-11A18-15A14-19A11-21A9-23A8-23A7-25A6-25A5-2(27A4-)27A3-4(29A2-)29A3-2(27A4-)27A5-25A6-25A7-23A8-23A9-21A11-19A14-15A18-11A23-5A86-9A20-13A16-17A13-19A11-21A9-23A7-25A6-25A5-27A4-27A3-8(29A2-)29A3-27A4-27A5-25A6-25A7-23A9-21A11-19A13-17A16-13A20-9A83-11A18-15A15-17A12-21A9-23A8-23A7-25A5-27A4-27A3-10(29A2-)29A3-27A4-27A5-25A7-23A8-23A9-21A12-17A15-15A18-11A54-5A23-11A18-15A14-19A11-21A9-23A7-25A6-25A5-27A4-27A3-2(29A2-)29A-155A-2(29A2-)29A3-27A4-27A5-25A6-25A7-23A9-21A11-19A14-15A18-11A23-5A25-4(7A21-13A16-17A13-19A11-21A9-23A7-25A5-27A4-27A3-2(29A2-)29A-217A-2(29A2-)29A3-27A4-27A5-25A7-23A9-21A11-19A13-17A16-13A21-7A24-)7A21-13A16-17A13-19A11-21A9-23A7-25A5-27A4-27A3-2(10A9-10A2-)10A9-10A-11A9-197A-2(29A2-)29A3-27A4-27A5-25A7-23A9-21A11-19A13-17A16-13A21-7A25-5A23-11A18-15A14-19A11-21A9-23A7-25A6-25A5-27A4-9A9-9A3-2(10A9-10A2-)10A9-10A-155A-2(29A2-)29A3-27A4-27A5-25A6-25A7-23A9-21A11-19A14-15A18-11A23-5A54-11A18-15A15-17A12-21A9-23A8-23A7-25A5-27A4-9A9-9A3-3(10A9-10A2-)7(29A2-)29A3-27A4-27A5-25A7-23A8-23A9-21A12-17A15-15A18-11A83-9A20-13A16-17A13-19A11-21A9-23A7-25A6-25A5-9A9-9A4-9A9-9A3-2(10A9-10A2-)6(29A2-)29A3-27A4-27A5-25A6-25A7-23A9-21A11-19A13-17A16-13A20-9A86-5A23-11A18-15A14-19A11-21A9-23A8-23A7-25A6-8A9-8A5-2(9A9-9A4-)9A9-9A3-4(29A2-)29A3-2(27A4-)27A5-25A6-25A7-23A8-23A9-21A11-19A14-15A18-11A23-5A117-9A20-13A16-17A13-19A11-21A9-23A8-23A7-8A9-8A6-8A9-8A5-2(9A9-9A4-)6(27A4-)27A5-25A6-25A7-23A8-23A9-21A11-19A13-17A16-13A20-9A148-5A23-11A18-15A15-17A13-19A11-21A9-23A8-7A9-7A7-2(8A9-8A6-)8A9-8A5-4(27A4-)27A5-2(25A6-)25A7-23A8-23A9-21A11-19A13-17A15-15A18-11A23-5A180-7A21-13A17-15A15-17A13-19A11-21A2(9-7A)2(8-7A9-7A)7-8A9-8A6(6-25A)7-2(23A8-)23A9-21A11-19A13-17A15-15A17-13A21-7A240-9A20-13A17-15A15-17A13-19A11-6A9-6A10-2(6A9-)7A9-7A8-7A3-C-C3-7A7(8-23A)9-21A10-21A11-19A13-17A15-15A17-13A20-9A301-9A20-13A17-5A5B5A15-4A9B4A13-3A13B3A12-2A3B9-2B3A11-3A3BC7-C3B3A10-3A4B3(C-)C4B3A10-2A17B2A10-2A3BA9BA3B2A10-2A2BACA7BACA2B2A10-2ABACDCA5BACDCAB2A10-2A2BACA7BACA2B2A10-3A2BA9BA2B3A10-3A15B3A11-3A13B3A12-3A13B3A13-4A9B4A15-5A5B5A17-13A20-9A364-7A22-3A5-3A19-2A9-2A17-A3-7B3-A15-2A3-3(C-)C3-2A14-A15-A13-2A15-2A12-A17-A12-2(A8-)A12-A3-C4-A4-C3-A12-A2-CDC3-A3-CDC2-A12-A2(3-C)A2(C3-)A12-2A5-C3-C5-2A13-A-C2-C5-C2-C-A14-2A-2C7-2C-2A15-A13-A17-2A9-2A19-3A5-3A22-7A647-A30-A25-D4-A4-D893-A30-A929-A511-
