model
size = 30 22 30, scale = 0.05, origin = -y
material deform = 1, fade = true, lighting = smooth, roughness = 0.3, metalness = 0.6
  colors = A:#EEE B:#B6CEDE C:#9AC9DF D:#58B2DC E:#111 F:#3A8FB7 G:#1E72C1 H:#888 I:#274695 J:#444 K:#0B346E L:#255359 M:#FBE251
voxels
493-4B27-2B597-4B27-2B625-2B4ABE23-2B2A2B25-4B592-2BA6-A2B19-2B6AEB21-2B4ABE24-4B559-3BA10-A3B13-3B2A6-2A3B16-2B7AL2B20-7BE556-B2A14-2BE10-3B2A10-2A2BE11-4B3A4-3A4B15-4B4ABE2B22-4B527-B20-C8-B3A14-2A2C9-CB4A8-4ABE12-4B8A4B18-7BE524-BA20-AC7-BA18-AC8-2B2A14-2AEC10-2C4A6-4A2C14-10CE3C521-BA20-AC6-B2A18-2AC7-B2A16-ALC9-BC3A10-3ACE12-D5C4ACE4C20-4C496-B22-C6-BA20-AC7-BA18-AD9-B2A14-2AE11-2C3D7AE5D17-7DE493-BA22-BC5-BA20-AC6-B2A18-2AD7-2B2A14-2AED10-2CD4A-2A-AE2A3D15-F8DE2D491-B24-C4-BA22-AC5-B2A18-2AD7-2BA16-AED10-2CD3A2-2A2-E2A3F15-D8FE2F83-2(2J28-)2J345-BA24-AC3-BA22-AC4-B2A20-ADC5-2B2(2A7-)2AD9-B2C5A-2A-AE3A2FE13-2DFG6FE3F52-2J3(28-2H)345-B26-C2-BA24-AC3-B2A20-2AC5-2BA6-6A6-A2D8-B2C2A-7AE-2A2GE13-2D2F6GE3G52-2H28-2H404-BA26-AC-BA24-AC2-B2A22-2AC3-2B2A6-6A6-2ADC6-2BC2A3-6A3-2AIED11-C2D2FGI4GE4G51-2(2H28-)12(2J28-)2J14-BA12-2J12-ACB2A11-2J11-2AC-B2A10-2J10-2AC3-2BA6-7AE5-2ADC6-2BC11AL4AGED11-C2D2F2G2A2IE4I21-2I58-13(2H28-)2H14-BA12-2H12-ACB2A11-2H11-2AC-B2A10-2H10-2AC3-2BA6-7AE5-2ADC6-2BC11AE4AGED11-C2D2F2G2A2IE2IKI21-IK464-BA26-AC-BA24-AC2-B2A22-2AC3-2B2A6-6A6-2ADC6-2BC2A3-6A3-2AGED11-C2D2F2G2I2KE2K2I488-B26-C2-BA24-AC3-B2A20-2AC5-2BA6-6A6-A2D8-B2C2A-7AE-2AIGE13-2D2F2G2I2KE2KI489-EA24-AE3-EA22-ALE3-ELA20-ALBE4-2E2(2A7-)2A3E7-5E2AE-2E-7EM13-10EM3E490-B24-C4-BA22-BC5-B2A18-2AD7-2BA16-AED10-2CD3A2-2A2-3A2IG15-D2F2G2I2KE2K491-BA22-BC5-BA20-AD6-B2A18-2AD7-2B2A14-2AED10-2CD4A-2A-4A2IG15-D2F2G2I2KE2K492-B22-C6-BA20-AD7-BA18-AD9-B2A14-2AE11-2C2DF7AE2IKIG17-F2GIK2IE494-BA20-AC6-BA19-2AD7-B2A16-ALD9-BC3A10-3AGE12-C2D2FG4AIE4I20-G3I496-BA20-AC7-BA18-AD8-2B2A14-2ALD10-2C4A6-4AGIE13-2D2FGI4GE3G522-B20-C8-B2A16-2AD9-BC4A8-4AGLD11-C2DF3A2-3A4G-E16-F6GE526-B2A14-2AC10-BC3A10-3AFLD10-2CD4A4-4A3FE14-DFGF4AFE2F22-4F529-3CA10-A3C13-C2D2A6-2AD2F-E14-DF7AL2F20-7FE560-2CA6-3C19-2D6ALD21-2D4A2D24-4D-E562-2C4ACE23-2D2A2DE24-4D-E131-
