model
size = 23 32 14, scale = 0.05, origin = -y
material deform = 1, fade = true, lighting = smooth, roughness = 0.3, metalness = 0.6
  colors = A:#EEE B:#DDD C:#C00 D:#BBB E:#AAA F:#111 G:#CCC H:#666 I:#888 J:#222 K:#333 L:#999 M:#636 N:#555 O:#444 P:#400 Q:#777 R:#FC0 S:#C69 T:#633 U:#F93 V:#C99 W:#C9C X:#CCF Y:#1B1B38 Z:#FF3 Aa:#25254B Ab:#C03 Ac:#603 Ad:#936 Ae:#639 Af:#969 Ag:#001 Ah:#500
voxels
309-JQJ20-IGI20-EBE387-5A16-2A5-2A13-A9-A12-A9-2(A11-)A9-A13-A8-A13-A7-A15-A6-A15-A5-3(A17-A4-)A17-A3-2(A19-A2-)A19-A-A21-2A21-A-6(A19-A2-)A19-A3-A17-A4-A17-A5-A15-A6-A15-A7-A13-A2(9-2A)12-9A38-7A15-B7-B13-A9-2(A11-)A9-B13-B7-B15-B6-B15-B5-2(A17-A4-)A17-A3-A19-A2-B19-B2(2-A19-A)2(2-B19-B)7(2-A19-A)3-2(A17-A4-)A17-A5-A15-A7-A13-A9-2(A11-)2A7-2A14-7A40-B3AB17-B5-B15-B7-B12-2(2B9-)B13-B7-B15-B5-2(B17-B4-)D17-D4-X17-X3-5(B19-B2-)H19-H2(2-B19-B)2-E19-E3(2-B19-B)3-B17-B2(4-A17-A)5-A15-A6-A15-A7-A13-A2(9-2A)12-8AC62-2(NL)N17-B5-B14-BA7-A2(B11-)B9-B13-B7-B15-B5-2(H17-H4-)D17-D4-X17-X3-B19-B2-E19-E2-W3(19-H2-H)19-H2-N19-N2-H19-H2-E19-E3-W17-W4-D17-D2(4-B17-B)4-A17-A5-G15-G6-A15-A7-A13-A9-2(A11-)3A5-ACA15-5A65-LNL18-BG3-GB14-BA7-A2(B11-)B9-B13-B7-E15-E6-O15-O5-H17-H4-D17-D4-X17-X4-B17-B3-E19-E2-W19-H2-H19-H2-Q19-Q2-H19-H2-N19-N2-H19-H3-Af17-Af4-W17-W4-D17-D4-G17-G5-L15-L2(6-C15-C)7-C13-C9-B11-C11-BD7-CB14-5A2C87-LNL18-BGI-IGB14-2A7-2A2(11-B)9-B13-B8-E13-E7-O15-O6-N15-N5-D17-D4-X17-X4-B17-B4-S17-S4-T17-T4-J17-J4-F17-F2(4-J17-J)4-O17-O2(4-C17-C)4-DG15-GC5-D15-D6-C15-C7-C13-R8-CB11-UC9-CE9-UC11-ABQ5-CAbC14-2BABA2C131-BG3IGB14-2A7-2A2(11-B)10-B11-B9-E13-E8-O13-O7-N15-N6-L15-L6-A15-A5-B17-B4-S17-S4-T17-T4-J17-J4-F17-F4-J17-J4-JF15-FJ4-OF15-FO5-J15-J6-C15-C6-G15-C6-CH13-HC7-C13-R9-G11-U11-E9-U13-EG5-2C16-4DC155-BG3IGB15-A7-A13-B9-B2(11-Aa)10-Y11-Y9-O13-O8-D13-D7-L15-L2(6-A15-A)6-S15-S6-P15-P6-F15-F76-F13-F7-JF13-FJ6-C15-U6-CE13-EC7-CD11-DC9-LC9-AbR11-AD7-CAb13-G2CDBDLGC16-QEDEQ178-BG3IGB15-A7-A14-D7-D13-E9-E12-K9-2(K11-)K10-Q11-Q9-I13-I8-A13-A7-2A13-2A6-2S13-2S6-2P13-2P7-2F11-2F101-F11-F9-Ac13-Ac8-2UW9-WZR9-2CL7-LIR12-UCDEHED2C15-2C3EAE223-BG3IGB16-A5-A15-Aa7-Aa14-Y7-Y14-K7-K13-D9-D12-H9-H11-LB9-BL2(10-2A9-2A)10-VD9-DV10-AhAc9-AcAh11-2FAg5-Ag2F61-JM-MJ17-FPV-VPF14-2FP5-P2F11-P2T7-2TP11-2ZBNJKJNB2Z12-URCEDHD2CAbR268-G3IG17-A5-A16-B5-B16-D5-D16-K5-K15-OD5-DO14-A7-A14-B7-B2(14-2A5-2A)14-G7-G14-TAd5-AdT16-M3-M18-MI-IM19-M-M20-3M20-VKV19-2CIBR17-ZCGEGCR16-RNJKJCAb18-DHD295-2AB2A18-AaBEBAa18-2(YD)Y18-5K18-OQEQO17-2ALBL2A16-GBEKEBG17-QKFKQ18-I3FI17-B5-B16-Ad5-Ad17-M3-M19-I-I20-MAeM572-EKE20-KFK20-3F19-GJ-JG18-V3-V18-ME-EM19-AeAAe378-
