model
size = 22 30 20, scale = 0.05, origin = -y
material deform = 1, fade = true, lighting = smooth, roughness = 0.3, metalness = 0.6
  colors = A:#13132A B:#03C C:#2A55FF D:#03F
voxels
29-2(B6-B14-)B6-C14-B5(6-B14-C)2(6-C14-B)2(6-B14-B)2(6-C14-C)3(6-C14-B)2(6-B14-B)6-C14-C6-B14-C6-C167-24(10A12-)10A13-8A99-23(14A8-)14A9-12A11-10A13-8A76-24(2A12-2A6-)2A12-2A7-2A10-2A9-12A11-10A35-D4C3D9-24(A16-A4-)A16-A5-A14-A7-2A10-2A9-12A12-8A13-D8-C7-18(A18-A2-)5(B18-B2-)B18-B3-A16-A4-A16-A5-A14-A7-2(2A10-)2A6-2A11-D10-C6-17(A18-A2-)B18-B134-B18-B3-A16-A5-A14-A7-A12-A9-2A8-2A2(9-C12-D4-A15(20-2A)20-AB20-B178-B16-B5-A14-A7-A12-A9-A10-A)3(9-D12-C4-A15(20-2A)20-AB20-B178-B16-B5-A14-A7-A12-A9-A10-A)9-C12-D4-A15(20-2A)20-AB20-B178-B16-B5-A14-A7-2(2A10-)A8-A11-C10-D5-A15(20-2A)20-AB20-B178-BA14-AB5-2A12-2A8-A-A6-A-A11-A8-A11-C10-D6-17(A18-A2-)B18-D2-B131-B2A14-2AB4-A14-A7-4A6-4A10-A8-A11-D10-C28-18(A18-A2-)5(B18-B2-)B18-B3-2A14-2A6-3AC6-D3A11-C6-D13-C8-C11-C10-C29-23(A16-A4-)2A14-2A5-5A6-5A10-D6-D56-D10-D30-22(2A12-2A6-)3A10-3A7-5A4-5A12-D4-D123-20(3A6-3A10-)4A4-4A10-4A4-4A11-3A4-3A14-D4-C148-22(A4-A16-)C4-C162-
