model
size = 30 29 24, scale = 0.05, origin = -y
material deform = 1, fade = true, lighting = smooth, roughness = 0.3, metalness = 0.6
  colors = A:#CC9F26 B:#2D2723 C:#8A0E2D D:#FFF E:#8A8A8A F:#000
voxels
459-B10-B622-3(4A26-)4A716-4A25-6A23-3(8A22-)8A23-6A25-4A626-4A25-6A23-8A21-3(10A20-)10A21-8A23-6A25-4A595-6A23-8A21-5(10A20-)10A21-8A23-6A565-3(4A24-8A21-10A20-10A19-3(12A18-)12A19-10A20-10A21-8A24-4A536-)4A24-8A21-10A20-10A19-3(12A18-)12A19-10A20-10A21-8A24-4A565-6A23-8A21-5(10A20-)10A21-8A23-6A595-4A25-6A23-8A21-3(10A20-)10A21-8A23-6A25-4A472-B10-B18-B10-B82-4B26-4A25-6A23-3(8A22-)8A23-6A25-4A27-2B533-2(B10-B18-)B3-4B3-B21-B4-B24-B4-B23-2(2B4A2B22-)2B4A2B23-B4AB24-2B2-2B25-B2-B26-B2-B27-2B567-4B22-B2-B4-B2-B18-B-B6-B-B18-B-2B4-2B-B19-3B4-3B21-2B4-2B22-2B4-2B23-2B2-2B23-3B2-3B23-2B2-2B25-4B596-4B25-6B23-3(2B4-2B22-)2B4-2B23-6B23-8B22-2B4-2B24-4B25-6C23-8C22-8C24-4C117-3(2B28-)2B268-2B26-6B23-3(8B22-)8B23-6B23-B-4B-B22-8B23-6B23-3(C6BC22-)8C55-2B27-4B25-6B25-2(4B26-)4B27-2B232-B12-B16-B4-4B4-B16-B3-6B3-B19-8B22-8B23-6B24-6B23-8B22-8B23-6B23-3(C6BC22-)3C2B3C25-2C27-4B25-2(6B24-)6B25-2(4B26-)4B27-2B266-6B20-B3-6B3-B16-B3-6B3-B17-B2-6B2-B18-B3-4B3-B19-10B21-8B23-6B23-3(C6BC22-)2C4B2C24-C2BC25-6B23-8B11-B10-8B10-2B11-6B11-2B12-4B12-B-B9-8B9-B2-B7-2B-6B-2B7-B3-B4-2B4-4B4-2B4-B5-4B7-2B7-4B256-2(4B26-)4B54-8B22-8B24-4B24-2C4B2C20-B-C6BC-B19-10B21-2C4B2C24-C2BC24-2(8B22-)8B23-6B25-2(4B26-)4B25-6B25-4B386-4B26-4B52-B2-6C2-B20-2C4B2C22-2C4B2C23-C4BC25-4C24-2(8B22-)8B21-2D6B2D20-3D4B3D2(20-4D2B4D)22-6B26-2B473-B10-B22-2(4C26-)4C55-6B23-8B22-8B21-2D6B2D3(20-4D2B4D)23-4B472-B10-B173-2B27-4B26-4B23-4D2B3(4D20-4D2-)4D499-B10-B203-2E28-2E55-2F4-2F22-2F4-2F530-B10-B203-2E28-2E194-
