model
size = 15 15 30, scale = 0.05, origin = -y
material 
  colors = A:#FFF B:#9BADB7 C:#FFFEFE D:#D0980C E:#5B6EE1 F:#A7A7A7 G:#0030D4 H:#0038D4 I:#696A6A J:#EFEFEF K:#BFBFBF L:#F7F7F7 M:#DFDFDF N:#0018CC O:#979797 P:#C7C7C7 Q:#7F7F7F R:#E7E7E7
voxels
17-11B4-2A7B2A4-3A5B3A6(4-4ADAD4A)4-F3ADAD3AF5-9F51-9B2(6-2(I3C)I)6-IC2AI3AI170-4BICBI3B4-AC7-CA4-AC2-CI3-CA5-A2(I2C)IC169-4B4CIBC2B2-2ACI7-2A2-A2C8-2A3-CA3CI-I2CA6-3(CI)C155-5B2C6B2-OA3-2C2-B-2A2-C-A8-2A2-5C-C4-2A4-4CI3CA154-4B4C5B2-A5-C-CB-2A2-2CA8-2A2-3C-E7-A3-C8E2A5-9E139-4B2C3B2C2B2-A7-CBC2A2-O7-3CAR2-2C10-A2-2C2E7-2A3-11E138-4BCB2CBC3B2-A-CA3-2C4A2-C6-AC3-A2-C7-2(A3-)2C8-A5-9E139-4BC2BCB2C2B2-ACA5-2CA-A2-C10-2A2-C11-A2-2C9-2A3-CN3G5-A5-N8G124-3BC4B3C2B2-2L7-C2-A2-C11-J2-C7-A3-A2(2-2C9-2A)3-11G123-2B-C4B3C2B2-AL6-2C2-A2-C6-3C2-A2-K6-2C3-A2-2C6-A2-2A3-C9-A5-9G124-2(3BC)B2C2B2-A6-2C3-A2-C6-3C2-A2-C11-J2-C-A8-2A2-2C9-2A3-CH8-A5-9H109-7B2(C2B)2-A3-B2-C4-A2-P-A3-KL2C2(2-A)11-A2-KC9-2A2-AC9-2A2-2C9-2A3-11H108-6B2C5B2-A-9A-A2-3A5-A3-A2-3A9-A2-AC2(A8-2A2-2C)9-A5-9H109-10BC2B2-11A-2(A2-2A-6A3-)A2-M2(2-6A2-2A2-A)C-6A2-2A2-13A4-2A5D3A6-7DAF4-2A2-3A2-2A63-13B2(2-9A-3A)2(2-9A-2AJ)2-J2-6A-3A2-12AM2-13A3-9A2-A2-2F7A3-F4-4A-3A-A4-A2DA3DA2DA4-11A3-A2D2A3D2A2DA2-13A2-13B2-13A2-A11-A2-A11-J2-2A-A8-A2-A11-A2-10A-2A2-F9A-2A3-12A2-F11-F77-13B2-13A2-Q11-A2-A11-P2-A11-A2-J11-M2-10A-2A2-10A-AK2-F2A7-3A2-F11-F77-13B2-13A4(2-A11-A)2(2-10A-2A)2-3A7-3A2-F11-F77-13B2-13A3(2-A11-A)2-A11-J2(2-10A-2A)2-3A7-3A2-F11-F77-13B2-13A2(2-A11-A)2-A11-D2-A11-A2-10A-AD2-10A-2A2-3A7-3A2-A11-A77-13B2-13A2-A11-A-2D11-D-2D11-A2-D11-4D9A-2A2-D9A-AD2-3A7-3A2-A11-A77-13B2-D11AD2-D11-4D11-2D-A11-A2-D11-D2-10A-2A2-D9A-A2D-D2A7-2AD-2D11-D77-13B2-13A2-A11-A2-D11-D2-A11-A2-D11-2D-10A-2A2-D9A-AD2-3A7-3A2-A11-A77-13B-2D11AD-2D11-2D-D11-D2-A11-A2-D11-D2-10A-2A2-D9A-AD-2D2A7-2AD2-D11-2D76-13B2-13A2-A11-A2-D11-D-DA11-D2-D11-3D10A-AD2-D9A-A2D-3A7-3A2-A11-A77-13B2-13A2(2-A11-A)2-D11-A2-A11-A-2D9A-2A2-10A-2A2-3A7-3A2-A11-A77-13B2-13A4(2-A11-A)2(2-10A-2A)2-3A7-3A2-F11-F77-13B2-13A3(2-A11-A)2-A4-D6-A2(2-10A-2A)2-3A7-3A2-F11-F77-13B2-13A3(2-A11-A)2-A6-D4-A2(2-10A-2A)2-13A2-F11-F76-
