model
size = 23 24 16, scale = 0.05, origin = -y
material 
  colors = A:#BBB B:#444
voxels
191-2(4(A-)A14-)9A12-13A9-6A3-6A8-6A3-6A7-8A-8A6-2A3-7A3-2A2(6-A5-5A5-A)6-2A3-7A3-2A7-15A9-13A13-7A340-3A19-5A17-7A14-11A12-11A13-9A384-5A17-7A16-2A3-2A15-2A5-2A12-3A7-3A2(10-A11-A)10-2A9-2A11-11A15-5A20-A272-7A15-9A14-2A5-2A13-2A7-2A12-2A7-2A11-2(2A9-)4(A13-A8-)2A11-2A9-4A5-4A12-4A-4A16-5A200-9A13-11A12-2A7-2A12-A9-A11-2(2A9-)2A11-2A7-3A11-3A6-2A13-2A5-3(2A15-2A4-)2A15-2A5-A15-A6-2A13-2A2(7-4A)12-A5-A17-5A87-2AB2A17-3AB3A15-A7BA14-9A13-A9-A12-A9-2(A11-)A9-2A11-2A7-2A13-2A6-A15-A5-A17-A4-A17-A3-2(A19-A2-)A19-A3-A17-A4-A17-A5-A15-A7-A13-A9-3A7-3A12-4A-4A18-A43-5A17-2A-B-2A16-3(A-)A37-11A2(11-A)2(10-A11-A)8-2A13-2A6-A15-A5-A17-A4-A17-A3-3(A19-A2-)A19-A3-2(A17-A4-)A17-A5-A15-A7-2A11-2A10-4A3-4A16-3A19-5A17-A5-A15-A3-B3-A14-4A-4A13-2A7-2A11-A2-7A2-3(A10-A11-)A8-2A13-2A5-A17-A4-A17-A3-5(A19-A2-)A19-A3-A17-A4-A17-A5-A15-A7-A13-A9-3A7-3A13-7A14-11A13-A7-A14-A3-B3-A13-A2(-3A)-A11-3A7-3A10-A2-7A2-A11-A9-2(A11-)A9-A13-A7-A15-A5-A17-A4-A17-A3-A19-A2-A19-A-A21-2A21-A-2(A19-A2-)A19-A3-A17-A4-A17-A5-2A13-2A8-2A9-2A12-9A13-11A12-A9-A12-A4-B4-A12-A2(-3A)-A13-A7-A13-A-7A-A12-A9-2(A11-)A9-A13-A7-A15-A5-A17-A4-A17-A3-A19-A2-A19-A-A21-2A21-A-2(A19-A2-)A19-A3-A17-A4-2A15-2A6-A13-A2(9-2A)12-9A13-11A12-A9-A12-A4-B4-A13-4A-4A14-A7-A13-A-7A-A12-A9-2(A11-)A9-A13-A7-A15-A5-A17-A4-A17-A3-A19-A2-A19-A-A21-2A21-A-2(A19-A2-)A19-A3-A17-A4-A17-A5-2A13-2A8-2A9-2A12-9A15-7A14-2A7-2A13-A3-B3-A14-2ABA-AB2A14-A7-A14-9A13-A9-2(A11-)A10-A11-A8-2A13-2A5-A17-A4-A17-A3-A19-A-A3(21-2A)21-A-A19-A2-A19-A3-A17-A4-A17-A5-2A13-2A8-2(A11-)11A13-9A13-A9-A13-A3(-B)-A14-2A2(-A)-2A14-A7-A14-9A13-A9-A12-A9-2(A11-)A8-2A13-2A6-A15-A5-A17-A4-A17-A3-3(A19-A2-)A19-A3-2(A17-A4-)A17-A5-A15-A7-2A11-2A10-4A3-4A16-3A18-7A14-2A3(-A)-2A14-3(A-)A16-3(A-)A15-A7-A14-4(AB)A13-A9-A12-A9-2(A11-)A9-A13-A7-A15-A5-A17-A4-A17-A3-2(A19-A2-)A4-B9-B4-A2-A4-B9-B4-A3-A17-A4-A17-A5-A15-A7-A13-A2(9-2A)12-9A39-5A16-3A-A-3A15-3(A-)A16-3(A-)A38-4(A-)A14-A3(B-)BA13-A3-B-B3-A12-A9-2(A11-)A8-2A13-2A6-A5-A3B2(A5-)A7-3B7-A4-A8-B8-A3-A4-B9-B4-A2-A3-B-B7-B-B2(3-A)2-B-B7-B-B2-A4-A2-3B7-3B2-A4-A17-A5-A15-A7-2A11-2A10-2A7-2A14-7A41-3A18-7A84-2(4(A-)A14-)AB2(A-)ABA13-A4(-B)-A12-A9-A10-2A3-5A3-2A7-A4-A5-A4-A6-A5-A3-2(A5-)A7-A-A7-A4-A2-3B3-A3-3B2-2(A4-A-B3-B5-B3-B-)A4-A-A3-A5-A3-A-A5-A-3B7-3B-A6-2A13-2A8-3A7-3A12-9A53-
