model
size = 32 31 20, scale = 0.05, origin = -y
material 
  colors = A:#FC0 B:#100 C:#330 D:#111 E:#001 F:#200
voxels
206-4B25-10B20-4B6-4B17-3B10-3B15-2B14-2B13-B18-B11-B20-B106-7B8-8B7-2(3BC)3B4-BFBC4BC2B6-2BC5BC2B4-2BC6BCB6-12B2-BF10B5-2(13B2-13B4-)3B2(C6B)C7BC2B3-5BC4BC8BC5BC4B2(2-B)E7B6-3B5DE2-B831-B991-B31-B930-B28-2(B31-)B898-B31-2(B28-2(B31-)B866-2(B31-))B28-B31-B898-B31-8(B28-B2-B28-B930-)B28-B2-B28-B238-3(7A22-3A7-3A17-2A13-2A14-A17-A12-A19-A10-A21-A8-A22-A7-A24-A6-A24-A5-A26-A4-A26-A3-2A27-A2-A28-A-2A29-4(2A30-)3A28-2A-3(A28-A2-)B2A25-AB2-B2A25-AB5-A23-A8-A21-A10-A19-A12-A17-A14-2A13-2A17-3A7-3A22-7A25-)7A22-13A17-17A14-19A12-21A10-23A8-24A7-26A6-26A5-28A4-28A3-30A2-30A-192A-3(30A2-)D28AB2-B28AB5-25A8-23A10-21A12-19A14-17A17-13A22-7A12-
