model
size = 22 19 32, scale = 0.05, origin = -y
material 
  colors = A:#444 B:#222 C:#111 D:#0F0 E:#777 F:#D00 G:#FFF
voxels
22-23A8(20D2A)20D23A228-6E16-6E15-8E14-2E4-2E36-E6-E3(14-8E)15-6E17-4A192-8B13-4B2-4B12-3B4-3B11-3B6-3B10-2B8-2B3(10-3B6-3B)11-3B4-3B37-2(4A18-)4A169-B8-B11-2B8-2B9-2(B-B8-)2B9-3B2(8-2B10-2B)9-B10-B102-4A18-4A188-3B10-3B3(6-2B12-2B)144-4A18-4A166-2(2B12-2B6-)2B12-2B188-4A144-2(B14-B6-)B14-2B4-2B14-2B187-4A18-4A121-3(2B14-2B4-)2B14-2B209-4A121-3(2B14-2B4-)2(B16-B209-4A121-3(B16-B4-))B16-B209-6(4A99-3(B16-B4-)B16-B231-)4A98-3(2B16-2B2-)2B16-2B208-4A18-4A98-3(2B16-2B2-)2B16-2B208-4A120-3(B18-B2-)B18-B186-4A18-4A55-2(2C14-2C4-)2C14-2C3-2(B2C14-2CB2-)B2C14-2CB3-2(2C14-2C4-)2C14-2C143-4A77-4C10-4C4-2C14-2C3-3(B-C14-C-B2-)B-C14-C-B3-2C14-2C4-C-2C10-2C-C4-4C10-4C121-4A18-4A76-2B4C7-5C2B2-B2C14-2C5(B2-BC16-C)B2-B-5C6-5C-B2-B6C6-6CB98-4A18-4A76-7A6-7A-A2-6C4-6C2-2A-2C14-2C5(-2A-C16-C)-2A-C2-12C2-C-2A2-16C2-A-3A14-3A54-4A18-4A98-7A6-7A-A2-6C3-7C2-2A-2C14-2C-2A-C2(2-5C)2-C-2A-C2(2-2C-2C)2-C-2A-2(C2-C3-)C2-C-2A-C2(2-2C-2C)2-C-2A-C3-3C4-3C3-C-2A-C4-G-4C-G4-C-2A2-16C2-A-6A8-6A10-2(4A18-)4A120-20A-A8-3E9-2A2-16E2-2A2-2(2E5-)2E2-2A2(2-2E2-F)2-2E2-2A2-2(2E-3F-)2E2-2A2(2-2E2-F)2-2E2-2A2-3E3-4E3-3E2-2A2-4E8-4E2-2A20-A-20A10-4A164-20A-A8(20-2A)20-A-20A178-20A-A4(8(20-2A)20-A-20A177-23A)8(20-2A)20-23A176-
