model
size = 32 32 17, scale = 0.05, origin = -y
material 
  colors = A:#DDD B:#906 C:#F99 D:#111 E:#100 F:#777 G:#E00 H:#6F6 I:#F0F J:#0FF K:#603 L:#0CF M:#C00 N:#FF3 O:#F90 P:#C03 Q:#F60 R:#F96 S:#F9C T:#F9F U:#FC0 V:#FC3 W:#0FC
voxels
365-2(D4-D26-)15(6D26-)6D247-3B6-3B213-4D2-4D21-2D2AD2BD2A2D18-B-DAB6ABAD-B16-B-DB8ABD-B16-C-DAB6ABAD-C16-C-DB8ABD-C16-C-DAB6ABAD-C11-6C-DAB6ABAD-6C7-5C-DAB6ABAD-5C9-4C-DAB6ABAD-4C11-3C-DAB6ABAD-3C13-2C-DB8ABD-2C15-B-DAB6ABAD-B16-B-DB8ABD-B16-B-DAB6ABAD-B18-DB8ABD18-C-DAB6ABAD-C18-3D6C3D213-E8-E20-5B4-5B50-5B4-5B52-2F6-2F86-D3B2-3BD20-2(2B4A)2B17-CD12ADC9-C6-CD12ADC6-C2(2-2C5-CD12ADC5-2C)2-7CAD12ADA7C3-5C2AD12AD2A5C4-6CAD12ADA6C5-5CAD12ADA5C7-4CAD12ADA4C9-3CAD12ADA3C11-2CAD12ADA2C13-3B12A3B14-3B12A3B16-2B10A2B17-CDB10ABDC17-DB10ABD20-10B181-3E6-3E18-7B2-7B48-7B2-7B18-4C4-4C20-C2FC4-C2FC42-P30-PI10-D3B2-3BD10-2IC7-2(2B4A)2B7-C2I2C5-B14AB5-2C2IB2C4-B14AB4-2CB2ICB2C3-B14AB3-2CBC2ICB5C16A5CBCI-CB26ABC2-CB26ABC3-B26AB4-B26AB5-C24AC7-C22AC9-C20AC11-C3B4AB2AB4A3BC13-3B4AB2AB4A3B16-2B3AB2AB3A2B17-CAB3AB2AB3ABAC17-JB3AB2AB3ABJ20-3B-2B-3B210-2B5EB2-B5E2B16-6B2-6B16-8B2-8B16-C5F2-5FC19-C2FB4-B2FC21-2C6-2C54-2DB4-B2D20-2D3A4B3A2D17-B14AB11-C4-B14AB4-C6-2C3-B14AB3-2C6-2C3B16A3B2C6-3B20A3B3(6-2CB20AB2C)6-ICB20ABCI7-CB20ABC9-B20AB11-C3B2ADAB2ABAD2A3BC13-3B2ADAB2ABAD2A3B16-2BADCB2ABCDA2B17-CABADCB2ABCDABAC17-JBADC-2A-CDABJ20-B2CL2BL2CB22-C8-C22-I8-I53-OMO6-OMO19-5E4-5E17-7E2-7E14-3B5EB2-B5E3B14-2B4E4-4E2B15-3B2EF-B2-B-F2E3B14-2CF2B2CB2-B2C2BF2C15-4FCB4-BC4F17-JCFC6-CFCJ19-C2F6-2FC20-BFB6-BFB21-BAB4DBAB19-BDB3A4D3ABD2(B16-B14A)B14-2(2B16A2B12-C2B14A2BC12-CB16ABC12-C2B14A2BC12-)I3B2ADAB2ABAD2A3BI13-3BAD-DB2ABD-DA3B16-2BC-CB2ABC-C2B17-2CB2(C-)2C2(-C)B2C18-BC-CL2BLC-CB117-P8-P21-3M6-3M18-6E4-6E15-8E2-8E13-3B5EB2-B5E3B14-2BE-2E4-2E-E2B15-3B3E-B2-B-3E3B16-4C2B2-2B4C19-3CB4-B3C21-2(2C6-2C22-)2B6-2B22-2B6-2B19-B2D2AB4DB2A2DB16-F14AF16-N14AN16-3(F14AF17-I12AI17-)F14AF16-GI12AIG15-GF3ADAB2ABAD3AFG14-GF2AD-DB2ABD-D2AFG15-3BC-CB2ABC-C3B18-B2(C-)2B2(-C)B180-OMO6-OMO19-5E4-5E17-7E2-7E14-3B5E4B5E3B15-BE-E6-E-EB16-3B2-E-B2-B-E2-3B16-F2EB-B2-B-B2EF19-CFCB4-BCFC21-2F6-2F22-J8-J22-B8-B22-B3-2D3-B16-H2-16D2-H11-H-F14AF-H13-2HD12AD2H15-HD12ADH17-2(N12AN18-D12AD18-)N12AN18-D12AD17-GQ12AQG14-G2MD2ADAB2ABAD2AD2MG13-GF2AD-DB2ABD-D2AFG15-3B2(C-)2D2(-C)3B18-B3CL2BL3CB211-5E4-5E18-5E4-5E16-2B5E4B5E2B16-4BD4-D4B17-7B2-7B17-2JBJ6-JB2J17-H2-BJ6-JB2-H15-H3-2J6-2J3-H13-H18-H12-H18-H11-H9-2C9-H19-4C22-5KB4AB5K16-N14AN16-3(F14AF17-I12AI17-)F14AF15-2GI12AI2G13-HGF3ADAB2ABAD3AFGH12-2GFBAD-DB2ABD-DABF2G16-B2(C-)2B2(-C)B276-3E6-3E18-7B2-7B49-4B6-4B184-2C29-4C27-6C21-2(KN)B6AB2(NK)16-K2B10A2B3(K16-D14AD16-K14A)K14-H-3C10A3C-H13-G3B3AB2AB3A3BG15-3BD-DB2ABD-D3B18-B2(C-)2B2(-C)B307-5B4-5B248-2J29-4C27-6C26-6C23-3B6A3B19-2D10A2D2(18-B12AB18-D12AD)18-B12AB15-H2-2C10A2C2-H15-2B3AB2AB3A2B18-2BA2(2D-)2DA2B19-B3CL2BL3CB308-2B8-2B280-J2CJ27-6C26-C4DC24-10C22-D8AD21-2(B10AB20-D10AD20-)B10AB17-H2-C10AC2-H17-G3AD2AD3AG21-G2K-2B-2KG21-2G7-3G631-J4CJ26-J4-J24-2CJ4CJ2C7(22-D8AD)18-H2-G10DG2-H15-4HG6-G2M2H27-3G633-2C62-2C26-C8BC2(22-LC6DCL22-L8CL)22-LC6DCL22-10C21-2GC2L2C2LC2G20-3G6-3G29-3G633-2V62-2C27-C6BC3(24-C6-C24-8C)27-2I35-W730-2U29-3(4B60-)4B829-2T62-2S62-2C62-2R271-
