model
size = 30 6 10, scale = 0.05, origin = -y
material 
  colors = A:#111 B:#960 C:#222 D:#444 E:#E00 F:#EEE G:#777
voxels
5-22C307-22C11-E14-E13-E-E12-E-E13-E14-E41-22B6-2C22A2C39-G14-G69-26B3-C26AC38-2(G14-)D14-D38-5B3D12B3D5B-C5AFAF12AFAF5A2(C67-3(D14-)D8-5BDBD12BDBD5B-C28A)C37-2(G14-)D14-D38-5B3D12B3D5B-C5AFAF12AFAF5AC37-G14-G69-26B3-C26AC8-E14-E13-E-E12-E-E13-E14-E41-22B6-2C22A2C2-
