model
size = 32, scale = 0.05, origin = -y
material 
  colors = A:#EEE B:#630 C:#CC0 D:#F90 E:#800 F:#CF6 G:#C00
voxels
32-96A896-141A6D23A12D19A7D4A3D17A6D2A4DA3D15A6DA7D3AD13A6DA9DA3D11A6DA3D5A3D3AD10A6DA3D6A3DA2D10A7DA2D7A2D2AD9A5D3A4D5A3D2(AD)8A4DA3DA4D3A3DA4D8A3DA5DA4DA3DA5D8A2DA7D2(A6D)8ADA3D3A3DA4DA7D8ADA3D4A3DA2DA8D9ADA3D5A2D2A8D10A2DA3D3A3DA9D10A3(3DA)10D11AD3A5DA10D13A2(3DA)10D15AD5A10D17A3DA10D19A3DA8D23A6D270A26(30B2A)30B162A26(30-2A)30-129A928-33A30B2A9-2F8E2F9-A928-33A30B2A7-2F3E6C3E2F7-A928-33A30B2A6-F2E12C2EF6-A928-33A30B2A5-F2E14C2EF5-A928-33A30B2A4-F2E16C2EF4-A16-G911-33A30B2A3-F2E18C2EF3-A928-33A30B2A3-FE20CEF3-A11-G916-33A30B2A2-FE22CEF2-A24-G903-33A30B2A2-FE22CEF2-A928-33A30B2A-F2E22C2EF-A6-G12-G908-33A30B2A-FE24CEF-A928-33A30B2A-FE24CEF-A14-G913-33A30B2A-FE24CEF-A928-33A30B2A-FE24CEF-A9-G918-33A30B2A-FE24CEF-A24-G903-33A30B2A-FE24CEF-A928-33A30B2A-F2E22C2EF-A16-G911-33A30B2A2-FE22CEF2-A928-33A30B2A2-FE22CEF2-A7-G920-33A30B2A3-FE20CEF3-A21-G906-33A30B2A3-F2E18C2EF3-A11-G916-33A30B2A4-F2E16C2EF4-A928-33A30B2A5-F2E14C2EF5-A17-G910-33A30B2A6-F2E12C2EF6-A928-33A30B2A7-2F3E6C3E2F7-A928-33A30B2A9-2F8E2F9-A928-33A30B2A11-8F11-A928-
