model
size = 12 18 32, scale = 0.05, origin = -y
material 
  colors = A:#E8E8E8 B:#000 C:#FF0004 D:#FFF
voxels
16-5C7-5B7-5A174-5C7-5B6(7-5A)8-3A9-3A10-A70-3C9-3C7-7C5-7B9(5-7A)6-4(5A7-)5B7-5A7-A3CA5-9C3-9B3(3-9A)2(3-2A4-3A)7(3-3A)3-2A4-3A3(3-2A5-2A)3-2A5-BA3-AB2(5-2A3-2A)4-9C3-9B3(3-9A)9(3-2A5-2A)3-A6-2A3-BA5-AB2(3-2A5-2A)2-11C-11B3(-11A)3(-2A7-2A)-2(2A7-A2-)2A4(7-A3-A)7-A3-B7-B2(3-A7-A)2-11C-11B3(-11A)2(-A8-2A)2(-2A7-2A)-2(2A7-A2-)2A3(7-A3-A)7-A3-B7-B2(3-A7-A)2-11C-11B3(-11A)2(-A8-2A)3(-2A7-2A)-2A7-A2-2A2(7-A3-A)7-A3-B7-B3(3-A7-A)2-11C-11B3(-11A)2(-A8-2A)3(-2A7-2A)-2A7-A2-2A7-A3-A7-A3-B7-B4(3-A7-A)2-11C-11B3(-11A)2(-A8-2A)2(-2A7-2A)-2(2A7-A2-)2A7-A3-B7-B5(3-A7-A)2-11C-11B3(-11A)2(-A8-2A)-2A7-2A-3(2A7-A2-)BA7-B6(3-A7-A)2-10C2-10B3(2-10A)5(2-3A5-2A)2-B2A5-AB2-3A6(5-2A3-2A)5-2A2-10C2-10B7(2-10A)2-B8AB2(2-10A)2(3-9A)4-8A4-7A5-7B5-7A3-C3DC2D3C2-10B6(2-10A)2-B8AB2(2-10A)2(3-9A)4-7A5-7B5-7A27-2C3DC2D2C2-10B7(2-10A)2(3-9A)3-8A5-7B5-7A51-2(2C2D)2C2-10B6(2-10A)2(3-9A)3-8A5-7A75-2(2C2D)2C2-10B6(2-10A)3-8A4-8A5-7B87-2(2C2D)2C2-10B5(2-10A)3-8A4-8A5-7A99-2(2C2D)2C2-10B4(2-10A)3-9A3-8A5-7B111-2(2C2D)3C-11B2(-11A)-10A2-10A3-9A3-8A123-C3DC4D2C-11B3(-11A)2-9A3-9A5-5A124-11C-11B3(-11A)2-9A3-8A135-12C12B23A-11A2-9A4-6A136-12C12B24A-10A2-9A5-5A136-12C12B24A-10A3-7A7-3A137-12C12B12A-11A-10A4-6A148-11C-11B2(-11A)2-9A4-5A149-11C-11B2(-11A)2-8A6-4A149-10C2-10B2(2-10A)3-8A160-9C3-9B2(3-9A)4-6A161-8C4-8B4-8A5-7A173-7C5-7B5-7A6-5A171-
