model
size = 24 14 14, scale = 0.05, origin = -y
material 
  colors = A:#52433D B:#1F1F1F
voxels
306-3A309-3A81-3(16A8-)16A160-7A57-7(B-)B7-3(19A5-)19A7-16A8-16A112-9A53-B21-22A2-2A18-2A2-2A19-A2-2A-A16-2A4-2A2-A4-2A7-A5-6A2-11A7-17A2(16-8A)2(15-9A)24-A26-B3-7(B-)B4-23A2(-A21-A)-3A19-A2-2A19-A2-4A6-5A6-A4-2A3-3A2-3A6-A6-3A5-3(3A6-A14-)3A6-A23-A28-B15-B3-25A22-2A22-3A21-A-A21-A2-2A8-ABA8-A2-2A5-ABA-BA8-A4-3ABA4-2(2A8-A13-)2A2(8-A14-A)8-A26-B3-6(B-)B5-25A2(22-2A)22-A-A21-A2-A9-3A8-A2-A6-2AB3A8-A3-5AB3-3A8-A12-B2A8-A13-2A3(8-A14-A)11-B3-6(B-)B5-25A2(22-2A)22-A-A21-A2-A9-3A8-A2-A6-2AB3A8-A3-5AB3-3A8-A12-B2A8-A13-2A3(8-A14-A)13-B15-B3-25A22-2A22-3A21-A-A21-A2-2A8-ABA8-A2-2A5-ABA-BA8-A4-3ABA4-2(2A8-A13-)2A2(8-A14-A)8-A26-B3-7(B-)B4-23A2(-A21-A)-3A19-A2-2A19-A2-4A6-5A6-A4-2A3-3A2-3A6-A6-3A5-3(3A6-A14-)3A6-A23-A28-B21-22A2(2-2A19-A)2-2A-A16-2A4-2A2-A4-2A7-A5-6A2-11A7-17A2(16-8A)2(15-9A)24-A30-7(B-)B7-3(19A5-)19A7-16A8-16A112-9A79-3(16A8-)16A160-7A51-
