model
size = 22 27 15, scale = 0.05, origin = -y
material 
  colors = A:#1D2455 B:#52433D C:#222
voxels
357-19(B10-)B318-5(B10-)B7-18A3-20A2-20A-110A-20A4-16A8-B10-B54-21(B10-)B6-4(20A2-)20A-132A-20A4-16A8-B10-B11-10A11-2(12A10-)12A9-14A8-14A7-2(16A6-)16A5-3(18A4-)18A3-3(20A2-)20A-154A3(-20A4-16A8-2(B10-)3(12A10-)12A9-14A8-14A7-2(16A6-)16A5-3(18A4-)18A3-2(20A2-)20A-176A)-20A4-16A8-B10-B11-3(10A12-)10A10-14A8-14A7-2(16A6-)16A5-3(18A4-)18A3-2(20A2-)20A-176A-20A4-16A8-B10-B12-3(8A14-)8A12-12A9-14A7-2(16A6-)16A5-3(18A4-)18A3-2(20A2-)20A-176A-20A4-16A8-B10-B13-3(6A16-)6A14-10A10-B12AB8-14A7-2(16A6-)16A5-2(18A4-)18A3-2(20A2-)20A-154A5-2(B8-5B8-)B8-5B121-6A14-B8AB10-B12AB2(8-14A)7-4(16A6-)16A4-20A2-20A-154A5-B8-5B207-B8-B10-B12AB3(8-14A)7-2(16A6-)16A5-18A4-18A2-132A5-B8-5B251-B8-B11-9(B10-)B8-16A6-16A5-18A3-20A-44A5-2(B9-3B9-)B8-5B404-11(B10-)B21-B42-C-C548-C159-
