model
size = 31 32 30, scale = 0.05, origin = -y
material 
  colors = A:#EEE B:#FF3 C:#FF0 D:#FF6 E:#CC3
voxels
15-DAD24-9C2(22-C2(E2A)EC)22-D2(E2A)EC22-9D10(22-C3AB3AC)22-CA5BA4(C22-C3AB3A)5(C22-C7A)C22-3CDAD3C25-4(DAD28-)DAD19-2C18BC2(10-5AB7AB2AB4A)10-20BD10(10-B4AB5AB4AB3AB)10-C4AB5AB4AB3AC10-C4AB3A5B2A3(B3AC10-C4AB5AB4A)4BC10-2C4B5AB4A5(B19-B10A)B19-5BA6B23-5(BAB28-)3B18-C21AC2(8-23A)8-D21AD9(8-23A)8-C21AC9-5(21A10-)17A6(19-12A)23-5(3A28-)3A17-C23AC2(6-25A)6-D23AD9(6-25A)6-C23AC8-5(21A10-)17A6(19-12A)23-5(3A28-)3A16-C25AC2(4-27A)4-D25AD8(4-27A)4-C26A4-C25AC7-5(21A10-)17A6(19-12A)23-5(3A28-)3A16-C25AC2(4-27A)4-D25AD9(4-27A)4-26AC7-5(21A10-)17A6(19-12A)23-5(3A28-)3A15-C27AC2(2-29A)2-D2(27AD2-C)8(27AC2-C)27AC6-5(21A10-)17A6(19-12A)23-5(3A28-)3A15-C27AC2(2-29A)2-D27AD10(2-29A)6-5(21A10-)17A6(19-12A)23-5(3A28-)3A14-C29A2C29ABC3(29A2C)29AB806-B29AC30AB93AB29AB806-30ACB60AB61A2B30A806-30ACB60AB31AB29AB31A806-30AC2(31AB29AB)31A806-30AC31AB30AB29AB62A806-15A-14AC15A-30A-15AB14A-14AB15A-30A-15A806-30AC31AB29A2B60AB31A806-30AC2(31AB29AB)31A806-30ACB60AB31AB29AB31A806-30ACB29AB93AB29AB806-B29AC30AB93AB29AB248A5-5(21A10-)17A6(19-12A)23-5(3A28-)3A14-C3(29A2C)29ACD29ADC8(29A2C)29AC5-2(5(21A10-)17A6(19-12A)23-5(3A28-)3A15-C27AC3(2-29A)2-D27AD8(2-29A)2-C27AC6-)5(21A10-)17A6(19-12A)23-5(3A28-)3A16-26AC3(4-27A)4-D25AD8(4-27A)4-C25AC7-5(21A10-)17A6(19-12A)23-5(3A28-)3A16-C25AC3(4-27A)4-D25AD8(4-27A)4-C25AC7-5(21A10-)17A6(19-12A)23-5(3A28-)3A17-C23AC3(6-25A)6-D23AD8(6-25A)6-C23AC8-5(21A10-)17A6(19-12A)23-5(3A28-)3A18-C21AC3(8-23A)8-D21AD8(8-23A)8-C21AC9-5(21A10-)17A6(19-12A)23-5(3A28-)3A19-2C17A2C3(10-21A)10-2D17A2D8(10-21A)5(10-C19AC)10-C18A2C10-2C15A6(19-12A)23-5(3A28-)3A21-2C13A2C3(14-17A)14-2D13A2D13(14-17A)14-15A2C14-2C13A6(19-12A)23-5(3A28-)3A23-2C9A2C3(18-13A)18-2D9A2D14(18-B11AB)18-B6(C10AC19-)C9A2C23-5(3A28-)3A14-
