model
size = 20 11 32, scale = 0.05, origin = -y
material 
  colors = A:#222 B:#0F6 C:#E00
voxels
-8A17-2A17-3A16-2ACA15-5A14-4ACA13-7A12-2(2AB)2A2(12-3A2B3A)12-2(2AB)2A18-2A17-3A16-2ACA15-5A14-4ACA13-7A12-2(2AB)2A2(12-3A2B3A)12-2(2AB)2A12-8A18-5A14-6A13-7A12-4A4B11-9A10-6A4B9-11A9-7A4B3(9-11A)19-3(3A17-)3(3B17-3A17-)3A17-3A5(19-3(2A18-)3(2B18-2A18-)2A18-2A)3(19-A)2(3(19-B19-A)2(19-A)19-3(2A18-)3(2B18-2A18-)2A18-2A3(19-A)3(19-B19-A)5(19-A))4(3(19-B19-A)5(19-A))3(19-B19-A)2(19-A)3(18-2A)3(18-2B18-2A)2(18-2A)18-3(A19-)3(B19-A19-)5(A19-)3(B19-A19-)A19-A3(18-2A)3(18-2B18-2A)2(18-2A)18-3(A19-)3(B19-A19-)A19-A3(18-2A)3(18-2B18-2A)2(18-2A)4(17-3(2A18-)3(2B18-2A18-)2A18-2A)16-3(3A17-)3(3B17-3A17-)3A17-3A13-5A14-6A13-7A12-4A4B11-9A10-6A4B9-11A9-7A4B3(9-11A)9-
