model
size = 9 11 18, scale = 0.05, origin = -y
material 
  colors = A:#002 B:#0F3 C:#EEE D:#777 E:#0E0 F:#CF3 G:#00E H:#36F I:#555 J:#111
voxels
31-2(2(2A7-)2A70-)4(2A7-)2A52-2A7-2A16-2C16-2A7-2A43-2(2A7-)2C6-D2CD6-2C2(7-2A)43-2A7-2A16-2C16-2A7-JG7-2G43-2A7-2A2(6-3A)7-2A8-B7-2B42-4C6-D8-DA6-BCA6-I8-3B7-2F52-C7-BCB6-B17-3B7-2F60-BDB24-3B7-2B60-3B6-3B7-2B6-3B96-3B6-3B21-2E5-2E22-2(2A7-)2A24-3B22-B5-B14-4(2A7-)2A15-3B6-BHB6-BCB4-E2B-3B5-2A7-2A16-2C16-2A7-2A6-3B34-2(2A7-)2C6-D2AD6-2C7-2A8-A43-2A7-2A16-2C16-2A7-2A52-4(2A7-)2A48-
