model
size = 22 16 28, scale = 0.05, origin = -y
material 
  colors = A:#EEE B:#930 C:#040 D:#F90 E:#E00
voxels
5-14A7-2(14A8-)2(2A6C6A8-)2(2A2(2C4A)8-)4(8A2C4A8-)2(2A2(2C4A)8-)2(2A6C6A8-)14A100-2(9(6A16-)6A148-)7(6A16-6A148-)6A16-6A58-31(10A12-)10A8-31(18A4-)18A2-48A12(14B8A)14-8A14-52A12(14B8A)14-8A14-2(48A3(2E2A14B4A)2E2A4(14B8A)4(14B4A2E2A)14B2(8A14-))2(48A2E2A14B4A2E2A14B8A7(14B2A2D4A)14B2A2D2E2A14B4A2E2A14B2(8A14-))2(48A2(2E2A14B2A2D)4A7(14B8A)14B4A2(2E2A14B2A2D)4A14-8A14-)2(52A14B2A2D4A14B2A2D7(2E2A14B4A)2E2A14B8A2(14B2A2D4A)14-8A14-)2(52A4(14B2A2D4A)4(14B8A)4(14B2A2D4A)14-8A14-)2(52A12(14B8A)14-8A14-)4A2-31(18A4-)18A6-2(14A8-)2(2A6C6A8-)2(2A2(2C4A)8-)4(8A2C4A8-)2(2A2(2C4A)8-)2(2A6C6A8-)14A8-14A4-
