model
size = 15 21 7, scale = 0.05, origin = -y
material 
  colors = A:#03F B:#111 C:#06F D:#400 E:#AAA
voxels
6C3-12C3-6C6B3-6B6A7(3-12A)3-38A2B7A2B3A3(B2CB5AB2CB2A)4B5A4B16A30D2(C4-C3-C4-2C4-C3-C4-CB4-B3-B4-BA8(4-A3-A4-2A)4-5A4-7(2A13-)AD13-2D13-D)C4-C3-C4-2C4-C3-C4-CB4-B3-B2(4-BA4-A3-A4-AB2(4-A3-A4-2B)4-A3-A)4-BA4-5A4-AB2(13-2B)13-BA13-AB2(13-2B)13-B2(D13-2D13-DC4-C3-C4-2C4-C3-C4-CB4-B3-B4-BA8(4-A3-A4-2A)4-5A4-7(2A13-)A)D13-2D13-D6C3-12C3-6C6B3-6B6A7(3-12A)3-66AB13ABAB11AB3AB9AB5ABA5BAB3A5D2(BE)B10D5B5D
