model
size = 18 21 9, scale = 0.05, origin = -y
material 
  colors = A:#FF0 B:#FF3 C:#111 D:#222 E:#555 F:#888
voxels
4-CD16-2(D17-C)329-F47-D328-2A11-A17-A13-2A-DAF12-A2-AD13-A2-DA13-A2-AD14-A-DA15-2(A2-2B13-)A2-AB2(13-A2-2A)12-2(A-)2A11-A2-A-2B10-A4-3B10-A5-B11-5A2B32-2A35-3A2-2A10-4A4-A8-B4A4-A7-2B4A4-A6-3B5A3-A6-8A3-A6-7A2B2-A6-6A2(3B2-A7-5A)3B2-A7-6A2B2-A7-3(8A10-)5A3B9-5A5B8-5A5BA7-5A3B10-6AB13-4A15-2A16-4A2-2A-A8-4A3-A-A7-2B3A3-A-A6-3B3A3-A-A5-4B4A2-A-A5-3B5A2-A-A5-7A2B2(-A)5-6A3B-B-A2(6-5A3B-B2A)6-6A2B-3A6-2(8A10-)2B6A10-2B3A3B9-3B2A2(5B3A5-5A)3B10-6AB13-4A15-2A16-4A2-2A-ACD6-4A2-2A-A7-2B3A3-A-A6-3B3A3-A-A5-4B4A2-A-A5-3B5A2-A-A5-9A2(-A)5-7A2B2(-A)2(6-6A2B-3A)6-8A-3A6-8A2-E7-2B6A2(2-E7-3B5A)2-E6-4B2A3B4A5-3B3A3B4A5-6A2B10-7A13-4A15-2A16-4A2-A-A2-2C5-4A4-A8-2B3A4-A7-3B3A4-A6-4B4A3-A6-3B5A3-2(A6-9A2-)3(A7-8A2-)A7-8A10-2B6A2(10-3B5A)9-4B6A8-3B7A2C6-8A10-7A13-4A15-2A22-A-A3-C17-D60-3(A17-)A16-3(A17-)A36-2A9-C5-B2A7-3C6-A6-3C109-2CD17-C202-2A9-3C3-3A16-A85-
