model
size = 18 32 14, scale = 0.05, origin = -y
material 
  colors = A:#FF0 B:#CC3 C:#222 D:#111 E:#777 F:#888
voxels
550-D17-CD276-3A12-21A-4A3B9A505-2(3A12-3B)18A-4A3B9A3-2A5B7A8-3B3A13-2B2A14-B3A14-4A15-3A15-2AB3(16-2B)17-3B12-2E2-4A10-2E4-2A17-E4-11(2A12-2A2-)2(2A12-2B2-)2A12-2B-2(3A12-3B)3A12E3A-4A3B9A3-2A5B7A8-2(3B3A12-)2B4A2(12-6A)12-4A2B3(12-3A3B)12-4A2B12-6A13-4A15-2A9-2(AC12-CA2-)2(DC12-CD2-AC12-CA2-)DC12-CD-2(2AC12-C2ADAC12-CAD)2(3A12-3B)2AE3(12-3B3A)12E3A-16A3-3A3B8A6-2A2B4A10-2A2B4A3(11-7A)12-4A2B3(12-3A3B)12-4A2B12-6A13-4A15-2A9-3(AC12-CA2-DC12-CD2-)AC12-CA-DAC12-CAD2AC12-C2ADAC12-CAD2AC12-C5A12-6A12-3B2AE2(12-3B3A)12-6A12E3A-16A3-14A8-3(6A12-)3(A3B2A12-)3(4A2B12-)6A12-6A13-4A15-2A9-13(2A12-2A2-)2A12-2A-3B12-3A3B12-2BA3B11E3BA-13A3B3-AD12A5-F-7A2-F6-D-7A2-CD5-D-2A3B2A3-2C6-A5BA4-C6-A2(5BA12-)A3B2A4(12-6A)13-4A15-2A260-3B12-2BA3B12-7B9A5B-2B10A4B3-12A2B8-6A13-4A10-2D2-3BA10-CD2-4B5-C5-2D2-3B5-CD8-3B16-BA2(16-2A)17-3A12-2A2-4A10-2A4-2A17-E273-3B12-7B9A5B-2B10A4B76-CD18-D11-2(D17-)D527-D17-D29-C2(17-D)15-3C15-D17-C17-D439-D575-CD130-2D443-D17-2D93-D17-C462-2D17-C2(D17-)DCD17-D18-D24-
