model
size = 30 31 18, scale = 0.05, origin = -y
material 
  colors = A:#FF3 B:#CC3 C:#111 D:#222 E:#001 F:#777 G:#AAA H:#F60
voxels
239-2(D29-)D28-2C28-C150-C29-D29-C148-C539-C238-2C28-D2(29-C)510-C2(29-D)29-C75-10A19-EA-6A-A19-D6A2(-A)19-EA-4A2(-A)5-C13-E4A3(-A)4-C14-D4A3(-A)4-C14-2(E2A4(-A)19-)D2A4(-A)20-10A11-7C6A236-3A27-4A26-4A2B24-4A3BA22-10A94-2C44-5B2A3B20-5B2A2-B20-A3B4A-B2(20-10A)19-E8A21-D2(8A7-D13-E)8A6-2C13-D2(8A21-E)8A21-D8A22-8A11-3C8-6A28-6(G29-)G24-D2AC26-C2A2C25-D2A4C23-C2A6C22-4A3B3A2F93-C29-D14-5B2A3B5-D14-5B2A3B20-A3B4A2B2(-A18-10A)-A17-D8A3-A3-C13-E8A3-B3-D13-E8A3-B17-D2(8A3-B17-E)8A3-B17-D8A3-A17-E8A3-A18-8A3-A6-2A10-8A3-2(A29-)A23-D5-D18-12D107-D2AC26-C2A2C25-D2A4C23-C2A6C22-4A3B3A2F29-D7-3B2A6C10A-D5-3B10-A3B4A2B-D5-B12-5B2A3B-B4-2A12-5B2A3B-B3-DA13-5B2A3B-B4-A13-A3B4A3B2A17-13A17-9A-3A16-D8A2-3A2-C13-E8A2-A2B16-E8A2-3B16-D2(8A2-3B16-E)8A2-A2B16-D8A2-3A16-E8A2-3A17-8A2-3A4-2A11-8A2-3A17-7A3-3A17-6A4-3A17-5A2(-3D)17-4A8D107-D2AC26-C2A2C25-D2A4C23-C2A6C22-4A3B3A2F48-2(10A20-)A3B4A2B20-A3B4A2B5-D14-A3B4A2B5-CA12-D8A2B-A3-CA12-E8A2B-A4-A12-E8A2B-A17-D8A3-A2-DC13-E8A3-B2-D14-E8A3-B17-D2(8A3-B17-E)8A3-B17-D8A3-A17-E8A3-A18-8A3-A4-A13-8A3-A18-7A4-A18-6A5-A18-5A6-D18-4A115-D2AC26-C2A2C25-D2A4C23-C2A6C22-C9A3(20-10A)19-E10A19-D10A19-E8A2B19-D7A3B4-CD13-E7A3B4-C-A12-E7A3B3-2C-A12-D8A2B6-A12-E10A4-D-A12-E10A3-2D-A12-D9AF3-2D-2(A12-E9AF6-)A12-D10A6-A12-E10A6-A13-9A7-2A12-8A9-2A11-7A11-2A10-6A13-3A8-5A16-13A115-D10A19-C10A19-D10A19-C10A2(20-C9A20-D9A)19-E10A19-D10A19-E8A2B19-D7A3B19-E7A3B19-D7A3B3-C15-E8A2B-3C2-A12-E10A2C17-D9AFG2-D2-B12-E9AFG2-D15-E9AF-3D15-D9AF2G17-E9AF19-E10A20-9A21-8A22-7A11-A11-6A24-5A21-8A116-2(10A20-)2(8A2B20-)C7A2B20-D9A20-C9A20-D9A19-E10A19-D10A19-E8A2B19-D7A3B19-E7A3B19-D7A3B19-E8A2B6-B12-E10A19-D9AF6-B12-E9AF19-E10A19-D2(9AF19-E)10A20-9A21-8A22-7A11-A11-6A24-5A21-8A23-2H28-2H61-10A20-8A2B2(20-7A3B)20-C6A3B20-D7A2B20-C9A20-D9A19-E10A19-D10A19-E10A19-D8A2B19-E8A2B19-D8A2B19-E10A2-D3-B12-E10A2-C16-D9AF-CD3-B12-E9AF2G17-E9AF19-D9AF2G17-E9AF19-E10A20-9A21-8A22-7A11-B11-6A24-5A21-8A23-2H28-2H60-D10A19-C8A2B19-D7A3B19-C7A3B20-C6A3B20-D7A2B20-C9A20-D9A2(19-E10A19-D10A)4-C14-E10A3-2C14-D10A2-CD15-E10A2-C3-B12-E10A19-D10A6-B12-2(E9AF19-)D9AF-2C16-E10A19-E10A20-9A21-8A22-2B5A11-B11-2B4A24-2B3A21-8A115-D2AC26-C2A2C25-D2A4C23-C2A6C22-C6A3B20-8A2B2(20-10A)19-E10A19-D10A19-E10A5-C13-D10A4-CD13-2(E10A6-A12-)D10A6-A12-E10A6-B12-E10A3-D2-B12-D10A2-2D2-B2(12-E10A2-C3-A)12-D10A6-A12-E9AB6-A13-9A7-AB12-2B6A9-2B11-3B4A11-2B10-3B3A13-2BA8-3B2A16-8A3B2A115-D2AC26-C2A2C25-D2A4C23-C2A6C22-8A3BF48-3(10A20-)10A5-C14-10A5-CA12-D2(10A-A4-A12-E)10A-A3-C13-D8A3-A3-C13-E8A3-A2-CD13-E8A3-A-2D14-D2(8A3-A17-E)8A3-A17-D8A3-B17-E8A3-B18-8A3-B4-A13-2B6A3-B18-3B4A4-B18-3B3A5-A18-3B2A6-D18-2B2A115-D2AC26-C2A2C25-D2A4C23-C2A6C22-10A2F29-D7-B4A6C10A-D5-3B10-10A-D5-B12-10A-D3-D2B12-10A-D3-CA13-10A-D4-A13-13A17-13A2-D14-9A-3A2-D13-2(D2(8A2-3A16-E)8A2-3A16-)D8A2-3B16-E8A2-3B17-8A2-3B4-2A11-2B6A2-3B17-3B4A3-3B17-3B3A4-3A17-3B2A2(-3D)17-2B2A8D107-D2AC26-C2A2C25-D2A4C23-C2A6C22-10A2F93-D29-C14-2(10A20-)10A-A18-10A-A3-D14-10A-2(A17-D2(8A3-A17-E)8A3-)A17-D8A3-A17-E8A3-B18-8A3-B6-2A10-8A3-B2(29-A)23-D5-D18-12D108-3A27-4A26-6A24-8A22-10A65-C29-D44-10A20-7A2-A20-8A-A20-10A5-C14-10A5-C13-E8A7-D13-D2(8A21-E)7AB21-D7AB21-E7AB7-C13-E8A7-D13-D8A7-C14-8A11-3C8-6A28-6(G29-)G220-D194-10A19-EA-6A-A5-C13-D6A2(-A)5-D13-EA-4A-A-B19-E4A-A2(-B)5-D13-D4A-A2(-B)5-C13-E2A2(-A)2(-B)5-D13-E2A3(-A)-B19-D2A4(-A)5-C14-10A4-2C5-7C6A222-
