model
size = 30 10 30, scale = 0.05, origin = -y
material 
  colors = A:#111 B:#930
voxels
41-8A262-8A290-12A285-18A280-22A277-24A276-24A275-26A274-26A13-8B22-8B23-6A24-6A25-4A26-4A27-2A28-2A46-26A10-14B16-14B17-12A19-10A20-10A21-8A22-8A23-6A25-4A14-12A4-12A9-2(4B2A2-2A4B16-)14A17-3(12A18-)12A19-4A2-4A20-10A11-10A8-10A9-3B8-3B16-4B6-4B16-4A6-4A2(16-5A4-5A)17-5A2-5A18-12A18-2A8-2A18-12A9-10A10-10A7-3B10-3B14-4B8-4B15-4(3A8-3A16-)14A17-A10-A18-12A9-10A10-10A7-2(3B10-3B14-)3A10-3A14-4A8-4A15-2(3A8-3A16-)14A16-2A10-2A17-12A9-9A12-9A7-2(3B10-3B14-)3(3A10-3A14-)4A8-4A15-14A16-2A10-2A16-2(14A8-9A12-9A7-2(2B12-2B14-)4(3A10-3A14-)16A14-2A12-2A15-)14A8-9A12-9A7-2(3B10-3B14-)3(3A10-3A14-)4A8-4A15-14A16-2A10-2A16-14A8-10A10-10A7-2(3B10-3B14-)3A10-3A14-4A8-4A15-2(3A8-3A16-)14A16-2A10-2A17-12A9-10A10-10A7-3B10-3B14-4B8-4B15-4(3A8-3A16-)14A17-A10-A18-12A10-10A8-10A9-3B8-3B16-4B6-4B16-4A6-4A2(16-5A4-5A)17-5A2-5A18-12A18-2A8-2A18-12A10-12A4-12A9-2(6B2-6B16-)14A17-3(12A18-)12A19-4A2-4A20-10A12-26A10-14B16-14B17-12A19-10A20-10A21-8A22-8A23-6A25-4A15-26A13-8B22-8B23-6A24-6A25-4A26-4A27-2A28-2A46-26A275-24A276-24A277-22A280-18A285-12A279-
