model
size = 16 6 29, scale = 0.05, origin = -y
material 
  colors = A:#111 B:#222 C:#0F0 D:#444 E:#EEE F:#E00 G:#FF0 H:#D00
voxels
38-4D76-4A11-D4BD60-2C12-6A9-2D4B2D58-4C11-6A9-D6BD58-4C10-3(8A8-D6BD57-6C9-)8A8-DBE2BEBD57-2C2D2C9-8A8-D6BD57-CDGFDC9-8A8-DBE2BEBD57-CDFGDC9-8A8-D6BD57-2C2D2C8(9-8A8-D6BD57-6C)9-8A8-D6BD57-2C2D2C9-8A8-D6BD57-CDGFDC9-8A8-DBE2BEBD57-CDFGDC9-8A8-D6BD57-2C2D2C9-8A6-3DBE2BEB3D55-6C9-8A5-4D6B4D5-D6-D41-6C9-8A4-5D6B5D3-2(2D6-)D8-D24-6C9-8A8-D6BD7-A8-A5-AHA6-AHA5-A8-A9-C2-C11-6A9-2(2DB)2D2(6-3B)4-B-B6-B-B4-3B6-3B24-A2-A11-2D2-2D53-
