model
size = 32 32 15, scale = 0.05, origin = -y
material 
  colors = A:#111 B:#EEE C:#9CF D:#03F E:#D00 F:#C63 G:#C00 H:#CF0
voxels
-2(30A2-)30A185-8A736-2(31A-)31A2-2(31A-)15A2BH2F11A-16A3H2F10A2-16A4FG9A4-4A13-2FG8A84-3(12A20-)12A544-31A2(-A23C7A)-A3(23C9A)23C40A3-5A12-12A20-2A3G-5A21-11A21-3(12A20-)12A544-3(31A-)138AB21A2-8A2(BA)B17A2-6A9-2(14A18-)15A3(20-12A)24-11(6B26-)6D26-6B26-6E26-6B25-8B24-8B7(3(-31A)-138AB21A2-8A2(BA)B17A2-6A9-2(14A18-)15A3(20-12A)23-11(B6-B24-)D6-D24-B6-B24-E6-E3(24-B6-B))3(-31A)-138AB21A2-8A2(BA)B17A2-6A9-2(14A18-)15A3(20-12A)24-11(6B26-)6D26-6B26-6E26-6B25-8B24-8B3(-31A)-160A3-5A12-12A20-2(11A21-)3(12A20-)12A544-2(31A-)31A2-3(31A-)31A2-30A4-4A12-12A84-3(12A20-)12A545-2(30A2-)30A181-12A736-
