model
size = 25 3 25, scale = 0.05, origin = -y
material 
  colors = A:#EEE B:#111
voxels
25A7B2-B4-3B-7B25-25AB5-B3(-2B)2-B5-B25-25AB-3B-B2-3B2-3(B-)3B-B25-25AB-3B-B-2B2(-B)4-B-3B-B25-25AB-3B-B3-2(B-)3B-B-3B-B25-25AB5-2(B-)B3-2B2-B5-B25-25A7B4(-B)3-7B25-25A12-B37-25A2(5B-)B-4B3(-B)26-25A5(-B)3-2B4-B3-B8-B17-25A-2B-3B2-B-3B-2B3-2B-2B25-25A2-2B-B2-4B4-3B5-B25-25AB2-7B2(-B)3-2B-B-3B25-25AB2-3B-2(B2-2(B-))B-B26-25AB5-B-2B4-8B-2B25-25AB3-2B2(-B)2(2-B)2-3B3-B25-25AB-2B-3B4-3B-5B-B27-25A8-B5-B-B3-2B28-25A7B-B-3B4(-B)-3B25-25AB5-2(B4-)B3-2B28-25AB-3B-B-4B3-6B-3B25-25AB-3B3(-B)-2B-B2-B-5B25-25AB-3B3(-B)2-2B-B4-2B-B25-25AB5-3(B-)2B2(-3B)2-B25-25A7B-B3-B-B4-6B25-
