model
size = 3 31 3, scale = 0.05, origin = -y
material 
  colors = A:#111 B:#AAA C:#09F
voxels
82-B-3B-C5-B25(2-A)2-B-4BCB3C-C83-B-3B-C4-
