model
size = 32 32 17, scale = 0.05, origin = -y
material 
  colors = A:#DDD B:#004 C:#111 D:#036 E:#09C F:#100 G:#00A H:#099 I:#09F J:#222 K:#6FF L:#6F6 M:#C00 N:#0A0 O:#F90 P:#6F9 Q:#0FC
voxels
365-2(C4-C26-)15(6C26-)6C247-3D6-3D213-4C2-4C21-2C2AC2BC2A2C18-B-CAB6ABAC-B16-B-CB8ABC-B16-E-CAB6ABAC-E16-E-CB8ABC-E16-E-CAB6ABAC-E11-6E-CAB6ABAC-6E7-5E-CAB6ABAC-5E9-4E-CAB6ABAC-4E11-3E-CAB6ABAC-3E13-2E-CB8ABC-2E15-B-CAB6ABAC-B16-B-CB8ABC-B16-B-CAB6ABAC-B18-CB8ABC18-G-CAB6ABAC-G18-3C6E3C213-F8-F20-5D4-5D50-5D4-5D52-2I6-2I86-C3B2-3BC20-2(2B4A)2B17-EC12ACE9-E6-EC12ACE6-E2(2-2E5-EC12ACE5-2E)2-7EAC12ACA7E3-5E2AC12AC2A5E4-6EAC12ACA6E5-5EAC12ACA5E7-4EAC12ACA4E9-3EAC12ACA3E11-2EAC12ACA2E13-3B12A3B14-3B12A3B16-2B10A2B17-GCB10ABCG17-CB10ABC20-10B181-3F6-3F18-2D3J2D2-2D3J2D48-7D2-7D18-4H4-4H20-H2IH4-H2IH42-P30-PL10-C3B2-3BC10-2LE7-2(2B4A)2B7-E2L2E5-B14AB5-2E2LD2E4-B14AB4-2ED2LED2E3-B14AB3-2EDE2LED5E16A5EDEL-ED26ADE2-ED26ADE3-D26AD4-D26AD5-E24AE7-E22AE9-E20AE11-E3B4AD2AD4A3BE13-3B4AD2AD4A3B16-2B3AD2AD3A2B17-EAB3AD2AD3ABAE17-2B3AD2AD3A2B20-3B-2G-3B210-2D5FD2-D5F2D16-6J2-6J16-8D2-8D16-H5I2-5IH19-H2ID4-D2IH21-2H6-2H54-2CD4-D2C20-2C3A4B3A2C17-B14AB11-E4-B14AB4-E6-2E3-B14AB3-2E6-2ED2B16A2BD2E6-3D20A3D3(6-2ED20AD2E)6-LED20ADEL7-ED20ADE9-D20AD11-E3B2ACAD2ADAC2A3BE13-3B2ACAD2ADAC2A3B16-2BACED2ADECA2B17-GABACED2ADECABAG17-2BACE-2A-ECA2B20-B2EB2GB2EB22-B8-B22-L8-L53-OMO6-OMO19-5F4-5F17-7F2-7F14-2DJ5FD2-D5FJ2D14-JD4F4-4FDJ15-3D2FI-D2-D-I2F3D14-2HI2J2HD2-D2H2JI2H15-4IHD4-DH4I17-2(IH)6-2(HI)19-H2I6-2IH20-DID6-DID21-BAB4CBAB19-BCB3A4C3ABC2(B16-B14A)B14-2B16A2B12-E2B14A2BE12-EB16ABE12-E2B14A2BE12-DB16ABD12-E2B14A2BE12-EB16ABE12-E2B14A2BE12-L3B2ACAD2ADAC2A3BL13-3BAC-CD2ADC-CA3B16-2BE-ED2ADE-E2B17-2EB2(E-)2H2(-E)B2E18-BE-EB2GBE-EB117-M8-M21-3M6-3M18-6F4-6F15-8F2-8F13-D2J5FD2-D5F2JD14-JDF-2F4-2F-FDJ15-3D3F-D2-D-3F3D16-4H2D2-2D4H19-3HD4-D3H21-2(2H6-2H22-)2D6-2D22-2D6-2D19-B2C2AB4CB2A2CB3(16-I14AI)3(17-L12AL17-I14AI)16-HL12ALH15-HI3ACAD2ADAC3AIH14-HI2AC-CD2ADC-C2AIH15-3BE-ED2ADE-E3B18-B2(E-)2G2(-E)B180-OMO6-OMO19-5F4-5F17-7F2-7F14-2DJ5F4D5FJ2D15-JF-F6-F-FJ16-3D2-F-D2-D-F2-3D16-I2FD-D2-D-D2FI19-HIHD4-DHIH21-2I6-2I22-I8-I22-D8-D22-D3-2G3-D16-K2-16C2-K11-K-I14AI-K13-2KC12AC2K15-KC12ACK17-2(N12AN18-C12AC18-)N12AN18-C12AC17-HN12ANH14-H2MC2ACAD2ADAC2AC2MH13-HI2AC-CD2ADC-C2AIH15-3B2(E-)2C2(-E)3B18-2(BE)B2G2(BE)B211-5F4-5F18-5F4-5F15-G2D5F4D5F2DG15-4JC4-C4J17-7D2-7D17-2IDI6-ID2I17-K2-DI6-ID2-K15-K3-2I6-2I3-K13-K18-K12-K18-K11-K9-2G9-K19-4B22-6B4A6B2(16-I14AI)3(17-L12AL17-I14AI)15-2HL12AL2H13-KHI3ACAD2ADAC3AIHK12-2HIBAC-CD2ADC-CABI2H16-B2(E-)2G2(-E)B276-3F6-3F18-7D2-7D49-4D6-4D19-2G8-2G21-G8-G122-2G29-4B27-6B21-5B6A5B16-3B10A3B3(16-C14AC16-B14AB)14-K-3B10A3B-K13-H3B3AD2AD3A3BH15-3BC-CD2ADC-C3B18-B2(E-)2G2(-E)B307-5D4-5D51-G10-G185-2G29-4B27-6B26-6B23-3B6A3B19-2C10A2C2(18-G12AG18-C12AC)18-G12AG15-K2-2B10A2B2-K15-2B3AD2AD3A2B18-2BA2(2C-)2CA2B19-2(BE)B2G2(BE)B307-G2DG6-G2DG279-B2GB27-6B26-B4CB24-10B22-C8AC21-2(B10AB20-C10AC20-)B10AB17-K2-B10AB2-K17-H3AC2AC3AH21-H2B-2G-2BH21-2G7-H2G631-2B2G2B26-B4-B24-10B7(22-C8AC)18-K2-H10CH2-K15-4KH6-H2M2K27-3H633-2G62-2B26-B8DB3(22-2B6C2B22-10B)21-2G8B2G20-GHG6-GHG29-3G633-2G62-2B27-2G4D2G24-G6-G24-2G4B2G24-G6-G24-G6BG24-G6-G24-2G4B2G27-2L35-Q730-2G29-3(4D60-)4D829-3(2G62-)2G271-
