model
size = 31 31 21, scale = 0.05, origin = -y
material 
  colors = A:#60F B:#3C9 C:#0FC D:#400 E:#003
voxels
382-2(AB)2AB23-A3BABA2BA21-5BAB2AB20-A5BAB2A-2B18-2B2(AB)A3B2AB17-2(4B2ABAB3ABA16-A)3B2(AB)A3B2A17-3A5BAB2AB18-8BAB2A20-2BA3B2(AB)23-2(BA)B2A434-2A25-6A22-10A20-12A18-14A17-15A15-18A13-20A2(10-21A)10-20A10-3A-17A10-2A-19A8-23A8-22A2(10-21A)10-20A12-19A13-17A16-14A19-10A214-3A28-3A26-6A23-8A20-12A16-15A16-A-13A15-A-6A2-4A-5A10-2A-2A7-4A-5A9-A-2A9-5A-3A8-2A-2A10-9A7-A-2A11-9A6-2A-2A14-6A6-5A14-6A6-A-3A14-6A5-2A-2A14-7A5-A-2A15-4A-2A5-A-2A15-6A6-4A14-4A-2A7-A-2A13-4A-A8-A2-3A10-4A-A10-A2-3A7-5A2-A10-2A2-13A2-A12-3A-10A3-A15-3A10-2A17-12A26-3A124-5A25-2(7A24-)7A25-5A27-5A15-A10-5A13-3A11-8A8-A-A12-3A3-2A8-A-A13-5A-2A6-A-A16-6A5-A2-A18-2A-A5-A-A20-A-A4-A-2A20-A-A4-A-A21-2A5-A-A20-2A-A3-A2-A20-2A-A3-A-A21-A-A4-A-A21-A-A5-2A20-A-A6-A-A19-A-A6-A2-A17-A-A8-A2-A15-A-A9-A3-A13-A-A11-A3-A10-2A-A13-2A2-10A2-2A15-2A10-2A19-10A96-3A26-6A25-3A-2A26-2A-2A27-A-2A27-6A25-A-4A25-7A7-3A14-5A-A7-2A16-4A-2A5-A-A19-2A2(-A4-A-A21-A)-A3-A-A22-2A4-2A3(23-2A3-A-A)23-2A2(3-2A23-A-A)3-A-A21-A-A4-A-A21-A-A5-A-A19-A-A6-A2-A17-A-A8-A2-A14-2A-A10-2(A2-A12-)A2-A9-2A2-2A13-2A-9A2-2A17-5A4-3A24-2BAB39-2A27-3(5A26-)2A-3A25-6A25-4A-A25-4A-2A25-4A-A6-2A20-A-A5-A-A20-3A5-2A22-2A4-A-A22-2A3-A-A23-2A3-2A24-2A2-A-A24-AC2-2A25-2A2-2A24-A-C2(-A)24-3(A-)A24-A-A2-2(2A23-A-A3-)2A22-A-A4-A-A20-A2-A5-A-A18-A2-A6-A2-A16-A2-A8-A2-A14-A2-A10-A2-A11-2A2-A12-2A-3A3-5A2-2A15-3A-3A4-3A20-3A2B3A38-4A27-2A2(-A28-A)-2A26-3A2(-A28-A)-A28-3A29-A-A28-A-A4-3A22-2A3-A-A23-2A3-2A24-2A2-A-A23-2A2-A-A24-2A2(2-2A25-AC)2-A26-AC2(-2A26-2A)-2A25-A-A2-2A23-A-A3-2A22-A2-A3-A-A21-A-A4-A-A20-A-A6-A-A17-2A2-A7-A-A15-A3-A9-A-2A11-2A2-2A11-A2-2A7-2A3-A14-3A-7A2-3A18-B4ABA3B39-3A28-A-A28-3A28-2A3(-A28-A)-A3(29-2A)4-3A22-2A4-2A23-2A2-3A24-2A2-2A25-2(2A-2A26-)2A-A26-A-3A27-2ABA26-A-3A26-2A-2A25-2(A-)2A25-2A3-2A23-A-A3-2A22-A-A4-A-A20-A2-A5-A-A18-A2-A7-A-A16-A2-A9-A-A13-2A2-A11-A-2A9-2A2-2A13-2A-9A-3A17-3AB2A4BA39-3A29-2A30-3(2A29-)AB2(29-2A)2(29-AB)4-2A23-2A3-A-A23-2A2-A-A24-2A2(-A)25-2(2A-2A26-)AC2A27-ACBA27-ACAE27-2ABD26-A-3A26-2A-BA25-2(A-)2A24-A-A3-2A23-A-A3-A-A21-A-A5-2A20-A-A6-A-A18-A-A8-4A14-2A-2A10-A-2A10-2A2-A13-2A-3A3-4A-3A16-2(A2B)2AB3A39-2A29-2A30-3(2A29-)3(AB29-)2A29-AB4-2A23-2A3-A-A24-A2-A-A24-2A2(-A)25-2(2A-2A26-)4A2(27-AC2A)27-3AD27-2A2(BA26-2A-)BA25-2A3-2A23-A-A3-2A22-A-A5-2A20-A2-A5-A-A18-A2-A7-A-A16-A2-A9-4A12-2A-2A12-5A6-6A16-3A2B3(AB)A39-2A29-A-A29-2A30-A2(2(29-2A)29-AB)4-2A24-B3-A-A24-A2-A-A25-2(A-)A26-A-2A26-2A-A27-AC2A27-2ABA27-ACBA27-3AE27-4A2(26-2A-2A)25-2A3-2A24-2A3-2A23-2A5-2A21-A-A5-A-A19-A-A7-A-A16-2A-A9-4A12-2A-2A12-5A6-6A16-3A4BA3BA39-2A29-2A30-3(2A29-)3(AB29-)2A29-AB4-2A23-2A3-A-A24-A2-A-A24-2A2(-A)25-2(2A-2A26-)4A2(27-AC2A)27-3AD27-2A2(BA26-2A-)BA25-2A3-2A23-A-A3-2A22-A-A5-2A21-A-A5-A-A18-2A-A7-A-A16-A-2A9-4A12-2A-A13-5A6-6A16-3A2B3(AB)A38-3A29-2A30-3(2A29-)AB2(29-2A)2(29-AB)4-2A23-2A3-A-A23-2A2-A-A24-2A2(-A)25-2(2A-2A26-)AC2A27-ACBA27-ACAE27-2ABD26-A-3A26-2A-BA25-2(A-)2A25-2A3-2A23-A-A3-A-A21-A-A5-2A20-A-A6-A-A18-A-A8-4A14-2A-2A10-A-2A10-2A2-A13-2A-3A3-4A-3A16-2(A2B)2AB3A38-3A28-A-A28-3A28-2A3(-A28-A)-A3(29-2A)5-2A22-2A3-3A23-2A2-A-A24-2A2-2A25-2(2A-2A26-)2A-A27-4A27-2ABA26-A-3A26-2A-2A25-2(A-)2A25-2A3-2A23-A-A3-2A22-A-A4-A-A20-A2-A5-A-A18-A2-A7-A-A16-A2-A9-A-A13-2A2-A11-A-2A9-2A2-2A13-2A-9A-3A17-3AB2A4BA37-4A27-2A2(-A28-A)-2A26-3A2(-A28-A)-A28-3A29-A-A29-2A4-3A22-2A3-A-A23-2A3-2A24-2A2-A-A23-2A2-A-A24-2A2(2-2A25-AC)2-A26-AC2(-2A26-2A)-2A25-A-A2-2(2A23-A-A3-)A-A21-A-A4-A-A20-A-A6-A-A17-2A2-A7-A-A15-A3-A9-A-2A11-2A2-2A11-A2-2A7-2A3-A14-3A-7A2-3A18-B4ABA3B37-2A27-2(5A26-)3A-A26-2A-3A25-6A25-4A-A25-4A-2A25-4A-A6-2A20-3A5-A-A20-3A5-2A22-2A4-A-A22-2A3-A-A23-2A3-2A24-2A2-A-A24-AC2-2A25-2A2-2A25-AC2(-A)24-3(A-)A24-A-A2-2(2A23-A-A3-)2A22-A-A4-A-A20-A2-A5-A-A18-A2-A6-A2-A16-A2-A8-A2-A14-A2-A10-A2-A11-2A2-A12-2A-3A3-5A2-2A15-3A-3A4-3A20-3A2B3A66-3A26-6A25-3A-3A25-2A2(-2A27-A)-4A25-A-4A25-7A7-3A14-5A-A7-2A16-4A-2A5-A-A19-2A2(-A4-A-A21-A)-A3-A-A22-2A4-2A3(23-2A3-A-A)23-2A2(3-2A23-A-A)3-A-A21-A-A4-A-A20-A2-A5-A-A19-A-A6-A-A18-A-A8-A-A15-2A-A10-A-2A2(12-A2-A)9-2A2-2A13-2A-9A2-2A17-5A4-3A24-2BAB94-5A25-2(7A24-)7A25-6A26-5A15-A10-5A13-3A11-8A8-A-A12-3A3-2A8-A-A14-4A-2A6-A-A16-4A-A5-A-A19-2A-A5-A-A20-2(A-A4-A-A21-)2A5-A-A20-4A3-A2-A20-2A-A3-A-A21-A-A4-A-A21-A-A5-2A20-A2-A5-A-A19-A-A6-A2-A17-A-A8-A-2A15-A-A9-A2-2A13-A-A11-A3-A10-2A-A13-2A2-10A2-2A15-2A11-A19-11A152-3A28-3A26-6A23-9A19-12A16-15A16-A-13A15-A-6A2-4A-5A10-2A-2A7-10A9-A-2A9-5A-4A7-5A10-6A-2A7-A-2A11-9A6-5A15-5A6-5A14-6A6-A-3A14-6A5-2A-2A14-2(4A-2A5-A-2A15-)6A6-A-2A14-4A-2A7-A-2A13-4A-A8-A2-2A11-4A-A10-A2-3A8-4A2-A10-2A2-13A2-A12-3A-10A3-A15-3A10-2A17-12A25-4A246-2A25-6A22-10A20-12A18-14A17-15A15-18A13-20A2(10-21A)10-20A10-3A-17A10-2A-19A8-23A8-22A9-22A10-21A10-20A12-19A13-17A16-14A19-10A486-2(AB)2AB23-A3BABA2BA21-5BAB2AB20-A5BAB2A-2B18-2B2(AB)A3B2AB17-2(4B2ABAB3ABA16-A)3B2(AB)A3B2A17-3A5BAB2AB18-8BAB2A20-2BA3B2(AB)23-2(BA)B2A232-
