model
size = 25 22 25, scale = 0.05, origin = -y
material 
  colors = A:#FCC B:#EEE C:#3CF D:#F0C E:#DDD F:#F0F
voxels
184-7B541-11B16-7C18-C2(-2C)18-2(C2-)C143-7C17-3C3-3C288-15B12-2C7A2C15-C7A-C16-5(7A18-)7A16-2C7B2C15-CEC3-CEC17-E5-E18-F5-F18-E5-E18-F5-F188-17B10-2(C11AC12-)C11AC13-4(11A14-)11A13-C11BC14-3C3-3C286-19B8-C13AC10-C6(13A12-)13A11-C13BC9-3C11-3C281-21B6-C2(15AC9-)5(15A10-)15A9-C15BC8-CEC11-CEC9-E13-E10-F13-F10-E13-E10-F13-F15-5B162-21B5-2(C17AC6-)C17AC7-4(17A8-)17A7-C17BC7-3C11-3C112-9B159-23B3-C19AC4-C6(19A6-)19A5-C2(5B2D)5BC134-11B17-5B136-23B3-C2(19AC5-)5(19A6-)19A5-C4B4D3B4D4BC3-3C17-3C108-11B16-7B134-25B-2(C21AC2-)C21AC3-4(21A4-)21A3-C4B5D3B5D4BC2-CEC17-CEC3-E19-E4-F19-F4-E19-E4-F19-F8-13B14-9B19-3B111-25B-C21AC2-C6(21A4-)21A3-C3B7DB7D3BC2-3C17-3C107-13B14-9B18-5B110-25B-C2(21AC3-)5(21A4-)21A3-C3B15D3BC132-13B14-9B18-5B22-3(B24-)B12-25B-C10AB2(10AC2-C10AE)10AC3-4(10AE10A4-)10AE10A3-C3B15D3BC132-13B14-9B18-5B110-25B-C21AC2-C6(21A4-)21A3-C3B15D3BC132-13B14-9B19-3B111-25B-C2(21AC3-)5(21A4-)21A3-C4B13D4BC2-3C17-3C108-11B16-7B134-25B-2(C21AC2-)C21AC3-4(21A4-)21A3-C5B11D5BC2-CEC17-CEC3-E19-E4-F19-F4-E19-E4-F19-F9-11B17-5B136-23B3-C19AC4-C6(19A6-)19A5-C5B9D5BC3-3C17-3C109-9B159-23B3-C2(19AC5-)5(19A6-)19A5-C5B9D5BC137-5B162-21B5-2(C17AC6-)C17AC7-4(17A8-)17A7-C5B7D5BC7-3C11-3C281-21B6-C15AC8-C6(15A10-)15A9-C5B5D5BC8-CEC11-CEC9-E13-E10-F13-F10-E13-E10-F13-F183-19B8-C2(13AC11-)5(13A12-)13A11-C5B3D5BC9-3C11-3C283-17B10-2(C11AC12-)C11AC13-4(11A14-)11A13-C5BD5BC14-3C3-3C288-15B12-2C7A2C14-C-7AC17-5(7A18-)7A16-2C7B2C15-CEC3-CEC17-E5-E18-F5-F18-E5-E18-F5-F191-11B16-7C18-2(2C-)C18-2(C2-)C143-7C17-3C3-3C292-7B359-
