model
size = 20 15 20, scale = 0.05, origin = -y
material 
  colors = A:#90C B:#CF6
voxels
27-6A274-6A292-10A288-14A285-16A9-6A14-6A249-4A8-4A7-10A10-10A12-6A14-6A208-4A10-4A5-3A6-3A8-5A2-5A10-8A12-8A13-5A15-5A169-3A12-3A5-A10-A8-3A6-3A9-2A6-2A10-4A2-4A11-7A13-7A14-5A15-5A128-3A14-3A3-2A10-2A6-3A8-3A7-3A6-2A9-3A6-2A10-4A2-3A11-9A12-7A13-7A15-3A17-3A89-3A14-3A3-2A10-2A6-3A8-3A7-2A8-A9-3A6-2A10-3A4-2A11-3A4-2A12-7A13-7A14-5A15-5A17-A19-A50-3A14-3A3-2A10-2A6-3A8-3A7-2A8-A9-2A8-A10-2A6-A11-3A4-2A12-3A2-2A13-B6A14-5A15-5A16-3A17-3A18-A19-A10-3A14-3A3-2A10-2A6-3A8-3A7-2A8-A9-2A8-A10-2A6-A11-3A4-2A12-B2A2-2A13-B6A13-B5A15-5A16-3A17-3A18-A19-A10-3A14-3A3-2A10-2A6-3A8-3A7-2A8-A9-3A6-2A10-3A4-2A11-3A4-2A12-7A13-B6A14-5A15-5A17-A19-A50-3A14-3A3-2A10-2A6-3A8-3A7-3A6-2A9-3A6-2A10-4A2-3A11-9A12-7A13-7A15-3A17-3A90-3A12-3A5-A10-A8-3A6-3A9-2A6-2A10-4A2-4A11-7A13-7A14-5A15-5A129-4A10-4A5-3A6-3A8-5A2-5A10-8A12-8A13-5A15-5A170-4A8-4A7-10A10-10A12-6A14-6A209-16A9-6A14-6A250-14A288-10A285-
