model
size = 32 32 22, scale = 0.05, origin = -y
material 
  colors = A:#555 B:#222 C:#777 D:#111 E:#CC0 F:#E00 G:#F0C H:#09F I:#0C0 J:#AAA K:#30C L:#EEE
voxels
68-F-L-E305-DLD28-5D27-L3DL27-5D28-DLD93-DLD28-5D27-L3DL27-5D28-DLD398-2(16A16-)7(A14DA16-16A16-)A14DA16-16A464-17(16A16-)16A458-22A10-EALAF17A16(10-22A)2(458-17(22A10-)22A)2(10-22A)18-5C371-19(22A10-)22A17-7C26-5C339-19(22A10-)22A16-9C24-7C27-3C243-21(24A8-)24A14-11C22-9C25-5C242-21(24A8-)24A14-11C22-9C24-7C241-21(24A8-)24A14-11C22-9C24-7C114-3C16-3C7-3C22-3C2-2C28-2C36-21(24A8-)24A14-11C22-9C24-7C27-4C25-3C4-3C19-3C10-3C140-21(25A7-)25A13-11C22-9C25-5C209-22(26A6-)26A14-9C24-7C27-3C210-22(26A6-)26A15-7C26-5C241-22(26A6-)26A16-5C273-22(26A6-)26A294-22(27A5-)27A3(292-22(28A4-)28A)292-28B4-23BD2BDB4-28B4-23B4DB4-28B2(4-B3J3E3H3I3G3F3KB4DB4-B3J3E3H3I3G3F3K6B)13(4-B3J3E3H3I3G3F3K6B)4-28B290-
