model
size = 22 32 30, scale = 0.05, origin = -y
material 
  colors = A:#C96 B:#630 C:#C8A175 D:#111 E:#444 F:#777 G:#555 H:#960 I:#FF0 J:#BBB K:#200 L:#222 M:#888 N:#400 O:#330 P:#FFF Q:#700 R:#050 S:#E00 T:#0C0 U:#D00 V:#C63
voxels
252-2(CE20-)AE522-4I2A4I11-2(I2CI2A)10-B2I2-2B3-2B10-I2-3(I2B)10-B4I-B2(I-)B10-B-I-B3-I3B12-4B-3B14-2B-B-3B-B10-B-2B2-4B-B10-5B-2B-3B11-B-B5-3B11-B-9B10-2B2-6B12-2B-B3-B-3B10-3B2-2B-4B10-2B-5B2-2B12-2B-7B10-3(B2-)B-B10-10B-B11-2B-B-3B2-B10-6B-5B11-2B2-2B-B-2B13-7B15-B-2B-B149-2ACA15-AI2A2CAI2A11-12A9-14A8-B3AIB2A3I2AB8-BA2B9AB8-B5AB2A2(IA)B8-3(BA)3B3A2B9-2B2ABAB3AB-B9-2BAB-2B2AB-B9-BAB2A2B4ABAB8-B5AB2AB3AB8-2BABA5B3AB9-BAB9AB9-BA2B6A3B9-2(BA)3BAB3AB9-B2A2B2AB4AB8-B2AB5A2B2AB8-3B2A2B6AB8-BA2BAB-3B2(AB)8-B-2(4AB)AB9-B2ABAB3A2BAB8-B6AB5AB9-B2A2B2ABAB2AB10-8BA3B11-B-6B16-2B2-B18-B87-AC17-10A10-12A8-15A7-C15A7-3(14AB6-B)14AB6-2B11A2B7-2B4AB5ABAB7-B14AB6-B14AB7-B13AB7-2B12AB7-B12AB8-B13AB6-2B13AB6-B14AB6-B13AB7-B6AB7AB6-B14AB6-2B13AB6-B13AB7-2B13AB8-9B3AB11-10B12-2B-3B2-B14-B2-B18-B65-4A3CA11-11AC9-13AC7-15A7-16A5-17A5-3(B16AB4-)2(B15AB5-)2(B16AB4-)2(2B15AB4-)2B14A2B4-2B2(15A2(B4-B16A)B4-B15A2B5-B)15AB6-10B4A2B7-14B8-B-9B14-3B2(-B)17-B3-B39-2A16-2C9A9-12AC8-C13A2(C7-15A)2(5-17A)B4-18A3-B18AB2-B17A2B3-B16A2B2-B18AB2-B17AB3-B18AB3-B16AB3-B18AB3-B17AB2-BAB16AB2-B18AB2-B17AB3-2B17AB2-B18AB3-B17AB3-B16AB4-B16AB5-11B5AB6-16B8-4B4A4B10-2B-5B-B13-B3-2B39-6A13-C10AC9-13AC7-15A7-2(16A6-)16A5-17A5-18A3-B19A3-B17AB2-B17AB3-B18AB3-B17A2(B2-B18A)B2-B17AB3-B18AB2-BAB15AB3-B18AB3-B17AB2-B18AB2-B17AB3-B17AB4-B17AB3-B16AB4-12B5AB6-16B7-2B9A3B10-9B14-B-B2-B37-C8A11-12AC7-C14A7-3(16A6-)15AC6-16A5-C17A3-B19A2(2-B18AB)3-B17AB2-B17AB3-B18AB2-B17AB4-B16AB3-B17AB4-2B16A5(B2-B18A)B2-B17AB4-B17AB3-12B5AB5-17B7-B11A2B9-11B11-B-2B-B3-B34-C10A9-C12AC7-15A7-2(C15A6-)16A6-C14AC6-16A5-18A3-B19A2-BAB16AB2-B18AB2-B17AB3-B18AB3-B17A2(B2-B18A)B2-B17AB3-BAB16AB2-BAB15AB4-B17AB2-B17AB4-B17A3(B2-B18A)B3-12B5AB5-17B6-2B2(3AB)4AB9-2BAB3A5B12-6B-B15-3H16-12A8-14A7-16A2(6-C15A)6-16A6-C14AC6-16A5-C17A3-B19A3-2B16AB2-B18AB3-B17AB2-B18AB3-B16AB3-B18AB2-B18AB3-B17A2(B2-BAB16A)B3-B17A3(B2-B18A)B3-B16AB3-B18AB2-12B7AB3-18B5-2B2A2B-BAB-B3AB8-4B-3B-2BCB11-2B3(-B)-2B12-5H14-13A8-15A2(6-16A)6-C14AC6-16A6-15AC6-16A5-C17A3-B19A3-2B16A6(B2-B18A)B2-B17AB3-BAB15AB3-BAB16A2(B2-B17AB3-B18A)B2-B18AB2-B17AB3-12B7AB3-5B-12B5-2(2BAB-)BAB2AB7-3B-4B-BA4B9-B2-B3-3B13-6H14-2AH8A-A7-16A2(6-15AC)6-C15A6-16A6-15AC6-16A5-18A3-20A2-2AB16AC2-19AC3(2-20A)2-19AB2-18AB3-19AB2-BAB15AB3-BA2(B16AB3-)B18AB3-B17AB2-B18AB2-B17AB4-B17AB2-11B3AB4AB4-12B-4B5-3B-2B-2(BA)B-BAB8-B-B2-3BAB-3B11-B3-2B2-B-B10-7H13-2AH10A7-C15A6-15AC6-16A2(6-C15A)6-C14AC6-16A5-18A3-20A2(2-19AC)2-C19A-43AC21AC44AC43A-2(B18AB2-)B17AB4-B17A2(B2-B18A)B3-9B9AB3-18B5-2BAB2AB-BAB-B2AB7-3BCAB-3B-4B10-2(2B-)B-B13-7H13-2AH10A7-C15A6-15AC3(6-16A)7-14AC6-16A5-18A3-2(19AC2-)C19A2-C42A-B18AB2-BA-16AB2-CA-17A2-20A2-C19A-44A2-B17AB3-B17A2(B2-B18A)B2-B17AB3-9B9AB4-18B5-2B4A2B2(AB)3AB8-BA2B-3(BA)3B9-B3-6B-B12-5H14-13A7-16A6-15AC6-16A7-15A7-14A8-15A6-15AC6-17A3-19AC2-C18AC2-C2J17ACA7-14A-B3A7-8AB2-B7A7-4AB-2A3-9A7-A24-B16AB3-C19A-C20AC22A-B11A6DAB2-B18AB2-B17AB4-B17AB2-B18AB2-8B2(5AB)3-12B-3BAB5-BAB3A3(B-)B2AB7-B-BA2B2(-B)-3B11-5(B-)B13-3H15-13A8-2(15A7-)C14A8-C12A9-13A8-15A6-16A6-17A3-19AC2-C18AC-21AC22A-B18AB2-B18AB-13A3-AV4A2-2B10A3-5A2-B16AB3-20A-C42AC-B11A6DAB3-B17AB2-B17AB3-B18AB2-B17AB3-6B13AB3-16BAB6-2B3A2B2(AB)3A2B6-B-3B-2(BA)4B10-2(B-)5B16-A17-5A-7A10-12A9-2(C11A10-)C11A9-14A7-16A7-15A5-18A3-20A2-19AC-2(21AC)-B18AB2-C18AB-C42A2(2-20A)-C20AC21AC-B11A6DAB2-B17AB3-B17AB4-B17AB2-B18AB2-2B16AB5-14B2AB7-B11A2B9-BA2BNB2A3B12-B2(-2B)58-12A9-11A11-12A9-14A7-15AC2(6-16A)5-18A3-20A2-19AC2-C18AC-43A2C43A-17AF2E2-19AE-22AC43A-B11A6DA2(B2-B18A)B2-B17AB3-B17AB4-2B16AB5-13B2AB6-BAB4A3B2A3B7-2B-BA7B11-B-2B5-2B76-14A8-14A7-16A6-15AC2(6-16A)5-18A3-2(20A2-)C19A3(2-20A)2-17A3F2-16AL5-18A2E2-19AM2(2-20A)2-12A6DA2(B2-B18A)B2-B17AB3-B18AB4-4A3B10AB4-14BA2B5-3BABA9B-B5-B-2B2(-B)N2B14-B-B2-3B57-5A3-5A8-14A7-2(16A6-)C14AC6-C15A6-16A5-18A3-2(20A2-)19AC2-20A2(2-C19A)2-C17AEF2-C16AE4-17AF4-18AL3-C18AM2-20A2-6A5BA6D2A2-B3A9B6AB2-B2A11B5AB2-BA13B4AB4-A12B4AB5-13B2AB6-15B8-11B-2B9-2(2B2-)2B20-2B54-6A-7A7-15A7-16A6-15AC6-16A7-14AC6-15AC5-18A3-2(20A2-)2(C19A2-)20A2-19AM2-18AE3-C13AG2AF4-C15AGF4-C16AL4-C17ADM2-20A2-12A6D2A2(2-20A)2-19AB4-16A2B6-7B7A8-12B10-9B-2B12-2(2B2-)B55-5A-7A7-15A7-16A6-15AC7-14AC6-16A6-15AC6-16A5-17A5-A-16A3-20A2-18AMA2-17AM-M2-19AM2-18AE3-14AG2AF4-11AKMAG2AG4-11AM2A2LEG5-8A-AGE4AL5-C9AJL4AD5-C16AFM2-12A6D2A2-20A3-19A4-2C16A6-14A9-6B6A10-10B13-B-7B15-7B16-2B-B35-5A-7A9-13AC6-16A6-15AC6-16A7-15A2(6-16A)5-17A5-16A6-14AKG5-2A-11A2K2GE3-14A2GKG5-13A5G4-10AFK5GK4-10AK6GK3-10AG-F4GE4-4A2C4AK-GE3-G5-2(2AC)2A-G2-L2ALE5-AC4AC2AJE-U3AL5-2(2AC)3APJAL2ALG5-11A6D2E2(4-18A)6-14A9-12A12-7BA14-B-B2-3B14-B-B2-B-B14-B-2B-B18-B38-5A-7A9-13A7-14AC7-C14A2(C6-15A)C8-2(14A7-)6AF2AF4A7-A3-10AG7-C3-9AF8-3A2-7AF2-KE5-2A3-7AF3-E8-C2-4A3F-K2-K6-7AF3-2FG7-8AF2-F3G6-9AF2-G4E5-2A4-2AJG-G4-G8-RO2-A-K3-NQ9-OTRO-A-G2-NQSN9-2O2-D2PDE-2N9-5D4A6DEM4-DG14AD7-AC12A9-12A12-A4B3A15-2(4B18-)2(B-2B18-)B2-B17-5C15-11A10-5AF7A8-13A8-3AE12A6-C15A6-16A6-15A10-10A11-A3-C2-F14-C4DCL4DG10-C9AF13-7AF15-6AF15-5AF14-A2-3AF13-2A-A-2AF13-A4-2ACF12-A6-A3(CF20-)CF19-A2JD13-D9AC3AD10-5A3C2A14-A2B3A17-2B20-2B105-7C14-4AF5A10-6AFE5A9-2AE2A4E5A8-2A-8AE2A7-4A8E3A7-5A6E4A8-13A11-10A33-C4DLE4DG10-C10AG11-9AF13-7AF15-5AF17-3AF19-2(CF20-)3(AF20-)D21-A20-A195-7A15-3A2F3A14-8A12-4A4-4A9-CA-3A2C3A-AC8-C2A8-2AC10-A3C2A3CA13-8A56-C4DCE4DG10-CJ9AF11-8A2F13-6AF16-4AF19-C2F19-2(AF20-)AE20-AE281-3A2E3A15-6A190-3A2CE4G12-4ACE4J12-4ACE2F2J15-ACEF19-A2F19-C2(E20-A)E545-4C4E14-3ACE3J17-CE2F18-CEF19-AE20-AE590-3C3E17-ACEF19-CE20-AE406-
