model
size = 25 15 32, scale = 0.05, origin = -y
material 
  colors = A:#100 B:#FFC C:#F99 D:#FF6 E:#FF3 F:#FC3 G:#F06 H:#CF6 I:#F6C J:#FC6 K:#FCF L:#CC0 M:#CC6 N:#F60 O:#FF0 P:#FFF Q:#F9C R:#CFC S:#FCC T:#CF9 U:#CC3 V:#F36 W:#FC9 X:#FC0 Y:#F69 Z:#F0C Aa:#CF3 Ab:#F63 Ac:#CCC Ad:#F96 Ae:#FF9 Af:#F9F Ag:#F39 Ah:#F6F Ai:#F90 Aj:#CC9 Ak:#CCF Al:#F0F Am:#F03 An:#F33 Ao:#F00 Ap:#F3F Aq:#F3C Ar:#F30 As:#CFF At:#F09 Au:#F66 Av:#F93 Aw:#CF0 Ax:#444
voxels
34-AdRTZXAgE343-2HJEAnND18-2AGKJ2A18-2AAbAG2A19-AHAkAbA21-3A268-IEDLAbGTGDAnT4(14-11A)15-9A17-7A214-AaHSGD5-HTEWZ2(10-5A5-5A)10-15A11-13A12-13A13-11A15-9A18-5A163-AjBAg2N9-JAeAdAvAs6-Aw4A9-4AX6-S4A9-4AAm6-U5A7-5AAe6-O6A5-6AB6-Aa-15A-U6-E-15A-Ah9-13A13-11A16-7A137-IAuAg13-AwAtN3(6-4A11-4A)6-5A9-2(5A7-)5A8-G7A-7AAv8-Aa15AAw8-M-13A-Ah11-11A16-7A111-YSAjAw13-AbAgDV3(4-4A13-4A)5-4A11-4A6-5A9-5A6-2(6A7-)17A9-Am13AAf10-Ae13AAt10-B-11A-I15-5A87-AjNY15-AaAkAp2(4-3A15-3A)2(4-4A13-4A)4-5A11-5A5-5A9-5A6-7A5-7A7-17A9-15A11-C11AE12-L-9A-Aq82-OIGC15-AcGZAe3(2-4A15-4A)2-5A13-5A3-4A13-4A4-5A11-5A5-6A7-6A6-19A7-17A9-15A12-K9AAs14-Ai-7A-X58-L2S17-IAqAf2(2-3A17-3A)2(2-4A15-4A)2-5A13-5A3-5A11-5A4-6A9-6A2(5-7A)7-17A9-15A11-13A14-As7AW58-NCNR17-JAqMAb4A17-8A17-4A-2(4A15-4A2-)5A13-5A2-6A11-6A3-6A9-6A2(5-7A)6-19A7-17A10-13A13-2AJ5AQ2A18-3A36-BMGA17-2AWF4A17-8A17-9A15-5A-4A15-4A2(2-5A13-5A)3-6A9-6A4-2(8A5-)19A7-17A9-15A12-11A17-C3AAn35-KOSA17-2AAkAr4A17-8A17-9A15-10A15-5A-5A13-5A2-6A11-6A3-6A9-6A4-2(8A5-)19A7-17A9-15A12-11A16-2AArAO2A34-AmFRA17-2AAjAr4A17-8A17-9A15-10A15-5A-5A13-5A2-6A11-6A3-6A9-6A4-2(8A5-)19A7-17A9-15A12-11A16-3AAl3A21-Ax12-AgAiAn2A15-3AYO5A2(15-10A)15-11A13-6A-5A13-5A2-6A11-6A3-7A7-7A4-21A5-19A7-17A9-15A12-11A16-2AQAAc2A34-ZQAt2A15-3AML5A15-10A15-11A13-6A-5A13-5A2-6A11-6A2-7A9-7A3-8A5-8A4-21A5-19A7-17A9-15A12-11A17-Ak3AN35-TBD3A13-4AIC6A13-12A13-6A-5A13-5A2-6A11-6A2-7A9-7A2-8A7-8A3-21A5-19A6-19A7-17A10-13A13-2AQ5AK2A18-3A37-EN3A13-4AAh3(2-6A11-6A)2-7A9-7A2-8A7-8A3-10A-10A4-21A5-19A7-17A9-15A11-13A14-F7AU59-2B5A9-6AL2(2-7A9-7A)2-8A7-8A2-9A5-9A3-21A4-21A5-19A6-19A7-17A9-15A12-Al9AS14-Ah-7A-F58-FK7A5-8AAo3-2(8A5-8A4-)2(21A4-)21A5-19A6-19A7-17A9-15A11-W11AB12-Ag-9A-Ap82-AdAm20AR3-2(21A4-)21A5-2(19A6-)19A7-17A9-U13AAe10-Af13AB10-V-11A-U15-5A86-EAgMAlWPZYLAfVAOWCAoAsRPNAbKAa4-3(19A6-)19A7-17A8-C15AH8-X15AQ8-Ao-13A-I11-11A16-7A110-GZAcQVAdJMCLAp2ICMOJHRDAuAjK4-J17AN6-C17AT6-L17AAc6-X17AP6-B-15A-V6-P-15A-Ab9-13A13-11A16-7A135-STFPYXAfIMAmZAhRAiOIAnDBAkAiZM6-2(15A10-)15A11-13A12-13A13-11A15-9A18-5A161-OMZAnCJWAhOAuAqLHApFRTDAuGAbAaP8-3(11A14-)11A15-9A17-7A211-AcJQ2HCLFYAqAoDAcAiHYHAjIXQ38-FJP21-T24-Y24-E25-FAeU213-FAfKLKAiAoAiAjERDGQDAhUYJOD355-WPAcDApRQIAfAaHAlBDWBCAkAr356-CUOArAcAaBSQKU2EHAeVSAmAl357-ICLGKENTMBAvBUKAdWF359-RAsAlMBGVPVAvFBPXV362-EPFSXAaAdAtAdVAd357-
