model
size = 18 32 18, scale = 0.05, origin = -y
material 
  colors = A:#9CF B:#CF0 C:#EEE D:#3FF E:#093 F:#E00 G:#D00 H:#00F I:#096 J:#00E K:#080 L:#36F M:#00D N:#FF9 O:#06C P:#CF3 Q:#555 R:#00A S:#AAA
voxels
402-7A550-8A354-3B15-4E14-4E13-5F13-6F2(12-6E)2(11-7D)11-2(8D10-)8D8-11A8-A35-10A138-2B15-4B13-6B12-7B10-6(9B9-)2ED-D3E9-4E2-4E8-2F2D-ED3F8-2FD3-2D2F2(8-2ED4-D2E)8-3D4-2(3D8-2D5-)3D2(7-3D6-2D)2(6-4A)5-12A7-2A6-2A8-3A4-3A8-10A117-8B9-3B3-3B9-3(3B4-3B8-)3(2B5-3B8-)2B5-3B7-3B5-3B7-3E6-2E7-2(3E6-)2(2F7-3F6-)2(2E8-2E6-)2(2D8-2D6-)2D8-2D5-3D8-2D5-2D9-2D4-3A9-3A4-5A2MHMO4A5-2(AC8-2A6-)12A7-9A99-5BP4B7-3B6-2(2B7-)3(3B6-2B7-)3B2(6-2B6-4B)2(6-2B7-3B)6-E8-3E5-2E9-2E5-2F9-2F5-2F10-F2(5-2E10-E)5-4(2D10-2D4-)D11-2D3-2A11-3A2-A5C2H3MO4A3-AC10-2A4-AC10-3A3-13A6-10A8-12A7-10A61-3B3KGK4B6-2B8-3(2B6-B9-)5(2B5-2B9-)3B4-2E9-A2E4-2E10-2E2(4-F11-AF)2(4-E11-2E)2(4-D12-D)4-2D11-2(D4-D12-)D2-3A12-3A-A2C2JC3MQ2M4A2-2A12-A2-3A11-3A2-15A3-15A4-13A6-11A8-9C44-3B3KGK4B2(5-2B10-B)5-3(2B10-2B4-)4(B11-2B4-)E11-2E4-E12-E2(4-F12-F)2(4-E12-E)4-2D11-4(D4-D12-)D2-2A13-3A-A2(CJ)C2MAH2MO3A19-3A12-2A2-2A4C9A3-2A4C9A4-A4C8A6-A3C7A8-C7AC43-4B3KGK4B5-2B10-B5-3(B11-2B4-)5(B12-B4-)2(E12-E4-)2(F12-F4-)2(E12-E4-)4(D12-D4-)D12-D2-2A14-2A-6A2(HM)A2JMRA19-2A13-2A2-6A2H7A3-15A4-13A6-2A6H3A8-C6HAC43-4B3KGK4B5-2(B11-2B4-)7(B12-B4-)2(E12-E4-)2(F12-F4-)2(E12-E4-)4(D12-D4-)D12-D2-2A14-CA-A2J2(2C4J)A5-J13-2A-HC10-2A2-A5CHC3H2C2A3-A12C2A4-3A2L-3J4A6-2A6-3A8-C6-AC43-4B3KGK4B5-3(B11-2B4-)6(B12-B4-)2(E12-E4-)2(F12-F4-)2(E12-E4-)4(D12-D4-)D12-D2-2A14-CA-A2J4CJ2C5JA5-JC12-2A-HCH9-2A2-A9C2HC2A3-A12C2A4-3AL-4L4A6-2A6-3A8-C6-AC43-4B4GK4B2(5-2B10-B)5-2B10-4(2B4-B11-)2B2(4-B12-B)2(4-E12-E)2(4-F12-F)2(4-E12-E)4(4-D12-D)4-D11-SD2-2A14-CA-A2J6CJCJ3CA5-JC2H10-2AHC-2CH7-2A2-A2C-6C3H2A3-A2C-C-7C2A4-3AG5L4A6-2AN5-3A8-CN5-AC10-N17-N15-3B5K4B6-B9-2B6-B5(10-B5-2B)2(10-2B4-2B)10-2B2(4-E11-2E)4-F11-AF4-F12-F2(4-E12-E)4(4-D12-D)4-D11-AD2-2A13-2CA-A9CJ4CA2-4A2(CH)6-A2-5A2-CH6-2A2-4A-4C3HCHA3-3A3-7C2A4-3A6L4A6-2A6-3A8-C6-AC44-11B7-6(2B8-2B6-)B9-2B6-B9-2B5-2B9-2B2(5-2E10-E)5-2(2F10-AF4-)2(2E10-2E4-)2D10-3(AD4-D11-)AD4-D12-D3-AC12-CA2-A13C2A3-A-AC-H6-CA4-3AC2-2CH2(3-3A)C-7C2A5-2A9C2A5-12A6-11A8-9C45-10B2(8-2B5-3B)3(8-2B6-2B)2(7-3B6-2B)7-GB7-2G7-GB7-2A2(G6-GD8-A)2(G6-FD8-A)G6-GD8-AG6-ED8-2(AG5-2D9-)A2(G5-2D10-)AD4-2D10-AD3-2AC10-2CA2-A4C5J4CA4-2A-C5-C-CA5-3ACHC2H2C-CA6-2A2C-6CA2(7-11A)7-10A63-2(7B11-)3(8B10-)3B-4B10-3B2-3B9-4B2-3B9-3G3-3G9-3B4-3B8-BIA4-AIB8-B2A4-2(AIB8-BA5-)2AB8-BA6-AB7-G2(BA6-AB7-F)BA6-ABG6-FB7-2BG6-FA7-3G6-DA8-AD4-2A2C8-3CA3-4A4J6A5-2AC6-3A6-2A2C4H-2A8-A7C2A9-8A157-2B15-3B15-4B14-4B13-5B13-6G12-6B12-G5I11-2IG4I11-3IG3I11-4IG3I10-5IG2I10-6IGI10-7GI9-B8I9-9B9-10G8-10D6-5A4-5A5-4AJ2AJ3A8-2A5-2A10-AH6A10-8A495-9A10-8A28-8A131-
