model
size = 16 14 31, scale = 0.05, origin = -y
material 
  colors = A:#EEE B:#F90 C:#E00 D:#F96 E:#555 F:#AAA G:#F9C H:#F9F
voxels
4-8B8-2C4B2C10-A2BD11-3AD2A10-2AD3A11-2ADA13-DA122-10B6-3C4A3C7-4(8A8-)8A9-A-2A-A2(10-6A)12-2A57-12B4-4C4A4C5-4(10A6-)10A10-2A-2A7-10A7-8A9-6A12-2A30-2A8-14B2-5C4A5C3-4(12A4-)12A5-10A5-12A4-12A5-10A7-8A9-6A12-2A7-16B-5C4B5C5(2-5A4-5A)3-7(4A4-)4A5-3A4-3A7-2A4-2A20-16B3C2A6B2A3C-2C2A6-2A2C4(2-5A4-5A)5-2A4-3A5-4(4A4-)3A6-3A4-2A8-2A5-A8-A19-8B2G6B3C2A6B2A3C-2C2A6-2A2C4(2-5A4-5A)3-4(4A4-)E3A4-3AE4-E2A6-2AE2(4-A10-A)18-8B2GH5B3C2A6B2A3C-2C2A6-2A2C4(2-5A4-5A)3-4(4A4-)E3A4-3AE4-E2A6-2AE2(4-A10-A)18-9B2H5B3C2A6B2A3C-2C2A6-2A2C4(2-5A4-5A)5-2A4-3A5-4(4A4-)3A6-3A4-2A8-2A5-A8-A19-16B-2C3A4B3A2C2-2C2A6-2A2C4(2-5A4-5A)3-5(4A4-)4A5-3A4-3A6-A8-A36-14B2-2C10A2C3-C2A6-2AC8(4-4A)5-3A4-3A7-2A4-2A25-2(6A10-)6A40-B8AB5-C2A6-2AC4(4-4A)5-3A4-3A6-3A4-3A7-2(2A4-2A8-)F6AF9-6A10-6A56-B5AD2AB6-BA6-AB5-3A6-3A5-3(2A6-)2A7-2A4-2A9-A4-A9-8A8-C6AC9-C4-C72-B2ADAD3AB6-BA6-AB5-3A6-3A5-2A6-2A7-2A4-2A9-A4-A9-2A4-2A8-8A9-6A11-4A12-4C57-B2(AD)4AB6-BA6-AB5-3A6-3A5-2A6-2A7-2A4-2A9-A4-A9-2A4-2A8-A-4A-A10-4A89-B8AB5-C3A4-3AC2(4-4A)5-3A4-3A6-3A4-3A7-2A4-2A9-A4-A9-F-4A-F9-C4AC70-5B-2A-5B3-C10AC4-C3A4-3AC4(4-4A)5-3A4-3A6-3A4-3A7-2A4-2A9-6A10-C4AC11-4C55-6B2A6B2-2C10A2C3-C10AC3(4-12A)5-10A7-F6AF10-4A87-6B2A6B2(2-2C10A2C)2-14A3-12A4-12A6-8A8-C6AC9-C4AC11-4C71-6B2A6B2(2-2C10A2C)2(2-14A)4-10A7-8A9-6A11-4A87-6B2A6B2(2-2C10A2C)2-14A3-12A5-10A7-8A8-F6AF10-4C87-6B2A6B2(2-2C10A2C)3-12A4-12A5-10A7-8A8-C6AC9-C4-C86-6B2A6B2-2C10A2C3-C10AC2(4-12A)5-10A7-8A10-4A103-6B2A6B3-2(C10AC4-)12A5-10A7-8A9-6A119-5B2A5B4-12C4-12A5-10A7-8A9-6A11-4A120-5B2A5B4-12C5-10A7-8A9-6A11-4A136-5B2A5B5-10C7-8A9-6A11-4A13-2A138-4B2A4B7-8C9-6A11-4A13-2A155-3B2A3B9-6C11-4A13-2A172-2B2A2B11-4C13-2A189-4B13-2C199-
