model
size = 16 14 16, scale = 0.05, origin = -y
material 
  colors = A:#111
voxels
86-4A11-2(6A10-)6A11-4A140-4A11-2(6A10-)6A11-4A123-6A9-8A7-4(10A6-)10A7-8A9-6A74-6A9-8A7-10A5-4(12A4-)12A5-10A7-8A9-6A42-6A9-8A7-10A5-12A3-4(14A2-)14A3-12A5-10A7-8A9-6A25-8A7-10A5-12A3-6(14A2-)14A3-12A5-10A7-8A23-10A5-12A3-2(14A2-)14A-48A-2(14A2-)14A3-12A5-10A9-4A9-4(10A5-12A3-14A2-14A-80A-14A2-14A3-12A5-10A8-6A8-)10A5-12A3-2(14A2-)14A-48A-2(14A2-)14A3-12A5-10A9-4A10-8A7-10A5-12A3-6(14A2-)14A3-12A5-10A7-8A25-6A9-8A7-10A5-12A3-4(14A2-)14A3-12A5-10A7-8A9-6A42-6A9-8A7-10A5-4(12A4-)12A5-10A7-8A9-6A74-6A9-8A7-4(10A6-)10A7-8A9-6A53-
