model
size = 28 14 29, scale = 0.05, origin = -y
material 
  colors = A:#222 B:#C93 C:#DDD D:#EEE E:#FFF F:#C96
voxels
3-4(6B10-6B6-)3(6A10-6A6-)6A10-6A173-8B8-8B4-8B8-8B3-2(9B8-9B2-)9A8-9A2-9A8-9A3-7A10-7A2(4-8A8-8A)5-6A10-6A116-4(10B6-10B2-)2(10A6-10A2-)9A8-9A2(2-2A6CA8-A6C2A)3-A6CA8-A6CA114-12B3(4-24B)3(4-12B12A4-24A4-12A-10A6-10A2(2-2AC4-C2A6-2AC4-C2A)3-AC4-CA8-AC4-CA114-12B4-24B4-12BE10BE4-E10BE12B)4-12B12A4-24A4-12A-10A6-10A2(2-2A6C2A6-2A6C2A)3-A6CA8-A6CA114-12B4-24B4-12BE10BE4-E10BE12B4-12B12A4-24A4-12A-2(10A6-10A2-)10A6-10A3-8A8-8A5-2(6A10-6A6-)6A10-6A7-4A12-4A4-12B3(4-24B)4-12B12A4-24A4-12A-2(10A6-10A2-)10A6-10A3-8A8-8A5-6A10-6A6-6A10-6A7-4A12-4A33-3(10B6-10B2-)3(10A6-10A2-)10A6-10A3-9A6-9A4-9A6-9A5-6A10-6A116-3(10B6-10B2-)3(10A6-10A2-)10A6-10A3-7A10-7A5-5A12-5A6-5A12-5A116-3(9B8-9B2-)3(9A8-9A2-)9A8-9A3-7A10-7A5-D3AD12-D3AD6-E3DE12-E3DE116-3(9B8-9B2-)3(9A8-9A2-)9A8-9A3-7A10-7A5-5A12-5A6-5A12-5A116-3(9B8-9B2-)3(9A8-9A2-)9A8-9A3-7A10-7A5-5D12-5D144-3(9B8-9B2-)3(9A8-9A2-)9A8-9A3-7A10-7A5-5A12-5A144-3(9B8-9B2-)3(9A8-9A2-)9A8-9A3-7A10-7A5-4DE12-5D143-11B2(6-22B)6-11B11A6-22A6-11A-10A6-10A2-9A8-9A3-7A10-7A170-11B2(6-22B)6-11B11A6-22A6-11A-10A6-10A2-9A8-9A3-2A3DEA10-A4D2A170-12B4-24B4-12BA11B4-11B13A4-24A4-12A-10A6-10A2-9A8-9A3-7A10-7A170-12B4-24B4-12BA11B4-11B13A4-24A4-12A-10A6-10A2-9A8-9A4-2A2DA12-A2D2A171-12B4-24B4-12BA10BA4-A10B13A4-24A4-12A-10A6-10A3-7A10-7A6-4A12-4A172-12B4-24B4-12B12A2(4-24A)4-12A-10A6-10A3-7A10-7A6-4A12-4A173-11B4-4B2F5B2-11B4-11B3(2-11A4-11A)3-9A6-9A5-6A10-6A7-4A12-4A173-11B4-4B2F5B2-11B4-11B3(2-11A4-11A)3-9A6-9A5-6A10-6A201-9B6-3B2F4B4-9B6-9B3(4-9A6-9A)4-8A8-8A228-8B8-2B2F4B4-8B8-8B3(4-8A8-8A)5-6A10-6A230-7B8-2B2F3B6-7B8-7B3(6-7A8-7A)7-5A10-5A232-5B10-B2F2B8-5B10-5B3(8-5A10-5A)9-3A12-3A234-2(3B12-3B10-)2(3A12-3A10-)3A12-3A257-
