model
size = 32, scale = 0.05, origin = -y
material 
  colors = A:#C0C B:#F0C C:#EEE D:#111 E:#F6F F:#E00
voxels
32-E1978-2BF32-2F985-2BADB1017-2B2ADAB1015-2B3ADAB1014-2B4AD2AB1012-2B5AD2AB949-C31-C30-B7D3AB917-C94-B5A2D2AB886-C126-B4ADAD2AB854-C158-B3AD2ADAB823-C190-B2AD3ADAB791-C222-BAD4ADB760-3(C32-)C28-C3-C27-C4-C26-C5-C25-C5-C24-BD5ADB727-E5(31-C)127-8B695-E990-E958-E32-E957-E990-E991-2(E990-)E958-E31-E958-2(E990-)E991-E990-E957-E32-E958-2(E990-)
