model
size = 20 17 20, scale = 0.05, origin = -y
material 
  colors = A:#700 B:#D00
voxels
26-7B313-8B331-10B329-12B327-14B10-14(6A14-)6A29-5B6-5B7-10(2A6-2A10-)4(10A10-)10A12-6A8-4B10-4B5-10(A10-A8-)4(12A8-)12A9-10A5-5B10-5B4-10(A10-A8-)4(12A8-)12A9-10A5-6(4B12-4B3-10(A12-A6-)4(14A6-)14A7-12A4-)5B10-5B4-10(A10-A8-)4(12A8-)12A9-10A6-4B10-4B5-10(A10-A8-)4(12A8-)12A9-10A7-5B6-5B7-10(2A6-2A10-)4(10A10-)10A12-6A10-14B10-14(6A14-)6A31-12B329-10B325-
