model
size = 16 4 26, scale = 0.05, origin = -y
material 
  colors = A:#111 B:#444 C:#222
voxels
23-2C60-6A10-6A12-2B26-3(2A6-)2A8-6A23-A10-A4-A10-A5-2A6B2A20-A12-A2-A12-A3-2AB6AB2A19-A12-A2-A12-A3-AB8ABA18-5(A14-2A14-A-AB10ABA17-)A14-2A14-A-AB10ABA18-A12-A2-A12-A3-AB8ABA19-A12-A2-A12-A3-2AB6AB2A20-A10-A4-A10-A5-2A6B2A22-3(2A6-)2A8-6A26-6A10-6A12-2B30-2B14-2B2(30-2(2C14-)2C)30-5(2C14-2C46-)2C14-2C39-
