model
size = 32 32 19, scale = 0.05, origin = -y
material 
  colors = A:#00E B:#008 C:#444 D:#FF0 E:#400 F:#6F3 G:#E00
voxels
194-6(2AC2A18-2AC2A4-)2AC2A18-2AC2A741-AC2A18-2ACA5-2AC2A18-2AC2A3-5(A4BA18-A4BA2-)A4BA18-A4BA3-A3BA18-A3BA5-AC2A18-2ACA6-AC2A18-2ACA646-AC2A18-2ACA5-A3BA18-A3BA3-A4BC18-C4B2(A2-A5B18-5B)2(A2-ABC3B18-3BCB)2(A2-A2BC2B18-2BC2B)A2-A5B18-5BA2-2A3BA18-A3B2A3-A3BA18-A3BA5-AC2A18-2ACA582-AC2A18-2ACA5-A3BA18-A3BA3-A5B18-5BA2-3AC2A18-2AC3A7(2-B28-B)2-6A18-5AC2-A4BA18-A4BA3-A3BA18-A3BA5-AC2A18-2ACA518-AC2A18-2ACA5-A3BA18-A3BA3-A5B18-5BA2-6A18-6A2(2-B28-B)-A5(B28-B2A)B28-BA-B28-B2-A2BC2B18-2(2BC)2-A4BA18-A4BA3-A3BA18-A3BA4-2AC2A18-2AC2A484-2AC2A18-2AC2A4-A3BC18-C3BA3-3A2CA18-A2C3A2-B28-B2-B28-C-A7(B28-B2A)B28-BA-B28-B2-A2BC2B18-2BC2BA2-A4BA18-A4BA3-2AC2A18-2AC2A453-AC2A18-2ACA4-2A3BA18-A3B2A2-3AC2A18-2AC3A2-B28-B2-B28-C-AB28-BADB28-B2A2(B28-BDA)B28-B2AB28-BDAB28-B2D2(B28-B2A)B28-BA-B28-B2-B4EB18-B4EC3-4BA18-A3BA4-2AC2A18-2AC2A420-5A18-5A3-A4BA18-A4BA2-4ACA18-AC4A2-B28-B-AB28-B2AB28-BAD2(B28-B2D2(B28-BAD))B28-BDA3(B28-B2A)B3ECB18-BC3EB2A5BA18-A4BCAB-4BA18-A3BA-2B-2AC2A18-2AC2A-2(2B30-)B2A28-2A-2D26-2D3-2A24-2A5-2A22-2A7-2A20-2A9-2A18-2A11-2A16-2A13-2A14-2A15-6AD2AD6A17-5AD2AD5A11-2AD2A18-2AD2A3-F4BA18-A4BF2-AB4A18-4ABA2-B28-B-D2(B28-B2D)2(B28-BDAB28-B2AB28-BAD)2(B28-B2D)B28-BD2B28-4B2ECAB18-BAC2E8BA18-A4BC2B-4BA18-A3BA-BA-2AC2A18-2AC2A-2A30-AB30-B2A28-2A-2D26-2D3-2A24-2A5-2A22-2A7-2A20-2A9-2A18-2A11-2A16-2A13-2A14-2A15-6AD2AD6A17-5AD2AD5A11-5A18-5A3-A4BA18-A4BA2-AB4A18-4ABA2-B28-B-3(AB28-B2AB28-BADB28-BD)A3(B28-B2A)BCECAB18-BACECB2A5BA18-A4BC2A-4BA18-A3BA2(-2A)C2A18-2AC2A-2A30-AB30-B2A28-2A-2D26-2D3-2A24-2A5-2A22-2A7-2A20-2A9-2A18-2A11-2A16-2A13-2A14-2A15-6AD2AD6A17-5AD2AD5A11-2AD2A18-2AD2A3-G4BA18-A4BA2-ABC3A18-3ACBA2-B28-B-D2(B28-B2D)2(B28-BDAB28-B2AB28-BAD)2(B28-B2D)B28-BD2B28-4BC2ECB18-BC2EC8BA18-A4BC2B-4BA18-A3BA-BA-2AC2A18-2AC2A-2A30-AB30-B2A28-2A-2D26-2D3-2A24-2A5-2A22-2A7-2A20-2A9-2A18-2A11-2A16-2A13-2A14-2A15-6AD2AD6A17-5AD2AD5A11-5A18-5A3-A4BA18-A4BA2-AB4A18-4ABA2-B28-B-AB28-B2AB28-BAD2(2(B28-BDA)B28-B2D)B28-BDA3(B28-B2A)B4EB18-B4EB2A5BA18-A4BCAB-A3BA18-A3BA-2B-2AC2A18-2AC2A-2(2B30-)B2A28-2A-2D26-2D3-2A24-2A5-2A22-2A7-2A20-2A9-2A18-2A11-2A16-2A13-2A14-2A15-6AD2AD6A17-5AD2AD5A12-AC2A18-2ACA4-2A3BA18-A3B2A2-AB4A18-4ABA2(2-B28-B)-AB28-B2AB28-B2DB28-BADB28-B2A2(B28-BAD)B28-B2AB28-BDAB28-B2AB28-BA-B28-C2-B4EB18-B4EC2-2A3BA18-A3B2A4-AC2A18-2ACA453-2AC2A18-2AC2A3-A4BA18-A4BA2-A2BC2B18-2BC2BA2-B28-B2-B28-C-A7(B28-B2A)B28-BA-B28-C2-4ACA18-AC4A2-A4BA18-A4BA3-2AC2A18-2AC2A485-AC2A18-2ACA5-A3BA18-A3BA3-A4BA18-A4BA2-A2B2CB18-B2C2BA2-B28-B2-B28-C-A5(B28-B2A)B28-BA-B28-C2-3A2CA18-A2C3A2-A4BA18-A4BA3-A3BA18-A3BA5-AC2A18-2ACA518-AC2A18-2ACA5-A3BA18-A3BA3-5BA18-A4BA2-A2BC2B18-2BC2BA2-B28-B6(2-B28-C)2-A3BCB18-BC3BA2-A4BA18-A4BA3-A3BA18-A3BA5-AC2A18-2ACA582-AC2A18-2ACA5-A3BA18-A3BA3-2A3BA18-A3B2A3(2-ABC3B18-3BCBA)4(2-A2BC2B18-2BC2BA)2-2A3BA18-A3B2A3-A3BA18-A3BA5-AC2A18-2ACA646-AC2A18-2ACA6-AC2A18-2ACA5-A3BA18-A3BA3-4(A4BA18-A4BA2-)A4BA18-A4BA3-A3BA18-A3BA5-AC2A18-2ACA6-AC2A18-2ACA742-AC2A18-2ACA6-AC2A18-2ACA5-2(2AC2A18-2AC2A4-)2AC2A18-2AC2A5-AC2A18-2ACA6-AC2A18-2ACA611-
