model
size = 22 19 14, scale = 0.05, origin = -y
material 
  colors = A:#111 B:#373C38 C:#E83015 D:#26453D E:#FFC408
voxels
22-7B2D4C2D7B7A2D4C2D14A2D4C2D7A330-7B2D4C2D7B7A2D4C2D14A2D4C2D7A352-B20AB2A19-3A19-A-6B2D4C2D6B5(2-6A2D4C2D6A)2-6B2D4C2D6B199-B20AB2A19-3A19-A-B18-B4(2-A18-A)2-A15-A-2A2-B15-2A-B2-6A2D4C2D6A177-B20AB2A19-3A19-A-B18-B5(2-A18-A)2-B17-AB2-2A13-2A2-A2-6A2D4C2D6A155-B20AB2A19-3A19-A-B18-B2-A2(18-A2-D)18-C2-D18-C2-A18-A2-B18-B2-A17-2A2-A13-2A3-A2-6A2D4C2D6A133-B20AB2A19-3A19-A-B18-B2-A18-A2-D18-C3(2-A18-A)2-B18-B2-A18-A2-A17-2A2-A12-2A4-A2-4AEAED4CDEAE4A7-B8-B12-B8-B13-B6-B15-B4-B17-4B9-B20AB2A19-3A19-A-B18-B2(2-A18-A)2(2-A18-C)2-A18-A2-B18-B3(2-A18-A)2-E18BE111-B20AB2A19-3A19-A-B18-B2(2-A18-A)2(2-C18-A)2-A18-A2-B18-B3(2-A18-A)2-E18BE111-B20AB2A19-3A19-A-B18-B2-A18-A2-C18-D3(2-A18-A)2-B18-B3(2-A18-A)2-4AEAED4CDEAE4A7-B8-B12-B8-B13-B6-B15-B4-B17-4B9-B20AB2A19-3A19-A-B18-B2-A18-A2-A2(18-D2-C)18-D2-A18-A2-B18-B2(2-A18-A)2-6A2D4C2D6A133-B20AB2A19-3A19-A-B18-B5(2-A18-A)2-B18-B2-A18-A2-6A2D4C2D6A155-B20AB2A19-3A19-A-B18-B5(2-A18-A)2-B18-B2-6A2D4C2D6A177-B20AB2A19-3A19-A-6B2D4C2D6B5(2-6A2D4C2D6A)2-6B2D4C2D6B199-
