model
size = 29 31 19, scale = 0.05, origin = -y
material 
  colors = A:#444 B:#111 C:#630 D:#963 E:#777 F:#222
voxels
681-E29-E808-E29-E88-E750-E148-E719-E178-E307-B351-E29-E209-E29-E217-B-B25-B-A-B25-3A25-B-A-B25-B-B263-E327-E160-B25-B-3A-B23-5A23-B5AB23-5A23-B-3A-B25-B234-E329-E29-E99-B-B26-3A25-5A22-B7AB21-7A21-B7AB22-5A25-3A26-B-B174-E390-E97-B-A-B24-5A22-B7AB21-7A21-9A21-7A21-B7AB22-5A24-B-A-B143-E449-E41-B27-3A24-B5AB22-7A21-9A19-B9AB19-9A21-7A22-B5AB24-3A27-B3(28-E)480-E29-E37-B-A-B24-5A22-B7AB21-7A21-9A21-7A21-B7AB22-5A24-B-A-B625-E37-B-B26-3A25-5A22-B7AB21-7A21-B7AB22-5A25-3A26-B-B569-E27-E96-B25-B-3A-B23-5A23-B5AB23-5A23-B-3A-B25-B308-3B260-E113-3B2(27-D)BD6-B-B18-D6-B-A-B16-DBD6-3A18-D6-B-A-B16-DBD6-B-B18-D27-4(DB2(D27-))DBD27-D26-5B230-E141-5B2(25-3C25-D3CD)6-B18-6(3C25-D3CD25-)3C24-7B25-F173-E171-5B8(24-D3CD24-B3CB)24-D3CD23-3BC3B24-FEF27-4(E28-)E200-5B8(25-3C25-D3CD)25-3C24-7B25-F346-3B2(27-D)7(B2(D27-)D)BD27-D26-5B895-3B350-
