model
size = 20 11 20, scale = 0.05, origin = -y
material 
  colors = A:#630 B:#111
voxels
180-2B18-2B91-4(5A15-)5A116-3A15-4(7A13-)7A15-3A77-3A16-5A13-4(3A3-3A11-)3A3-3A13-A3-A75-5A14-7A12-4(2A5-2A11-)2A5-2A12-A5-A56-A17-5A14-7A12-2A3(5-2A10-3A)5-2A11-2A5-2A12-A5-A74-5A14-7A11-4(3A5-2A10-)3A5-2A12-A5-A75-3A16-5A12-4(4A3-3A10-)4A3-3A13-A3-A96-3A13-3(A-7A11-)9A11-9A15-3A116-2(5A12-A2-)5A12-2A-5A12-8A134-3A15-6A14-6A13-7A13-6A13-3A178-2A18-2A17-3A16-3A198-3A16-3A17-2A197-4A16-3(3A196-3A17-)3A176-A19-3A18-2A176-3A17-3A196-B2A17-B2A37-
