model
size = 32 32 19, scale = 0.05, origin = -y
material 
  colors = A:#FF0 B:#CC0 C:#C90 D:#111 E:#222 F:#400 G:#E00 H:#6F3
voxels
194-6(2AC2A18-2AC2A4-)2AC2A18-2AC2A741-AC2A18-2ACA5-2AC2A18-2AC2A3-5(A4BA18-A4BA2-)A4BA18-A4BA3-A3BA18-A3BA5-AC2A18-2ACA6-AC2A18-2ACA646-AC2A18-2ACA5-A3BA18-A3BA3-A4BC18-C4B2(A2-A5B18-5B)2(A2-ABC3B18-3BCB)2(A2-A2BC2B18-2BC2B)A2-A5B18-5BA2-2A3BA18-A3B2A3-A3BA18-A3BA5-AC2A18-2ACA582-AC2A18-2ACA5-A3BA18-A3BA3-A5B18-5BA2-3AC2A18-2AC3A7(2-C28-C)2-6A18-5AC2-A4BA18-A4BA3-A3BA18-A3BA5-AC2A18-2ACA518-AC2A18-2ACA5-A3BA18-A3BA3-A5B18-5BA2-6A18-6A2(2-C28-C)-A5(D28-E2A)D28-EA-C28-C2-A2BC2B18-2(2BC)2-A4BA18-A4BA3-A3BA18-A3BA4-2AC2A18-2AC2A484-2AC2A18-2AC2A4-A3BC18-C3BA3-3A2CA18-A2C3A2(2-C28-C)-A7(D28-E2A)D28-EA-C28-C2-A2BC2B18-2BC2BA2-A4BA18-A4BA3-2AC2A18-2AC2A453-AC2A18-2ACA4-2A3BA18-A3B2A2-3AC2A18-2AC3A2(2-C28-C)-AD28-EA2D28-E2A2(D28-EDA)D28-E2AD28-EDAD28-E3D2(28-E2AD)28-EA-C28-C2-B4FB18-B4FC3-4BA18-A3BA4-2AC2A18-2AC2A420-5A18-5A3-A4BA18-A4BA2-4ACA18-AC4A2-C28-C-AD28-E2AD28-EA2D2(28-E3D2(28-EA2D))28-EDA3(D28-E2A)B3FCB18-BC3FB2A5BA18-A4BCAB-4BA18-A3BA-2B-2AC2A18-2AC2A-2(2B30-)B2A28-2A-2D26-2D3-2A24-2A5-2A22-2A7-2A20-2A9-2A18-2A11-2A16-2A13-2A14-2A15-6AD2AD6A17-5AD2AD5A11-2AD2A18-2AD2A3-H4BA18-A4BA2-AB4A18-4ABA2-C28-C-2D2(28-E3D)2(28-EDAD28-E2AD28-EA2D)2(28-E3D)28-EDBD28-E3B2FCAB18-BAC2F8BA18-A4BC2B-4BA18-A3BA-BA-2AC2A18-2AC2A-2A30-AB30-B2A28-2A-2D26-2D3-2A24-2A5-2A22-2A7-2A20-2A9-2A18-2A11-2A16-2A13-2A14-2A15-6AD2AD6A17-5AD2AD5A11-5A18-5A3-A4BA18-A4BA2-AB4A18-4ABA2-C28-C-3(AD28-E2AD28-EA2D28-ED)A3(D28-E2A)BCFCAB18-BACFCB2A5BA18-A4BC2A-4BA18-A3BA2(-2A)C2A18-2AC2A-2A30-AB30-B2A28-2A-2D26-2D3-2A24-2A5-2A22-2A7-2A20-2A9-2A18-2A11-2A16-2A13-2A14-2A15-6AD2AD6A17-5AD2AD5A11-2AD2A18-2AD2A3-G4BA18-A4BA2-ABC3A18-3ACBA2-C28-C-2D2(28-E3D)2(28-EDAD28-E2AD28-EA2D)2(28-E3D)28-EDBD28-E3BC2FCB18-BC2FC8BA18-A4BC2B-4BA18-A3BA-BA-2AC2A18-2AC2A-2A30-AB30-B2A28-2A-2D26-2D3-2A24-2A5-2A22-2A7-2A20-2A9-2A18-2A11-2A16-2A13-2A14-2A15-6AD2AD6A17-5AD2AD5A11-5A18-5A3-A4BA18-A4BA2-AB4A18-4ABA2-C28-C-AD28-E2AD28-EA2D2(2(28-EDAD)28-E3D)28-EDA3(D28-E2A)B4FB18-B4FB2A5BA18-A4BCAB-A3BA18-A3BA-2B-2AC2A18-2AC2A-2(2B30-)B2A28-2A-2D26-2D3-2A24-2A5-2A22-2A7-2A20-2A9-2A18-2A11-2A16-2A13-2A14-2A15-6AD2AD6A17-5AD2AD5A12-AC2A18-2ACA4-2A3BA18-A3B2A2-AB4A18-4ABA2(2-C28-C)-AD28-E2AD28-E3D28-EA2D28-E2AD2(28-EA2D)28-E2AD28-EDAD28-E2AD28-EA-C28-C2-B4FB18-B4FC2-2A3BA18-A3B2A4-AC2A18-2ACA453-2AC2A18-2AC2A3-A4BA18-A4BA2-A2BC2B18-2BC2BA2(2-C28-C)-A7(D28-E2A)D28-EA-C28-C2-4ACA18-AC4A2-A4BA18-A4BA3-2AC2A18-2AC2A485-AC2A18-2ACA5-A3BA18-A3BA3-A4BA18-A4BA2-A2B2CB18-B2C2BA2-C28-B2-C28-C-A5(D28-E2A)D28-EA-C28-C2-3A2CA18-A2C3A2-A4BA18-A4BA3-A3BA18-A3BA5-AC2A18-2ACA518-AC2A18-2ACA5-A3BA18-A3BA3-5BA18-A4BA2-A2BC2B18-2BC2BA2-C28-B6(2-C28-C)2-A3BCB18-BC3BA2-A4BA18-A4BA3-A3BA18-A3BA5-AC2A18-2ACA582-AC2A18-2ACA5-A3BA18-A3BA3-2A3BA18-A3B2A3(2-ABC3B18-3BCBA)4(2-A2BC2B18-2BC2BA)2-2A3BA18-A3B2A3-A3BA18-A3BA5-AC2A18-2ACA646-AC2A18-2ACA6-AC2A18-2ACA5-A3BA18-A3BA3-4(A4BA18-A4BA2-)A4BA18-A4BA3-A3BA18-A3BA5-AC2A18-2ACA6-AC2A18-2ACA742-AC2A18-2ACA6-AC2A18-2ACA5-2(2AC2A18-2AC2A4-)2AC2A18-2AC2A5-AC2A18-2ACA6-AC2A18-2ACA611-
