model
size = 18 18 19, scale = 0.05, origin = -y
material 
  colors = A:#C31518
voxels
294-6A300-6A10-10A10-6A280-2A6-2A7-3A6-3A7-2A6-2A277-A10-A5-2A10-2A5-A10-A275-A12-A3-2A12-2A3-A12-A274-A12-A3-2A12-2A3-A12-A273-5(A14-A-2A14-2A-A14-A272-)A14-A-2A14-2A-A14-A273-A12-A3-2A12-2A3-A12-A274-A12-A3-2A12-2A3-A12-A275-A10-A5-2A10-2A5-A10-A269-2(2A6-)5A4-3A6-5A5-2A6-4A18-5(A17-)2A5(17-A)16-2A16-A17-A15-3A7-6A2-3A5-13A7-6A2-2A16-4(A17-)A88-6(A17-)3A8-6A2-2A106-5(A17-)A147-
