model
size = 30 20 31, scale = 0.05, origin = -y
material 
  colors = A:#04003E B:#EBD15F C:#A7CFDA D:#A0883A E:#FFF F:#248369 G:#B32121
voxels
160-9(10A20-)10A318-9(2A10-2A16-)2A10-2A314-9(2A14-2A12-)2A14-2A311-9(A18-A10-)A18-A309-9(A20-A8-)A20-A307-9(A22-A6-)A22-A305-9(A24-A4-)A24-A304-9(A24-A4-)A24-A303-9(A26-A2-)A26-A302-9(A26-A2-)A26-A301-7(A9(28-2A)28-A300-)A9(28-2A)28-A301-9(A26-A2-)A26-A302-2(A26-A2-)A26-A-B3(A26-A2B)A26-AB-2(A26-A2-)A26-A302-A26-A2-A26-A-BA26-ABG3(A26-A2G)A26-AGBA26-AB-A26-A2-A26-A303-A24-A3-BA24-AB2-DA24-AD4(2-EA24-AE)2-DA24-AD2-BA24-AB3-A24-A304-A24-A3-BA24-AB2-DA24-AD4(2-EA24-AE)2-DA24-AD2-BA24-AB3-A24-A305-A22-A6-A22-A5-BA22-AB4(4-FA22-AF)4-BA22-AB5-A22-A6-A22-A307-2(A20-A8-)A20-A7-3(BA20-AB6-)BA20-AB7-2(A20-A8-)A20-A309-9(A18-A10-)A18-A252-2A12-2A13-5(3A12-)3A11-5(B3A12-3AB10-)B3A12-3AB11-5(3A12-)3A13-2A12-2A110-4A23-10A18-2(14A16-)14A15-B14AB13-7(2B14A2B12-)2B14A2B13-B14AB15-2(14A16-)14A18-10A23-4A85-6B22-10B18-2(14B16-)BD10BDB15-16B2(14-BD12BDB14-D14BD)14-BD12BDB15-2(BD10BDB16-)2B2D6B2D2B18-10B22-6B204-6F22-2F6B2F20-3BC2BC3B19-12B18-2BC6BC2B18-D10BD18-12B18-DBC6BCBD18-12B19-3BC2BC3B20-10B22-6B326-CE26-3C2EC24-3C2EC23-2(3CE)22-2C3E2CE23-C3E2C24-2E4C26-2C194-
