model
size = 31 22 31, scale = 0.05, origin = -y
material 
  colors = A:#FC0 B:#0F6 C:#F90 D:#F03 E:#F93 F:#F0C G:#99F H:#F63 I:#66F J:#30F K:#CFF L:#3CF M:#0F3
voxels
44-I-M-I645-2(7A24-)7A26-GLG29-G60-FKF29-F60-EBE29-E60-BJB29-B272-13A18-DAD7ADAD18-13A21-2AGLG2A24-3AG3A24-7A24-2AFKF2A24-3AF3A24-7A23-C2AEBE2AC23-3AE3A24-7A24-2ABJB2A25-2AB2A27-3A29-A208-5A7-5A14-D4A7-4AD14-5A7-5A16-6(3A7-3A18-)C2A7-2AC19-2A7-2A357-2(4A11-4A12-)4A11-4A13-6(3A11-3A14-)C2A11-2AC15-2A11-2A354-3A15-3A10-D2A15-2AD10-3A15-3A11-6(2A15-2A12-)CA15-AC13-A15-A352-2(3A17-3A8-)3A17-3A9-6(2A17-2A10-)CA17-AC11-A17-A350-3A19-3A6-D2A19-2AD6-3A19-3A7-6(2A19-2A8-)CA19-AC9-A19-A349-2(2A21-2A6-)2A21-2A7-7(A21-A8-)A21-A347-3A21-3A4-D2A21-2AD4-3A21-3A5-6(2A21-2A6-)CA21-AC7-A21-A347-2(2A23-2A4-)2A23-2A5-7(A23-A6-)A23-A346-2A23-2A4-DA23-AD4-2A23-2A5-5(A23-A6-)A23-A5-CA23-AC5-A23-A345-2(2A25-2A2-)2A25-2A3-9(A25-A4-)A25-A282-2A25-2A-I2A25-2AI-2A25-2A3-10(A25-A4-)A25-A92-H30-H61-H30-H34-3(2A25-2A2-)2G25-2G3-A25-A4-A25-A3-2F25-2F3-A25-A4-A25-A3-2E25-2E3-A25-A4-A25-A3-2B25-2B3-A25-A4-A25-A2(30-H)2(61-H)30-H3-2A25-2A-M2A25-2AM-2A25-2A2-2L25-2L2-2G25-2G3-A25-A3-2K25-2K2-2F25-2F3-A25-A3-2B25-2B2-2E25-2E3-A25-A3-2J25-2J2-2B25-2B3-A25-A4-A25-A30-2(H61-)H34-3(2A25-2A2-)2G25-2G3-A25-A4-A25-A3-2F25-2F3-A25-A4-A25-A3-2E25-2E3-A25-A4-A25-A3-2B25-2B3-A25-A4-A25-A7(30-H)3-2A25-2A-I2A25-2AI-2A25-2A3-10(A25-A4-)A25-A92-H123-H34-2(2A25-2A2-)2A25-2A3-9(A25-A4-)A25-A283-2A23-2A4-DA23-AD4-2A23-2A5-5(A23-A6-)A23-A5-CA23-AC5-A23-A346-2(2A23-2A4-)2A23-2A5-7(A23-A6-)A23-A346-3A21-3A4-D2A21-2AD4-3A21-3A5-6(2A21-2A6-)CA21-AC7-A21-A348-2(2A21-2A6-)2A21-2A7-7(A21-A8-)A21-A348-3A19-3A6-D2A19-2AD6-3A19-3A7-6(2A19-2A8-)CA19-AC9-A19-A350-2(3A17-3A8-)3A17-3A9-6(2A17-2A10-)CA17-AC11-A17-A352-3A15-3A10-D2A15-2AD10-3A15-3A11-6(2A15-2A12-)CA15-AC13-A15-A354-2(4A11-4A12-)4A11-4A13-6(3A11-3A14-)C2A11-2AC15-2A11-2A356-5A7-5A14-D4A7-4AD14-5A7-5A16-6(3A7-3A18-)C2A7-2AC19-2A7-2A360-13A18-DAD7ADAD18-13A21-2AGLG2A24-3AG3A24-7A24-2AFKF2A24-3AF3A24-7A23-C2AEBE2AC23-3AE3A24-7A24-2ABJB2A25-2AB2A27-3A29-A213-2(7A24-)7A26-GLG29-G60-FKF29-F60-EBE29-E60-BJB29-B307-I-B-I633-
