model
size = 13 24 32, scale = 0.05, origin = -y
material 
  colors = A:#272727 B:#564530 C:#292929 D:#202020 E:#FCC F:#B28065 G:#2D2D2D H:#786A3A I:#100
voxels
56-5C8-5B8-5A9-3A219-C-C9-3(5C8-)5B9-5(3A10-)4(2A11-)A37-5G5(8-5D)21-2(C-)3(C7-C4F)C7-B4EB3(8-A3BA)8-6(A2BA9-)AB2A9-4A8-6A7-6G7-D4I3(D7-D4B)D7-6D20-3(C-)3(C5-C6F)C5-B6EB6-A4BA4(7-6A)8-5A4(7-6A)7-7A6-5ABA5-GI6G5-DG4DI3(D5-DB4DB)D5-8D17-2C4(-C)3(3-C8FC)3-B8EB4-A6B2A3-2AB3(4-3A3-3A)6(4-3A4-2A)4-ABA2(4-2A)2(4-3G)4(3-DID4-DID)3-3D4-3D16-4(C-)C4-3(C8FC3-)B8EB3-A8BA2(3-2A6-2A)3-GA6-2A3-2A7(6-2A4-A)6-A4-2G6-2G5(3-2D6-2D)16-2C4(-C)3(3-C8FC)3-B8EB3-A8BA2(3-GA6-2A)2(3-2A6-2A)6(4-A6-2A)4-A6-A4-2G6-2G5(3-2D6-2D)16-4(C-)C4-3(C8FC3-)B8EB3-A8BA2(3-2A6-2A)3-GA6-2A3-2A7(6-2A4-A)6-A4-2G6-2G5(3-2D6-2D)16-2C4(-C)3(3-C8FC)3-B8EB3-A8BA4(3-2A6-2A)2(4-A6-2A)4-4(A6-A5-)A6-A4-2G6-2G5(3-2D6-2D)16-4(C-)2C3(3-C8FC)3-B8EB3-A8BA2(3-2A6-2A)3-2A6-A4-2A7(6-A5-A)6-A4-2G6-2G5(3-2D6-2D)16-2C2(-C)-2C4-9C2(4-C7FC)4-B7EB4-A7B3(A4-2A6-)8(A5-A6-)A5-G6-G5(5-D6-D)43-9C4-C7FC4-B7EB4-A7B3(A4-2A6-)8(A5-A6-)A6(5-G6-G)43-9C4-B7EB2(4-A7BA)3(4-2A6-A)9(5-A6-A)2(3-D-A6-A)2(-D)-A6-A-D2-DA6-AD4-H6AH6-6A31-9C4-B7EB2(4-A7BA)2(4-2A6-A)9(5-A6-A)3(5-8A)5-H7A5-D6AH55-10C3-B8EB3-A8BA4-A7B2(A4-2A6-)6(A5-A6-)A3(5-8A)5-H6-A12-H2(5-D)13-D55-10C3-C8FC3-B8EB3-A8BA4-A7BA4-2A4(6-A5-A)6-A3(5-8A)5-A6-A5-H6-H32-2D2-2D82-10C3-B8EB2(3-A8BA)4-A7BA4-2A2(6-A5-A)6-A2(5-8A)5-A6-A5-H6-H45-D4-D21-4D83-10C3-B8EB2(3-A8BA)4-A7B2(A5-A6-)A5-8A5-A6-A5-H6-H32-6D33-5D96-4(C-)2C3-2C4(FC)3-B8EB2(3-A8BA)3-2A7BA5-A6-A2(5-8A)5-H6-H19-6D160-2C4(-C)3-B8EB4(3-A8BA)3-2AB7A4-A7BA5-H6AH19-6D172-2C3(-C)-2C2-B9EB2(2-A9BA)3(3-A8BA)4-9A19-6D185-5(C-)C2-B9EB3(2-A9BA)2(3-A8BA)4-9A210-2C5(-C)-B10EB3(-A10BA)-A9BA3-2A7BA5-7A211-5(C-)2C-B10EB3(-A10BA)-2A9BA3-A7BA5-7A211-2C4(-C)-2CB11EBA2(11B2A)10BA-2A9BA3-A7BA5-7A211-6(C-)CB11EBA2(11B2A)11B3A9BA3-A7BA5-7A211-2C4(-C)-2CB11EBA2(11B2A)11B3A9BA3-A7BA5-7A211-6(C-)2C11FCB11EBA11B2A11BA-A9BA3-A7BA5-7A212-6(C-)C11FCB11EBA11BA-A9BA2-A9BA3-A7BA5-7A213-4(C-)C3-5(CF)C2-B9EB3(2-A9BA)3-A7BA5-7A226-10C2-C9FC2-B9EB2-A9BA3-A7BA4-2A5B2A6-5A240-9C4-2B5E2B2(4-2A5B2A)5-7A224-
