model
size = 24 22 10, scale = 0.05, origin = -y
material 
  colors = A:#777 B:#888 C:#444 D:#555 E:#700 F:#AAA
voxels
249-3(2(E2-)E17-)2(E2-)E427-2(3F21-)3F477-2(3F21-)3F428-4A19-6A17-3A3-2A16-3A-A-2A16-3A3-2A16-8A17-6A19-4A284-4A18-2A5BA15-2A7BA13-2A3B3-3BA12-A3B5-3B11-2A2B7-2BA10-2A2B3-F3-2BA10-2A2B7-2BA10-2A3B5-3BA11-2A3B3-3BA12-3A7B2A13-3A5B2A15-8A18-4A165-2A19-8A14-12A11-5A5-4A10-4A7-3A9-4A9-3A2(8-3A11-2A)7-4A5-F5-3A6-4A11-3A7-3A11-2A8-4A9-3A8-5A7-4A9-5A5-4A10-14A11-12A14-8A19-2A92-6C16-10C12-A4C2-D2-4C9-A3C-2(D2-)D-3CA7-3C3(2-D)2-3C6-A2C3-2(D2-)D3-2C6-3C3-2(D2-)D3-2C5-A2C4-2(D2-)D4-2C4-3C4-2(D2-)D2(4-2C)16D2C4-2C5-2(D2-)D2(4-2C)5-2(D2-)D4-2C4-A2C4-2(D2-)D3-3C5-A2C3-2(D2-)D3-2C6-A3C3(2-D)2-3C7-A3C-2(D2-)D-3C8-2A3C2(D2-)D3CA9-2A4C-D-4CA12-2A7CA16-6A41-8A14-3A6-3D11-2A10-2D9-2A13-A7-2A15-A5-AD17-D4-AD17-D3-AD18-2D2-2D6-2(E2-)E6-4(D2-D20-)D2-2D6-2(E2-)E6-D2-3A17-DA3-2A17-D4-2AD15-2A5-2AD13-2A7-2AD11-2A9-4A7-3A11-12A14-8A16-3B4-3A12-2A10-2A9-A13-2A6-2B15-A5-2B17-A3-2B19-A2-2B19-A-2B21-2B8-2(E2-)E7-4(2B22-)2B8-2(E2-)E7-4B19-2B-2B19-B2-3B17-2B3-3B15-2B5-3B13-2B6-4B11-3B8-4B7-3B11-12B207-2(E2-)E113-2(E2-)E200-
