model
size = 26 32 25, scale = 0.05, origin = -y
material 
  colors = A:#EEE B:#222 C:#F93 D:#FF6 E:#F60 F:#3CF G:#111
voxels
61-2(8B18-8B798-)3(8B18-)8B746-3(8B18-)8B740-16(20B6-)20B396-16(2B16A2B6-)2B16A2B8-16D6(10-16C11(10-16B)60-16(2B16A2B6-)2B16A2B8-3D10C3D)10-16C11(10-16B)60-2B16A2B6-2B16A2B3-2B10(-B18AB-4B)-B18AB-4(6B2(18A8B)18A4B3-2B16A2B8-3D10C3D10-16C11(10-16B)60-2B16A2B6-2B16A2B3-2B-B18AB-10(4BAB18ABA))6B2(18A8B)2(18A4B3-2B16A2B8-3D10C3D10-16C11(10-16B)2(10-5C6-5C)8-2B16A2B6-2B16A2B3-2B-B18AB-11(4BAB18ABA)6B18A8B)18A4B3-2B16A2B8-16D10-16C5(10-16B)2(10-3BAF2G2B2GFA3B)10-3BA3F2B3FA2(3B10-3B4A2B4A)3B10-16B2(10-5C6-5C)8-2B16A2B6-2B16A2B3-2B11(-B18AB-4B)-B18AB-6B18A8B18A4B3-2(2B16A2B143-6C20-6C171-5C6-5C10-5C6-5C8-16(2B16A2B6-))2B16A2B143-6C20-6C171-5E6-5E10-5E6-5E587-6C20-6C171-5E6-5E10-5E6-5E790-2(CE)C6-2(CE)C10-2(CE)C6-2(CE)C785-
