model
size = 16 30 32, scale = 0.05, origin = -y
material 
  colors = A:#3C3A27 B:#6B5637 C:#22271D D:#3D4B2C E:#1A1A1A F:#47412C G:#745638
voxels
21-2(5B11-)5B28-3A12-2(5A11-)5A12-3A332-2(5B11-)5B3(27-5A10-7A8-9A7-9A8-7A10-5A)27-5A2(11-2AG2A)11-2(AG)A11-5A9-9B2(7-2B5A2B)9-5C3(9-9A6-4A3C4A2(5-3A5C3A)5-4A3C4A6-9A9-5D)9-4(9A7-)9E6-11B5-B2A5B2AB5-B9AB6-2C5A2C6-11A5-11A4-13A3-13A4-11A5-11A6-2D5A2D6-11A5-11A4-13A3-13A4-11A5-11A6-2D5AD7-11A5-11A4-13A3-13A4-11A5-11A6-2D5A2D6-4(11A5-)11E5-11B5-BA7BAB5-B9AB6-C7AC6-11A2(4-4A5-4A2-5A5-5A-5A5-5A2-4A5-4A4-3A5-3A6-DA5-AD6-3A5-3A)4-4A5-4A2-5A5-5A-5A5-5A2-4A5-4A4-2(3A5-)D2A5-AD6-8(3A5-)3E5-3E4-2(13B3-BA9BAB3-B11AB4-C9AC4-13A2-4A7-4A-B3A7-5A-2(3A7-9A7-4A2-3A7-3A4-DA7-AD4-3A7-3A2-4A7-4A2-3A7-5AB)3A7-9A7-4A2-3A7-3A4-DA7-AD4-4(3A7-3A3-)3E7-3E3-13B3-BA9BAB3-B11AB4-C9AC4-13A2-4A7-4A2-3A7-5AB2(3A7-9A7-4A2-3A7-3A4-DA7-AD4-3A7-3A2-4A7-4A-B3A7-5A-)3A7-9A7-4A2-3A7-3A4-DA7-AD4-4(3A7-3A3-)3E7-3E3-)13B3-BA9BAB3-B11AB4-C9AC4-13A2-4A7-4A-B3A7-5A-2(3A7-9A7-4A2-3A7-3A4-DA7-AD4-3A7-3A2-4A7-4A2-3A7-5AB)3A7-9A7-4A2-3A7-3A4-DA7-AD4-4(3A7-3A3-)3E7-3E3-13B3-BA9BAB3-B11AB4-C9AC4-13A2-4A7-4A2-3A7-5AB3A7-9A7-4A2-3A7-3A4-DA7-AD4-3A7-3A2-5A6-4A-B4A5-6A-4A5-11A5-5A2-4A5-4A4-D2A5-2AD4-4A5-4A2-5A5-5A-B4A5-6A-4A5-11A5-5A2-4A5-4A4-D2A5-2AD4-4(4A5-4A3-)4E5-4E4-11B5-BA7BAB5-B9AB6-C7AC6-11A3-4A7-3A2-B3A7-4A2-3A7-4A-4A7-3A3-3A7-2A6-D7-D6-2A7-2A2(3-5A5-4A3-4A5-5A-B4A5-5A-5A5-4A4-3A5-3A6-DA5-AD6-3A5-3A)6(5-3A)2(5-3E)5-11B5-BA7BAB5-B9AB6-C7AC6-11A3-4A7-3A3-3A7-4A-B3A7-4A-4A7-3A4-2A7-2A6-D7-D6-2A7-2A2(4-13A2-15A-15A2-13A4-11A6-D7AD6-11A)3(5-11A)5-11E5-11B5-BA7BAB5-B9AB6-C7AC6-10A5-3A2(7-2A3-4A)7-2A4-3A7-2A5-2A7-A2(7-D6AD7-10A5-12A4-2(12AF3-)12A5-10A)7-D6AD8-4(9A7-)9E6-11B5-BA7BAB5-B9AB6-C7AC6-10A5-2(3A7-2A4-)3A7-3A3-3A7-2A5-2A7-A7-D6AD7-5(10A6-)10A7-8D7-5(10A6-)10A8-7D9-7A2(9-3AG3A)9-2AGAG2A9-E5AE8-10B6-BA6BAB6-B8AB7-C6AC7-9A6-11A5-2(12A4-)11A6-9A8-7A9-D5AD9-7A8-F7AF7-F7AF8-7A9-7A41-7A8-F7AF7-F7AF8-7A9-7A104-10B6-BA6BAB6-B8AB7-C6AC7-9A6-12A4-12A3-13A4-11A6-9A8-7A10-5A10-2(7A9-)7A10-5A74-7A9-7A10-5A121-10B6-BA6BAB6-B8AB7-C6AC7-10A5-12A4-12A3-13A4-12A5-9A8-7A10-5A13-2D282-10B6-BA6BAB6-B8AB7-C6AC7-10A5-12A3-14A2-14A3-12A5-9A8-8A9-5A12-3A281-11B5-BA7BAB5-B9AB6-C7AC7-10A5-12A3-13A3-14A3-12A5-10A7-8A9-5A12-3A281-11B5-BA7BAB5-B9AB6-C7AC6-11A5-12A3-14A2-14A3-12A5-10A7-8A9-5A12-3A280-13B3-BA9BAB3-B11AB4-C9AC5-12A3-13A3-14A2-14A3-12A5-10A7-8A9-6A11-3A280-13B3-BA9BAB3-B11AB4-C9AC4-2(13A3-)14A2-14A3-12A4-12A5-9A9-6A11-4A278-15B-BA11BAB-B13AB2-C11AC3-13A2-2(15A-)15A2-13A4-12A5-10A7-7A11-4A278-15B-BA11BAB-B13AB2-C11AC2-4(15A-)15A2-13A4-11A7-8A10-4A278-15B-BA11BAB-B13AB2-C11AC2-15A-15AF31AF15A2-13A4-11A6-9A10-4A278-15B-BA11BAB-B13AB2-C11AC2-15A-31AF31A2-13A4-11A7-8A10-4A278-15B-BA11BAB-B13AB2-C11AC3-14A2(-15A)F15A2-14A3-12A5-10A8-6A12-3A279-13B3-BA9BAB3-B11AB4-C9AC4-13A3-2(14A2-)14A3-12A5-10A7-8A10-5A294-13B3-BA9BAB3-B11AB4-C9AC5-11A4-13A3-13A4-12A5-10A7-8A9-7A11-2A297-11B5-B2A5B2AB5-B9AB6-2C5A2C7-9A6-11A5-11A6-10A7-8A8-7A11-4A313-9B2(7-2B5A2B)9-5C10-7A8-9A7-9A8-8A8-7A10-5A326-
