model
size = 9 30 9, scale = 0.05, origin = -y
material 
  colors = A:#222 B:#FFFFCE C:#95A59A D:#D0D0D0 E:#1B813E F:#555 G:#2F2F2F H:#E83015 I:#FD0 J:#EEE K:#5DAC81 L:#F7D94C M:#BDC0BA N:#656765 O:#868686 P:#D0104C Q:#2EA9DF R:#DDD S:#7BA23F T:#111
voxels
2-2(LC)L3-7C2-2C3-2C2-3C3-C2-C-2C2(2-C)2-2C-C2-C3-3C2-C4-2C2(2-2C4-C)2(2-7C)2-C3-3C2-C2-4C2-C2-2C-C2-C-2C2-C2-3C3-2(C2-2C4-)C2-2C3-2C2-C3-3C2-7C3-5C66-3(CL)C-CADA3DA2CD-F3-2(D2CD-F-H-)2(D2CD2(-F)-)2(D2CD-H-F-)D2CD3-F-D2CA5DA2C2AP4A2CA-P-R-A2CA2P3-A2CAR2-2QA2CA3-Q2(-A2CA-M2FMA2CA2-2F)-A2CA-MFGMA2C7AC-7C64-B7C2B3A3DA2BAG2FO-D2(2BAF2(GH)A)2BA2(FG)FA2BA2(FI)2(FA2BA2(HI))FA2BD-2(OF)D2BA2(DO)DA2B7A9(2BA5EA)BC7AC-3CA3C5-N58-2B2(C3B)3A3DA2BD-F3-D2BD-FDH2D2(2BD2(-G)-D)2(2BD2(-I)-D)2BD-I-G-D2B2D2-G-D2BA5DA11(2B7A)B3C3A3C3-GAG7-G49-2B5C3B7A2BADA3DAB-3(7A2-3(AD)A2-)6(7A2-)7A-B5(7A2B)7A3B5A2B2-N3AN5-GAG7-4(A8-)T5-7B-B7AB-7A12-3(2(J-)J13-)S3-H13-3(K4E4-)5K3-7A-B4(7A2B)7A4B3A3B3-GAG7-G51-5B3-B2GN2GB137-7A-B3(7A2B)7A5BA4B4-N221-7A-B2(7A2B)7A10B236-2(FA)F2-BA2(GF)GA3B5A2B-7B64-
