model
size = 32 10 3, scale = 0.05, origin = -y
material 
  colors = A:#1A1C1E B:#000 C:#292D2F D:#98A3AE E:#FFF F:#687077 G:#585F65 H:#410000 I:#003545 J:#104B61 K:#600D0D L:#005B89 M:#0176AD N:#395059 O:#604646 P:#B60000 Q:#730000 R:#10A6C5 S:#66E5FF T:#FFA9A9 U:#E04444
voxels
108-G6-G24-G6-G25-G4-G144-A2B3A14-A2B3A4-FC5-B2A10-F2C5-2A-FG8-BA8-FG8-2AF10-BA6-2D10-AD11-A6-E11-AD11-AB4-BE11-BD11-B6-D11-B-D9-AB6-DE9-B3-D6-CAB8-D2E6-C5-FD2EDFC12-D3EDFC38-3A2B16-2A3B5-F3C2A2B12-F3C2A2B3-FGO2KC2A2B10-2GN2JC2A2B2-DFOTPHC2A2B8-DFGNSMIC2AB2-EDFKUQHC2AB8-EDFGJRLICAB2-2EDGKPQACAB2-4B2-2EDFGJMLACA3-E2DG2HCAC10-2EDFG2ICA5-2EDFGC14-EDFGCA35-
