model
size = 31 32 22, scale = 0.05, origin = -y
material 
  colors = A:#1C1208 B:#20180C C:#EEE D:#555 E:#BBB F:#777 G:#111 H:#888
voxels
725-C2(5-C23-2E5-2E23-E)5-C148-2(7B24-)7B921-2(11B20-)3BA7B22-B3A3B24-3BA3B24-4BA2B6(24-4B3A)24-3B3AD24-3B2A2D24-2B3A2D24-B3A3D24-4A3D2(24-3A3DA)2(24-2A3D2A)2(24-A3D3A)24-3D4A269-3BA8BA18-4BA8B18-4B3A6B19-3B3A5B20-4B2A5B20-5B2A4B3(20-6B5A)2(20-6B4AD)2(20-5B4A2D)2(20-4B5ADA)20-3B8A20-2B9A20-B10A20-11A4(20-10AB)20-AD7A2B20-4D4A3B21-2D5A2B205-A2B2A5-2B3A16-4BA5-3B2A16-5B5-4BA17-4B5-4B18-4B5-3BA18-4B5-2B2A18-4B5-4A2(18-4B5-3AD)18-A3B2(5-3AD18-4B)3(5-4A18-4B)5-4A2(18-3BA5-3AB)18-2B2A5-4A18-B3A5-3AB15-4B3A5-2A5B11-4B4A2(5-2A6B10-8A)5-2A6B11-7A5-A6B13-6A5-6B14-3AD7A6B16-3D6A4B171-4A9-4A14-2A2B9-4A14-A3B9-B3A15-3B9-B2A16-3B9-3A2(16-3B9-2AD)16-A2B9-2AD16-2AB9-2AD16-3A9-3A16-2AB3(9-3A16-3B)9-2AB3(16-3B9-A2B)13-6B9-A5B9-6BA9-2A4BA7-A6BA9-A4B3A6-2A4B2A2(9-6B2A6-8A)9-A4B3A6-GH6A9-4B2A2F7-H6A9-3B3AF9-13A6B2A11-12A6BA14-3D8A4B138-2(4A11-3AD12-)4A11-3AD13-4(3A11-2AD14-)5(3A11-3A14-)A2B11-3A14-3B11-A2B2(14-3B11-3B)12-5B11-5B9-6B11-6B7-A6B11-A4B2A5-3A4BA11-A2B5A4-4A2B2A11-4B4A4-H7A11-4B4A4-8A11-A2B5A4-HG6A11-5A3F5-G6A11-B4A2F7-H14A4B3AG9-2H12A4B2AG11-HAD11A2BFAF15-D12A21-E4C2E24-C6E24-2(C3E)17-2(3A13-2AD12-)3A13-2AD13-2A13-AD9(14-2A13-2A)14-2A13-AB14-2B13-2B12-A3B13-4B9-A4B13-5B7-2A4B13-4B2A5-3A4B13-A2B4A3-5A2BA3(13-8A2-8A)13-8A2-2AG5A13-6AFA3-HG5A13-6AF5-G8A7-8AG7-G7A7-7AF9-2H5A7-4A3G12-2D3A7-4A19-C7-C22-E7-C22-C7-C16-2(4A13-3AD10-)4A13-3AD11-3A13-2AD10(12-3A13-3A)12-3A13-A2B10-5A13-4BA7-6A13-4B2A5-7A13-A2B4A3-5(8A13-8A2-)8A13-6AFA2-8A13-6AFA3-G8A9-8AF5-G7A9-8A7-H6A9-6AF11-2D2A9-4A16-EC9-2C18-EC9-2C19-E9-CE14-3A15-3A10-3A15-2AC10-3A15-3A11-11(2A15-2A12-)2A15-2A9-5A15-5A5-6A15-6A3-2(7A15-7A2-)7A15-7A-8A2(15-16A)15-8A-2(7A15-7A2-)9A11-9A3-8A11-7AG5-AHG4A11-6AG9-2D2A11-2A2G15-C11-C18-E11-E18-C11-C14-2(3A15-3A10-)3A15-3A11-10(2A15-2A12-)2A15-2A11-3A15-3A8-5A15-5A5-6A15-6A3-7A15-7A2-7A15-7A-8A4(15-16A)15-8A-7A15-7A2-9A11-9A3-8A11-8A4-CAH5A11-7AC5-2HC2D2A11-2A2GA2C12-2(C11-C18-)C11-C14-2(3A15-3A10-)3A15-3A11-10(2A15-2A12-)2A15-2A11-3A15-3A8-5A15-5A5-6A15-6A3-7A15-7A2-7A15-7A-8A4(15-16A)15-8A-7A15-7A2-9A11-9A3-8A11-8A4-C7A11-7AC4-3C3D2A11-2AF2A3C2(11-C)18-E11-E18-C11-E14-2(3A15-3A10-)3A15-3A11-2A15-2A12-BA15-2A2(12-2B15-2B)12-BA2(15-2B12-2A)4(15-2A12-2A)15-2A11-3A15-3A8-5A15-5A5-6A15-6A3-7A15-7A2-7A15-7A-8A4(15-16A)15-8A-7A15-7A2-9A11-9A3-H7A11-8A4-H7A11-7AC5-C4D2A11-4AFCF12-C11-C18-C11-E45-2(3B15-3A10-)2BA15-3A11-BA15-2A4(12-2B15-2B)12-BA2(15-2B12-2A)3(15-2A12-2A)15-2A12-BA15-2A9-4BA15-5A5-2A2B2A15-6A3-2(7A15-7A2-)7A15-7A-8A2(15-16A)15-8A-2(7A15-7A2-)9A11-9A3-H7A11-7AG5-GDG4A11-7A9-2D2A11-A2GA15-C11-E18-E11-E45-2(4B13-3AD10-)3BA13-4A11-2BA13-3A4(12-3B13-3B)12-2BA2(13-3B12-3A)2(13-3A12-3A)13-3A12-B2A13-A2B12-2BA13-3B10-4BA13-4BA7-4B2A13-A2B3A5-2A2B3A13-7A3-6(8A13-8A2-)8A13-8A3-9A9-9A5-2H6A9-6A2G7-3D4A9-6AG11-D3A9-2A2G16-2C9-2C19-C9-C47-2(3B13-2AC12-)3B13-3A13-BA13-2A4(14-2B13-2B)14-BA2(13-2B14-2A)2(13-2A14-2A)13-AB14-BA2(13-2B)A13-3B11-3BA13-4B9-4BA13-4BA7-4B2A13-A2B3A5-7A13-7A3-4(8A13-8A2-)8A13-2A6F3-G6A13-2A5F5-G8A7-5A4F7-H7A7-5A3F9-3D4A7-5A2F13-4A7-3AG17-3C7-3C20-C7-C48-2(3BA11-3AD12-)3BA11-3AD13-3B11-2AD14-3B11-2AB14-3B11-A2B14-3B11-3B14-B2A3(11-3B14-3A)11-2BA14-3A11-B2A14-3A11-A2B2(14-B2A11-3B)13-2B2A11-4B11-3B2A11-5B9-3B3A11-A4BA7-7A11-3A2B2A5-2(8A11-2A4B2A4-)8A11-3A2B3A4-H7A11-8A4-8A11-3A4FG5-G6A11-3A4F7-H8A5-6A3F9-G7A5-6AFG11-HD5A5-4AFAF15-4A5-4A18-2E2C5-3CE20-EC5-2C49-2B2A9-4A14-2B2A9-3AD14-3BA9-3AD15-2(3B9-2AD16-)3B9-3A16-3B9-2AB16-2BA6(9-3B16-3A)9-A2B16-3A9-A2B15-B3A9-A3B13-BAD2A9-A4B11-B2AD2A9-2A4B9-3A2D2A9-3A4B7-2(8A9-2A6B6-)8A9-3A4BA6-8A9-4A2B2A6-H7A9-8A7-2AD4A9-7A9-A2D5A5-8A11-2D5A5-6AF13-D5A5-6A16-3CE5-E3C20-2C5-2C22-2C5-2E50-2(5A5-5A16-)3B2A5-4AD17-3(3BA5-3AD18-)3BA5-4A18-2B2A5-A3B4(18-4A5-4B)18-4A5-A3B18-4A5-4A2(18-D3A5-3AB)18-D3A5-4A17-2D3A5-5A15-2DC3A5-4A2B13-A2DC3A5-4A3B11-2A2D4A5-4A4B10-2AD5A5-4A4B10-A2D5A5-5A3B11-3D4A5-7A13-D5A5-6A15-5A5-5A17-4A5-4A18-4C5-4C19-3C5-2CE21-CE5-2C23-C5-E52-4AB3-2B3A18-5A3-B4A18-2B3A3-4AD19-3(2B2A3-2A2D20-)2B2A3-2ADA20-B3A3-2A2B3(20-4A3-A3B)20-AD2A3-A3B20-AD2A3-2A2B20-AD2A3-4A20-DCA5-3A20-D3(2A5-3A20-C)2A5-3A20-3A5-3A19-C3A5-4A17-DC3A5-4AB16-D4A5-5A17-4A5-4A18-C3A5-3AC18-2C2A5-2A2C18-3CE5-E3C19-2CE5-3C21-EC5-2E23-C5-C84-2(3AB3-2B2A20-)4A3-B3A22-2A3-2A24-2A3-AD24-2A3-2D24-2A2-3D24-2A-4D24-2A4DA24-A3D-AB24-3D2-AB24-2D3-2A24-DA3-2A24-CA3-2A24-A5-A23-3(CA5-AC22-)CA5-A2C20-2CA5-A2C20-C-A5-ACE20-2CA5-A2C19-3CA5-A3C18-E2CA5-A3C19-3C5-4C18-4C5-3CE19-2CE5-2CE21-2C5-2E23-E5-E117-2(AB3-2B24-)2A3-BA335-C3-E25-2(C5-C24-)C5-E24-E5-E23-2C5-2E21-C-E5-C-C21-2C5-EC21-C-C5-C-C2(21-CE5-2C-C19-C-C5-3C)21-2C5-2C23-C5-C136-
