model
size = 14 26 13, scale = 0.05, origin = -y
material 
  colors = A:#FF6 B:#9CF C:#C63 D:#CF3
voxels
102-6A8-6A7-8A6-8A5-11(10A4-)10A5-8A76-8A5-10A3-3(12A2-)2(4A4-4A2-)2(3A6-3A2-)10(2A8-2A2-)3A6-3A2-12A3-10A47-8A5-10A3-3A6-3A2-AB8-B17(A2-A10-)A2-AB8-BA3-10A46-10A3-2(3A2-2A2-)4A2-2A2-A5-2B3-A-AB2(3-4B3-4A)7(3-4B3-3AB)2(3-B2AB3-3AB)3-BA2B3-3AB3-B3(2AB3-3AB2-2B)2AB3-3AB3-4B3-2A-2A2-4B2-BA2-12A2(4-2A)33-10A3-2A-6A-2A2(2-A)2C3A2-A-2A5-3B2-4A2(2-2B)2-3A10(3-2B2-2B3-2A)2(3-BA2-2B3-2A)3(3-2B2-AB3-2A)B2-BC2A2B2-4A2-2B2A2B2-BA-12A2(4-2A)19-2(3A4-)10A3-2A-A-4A-2A2(2-A)3-2A2-A-2A6-2B2-3A13(3-B4-B3-2A)3(2-2B4-B3-2A)2-BA4-B3-3A-ABC2-AB2-BA-12A4-8A19-10A4-10A3-2A-A3-2A-2A2(2-A)4-A2-A-2A7-B2-3A13(3-B4-B3-2A)2-2B4-B3-2A2-2B3-CA3-2(2A2-2B4-AB2-)3A-AC4-AB-BA-5A2-5A4-8A21-5A7-4A2-4A3-2A-A4-A-2A2(2-A)4-A2-A-2A6-2B2-3A14(3-B3-2B3-2A)2(2-2B4-B3-2A)2-2B4-AB2-3A-2A4-2B-BA-2(4A4-)8A21-6A6-3A2(3-4A)4-4A2(2-A)C3-A2-A-2A6-2B2-3A3-A4BC3-2A3-4BC2(B3-2A3-3B2C)B3-2A3-BCB-CB3-2A3-B2CB-B3-2A3-BC-3B3-2A3-BC4B3-2A3-B-2BCB3-2A3-3B2CB3-2A3-3B-CB3-2A3-BC2B-B2(3-2A3-BC4B)3-2A3-B-2A2B3-2A3-2B2-2B3-2AB2-2B3-B2-5A-B4-A-2BA-4A4-4A5-A4CA22-6A7-2(2A4-)4A2C2-4A2-2A-A3C2(2A-)2A2-3C2DC2-3A3-C4D4-2A3-A3D-C3-2A3-B2D2-C3-2A3-B2DC-C3-2A3-C-2D2C3-2A3-C2-2D2(C3-2A3-C-3D)C3-2A3-B3D-C3-2A3-B2D2-C3-2A3-B2DC-C3-2A3-C-2DCA3-2A3-C-3DA3-2A3-B3CDA3-2A3-B-2B-A3-2A3-5BA3-2AB2(2-2B)2-2A-3AB4-B3A3-3A4-3A6-A4CA10-3C9-AC2-CA8-AC3-A6-3A4-3A3-4A3-C4A-3A8-5A10-3AB2-C4-C2-3A5(3-C4-C3-2A)7(B2-C4-C2-3A)B2-B2C2DA2-3AB2-B4-A2-3A3BAC2-CA2B2A-4A4-4A5-A4-A8-A4CA9-4C9-AB-2BA8-A3-BA8-A4-A6-3A2C2D3A3-3A6-3A2-3A6-3A-5A6(4-10A)4-5A-7(4A4-4A2-)4AC2DC4A2-3A-CD2C-3A6-4C10-4C38-4C9-ACD2C9-AC2DC313-
