model
size = 32 30 32, scale = 0.05, origin = -y
material 
  colors = A:#AAA B:#9CF C:#E00 D:#009
voxels
684-9C919-9C947-4C9A3C944-C14AC884-9A23-9A16-3C16A4C16-9A23-9A819-16A16-16A12-C23AC11-16A16-16A816-16A16-16A12-C23AC11-16A16-16A757-7A25-7A19-19A13-19A10-C23AC10-19A13-19A19-7A729-7A25-7A19-19A13-19A10-C23AC10-19A13-19A19-7A726-13A19-13A14-23A9-23A6-2C25A2C6-23A9-23A14-13A721-16A16-16A13-23A9-23A6-C27AC6-23A9-23A12-16A21-4(7B25-)7B564-16A16-16A13-23A9-23A6-C27AC6-23A9-23A12-16A21-4(7B25-)7B183-D73-D217-D88-16A16-16A12-25A7-25A3-2C29AC4-25A7-25A11-16A20-4(9B23-)9B24-7B27-D503-2(19A13-19A10-25A7-25A3-C30AC4-25A7-25A10-19A16-4(13B19-)13B21-9B530-)19A13-19A10-25A7-25A3-C30AC4-25A7-25A10-19A16-4(13B19-)13B21-9B125-D404-19A13-19A10-25A7-25A3-C30AC4-25A7-25A10-19A16-4(13B19-)13B21-9B470-D59-2(19A13-19A10-25A7-25A3-C30AC4-25A7-25A10-19A16-4(13B19-)13B21-9B530-)19A13-19A10-25A7-25A3-C30AC4-25A7-25A10-19A16-4(13B19-)13B21-9B118-D263-D148-16A16-16A12-25A7-25A3-2C29AC4-25A7-25A11-16A20-4(9B23-)9B24-7B158-D153-D219-16A16-16A13-23A9-23A6-C27AC6-23A9-23A12-16A21-4(7B25-)7B564-16A16-16A13-23A9-23A6-C27AC6-23A9-23A12-16A21-4(7B25-)7B566-13A19-13A14-23A9-23A6-C27AC6-23A9-23A14-13A723-13A19-13A14-23A9-23A6-2C25A2C6-23A9-23A14-13A726-7A25-7A19-19A13-19A10-C23AC10-19A13-19A19-7A788-16A16-16A12-C23AC11-16A16-16A816-16A16-16A12-C23AC11-16A16-16A820-9A23-9A16-3C16A4C16-9A23-9A883-C14AC944-4C9A3C948-C7AC299-
