model
size = 22 24 9, scale = 0.05, origin = -y
material 
  colors = A:#385460 B:#476673 C:#161616 D:#E4E4E4 E:#272A3D
voxels
14-2A20-A21-A5(17-5A)70-A17-5A17-2A20-2A301-4A18-5A3(14-8A)14-6A17-5A46-A21-2A20-2A71-A21-A246-10A11-12A9-13A9-14A2(7-15A)6-16A6-3A3-10A7-A6-8A15-7A27-A10-10A-A10-6A16-3(11A11-)3AD7A11-2A3B6A12-9A96-2A3B15-7A3B11-11AB9-13A2(B7-14A)2(B6-15A)B5-4A3-10A5-4A4-9A5-3A6-8A5-2A10-4A6-2A9-10A-A10-3ACA17-3(11A11-)10AE11-11A12-9A96-3A2B15-7A3B11-11AB9-13A2(B7-14A)2(B6-15A)B5-5A2-10A5-4A4-9A5-3A6-8A5-3A8-5A6-2A9-10A12-3AC18-4(11A11-)11A12-9A96-2A3B15-7A3B11-11AB9-13A2(B7-14A)2(B6-15A)B6-4A2-10A5-4A4-9A5-3A6-8A6-A10-4A17-10A12-3ACA17-3(11A11-)10AE11-11A12-9A116-10A11-12A9-13A8-2(15A7-)15A6-16A7-2A3-10A14-8A15-7A38-10A12-6A16-3(11A11-)3AD7A11-2A3B6A12-9A74-4A18-4A17-4(6A16-)6A46-A21-2A20-2A232-A21-4A21-2A18-4A5(17-5A)51-A17-5A17-2A20-2A226-
