model
size = 5 24 7, scale = 0.05, origin = -y
material 
  colors = A:#E00 B:#080 C:#FF0
voxels
77-2(B4-)B94-2(B4-)B19-B29-6(B4-)B24-B4-B29-B8-3C53-3(B4-)B44-B2-5C-2(3A2-)3A98-B2-2(2C-)2(A-A2-)A-A101-5C-2(3A2-)3A102-3C16-
