model
size = 32 31 18, scale = 0.05, origin = -y
material 
  colors = A:#EEE B:#800 C:#FF0 D:#C03 E:#200 F:#CC0 G:#CC3 H:#FF6 I:#FF3
voxels
39-2(3CG)CHCG3CG2C18-2F4-2(F2-)F911-3CG5CG2CG3CGC17-3F7-F686-7B253-G2(7CF)G15-G5C2G8C17-3B4-B2-2B20-2B9-B-B467-4B4-4B19-5BC2-C5B17-2(6BC2BC6B16-)16B11-21B16-16B207-G17C15-C14BG16-15B3(18-5BC2BC5B)18-4B9CB18-3B9C2B18-3B3C3B2C3B18-3B2C4B2C2BD18-3B3C3B2C2BD2(18-4B7C3B)18-3B3C3B2C3B18-3B2C4B2C3B18-3B3C3B2C3B18-3B9C2B16-BEB3E2F2C4FGBEB14-B2E4AF2EF4A2EB14-2(2E6A)E3(B14-B16A)B10-5B16AB9-B5-B14A2(B5-)B4-16B4-B7-5B14-5B9-4B14-4B108-G17C15-GB12ABG17-D12ABF17-6(B12AB18-)2(B12AD18-)5(B12AB18-)B12AB16-BD14AD3(B14-B16A)B9-4B-B16AB-4B4-4BDB16ABD4B3-5BDB16ABD5B3-2(4BD-B14AB-D4B4-)13BFC13B4-11B4CFC11B6-4B-3BC6-C3B-4B10-B2-B2C8-2CB2-B45-G17C15-CB12ABC17-D14(12AB18-B)12AB16-BD14ADB14-B16AB8-F2C2F-B16AB-CF2CF2-5B-B16AB-2(5B2-)D14AD2-5B2-6B-D14AD-6B-7B-D14AD-14B2D14A2D14B-DAB10DBAD-7B-6B3AB10DB2A7B3-5B3AB10DB3A5B6-3BADAB10-BADA3B10-B2DAB10-BA2DB13-3BF10-F3B14-G16CG14-GCB12ABCF16-B12AB17-2B12AB18-B12AD2(18-B12AB)3(18-D12AB)3(18-B12AB)18-D3(12AB18-B)12AB16-ED14ADE14-E16AE8-F3-F-E16AE-C3-F2-4BE-E16AE-E4B2-B3AE2-D14AD2-E3AB2-B4AD-D14AD-D4AB-D6B-D14AD-14B-D14AD-15BDA2B8D2BAD8B-6B2AB12-B2A6B3-5B2AB12-B2A5B6-3B3AB10-B3A3B2(10-B3AB)13-3BC10-C3B14-17CG15-CB12ABC16-2B2(12AB18-B)12AD2(18-B12AB)2(18-B12AD)2(18-B12AB)18-B12AD5(18-B12AB)16-ED14ADE14-E16AE8-C3-C-E16AE-C3-C2-4BE-E16AE-E4B2-B3AE2-D14AD2-E3AB2-B4AD-D14AD-D4AB-D6B2(-D14AD-14B)-DA12BAD-7B-6BDAB12-BAD6B3-5B2AB12-B2A5B6-BDB3AB10-B3ABDB10-D3AB10-B3AD13-2BDC10-CD2B14-18C15-CB12ABG17-3(D12AB18-)11(B12AB18-)B12AB16-ED14ADE14-B16AB8-C3-F-E16AE-C3-C2-4BE-E16AE-E4B2-B3AE2-D14AD2-E3AB2-D4AD-B14AB-D4AB-7B-D14AD-14B-D14AD-7BD6B-DA12BA2(D-6B)DAB12-BAD6B3-D4B2AB12-B2A4BD6-3B3AB10-B3A3B2(10-B3AB)13-3BC10-F3B14-18C15-GB12ABC17-2(B12AD18-)3(B12AB18-)D3(12AB18-B)2(12AB18-D)4(12AB18-B)12AB16-ED14ADE14-E16AE8-F3-C-E16AE-C3-F2-4BE-E16AE-E4B2-D3AE2-D14AD2-E3AB2-D4AD-D14AD-D4AB-7B2(-D14AD-14B)-DA3B6D3BAD-7B-6BDAB12-BAD6B3-D4B2AB12-B2A4BD6-D2B3AB10-B3A2BD2(10-B3AB)13-3BC10-C3B14-18C15-CB12ABC17-B12A2B17-B12AB3(18-B12AD)10(18-B12AB)16-BD14ADB14-B16AB8-C3-C-E16AE-C3-C2-4BE-D16AD-E4B2-D3AE2-B14AB2-E3AB2-B4AD-D14AD-D4AB-7B-B14AB-7BD6B-D14AD-14B-DA4BD2BD4BAD-7B-6BDAB12-BAD6B3-5B2AB12-B2A5B6-D2B3AB10-B3A2BD2(10-B3AB)13-3BF10-F3B14-17CG15-CB12ABC16-2B12AB18-B12A2B17-3(B12AB18-)2(B12AD18-)5(B12AB18-)D12AD18-D12AB18-B12AB16-ED14ADE14-E16AE8-C3-C-E16AE-C3-C2-4BE-E16AE-E4B2-B3AE2-D14AD2-E3AB2-B4AD-D14AD-D4AB-D6B-D14AD-7BD6B-D14AD-14B-DA5B2D5BAD-7B-6BDAB12-BAD6B3-5B2AB12-B2A5B6-B2D3AB10-B3A2DB10-D3AB10-B3AD13-BDBC10-CBDB14-18C14-FCB12ABC2(17-B12A2B)17-D3(12AB18-B)3(12AB18-D)12AD18-D2(12AB18-B)12AB18-D12AD18-D12AB18-B12AB16-BD14ADB14-E16AE8-F3-C-B16AB-C3-C2-4BE-E16AE-E4B2-D3AE2-D14AD2-E3AB2-B4AD-B14AB-D4AB-D6B-B14AB-7BD6B-D14AD-14B-DA12BAD-7B-6BDAB12-BAD6B3-D4B2AB12-B2A4BD6-3B3AB10-B3A3B10-2D2AB10-B2A2D13-2DBF10-FB2D14-18C14-FCB12ABC17-B12ABF17-B12AD18-D3(12AB18-B)4(12AB18-D)12AD5(18-B12AB)16-ED14ADE14-E16AE8-F3-C-E16AE-C3-F2-4BE-E16AE-E4B2-D3AE2-D14AD2-E3AB2-B4AD-D14AD-D4AB-7B2(-B14AB-14B)-DA4BD2BD4BAD-7B-6BDAB12-BAD6B3-5B2AB12-B2A5B6-3B3AB10-B3A3B2(10-B3AB)13-BDBC10-CBDB14-17CG15-CB12ABCF15-2B12ABG17-D12AD18-D3(12AB18-B)3AF8A9(B18-B12A)B16-ED14ADE14-E16AE8-C3-F-E16AE-C3-F2-4BE-E16AE-E4B2-B3AE2-D14AD2-E3AB2-B4AB-D14AD-B4AB-7B2(-D14AD-14B)-DA12BAD-7B-6BDAB12-BAD6B3-5B2AB12-B2A5B6-3B3AB10-B3A3B10-2B2AB10-B2A2B13-3BC10-C3B14-18C15-CB12ABC17-B2(12AB18-D)3(12AB18-B)3AF8A6(B18-B12A)B18-D2(12AB18-B)12AB16-2B14A2B14-E16AE8-F2CFH-E16AE-HCFHC2-4BE-E16AE-E4B2-BD3B2-B14AB2-2BD2B2-6B-B14AB-5BD-2BD4B-B14AB-2BD7BD3B-B14AB-4BD9B-BA12BAB-7B-4B2ADAB12-BAD2A4B3-3B4AB12-B4A3B6-5BAB10-BA5B10-B-BDB10-BDB-B16-C10-C17-18C14-FC14BC16-12B2DB18-5B2D7B18-2BIG2C3B2HC2B18-2BDGBCBHBC4B18-3BH3(BC)4B18-3BH2CBGBH4B18-3BCBG2(BC)2BDB18-BD4(BC)2BDB18-2BIG2CBCB2CG2B18-BD5BH6B18-4B2CHG3C3B18-6BD7B18-14B18-8BD3B2D18-BD4BD7B18-14B16-18B14-E16BE14-7BD2BD7B15-6BD2BD6B16-7BD5BD2B16-6B2D5BD2B16-5B3D2BD5B16-D12BD2B12-5BD18B9-7BD3BD10B14-11B2DB18-6B2F6B20-2(CF)2CF3C18-17CG14-F2C4FH7FHG18-B-2(B2-)B23-B5-2(B-)2B2(31-B)20-B10-B778-
