model
size = 32 17 32, scale = 0.05, origin = -y
material 
  colors = A:#161616 B:#858585 C:#9AA6AB D:#929292 E:#777 F:#FFF G:#0F0F0F H:#898989 I:#7EA97D J:#A97DA5 K:#7D7EA9 L:#A9937D M:#A2A97D N:#A97D7D O:#827DA9 P:#F30 Q:#FFFF80
voxels
39-3(8B24-)2(8A24-)8A25-6A27-4A281-3(10B22-)10A22-2A6-2A23-8A24-2A4-2A25-6A311-BJ-6D-IB20-3BE4CE3B20-12B20-12A20-3A6F3A20-12A20-4A4F4A20-12A21-4A2-4A24-6A154-6A26-6F26-6A23-B-D6-D-B19-3BCEC2ECEC3B18-14B5(18-14A)18-6A2F6A19-12A21-10A87-8A3(24-A6-A)20-B-BD-D4-D-DB-B16-3B3(E2C)E3B16-16B6(16-4A8B4A)17-A12-A19-12A54-8A2(24-A6-A)23-A8-A22-A8-A19-B-B3(D2-)DB-B16-3B2(CE)2C2(EC)3B16-16B3(17-F2AB6-B4A)17-F2AB6-B3AK17-F2AB6-B4A16-4AB6-B4A17-A12-A19-12A23-6A25-A6-A24-A6-A116-B-BD3-DE3-DB-B16-3B2CEC2BCE2C3B16-16B16-4AB6-B4A16-4AB6-B3AI16-4AB6-B3AJ3(16-4AB6-B4A)17-A2-B6-B2-A19-3A6-3A22-A6-A24-A6-A148-B-BD3-ED3-DB-B16-3B2CEC2BCE2C3B16-16B3(17-F2AB6-B4A)17-F2AB6-B3AL2(16-4AB6-B4A)17-A2-B6-B2-A19-3A6-3A21-A8-A22-A8-A147-B-B3(D2-)DB-B16-3B2(CE)2C2(EC)3B16-16B5(16-4AB6-B4A)17-3AB6-B3A18-A2-B6-B2-A19-3A6-3A21-2(A8-A22-)A8-A117-BD-D4-D-DB19-2B3(E2C)E2B18-14B6(18-3AB6-B3A)18-2A-B6-B-2A19-3A6-3A21-2(A8-A22-)A8-A117-B-D6-D-B20-2BCEC2ECEC2B20-12B7(20-2AB6-B2A)20-3A6-3A21-2(A8-A22-)A8-A115-B-B2-6D2-B-B16-5BE4CE5B16-16B5(16-4AB6-B4A)17-3AB6-B3A19-3AB4-B3A20-4A4-4A22-A6-A24-A6-A148-B-B10-B-B15-2(18B14-)5(5AB6-B5A14-)5AB6-B5A17-4A4H4A242-2(B-)M-K2-L-O3(-B)2(13-19B)2(13-5AB6-B6A)2(12-6AB6-B6A)13-5AB6-B6A13-5AB-4B-B5A15-16A240-3(B-)B2-4(B-)B2(13-19B)2(13-5AB6-B6A)13-5AB6-B17A-6AB6-B6A10FA2-5AB-4B-B6A13-5AB-4B-B5A15-16A17-14A207-4(B-)B2-4(B-)B12-20B3-2C7-20B2(2-D2-C7-5AB6-B6A)3-DC7-6AB6-B17A-6AB6-B17A2-5A8B6A13-5A8B5A15-16A17-14A19-12A176-3(B-)B6-3(B-)B12-20B3-2C7-20B2-DQPC7-5AB6-B6A2-DPQC7-5AB6-B6A3-DC7-6AB6-B16A2-6AB6-B6A9FA3-5A8B6A13-5A8B5A15-16A17-14A19-2A2G8A176-B-N-B2-6D2-B-J-B12-7BE4CE7B3-2C7-20B2(2-D3C7-5AB6-B6A)3-DC7-6A8B16A2-6A8B16A3-5A8B6A13-5A8B5A15-16A17-14A19-A2(G2A)GAG2A176-2(B-)K-D6-D-I2(-B)12-6BCEC2ECEC6B3-2C7-20B2-D3C7-5AB6-B6A2-D3C6-6AB6-B6A3-DC7-6A8B15A3-6A8B6A8FA4-5A8B6A13-5A8B5A15-16A17-14A19-4A2(G3A)176-2(B-)BD-D4-D-D2(B-)B12-5B3(E2C)E5B3-2C7-20B2(2-D3C6-6A8B6A)3-DC7-6A8B14A4-6A8B15A3-6A8B6A13-5A8B5A15-16A17-14A19-3AG2A3(GA)176-2(B-)B3(D2-)D2(B-)B12-5B2(CE)2C2(EC)5B3-2C7-20B2-D2EC6-6A8B6A2-D2EC5-G6A8B6A3-DC6-7A8B13A4-G6A8B6A6FA5-6A8B6A13-5A8B5A15-16A17-14A19-2AG9A176-2(B-)BD3-ED3-D2(B-)B12-5B2CEC2BCE2C5B3-2C7-20B2-D2-C6-6A8B6A2-D2-C5-7A8B6A3-2D6-G6A8B12A5-7A8B13A5-6A8B6A13-5A8B5A15-16A17-14A19-A2(G2A)4GA176-2(B-)BD3-DE3-D2(B-)B12-5B2CEC2BCE2C5B12-20B2(12-6A8B6A)11-G6A8B10A8-6A8B6A12-6A8B6A13-5A8B5A15-16A17-14A19-A4G2AG4A176-2(B-)B3(D2-)D2(B-)B12-5B2(CE)2C2(EC)5B12-20B13-5A3(8B6A12-6A)8B6A13-5A8B5A14-5A8B5A15-16A17-14A19-7A3G2A178-B-BD-D4-D-DB-B15-4B3(E2C)E4B14-18B6(14-18A)15-16A17-14A19-2AGAG5AGA178-B-L-D6-D-N-B15-5BCEC2ECEC5B14-18B6(14-18A)15-16A17-14A19-3AG6AGA178-B-B2-6D2-B-B15-6BE4CE6B14-18B5(14-18A)15-16A16-16A17-14A19-4(AG)2AGA178-B-B10-B-B2(16-16B)7(16-16A)17-14A19-8A2G2A178-2(B-)O6-M2(-B)2(16-16B)6(16-16A)17-14A18-14A20-10A181-2(B-)I2-J2(-B)19-2(14B18-)6(14A18-)14A19-12A212-2(B-)B2-2(B-)B2(20-12B)6(20-12A)21-10A246-3(B2-)B2(22-10B)5(22-10A)23-8A273-
