model
size = 20 32 21, scale = 0.05, origin = -y
material 
  colors = A:#A00 B:#E00 C:#363 D:#3F0 E:#0C0
voxels
470-3A17-3AB592-2A21-4A17-A2-3B11-2BA3B17-3B551-2B5A16-2A2-3A13-3A4-A2B10-B5-2A11-AB2A-3A2B11-B3A512-B-B3A14-3B2A-3A16-A3-3A12-A7-3B8-A5-A2-2A8-5A-A-2A2B12-3A512-7A11-5A4-3A13-A6-AB11-A-A6-2B7-6A-3A2-A7-2(2A3-)B-B18-2B13-3A17-3A452-5A12-4A4-AB8-B4A-A5-2A12-A-A5-2B9-2(A-)A6-2B5-4A3-A2-A3-B5-2A5-3A2(-B)11-A-4A-2B11-3A2-AB12-2AB-3AB449-7A11-4A5-2B7-B3A2-A6-AB9-2A9-B7-2A3-A7-2B4-A-2A-3A7-2B3-2A2-4A3-A2-B8-3A-A4-3B8-3A4-A2(-B)10-3A2B-A2B15-B414-3A-A13-2A3-A-A10-3A7-2B5-AB3A-A8-B9-A10-2B6-A13-B4-A-A11-A-B3-2A-A9-B-A6-A11-B7-2A9-B10-BA2-B-2A2B12-2A-2B413-6A12-2A5-A9-4A7-2B5-AB2A2-A8-2B8-A11-B6-A13-B4-A13-A-B3-A-2A9-B-AB4-B-A9-B8-B10-B9-2B7-3B10-BA-2ABA15-A226-CD18-CD8-EC8-CD8-EC7-CD9-E3C17-2E3-C19-2C2-CE14-E4CD12-2A-E3CD8-4A-A2-4D6-2A6-A8-3A9-2B4-AB2A-A10-B8-A10-B7-A12-B5-A2-A11-A3-A2-A-A9-2AB3-A2B-A8-A9-A10-A8-A7-3AB9-2A4-B15-4A16-2(CD18-)CD19-CD18-CD2(19-C)4(D18-C)D2-3C13-CD2-3C10-10C10-9C11-3C-6C13-7CE12-8C12-2C-4C12-A-A3-2C7-5A2-A12-A7-A8-3A9-B5-3A-A10-B4-BA-2A11-B6-A13-B5-A2-A11-A3-A2-A-A9-A-B3-AB2-A8-A-A7-A10-2(A8-)3A9-A6-B13-5AB15-CD18-CD19-D320-2A12-6A-A11-A8-A9-A10-B5-3A12-B4-B2A13-B5-A14-B3-3A14-A3-2A-2A10-A-B3-AB-A9-A-AB6-A10-A8-A7-2A2B8-A2B4-B15-3AB392-7A12-A7-2A9-A10-2B4-3A12-B4-B15-B4-A-A13-B3-2A-A13-A5-2B11-A-B3-AB-A9-A-AB6-A10-A8-A7-2ABA8-A2B2-B2A15-2B395-A4B13-2A5-2BA9-A10-2B6-A12-B5-A14-B4-A-A12-2B3-BA-A11-A2B5-2B11-3B3-AB-A9-A-2B6-A8-A-B8-2A6-A3B10-6A414-B16-2AB-4B10-2A8-A7-2A11-2B5-A13-A6-A11-2A6-2A11-A7-A-A10-A6-2A-A8-BA9-A7-B-AB9-2A2-3A2-A12-2A435-A4B13-2A5-2BA7-3A10-B6-A12-A7-A10-A8-B11-A8-3A9-A7-3A10-A9-2B7-3B10-6AB469-3A5B9-3A8-BAB7-A11-A8-A-2A7-A8-B2A7-A12-A6-2A9-5A2-5A11-3BA-4AB14-2A475-2B12-B4AB2-3B10-2B2A6-2A9-B2-2A4-AB9-3A4-2A13-3A2-2A13-A2-2A18-3A2-2B507-4A5B13-4B3-2B15-B-4B11-5B3-B11-6A553-2AB17-8B17-5B18-2B12-4A17-2A537-B19-BA3B18-5B145-
