model
size = 23 31 12, scale = 0.05, origin = -y
material 
  colors = A:#FC9 B:#FF9 C:#FFF D:#F66 E:#DDD F:#FC3 G:#EEE H:#09F I:#111
voxels
333-C22-B540-A22-A19(21-2A)21-A185-A19-A2-A19-A-2A20(19-4A)19-2A-A19-A141-A17-A3-2A17-2A2-2A17-2A-3A20(17-6A)17-3A-2A17-2A3-A17-A97-A15-A5-2A15-2A3-B2A15-2AB2-B2A15-2AC2-B2A15-2AB2-C2A15-2A7(C2-BA17-AB2-CA17-A)C2-B2A16-A2(B2-C2A15-2AC2-B2A15-2A)B2-C2A15-2AC3-2A15-2A53-A11-A9-2A11-2A7-B2A11-2A6-2(AB2A11-4A4-)3(4A11-4A4-)10(2A15-2A4-)2(3A13-3A4-)A17-A4-2A15-2A4-3A13-3A6(4-4A11-4A)11-5A16-9A12-B11AB9-15A8-15A7-C15AC6-B2A11-2AB6-C2A11-2AC6-B2A11-2A2(B6-C15AC6-B15A)B6-C5A5-5AC6-B5A5-5AB6-C6A3-6AC6-B7A-7AB6-C7A-7AC6-BF6A-6AFB6-C15AC6-BD3E7A3EDB6-2DE-E7AE-E2D8-3E-5A-3E8-3(C15AC6-B15AB6-)C15AC6-B15AB33-4(CA)C13-5(AB)A11-6(CA)C10-6(BA)B10-C11DC10-D3(2G-)2GD10-D11-D10-D3(2G-)2GD10-B2D7A2DB10-BAB7ABAB10-CAC7ACAC10-BAB7ABAB10-2(CA)5-2(AC)10-2(BA)5-2(AB)10-CAC2A3-2ACAC10-BAB3A-3ABAB10-CAC3A-3ACAC10-BFB3A-3ABFB10-CAC7ACAC13-7A16-D5AD17-5A14-CAB7ACAC10-2(BA)2(FH)F2(AB)10-CACFH3AHFCAC10-BAFHF3AFHFAB10-CACFH3AHFCAC10-2(BA)2(FH)F2(AB)10-CAC7ACAC10-6(BA)B126-11D2(11-D)2(10-D11-D)11-11D14-3(AB)A16-3(AC)A16-3(AB)A2(16-2A3-2A)16-ACA-ACA16-ABA-ABA16-ACA-ACA16-FBA-ABF16-AC3ACA16-AB3ABA16-DC3ACD18-ABA19-CA-AC17-A5-A18-3E20-EIE20-3E18-A5-A17-2(CA)C340-CA-AC18-BA2-B19-5(3A20-)3A21-C527-A-A20-3A21-2(C22-A22-)C22-B550-3A20-3A21-2(C22-B22-)C264-
