model
size = 32 32 29, scale = 0.05, origin = -y
material 
  colors = A:#0C0 B:#EEE C:#E00 D:#111 E:#555 F:#070 G:#444 H:#0E0 I:#0CF J:#3CF
voxels
947-2(3A5-3A21-)3A5-3A948-2(AC2-2(A3-)A19-)AC2-2(A3-)A946-2(A2-C2-A-A4-CA17-)A2-C2-A-A4-CA945-2(A2-D2-2(A-)CDC-A17-)A2-D2-2(A-)CDC-A945-2(A2-C2-A-AC4-A17-)A2-C2-A-AC4-A949-C2(A3-)A19-A2-CAD-DA3-A19-A2-C2(A3-)A948-3A5-3A21-3A2(-D)-3A21-3A5-3A953-DJD29-3D29-DID953-3A5-3A21-3A2(-D)-3A21-3A5-3A948-2(A3-)A2-CA19-A3-AD-DA2-CA19-2(A3-)A2-CA946-2(AC4-A-A2-C2-A17-)AC4-A-A2-C2-A945-2(A-CDC2(-A)2-D2-A17-)A-CDC2(-A)2-D2-A945-2(A4-CA-A2-C2-A17-)A4-CA-A2-C2-A946-2(2(A3-)AC2-A19-)2(A3-)AC2-A948-2(3A5-3A21-)3A5-3A7170-7B3EG21-10HG21-2BH6BHG21-2(BH)5BHG21-H3BH2B3HG21-11B25-3G30-12(D31-)DC30-D2C29-DC345-5(7B3EG21-)11B853-2(7B3EG21-)4BF2B3EG21-6BF3EG21-4BFBF3EG21-7BE3B853-FEF5BFEF21-11B21-4B-BEB2EG21-4BGB-B2EG21-4B2(-B)2EG21-11B917-3F3-E-3F21-FDF-E3-FEF21-3F5-3F982-D7-D1015-D7-D918-
