model
size = 32 32 30, scale = 0.05, origin = -y
material 
  colors = A:#888 B:#EEE C:#BBB D:#777 E:#DDD F:#555 G:#111 H:#444 I:#E00
voxels
129-G7-G1422-3(4A4C24-)4A4C20-4(4C28-)3(4E28-)4E32-3(4D4A24-)4D4A536-AG-ACG-C24-AG-2AG-C24-7AC24-4A4C20-4(4C28-)3(4E28-)4E32-3(4D4A24-)4D4A536-A2-AC-GC24-2AG2A-GC24-7AC24-4A4C20-4(4C28-)3(4E28-)4E32-3(4D4A24-)4D4A536-3(4A4C24-)4A4C20-4(4C28-)3(4E28-)4E32-3(4D4A24-)4D4A19456-7B3FH21-10AH21-2BA6BAH21-2(BA)5BAH21-A3BA2B3AH21-11B25-3H30-12(G31-)GI30-G2I29-GI345-5(7B3FH21-)11B853-2(7B3FH21-)4BA2B3FH21-6BA3FH21-4BABA3FH21-7BF3B853-AFA5BAFA21-11B21-4B-BFB2FH21-4BHB-B2FH21-4B2(-B)2FH21-11B917-3A3-F-3A21-AGA-F3-AFA21-3A5-3A982-G7-G918-
