model
size = 22 20 25, scale = 0.05, origin = -y
material 
  colors = A:#FFE2C5 B:#563F2E C:#EEE D:#FFFFFB E:#00AA90 F:#F8B09C G:#111
voxels
120-2A16-10A12-10A11-3(12A10-)12A11-10A12-10A16-2A214-10A11-5A2-5A9-2(2A10-2A8-)4(A12-A8-)2A10-2A8-2A10-2A9-5A2-5A11-10A165-5A2-5A9-2A3-4A3-2A2(8-A12-A)7-5(A14-A6-)A14-A7-2(A12-A8-)2A3-4A3-2A9-5A2-5A119-5B4-5B8-3A-6A-3A8-A5-2A5-A7-3(A14-A6-)A14-A5-2A14-2A4-2A14-2A5-3(A14-A6-)A14-A7-A5-2A5-A8-3A-6A-3A8-5B4-5B95-B14-B7-14A7-3A3-4A3-3A2(6-A-12A-A)5-5(A16-A4-)A16-A5-2(A-12A-A6-)3A3-4A3-3A7-14A7-B14-B116-A5-4A5-A6-2A3-A5-3D-A6-2A3D6A3C2A5-3A3C7A2C3A4-A-A2C2A5-A2D2-2(A3-)2DA12-2(A2-A18-)A2-A3-2DA12-A3-A-A2C2A5-A2D2-A4-3A3C7A2C3A5-2A3D6A3C2A6-2A3-A5-3D-A6-A5-4A5-A145-2A13-A5-4AD3-CA5-2AC3-D4ACE-EC2A4-A-CE-EC5AEGEC-A3-2A-CEGEA5-D2ED-2A2-A2-D2ED12-2(A2-A18-)2(A2-)D2ED12-A2-2A-CEGEA5-D2ED-2A3-A-CE-EC5AEGEC-A4-2AC3-D4ACE-EC2A5-A5-4AD3-CA13-2A167-A5-4AD3-CA5-A-C3-D4ACE-EC-A4-A-CE-ECA2-2AEGEC-A3-A2-CEGEA5-D2ED2(2-A)2-D2ED12-A-2A18-4A18-2A-A2-D2ED12-2(A2-)CEGEA5-D2ED2-A3-A-CE-ECA2-2AEGEC-A4-A-C3-D4ACE-EC-2(A5-)4AD3-CA182-2A3-5A-3D-A5-A-A3D6A3CA-A4-A-A3C7A2CA-A3-2A-A2C2A5-A2DA-2A2(2-A)2DA12-A-2A18-4A18-2A-A2-A2DA12-A2-2A-A2C2A5-A2DA-2A3-A-A3C7A2CA-A4-A-A3D6A3CA-A5-2A3-5A-3D-A167-2A13-16A6-6A4-6A5-A2-2A8-2A2-A4-A16-A3-3(A18-A2-)A18-A3-A16-A4-A2-2A8-2A2-A5-6A4-6A6-16A13-2A130-2A19-4A13-6A2-6A7-5A6-5A5-4A10-4A2(4-A16-A)3-A18-A2-A18-A3-2(A16-A4-)4A10-4A5-5A6-5A7-6A2-6A13-4A19-2A86-2A19-4A17-2A2-2A12-4A6-4A2(8-3A)7-3A10-3A5-2A14-2A4(4-A16-A)4-2A14-2A5-3A10-3A7-2(3A8-)4A6-4A12-2A2-2A17-4A19-2A42-2A19-4A17-2A2-2A15-2A4-2A12-3A6-3A9-2A10-2A7-B2A10-2AB6-BA12-AB5-3(2B14-2B4-)2B14-2B5-BA12-AB6-B2A10-2AB7-2A10-2A9-3A6-3A12-2A4-2A15-2A2-2A17-4A19-2A19-4A17-6A15-2A4-2A13-2A6-2A11-2A8-2A9-2(3A8-)2A10-2A7-BA12-A4(B6-B14-)B6-BA12-AB7-2A10-2A2(8-3A)9-2A8-2A11-2A6-2A13-2A4-2A15-6A17-4A17-6A15-3A2-3A14-2A4-2A13-2A6-2A11-2A8-2A10-2A8-2A9-BA10-AB8-B12-B7-3(B14-B6-)B14-B7-B12-B8-BA10-AB9-2A8-2A10-2A8-2A11-2A6-2A13-2A4-2A14-3A2-3A15-6A17-4A16-2BA2-A2B13-B2A4-2AB11-B2A6-2AB10-BA8-AB9-2B10-2B8-B12-B7-2B12-2B4(6-B14-B)6-2B12-2B7-B12-B8-2B10-2B9-BA8-AB10-B2A6-2AB11-B2A4-2AB13-2BA2-A2B16-4A39-6B14-2BA4-A2B11-B2A6-2AB10-BA8-AB9-2B10-2B7-2B12-2B6-2B12-2B5-2B14-2B2(4-B16-B)4-2B14-2B5-2B12-2B6-2B12-2B7-2B10-2B9-BA8-AB10-B2A6-2AB11-2BA4-A2B14-6B81-BF4-FB12-3BA4-A3B10-B2A6-2AB9-2B10-2B7-2B12-2B5-2B14-2B4(4-B16-B)4-2B14-2B5-2B12-2B7-2B10-2B9-B2A6-2AB10-3BA4-A3B12-BF4-FB103-B4FB14-2B2A2-2A2B11-2BA6-A2B9-2BA8-A2B7-3B10-3B6-B14-B5-3(B16-B4-)B16-B5-B14-B6-3B10-3B7-2BA8-A2B9-2BA6-A2B11-2B2A2-2A2B14-B4FB106-2B17-3B2A3B12-4BA2-A4B9-4B6-4B8-2B10-2B7-B14-B6-B14-B5-B16-B4-B16-B5-B14-B6-B14-B7-2B10-2B8-4B6-4B9-4BA2-A4B12-3B2A3B17-2B129-4B15-4B2A4B11-4B4-4B9-2(3B8-)2B10-2B7-3(B14-B6-)B14-B7-2B10-2B2(8-3B)9-4B4-4B11-4B2A4B15-4B151-2B18-6B14-4B2-4B11-B10-B9-2B10-2B8-B12-B7-B14-B6-B14-B7-B12-B8-2B10-2B9-B10-B11-4B2-4B14-6B18-2B173-4B16-3B2A3B13-B3A2-3AB11-2B8-2B9-2B10-2B2(8-B12-B)8-2B10-2B9-2B8-2B11-B3A2-3AB13-3B2A3B16-4B215-6B15-2B4A2B13-2B6-2B11-2B8-2B9-2B10-2B8-2B10-2B9-2B8-2B11-2B6-2B13-2B4A2B15-6B238-2B18-2B2A2B15-2B4-2B13-2B6-2B11-2B8-2B10-2B8-2B11-2B6-2B13-2B4-2B15-2B2A2B18-2B120-
