model
size = 30 14 12, scale = 0.05, origin = -y
material 
  colors = A:#222 B:#EEE C:#2F2F2F D:#A23625 E:#E2943B F:#C7802D G:#282828 H:#777
voxels
34-21B8-2(23B7-)5A6-8AG24-3A112-H2(29-B)81-21B8-2(23B7-)5A6-8AG24-3A112-H2(29-B)109-3B9(FE)F3B5-2B21D3B4-26B5-21AG8-6C4-8A12-5A2C7-3A13-4A2D2C23-2A-2D-3C29-C59-B29-B79-B11(EF)E3B2-2B24D2B2-2B25AB3-25AG4-C6A5C7A3CG7-8AGA6C2ACG10-9A3(GA)C14-2C2AG7AGC16-5C3(GA)C19-6CAG2A22-6CG27-2CGB27-2A49-2B12(FE)FB-2BD24CDB-2BA24-AB2-2A24-A3-CA21-ACG4-2A17-2ACG7-2A15-GAB10-C14-GAB12-C9-3AGAB24-2AGA26-3AB26-3A27-2A47-2B13(FE)3BD4CD2C2(DC)2(3DC)D2C3DC3BA26-AB2A25-AG-2C22-2AGC2-2A18-2AGAC5-2A16-2AGB9-C14-2AGB11-C9-5AGB13-C9-4AB25-3AG26-3AB26-3A27-2A17-B14(FE)2BD2(C2D)CD3C2(2D2C)D2C2(DC)D2BA26-ABDA25-2A-2C22-AGAC2-2A18-3AGC5-2A16-3AB8-2A14-3AB11-C9-6AB13-C9-4AB25-4A26-B2AB26-B2A27-2A17-B14(EF)2B2(DC2DC)2(D3C)DCD2C3DCD2BA26-ABDA25-2A-2C22-2AGC2-2A18-2AGAC5-2A16-2AGB8-2A14-2AGB11-C9-5AGB13-C9-4AB25-3AG26-B2AB26-B2A27-2A17-2B13(EF)3BD4CD2C2(DC)2(3DC)2D2(CD)C3BA26-AB2A25-AG-2C22-AGAC2-2A18-3AGC5-2A16-3AB9-C14-3AB11-C9-6AB13-C9-4AB25-4A26-3AB26-3A27-2A18-2B12(EF)EB-2BD24CDB-2BA24-AB2-2A24-A3-CA21-ACG4-2A17-2ACG7-2A15-GCB10-C14-GAB12-C9-3AGAB24-2AGA26-3AB26-3A27-2A49-B11(FE)F3B2-2B24D2B2-2B25AB3-25AG4-C6A4C8A3CG7-8AGA5C3ACG10-9A3(GA)C14-2C10AGC16-5C3(GA)C19-6CAGA23-6CG27-2CGB27-2A50-3B9(EF)E3B5-2B21D3B4-26B5-21AG8-6C4-8A12-5A2C7-3A13-4A2D2C23-2A-2D-3C29-C59-B29-B77-
