model
size = 32, scale = 0.05, origin = -y
material 
  colors = A:#290068 B:#BA3AE1 C:#DE53D4 D:#FA72B2 E:#9D25EC F:#FC8980 G:#7307FB H:#FE975B I:#FEA545
voxels
-13A6D12A24-8A6(24-A6GA)24-AE5GA24-A2E4GA24-A3E3GA24-A4E2GA4-21A5EGA4-A7C10B9EA4-A8C10B8EA4-A9C10B7EA4-A10C10B6EA4-AD10C10B5EA4-A2D10C10B4EA4-21A3B3EA24-A4B2EA24-A5BE3(A24-A6B)26A6B2A13D11C6B2A14D11C5B2AF14D11C4B2A2F14D11C3B2A3F14D11C2B2A4F14D11CBA23(24-8A)24-264A24-8A9(24-7AB)13(24-7AC)24-7A7(D31A)DA9I11H10FD24-8A10(24-7AB)13(24-7AC)7(31AD)A8I11H10F2D24-8A24-7AE10(24-7AB)12(24-7AC)31AC6(31AD)A7I11H10F3D24-8A2(24-7AE)10(24-7AB)11(24-7AC)2(31AC)5(31AD)A6I11H10F4D24-8A3(24-7AE)10(24-7AB)10(24-7AC)3(31AC)4(31AD)A5I11H10F5D24-8A4(24-7AE)10(24-7AB)9(24-7AC)4(31AC)3(31AD)A4I11H10F6D21(24-8A)3(24-7AC)5(31AC)31AD45A2H4F13A600-2(8A24-)3(7AC24-)6(7AC12-8A4-)8A12-8A4-8A12-AH5FA580-2(8A24-)4(7AC24-)5(7AC12-8A4-)8A12-8A4-8A12-8A24-A6FA548-2(8A24-)7AB5(24-7AC)3(12-8A4-7AC)2(12-8A4-8A)12-2(8A24-)A6FA516-2(8A24-)3(7AB24-)3(7AC24-)3(7AC12-8A4-)8A12-8A4-8A12-3(8A24-)A6FA484-2(8A24-)5(7AB24-)2(7AC24-)2(7AC12-8A4-)8A12-8A4-8A12-4(8A24-)A6FA452-2(8A24-)7(7AB24-)7AC24-7AC2(12-8A4-8A)12-5(8A24-)A6FA420-2(8A24-)9(7AB24-)8A12-8A4-8A12-6(8A24-)A6FA388-2(8A24-)9(7AB24-)8A24-8A12-7(8A24-)A6FA356-2(8A24-)9(7AB24-)8A24-8A44-7(8A24-)A6FA324-2(8A24-)9(7AB24-)8A24-8A76-7(8A24-)A5FDA292-2(8A24-)2(7AE24-)7(7AB24-)8A24-8A108-7(8A24-)A4F2DA260-2(8A24-)4(7AE24-)5(7AB24-)8A24-8A140-7(8A24-)A3F3DA228-2(8A24-)6(7AE24-)3(7AB24-)8A24-8A172-7(8A24-)A2F4DA196-2(8A24-)8(7AE24-)7AB2(24-8A)204-7(8A24-)AF5DA164-2(8A24-)9(7AE24-)8A24-8A236-7(8A24-)A6DA132-2(8A24-)9(7AE24-)8A24-8A268-7(8A24-)A6DA100-2(8A24-)2(7AG24-)4(7AE24-)7A2(E4-27A)E6(4-28A)4(24-8A)24-245A6D13A56-2(8A24-)4(7AG24-)3(7AE24-)7A7(E4-27A)B4-27A5(B24-7A)4(B31A)3(C31A)C13A6D13A2(24-8A)6(24-7AG)3(24-7AE)7(4-27AE)4-27A5(B24-7A)5(B31A)2(C31A)C13A6D13A24-8A8(24-7AG)2(24-7AE)8(4-27AE)5(24-7AB)5(31AB)2(31AC)13A6D13A24-8A9(24-7AG)24-7A8(E4-27A)2(E24-7A)3(B24-7A)7(B31A)C13A6D13A24-8A10(24-7AG)8(4-27AE)2(24-7AE)3(24-7AB)7(31AB)13A6D13A24-8A10(24-7AG)4-27AG7(4-27AE)3(24-7AE)2(24-7AB)7(31AB)13A6D13A
