model
size = 24 24 27, scale = 0.05, origin = -y
material 
  colors = A:#555 B:#777 C:#444
voxels
75-C500-12B12-B23-3(B-3B19-)6(B23-)B311-12AB11-3(12A12-)3(11A13-)10A14-9A15-7A17-3A21-2A22-B297-3AB20-4(3A21-)2(2A22-)2A15-8A16-7A17-5A16-4A20-3A21-B274-3AB20-5(3A21-)2(2A22-)2A15-8A16-7A17-5A15-5A19-4A20-B251-3AB20-6(3A21-)2(2A22-)2A15-8A16-7A17-5A14-6A18-5A19-B228-3AB20-7(3A21-)2(2A22-)2A15-2(7A17-)5A13-2(6A18-)B205-3AB20-8(3A21-)2A22-2A15-9A15-7A17-7A10-12A12-2(7A17-)B181-4AB19-8(4A20-)2(3A21-)3A14-2(8A16-)8A2B7-12A2-3B7-8A6-4B6-8A7-4B5-B15-4B2(21-3B)90-5AB18-9(5A19-)4A20-4A18-6A18-4A20-4A15-6A-3B14-6A-4B6-9A6-4B5-9A7-4B4-B16-3B21-3B90-6AB17-9(6A18-)5A19-5A17-7A17-5A19-5A14-7A17-7A10-14A10-2(10A14-)B109-6AB17-9(6A18-)5A19-5A17-7A17-5A19-5A14-2(7A17-)7A10-2(10A14-)B109-3(7AB16-9(7A17-)6A18-6A16-8A16-6A18-6A13-10A14-8A16-8A9-14A10-2(11A13-)B85-)6AB17-9(6A18-)5A19-5A17-7A17-5A19-5A14-2(7A17-)7A10-2(10A14-)B109-6AB17-8(6A18-)6A4B2(14-5A5B)12-7A17-5A19-5A14-7A17-7A10-14A10-2(10A14-)B6-3(3B21-)3B28-5AB18-8(5A19-)5A5B2(14-4A6B)12-6A18-4A20-4A15-6A18-6A11-2(9AB14-)B6-4(3B21-)3B28-4AB19-8(4A20-)2(3A7B14-)3A7B7-2(8A16-)8A9-12A12-2(7A3B14-)B6-5(3B21-)3B28-3AB20-8(3A21-)2A22-2A15-9A15-7A17-7A10-12A12-2(7A17-)B180-3AB20-7(3A21-)2(2A22-)2A15-2(7A17-)5A13-2(6A18-)B203-3AB20-6(3A21-)2(2A22-)2A15-8A16-7A17-5A14-6A18-5A19-B226-3AB20-5(3A21-)2(2A22-)2A15-8A16-7A17-5A15-5A19-4A20-B249-3AB20-4(3A21-)2(2A22-)2A15-8A16-7A17-5A16-4A20-3A21-B263-12AB11-3(12A12-)3(11A13-)10A14-9A15-7A17-3A21-2A22-B287-12B12-B23-3(B-3B19-)6(B23-)B386-C500-
