model
size = 27 27 29, scale = 0.05, origin = -y
material 
  colors = A:#BBB B:#AAA C:#888 D:#DDD E:#09F F:#080 G:#006
voxels
11-2F2CA23-A-C695-A-8A18-B4AFBA692-11A16-A2B4A2B2A690-14AB12-ADAB3A2B2A2BA687-15AB11-3ADBAC2BF2AB2CB685-19A8-2AF2AD2BCAF2ABCA2BA681-21A7-3AFA3BACAFA4B3A681-11A3-8AC4-4A2BADBAC3A3B4A2B15-CFG661-14A-7A5-3ACAG5-4A-5AB11-GD2BC3-GB18-ADBAC2FG19-BA2B2CBG23-ACB580-11A4-7A2C3-ABA-A2-4A3-A2-3ACB2A7-2C-7A2-A2(16-C8-2A)17-CADB3-GB19-CD2B2CF23-BC526-8A9-5ACAC2-6A-A8-A2-2ACBAC8-2A6-2A2-A14-C-6A4-A14-F11-A14-2F9-A16-FA7-B18-F2CA2-CAB19-BCD2BCA23-2B472-7A2-C2A6-7AF-5A-A2-3A5-A2-A2B3A6-2A2-5A-2A2-A12-A-2A3-A-A3-A13-A6-A5-A14-A11-A14-A10-A16-F9-A17-F7-B18-FADC2-CA20-BDC2BC24-CB25-2B391-6A2-A10-6AF-2AEA-A2-A8-2A-3B3A5-2(A-)A7-A2-B11-A2-A2(-3A)3-A11-F6-2(A-)A3-A12-A6-A5-A14-A11-A14-A10-A16-A9-A16-B8-B18-A6-B2(20-FDC2-CA)20-AFCABC24-GB336-7A13-6AFC2A2E-A12-A3-B3A5-E-A7-A-2A2-CB9-F2-5A2-A-A2-C11-C3-4A2-A-A2-A12-B2-4A2(-A)3-B13-B2-5A4-A14-B5-2(2A3-A16-B4-)2(2A2-A18-B3-)2A-B19-B3-2A-B20-B2-2A-B20-BDC2AC21-2ACABC21-ADCBCA24-GC25-BC26-C202-6A13-7A-4C-A13-A2-4F5-EA10-3A-FG9-E-2A8-F2-F11-E2-A8-F2-C12-B-A6-AF3-C12-C2-A5-F3-C14-F2-3A2-A18-F4-2(A2-)C16-F3-A2-A19-F3-A2-A2(20-F2(2-A))20-F2-A2-B21-B-A2-2(B21-B2-A-)A21-FDGA-A24-2(G26-)BA26-2(A25-D)95-6A13-7A-2AF2-A13-A3-2AF4-B2-A10-A-2A2G8-B-A9-A-AG11-E-A9-B15-E-2A6-B16-E2-A5-A18-E2-3A2-A18-D4-A2-A19-A3-A2-A19-D3-A2-A20-2(A2-)A-C18-D2-A2-C20-F2-A2-C21-F-A2-C21-2(D-A24-)D-A25-DA25-2D2-G26-G24-A-G24-2(A26-)D-D66-6A13-7A-D2A2-A13-A3-3A4-B2-A10-A-AGBD8-D-A9-A-A12-D-A9-A15-D-2A6-B3-G12-E2-A5-A3-G14-E2-3A2-C3-G14-E4-2(A2-C2-B16-E3-)2(A2-C-B18-E2-)A2-A-B18-E2(2-A)D20-E-A2-AD20-2(E-A2-D21-)E-2(E2-D23-)G2-2(E26-)E24-G-D26-D24-G-A24-A-A26-A12-6A13-7A-3D2-A13-A3-3A4-B2-A12-G11-D-A10-AG12-D-A9-AD-G12-D-2A7-D2-B12-A2-A5-AD2-A14-A2-3A2-A3-B14-A4-2(A2-)A16-A3-2(A2-)B16-A3-A2-A2(-B18-2(A2-)D)-B18-2(A2-)AB20-A-A2-AF20-A2(-A2-C21-D)-D2-C23-E2-C23-G2-C2(24-D-F)24-A-F24-D-F24-A-A2(24-3A)13-5A14-6A2-3A-A13-AEB4D5-A-A12-D12-A-A9-2AG12-A-A10-AD12-A-A7-3AD14-A-4A2-D-A-B14-A5-2A3-B16-A4-2A3-B16-G4-2A2-D18-G3-2A2-F18-G3-2A-C19-G3-2A-C20-DAE2AEC20-DAEFAC21-DAEFC22-2A2EC22-2AFEC23-AFEC25-EA25-2A3(26-A)95-5A13-6A3-A2G-A13-AEB3A6-2A13-D12-3A9-2AE12-A-A9-A-D12-2(A-)2A6-AB14-A-A2-2A-DA-B16-G5-D2-2A16-G8-C18-G7-C19-AEA2-AC20-A2EBAE21-2AEBAE24-FA365-5A12-7A3-A3GA12-A-EB3D7-D2A9-2AE12-D2-A8-AE13-D2-A8-AE14-D-2A-A-5A16-G2-A-2A2-AC16-DA7-C18-2AEA2-AE20-AEACBAE23-CB447-5A11-7A4-4GA10-A-BEB3A8-3A7-A-B14-A-A4-4AC15-G-A4-4AC16-G-4A3-AC17-2AEB2-AGE19-AE2BA2G23-2B502-6A7-9A5-A2G3A7-A-2AE4B9-A-3A2-3AC16-2AEBF2A-FC17-2A2EBA2-2C18-2AEB3AC23-BA556-21A6-5A-7ACAGAE3A11-2BEC3AF23-3C24-CAC610-19A8-4ABAE2(CA)2F2CA2EA685-2B11AC2A11-A2BAEA2C2AF2ACAE688-10AC16-BFEA3C4A694-AC4A21-C2A2CA698-2A25-2A686-
