model
size = 20 10 10, scale = 0.05, origin = -y
material 
  colors = A:#111 B:#967249 C:#78552B D:#CA7A2C E:#F05E1C F:#AF5F3C
voxels
28-4B16-4C156-4B16-4C37-2A136-B4-B14-6C15-4B17-2(2A18-)2A95-B6-B12-C6-C13-B4-B15-4D17-2A16-6A7-3A2-3A-2A-3A2-3A65-B8-B10-2C6-2C11-B6-B13-D4-D15-4E17-2A16-6A8-7A4-7A46-B8-B10-2C6-2C11-B6-B13-D4-D15-E2-E17-2F2(18-2A)11-5A6-5A27-B8-B10-2C6-2C11-B6-B13-D4-D15-E2-E17-2F38-2A18-2A12-2(3A8-)B8-B10-2C6-2C11-B6-B13-D4-D15-4E57-2A55-B6-B12-C6-C13-B4-B15-4D135-B4-B14-6C15-4B148-
