model
size = 30 21 30, scale = 0.05, origin = -y
material 
  colors = A:#555 B:#777
voxels
581-2B4-2B22-2B4-2B561-2B6-2B20-2B6-2B590-2B6-2B20-2B6-2B530-4(11A19-)11A51-2B2-2B24-2B2-2B410-4(15A15-)15A18-3(9A21-)9A141-7(9A21-)9A17-17A13-17A10-2B-17A2B8-2B-17A2B11-17A15-3(12A18-)12A138-7(12A18-)12A15-19A11-19A9-2B19AB8-2B19AB10-19A13-14A14-2B14A2B12-2B14A2B14-14A20-3(7A23-)7A19-7(14A16-)14A13-4(21A9-)21A11-16A13-B16AB12-B16AB13-16A17-3(11A19-)11A16-7(16A14-)16A11-23A4(7-3A17-3A)9-3(3A13-2A12-)18A15-3(13A17-)13A14-18A7(12-3A13-2A)10-5A13-5A4(7-3A17-3A)9-3(3A13-2A12-)4A11-3A14-3(2A11-2A15-)2A11-2A13-4A11-3A7(12-3A13-2A)9-6A13-6A4(5-4A17-4A)7-3(4A13-4A9-)5A11-5A12-3(2A11-2A15-)2A11-2A12-5A11-5A7(9-4A13-4A)7-6A13-6A5-4A17-4A2-2B-4A17-4A4B-4A17-4A2B3-4A17-4A7-4A13-4A8-B4A13-4AB7-B4A13-4AB8-2(5A11-)3(3A11-3A13-)2(3A11-)5A11-5A7(9-4A13-4A)6-7A13-6A4-5A17-4A2-2B5A17-4A4B5A17-4A2B2-5A17-4A7-4A13-4A8-B4A13-4AB7-B4A13-4AB8-2(2(5A11-)3(3A11-3A13-)2(3A11-)5A11-5A7(9-4A13-4A)6-7A13-6A4(4-5A17-4A)7-3(4A13-4A9-))2(2(5A11-)3(3A11-3A13-)2(3A11-)5A11-5A7(9-4A13-4A)6-7A13-6A4(4-5A17-4A)7-4A13-4A8-B4A13-4AB7-B4A13-4AB8-)2(5A11-)3(3A11-3A13-)2(3A11-)5A11-5A7(9-4A13-4A)6-7A13-6A4(4-5A17-4A)7-3(4A13-4A9-)2(5A11-)3(3A11-2A14-)3A11-2A12-5A11-5A7(9-4A13-4A)6-7A13-6A4-5A17-4A2-2B5A17-4A4B5A17-4A2B2-5A17-4A7-3(4A13-3A10-)5A11-4A13-3(2A11-2A15-)2A11-2A12-5A11-4A7(10-4A13-3A)8-6A13-6A5-4A17-4A2-2B-4A17-4A4B-4A17-4A2B3-4A17-4A8-3(3A13-2A12-)18A16-3(11A19-)11A15-18A7(12-3A13-2A)9-6A13-6A4(5-4A17-4A)9-2A13-A13-B2A13-AB12-B2A13-AB13-16A18-3(9A21-)9A17-7(16A14-)16A11-23A4(7-3A17-3A)11-14A14-2B14A2B12-2B14A2B14-14A20-3(7A23-)7A19-7(14A16-)14A12-23A4(7-3A17-3A)12-3(12A18-)12A22-3(5A25-)5A21-7(12A18-)12A14-4(21A9-)21A15-3(9A21-)9A141-7(9A21-)9A16-19A11-2(19A10-B)19A11-19A17-3(7A23-)7A143-7(7A23-)7A18-17A13-17A11-2B17AB10-2B17AB12-17A48-2B2-2B24-2B2-2B410-2(15A15-)2(15A2B13-)15A497-4(11A19-)11A501-7A23-2(7A22-B)7A23-7A562-2B4-2B22-2B4-2B41-
