model
size = 30 13 6, scale = 0.05, origin = -y
material 
  colors = A:#111 B:#222 C:#333 D:#444 E:#555
voxels
133-3A26-4(5A25-)5A26-3A177-3A26-4(5A25-)5A26-3A137-2A19-4A5-5A14-6A4-8A3-3A5-7A4-11AB2C12A4-10A5B12A2-11A2B2CB12A3-10AB3DB11A4-11A3B12A4-7A4-3A5-7A4-5A16-5A4-2A21-3A34-5A18-3A4-A2B4A14-6A2-2A2B3C3A11-A5BA2-3AB2CDCBA-4A2-4A3D2ECA2-7AB2CA2B2C2ACDC3BC2DE4A2C3B4A6BC9ACD2A7D4C2B2C2BC7B2AB3ABC3B2A3BC3D5B2C4DC2A-8A2B2AE2D2(3AB)C3DA2-ABA3B2C2A2(2-3A)B4A2BA2-A5C3A9-4AC4BA2-2AD4A14-3A3CA2-4A19-5A3-5A18-2A5-A2B4A14-6A2-2A2B3C3A11-A5BA2-3AB2CDCB2A-3A2-4A3D2ECA2-7AB2CBAB2C2ACDC3BC2DE5AC3B4A6BC9ACD2ADA5D4C2B2C2BC7B2AB4AC3B2A3BC3D5B2C4DC2A-8A2B2AE2D2ACB3ABC3DA2-3A3B2C2A2(2-3A)B4A2BA2-2A4C3A9-4AC4BA2-2AD4A14-3A3CA2-4A19-5A34-2A19-4A5-5A14-6A5-7A3-3A5-7A5-10AB2C12A5-9A5B12A2-A-9A2B2CB12A4-9AB3DB11A5-10A3B12A5-6A4-3A5-7A5-4A16-5A5-A21-3A32-
