model
size = 15 27 4, scale = 0.05, origin = -y
material 
  colors = A:#111
voxels
-14A349-7A7-9A4-13A350-2(7A7-9A4-13A-15A5-5A8-9A4-13A-285A2-11A6-)7A7-9A4-13A-15A
