model
size = 32 27 32, scale = 0.05, origin = -y
material 
  colors = A:#111
voxels
44-8A824-8A853-14A848-18A845-20A843-22A841-24A839-26A837-28A836-11A6-11A15-5(6A26-)6A654-10A10-10A12-5(2A6-2A22-)10A24-2(6A26-)6A558-9A12-9A11-5(A10-A20-)3A6-3A21-2(2A6-2A22-)10A24-2(6A26-)6A462-8A14-8A10-5(A12-A18-)3A8-3A19-2(2A8-2A20-)3A6-3A22-2(A6-A24-)8A25-3(6A26-)6A333-9A14-9A9-5(A12-A18-)2A10-2A19-2(A10-A20-)2A8-2A21-2(A8-A22-)3A4-3A23-3(2A4-2A24-)8A26-2(4A28-)4A238-8A16-8A8-5(A14-A16-)2A12-2A17-2(A12-A18-)2A10-2A19-2(A10-A20-)3A6-3A21-3(2A6-2A22-)3A4-3A24-2(A4-A26-)A4-A27-2(4A28-)4A142-8A16-8A8-5(A14-A16-)2A12-2A17-2(A12-A18-)2A10-2A19-2(A10-A20-)2A8-2A21-3(A8-A22-)2A6-2A23-2(A6-A24-)A6-A25-2(6A26-)6A27-4A28-4A78-2(8A16-8A8-5(A14-A16-)2A12-2A17-2(A12-A18-)2A10-2A19-2(A10-A20-)2A8-2A21-3(A8-A22-)2A6-2A23-2(A6-A24-)A6-A25-2(6A26-)6A27-4A28-4A29-2A30-2A15-)8A16-8A8-5(A14-A16-)2A12-2A17-2(A12-A18-)2A10-2A19-2(A10-A20-)2A8-2A21-3(A8-A22-)2A6-2A23-2(A6-A24-)A6-A25-2(6A26-)6A27-4A28-4A78-8A16-8A8-5(A14-A16-)2A12-2A17-2(A12-A18-)2A10-2A19-2(A10-A20-)3A6-3A21-3(2A6-2A22-)3A4-3A24-2(A4-A26-)A4-A27-2(4A28-)4A142-9A14-9A9-5(A12-A18-)2A10-2A19-2(A10-A20-)2A8-2A21-2(A8-A22-)3A4-3A23-3(2A4-2A24-)8A26-2(4A28-)4A239-8A14-8A10-5(A12-A18-)3A8-3A19-2(2A8-2A20-)3A6-3A22-2(A6-A24-)8A25-3(6A26-)6A334-9A12-9A11-5(A10-A20-)3A6-3A21-2(2A6-2A22-)10A24-2(6A26-)6A462-10A10-10A12-5(2A6-2A22-)10A24-2(6A26-)6A559-11A6-11A15-5(6A26-)6A655-28A837-26A839-24A841-22A843-20A845-18A848-14A841-
