model
size = 32, scale = 0.05, origin = -y
material 
  colors = A:#99F B:#777 C:#888 D:#AAA E:#444 F:#63F G:#555 H:#E00 I:#111 J:#222
voxels
678-H18-H76-H18-H725-3(2A30-)2A830-3(2A30-)2A29-F2AF28-F2AF29-3(2A30-)2A638-2A30-2A29-10(F2AF28-)F2AF29-2A30-2A510-2A29-3(F2AF28-)F2AF27-8(B4AB26-)B4AB27-4A28-F2AF29-2A478-2A29-F2AF28-F2AF27-2(B4AB26-)B4AB25-8(D6AD24-)D6AD25-B4AB27-4A28-F2AF29-2A414-2A29-F2AF28-F2AF27-B4AB25-3(D6AD24-)D6AD23-6(2D6A2D22-)2D6A2D23-D6AD24-D6AD25-B4AB27-F2AF29-2A382-2A29-F2AF28-F2AF27-B4AB25-2(D6AD24-)D6AD23-D8AD22-D8AD21-6(2D8A2D20-)2D8A2D21-D8AD22-D8AD23-D6AD25-B4AB27-F2AF29-2A350-2A29-F2AF27-B4AB26-B4AB25-8(D6AD24-)D6AD23-2D6A2D21-3D6A3D19-C3D6A3DC19-3D6A3D21-D8AD23-D6AD25-B4AB27-F2-F29-2A318-2A29-F2AF27-B4AB26-B4AB25-DB4ABD24-DB4ABD25-6(B4AB26-)B4AB25-D6AD23-D8AD21-2D8A2D19-CD10ADC19-D10AD21-D8AD20-B2ED6AD2EB17-BA2E-B4AB-2EAB21-BA2-AB27-F2AF29-2A286-2A29-F2AF27-BF2AFB26-BF2AFB25-DBF2AFBD24-DBF2AFBD26-5(F2AF28-)F2AF27-B4AB25-D6AD23-D8AD21-2D8A2D19-CD10ADC19-D10AD11-E9-D8AD9-E2-G6-2B2ED6AD2E2B6-G2-BA6BA2ED6AD2EA6BAB2-E11-BA2-AB11-E15-C2-C29-2A254-2A29-F2AF27-BF2AFB26-BF2AFB25-DBF2AFBD24-DBF2AFBD25-BF2AFB27-F2AF29-3(2A30-)2A29-F2AF27-B4AB25-D6AD24-D6AD22-2D8A2D19-C12AC19-12A11-E7-C2D8A2DC7-E2-G5-3B2E8A2E3B5-G-HBA6BA2E8A2EA6BABH-E9-EC2A2-2ACE9-E14-BA2-AB27-C2AC29-2A222-2A29-F2AF27-BF2AFB26-BF2AFB25-DBF2AFBD25-BF2AFB27-F2AF29-2A126-2A30-2A29-C2AC27-BC2ACB25-DB4ABD22-2D8A2D19-G12AG18-G12AG10-E7-C12AC7-E2-G3-5B2E8A2E5B3-G-HBA6EA2E8A2EA6EABH-E9-EC2A2-2ACE9-E14-B4AB26-2C2A2C28-2A190-2A29-F2AF27-BF2AFB26-BF2AFB25-DBF2AFBD25-BF2AFB27-F2AF29-2A190-2A29-C2AC27-BC2ACB25-DB4ABD22-2D8A2D20-D10AD19-2D10A2D10-E6-2C12A2C6-E2-G5-2BD2E8A2ED2B5-G2-BA6BA2(2E3A)2EA6BAB2-E9-EC2A2-2ACE9-E14-B4AB26-2C2A2C28-2A190-2A29-F2-F27-BF2AFB25-DBF2AFBD25-BF2AFB27-F2AF29-2A253-C2AC27-BC2ACB25-DB4ABD22-B-D6AD-B20-DC8ACD19-2D10A2D10-E7-D12AD7-E10-D2E8A2ED14-4BA2(2E3A)2EA4B6-E9-EC2A2-2ACE9-E12-EC6ACE24-B4AB27-I2AI29-2H126-2A29-F2AF28-F2AF27-BF2AFB26-BF2AFB27-F2AF29-2A285-C2AC28-C2AC27-B4AB23-B-C6AC-B20-2C8A2C19-C12AC10-G7-D12AD7-G10-D2E8A2ED19-2E3A2-3A2E11-G8-2EC2A2-2AC2E8-G12-E-6A-E22-E-B4AB-E25-I2-I29-2H126-2A29-F2AF27-BF2AFB26-BF2AFB27-F2AF29-2A318-2C30-2C28-BC2ACB23-B-C6AC-B20-2C8A2C19-C12AC10-E7-C12AC7-E10-D12AD19-D4A2E4AD11-E8-DAC2A2-2ACAD8-E11-DAC6ACAD21-EC6ACE24-CI2-IC28-4(2H30-)2A28-BF2AFB27-F2AF28-F2AF29-2A382-2C28-BC2ACB23-B-G6AG-B20-2C8A2C19-C12AC10-G7-C12AC7-G10-C12AC18-D5A2-5AD10-G8-DAC2A2-2ACAD8-G11-DAC6ACAD21-EC6ACE24-C4AC27-4H28-4H29-2H61-F2AF29-2A30-2A476-6C25-EC-2A-CE22-BCEC4ACECB20-4C4A4C11-E7-2C10A2C7-E10-2C4A2E4A2C18-2C4A2-4A2C10-E8-DAC2A2-2ACAD8-E11-DAC6ACAD21-EC6ACE24-CA2-AC27-4H29-2H94-2F540-6C25-EC4ACE24-EC4ACE22-4C4A4C11-G7-2C4A2-4A2C7-G10-2C4A2-4A2C18-2C4A2-4A2C10-G8-5C2-5C8-G11-5C2A5C21-4C2A4C24-2C2-2C28-2H670-2C27-E6CE24-E6CE22-12C11-I8-C4A2-4AC8-I10-2C4A2-4A2C19-C3AE2-E3AC11-I8-5C2-5C8-I12-4C2A4C23-3C2A3C25-2C2A2C28-2H670-2B27-G6BG24-G6BG18-EDG-4B4A4B-GDE7-H6-G-4B4A4B-G6-H9-EC4B4I4BCE14-EDG-4B4A4B-GDE7-H8-4B4A4B8-H12-3B4A3B23-2B4A2B25-6B699-4B26-EB4ABE24-E6AE18-EDG-2B8A2B-GDE14-G-B10AB-G16-EGB2A6I2ABGE14-EDG-BA8HAB-GDE16-B10AB21-B8AB23-B6AB25-6B729-G-4G-G25-G4AG19-EDG3-2GA2IA2G3-GDE14-G2-G3A2I3AG2-G16-E3GA6IA3GE14-EDG2-GH6-HG2-GDE17-GA6IAG23-G6AG25-6G761-E6-E26-4G20-E7-G2-G7-E18-E2G2-2GE24-E6IE18-E4-JE6-EJ4-E18-E6IE25-6G793-G6-G50-E18-E51-6E19-E4-J8-J4-E19-6E825-J6-J50-E18-E76-E4-J8-J4-E850-H6-H50-2(G18-G76-G4-E8-E4-G908-E18-E76-E4-J8-J4-E908-)I18-I76-I4-H8-H4-I262-
