model
size = 19 30 31, scale = 0.05, origin = -y
material 
  colors = A:#111 B:#0F0 C:#E00 D:#777 E:#00E F:#93C G:#C09 H:#FF6 I:#F06 J:#F6F K:#FC9
voxels
527-H569-I80-D4(-D13-D-2D)-D13-D-D375-2(I18-)I42-D-D13-D-DA4(-A13-A-2A)-A13-A-AD-D13-D-D356-G18-J18-G23-D-D13-D-DA6(-A13-A-2A)-A13-A-AD-D13-D-D318-I3(18-G)18-I4-D-D13-D-DA4(-A13-A-2A)-H2(13-A-2A-A)13-A-AD-D13-D-D318-2(H18-I18-)H4-D-D13-D-DA2(-A13-A-2A)-A13-A-A19C2(A-)2(C9-C-A-2A-A-)C9-C2(-A)2(D-)11H2(-D)4-2(11H8-)2(11K8-)2(11J8-)2(11I8-)2(11G8-)2(11F8-)11E8-11E7(18-C)4-D-D13-D-DA6(-A13-A-2A)-A-C9-C2(-A)2(D-)C9HC2(-D)4-2(H9BH8-)K9BK8-K9-K2(8-J9-J)2(8-I9-I)2(8-G9-G)2(8-F9-F)2(8-E9-E)137-D-D13-D-DA6(-A13-A-2A)-A13-A-A2(D-)C9HC2(-D)4-C9BC8-H9BH8-K9BK8-K9-K2(8-J9-J)2(8-I9-I)2(8-G9-G)2(8-F9-F)2(8-E9-E)156-D-D13-D-2D4(-A13-A-2A)-A13-A-AD-D13-D-D23-C9HC8-C9BC8-K9BK8-K9-K2(8-J9-J)2(8-I9-I)2(8-G9-G)2(8-F9-F)2(8-E9-E)175-D4(-D13-D-2D)-D13-D-D61-C9HC8-C9BC8-K9-K2(8-J9-J)2(8-I9-I)2(8-G9-G)2(8-F9-F)2(8-E9-E)350-11C8-C9-C2(8-J9-J)2(8-I9-I)2(8-G9-G)2(8-F9-F)2(8-E9-E)369-C9KC8-C9BC8-J9-J2(8-I9-I)2(8-G9-G)2(8-F9-F)2(8-E9-E)388-C9JC8-C9BC2(8-I9-I)2(8-G9-G)2(8-F9-F)2(8-E9-E)407-C9JC8-C9BC8-I9-I2(8-G9-G)2(8-F9-F)2(8-E9-E)426-C9IC8-C9BC2(8-G9-G)2(8-F9-F)2(8-E9-E)445-C9IC8-C9BC8-G9-G2(8-F9-F)2(8-E9-E)464-C9GC8-C9BC8-F9BF8-F9-F2(8-E9-E)483-C9GC8-11C8-F9BF2(8-E9-E)483-11C8-C9FC8-C9BC2(8-E9-E)521-C9FC8-C9EC8-11E540-8(C9-C8-C9-C559-)C9-C559-C9AC4-
