model
size = 32 31 32, scale = 0.05, origin = -y
material 
  colors = A:#888 B:#AAA C:#777 D:#222 E:#444 F:#9CF G:#0C6 H:#9FF I:#6FF J:#93F K:#EEE L:#555 M:#36F N:#F90 O:#6CF P:#3F3 Q:#040 R:#500 S:#F6F T:#960 U:#080 V:#D00 W:#06F X:#660 Y:#390 Z:#396 Aa:#0C3 Ab:#0F9 Ac:#B00 Ad:#3C6 Ae:#E00 Af:#050
voxels
323-V24-V16-MD2AfDM26-6D761-Ae6-Ae153-MD2AcDM26-6D793-K6-K150-M2D2F2J2F2DM20-6DA5D24-4B730-K6-K23-KCK4-3K23-K6-K2(24-D6-D)24-D6ED20-MD5F2J5FDM16-8DA7D19-10B26-2E731-D6-D89-6E23-3E6D3E16-MD7F2J7FDM12-10D8A2D15-14B21-3E2A3E728-L6-L25-6A26-6C23-3E6C3E18-2E3D6C3D2E13-D9F2J9FD10-11D9A2D12-18B17-2E8A2E25-2B729-3A6-3A20-3C6-3C18-2E12C2E14-2E2D12C2DE11-D8F6A8FD8-12D9A3D10-20B14-2E12A2E21-6B725-2A12-2A16-2C12-2C15-E16CE13-ED16CDE9-M2FJ3F3A6C3A3FJ2FM6-10D12A4D8-22B12-E16AE19-9B722-A16-A14-C16-C10-E2-E18CE2-E6-E2-D18CDE-E6-D4F2A12C2A4FD6-7D3A6C6A4D7-24B10-E18AE16-4B4E4B721-A16-A10-E3-C16-C3-E6-E2-E4C10-4CE2-E5-4ED4C10-4CD4E4-M5FA2C10-2CA5FM4-7D2A10-4A5D6-24B9-E20AE14-2(4BE)4B23-4C692-A18-A9-E2-C18-C2-E5-4E5C10-5C4E4-3ED5C10-5CD3E4-D4F2A2C10-2C2A4FD4-7D2A10-2C2A5D5-2(9B8-)E20AE13-4BE6BE4B21-C4EC27-4D660-A18-A9-E2-C18-C2-E5-4E4C12-4C4E4-3ED4C12-4CD3E3-M5FA2C12-2CA5FM2-7DAC12-C2A6D4-5BA3B8-9B7-E22AE11-4BE8BE4B19-CE4AEC25-D4-D26-L4-L462-C28-L134-A20-A8-E-C20-C-E5-3E4C14-4C3E4-3E4C14-4C3E3-D4F2AC14-C2A4FD2-5DADA14-2A6D3-6BA3B8-10B6-E22AE11-3BE10BE3B18-CEA4-AEC23-DA4-AD24-LA4-AL24-O6-O2(24-I6-I)24-H6-H25-H4-H27-H2-H29-2H240-D28-D134-A20-A8-E-C20-C-E5-3E4C15-3C3E4-3E4C15-3C3E3-D4FA2C15-CA4FD2-5D2AC15-A6D3-5B2AB12-8B5-E24AE9-3BE2B8-2BE3B16-CE8-EC21-D8-D22-L8-L24-P4-P56-I8-I89-I2-I239-K28-K-KCK26-KEK-K28-K102-A20-A8-E-C20-C-E5-3E3C16-3C3E4-3E3C16-3C3E2-W5FAC16-CA5FM6DAC16-CA6D2-5BA2B12-8B5-E24AE9-3BE2B2(2-U)2-2BE3B16-CE8-EC21-D8-D22-L8-L24-P4-P55-I10-I88-I2-I239-K28-K-KCK26-KEK-K28-K101-A22-A8-C22-C7-E4C16-4CE5-DE4C16-4CED2-D4FA2C16-2CA4F7DAC16-CA6D-8B14-8B4-E24AE9-3BE2B-BU2BUB-2BE3B16-CE-6G-EC21-D-6G-D22-L-2G2Ab2G-L24-6G26-RV2ZVR23-I3-R2QR3-I88-I2-H157-T113-C28-C133-A22-A8-C22-C8-E3C16-3CE6-DE4C16-4CED2-5JA2C16-2CA5J6DAC16-CA6D-8B14-8B3-E26AE7-3BE3B-6B-3BE3B14-CEA-6G-AEC19-DA-6G-AD20-LA-6G-AL20-O2-AdH4G2-O20-I2-AdH4G2-I20-I3-Ad2QG3-I20-HI2(2-Aa)2-IH21-HI6-IH23-HI4-IH25-HI2-IH27-4H29-A32-A30-T32-2T2X30-X46-C27-3C-4(D28-D2-)D2-A22-A2-D2-2D-C22-C-2D3-D-E3C16-3CE-D4-DE4C16-4CED2-5JA2C16-2CA5J6DAC16-CA6D-8B14-8B3-E26AE7-3BE3B-6B-3BE3B14-CEA-6G-AEC19-DA-6G-AD20-LA-6G-AL20-O2-6G2-O20-I2-6G2-I20-I3-G2QG3-I20-HI2(2-Aa)2-IH21-HI6-IH23-HI4-IH25-HI2-IH27-4H2(30-A)32-T27-2X2T29-X51-C28-C133-A22-A8-C22-C8-E3C16-3CE7-E4C16-4CE3-D4FA2C16-2CA4F7DAC16-CA6D-8B14-8B4-E24AE9-3BE2B-BY2BYB-2BE3B16-CE-6G-EC21-D-6G-D22-L-2G2Ab2G-L24-6G26-RV2ZVR23-I3-R2QR3-I88-H2-H158-T112-C28-C134-A20-A10-C20-C9-E3C16-3CE7-3E2C16-3CDE3-W5FAC16-CA5FM6DAC16-CA6D2-7B14-7B5-E24AE9-3BE2B2(2-U)2-2BE3B16-CE8-EC21-D8-D22-L8-L24-P4-P55-I10-I88-H2-H271-C28-C134-A20-A10-C20-C9-E3C16-3CE7-3E2C16-3CDE4-D4FAC16-CA4FD2-5D2A16-2A5D3-8B12-8B5-E24AE9-3BE2B8-2BE3B16-CE8-EC21-D8-D22-L8-L24-P4-P56-I8-I89-H2-H271-K28-K134-A20-A10-C20-C9-E4C14-4CE7-3E3C14-4CDE4-D4F2AC14-C2A4FD2-5D3A14-3A5D3-8B12-8B6-E22AE11-3BE10BE3B18-CEA4-AEC23-DA4-2D24-LA4-AL24-OY4-YO2(24-I6-I)24-H6-H25-H4-H27-H2-H29-2H240-Ae28-Ac135-A18-A12-C18-C10-2E3C14-3CE8-ECED2C14-3CD2E4-W5FAC14-C2A4FM2-6D2A14-3A5D4-9B8-9B7-E22AE11-4BE8BE4B19-CE4AEC25-D4-D26-L4-L627-A18-A12-C18-C10-2E5C10-5CE8-ECED4C10-4CAD2E5-D4FA3C10-2C3A3FD4-5D4A10-2A7D5-2(9B8-)E20AE13-4BE6BE4B21-C4EC27-4D661-A16-A14-C16-C12-2E4C10-4CE9-E-ED4C10-3CADE-E5-W5F2AC10-C3A4FM4-5D4A10-A8D6-24B9-E20AE14-2(4BE)4B23-4C693-A16-A14-C16-C13-E18CE9-E2-2E16CADE-E6-D4F3A10C4A3FD6-8D2A6C3A7D7-24B10-E18AE16-4B4E4B722-2A12-2A16-2C12-2C15-E16CE10-E2-ED2E12C2ADE2-E6-W2FJ3F3A6C6AJ2FM6-8D11A7D8-22B12-E16AE19-9B725-3A6-3A20-3C6-3C18-2E12C2E11-E3-E2D2EA6C3A2DE3-E7-D7F10A5FD8-7D11A6D10-20B14-2E12A2E21-6B730-6A26-6C23-3E6C3E13-E4-2E3D6A3D2E4-E8-D7F6A7FD10-6D11A5D12-18B17-2E8A2E25-2B796-6E15-NEN5-3E6D3E5-NEN8-WD7F2J7FDM12-5D11A4D15-14B21-3E2A3E815-N24-N5-NEN8-6E8-3N5-N4-MD5F2J5FDM4-N11-3D11A2D19-10B26-2E818-S24-S5-SES22-SES5-S6-M2D2F2J2F2DM6-S13-12D24-4B590-
