model
size = 22 25 20, scale = 0.05, origin = -y
material 
  colors = A:#FF0 B:#888 C:#222
voxels
26-2(3(14A8-)2(14B8-))6(14A8-)4A6-4A2(8-3A)162-2(14A8-)2(2(14B8-)3(14A8-))2(14A8-)2(3A8-)2A10-2A8-A12-A183-2(A14-A6-)2(2(B14-B6-)3(A14-A6-))4(A14-A6-)2A12-2A7-2(A12-A8-)A12-A116-2(A16-A4-)2(2(B16-B4-)3(A16-A4-))4(A16-A4-)2A14-2A5-2(A14-A6-)2A12-2A7-A12-A93-2(A18-A2-)2(2(B18-B2-)3(A18-A2-))4(A18-A2-)2A16-2A3-2(A16-A4-)2A14-2A5-2A12-2A7-A12-A70-A20-2A2(20-AB20-2B20-BA2(20-2A))4(20-2A)20-3A2(18-4A)18-2A-2A16-2A3-2A14-2A5-2A12-2A7-A12-A158-A20-2A20-A265-A18-A2-2A16-2A3-2A14-2A5-2A12-2A157-A20-2A20-A287-A18-A2-2A16-2A3-3A12-3A6-A12-A136-A20-2A20-A309-A18-A2-3A14-3A3-3A12-3A134-A20-2A20-A331-A18-A2-4A12-4A133-C20-2C20-C353-3A14-3A133-A20-2A20-A353-3A14-3A133-C20-2C20-C331-A18-A2-4A12-4A133-A20-2A20-A309-A18-A2-3A14-3A3-3A12-3A134-A20-2A20-A287-A18-A2-2A16-2A3-3A12-3A6-A12-A136-A20-2A20-A265-A18-A2-2A16-2A3-2A14-2A5-2A12-2A25-2(A2(20-2A)20-AB20-2B20-B)A6(20-2A)20-3A2(18-4A)18-2A-2A16-2A3-2A14-2A5-2A12-2A7-A12-A27-2(3(A18-A2-)2(B18-B2-))7(A18-A2-)2A16-2A3-2(A16-A4-)2A14-2A5-2A12-2A7-A12-A50-2(3(A16-A4-)2(B16-B4-))7(A16-A4-)2A14-2A5-2(A14-A6-)2A12-2A7-A12-A73-2(3(A14-A6-)2(B14-B6-))7(A14-A6-)3A10-3A7-2A10-2A2(8-A12-A)92-
