model
size = 18 18 32, scale = 0.05, origin = -y
material 
  colors = A:#111 B:#06F C:#0CF
voxels
7-6A11-6A10-10A6-4A6B4A4-2A10B2A3-2A12B2A2-2A12B2A-2A5(14B4A)14B2A-2A2BC9B2A2-2A2B2C8B2A3-2A10B2A4-4A6B4A6-10A119-4A13-3(A4BA12-)A4B4(A13-4A230-4A13-3(A4-A12-)A4-)A13-4A212-2(4A13-A4-A11-3(A6-A10-)A6-A11-A4-A13-4A194-)4A13-A4-A11-3(A6-A10-)A6-A11-A4-A13-4A175-3(6A11-2A4-2A9-2A6-2A8(8-A)8-2A6-2A9-2A4-2A11-6A156-)6A11-2A4-2A9-2A6-2A8(8-A)8-2A6-2A9-2A4-2A11-6A138-4(6A11-A6-A9-A8-A7-5(A10-A6-)A10-A7-A8-A9-A6-A11-6A120-)6A11-A6-A9-A8-A7-5(A10-A6-)A10-A7-A8-A9-A6-A11-6A84-5(6A10-10A7-3A6-3A5-3A8-3A4-2A10-2A3-5(2A12-2A2-)2A12-2A3-2A10-2A4-3A8-3A5-3A6-3A7-10A10-6A48-)6A10-10A7-3A6-3A5-3A8-3A4-2A10-2A3-5(2A12-2A2-)2A12-2A3-2A10-2A4-3A8-3A5-3A6-3A7-10A10-6A30-7(6A10-10A2(6-4A)4-2A10-2A3-2A12-2A2-2A12-2A-2A5(14-4A)14-2A-2A12-2A2-2A12-2A3-2A10-2A4-2(4A6-)10A10-6A12-)6A10-10A2(6-4A)4-2A10-2A3-2A12-2A2-2A12-2A-2A5(14-4A)14-2A-2A12-2A2-2A12-2A3-2A10-2A4-2(4A6-)10A10-6A6-
