model
size = 28 32 32, scale = 0.05, origin = -y
material 
  colors = A:#FCC B:#555 C:#777 D:#888 E:#F0C F:#F9C G:#111 H:#F3F I:#222 J:#FCF K:#969 L:#3CC M:#E00 N:#444 O:#F9F P:#F60 Q:#3CF R:#99C S:#F3C T:#39C U:#F99 V:#0FC W:#6FF X:#F96 Y:#C39 Z:#FC3
voxels
457-H8-H18-E8-E16-HEH8-HEH13-HE12-EH11-HE14-EH795-16B822-2B16-2B9-2B14-2B11-7C2N7C18-B2VB25-2B745-2B16-2B8-2C16-2C9-2C14-2C11-2BCBC2B2C2BCBC2B19-2B745-2B16-2B5-V3NC16-C3NV5-BC16-CB9-BC14-CB11-B6C2N6CB19-2B612-6D50-2A2-2A18-6B2-6B12-2B14-2B9-2(2C16-2C8-)2C16-2C9-2C14-2C11-B5C4N5CB16-A6-A607-2D6C2D21-A2-A21-4A2-4A15-7C2B7C11-2C14-2C9-2C16-2C2(8-BC16-CB)9-BC14-CB11-B14CB14-J4A2-4AJ17-2A6-2A577-D2C6B2CD19-2A2-2A20-4A2S4A15-16C11-2C14-2C9-2C16-2C8-BC16-CB8-2C16-2C9-2C14-2C11-7C2N7C14-4A4-4A16-4A4-4A17-A8-A526-2D19-D2C10B2CD17-JA2SAJ20-J3A2-3AJ15-4C3A2C3A4C11-2C14I2C9-CA4IV6IV4IAC8-NA3IVIV4IVIV3IAN8-2A2(2IV3IV)2I2A9-2A14I2A11-C6A2C6AC14-5A2-5A17-3A4-3A18-2A6-2A523-8B15-DC14BCD14-2A6-2A18-4A2-4A15-3A-3A2-3A-3A11-CA14BAC9-3A14B3A8-N2A14B2AN8-3A14B3A9-AJ14BJA11-7A2-7A12-7A2-7A14-4A4-4A17-J2A4-2AJ497-B2DB20-12B12-DC16BCD13-2A6-2A19-3A2-3A14-9A2-2(9A8-9A2F)9A8-B5A-2A2F2A-5AB7-4A2-4A2O4A2-4A7-AOA2-3AK2-K3A2-AOA9-O7A2-7AO11-J5AJ2-J5AJ13-NJ3A4-3AJN14-NCAYA4-AYACN14-NCO8-OCN465-8B17-14B11-DC16BCD12-3A6-3A14-5A6-5A12-7A2F7A9-10A2F10A7-6A-2A2F2A-6A8-B5A-2A2X2A-5AB6-11A2X11A5-10A2F10A7-AO6AK2-K6AOA9-8A2-8A7-H4-N4A4-4AN4-H4-2(EH)2E3A6-3A2E2(HE)9-NC2O6-2OCN15-E10-E16-E10-E409-3B4D3B16-14B10-DC18BCD9-J4A6-4AJ12-5A6-5A10-7A6G7A7-10A2F10A6-J6A-2A2F2A-6AJ6-2B5A-2A2X2A-5A2B5-4A-6A2X6A-4A5-10A2X10A6-9AK2FK9A7-8A4-8A5-2E3-5A6-5A3-2E8-N2AY6-Y2AN14-NCO8-OCN43-E10-E384-4B20-2B2D4B2D2B14-16B9-DC18BCD9-4A8-4A12-4AG6-G4A10-7A6G7A8-9A2F9A7-7A-2A2F2A-7A6-2B5A-2A2F2A-5A2B3-H-4A-6A2F6A-4A-HE2-10A2F10A2-EH2-10A2F10A2-H2E2-AJ7A2S7AJA2-2E-H4-7A2-7A4-H7-5A6-5A70-E10-E383-2B2-2B19-B2D2B2-2B2DB14-7B2-7B8-DC6B3G2-3G6BCD8-3A10-3A12-J3AG6-G3AJ11-6A2G2-2G6A8-10A2G10A6-7A-2A2F2A-7A3-H-B7A-2A2F2A-7AB-HE-AO9A2F9AOA-E3-10A2F10A6-2AU7A2F7AU2A7-8AK2-K8A10-2A2(2-3A)2-2A13-J3A6-3AJ14-5A4-5A43-E10-E160-4Q24-Q2-Q24-4Q80-Z2-Z52-P2-P22-2BP2-P2B17-2BD2BP2-P2BD2B13-6BP2-P6B8-DC8BP2-P8BCD7-4A3-P2-P3-4A11-4AG-P2-P-G4A10-6A2GP2-P2G6A7-9A4G9A3-H2-AU5A-2A2F2A-5AUA2-HE-B7A-2A2F2A-7AB-E2-11A2F11A4-11A2F11A5-2AU7A2K7AU2A6-9AK2-K9A7-5A-3A2-3A-5A8-A-6A4-6A-A11-5A4-5A14-RAR8-RAR14-RTR8-RTR244-2M110-2M23-B2-2M2-B17-2(DB)2-2M2-2(BD)12-D5B2-2M2-5BD7-DC7B2-2M2-7BCD7-4A4-2M4-4A10-O3AG3-2M3-G3AO9-5AG3-2M3-G5A4-H2-AJ5A3G2M3G5AJA2-HE-8A-2A2F2A-8A-E2-BAO5A-2A2F2A-5AOAB2(4-11A2F11A)4-4A-5AK2-K5A-4A5-10A2-10A7-5A-3A2-3A-5A8-7A6-7A11-5A4-5A14-3A8-3A14-3R8-3R15-T10-T16-T10-T15-2L10-2L14-L12-L13-2(2L12-)L5-4W5-L12-2LQ3(W2-)WQ2L18-4W25-2M110-2M23-B2-2M2-B17-2(DB)2-2M2-2(BD)12-D5B2-2M2-5BD7-DC7B2-2M2-7BCD7-4A4-2M4-4A10-5AG2-2M2-G5A9-6AG2-2M2-G6A4-E2-8A2G2M2G8A2-E2-7A2-2A2F2A2-7A4-B5A3-2A2F2A3-5AB4-11A2F11A4-2AJ8A2O8AJ2A4-10AK2-K10A5-AJ7A4-7AJA7-5A10-5A8-2AU4A6-4AU2A9-6AJ4-J6A11-4A8-4A13-TRT8-TRT15-T10-T16-T10-T15-2L10-2L14-L12-L13-2(2L12-)L5-4L5-L12-2LQW2(2-L)2-WQ2L18-4L80-Z2-Z52-P2-P22-2BP2-P2B17-2BD2BP2-P2BD2B13-6BP2-P6B8-DC8BP2-P8BCD7-J3A3-P2-P3-3AJ10-5AG-P2-P-G5A9-A-5AGP2-PG5A-A4-H2-J2-6A4G6A2-J2-HE2-6A2-2A2F2A2-6A2-E2-B5A3-2A2F2A3-5AB4-4A-6A2F6A-4A4-11A2S11A5-9AK2-K9A6-9A4-9A7-7A6-7A8-7A6-7A9-7A4-7A11-2(AR)8-2(RA)13-RTR8-RTR382-2B2-2B19-B2D2B2-2B2DB14-7B2-7B8-DC8BG2-G8BCD7-2(4A10-)O4AG6-G4AO10-6A2G2-2G6A8-10A2G10A3-H2-6A2-2A2F2A2-6A2-HE2-5B3-2A2F2A3-5B2-E2-11A2F11A4-10AK2-K10A5-9AK2-K9A7-8A4-8A8-8A4-8A9-6A6-6A12-5A4-5A15-E10-E188-4Q24-Q2-Q24-4Q164-4B20-2B2D4B2D2B14-16B9-DC18BCD9-6A4-6A12-4AG6-G4A10-7A6G7A8-AU7A2F7AUA7-10A2F10A3-H2-6B4A2F4A6B2-HE-2AOU7A2F7AUO2A-EH2-9AK2-K9A2-H3-10A2-10A7-2A-6A2-6A-2A8-8A4-8A10-5A6-5A13-J3A6-3AJ15-H10-H437-2(2B2D)2B16-5BD2BD5B10-DC7BD2BD7BCD9-6A4-6A12-5A6-5A10-7A6G7A8-9A2F9A7-10A2F10A6-6B4A2S4A6B5-2A2-7A2F7A2-2A2-E2-9AK2-K9A2-EH2(2-10A)2-HE3-9A2-9A3-EH3-8A4-8A3-H7-4A6-4A15-2A8-2A16-E10-E438-2(2BD)2B17-5BD2BD5B11-DC6BD2BD6BCD10-6A4-6A12-5A6-5A10-8A4G8A9-O7A2S7AO10-O7A2F7AO8-6B4A2-4A6B6-A2-7A2F7A2-A6-AJ7AK2-K7AJA6-10A2-10A7-9A2-9A4-E3-8A4-8A3-EH6-3AJ6-J3A6-HE7-E10-E7-E8-H10-H440-D2BD20-4BD2BD4B12-DC6BD2BD6BCD10-7A2-7A11-J7A2-7AJ11-7A2S7A11-7AK2-K7A10-2A-4AK2-K4A-2A9-3B-B3AK2-K3AB-3B7-JO7AK2-K7AOJ6-9AK2-K9A7-3A-5A2-5A-3A8-AJ2A-4A2-4A-2AJA10-A3-2A4-2A3-A14-E10-E8-H7-E10-E7-HE26-E458-2(2BD)2B15-DC5BD2BD5BCD13-A-3A2-3A-A13-4A-3A2-3A-4A11-7A2S7A11-7AK2-K7A10-J6AK2-K6AJ11-3BA-AK2-KA-A3B11-7AK2-K7A10-8A2-8A9-3A-5A2-5A-3A9-AJ5A4-5AJA12-2A10-2A14-2A10-2A15-H10-H8-H26-HE26-E433-2B19-D2C3BD2BD3B2CD45-2A2-2A17-7A2-7A12-6AK2-K6A13-6A2-6A13-3BA-2A2-2A-A3B2(12-7A2-7A)10-9A2-9A10-6A4-6A13-5A4-5A15-A-2A4-2A-A16-E10-E36-H26-H455-2D2C6B2C2D70-AJ4A2-4AJA14-J4A4-4AJ15-4A4-4A15-2B3A4-3A2B13-6A4-6A12-6A4-6A15-3A4-3A16-2AJAJ4-JAJ2A14-2AU2A4-2AU2A15-H-A6-A-H64-E26-E457-2D6C2D102-AOA4-AOA17-4A4-4A16-B3A4-3AB14-4A8-4A11-6A6-6A11-5A6-5A13-2A10-2A15-A10-A16-E10-E64-HE24-EH459-6D132-B8-B17-B3A4-3AB15-6A2-6A14-4A6-4A15-JA8-AJ16-E10-E16-H10-H65-2E22-2E2-H24-H598-B8-B17-2BN6-N2B15-5B4-5B15-2BN6-N2B16-HE8-EH94-2E20-2E4-H22-H654-3B6-3B16-BEB6-BEB16-3B6-3B95-2E18-2E6-H20-H712-E8-E97-2E16-2E8-H18-H312-
