model
size = 30 15 12, scale = 0.05, origin = -y
material 
  colors = A:#6CC B:#66F C:#099
voxels
6-A2B2A10-2A2BA9-2B2AB10-B2A2B8-4B3A10B3A4B5-3A4B3A2B2A2B3A4B3A3-2A2(BA)2B4A4B4A2B2(AB)2A2-2(2AB)2(A4BAB2AB)2A-B11AB4AB11A6B4A2(BA)4B2(AB)4A6B3ABA6BA4BA6BA2(B3A2(BA))BAB2A3(BA)2(B3ABA)2(B2A)3B4A3B2(2AB)AB2A-B2A2(BA)5(2BA)BAB2AB2-BA2BABA3BA6BA3BABA2BAB3-2BAB3AB2ABA2BAB2AB3ABA2B5-3B2(2AB)2(AB2AB)2A3B153-A28-AB28-BA2(28-2A)28-A241-B26-B2-B26-B-AB26-B3A26-3AB26-B2AB26-B3A26-2A-B26-B2-B26-B153-A24-A3-2A24-2A2-2A24-2A-3A24-5AB24-B5A24-5AB24-B4AB24-B2A-2A24-2A2-2A24-2A3-B24-B95-A22-A5-AB22-BA3-3A22-3A2-3A22-3A-3AB22-B7A2(22-8A)22-7AB22-B3A-2AB22-B2A2-2AB22-B2A3-AB22-BA5-B22-B66-2A20-2A5-2AB20-B2A3-4A20-4A2-3AB20-B3A-4AB20-B9A3(20-10A)20-5A-4A20-4A2-4A20-4A3-3A20-3A5-AB20-BA38-3A2B10-2B3A8-5A3B2A4B2A3B5A5-3AB18-B3A3-4AB18-B4A2-5A18-5A-5AB18-B10AB18-B11A18-12A18-11AB18-B5A-5A18-5A2-4AB18-B4A3-4A18-4A5-4AB3ABAB2ABAB3AB4A8-BAB2A10-2ABAB10-3A2B10-2B3A8-7A3BA2BA3B7A5-4A18-4A3-5A18-5A2-5A18-5A-6A4(18-12A)18-6A-5A18-5A2-5A18-5A3-4A18-4A5-7A3BA2BA3B7A8-3A2B10-2B3A10-BAB2A10-2ABAB8-7A2BA4BA2B7A5-4A18-4A3-5A18-5A2-5A18-5A-6A4(18-12A)18-6A-5A18-5A2-5A18-5A3-4A18-4A5-7A2BA4BA2B7A8-BAB2A10-2ABAB2(10-2AB2A)8-7A2B6A2B7A5-6A2(B2A)2B2(2AB)6A3-5A18-5A2-5A18-5A-6A4(18-12A)18-6A-5A18-5A2-5A18-5A3-4A18-4A5-7A2B6A2B7A8-2(2AB2A10-)B4A10-4AB8-7A3BA2BA3B7A5-26A3-5A18-5A2-5A18-5A-6A4(18-12A)18-6A-5A18-5A2-5A18-5A3-4A18-4A5-7A3BA2BA3B7A8-B4A10-4AB2(10-2(AB)A)8-10AB2AB10A5-26A3-28A2-7A4C6A4C7A-7A6C4A6C13A3(8C2A8C12A)8C2A8C6A-6A6C4A6C6A2-7A4C6A4C7A3-26A5-10AB2AB10A8-2(AB)A10-2(AB)A5-
