model
size = 30 15 12, scale = 0.05, origin = -y
material 
  colors = A:#F9F B:#555 C:#F03
voxels
6-3A2B10-2B3A9-2BABA10-ABA2B8-AB2A3BABA4BABA3B2ABA5-6ABA2B6A2BAB6A3-3AB9A2B9AB3A2-AB3A5B2(2AB)2A5B3ABA-2BABA3B2ABA6BAB2A3BABA2B2A2B4(AB)2A2B2A4(BA)2B6A2B2A2BA3B2A3BA2B2A2B6ABAB2A2B2(2ABAB)2A2B2ABAB2AB4A2(4BA2BA)4B4AB-3BA6BAB4ABA6BA3B2-BA2B3A2(BA)2B2A2B2(AB)3A2BAB3-3A5B2ABA2BAB2A5B3A5-2(2A2B2A3B)2A2B2A153-B28-BA28-2A28-AB28-BA28-A241-B26-B2-A26-A-A2(B26-B2A)B26-B3A26-3AB26-BA-A26-A2-A26-A153-B24-B3-AB24-BA2-AB24-BA-3A24-6A24-5AB24-B5A24-5AB24-B2A-AB24-BA2-2A24-2A3-B24-B95-B22-B5-AB22-BA3-3A22-3A2-2AB22-B2A-4A22-7AB22-B6AB22-B7A22-8A22-4A-3A22-3A2-3A22-3A3-AB22-BA5-B22-B66-2A20-2A5-2AB20-B2A3-4A20-4A2-4A20-4A-4AB20-B9A2(20-10A)20-9AB20-B4A-3AB20-B3A2-3AB20-B3A3-2AB20-B2A5-AB20-BA38-3B2A10-2A3B8-2A2B5A6B5A2B2A5-3AB18-B3A3-4AB18-B4A2-4AB18-B4A-6A18-11AB18-B11A2(18-12A)18-6A-5A18-5A2-5A18-5A3-4A18-4A5-3ABA3BAB4ABA3BAB3A8-3A2B10-2B3A2(10-5A)2(8-24A5-4A18-4A3-5A18-5A2-5A18-5A-6A4(18-12A)18-6A-5A18-5A2-5A18-5A3-4A18-4A5-24A8-3(5A10-)5A)8-24A5-6AB3ABA2BAB3AB6A2(3-5A18-5A2-5A18-5A-6A4(18-12A)18-6A-5A18-5A2-5A18-5A3-4A18-4A5-24A8-3(5A10-)5A8-24A5-26A)3-28A2-7A4C6A4C7A-7A6C4A6C13A3(8C2A8C12A)8C2A8C6A-6A6C4A6C6A2-7A4C6A4C7A3-26A5-24A8-5A10-5A5-
