model
size = 30 15 12, scale = 0.05, origin = -y
material 
  colors = A:#008 B:#C36 C:#004
voxels
6-2AB2A10-2AB2A9-3BAB10-BA3B8-2A2B2AB2(2A2B)2AB2A2B2A5-A4BA2BA3B2A3BA2BA4BA3-3BA2BAB2A8B2ABA2BA3B2-2ABA4BA3B4A3BA4BAB2A-2A2(BA)B7A2B7A2(BA)B2AB4A2(B3A)B2A2(B3A)B4A2BAB2A2B2ABAB6ABAB2A2B2ABAB3A3B3A2(BA)4B2(AB)3A3B4A3B2A3B3A6B3A3B2A3BA-ABA2BA3B2(2A2B)2A3BA2BABA2-AB3AB3(A4B)AB3ABA3-4B2ABAB8ABAB2A4B5-2BAB6A4B6ABA2B153-A4(28-2A)28-A241-A26-A2-A26-A-BA26-AB2A2(26-4A)26-2ABA26-AB-A26-A2-A26-A153-A24-A3-2A24-2A2-2A24-2A-3A24-3AB2(2A24-2A2B)2A24-2AB3A24-3A-2A24-2A2-2A24-2A3-A24-A95-A22-A5-2A22-2A3-3A22-3A2-3A22-3A-2(B3A22-3AB4A22-4A)B3A22-3AB-3A22-3A2-3A22-3A3-2A22-2A5-A22-A66-2A20-2A5-3A20-3A3-4A20-4A2-4A20-4A-2(5A20-5AB4A20-4AB)5A20-5A-4A20-4A2-4A20-4A3-3A20-3A5-2A20-2A38-5A10-5A8-24A5-4A18-4A3-5A18-5A2-5A18-5A-6A18-6AB2(5A18-5A2B)5A18-5AB6A18-6A-5A18-5A2-5A18-5A3-4A18-4A5-24A8-2(5A10-)BA3B10-3BAB8-7A3BA2BA3B7A5-4A18-4A3-5A18-5A2-5A18-5A-B4(5A18-5A2B)5A18-5AB-5A18-5A2-5A18-5A3-4A18-4A5-7A3BA2BA3B7A8-BA3B10-3BAB10-A4B10-4BA8-7A2B6A2B7A5-4A18-4A3-5A18-5A2-5A18-5A-B5A18-5A2B5A18-5AB6A18-6AB5A18-5A2B5A18-5AB-5A18-5A2-5A18-5A3-4A18-4A5-7A2B6A2B7A8-A4B10-4BA10-3BAB10-BA3B8-7A2BA4BA2B7A5-26A3-5A18-5A2-5A18-5A-B4(5A18-5A2B)5A18-5AB-5A18-5A2-5A18-5A3-4A18-4A5-7A2BA4BA2B7A8-3BAB10-BA3B10-3BAB10-BA3B8-7A10B7A5-26A3-5A18-5A2-5A18-5A-B4(5A18-5A2B)5A18-5AB-5A18-5A2-5A18-5A3-4A18-4A5-7A10B7A8-3BAB10-BA3B2(10-2(BA)B)8-7A3(B2A)B7A5-26A3-28A2-7A4C6A4C7A-B6A6C4A6C6A4(2B5A8C2A8C5A)B-6A6C4A6C6A2-7A4C6A4C7A3-26A5-7A3(B2A)B7A8-2(BA)B10-2(BA)B5-
