model
size = 30 15 12, scale = 0.05, origin = -y
material 
  colors = A:#F00 B:#6C0 C:#A00
voxels
6-2(AC)A10-2(AC)A9-2CA2B10-2BA2C8-AC3B2A3C4A3C2A3BCA5-ACBA2C2(4AC)4A2CABCA3-AB2(AC)2BA2(CB)2A2(BC)A2B2(CA)BA2-2(AB)2(AC)2BC6AC2B2(CA)2(BA)-C2(BA)C2(AB)4A2B4A2(BA)C2(AB)CB2(2AC)2AB10AB2(2AC)2AB4ABAB2A2B2A4B2A2B2ABAB7A2B2AC3AB2C2B2CB3AC2A2B8ACBC3AC2A2B2AC3ACBC5A-2B6ABC2AB2CB2ACB6A2B2-2A2BCB3ABA2B2A2BAB3ABC2B2A3-C2B4ABC3A2B3ACB4A2BC5-2ABACA2CACB2ABCA2CACAB2A153-A4(28-2A)28-A241-A26-A2-A26-A-2A4(26-4A)26-2A-A26-A2-A26-A153-A24-A3-2A24-2A2-2A24-2A-3A4(24-6A)24-3A-2A24-2A2-2A24-2A3-A24-A95-A22-A5-2A22-2A3-3A22-3A2-3A22-3A-2(4A22-4AB3A22-3AB)4A22-4A-3A22-3A2-3A22-3A3-2A22-2A5-A22-A66-2A20-2A5-3A20-3A3-4A20-4A2-4A20-4A-5A20-5AB4A20-4ABC4A20-4ACB4A20-4AB5A20-5A-4A20-4A2-4A20-4A3-3A20-3A5-2A20-2A38-5A10-5A8-24A5-4A18-4A3-5A18-5A2-5A18-5A-6A18-12A18-6AB5A18-5AB6A18-12A18-6A-5A18-5A2-5A18-5A3-4A18-4A5-24A8-3(5A10-)5A8-11A2C11A5-4A18-4A3-5A18-5A2-5A18-5A-6A18-6AB2(5A18-5A2B)5A18-5AB6A18-6A-5A18-5A2-5A18-5A3-4A18-4A5-11A2C11A8-2(5A10-)C2A2C10-2C2AC8-24A5-4A18-4A3-5A18-5A2-5A18-5A-6A4(18-12A)18-6A-5A18-5A2-5A18-5A3-4A18-4A5-24A8-C2A2C10-2C2AC10-C2ACA10-AC2AC8-11A2C11A5-26A3-5A18-5A2-5A18-5A-6A4(18-12A)18-6A-5A18-5A2-5A18-5A3-4A18-4A5-11A2C11A8-C2ACA10-AC2AC10-A2C2A10-2A2CA8-24A5-26A3-5A18-5A2-5A18-5A-6A18-12A18-6AB5A18-5AB6A18-12A18-6A-5A18-5A2-5A18-5A3-4A18-4A5-24A8-A2C2A10-2A2CA2(10-2AC2A)8-7ACAC4ACAC7A5-26A3-28A2-7A4B6A4B7A-7A6B4A6B13A3(8B2A8B12A)8B2A8B6A-6A6B4A6B6A2-7A4B6A4B7A3-26A5-7ACAC4ACAC7A8-2AC2A10-2AC2A5-
