model
size = 30 15 12, scale = 0.05, origin = -y
material 
  colors = A:#010 B:#F3C C:#C3F
voxels
6-A2CAB10-BA2CA9-3ACA10-AC3A8-CB4ACACB4ABCAC4ABC5-4A2C3AC2A2C2AC3A2C4A3-CB2(AC)B3AB6AB3AB2(CA)BC2-2CAB3ABAB3A2C3ABAB3ABA2C-3AB4ABCB2(2CA)2CBCB4AB3A2B2(CA)BCA2CBAC2ACAB2CACB2(AC)2BC2A4CBCA3(B2A)BACB4C2A2(CA)2BABCABA3C2A3CABACBA2BAC3A2(CA)BACAB2A4B2A2(BACA)C2A-BC2AB3AC10AC3AB2ACB2-CB3(CA)B2ABA2CAB2AB3(AC)BC3-2(AB)CA3BAB4ABA3BAC2(BA)5-AB2C2A2CBA4BAB2C2A2CBA153-A4(28-2A)28-A241-A26-A2-A26-A-2A2(26-4A)26-3AC26-C3A26-2A-B26-B2-C26-C153-A24-A3-2A24-2A2-2A24-2A-3A24-3ACAC24-CAC2AB24-B2AC2A24-2AC3A24-3A-AC24-CA2-AC24-CA3-A24-A95-A22-A5-AC22-CA3-3A22-3A2-3A22-3A-B3A22-3AB4A2(22-8A)22-4AB3A22-3AB-3A22-3A2-2AC22-C2A3-AB22-BA5-B22-B66-2A20-2A5-3A20-3A3-4A20-4A2-4A20-4A-2(5A20-5AC3AC20-C3AC)5A20-5A-4A20-4A2-4A20-4A3-2AB20-B2A5-2A20-2A38-ABCAC10-CACBA8-4AC2(4AB)4AC4A5-4A18-4A3-4AC18-C4A2-4AB18-B4A-6A18-11AB18-B5AC5A18-5AC5AB18-B11A18-6A-4AB18-B4A2-5A18-5A3-4A18-4A5-6ABC8ACB6A8-B2ABA10-AB2AB2(10-5A)8-24A5-4A18-4A3-5A18-5A2-5A18-5A-6A4(18-12A)18-6A-5A18-5A2-5A18-5A3-4A18-4A5-24A8-3(5A10-)5A8-24A5-4A18-4A3-5A18-5A2-5A18-5A-B5A18-5ABC5A18-5AC6A18-6AC5A18-5ACB5A18-5AB-5A18-5A2-5A18-5A3-4A18-4A5-24A8-3(5A10-)5A8-24A5-6ACAB8ABAC6A3-5A18-5A2-5A18-5A-6A18-12A18-6AB5A18-5AB6A18-12A18-6A-5A18-5A2-5A18-5A3-4A18-4A5-24A8-3(5A10-)5A8-24A5-26A3-5A18-5A2-5A18-5A-6A4(18-12A)18-6A-5A18-5A2-5A18-5A3-4A18-4A5-24A8-3(5A10-)5A8-24A5-26A3-28A2-7A4B6A4B7A-7A6B4A6B13A3(8B2A8B12A)8B2A8B6A-6A6B4A6B6A2-7A4B6A4B7A3-26A5-24A8-5A10-5A5-
