model
size = 32 27 32, scale = 0.05, origin = -y
material 
  colors = A:#30C B:#111 C:#FC0
voxels
44-8A824-8A853-14A848-18A845-20A843-22A841-24A839-26A837-28A836-11A6-11A15-3(6A26-)5AC26-4A2C26-5AC654-10A10-10A12-2A6-2A22-CA3(6-2A22-2A)6-CA22-10A24-2(6A26-)C5A558-9A12-9A11-5(A10-A20-)3A6-3A21-2(2A6-2A22-)10A24-2(6A26-)6A462-8A14-8A10-5(A12-A18-)3A8-3A19-2(2A8-2A20-)3A6-3A22-2(A6-A24-)8A25-6A26-AC4A2(26-6A)333-9A14-9A9-A12-C4(18-A12-A)18-2A10-2A19-A10-A20-C10-A20-2A8-2A21-2(A8-A22-)3A4-2AC23-3(2A4-2A24-)8A26-2(4A28-)3AC238-8A16-8A8-5(A14-A16-)2A12-2A17-2(C12-A18-)CA10-2A19-2(A10-A20-)3A6-3A21-3(2A6-2A22-)3A4-3A24-2(A4-A26-)A4-A27-2(4A28-)4A142-8A16-8A8-A14-A16-C3(14-A16-A)14-A16-2A12-2A17-A12-A18-C12-A18-2A10-2A19-2(A10-A20-)2A8-2A21-3(A8-A22-)2A6-2A23-2(A6-A24-)A6-A25-6A26-A4BA26-C4BA27-4A28-4A78-8A16-8A8-5(A14-A16-)2A12-2A17-2(A12-A18-)2A10-2A19-2(A10-A20-)2A8-2A21-2(A8-A22-)C8-A22-2A6-2A23-2(A6-A24-)A6-A25-6A2(26-A4BA)27-A2BA28-A2BA29-2A30-2A15-8A16-8A8-A14-A16-A14-C3(16-A14-A)16-2A12-2A17-2(A12-A18-)2A10-2A19-2(A10-A20-)2A8-2A21-A8-C2(22-C8-A)22-CA6-2A23-2(A6-A24-)A6-A25-6A26-A4BC26-A4BA27-A2BA28-A2BA29-2A30-2A15-8A16-8A8-5(A14-A16-)2A12-2A17-A12-A18-A12-C18-2A10-2A19-2(A10-A20-)2A8-2A21-2(A8-A22-)C8-A22-2A6-2A23-2(A6-A24-)A6-A25-6A2(26-A4BA)27-4A28-4A78-8A16-8A8-5(A14-A16-)2A12-2A17-A12-A18-A12-C18-2A10-2A19-2(A10-A20-)3A6-3A21-3(2A6-2A22-)3A4-3A24-2(A4-A26-)A4-A27-2(4A28-)4A142-9A14-9A9-3(A12-A18-)C12-A18-A12-A18-2A10-2A19-A10-A20-A10-C20-2A8-2A21-2(A8-A22-)3A4-3A23-3(2A4-2A24-)8A26-2(4A28-)C3A239-8A14-8A10-5(A12-A18-)3A8-3A19-2(2A8-2A20-)3A6-3A22-2(A6-A24-)8A25-3AC2A26-2A3CA26-3AC2A26-6A334-9A12-9A11-2(A10-A20-)A10-C2(20-A10-A)20-3A6-3A21-AC6-2A22-2A6-2A22-10A24-2(6A26-)6A462-10A10-10A12-5(2A6-2A22-)10A24-2(6A26-)2AC3A559-11A6-11A15-3(6A26-)4ACA2(26-6A)655-28A837-26A839-24A841-22A843-20A845-18A848-14A841-
