model
size = 30 15 12, scale = 0.05, origin = -y
material 
  colors = A:#CF0 B:#306 C:#9F6
voxels
6-BA3B10-3BAB9-5B10-5B8-A2BABA2B8A2BABA2BA5-3BA4BA8BA4BA3B3-BA2B2AB3A8B3AB2A2BAB2-5AB3A3BA2BA3B3AB5A-B2A4B5AB4AB5A4B2A2(3BA2BA)B2ABA2BA3BA2BA4BAB2A4BA2B4A2BA4B2ABA2B3ABA4BA2BAB2ABA2BA4BAB4ABAB4A2B2AB4AB2A2B4A2(BA)-A4B4(2A2B)2A4BA2-B4AB2A4B4A4B2AB4AB3-AB2A2B4ABA2BAB4A2B2ABA5-2(BA)B3ABAB2ABAB3A2(BA)B153-B28-2B28-BA28-AB28-2B28-B241-B26-B2-A26-A-AB26-B2AB26-B3A2(26-4A)26-2A-B26-B2-A26-A153-A24-A3-2A24-2A2-AB24-BA-2A2(B24-B4A)B24-B5A24-5AB24-B2A-AB24-BA2-AB24-BA3-A24-A95-A22-A5-AB22-BA3-2AB22-B2A2-2AB22-B2A-3A4(B22-B6A)B22-B3A-3A22-3A2-2AB22-B2A3-AB22-BA5-B22-B66-AB20-BA5-2AB20-B2A3-3AB20-B3A2-3AB20-B3A-4A4(B20-B8A)B20-B4A-3AB20-B3A2-4A20-4A3-2AB20-B2A5-AB20-BA38-4BA10-A4B8-2A6BABA2BABA6B2A5-3AB18-B3A3-4AB18-B4A2-4AB18-B4A-5A2(B18-B10A)B18-B11A18-11AB18-B5A-4AB18-B4A2-4AB18-B4A3-4A18-4A5-4A16B4A8-A2BAB10-BA2BA10-AB3A10-3ABA8-24A5-4A18-4A3-5A18-5A2-5A18-5A-6A4(18-12A)18-6A-5A18-5A2-5A18-5A3-4A18-4A5-24A8-AB3A2(10-3ABA)10-AB3A8-7AB3A2B3AB7A5-4A18-4A3-5A18-5A2-5A18-5A-6A4(18-12A)18-6A-5A18-5A2-5A18-5A3-4A18-4A5-7AB3A2B3AB7A8-3ABA2(10-AB3A)10-3ABA8-24A5-4A4BA8BA4B4A3-5A18-5A2-5A18-5A-6A4(18-12A)18-6A-5A18-5A2-5A18-5A3-4A18-4A5-24A8-AB3A10-3ABA2(10-2AB2A)8-10AB2AB10A5-26A3-5A18-5A2-5A18-5A-6A4(18-12A)18-6A-5A18-5A2-5A18-5A3-4A18-4A5-10AB2AB10A8-2(2AB2A10-)4AB10-B4A8-9ABA2BAB9A5-26A3-28A2-7A4C6A4C7A-7A6C4A6C13A3(8C2A8C12A)8C2A8C6A-6A6C4A6C6A2-7A4C6A4C7A3-26A5-9ABA2BAB9A8-4AB10-B4A5-
