model
size = 30 15 12, scale = 0.05, origin = -y
material 
  colors = A:#F9C B:#FC3 C:#CF3
voxels
6-BA2BA10-A2BAB9-AB3A10-3ABA8-B2A4B4A2B4A4B2AB5-AB2ABA3BABA2BABA3BAB2ABA3-4BA2BABA3B2A3BABA2BA4B2-2(AB)A2B3AB6AB3A2B2(AB)A-B5A2B3ABA4BAB3A2B5AB2A5B3A4B2A4B3A5B2ABA3BAB3A2(2B2A)2B3ABA3BAB2ABA2B2(AB)2ABA2BAB2A2(BA)2BAB2A2B2A4BA5B2A5BA4B2A2B-2(AB)A2B2A10B2A2B2(AB)A2-A4B2(4A3B)4A4BA3-2(4A2BABA2B)4A5-BA2(2B2ABAB2A)2BAB153-A4(28-2A)28-A241-B26-B2-A26-A-2A2(26-4A)26-3AB26-B2AB26-BA-A26-A2-A26-A153-A24-A3-AB24-BA2-AB24-BA-2A2(B24-B4A)B24-B5A24-5AB24-B2A-2A24-2A2-2A24-2A3-B24-B95-B22-B5-2A22-2A3-3A22-3A2-3A22-3A-4A22-8A22-7AB22-B6AB22-B7A22-4A-3A22-3A2-2AB22-B2A3-2A22-2A5-B22-B66-2A20-2A5-2AB20-B2A3-3AB20-B3A2-4A20-4A-4AB20-B8AB20-B9A20-9AB20-B9A20-5A-4A20-4A2-3AB20-B3A3-3A20-3A5-2A20-2A38-A2B2A10-2A2BA8-3AB2A2(2B3A)2B2AB3A5-3AB18-B3A3-5A18-5A2-4AB18-B4A-5A2(B18-B11A18-11A)B18-B5A-4AB18-B4A2-5A18-5A3-4A18-4A5-2ABA2B2A2B4A2B2A2BAB2A8-B2A2B10-2B2AB2(10-5A)2(8-24A5-4A18-4A3-5A18-5A2-5A18-5A-6A4(18-12A)18-6A-5A18-5A2-5A18-5A3-4A18-4A5-24A8-3(5A10-)5A)8-24A5-4A3BABA2B2A2BABA3B4A2(3-5A18-5A2-5A18-5A-6A4(18-12A)18-6A-5A18-5A2-5A18-5A3-4A18-4A5-24A8-3(5A10-)5A8-24A5-26A)3-28A2-7A4C6A4C7A-7A6C4A6C13A3(8C2A8C12A)8C2A8C6A-6A6C4A6C6A2-7A4C6A4C7A3-26A5-24A8-5A10-5A5-
