model
size = 30 15 12, scale = 0.05, origin = -y
material 
  colors = A:#606 B:#070 C:#303
voxels
6-3ACB10-BC3A9-ABACA10-ACABA8-2AB3ACAC6ACAC3AB2A5-3A4BA2C6A2CA4B3A3-C2(B2A)C5A2C5AC2(2AB)C2-CB2AB3ABACBA2CABCAB3AB2ABC-4AB5ABCAB2ABACB5AB4ABABCAB7AC2AC7ABACBABC2BCAB3ACB2(2AC)2ABC3ABAC2B2CACB2CA3B2CBA2BAB2C3BA2CBCAC3ABA2B2(AB)C2A2C2AC2(BA)2BAB3A-2(BA)C2AC3AC4AC3AC2AC2(AB)2-BA2B3AB2AC2B2C2BC2AB3A2BAB3-BAB3A2(CA)2B2A2B2(AC)3ABAB5-2ABC2ACB2(2CA)2CBC2ACB2A153-A4(28-2A)28-A241-A26-A2-A26-A-CA26-A2CA26-AC2A26-2ACA26-A2CA26-AC-A26-A2-A26-A153-A24-A3-2A24-2A2-2A24-2A-3A24-3AC2A24-2ACB2A24-2ABC2A24-2AC3A24-3A-2A24-2A2-2A24-2A3-A24-A95-A22-A5-2A22-2A3-3A22-3A2-3A22-3A-B3A22-3ABC2(3A22-3A2C)3A22-3ACB3A22-3AB-3A22-3A2-3A22-3A3-2A22-2A5-A22-A66-2A20-2A5-3A20-3A3-4A20-4A2-4A20-4A-2(5A20-5AC4A20-4AC)5A20-5A-4A20-4A2-4A20-4A3-3A20-3A5-2A20-2A38-5A10-5A8-24A5-4A18-4A3-5A18-5A2-5A18-5A-6A18-6AC2(5A18-5A2C)5A18-5AC6A18-6A-5A18-5A2-5A18-5A3-4A18-4A5-24A8-3(5A10-)5A8-24A5-4A18-4A3-5A18-5A2-5A18-5A-B5A18-5A2B5A18-5AB6A18-6AB5A18-5A2B5A18-5AB-5A18-5A2-5A18-5A3-4A18-4A5-24A8-3(5A10-)5A8-24A5-4A18-4A3-5A18-5A2-5A18-5A-2(6A18-6AC5A18-5AC)6A18-6A-5A18-5A2-5A18-5A3-4A18-4A5-24A8-3(5A10-)5A8-24A5-26A3-5A18-5A2-5A18-5A-B5A18-5ABC2(5A18-5A2C)5A18-5ACB5A18-5AB-5A18-5A2-5A18-5A3-4A18-4A5-24A8-3(5A10-)5A8-24A5-26A3-5A18-5A2-5A18-5A-6A18-12A18-6AC5A18-5AC6A18-12A18-6A-5A18-5A2-5A18-5A3-4A18-4A5-24A8-3(5A10-)5A8-24A5-26A3-28A2-7A4B6A4B7A-C6A6B4A6B6A2(CB5A8B2A8B5ABC5A8B2A8B5A)C-6A6B4A6B6A2-7A4B6A4B7A3-26A5-24A8-5A10-5A5-
