model
size = 30 15 12, scale = 0.05, origin = -y
material 
  colors = A:#360 B:#E00 C:#90C
voxels
6-2ACAB10-BAC2A9-3ABC10-CB3A8-2ACB2C2BA6CA2B2CBC2A5-CB2CA2(C2A)2(B2A)C2ACA2CBC3-A3B4AC4A2C4AC4A3BA2-3C2ABAB2A2(2CB)2C2ABAB2A3C-ACBC3BCB3ABA2CAB3ABC3BCBCAB2ACA3BACBAC4ACABCA3BAC2ABCB2ABAB2C2AB2C2B2CB2A2CBAB2ABC2(BA)B9A2C9A2(BA)BC2A2BC2AC3ACB2ABC3AC2AC2B2AC-CBC2A2CB4AC2AC4AB2C2ACBC2-BACAB4AB2CB2AB2CB4ABACAB3-2A2C2(BA)C3A2C3AC2(AB)2C2A5-2C2A2B2CBA4BAB2C2B2A2C153-A4(28-2A)28-A241-A26-A2-A26-A-CA26-AC2A2(26-4A)26-2ACA26-AC-A26-A2-A26-A153-A24-A3-2A24-2A2-2A24-2A-3A24-6A24-3AB2A24-2AB3A24-6A24-3A-2A24-2A2-2A24-2A3-A24-A95-A22-A5-2A22-2A3-3A22-3A2-3A22-3A-4A4(22-8A)22-4A-3A22-3A2-3A22-3A3-2A22-2A5-A22-A66-2A20-2A5-3A20-3A3-4A20-4A2-4A20-4A-B4A20-4AB5A2(20-10A)20-5AB4A20-4AB-4A20-4A2-4A20-4A3-3A20-3A5-2A20-2A38-5A10-5A8-24A5-4A18-4A3-5A18-5A2-5A18-5A-6A18-6AC5A18-5ACB5A18-5ABC5A18-5AC6A18-6A-5A18-5A2-5A18-5A3-4A18-4A5-24A8-2(5A10-)2BACA10-ACA2B8-7AC2(2AB)2AC7A5-4A18-4A3-5A18-5A2-5A18-5A-6A18-12A18-6AB5A18-5AB6A18-12A18-6A-5A18-5A2-5A18-5A3-4A18-4A5-7AC2(2AB)2AC7A8-2BACA10-ACA2B10-BACBA10-ABCAB8-9AC4BC9A5-4A18-4A3-5A18-5A2-5A18-5A-2(6A18-6AB5A18-5AB)6A18-6A-5A18-5A2-5A18-5A3-4A18-4A5-9AC4BC9A8-BACBA10-ABCAB2(10-A3BA)8-8AB2A2B2AB8A5-26A3-5A18-5A2-5A18-5A-2(B5A18-5AB6A18-6A)B5A18-5AB-5A18-5A2-5A18-5A3-4A18-4A5-8AB2A2B2AB8A8-2(A3BA10-)2ABCB10-BCB2A8-7A2BAB2ABA2B7A5-26A3-5A18-5A2-5A18-5A-6A4(18-12A)18-6A-5A18-5A2-5A18-5A3-4A18-4A5-7A2BAB2ABA2B7A8-2ABCB10-BCB2A10-3CAB10-BA3C8-10AC2BC10A5-26A3-28A2-7A4B6A4B7A-7A6B4A6B13A3(8B2A8B12A)8B2A8B6A-6A6B4A6B6A2-7A4B6A4B7A3-26A5-10AC2BC10A8-3CAB10-BA3C5-
