model
size = 30 15 12, scale = 0.05, origin = -y
material 
  colors = A:#390 B:#040 C:#FC6
voxels
6-2(BA)B10-2(BA)B9-A2B2A10-2A2BA8-3BABA2B8A2BABA3B5-A4BAB2AB6AB2ABA4BA3-2BA2B4ABA2B2A2BAB4A2BA2B2-3B2A3BAB2A4B2ABA3B2A3B-B2ABA3BAB3(A2B)ABA3BAB2A2(2BA)2(B3A)B2A2(B3A)BA2BA3BABA2B3A2BAB2ABA2B3A2BABA3B3ABA3BA2B6A2BA3BAB3AB2A2BABA3BAB2A2B2ABA3BABA2B2A-3(BA)B2ABA2B2A2BAB2A3(BA)B2-2BAB5AB3A2B3AB5ABA2B3-4BA2B2A8B2A2BA4B5-4A2B2A2(2BA)2B2A2B4A153-2(A28-AB28-B)A28-A241-A26-A2-A26-A-2A3(26-4A)26-3AB26-BA-A26-A2-B26-B153-A24-A3-AB24-BA2-2A24-2A-3A24-6A24-5AB24-B5A24-5AB24-B2A-AB24-BA2-AB24-BA3-B24-B95-A22-A5-2A22-2A3-2AB22-B2A2-3A22-3A-4A4(22-8A)22-4A-3A22-3A2-3A22-3A3-2A22-2A5-A22-A66-AB20-BA5-3A20-3A3-3AB20-B3A2-4A20-4A-5A2(20-10A)20-9AB20-B9A20-5A-4A20-4A2-4A20-4A3-2AB20-B2A5-2A20-2A38-AB3A10-3ABA8-3AB3A2(2B2A)2B3AB3A5-4A18-4A3-5A18-5A2-4AB18-B4A-6A18-12A18-11AB18-B11A18-11AB18-B5A-5A18-5A2-5A18-5A3-4A18-4A5-7AB8AB7A8-4AB10-B4A2(10-5A)2(8-24A5-4A18-4A3-5A18-5A2-5A18-5A-6A4(18-12A)18-6A-5A18-5A2-5A18-5A3-4A18-4A5-24A8-3(5A10-)5A)8-24A5-4AB7A2B7AB4A2(3-5A18-5A2-5A18-5A-6A4(18-12A)18-6A-5A18-5A2-5A18-5A3-4A18-4A5-24A8-3(5A10-)5A8-24A5-26A)3-28A2-7A4C6A4C7A-7A6C4A6C13A3(8C2A8C12A)8C2A8C6A-6A6C4A6C6A2-7A4C6A4C7A3-26A5-24A8-5A10-5A5-
