model
size = 30 15 12, scale = 0.05, origin = -y
material 
  colors = A:#990 B:#FC0 C:#969
voxels
6-ACB2A10-2ABCA9-ACABA10-ABACA8-3A2CBAC2BA2CA2BCAB2C3A5-2A3(BA)2C6A2C3(AB)2A3-2CACA2B2CBC2A2B2ACB2C2BACA2C2-CBC3A2CABC6BCBA2C3ACBC-BA2BA2CA2B2(AC)2B2(CA)2BA2CA2BABA2C3A3(CA)C4B3(CA)C3A2CACB2CABAC2BABA4BABA2BCABA2CBCA2(BC)2AB2AC2(2AB)2AC2AB2(2A2(CB))3ACAC2(2AB)2ACAC3A2(BC)A-2AB5ABAB6ABAB5AB2A2-2CA2CB2AB3AB2CB3AB2AB2CA2C3-2(AC)2BA2(2B3A)2BA2B2(CA)5-3AC4ABAB2CBAB4AC3A153-A4(28-2A)28-A241-A26-A2-A26-A-2A4(26-4A)26-2A-A26-A2-A26-A153-A24-A3-2A24-2A2-2A24-2A-B2A24-2ABC2A24-2AC3A24-3AC2A24-2ACB2A24-2AB-2A24-2A2-2A24-2A3-A24-A95-A22-A5-2A22-2A3-3A22-3A2-3A22-3A-C3A22-3AC4A2(22-8A)22-4AC3A22-3AC-3A22-3A2-3A22-3A3-2A22-2A5-A22-A66-2A20-2A5-3A20-3A3-4A20-4A2-4A20-4A-5A20-5AB4A20-4ABC4A20-4ACB4A20-4AB5A20-5A-4A20-4A2-4A20-4A3-3A20-3A5-2A20-2A38-5A10-5A8-24A5-4A18-4A3-5A18-5A2-5A18-5A-2(6A18-6AB5A18-5AB)6A18-6A-5A18-5A2-5A18-5A3-4A18-4A5-24A8-3(5A10-)5A8-24A5-4A18-4A3-5A18-5A2-5A18-5A-B4(5A18-5A2B)5A18-5AB-5A18-5A2-5A18-5A3-4A18-4A5-24A8-3(5A10-)5A8-24A5-4A18-4A3-5A18-5A2-5A18-5A-2(6A18-6AB5A18-5AB)6A18-6A-5A18-5A2-5A18-5A3-4A18-4A5-24A8-3(5A10-)5A8-24A5-26A3-5A18-5A2-5A18-5A-B5A18-5AB6A18-6AC5A18-5AC6A18-6AB5A18-5AB-5A18-5A2-5A18-5A3-4A18-4A5-24A8-3(5A10-)5A8-24A5-26A3-5A18-5A2-5A18-5A-2(B5A18-5AB6A18-6A)B5A18-5AB-5A18-5A2-5A18-5A3-4A18-4A5-24A8-3(5A10-)5A8-24A5-26A3-28A2-7A4B6A4B7A-7A6B4A6B13A8B2A8B6AC5A8B2A8B5AC6A8B2A8B12A8B2A8B6A-6A6B4A6B6A2-7A4B6A4B7A3-26A5-24A8-5A10-5A5-
