model
size = 30 15 12, scale = 0.05, origin = -y
material 
  colors = A:#CFC B:#933 C:#660
voxels
6-3B2A10-2A3B9-2A2BA10-A2B2A8-2B3A3B8A3B3A2B5-B4A2(2BA3BA)2B4AB3-BA4BA3BA2B2A2BA3BA4BAB2-8ABA3B2A3BAB8A-3A2B2AB4ABA2BAB4AB2A2B5A4(BA)2BA4BA2B4(AB)2AB4AB3AB2AB4AB2AB3AB4AB2A2BA4B2(AB)A2B2(AB)A4BA2B4A3BA2B2AB3A2B3AB2A2BA3B2A-AB4A2(4B2A)4B4ABA2-BA2B2(AB)A3BA2BA3B2(AB)A2BAB3-7AB2A6B2AB7A5-2(AB)A4B2A2B2A4B2(AB)A153-A4(28-2A)28-A241-A26-A2-A26-A-2A26-4A26-2ABA26-AB2A26-4A26-2A-A26-A2-A26-A153-A24-A3-2A24-2A2-2A24-2A-B4(2A24-2A2B)2A24-2AB-2A24-2A2-2A24-2A3-A24-A95-A22-A5-2A22-2A3-3A22-3A2-3A22-3A-B4(3A22-3A2B)3A22-3AB-3A22-3A2-3A22-3A3-2A22-2A5-A22-A66-2A20-2A5-3A20-3A3-4A20-4A2-4A20-4A-B4A20-4AB5A2(20-10A)20-5AB4A20-4AB-4A20-4A2-4A20-4A3-3A20-3A5-2A20-2A38-5A10-5A8-24A5-4A18-4A3-5A18-5A2-5A18-5A-B4(5A18-5A2B)5A18-5AB-5A18-5A2-5A18-5A3-4A18-4A5-24A8-3(5A10-)5A8-24A5-4A18-4A3-5A18-5A2-5A18-5A-B5A18-5AB6A2(18-12A)18-6AB5A18-5AB-5A18-5A2-5A18-5A3-4A18-4A5-24A8-3(5A10-)5A8-24A5-4A18-4A3-5A18-5A2-5A18-5A-2(6A18-6AB5A18-5AB)6A18-6A-5A18-5A2-5A18-5A3-4A18-4A5-24A8-3(5A10-)5A8-24A5-26A3-5A18-5A2-5A18-5A-B4(5A18-5A2B)5A18-5AB-5A18-5A2-5A18-5A3-4A18-4A5-24A8-3(5A10-)5A8-24A5-26A3-5A18-5A2-5A18-5A-2(B5A18-5AB6A18-6A)B5A18-5AB-5A18-5A2-5A18-5A3-4A18-4A5-24A8-3(5A10-)5A8-24A5-26A3-28A2-7A4C6A4C7A-B6A6C4A6C6A4(2B5A8C2A8C5A)B-6A6C4A6C6A2-7A4C6A4C7A3-26A5-24A8-5A10-5A5-
