model
size = 30 15 12, scale = 0.05, origin = -y
material 
  colors = A:#699 B:#336 C:#639
voxels
6-2A2BA10-A2B2A9-AB3A10-3ABA8-7A2BA4BA2B7A5-2BA2(B3A)B2A2(B3A)BA2B3-5BAB2ABA6BAB2ABA5B2-3BAB3ABAB6ABAB3ABA3B-4AB2AB4A6B4AB2AB5ABA5BAB3A4B3ABA5BABA3BA6BAB2A2B2ABA6BA3B2A5B2AB3A4B3AB2A5B3AB4AB2A3B2A2B2A3B2AB4ABA-A2(2B3A)2B2A2(2B3A)2BA2-3BA2(2B7A)2BA3B3-2A2BABA2BAB4ABA2BABA2B2A5-2AB3A4BA2BA4B3AB2A153-A4(28-2A)28-A241-A26-A2-A26-A-2(BA26-AB2A26-2A)BA26-AB-A26-A2-A26-A153-A24-A3-2A24-2A2-2A24-2A-2(B2A24-2AB3A24-3A)B2A24-2AB-2A24-2A2-2A24-2A3-A24-A95-A22-A5-2A22-2A3-3A22-3A2-3A22-3A-4A22-4AB2(3A22-3A2B)3A22-3AB4A22-4A-3A22-3A2-3A22-3A3-2A22-2A5-A22-A66-2A20-2A5-3A20-3A3-4A20-4A2-4A20-4A-5A20-5AB2(4A20-4A2B)4A20-4AB5A20-5A-4A20-4A2-4A20-4A3-3A20-3A5-2A20-2A38-5A10-5A8-24A5-4A18-4A3-5A18-5A2-5A18-5A-2(B5A18-5AB6A18-6A)B5A18-5AB-5A18-5A2-5A18-5A3-4A18-4A5-24A8-3(5A10-)5A8-24A5-4A18-4A3-5A18-5A2-5A18-5A-B5A18-5AB6A2(18-12A)18-6AB5A18-5AB-5A18-5A2-5A18-5A3-4A18-4A5-24A8-3(5A10-)5A8-24A5-4A18-4A3-5A18-5A2-5A18-5A-B5A18-5A2B5A18-5AB6A18-6AB5A18-5A2B5A18-5AB-5A18-5A2-5A18-5A3-4A18-4A5-24A8-3(5A10-)5A8-24A5-26A3-5A18-5A2-5A18-5A-6A18-12A18-6AB5A18-5AB6A18-12A18-6A-5A18-5A2-5A18-5A3-4A18-4A5-24A8-3(5A10-)5A8-24A5-26A3-5A18-5A2-5A18-5A-6A18-6AB2(5A18-5A2B)5A18-5AB6A18-6A-5A18-5A2-5A18-5A3-4A18-4A5-24A8-3(5A10-)5A8-24A5-26A3-28A2-7A4C6A4C7A-7A6C4A6C13A8C2A8C6AB5A8C2A8C5AB6A8C2A8C12A8C2A8C6A-6A6C4A6C6A2-7A4C6A4C7A3-26A5-24A8-5A10-5A5-
