model
size = 18 30 18, scale = 0.05, origin = -y
material 
  colors = A:#888 B:#777 C:#700 D:#500 E:#800 F:#555 G:#B00
voxels
316-F252-F106-F51-A110-F287-F88-A51-A92-B323-A70-A51-A74-B359-A52-A51-A56-B395-A32-3A2(14-4A)15-2A37-B409-4A14-5A12-2(7A11-)7A10-8A9-A2-5A9-2(A16-)F342-F2(18-A)2-5A11-A-6A4(10-8A)11-5A14-4A322-F3(17-A)16-3A13-7A10-8A10-12AF5-2(9A9-)8A11-7A12-5A14-2(3B15-)BAB3-2(3C10-A4-)2CG10-A4-2DG2(10-A4-3D)15-CDC15-D2C2(10-A4-2DC)10-A4-CDG10-A3-C2AC10-A3-A13-A-2A102-4A13-7A10-8A10-9A2(8-10A)4-F4B8AB9-8A11-6A14-2(BAB15-)3B3-3(CAC15-)DAC9-3B3-CAC9-BAB3-CAG2(9-B-B3-CAD)9-BAB3-CAD9-3B3-2(CAD15-)CAC9-BAB2A13-BA-AB13-5B84-4A13-7A10-8A5-F13A2(8-10A)9-9A3BF5-8A11-6A14-2(3B15-)BAB3-2(3E10-A4-)3(EDE10-A4-)EDE15-E2D15-3D10-A4-DGD10-A4-EGD10-A4-2ED10-A3-E2AE10-A3-A13-A-2A31-F17-A17-B7-F9-B6-B10-BA4-B9-6A-B10-6AB10-8A10-2(9A9-)8A11-7A12-5A409-B3A13-B4A13-7A2(10-8A)11-7A12-5A14-2A410-B18-4A14-5A2(12-6A)13-5A14-3A409-A56-A2(16-2A)16-B37-A373-B74-A52-B55-B337-B92-A52-B73-B412-F52-F91-B259-
