model
size = 21 31 31, scale = 0.05, origin = -y
material 
  colors = A:#C90 B:#900 C:#800 D:#699 E:#200 F:#E00
voxels
344-2(AB)A15-AC3ACA12-2(CA)3B2(AC)10-ACAB3ABACA11-ABA3BABA13-ACBABCA15-2AB2A457-5A14-9A11-11A9-13A8-13A7-2A-2AF3AF2A-2A6-2A-2A2EF2E2A-2A6-15A7-13A8-13A9-11A11-9A391-7A12-3A5-3A9-2A-7A-2A7-2A2(-4A)-2A6-A-2A7-2A-A6-A-A9-A-A5-A2-A9-A2-2(A4-A-2A9-2A-)A4-2A-2A7-2A-2A5-A-3A5-3A-A6-2A2-7A2-2A7-2A3-3A3-2A9-11A13-5A329-9A10-3A6-4A7-2A2-7A2-2A6-A-2A7-2A-A5-A-2A9-2A3(-A4-A-A11-A)-A3-2(A-A13-A-A2-)A-2A11-3A4-A-A11-A-A4-A2-2A7-2A2-A5-A2-3A3-3A2-A6-2A3-5A3-2A8-3A5-3A13-5A286-11A9-2A-A5-A-2A7-A2-9A2-A5-A2-2A7-2A2-A4-A-A11-A-A2(4-2A13-2A)3-2(A-A13-A-A2-)3(2A15-2A2-)A-A13-A-2(A2-)A11-A2-A3-A-2A9-A2-A4-A3-2A5-2A3-A5-2A3-5A3-2A8-4A3-4A14-3A244-2A9-2A7-2A-9A-2A5-2A-11A-2A4-A-2A9-2A-A4-3A11-A-A3-A-A13-A-A2-2A14-A-A7(2-2A15-2A)2-A-A13-A-A2-A-A12-A2-A3-A-2A9-A2-A4-A3-2A5-2A3-A5-2A3-5A3-2A8-11A239-3A9-3A5-A-4A5-4A-A4-A-A11-A-A3-A-A13-A-A2-2A14-A-A4(2-2A15-2A)2(-A)15-A-3A17-4A17-2ABA17-AB-2(2A15-2A2-)A-A13-A-A2-A-A12-A2-A3-A-2A9-A2-A5-A2-3A3-3A2-A7-2A3-3A3-2A10-9A197-A15-A4-3A11-3A3-2(A-A13-A-A2-)4(2A15-2A2-)2A15-2A2(-A)15-A-3A17-4A17-2ABA17-ABCA17-ACBA17-AB-2(2A15-2A2-)A-A13-A-A3-A-A11-A-A4-A2-2A7-2A2-A5-2A2-7A2-2A8-11A196-2A13-2A3-A-A13-A-A4(2-2A15-2A)2-A17-A-2A17-2AB3(A17-A2B)A17-AB2A17-2ABA17-AB2A17-2A-A16-2(2A2-2A15-)2A2-A-A13-A-A3-A-A11-A-A4-2A-4A3-4A-2A6-2(3A2-)3A11-2ABAB2A176-4(2A15-2A2-)A17-A-2A2(17-4A)17-2ACA17-ACBA17-A2BA17-ABCA17-AC2A2(17-4A)17-2ABA17-AB-2(2A15-2A2-)2A15-2A3-2A13-2A4-A-3A7-3A-A5-3A-7A-3A9-2(C3A)C155-A15-A3-3(2A15-2A2-)A17-A-2A2(17-4A)17-2ACA17-AC2A3(17-4A)17-2ACA17-AC2A2(17-4A)17-2A-A17-A2(2-2A15-2A)2-A-A13-A-A3-A-2A9-2A-A5-2A-9A-2A8-2C2ACBC2A2C154-A15-A3-3(2A15-2A2-)A17-A-BA17-ABCA17-AC2A17-2ACA17-A2CA17-AC2A17-4A17-2ACA17-A2CA17-AC2A17-2ACA17-ACBA17-AB-A17-A2(2-2A15-2A)2-A-A13-A-A3-A-A11-A-A5-6A3-6A8-2(AB2AB)A153-4(2A15-2A2-)A17-A-CA17-ACBA17-A2BA17-ABCA17-A2CA17-AC2A17-4A17-2ACA17-A2CA17-ACBA17-A2BA17-ABCA17-AC-A17-A2(2-2A15-2A)2-A-A13-A-A3-A-A11-A-A2(5-5A)8-B2(C3A)CB133-A15-A3-4(2A15-2A2-)A17-A-BA17-AB2A2(17-4A)17-2AC3(A17-A2C)A17-AC2A2(17-4A)17-2ABA17-AB-A17-A2(2-2A15-2A)2-A-A13-A-A3-A-A11-A-A5-A-3A5-3A-A7-2AC3(AB)AC2A132-A15-A3-3(2A15-2A2-)A17-A2-A17-A-CA17-ACBA17-ABCA17-A2CA17-ACBA17-AB2A17-4A17-2ABA17-ABCA17-A2CA17-ACBA17-ABCA17-AC-A17-A2(2-2A15-2A)2-A-A13-A-A3-A-2A9-2A-A4-2A2-2A5-2A2-2A6-BCA2BCBC2BACB111-A15-A4-A15-A3-3(2A15-2A2-)A17-A2-A17-A-BA17-AB2A2(17-4A)17-2AB3(A17-A2B)A17-AB2A2(17-4A)17-2ABA17-AB-A17-A2(2-2A15-2A)2-A-A13-A-A3-A-2A9-2A-A4-2A2-3A3-3A2-2A6-ACAB5ABACA111-A15-A3-5(2A15-2A2-)A17-A-2(2A17-2ABA17-AB)C3(A17-A2C)A17-ACBA17-AB2A17-2ABA17-AB-2(A17-A2-)2(2A15-2A2-)A-A13-A-A3-A-2A9-2A-A4-2A2-3A3-3A2-2A6-2(AB3AB)A69-2(2A13-2A4-)2A13-2A3-6(2A15-2A2-)A17-A-2A17-2ABA17-AB2A5(17-4A)17-2ABA17-AB-2(A17-A2-)A16-2(2A2-2A15-)2A2-A-A13-A-A3-A-3A7-3A-A4-3A2-7A2-3A7-2AC2AB2AC2A50-A13-A5-4(2A13-2A4-)A15-A3-4(2A15-2A2-)2A15-2A-BA17-ABCA17-AC-A17-A-2A17-2ABA17-A2BA17-AB2A17-2ABA17-AB-3(A17-A2-)3(2A15-2A2-)A-2A11-2A-A3-A2-3A5-3A2-A5-3A2-5A2-3A9-A7CA51-A13-A5-5(2A13-2A4-)2A13-2A3-5(2A15-2A2-)2A15-2A-CA17-A2CA17-AC2A17-4A17-2ACA17-AC-3(A17-A2-)3(2A15-2A2-)A-A13-A-2(A2-)3A7-3A2-A3-A4-2(2A3-)2A5-5A-3A-4A12-B3AB53-2(2A11-2A6-)A13-A5-4(2A13-2A4-)2A13-2A3-A-A13-A-A4(2-2A15-2A)-2A17-4A17-2ABA17-A2BA17-AB-2(A17-A2-)5(2A15-2A2-)A-2A11-2A-A3-A2-3A5-3A2-A5-2A3-5A3-2A8-11A71-3(2A11-2A6-)A2(13-A5-2A)3(13-2A4-2A)13-2A3-2A14-A-A3(2-2A15-2A)3(2-A17-A)7(2-2A15-2A)2-A-2A11-2A-A2-A3-2A7-2A3-A4(3-2A)6-2A3-3A3-2A10-9A52-A11-A7-7(2A11-2A6-)2A11-2A5-2A13-2A4-2A13-2A3-3(2A15-2A2-)A16-8(2A2-2A15-)2A2-A-A13-A-2(A2-)3A7-3A2-A3-2A3-A5-A3-2A5-2A3-5A3-2A8-3A5-3A13-5A54-2A9-2A8-2A9-2A7-3(A-A9-A-A6-)A-A9-2A7-A-A9-A-A2(6-2A11-2A)5-A-A11-A-A4-2A13-2A3-A-A13-A-A10(2-2A15-2A)2-A-A13-A-2(A2-)2A9-2A2-A3-2A2-2A5-2A2-2A6-A3-2A-2A3-A8-3A3-A3-3A11-7A74-7(2A9-2A8-)2A9-2A7-2A11-2A5-A-A11-A-A2(4-2A13-2A)3-8(2A15-2A2-)A-A13-A-A2-A-2A12-A-A3-A-2A9-2A-A4-2A2-2A5-2A2-2A6-A3-A2-2A3-A9-A3-2A4-A11-4A2-3A15-3A56-2A7-2A10-2A7-2(2A9-)2A8-2A9-2A8-A-A7-A-A4(8-2A9-2A)7-2A11-2A5-A-A11-A-A2(4-2A13-2A)3-A-A13-3A2(2-2A15-2A)3-A15-A4-2A13-2A3-A-A13-3A2-A-A13-A-A3-2A13-2A4-A-A11-A-A4-A2-A8-3A-A5-A2-2A5-2A2-A7-A3-2A-2A3-A9-A3-2A4-A11-3A3-3A14-5A76-2(2A7-2A10-)2A7-2A9-A-A7-2A10-2A7-2A10-2(A9-)2(2A9-2A8-)2A9-2A7-2A11-2A6-2A11-2A5-A-A11-A-A7(4-2A13-2A)4-A-A11-A-A4-A-2A9-2A-A4-A2-2A7-2A-2A5-A2-2A4-2A3-A7-A3-2A-2A3-A9-2A3-A3-2A11-3A3-3A15-3A99-3A3-3A11-3(A-A5-A-A10-)2A7-2A10-2A7-2A9-2(A-A7-A-A8-)2A9-2A7-2(A-A9-A-A6-)2A2(11-2A5-A-A)2(11-A-A4-A-A)11-A-A4-3A11-3A4-3A10-2A-A4-A-2A9-2A-A4-2A-A9-A-2A5-A2-2A5-2A2-A6-2A2-2A3-2A2-A8-2A2-4A3-2A9-3A2-A2-3A12-7A16-3A120-9A12-A-5A-A2(12-2A5-2A)11-3(A-A5-A-A10-)2A7-2A9-A-A7-A-A8-2A8-A-A8-2A9-2A7-2(A-A9-A-A6-)A-2A7-2A-A2(6-4A7-4A)7-3A6-2(4A7-)A-2A6-2A-2A5-2A-2A7-A-3A3-3A-A8-2A2-5A2-2A9-2(3A-)3A11-9A14-5A162-7A14-3A-3A14-7A13-A2(-2A)3(-A12-A-5A)-A11-11A10-A-7A-A10-9A-A9-6A-6A8-5A3-5A2(8-6A-6A)9-2(11A10-)D7A-AD10-AD7ADA10-AD-5A-DA10-2(3A-)3A11-9A14-5A228-A18-5A15-3(7A14-)AB3ABA14-AB3ABA13-2A2(BA)B2A12-3A3B3A3(12-9A)13-3(7A14-)A5DA14-2(D2A)D14-7D15-5A239-
