model
size = 32 31 32, scale = 0.05, origin = -y
material 
  colors = A:#AAA B:#C96 C:#EEE D:#633 E:#555
voxels
32-CA1883-2(3D29-)3D892-3B29-3BD28-2BAD29-3D859-3B29-4B28-2B2AD28-3BD30-2D826-3B29-4B28-2B2AB28-4B30-2B794-E30-E3B29-4B28-B3AB28-4B30-2B827-2E29-E3B28-EB2AB28-2BAB30-2B861-2E28-2A2B28-2E2B30-2B891-3A30-CA2E29-2E891-22(3A30-CA924-)3A30-CA957-
