model
size = 30 15 12, scale = 0.05, origin = -y
material 
  colors = A:#9F0 B:#660 C:#C6C
voxels
6-2BA2B10-2BA2B9-3BAB10-BA3B8-2A5B2(2A2B)2A5B2A5-2A2(2BA6BA)2B2A3-2(BA)4B2A2B4A2B2A4B2(AB)2-B2A7B2(2AB)2A7B2AB-A3BA2BAB2A2B4A2B2ABA2BA3BABA5BA3BABA2BABA3BA5B3(AB)2AB3A2(BA)2B2(AB)3AB2A2(BA)B2A2B4A2B2A4B2A2B4A2B2A2(BA)4B4AB2A2B2AB4A4BABA-3ABA2B2ABAB4ABAB2A2BAB3A2-AB3ABA2BA8BA2BAB3ABA3-3A2BA3BAB4ABA3BA2B3A5-ABA2BAB2AB4AB2ABA2BABA153-A4(28-2A)28-A241-A26-A2-A26-A-B4(A26-A2B)A26-AB-A26-A2-A26-A153-A24-A3-2A24-2A2-2A24-2A-2(B2A24-2AB3A24-3A)B2A24-2AB-2A24-2A2-2A24-2A3-A24-A95-A22-A5-2A22-2A3-3A22-3A2-3A22-3A-B3A22-3AB4A2(22-8A)22-4AB3A22-3AB-3A22-3A2-3A22-3A3-2A22-2A5-A22-A66-2A20-2A5-3A20-3A3-4A20-4A2-4A20-4A-5A4(20-10A)20-5A-4A20-4A2-4A20-4A3-3A20-3A5-2A20-2A38-5A10-5A8-24A5-4A18-4A3-5A18-5A2-5A18-5A-6A18-12A18-6AB5A18-5AB6A18-12A18-6A-5A18-5A2-5A18-5A3-4A18-4A5-24A8-3(5A10-)5A8-24A5-4A18-4A3-5A18-5A2-5A18-5A-B5A18-5A2B5A18-5AB6A18-6AB5A18-5A2B5A18-5AB-5A18-5A2-5A18-5A3-4A18-4A5-24A8-3(5A10-)5A8-24A5-4A18-4A2(3-5A18-5A2-5A18-5A-2(B5A18-5AB6A18-6A)B5A18-5AB-5A18-5A2-5A18-5A3-4A18-4A5-24A8-3(5A10-)5A8-24A5-26A)3-5A18-5A2-5A18-5A-B5A18-5AB6A2(18-12A)18-6AB5A18-5AB-5A18-5A2-5A18-5A3-4A18-4A5-24A8-3(5A10-)5A8-24A5-26A3-28A2-7A4C6A4C7A-B6A6C4A6C6A2B5A8C2A8C5AB6A8C2A8C6AB5A8C2A8C5A2B5A8C2A8C5AB-6A6C4A6C6A2-7A4C6A4C7A3-26A5-24A8-5A10-5A5-
