model
size = 32 10 31, scale = 0.05, origin = -y
material 
  colors = A:#FC3 B:#3CF C:#E00 D:#001
voxels
13A5-27A5-16A9C2A5-2A10B4A9C3A3-3A10B4A9C4A-4A3(10B4A9C9A)10B79A5-27A5-16A9-2A5-2A10-4A9-3A3-3A10-4A9-4A-4A10-4A9-9A10-AD2A9-9A10-4A9-9A10-AD63AD13A5-27A5-16A9-2A5-2A10-4A9-3A3-3A10-4A9-4A-4A10-4A9-9A10-AD2A9-9A10-4A9-9A10-AD63ADA5(30-2A)5(30-DA)9(30-2A)30-A32-A5(30-2A)30-DA2(30-2A)30-D64-A4(30-2A)3(30-DA)30-D96-A3(30-2A)30-DA2(30-2A)30-D128-A5(30-2A)30-A160-A2(30-2A)2(30-DA)30-A192-A30-DA2(30-2A)30-D192-4(A30-D)192-A3(30-2A)2(30-A192-A30-DA2(30-2A))30-A192-4(A30-D)192-A3(30-2A)30-A192-4(A30-D)192-A30-DA2(30-2A)30-D192-4(A30-D)192-A3(30-2A)30-A2(192-A30-DA2(30-2A)30-D)192-4(A30-D)160-A4(30-2A)30-A128-A5(30-2A)30-A96-A6(30-2A)30-A64-A6(30-2A)30-A32-A7(30-2A)30-A64-A6(30-2A)30-A96-A3(30-2A)30-A192-
