model
size = 26 32 26, scale = 0.05, origin = -y
material 
  colors = A:#FEBFC7 B:#9AA9BC C:#7D0028 D:#ED00A8 E:#3588FE F:#9AD0FF G:#71F7B2 H:#C34B29 I:#FEEA41 J:#8214D4 K:#FF7200 L:#EDE8FF M:#1E1729 N:#FFD240 O:#FDA228 P:#84492C Q:#990027
voxels
354-4N6I16-4N6I872-2D24-2D22-3(2D24-)2D22-2D24-2D22-3(2E24-)2E26-2E24-2E496-2D24-2D22-3(2D24-)2D22-2D24-2D22-3(2E24-)2E26-2E24-2E74-2(8C18-)2(2A4I2G18-)2(4I4G18-)2(2I4G2F18-)2(4G4F18-)2(2G4F2E18-)2(4F4E18-)2(2F4E4D16-)4E2J2B2D16-4E2J2B2D14-2(4E2J2B2D16-)4J2D2B2J16-4J2D2B2J18-2(2D2C6D16-)2E2F4G18-2E2F4G2(16-2G4E2F2G)2(18-2G4E2F)4(18-8C)2(18-2A4I2G)2(18-4I4G)2(18-2I4G2F)2(18-4G4F)2(18-2G4F2E)2(18-4F4E)18-2(2F4E4D16-)4E2J2B2D16-4E2J2B2D14-2(4E2J2B2D16-)4J2D2B2J16-4J2D2B2J18-2(2D2C6D16-)2E2F4G18-2E2F4G2(16-2G4E2F2G)2(18-2G4E2F)2(18-8C)14-2(16C10-)2(2(12A2G2F10-)2(12A4F10-)2(2A2I8A2F2E10-)2(4I8C4E10-)2(2I2G8B2E2J10-)2(4G8B4D10-)2(2G2F8B2F2D10-)2(2G2F10B2J10-)2(2F2E8B2J2A10-)2(4E8B2J4A8-)2(4J8C4D10-)2(2G2E8A4I10-)2(2A2G8A2G2I10-)2(12A4G10-)4(16C10-))2(14A2F10-)2(14A2E10-)2(2I12A2E10-)2(2I12C2J10-)2(2G12B2F2D8-)2(2G12B2J10-)2(2F12B2A10-)2F12B2F2A2D6-2F2(12B2F2A2D4-4E)12B2F2A2D2(4-2J2E12B2F4A)6-2(2J12C4A8-)2E12A4D8-2E12A4D6-4G12A2I8-4G12A2(2I10-14A)2I4(10-16C)2(10-14A2F)2(10-14A2E)2(10-2I12A2E)2(10-2I12C2J)10-2(2G12B2F2D8-)2(2G12B2J10-)2(2F12B2A10-)2F12B2F2A2D6-2F2(12B2F2A2D4-4E)12B2F2A2D2(4-2J2E12B2F4A)6-2(2J12C4A8-)2E12A4D8-2E12A4D6-4G12A2I8-4G12A2(2I10-14A)2I2(10-16C)8-2(20C6-)2(18A2E6-)2(2I16A2E6-)2(2I18A6-)2(2G16C2H6-)2(2G16B2H6-)2(2F16B2H6-)2(2F16B2A2D4-)4(2E16B2A6-)2(2J16B4D4-)2D16C4A4-2D16C4A2-2(4E18A4-)4E16A2D4-4E2(16A2D6-2G)16A2D4(6-20C)2(6-18A2E)2(6-2I16A2E)2(6-2I18A)2(6-2G16C2H)2(6-2G16B2H)2(6-2F16B2H)6-2(2F16B2A2D4-)4(2E16B2A6-)2(2J16B4D4-)2D16C4A4-2D16C4A2-2(4E18A4-)4E16A2D4-4E2(16A2D6-2G)16A2D4(6-20C)2(6-2I16A2E)2(6-2I18A)2(6-2G16A2H)2(6-2G16C2H)2(6-2F16B2Q)6-2(2F18B2K4-)2E16B2L6-2E4B2M6B2M2B2L2(6-2E16B2J)2(6-2J16B2L)6-2D18B2D4-2D18B2D2(2-2D18C4A)4-2(2F18A6-)2E16A2D6-2E2(16A2D4-4E)16A2D4(6-20C)2(6-2I16A2E)2(6-2I18A)2(6-2G16A2H)2(6-2G16C2H)2(6-2F16B2Q)6-2(2F18B2K4-)2E16B2L6-2E4B3(2M2B)2L2(6-2E16B2J)2(6-2J16B2L)6-2D18B2D4-2D18B2D2(2-2D18C4A)4-2(2F18A6-)2E16A2D6-2E2(16A2D4-4E)16A2D4(6-20C)4(6-2G18A)2(6-2G16A2H)6-2(2F18C2K4-)2(2F14B2C8-)2(2E16B2H2K4-)2E16B2L6-2E4B3(2M2B)2L2(6-2J16B2M)2(4-2D18B2L)4-2D18B2F2D2-2D18B2F2D4-2(2G16C2A6-)2(2G18A6-)2(2F16A2D6-)2(2E16A2E6-)4(20C6-)4(2G18A6-)2(2G16A2H6-)2(2F18C2K4-)2(2F14B2C8-)2(2E16B2H2K4-)2E16B2L6-2E4B3(2M2B)2L2(6-2J16B2M)2(4-2D18B2L)4-2D18B2F2D2-2D18B2F2D4-2(2G16C2A6-)2(2G18A6-)2(2F16A2D6-)2(2E16A2E6-)2(4(20C6-)2(2G18A6-)2(2G16A2H6-)2(2F16A2K6-)2(2F16C2H2K4-)2(2E12B2C10-)2(2E14B2C2H2K4-)2D16B2L6-2D4B10M2B2L2(4-2D18B2M)2(6-2D16B2L)6-2(2J14B2D2A2D4-)2(2D14C2D2A6-)4(2G16A2D6-)2(2F16A2E6-))20C6-20C8-2(16C10-)2(2G12A2C10-)2(2F12A4H8-)2(2F12A2H2K8-)2(2E12C4H2O6-)2(2E8B2C14-)2D10B4C4H2N4-2D10B4C4H2N2-2(2D2F14B2F2O4-)2D16B2L6-2D16B2L2(8-2J12B4D)2(8-2J10B2P2D2A)6-4D12C2D8-4D12C2(2D10-2I12A)2D4(10-2G12A2E)4(10-16C)2(10-2G12A2C)10-2(2F12A4H8-)2(2F12A2H2K8-)2(2E12C4H2O6-)2(2E8B2C14-)2D10B4C4H2N4-2D10B4C4H2N2-2(2D2F14B2F2O4-)2D16B2L6-2D16B2L2(8-2J12B4D)2(8-2J10B2P2D2A)6-4D12C2D8-4D12C2(2D10-2I12A)2D4(10-2G12A2E)4(10-16C)2(10-4F8A4C)2(10-2F2E8A4H)10-2(4E8A4H2K8-)2(2E2J8C2H4C2N6-)2(2J2F4B2C16-)2(2D2J6B8C2H2N4-)2(2D2A14B2O6-)2(2J2A4B2J2B2F2B2C8-)2(4A8B2D2P2D8-)2(2A2D6B4D2A10-)2(2D2A6C6D10-)2(2I10A2D2E10-)2(4I8A4E10-)2(2G2I8A2E2C10-)4(16C10-)2(4F8A4C10-)2(2F2E8A4H10-)2(4E8A4H2K8-)2(2E2J8C2H4C2N6-)2(2J2F4B2C16-)2(2D2J6B8C2H2N4-)2(2D2A14B2O6-)2(2J2A4B2J2B2F2B2C8-)2(4A8B2D2P2D8-)2(2A2D6B4D2A10-)2(2D2A6C6D10-)2(2I10A2D2E10-)2(4I8A4E10-)2(2G2I8A2E2C10-)16C10-16C14-2(8C18-)2(4E4A18-)2(2E4A4H16-)2(2A4H8K12-)2(4H2C)2O2I10-2(4H2C)2O2I8-2D2H2Q20-2D2H2Q22-2(2H2B6H4C2H2I8-)2A6L2O4B2N10-2A6L2O4B2N8-2(4A2J4M2L4C10-)4A6L4D2C10-4A6L4D2C8-4A2D4B4A12-4A2D4B4A14-2(10A16-)2D6A2D16-2D6A2D2(18-8D)2(18-2I6E)4(18-8C)2(18-4E4A)18-2(2E4A4H16-)2(2A4H8K12-)2(4H2C)2O2I10-2(4H2C)2O2I8-2D2H2Q20-2D2H2Q22-2(2H2B6H4C2H2I8-)2A6L2O4B2N10-2A6L2O4B2N8-2(4A2J4M2L4C10-)4A6L4D2C10-4A6L4D2C8-4A2D4B4A12-4A2D4B4A14-2(10A16-)2D6A2D16-2D6A2D2(18-8D)2(18-2I6E)2(18-8C)230-4K2O2N4I14-4K2O2N4I64-6K6H2P2I10-6K6H2P2I8-2D6-4O4N10-2D6-4O4N8-4(2D24-)2A8D16-2A8D18-4A22-4A442-4K2O2N4I14-4K2O2N4I64-6K6H2P2I10-6K6H2P2I8-2D6-4O4N10-2D6-4O4N8-4(2D24-)2A8D16-2A8D18-4A22-4A550-4N6I16-4N6I468-
