model
size = 19 28 19, scale = 0.05, origin = -y
material 
  colors = A:#222 B:#444 C:#777
voxels
4-8A10-2A4-2AB2A7-2A5-2A2(BA)5-2A6-2(2ABAB3A3-A7-)2ABAB3A2-2A7-14(2ABAB3A2-A8-)2ABAB3A2-2A2(7-2ABAB3A3-A)7-2A2(BA)5-2A6-2AB2A7-2A5-4A9-2A2-3A13-4A15-8A10-2A4-5A7-2A5-6A5-2A6-8A3-A6-11A-A6-13A6-12A2(8-11A)4(7-12A)7(7-9A2-A)7-9A2-2A2(6-9A3-A)6-7A5-2A5-6A7-2A5-4A9-2A2-3A13-4A20-6(3A16-5A14-6A13-8A10-2(11A8-)11A2(9-10A)8-11A8-10AB2(8-11A)8-10(9A10-)7A12-6A14-4A53-)2(3A16-5A14-6A13-8A10-2(11A8-)11A2(9-10A)8-11A8-10AB2(8-11A)8-4(9A10-)2(9AC9-2(9A10-))7A12-6A14-4A53-)3A16-5A14-6A13-8A10-2(11A8-)11A2(9-10A)8-11A8-10AB2(8-11A)8-5(9A10-)2(9AC9-)3(9A10-)5(7A12-6A14-4A53-3A16-5A14-6A13-8A10-2(11A8-)11A2(9-10A)8-11A8-10AB2(8-11A)8-10(9A10-))7A12-6A14-4A48-8A10-2A4-5A7-2A5-6A5-2A6-8A3-A6-11A-A6-13A6-12A2(8-11A)4(7-12A)7(7-9A2-A)7-9A2-2A2(6-9A3-A)6-7A5-2A5-6A7-2A5-4A9-2A2-3A13-4A15-8A10-2A4-5A7-2A5-6A5-2A6-2(8A3-A7-)8A2-2A7-2(8A2-A8-)12(2AC5A2-A8-)2AC5A2-2A2(7-2AC5A3-A)7-3AC2A5-2A6-5A7-2A5-4A9-2A2-3A13-4A116-6A13-6A402-
