model
size = 20 29 13, scale = 0.05, origin = -y
material 
  colors = A:#222 B:#777 C:#AAA D:#555 E:#FFF F:#FFC G:#009 H:#00C I:#00F J:#444 K:#D00 L:#0E0 M:#500
voxels
23-16C4-12A2-2A4(4-16A)3(4-5A9-2A)4-16A4-16C4-15A5-7A313-16D2-2CA15BC-2A12BLK2B4(A-2A16B)A-2A5B9I2BA-2A5B9H2BA-2A5B9G2BA-2A16BA-2C15B2C-2A14BA3-17A303-3D14AD-C18BCA8(18B2A)18BAC17B2CA16BA2-5A3B10A7-2(3D17-)2(3F17-)3(3E17-)3D17-3D133-D16AD-C18BCA8(18B2A)18BAC17B2CA16BA2-4A5B9A6-2(D3BD15-)2(F3BF15-)3(E3BE15-)D3BD15-5D132-D16AD-C4B3A11BCA8(4B3A11B2A)4B3A11BAC4B3A10B2CA4B3A9BA2-2(3A2B)8A5-2(DB3ABD13-)2(FB3ABF13-)2(EB3ABE13-)EB3JBE13-D5BD13-2D4BD15-4(3C17-)3C18-C14-D16AD-C2B16ACA5(2B18A)3(2B6A8B4A)2B17AC2B15A2CA2B6A8BA2-2A2(B7A)4-2(DB5ABD11-)2(FB5ABF11-)2(EB5ABE11-)EBJ2A2JBE11-D7BD11-2D5B2D13-4(C3BC15-)C3BC16-3C13-D16AD-C2B16ACA5(2B18A)3(2B6A8B4A)2B17AC2B15A2CA2B6A8BA2-2A2(B7A)4-2(DB5ABD11-)2(FB5ABF11-)2(EB5ABE11-)EBJ2A2JBE11-D7BD11-2D5B2D13-5(C3BC15-)5C12-D16AD-C2B16ACA5(2B18A)3(2B6A8B4A)2B17AC2B15A2CA2B6A8BA2-2A2(B7A)4-2(DB5ABD11-)2(FB5ABF11-)2(EB5ABE11-)EB5JBE11-D7BD11-2D5B2D13-4(C3BC15-)C3BC16-3C13-D16AD-C2B16ACA5(2B18A)3(2B5A9B4A)2B17AC2B15A2CA2BAB3A9BA2-18A5-DBAJABD13-DBAMABD13-FB3ABF13-F5BF3(13-E5BE)13-D5BD13-2D3B2D15-4(3C17-)3C18-C14-D16AD-C2B16ACA5(2B18A)3(2B5A9B4A)2B17AC2B15A2CA2BA13BA2-18A6-2(D3BD15-)2(F3BF15-)3(E3BE15-)D3BD15-5D132-3D14AD-C2B16ACA5(2B18A)3(2B5A9B4A)2B17AC2B15A2CA2BA13BA2-18A7-2(3D17-)2(3F17-)3(3E17-)3D17-3D135-16D2-2C16AC-14ALK3A4(-19A)-7A9I3A-7A9H3A-7A9G3A-19A-2C15A2C-3A13BA3-17A325-16C4-12A2-2A4(4-16A)3(4-5A9-2A)4-16A4-16C4-15A5-7A310-
