model
size = 20 29 13, scale = 0.05, origin = -y
material 
  colors = A:#33C B:#777 C:#222 D:#AAA E:#555 F:#FCF G:#FFF H:#050 I:#090 J:#0C0 K:#0F3 L:#444 M:#D00 N:#0E0 O:#500
voxels
23-16D4-12A2-2A4(4-16A)3(4-5A9-2A)4-16A4-16D4-15A5-7A313-16E2-2DC15BD-2A2(B4A)2BNM2BA-2A3B6A7BA-2A5B4A7BA-2A7B3A6BA-2A7B4A5BA-2A5B9K2BA-2A5B9J2BA-2A3B2A9I2BA-2A2B5A9BA-2D15B2D-12A4BA3-17A303-3E14AE-D18BDA2H2(B4A)6B2A2H3B6A7B2A2H5B4A7B2A2H7B3A6B2A2H7B4A5B2(2A2H16B)2A2H3B2A11B2A2H2B5A9BAD17B2D2AB15A2-18A7-2(3E17-)2(3F17-)3(3G17-)3E17-3E133-E16AE-D18BDA2H2(B4A)6B2A2H3B6A7B2A2H5B4A7B2A2H7B3A6B2A2H7B4A5B2(2A2H16B)2A2H3B2A11B2A2H2B5A9BAD17B2DA12B5A2-18A6-2(E3BE15-)2(5F15-)3(G3BG15-)E3BE15-5E132-E16AE-D4B3C11BDA3B4AB4A6B2A4BC6A7B2A4B3C4A7B2A4B3C2B3A6B2A4B3C2B4A5B2(2A4B3C11B)2A4BC2A4B9A4B5A2B8AD4B3C10B2DA4B3C5B5A2-18A5-2(EB3CBE13-)7F13-2F3C2F2(13-GB3CBG)13-GB3LBG13-E5BE13-2E4BE15-4(3D17-)3D18-D14-E16AE-D2B16CDA2B2(C4A)6C2A2B3C6A7C2A2B5C4A7C2A2B7C3A6C2A2B7C4A5C2(2A2B6C8B2C)2A2B3C2AC8B2C2A2B2C5A2C8AD2B15C2DA2B6C4B5A2-18A4-2(EB5CBE11-)3F4C2F11-3F3C3F2(11-GB5CBG)11-GBL2C2LBG11-E7BE11-2E5B2E13-4(D3BD15-)D3BD16-3D13-E16AE-D2B16CDA2B2(C4A)6C2A2B3C6A7C2A2B5C4A7C2A2B7C3A6C2A2B7C4A5C2(2A2B6C8B2C)2A2B3C2AC8B2C2A2B2C5A2C8AD2B15C2DA2B6C4B5A2-18A4-2(EB5CBE11-)3F4C2F11-3F3C3F2(11-GB5CBG)11-GBL2C2LBG11-E7BE11-2E5B2E13-5(D3BD15-)5D12-E16AE-D2B16CDA2B2(C4A)6C2A2B3C6A7C2A2B5C4A7C2A2B7C3A6C2A2B7C4A5C2(2A2B6C8B2C)2A2B3C2AC8B2C2A2B2C5A9CAD2B15C2DA2B6C4B5A2-18A4-2(EB5CBE11-)2(9F11-)2(GB5CBG11-)GB5LBG11-E7BE11-2E5B2E13-4(D3BD15-)D3BD16-3D13-E16AE-D2B16CDA2B2(C4A)6C2A2B3C6A7C2A2B5C4A7C2A2B7C3A6C2A2B7C4A5C2(2A2B5C9B2C)2A2B3C2A9B2C2A2B2C5A9CAD2B15C2DA2BCB3C5B5A2-18A5-EBCLCBE13-EBCOCBE2(13-7F)3(13-G5BG)13-E5BE13-2E3B2E15-4(3D17-)3D18-D14-E16AE-D2B16CDA2B2(C4A)6C2A2B3C6A7C2A2B5C4A7C2A2B7C3A6C2A2B7C4A5C2(2A2B5C9B2C)2A2B3C2A9B2C2A2B2C5A9CAD2B15C2DA2BC9B5A2-18A6-2(E3BE15-)2(5F15-)3(G3BG15-)E3BE15-5E132-3E14AE-D2B16CDA2B2(C4A)6C2A2B3C6A7C2A2B5C4A7C2A2B7C3A6C2A2B7C4A5C2(2A2B5C9B2C)2A2B3C2A9B2C2A2B2C5A9CAD2B15C2DA2BC9B5A2-18A7-2(3E17-)2(3F17-)3(3G17-)3E17-3E135-16E2-2D16CD-2A2(C4A)2CNM2CA-2A3C6A7CA-2A5C4A7CA-2A7C3A6CA-2A7C4A5CA-2A5C9K2CA-2A5C9J2CA-2A3C2A9I2CA-2A2C5A9CA-2D15C2D-17A3-17A325-16D4-12A2-2A4(4-16A)3(4-5A9-2A)4-16A4-16D4-15A5-7A310-
