model
size = 20 29 13, scale = 0.05, origin = -y
material 
  colors = A:#777 B:#222 C:#906 D:#AAA E:#555 F:#FFF G:#6FF H:#009 I:#00C J:#00F K:#444 L:#D00 M:#0E0 N:#500
voxels
23-16D4-12C2-2C4(4-16C)3(4-5C9-2C)4-16C4-16D4-15C5-7C313-16E2-2DB15AD-2C12AML2A4(C-2C16A)C-2C5A9J2AC-2C5A9I2AC-2C5A9H2AC-2C16AC-2D15A2D-2C14AC3-17C303-3E14CE-D18ADC8(18A2C)18ACD17A2DC16AC2-5C3A10C7-2(3E17-)2(3G17-)3(3F17-)3E17-3E133-E16CE-D18ADC8(18A2C)18ACD17A2DC16AC2-4C5A9C6-2(E3AE15-)2(G3AG15-)3(F3AF15-)E3AE15-5E132-E16CE-D4A3B11ADC8(4A3B11A2C)4A3B11ACD4A3B10A2DC4A3B9AC2-3C2A3B2A8C5-2(EA3BAE13-)2(GA3BAG13-)2(FA3BAF13-)FA3KAF13-E5AE13-2E4AE15-4(3D17-)3D18-D14-E16CE-D2A16BDC5(2A16B2C)3(2A6B8A2B2C)2A16BCD2A15B2DC2A6B8AC2-2CA7BA7C4-2(EA5BAE11-)2(GA5BAG11-)2(FA5BAF11-)FAK2B2KAF11-E7AE11-2E5A2E13-4(D3AD15-)D3AD16-3D13-E16CE-D2A16BDC5(2A16B2C)3(2A6B8A2B2C)2A16BCD2A15B2DC2A6B8AC2-2CA7BA7C4-2(EA5BAE11-)2(GA5BAG11-)2(FA5BAF11-)FAK2B2KAF11-E7AE11-2E5A2E13-5(D3AD15-)5D12-E16CE-D2A16BDC5(2A16B2C)3(2A6B8A2B2C)2A16BCD2A15B2DC2A6B8AC2-2CA7BA7C4-2(EA5BAE11-)2(GA5BAG11-)2(FA5BAF11-)FA5KAF11-E7AE11-2E5A2E13-4(D3AD15-)D3AD16-3D13-E16CE-D2A16BDC5(2A16B2C)3(2A5B9A2B2C)2A16BCD2A15B2DC2ABA3B9AC2-3C7B8C5-EABKBAE13-EABNBAE13-GA3BAG13-G5AG3(13-F5AF)13-E5AE13-2E3A2E15-4(3D17-)3D18-D14-E16CE-D2A16BDC5(2A16B2C)3(2A5B9A2B2C)2A16BCD2A15B2DC2AB13AC2-4C5B9C6-2(E3AE15-)2(G3AG15-)3(F3AF15-)E3AE15-5E132-3E14CE-D2A16BDC5(2A16B2C)3(2A5B9A2B2C)2A16BCD2A15B2DC2AB13AC2-5C3B10C7-2(3E17-)2(3G17-)3(3F17-)3E17-3E135-16E2-2D16BD-2C12BML2B4(C-2C16B)C-2C5B9J2BC-2C5B9I2BC-2C5B9H2BC-2C16BC-2D15B2D-2CB13AC3-17C325-16D4-12C2-2C4(4-16C)3(4-5C9-2C)4-16C4-16D4-15C5-7C310-
