model
size = 20 29 13, scale = 0.05, origin = -y
material 
  colors = A:#777 B:#222 C:#050 D:#AAA E:#555 F:#040 G:#020 H:#FFF I:#C33 J:#070 K:#009 L:#00C M:#00F N:#444 O:#D00 P:#0E0 Q:#500
voxels
23-16D4-G4C4FCGC2-2C4-G2C2GC2FGC2G3CG4-3CG2CF2GCJG3CG4-4F2CF2G2C2FC2G4-FGJ3CGF2C4FCG4-C2G2C9-2C4-C3GC9-2C4-C2G2F9-2C4-CG5F4CG4C4-16D4-2G2C2F4C2G2CF5-G4C2F313-16E2-2DB15AD-FG12APO2A2(C-2C16A)J-CF16AG-GF16AG-CF5A9M2AG-CF5A9L2AF-2C5A9K2AC-2C16AC-2D15A2D-FJ14AF3-F2G8C3GJ2F303-3E14CE-D18AD2(F2C16AC)J2(2C16ACG)2C16A2G2C2(16AF3C)16ACF2C16ACD17A2DF16AF2-2FG2C3A4C2F2G2F7-2(3E17-)2(3I17-)3(3H17-)3E17-3E133-E16CE-D18ADF2C16AG3C16A4C2(16ACG2C)2(16A4C)2(16AF3C)16ACD17A2DC16AC2-J3C5AJF2J2F3C6-2(E3AE15-)2(I3AI15-)3(H3AH15-)E3AE15-5E132-E16CE-D4A3B11AD2(C4A3B11AG)C4A3B11AFC4(4A3B11A2C)4A3B11AJC4A3B11AJD4A3B10A2DC4A3B9AC2-3C2A3B2AF2J4CG5-2(EA3BAE13-)2(IA3BAI13-)2(HA3BAH13-)HA3NAH13-E5AE13-2E4AE15-4(3D17-)3D18-D14-E16CE-D2A16BDC2A16BGC2A16BFG2A16BCF2(2A16B2C)2(2A6B8A2B2C)2A6B8A2BGC2A16BJD2A15B2DF2A6B8AG2-GJA7BAJF4CG4-2(EA5BAE11-)2(IA5BAI11-)2(HA5BAH11-)HAN2B2NAH11-E7AE11-2E5A2E13-4(D3AD15-)D3AD16-3D13-E16CE-D2A16BDC2A16BFC2A16B2F2(2A16BCF)2A16B3(2C2A6B8A2B)CF2A16BJD2A15B2DF2A6B8AJ2-2GA7BAF3C3G4-2(EA5BAE11-)2(IA5BAI11-)2(HA5BAH11-)HAN2B2NAH11-E7AE11-2E5A2E13-5(D3AD15-)5D12-E16CE-D2A16BDG2A16BFC4(2A16B2C)2A6B8A2BFC2A6B8A2B2F2A6B8A2BCG2A16BCD2A15B2DF2A6B8AC2-2GA7BA2C2F2GF4-2(EA5BAE11-)2(IA5BAI11-)2(HA5BAH11-)HA5NAH11-E7AE11-2E5A2E13-4(D3AD15-)D3AD16-3D13-E16CE-D2A16BDF2A16B2C2A16BGC2A16B2G2(2A16BFC)2(2A5B9A2BFG)2A5B9A2BCJ2A16BCD2A15B2DC2ABA3B9AC2-3C7B2G3C3F5-EABNBAE13-EABQBAE13-IA3BAI13-I5AI3(13-H5AH)13-E5AE13-2E3A2E15-4(3D17-)3D18-D14-E16CE-D2A16BD2(F2A16BC)G2(2A16B2G)2A16BGC2A5B9A2BFC2(2A5B9A2BCG)2A16BCD2A15B2DC2AB13AF2-4C5B4G3CJF6-2(E3AE15-)2(I3AI15-)3(H3AH15-)E3AE15-5E132-3E14CE-D2A16BDF2A16B2F2A16BCJ2A16B2G2A16BGF2A16BJG3(2A5B9A2B2C)2A16BCD2A15B2DC2AB13AF2-2F3C3BC2G2F5C7-2(3E17-)2(3I17-)3(3H17-)3E17-3E135-16E2-2D16BD-FG12BPO2BF-FC16BF3(-2C16BC)-2C5B9M2BC-2C5B9L2BG-2C5B9K2BG-CG16BF-2D15B2D-FCB13AJ3-FJC3F3CJ2F3C2G325-16D4-2(G4C)2F2-CG4-2GF6CG2F3CF4-JG3F4CF2G3CF4-2C2G3F3C2G4C4-2C4GF4CGC2JC4-3C2G9-JC4-4CG9-2C4-G4C9-CG4-2G5CJG6CF4-16D4-FGF4C3F3CFG5-2G2F3C310-
