model
size = 16 21 13, scale = 0.05, origin = -y
material 
  colors = A:#DDD B:#960 C:#CC6
voxels
110-B271-4(B15-)B255-B15-B303-B15-B319-2(B335-)2(B15-B335-)4(B15-)2(B335-2(B15-))B15-B277-5B9-2B5A2B6-2B7A2B5-B9AB2-B-B11A2(B-)B11A2(BC)B11AB2-CB11AB3CB11AB4-B9AB5-2B7A2B6-2B5A2B9-5B155-5C10-2C3-2C8-2C5-2C6-2C7-2C3(5-C9-C)5-2C7-2C6-2C5-2C8-2C3-2C10-5C23-
