model
size = 19 31 19, scale = 0.05, origin = -y
material 
  colors = A:#F6F B:#FF4BFF C:#FF09FF D:#DDD E:#AAA F:#E44BFF
voxels
4-5B3A10-2B4-5A7-2B5-2AB3A5-2B6-2AB5A2(3-B7-2ABAB3A)2-2B7-14(2ABAB3A2-B8-)2ABAB3A2-2B2(7-2ABAB3A3-B)7-2AB3A5-2B6-2AB2A7-2B5-4A9-2B2-B2A13-4B72-5B3A10-2B4-5A7-2B5-3AC2A5-2B6-3AC4A3-B6-B3AC4A2B-B6-B3AC4A4B6-B4C2(4A3B8-A3C)4A3B7-BA3C4A3B7-B4C4A3(3B7-B8A)7(2-B7-B8A)2-2B2(6-B8A3-B)6-B6A5-2B5-B5A7-2B5-4A9-2B2-B2A13-4B77-3A16-5A14-3AC2A13-3AC4A10-2(B3AC4A2B8-)B4C2(4A2B9-A3C)4A2B8-BA3C4A2B8-B4C4A3(2B8-B8A)9(10-B8A)10-B6A12-B5A14-4A17-2(A18-)A54-3A16-5A14-3AC2A13-3AC4A10-2(B3AC4A2B8-)B4C2(4A2B9-A3C)4A2B8-BA3C4A2B8-B4C4ABE2(8-B8A2B)8-10(B2C6A10-)B2C4A12-B2C3A14-4A17-2(D18-)A18-A35-3A16-5A14-3AC2A13-3AC4A10-2(B3AC4A2B8-)B4C2(4A2B9-A3C)4A2B8-BA3C4A2B8-B4C4ABE2(8-B8A2B)8-2(B2C6A10-)4(B2C5AD10-)4(B2C6A10-)B2C4A12-B2C3A14-4A17-3(D18-)A18-A16-3A16-5A14-3AC2A13-3AC4A10-2(B3AC4A2B8-)B2(A3C4A2B9-)2(A3C4A2B8-B)A3C4ABE2(8-B8A2B)8-BA3C4A4(10-BA3C3AD)4(10-B3C4AD)10-B3C5A10-B3C3A12-B3C2A14-4A17-2(D18-)A18-A35-3A16-5A14-3AC2A13-3AC4A10-2(B3AC4A2B8-)B2(A3C4A2B9-)2(A3C4A2B8-B)A3C4ABE2(8-B8A2B)8-BA3C4A4(10-BA3C3AD)10-B3C4AD2(10-B3C5A)10-B3C4AD10-B3C5A10-B3C3A12-B3C2A14-4A17-2(A18-)A54-3A16-5A14-3AC2A13-3AC4A10-2(B3AC4A2B8-)B2(A3C4A2B9-)2(A3C4A2B8-B)A3C4ABE2(8-B8A2B)8-BA3C4A2(10-BA3C3AD)2(10-BA3C4A)4(10-B3C4AD)10-B3C5A3(10-B3C3A12-B3C2A14-4A110-3A16-5A14-3AC2A13-3AC4A10-2(B3AC4A2B8-)B2(A3C4A2B9-)2(A3C4A2B8-B)A3C4ABE2(8-B8A2B)8-5(BA3C3AD10-)B3C4AD4(10-B3C5A))10-B3C3A12-B3C2A14-4A110-3A16-5A14-3AC2A13-3AC4A10-2(B3AC4A2B8-)B2(A3C4A2B9-)2(A3C4A2B8-B)A3C4ABE2(8-B8A2B)8-BA3C4A2(10-BA3C3AD)2(10-BA3C4A)4(10-B3C4AD)10-B3C5A10-B3C3A12-B3C2A14-4A17-2(A18-)A54-3A16-5A14-3AC2A13-3AC4A10-2(B3AC4A2B8-)B2(A3C4A2B9-)2(A3C4A2B8-B)A3C4ABE2(8-BA3C4A2B)8-BA3C4A4(10-BA3C3AD)10-B3C4AD2(10-B3C5A)10-B3C4AD10-B3C5A10-B3C3A12-B3C2A14-4A17-2(D18-)A18-A35-3A16-5A14-6A13-8A10-B8A2B8-B3AC4A2B8-B2(A3C4A2B9-)2(A3C4A2B8-B)A3C4ABE2(8-BA3C4A2B)8-BA3C4A4(10-BA3C3AD)4(10-B3C4AD)10-B3C5A10-B3C3A12-B3C2A14-4A17-3(D18-)A18-A16-3A16-5A14-6A13-8A10-B8A2B8-B3AC4A2B8-B2(A3C4A2B9-)2(A3C4A2B8-B)A3C4ABE2(8-BA3C4A2B)8-2(BA3C4A10-)3(BA3C3AD10-)B3C4AD4(10-B3C5A)10-B3C3A12-B3C2A14-4A17-2(D18-)A18-A35-3A16-5A14-6A13-8A10-2(B8A2B8-)B8A2(2B9-A3C4A)5(2B8-BA3C4A)4(10-BA3C4A)5(10-B3C5A)10-B3C3A12-B3C2A14-4A17-2(A18-)A49-5B3A10-2B4-5A7-2B5-6A5-2B6-8A3-B6-B8A2B-B6-B8A4B6-B8A2(3B8-A3C4A)5(3B7-BA3C4A)4(2-B7-BA3C4A)3(2-B7-B3C5A)2-2B2(6-B3C5A3-B)6-B3F3A5-2B5-B5A7-2B5-4A9-2B2-B2A13-4B72-5B3A10-2B4-5A7-2B5-6A5-2B6-2(8A3-B7-)8A2-2B7-5(8A2-B8-)9(2AE5A2-B8-)2AE5A2-2B2(7-2AE5A3-B)7-3AE2A5-2B6-5A7-2B5-4A9-2B2-B2A13-4B173-6B13-6B459-
