model
size = 27 18 11, scale = 0.05, origin = -y
material 
  colors = A:#933 B:#111 C:#EEE D:#AAA
voxels
5-20B7-20A7-20C7-20D7-11A3C6A9-7A3CB3C4A12-3A3C3B3C3A15-2C5B2C3A15-3C3B3C2AC16-3CB3C2-AC18-3C5-C193-24B3-3A20-A3-3C20-C3-3D20-D3-4A19-A6-2A-18A6-21A9-5A3C3B4C2-A11-3A10C2BA13-2A7C2A3C15-2A3C5A2C17-5AB3AC17-4ABAB3A20-2ABAB2A20-3(AB)A20-7A20-3A33-26B-A23-2A-C23-2C-D23-2D-2A-A20-2A2-3A20-2A5-A19-2A5-3C17-2A8-BA15-2A10-BA13-C13-B2A10-C15-AB9-C17-A8-A17-3A2(6-A18-BA)6-A18-3A2-4B18-2A5B3-27BA24-2AC24-2CD24-2D2A23-2A-2A22-2A3-2C20-AC5-CDC17-2A8-BC15-2A10-BC13-CA12-BC11-2C14-B11-C15-B10-C15-2B9-2(A17-B8-)A17-C7-2B17-C9-27BA24-2AC24-2CD24-2DA24-4A23-AC-ACDC20-AC5-D2C17-AC7-D2BC14-2A9-BCB13-CA11-B2C11-2C13-BC11-B14-CB10-C15-BC9-A16-CB8-A16-B9-A16-A9-B16-A10-27BA24-2AC24-2CD24-2DA24-AC2A23-AC-A2CD20-AB5-CDC17-AC7-D2BC14-AC9-BCB13-CA11-B2C11-2C13-2C11-B14-CB10-C15-B2(C9-A16-)B9-A16-A9-B16-A10-27BA24-2AC24-2CD24-2DA24-4A23-AC-ACDC20-AC5-D2C17-AC7-D2BC14-2A9-BCB13-CA11-B2C11-2C13-BC11-B14-CB10-C15-BC9-A16-CB8-A16-B9-A16-A9-B16-A10-27BA24-2AC24-2CD24-2D2A23-2A-2A22-2A3-2C20-AC5-CDC17-2A8-BC15-2A10-BC13-CA12-BC11-2C14-B11-C15-B10-C15-2B9-2(A17-B8-)A17-C7-2B17-C10-26B-A23-2A-C23-2C-D23-2D-2A-A20-2A2-3A20-2A5-AC18-2A5-3C17-2A8-BA15-2A10-B3A11-C13-BA11-C15-AB9-C2(17-3A6-A)2(18-BA6-A)18-3A2-4B18-2A4B6-24B3-3A20-A3-3C20-C3-3D20-D3-4A19-A6-2A-18A6-5A15-A9-5A3C6BC3A11-3A4CB3C3BAC13-2A7C2A3C15-2A3C5A2C17-5AB3AC20-2(AB)3A20-2ABAB2A20-3(AB)A20-7A20-3A37-20B7-20A7-20C7-20D7-11A3C6A9-7A3CB3C4A12-3A3C3B3C3A15-2C5B2C3A15-3C3B3C2AC16-3CB3C2-AC18-3C5-C191-
