model
size = 12 14 29, scale = 0.05, origin = -y
material 
  colors = A:#222 B:#C93 C:#DDD D:#EEE E:#C96 F:#FFF
voxels
3-4(6B6-)3(6A6-)6A77-4(9B3-)9A3-9A4-7A2(4-8A)5-6A52-4(10B2-)10A2-10A3-9A2(3-A6C2A)3-A6CA50-48B4(24A-10A2(2-2AC4-C2A)3-AC4-CA50-12BD10BDF10BD12B)24A-10A2(2-2AC4-C2A)3-AC4-CA50-48B24A-10A2(2-2A5C3A)3-A5C2A5-A4CA6-6A7-4A17-3(10B2-)4(10A2-)9A3-9A5-2(6A6-)6A7-4A8-4A5-3(10B2-)3(10A2-)10A4-7A6-5A7-5A53-3(9B3-)3(9A3-)9A4-7A6-D3AD7-F3DF53-3(9B3-)3(9A3-)9A4-7A6-5A7-5A53-3(9B3-)3(9A3-)9A4-7A6-5D65-3(9B3-)3(9A3-)9A4-7A6-5A65-3(9B3-)3(9A3-)9A4-7A6-5D64-3(11B-)2(11A-)10A3-9A4-7A75-3(11B-)2(11A-)10A3-9A4-A4D2A74-35B25A-10A3-9A4-7A74-35B25A-10A3-9A5-A2D2A75-24BA10B25A-10A4-7A6-4A76-24B36A-10A4-7A6-4A76-4B2E5B-11B3(-11A)2-9A5-6A7-4A76-4B2E5B-11B3(-11A)2-9A5-6A88-3B2E4B3-9B3(3-9A)4-8A100-2B2E4B4-8B3(4-8A)5-6A101-2B2E3B5-7B3(5-7A)6-5A103-B2E2B7-5B3(7-5A)8-3A105-2(3B9-)2(3A9-)3A113-
