model
size = 32 4 3, scale = 0.05, origin = -y
material 
  colors = A:#EEE B:#C93 C:#C96 D:#FC9 E:#AAA F:#888 G:#F96 H:#CCC I:#555 J:#DDD K:#633 L:#BBB M:#100 N:#FFF O:#999 P:#444
voxels
33-IF-FPK15AGB2CB3CBD2-IHL2E14ANG3BCBC2BD3-2HJ-15AG2(BC)B3CD2-F30-IFOFPK15AG4(CB)DJMIHL2E14ANC8BD2-EH-JK15AG2C2(2BC)D32-FIFOF-K15AG2B3CB2CDJMIHLE-15AG3C2BC2BD2-E-HJE15AG2B3CBCBD
