model
size = 30 27 9, scale = 0.05, origin = -y
material 
  colors = A:#AAA B:#5D5D5D C:#313131 D:#91989F E:#777 F:#111 G:#EEE H:#C4E0E4 I:#BBB J:#E83015 K:#FFFFFB
voxels
2-2AF20A-2A3-3AF20A-3A2-A-AF20A2(-A)-4A-20A-8A22-186A-24A-7A2D18-5A-2A3-2D19-2A8-6(D29-2D29-)B17-3AF21-3A-32AE24AE244AE24AE9A18E8A-22A-3A390-2A-AF22A-4AE24AE2A-C26AC2-B26AB2-C26AC2-B26AB-60A-C26AC2-B26AB2-C26AC2-B26AB-6A4(GC)J4(CG)C9A-2A18-2A-3A2-B-B20-B-B362-4AF21-4A-C2AF4(-3F)2-2FB2AC-120A-B26AB2-C26AC-120A-B4A8GJ9G4AB-3AE2A18-2AE3A2-BDB20-BDB5-2(D22-D6-)24D273-2A-A22-A-4AEA8(F-)5F-AE2A2(-C26AC2-B26AB2-C26AC2-B26AB-60A)2-3B20-3B363-3A22-3A-4A3(3F-)3F4-2FB76A6H24AHK2FKH24A6H54AIE2IEI108A19E11A19-5A393-24A5-9A8B9A3-10A8B10A-11A8B3(22AB6-B)22A8B22AB-B2-B-B22A8B43AB2A3(2BD)5B2(D2B)2AB7AB6(D2B)D2(5A-)6(2A-)4A424-5B14-5B5-2BCBC2B3-2(E-)2E3-2BCBC2B3-2(2B2(CB)C2B10-2B2(CB)C2B2-4(BC)B10-4(BC)B2-)2B2(CB)C2B10-2B2(CB)C2B3-2BCBC2B12-2BCBC2B5-5B14-5B5-B24-B3-B-B8-3(G-)J7-B-B3-B24-B455-5B14-5B5-2B3-2B12-2(2B3-)2B5-2B10-2B5-2B3(2-B7-B10-B7-B)2-2B5-2B10-2B5-2(2B3-)2B12-2B3-2B5-5B14-5B513-
