model
size = 14 31 32, scale = 0.05, origin = -y
material 
  colors = A:#AAA B:#FC0 C:#002 D:#777 E:#9CF F:#EEE
voxels
183-2ADA2BABAD2A2-4ABA2B4A2-D2AD2BABD2AD2-2ADABA2BAD2A2-A2DA2BABA2DA2-4ABA2B4A2-D2AD2BABD2AD2-2ADABA2BAD2A310-2ADA2BABAD2A2-4ABA2B4A2-D2AD2BABD2AD2-2ADABA2BAD2A2-A2DA2BABA2DA2-4ABA2B4A2-D2AD2BABD2AD2-2ADABA2BAD2A282-2ADABA2BAD2A2-D3A2BAB3AD2-4ABA2B8(4A2-4A4B)4A2-AD2A2BAB2ADA2-4ABA2B4A2-2ADA2BABAD2A212-AD2ABA2B2ADA2-4A2BAB2(4A2-4A4B)4A2-2ADA4BAD2A2-D3A4B3AD2-AD2A4B2ADA2-4A4B4A2-3AD4BD3A2-AD2A4B2ADA2-2(DA)4B2(AD)5(2-4A4B4A)2-D3ABA2B3AD2-2ADA2BABAD2A170-4A2BAB2(4A2-4A4B)4A2-2ADA4BAD2A2-AD2A4B2ADA114-6(4A4B4A2-)AD2ABA2B2ADA142-2(DA)BA2B2(AD)2(2-4A4B4A)2-AD2A4B2ADA170-D3A4B3AD2-2ADA4BAD2A3(2-4A4B4A)2-2ADA2BABAD2A114-AD2A2BAB2ADA2-4A4B4A2-3DA4BA3D226-2(AD2A4B2ADA2-)2(4A4B4A2-)D3ABA2B3AD-42B43-3ADBA2BD3A2(2-4A4B4A)254-AD2A4B2ADA3(2-4A4B4A)-BA10EA2(2B5C)2BA4-2A4-AB29-AD2A2BAB2ADA2-4A4B4A2-AD2A4B2ADA282-2ADA4BAD2A2(2-4A4B4A)2-A10EA-B12C2B12-B29-4A4B4A2-4A4B4A310-2(4A4B4A2-)A10EA-B12C2B12-B15-5BA6B2(2-12B)310-AD2A4B2ADA2-4A4B4A2-A10EA-B12C2B12-B15-12B2-12B338-4A4B4A2-A10EA-B5C2F5C2B12-B15-12B2-12B338-AD2A4B2ADA2-A10EA4(-B5C2F5C2B12-B-12B2-12B366-12A)2(-2B4C2A4C3BA4-2A4-AB-12B2-12B366-12A)-B5CF6C2B12-B-12B2-12B366-12A-B4CF7C2B12-B-12B2-12B366-12A-B3CF8C2B12-B15-12B2-12B338-AD2A4B2ADA2-A10EA-B2CF9C2B12-B15-12B2-12B338-4A4B4A2-A10EA-BCF10C2B12-B15-5BA6B2(2-12B)310-AD2A4B2ADA2-4A4B4A2-A10EA-B12C2B12-B29-4A4B4A2-4A4B4A310-2(4A4B4A2-)A10EA-B12C2B12-B29-AD2A2BAB2ADA2-4A4B4A2-AD2A4B2ADA282-2ADA4BAD2A2(2-4A4B4A)2-AC9EA-BC-10C2B12-B43-3ADBA2BD3A2(2-4A4B4A)254-AD2A4B2ADA3(2-4A4B4A)-BA10EA2(2B5C)2BA4-2A4-AB57-AD2A2BAB2ADA2-4A4B4A2-3DA4BA3D226-2(AD2A4B2ADA2-)2(4A4B4A2-)D3ABA2B3AD-42B71-2(DA)BA2B2(AD)2(2-4A4B4A)2-AD2A4B2ADA170-D3A4B3AD2-2ADA4BAD2A3(2-4A4B4A)2-2ADA2BABAD2A142-4A2BAB2(4A2-4A4B)4A2-2ADA4BAD2A2-AD2A4B2ADA114-6(4A4B4A2-)AD2ABA2B2ADA170-AD2ABA2B2ADA2-4A2BAB2(4A2-4A4B)4A2-2ADA4BAD2A2-D3A4B3AD2-AD2A4B2ADA2-4A4B4A2-3AD4BD3A2-AD2A4B2ADA2-2(DA)4B2(AD)5(2-4A4B4A)2-D3ABA2B3AD2-2ADA2BABAD2A212-2ADABA2BAD2A2-D3A2BAB3AD2-4ABA2B8(4A2-4A4B)4A2-AD2A2BAB2ADA2-4ABA2B4A2-2ADA2BABAD2A113-
