model
size = 21 20 28, scale = 0.05, origin = -y
material 
  colors = A:#FFD700
voxels
202-A412-A66-2A329-2A2(20-A)-A42-3A19-2A20-A245-A21-2A18-4A18-3A18-5A17-5A16-A-3(4A17-)7A16-A180-3A18-3A19-4A19-2(3A18-)A2-A21-A42-A18-A23-5A15-A-4A18-2A136-A20-A18-3A17-5A62-A113-A19-3A18-4A17-3A112-3A18-3A17-4A18-4A197-3A18-3A17-2A71-A20-2A19-3A2(17-4A)18-3A197-A2-A18-A-3A18-2A19-A68-A-A19-3A18-3A19-2A18-2A201-A20-3A18-2A19-A48-A19-3A18-3A20-2A18-3A18-A202-A20-2(3A18-)3A46-A18-4A17-4A19-A41-A223-2(3A18-)3A46-A17-5A17-2A288-3A18-2A19-2A3-2A19-3A17-4A17-2A-A287-A19-2(3A18-)2A3-A19-2(5A16-)2A-2A286-A19-3A39-2A3-2A19-2(4A17-)3A307-3A39-2A3-2A17-A-2(4A17-)A-2A287-A18-3A20-A18-2A3-3(3A18-)4A286-2A2(18-3A)18-2A24-3A19-2A-A16-2A-A286-2A2(18-3A)19-A4-3A19-2(3A17-)A-2A285-3A18-3A19-A24-4A17-2A-2A17-4A19-2A284-3A18-3A19-A48-2A-A17-4A16-5A18-3A177-A20-3(2A19-)3A71-A18-A-A18-3A17-4A2(19-2A)156-A18-4A2(18-3A)19-2A72-A3(17-4A)19-2A19-3A18-3A46-A63-2A-A17-2A-A18-4A2(18-3A)19-A94-A18-2A41-2A20-3A17-6A16-A-3A19-5A18-A-2A18-A20-3A-A17-4A19-2(3A18-)2A20-A156-4A17-6A15-6A17-4A18-6A19-3A17-4A18-5A17-4A18-2A20-2A19-2A179-2A19-2(4A17-)4A18-7A17-4A17-5A16-6A17-4A19-A222-A21-3A17-3A18-4A19-6A17-4A18-4A17-A21-3A20-A308-6A18-2A19-2A194-
