model
size = 31 31 9, scale = 0.05, origin = -y
material 
  colors = A:#7B3F00 B:#FFE599
voxels
44-6A22-12A17-16A14-18A12-20A10-22A8-24A2(6-10A)5-8A10-8A4-8A12-8A2(3-7A14-7A)2-5(7A16-7A-)7A16-7A2-2(7A14-7A3-)8A12-8A4-8A10-8A5-2(10A6-)24A8-22A10-20A12-18A14-16A17-12A22-6A26-4B23-4B4-4B17-2B12-2B13-2B16-2B10-2B18-2B8-2B20-2B6-2B22-2B5-B24-B4-B10-6B10-B3-B8-2B6-2B8-B2-B2(8-2B)8-B-B7-2B10-2B7-B-B7-B12-B7-B-B6-B14-B6-2B7-3(B14-2(B7-))B14-B8-B6-B14-B6-B-B7-B12-B7-B-B7-2B10-2B7-B-B2(8-2B)8-B2-B8-2B6-2B8-B3-B10-6B10-B4-B24-B5-2B22-2B6-2B20-2B8-2B18-2B10-2B16-2B13-2B12-2B17-4B4-4B20-10B18-3B10-3B14-B16-B11-2B18-2B8-B22-B6-B24-B5-B24-B4-B26-B2-B13-2B13-B-B11-2B2-2B11-B-B9-2B6-2(2B9-)B10-2(B9-)B10-B9-B8-B12-2(B8-)B12-B8-B7-B14-2(B7-)B14-B7-B8-B12-2(B8-)B12-B8-B9-B10-2(B9-)2(B10-)B9-2B6-2B9-B-B11-2B2-2B11-B-B13-2B13-B2-B26-B4-B24-B5-B24-B6-B22-B8-2B18-2B11-B16-B14-3B10-3B17-12B17-2B12-2B14-B16-B11-2B18-2B8-B22-B6-B24-B5-B24-B4-B26-B2-B28-B-B11-6B11-2B11-B6-B11-B10-B8-2(B10-B9-)B8-5(B12-2(B8-))B12-B8-2(B9-B10-)B8-B10-B11-B6-B12-B11-6B11-B-B28-B2-B26-B4-B24-B5-B24-B6-B22-B8-2B18-2B11-B16-B14-2B12-2B17-12B17-2B12-2B13-2B16-2B10-B20-B8-B22-B6-B24-B4-B26-B3-B26-B2-B28-B-B11-6B11-2B11-B6-B11-B10-B8-2(B10-B9-)B8-5(B12-2(B8-))B12-B8-2(B9-B10-)B8-B10-B11-B6-B12-B11-6B11-B-B28-B2-B26-B3-B26-B4-B24-B6-B22-B8-B20-B10-2B16-2B13-2B12-2B17-12B17-2B12-2B14-B16-B11-2B18-2B8-B22-B6-B24-B5-B24-B4-B26-B2-B28-B-B11-6B11-2B11-B6-B11-B10-B8-2(B10-B9-)B8-5(B12-2(B8-))B12-B8-2(B9-B10-)B8-B10-B11-B6-B12-B11-6B11-B-B28-B2-B26-B4-B24-B5-B24-B6-B22-B8-2B18-2B11-B16-B14-2B12-2B18-10B18-3B10-3B14-B16-B11-2B18-2B8-B22-B6-B24-B5-B24-B4-B26-B2-B13-2B13-B-B11-2B2-2B11-B-B9-2B6-2(2B9-)B10-2(B9-)B10-B9-B8-B12-2(B8-)B12-B8-B7-B14-2(B7-)B14-B7-B8-B12-2(B8-)B12-B8-B9-B10-2(B9-)2(B10-)B9-2B6-2B9-B-B11-2B2-2B11-B-B13-2B13-B2-B26-B4-B24-B5-B24-B6-B22-B8-2B18-2B11-B16-B14-3B10-3B21-4B23-4B4-4B17-2B12-2B13-2B16-2B10-2B18-2B8-2B20-2B6-2B22-2B5-B24-B4-B10-6B10-B3-B8-2B6-2B8-B2-B2(8-2B)8-B-B7-2B10-2B7-B-B7-B12-B7-B-B6-B14-B6-2B7-3(B14-2(B7-))B14-B8-B6-B14-B6-B-B7-B12-B7-B-B7-2B10-2B7-B-B2(8-2B)8-B2-B8-2B6-2B8-B3-B10-6B10-B4-B24-B5-2B22-2B6-2B20-2B8-2B18-2B10-2B16-2B13-2B12-2B17-4B4-4B54-5A22-12A17-16A14-18A12-20A10-22A8-24A2(6-10A)5-8A10-8A4-8A12-8A2(3-7A14-7A)2-7A16-6A2-3(7A16-7A-)7A16-7A2-6A16-7A2-2(7A14-7A3-)8A12-8A4-8A10-8A5-2(10A6-)24A8-22A10-20A12-18A14-16A17-12A22-5A13-
