model
size = 6 26 30, scale = 0.05, origin = -y
material 
  colors = A:#000 B:#141414
voxels
2(108-42A)114-A6(4-2A)4-7A108-2(A5(4-2A)4-2(4A2-)7A102-)7A4(4-2A)2(4-2(4A2-)7A109-6A3(4-2A))4-2(4A2-)7A-4B-103A4(4-2A)4-2(4A2-)8A22(4-2A)4-2(4A2-)7AB6(4-2A)5(4-AB4-2A)6(4-2A)4-2(4A2-)7AB5(4-2A)6(4-AB4-2A)8(4-2A)4BAB4(4-2A)2(2(4-AB4-2A)6(4-2A))4-A2B2-3B2(3(4-2A)4-AB)7(4-2A)2(4-AB4-2A)4(4-2A)2(4-AB)4-2B2(4-2A)4-AB5(4-2A)4-AB4-2A4(4-AB)2(4-2A)2(4-AB4-2A)3(4-2A)4-AB4-BA5-3(B2(4-2A)4-A)B8(4-2A)2(4-AB4-2A)2(4-2A)4-2B5-A5-B2(4-2A)5(4-AB4-2A)4-2A4-AB4(4-2A)2(4-AB4-2A)4-2A4-2B5-A5-4(B2(4-2A)4-A)B4-2A4-AB5(4-2A)4-AB3(4-2A)4-AB4-BA5-B2(4-2A)4-AB5(4-2A)3(4-AB4-2A)9(4-2A)2(4-AB)4-2B2(3(4-2A)4-AB)16(4-2A)4-A2B2-3B4(4-2A)3(4-AB)18(4-2A)4BAB22(4-2A)4-2(4A2-)8A22(4-2A)4-2(4A2-)7A-4B-103A4(4-2A)2(4-2(4A2-)7A109-6A3(4-2A))4-2(4A2-)7A102-7A4(4-2A)3(4-2(4A2-)7A102-A5(4-2A))4-2A4-7A6-
