model
size = 30 32 31, scale = 0.05, origin = -y
material 
  colors = A:#33F B:#06F C:#6CC D:#60C E:#03C F:#444 G:#00D H:#A00 I:#DDD
voxels
193-6(4B26-)5B24-2(7B23-)6B16-21B9-21B587-2(6B24-)6B23-7B23-4(8B22-)8B23-6B18-18B9-23B7-23B8-21B11-6B31-C28-C479-2(6B24-)7B23-7(6B24-)6B6-B8-2(23B7-)23B17-C-7B-3(C30-)C435-6B24-6B23-8B23-6B116-B29-B28-B29-B10-B8-3B6-B10-3B6-4B6-B10-4B6-3B17-3B8-B19-B76-C28-C15-C12-C241-7A21-A2-6A23-7A84-6B24-6B23-8B23-6B27-B168-B19-B8-3B17-3B6-4B17-4B6-3B17-3B8-B19-B151-C12-C15-C193-2(11A19-)11A82-6B24-6B23-8B23-6B27-B168-B19-B8-3B17-3B6-4B17-4B6-3B17-3B8-B19-B193-C16-C30-C130-2(15A15-)15A19-2(7A23-)A5BA24-6B23-8B23-6B26-B169-B19-B8-3B17-3B6-4B17-4B6-3B17-3B8-B19-B192-C78-C99-17A2(13-10A2-5A)16-2(7A2-2A19-)11A22-6B23-7B24-6B25-2B169-B19-B8-3B17-3B6-4B17-4B6-3B17-3B8-B19-B191-C28-C50-C98-19A2(11-11A2-6A)14-8A2-3A2(17-13A)21-2(5A25-)5A27-B169-B19-B8-3B17-3B6-4B17-4B6-3B17-3B8-B19-B220-C50-C98-7A5-7A2(11-7A6-6A)13-2(5A6-4A15-)5A6-4A18-2(9A21-)9A25-B169-B19-B8-3B17-3B6-4B17-4B6-3B17-3B8-B19-B47-3A2(26-4A)2(27-3A)2(50-C)97-5(6A9-)6A11-2(4A9-4A13-)4A9-4A16-A2-8A2(19-11A)24-B28-B29-B110-B19-B8-3B17-3B6-4B17-4B6-3B17-3B8-B19-B16-3A2-A24-6A24-2(7A23-)6A23-7A23-5A20-C50-C97-2(5A11-A2-2A9-)2(5A11-)2(3A11-3A13-)3A11-3A15-2A2-9A2(17-13A)21-2(5A25-)5A26-B80-B19-B8-3B17-3B6-4B17-4B6-3B17-3B8-B6-6A7-B16-4(7A23-)7A22-8A22-7A18-C4-7A9-C15-4A9-3C28-C66-7A10-2(A2-3A7-6A11-)A2-3A9-2(4A11-2A-A11-)4A11-4A14-2A2-9A2(17-13A)20-7A2(24-6A)106-B19-B8-3B17-3B6-4B17-4B6-3B6-4A7-3B8-B7-6A6-B17-5(6A24-)6A17-C3-9A16-3C3-8A7-3C7-C5-6A8-3C14-D2A10-3C14-D-D27-D-D18-2(5A15-3A7-)5A15-3A9-2(3A15-A11-)3A14-2A13-2(9A2-4A15-)15A18-9A2(23-7A)24-2(3A27-)3A18-B8-3A8-B8-3B8-2A7-3B6-4B6-3A8-4B6-3B5-6A6-3B8-B5-8A6-B15-5(9A21-)9A15-3C3-8A16-3C3-8A8-C7-3C3-8A7-CGC14-4AD9-C19-D29-D16-5A9-2A4-2(3A7-5A15-)3A9-3A15-A11-3A15-A9-B-3A14-2A8-2(6B8A2-4A10-)6B14A18-9A2(21-6A2-A)24-2(3A27-)3A18-B8-3A8-B8-3B8-2A2(7-3B)6-3A-A6-4B6-3B5-6A6-3B14-2(9A21-)3(9A18-3E)9A21-9A16-C4-9A15-CGC3-8A17-C4-8A8-G14-6A76-5A13-2A2-A7-3A15-5A7-3A8-A6-5A9-A15-3A11-A-A13-3A9-B-2A14-3A8-2(6B6A-6A6B5-)6B13A6B13-2(4A-4A21-)4A-4A23-3(5A25-)5A16-3B6-5A6-3B7-3B5-6A6-3B7-3B4-7A6-3B14-3(9A21-)3(9A3E18-)9A21-9A16-G4-2(8A22-)D6A2(23-3(D-)D)16-5A13-2A2-A2(7-3A15-5A)9-A15-3A11-A15-3A9-B-2A14-3A-B6-6B13A6B4-7B13A7B4-6B13A6B13-2(9A21-)9A23-3(2A-2A25-)5A16-C-C6-5A6-C-C16-5A16-C-C5-6A6-C-C14-8A22-7(9A21-)8A22-8A23-5A-2(D29-)D15-5A13-2A2-A2(7-3A15-5A)9-A15-3A11-A15-3A9-B-2A14-3A-B6-3B2-14A6B4-4B2-14A7B4-3B2-14A6B6-B6-9A6-B14-9A21-9A23-3(5A25-)5A16-C-C6-5A6-C-C16-5A16-C-C5-6A6-C-C14-8A22-6(9A21-)8A22-8A23-7A24-3A78-6A11-3A2-A2(7-6A11-6A)9-2(4A11-)A2-A11-4A9-B-2A-A11-4A-B6-3B2-14A3-3B4-4B2-14A3-4B4-3B2-14A3-3B6-B8-6A7-B16-6A22-6A3(27-3A)19-C7-3A9-C6-C10-4A6-C18-6A23-7A5-C-C7-C-C5-6A23-8A22-5(9A21-)8A23-7A23-D5A3(D23-3(D-))D16-5A9-A-3A2(11-5A)9-2(5A11-)3A11-3A13-3A11-3A10-B2-3A11-3A2-B6-3B3-13A3-3B4-4B3-13A3-4B4-3B3-13A3-3B6-B8-5A8-B16-5A23-5A101-C5-C3-C35-5A5-C20-4A25-5A5-C3-C5-C8-6A10-C7-C5-6A23-8A22-2(9A21-)8A22-8A23-7A23-6A25-3A109-6A8-5A11-3(6A9-)6A11-4A9-4A13-4A9-4A10-B2-4A9-4A2-B6-3B4-11A4-3B4-4B4-11A4-4B4-3B4-11A4-3B6-B21-B151-C3-C5-C14-C50-4A25-5A25-A3IA5-2(C9-)2AF2A10-C7-C5-A5F2(24-6A)2(24-2(A2G))24-7A167-7A5-5A13-7A5-7A11-7A5-7A13-2(5A5-5A15-)5A5-5A3-B6-3B5-9A5-3B4-4B5-9A5-4B4-3B5-9A5-3B6-B21-B151-C3-C5-C13-C80-5H45-C9-2H-2H4-C5-C7-C37-3A27-3A28-A29-A26-3F-3F167-17A13-19A11-19A14-2(13A17-)13A4-B6-3B7-5A7-3B4-4B7-5A7-4B4-3B7-5A7-3B6-B21-B151-C3-C5-C13-C130-C18-C5-C7-C330-15A15-17A13-17A16-2(11A19-)11A12-C-C19-3B27-3B5-C-C19-3B180-C3-C5-C13-C130-C18-C5-C7-C331-14A16-15A15-15A19-2(7A23-)7A14-C-C19-C-C35-C-C19-C-C180-C3-C5-C13-C130-D18-C5-C7-C333-2(9A21-)9A104-C-C19-C-C35-C-C19-C-C180-C3-D5-D13-C149-C5-C7-D335-7A23-5A25-5A66-C5-C24-3(C3-)C18-C-C57-C-C5-C-C18-C3-C149-D23-C149-C5-C445-C35-C-C3-C115-C3-C46-C4-C30-C112-C149-C5-D445-C35-2C5-C144-C3-C16-C35-C112-D149-D451-C35-2C5-C143-C21-C12-C22-C714-D35-2D5-D143-D21-D12-D22-D601-
