model
size = 32, scale = 0.05, origin = -y
material 
  colors = A:#630 B:#EEE C:#DDD D:#E00 E:#800 F:#093 G:#BBB H:#040 I:#0A0 J:#080 K:#070 L:#0E0
voxels
430-2ACA27-6A25-4AB3A24-3ABC3A24-2A3BC2A24-2A3BCBA25-3C2BC27-C2BC764-2AGA27-2A2B2A25-3A2B3A24-2A4B2A24-3BC3BA24-4BC3B25-3BC2B27-CB2C700-2ABA26-8A23-5AB4A21-12A20-12A19-2(14A18-)2AB11A18-3B8A2BA19-3B6A3B20-4B4A4B21-3BCBC4B23-2(2BC)2B26-C2BC541-2A27-8A22-12A19-14A18-14A17-2(16A16-)16A15-18A14-18A15-16A2(16-2B12A2B)17-CB10A2B18-C2B8A3B19-3BC4A4B22-BC3B3C27-IHF443-6A24-10A20-14A17-16A16-16A15-18A14-18A13-5(20A12-)AB16A2B13-B16AB14-2B14A2B15-C14AB16-CB12A2B17-3B3C3A4CB20-B3-CAI27-3IH2IF376-8A22-12A19-14A17-16A15-18A13-20A12-20A11-6(22A10-)21AB10-2B18A2B11-B18AB12-2B16A2B13-B16AB15-C14AB17-2BA3C3A3C2B19-2B2C5A3B24-2FH2F313-8A22-12A19-14A16-18A14-18A13-20A11-22A10-22A9-7(24A8-)B22AB9-B20AB10-B20AB11-B18AB13-B16AC14-2C14ACB16-C12AC19-2B3C3A4C25-IHI251-6A23-12A19-14A16-18A13-20A12-20A11-22A9-2(24A8-)24A7-5(26A6-)26A7-23A2(B8-B22A)B9-B20AB11-B18AC12-B18AC13-BC14A2C16-C2A2C5A4C19-2B2-C3AC27-2IH2I188-2A26-10A20-14A16-18A13-20A11-22A10-22A9-24A8-24A7-3(26A6-)26A5-28A4-28A5-2(26A6-)B24AB6-B24AB7-B22AB8-B22AB9-C20AC10-B20AC11-B18AC13-BC14A2C16-C2B2C5A2C2B21-4FH4F183-8A21-14A17-16A15-18A13-20A11-22A9-24A7-2(26A6-)26A5-6(28A4-)B27A4-B26AB5-2(B24AB6-)B24AB7-B22AC9-C20AB11-C18AB13-B16AB15-G5B5A3B2G22-2IH2I155-4A24-12A18-16A15-18A13-20A11-22A9-24A7-26A6-26A5-3(28A4-)28A3-3(30A2-)B29A3-3(B26AB4-)B26AB5-B24AB6-B24AB7-B22AB9-C20AB11-C18AB13-2BG5B3A3BG2BG22-IHI154-8A21-14A17-16A14-20A11-22A9-24A8-24A7-26A5-2(28A4-)28A3-5(30A2-)B29A2(2-B28AB)3-2(B26AB4-)B26AB5-B24AB7-B22AB8-B22AB9-B20AB11-2C2BG3B5ABG3BGB20-2IH2I152-10A20-14A16-18A13-20A11-22A9-24A7-26A6-26A5-28A4-28A3-6(30A2-)3(B28AB2-)B28AB3-B26AB4-B26AB5-B24AB6-B24AC7-B22AC9-B20AB11-2B2GBGB10A3B19-3IH2A4D26-6D87-4A24-12A18-16A15-18A12-22A9-24A8-24A7-26A5-28A4-28A3-3(30A2-)30A-96AB30AB-B28AB2-B28AG2-B28AB2-B28AG3-B26AG4-B26AC5-B24AC7-B22AB8-B22AB9-C2G7B8A4B20-IH5AD12-F13-D4AE4-F22-4D55-6A23-12A18-16A14-20A11-22A9-24A7-26A6-26A5-28A4-28A3-2(30A2-)30A-127A2(2B30A)B-B28AG2-B28AB2-B28AC3-B26AC4-C26AB5-B24AB6-C24AB7-C22AB9-CBA2B13ABA2B12-F2-5DAH5AD-F10-F6-6D-D4AD4-F22-D2BD28-2DE23-8A21-14A17-16A14-20A11-22A9-24A7-26A6-25AB5-28A3-2(30A2-)30A-128AB30A2B30ACB30ABC30AB-C28AC2(2-C28AB)3-C26AB5-C24AB6-B24AB7-B9A4E9AB9-B2A2B4A4E5ABABC11-KF2-D3A4E4AD-FJ8-KFK5-D3AED-D4AD3-JFJ3-K10-4D3-DABD9-JL17-3D10-L12-8A21-14A16-18A13-20A11-22A9-24A7-26A5-28A4-28A3-30A2-29AC2-29AB-63AB2(31AC)B30ACB30A2B30A2C30AC-C28AC2(2-C28AB)3-C26AB4-C26AB5-C10A4E10AC7-C8AE4-E8AC9-C3AB3AE4-E7AC10-2KFK-D2AE4-E4AJFJ8-KFK5-D2AE4-E3AD3-JFJ3-2K9-DAE4-EA2D7-3JL11-DE4-3D10-L12-8A21-14A16-18A13-20A11-22A9-24A7-26A5-28A4-28A3-2(30A2-)30A-95A5(2B30A)C-B28AB2-B28AC2-C28AC3-B26AC4-C26AC5-C10A4E10AC7-C8AE4-E8AC9-C7AE4-E7AB9-6H3AE4-E4A4H6-4H5-D2AE4-E2(AD)3-4H2-2H9-EAE4-E3D7-4H11-DE17-H12-8A21-14A17-16A14-20A11-22A9-24A7-26A6-26A5-28A3-30A2-B29A2-30A-B31AB63AB2(30A2B)30ACB30ABC30AB-C2(28AB2-B)28AC3-B26AB5-B24AB6-B10A4E10AB7-B8AE4-E8AB9-2(B3A)E4-E7AB10-2KFK-D2AE4-E2A2DJFJ8-KFK5-D2AE4-EA3D3-JF2J2-2K9-DAE4-ED9-3JL11-DE17-L13-6A23-12A18-16A14-20A11-22A9-24A7-26A6-26A5-28A4-28A3-2(30A2-)30A-96AB2(30A2B)30AC-B28AC2-B28AB2-C28AB3-C26AB4-B26AB5-B24AB6-B24AB7-B9A4E9AB9-B2A2B4A4E3A3B2AB11-KF2-D3A4E2AD3-FJ8-KFK5-D3A4E2AD5-JFJ3-K10-3D4EAD11-JL15-3D12-L14-4A24-12A18-16A15-18A12-22A9-24A8-24A7-26A5-28A4-28A3-3(30A2-)30A-64AB31AB30AB-2(B28AB2-)B28AC2-B28AC3-B26AB4-C26AB5-C24AB7-C22AB8-C22AB9-CBA2B11ABGBA2B12-F2-4D6AD3-F10-F6-5D5AD6-F19-D2A2D28-DED56-10A20-14A16-18A13-20A11-22A9-24A7-26A6-26A5-28A4-28A3-6(30A2-)3(B28AB2-)B28AC3-B26AC4-B26AB5-B24AB6-B24AB7-B22AB9-C20AB11-8C7A2BG2B20-D5AD14-F10-2D4AD6-F19-5D28-E2D57-8A21-14A17-16A14-20A11-22A9-24A8-24A7-26A5-2(28A4-)28A3-6(30A2-)29AB2-B28AB3-2(B26AB4-)B26AC5-B24AC7-B22AB8-B22AB9-B7AB12AB11-2BC4B-D6A2BG2B21-D4AD25-2D4AD26-5D90-4A24-12A18-16A15-18A13-20A11-22A9-24A7-26A6-26A5-3(28A4-)28A3-3(30A2-)30A3-27A3(B4-B26A)B5-B24AB6-B24AC7-B22AC9-B20AC11-B18AC13-2BC5B6A3BG22-6D26-6D151-8A21-14A17-16A15-18A13-20A11-22A9-24A7-2(26A6-)26A5-6(28A4-)27AB4-B26AB5-B2(24AB6-C)24AB7-C22AB9-B20AB11-B18AB13-C16AC15-C4BG9BC215-2A26-10A20-14A16-18A13-20A11-22A10-22A9-24A8-24A7-3(26A6-)26A5-28A4-28A5-2(26A6-)B24AB6-B24AB7-B22AB8-C22AB9-C20AB10-B20AB11-C18AB13-CB14A2B16-B2CG3BG2B2G2B246-6A23-12A19-14A16-18A13-20A12-20A11-22A9-2(24A8-)24A7-5(26A6-)26A7-23AB8-B22AB8-C22AG9-C20AG11-B18AB12-B18AB13-2B14A2G16-C12AG19-C4BG5BG278-8A22-12A19-14A16-18A14-18A13-20A11-22A10-22A9-7(24A8-)23AB9-B20AC10-C20AB11-C18AB13-B16AB14-2B14ABG16-CB11AB19-CB8A2B22-2BG2B2CB312-8A22-12A19-14A17-16A15-18A13-20A12-20A11-7(22A10-)20ACB11-B18AB12-2C16A2B13-B16AB15-B14AB17-2C10A2B19-C4B4AB2C22-5B2CB377-6A24-10A20-14A17-16A16-16A15-18A14-18A13-5(20A12-)20A13-B16AB14-2C14A2C15-B14AB16-BC12A2B17-CBC8A3B20-C3B2A2B2C24-3B3C444-2A27-8A22-12A19-14A18-14A17-2(16A16-)16A15-18A14-18A15-2(16A16-)BC12A2B17-CB10A2C18-3B8ABCB19-3CB4AC3B22-2(3BC)27-BC541-4A26-8A23-10A21-12A20-12A19-3(14A18-)14A19-2AB6AC2A20-3BC4A2C2B21-2BCB2C2BCB23-C4B3C26-B3C302-
