model
size = 7 20 25, scale = 0.05, origin = -y
material 
  colors = A:#7D6C46 B:#E83015 C:#0F4C3A D:#FFC408
voxels
DC3BCDA14(C3BC2A)C3BCADC3BCD21-AC3BC107AC3BCA21-AC3BCA2(C6A)C91AC3BCA21-AC3BCAC105AC3BCA21-AC3BC107AC3BCA21-AC3BC8AB6AB91AC3BCA21-AC3BCAB105AC3BCA21-AC3BC8AB6AB91AC3DCA3-2(D6-)2(D3-AC3BC107AC3BCA17-)5(D3-AC3BC85AD5A2D5AD8AC3BCA17-)D3-AC3BC85AD6AD14AC3BCA17-D3-AC3BC107AC3BCA17-D3-AC3BC14AB6AB85AC3BCA17-D3-AC3BC7AB99AC3DCA3-2(D6-)D3-AC3BC14AB6AB85AC3BCA21-AC3BC107AC3BCA21-AC3BC7AC99AC3BCA21-AC3BC7A2(C6A)C85AC3BCA21-AC3BC107AC3BCA21-DC3BCDA14(C3BC2A)C3BCADC3BCD21-
