model
size = 32 7 13, scale = 0.05, origin = -y
material 
  colors = A:#EEE
voxels
34-11A20-A2(2-2A)2-A6-2A12-A2(2-2A)2-A6-5A9-12A8-7A27-6A30-2A37-12A6-10A2-2A11-17A2-2A10-9A11-3A5-11A9-A4-17A10-2A30-2A4-12A6-9A5-A11-6A9-2A-2A27-2A-A31-3A30-11A17-2A13-6A11-2A3-12A6-11A3-A11-6A10-A-2A28-A-A31-3A30-11A18-A13-6A12-A3-3(14A2-13A3-A12-5A11-3A29-2A31-3A30-11A19-A12-6A13-A2-)14A2-13A3-A12-5A11-3A29-2(3A30-)11A19-A12-6A13-A2-14A2-13A3-A12-5A11-A2-A28-A2-2(A31-)10A19-A12-6A13-A3-11A6-10A4-6A6-6A10-A3-A27-A3-2(A31-)10A18-A13-6A12-A5-10A6-10A5-17A9-2A6-A2-2A2-6A11-2A6-A2-2A2-6A2(17-15A)11-2A30-2A37-10A6-10A7-A2-2A2-18A7-A2-2A2-10A14-15A17-14A11-A31-A40-5A29-2A11-2A17-2A11-3A14-5A11-6A10-5A12-6A30-2A3-
