model
size = 30 15 12, scale = 0.05, origin = -y
material 
  colors = A:#069 B:#C30 C:#500
voxels
6-BAB2C10-2CBAB9-2ABCA10-ACB2A8-3ABCABACAB2CBACABACB3A5-B2CB3ABACA4BACAB3AB2CB3-B4A2CABCAB4ABACBA2C4AB2-ABC5ACA2B4A2BAC5ACBA-3AB2C2(AC)ABAC2ACAB2(AC)A2CB4AB2(A2C)3A2B4A2B3A2(2CA)2(BA)2B2AB5A2C2B2C5AB2A2BA3B2ABAC2ACABCA2BACBAC2ACAB2A2B4A2B2ACACB6ABCAC2A2B4A-2ACB3ABABCBA2CABCBAB3ABC2A2-C4ABABC2ACA2BAC2ACBAB4AC3-4AC4AB2A2B2AB4AC4A5-2AC2(AB)C8AC2(BA)C2A153-A4(28-2A)28-A241-A26-A2-A26-A-2A4(26-4A)26-2A-A26-A2-A26-A153-A24-A3-2A24-2A2-2A24-2A-3A4(24-6A)24-3A-2A24-2A2-2A24-2A3-A24-A95-A22-A5-2A22-2A3-3A22-3A2-3A22-3A-2(C3A22-3ACB3A22-3AB)C3A22-3AC-3A22-3A2-3A22-3A3-2A22-2A5-A22-A66-2A20-2A5-3A20-3A3-4A20-4A2-4A20-4A-5A20-10A20-5AC4A20-4AC5A20-10A20-5A-4A20-4A2-4A20-4A3-3A20-3A5-2A20-2A38-5A10-5A8-24A5-4A18-4A3-5A18-5A2-5A18-5A-6A18-12A18-6AC5A18-5AC6A18-12A18-6A-5A18-5A2-5A18-5A3-4A18-4A5-24A8-2(5A10-)B2(AC)10-2(CA)B8-7A3BC2AC3B7A5-4A18-4A3-5A18-5A2-5A18-5A-6A4(18-12A)18-6A-5A18-5A2-5A18-5A3-4A18-4A5-7A3BC2AC3B7A8-B2(AC)2(10-2(CA)B)10-B2(AC)8-7ACB6CBC7A5-4A18-4A3-5A18-5A2-5A18-5A-C5A18-5AC6A2(18-12A)18-6AC5A18-5AC-5A18-5A2-5A18-5A3-4A18-4A5-7ACB6CBC7A8-2(CA)B10-B2(AC)2(10-2(AB)A)8-7A3C4A3C7A5-26A3-5A18-5A2-5A18-5A-6A18-12A18-6AC5A18-5AC6A18-12A18-6A-5A18-5A2-5A18-5A3-4A18-4A5-7A3C4A3C7A8-2(2(AB)A10-)2C3B10-3B2C8-7AB3C2B3CB7A5-26A3-5A18-5A2-5A18-5A-B5A18-5AB6A2(18-12A)18-6AB5A18-5AB-5A18-5A2-5A18-5A3-4A18-4A5-7AB3C2B3CB7A8-2C3B10-3B2C10-BACBC10-CBCAB8-8ACAC2ACAC8A5-26A3-28A2-7A4B6A4B7A-7A6B4A6B7A2(C5A8B2A8B5AC6A8B2A8B6A)-6A6B4A6B6A2-7A4B6A4B7A3-26A5-8ACAC2ACAC8A8-BACBC10-CBCAB5-
