model
size = 30 15 12, scale = 0.05, origin = -y
material 
  colors = A:#0A0 B:#AAA C:#002
voxels
6-4AC10-C4A9-5A10-5A8-CB2AC3ABA4CAB3AC2ABC5-BCABC2ABAC6ACAB2ACBACB3-2ABCB2ACACB6ABCAC2ABCB2A2-B3A2C16A2C3AB-2B2AC2A2CA3(C2A)CA2C2AC2A3B2(CB)CAB2CACB4ABCA2CBA3(CB)CAC2A2(CA)B2ACA2CAC2AB2(AC)2ACA2(C2A)CBA2(CB)6A2(BC)AB2(C2A)CAB3ACACBAB6ABABCAC3ABAC-4A2BAB4AC2AC4ABA2B4A2-2BCBCABACBA6CABCABACBC2B3-BCAB3AB2ACA2CAC2AB3ABACB5-BA2(CAB)C2A2C2A2(CBA)CAB153-C28-CA28-AB2(28-2B)28-B241-C26-C2-A26-A-A2(C26-C3A26-3A)C26-CA-B26-B2-A26-A153-A24-A3-2A24-2A2-2A24-2A-3A24-5AB24-B2(4AC24-C)4AB24-B2A-2A24-2A2-2A24-2A3-C24-C95-B22-B5-2A22-2A3-3A22-3A2-3A22-3A-4A22-8A22-7AB22-B7A22-8A22-4A-2AC22-C2A2-2AC22-C2A3-AB22-BA5-C22-C66-AC20-CA5-2AB20-B2A3-3AC20-C3A2-3AB20-B3A-4AC20-C8AC20-C9A20-10A20-9AB20-B4A-4A20-4A2-4A20-4A3-3A20-3A5-AC20-CA38-4AC10-C4A8-2(2A2(C3A)C)2A5-3AB18-B3A3-4AC18-C4A2-4AB18-B4A-6A2(18-12A)18-11AB18-B10AB18-B5A-4AC18-C4A2-5A18-5A3-3AC18-C3A5-2(6A3B)6A8-ACB2C10-2CBCA2(10-5A)2(8-24A5-4A18-4A3-5A18-5A2-5A18-5A-6A4(18-12A)18-6A-5A18-5A2-5A18-5A3-4A18-4A5-24A8-3(5A10-)5A)8-24A5-4AC2A2C2(2AB)2A2C2AC4A2(3-5A18-5A2-5A18-5A-6A4(18-12A)18-6A-5A18-5A2-5A18-5A3-4A18-4A5-24A8-3(5A10-)5A8-24A5-26A)3-28A2-7A4B6A4B7A-7A6B4A6B13A3(8B2A8B12A)8B2A8B6A-6A6B4A6B6A2-7A4B6A4B7A3-26A5-24A8-5A10-5A5-
