model
size = 30 15 12, scale = 0.05, origin = -y
material 
  colors = A:#699 B:#366 C:#FFC
voxels
6-B2ABA10-AB2AB9-B4A10-4AB8-5BA3B6A3BA5B5-2BA3BAB3AB2AB3ABA3BA2B3-3AB5A2(BA)2B2(AB)5AB3A2-2B2A2B2(AB)3A2B3A2(BA)2B2A2B-3B6A2B8A2B6A4B3ABA4B2(AB)2A2(BA)4BAB3A2B2(AB)5AB2A4B2AB5A2(BA)B3AB4ABAB3A2B3ABAB4AB3A3B2A2BA2(B2A)2B2(2AB)A2B2A3B-2(2AB)A2B3AB2AB3A2BA2(B2A)2-3AB3A2BA3B2A3BA2B3AB3A3-3ABA2B2A2B4A2B2A2BAB3A5-7BAB6ABA7B153-B28-BA28-AB2(28-2B)28-B241-B26-B2-A26-A-2A26-3AB26-B2AB26-B3A26-3AB26-BA-B26-B2-A26-A153-A24-A3-2A24-2A2-AB24-BA-2AB24-B5A24-5A2(B24-B4A)B24-B2A-AB24-BA2-2A24-2A3-B24-B95-A22-A5-2A22-2A3-3A22-3A2-3A22-3A-3AB22-B7A2(22-8A)22-7AB22-B3A-2AB22-B2A2-2AB22-B2A3-AB22-BA5-A22-A66-AB20-BA5-2AB20-B2A3-3AB20-B3A2-3AB20-B3A-4A4(B20-B8A)B20-B4A-4A20-4A2-3AB20-B3A3-2AB20-B2A5-2A20-2A38-2B3A10-3A2B8-2(2A3B)A2BA2(3B2A)5-3AB18-B3A3-4AB18-B4A2-4AB18-B4A-5A3(B18-B10A)B18-B11A18-6A-4AB18-B4A2-4AB18-B4A3-3AB18-B3A5-2A20B2A8-4BA10-A4B10-BA3B10-3BAB8-7ABA6BAB7A5-4A18-4A3-5A18-5A2-5A18-5A-6A4(18-12A)18-6A-5A18-5A2-5A18-5A3-4A18-4A5-7ABA6BAB7A8-BA3B10-3BAB10-BAB2A10-2ABAB8-7A4B2A4B7A5-4A18-4A3-5A18-5A2-5A18-5A-6A4(18-12A)18-6A-5A18-5A2-5A18-5A3-4A18-4A5-7A4B2A4B7A8-BAB2A10-2ABAB10-3BAB10-BA3B8-8ABAB2ABAB8A5-5A16B5A3-5A18-5A2-5A18-5A-6A4(18-12A)18-6A-5A18-5A2-5A18-5A3-4A18-4A5-8ABAB2ABAB8A8-3BAB2(10-BA3B)10-3BAB8-7A10B7A5-26A3-5A18-5A2-5A18-5A-6A4(18-12A)18-6A-5A18-5A2-5A18-5A3-4A18-4A5-7A10B7A8-BA3B10-3BAB2(10-5B)8-7A4B2A4B7A5-26A3-28A2-7A4C6A4C7A-7A6C4A6C13A3(8C2A8C12A)8C2A8C6A-6A6C4A6C6A2-7A4C6A4C7A3-26A5-7A4B2A4B7A8-5B10-5B5-
