model
size = 30 15 12, scale = 0.05, origin = -y
material 
  colors = A:#666 B:#111 C:#E00
voxels
6-C3AB10-B3AC9-AC3A10-3ACA8-A4CBAB2A4C2ABAB4CA5-2CAB2AC2BCBA2CABC2BC2ABA2C3-2CBAB7AC2BC7ABAB2C2-2ABA3B2C2(2A2B)2A2C3BAB2A-2BC3AB2ACBACB2CBCABC2AB3AC2B6ACABA2C2A2B2A2CABAC6A2CB2(AC)4BA2B2A2BA4B2(CA)B2CA2C4ABA2(BC)A2CA2(CB)AB4A2CABCB4A3C3AC2AC3A3C4ABCB-BA2(2C2AC3AC2A)2CAB2-AB2(AC)BCB10A2(BC)ACABA3-2(AB)2AB2(AC)4A2(CA)B2A2(BA)5-2A2BAB2C3A2B3A2CBA2B2A153-A28-2A28-AC28-CA28-2A28-A241-A26-A2-A26-A-2A4(26-4A)26-2A-A26-A2-A26-A153-A24-A3-2A24-2A2-2A24-2A-3A24-5AB24-B5A2(24-6A)24-3A-2A24-2A2-AB24-BA3-A24-A95-A22-A5-2A22-2A3-3A22-3A2-3A22-3A-4A4(22-8A)22-4A-2AC22-C2A2-3A22-3A3-AC22-CA5-A22-A66-AC20-CA5-2AB20-B2A3-4A20-4A2-4A20-4A-4AB20-B8AB20-B9A20-9AC20-C8AB20-B4A-4A20-4A2-4A20-4A3-3A20-3A5-AC20-CA38-3ABA10-AB3A8-3AB4ABC4ACB4AB3A5-3AC18-C3A3-5A18-5A2-5A18-5A-6A3(18-12A)18-11AB18-B5A-5A18-5A2-5A18-5A3-3AB18-B3A5-8ACBA2CABC8A8-AC3A10-3ACA2(10-5A)2(8-24A5-4A18-4A3-5A18-5A2-5A18-5A-6A4(18-12A)18-6A-5A18-5A2-5A18-5A3-4A18-4A5-24A8-3(5A10-)5A)2(8-24A5-26A3-5A18-5A2-5A18-5A-6A4(18-12A)18-6A-5A18-5A2-5A18-5A3-4A18-4A5-24A8-3(5A10-)5A)8-24A5-26A3-28A2-7A4B6A4B7A-7A6B4A6B13A3(8B2A8B12A)8B2A8B6A-6A6B4A6B6A2-7A4B6A4B7A3-26A5-24A8-5A10-5A5-
