model
size = 27 15 30, scale = 0.05, origin = -y
material 
  colors = A:#111 B:#222
voxels
37-7A20-7A344-7A20-7A369-12A15-3A6-3A365-14A13-A11-2A362-18A9-3A12-3A359-20A7-2A16-2A357-22A5-2A6-6B6-2A13-6B8(21-6A)121-8A6-8A5-A5-2B6-B6-A11-2B6-B7(18-2A6-A)18-3A5-A21-5A23-2A68-7A9-8A3-2A4-B9-2B4-2A9-B9-2B6(15-A9-2A)2(15-A8-3A)16-3A4-A22-A2-A23-4A39-7A12-6A2-2A4-B12-B4-A8-B12-B6(13-A12-A)2(13-A11-2A)14-A8-2A17-3A4-A20-4A-2A23-2A13-7A12-6A2-A5-B12-B4-A8-B12-B8(13-A12-A)14-A10-A16-A7-2A17-2A5-3A19-5A12-6A14-5A2-A4-B14-B3-A7-B14-B6(11-A14-A)11-A13-2A11-2A12-2A13-A10-A15-A9-A16-A9-A17-9A9-7A14-8A4-B14-B3-2A6-B14-B8(11-A14-A)2(12-A)14-A10-A15-A9-2A16-9A9-6A16-6A4-B16-B2-2A5-B16-B6(9-A16-A)9-A15-2A9-2A14-2A11-A12-A14-A10-A15-A10-A16-10A8-6A16-6A4-B16-B3-A5-B16-B8(9-A16-A)10-2A12-2A13-2(A10-A15-)2(12A7-6A16-6A4-B16-B3-A5-A16-B8(9-A16-A)10-A14-2(A12-)A13-A12-A14-)12A7-6A16-6A4-B16-B3-A5-B16-B8(9-A16-A)10-A14-2(A12-)A13-A12-A14-12A7-6A16-6A4-B16-B3-A5-B16-B8(9-A16-A)10-2A12-2A13-2(A10-A15-)11A8-7A14-8A4-B14-B3-2A6-B14-B8(11-A14-A)2(12-A)14-A10-A15-A9-2A16-9A10-6A14-5A2-A4-B14-B3-A7-B14-B8(11-A14-A)12-A11-2A14-A9-A16-2A7-2A18-7A11-7A12-6A2-A5-B12-B4-A8-B12-B8(13-A12-A)14-A9-2A16-2A6-A18-3A5-A21-5A11-7A12-6A2-2A4-B12-B4-A8-B12-B7(13-A12-A)13-A11-2A14-3A6-2A19-2A3-A21-3A-2A24-A14-7A9-8A3-2A4-B9-2B4-2A9-B9-2B7(15-A9-2A)15-2A8-2A17-3A3-2A22-3A24-3A41-8A6-8A5-A5-2B6-B5-2A11-2B6-B7(18-2A6-A)18-3A5-A21-5A94-22A5-2A6-6B5-3A13-6B8(21-6A)122-20A7-2A16-2A359-18A9-3A12-3A362-14A13-A11-2A365-12A15-3A6-3A358-
