model
size = 30 15 12, scale = 0.05, origin = -y
material 
  colors = A:#09C B:#0D0 C:#DDD
voxels
6-4BA10-A4B9-AB3A10-3ABA8-B5A2(2BABA)2B5AB5-3(AB)2A2B6A2B2A3(BA)3-2B2(AB)A5BA2BA5B2(AB)A2B2-2A2BABA2BA8BA2BABA2B2A-3B2A2B6AB2AB6A2B2A4BA3BA2B2AB8AB2A2BA3BA2B2A4B4AB2A2B2AB4A4B2ABA5BA3BAB2A2B2ABA3BA5B5ABA3BAB3A2B3ABA3BAB4A-2(AB)3A2(B2A)2B2(2AB)3A2(BA)2-A7B2(2ABAB)2A7BA3-4B2(AB)3(A2B)2(AB)A4B5-B4A4BAB2ABA4B4AB153-B28-BA28-AB28-BA28-2A28-A241-A26-A2-B26-B-2B26-2B2A26-3AB26-B2AB26-BA2B26-2B-A26-A2-B26-B153-B24-B3-AB24-BA2-AB24-BA-2AB24-B5A24-5A2(B24-B4A)B24-B2A-2A24-2A2-AB24-BA3-B24-B95-A22-A5-2A22-2A3-3A22-3A2-2AB22-B2A-4A3(22-8A)22-7AB22-B3A-3A22-3A2-3A22-3A3-AB22-BA5-A22-A66-AB20-BA5-2AB20-B2A3-4A20-4A2-3AB20-B3A-B3AB20-B3AB5A20-9AB20-B8AB20-B4AB3AB20-B3AB-3AB20-B3A2-3AB20-B3A3-2AB20-B2A5-2A20-2A38-2(AB)A10-2(AB)A8-4A3B2ABA2BAB2A3B4A5-3AB18-B3A3-5A18-5A2-4AB18-B4A-5A3(B18-B10A)B18-B11A18-6A-5A18-5A2-5A18-5A3-4A18-4A5-8A3B2A3B8A8-2(2AB2A10-)5A10-2(5A8-24A5-4A18-4A3-5A18-5A2-5A18-5A-6A18-12A18-6AB5A18-5AB6A18-12A18-6A-5A18-5A2-5A18-5A3-4A18-4A5-24A8-3(5A10-))5A8-24A5-7ABA3B2A3BAB7A2(3-5A18-5A2-5A18-5A-6A4(18-12A)18-6A-5A18-5A2-5A18-5A3-4A18-4A5-24A8-3(5A10-)5A8-24A5-26A)3-28A2-7A4C6A4C7A-7A6C4A6C13A3(8C2A8C12A)8C2A8C6A-6A6C4A6C6A2-7A4C6A4C7A3-26A5-24A8-5A10-5A5-
