model
size = 30 15 12, scale = 0.05, origin = -y
material 
  colors = A:#CF3 B:#555 C:#399
voxels
6-2AC2A10-2AC2A9-2AB2A10-2AB2A8-2(AB)2A2BAB4ABA2B2A2(BA)5-3ABCABA3CA2BA3CABACB3A3-3ACACB4ACA2BAC4ABCAC3A2-2AB5ACB8ABC5AB2A-AB2ACB3A2CAC4ACA2C3ABC2ABACB6AB5A2B5AB6ABCB3ABA3B3A2C2A2C3A3BAB3AB2CAB2CBAB3AB4AB3ABAB2CBA2C2A3C2(3AC)B2AB2(C3A)3C2A-2ABAB2CAB2AB4AB2ABA2CBAB2A2-CB2AB2CAB4A2C4ABA2CB2ABC3-B2AC2(B2A)BC2BC2(B2A)BC2AB5-A2C4A2B6C2B4A2CA153-A4(28-2A)28-A241-A26-A2-A26-A-2A4(26-4A)26-2A-A26-A2-A26-A153-A24-A3-2A24-2A2-2A24-2A-3A4(24-6A)24-3A-2A24-2A2-2A24-2A3-A24-A95-A22-A5-2A22-2A3-3A22-3A2-3A22-3A-4A4(22-8A)22-4A-3A22-3A2-3A22-3A3-2A22-2A5-A22-A66-2A20-2A5-3A20-3A3-4A20-4A2-4A20-4A-5A4(20-10A)20-5A-4A20-4A2-4A20-4A3-3A20-3A5-2A20-2A38-5A10-3(5A8-24A5-4A18-4A3-5A18-5A2-5A18-5A-6A4(18-12A)18-6A-5A18-5A2-5A18-5A3-4A18-4A5-24A8-3(5A10-))2(5A8-24A5-26A3-5A18-5A2-5A18-5A-6A4(18-12A)18-6A-5A18-5A2-5A18-5A3-4A18-4A5-24A8-3(5A10-))5A8-24A5-26A3-28A2-7A4B6A4B7A-7A6B4A6B13A3(8B2A8B12A)8B2A8B6A-6A6B4A6B6A2-7A4B6A4B7A3-26A5-24A8-5A10-5A5-
