model
size = 30 15 12, scale = 0.05, origin = -y
material 
  colors = A:#C9C B:#93F C:#F66
voxels
6-ABACA10-ACABA9-CACBA10-ABCAC8-2C2ABABC2B4A2BCBAB2A2C5-CA2CBA2C2BAB2ABA2B2CAB2CAC3-B2A3C3ACAB4ABAC3A3C2AB2-A2CAC2ABA3BA2BA3BAB2ACA2CA-2(AC)BAB3A2(BA)2C2(AB)3ABAB2(CA)2CAB3A2CA2CB4CB2CA2C3ABA3CB2A2(CA)2BAC6BCA2B2(AC)2ABCA2C3ACBC2A2(2BC)2B2ACBC3A2(2CA)2BA2BC5A2C5AC2(2BA)2C-2C3A2B3AC2A2C2AC3A2B3A2C2-A2B3AB2ACAC4ACAC2AB3A2BA3-BCA2C2B2CAC4ACA2C2B2CACB5-A2(CB)2CABC4ACBA2C2(BC)A153-A4(28-2A)28-A241-A26-A2-A26-A-2A4(26-4A)26-2A-A26-A2-A26-A153-A24-A3-2A24-2A2-2A24-2A-3A4(24-6A)24-3A-2A24-2A2-2A24-2A3-A24-A95-A22-A5-2A22-2A3-3A22-3A2-3A22-3A-4A4(22-8A)22-4A-3A22-3A2-3A22-3A3-2A22-2A5-A22-A66-2A20-2A5-3A20-3A3-4A20-4A2-4A20-4A-5A4(20-10A)20-5A-4A20-4A2-4A20-4A3-3A20-3A5-2A20-2A38-5A10-5A8-24A5-4A18-4A3-5A18-5A2-5A18-5A-6A4(18-12A)18-6A-5A18-5A2-5A18-5A3-4A18-4A5-24A8-2(5A10-)CA3B10-3BAC8-8A3C2B3C8A5-4A18-4A3-5A18-5A2-5A18-5A-6A4(18-12A)18-6A-5A18-5A2-5A18-5A3-4A18-4A5-8A3C2B3C8A8-CA3B10-3BAC10-C2BAC10-CA2BC8-7ACBA4CABC7A5-4A18-4A3-5A18-5A2-5A18-5A-6A4(18-12A)18-6A-5A18-5A2-5A18-5A3-4A18-4A5-7ACBA4CABC7A8-C2BAC10-CA2BC10-2C2BC10-C2B2C8-7ABA2B2A2BAB7A5-26A3-5A18-5A2-5A18-5A-6A4(18-12A)18-6A-5A18-5A2-5A18-5A3-4A18-4A5-7ABA2B2A2BAB7A8-2C2BC10-C2B2C10-B2CAC10-CA2CB8-8AB2C2A2CB8A5-26A3-5A18-5A2-5A18-5A-6A4(18-12A)18-6A-5A18-5A2-5A18-5A3-4A18-4A5-8AB2C2A2CB8A8-B2CAC10-CA2CB10-3B2A10-2A3B8-7A2CB4AB2C7A5-26A3-28A2-7A4B6A4B7A-7A6B4A6B13A3(8B2A8B12A)8B2A8B6A-6A6B4A6B6A2-7A4B6A4B7A3-26A5-7A2CB4AB2C7A8-3B2A10-2A3B5-
