model
size = 30 15 12, scale = 0.05, origin = -y
material 
  colors = A:#3F9 B:#036 C:#663
voxels
6-B2CBA10-AB2CB9-C2B2A10-2A2BC8-3A3B2AC6AC2A3B3A5-C2ACB2CAC2B4A2BCA2CBC2AC3-2(CB)2C5AC4AC5A2C2(BC)2-3AB2AC3ABAB2CBAB3AC2AB3A-5AB3ACA8BAC3AB5ACA2C2AB3ACBAB2ABABC3AB2A2CACB6AB3AC2B2A2BC3AB6A2BAB5AC3AC4AC3AC5ABA2B4ABACB2A2(2CB)2C2ABCAB4AB-A2(CB)3A2(BC)4A2(CB)3A2(BC)A2-4A2(CA)BCB6ABCB2(AC)4A3-AB2A3CBAC2B2A2BCAB3C2ABA5-4AB2AC2BA2CA2BC2AB4A153-C28-CB3(28-2B)28-B241-B26-B2-C26-C-AB26-BABC26-CBAC26-CABA26-ABAC26-CA-B26-B2-C26-C153-B24-B3-AB24-BA2-AB24-BA-C2A24-2A2CAB24-BAC2AC24-C2ACAB24-BA2CAC24-CAC-AB24-BA2-AC24-CA3-B24-B95-A22-A5-AB22-BA3-3A22-3A2-2AC22-C2A-C3A22-3ACB3A22-3A2B2AB22-B2A2B2AC22-C2ABC2AC22-C2AC-2AB22-B2A2-2AC22-C2A3-2A22-2A5-A22-A66-2A20-2A5-2AC20-C2A3-3AC20-C3A2-3AC20-C3A-4AB20-B8AC20-C4AC3AB20-B3AC5A20-9AC20-C4A-3AB20-B3A2-4A20-4A3-2AC20-C2A5-AB20-BA38-2B2CA10-A2C2B8-2AB2C3BABA2BABA3B2CB2A5-4A18-4A3-4AC18-C4A2-4AB18-B4A-B4AB18-B4AB5A2(B18-B10A)B18-B5AB4AB18-B4AB-4AB18-B4A2-5A18-5A3-3AB18-B3A5-2A2(CA)BACBC2BCBCAB2(AC)2A8-C2BAB10-BA2BC2(10-5A)8-24A5-4A18-4A3-5A18-5A2-5A18-5A-6A18-12A18-6AB5A18-5AB6A18-12A18-6A-5A18-5A2-5A18-5A3-4A18-4A5-24A8-3(5A10-)5A8-24A5-4A18-4A3-5A18-5A2-5A18-5A-C5A18-5AC6A18-6AB5A18-5AB6A18-6AC5A18-5AC-5A18-5A2-5A18-5A3-4A18-4A5-24A8-3(5A10-)5A8-24A5-4A2CACA2B4C2BACA2C4A3-5A18-5A2-5A18-5A-6A18-12A18-6AC5A18-5AC6A18-12A18-6A-5A18-5A2-5A18-5A3-4A18-4A5-24A8-3(5A10-)5A8-24A5-26A3-5A18-5A2-5A18-5A-6A4(18-12A)18-6A-5A18-5A2-5A18-5A3-4A18-4A5-24A8-3(5A10-)5A8-24A5-26A3-28A2-7A4B6A4B7A-B6A6B4A6B6A4(2B5A8B2A8B5A)B-6A6B4A6B6A2-7A4B6A4B7A3-26A5-24A8-5A10-5A5-
