model
size = 30 15 12, scale = 0.05, origin = -y
material 
  colors = A:#6FC B:#C00 C:#FF9
voxels
6-A2B2A10-2A2BA9-CAC2A10-2ACAC8-ACA3BCA2C4A2CAC3BACA5-2A3BAC2(BA)B2A2(BA)BCA3B2A3-B2C3ACABA8BABAC3A2CB2-A2(BC)B4AB6AB4A2(BC)BA-AB2(AC)3A4CB2AB4C3A2(CA)BA2BCB2CA2BC2AB4CB2AC2BA2CBC2BA2B2ABACBA2CAC2ACA2CABCAB2A2B4AC6ABACA2CACAB6AC6A2CB4AB3A2B3AB4AB2C3A-2AC3AB2ABCAC2ACACB2AB3AC2A2-C2BACA2B2ABAC2ACAB2A2BACA2BC3-4A2C2(ACB)2A2(BCA)2C4A5-2CAB5AC4AC5ABA2C153-A4(28-2A)28-A241-A26-A2-A26-A-2A4(26-4A)26-2A-A26-A2-A26-A153-A24-A3-2A24-2A2-2A24-2A-3A4(24-6A)24-3A-2A24-2A2-2A24-2A3-A24-A95-A22-A5-2A22-2A3-3A22-3A2-3A22-3A-4A4(22-8A)22-4A-3A22-3A2-3A22-3A3-2A22-2A5-A22-A66-2A20-2A5-3A20-3A3-4A20-4A2-4A20-4A-5A4(20-10A)20-5A-4A20-4A2-4A20-4A3-3A20-3A5-2A20-2A38-5A10-5A8-24A5-4A18-4A3-5A18-5A2-5A18-5A-6A4(18-12A)18-6A-5A18-5A2-5A18-5A3-4A18-4A5-24A8-2(5A10-)CAC2B10-2BCAC8-7A3B4A3B7A5-4A18-4A3-5A18-5A2-5A18-5A-6A4(18-12A)18-6A-5A18-5A2-5A18-5A3-4A18-4A5-7A3B4A3B7A8-CAC2B10-2BCAC10-B2CBC10-CB2CB8-7AB2CB2AB2CB7A5-4A18-4A3-5A18-5A2-5A18-5A-6A4(18-12A)18-6A-5A18-5A2-5A18-5A3-4A18-4A5-7AB2CB2AB2CB7A8-B2CBC10-CB2CB10-2BCBA10-ABC2B8-7A2BCB2ABC2B7A5-26A3-5A18-5A2-5A18-5A-6A4(18-12A)18-6A-5A18-5A2-5A18-5A3-4A18-4A5-7A2BCB2ABC2B7A8-2BCBA10-ABC2B10-AC2BC10-C2BCA8-7A2(CB)2A2(BC)7A5-26A3-5A18-5A2-5A18-5A-6A4(18-12A)18-6A-5A18-5A2-5A18-5A3-4A18-4A5-7A2(CB)2A2(BC)7A8-AC2BC10-C2BCA10-B2CBA10-AB2CB8-7A4C2B4C7A5-26A3-28A2-7A4B6A4B7A-7A6B4A6B13A3(8B2A8B12A)8B2A8B6A-6A6B4A6B6A2-7A4B6A4B7A3-26A5-7A4C2B4C7A8-B2CBA10-AB2CB5-
