model
size = 30 15 12, scale = 0.05, origin = -y
material 
  colors = A:#3F6 B:#F0F C:#F36
voxels
6-3A2B10-2B3A9-5A10-5A8-BAB4A2(2B2A)2B4ABAB5-2B5A2B2(2AB)2A2B5A2B3-4ABA3B3(A2B)A3BAB4A2-A2B6ABA6BAB6A2BA-2BA3BABA3B2A2B2A3BABA3BA6B2(2AB)2(3AB2AB)2A5BABA5BAB2A4B2ABA5B2(AB)2AB3A4B2AB4AB2A4B3AB3A2B2A2B3ABAB4ABAB3A2B2A2BA-2(2A2B)A3(B2A)BA2(2B2A)2-2A3BA3B2A6B2A3BA3B2A3-5BA3BAB4ABA3BA5B5-2A5B2AB4AB2A5B2A153-A28-AB28-BA28-2A28-AB28-B241-B26-B2-B26-B-BA26-2(AB)2(26-B2AB)26-BA2B26-2B-B26-B2-A26-A153-B24-B3-2A24-2A2-AB24-BA-BAB24-BAB2AB24-B4AB24-B5A24-3AB2A24-2AB-AB24-BA2-2A24-2A3-A24-A95-B22-B5-2A22-2A3-3A22-3A2-2AB22-B2A-B3A22-2(3AB)22-B3AB2AB22-B2AB3AB22-2(B3A)22-3AB-2AB22-B2A2-3A22-3A3-AB22-BA5-B22-B66-2A20-2A5-3A20-3A3-4A20-4A2-4A20-4A-B3(4A20-4A2B)3AB20-B3A2B4A20-4AB-4A20-4A2-4A20-4A3-3A20-3A5-2A20-2A38-3ABA10-AB3A8-3ABAB12ABAB3A5-4A18-4A3-4AB18-B4A2-4AB18-B4A-B5A18-5A2B4AB18-B4AB6A18-6AB4AB18-B4A2B4AB18-B4AB-4AB18-B4A2-4AB18-B4A3-4A18-4A5-2(2A2B)2(ABA2B)2A2B2A8-A2B2A10-2A2B2(A10-A3B)A8-7A2BAB2ABA2B7A5-4A18-4A3-5A18-5A2-5A18-5A-6A18-6AB2(5A18-5A2B)5A18-5AB6A18-6A-5A18-5A2-5A18-5A3-4A18-4A5-7A2BAB2ABA2B7A8-2(A3BA10-)3BAB10-BA3B8-7A3BA2BA3B7A5-4A18-4A3-5A18-5A2-5A18-5A-B4(5A18-5A2B)5A18-5AB-5A18-5A2-5A18-5A3-4A18-4A5-7A3BA2BA3B7A8-3BAB10-BA3B2(10-B3AB)8-10A4B10A5-4A3B2AB2A2B2AB2A3B4A3-5A18-5A2-5A18-5A-6A18-6AB2(5A18-5A2B)5A18-5AB6A18-6A-5A18-5A2-5A18-5A3-4A18-4A5-10A4B10A8-2(B3AB10-)4BA10-A4B8-7A2BAB2ABA2B7A5-26A3-5A18-5A2-5A18-5A-B4(5A18-5A2B)5A18-5AB-5A18-5A2-5A18-5A3-4A18-4A5-7A2BAB2ABA2B7A8-4BA10-A4B2(10-A3BA)8-7A3(B2A)B7A5-26A3-28A2-7A4C6A4C7A-7A6C4A6C7AB2(5A8C2A8C5A2B)5A8C2A8C5AB6A8C2A8C6A-6A6C4A6C6A2-7A4C6A4C7A3-26A5-7A3(B2A)B7A8-A3BA10-A3BA5-
