model
size = 30 15 12, scale = 0.05, origin = -y
material 
  colors = A:#400 B:#444 C:#903
voxels
6-C2A2B10-2B2AC9-ACB2A10-2ABCA8-ABC2AB2(CA)4C2(AC)B2ACBA5-5A3CBAC4ACAB3C5A3-C7ABCB6ABCB7AC2-3AC2A2CA4C2A4CA2C2AC3A-A3CB2CB2(AC)BC2BCB2(CA)B2CB3C2A2C3A2C2ABAC4ACAB2A2C3A2(2CA)3CABA3C6A3CABA3CA2C2ACA2C2A2(BC)AB2CBA2(CB)2A2CAC2ACBA2(B2A)CACBC2ACBCAC2(2AB)ABC-B2(CA)B2C4A4B4A2CB2(AC)B2-A3CACBA2C2(2BA)2B2CABCA3CA3-C3ABCB2AB6AB2ABCB3AC5-B2A2(C3A)2B2(3AC)2AB153-A4(28-2A)28-A241-A26-A2-A26-A-2(2A26-2ACA26-AC)2A26-2A-A26-A2-A26-A153-A24-A3-2A24-2A2-2A24-2A-3A4(24-6A)24-3A-2A24-2A2-2A24-2A3-A24-A95-A22-A5-2A22-2A3-3A22-3A2-3A22-3A-4A4(22-8A)22-4A-3A22-3A2-3A22-3A3-2A22-2A5-A22-A66-2A20-2A5-3A20-3A3-4A20-4A2-4A20-4A-2(C4A20-4AC5A20-5A)C4A20-4AC-4A20-4A2-4A20-4A3-3A20-3A5-2A20-2A38-5A10-5A8-24A5-4A18-4A3-5A18-5A2-5A18-5A-6A18-12A18-6AC5A18-5AC6A18-12A18-6A-5A18-5A2-5A18-5A3-4A18-4A5-24A8-2(5A10-)2AB2A10-2AB2A8-24A5-4A18-4A3-5A18-5A2-5A18-5A-B5A18-5AB6A18-6AC5A18-5AC6A18-6AB5A18-5AB-5A18-5A2-5A18-5A3-4A18-4A5-24A8-2(2AB2A10-)CAB2A10-2ABAC8-10AB2AB10A5-4A18-4A3-5A18-5A2-5A18-5A-6A18-6AC5A18-5ACB5A18-5ABC5A18-5AC6A18-6A-5A18-5A2-5A18-5A3-4A18-4A5-10AB2AB10A8-CAB2A10-2ABAC10-2ACAC10-CAC2A8-7ACAB4ABAC7A5-26A3-5A18-5A2-5A18-5A-6A18-12A18-6AB5A18-5AB6A18-12A18-6A-5A18-5A2-5A18-5A3-4A18-4A5-7ACAB4ABAC7A8-2ACAC10-CAC2A10-ACABA10-ABACA8-24A5-26A3-5A18-5A2-5A18-5A-6A4(18-12A)18-6A-5A18-5A2-5A18-5A3-4A18-4A5-24A8-ACABA10-ABACA10-4AC10-C4A8-7AC8AC7A5-26A3-28A2-7A4B6A4B7A-B6A6B4A6B6A2(B6A8B2A8B6AB5A8B2A8B5A)B-6A6B4A6B6A2-7A4B6A4B7A3-26A5-7AC8AC7A8-4AC10-C4A5-
