model
size = 30 15 12, scale = 0.05, origin = -y
material 
  colors = A:#03F B:#F9F C:#FFC
voxels
6-BA3B10-3BAB9-B2A2B10-2B2AB8-2B2(AB)4AB2AB4A2(BA)2B5-ABA2B2A2(2BABA)2B2A2BABA3-3ABA4B2(AB)2A2(BA)4BAB3A2-3ABA2B2A2BA4BA2B2A2BAB3A-2B2A7B8A7B2A3B3A2BAB6A2B6ABA2B3A2B2ABA3B2(AB)2A2B2A2(BA)3BA2(B2A)BA2BAB5A4B5ABA2BAB2(3A2B)A5B2A5BA2B3A2BA-B2A2B3A2(BA)4B2(AB)3A2B2AB2-2(4AB)8A2(B4A)3-2ABA2(B2A)BA2BA2(B2A)BAB2A5-2B2ABA2B2(2AB)2A2BAB2A2B153-A4(28-2A)28-A241-A26-A2-A26-A-2A26-2AB2(A26-A2B)A26-AB2A26-2A-A26-A2-A26-A153-A24-A3-2A24-2A2-2A24-2A-B4(2A24-2A2B)2A24-2AB-2A24-2A2-2A24-2A3-A24-A95-A22-A5-2A22-2A3-3A22-3A2-3A22-3A-2(B3A22-3AB4A22-4A)B3A22-3AB-3A22-3A2-3A22-3A3-2A22-2A5-A22-A66-2A20-2A5-3A20-3A3-4A20-4A2-4A20-4A-B4A20-4AB5A2(20-10A)20-5AB4A20-4AB-4A20-4A2-4A20-4A3-3A20-3A5-2A20-2A38-5A10-5A8-24A5-4A18-4A3-5A18-5A2-5A18-5A-2(B5A18-5AB6A18-6A)B5A18-5AB-5A18-5A2-5A18-5A3-4A18-4A5-24A8-3(5A10-)5A8-24A5-4A18-4A3-5A18-5A2-5A18-5A-6A18-12A18-6AB5A18-5AB6A18-12A18-6A-5A18-5A2-5A18-5A3-4A18-4A5-24A8-3(5A10-)5A8-24A5-4A18-4A3-5A18-5A2-5A18-5A-2(B5A18-5AB6A18-6A)B5A18-5AB-5A18-5A2-5A18-5A3-4A18-4A5-24A8-3(5A10-)5A8-24A5-26A3-5A18-5A2-5A18-5A-6A18-6AB2(5A18-5A2B)5A18-5AB6A18-6A-5A18-5A2-5A18-5A3-4A18-4A5-24A8-3(5A10-)5A8-24A5-26A3-5A18-5A2-5A18-5A-B5A18-5A2B5A18-5AB6A18-6AB5A18-5A2B5A18-5AB-5A18-5A2-5A18-5A3-4A18-4A5-24A8-3(5A10-)5A8-24A5-26A3-28A2-7A4C6A4C7A-7A6C4A6C7AB2(5A8C2A8C5A2B)5A8C2A8C5AB6A8C2A8C6A-6A6C4A6C6A2-7A4C6A4C7A3-26A5-24A8-5A10-5A5-
