model
size = 30 15 12, scale = 0.05, origin = -y
material 
  colors = A:#996 B:#666 C:#360
voxels
6-C4A10-4AC9-BAC2A10-2ACAB8-2B2A2BABACB2CBCABA2B2A2B5-AC2(AB)6A2B6A2(BA)CA3-2A3C8A2C8A3C2A2-CB3AB2ABC2A4C2ACB2AB3ABC-2(CB)C3ACAB2C4A2CBAC3A2(CB)C2AB2ACB6AB2CB6ABC2AB2ACB2(CA)B2ABC2(2AB)2ACB2AB2(AC)BC3A2B2(AC)2(2ABAB)2A2(CA)2B5ACB2ABAC3ACA2CAC3ACAB2ABC2A-AB4ACBCAC2A2C2ACACBC4ABA2-CA4CA2BC2(2AB)2AC2BA4CAC3-AC2A3B4AC2AC4A3B2ACA5-AB3A2(BC)2A2B2A2(CB)3ABA153-A4(28-2A)28-A241-A26-A2-A26-A-2A4(26-4A)26-2A-A26-A2-A26-A153-A24-A3-2A24-2A2-2A24-2A-3A4(24-6A)24-3A-2A24-2A2-2A24-2A3-A24-A95-A22-A5-2A22-2A3-3A22-3A2-3A22-3A-4A4(22-8A)22-4A-3A22-3A2-3A22-3A3-2A22-2A5-A22-A66-2A20-2A5-3A20-3A3-4A20-4A2-4A20-4A-5A4(20-10A)20-5A-4A20-4A2-4A20-4A3-3A20-3A5-2A20-2A38-5A10-3(5A8-24A5-4A18-4A3-5A18-5A2-5A18-5A-6A4(18-12A)18-6A-5A18-5A2-5A18-5A3-4A18-4A5-24A8-3(5A10-))2(5A8-24A5-26A3-5A18-5A2-5A18-5A-6A4(18-12A)18-6A-5A18-5A2-5A18-5A3-4A18-4A5-24A8-3(5A10-))5A8-24A5-26A3-28A2-7A4B6A4B7A-7A6B4A6B13A3(8B2A8B12A)8B2A8B6A-6A6B4A6B6A2-7A4B6A4B7A3-26A5-24A8-5A10-5A5-
