model
size = 30 15 12, scale = 0.05, origin = -y
material 
  colors = A:#93C B:#060 C:#939
voxels
6-ABA2B10-2BABA9-A4B10-4BA8-AB4A3B6A3B4ABA5-AB2AB3ABAB4ABAB3AB2ABA3-ABA3B2(AB)3(2AB)ABA3BABA2-3B5A2B2A4B2A2B5A3B-2B2(AB)2ABA2BA4BA2BAB2A2(BA)2B3A2B5A2(2B2A)2B5A2B3A2(BA)2BAB2A2B6A2B2A2(BA2BA)B2A5B4A2B4A5B2A2(BA)B2A2BA2B4AB2AB4A2BA2B2ABA-B2A4(BA)B4A4(BA)B2AB2-BA3BA4BA6BA4BA3BAB3-2(B2A)4(2BA)2B2(2AB)5-B2A2B3A2B4A2B3A2B2AB153-A28-AB3(28-2B)28-B241-A26-A2-B26-B-AB26-B3A3(26-4A)26-2A-B26-B2-A26-A153-B24-B3-AB24-BA2-2A24-2A-3A24-6A24-3ABAB24-BAB3A24-5AB24-B2A-2A24-2A2-AB24-BA3-B24-B95-A22-A5-2A22-2A3-2AB22-B2A2-2AB22-B2A-4A22-7AB22-B7A2(22-8A)22-4A-3A22-3A2-2AB22-B2A3-AB22-BA5-A22-A66-AB20-BA5-3A20-3A3-3AB20-B3A2-3AB20-B3A-5A20-5AB3AB20-B3AB4AB20-B4AB3AB20-B3AB5A20-5A-4A20-4A2-4A20-4A3-2AB20-B2A5-2A20-2A38-3B2A10-2A3B8-7A4B2A4B7A5-3AB18-B3A3-5A18-5A2-4AB18-B4A-5AB18-B10AB18-B11A18-11AB18-B11A18-6A-4AB18-B4A2-4AB18-B4A3-3AB18-B3A5-5A3(BA)2B3(AB)5A8-2(2(BA)B10-)5A10-5A8-24A5-4A18-4A3-5A18-5A2-5A18-5A-6A18-6AB2(5A18-5A2B)5A18-5AB6A18-6A-5A18-5A2-5A18-5A3-4A18-4A5-24A8-3(5A10-)5A8-24A5-4A18-4A3-5A18-5A2-5A18-5A-2(6A18-6AB5A18-5AB)6A18-6A-5A18-5A2-5A18-5A3-4A18-4A5-24A8-3(5A10-)5A8-24A5-4A4B2A6B2A4B4A3-5A18-5A2-5A18-5A-6A4(18-12A)18-6A-5A18-5A2-5A18-5A3-4A18-4A5-24A8-3(5A10-)5A8-24A5-26A3-5A18-5A2-5A18-5A-2(B5A18-5AB6A18-6A)B5A18-5AB-5A18-5A2-5A18-5A3-4A18-4A5-24A8-3(5A10-)5A8-24A5-26A3-28A2-7A4C6A4C7A-B6A6C4A6C6AB6A2(8C2A8C12A)8C2A8C6AB5A8C2A8C5AB-6A6C4A6C6A2-7A4C6A4C7A3-26A5-24A8-5A10-5A5-
