model
size = 30 15 12, scale = 0.05, origin = -y
material 
  colors = A:#690 B:#D00 C:#001
voxels
6-4AB10-B4A9-3A2B10-2B3A8-2(2A2B)A6BA2(2B2A)5-B2A2(2B7A)2B2AB3-B3ABA2BA3B4A3BA2BAB3AB2-B3AB4AB3A2B3AB4AB3AB-B2AB2(A3B)6A2(3BA)3(B2A)BA3BAB2A2B2ABA3BAB2AB4A2BAB2ABAB2A4B2ABAB2ABA2B2(2AB)4ABA4B2A4BAB4AB2A3BAB2A5B8A5B2ABA2B-2BA4B2A2(BA)2B2(AB)2A4BA2B2-2B3(AB)2ABA4BAB2A3(BA)2B3-A9BA4BA9BA5-B3A2BA10BA2B3AB153-A3(28-2A)28-AB28-B241-B26-B2-B26-B-AB26-B3A2(26-4A)26-3AB26-BA-B26-B2-B26-B153-B24-B3-AB24-BA2-AB24-BA-3A24-3AB2(2A24-2A2B)2A24-2AB3A24-3A-2A24-2A2-2A24-2A3-A24-A95-A22-A5-2A22-2A3-2AB22-B2A2-3A22-3A-3A2(B22-B6A)B22-B7A22-7AB22-B3A-2AB22-B2A2-3A22-3A3-2A22-2A5-A22-A66-AB20-BA5-3A20-3A3-3AB20-B3A2-3AB20-B3A-B4A20-4A2B3AB20-B3AB4AB20-B4AB3AB20-B3A2B3AB20-B3AB-3AB20-B3A2-4A20-4A3-3A20-3A5-2A20-2A38-AB2AB10-B2ABA8-5AB4A4B4AB5A5-3AB18-B3A3-5A18-5A2-4AB18-B4A-5AB18-B11A18-12A18-11AB18-B11A18-6A-5A18-5A2-4AB18-B4A3-4A18-4A5-2A5BA2B4A2BA5B2A8-3B2A10-2A3B2(10-5A)8-24A5-4A18-4A3-5A18-5A2-5A18-5A-6A4(18-12A)18-6A-5A18-5A2-5A18-5A3-4A18-4A5-24A8-3(5A10-)5A8-24A5-4A18-4A3-5A18-5A2-5A18-5A-2(6A18-6AB5A18-5AB)6A18-6A-5A18-5A2-5A18-5A3-4A18-4A5-24A8-3(5A10-)5A8-24A5-5A2(BA)3B2A3B2(AB)5A3-5A18-5A2-5A18-5A-6A4(18-12A)18-6A-5A18-5A2-5A18-5A3-4A18-4A5-24A8-3(5A10-)5A8-24A5-26A3-5A18-5A2-5A18-5A-6A18-12A18-6AB5A18-5AB6A18-12A18-6A-5A18-5A2-5A18-5A3-4A18-4A5-24A8-3(5A10-)5A8-24A5-26A3-28A2-7A4C6A4C7A-7A6C4A6C13A3(8C2A8C12A)8C2A8C6A-6A6C4A6C6A2-7A4C6A4C7A3-26A5-24A8-5A10-5A5-
