model
size = 30 15 12, scale = 0.05, origin = -y
material 
  colors = A:#C9F B:#3C6 C:#300
voxels
6-3B2A10-2A3B9-AB2AB10-B2ABA8-AB2A3B4A2B4A3B2ABA5-2B4AB2ABA4BAB2AB4A2B3-2(AB)3ABA2B6A2BAB3A2(BA)2-2B5A3BA6BA3B5A2B-2B2ABA5BA6BA5BAB2A2B3A3BABA2BAB4ABA2BABA3B6A3(BA)3B6A3B3(AB)3A2BABA2(2B3AB3A)2BABA2(2B2A)2BAB2AB4AB2ABA2(2B2A)-A4BA16BA4BA2-2BABA4BA2B4A2BA4BABA2B3-3A7BA4BA7B3A5-2B2(AB)A2(2B2A)2B2(AB)A2B153-A4(28-2A)28-A241-A26-A2-A26-A-2A4(26-4A)26-2A-A26-A2-A26-A153-A24-A3-2A24-2A2-2A24-2A-3A4(24-6A)24-3A-2A24-2A2-2A24-2A3-A24-A95-A22-A5-2A22-2A3-3A22-3A2-3A22-3A-4A4(22-8A)22-4A-3A22-3A2-3A22-3A3-2A22-2A5-A22-A66-2A20-2A5-3A20-3A3-4A20-4A2-4A20-4A-5A4(20-10A)20-5A-4A20-4A2-4A20-4A3-3A20-3A5-2A20-2A38-5A10-5A8-24A5-4A18-4A3-5A18-5A2-5A18-5A-6A4(18-12A)18-6A-5A18-5A2-5A18-5A3-4A18-4A5-24A8-2(5A10-)ABA2B10-2BABA8-7A4B2A4B7A5-4A18-4A3-5A18-5A2-5A18-5A-6A4(18-12A)18-6A-5A18-5A2-5A18-5A3-4A18-4A5-7A4B2A4B7A8-ABA2B10-2BABA2(10-B3AB)8-9A6B9A5-4A18-4A3-5A18-5A2-5A18-5A-6A4(18-12A)18-6A-5A18-5A2-5A18-5A3-4A18-4A5-9A6B9A8-2(B3AB10-)2A2BA10-A2B2A8-9A6B9A5-26A3-5A18-5A2-5A18-5A-6A4(18-12A)18-6A-5A18-5A2-5A18-5A3-4A18-4A5-9A6B9A8-2A2BA10-A2B2A10-A2BAB10-BA2BA8-7A2(2B2A)2B7A5-26A3-5A18-5A2-5A18-5A-6A4(18-12A)18-6A-5A18-5A2-5A18-5A3-4A18-4A5-7A2(2B2A)2B7A8-A2BAB10-BA2BA10-4AB10-B4A8-10A4B10A5-26A3-28A2-7A4C6A4C7A-7A6C4A6C13A3(8C2A8C12A)8C2A8C6A-6A6C4A6C6A2-7A4C6A4C7A3-26A5-10A4B10A8-4AB10-B4A5-
