model
size = 30 15 12, scale = 0.05, origin = -y
material 
  colors = A:#0F6 B:#F99 C:#939
voxels
6-2(AB)A10-2(AB)A9-2A3B10-3B2A8-ABA4(2B2A)2BABA5-5BAB4A4B4ABA5B3-A5B2AB4A2B4AB2A5BA2-2(BA)2B5AB4AB5A2B2(AB)-B5AB2(2A5B)2AB5A3B2(3AB)ABA4B2(AB)3AB3A3BA4B2A3BAB4ABA3B2A4BA3B2A2B2(2AB)A4BA2(B2A)2B2A3B2(AB)3A4BAB2ABA4B3A2(BA)B-AB4A2(BA)B2A2B2A2(BA)B4ABA2-2B2A2(BA)2BA2B2A2(2BA)BAB2A2B3-3(BA)2B2(AB)2A2(BA)2B3(AB)5-3B2ABA4B2A4BAB2A3B153-A4(28-2A)28-A241-A26-A2-A26-A-2A4(26-4A)26-2A-A26-A2-A26-A153-A24-A3-2A24-2A2-2A24-2A-3A24-6A24-3AB2A24-2AB3A24-6A24-3A-2A24-2A2-2A24-2A3-A24-A95-A22-A5-2A22-2A3-3A22-3A2-3A22-3A-B3A22-3AB4A2(22-8A)22-4AB3A22-3AB-3A22-3A2-3A22-3A3-2A22-2A5-A22-A66-2A20-2A5-3A20-3A3-4A20-4A2-4A20-4A-5A4(20-10A)20-5A-4A20-4A2-4A20-4A3-3A20-3A5-2A20-2A38-5A10-5A8-24A5-4A18-4A3-5A18-5A2-5A18-5A-6A4(18-12A)18-6A-5A18-5A2-5A18-5A3-4A18-4A5-24A8-2(5A10-)A2BAB10-BA2BA8-8A3B2A3B8A5-4A18-4A3-5A18-5A2-5A18-5A-6A4(18-12A)18-6A-5A18-5A2-5A18-5A3-4A18-4A5-8A3B2A3B8A8-A2BAB10-BA2BA10-BAB2A10-2ABAB8-7AB8AB7A5-4A18-4A3-5A18-5A2-5A18-5A-2(6A18-6AB5A18-5AB)6A18-6A-5A18-5A2-5A18-5A3-4A18-4A5-7AB8AB7A8-BAB2A10-2ABAB2(10-5B)8-7A2(BA)2B2(AB)7A5-26A3-5A18-5A2-5A18-5A-6A4(18-12A)18-6A-5A18-5A2-5A18-5A3-4A18-4A5-7A2(BA)2B2(AB)7A8-2(5B10-)BAB2A10-2ABAB8-10A4B10A5-26A3-5A18-5A2-5A18-5A-B5A18-5AB6A2(18-12A)18-6AB5A18-5AB-5A18-5A2-5A18-5A3-4A18-4A5-10A4B10A8-BAB2A10-2ABAB10-2A3B10-3B2A8-7AB2A4B2AB7A5-26A3-28A2-7A4C6A4C7A-B6A6C4A6C6A2B5A8C2A8C5AB6A8C2A8C6AB5A8C2A8C5A2B5A8C2A8C5AB-6A6C4A6C6A2-7A4C6A4C7A3-26A5-7AB2A4B2AB7A8-2A3B10-3B2A5-
