model
size = 30 15 12, scale = 0.05, origin = -y
material 
  colors = A:#C30 B:#CC9 C:#C63
voxels
6-BA3B10-3BAB9-BA3B10-3BAB8-2(AB)2(A2B)4A2(2BA)2(BA)5-3A4BABA6BABA4B3A3-BA3B2A3B8A3B2A3BAB2-2(A2BAB)3A2B3A2(BA2BA)-2A3(BA)B3AB4AB3A3(BA)B3A5BA2BA4B2A4BA2BA5B2AB2A2(2BA)B8AB2(A2B)2ABA2B4A2(2B6A)2B4A6B4A2(BA)6B2(AB)4A4B-B3A3(BA)2B4A2B3(AB)3AB2-2A2(6B3A)6B2A3-ABA2B2(AB)8A2(BA)2BABA5-A2BAB3A8B3ABA2BA153-A28-2A28-AB28-BA28-2A28-A241-A26-A2-A26-A-2B26-3B2(A26-A2B)A26-A3B26-2B-A26-A2-A26-A153-A24-A3-AB24-BA2-2A24-2A-2AB24-2(B2A)2(24-2A2B2A)24-2(2AB)24-B2A-2A24-2A2-2A24-2A3-A24-A95-A22-A5-AB22-BA3-3A22-3A2-3A22-3A-B3A22-3AB4A2(22-8A)22-4AB3A22-3AB-2AB22-B2A2-3A22-3A3-2A22-2A5-A22-A66-AB20-BA5-3A20-3A3-4A20-4A2-4A20-4A-B4A20-4AB5A20-9AB20-B8AB20-2(B4A)20-4AB-3AB20-B3A2-3AB20-B3A3-3A20-3A5-2A20-2A38-B4A10-4AB8-2ABA2B4AB2AB4A2BAB2A5-4A18-4A3-4AB18-B4A2-5A18-5A-B4AB18-B4A2(2B5A18-5A)2B4AB18-B4A2B5A18-5AB-4AB18-B4A2-5A18-5A3-4A18-4A5-3A2(B2A)BA2BA2(B2A)B3A8-2B2AB10-B2A2B10-A4B10-4BA8-8AB6AB8A5-4A18-4A3-5A18-5A2-5A18-5A-B4(5A18-5A2B)5A18-5AB-5A18-5A2-5A18-5A3-4A18-4A5-8AB6AB8A8-A4B10-4BA10-2B3A10-3A2B8-7A2BAB2ABA2B7A5-4A18-4A3-5A18-5A2-5A18-5A-B4(5A18-5A2B)5A18-5AB-5A18-5A2-5A18-5A3-4A18-4A5-7A2BAB2ABA2B7A8-2B3A2(10-3A2B)10-2B3A8-7A2(2B2A)2B7A5-12A2B12A3-5A18-5A2-5A18-5A-B4(5A18-5A2B)5A18-5AB-5A18-5A2-5A18-5A3-4A18-4A5-7A2(2B2A)2B7A8-3A2B10-2B3A10-AB3A10-3ABA8-9AB4AB9A5-26A3-5A18-5A2-5A18-5A-B4(5A18-5A2B)5A18-5AB-5A18-5A2-5A18-5A3-4A18-4A5-9AB4AB9A8-AB3A10-3ABA10-B2ABA10-AB2AB8-7AB3A2B3AB7A5-26A3-28A2-7A4C6A4C7A-B6A6C4A6C6A4(2B5A8C2A8C5A)B-6A6C4A6C6A2-7A4C6A4C7A3-26A5-7AB3A2B3AB7A8-B2ABA10-AB2AB5-
