model
size = 30 15 12, scale = 0.05, origin = -y
material 
  colors = A:#063 B:#3FC C:#F30
voxels
6-B2ABA10-AB2AB9-4AB10-B4A8-2(AB)2ABA8BAB2A2(BA)5-5B2ABA3B2A3BAB2A5B3-2B3(AB)12A3(BA)2B2-2(B2A)B5A4B5A2(B2A)B-2B2AB2A4BABA2BABA4B2AB2(2A2B)3ABA4B4A4BAB3A2B2A3BAB3ABA2BAB2ABA2BAB3ABA3BAB5AB3(2A2B)2AB5A4(BA)2BAB3A4B3ABA2B3(AB)-2(2AB)2(AB)2A4B2A2(BA)2(B2A)2-3AB2AB3A2B4A2B3AB2AB3A3-B2ABA2B12A2BAB2AB5-3BAB4ABA2BAB4ABA3B153-A4(28-2A)28-A241-A26-A2-A26-A-BA26-AB2A2(26-4A)26-2ABA26-AB-A26-A2-A26-A153-A24-A3-2A24-2A2-2A24-2A-2(3A24-3AB2A24-2AB)3A24-3A-2A24-2A2-2A24-2A3-A24-A95-A22-A5-2A22-2A3-3A22-3A2-3A22-3A-4A22-8A22-4AB3A22-3AB4A22-8A22-4A-3A22-3A2-3A22-3A3-2A22-2A5-A22-A66-2A20-2A5-3A20-3A3-4A20-4A2-4A20-4A-5A4(20-10A)20-5A-4A20-4A2-4A20-4A3-3A20-3A5-2A20-2A38-5A10-5A8-24A5-4A18-4A3-5A18-5A2-5A18-5A-6A18-12A18-6AB5A18-5AB6A18-12A18-6A-5A18-5A2-5A18-5A3-4A18-4A5-24A8-2(5A10-)B4A10-4AB8-8AB6AB8A5-4A18-4A3-5A18-5A2-5A18-5A-6A4(18-12A)18-6A-5A18-5A2-5A18-5A3-4A18-4A5-8AB6AB8A8-B4A10-4AB10-A2BAB10-BA2BA8-7ABAB4ABAB7A5-4A18-4A3-5A18-5A2-5A18-5A-B5A18-5A2B5A18-5AB6A18-6AB5A18-5A2B5A18-5AB-5A18-5A2-5A18-5A3-4A18-4A5-7ABAB4ABAB7A8-A2BAB10-BA2BA10-2ABAB10-BAB2A8-7A3(B2A)B7A5-26A3-5A18-5A2-5A18-5A-2(6A18-6AB5A18-5AB)6A18-6A-5A18-5A2-5A18-5A3-4A18-4A5-7A3(B2A)B7A8-2ABAB10-BAB2A10-AB3A10-3ABA8-7A4B2A4B7A5-26A3-5A18-5A2-5A18-5A-6A18-12A18-6AB5A18-5AB6A18-12A18-6A-5A18-5A2-5A18-5A3-4A18-4A5-7A4B2A4B7A8-AB3A10-3ABA2(10-B3AB)8-7AB8AB7A5-26A3-28A2-7A4C6A4C7A-7A6C4A6C13A3(8C2A8C12A)8C2A8C6A-6A6C4A6C6A2-7A4C6A4C7A3-26A5-7AB8AB7A8-B3AB10-B3AB5-
