model
size = 30 15 12, scale = 0.05, origin = -y
material 
  colors = A:#690 B:#004 C:#33C
voxels
6-A4B10-4BA9-4BA10-A4B8-2A2B2A3B6A3B2A2B2A5-6A2BA8BA2B6A3-2BA2(2B2(2AB)2A)2BA2B2-3B4A2(BA)6B2(AB)4A3B-2B2(2AB)3(AB)2A3(BA)2(B2A)7BA3B2(AB)4A2(BA)3BA8B5AB12AB5A3B3AB3A4BABA2BABA4B3AB3A3B3ABAB3A6B3ABAB3A3B-A2BAB2A2B2(AB)2A2(BA)2B2ABA2BA2-ABA2B2AB2A2B4A2B2AB2A2BABA3-A2B3A2B2(AB)2A2(BA)2B3A2BA5-B3A5(B2A)B3AB153-A4(28-2A)28-A241-A26-A2-A26-A-2A4(26-4A)26-2A-A26-A2-A26-A153-A24-A3-2A24-2A2-2A24-2A-3A4(24-6A)24-3A-2A24-2A2-2A24-2A3-A24-A95-A22-A5-2A22-2A3-3A22-3A2-3A22-3A-4A4(22-8A)22-4A-3A22-3A2-3A22-3A3-2A22-2A5-A22-A66-2A20-2A5-3A20-3A3-4A20-4A2-4A20-4A-5A4(20-10A)20-5A-4A20-4A2-4A20-4A3-3A20-3A5-2A20-2A38-5A10-3(5A8-24A5-4A18-4A3-5A18-5A2-5A18-5A-6A4(18-12A)18-6A-5A18-5A2-5A18-5A3-4A18-4A5-24A8-3(5A10-))2(5A8-24A5-26A3-5A18-5A2-5A18-5A-6A4(18-12A)18-6A-5A18-5A2-5A18-5A3-4A18-4A5-24A8-3(5A10-))5A8-24A5-26A3-28A2-7A4C6A4C7A-7A6C4A6C13A3(8C2A8C12A)8C2A8C6A-6A6C4A6C6A2-7A4C6A4C7A3-26A5-24A8-5A10-5A5-
