model
size = 30 15 12, scale = 0.05, origin = -y
material 
  colors = A:#C33 B:#C0F C:#010
voxels
6-BC2AC10-C2ACB9-B3AC10-C3AB8-5ACBAC6ACABC5A5-AC3ABA2B2(2AB)2A2BAB3ACA3-2(AC)2B2A2B8A2B2A2B2(CA)2-C2(AB)ACB2A2C4B2C2ABC2(AB)AC-3ACBAB3ABA2C2B2CAB3ABABC5ABCB3ABC2(2A2B)2ACB3ABCB2A2BCA2C2(AB)2ABC2ACB2A2(BA)2CAC2BABCAB4AC2(BA)2B2(AB)C4A2(BAC)AC2AC3ABCABA2CABACB3AC2ACAC-ACAB2ACACB3C2A3CBCAC2ABACA2-AB5C4ABA2CAB4A5CBA3-A2B2(AC)3(2ACAC)A2BA5-3A2C2(AC)2A2B2A2(CA)2C3A153-C28-C2(B28-BA28-A)241-B26-B2-A26-A-AC26-C3A26-3AB26-B2AC26-C2AB26-BA-A26-A2-A26-A153-A24-A3-AB24-BA2-2A24-2A-2AC24-C2AB2A24-2(2AB)24-2(B2A)24-2AB2AC24-C2A-AB24-BA2-AC24-CA3-C24-C95-B22-B5-AB22-BA3-2AC22-C2A2-3A22-3A-3AB22-B6AC22-C3AB2AB22-B2AB4A22-7AC22-C3A-3A22-3A2-2AB22-B2A3-AB22-BA5-C22-C66-AB20-BA5-3A20-3A3-4A20-4A2-3AB20-B3A-5A2(20-10A)20-9AC20-C9A20-5A-4A20-4A2-3AB20-B3A3-3A20-3A5-AB20-BA38-2AB2A10-2AB2A8-2A2CA2(B2A)2B2(2AB)A2C2A5-4A18-4A3-5A18-5A2-5A18-5A-C4AC18-C4AC6A18-6AC4AC18-C4AC5AC18-C5AC4AC18-C4AC-4AB18-B4A2-4AB18-B4A3-4A18-4A5-6AC3AC2AC3AC6A8-3ACB10-BC3A10-4AB10-B4A8-9AC4AC9A5-4A18-4A3-5A18-5A2-5A18-5A-6A18-12A18-6AC5A18-5AC6A18-12A18-6A-5A18-5A2-5A18-5A3-4A18-4A5-9AC4AC9A8-4AB10-B4A10-ACA2C10-2CACA8-7A2BC4BC2B7A5-4A18-4A3-5A18-5A2-5A18-5A-6A18-6AC2(5A18-5A2C)5A18-5AC6A18-6A-5A18-5A2-5A18-5A3-4A18-4A5-7A2BC4BC2B7A8-ACA2C10-2CACA10-A2BCA10-AC2BA8-9ABA2BAB9A5-5ABA3CBA2CAB3CAB5A3-5A18-5A2-5A18-5A-2(6A18-6AC5A18-5AC)6A18-6A-5A18-5A2-5A18-5A3-4A18-4A5-9ABA2BAB9A8-A2BCA10-AC2BA10-BA2CA10-A2CAB8-7ABC2B2A2BCB7A5-26A3-5A18-5A2-5A18-5A-6A4(18-12A)18-6A-5A18-5A2-5A18-5A3-4A18-4A5-7ABC2B2A2BCB7A8-BA2CA10-A2CAB10-BC3A10-3ACB8-8AB2A2C2AB8A5-26A3-28A2-7A4B6A4B7A-7A6B4A6B13A8B2A8B6AC5A8B2A8B5AC6A8B2A8B12A8B2A8B6A-6A6B4A6B6A2-7A4B6A4B7A3-26A5-8AB2A2C2AB8A8-BC3A10-3ACB5-
