model
size = 30 15 12, scale = 0.05, origin = -y
material 
  colors = A:#9F6 B:#C6F C:#C3C
voxels
6-AB2CB10-B2CBA9-AC3A10-3ACA8-A2CAB2A2CB4CB2C2ABA2CA5-BAC4AB3A4B3AB4ACAB3-ACAB2ACBC2A6B2ACBC2ABACA2-BACBAB3A3BA2CA3B3ABABCAB-2C3ABCA2B2(AB)2A2(BA)2BACB3A3C2BA2CB2ABCB2A2C2ABCB2AB2CA2BC2ACAC2A3B4C2A4C3B2ACAC2A2C5AB2CABAC2BCABA2CB5A2CBACA3BAC3ABA2CAB3ACA3BACAB-2A2BCAB5AB2AB5ABAC2B2A2-A2CABACAB4A2B4ABACABA2CA3-AC2B5A2BA2CA2B5A2BCA5-A2B2C2A4B2C4B2A2C2BA153-A2(28-2A)28-AB28-BA28-A241-A26-A2-A26-A-2C26-2C2(2A26-2ACA26-AC)-A26-A2-B26-B153-A24-A3-2A24-2A2-2A24-2A-CAB24-BAC3A24-3AB2A24-2AB3A24-3AC2A24-2AC-2A24-2A2-AB24-BA3-A24-A95-B22-B5-2A22-2A3-3A22-3A2-3A22-3A-4A22-4AB2AB22-B2ABC3A22-3ACB3A22-3AB4A22-4A-2AB22-B2A2-2AC22-C2A3-2A22-2A5-A22-A66-2A20-2A5-3A20-3A3-4A20-4A2-4A20-4A-B4A20-4A2B3AB20-B3ABC4A20-4ACB4A20-4A2B4A20-4AB-4A20-4A2-4A20-4A3-3A20-3A5-2A20-2A38-3ABA10-AB3A8-7AC8AC7A5-3AC18-C3A3-5A18-5A2-4AB18-B4A-C5A18-5ACB5A18-5AB6A18-6AB5A18-5ABC4AB18-B4AC-4AB18-B4A2-4AC18-C4A3-3AC18-C3A5-4AC2AC8AC2AC4A8-BA2BA10-A2BAB2(10-5A)8-24A5-4A18-4A3-5A18-5A2-5A18-5A-2(B5A18-5ABC5A18-5AC)B5A18-5AB-5A18-5A2-5A18-5A3-4A18-4A5-24A8-3(5A10-)5A8-24A5-4A18-4A3-5A18-5A2-5A18-5A-C5A18-5AC6A18-6AB5A18-5AB6A18-6AC5A18-5AC-5A18-5A2-5A18-5A3-4A18-4A5-24A8-3(5A10-)5A8-24A5-4A2C3AC2A2B2AC3A2C4A3-5A18-5A2-5A18-5A-C5A18-5A2C5A18-5AC6A18-6AC5A18-5A2C5A18-5AC-5A18-5A2-5A18-5A3-4A18-4A5-24A8-3(5A10-)5A8-24A5-26A3-5A18-5A2-5A18-5A-2(B5A18-5ABC5A18-5AC)B5A18-5AB-5A18-5A2-5A18-5A3-4A18-4A5-24A8-3(5A10-)5A8-24A5-26A3-28A2-7A4B6A4B7A-B6A6B4A6B6AB6A2(8B2A8B12A)8B2A8B6AB5A8B2A8B5AB-6A6B4A6B6A2-7A4B6A4B7A3-26A5-24A8-5A10-5A5-
