model
size = 30 15 12, scale = 0.05, origin = -y
material 
  colors = A:#363 B:#093 C:#C0F
voxels
6-AB2AC10-C2ABA9-CAB2A10-2ABAC8-AC3ACAB3A2C3ABAC3ACA5-2AB3CACABAC2ACABACA3CB2A3-B4CABCB2AC4AC2ABCBA4CB2-C2A3B2(AB)3A2B3A2(BA)3B2AC-BC2(BA)BC2A2(2C2B)2C2AC2(BA)BC3BACB3AC3AB4AB3AC3ABCA2B2(C2A)2BAB3(A2C)ABA2B2(2AC)4AC2ABCAC8ACACB2AC4ACACB3ACAB2(AC)2B2(CA)BAC3ABCAC-CA2BAB3CAC6ACA3CBA2BAC2-AC2(A2C)B2C6A2CB2(2CA)CA3-CAB2A2B4AB2AB4A2B2ABAC5-AC2BA2C2AB4AB2A2CA2BCA153-A4(28-2A)28-A241-A26-A2-A26-A-2(2A26-2ABA26-AB)2A26-2A-A26-A2-A26-A153-A24-A3-2A24-2A2-2A24-2A-3A24-6A24-3AC2A24-2AC3A24-6A24-3A-2A24-2A2-2A24-2A3-A24-A95-A22-A5-2A22-2A3-3A22-3A2-3A22-3A-C4(3A22-3A2C)3A22-3AC-3A22-3A2-3A22-3A3-2A22-2A5-A22-A66-2A20-2A5-3A20-3A3-4A20-4A2-4A20-4A-5A20-10A20-5AC4A20-4AC5A20-10A20-5A-4A20-4A2-4A20-4A3-3A20-3A5-2A20-2A38-5A10-5A8-24A5-4A18-4A3-5A18-5A2-5A18-5A-C5A18-5AC6A2(18-12A)18-6AC5A18-5AC-5A18-5A2-5A18-5A3-4A18-4A5-24A8-3(5A10-)5A8-24A5-4A18-4A3-5A18-5A2-5A18-5A-C5A18-5ACB2(5A18-5A2B)5A18-5ABC5A18-5AC-5A18-5A2-5A18-5A3-4A18-4A5-24A8-3(5A10-)5A8-24A5-4A18-4A3-5A18-5A2-5A18-5A-6A18-6AB5A18-5ABC5A18-5ACB5A18-5AB6A18-6A-5A18-5A2-5A18-5A3-4A18-4A5-24A8-3(5A10-)5A8-24A5-26A3-5A18-5A2-5A18-5A-C5A18-5A2C5A18-5AC6A18-6AC5A18-5A2C5A18-5AC-5A18-5A2-5A18-5A3-4A18-4A5-24A8-3(5A10-)5A8-24A5-26A3-5A18-5A2-5A18-5A-6A18-12A18-6AC5A18-5AC6A18-12A18-6A-5A18-5A2-5A18-5A3-4A18-4A5-24A8-3(5A10-)5A8-24A5-26A3-28A2-7A4B6A4B7A-7A6B4A6B7A2(B5A8B2A8B5AB6A8B2A8B6A)-6A6B4A6B6A2-7A4B6A4B7A3-26A5-24A8-5A10-5A5-
