model
size = 29 31 6, scale = 0.05, origin = -y
material 
  colors = A:#111 B:#EEE
voxels
58-A-BA25-2AB4A22-2AB3A2B21-A-B2A2B2A25-B4A25-3AB26-2B26-3BA3(25-4A26-2B26-4A)25-4A26-3B26-4A25-3AB26-3B26-2BAB25-3ABA25-2AB2A2B23-AB2A2B2AB-2A-2B15-B2(2A2B)3A2BA17-2B2A2B3A2BA20-AB-2A-2B33-A-BA25-2AB3AB22-2AB3A2B21-A-B2A2B2A25-B4A25-4B4(26-2B26-4A25-4A)26-3B26-4A25-4A26-3B26-4B25-3ABA25-2AB2A2B23-AB2A2B2AB-2A-2B15-B2(2A2B)3A2BA17-2B2A2B3A2BA20-AB-2A-2B33-A-BA25-2AB4A22-2AB4AB21-2AB5AB20-2AB7A19-A-BAB6A23-B4AB4(24-B2AB24-6A23-6A)24-B3AB24-6A23-6A2(24-B3AB)A23-4AB2A2B21-3AB2A2B2AB-2A-2B13-2AB2(2A2B)3A2B3A11-AB2A2B2AB4A2B3A12-B2A2B2AB4A2B2A16-2B2A2B3A3B20-AB-2A-2B4-2AB2A24-2AB4AB21-2AB5AB20-2AB7A19-2AB8A18-2AB8A22-B5AB4(23-B4AB2(23-6A))23-B5AB2(23-6A)23-B4A2B23-B3AB2A22-4AB2A2BA19-4AB2(2A2B)3A2B3A9-3AB2(2A2B)3A2B4A9-2AB2(2A2B)3A2B4A10-AB2(2A2B)3A2B3A14-A2B2A2B3A2B2A18-2A2B3A3B3-2AB2A24-2AB4AB21-2AB5AB20-2AB7A19-2AB8A18-2AB8A22-B5AB3(23-6B2(23-6A))23-B4AB2(23-6A)23-B5AB23-6A23-5AB23-B4A2B23-B3AB2A22-4AB2A2BA19-4AB2(2A2B)3A3B2A9-3AB2(2A2B)3A4B2A9-2AB2(2A2B)3A4B2A10-AB2(2A2B)3A4BA14-A2B2A2B3A3BA18-2A2B3A3B3-A-BA25-2AB4A22-2AB4AB21-2AB6A20-2AB7A19-A-BAB6A23-5AB24-4B24-5BA2(23-6A24-4B24-6A)23-A4BA24-B2AB24-6A23-6A24-B3AB24-6A23-5A2(B24-B3A)BA23-4AB2A2B21-3AB2A2B2AB-2A-2B13-2AB2(2A2B)3A3B2A11-AB2(2A2B)3A3B2A12-B2(2A2B)3A3BA16-2B2A2B3A3B20-AB-2A-2B4-
