model
size = 26 31 27, scale = 0.05, origin = -y
material 
  colors = A:#06C B:#EEE
voxels
141-14(4B22-)4B11-11A5(4B22A)4B11A141-5(4B22-)4B13-9A13(4B10A2-10A)4B10A-11A5(4B22A)4B11A132-6(22A4-)23A3(2-2A21-12(A2-A22-)A-141A4B11A132-22A5(4-A20-A)4-A20-2A)3(2-2A21-12(A2-A22-)A-2A23-4(2A24-)12A4B11A132-22A5(4-A20-A)4-A20-2A)2-2A21-12(A2-A22-)A-2A23-4(2A24-)12A4B11A4-2B23-3B24-2B74-22A5(4-A20-A)4-A20-2A2-2A21-12(A2-A22-)A-2A23-4(2A24-)12A4B11A4-4B8-3B10-6B7-4B9-7B6-4B10-4B46-22A5(4-A20-A)4-A20-2A2-2A21-12(A2-A22-)A-2A23-4(2A24-)12A4B11A3-2(9B3-6B8-)9B3-6B9-5B44-B22A5(B2-BA20-A)4BA20-A4BA21-12(4B22-)4B23-4(2B24-)27B2-2(11B-8B6-)10B3-7B7-6B9-3B32-B22A5(B2-BA20-A)4BA20-A4BA21-12(4B22-)4B23-4(2B24-)27B2-2(21B5-)9B4-9B5-6B8-6B30-B22A5(B2-BA20-A)4BA20-A4BA21-12(4B22-)4B23-4(2B24-)27B2-21B6-20B5-9B4-8B6-5B8-7B30-B22A5(B2-BA20-A)4BA20-A4BA21-12(4B22-)4B23-4(2B24-)27B2-2(21B5-)9B3-9B6-5B8-7B31-22A5(4-A20-A)4-A20-2A2-2A21-12(A2-A22-)A-2A23-4(2A24-)12A4B11A3-20B6-6B2-12B6-6B5-9B7-3B9-6B32-22A5(4-A20-A)4-A20-2A2-2A21-12(A2-A22-)A-2A23-4(2A24-)12A4B11A6-5B2-10B9-5B2-B-8B18-8B20-5B32-22A5(4-A20-A)4-A20-2A2-2A21-12(A2-A22-)A-2A23-4(2A24-)12A4B11A5-6B3-8B9-6B3-8B21-5B22-4B32-22A5(4-A20-A)4-A20-2A2-2A21-12(A2-A22-)A-2A23-4(2A24-)12A4B11A5-6B3-4B-3B9-6B3-4B-3B8-4B11-3B23-2B33-22A5(4-A20-A)4-A20-2A2-2A21-12(A2-A22-)A-2A23-4(2A24-)12A4B11A6-4B4-5B13-4B4-5B11-5B9-B10-2B49-22A5(4-A20-A)4-A20-2A2-2A21-12(A2-A22-)A-2A23-4(2A24-)12A4B11A9-B4-5B15-2B4-5B11-6B6-3B9-5B21-2B24-22A5(4-A20-A)4-A20-2A2-2A21-12(A2-A22-)A-2A23-4(2A24-)12A4B11A14-4B22-5B13-3B5-6B9-5B11-B8-4B22-22A5(4-A20-A)4-A20-2A2-2A21-12(A2-A22-)A-2A23-4(2A24-)12A4B11A66-6B11-2(3B9-)4B21-6(22A4-)23A2-24A12(2-A22-A)-2A23-4(2A24-)12A4B11A67-4B22-6B10-2B13-B16-6(4B22-)4B12-12(10A4B10A2-)10A4B10A-11A4B12A3(24-2A)24-12A4B11A93-6B22-4B172-13(4B22-)4B11-11A5(4B22A)4B11A94-3B23-5B802-B8-
