model
size = 29 28 27, scale = 0.05, origin = -y
material 
  colors = A:#900 B:#C30 C:#050 D:#080 E:#CF3 F:#0B0 G:#EEE H:#630 I:#CC6 J:#CC9 K:#CF0 L:#C60 M:#F96 N:#F9F O:#F33 P:#F99 Q:#F36 R:#FCF S:#F6F T:#F0C U:#FC6 V:#FC3 W:#FF6 X:#F0F Y:#FFF Z:#CFC Aa:#F9C Ab:#F06 Ac:#CC3 Ad:#F03 Ae:#F3F Af:#F90 Ag:#CFF Ah:#CCF Ai:#F60 Aj:#F69 Ak:#F66 Al:#F6C Am:#F09 An:#CCC Ao:#F3C Ap:#FF9 Aq:#CC0 Ar:#CF6
voxels
16-An29-T27-K27-Ae840-A24-2AK3A23-2AL3A23-6A24-AL3A663-V24-10A19-11A18-3A5-3A18-3A-AI2-3A18-10A20-8A603-X27-M24-14A14-3A4-2A5-2(2A13-)A13-2A2-8A3-A13-2A2(E3-3A)14-4A2-2A2-4A542-U29-O25-Ag35-G17-17A11-3A2-8A3-2A11-2A3-8A3-2A11-IA-12A-2A11-3A-10A2-2A12-3A-8A-AEA19-2B2G516-Y29-Ah11-Ae68-6A6-7A10-AK2-2A6-3A2-2A10-A3-3A5-3A-3A10-A-14A-2A10-AL-12A-IAJ10-AKA-10A-3A16-2CD5G22-2C4B24-2C2B453-R72-Q29-N12-4A10-5A9-3A-A10-2A2-2A8-A3-2A8-3A2-2A8-A-AI14A-2A8-2A-4AC9A-3A9-6AC10ALA13-2BF2CB3G3B18-B3C6B20-3CD4B22-H5B24-4B425-Af83-5A13-4A7-2A-2A13-A2-A7-A2-2A13-A10-A-18A9-AE-2AE12AJ2-A7-2A-19A11-3BD2C2BG5B16-2B2CD7B18-5C5B19-10B20-8B22-4BCD24-4B389-X5-S21-Aa7-P19-Ap5-4A14-5A6-A-2A14-2A2-A6-A-2A14-2A2-2A5-17AE3A-A6-A-18A-A7-2A-14AEA-AE10-16B14-14B16-BF3CD6B17-8B2CDB18-7B3C20-5BD2C22-6B23-D2C3B25-2B301-Ab92-3A16-4A6-A-E16-A2-A8-2A14-2A2-A7-AE18A2(-A)4-21A-A6-20A-A10-16B13-11BC4B14-10B2C2D15-9BF2C2B16-8B3CB18-B2CD2B4C19-B3C4BHB20-4C4B22-6B24-4B26-2B273-U62-3A16-4A2(8-A16-2A-A)6-23A6-21A-A6-23A8-14B2CDB12-13B3C13-12BD3C14-4BC4BD2C2B15-4BC4B2CD2B16-2BF2C2B5C18-B3C6B19-4CD5B20-BH6B22-6B23-3B2CD24-2B2C26-DC243-O27-Ad6-KA18-3A4-2A20-A-2A3-A21-A2-A3-A-L21A-A3-2A-16AC3A-A6-17AC3A-A8-14BF2CB11-14B3CB12-12B4C13-14BHB14-14B15-3BD2C2BF3CDB16-2B2CD7B17-B5C6B18-6BC3B20-5BC2B21-4BF2CB22-3B3C24-B3C25-3BH26-2B192-S27-2A18-3A4-2A20-4A3-A21-A2-A3-A-22A-A3-26A5-21A-A7-15BD2C2B10-14B2CDB11-13B5C12-16B13-16B14-14B15-14B16-BF3CD6B18-10B19-10B20-4BD2CB21-4B2CDB22-2B4C23-6B24-2CDB26-2C133-T57-2A19-3A3-EA20-4A3-A21-A2-A3-E3AE21A3-26A5-23A7-20B10-18B11-13BF3CD12-16B13-16B14-14B15-14B16-12B17-12B18-C2D2C5B19-10B20-8B21-3B4CD22-2BC3B23-BF2C2B24-3CB26-2C27-HB17-V29-W30-N19-Am3-Ao30-2A19-3A3-2A20-4A3-A21-A2-A2(3-26A)5-23A7-20B10-18B11-18B12-2D2C12B13-16B14-14B15-14B16-2B2CD7B17-2B3C7B18-D4C5B19-5BC2D2C20-8B21-8B22-6B23-BD2C2B24-2CDB26-2C27-2B69-Al31-S-N2-Q18-U7-2A18-3A4-2A20-A-2A3-A21-A2-A3-A-22A-A3-25A6-21A-A7-20B10-B2CD14B11-B3C14B12-4C12B13-11BC2D2C14-4BC9B15-4BC9B16-2BF2C7B18-B3C2B2CDB19-4CDB3CB20-BH2BD3C21-8B22-6B23-6B24-4B26-2B98-Ak35-M27-W28-2A18-3A4-2A2-A17-A-2A3-2A2-A16-2A-2A3-26A6-20A-A6-4AC18A8-2BC15B11-BF2C14B12-3C9B2CDB13-3CD8B3CB14-H9BD3C15-14B16-8BC3B17-2BD2C3BC3B18-B2CD2BF2CB20-4CB3C21-4B4C22-5BH24-4B25-4B26-2B220-3A16-4A2(8-A16-2A-A)6-23A6-21A-A6-23A8-14BC3B12-D2C10BC2B13-2CD9BF2CB14-3C8B3C15-10B4C16-11BH18-10B19-10B20-5BD2C22-2CDB2C23-3B3C24-4B26-2B278-3A16-4A6-A-A16-A2-A8-2A14-2A2-A7-20A-A6-21A-A6-20A-A10-16B13-16B14-11BD2C15-2CD8B2CD16-9B3C18-10B19-10B20-8B22-6B24-4B26-BF219-Ab22-N35-P22-M34-5A13-4A7-2A-2A13-A2-A7-A2-2A13-A10-21A8-AE3AE14A-A7-2A-19A10-16B14-14B16-12B17-12B18-8BFC20-8B22-6B23-6B25-2B306-Ac22-Ai12-Aa23-Q20-R7-5A11-5A7-2A2-2A11-A2-2A7-2A2-2A11-A3-A7-2AIAJ15A-A8-A-12AE3A-2A8-21A11-14B16-12B18-2BC2D2C3B19-10B20-8B22-6B24-4B354-P58-N8-Ac-M2-Ad25-4A10-5A9-2A2-A10-2A2-2A8-A3-2A8-3A2-2A8-A-16A-2A8-2A-14A-3A9-AK12AIAJ2A13-4B2CD5B18-3B3C4B20-BD4C2B22-6B24-4B397-M43-Y13-ZP26-T15-Aq11-6A6-7A10-2A2-2A6-3A2-2A10-A3-3A5-3A2-2A10-J-I2AE3AE5AK-2A10-2A-5AC6A-3A10-3A-AE2ACE4A-3A16-2BF2C3B22-B3C2B24-3CD484-Aj11-O47-R10-Ar15-14A14-3A4-2A5-2(2A13-)A13-14A-A13-2AE2AIAJ8A14-12AJA20-D2CB526-Z57-O45-13A15-3A8-3A15-2A10-2A15-2A-2AL5A-2A16-3A-4A-AE2A16-4AL7A656-10A19-11A18-3A5-3A18-3A-2A2-3A18-2AJAI5A20-8A689-2(6A23-)3AE2A24-5A563-
