model
size = 29 28 27, scale = 0.05, origin = -y
material 
  colors = A:#6C9 B:#010 C:#070 D:#EEE E:#0E0 F:#F96 G:#F9F H:#F99 I:#F33 J:#F36 K:#FCF L:#F6F M:#F0C N:#FC6 O:#FC3 P:#FF6 Q:#F0F R:#FFF S:#CFC T:#F9C U:#F06 V:#CC3 W:#F3F X:#F03 Y:#F90 Z:#CFF Aa:#CCF Ab:#F60 Ac:#F69 Ad:#F66 Ae:#F6C Af:#F09 Ag:#CF0 Ah:#CCC Ai:#F3C Aj:#FF9 Ak:#CC0 Al:#CF6
voxels
16-Ah29-M27-Ag27-W840-A24-2(6A23-)6A24-5A663-O24-10A19-11A18-3A5-3A18-3A-2A2-3A18-10A20-8A603-Q27-F24-14A14-3A4-2A5-2(2A13-)A13-2A2-8A3-A13-3A3-4A3-3A14-4A2-2A2-4A542-N29-I25-Z35-H17-17A11-3A2-8A3-2A11-2A3-8A3-2A11-2A-12A-2A11-3A-10A2-2A12-3A-8A-3A19-4C516-R29-Aa11-W68-6A6-7A10-2A2-2A6-3A2-2A10-A3-3A5-3A-3A10-A-14A-2A10-2A-3A3B6A-3A10-3A-2ABEB5A-3A16-CBE3B2C22-2(BE)BC24-2BEB453-K72-J29-G12-6A8-5A9-3A-3A8-2A2-2A8-A3-2B8-3A2-2A8-A-ABEB12A-2A8-2A-BEBA3B7A-3A9-2ABE3BEB10A13-2BEBE6BC18-BE3BE2BEB20-E3BE2BE22-3BE2B24-4B425-Y83-5A13-4A7-2A-2A13-A2-A7-A2-AB2A11-A10-A-2ABEB13A9-2A-ABEB12A2-A7-2A-ABE3B6A3B4A11-3BEB3C4BEB16-CBE2B2C2BEBE18-BE2B2C2BEB19-4B2C2BEB20-E7B22-3BEBE24-CBEB389-Q5-L21-T7-H19-Aj5-4A14-5A6-A-2A14-2A2-A6-A-2A14-2A2-2A5-21A-A6-A-18A-A7-2A-12A3BA-2A10-12CBEBC14-C4B6CBEB16-BE2B6CBE17-BE4BC5B18-E2BE3BE2B20-2B3(EB)22-3(BE)23-2DBE2B25-2B301-U92-3A16-4A6-A-A16-A2-A8-2A13-3A2-A7-16A3B2(A-)A4-17ABEBA-A6-2A3B12ABEB-A10-EB10C3BE13-E4B7CBE2B14-2BEB7CBEB15-2BE4BC4BEB16-BE2BEBCBE3B18-3B2DCBEBC19-2EB3DBEBC20-2B4D2B22-5BE24-3EB26-2B273-N62-3A16-4A8-A16-2A-A8-A14-4A-A6-17A3B3A6-17ABEBA-A6-2A3B12ABEB3A8-BE2B11CBEB12-E2B11C2B13-E2B10C3B14-2B10CBE15-4DB4C4BE16-4B4DBE2B18-2E2B3D3B19-3BEB3D2B20-6BDB22-B3EBD23-6B24-DBEB26-2B243-I27-X6-2A18-3A4-2A20-A-2A3-A2-3A16-A2-A3-A-A3B18A-A3-2A-BEB17A-A6-ABEB17A-A8-E3B14C11-2BEB14C12-BEB10C3B13-BEB10CBEB14-8DC4BE15-2CBEBC3DBE2BE16-CBE2B2C2D3B17-CBE2B2C2DBEB18-5BCBDBE20-4BC2DB21-2E2B3DB22-2BD2BE24-BE2B25-BE2B26-EB192-L27-2A18-3A4-2A20-4A3-A2-3A16-A2-A3-A-A3B18A-A3-3ABEB20A5-ABEB17A-A7-BEB17C10-2B16C11-15C3B12-3B11CBE13-2EB6D5CBE14-2B5C2D4CB15-EB6C2D4B16-4B4CDBEB18-BEB3CBDBE19-4B2CBDBE20-5B2DB21-2EB2DBEB22-2BE3B23-CBE2BC24-BE2B26-2B133-M57-2A19-3A3-2A20-4A3-A21-A2-A2(3-26A)5-23A7-16C3BC10-15CBEB11-C3B11CBEB12-3B11CBE13-2EB6D5C2B14-2B5C2D4CB15-EB6C2DC3B16-4B4CDCBE17-2BEB4CDCBE18-BEB3C2DCB19-4BC3D2B20-2EB3DBE21-3B3CBE22-5CB23-C3BCB24-BEBC26-EB27-EB17-O29-P30-G19-Af3-Ai30-2A19-3A3-2A20-4A3-A21-A2-A3-26A3-3A3B20A5-ABEB19A7-BEB13C3BC10-EB13CBEB11-4B11CBEB12-BEB11CBE13-6D8C2B14-3B6D5C15-2EB4C3DC3B16-2B5C2DCBE17-7C2DCBE18-C3B2C2DCB19-CBEB3D3B20-5DCBE21-BEBC3BE22-2BCBEB23-C3BEB24-2(BE)26-EB27-EB69-Ae31-L-G2-J18-N7-2A18-3A4-2A20-A-2A3-A21-A2-A3-A-22A-A3-3A3B19A6-ABEB17A-A7-BEB17C10-EB12C3BC11-2B5C7DBEBC12-3B3C7DBEB13-BEB10CBEB14-3B5D2C4B15-2EB6DCBEBC16-2B4C2DCBEB18-5C2DCBE19-C3B3DC2B20-6D2C21-4D4C22-E5B23-6B24-3EB26-2B98-Ad35-F27-P28-2A18-3A4-2A2-A17-A-2A3-2A2-A16-2A-2A3-26A6-20A-A6-2A3B18A8-BEB3C9D3C11-BEB2C11DBC12-EBC13D13-3B9D4B14-EB9DB2E15-EBC8D3B16-3DB5CBEB17-6D3CBEB18-5BD3BE20-8B21-B3EBE2B22-4BEB24-3BE25-4B26-2E220-3A16-4A2(8-A16-2A-A)6-23A6-17A3BA-A6-2A3B3A6D3ABEB3A8-BEBC13DB12-EBC3D7C3D13-EB3D9C2D14-4B7C3B15-3EB7CB2E16-3B4D5B18-3B3DB3E19-BEBC6B20-4BE2BE22-6B23-3EBEB24-3BE26-2B278-3A16-4A6-A-A16-A2-A8-2A14-2A2-A7-20A-A6-17A3BA-A6-3A3BA11DEB-A10-BEB3D6CB3D13-BE2D8CBEBD14-E2DB7CBEB15-4B7CBEB16-2EB7C2B18-2B4C4B19-B5DB3E20-3C5B22-3BE2B24-2(EB)26-BE219-U22-G35-H22-F34-5A13-4A7-2A-2A13-A2-A7-A2-2A13-A10-21A8-20A-A7-2A-3BA11D4A10-BEB2D7C2B2D14-E2D8CBEB16-D2B7CBE17-9BCBE18-B3E2BEBCB20-8B22-B3EBD23-5BD25-BC306-V22-Ab12-T23-J20-K7-5A11-5A7-2A2-2A11-A2-2A7-2A2-2A9-3A3-A7-15A3B2A-A8-A-12ABEBA-2A8-4A2B11D4A11-CB2D4C6B16-5B2C2B3E18-3EB2C4B19-9BC20-3E2BE2B22-6B24-3EB354-H58-G8-V-F2-X25-4A10-5A9-2A2-A10-2A2-2A8-A3-2A8-3A2-2A8-A-12A3BA-2A8-2A-11ABEB-3A9-3A3B7DBEB3A13-BD10B18-2B2(3EB)20-8B22-5BE24-EBCB397-F43-R13-SH26-M15-Ak11-6A6-7A10-2A2-2A6-3A2-2A10-A3-3A5-3A2-2A10-A-14A-2A10-2A-5A3B4A-3A10-3A-4ABEB3A-3A16-8B22-3EB2E24-4B484-Ac11-I47-K10-Al15-14A14-3A4-2A5-2(2A13-)A13-14A-A13-7A3B6A14-6ABEB5A20-CBEB526-S57-I45-13A15-3A8-3A15-2A10-2A15-2A-8A-2A16-3A2(-4A)16-12A656-10A19-11A18-3A5-3A18-3A-2A2-3A18-10A20-8A689-2(6A23-)6A24-5A563-
