model
size = 29 21 24, scale = 0.05, origin = -y
material 
  colors = A:#C90 B:#C96 C:#630 D:#E00 E:#800 F:#C99 G:#CC0 H:#EEE I:#F90 J:#B00
voxels
154-5A576-AGA546-7A22-7C20-11A540-12A17-12C16-4A5-5A536-15A14-15C13-AG2A9-4A534-17A12-17C2(12-3A)131-10A19-C9A19-GC8A333-19A10-6C7B6C10-2A4-7B4-2A16-3BE2FBE21-5BFBE21-3B2(FB)E21-3BE4B18-6AEA3E3A15-13AG15-G12AC18-8B21-7D277-19A10-5C10B4C9-3A3-10B3-2A13-3B5-BEB3(18-3B6-2B)17-6AEAE5A15-14A15-13AG16-4B3-4B19-10D274-21A8-5C12B4C8-2A3-BEB6-3B2-2A12-FBE8-2B16-FB9-2B16-2B9-2B16-FE9-2B15-C6A5E3AC13-16A13-G14AG14-3B7-3B17-3D5B4D20-5B248-21A8-4C14B3C7-2A3-FB9-3B2-2A11-2B10-2(2B15-B11-)2B15-E11-2B14-15AG13-16A13-C15A14-2B9-3B15-3D8B3D18-8B246-22A7-3C15B4C6-2A2-B2E10-2B2-AG10-2B12-B14-BE12-B14-2B12-B14-2E12-B13-8A3EAE5A2(11-18A)12-2B11-2B15-2D4B-5B2D17-10B245-22A7-3C16B3C6-2A2-2B12-2B-2A10-3(B13-2B13-)B13-2B12-2(18A11-)18A2(12-2B)13-2D3B5-3B2D16-11B244-23A6-4C16B3C6-2A2-2E12-2B-2A10-B14-B13-F14-B13-B14-B13-E14-B12-2(8A-9A11-)8A-9A12-B13-2B13-2D3B2-3B-2B3D15-11B244-23A6-4C16B3C6-2A2-2B12-2B-2A10-3(B14-B13-)B14-B12-2(18A11-)18A12-B13-2B13-2D2B2-4B-2B3D15-11B24-3(H28-)H57-I75-22A7-3C16B3C6-GA2-2B12-2B-2A10-3(B14-B13-)B14-B12-2(18A11-)18A12-B13-2B13-2D3B-3B2-2B3D15-11B22-2(H28-)H57-J75-A30-22A7-3C16B3C6-2A2-2B12-BE-2A10-B13-BE2(13-B)F13-B13-2B13-B13-EF12-2(18A11-)C17A2(12-2B)13-2D3B6-2B3D15-6BF4B245-21A8-3C15B3C7-2A2-2B11-EB2-2A10-3(2B12-B14-)2B12-B13-2(18A11-)C17A12-2B11-3B13-3D3B3-4B2D17-6BF3B245-21A8-4C14B3C8-2A2-2B9-B2E-2AG11-B11-2B15-B11-2E15-B11-2B14-2B11-2E14-3(17A12-)3B10-2B15-2D9B3D17-9B247-19A10-3C13B3C9-3A-3B7-E2B2-2A12-3(2B10-B16-)2B10-B15-2(16A13-)16A14-3B8-3B15-3D7B3D19-2BFBF2B248-19A10-4C12B3C10-2A2-4B4-B3E-C2A13-2B7-2BF17-2B7-E2F17-2B7-E2B17-2B7-3E16-C13A2(15-14A)16-3B5-4B17-11D276-17A12-4C9B4C11-G2A2-9B2-3A15-4B2-3B20-F2B2(3-3B20-3B)3-4B18-12A17-2AC9A17-12A18-10B19-9D278-15A14-6C4B5C13-4A3-4B2-4A18-3(5B24-)6B21-10A19-AC8A19-2AC7A21-6B24-3D282-13A16-13C16-4A5-3AGA135-2(6A23-)C5A340-9A20-9C19-11A476-
