model
size = 27 29 27, scale = 0.05, origin = -y
material 
  colors = A:#D00 B:#F90 C:#9CF D:#90C E:#606 F:#90F G:#C3C H:#609 I:#636 J:#93C
voxels
12-21(3B24-)10(3B213-3B13-15(11A3C11A2-)4(11A3B11A2-)11A3B11A13-)3B106-E106-3B13-15(11A3C11A2-)4(11A3B11A2-)11A3B11A13-3B78-2(3H24-)3H66-28B8(25C2B)11(14C13B)14C25BC13B13-E25-3E23-E3CG22-ED2CG22-2D2CG23-D2H39-28B8(25C2B)11(14C13B)14C25B2C12B12-3E24-3E23-E2C2I21-2ED4F21-2D3F23-D2F25-G13-28B8(25C2B)11(14C13B)14C25BC13B13-G25-2GI23-3G2I2(22-2DFJF)23-D2F51-3B13-2(11A3C11A2-)17(11A3B11A2-)11A3B11A13-3B78-2G2(J24-2D)J78-3B13-2(11A3C11A2-)17(11A3B11A2-)11A3B11A13-3B106-D106-9(3B13-2(11A3C11A2-)17(11A3B11A2-)11A3B11A13-3B213-)21(3B24-)3B201-
