model
size = 32 26 32, scale = 0.05, origin = -y
material 
  colors = A:#0F3 B:#00F C:#900 D:#603 E:#C60 F:#E00 G:#639 H:#006 I:#500 J:#700 K:#005 L:#9FC M:#600 N:#001 O:#099 P:#B00 Q:#777 R:#444 S:#080 T:#0F9 U:#400 V:#0A0
voxels
528-2K12-2K16-2K12-2K934-3(2(J-)J27-)2(J-)J281-3(8B24-)8I5(24-8D)24-2D4A2D27-2A30-2A28-6A26-3(6A25-J)2(6AJ24-J6A27-2(J-)J25-3(2A4-2A24-)4(2B4-2B24-)BA4BA2(B24-B6A)B24-I6AI4(24-D6AD)20-3AC8AC3A16-3A3D4A3D3A23-2A30-2A28-4(6A26-))6AJ24-J6A27-2(J-)J25-2A4-2A216-3(8B24-)3IQ4I4(24-8D)20-2A2-8D2-2A16-2A2-2D4A2D2-2A23-2A30-2A29-4A27-2(6A26-)3AN2A26-AO2AOAJ24-J-4A28-2(J-)J25-2A4-2A468-2A12-2A16-2A12-2A118-4J29-2R30-2R123-2A4-2A468-2A12-2A16-2A12-2A308-2N4-2N468-2A12-2A16-2A12-2A166-3(2(L-)L27-)2(L-)L281-3(8G24-)8I4(24-8E)4-2A12-2A4-8E4-2A12-2A4-2E4A2E27-2A30-2A28-6A26-3(6A25-L)2(6AL24-L6A27-2(L-)L25-3(2A4-2A24-)4(2G4-2G24-)GA4GA2(G24-G6A)G24-I6AI4(24-E6AE)4-2K12-2K3AC8AC3A2K12-2K3A3E4A3E3A23-2A30-2A28-4(6A26-))6AL24-L6A27-2(L-)L25-2A4-2A216-3(8G24-)3IQ4I4(24-8E)20-2A2-8E2-2A16-2A2-2E4A2E2-2A23-2A30-2A29-4A27-2(6A26-)3AN2A26-AO2AOAL24-L-4A28-2(L-)L25-2A4-2A468-2A12-2A16-2A12-2A118-4P29-2S30-2S123-2A4-2A468-2A12-2A16-2A12-2A308-2N4-2N468-2(2A12-2A16-2A12-2A784-)2K12-2K16-2K12-2K134-3(2(M-)M27-)2(M-)M281-3(8H24-)8I5(24-8F)4-2K12-2K4-2F4A2F4-2K12-2K7-2A30-2A28-6A26-3(6A25-M)2(6AM24-M6A27-2(M-)M25-3(2A4-2A24-)4(2H4-2H24-)HA4HA2(H24-H6A)H24-I6AI4(24-F6AF)20-3AC8AC3A16-3A3F4A3F3A23-2A30-2A28-4(6A26-))6AM24-M6A27-2(M-)M25-2A4-2A216-3(8H24-)3IQ4I4(24-8F)20-2A2-8F2-2A16-2A2-2F4A2F2-2A23-2A30-2A29-4A27-2(6A26-)3AN2A26-AO2AOAM24-M-4A28-2(M-)M25-2A4-2A468-2A12-2A16-2A12-2A118-4P29-2T13-2(J-)J12-2T13-2(2(J-)J27-)2(J-)J41-2A4-2A232-3(8B24-)8I4(24-8C)4-2A12-2A4-8C4-2A12-2A4-2C4A2C27-2A30-2A28-6A26-3(6A25-J)6AJ24-J6A27-2(J-)J9-2N4-2N8-2(3(2A4-2A24-)4(2B4-2B24-)3(B6AB24-)I6AI4(24-C6AC)4-2A12-5AC8AC5A12-5A3C4A3C3A23-2A30-2A28-4(6A26-)6AJ24-J6A27-2(J-)J25-)2A4-2A216-3(8B24-)3IQ4I4(24-8C)4-2K12-2K2A2-8C2-2A2K12-2K2A2-2C4A2C2-2A23-2A30-2A29-4A27-2(6A26-)3AN2A26-AO2AOAJ24-J-4A28-2(J-)J25-2A4-2A452-2(2K12-2K2A12-2A)118-4U29-2V30-2V123-2A4-2A468-2A12-2A16-2A12-2A308-2N4-2N468-2(2A12-2A16-2A12-2A784-)2K12-2K16-2K12-2K288-
