model
size = 19 19 20, scale = 0.05, origin = -y
material 
  colors = A:#222 B:#555 C:#444 D:#F9C E:#888 F:#F30 G:#F9F
voxels
161-C14-9B2(9-B)9-9B13-3B225-3A15-5A4(14-2(A-)A)14-5A16-E224-C-3A-C13-A3-A13-4(A2(-F)-A12-)A5-A13-2C-2C16-E18-E170-C15-2BC-C2B12-B5-B11-4(B7-B10-)B7-B11-C5-C13-5E35-E132-C16-2C-2C12-BC5-CB10-B7-2(B9-)4(B8-B9-)B8-EC-D3-D-C11-E-3D-E53-E94-C17-C-C14-2C3-2C10-BC7-CB8-B9-B7-4(B11-B6-)B11-B7-C-2D6-C9-E2-D-3DE10-E3-D3-E10-E7-E14-E75-C18-C17-C-C13-A2C3-2CA2(9-B)8-B9-B7-B11-B5-3(A13-A4-)A13-A5-C-4D-DGD2-C7-E4-D3-DE13-D34-E5-E15-E55-C-C15-2C-2C14-C3-C12-AC5-CA2(9-B)7-B11-B5-A13-A4-A13-A5-C11-C5-A13-A3-A15-A3-2C2-D3-G2-D-2C6-ED-D2G-2D-E13-G-D15-DG35-2(E-)E52-C3-C13-C5-C12-C5-C11-A7-A2(9-B)7-B11-B5-A13-A4-A13-A5-C11-C5-A13-A2-2A15-2A2-C2-D5-GD3-C5-CE-D3-D2-DEC9-4D16-D2-2(D17-)E-E17-E53-C5-C12-C5-C11-A7-A2(9-B)7-B11-B5-A13-A4-A13-A5-C11-C5-A13-A2-2A15-2A-AC2-D10-CA4-CE-G-2G-3DEC10-D2-D-D14-DG2D54-E34-2C3-2C11-AC5-C2(A10-A7-)A2(9-B)7-B11-B5-A13-A4-A13-A5-C11-C5-A13-A2-2A15-2A-AC5-D3-G3-CA4-C5(-D)-C7-E-2(D3-)E8-E2-4D3-E9-E2-D-D2-E11-2E3-2E14-3E34-2C-2C12-AC5-C2(A10-A7-)A2(9-B)7-B11-B5-A13-A4-A13-A5-C11-C5-A13-A2-2A15-2A-AC4-3(D-)D2-CA4-CE2D2(-G)-D-EC9-D-G3-D14-G-D55-E37-A16-BC-CB13-A5-A12-A5-A10-BA7-AB7-B11-B5-A13-A4-A13-A5-C11-C5-A13-A2-2A15-2A-AC2-D-G-D2-D3-CA4-CE3(-D)G-DEC10-3D-D15-2G18-D17-E-E17-E54-B3CB13-A5-A13-F3-F11-BAB5-2AB7-B11-B5-A13-A4-A13-A5-C11-C5-A13-A2-2A15-2A2-2C2-D-2D-G-D-2C6-ED-D2-2(D-)E11-D2-D-D13-G-D35-2(E-)E52-2BC2B13-B5-B12-A5-A13-F3-F11-BAB5-2AB7-B11-B5-A13-A4-A13-A5-C11-C5-A13-A2-2A15-2A2-2C-D4-D-D2-2C6-E-G-2D-G-DE11-GD18-D16-E5-E15-E37-B17-A-A15-B3-B13-A5-A13-F3-F11-BAB5-2AB7-B11-B5-A13-A4-A13-A5-C11-C5-A13-A3-AC13-CA4-2C-D5-D-2C8-E-5D-E10-E4-2D-E10-E2-2D3-E14-E56-B18-A16-2A-2A13-A5-A13-F3-F11-BAB5-2AB7-B11-B6-B11-B5-3(A13-A4-)2A11-2A6-EC2(-D)3-CE10-E-D-2DE14-D38-E75-B17-A-A14-2A3-2A12-A5-A11-A7-A2(9-B)8-B9-B7-B11-B5-E13-E5-B11-B6-BAC7-CAB9-C5-C13-5E35-E113-B16-2A-2A13-A2F-2FA12-A2(-F)-A11-B7-B10-A2-C-C2-2(A9-)A7-B11-B7-2(A9-)2A5-2A12-A3-A15-C-C17-E149-5A13-2(A2-)A12-2A-A-2A12-7A11-3A-A-3A10-B2-B-B2-B9-B9FB9-B7-B10-3A3-3A12-5A16-C104-
