model
size = 32 32 31, scale = 0.05, origin = -y
material 
  colors = A:#00F B:#09F C:#D00
voxels
823-2B30-2B24-2B2-2B26-2B2-2B28-2B30-2B866-2B30-2B24-2B2-2B26-2B2-2B28-2B30-2B802-2C30-2C24-2B30-2B932-2C30-2C24-2B30-2B984-2A2-2B26-2A2-2B24-2B2-2B26-2B2-2B924-2A2-2B26-2A2-2B24-2B2-2B26-2B2-2B911-2C30-2C105-2B30-2B851-2C30-2C105-2B30-2B254-7A25-6A2-A23-7A25-7A23-A2-6A25-7A89-7A25-6A2-A23-7A25-7A23-A2-6A25-7A173-2B30-2B10-7A11-2B12-6A2-A9-2B12-7A9-2B14-7A9-2B12-A-7A25-7A215-5(11A21-)11A85-5(11A21-)11A171-2B30-2B8-2(11A9-2B10-)2(11A7-2B12-)11A21-11A27-2(3B29-)3B25-A5-A2(25-7A)2(21-5(15A17-)15A21-7A25-7A)2(25-A5-A)2(25-7A)21-2(15A17-)2(15A3-2B12-)15A17-15A24-2(5B27-)5B22-11A2(21-2A2-7A)18-5A2-10A7-B7-5A2-10A8-B6-17A9-C5-17A15-10A2-5A15-17A18-11A21-11A18-17A15-5A2-10A2(15-17A)2(15-10A2-5A)18-2(7A2-2A21-)2(11A21-)2A2-7A21-2A2-7A18-2(5A2-10A15-)2(17A2-2B11-)10A2-5A15-10A2-5A22-2(7B25-)7B20-2(13A19-)3A2-8A7-B8-6A2-11A5-B7-6A2-11A2(13-19A)13-11A2-6A13-19A16-13A19-13A16-19A13-6A2-11A2(13-19A)2(13-11A2-6A)16-8A2-3A4(19-13A)19-3A2-8A16-2(6A2-11A13-)2(19A13-)11A2-6A3-2B8-11A2-6A3-2B16-2(7B25-)7B19-4A6B2(5A17-4A6-)5A5-B9-6A6-7A2-B10-6A6-2(7A13-7A5-)7A13-7A6-6A13-7A5-7A15-5A5-5A17-5A5-5A15-7A5-7A13-6A6-2(7A13-7A5-)7A2(13-7A6-6A)15-3(5A6-4A17-)2(4A6-5A12-2A3-)4A6-5A15-2(6A6-7A13-)2(7A5-7A13-)7A6-6A3-2B8-7A6-6A3-2B16-2(7B25-)7B18-4A9B2(4A15-4A9-)4A13-6A9-6AB10-4(6A9-6A11-)6A9-6A13-4A9-4A15-4A9-4A13-5(6A9-6A11-)6A9-6A13-3(4A9-4A15-)2(4A9-4A11-2A2-)4A9-4A13-4(6A9-6A11-)6A9-8A9-6A9-8A19-2(5B27-)5B19-3A11B2(3A15-3A11-)2(3A13-2(5A11-)2(2A2-A11-5A11-)2(5A11-A2-2A11-)5A11-5A13-3A11-3A15-3A11-)4(3A15-3A11-)3A13-5A2(11-5A7-2C2-2A2-A)2(11-5A)11-A2-2A11-5A11-A2-4A9-5A11-7A20-2(3B29-)3B19-4A11B2(4A13-A-2A11-)4A11-2(3A2-A11-6A9-)3A2-A10-7A9-7A10-2(A2-3A9-6A11-)6A2(11-4A)13-2(4A11-)6A2(11-6A9-3A2-A)10-7A9-7A10-2(A2-3A9-6A11-)A2-3A11-2(4A11-2A-A13-)2(4A11-4A13-)A-2A11-4A13-A-2A11-4A11-2(3A2-A11-6A6-2C-)3A2-A10-7A9-7A10-2(A2-3A9-6A11-)A2-3A2(107-2A14B2(3A13-A15-)3A11-3(3A15-5A9-)2(5A15-3A9-)5A13-5A11-3(3A13-)3A11-5A13-2(5A9-3A15-)5A3(9-5A15-3A)11-2(3A15-A13-)3A14-2A4B9-2A14-3A4B9-A15-3A4-2B7-A15-3A4-2B5-2(3A15-5A4-2B3-)3A15-5A3(9-5A15-3A))107-3A14B2A13-3A13-A-A13-3A15-A11-2(5A15-3A9-)A2-2A13-5A9-5A13-2A2-A9-3A15-5A9-5A13-5A11-3(3A13-)3A11-5A13-5A9-5A15-3A9-A2-2A13-5A9-5A13-2A2-A2(9-3A15-5A)11-A15-3A13-A-A13-3A13-2A14-3A13-3A14-2A13-3A13-A-A13-3A15-A11-2(5A15-3A9-)A2-2A13-5A9-5A13-2A2-A2(9-3A15-5A)107-3A14B2A2(13-3A15-A)11-2(5A15-3A9-)A2-2A13-5A9-5A13-2A2-A9-3A15-5A9-5A13-5A11-3(3A13-)3A11-5A13-5A9-5A15-3A9-A2-2A13-5A9-5A13-2A2-A2(9-3A15-5A)11-2(A15-3A13-)2A14-3A13-3A14-2A2(13-3A15-A)11-2(5A15-3A9-)A2-2A13-5A9-5A13-2A2-A2(9-3A15-5A)107-3A14B2A2(13-3A15-A)11-2(5A15-3A9-)A2-2A13-5A9-5A13-2A2-A9-3A15-5A9-5A13-5A11-3(3A13-)3A11-5A13-5A9-5A15-3A4-2C3-A2-2A13-5A4-2C3-5A13-2A2-A2(9-3A15-5A)11-2(A15-3A13-)2A14-3A13-3A14-2A2(13-3A15-A)11-2(5A15-3A9-)A2-2A13-5A9-5A13-2A2-A2(9-3A15-5A)20-2(3B29-)3B20-4A11BAB2A13-4A11-A2-A13-2(4A11-)2(6A11-6A9-)A2-3A11-6A9-6A11-3A2-A2(9-6A11-6A)2(11-4A)13-2(4A11-)6A11-6A9-6A11-6A4-2C3-A2-3A11-6A4-2C3-6A11-3A2-A2(9-6A11-6A)2(11-4A)13-A2-A11-4A13-2A-A11-4A13-4A11-A-2A13-4A11-A2-A13-2(4A11-)2(6A11-6A9-)A2-3A11-6A9-6A11-3A2-A2(9-6A11-6A)19-2(5B27-)5B20-3A11B2(3A15-3A11-)3A13-3(5A11-)5A13-3A-A9-5A11-5A9-A-3A13-3(5A11-)5A13-3A11-3A15-3A11-3A13-3(5A11-)5A3-2B8-3A-A9-5A3-2B6-5A9-A-3A13-3(5A11-)5A13-5(3A11-3A15-)3A11-3A13-3(5A11-)5A13-3A-A9-5A11-5A9-A-3A13-3(5A11-)5A19-2(7B25-)7B19-4A9B2(4A15-4A9-)4A13-6A9-6A11-6A9-6A13-5A8-6A11-6A8-5A13-6A9-6A11-6A9-6A13-4A9-4A15-4A9-4A13-6A9-6A11-6A9-6A3-2B8-5A8-6A3-2B6-6A8-5A13-6A9-6A11-6A9-6A13-5(4A9-4A15-)4A9-4A13-6A9-6A11-6A9-6A13-5A8-6A11-6A8-5A13-6A9-6A11-6A9-6A19-7B10-B14-7B25-7B20-5A5B2(5A17-5A5-)5A15-7A5-7A13-7A5-7A15-5A5-7A13-7A5-5A15-7A5-7A13-7A5-7A15-5A5-5A17-5A5-5A15-7A5-7A13-7A5-7A15-5A5-7A13-7A5-5A6-2B7-7A5-7A4-2B7-7A5-7A2-2B11-5A5-5A4-2B11-4(5A5-5A17-)5A5-5A15-7A5-7A13-7A5-7A15-5A5-7A13-7A5-5A15-7A5-7A13-7A5-7A20-7B11-B13-7B10-B-C12-7B9-B11-13A19-13A5-B13-13A4-B11-19AB12-19A15-17A13-17A15-19A13-19A16-13A19-13A16-19A13-19A15-17A13-17A6-2B7-19A4-2B7-19A2-2B12-13A5-2B12-4(13A19-)13A16-19A13-19A15-17A13-17A15-19A13-19A21-2(5B27-)5B23-11A8-B12-11A7-B13-2(11A18-17A15-17A17-15A15-15A17-17A15-17A18-11A21-)2(11A4-2B15-)2(11A21-)11A18-17A15-17A17-15A15-15A17-17A15-17A23-2(3B29-)3B26-2(7A25-)2(7A21-15A17-15A18-14A17-14A18-15A17-15A21-7A25-)2(7A6-2B17-)2(7A25-)7A21-15A17-15A18-14A17-14A18-15A17-15A213-2(9A23-)9A21-2(9A23-)9A89-2(9A23-)9A21-2(9A23-)9A126-6A2-2B22-6A2-2B28-2B19-9A2-2B19-9A23-9A21-2(9A23-)9A219-5A27-5A2(25-7A)25-5A27-5A93-5A27-5A2(25-7A)25-5A27-5A128-6A2-2B22-6A2-2B28-2B21-5A4-2B21-5A2(25-7A)25-5A27-5A18-
