model
size = 16 20 19, scale = 0.05, origin = -y
material 
  colors = A:#E00 B:#EEE
voxels
102-4A11-6A9-3(8A8-)8A9-6A11-4A172-4A10-8A7-10A6-10A5-3(12A4-)12A5-10A6-10A7-8A10-4A122-8A8-8A7-10A4-7(14A2-)14A4-10A7-8A8-8A90-4A10-8A7-10A5-12A3-14A2-14A-64A-14A2-14A3-12A5-10A7-8A10-4A74-8A7-10A5-12A3-14A-128A-14A3-12A5-10A7-8A58-4A9-10A4-14A2-14A-160A-14A2-14A4-10A9-4A43-6A8-10A4-14A2-14A-160A-14A2-14A4-10A8-6A12-2A13-4A10-8A6-12A3-14A-192A-14A3-12A6-8A10-4A12-4A10-8A6-12A3-14A-192A-14A3-12A6-8A9-6A11-4A10-8A6-12A3-14A-192A-14A3-12A6-8A-2A6-6A3-A7-4A10-8A6-12A3-14A-192A-14A3-B11A6-8A10-4A27-6A8-10A4-14A2-14A-160A-14A2-14A4-B9A8-6A12-2A29-4A9-10A4-14A2-14A-160A-14A2-14A4-B9A9-4A58-8A7-10A5-12A3-14A-128A-14A3-12A5-10A-A5-8A74-4A10-8A7-10A5-12A3-14A2-14A-64A-14A2-14A3-12A5-10A7-8A10-4A90-8A8-8A7-10A4-5(14A2-)B12AB2(2-14A)4-10A7-AB4ABA8-8A122-4A10-8A7-7AB2A6-10A5-2(12A4-)B10AB4-12A5-2B6A2B6-2B6A2B7-8B10-B2AB172-4B11-6B9-AB4ABA8-8A8-2B4A2B8-B6AB9-2B2A2B11-4B236-4B2(12-4A)12-4B134-
