model
size = 32 10 32, scale = 0.05, origin = -y
material 
  colors = A:#BBB B:#001 C:#3CF D:#E00 E:#FC3 F:#111
voxels
32-A3(30-2A)30-A160-13A5-27A5-16A9-2A5-2A10-4A9-3A3-3A10-4A9-4A-4A3(10-4A9-9A)10-79A5-27A5-16A9D2A5-2A10C4A9D3A3-3A10C4A9D4A-4A10C2AFA2(9D9A10C4A)9D9A10C67A12B5-13B2AE9BEB5-BE10BE2AB9-2B5-2B10-B2AB9-BEB3-BEB10-B2AB9-B2EB-B2EB10-B2AB9-2(B3E)B10-2BFB9-B7EB10-B2AB9-B7EB10-2BAE9B9E10BE32AB13A5-27A5-16A9-2A5-2A10-4A9-3A3-3A10-4A9-4A-4A10-4A9-9A10-AB2A9-9A10-2AFA9-9A10-AB63ABA5(30-2A)5(30-BA)3(30-2A)2(30-AF)30-2A30-AF2(30-2A)30-A32-A2(30-2A)30-AF30-2A30-AF30-BF2(30-2A)30-B64-A4(30-2A)3(30-BA)30-B96-A3(30-AF)30-BF2(30-2A)30-B128-A5(30-2A)30-A160-A2(30-2A)2(30-BA)30-A192-A30-BA2(30-2A)30-B192-4(A30-B)192-A3(30-2A)2(30-A192-A30-BA2(30-2A))30-A192-4(A30-B)192-A3(30-2A)30-A192-4(A30-B)192-A30-BA2(30-2A)30-B192-4(A30-B)192-A3(30-2A)30-A2(192-A30-BA2(30-2A)30-B)192-4(A30-B)160-A4(30-2A)30-A128-A5(30-2A)30-A96-A6(30-2A)30-A64-A6(30-2A)30-A32-A7(30-2A)30-A64-A6(30-2A)30-A96-
