model
size = 32 10 32, scale = 0.05, origin = -y
material 
  colors = A:#FF3 B:#001 C:#F3F D:#3CF E:#0F3 F:#E00 G:#FC3 H:#EEE I:#111
voxels
32-A3(30-2A)30-A160-2(2C9A2E5-14E)2C9-2E5-2C10-2A2C9-2EC3-3C10-2A2C9-2ECH-3HC10-2A2C9-2ECH3CHC10-2A2C9-2EC3HCHC10-2A2C9-2E5CHC10-2A11C2EC5H11C2A13E17C15A5-27A5-16A9F2A5-2A10D4A9F3A3-3A10D4A9F4A-4A3(10D4A9F9A)10D67A12B5-13B2AG9BGB5-BG10BG2AB9-2B5-2B10-B2AB9-BGB3-BGB10-B2AB9-B2GB-B2GB10-BAIB9-2(B3G)B10-2BAB9-B7GB10-B2AB9-B7GB10-2BAG9B9G10BG32AB13A5-27A5-16A9-2A5-2A10-4A9-3A3-3A10-4A9-4A-4A10-4A9-9A10-ABIA9-9A10-4A9-9A10-AB63ABA5(30-2A)30-BA30-BI3(30-BA)9(30-2A)30-A32-A2(30-2A)3(30-AI)30-BI30-AI30-2A30-B64-A4(30-2A)3(30-BA)30-B96-A3(30-2A)30-BA2(30-2A)30-B128-A5(30-2A)30-A160-A2(30-2A)2(30-BA)30-A192-A30-BA2(30-2A)30-B192-4(A30-B)192-A3(30-2A)2(30-A192-A30-BA2(30-2A))30-A192-4(A30-B)192-A3(30-2A)30-A192-4(A30-B)192-A30-BA2(30-2A)30-B192-4(A30-B)192-A3(30-2A)30-A2(192-A30-BA2(30-2A)30-B)192-4(A30-B)160-A4(30-2A)30-A128-A5(30-2A)30-A96-A6(30-2A)30-A64-A6(30-2A)30-A32-A7(30-2A)30-A64-A6(30-2A)30-A96-
