model
size = 21 26 30, scale = 0.05, origin = -y
material 
  colors = A:#F93 B:#FC0 C:#AAA D:#06C
voxels
388-3B18-5B17-3B330-6B16-6B495-7B14-2B5A3B12-3B3-4B14-3B436-4A16-A2-A-A14-B5A6B8-BA7-3B10-2B7-B-B11-3B2A2B2-B11-6B15-6B16-4B355-2A14-9A12-8A-2A10-B5ABA2B2A2B6-BA9-3B7-B2A9-B9-2BA4-2A2B11-BA4-A2B11-2B2A3-AB12-3B4A2B13-7B15-5B20-B253-A19-3A13-A4-4A9-4A4-4A7-B5A4-7A5-B2-12AB5-BA2-AB4AB3-2B5-B2A-5AB3-B8-B8A-AB9-2B3A2-4AB9-B2A6-A2B9-B2A5-2A2B9-2B2A4-A2B10-3B5A2B12-6BA2B12-8B19-B167-A15-A20-2A4-3A14-8A9-13A6-16A4-BA-15A3-2BA-B12AB4-BA-9A2B2-AB4-B4A4-A2B-A2B5-BA-7AB2-2B7-B-8A-AB6-3B-8A-AB8-B-10AB7-BA3-A2-A-2AB8-B2A7-A2B8-2BA6-2A2B8-2B2A5-A2B10-7BAB13-7B124-A18-5A15-8A11-2(12A8-)14A6-16A4-18A3-2A-14AB3-BA-14AB3-2B-A2-8AB2-AB2-2B-B2(2-A)4-B2-2B2-3B2A-A2-A3-AB2-B3-3B2A2-2A4-AB-2B3-3B2A8-AB-2B3-2B-4A4-3A3B4-2B2-2A-2A2-3A-2B4-2B3-3A-4A2-2(2B4-)6A2-2B6-2BA4-2A-A2B10-B2A2-3A2B11-8B103-3A16-7A11-10A9-15A7-13A6-15A6-16A5-17A3-18A3-2A2-13AB2-BA4-9A2B-AB-BA16-2(AB-BA2-A10-B2-)AB-B2(A2-)4A4-2(B2-)BA2-2A-4A3-AB-2B2-BA2-3A6-2AB-2B2-BA2-4A4-B2A4B3-B4-3A2-ABA2-2B4-B2A3-5A-2AB7-2BA4-2A-3B10-B7AB12-8B81-5A13-10A9-12A8-15A6-14A2(6-15A)7-16A4-17A2-B18A2-BA-B-3B4A7B2(2-B)2(12-B2-B-B2-B)12-B-2B-B17-AB-B17-B2-B3-A10-2(B2-)BA2-3A6-3B-2B2-BA2-4A4-7B2-B2A4-5AB-BAB5-B2A3-5A4B7-2BA4-3A3B10-8B80-6A12-11A8-13A7-15A6-16A5-15A7-14A7-15A5-16A4-17A3-B18AB-B2-B4-5B3-B-2B3(-B2-B12-B2-B)-B2-B12-B-B2-B17-AB-B3-A10-B2-AB-B3-B2A6-3B2(2-B)A2-5A2-2A2BA3B2-B2A4-6A-2B6-B2A4-5A3B7-5B2-2A2B15-4B40-3A17-7A11-11A9-13A6-15A6-16A6-2(14A7-)15A3(5-16A)B2-B18AB2-B2A3-6A3-3AB2-B2A12-A3(B-)2A12-A2(B-)2(B2-B12-B2-B-)B2-B12-B2-3B18-B-B3-B10-A2-AB-B3-2A8-2A4B-BA2-4A4-4AB4-2BA3-7A3B7-5B4A3B12-7B17-5A16-7A12-10A9-13A4(7-14A)6-3(16A5-)16A3-B17AB2-B2A2-11A-2AB2-BA5-4A5-3(B-)2A12-A2(B-)B3A12-A2(B-)B3(2-B12-B2-3B)3-A10-A-2AB-B3-A10-2A2B2-B3-3A6-3AB4-2B4-3B2-B2A-B7-3BA5-4B11-7B18-5A14-8A11-11A9-13A3(7-14A)6-3(16A5-)3(16AB3-B)14A-2AB2-BA3-7A4-2A2(B-)A5-A8-2(B-)B3A12-A3(B-)BA12-AB-3B2-B12-B2-3B2-B12-B4-B3-A10-3A2B-B3-A10-2A2(B3-)3A6-3AB4-2B4-3B2-B2A-2B6-3BA5-4B11-7B17-6A12-10A11-11A9-12A9-13A2(7-14A)6-2(16A5-)16A4-B16A2(B3-B-15A)B3-B16AB2-B14A2-2AB-B2A3-6A5-2AB-B2A5-2A7-2(B-)3BA12-A2(B-)2(B2-B12-B2-B-)B3-A10-2A3B-B3-A10-AB4-B3-3A6-4AB3-2B4-3B2-B2A-AB6-3BA5-5B10-7B16-6A14-8A11-10A11-12A8-2(14A7-)14A6-2(16A5-)16A4-3(B16AB3-)B16AB4-16AB3-B12A3-2AB2-B10A4-A2(B-)2(BA)12-A2(B-)BA-B12-B2-B-B2-B12-B4-BA14-AB3-BA2-A10-2AB3-BA2-2A8-4AB2-2B3-A2B4-3A-2B5-3BA6-A3B10-8B15-7A13-8A11-11A10-12A8-2(14A7-)14A6-3(16A5-)B15A5-16AB4-2(16A5-)16AB4-14A-AB3-B11A3-AB-B2-B-9B4-B2-B-BA-B5-2B5-B2-B-BA-B12-B-B2-BA14-AB4-B2-A10-3AB2-BA2-2A8-2A-AB2-2B3-A2B4-3A-2B5-3BA6-A3B10-8B16-A-3A14-2A2-3A13-3A2-5A10-2A5-5A8-2(2A6-6A7-)2A6-6A6-7(3A6-7A5-)16A5-16AB3-B13A-3AB2-B11A3-B-AB2-B10A4-2(B2-)B-B5-2B5-B-2B2-B14-AB4-B2-A10-3AB2-BA2-2A8-2A-2AB-2B3-A2B4-3A-A2B5-2BA6-2A3B9-9B16-2A17-6A13-10A10-5A2-5A9-12A8-2(14A7-)14A6-7(16A5-)16A6-16A4-2(17AB2-B)14A4B2-B2-A9-3AB4-B2-A10-A-A2B2-B2-2A8-2A2-AB-3B2-A3B2-B3A2-2B5-2BA7-A3B9-9B17-A18-4A16-6A13-4A2-4A10-12A9-12A8-9(14A7-)11A-2A2(7-14A)8-12A7-B3A2-8A6-BA-2A7-3A2B4-BA-2A7-3A-AB3-B2-4A4-4A-AB3-2B3-6B2A2-2B6-B2A5-BA3B9-9B38-2A18-4A15-3A2-3A11-3(12A9-)12A8-6(14A7-)14A8-10A-A3(9-12A)9-2A2-8A7-B-2A7-3A2B4-BA-3A6-3A-A2(B3-)4A2-4A-2AB3-2B4-5BA3-2B6-B2A3-7B9-8B59-4A16-6A13-10A10-10(12A9-)10A-A3(9-12A)9-2A2-8A7-2B3A6-3A2B4-BA2-3A4-2AB2-AB3-BA3-8A2-AB4-2BA4-4B3-2B7-2BA9B11-5B62-2A18-4A15-8A12-10A10-8(12A9-)C10AC9-12A9-2B8A2B2(9-12A)9-BA2-7AB7-2B-10B-2B5-BA2-8B2-AB5-BA3-6B3-AB5-2B10-3B8-10B120-4A16-6A14-7(8A13-)8A12-CDC4ACDC12-2B4A2B3(13-8A)11-12B8-B3-A2-A5-2B6-B12-AB6-BA10-AB8-3B5-4B12-5B123-2A18-4A16-4(6A15-)6A16-4A16-6A16-4A17-C2AC2(17-4A)17-A2-2A15-5A13-12B9-B11-2B7-B10-AB8-BA7-2AB9-5B2-5B14-2B145-2A18-4A17-4A16-6A16-4A17-4A18-2A18-4A17-A2-A102-2B15-11B9-B11-B8-BA8-2AB8-B2AB4-4B10-9B204-4A17-A2-A18-2A40-2A19-2A127-B13-11B10-2B7-2AB8-2B-B4-2A2B10-5B2A3B13-6B290-2A142-9B12-BA5-2AB12-B3A-2A2B13-2B2A2B17-2B457-8B13-BA4-AB14-2B2A2B17-2B459-2B18-B2A3B15-2B3AB16-4B112-
