model
size = 32 26 31, scale = 0.05, origin = -y
material 
  colors = A:#060 B:#39F C:#001 D:#60F E:#EEE F:#555 G:#E00 H:#0E0
voxels
301-6A25-2(A2B)AB24-A2BAB3A24-8A24-A2BAB3A24-2(A2B)AB25-6A2(634-2(2BA)25-8B24-5B3A24-A2BAB3A24-5B3A24-8B25-2(2BA))633-8A24-2(A2B)AB24-A2BAB3A24-8A24-A2BAB3A24-2(A2B)AB25-6A409-8A22-12A17-18A12-4A-12A-4A9-8A-6A-8A7-9A-6A-9A6-26B6-2(A2B)AB10-2(A2B)AB6-8B10-8B6-5B3A10-5B3A6-A2BABAC12-2BAB3A7-4B2A12-4B2A9-5B12-5B10-BA2BA12-2BA2B11-5B10-5B13-4B10-2B2A15-BA2BA6-2BABA17-14B274-14C16-2A14-2A12-22A9-24A7-3A2C16A2C3A6-26A6-5B2(3A6B)3A6-2(A2BAB3AB)A2BAB3A6-5B2(3A6B)3A2(6-4A-16A-4A)7-3A3-12A3-3A8-3B3-A6B3A2B3-B2A8-2BA3-ABA2BAB3ABA3-B2A8-3B4-6B3AB4-B2A10-2B3-6B3AB3-2A13-BA4-2BAB2A4-2A15-2A12-BA270-3C14D3C12-2A16-2A10-24A8-24A7-2AC20AC2A6-26A6-2(A2BAB3AB)A2BAB3A6-4A-16A-4A6-A2B2-3ABA2BAB3ABA2B2-3(3A6-3A-18A-)3A7-2B-2(B3ABA2BA)-2A8-2A-18A-2A8-2B-2(B3ABA2BA)-2A8-ABA-3ABA2BAB3A2(BA)-3A9-3A-14A-3A12-BA-ABA2BAB3ABA-2A18-10A23-8A210-C12D3C3DC11-A-A16-A-A9-AC20ACA7-2(2AC20AC2A6-)26A6-5B2(3A6B)3A6-A2B-2(B3ABA2BA)-3A6-2B-2B2(3A6B)-2A6-2A-20A-2A6-2A-10AC9A-2A6-2A-20A-2A6-2B-2B2(3A6B)-2A7-B-2(AB3ABA2B)AB-A8-B-2B2(3A6B)-A8-AB-B3A6B3A3B2A-2A9-BA-3ABA2BAB3A2(BA)-2A11-2B-2A6B3A3B-2A16-12A21-10A23-8A148-5G24-C16DC3DC9-6A12-6A8-AC20ACA7-2(2AC20AC2A6-)3AC18AC3A5-28B4-BAB-C6(2BA)B-A2B4-28B4-2B-3B2(3A6B)A-AB4-BA-BC2(B3ABA2BA)BA-AB5-B-3B2(3A6B)A-A6-B-22B-B6-A-B7(A2B)-B7-24B8-A-17B3A-A8-AB-5(2BA)B2A-2A9-2B-15BA-2A13-3A6B3A3BA18-ABA2BAB3ABA21-6B3AB23-8B115-3GC3G22-AC20DCA8-24A7-2AC20AC2A6-2AC8A-2A-8AC2A6-2AC3A6-2C6-3AC2A5-3A2(2C8-)2C3A4-BA2BC8-CB8-2BA2B3-2(A-)2(2C8-)2C2(-A)2-B-A-BC8-CB8-2B-B-A2-A-A2BC8-CB8-BC2A-A3-3A2(2C8-)2C3A4-3(BA2BAB3A)B5-8(A2B)AB6-26A7-8(2BA)8-AB5(A2B)AB5A8-A-20A-A8-AB-5(2BA)B2A-2A11-B3ABA2BAB3ABAB2A15-16A18-ABA2BAB3ABA21-B3(A2B)23-8A83-3G2C2G4-5G13-C22DC8-AF20-FA7-A11F2-11FA6-2ACF8C2-8CFC2A5-3ACF8C2-8CFC3A4-3ACF8C2-8CFC3A5-12B2-12B3-A2-A2B-2(2BC)2B2-B2(C2B)C-BAB2-2B2(2-12B)2-B-A-5B3C4B2-3C6BC2A-B2-A-A2B20-C2A-A3-2(6B3C)6B3AB4-28B5-8(A2B)AB7-24B8-A18B5A8-AB5(A2B)AB5A8-A-17B3A-A10-2B3A6B3A3B3A13-B3ABA2BAB3ABAB2A15-3A6B3A3BA18-12B21-B3(A2B)81-5GC3G2-7G12-C22DC8-A22-A7-A2F8-4F8-2FA6-2A2C18-2C2A5-3A2C18-2C3A3-A-2A2C2-2E10-2E2-2C2A-A-B2-4B2-2B10-2E2-2C2(2A2-)A2BC-BE2B8-4E-2C2A2-AB2-4B-3B10-3E-2C2(2A2-)4B18-2C2A2-2(A-)A2B20-C2A-A2-A-5B3C3B12C3A-A3-12B16A5-3(A2B)AB15A6-11B15A7-A9B14A8-AB2(A2B)AB14A9-9B13A11-2B3A3B12A13-B3ABAB11A15-3A3B10A17-5B9A19-2BAB8A80-2C7G2-3G2C2G12-C22DC7-A24-A6-A2F9-2C9-2FA6-2AC3-E12-E3-C2A5-2A2C3-2E10-2E3-2C2A3-A-2ACD-4E8-4E2-C2A2(-A)-BA2B2-BE2B8-4E2-C3A-2A-3AC2-4E8-4E2-C3A-2A-BA2B2-BE2BE6-5E2-C3A-2A-BA2B20-C3A-A-4AC20-C4A2-A-A2BCB3CBCB12C3A-A3-B3(A2B)AB16A5-26A6-3(A2B)AB15A6-2AB2(A2B)AB15A7-24A8-AB2(A2B)AB14A9-BAB3ABAB13A11-20A13-B3ABAB11A15-BA2BAB10A17-14A22-B5A53-2C5G-3G3C3G11-C22DC7-A24-A6-AF22-FA6-AC4-2E10-2E4-CA5-3AC2-4E8-4E2-C3A3-4AC2-4E8-4E2-C4A-6B2-5B6-5E2-C6A2BA2B-2(2BE)6-6E-C5A6B2-5B6-5E2-C7A4B2-3CB8-4C2-C5A-ABA2B2-3CB8-4C2-C4A2-A4BDB3C3B12C5A3-12B16A5-3(A2B)AB15A6-11B15A6-2A9B15A6-2AB2(A2B)AB15A7-A9B14A8-A3B3A3B14A9-BAB3ABAB13A11-2B3A3B12A13-7B11A15-BA2BAB10A19-3B7A17-D35-2C3G-9G11-C22DC7-A24-A6-AF22-FA6-AC4-2E10-2E4-CA5-3AC3-3E8-3E3-C3A4-3AC-6E6-6E-C3A2-2A4B-B3E2B6-6E-C7ABA2B-B3EBE6-6E-C7A4B-B3E2B6-6E-C10AC2-4C8-4C2-C5A-4AC2-4C8-4C2-C4A2-5A2C3-10C3-2C5A3-6B3A3B16A5-A2BAB3ABAB15A6-5B3A3B15A6-2A3B3A3B15A7-2(AB)3ABAB14A8-A3B3A3B14A2(8-24A)9-22A11-2B3A3B12A13-B3ABAB11A18-3B7A55-2CG-7G2C11-C22DC7-A19-D4-A6-AF18-D3-FA6-AC4-3E8-3ED3-CA5-3AC2-4E8-4E2-C3A3-4AC-6E6-6E-C4A-2ABA2B-B3EBE6-6E-C10AC-6E6-6E-C7ABA2B-B3EBE6-6E-C10AC-6C6-6C-C5A-4AC2-4C8-4C2-C4A2-5A5C-8C-5C5A3-BA2BAB3ABAB16A5-26A6-A2BAB3ABAB15A6-2ABAB3ABAB15A6-26A6-2ABAB3ABAB15A7-24A8-24A9-22A11-AB3ABAB12A13-18A17-2(AB)8A58-4G3C13-C22DC7-A8-D15-A6-AF7-D7-2D5-FA6-AC4-3ED7-D2E4-CA5-3AC2-4ED7-3ED2-C3A3-4AC-5ED7-5E-C4A-2A4B-B3E2B6-6E-C7ABA2B-B3EB8-5E-C7A4B-B3E2B6-6E-C10AC2-5C6-5C2-C5A-4AC2-4C8-4C2-C4A2-5A20C5A3-6B3A3B16A5-A2BAB3ABAB15A6-5B3A3B15A6-2A3B3A3B15A6-2ABAB3ABAB15A6-2A3B3A3B15A7-24A8-24A9-22A11-2B3A3B12A13-B3ABAB11A17-A3B8A58-2G2C16-C22DC7-A8-D7-2D2(6-A)F7-D7-2D5-FA6-AC3-3E10-D2E3-CA5-3AC2-4ED7-4E2-C3A3-4AC-5ED7-5E-C4A2-5B-5BD6-6E-C4A-2(A2B)-2BE2BD6-6E-C5A6B-6B6-6E-C7A4B-B3C2B6-6C-C5A-ABA2B2-3CB8-4C2-C4A2-A6B3C3B12C5A3-12B16A5-3(A2B)AB15A6-11B15A6-2A9B15A6-2AB2(A2B)AB15A6-2A9B15A7-A3B3A3B14A8-2(AB)3ABAB14A9-3B3A3B13A11-8B12A13-2(2BA)B11A17-4B8A59-C18-CDC9DC7DC2DC7-A24-A6-AF22-FA6-AC4-2E10-2E4-CA5-3AC2-3E10-3E2-C3A4-3AC2-3E10-3E2-C3A3-2BA2B2-BEB10-3E2-C4A2-4AC2-4E8-4E2-C4A2-2BA2B20-C4A2-ABA2B2-3CB8-4C2-C4A2-4AC2-4C8-4C2-C4A3-BA2BCB3CBCB12C4A4-B3(A2B)AB16A5-26A6-3(A2B)AB15A6-2AB2(A2B)AB15A6-26A6-2AB2(A2B)AB15A7-2(AB)3ABAB14A8-24A9-BAB3ABAB13A11-2(A2B)AB12A13-18A17-2BAB8A78-C2DC15DC3DC7-A24-A6-AF22-FA6-AC22-CA6-2AC3-E12-E3-C2A5-3AC3-2E10-2E3-C3A4-4B3-2B10-2E3-C3A3-2BA2B3-E12-E3-C4A2-5B2-4B8-4C2-C4A2-A4B2-3C10-3C2-C4A3-BA2B2-3C10-3C2-C3A4-6B3C3B13C3A5-11B15A6-3(A2B)AB15A6-11B15A6-2A9B15A6-2AB2(A2B)AB15A7-A9B14A8-A3B3A3B14A8-2(AB)3ABAB14A9-3B3A3B13A11-8B12A13-2(2BA)B11A18-3B7A79-2C2D2C11D2C3D2C7-A24-A6-A2F3-F12-F3-2FA6-2AC20-C2A6-A2C20-2CA6-2AC20-C2A5-2(3AB20-C3A4-)3AB2-3B10-3C2-C3A4-3AB2-3C10-3C2-C3A4-3AB20-C3A5-2A3B3C3B13C2A6-2A9B15A6-2AB2(A2B)AB15A6-2A9B15A2(6-26A)7-24A8-24A9-22A10-22A11-20A14-16A19-10A80-2C18D2C9-A22-A7-2A2F-3F10-3F-2F3(2A6-2AC20-C)2A6-2AB20-C2A6-2AC2(20-C2A6-2AB)20-C2A6-2AC20-C2A6-2ABCB3CBCB13C2A2(6-2AB2(A2B)AB15A6-26A)7-2(24A8-)24A9-22A11-20A13-18A15-16A19-10A81-20C10-2A20-2A8-2A20F2A7-3A20-2(3A6-3A2C16-2C)3A6-A-3B16-2CA-A6-2ABCB2(16-2C3A6-2A3B)2(7-2C)3A6-2ABCB2(7-2C)3A6-2A3B3C3B2CA7C5A6-2A9B15A6-2AB2(A2B)AB15A6-2A9B15A7-24A7-26A8-22A11-20A13-18A15-16A17-14A19-12A117-10A17-20A11-22A9-2A20F2A8-4A16C4A7-5A16C5A6-A2-2B3C3B10C2A2-A6-2ABAB3CBCB10C5A6-2A3B3C3B10C5A6-5A16C5A6-5A8CA7C5A6-5A7C2A7C5A6-2A3B3A3B15A7-2(AB)3ABAB14A8-A3B3A3B14A8-24A9-22A11-20A12-20A13-18A15-16A18-12A21-10A149-12A19-14A15-4AC10AC4A12-3AC12AC3A11-22A9-AB-B3ABAB11A-2A8-24A8-2(AB)3ABAB14A3(8-24A)2(8-2(AB)3ABAB14A8-24A)10-20A13-18A14-18A15-16A18-12A21-10A23-8A184-8A23-C8AC21-H10AH18-CH12AHC16-3A3B10A14-AB3ABAB12A11-3B3A3B13A3(10-22A)10-3B3A3B13A10-BAB3ABAB13A10-3B3A3B13A11-20A13-18A15-16A16-16A18-12A21-10A23-8A248-8A23-C8AC21-H10AH19-C4B8AC16-2(2BA)B11A13-8B12A12-2B3A3B12A12-AB3ABAB12A12-2B3A3B12A12-8B12A12-2(A2B)AB12A12-8B12A13-18A15-16A17-14A19-12A21-10A23-8A312-8A23-C8AC21-2CAB6A2C18-16A16-BA2BAB10A15-B3ABAB11A14-18A14-B3ABAB11A14-2(2BA)B11A14-18A14-2(2BA)B11A15-16A17-14A19-12A21-10A23-8A378-4A26-2B6A22-2BAB8A19-5B9A18-2A3B9A18-2ABAB9A17-3A3B10A16-6B10A17-A2BAB9A18-5B9A19-12A21-10A23-8A26-4A473-BAB2(7A22-3B)7A21-2(AB)8A20-A3B8A20-4B8A20-2BAB8A21-3B7A22-3B7A24-B5A570-B5A25-AB6A24-8A2(24-AB6A)24-8A24-AB6A300-
