model
size = 17 26 12, scale = 0.05, origin = -y
material 
  colors = A:#FFC17A B:#FD0 C:#222 D:#AB8B00 E:#555 F:#FF8B17 G:#444 H:#D9BC00 I:#AAA J:#B69A00 K:#A00 L:#FFF M:#BBB N:#500 O:#777 P:#E00 Q:#C4945D R:#9D550E
voxels
413-B374-8DB325-3G4-B2-B-B23-2G3-BH-BH2B8-5G5B23-D9GJ6-2HDE2G4EB6-D2-6DJB10-4DJB11-2B2-2B8-2B-B236-5B11-B5D2B3-3G3-BA2D2(AD)B7-2B7DB4-2GBGOCADANCLB6-G5C5A6-10GHG5-DC8EJG4-3H2E2G4E2B4-B9DJB7-BDB4DJBH7-2B-4B-B13-B234-5BD10-3A2KA2B8-3AK5AB6-B7ALA2B5-BCOC3ANCLB6-G5C5AB5-GCM3IC3IHG5-DC8EJG4-3H2E2G4EB5-B9DJBH4-2H3B4DJBHJ5-D-B-D2-B30-B219-6B10-3A2KABD8-3AK4A2B6-B7ALA2B5-BCOC3ANCL2B5-G5C5AB5-GCM3IC3IHG5-DC8EJG4-3H2E2G4E2B4-B9DJB5-2H2B-4DJBH5-2B7-BD-B12-B3-2B11-B-B2-B57-2F5-F9-8F10-7F9-C7F10-2F3P2F10-FC3P2C2(10-7C)11-2CRC13-5A10-3A2K2AB8-3AK4ABH6-B7ALA2B6-GOC3ANCL2B5-G5C5A6-GCM3IC3IHG5-DC8EJG4-3H2E2G4E2B4-B9DJB5-2HBDB4DJBHJ7-B-2BHB2-BH7-B83-11F6-2FC2(7F9-)C2(2FCGC2F10-)FCAGQ2C10-3C2A2C10-7C11-2CRC12-6A10-3A2K2AB8-3AK4A2B7-7AL2A7-GOC3ANCLA6-G5C5AB5-GCM3IC3IHG5-DC8EJG4-3H2E2G4E2B4-B9DJBH5-HBD-4DJBH5-2B20-B16-B64-2F-5F-2F6-2FC7F9-7F2(10-2FCGC2F)10-FCAGQ2C10-3C2A2C10-7C11-2CRC12-6A10-3A2K3A8-3AK4AB7-B7AL3A6-GOC3ANCL2A5-G5C5AB5-GCM3IC3IHG5-DC8EJG4-3H2E2G4E2B4-B9DJBH4-2HBDB-3DJBHJ4-2B4-B3-2B4-2B15-B18-C10-2C4-GC9-CG4-2F8-3F5-2F7-2F6-2F7-F59-C16-2C5-2G9-2C2-3C27-6A10-3A2K3A8-3AK4AB7-B7ALAB7-GOC3ANCLA6-G5C5AB5-GCM3IC3IHG5-DC8EJG4-3H2E2G4E2B5-9DJBH4-2HBDB-3DJBHJ4-2B-BD2(-B)H2-B12-B26-C10-2C4-GC9-CG5-F9-F6-2F7-2F75-3CA-Q-C9-2C3-A2G45-4A12-2A2K2A10-2AK5A8-AL5AL2A7-GCL3ANCLA6-2G9AB4-H2CM3IC3IHG4-HDC8EJG4-3H2E2G4E2B4-B9DJBH4-2H-DB-3DJBHJ4-DB2-H3-H-B-2B7-B3-B-B2-B3-B17-C10-2C293-2GM3IG3IHG5-DG8EJG4-3H8E2B5-B16-B27-B17-B11-B5-
