model
size = 32 31 31, scale = 0.05, origin = -y
material 
  colors = A:#09F B:#00E C:#E00
voxels
106-C496-C24-C5-A24-A5-A30-A402-A31-A32-A518-A3-A312-C32-A154-A32-A456-A28-A274-C32-A20-C11-A9-A186-A338-C84-A61-A30-A278-B17-A13-8B-A7-A15-7B8-A16-10(7B25-)2(4BA2B25-)5BAB25-2(2BA)B16-A8-2(2(2BA)B25-)BA3B2A2(25-8A24-7A)5(25-7A)119-B8ABA2(21-2B7A2B)4-2A15-2B7A2B4-A16-2B7A2B3-A17-2B7A2B2-A18-2B7A2B-A19-2B7A3B20-3(2B7A2B21-)4(B8A2B21-)B8A2B15-A5-9A2B16-A4-9A2B17-A3-9A2B18-A2-8(11A21-)11A39-C76-14(B11AB19-)B11AB10-A8-B11AB11-C7-B11AB2(19-B12A)18-14A8(19-13A)37-A76-2(B13AB17-)B13AB16-2B9(13AB17-B)14A6-A10-15A7-A9-B14A8-A8-B14A10(17-15A)2(17-7A3-5A)50-A3-C4-C2-C5-A13-A3-A4-A2-A12-A4-16AB11-A3-16AB12-A2-16AB13-18A8(B15-B15A)B15-16AB4-A10-17A2(15-B16A)3(15-B15AB)7(15-17A)2(15-7A5-5A)74-A24-A10-B17AB-A11-10(B17AB13-)18AB-A11-18AB2-A10-19A3(13-18AB)9-C3-2(18AB13-)7(19A13-)8A5-6A13-8A5-6A41-A67-B18AB12-10(B17AB13-)B19A12-2(B18A13-)19A13-19A9-A3-19A2(13-B18A)7(13-19A)2(13-8A5-6A)9-C30-C67-13(B19AB11-)B19AB9-A-20AB8-A2-B19A3(B11-20A)B7(11-21A)2(11-10A3-8A)39-A7-A23-A7-A22-A4-12(B19AB11-)B19AB9-A-6(B19AB11-)8(21A11-)21A46-C7-C5-C17-2A6-A5-A14-B19AB6-A4-B19AB5-A5-9(B19AB11-)B20A9-A-3(B20A11-)2(B19AB11-)2(20AB11-)21A11-22A10-6(21A11-)21A53-C31-A21-2(B19AB11-)B19AB4-A6-B19AB3-A7-7(B19AB11-)B19AB10-AB19A2(B11-20A)B2(11-21A)2(11-B20A)2(11-21A)-A9-2(21A11-)21A10-22A3(11-21A)107-4(B19AB11-)B19AB2-A8-B19AB-A9-B21A10-12(B19AB11-)21A11-21A2-A8-21A3-A7-21A4-A3-A2-21A9-A-3(21A11-)21A107-11(B19AB11-)8(B20A11-)21A11-21A7-C3-21A8-A2-21A5-A5-4(21A11-)21A57-C31-A17-19(B19AB11-)21A11-21A8-A2-21A7-A3-21A6-A4-4(21A11-)21A108-9(B17AB13-)B17AB7-A5-B17AB6-A6-B17AB5-A7-2(B17AB4-A8-)3(B17AB3-A9-)18AB2-A10-B17AB2-A10-19A2-A6-C3-3(19A-A11-)3(20A12-)19A13-19A109-B19A12-8(B17AB13-)B17AB8-A4-4(B17AB13-)4(19A13-)18AB7(13-19A)2(13-8A3-8A)36-C2(30-A)11-B13A3B2-A12-7(B13A3B15-)B13A3B9-A5-5(B13A3B15-)2(14A3B15-)B13A3B2(15-B13A2BA)7(15-17A)2(15-6A5-6A)12-C39-C31-A27-7(B13AB17-)B13AB10-C6-4(B13AB17-)14AB2(17-15A)3(17-B14A)8(17-15A)2(17-5A5-5A)46-2(A32-)A-12AB18-B12A6(B19-B11A)2B18-3(B11AB19-)12AB19-12AB18-13A4(B19-12A)B19-B11AB7(19-13A)2(19-4A5-4A)116-2B8AB6(21-2B7A2B)3-A17-2B7A2B2-A18-3(2B7A2B21-)AB7A2B19-A-7(2B7A2B21-)11A6(21-2A-5A-2A)2(21-2A-A3-A-2A)119-8B24-7B25-7B9-A15-7B8-A16-7B7-A17-7B6-A9-A8-7B17-A7-7B18-A6-7B19-A5-7B20-A4-2BA4B21-A3-3(2(2BA)B25-)B2A2BAB2(25-BA4BA)25-B2A3BA25-2BA3BA25-7A27-7(3A29-)3A37-C2(30-A)55-B15-A133-C107-2(A31-)A258-A302-C3(30-A)14-B161-2(A31-)A355-2(A32-)A311-A129-C31-A549-2(A32-)A181-A810-C148-A959-C981-
