model
size = 29 32 12, scale = 0.05, origin = -y
material 
  colors = A:#9FC B:#001 C:#FF3 D:#C0C E:#3C0 F:#69F G:#C96 H:#00D I:#900 J:#3CC K:#F39 L:#306 M:#C33 N:#969 O:#6CF
voxels
38-10(11A18-)3A5B3A18-3ABHADB3A18-2ABHFBFGB2A18-ABKA3BNGBA18-ABF5BGBA18-AB7CBA18-BC7BCB18-BJ7CFB18-BL2BJLJ2BIB18-2B2CBEB2C2B18-BH2BEKI2BMB18-B3D2EIMAOB18-11B19-9BA19-9B308-7(A11-A16-)A11-A15-3A10-2A8(14-15A)13-2(17A12-)17A13-15A14-15A15-13A17-11A21-5A105-2(17A12-)17A13-15A6(15-14A)10(14-15A)11-3(21A8-)21A9-19A11-17A13-3A9-3A14-6A3-6A16-11A21-5A76-2(A15-A12-)17A6(13-16A)13-7(15A14-)15A8-4A2-15A2-4A7-17A8-25A4-25A5-4(4A15-4A6-)5A13-5A7-4A13-4A2(9-5A)11-7A3-7A15-11A21-5A24-5A18-5(A15-A12-)2(17A12-)A15-A13-16A13-15A13-17A12-17A13-3(15A14-)15A13-17A7-2(27A2-)2(6A15-6A2-)6A15-6A3-2(4A17-4A4-)3A19-3A4-3A19-3A5-3A17-3A6-4A15-4A7-6A9-6A10-7A3-7A16-3A4-2A21-A5-A17-2(5(A15-A12-)2(17A12-)A15-A4(12-17A)13-2(15A14-)15A13-17A12-17A7-A3-2A15-2A3-A-2A3-2A15-2A3-2(4A4-A15-A4-)2A-2A3-A15-A3-2(2A2-2A23-)2A3-A23-A2(4-2A21-2A)5-2A19-2A6-4A15-4A8-6A7-6A13-4A5-4A18-2A5-2A16-)5(A15-A12-)2(17A12-)A15-A12-17A13-15A13-17A12-17A13-3(15A14-)15A13-17A7-2(27A2-)2(6A15-6A2-)6A15-6A3-2(4A17-4A4-)3A19-3A4-3A19-3A5-3A17-3A6-4A15-4A7-6A9-6A10-7A3-7A16-2A5-2A45-2(A15-A12-)6(17A12-)17A13-7(15A14-)15A9-3A2-15A2-3A8-17A8-25A4-25A5-4(4A15-4A6-)5A13-5A7-4A13-4A2(9-5A)11-7A3-7A15-11A73-2(17A12-)17A13-7(15A14-)3A9-3A9(14-15A)11-3(21A8-)21A9-19A11-17A13-3A9-3A14-6A3-6A16-11A21-5A77-2(15A14-)3(3A9-3A14-)15A3(14-3A9-3A)15-2A9-2A16-3A7-3A16-2A9-2A15-3A9-3A2(14-15A)4(14-3A9-3A)2(14-15A)13-2(17A12-)17A13-3A9-3A14-5A5-5A15-13A17-11A21-5A107-13A3(16-5A3-5A)5(16-4A5-4A)17-2A7-2A18-3A5-3A17-3(3A7-3A16-)2A9-2A16-2A9-2A17-A9-A18-A9-A16-3(3A9-3A14-)2(ABA9-ABA14-)4A7-4A15-13A17-2A7B2A20-7A156-
