model
size = 21 25 31, scale = 0.05, origin = -y
material 
  colors = A:#E00 B:#B00 C:#EEE D:#DDD
voxels
303-3C17-4C17-2(CD)C16-5C17-D2C416-CD2C16-2(DC)2D15-3C-3C14-DC2-3D14-2C2-2CD14-5DC16-5C373-3C18-5C15-2C2-2CD14-C4-2C14-C5-D14-C4-2C14-CA3-CD14-2C2A2C17-2A354-4C16-2C2(DC)15-2D3-CD14-D5-C2(14-D5-D)14-D4-CD14-C4A2C15-4A353-3C17-6C15-2C3-CD3(14-C5-C)14-C4-CD14-CA2-2AC15-B3AB17-BAB353-5C15-3D-DCD14-C2(4-CD14-D)4-2D14-D4-2D14-CA3-A15-B4AB16-B3AB16-2BAB333-3C16-6C15-7C2(14-2C2-3C)14-CA2-CA15-B4-3(B15-B4A)B16-4A353-2(4C17-)A3C16-6A15-2(B5AB14-)2(6AB14-)6A17-3A38-4C16-2(6C15-)7C15-5C268-5A15-6AB13-7AB2(13-8A)14-7A15-4A15-9C11-3C4A3C2(11-2C6A2C)11-2C7AC11-3C4B3C246-2B17-AB4A14-5BA2B13-B7A13-3B2(AB)A13-8A14-ABA3BA15-5A12-2C9AC9-4(C10A2C8-)C7A2B2C13-4B2(18-3B)164-5A15-3A2(BA)13-2ABA3BA13-B3ABAB2A12-2A5BAB12-3(BA)B2A12-2A3BABA14-AB3ABA15-2(BA)12-2(C12AC7-)2(C13AC6-)C12AC7-C10A3C10-2B4A2B2-C10-2B4A2B14-2B3A2B2(14-7B)14-6B2(16-5B)15-6B15-4B2AB13-2B6A13-5BABA13-2AB3ABAB12-2(BA)3B2A12-2AB5AB12-2(BA)3B2A12-2A3(BA)14-4BABA15-2(BA)12-C13A4(C5-C14A)C6-C13AC6-CB10AB2C8-B8AB12-7BAB12-2(B3A)B12-3BABA3B12-B6A2B12-3(BA)3B12-B6A2B12-BA7B12-8AB12-ABA3BABA12-3A2BAB2A12-A8B12-AB2ABAB2A12-A8B12-6AB2A12-A7B14-3ABAB17-3B11-C14AC5-5(C15AC4-)C2B11ABC8-B9AB10-B2A3(BA)2B10-B9AB10-B4AB3A2B10-B8AB11-3(AB)3AB11-9AB11-AB3A2(BA)B11-10A11-2AB3A2(BA)11-2(A3B)2A11-2A2BABA3B11-4B2(AB)2A12-2BA3BA2B12-BA3BAB2A13-BAB2A2B15-3BAB31-C15AC4-C15A3(C3-C16A)C4-C15AC4-CB12AB2C6-B10AB9-7BA4B9-BAB3ABAB2AB10-2BA3BABA2B10-2(3AB)2AB10-ABA5BABA10-3ABAB3ABA10-4BA3BABA10-11A10-2A5BAB2A10-AB2AB6A10-2A8B11-B4ABAB2A12-A8B12-2AB3A2B14-7B15-2(BA)31-6(C16AC3-)2CB13ABC6-12AB8-B3ABAB4AB9-B10AB9-B5A2(BA)2B9-B10AB9-2(B5A)9-B11A9-B3A4(BA)10-8A2-A10-6ABA2-A10-A7B3A10-2(AB)3A2BA11-6BAB2A12-4ABA3B12-2(3BA)14-ABA3B51-C16AC3-C3(16AC2-2C)16AC3-C16AC3-2CB13ABC6-12AB-C6-3BA7BAB8-2ABAB5ABAB8-3BA9B8-2(B3A)3B2A8-BA10BA8-B3AB2(A2B)A9-BA3BA6B9-9A2-A10-2A3BA2B2-B10-4ABAB4A10-BA8B12-A2B2(2AB)12-A7B14-B4A2B15-5B51-C2(16AC2-2C)3(17AC-2C)17AC2-C17AC2-2CB13ABC6-B11AB8-12AB8-A7B3A2B8-AB11A8-4B2(AB)5A8-B12A8-2BA5B2(AB)9-9A-2A10-BA3BABA-2A10-10AB10-B5ABA2B12-8AB12-3AB4A14-6A72-C10A5DAD2-2C10AD5AC2-2C10A3D2(AD)C-2C16A-4C10A2(DA)2D-4C16A-2C-C17AC2-2CB13AB2C5-7B5AB8-2(B5A)B8-13B8-4ABAB2AB3A8-3BA4BABA2B8-BAB2A2B6A8-8B2(AB)9-B11A10-BA9B10-BAB5A2B12-A5BA2B12-5ABAB14-3BA2B16-AB2A73-C10AD5AD2-2C16AC2-2C10A3(DA)DC-2C16A-4C10ADAD3A-C-2C16A-2C-C16A-C2-2C14AB2C4-B2(12AB8-)4BAB5A2B8-AB11A8-ABA3B7A8-12A9-2BA3B6A10-B3AB2A-2AB10-3BAB2A-AB12-6A-AB12-7AB14-7A15-5A93-C3DAD5A2(DA)3D3-CD15AC2-C4DAD5A2(DA)3DC-2C16AD3C2D2(AD)5A5DA-2C-C16A-2C-CDA3D11A-C2-2C15A2C4-B2(12AB8-)3A2(BA)3BA2B8-9ABA2B8-5ABA3BAB9-B6AB3AB10-B3A2(BA)3B10-B5AB2AB12-3(AB)A2B12-8A14-7A15-5A114-C2ADAD11AD3-C16AC3-C4AD11AD3-C17AC2-C2(DA)D9ADADC2-C16A-C2-CD3AD12AC2-C5ABA3BAB5AC3-CB5AB7ABC6-B2A5BAB2AB8-2BA3BAB4AB8-2BA3B2(AB)2AB8-2B2(AB)5AB10-3(BA)3BAB10-3BAB3A3B11-3AB4AB12-2BAB4A14-6A16-4A137-3DAD5A3D2(AD)3-CD9AD3ADAC3-CDA3D5ADA3DAD3-C10AD5AD3-CDA3D5ADA3DADC2-C4AD12AC2-4DAD12AC2-C5AB3ABAB4AC4-CB13ABC6-B2AB5AB2AB8-B6A6B8-B2A3(BA)B2A10-2(BA)B-5B10-2(BA)B-2A2B12-4A-3B14-4ABAB15-2(AB)A17-3A158-2CDAD4ADA5D5-C10AD4AC3-C4AD4A5DADC3-C9AD6AC3-C4AD4A3DA4D3-C16AC3-C2ADAD4A2(DA)3DC3-C5A5BAB4AC4-CB5AB6A2BC6-B2A2(BA)3BAB9-6B5AB10-3(BA)3BAB11-2BAB3A2B12-A5BAB14-3B3A16-2B2A203-2D4A5D7-DCD11ADCD4-2(DA)D4A4DA3D4-CAD7ADAD2A2D4-3DAD4A8D4-C3AD11AC4-3DAD4ADAD3ADC4-C8ABAB4AC4-C2B11A2BC7-8ABAB10-B8AB12-7A2B13-7A15-3ABA244-C5A5D7-3C8AD2A2C5-C2(AD)4A2(DA)3D5-C14AC5-D8A2(DA)3D5-C14AD5-C2(AD)4A5DAD5-C4A3BA3B3AC5-2CB4ABAB3A2BC8-2A3BABA2B12-ABA5B15-A3BA287-D7AC9-3CD7A3C7-2DAD10AD6-CDAD6A3-AC6-C3D6A3-AD6-CA2D6A3-AC6-C3D6A3-AD6-C3AB5A2-2AC6-C12A2C7-CA-A7BC326-5C3D13-7CD11-2C5A3DC3(DC8-C6ADA2-)AC8-C6ADA-2DC8-C2A6B-A2C8-C2AB5ABAC10-2C7B2C367-10CD10-2C7A2C10-2C6AD2(2C10-2C7A)CD10-2C6A2C11-3C5A2C12-8C371-4C3D14-7C14-4C3D2(14-4CDCD)14-6C16-5C395-3C17-2(5C16-)5C17-3C387-
