model
size = 26 29 23, scale = 0.05, origin = -y
material 
  colors = A:#CC9 B:#111 C:#001 D:#222 E:#C96 F:#EEE
voxels
128-C24-2C727-C24-2C399-11B16-8B267-C2(24-2C)23-2C347-13B11-16B314-C2(24-2C)22-3C69-A24-EA24-2A24-C-C24-2C119-16B9-19B7-2DB13-2B338-C49-2C24-2C18-2A23-3A22-D3A19-3CD3A-C17-4CAD-3C16-5CA-3C16-2C3-2C91-21B5-2D5B6-8B325-6A19-E7A4-C13-8A3-2C12-E9A-3C12-10A-2C13-2AD7A16-10A14-2CA2D3A-3A13-3C6A-DAC13-2(3C10AC12-)3C2A2DC2A3D16-10D16-6D2BDB18-2DB2D2B10-22B5-D4B4-4D3-5B303-A18-10A15-12A14-2AE9A-3C10-AE10A2(-2C11-12A)2(-2C10-C12A)13-2(C12AC12-)C11AC2(13-C11AD)14-11AB14-2A2D7AB9-D21B5-DB5-BD4B5-3B13-2BD2B283-4A16-2A-9A4(14-12A)-2C11-12A-2C10-C12A-C11-C12A13-2(C12A2C11-)C11AC-C11-2(C11AD13-)D11AB8-2B4-11AB5-B2-BD7B6A9B8-4B5A3B15-10BD15-3(10B16-)D9B174-6A17-5(12A14-)12A13-C12AC12-C12A-C11-C12A3C11-F11A4C10-11AC-2C10-C11AC13-C11AD13-D11AB7-4B3-11AB4-12B8A9B7-2B8A3B13-12BD14-2(11B15-)D10B15-11B15-D9B16-D2B5-2B50-3A23-3A20-2A-3A16-10A2(14-12A)14-B11A4(14-12A)2C11-C12A-C11-2(C12A4C9-)C11AC-3C9-C12AC12-C11AD14-D10AD7-4B3-11AB4-11B10A8B6-2B10A2B3(13-13B)14-4(11B15-)10B23-4A22-4A18-8A16-10A2(14-12A)14-B11A2(14-12A)13-13A14-11A-C12-C12A2C11-2(C12A4C9-)C12A3C10-C2(11AD14-)11AD7-4B3-11AD4-11B11A2BD4B6-2B11AB12-14B2(13-13B)2(13-D12B)14-2(11B15-)10B24-3A23-3A18-8A16-10A14-12A3-C10-12A-3C10-B11A-2C11-12A2C12-2(12AC13-)12AC12-C12A2C11-2(C12A4C9-)C12A3C10-C12A2C12-11AD14-11AD7-4B3-11AB4-11B11A2BD4B6-2B11AB2(12-14B)4(13-13B)14-11B49-3A23-3A20-2A-2AE4-C11-10A3-2C9-12A3-C10-12A-3C10-2(12A-2C11-)12A14-12A13-2(C12AC12-)C12A2C11-C12AC12-C12A3C10-C12AC12-C11AD13-D11AD7-4B3-11AB4-11B11A7B6-2B11AB12-14B5(13-13B)14-11B15-10B57-2C24-C12-6A6-2C9-12A3-C10-12A-3C10-12A-2C11-12A-C12-12A14-12A13-2(C12AC12-)C12AC13-F11AC13-12A2C11-2(C11AD13-)D11AD7-4B3-11AB4-11B11A7B6-2B10A2B12-3B2(A6BA3B13-2B)2(-6B-3B13-2B)-6B-3B14-B-6B-2B15-11B15-10B32-C2(24-2C)12-5A-A4-2C9-12A3-2C9-12A-C12-3(12A14-)2(12A13-C)4(12AC12-C)11AD13-C11AD13-D11AD7-4B3-11AB4-11B10A8B6-2B10A2B13-11B2D13-11BDB14-10B2(D15-D9B)D15-11B15-10B16-4B3-3B57-2C24-C15-4A17-A-9A6(14-12A)13-3(C12AC12-)C11AC2(13-C11AD)14-11AD8-2B4-3DB7AB5-B2-10B5A9B8-5B3A3BD15-2(9BD16-)D8BD17-D7B18-8B202-3AE2A19-4AE3A18-E7A17-2E8A16-3AD6A16-10A16-2A2D6A13-3C2AD7A13-3C6AB2AC13-2(3C10AC12-)3C2(2A3D)16-A7DBD16-3DBD5B18-7B9-23BD9-D7B2D17-3D3B2D19-6B20-6B21-5B22-3B336-2A24-2A23-D2-A19-2C2D2-A-C17-4CA-A3C16-5C2A3C16-2C3-2C90-16BD4BD5-2DB5-4DB4-3BD509-2A24-EA24-CAC24-2C117-21B5-2B3D10-5BD710-14B10-4BD13BD7-4D10-4B689-8B13-18B8-3B5D10B714-10B14-14B15-3BD4B721-6B20-6B166-
