model
size = 21 30 3, scale = 0.05, origin = -y
material 
  colors = A:#F6C B:#EEE C:#3CF
voxels
3-15A6-A13BA6-AB11ABA6-ABA3C2ACAC2ABA5-2AB2AC2A5CABA4-2AB2(3AC)AC2ABA4-AB4AC2A5CAB2A2-2AB4A2C2ACAC3AB2A-AB3A3B10ABA-AB2AB3A3B7AB3ABA2(B3A)2B6AB2AB4AB3AB2AB5AB2A3(B3A)2B4AB2AB6AB3ABAB4AB2AB5AB2A4B5AB3AB6AB8AB2A-2A2B4A2B5A2B2A3-3A2B4A5B3A6-3A3B4ABA11-4A8(B3ABA14-A)B3ABA14-2A3B2A15-5A2(9-3A)3(6-3A9-3A)5-4A2(9-3A4-5A)9-4A2-2(6A9-5A-)6A6(9-12A)9-6A-5A9-5A3-17A6-12A11-10A9(14-7A)15-5A9-15A6-A13BA6-AB11ABA6-AB2ACAC2A3CABA5-2ABA5C2AC2ABA4-2AB3ACAC3AC2ABA4-AB3A5C2AC3ABA2-2AB4ACAC2A2C4ABA-AB3A3B10ABA-AB2AB3A3B8AB2ABA2(B3A)2B6AB2AB4AB3AB2AB5AB2A3(B3A)B5A2(B2A)2(B3A)BAB4AB2AB5AB2A4B5AB3AB6AB8AB2A-2A2B4A2B5A2B2A3-3A2B4A5B3A6-3A3B4ABA11-4A8(B3ABA14-A)B3ABA14-2A3B2A15-5A6-
