model
size = 20 29 7, scale = 0.05, origin = -y
material 
  colors = A:#DDD B:#FFF C:#EEE D:#AAA E:#FCFAF2
voxels
B18-BC2(18-2C)18-CA18-AC18-CA7(18-2A)18-AB18-BC18-CB18-2B18-BA18-AE18-EB18-2B18-B2A16-2A-2A14-2A2-B2A12-2AB3-B2A10-2AB5-3A8-3A84-C16-C2-D16-D4(2-A16-A)2-D16-D-BA16-AB2A16-2ABA16-ABEA16-AECA16-ACBC16-C3B16-2B2A16-2ABA16-ABAC16-CABE16-EB-A16-A2(2-B16-B)2-2A14-2A2-BCA12-ACB3-ACA10-ACA5-ACB8-BCA7-2B8-2B106-2(A14-A4-)D14-D4-A14-A3-CE14-EC2-BA14-AB3(2-2A14-2A)2(2-BA14-AB)2-EA14-AE2-2A14-2A2(2-BA14-AB)2-2A14-2A2-EA14-AE2-DA14-AD3-B14-B4-A14-A4-BA12-AB4-3A10-3A5-ACB8-BCA7-2DB6-B2D9-B8-B128-A12-A5-AE12-EA4-DA12-AD4-2A12-2A4-CA12-AC2(4-AD12-DA)4-BA12-AB3(4-2A12-2A)2(4-BA12-AB)4-AC12-CA4-2A12-2A2(4-CA12-AC)4-BA12-AB5-B12-B6-2A10-2A6-ACB8-BCA7-C2B6-2BC9-B8-B128-A12-A6-B12-B2(6-2A10-2A)6-EA10-AE6-AB10-BA6-BD10-DB6-BC10-CB3(6-2A10-2A)6-BA10-AB6-2A10-2A6-BC10-CB2(6-2A10-2A)6-BA10-AB6-BD10-D2(B6-BA10-A)B6-ACB8-BCA7-AEB6-BEA9-B8-B169-A10-A8-E10-E8-DA8-AD8-AB2(8-BA)8-AB8-CA8-AC6(8-2A)8-BC8-CB2(8-2A)2(8-BA8-AB)8-BD8-DB8-BC8-CB8-CA8-AC2(8-2A)8-B2A6-2AB8-ABA6-ABA2(8-2A)329-2(C8-C10-)B8-B2(10-A8-A)10-B8-B10-BA6-AB10-AE6-EA10-2A6-2A10-CB6-BC10-CA6-AC11-B6-B46-
