model
size = 23 30 29, scale = 0.05, origin = -y
material 
  colors = A:#E83015 B:#444 C:#AE2626 D:#2D6D4B E:#FEDFE1 F:#FB9966 G:#222 H:#DDD I:#888 J:#777 K:#FFFFFB L:#7DB9DE M:#EEE N:#555
voxels
329-9A13-5(11A12-)11A13-9A15-7A17-5A404-A13-A8-2A11-2A8-3A9-3A8-15A8-2A2(3CE)3C2A8-2A5(EC)E2A8-2AC2(E3C)EC2A2(8-3A9B3A)8-7AB7A9-6AB6A11-5AB5A12-5AB5A15-5A357-2(2A13-2A6-)AE13-2A6-AC13-CA6-AE13-EA6-ACE11-ECA6-AEC11-CEA6-A2C11-2CA2(6-2A2B9-2B2A)6-3A11-3A7-2A11-2A9-A11-A10-2(A11-)5AB5A15-5A310-A17-A4-2A15-2A4-AE15-2A4-AC15-CA4-AE15-E3(A4-AC15-C)A4-AE15-EA2(4-2AB13-B2A)4-3A13-3A5-2A13-2A7-A13-A8-2A11-2(2A9-)2A12-4AB4A16-5A264-3(A17-A4-)AC16-3(A4-AE15-EA4-AC15-C)2(A4-A2B13-2B)A2(4-2AB13-B2A)5-AB13-BA6-ABA11-ABA7-2(3A9-)6AB6A12-9A262-A17-2A2-AE17-CA2-AC17-CA2-AE17-E3(A2-AC17-C)A2-AE17-E2(A2-AC17-C)A2(2-2AB15-B2A)2-2A17-2A3-A17-A4-A17-A5-2AB11-B2A6-2ABA9-AB2A2(7-4A)10-5AB5A15-5A240-A19-4(A2-AC17-CA2-AE17-E)A2-AC17-C2(A2-AB17-B)2(A2-A19-)A3-A17-A4-A17-A5-3AB9-B3A6-3ABA7-AB3A8-6AB6A12-9A237-2A19-3A2(E19-E3(2AC19-C)2A)E19-E3AB17-B4AB17-B2A-A19-A2-A19-A3-A17-A4-A17-A5-A15-A6-4AB7-B4A8-6AB3AB2A12-9A214-2A19-3A5(E19-E2AC19-C2A)B19-B2AB19-B3A19-2A-A19-A2-2A17-2A3-A17-A4-2A15-2A5-3A11-3A8-3ABA3-AB3A12-4AB4A17-3A171-A21-3A19-3A3(C19-C2A)E19-E3(2AC2-G13-G2-C)2AE19-E2(2AC19-C)2(2AB19-B)3A19-4A19-2A-2A17-2A2-2A17-2A3-2A15-2A4-4A11-4A6-5AB3-B5A10-3A2(BA)B3A15-5A32-D7(21-2D)A19-ADA3(E19-E2AC19-C2A)E2-G13-G2-E2AC19-C2AE19-E2AC19-C2(2AB19-B)3A19-4A19-2A-2A17-2A2-2A17-2A3-2A15-2A4-4A11-4A6-4A7-4A10-4A3B4A14-7A18-3D10-D7(21-2D)A19-ADAC19-C2AE19-E3(2AC19-C)2AE19-E2AC2-G13-G2-2(C2AC19-)C2AE19-E4(2AB19-B)A-AB17-BA2-AB17-BA3-AB15-BA4-2A2B11-2B2A6-2A2B7-2B2A10-2A7B2A14-3AD3A18-3D148-A21-3A19-3A3(E19-E2AC19-C2A)E2-G13-G2-E2AC19-C2AE19-C2AC19-C2(2AB19-B)3A19-4A19-2A-2A17-2A2-2A17-2A3-2A15-2A4-4A11-4A6-4A7-4A10-4A3B4A14-7A18-3D171-2A19-3A3(C19-C2A)E19-E2(2AC19-C)2AC2-G13-G2-C2AE19-E2(2AC19-C)3A2(B17-B4A)19-2A-A19-A2-2A17-2A3-A17-A4-2A15-2A5-3A11-3A2(7-4A)10-3A2(BA)B3A15-5A193-2A21-AE19-3A2(C19-C2AE19-E2A)C19-C2AE2-G13-G2-C2AC19-C2AE19-E2AC19-C3AB17-B2A-AB17-B2(A2-A19-)A3-A17-A4-A17-A5-A15-A6-3A11-3A8-3AB5-B3A12-4AB4A17-3A218-2A17-2A2-AE17-E3(A2-AC17-C)A2-AE17-EA2-AC-G13-G-2(CA2-AC17-)CA2-AE17-EA2(2-2AB15-B2A)2(2-2A17-2A)3-2A15-2A4-2A15-2A5-A15-A6-3A11-3A8-2A2(B3A)B2A12-9A262-5(A17-A4-)A-G13-G-3(A4-A17-)2(A4-AB15-B)2(A4-A17-)A4-2A15-2A5-A15-A7-2AB9-B2A8-2AB9-B2A10-5AB5A14-7A355-A17-A4-A-G13-G-3(A4-A17-)A4-A3B11-3BA4-2A2B11-2B2A2(4-3AB11-B3A)5-2AB11-B2A7-AB11-BA2(9-2A)10-2A9-2A12-9A17-3A382-G13-G75-DJI2B9-2BIJD4-D2A2B9-2B2AD5-3A11-3A6-3A11-3A7-2A11-2A9-A11-A10-2A9-2A11-11A13-9A152-4(H-)H13-11H12-11H13-4HF4H15-2H3F2H17-2(5F18-)5F14-4G-3F-4G9-G2KLNG3FG2KLNG8-G2K2LG3FG2K2LG8-G4KG3FG4KG9-6GF6G15-3G15-5H4-5H6-D2(JI)9B2(IJ)D4-DE3A9B3AED6-3A4-A4-3A8-3A4-A4-3A9-2(2A4-A4-2A10-)2A4-A4-2A11-11A14-7A177-3(H-)H14-11H13-2H5G2H16-3(5F18-)5F14-4G-3F-4G9-2(G4-G3FG4-G8-)G4-G3FG4-G9-6GF6G15-3G15-4H5-4H7-D3(JI)J3I3(JI)JD4-2(DE)D9A2(DE)D8-3(11A12-)11A13-9A14-9A221-4(H-)H15-3HF3H18-3F19-5F18-5F19-2(3F20-)3F21-F105-D2(JI)J2I3J2I2(JI)JD4-3(DE)7D3(ED)13-M45-M23-M22-M20-2M274-3F19-5F19-3F20-3F21-F151-D3(IJ)5I3(JI)D4-2D2(ED)E5D2(ED)E2D403-2(3F20-)3F197-D2(IJ)I5J2(IJ)ID6-2D2(ED)5E2(DE)2D404-3F20-3F220-D2IJIJ5IJIJ2ID6-3DEDE5DEDE3D651-D2IJI5JIJ2ID8-3DED5EDE3D653-D2IJ5IJ2ID10-3DE5DE3D655-2DI5JI2D12-3D5E3D657-9D14-9D237-
