model
size = 23 30 29, scale = 0.05, origin = -y
material 
  colors = A:#EBB471 B:#444 C:#222 D:#BC9F77 E:#6E552F F:#FB9966 G:#AA8F6B H:#888 I:#777 J:#855B32 K:#FFFFFB L:#7DB9DE M:#555
voxels
329-9A13-5(11A12-)11A13-9A15-7A17-5A404-A13-A8-2A11-2A8-3A9-3A8-15A8-2A2(3DG)3D2A8-2A5(GD)G2A8-2AD2(G3D)GD2A2(8-3A9B3A)8-7AB7A9-6AB6A11-5AB5A12-5AB5A15-5A357-2(2A13-2A6-)AG13-2A6-AD13-DA6-AG13-GA6-ADG11-GDA6-AGD11-DGA6-A2D11-2DA2(6-2A2B9-2B2A)6-3A11-3A7-2A11-2A9-A11-A10-2(A11-)5AB5A15-5A310-A17-A4-2A15-2A4-AG15-2A4-AD15-DA4-AG15-G3(A4-AD15-D)A4-AG15-GA2(4-2AB13-B2A)4-3A13-3A5-2A13-2A7-A13-A8-2A11-2(2A9-)2A12-4AB4A16-5A264-3(A17-A4-)AD16-3(A4-AG15-GA4-AD15-D)2(A4-A2B13-2B)A2(4-2AB13-B2A)5-AB13-BA6-ABA11-ABA7-2(3A9-)6AB6A12-9A262-A17-2A2-AG17-DA2-AD17-DA2-AG17-G3(A2-AD17-D)A2-AG17-G2(A2-AD17-D)A2(2-2AB15-B2A)2-2A17-2A3-A17-A4-A17-A5-2AB11-B2A6-2ABA9-AB2A2(7-4A)10-5AB5A15-5A240-A19-4(A2-AD17-DA2-AG17-G)A2-AD17-D2(A2-AB17-B)2(A2-A19-)A3-A17-A4-A17-A5-3AB9-B3A6-3ABA7-AB3A8-6AB6A12-9A237-2A19-3A2(G19-G3(2AD19-D)2A)G19-G3AB17-B4AB17-B2A-A19-A2-A19-A3-A17-A4-A17-A5-A15-A6-4AB7-B4A8-6AB3AB2A12-9A214-2A19-3A5(G19-G2AD19-D2A)B19-B2AB19-B3A19-2A-A19-A2-2A17-2A3-A17-A4-2A15-2A5-3A11-3A8-3ABA3-AB3A12-4AB4A17-3A171-A21-3A19-3A3(D19-D2A)G19-G3(2AD2-C13-C2-D)2AG19-G2(2AD19-D)2(2AB19-B)3A19-4A19-2A-2A17-2A2-2A17-2A3-2A15-2A4-4A11-4A6-5AB3-B5A10-3A2(BA)B3A15-5A32-E7(21-2E)A19-AEA3(G19-G2AD19-D2A)G2-C13-C2-G2AD19-D2AG19-G2AD19-D2(2AB19-B)3A19-4A19-2A-2A17-2A2-2A17-2A3-2A15-2A4-4A11-4A6-4A7-4A10-4A3B4A14-7A18-3E10-E7(21-2E)A19-AEAD19-D2AG19-G3(2AD19-D)2AG19-G2AD2-C13-C2-2(D2AD19-)D2AG19-G4(2AB19-B)A-AB17-BA2-AB17-BA3-AB15-BA4-2A2B11-2B2A6-2A2B7-2B2A10-2A7B2A14-3AE3A18-3E148-A21-3A19-3A3(G19-G2AD19-D2A)G2-C13-C2-G2AD19-D2AG19-D2AD19-D2(2AB19-B)3A19-4A19-2A-2A17-2A2-2A17-2A3-2A15-2A4-4A11-4A6-4A7-4A10-4A3B4A14-7A18-3E171-2A19-3A3(D19-D2A)G19-G2(2AD19-D)2AD2-C13-C2-D2AG19-G2(2AD19-D)3A2(B17-B4A)19-2A-A19-A2-2A17-2A3-A17-A4-2A15-2A5-3A11-3A2(7-4A)10-3A2(BA)B3A15-5A193-2A21-AG19-3A2(D19-D2AG19-G2A)D19-D2AG2-C13-C2-D2AD19-D2AG19-G2AD19-D3AB17-B2A-AB17-B2(A2-A19-)A3-A17-A4-A17-A5-A15-A6-3A11-3A8-3AB5-B3A12-4AB4A17-3A218-2A17-2A2-AG17-G3(A2-AD17-D)A2-AG17-GA2-AD-C13-C-2(DA2-AD17-)DA2-AG17-GA2(2-2AB15-B2A)2(2-2A17-2A)3-2A15-2A4-2A15-2A5-A15-A6-3A11-3A8-2A2(B3A)B2A12-9A262-5(A17-A4-)A-C13-C-3(A4-A17-)2(A4-AB15-B)2(A4-A17-)A4-2A15-2A5-A15-A7-2AB9-B2A8-2AB9-B2A10-5AB5A14-7A355-A17-A4-A-C13-C-3(A4-A17-)A4-A3B11-3BA4-2A2B11-2B2A2(4-3AB11-B3A)5-2AB11-B2A7-AB11-BA2(9-2A)10-2A9-2A12-9A17-3A382-C13-C75-EIH2B9-2BHIE4-E2A2B9-2B2AE5-3A11-3A6-3A11-3A7-2A11-2A9-A11-A10-2A9-2A11-11A13-9A152-4(C-)C13-11C12-11C13-4CF4C15-2C3F2C17-2(5F18-)5F14-4C-3F-4C9-C2KLMC3FC2KLMC8-C2K2LC3FC2K2LC8-C4KC3FC4KC9-6CF6C15-3C15-5C4-5C6-E2(IH)9B2(HI)E4-EJ3A9B3AJE6-3A4-A4-3A8-3A4-A4-3A9-2(2A4-A4-2A10-)2A4-A4-2A11-11A14-7A177-3(C-)C14-11C13-9C16-3(5F18-)5F14-4C-3F-4C9-2(C4-C3FC4-C8-)C4-C3FC4-C9-6CF6C15-3C15-4C5-4C7-E3(IH)I3H3(IH)IE4-2(EJ)E9A2(EJ)E8-3(11A12-)11A13-9A14-9A221-4(C-)C15-3CF3C18-3F19-5F18-5F19-2(3F20-)3F21-F105-E2(IH)I2H3I2H2(IH)IE4-3(EJ)7E3(JE)13-C45-C23-C22-C20-2C274-3F19-5F19-3F20-3F21-F151-E3(HI)5H3(IH)E4-2E2(JE)J5E2(JE)J2E403-2(3F20-)3F197-E2(HI)H5I2(HI)HE6-2E2(JE)5J2(EJ)2E404-3F20-3F220-E2HIHI5HIHI2HE6-3EJEJ5EJEJ3E651-E2HIH5IHI2HE8-3EJE5JEJ3E653-E2HI5HI2HE10-3EJ5EJ3E655-2EH5IH2E12-3E5J3E657-9E14-9E237-
