model
size = 28 30 30, scale = 0.05, origin = -y
material 
  colors = A:#563F2E B:#FB9966 C:#E83015 D:#FFF E:#EDEDED F:#7DB9DE G:#222 H:#EEE I:#555 J:#DDD
voxels
293-2B25-4B24-4B25-2B937-2C3(24-4C)24-2C756-2C4(24-4C)24-2C784-2C2(24-4C)17(24-2C784-2C24-4C)24-2C784-CE24-E2CE24-EC178-8G42-2(2A3(-A)-)2A6-24A4-24A5-22A7-20A9-7A4B7A12-4A6B4A17-8B19-2(10B18-)10B19-8B20-8B21-6B13-8C-6B-8C4-8C2-4B2-8C2-2C5(8-2C4B2C8-4C)8-2C4B2C8-2C2-11C2B11C4-8C-6C-8C14-4C14-8A8-8A3-10A6-10A3-8A8-8A62-2(2A3(-A)-)2A6-24A4-24A5-22A7-20A9-7A4B7A12-4A6B4A17-8B19-2(10B18-)10B19-8B20-8B21-6B13-8C-6B-8C4-8C2-4B2-8C2-2C7DE2C4B2C7DE4C2DH2FHDE2A4B2C2DH2FHDE4C2DF2IFDE2A4B2C2DF2IFDE4C2DFIJFDE2A4B2C2DFIJFDE4C2DH2FHDE2A4B2C2DH2FHDE4C8E2A4B2C8E2C2-10CA2BA2C7AC4-8C-C4AC-8C14-4C14-8A8-8A3-10A6-10A3-8A8-8A63-4(A-)2A4(-A)9-20A7-22A7-20A9-18A11-6A4B6A17-6B21-8B19-2(10B18-)10B19-8B21-7B21-6B13-8C2-4B2-8C4-8C2-4B2-8C2-2C5(8-2C4B2C8-4C)8-2C4B2C8-2C2-11C2B11C4-8C-6C-8C14-4C15-6A10-6A5-8A8-8A5-6A10-6A64-4(A-)2A4(-A)10-18A9-20A9-18A11-16A14-3A2-2B-4A20-5B22-7B19-2(10B18-)10B19-8B21-6B22-6B23-6(4B24-)4B25-2B128-6A10-6A121-16A11-18A11-16A14-12A21-2B25-4B23-6B21-2(8B20-)8B21-2(6B22-)6B23-2(4B24-)4B25-3(2B26-)2B328-14A17-8A22-4A25-2B25-4B23-6B21-2(8B20-)8B21-6B23-4B25-4(2B26-)2B502-2B25-4B23-6B21-8B20-8B21-6B22-6B23-4B25-2B26-2B614-2B25-4B23-6B22-6B23-4B24-4B25-2B433-
