model
size = 28 30 30, scale = 0.05, origin = -y
material 
  colors = A:#222 B:#FB9966 C:#FFF D:#BBB E:#7DB9DE F:#EEE G:#555 H:#777 I:#DDD
voxels
293-2B25-4B24-4B25-2B937-2A3(24-4A)24-2A756-2A4(24-4A)24-2A784-2A2(24-4A)17(24-2A784-2A24-4A)24-2A784-AH24-H2AH24-HA178-8A42-2(2A3(-A)-)2A6-24A4-24A5-22A7-20A9-7A4B7A12-4A6B4A17-8B19-2(10B18-)10B19-8B20-8B21-6B13-8A-6B-8A4-8A2-4B2-8A2-2A5(8-2A4B2A8-4A)8-2A4B2A8-2A2-11A2B11A4-8A-6A-8A14-4A14-8A8-8A3-10A6-10A3-8A8-8A62-2(2A3(-A)-)2A6-24A4-24A5-22A7-20A9-7A4B7A12-4A6B4A17-8B19-2(10B18-)10B19-8B20-8B21-6B13-8A-6B-8A4-8A2-4B2-8A2-2A7CD2A4B2A7CD4A2CF2EFCD2A4B2A2CF2EFCD4A2CE2GECD2A4B2A2CE2GECD4A2CEGIECD2A4B2A2CEGIECD4A2CF2EFCD2A4B2A2CF2EFCD4A8D2A4B2A8D2A2-11A2B11A4-8A-6A-8A14-4A14-8A8-8A3-10A6-10A3-8A8-8A63-4(A-)2A4(-A)9-20A7-22A7-20A9-18A11-6A4B6A17-6B21-8B19-2(10B18-)10B19-8B21-7B21-6B13-8A2-4B2-8A4-8A2-4B2-8A2-2A5(8-2A4B2A8-4A)8-2A4B2A8-2A2-11A2B11A4-8A-6A-8A14-4A15-6A10-6A5-8A8-8A5-6A10-6A64-4(A-)2A4(-A)10-18A9-20A9-18A11-16A14-3A2-2B-4A20-5B22-7B19-2(10B18-)10B19-8B21-6B22-6B23-6(4B24-)4B25-2B128-6A10-6A121-16A11-18A11-16A14-12A21-2B25-4B23-6B21-2(8B20-)8B21-2(6B22-)6B23-2(4B24-)4B25-3(2B26-)2B328-14A17-8A22-4A25-2B25-4B23-6B21-2(8B20-)8B21-6B23-4B25-4(2B26-)2B502-2B25-4B23-6B21-8B20-8B21-6B22-6B23-4B25-2B26-2B614-2B25-4B23-6B22-6B23-4B24-4B25-2B433-
