model
size = 24 17 16, scale = 0.05, origin = -y
material 
  colors = A:#390 B:#CF0 C:#008 D:#3CF E:#DC6A41 F:#F6C G:#0C6 H:#FF3
voxels
120-A290-5A8-5A5-2A3-2A6-2(2A3-)2A5-2A4-2A5-2A2-A7-A4-A7-A-2A7-6A7-2A-A7-A4-A7-A2-2A5-2A4-2A5-2A-2ADA3-4A2-4A3-2AD9AC2A2-2AF8A-2AE2AH3A4-6AE2A3-7A6-2AC4A5-2AC2A8-2AG2A7-3A10-3A9-A12-A10-B12-B9-3B10-3B9-B12-B101-13(A22-A384-)A22-A288-
