model
size = 31 29 22, scale = 0.05, origin = -y
material 
  colors = A:#020 B:#FF3 C:#F60 D:#777 E:#AAA
voxels
416-5B863-5B57-2(5A26-)5A768-4(2A5-2A22-)2A5-2A23-7A25-5A705-A9-A20-A9-A19-2A9-2A19-2(A9-A20-)2A7-2A21-2A5-2A23-7A27-A644-5(A11-A18-)A11-A19-A9-A21-A7-A23-7A634-3D2(3-A13-A10-A2B3-A13-A10-BAB)3-A13-A10-A2B4-2(A11-)3A4-2(A11-)ABA5-A9-A12-BAB6-2A5-2A13-BAB8-5A15-3A28-3E554-5D2-A13-A3-3D2(3-5A2-A13-A3-A2B3-5A2-A13-A3-BAB)3-5A2-A13-A3-A2B3-5A3-A11-A4-3A3-5A3-A11-A4-ABA3-5A4-2A7-2A5-BAB3-5A6-7A7-BAB3-5A20-3A3-5E20-3E529-8D15-D-5D4(-8A15-A-5A)2(-7A-A13-A2-5A)-7A2-A11-A3-5A-7A3-A9-A4-5A-7A4-2(2A5-)5A-7A6-5A7-5A-7E18-5E528-8D15-8D8A3(15-16A)15-15A2(-A13-A-14A)2-A11-A2-14A3-A9-A3-14A4-2A5-2A4-14A6-5A6-7A7E17-7E527-8D7-A7-8D8A3(15-16A)15-15A2(-A13-A-14A)2-A11-A2-14A2-2A9-2A2-14A4-2A5-2A4-14A6-5A6-7A7E8-B8-7E5-C20-C9-C20-C470-5D-D15-8D4(-5A-A15-8A)2(-5A2-A13-A-7A)-5A3-A11-A2-7A-5A4-A9-A3-7A-5A2(5-2A)4-7A-5A7-5A6-7A-5E18-7E36-C20-C9-2C18-2C10-C18-C410-3D2-D15-D-5D2(3-2BA2-A15-A-5A3-BAB2-A15-A-5A)3-2BA3-A13-A2-5A3-3A3-A13-A2-5A3-ABA4-A11-A3-5A3-BAB5-A9-A4-5A3-BAB6-2(2A5-)5A3-3A8-5A7-5A3-3E20-5E100-C18-C416-B13-B3-3D2(10-A13-A3-2BA10-A13-A3-BAB)10-A13-A3-2B2(A11-)A4-3A2(11-A)4-ABA12-2A7-2A5-BAB14-7A7-BAB28-3A28-3E101-C18-C11-C18-C385-B13-B4(16-A13-A)17-A11-A18-A11-A19-A9-A21-2A5-2A24-5A205-C18-C385-BA11-AB17-4(A11-A18-)A11-A19-A9-A21-A7-A23-7A204-C18-C11-C18-C385-B2A9-2AB18-A9-A19-2A9-2A19-2(A9-A20-)B9-A21-A7-A23-7A27-A176-C18-C11-C18-C50-C2-C362-B4A5-4AB19-AB5-2A22-B7-A22-2A5-2A21-B2A5-B2A21-3ABA2B2A23-7A143-C16-C12-2C16-2C2(11-C18-C)81-C2-C362-B13AB20-B2(A-)B24-B2(A-)B-B23-B-BA-2B-A24-2(AB)A175-C16-C13-C16-C175-C2-C363-B11AB23-A-B27-B2(-A)28-A146-2(C16-C13-)C16-C204-3C2-3C22-2C6-2C20-2C8-2C18-2C10-2C7(17-C12-C)16-2C12-2C14-2CB11AB-2C8(13-C16-C)636-B9AB889-2B5A2B507-
