model
size = 11 32 4, scale = 0.05, origin = -y
material 
  colors = A:#333 B:#DDD C:#222 D:#444 E:#555 F:#666 G:#777 H:#EEE I:#888 J:#999 K:#CCC L:#FFF M:#BBB N:#AAA O:#06C P:#111 Q:#CF6
voxels
9-C2-3D2E3D2-DE2ID5C-FIF2G5C-EAD2CAC2AC-2E5FD2C2(-E7-AC)-D7-2A-2(E7-A2-)E7-9(A10-)AO2-6CA4-6AQA5-A3-A88-C47-C5AC4-7A5(4-JH3BHG)4-I2-B2-2(G4-I5B)G70-6CA4-8A5-A3-A113-DE2ID5C-FIF2G5C-EAD2CAC2AC-2E5FD2C-ENL3HLIAC-EJH3BHGAC-DJH3BHG2A3(-EJH3BHGAC)-FI4BH4(GAC-FI5B)GAC-FIBK3BGAC-FI2B2KBFAC-FI2(BK)BGAC-FI3KMBFAO-G6CA2C-G8AC-F2(EDAD)C-FEA2DA3DC-2EAD2ADEDC2-E2A3DED54-C10-C2-J3D2E3DA-DE2ID5C-FIF2G5C-EAD2CAC2AC-2E5FD2C-ENL3HLIAC-EJH3BHGAC-DJH3BHG2AI3(EJH3BHGAC-)FI4BH4(GAC-FI5B)GAC-FIBK3BGAC-FI2B2KBFAC-FI2(BK)BGAC-FI3KMBF2A-G6CA2C-G8AC-F2(EDAD)C-FEA2DA3DC-2EAD2ADEDC-2E2A3DEDP9-AC9-J10-M10-G9-CEC8-CGC-
