model
size = 28 28 14, scale = 0.05, origin = -y
material 
  colors = A:#111
voxels
33-A841-A27-A-A25-2(A-)A23-5A22-8(7A21-)7A496-3A25-3A4-A20-2A4-2A20-4A-3A19-10A18-10A19-9A19-8A19-9A2(20-8A)2(21-7A)384-2(A27-)2A25-2A26-2A5-A20-A9-A16-3A-A4-4A15-3A3-2(A-)4A14-4A3-A-6A-A11-4A-A-12A9-4A-14A9-20A9-15A-2A10-12A2-A14-11A2-A15-7A22-6A300-A82-A27-2A26-2A25-2A9-A15-3A9-2(2A14-4A8-)2A5-A8-4A8-5A-3A7-5A4-A-11A6-5A3-14A7-5A-13A10-19A10-16A13-10A2-3A13-7A6-A15-5A24-4A300-A27-A26-3A25-2A26-2A2(24-4A)10-A13-5A8-A8-2A4-4A10-A7-2A5-3A9-12A4-4A9-10A5-5A5-A-10A7-4A4-A-10A8-4A2-A2-10A9-3A2-2(A-)9A11-4A-11A13-3A-9A17-9A22-5A24-A216-2(A27-)A26-2A24-2(3A25-)3A2(24-4A)21-A3-3A20-2A4-2A13-A3-A-4A3-2A12-3(A-)5A3-4A10-A-8A5-3A9-A-8A6-4A6-A2-6A9-4A7-A-6A10-3A2-2(A-)7A13-3A4-6A16-3A-6A19-8A22-6A25-A-A157-A54-2(2A24-A-)A25-A-A25-3A3(24-4A)21-2A2-3A21-3A-4A21-2A2-3A20-2A3-4A18-3A4-3A15-5A5-3A14-4A8-2A12-4A11-2A10-4A13-A9-3A15-2A7-3A17-3A2-6A18-9A21-6A23-5A25-2A129-2(A26-2A26-)A26-2A25-3A25-4A24-4A25-2A23-2A2-2A23-A2-3A21-2A3-2A21-A4-2A18-A-2A5-A16-3A9-A13-3A23-4A13-A10-3A24-3A16-A7-3A18-2A5-3A19-3A2-3A22-6A23-4A100-A27-A54-A25-3A25-2A25-3A25-4A25-2A26-2A2(27-A)24-2(A3-A23-)A4-A71-A27-A2(25-2A)26-A18-2A5-3A19-3A4-A21-4A-2A22-5A24-3A45-A108-3A25-4(2A26-)A28-A322-A19-A7-A20-A5-A21-3A2-2A22-5A25-2A127-2A26-A26-2A27-A26-A456-A5-A22-A4-A23-4A24-3A100-2A25-2A26-A568-A28-A2-A25-2A45-A27-A723-
