model
size = 28 28 14, scale = 0.05, origin = -y
material 
  colors = A:#040404 B:#04052D C:#000F5B
voxels
33-C841-C27-C-C25-B-C-B23-3BCB22-C2BC3B2(21-2BA4B)21-B2A4B21-B3A3B21-AB2A2BA21-B4ABA21-7A21-4AB2A496-BCB25-CBC4-B20-BC4-2B20-4B-3B19-A9B18-A4B3ABA19-2(A2B)3A19-2(A2B)2A19-9A2(20-8A)2(21-7A)384-2(C27-)2C25-2B26-2B5-C20-C9-B16-3B-B4-4B15-3B3-2(B-)4B14-A3B3-B-B2ABAB-B11-A3B2(-B)2(3AB)3A9-A3B-B7AB5A9-A5B14A9-15A-2A10-12A2-A14-11A2-A15-7A22-6A300-C82-C27-2C26-CB25-2B9-B15-3B9-BA14-4B8-BA14-BA2B8-2A5-A8-BA2B8-3A2B-B2A7-BA3B4-A-11A6-2A3B3-B13A7-5A-13A10-19A10-2AB13A13-10A2-3A13-7A6-A15-5A24-4A300-C27-C26-3C25-BC26-2B24-C3B24-4B10-B13-5B8-B8-2A4-4B10-B7-2A5-A2B9-B11A4-A3B9-10A5-A4B5-A-10A7-3AB4-A-10A8-4A2-A2-10A9-3A2-2(A-)9A11-4A-11A13-3A-9A17-9A22-5A24-A216-2(C27-)C26-2C24-2(C2B25-)3B24-4B24-BA2B21-A3-2AB20-2A4-AB13-A3-B-4A3-AB12-A-B-A-5A3-4B10-A-8A5-B2A9-A-8A6-4A6-A2-6A9-4A7-A-6A10-B2A2-2(A-)7A13-3A4-6A16-3A-6A19-8A22-6A25-A-A157-C54-2C24-C-2C24-B-C25-B-B25-2BC24-4B24-C3B24-4B21-2A2-BAB21-3A-BA2B21-2A2-A2B20-2A3-4B18-3A4-3A15-5A5-3A14-4A8-2A12-4A11-2A10-4A13-B9-3A15-2A7-3A17-3A2-6A18-9A21-6A23-5A25-2A129-2(C26-2C26-)B26-2B25-C2B25-3BC24-4B25-2B23-2A2-2B23-A2-3B21-2A3-2B21-A4-2B18-A-2A5-B16-3A9-B13-3A23-4A13-A10-3A24-3A16-A7-3A18-2A5-3A19-3A2-3A22-6A23-4A100-C27-C54-C25-3C25-CB25-C2B25-4B25-2B26-C2(B27-)C24-2(A3-B23-)A4-B71-A27-A2(25-2A)26-A18-2A5-3A19-3A4-A21-4A-2A22-5A24-3A45-C108-3C25-4(2C26-)C28-C322-A19-A7-A20-A5-A21-3A2-2A22-5A25-2A127-2C26-C26-2C27-C26-C456-A5-A22-A4-A23-4A24-3A100-2C25-2C26-C568-A28-A2-A25-2A45-C27-C723-
