model
size = 28 28 9, scale = 0.05, origin = -y
material 
  colors = A:#222 B:#F9F C:#CF9 D:#111 E:#CFC F:#CF6 G:#777 H:#444 I:#E00 J:#EEE K:#39C L:#30C
voxels
161-4(2F26-)2F572-F26-2F12-C12-3F12-4C8-4F12-C2AC8-4F13-2(CAC8-3F14-)CA2C7-3F14-CA2C6-4F15-C8-4F15-C488-C26-CHC11-CE10-2CHAC11-2C3E7-CH2A2(C11-CA2HE6-CH3A)C11-CA2HE6-CH2AC12-CA2H2E5-CH2AC12-CA3HE4-2CH2AC12-CA3H2E3-C2H2AC13-CH3E4-C3HAC13-CHE6-5C14-3E457-5E9-E3G8-3E2D13-D3G6-EG2D15-D2GE4-2EGD16-2(2DGE4-EGD17-)2DG2E3-EGD17-2D2GE-K2EGD17-2D2GE2KE2GD17-2D3GK2E2GD17-2DG3E-E3GD16-2GE4-E4GE13-E3GE4-7E13-3E89-2J23-J288-J13-J11-4DB9-2BIB8-2B3D13-DI2B6-BI2D15-D2IB4-B2ID17-2(DIB4-BID18-)D2IB3-BID18-D2IB-KB2ID18-D2IL2KL2ID18-D3IKB3ID17-2DI3B-B3ID16-BIB2-B-BIB2IB13-2B2IB2(-2B)-4B13-3B2-3(2B-B24-)2BJLBJ21-JLJ-2B22-2B2-3B21-2B3-2B20-3B3-3B18-3B5-3B16-3B7-6B8-6B9-8B2J8B12-6B2J7B15-4B2J5B20-B2KB19-J13-J11-4DA9-4A8-2A3D13-D3A6-2A2D15-D3A4-3AD17-2(D2A4-2AD18-)D3A3-2AD18-D3A-K3AD18-D3A2K3AD18-D3AK4AD17-2D4A-4AD16-3A2-A-6A13-5A2(-2A)-4A13-3A2-3(2A-A24-)2(2AJ)21-JAJ-2A22-2A2-3A21-2A3-2A20-3A3-3A18-3A5-3A16-3A7-6A8-6A9-18A12-15A15-11A20-4A45-4DE9-4E8-2E3D13-DG2E6-EG2D15-D2GE4-2EGD17-3(DGE4-EGD18-)DG2E-K2EGD18-D2GE2KE2GD18-D2GE-E3GD17-2D2GE2-E3GD16-3G4-4EGE13-E3GE7-4E13-4E88-2J23-J315-2C25-C2HC11-3C9-C2HAC11-C2H2C7-CH2A2(C11-C3HC6-CH3A)C11-2(C3HC6-CH2AC12-)C3H2C4-C2H2AC12-C4HC3-2C2H2AC13-4HC4-3CHAC13-C2HC8-2C14-3C486-2F25-3F13-2F10-3F2(13-3F8-4F)13-2(3F8-3F14-)3F7-4F14-4F6-4F14-4F8-2F15-2F452-
