model
size = 32 14 6, scale = 0.05, origin = -y
material 
  colors = A:#F60 B:#777 C:#888 D:#444 E:#222 F:#F90 G:#0CF H:#3CF I:#6CF J:#FFF K:#6FF L:#D00 M:#AAA N:#EEE O:#040 P:#080 Q:#070 R:#111 S:#F03 T:#FF9 U:#FF0 V:#A00 W:#0B0 X:#963 Y:#9CF Z:#CFF Aa:#FF6 Ab:#555 Ac:#0A0 Ad:#0CC Ae:#E00
voxels
130-E25-2E3-E-E23-4E3-E24-4E29-2E4-2E29-4E24-E3-4E23-E-E3-2E25-E386-B30-3B28-2B-3B24-3B321-B30-3B28-3BKB26-BMBE2K2B22-2B2ME-3E24-3E3-3B10A2-10A3B3-4B2A6-2A2-2A6-2A4B-5B22A10B8A2FA2F9A10B7A3F2(AF)8A10B6A4FAF2AF7A10B6A2F2(AF)2AF7A10B6A4FAF2AF7A10B6A4FA2FAF7A10B6A4FAF2AF7A6BK3B7A3F2(AF)8A3BS2B2K2B8A2FA2F9A2BSMB-B2KB22AB2MB3-2B-22A-2B4-3B10A2D10A3B3-B4C20D4CB-B5CD3WJ3B2R2B2R3BJWD5C2B5CDAcX2PJ2DL4VL2AbJPAcD5C2B5CDPOPXPJD4LAeLDJPXPD5C2B5CD2(QO)2QJDL2NLDJ2QOQD5C2B5CDY2(OI)2GHG2L2H2TUOUD5C2B5CDIOIGI2(2G2I)H2T2UD5C2B5CD6GI4GI3HTAaUD5C2B5CD2G2I3HG3H3I2HTAaD5C2B5CD3N2HI5GHG5ND5C2B5CDY3JZJAd7GY2JZD4CMBE3CBC20DCB3ME-3E-2A3R9A2(-A)-3A-3E3-3B22A3B3-4BA20-A4B-5BA20-A7BK2BA20-AB2E3B2(KB)A20-AC3E3BK2BA20-AC3E6BA20-AB2E4B2CBA20-A6B4CA20-A2BS3B4CA20-A2(BS)3B2CBA20-A2BS7BA20-A5B-4BA20-A4B3-2B-22A-2B2-
