model
size = 32 13 6, scale = 0.05, origin = -y
material 
  colors = A:#0FC B:#888 C:#0F9 D:#EEE E:#3CF F:#444 G:#222 H:#C93 I:#0CF J:#630 K:#6CF L:#6FF M:#AAA N:#C90 O:#F03 P:#0C0 Q:#0D0 R:#FF0 S:#080 T:#960 U:#070 V:#090 W:#0E0 X:#F90 Y:#0B0 Z:#E00 Aa:#0C3 Ab:#0A0 Ac:#963
voxels
98-D25-2D3-D-D23-4D3-D24-4D29-2D4-2D29-4D24-D3-4D23-D-D3-2D25-D354-A30-3A28-2A-3A24-3A289-A30-3A28-3ALA26-AMAD2B2A22-2A2MD-3D24-3D2-13A3-14A-6A5-9A5-20A2CA2C26A3C2(AC)24A4CAC2AC23A2C2(AC)2AC23A4CAC2AC23A4CA2CAC23A4CAC2AC13AL10A3C2(AC)11AO2A2L10A2CA2C11AOMA-30A34-13A3C14A-A5B19CF5B2A5BFCH2N3H2(NH)4JTAcCF5B2A5BFCW2QAaPWPQP2NHUSVAbCF5B2A5BFC2I2EZ3JUWP2HK2ECF5B2A5BFC2KEDXSUV3EYQHERCF5B2A5BFC2K2TXEK3EREPNHICF5B2A5BFCITJSVKRI2EK2EYPHCF5B2A5BFCTJUS6EKERKQNCF5B2A5BFC2JSER2IC2I2EICIQCF5B2A5BF18CF4BMAD3B3A3G10A2(-A)-3A3MD-3D24-3D2-30A-7A18-9AL4A18-3A2G3ALAL3A18-2AB3G3AL4A18-2AB3G8A18-3A2G4A2B3A18-8A4B2A18-4AO3A4B2A18-3AOAO3A2B3A18-4AO9A18-7A-30A33-
