model
size = 32 13 6, scale = 0.05, origin = -y
material 
  colors = A:#FC3 B:#888 C:#FC6 D:#BBB E:#3CF F:#444 G:#222 H:#C93 I:#0CF J:#630 K:#6CF L:#6FF M:#AAA N:#C90 O:#F03 P:#0C0 Q:#0D0 R:#FF0 S:#080 T:#070 U:#960 V:#090 W:#00E X:#0E0 Y:#3CC Z:#E00 Aa:#0B0 Ab:#EEE Ac:#0C3 Ad:#0A0 Ae:#963
voxels
98-D25-2D3-D-D23-4D3-D24-4D29-2D4-2D29-4D24-D3-4D23-D-D3-2D25-D354-A30-3A28-2A-3A24-3A289-A30-3A28-3ALA26-AMAD2BCA22-AC2MD-3D24-3D2-13A3-14A-6A5-9A5-20A2CA2C26A3C2(AC)24A4CAC2AC23A2C2(AC)2AC23A4CAC2AC23A4CA2CAC23A4CAC2AC13AL10A3C2(AC)11AO2A2L10A2CA2C11AOMA-30A34-13A3C14A-A5B19CF5B2A5BFCH2N3H2(NH)4JUAeCF5B2A5BFCX2QAcPXPQP2NHTSVAdCF5B2A5BFC2IE2Z3JTXP2HK2ECF5B2A5BFC2KEAbWSTV3EAaQHERCF5B2A5BFC2KU2WEK3EREPNHICF5B2A5BFCIUJSVKRI2EK2EAaPHCF5B2A5BFCUJTS6EKERKQNCF5B2A5BFC2JSER2IY2I2EIYIQCF5B2A5BF18CF4BMAD3B3A3G10A2(-A)-3A3MD-3D24-3D2-30A-7A18-9AL4A18-3A2G3ALAL3A18-2AB3G3AL4A18-2AB3G8A18-3A2G4A2B3A18-8A4B2A18-4AO3A4B2A18-3AOAO3A2B3A18-4AO9A18-7A-30A33-
