model
size = 26 15 26, scale = 0.05, origin = -y
material 
  colors = A:#252525 B:#717171
voxels
34-2(10A16-)10A303-2(8A18-)8A19-6A303-2(2A8-2A14-)2A8-2A16-2(8A18-)8A19-6A223-2(2A12-2A10-)2(2A12-)2(2A8-2A14-)12A14-12A17-6A196-2(A16-A8-)A16-A9-2(2A12-2A10-)4A8-4A11-3A8-3A14-10A16-10A17-8A142-2(A18-A6-)A18-A7-2(2A14-2A8-)3A12-3A8-3A12-3A9-5A6-5A11-4A6-4A13-12A16-8A19-6A89-2A20-2A3-A20-A4-A20-A5-2(2A16-2A6-)3A14-3A7-2A14-2A8-4A10-4A9-3A10-3A11-4A6-4A13-12A15-10A87-2A20-2A3-A20-A4-A20-A5-2(A18-A6-)2A16-2A7-A16-A2(8-2A14-2A)9-3A10-3A11-4A6-4A13-12A17-6A63-2(A22-A2-)A22-A3-2(A20-A4-)2A18-2A5-A18-A7-2(2A14-2A8-)3A12-3A9-3A10-3A11-4A6-4A14-10A18-6A37-2(A22-A2-)A22-A3-2(A20-A4-)2A18-2A5-A18-A6-2A16-2A7-A16-A8-2A14-2A8-3A12-3A9-4A8-4A12-3A6-3A16-8A35-A2(24-2A)24-A-B22-B2-A22-A3-A20-A4-A20-A5-2A16-2A6-2A16-2A7-2A14-2A8-3A12-3A9-3A10-3A12-2A8-2A15-10A34-A2(24-2A)24-A-A22-A2-B22-B3-2(A20-A4-)2A18-2A5-A18-A6-2A16-2A7-2A14-2A8-3A12-3A2(10-2A)13-4A4-4A18-4A11-A2(24-2A)24-A-A22-A2-B22-B2-2A20-2A3-B20-B2(4-2A18-2A)5-2A16-2A6-3A14-3A7-3A12-3A2(10-2A)13-3A6-3A17-6A10-A2(24-2A)24-A-A22-A2-B22-B2-BA20-AB3-B20-B2(2(4-2A18-2A)4-3A16-3A5-3A14-3A7-3A12-3A2(10-2A)13-3A6-3A17-6A10-A2(24-2A)24-A-A22-A2-B22-B2-2A20-2A3-A20-A)4-BA18-AB4-2A18-2A5-2A16-2A6-3A14-3A7-3A12-3A2(10-2A)13-3A6-3A17-6A10-A2(24-2A)24-A-A22-A2-B22-B3-A20-A4-B20-B4-BA18-AB5-A18-A6-2A16-2A7-2A14-2A8-3A12-3A2(10-2A)13-4A4-4A18-4A11-A2(24-2A)24-A-A22-A2-B22-B3-A20-A4-A20-A5-2A16-2A6-2A16-2A7-2A14-2A8-3A12-3A9-3A10-3A12-2A8-2A15-10A35-2(A22-A2-)A22-A3-2(A20-A4-)BA18-AB5-B18-A6-2A16-2A7-A16-A8-2A14-2A8-3A12-3A9-4A8-4A12-3A6-3A16-8A36-2(A22-A2-)A22-A3-2(A20-A4-)2A18-AB5-B18-B7-2(2A14-2A8-)3A12-3A9-3A10-3A11-4A6-4A14-10A18-6A38-2(A20-A4-)A20-A5-2(A18-A6-)2A16-2A7-A16-A2(8-2A14-2A)9-3A10-3A11-4A6-4A13-12A17-6A64-2(2A18-2A4-)2A18-2A5-2(2A16-2A6-)3A14-3A7-2A14-2A8-4A10-4A9-3A10-3A11-4A6-4A13-12A15-10A89-2(2A16-2A6-)2A16-2A7-2(3A12-3A8-)3(5A8-)5A9-16A11-6A2-6A13-12A16-8A19-6A92-2(3A12-3A8-)3A12-3A9-2(4A8-4A10-)16A11-14A13-12A15-10A17-8A144-2(4A8-4A10-)4A8-4A12-2(12A14-)12A15-10A16-10A197-2(12A14-)12A15-10A16-10A18-6A244-
