model
size = 11 5 31, scale = 0.05, origin = -y
material 
  colors = A:#047CD2 B:#2D2D2D C:#151515 D:#1B4361 E:#141515 F:#0C4670 G:#141617 H:#141719 I:#14171A J:#0C4974 K:#131D24 L:#0E3957 M:#131D23 N:#12212C O:#131B20 P:#14191C
voxels
3-4(5B6-)5B5-2(7B4-B5C3(B4-B5-)B4-)7B4-BE4C3(B4-B5-)B4-7B4-BE3CE3(B4-B5-)B4-7B4-BO3CPB4-2B3-2B4-2(B5-)5B5-7B4-BM3CNB4-2B3-2B4-2(B5-)5B5-7B4-BK3CLB4-2B3-2B4-2(B5-)5B5-7A4-BFGHIJB4-2B3-2B4-B4-2B5-5B5-7A4-7B4-2(B5-)B3-B7-3B6-2(7A2(4-B5-B)5-5B16-)7A2(4-B5-B)5-5B15-8A47-4(9A46-)9A45-10A45-3(11A44-)8(2AD5AD2A44-)
