model
size = 29 19 32, scale = 0.05, origin = -y
material 
  colors = A:#BBB B:#DDD C:#E00 D:#888 E:#C93 F:#C90
voxels
42-A2B710-C26-C29-C436-2C27-C28-C24-C3-E24-C2-C26-E-C378-2C27-C28-E22-C5-E22-E4-E24-E3-F24-E3-C24-E324-2C27-2C18-C8-E20-C7-E20-E6-CE20-EC5-E22-E5-F22-E5-C22-E298-C27-2C16-2C9-E18-C9-E18-E8-CE18-EC7-E2(20-E7-F)20-E6-2C20-FC5-C22-C269-2C14-2C11-CE14-EC2(11-E16-E)10-CE16-EC9-E18-E9-F18-E8-CF18-FC7-C20-F7-C20-C242-2C27-2C12-EC13-CE12-EC13-E14-E12-CE14-EC2(11-E16-E)10-2(CF16-FC9-)C18-C273-2C10-2C15-CE10-EC15-CE3-3A4-EC14-CE4-B2A5-EC13-CE4-3B5-EC2(13-E14-E)12-CF14-FC11-C16-F11-C16-C275-C10-C17-C2-4BA3-C16-2C2-2(BA)B3-2C15-CE2-4BA3-EC15-E3-B2A2B4-E15-E12-E14-CE12-FC13-CF12-FC13-C14-C309-3A25-B4A21-2CB2A2B2A-2C17-2CAB5A-2C17-C-2A2(BA)B2-E17-E3-3B4-E16-CF3-A2B4-2C2(15-C12-C)310-3A24-5B2AC20-2C3BA2B2C19-2CBA2BA3C19-2C5B-2C18-2C2-B2A3-2C17-C3-3B4-C17-C10-C340-B2A24-CBAB2A2C21-2CB3A2C20-3C2(BA)3C20-C3A2B-C23-B2A26-2AB402-A2BABC23-2C2B2C22-3C2A3C22-CABA-C488-2(AB)25-A2BC25-A2B431-B5A23-2B2(AB)23-A3B2A23-2(B2A)23-AB2AB24-A4B24-2A2BA24-5C53-5C84-A26-B2ABA24-4AB2(26-A)BA2B52-2BAB3A22-A2B2(AB)21-2(AB)5A20-2B5ABA21-2(A2B)23-5ABA22-BA3B2A21-BAB2ABA2B21-CA3BAC23-5F23-CA2BABC23-5F23-6D22-BA3BA2BA22-5A23-BA2BABA24-A2B25-2(AB)A23-6D22-A3B3A2B21-B3A2BA21-B2A3B3A21-2B2A3B21-3ABA3BA20-A2B3(AB)20-4B3A2B20-B2A4B2A20-2(A3B)A21-FB3ABF22-2(2BA)B21-BFB3ABFB20-2DAB2A2D21-3A2BA3B20-2BABA2BAB22-3B2A80-2D4-2D21-2AB2A4B21-B2A2BAB21-2(B2A)2BA49-A7-B20-A7-A20-B7-A20-A7-B20-AB2AB4A20-4B3A2B20-5B4A20-2(AB)3A2B19-2D2(AB)2A2D49-A7-B106-2D6-2D21-3ABA2B22-5BAB21-A7-B194-B2(7-B20-A)7-A19-D8-D164-D8-D78-A7-B280-D8-D164-D8-D49-3A2B2A2B20-A7-A280-D8-D164-D8-D49-3(BA)3B20-B7-B20-A7-B251-2D6-2D164-2D6-2D20-AB2A2BABA20-2A3(BA)B20-B7-B20-A7-B252-2D4-2D166-2D4-2D21-2ABA4BA20-2B3A2(BA)20-B7-B282-2D2-2D168-2D2-2D23-3B2(AB)22-2B2ABAB313-4D170-4D24-2(BA)B2A22-B2A3BA22-A5-A23-5A25-3A429-AB7A20-AB2(A2B)A21-A5-A23-5A457-A2BAB2A2B20-3A4B2A22-2A2BA24-5A457-2B3A2B2A21-ABA3BA23-2AB2A25-3A459-2B3ABA22-2ABAB2A24-3A27-A460-2(2AB)A24-3A506-
