model
size = 21 31 29, scale = 0.05, origin = -y
material 
  colors = A:#963 B:#111 C:#960 D:#222
voxels
390-B20-2B19-B443-B41-B39-2B35-B2-B3-B16-3B15-B2-3B14-B2-4B17-2B419-A3-B16-A2-2B15-2A2-B13-B2-2B3-2B12-2BAC2-2B14-BDB-D2B13-B3-2B13-B-5B-3B10-2B2-5B13-7B-2B10-11B11-B-5B15-4B-B20-B358-B16-2A-2BD14-3A-2BD13-C3A3BDB10-B-4A5B10-3B2A-5B9-4B2A5B10-12B9-BD9B10-10B11-13B7-12B11-B-6B13-7B16-B2-3B15-B2-B247-2C4A14-3C5A13-2C6A12-4C6A11-3C7A2B9-4C6AD10-A2C7A2B9-6A-3ABD9-6A-3A3B8-10A2B9-10AB9-B10A2B8-B10A4B6-D10A2B7-D3B7A3B7-4B7AB9-B-3B4A2B-B10-8B15-4B-2B16-B2-B229-A13-5C5A10-2(3C9A9-)2C2(10A2B7-AC)10A4B5-2(12A2B7-)12A5B4-12A3B6-12AB8-12A4B5-2(12A2B7-)12A2B3-B2-B11A2B5-B-5B5A2B-B7-5B4A3B10-B2-8B15-3B16-B212-4A11-2C-CAC6A2B7-12AB8-12AD3(8-12AB)D7-12A4B5-12A2B7-12AB8-12AB-B5-B12A2B6-C12AB-B6-12A2B7-12A2B5-2B12A2B6-B11A2B5-3B11A2B8-3B7A4B6-5B5A2B12-9B13-B2-2B20-B184-3C3A12-3C9A9-3(12AB8-)12A2B7-12AB8-12A5B4-12AB-B6-12A4B5-12AB7-B12A2B6-C3(12A2B7-)12A2B5-2B12A4B4-2(B12AB7-)3B9A2B9-D2B4A6B10-6B3-B14-B-B126-3A18-3A15-2A-3A11-4C6A9-2C10A9-12A2B7-B11A2(2B7-12A)3B6-12AD8-12A3BD5-3(12A3B6-)12A3B5-C2(12A4B5-)12A3B6-12AB8-12A2B6-B12A3B4-2B12A2B6-2B11AB8-3B2AC4A2B10-9B17-B-B125-4A17-4A13-2C6A11-2C8A9-2C10A9-12A9-B11A2(B8-12A)BD7-12AD8-B11A3B6-12A2BD6-12A-2B3(6-12A3B)6-12A4B5-12A3B6-12A2B7-12A2B5-2B12A3B4-2B12A3B6-B11A3B6-2B8A3B9-11B13-2B2-B126-3A18-3A13-2C6A11-2C8A9-2C10A9-12AB8-B11A3BD5-12A3B6-12AB8-12A4B5-B11A2B7-2(12A4B5-)12A3B6-12A2B7-2(12A4B5-)12A2B2(-B)3-12A2B4-3B12AB6-2B12A3B4-2B12A2B7-B11AB9-BC7A3B9-10B13-3B2-B-B13-B110-3A18-3A15-CA-ADC11-4C4ADA9-2C10A9-12A3B6-B11ABD2(7-12A2B)7-12A3B6-3(12A4B5-)12A2B6-B12A3B5-C12AB-2B5-12A3B6-12A2B7-12A4B5-12A3B5-B12A2B5-2B12A3B5-2B11A3B7-2B4AC2A4B9-11B10-4B3-2B181-4C2A12-3C9AB8-12A9-12AD8-12A2B7-12ABD7-12A2B7-3(12A4B5-)12A2B-B4-B12A4B4-C12AB-B6-12A4B5-12A3B6-12A4B4-B12AB-B4-2B12A2B5-2B12A3B4-4BAC7A2B10-2B4A4B12-6B2-2B14-4B-B181-2C3A-A10-4C8A2(9-12A)2B7-2(12AB8-)12A2B7-12AB-B6-2(12A4B5-)12AB8-12A3B5-C12AB8-2(12A3B6-)12A4B5-12AB-2B3-2B12A2B5-4B9AB-2B8-BC6A3B10-3B2AC5B12-4B2-3B14-B3-B16-B167-2C2A12-C-3C6A2(B8-3C9A)2B7-2C10AB8-C11A4(2B7-12A)3B6-3(12A4B5-)2(12A3B6-)12AB-2B4-B11A2B-B4-2B11AB8-4B7A2B11-2B5A3B12-6B16-3B3-3B19-B202-4C2A14-5C3A13-4C4A12-2(4C6AB10-)4C6A3B8-A3C6A2B9-6A-3ABDB8-6A-2AC2(B10-10A)4B7-10A2B8-B10AB-B7-B8A2CB-B7-3BAC5A2B-2B4-5B7A2B-B5-6B4A3B12-9B12-8B14-3B2-B354-2A2-2B15-2A-2B14-C3A4B12-B4A5B10-3B2A5B10-4B2A4B11-8BDB-B8-11B11-11B7-2B2-9B9-B2-8B13-6B15-5B20-B-B20-B354-A20-A2-B16-2A3-B13-B3A2-2BD13-BAC2-3B12-3BD3-B14-2B2-B12-B2-B4-3B12-2B-5B-B8-B3-3B2(-B)10-B3-2B2-B16-B2-B17-2B24-B421-B19-B58-B2-B15-B5-B18-B-B20-B9-2B4-B2-B12-B6-B90-2(B20-)B332-B19-B102-B131-2(B20-)2(D20-)2(B566-4(B20-))B587-6(B20-)B650-B524-2(B20-)B83-B503-2(B20-)2(D20-)2(B62-B503-4(B20-))B62-B524-6(B20-)B2-
