model
size = 7 20 25, scale = 0.05, origin = -y
material 
  colors = A:#FCFAF2 B:#3A3226 C:#E83015 D:#0F4C3A E:#FFC408
voxels
E5AE105AE5AE21-7AB14(5A2B)5AB7A21-7AB10(5A2B)5A3(B6A)2B5AB7A21-7AB10(5A2B)5AB6A3(2B5A)B7A21-7AB8(5A2B)5A2(B6A)4(2B5A)B7A21-7AB7(5A2B)5AB6A6(2B5A)B7A21-7AB8(5A2B)5A2(B6A)4(2B5A)B7A21-7AB14(5A2B)5AB2A3E2A3-2(E6-)E3-7AB14(5A2B)5AB7A17-E3-119A17-E3-8D11(5A2D)5ADE5A2E5AED5A8D3(17-E3-8C11(5A2C)5ACE5A2E5AEC5A8C)17-E3-8D11(5A2D)5ADE5A2E5AED5A8D17-E3-119A2(17-E3-7AB14(5A2B)5AB7A)17-E3-7AB9(5A2B)2(6AB)3(5A2B)5AB2A3E2A3-2(E6-)E3-7AB8(5A2B)6AB5(5A2B)5AB7A21-7AB9(5A2B)2(6AB)3(5A2B)5AB7A21-7AB11(5A2B)6AB2(5A2B)5AB7A21-7AB11(5A2B)3(6AB)5AB7A21-7AB14(5A2B)5AB7A21-E5AE105AE5AE21-
