model
size = 32 32 11, scale = 0.05, origin = -y
material 
  colors = A:#FF3 B:#FC3 C:#FFF D:#E00 E:#FF9 F:#F93 G:#EEE
voxels
2(28-4A)29-A62-A735-A31-A32-2(A31-)A29-5A3(28-4A)2(27-A-3A)29-A33-2(A95-A31-)A2(30-2A)190-A2(30-2A)28-A-A29-3A29-2(2A30-)A-A31-A2-4AB22-9A24-8A24-9A22-A-8A22-A-7A-A23-7A2-A22-7A2-A21-5A5-2A24-2A30-2(A31-)3(A29-A-)2A30-3A27-A-2A28-A-2A30-2A28-A-2A2(28-A2-A)28-A3-A26-A4-A3-A18-A3-A4-A3-A18-2(A-)A5-A-A20-3A6-2A22-2A2(7-A22-A)-2(A31-)2A2-4AB22-9A24-9A22-A-7A-A21-A-7A-A23-7A2-A22-8A-A22-7A27-2A31-3A2-A20-A3-A-2A3-A20-A3-3(A-3A27-)A-4A26-A-3A27-A-3A26-2A-3A25-2(A-)3A27-A2(3-A26-2A)30-2A4-A5-A19-2A4-A25-2A4-A3-A16-A4-A5-2A-A18-A2-A7-A-A18-A-A8-2A20-2A9-2A18-2A9-A20-A-A7-A24-A6-2B22-2B3-4AB3-3A12-2A2-10A23-8A-A23-7A-A23-10A19-2A-7A2-2A16-12A2-3A14-2A-A3-6A4-2A13-A4-7A2(2-2A)14-5A-A2-2A-A21-4A3-2A-2A11-2A7-4A3-2A-A6-A5-2A7-4A3-2A12-A8-A-4A3-4A19-6A3(3-2A23-4A)3(3-3A22-4A)3-2A23-4A4-2A8-2(A6-)4A4-2A5-2A15-3A6-A5-A10-3A3-2A7-2A3-A12-2A2-3A8-A-2A14-2A-3A8-3A16-4A10-2A16-4A9-A-2A14-2A-A10-A17-4A9-A19-A2-A7-5B17-4B3-4AB3-3A10-15A-A20-A-8A2-A18-A3-7A2-2A16-2A3-9A-A16-A-2A-9A2-A14-2(A2-)7A-A3-A12-A3-6A3-3A4-12A4-4A4-5A4-10A5-A-A5-4A7-7A6-A-A5-2(4A8-)3(3A5-4A20-)3A5-4A19-2A7-4A20-A8-3A19-2A7-4A19-2A2(8-2A21-A)8-3A20-A8-3A10-2A8-A8-4A5-2A-5A5-2A9-3A5-2A4-2A5-2A11-A4-A8-A4-A12-2A16-2A13-2A15-2A13-3A12-A-2A12-2A-2A10-2A-2A12-A3-4A4-2A-A3-A11-A20-A9-5B16-3B4-5B3-5B6-B-10B-31A-32A3B4A-16A-14A-16A-7A3-4A2-4A6-4A2-4A8-2A3-12A3-4A9-A4-9A5-4A9-A7-4A7-A-2(A10-)A7-A-A10-A4-A13-A-A10-5(A18-A12-)A18-A8-A2-2A18-A11-4A14-3A2(11-3A16-2A)11-4A14-3A12-3A14-2A12-A-2A6-3A5-2A14-3A2-A-6A2-3A15-5A6-6A16-3A8-4A16-7A2-7A16-A2-10A2-A15-A6-2A-A6-A13-A18-A11-B2AB15-3B6-5B2-23B2-30B2-A3B26A9-2(16A16-)5A6-5A16-4A-6A-4A14-3(A-4A8-4A-A12-)2(A-4A-A6-4A-A12-)A-5A2-2A3-4A-A12-A-4A5-A2-2(4A-A12-A-4A8-)4A-A12-A-4A7-5A-A12-A-4A8-4A-A14-2(4A8-4A16-)4A8-4A17-3A8-3A18-3A4-A3-3A18-4A2-3A-4A19-12A21-10A23-8A22-3A2-2A2-3A19-2A10-2A17-2B12-2B15-2B14-2B13-20B8-28B11-14A14-5C12A6C15-10A23-8A24-A6-A3(24-8A)18-2(A5-8A5-A12-)A5-D6AD5-A12-A5-D5A2D5-A12-A4-G-D5A-G4-A12-A7-4A7-A12-A4-A2D4A2DA4-A17-AD6ADA22-F8AF23-4(8A24-)8A25-6B27-4E29-2E60-6B24-10B21-3B6-3B19-2B10-2B17-16B18-12B21-10A24-6A27-4C827-6B24-10B21-12B23-6B924-2E29-4E27-6B13-
