model
size = 29 23 31, scale = 0.05, origin = -y
material 
  colors = A:#FF3 B:#777 C:#F09 D:#CFF E:#FFF F:#CCC G:#F99 H:#F60 I:#FC0 J:#FCC K:#CC0 L:#CF9 M:#CC6 N:#CC9 O:#F96 P:#F3F Q:#FFC R:#F6F S:#CF6 T:#F30 U:#F6C V:#F69 W:#FF9 X:#CC3 Y:#FCF Z:#FC3 Aa:#FF6 Ab:#CF3 Ac:#F9F Ad:#F33 Ae:#FC9 Af:#F36 Ag:#F66 Ah:#CCF Ai:#FC6 Aj:#F03 Ak:#FF0 Al:#F00 Am:#F3C An:#F06 Ao:#CF0 Ap:#F0F Aq:#F9C Ar:#F93 As:#F39 At:#CFC Au:#F0C Av:#F63 Aw:#F90
voxels
89-5B14-4B152-24A439-2A19-5A3-5A14-4A8-5A10-4A13-15A69-22A6-24A4-26A31-28A58B58A204-2A23-2A3-2A19-5A3-5A14-4A8-5A10-4A13-15A41-20A8-22A6-24A4-26A2-27A2B173A146-2B24-2B-2A23-2A3-2A19-5A3-4A15-4A8-5A10-4A13-15A14-15AB11-A-18A8-2A-19A6-3A-20A4-4A-21A2-5A-21A2B5A5(-28A)-22A-27A118-2A24-2A-2A23-2A3-2A19-5A3-5A14-4A8-5A10-4A13-15A13-B15AB11-20A8-22A6-24A4-26A2-27A2B173AB27AB-27B89-2(2A24-2A-2A23-2A3-2A19-5A3-5A14-4A8-5A10-4A13-15A13-B15AB11-20A8-22A6-24A4-26A2-27A2B173AB27AB-27B3-26B60-)2A24-2A-2A23-2A3-2A19-5A3-5A14-4A8-5A10-4A13-15A13-B15AB11-20A8-22A6-24A4-26A2-27A2B173AB27AB-27B3-26B4-24B32-5(2A24-2A-2A23-2A3-2A19-5A3-5A14-4A8-5A10-4A13-15A13-B15AB11-20A8-22A6-24A4-26A2-27A2B173AB27AB-27B3-26B4-24B6-22B4-)2A24-2A-2A23-2A3-2A19-5A3-5A14-4A8-5A10-4A13-15A13-B15AB11-20A8-22A6-24A4-26A2-27A2B145A27CAB27AB-27B3-26B4-24B32-2A24-2A-2A23-2A3-2A19-5A3-5A14-4A8-5A10-4A13-15A13-B15AB11-20A8-22A6-24A4-26A2-27A2B29A27C2A27C75A-12AB15AC11AB-27B3-26B60-EL24-DV-AfV23-RI3-AAq19-AAlNHAj3-AqUMAaAn14-Aq2AAq8-ApMAbDP10-H2AbA13-JCAmIAaAdUEAnAgAoYFAjD13-B15AB11-20A8-22A6-24A4-26A2-27A2B27C2A9C-17C2A15C-11C2(2A27C)2A15C-11CAB15AC11AB-27B89-GAk24-AbAt-KW23-AmD3-AoE19-AAwAuWAc3-JAgAnRG14-I2AL8-AaHSYD10-VAtAjAp13-GJKOAiHFPAdAjCZNAsW13-B15AB11-20A8-22A6-24A4-26A2-27A2-11A-25A4-3A-2A3-17A3(-2A)-19A-A-3A-2A-19A3(-2A)-17A5-2A3-A3-7A-27A118-YQ24-LY-KD23-NM3-IR19-ANEAoAd3-AjAmVTAu14-G2AO8-TAhSYD10-AaUIQ13-KFDAnAvPNAhHAsMSApTAl13-B9-6AB11-20A8-22A6-24A380-FAc24-UAt-EG23-OAv3-AuV19-AKHGT3-AwAu2AU14-Aq2AAr8-AmAqTLO10-AAlMA13-AaLAiAdUWApDPTAsESIAp13-B15AB11-20A8-22A410-CA24-IG-AiS23-AgH3-AjL19-AIWXF3-VFMAkAo14-AtRQAl8-CGFZG10-VWJAm13-LAhIHPJS2WIAbAoANZ13-B15AB471-AvE24-AuE-TAc23-AbA3-KAd19-ALAoMY3-AlDAcZAf14-AfKOAa8-CUERT10-JNAvAl13-UAiYPILAAlJNVAvArZT501-MAu24-AhL-AdAs23-YN3-AgL19-AVGAAq3-HMISAf14-AqAAsT8-HAs2AkW10-AcAhAcS13-AeAcPWATArApLZEA2AfD501-MAd24-AlAp-ApAi23-NR3-NAh19-AAfXDQ3-AoOAjCP14-MKAhE8-VAbCIZ10-REAuI13-3HJAmNAfZTAfAtFEAkA501-DAi24-AeU-JAn23-AcS3-AvZ19-AOMGAp3-SAdCOAh14-JFAoAt8-AaAtNSAe10-AmArXAr13-ApAAcLArQETNAkOGAwAoAk501-JAk24-AhAi-PI23-JAa3-HT19-AAfAXAr3-FPAeRAg14-IQEP8-AUHAjAs10-AgAAlAn13-ZAgFTAeAbAwDQAoAnMHYK501-AjF24-PV-ZAr23-OP3-AoJ19-AAvDLAa3-RApLAgG14-AeQYT8-VAlXZE10-AdAwAaF13-AdAfAbNAmOHAAbYGAcDAdAt501-OR24-AqAp-AwE23-AeAb3-AcAn19-ACGAaD3-KAvDAeS14-AkAiLAi8-JWAjAvF10-KIAeAn13-SArAiQGQDAkOAdRAuYAgS501-AR24-TAn-YAm23-QAi3-AeE19-AQ2XAk3-AAsXWD14-JNAcF8-AcNJXAd10-GAcPZ13-RAhLAbAvFYKQAgAvDAuCAh501-VF24-AeX-AuAi23-QA3-GAj19-AULES3-KAoXPAg14-JAbAeAt8-RAhHAeAl10-AtGApAf13-AsAqE2OXAuAtFCOKVKAg501-EAw24-PAn-AsAd23-UAa3-DAf19-AAlAaAmM3-FICKY14-AuGAR8-AmEAAtAf10-HAqAwK13-JAkWQWUVSXKOAdXMC501-AmK24-AoW-AeAl23-AnR3-RZ19-SYXAnAm3-QUAsJAb14-AkAaAsQ8-AgArAjIP10-AcArAbAr13-AjAaAqFMAiXAhUMWVUZA500-
