model
size = 23 32 21, scale = 0.05, origin = -y
material 
  colors = A:#FC0
voxels
168-2(2A21-)3A21-A594-2(3A20-)2(4A20-4A19-)4A2(20-3A)522-3A20-4A20-A-2A19-4A20-2(4A19-)5A19-4A20-A-2A19-4A20-3A21-2A452-2(3A20-)4A19-4A20-2(4A19-)4A20-4A2(19-5A)18-3A-A20-4A19-3A21-2A406-2A20-4A19-4A3(20-3A)21-3A20-2(3A21-)2A21-5A18-2(5A19-)4A19-4A404-3A20-2(4A19-)3A2(21-2A)117-2A21-4A19-5A18-3A-A19-4A20-3A358-2A21-3A3(19-4A)21-2A163-2A21-5A18-5A19-2A-A20-3A358-2A19-5A17-6A18-4A20-3A21-A189-2A20-5A19-2A-2A19-3A21-2A334-3A19-5A17-5A19-4A20-3A21-A211-5A18-3A-2A19-4A19-3A334-3A19-4A18-5A19-4A19-3A22-A21-A190-4A19-5A18-2A-2A19-4A20-2A311-3A20-A-A18-5A19-4A19-3A21-A22-A190-4A18-6A18-2A2-A2(19-4A)20-4A20-3A263-2(3A20-)3A2(19-4A)20-2A21-A189-4A19-6A18-2A-2A19-A2-A2(19-5A)2(18-5A)19-3A218-A21-3A20-3A19-4A19-3A20-3A21-2A188-3A20-2(5A19-)2A-2A18-2A-2A19-5A18-2A-2A18-5A19-4A20-3A216-3A20-A-A3(20-3A)19-3A21-A22-2A21-2A73-A22-2A21-3A20-3A21-5A2(19-5A18-2A-2A)18-2A2-2A18-2A-2A18-5A19-3A193-2(3A20-)3A21-2A4(20-3A)2(21-2A)21-A27-A22-2A21-3A20-3A46-3A20-2(4A19-)5A19-2A-2A18-A2-2A18-5A19-3A216-3A20-4A2(20-3A)2(19-4A)2(20-3A)21-4A18-3A-2A18-A2-3A21-2A20-3A21-2A118-3A19-5A18-A2-2A18-2A-2A18-5A19-3A194-2A21-4(3A20-)2(4A19-)2(5A19-)4A18-A2-2(3A20-)3A140-4A18-6A2(17-2A3-A)17-6A18-4A218-A21-2(3A20-)4A20-3A19-5A18-2(5A19-)4A19-A-2A21-2A141-5A16-7A16-3A2-3A2(15-2A4-2A)15-3A2-3A15-8A17-5A240-2A21-2(3A20-)4A2(20-3A)21-3A21-A141-6A16-8A14-4A2-3A13-4A4-3A2(12-3A6-2A)12-4A4-3A13-4A2-4A14-8A15-7A475-7A14-11A11-13A10-6A4-3A10-5A6-3A8-4(5A8-3A7-)6A6-3A9-6A4-4A9-13A11-11A13-8A386-6A15-10A12-12A10-3A8-2A9-4A9-2A8-2A11-3A7-2A12-2A6-3(2A14-2A5-)2A13-3A5-3A12-2A7-2A11-3A7-4A8-3A9-5A5-4A10-12A12-10A15-6A6-
