model
size = 17 15 29, scale = 0.05, origin = -y
material 
  colors = A:#33C B:#603
voxels
41-2(2A15-)2A202-2A13-6A11-2A2-2A200-2A14-4A12-A4-A11-A4-A199-4A12-6A10-2(2A-)2A214-2A2-2A11-2A2-2A10-A2-2A2-A214-A4-A11-A4-A9-2A-4A-2A11-2A159-B16-2B16-B5-A4-A10-2A4-2A8-3(A2-)A10-4A14-2A72-2(2B15-2B16-)B39-A6-A9-A6-A7-2A-2A2-2A-2A9-A2-A13-4A14-2A38-B16-2B2(16-B)74-A6-A8-2(2A6-)A2-A4-A2-A8-2A2-2A12-A2-A13-4A2-2B10-2A3-2B15-2B16-B108-A8-A7-A8-A5-2A-2A4-2A-2A7-A4-AB10-2A2-2A2B10-A2-A-3B9-4A3-B10-2A130-A8-A6-2A8-2A4-A2-A6-AB-A6-2A4-2AB9-A4-A2B9-2A2-2A-B10-A2-A13-4A14-2A112-A10-A5-A10-A3-2A-2A6-2A-2A5-A6-A9-2A4-2A10-A4-A11-2A2-2A12-A2-A13-4A14-2A95-A10-A4-2A10-2A2(2-A)8-A2-A4-2A6-2A8-A6-A9-2A4-2A10-A4-A11-2A2-2A12-A2-A13-4A14-2A77-A12-A3-A12-A2-A-2A8-2A-A4-2A6-2A7-2A6-2A8-A6-A9-2A4-2A10-A4-A11-2A2-2A12-A2-A13-4A14-2A60-A12-A3-A12-A2-A-2A8-2A-A4-A8-A7-2A6-2A8-A6-A9-2A4-2A10-A4-A11-2A2-2A12-A2-A13-4A14-2A61-A10-A4-2A10-2A2(2-A)8-A2-A4-2A6-2A8-A6-A9-2A4-2A10-A4-A11-2A2-2A12-A2-A13-4A14-2A78-A10-A5-A10-A3-2A-2A6-2A-2A5-A6-A9-2A4-2A10-A4-A11-2A2-2A12-A2-A13-4A14-2A96-A8-A6-2A8-2A4-2(A2-A6-)2A4-2A10-A4-A11-2A2-2A12-A2-A13-4A14-2A113-A8-A7-A8-A5-2A-2A4-2A-2A7-A4-A11-2A2-2A12-A2-A13-4A14-2A130-2A6-2A7-2(2A6-)A2-A4-A2-A8-2A2-2A12-A2-A13-4A14-2A148-A6-A9-A6-A7-2A-2A2-2A-2A9-A2-A13-4A14-2A166-A4-A10-2A4-2A8-3(A2-)A10-4A14-2A183-A4-A11-A4-A9-2A-4A-2A11-2A201-A2-A12-2A2-2A10-A2-2A2-A215-A2-A13-A2-A11-2(2A-)2A216-2A14-4A12-2A2-2A11-A4-A217-2A13-2A2-2A11-2A2-2A233-4A13-A2-A235-2(2A15-)2A178-
