model
size = 22 25 5, scale = 0.05, origin = -y
material 
  colors = A:#FC9 B:#EEE C:#B00 D:#111 E:#001 F:#DDD
voxels
10-2A19-4A16-8A13-10A11-12A9-14A8-14A7-16A6-16A5-18A4-18A3-20A2-20A-176A-20A2-20A3-18A4-18A55-4A16-8A13-10A12-10A10-2(14A8-)14A7-3(16A6-)16A5-18A4-18A3-6(20A2-)20A3-18A4-18A5-16A78-4A16-8A14-8A12-2(12A10-)12A9-4(14A8-)14A7-16A6-16A5-4(18A4-)18A5-16A6-16A7-14A8-14A101-4A16-8A14-8A13-2(10A12-)10A10-3(14A8-)14A7-5(16A6-)4AF6AF4A2(6-16A)7-2(14A8-)14A168-2C19-C2BC17-C4BC15-C6BC13-C8BC11-C10BC9-14C99-E6-E13-EDE4-EDE12-DFD4-DFD13-D6-D73-
