model
size = 11 31 11, scale = 0.05, origin = -y
material 
  colors = A:#B00 B:#2D1600 C:#200 D:#603 E:#444
voxels
4-22(3C8-)3C6-7B192-D4A6-AD3A2(6-2A2DA)6-4AD6(6-5A)6-D4A6-AD3A4-9B4-2(5B6-)5B159-5(7A4-)6AD4(4-7A)4-D6A2(4-7A)2-11B2-2(7B4-)7B5-5B147-2A5E2A2-B8A2(2-9A)2-B8A2-9A2-8AD2-9A2(2-D8A)3(2-9A)-11B-2(9B2-)9B3-7B5-5B136-2(2A5E2A6(2-9A)2-D7AD5(2-9A)-11B-2(9B2-)9B3-7B5-5B7-3B8-3B115-)2A5E2A5(2-9A)2-D8A2-9A2(2-8AD)3(2-9A)-11B-2(9B2-)9B3-7B5-5B7-3B8-3B115-2A5EAB2-9A2(2-8AB)2-9A2-D7AB4(2-9A)2-8AD2(2-9A)-11B-2(9B2-)9B3-7B5-5B137-4(7A4-)D6A6(4-7A)4-6AD4-7A2-11B2-2(7B4-)7B5-5B149-2A2DA6-AD3A2(6-D4A)8(6-5A)6-4AD4-9B4-2(5B6-)5B302-7B79-
