model
size = 29 24 31, scale = 0.05, origin = -y
material 
  colors = A:#CFB53B B:#FF3 C:#1AAB9B D:#F09 E:#FFF
voxels
89-5A14-4A152-24A439-2A27-2A19-5A3-5A14-4A8-5A10-4A13-15A69-22A6-A21B2A4-26A31-144A233-3A22-2A3-2A19-5A3-5A14-4A8-5A10-4A13-15A41-19A9-A19B2A6-A21B2A4-A23B2A-61A3(23B6A)23B32A175-2A24-2A-3A22-2A3-2A19-5A3-5A14-4A8-5A10-4A13-15A14-16A11-A-17A9-AB-17B2A6-A2B-18B2A4-A3B-19B2A-6A-28A-25A3(3B-19B6A)3B-19B5A4B-20B2A-27A147-2A24-2A-3A22-2A3-2A19-5A3-5A14-4A8-5A10-4A13-15A13-17A11-19A9-A19B2A6-A21B2A4-A23B2A-61A3(23B6A)23B5A25B31A-27A118-2(2A24-2A-3A22-2A3-2A19-5A3-5A14-4A8-5A10-4A13-15A13-17A11-19A9-A19B2A6-A21B2A4-A23B2A-61A3(23B6A)23B5A25B31A-27A3-26A89-)2A24-2A-3A22-2A3-2A19-5A3-5A14-4A8-5A10-4A13-15A13-17A11-19A9-A19B2A6-A21B2A4-A23B2A-61A3(23B6A)23B5A25B31A-27A3-26A4-24A61-2(2A24-2A-3A22-2A3-2A19-5A3-5A14-4A8-5A10-4A13-15A13-17A11-19A9-A19B2A6-A21B2A4-A23B2A-61A3(23B6A)23B5A25B31A-27A3-26A4-24A6-22A33-)2A24-2A-3A22-2A3-2A19-5A3-5A14-4A8-5A10-4A13-15A13-17A11-19A9-A19B2A6-A21B2A4-A23B2A-61A3(23B6A)23B5A25B31A-27A3-26A4-24A6-22A16-CE15-2A24-2A-3A22-2A3-2A19-5A3-5A14-4A8-5A10-4A13-15A13-17A11-19A9-A19B2A6-A21B2A4-A23B2A-61A3(23B6A)23B5A25B31A-27A3-26A4-24A6-22A16-EC15-2A24-2A-3A22-2A3-2A19-5A3-5A14-4A8-5A10-4A13-15A13-17A11-19A9-A19B2A6-A21B2A4-A23B2A-61A3(23B6A)23B5A25B31A-27A3-26A4-24A6-22A33-2A24-2A-3A22-2A3-2A19-5A3-5A14-4A8-5A10-4A13-15A13-17A11-19A9-A19B2A6-A21B2A4-A23B2A-61A3(23B6A)23B5A14DB10D31A-27A3-26A4-24A61-2A24-2A-3A22-2A3-2A19-5A3-5A14-4A8-5A10-4A13-15A13-17A11-19A9-A19B2A6-A21B2A4-A23B2A-61A7DB15D6A13D2B8D2(6A23B)5A14B-10B31A-27A3-26A89-2A24-2A-2A23-2A3-2A19-5A3-5A14-4A8-5A10-4A13-15A13-17A11-19A9-A19B2A6-A21B2A4-A23B2A-61A5D2B-6B2D3B4D6A5D8B-2(2D3B4D6A5D9B)2D3B4D19A-41A2-26A4-23A91-2A24-2A-2A23-2A3-2A19-5A3-5A14-4A8-5A10-4A13-15A13-17A11-19A9-A19B2A6-A21B2A4-A6(23B2A2-2A)23B2A2-A25BA2-27A3-25A119-2A24-2A-2A23-2A3-2A19-5A3-5A14-4A8-5A10-4A13-15A13-A9-7A11-19A9-A19B2A6-A21B2A4-A2(23B2A2-2A)23B2A2-27A3(2-2A23B2A)2-27A3-26A4-24A119-2A24-2A-2A23-2A3-2A19-5A3-5A14-4A8-5A10-4A13-15A13-17A11-19A9-A19B2A6-A21B2A5-A22B6(A4-A23B)A4-25A5-23A149-2A24-2A-2A23-2A3-2A19-5A3-5A14-4A8-5A10-4A13-15A50-2A18-19A9-21A7-6(23A6-)23A7-21A16-5A158-2A24-2A-2A23-2A3-2A19-5A3-5A14-4A8-5A10-4A13-15A48-5C23-7C21-9C19-11C17-7C2(A2C)15-8CA2CA3C14-5CA3CACA3C14-10C2A3C14-11CA3C15-13C17-11C19-9C21-7C23-5C100-2A24-2A-2A23-2A3-2A19-5A3-5A14-4A8-5A10-4A13-15A162-2(E2-E-E2-E20-)E-E3-E-E20-2E5-2E20-E7-E243-8(2A24-2A-2A23-2A3-2A19-5A3-5A14-4A8-5A10-4A13-15A530-)2A24-2A-2A23-2A3-2A19-5A3-5A14-4A8-5A10-4A13-15A529-
