model
size = 29 24 31, scale = 0.05, origin = -y
material 
  colors = A:#1AAB9B B:#FF3 C:#EEE D:#F09
voxels
89-2A3C14-4C152-24A439-2A27-2A19-3C2A3-2A3C14-4C8-5C10-4C13-4C7A4C69-22A6-A21B2A4-26A31-144A233-3A22-2A3-2A19-3C2A3-2A3C14-4C8-5C10-4C13-4C7A4C41-19A9-A19B2A6-A21B2A4-A23B2A-61A3(23B6A)23B32A175-2A24-2A-3A22-2A3-2A19-3C2A3-2A3C14-4C8-5C10-4C13-4C7A4C14-16A11-A-17A9-AB-17B2A6-A2B-18B2A4-A3B-19B2A-6A-28A-25A3(3B-19B6A)3B-19B5A4B-20B2A-27A147-2A24-2A-3A22-2A3-2A19-3C2A3-2A3C14-4C8-5C10-4C13-4C7A4C13-17A11-19A9-A19B2A6-A21B2A4-A23B2A-61A3(23B6A)23B5A25B31A-27A118-2(2A24-2A-3A22-2A3-2A19-3C2A3-2A3C14-4C8-5C10-4C13-4C7A4C13-17A11-19A9-A19B2A6-A21B2A4-A23B2A-61A3(23B6A)23B5A25B31A-27A3-26A89-)2A24-2A-3A22-2A3-2A19-3C2A3-2A3C14-4C8-5C10-4C13-4C7A4C13-17A11-19A9-A19B2A6-A21B2A4-A23B2A-61A3(23B6A)23B5A25B31A-27A3-26A4-24A61-2(2A24-2A-3A22-2A3-2A19-3C2A3-2A3C14-4C8-5C10-4C13-4C7A4C13-17A11-19A9-A19B2A6-A21B2A4-A23B2A-61A3(23B6A)23B5A25B31A-27A3-26A4-24A6-22C33-)2(2A24-2A-3A22-2A3-2A19-3C2A3-2A3C14-4C8-5C10-4C13-4C7A4C13-17A11-19A9-A19B2A6-A21B2A4-A23B2A-61A3(23B6A)23B5A25B31A-27A3-26A4-24A6-22C16-2A15-)2A24-2A-3A22-2A3-2A19-3C2A3-2A3C14-4C8-5C10-4C13-4C7A4C13-17A11-19A9-A19B2A6-A21B2A4-A23B2A-61A3(23B6A)23B5A25B31A-27A3-26A4-24A6-22C33-2A24-2A-3A22-2A3-2A19-3C2A3-2A3C14-4C8-5C10-4C13-4C7A4C13-17A11-19A9-A19B2A6-A21B2A4-A23B2A-61A3(23B6A)23B5A14DB10D31A-27A3-26A4-24A61-2A24-2A-3A22-2A3-2A19-3C2A3-2A3C14-4C8-5C10-4C13-4C7A4C13-17A11-19A9-A19B2A6-A21B2A4-A23B2A-61A7DB15D6A13D2B8D2(6A23B)5A14B-10B31A-27A3-26A89-2A24-2A-2A23-2A3-2A19-3C2A3-2A3C14-4C8-5C10-4C13-4C7A4C13-17A11-19A9-A19B2A6-A21B2A4-A23B2A-61A5D2B-6B2D3B4D6A5D8B-2(2D3B4D6A5D9B)2D3B4D19A-41A2-26A4-23A91-2A24-2A-2A23-2A3-2A19-3C2A3-2A3C14-4C8-5C10-4C13-4C7A4C13-17A11-19A9-A19B2A6-A21B2A4-A6(23B2A2-2A)23B2A2-A25BA2-A25CA3-3A19C3A119-2A24-2A-2A23-2A3-2A19-3C2A3-2A3C14-4C8-5C10-4C13-4C7A4C13-A9-7A11-19A9-A19B2A6-A21B2A4-A2(23B2A2-2A)23B2A2-27A3(2-2A23B2A)2-27A3-A23C2A4-A21C2A119-2A24-2A-2A23-2A3-2A19-3C2A3-2A3C14-4C8-5C10-4C13-4C7A4C13-17A11-19A9-A19B2A6-A21B2A5-A22B6(A4-A23B)A4-A23CA5-23C149-2A24-2A-2A23-2A3-2A19-3C2A3-2A3C14-4C8-5C10-4C13-4C7A4C50-2A18-19C9-21C7-6(23C6-)23C7-21C16-5A158-2A24-2A-2A23-2A3-2A19-3C2A3-2A3C14-4C8-5C10-4C13-4C7A4C48-5A23-7A21-9A19-11A17-13A15-3(15A14-)15A15-13A17-11A19-9A21-7A23-5A100-2A24-2A-2A23-2A3-2A19-3C2A3-2A3C14-4C8-5C10-4C13-4C7A4C162-2(C2-C-C2-C20-)C-C3-C-C20-2C5-2C20-C7-C243-8(2A24-2A-2A23-2A3-2A19-3C2A3-2A3C14-4C8-5C10-4C13-4C7A4C530-)2A24-2A-2A23-2A3-2A19-3C2A3-2A3C14-4C8-5C10-4C13-4C7A4C529-
