model
size = 30 27 9, scale = 0.05, origin = -y
material 
  colors = A:#FFF B:#050000 C:#000 D:#9BADB7 E:#FBF236 F:#080808 G:#F3ECEC
voxels
43B3C26B5C23B9C21B9C20B12C17B13C16B16C5(13B17C)14B15C15B15C17B11C19BCB9C22B7C23B6C25B4C19BC7B2C14B180-31B10AB4A3B10A2B10AB4A2B11A3(2B28A)2B27A3B12(28A2B)AB2AB18A2B3A7BC19BC3B2-2E22-2E152-30BD9AB4A2B12A17(2D28A)2DB2AB24A31D2-2E22-2E152-31B8AB5AB13A7(2B28A)2(BC28A)8(2B28A)2B2AB25A7BC2A10BCB2AB2C4B2-2E2-5E8-5E2-2E9-ECE10-ECE14-3C10-3C14-CBC10-CBC14-CBF10CFBC15-C2BC8B2C8-29B2C25AB2A17(2C28A)2CB27A8C2A2B9CBA8C6-ECBCE8-ECBCE13-3E10-3E14-3C10-3C14-CBC10-CBC14-CBG10CGBC15-CBC9B2C8-31B25AB2A6(2B28A)2(BC28A)9(2B28A)3B27A7BC2A12BA3C5B6-5E8-5E13-ECE10-ECE14-3C10-3C14-CBC10-CBC14-CBF10CFBC15-2C10BFC8-31B14ABAB8AB2A17(2B28A)3B3AB23A7BCF13B4C5B180-31B14ABAB11A2B25AB2A16(2B28A)3B3AB23A13B2C8B2C6B180-614B2C5B3C6B180-
