model
size = 31 5 31, scale = 0.05, origin = -y
material 
  colors = A:#C00 B:#001 C:#6F6
voxels
12-2B2(4-A25-B)-C-2A25-B3-A25-2B3-A22-B11-A18-B-B28-B-B7-A-A18-B-B7-A20-B9-A-A16-B14-2A30-A14-B14-2A14-B15-A14-B14-2A13-2(B61-)B29-2(B19-A10-)B50-A10-B19-A31-2(A61-)A7-4(A23-A6-)A23-A5-A123-A30-4(A25-A4-)A25-A31-A123-5(A2-A27-)A2-2(A61-)2(A29-)BA29-B30-BA30-A29-B30-2(B61-)BA29-BA30-3(A29-B)2(A61-)A30-2(A29-B30-B)A29-B216-2(BA29-)BA31-A27-B2-A30-A89-2(B30-)3(B2-A27-)B220-C25-C222-2(B30-)2(B23-A6-)B23-A7-B21-2(A30-)A39-B62-B30-B19-A10-B19-A30-A167-2(B14-2A14-B30-)B14-2A16-3B7-A-A20-B7-A-A18-3B9-A18-B9-A-A18-3B7-A-A22-3A-2A25-2(A-)A26-2(A-)2A25-2(A-)A26-3A-2A12-
