model
size = 27 28 23, scale = 0.05, origin = -y
material 
  colors = A:#7EC200 B:#EFDB2D C:#35008B D:#B74242 E:#009
voxels
376-D25-3D25-D646-6(A2B24-)A2B537-2(A2B24-)7(AB25-)A2B24-A2B456-A2B3(24-3A)23-4(3B24-)2B2A2(24-3A)24-AB25-A2B402-A2B24-3A24-ACA3(23-B3A)23-2(BAB24-)3(B3A23-)B2(3A24-)AB25-A2B348-2(A2B24-)3A23-3(BAC24-)4A23-2AB24-2(4A23-)2AC24-2(B3A23-)B2(3A24-)AB25-A2B144-8B17-2B8-3B12-2B13-2B9-B17-B7-B19-2B4-B21-3B-B22-2AB-B22-AB-2B21-B3A2B21-B-CA2B21-BACA2(2B21-4A)2B22-EB-2B21-4A2B22-E2(CA2B21-2A)C-2(2B21-B3A)-B21-B3A-B22-AB3-B21-A2B3-B19-BA2B4-B17-B9-2B13-2B12-2B8-3B16-8B19-8A17-2A8-3A12-2A13-2A9-A17-A7-A19-2A4-A21-2AB-A22-A2B-A22-2(AB-2A21-B)-4A2(21-5AB)21-2AB-A22-2AB-AB21-5A22-5AB2(21-6A)21-2AC-2A2(21-B3A-A)22-AB3-A21-A2B3-A19-4B4-A17-A9-2A13-2A12-2A8-3A16-8A19-8B17-BA8-A2B12-BA13-BA9-A17-B7-B19-AB4-A21-2AB-B22-2AB-A21-BAB-AB21-BA2(B-2B21-2A)B-BA4(21-2AB-2B)21-4A2B21-4ABA21-4A2B21-5AB21-4A-A21-BAB2-B21-BAB3-A21-A2B3-B19-BA2B4-A17-B9-BA13-BA12-BA8-BAB16-BA4BAB19-8B17-BA8-A2B12-BA13-BA9-A17-B7-B19-AB4-A21-2AB-B22-A2B-A21-BAB-AB21-2(BA)2(2B21-2ABA)2B22-E2(BA)21-2ABA2B22-EBA2B21-2AB-2B22-EB-BA21-4A2B22-E2A2B21-5AB21-2AB2-A21-BAB2-B21-BCB3-A21-A2B3-B19-BA2B4-A17-B9-BA13-BA12-BA8-BAB16-BA4BAB19-8A17-2A8-3A12-2A13-2A9-A17-A7-A19-2A4-A21-2AB-A22-A2B-A21-BAB-2A21-BAB3A21-2AC2(-2A21-2AB)-AB21-2AB-2A21-2(2AB)21-2AB-2A21-2AB-AB3(21-2AB-2A)21-2AB2-A21-B2C2-A21-BAB3-A21-A2B3-A19-4B4-A17-A9-2A13-2A12-2A8-3A16-8A19-8B17-2B8-3B12-2B13-2B9-B17-B7-B19-2B4-B21-3B-B22-A2B-B21-2(B-)2B21-B-BA2(2B21-2AC-)2(2B21-2AB-)2B21-2A2(BA)21-2AB-2B21-A2B3(-2B21-2AB)-2B21-2AC2-B21-2BC2-B21-3B3-B21-A-B3-B19-BA2B4-B17-B9-2B13-2B12-2B8-3B16-8B19-8B17-2B8-3B12-2B13-2B9-B17-B7-B19-2B4-B21-3B-B22-2AB-B21-3B-2B21-3BA3(2B21-ABC-)2B21-A2B-2B21-A2BABA21-ACB5(-2B21-A2B)2-B21-B2C2-B21-BCB3-B21-A2B3-B19-BA2B4-B17-B9-2B13-2B12-2B8-3B16-8B19-8A17-2A8-3A12-2A13-2A9-A17-A7-A19-2A4-A21-2AB-A22-A2B-A21-BAB-2A21-BA2(B3A21-2A)B3A22-EB2AB21-2AB3A22-EB-AB21-2AB-2A22-EB-AB21-6A22-E4A21-6A21-2AB2-A21-BAB2-A21-BCB3-A21-A2B3-A19-4B4-A17-A9-2A13-2A12-2A8-3A16-8A19-8B17-BA8-A2B12-BA13-BA9-A17-B7-B19-AB4-A21-2AB-B22-2AB-A21-BAB-AB21-BA3(B-2B21-2A)B-BA3(21-2AB-2B)21-4ABA2(21-4A2B)21-5AB21-4A-A21-BAB2-B21-BAB3-A21-A2B3-B19-BA2B4-A17-B9-BA13-BA12-BA8-BAB16-BA4BAB19-8B17-BA8-A2B12-BA13-BA9-A17-B7-B19-AB4-A21-2AB-B22-A2B-A22-AB-AB21-BAB-2B21-B3A2B21-4ABA21-4A2(2B21-2AB-)2(2B21-4A)2B21-2AC-BA21-4A2B21-2AC-AB21-B3A-A21-B3A-B22-AB3-A21-A2B3-B19-BA2B4-A17-B9-BA13-BA12-BA8-BAB16-BA4BAB19-8A17-2A8-3A12-2A13-2A9-A17-A7-A19-2A4-A21-2(2AB-A22-)AB-2A2(21-B5A)21-B4A2(B21-5A)23-EB-AB21-5A23-EC2AB21-2AC3A21-2AC-2A21-B5A2(21-B3A-A)22-AB3-A21-A2B3-A19-4B4-A17-A9-2A13-2A12-2A8-3A16-8A19-8B17-2B8-3B12-2B13-2B9-B17-B7-B19-2B4-B21-2B2-B22-A2B-B22-A4B22-2(3A2B21-B)AC-2B21-B3A2B21-4A2B21-2AB-3(2B21-4A)3(2B21-B3A)-B22-3A-B22-A2B2-B21-A2B3-B19-BAB5-B17-B9-2B13-2B12-2B8-3B16-8B223-A2B24-2AB24-4(3A23-B)2(AB24-B)3(3A23-B)2(3A24-)A2B24-A2B402-A2B24-2AB2(24-3A)23-4(3B24-)2B2A2(24-3A)2(24-A2B)456-A2B24-9(AB25-)A2B511-7(2B24-A)2B25-2B592-2D25-2D52-2D25-2D297-
