model
size = 27 28 21, scale = 0.05, origin = -y
material 
  colors = A:#316A4D B:#25AA23 C:#3C3C8B D:#0A0A0A E:#007
voxels
376-D25-3D25-D646-6(A2B24-)A2B537-3(A2B24-)5(2B25-)AB25-A2B24-A2B456-A2B2(24-2AB)24-B2A23-4(3B24-)2B2A24-B2A24-3A24-AB25-A2B402-A2B24-2AB24-AC24-3(B3A23-)2(BAB24-)3(B3A23-)B2(3A24-)AB25-A2B348-2(A2B24-)2(3A23-B)AC24-B3A22-5A22-3AB23-2(5A22-)5A3(23-B3A)24-3A24-AB25-A2B144-8B17-2B8-3B12-2B13-2B9-B17-B7-B19-2B4-B21-3B-B22-2AB-B22-AB-2B21-B3ABA21-B-2ABA21-B3A2(BA20-5A)BA21-EAB-BA20-5ABA21-EA2(C-BA20-3A)C-BA21-B3A2B2(21-B3A-B)22-AB3-B21-A2B3-B19-2(AB)4-B17-B9-2B13-2B12-2B8-3B16-8B19-8A17-2A8-3A12-2A13-2A9-A17-A7-A19-2A4-A21-2AB-A22-A2B-A22-2(AB-2A21-B)-3A21-7A20-6A21-3AB-2A20-3AB-A21-7A20-6A21-2(7A20-)3AC-2A2(21-B3A-A)22-AB3-A21-A2B3-A19-2A2B4-A17-A9-2A13-2A12-2A8-3A16-8A19-8B17-BA8-A2B12-BA13-BA9-A17-B7-B19-AB4-A21-A2B-B22-2AB-A21-BAB-AB21-BA6(B-BA20-3A)B-3(BA20-5A)2B20-6AB20-5A-A21-BAB2-B21-BAB3-A21-A2B3-B19-2(AB)4-A17-B9-BA13-BA12-BA8-BAB16-BA4BAB19-8B17-BA8-A2B12-BA13-BA9-A17-B7-B19-AB4-A21-A2B-B22-A2B-A21-BAB-AB21-BAB-2A20-7A20-6A22-E5A2(20-3AB-A22-EAB-2A)20-7A21-E4AB20-6AB20-3AB2-A21-BAB2-B21-BC4-A21-A2B3-B19-2A2B4-A17-B9-BA13-BA12-BA8-BAB16-BA4BAB19-8A17-2A8-3A12-2A13-2A9-A17-A7-A19-2A4-A21-BAB-A22-BAB-A21-3B-2A21-2B2A2B20-2AB4A3(20-2(2AB)A)20-2A2B-BA20-2AC2-2(BA20-2A2B-)AB20-2A2B-BA20-2A2B-2A20-2A2B2-A21-BC3-A21-BC4-A21-3B3-A19-2(AB)4-A17-A9-2A13-2A12-2A8-3A16-8A19-8B17-2B8-3B12-2B13-2B9-B17-B7-B19-2B4-B21-A2B-B22-A2B-B21-BAB-BA21-B3ABA20-5A2B20-3AC-2B20-5A-A20-5A2(2B20-3AB2-A20-3AB-)2(BA20-3AB-)BA20-3A2(B2-B21-BA)B3-B21-A2B3-B19-BA2B4-B17-B9-2B13-2B12-2B8-3B16-8B19-8A17-2A8-3A12-2A13-2A9-A17-A7-A19-2A4-A21-2AB-A22-2AB-A21-BAB-2A21-B3A2B20-3AC-2A20-5ABA21-E3ABA20-5ABA21-EAB-BA20-5ABA21-E3ABA20-6AB21-E3ABA20-7A20-5A-A21-B3A-A21-BAB3-A21-A2B3-A19-2(AB)4-A17-A9-2A13-2A12-2A8-3A16-8A19-8B17-BA8-A2B12-BA13-BA9-A17-B7-B19-AB4-A21-A2B-B22-A2B-A21-BAB-AB21-BAB-2A20-7A20-6A21-7A20-3AB-A21-3AB-2A20-6A21-3AB-2A20-3A2C2A2(20-3AB-AB)20-3AB2-A21-B3A-B21-BAB3-A21-A2B3-B19-2A2B4-A17-B9-BA13-BA12-BA8-BAB16-BA4BAB19-8B17-BA8-A2B12-BA13-BA9-A17-B7-B19-AB4-A21-3B-B22-2AB-A22-AB-AB2(21-BAB-BA)4(20-3AB-BA)20-5ABA20-3A2CBA20-3AB-BA20-3A2C2B20-3AB-AB21-BAB2-A21-B3A-B22-AB3-A21-A2B3-B19-2(AB)4-A17-B9-BA13-BA12-BA8-BAB16-BA4BAB19-8A17-2A8-3A12-2A13-2A9-A17-A7-A19-2A4-A21-BAB-A22-A2B-A22-2(AB-2A21-B)AB-A22-B5A20-6A2(21-7A21-EAB-A)21-3A2C2A20-3A2(B-2A21-BA)B2-A21-B3A-A22-AB3-A21-A2B3-A19-2A2B4-A17-A9-2A13-2A12-2A8-3A16-8A19-8B17-2B8-3B12-2B13-2B9-B17-B7-B19-2B4-B21-2B2-B23-2B-B22-A4B22-2(AB-BA21-B)3ABA21-BAC-BA20-5ABA20-3AB-BA20-5ABA20-3A2CBA20-3AB-BA21-BA2CBA21-BAB-2B21-B3A-B22-AB2-B22-A2B2-B22-2B3-B19-2(AB)4-B17-B9-2B13-2B12-2B8-3B16-8B224-2(2B24-A)B24-3(B3A23-)BAB24-4(B3A23-)B3A24-AB25-A2B25-2B403-2B24-2(AB25-)5(AB24-B)2(AB25-)AB26-2B25-2B457-2B25-2B7(24-3B)2(25-2B)511-2(2(2B25-)2(2D25-))2B243-
