model
size = 26 28 21, scale = 0.05, origin = -y
material 
  colors = A:#0A0A0A B:#000 C:#001 D:#007
voxels
362-2B24-2C24-2B622-2(AB24-)3(2B24-)AB24-AB518-3(AB24-)2B2(24-BA)2(24-2B)3(24-AB)440-AB2(24-2A)24-BA4(23-3B)23-2BA24-BA24-2A2(24-AB)388-AB24-2A24-AC3(23-B2A)2(23-BAB)4(23-B2A)24-2A2(24-AB)165-8B16-2B8-3B11-2B13-2B8-B17-B6-B19-2B3-B21-B2-B22-AB-B22-A3B22-2(2ABA21-B)ACBA21-B2ABA20-4ABA20-3A2B3(A20-4AB)A21-B2ABA21-B2A2B21-B2(2A-B22-)AB2-B21-AB3-B19-2B5-B17-B8-2B13-2B11-2B8-3B15-8B18-8A16-2A8-3A11-2A13-2A8-A17-A6-A19-2A3-A21-2B-A22-2A-A22-AB2A21-B4A21-B-2A22-B4A20-5A21-6A21-DABA21-6A21-DACA21-3AC2A20-3AC2A21-B4A2(21-B2A-A)22-AB2-A21-AB3-A19-ABA4-A17-A8-2A13-2A11-2A8-3A15-8A18-8B16-BA8-A2B11-BA13-BA8-A17-B6-B19-AB3-A21-AB-B22-AB-A22-2(AB)21-BA2BA21-B-A2(BA20-4A)B2(A20-3A2B)3(A20-4AB)A20-4A2B20-3ACAB21-B2A-A21-B2A-B22-AB2-A21-AB3-B19-2AB4-A17-B8-BA13-BA11-BA8-BAB15-BA4BAB18-8B16-BA8-A2B11-BA13-BA8-A17-B6-B19-AB3-A21-AB-B22-2A-A21-2(BA)B21-BA2(B2A20-3A)2(BA21-3AB2A20-3A)BA21-2(6A20-)2(5AB20-)4A-A21-BAB-B21-BAB2-A21-AB3-B19-ABA4-A17-B8-BA13-BA11-BA8-BAB15-BA4BAB18-8A16-2A8-3A11-2A13-2A8-A17-A6-A19-2A3-A21-AB-A22-AB-A21-BAB2A21-BA3B20-6A20-4ABA21-D2AB2(A20-3A2BA21-DA2B)A20-5AB21-D2ABA20-6A20-3A2(B-A21-BA)C2-A21-AB3-A19-2AB4-A17-A8-2A13-2A11-2A8-3A15-8A18-8B16-2B8-3B11-2B13-2B8-B17-B6-B19-2B3-B21-2B-B22-BA-B21-4BA21-2BABA2(20-2ABA2B)20-2ABA-B20-2ABA2B20-2A2B-B20-2AC-2B20-2A2B-B3(20-2A3BA)20-2A2B2(-B21-2BC)2-B21-2B3-B19-2BA4-B17-B8-2B13-2B11-2B8-3B15-8B18-8A16-2A8-3A11-2A13-2A8-A17-A6-A19-2A3-A21-AB-A22-AB-A21-BAB2A21-B2A2B20-6A20-3AC2(BA20-4A)B3(A20-3A2B)A20-3ABAB20-3A2BA20-3AB2A20-3A2(B-A21-BA)B2-A21-AB3-A19-2AB4-A17-A8-2A13-2A11-2A8-3A15-8A18-8B16-BA8-A2B11-BA13-BA8-A17-B6-B19-AB3-A21-AB-B22-2A-A21-2(BA)B21-B4A20-3AC2A20-5A22-D4A20-5A22-DAB2A20-5A22-D4A20-6A21-D3AB20-5AB20-4A-A21-B2A-B21-BAB2-A21-AB3-B19-ABA4-A17-B8-BA13-BA11-BA8-BAB15-BA4BAB18-8B16-BA8-A2B11-BA13-BA8-A17-B6-B19-AB3-A21-AB-B22-AB-A21-2(BA)B21-BA2B3(A20-4AB)2(A20-3A2B)A20-4ABA20-3A2BA20-3ACBA20-3A3B20-3ABAB20-3AB-A21-B2A-B21-BAB2-A21-AB3-B19-2AB4-A17-B8-BA13-BA11-BA8-BAB15-BA4BAB18-8A16-2A8-3A11-2A13-2A8-A17-A6-A19-2A3-A21-2B-A22-2A-A22-2(AB2A21-B)A2(BA21-3AB2A20-3A)BA21-6A20-3ACA21-3AB2A20-3AC2A20-3AB2A21-BAB-A21-B2A-A22-AB2-A21-AB3-A19-ABA4-A17-A8-2A13-2A11-2A8-3A15-8A18-8B16-2B8-3B11-2B13-2B8-B17-B6-B19-2B3-B21-B2-B22-AB-B22-A3B21-BACBA21-BA2BA21-B2A2(BA20-4A)BA21-DA2BA20-4ABA21-DA2BA20-3ACBA20-3A2BA21-BA3B21-BAB-B21-B2A-B22-AB2-B21-AB3-B19-2B5-B17-B8-2B13-2B11-2B8-3B15-8B190-2(B24-A)B23-BAB23-B2A23-BAC22-4A22-3AB22-4A22-3AC22-3AB23-BAC23-BAB23-B2A2(24-AB)25-B337-2(B24-A)B3(23-B2A)23-BAB5(23-B2A)2(24-AB)25-B389-3(B24-A)5(B23-BA)2(B24-A)2(B25-)B441-B25-B7(24-2B)2(25-B)519-B2(25-C)51-B2(25-C)260-
