model
size = 29 27 27, scale = 0.05, origin = -y
material 
  colors = A:#111 B:#FC6 C:#222 D:#F4C874 E:#DAAF57 F:#888 G:#AAA H:#B69248 I:#EEE J:#777 K:#BBB L:#92763A M:#4A3D1D N:#D3BDA0 O:#DDD P:#633 Q:#26200E R:#996
voxels
368-A29-A26-2A695-C26-C4A23-2A22-C4-2A-A20-2A4-2A-C19-C-A-CAC3-C18-2A2-2A3-A24-3A21-A2-A-3AC22-A2-2A465-A26-A-AC23-2A-3A23-A2-2A2CA19-A-AC4A18-2A2-2C8A16-CA-2AC5A18-C6AC-AC18-2(C2A)2C2AC18-2AC-AC2A-2A18-C-2AC4A20-A2-C-2CA23-C410-A28-2A21-2A3-4A21-C-C2AC3A20-9AC17-A2C4ACA2CA16-2A-2ACAC5AC13-I2-C8AC2AC16-2(3AC)2A2CA16-2A2C2AC5A17-2(2AC)A5C17-C10AC17-A-2(C3A)19-3A2-CAC26-A28-A319-C28-C2A26-C3AC19-2D-7AC17-BC7AC2A17-2ACA3(C2A)15-2AC6AC2ACA15-F5AC8A12-A-I7ACA2CAC13-I2-CA2CAC3A2(CA)14-IA-AC5AC3AC17-CA2C3AC2A2C18-2(CA)C6A16-A2-4A3CAC17-3C-C6A18-ACA2-ACA-C21-A-2A312-2J6-3A18-C6-C5A15-CAD4-CAC4AC13-B2C2B-10A14-AG3AC6ACA15-AF2(2AC)6AC14-AFB4A2C4ACA13-2CFB9AC2AC12-2GFGA3C9A14-A-4A2C7A12-G-C-GC4A2(CA)C2A14-A-F2AC4ACAC2A12-I-G2-C2AC7A11-2I2-F2-6A3CAC19-G2A2C4A18-F2-G2A4C18-3CA2C2A25-GA199-A4-2A21-A32-A22-2A5-3AC2A15-A2B4-AC3AC2A13-DBD2C-4AC5AC-C9-2BCADB2C2AC2A2C2A12-DA3B2(A2C)2AC6A9-A2(BD)C5AC7A8-4KGBDAC3A2BDA2C3A10-H2BDB3CA2BDB4A2C10-3D2B4ADBD2AC4A10-C2GD2(B2D)BD5ACA9-GC2(BF)3BD3B2C4A9-IAG-GA4C3AC3A2CA10-FI2(AC)4AC2ACAC2AC8-GFC3A-3AC9A8-G2IJ2IA3-3AC3A2C2A8-I6-2A3-AC5A13-F4-10A22-2A-2A25-C86-ED3B22-E2D3B21-H-B2DB23-A5-2C-A19-3A2-ACA13-EBD3EL-A-3AC-2AC3A8-HBDBE4B2-A-2C4A3C7-HD2BAEDBAD2(AC)6AC2A7-HBDB3D2B6ACAC3A9-2D5BDA2C4AC4A-A2-J4-5BD2B4A3(C2A)3-K4-DBD2BDBD7B6A3-3OKO6B2(D3B)DACA2CA8-HD2BD7B2DBC5A8-3D3BDBD4BDB7A7-DB2(D2B)3(DB)DAC4A7-C-BDB3A3(CA)C3A2C2A7-2GBDG10A3(CA)9-FDFB5A2CAC3AC2AC5-IF-GC-BD4A3C6A2CA7-GAJ-F7AC2A3C3A8-2G3-3A3C3A2C3AC11-G3-4A2C6AC12-A4-2A2C5ACA21-A2CAC2A24-C53-E2BD4BD21-H2D3BDB13-H5-H2B2D4B12-H2D3B2DA2B-2ACAC3A9-HB3D2B2A2DBC-2CA3-A8-LD3BD2BL3D2-5A2(CA)7-L2B3DBD4B5A3C2A-A5-HB2(D3B)2D-9AC6-H2D2B4DB2D3A3C5A3-J-B2H3(BD)4BC6AC4A4-5BD2B3DBD2BD3B3ACAC3-M-4BD9BD2BDC4A4-B-5B2D3BDBD3B2D3AC2A3-N3BD4BDBD2BD4BD3AC2A4-HQDB2(D3B)D6BACA2CA5-4BD3B8D2BCAC3A6-2D3BAC2AC8AC2ACA5-A4BD2AC5A2C3A2(CA)5-R-FD3BCA2C3(AC)2A2C3A4-I2G2-BDBC10AC4A5-IFG2-ADBAC4ACA2C3A2C8-G3-JA2C5A2CAC2A2C9-F3-3A2C4AC5A11-A3-6ACA2CACA12-A4-11A19-A-2A-3A-A19-4BDB2DB18-HED4B2D2BD10-3DB2-3D9B10-E2DB2D6BD5BD10-E4DB2A2(BD)2B2ACAC2A8-E4B5D4BC4A2-2A7-HBD2BD3B2(DB)A-5CACA6-HD2B2D7B2C4AC5A5-H2(BD)B3DB2D5AC5A6-HBD9BACA3CAC2A2C2-J2-BD5B2D2BD2AC7A-C2-HB-7B2DBDB5ACA2CACA2-ED-5BD3B2D2BD3BDB4AC2-MBD2B2(DB)D2B2(2DB)DB2C5A2-N2BDA2BD3BD5BD2B7A3-A2BC5BD4B3D2B6AC4-BD3B2D2BDB2D5BA2CAC2A5-2B2D2B2(3CA)CA2(C3A)5-3D2BD16AC5-IA4BD2A2C2(AC)2A3CAC2A6-CF2BDB2C6AC4AC2A6-FAGFGDBAC2AC4A2C2A2(CA)7-G2-GB5ACAC4AC3A7-G5-6ACAC5AC8-F-C2-AC13A12-2C2-5AC2AC3A17-2C4A3-A-A17-5B3D3B10-E2D2-3DBD7B2D10-E-B2D3BD2(2B2D)B11-E3B2D2BD3BDBD3B10-LPBD4BD2B2DB5AC2A7-E2D2(BD)B2D2B2D3AC2AC3A5-E2BDB2D4BD2B4A3C3A-A4-L-2BDBD2BD3B2C8AC5-E2B2DBD2B2D2B4A2C5A5-H2DB5DB3D2CAC3AC4A2-J-7BDBD2BD8AC3A2-H2BD2B2D6BDC3A3C4AC2-E2(B3D)3B2D2BDBD2BDC3AC2-M4B2D6B3D4B2(2AC)AC-N7B2DB3D2(2BD)2(C2A)2C2-Q2BA3BD3B2D2B2DBD2A3C2A3-B2D2B2D6B2D4B7A4-2B3D2BC5AC3AC7A5-5BD2C5A4CAC3AC6-4BDB3A2C10AC2A4-F-3BDBC2A3CAC7A2C6-IF2(DB)AC8A3CAC2A5-IGA-FDB2A2C6AC2A2CA11-FG2(CA)2(C3A)CAC11-FC-14A12-11AC3A16-C4AC3A3-C17-B2DBD5B2D9-2(ED)2-3B4DBD3BDBD8-E5B2D2(BD)3B4DB9-E6B4D3B4DB2-A7-EB3D5BD3B3C4A8-LPDBD5B2D2B3A2C2-3A5-EBD2BD6BDB7AC2AC4-E2D2BD5BDBD2AC3AC4A5-D5BDB2DBDBC2AC5ACAC4-2DBD4B2D3B2ACAC2AC4A2-J2BDB2D8B9A2CA2-F2BD4B3D2BDBA3C2AC5A2-KBD3BD5BD3BDB2DBDB4AC-K6B3D4B2D2BDB3A2C3A2-H2DBD5B2D3(BD)BA2C5A2-H2DA2BD2B2D7BDC7A2-A6B3DB2D2ACAC2AC4ACA3-2B2(DB)DC2AC7A3C2A2C4-2(D2B)D4A3C3AC7A5-2B2D2B3C4A2C4AC4A5-D5B2C10ACAC2A5-2F2B3D2C6AC4A2CAC7-2G3D4AC3AC7A10-IGDC4ACAC5A2CA8-F4-G14A9-G-4A2C3A2C2ACA-A12-A-2AC7A2-A16-3BDB2D2BD3B9-EB2D2-10B2DB2D8-E3DBDB2D7B2D2B9-2DB3D4B3(DB)D2B2-A7-DBD2BDB2D3BDB3A3C9-LPD2BD5B3D5A2-3A5-7BD2B2(DB)ACA5C3A4-E2(2BD)4BD2B6A2C3AC4-2D4BDBD4B4AC7A3-6BDB2(D2B)4ACAC3A2C-2BDBD2BD3BD4B2(AC)6AC2AB4DB2D2BDB3DBA2(C2A)C5A2-2(D5B)D4BDB3D2C3A2-JD2B2D2BD4BD5BDBD3ACA2-8BD3B2(D2B)D2AC2A3C2-2B2(D3B)2(D2B)2DB4AC3A2-2DB2D3B5AC3ACA2CAC3AC3-D3BD2B5A2CAC2A2(CA)C2A4-3D2(BD)7AC6AC2AC4-BDB2D2BC5A2C3A2(C2A)6-2D2BDBAC3A3C4AC5A4-G-2BD2BCAC5AC2ACA3CA6-AG4BC3AC7AC3A9-IF2G7AC3AC4A8-F4-G2A3C2AC2A2C2A14-4A2C6A-A15-7ACAC-C16-3B2DBD5BD9-E3D2-2BD3BDB2(D2B)D8-E4DBD2B2D4BD4B9-DB2D5BD2BD6B10-2D2B2DB2D2BD2B3A2C2-A7-LPD6BD4B2AC2A2-C2AC4-BD12B8AC2A4-E2(2BD)BD5BA2(C2A)C4A4-D3BD6B2D5A2(C2A)C3-2B2(DB)D2BDBD2B6A2(2CA)-2(2BD)B3DBD2B2D5ACA2C4A5B3D3(BD)2B3AC2(A2C)AC3-3BD4BDB3D5B2DBDAC2A3-J2B2D2BDBD2B2D7BD4A3-4BD9BD4BAC5A3-5BD8B2D2BDCAC4A3-8B2A2(C6A)CA4-3BDB2DAC2A2C6AC6A3-DBD4BC2AC7AC2AC4A3-2B2D3B8A3C5AC6-DBD3B2CAC3A2C5AC3A6-D2BDB4A2C3ACA2C2ACA6-R-2BA4C2A2C5A2(CA)8-F2-C2A2C3AC2A2C5A9-A-2AC4A2CA2C5A11-2AC2A2C8A2C14-3AC2ACA3-CA16-HDBD3B2(D2B)9-E3D2-6B3D3BDBD8-EB2D6BD3BDBD2BD9-EBD3BDBD4BDB2AC2A9-2(2D2B)D5B4ACA-C7-LPBD2B3D3BDB4A2C-C3A4-E5B3D5BCAC5A2CA4-E3BD4B2DBDBAC2AC6AC4-BD4B2D2B2DBC4AC6A4-H2(D2B)DBD3B9AC2A2-J2D2(BD2BD)2B3A4C4A2C-G3D7BD3B6A2CA2C2A-FD3B2(D2B)3DB2D3BD2B3AC2-OBD3B2DB2D3BD2BD3BDBC3A3-H5BDB2DBD3BD2BDA2C2(AC)3-HB4(D3B)C2AC5A2-A3(BD)B4AC2A3C6AC2A3-2D2BD2B3AC6AC3A2CACA3-2BD4B6AC7AC3A5-D5BC6A2C7ACA5-B2D3B3AC5ACAC3AC2A6-2BAC4ACA2C3AC5A8-GB6ACAC3AC2A2C3A7-C-G2AC11AC3A12-3AC8AC2AC13-AC2ACAC5AC-A18-C2ACA3-A17-HD2BD7B10-ED3-2H3B2D4BD2BD9-2B3D2BD10B11-E2BD2B2D4BDB4AC9-LP2B3DBD4BC6A3-A5-ED2BDB4D2BD7A-3A5-EDB2DBD6BC2A2C3AC2AC5-L3BD2BDBD2B4AC6A6-ED2(B2D)3BDB7AC2ACA4-HB6DBDB2D5AC3A2CA2-J-B3D2BD3B2DB6AC5A2-4BD2BD3B2(DB)2(AC)5AC3A-E2DBDB2DB2(D2B)C3AC2BDC4A-M4B2DB4D4B3D4B2CA2C-ND3B2DBD3BD2B2(DB)2AC6A2-Q2BAB3DBD5BDBD3AC3A2C2-HBD4BD3AC7AC4A2CA3-B2DBD2B2A2(C4A)CAC3AC3-B2D2(BD)AC3AC5AC4ACA5-2B2DBDAC2A3CAC4ACAC3A4-2(B2D)B11AC5A5-D2BC7A2C3AC6A7-IBD8ACA2C2(AC)2A9-I-AC3ACAC6AC2AC11-C2AC6AC4A-A13-A-2A2CAC3ACA-C16-A2-AC2A3-A18-3D3B4D17-H4B2DBD4B10-EDB2-2BD3BD5BD10-E4D2(BD)6B5A9-E2B3DB2D2BDB2AC5A8-E2DB3(D2B)3AC4AC2A6-L5BD3BDB3(AC)6A5-H2BD3BDB3DAC4ACA2C2A6-EB2D2B3DBDB4A3C2AC2A5-DB2DBD6BC2A3C2(2AC)2-J-2D4BDBD4B12A2-2(BD)2(3B2D)B3AC2AC5A2-E3B2DB2D6BC4AC6A2-MB2DBD3B2D2BD3BDBD2BD5A-N3(BD)B2D4BD3BD4A2C3A2-QDBA3BD3AC2ACAC3A2C4A4-2D2BDBDACA2C5A2CAC2A2C4-B2D2BDB6AC4A2C4A6-2BD3B2(2AC5AC)A4-2B2DB2D2AC7AC6AC5-D2B4AC6A2(2C2A)7-JB2A2(CA)C4AC3A2CACA8-IB18A10-IB4AC2ACAC2AC3A12-I2-AC6AC3A2C16-3(C2A)-CA17-2A4-A2C20-D5-D20-HDB5D2BD18-3HDBD3BDB11-2B2-3B2D2H2BD2A2CA10-L2(2BD)BE3B6A11-HBD2B3DBDED2AC3A-CAC7-L3B2(D2B)DB2(CA)C6A7-LB2D4B2DB3A2(C2A)2CA6-H2DB2D5BD3AC2AC4A6-E2BD4BD3B2A3C2A2CAC3-J2-4BD3BD2BD8A2CA4-B-BD7BDBD6AC5A3-MD11BD2AC3A2CAC2A2-3BDB7D4B2D4B5A3-N2DA3D5BDB2DBDCAC4AC4-HBAB2DBC3ACAC7A2(CA)4-3D4B2AC9A2C2ACA5-2B2D2BAC2AC8A2C4A4-A3BD2B3A2C6A2C5A5-A2(DB)D4ACA3C4A3C7-JBDCA2C14A9-ID5ACAC8ACA10-IA2C3A2(CA)C2A4C12-IG2ACA2C2(AC)2AC2A15-6AC6A16-A2-4A-C-AC19-AC3AC51-ED4BD-B21-E7B24-D3AC12-2(BD)7-6A12-E2(BD)2BE3-2(CA)5-A8-HBD3BD2BAC3AC6A8-H4B2(DB)2AC3AC6A7-EBE4D2(BD)B9AC7-EDEBDB4D2BAC3A3CACA7-H6B3DB11A3-F3-11B8A2CA2(3-K)3BD3B2DB11A3-O2K-B3D3BD4B2D2BDC4A6-H3BD6B2D2BD4(AC)5-2(D2B)5A2CAC2AC6A6-2BDBDAC3AC6A2C4A5-A-D2BDB2AC11ACA7-A2BD2B4A3CA2C2ACAC8-JD4BCAC7A2C4A8-IBC2AC3A2C7A2C10-I2F3AC2A2C4A2(CA)12-F4A2CAC2AC4A15-2C2(2AC)2(AC)A16-2(C5A)19-2AC2A2C142-3A26-2CA50-C2(2-2A)CAC13-2ED2(-A)-C2A2C4A11-2EBDBA2B2A2C3A2C2A10-2BD3BAB2(4AC)A9-BD2BD5B3AC5AC8-E7B2DB3C2ACAC2A9-BD4BD2BDC3A2(CA)2CA6-K2(DB)D6BD4B2A2C2A9-BDB3DBD6B2AC3A9-2BD2C9A2C4A9-B2D3A2C2(AC)6ACA9-C3B2C4AC5AC3A9-C2BD5ACAC8A9-F2GBA3C2(AC)8A10-IFCAC4ACAC6A13-F3C2A2C4AC2A14-2CAC4ACAC3A16-4ACA2C-3A18-3A3-ACA257-A3-C19-A5-6A15-3ACA-2C4AC2A14-ABCBA-AC3AC2AC13-IBA2B-2C2AC3ACA14-2AD2B4AC6A12-CADB2DC5AC4A8-5KCB3D2BD2B3AC2A12-AKBD2B2(3AC)AC2A11-CFAF2AC4AC6A11-FBCF3AC2A2CAC3AC11-FD6A2(C4A)10-IGB3AC6AC3AC11-2IG2AC3ACAC3A2CA13-FAC2A2C8A15-F3(AC)2AC4A16-6A2C3A18-C3AC2ACA23-4A290-CAC18-A5-3ACAC16-4A2-7AC15-A-3B-A2C5A14-IA-DAC5A5C13-I2-B2DC3ACA2C2A15-F5B9A14-FC2ACAC8A16-F9ACAC13-I2-3C2(2AC)4A13-3I3A3CAC5A12-IFA-3A2CAC3A3C13-F3AC5ACAC2A15-4AC7ACA16-6A2C4A17-C3A2C4A20-2AC3A348-C26-AC3A20-A-8A19-DB-8A18-D2AC5ACA17-DCBC5AC3A16-I2G4A3CA2C18-2AC5AC2A17-IC10A16-C-4(AC)3A15-2A-CAC5AC2A15-2A2C4A2(C2A)16-2A4CAC3AC17-C4AC5A19-2AC3A435-2C21-A4-2ACAC19-2A-GC5A22-FC2A2CA21-2F7A19-FGC7AC17-8AC2AC17-C-A2C5AC17-FA-C3AC4A17-2(AC)7A19-AC7A21-C4A521-3A25-2(C2A)23-C5A22-G2(AC)3A18-3F2AC5A17-FCF4A2(CA)19-F2ACA2C2AC19-2C7A22-4A25-A583-AC25-4AC23-CAC2A25-3A26-A-AC24-A638-A-2A24-GAC2A25-2A300-
