model
size = 29 27 28, scale = 0.05, origin = -y
material 
  colors = A:#111 B:#FC6 C:#222 D:#F4C874 E:#888 F:#AAA G:#EEE H:#DAAF57 I:#202424 J:#B69248 K:#000 L:#404848 M:#BBB N:#777 O:#819191 P:#600 Q:#E00 R:#92763A S:#DDD T:#D3BDA0 U:#996 V:#26200E W:#A2B6B6
voxels
452-A-2A24-FAC2A25-2A669-C752-A29-A26-2A695-C26-C4A23-2A22-C4-2A-A20-2A4-2A-C19-C-A-CAC3-C18-2A2-2A3-A24-3A21-A2-A-3AC22-A2-2A465-A26-A-AC23-2A-3A23-A2-2A2CA19-A-AC4A18-2A2-2C8A16-CA-2AC5A18-C6AC-AC18-2(C2A)2C2AC18-2AC-AC2A-2A18-C-2AC4A20-A2-C-2CA23-C410-A28-2A21-2A3-4A21-C-C2AC3A20-9AC17-A2C4ACA2CA16-2A-2ACAC5AC13-G2-C8AC2AC16-2(3AC)2A2CA16-2A2C2AC5A17-2(2AC)A5C17-C10AC17-A-2(C3A)19-3A2-CAC26-A28-A319-C28-C2A26-C3AC19-2D-7AC17-BC7AC2A17-2ACA3(C2A)15-2AC6AC2ACA15-E5AC8A12-A-G7ACA2CAC13-G2-CA2CAC3A2(CA)14-GA-AC5AC3AC17-CA2C3AC2A2C18-2(CA)C6A16-A2-4A3CAC17-3C-C6A18-ACA2-ACA-C21-A-2A312-2N6-3A18-C6-C5A15-CAD4-CAC4AC13-B2C2B-10A14-AF3AC6ACA15-AE2(2AC)6AC14-AEB4A2C4ACA13-2CEB9AC2AC12-2FEFA3C9A14-A-4A2C7A12-F-C-FC4A2(CA)C2A14-A-E2AC4ACAC2A12-G-F2-C2AC7A11-2G2-E2-6A3CAC19-F2A2C4A18-E2-F2A4C18-3CA2C2A25-FA199-A4-2A21-A32-A22-2A5-3AC2A15-A2B4-AC3AC2A13-DBD2C-4AC5AC-C9-2BCADB2C2AC2A2C2A12-DA3B2(A2C)2AC6A9-A2(BD)C5AC7A8-4MFBDAC3A2BDA2C3A10-J2BDB3CA2BDB4A2C10-3D2B4ADBD2AC4A10-C2FD2(B2D)BD5ACA9-FC2(BE)3BD3B2C4A9-GAF-FA4C3AC3A2CA10-EG2(AC)4AC2ACAC2AC8-FEC3A-3AC9A8-F2GN2GA3-3AC3A2C2A8-G6-2A3-AC5A13-E4-10A22-2A-2A25-C86-HD3B22-H2D3B21-J-B2DB23-A5-2C-A14-B4-3A2-ACA13-HB-3HR-A-3AC-2AC3A8-JBDBH4B2-A-2C4A3C7-JD2BAHDBAD2(AC)6AC2A7-JBDB3D2B6ACAC3A9-2D5BDA2C4AC4A-A2-N4-5BD2B4A3(C2A)3-M4-DBD2BDBD7B6A3-3SMS6B2(D3B)DACA2CA8-JD2BD7B2DBC5A8-3D3BDBD4BDB7A7-DB2(D2B)3(DB)DAC4A7-C-BDB3A3(CA)C3A2C2A7-2FBDF10A3(CA)9-EDEB5A2CAC3AC2AC5-GE-FC-BD4A3C6A2CA7-FAN-E7AC2A3C3A8-2F3-3A3C3A2C3AC11-F3-4A2C6AC12-A4-2A2C5ACA21-A2CAC2A24-C53-H2BD4BD21-J2D3BDB13-J5-J2B2D4B12-J2-3B2DA2B-2ACAC3A9-JBD-D2B2A2DBC-2CA3-A8-RD3BD2BR3D2-5A2(CA)7-R2B3DBD4B5A3C2A-A5-JB2(D3B)2D-9AC6-J2D2B4DB2D3A3C5A3-N-B2J3(BD)4BC6AC4A4-5BD2B3DBD2BD3B3ACAC5-4BD9BD2BDC4A6-2Q3B2D3BDBD3B2D3AC2A3-T3BD4BDBD2BD4BD3AC2A4-JVDB2(D3B)D6BACA2CA5-4BD3B8D2BCAC3A6-GD3BAC2AC8AC2ACA4-GA4BD2AC5A2C3A2(CA)4-GU-ED3BCA2C3(AC)2A2C3A4-G2F2-BDBC10AC4A5-GEF2-ADBAC4ACA2C3A2C8-F3-NA2C5A2CAC2A2C9-E3-3A2C4AC5A11-A3-6ACA2CACA12-A4-11A19-A-2A-3A-A19-4BDB2DB18-JHD4B2D2BD10-D-DB2-3D9B10-H2DB2D6BD5BD10-H2DBDB2A2(BD)2B2ACAC2A8-H4B5D4BC4A2-2A7-JBD2BD3B2(DB)A-5CACA6-JD2B2D7B2C4AC5A5-J2(BD)B3DB2D5AC5A6-JBD9BACA3CAC2A2C2-N2-BD5B2D2BD2AC7A-C2-JB-7B2DBDB5ACA2CACA3-D-5BD3B2D2BD3BDB4AC5-Q3(BD)2B2(2DB)DB2C5A2-T2BDA2BD3BD5BD2B7A3-A2BC5BD4B3D2B6AC4-BD3B2D2BDB2D5BA2CAC2A5-2B2D2B2(3CA)CA2(C3A)5-3D2BD16AC5-GA4BD2A2C2(AC)2A3CAC2A6-CE2BDB2C6AC4AC2A6-EAFEFDBAC2AC4A2C2A2(CA)7-F2-FB5ACAC4AC3A7-F5-6ACAC5AC8-E-C2-AC13A12-2C2-5AC2AC3A17-2C4A3-A-A17-5B3D3B10-H2D2-3DBD7B2D10-H-B2D3BD2(2B2D)B11-P3B2D2BD3BDBD3B11-PBD4BD2B2DB5AC2A7-H2D2(BD)B2D2B2D3AC2AC3A5-H2BDB2D4BD2B4A3C3A-A4-R-2BDBD2BD3B2C8AC5-H2B2DBD2B2D2B4A2C5A5-J2DB5DB3D2CAC3AC4A2-N-7BDBD2BD8AC3A2-J2BD2B2D6BDC3A3C4AC3-2(B3D)3B2D2BDBD2BDC3AC5-QB2D6B3D4B2(2AC)AC-T7B2DB3D2(2BD)2(C2A)2C2-V2BA3BD3B2D2B2DBD2A3C2A3-B2D2B2D6B2D4B7A4-2B3D2BC5AC3AC7A5-5BD2C5A4CAC3AC6-4BDB3A2C10AC2A4-E-3BDBC2A3CAC7A2C6-GE2(DB)AC8A3CAC2A5-GFA-EDB2A2C6AC2A2CA11-EF2(CA)2(C3A)CAC11-EC-14A12-11AC3A16-C4AC3A3-C17-B2DBD5B2D9-2(HD)2-3B4DBD3BDBD8-D5B2D2(BD)3B4DB9-H6B4D3B4DB2-A9-P2D5BD3B3C4A9-PDBD5B2D2B3A2C2-3A5-2(2BD)6BDB7AC2AC5-2D2BD5BDBD2AC3AC4A5-D5BDB2DBDBC2AC5ACAC4-2DBD4B2D3B2ACAC2AC4A2-N2BDB2D8B9A2CA2-E2BD4B3D2BDBA3C2AC5A2-MBD3BD5BD3BDB2DBDB4AC4-Q3B3D4B2D2BDB3A2C3A-LJ2DBD5B2D3(BD)BA2C5A2-J2DA2BD2B2D7BDC7A2-A6B3DB2D2ACAC2AC4ACA3-2B2(DB)DC2AC7A3C2A2C4-2(D2B)D4A3C3AC7A5-2B2D2B3C4A2C4AC4A5-D5B2C10ACAC2A5-2E2B3D2C6AC4A2CAC7-2F3D4AC3AC7A10-GFDC4ACAC5A2CA8-E4-F14A9-F-4A2C3A2C2ACA-A12-A-2AC7A2-A16-3BDB2D2BD3B9-DB2D2-10B2DB2D8-4DBDB2D7B2D2B9-2DB3D4B3(DB)D2B2-A9-P2BDB2D3BDB3A3C10-PD2BD5B3D5A2-3A5-7BD2B2(DB)ACA5C3A5-2(2BD)4BD2B6A2C3AC4-2D4BDBD4B4AC7A3-6BDB2(D2B)4ACAC3A2C-2BDBD2BD3BD4B2(AC)6AC2AB4DB2D2BDB3DBA2(C2A)C5A2-L2(5BD)4BDB3D2C3A2-LD2B2D2BD4BD5BDBD3ACA2-8BD3B2(D2B)D2AC2A3C2-2B2(D3B)2(D2B)2DB4AC3A2-2DB2D3B5AC3ACA2CAC3AC3-D3BD2B5A2CAC2A2(CA)C2A4-K2D2(BD)7AC6AC2AC4-IDB2D2BC5A2C3A2(C2A)6-2D2BDBAC3A3C4AC5A4-F-2BD2BCAC5AC2ACA3CA6-AF4BC3AC7AC3A9-GE2F7AC3AC4A8-E4-F2A3C2AC2A2C2A14-4A2C6A-A15-7ACAC-C16-3B2DBD5BD9-4D2-2BD3BDB2(D2B)D8-5DBD2B2D4BD4B9-2B2D5BD2BD6B12-P2(B2D)2BD2B3A2C2-A8-PD6BD4B2AC2A2-C2AC4-BD12B8AC2A5-2(2BD)BD5BA2(C2A)C4A4-D3BD6B2D5A2(C2A)C3-2B2(DB)D2BDBD2B6A2(2CA)-2(2BD)B3DBD2B2D5ACA2C4A5B3D3(BD)2B3AC2(A2C)AC3-K2BD4BDB3D5B2DBDAC2A3-K2B2D2BDBD2B2D7BD4A3-I3BD9BD4BAC5A3-K4BD8B2D2BDCAC4A3-K7B2A2(C6A)CA4-I2BDB2DAC2A2C6AC6A3-KBD4BC2AC7AC2AC4A4-I2D3B8A3C5AC6-DBD3B2CAC3A2C5AC3A6-D2BDB4A2C3ACA2C2ACA6-U-2BA4C2A2C5A2(CA)8-E2-C2A2C3AC2A2C5A9-A-2AC4A2CA2C5A11-2AC2A2C8A2C14-3AC2ACA3-CA16-JDBD3B2(D2B)9-H3D2-6B3D3BDBD8-HB2D6BD3BDBD2BD9-HBD3BDBD4BDB2AC2A11-PB2D2BD5B4ACA-C8-PBD2B3D3BDB4A2C-C3A4-D5B3D5BCAC5A2CA6-2BD4B2DBDBAC2AC6AC4-BD4B2D2B2DBC4AC6A4-K2(D2B)DBD3B9AC2A4-O2(BD2BD)2B3A4C4A2C-IO2D7BD3B6A2CA2C2A2-L3B2(D2B)3DB2D3BD2B3AC4-Q3B2DB2D3BD2BD3BDBC3A3-L5BDB2DBD3BD2BDA2C2(AC)3-LB4(D3B)C2AC5A2-I3(BD)B4AC2A3C6AC2A3-K2(D2B)3AC6AC3A2CACA3-IBD4B6AC7AC3A5-I5BC6A2C7ACA5-B2D3B3AC5ACAC3AC2A6-2BAC4ACA2C3AC5A8-FB6ACAC3AC2A2C3A7-C-F2AC11AC3A12-3AC8AC2AC13-AC2ACAC5AC-A18-C2ACA3-A17-JD2BD7B10-HD3-2J3B2D4BD2BD9-2B3D2BD10B11-P2BD2B2D4BDB4AC10-P2B3DBD4BC6A3-A5-HD2BDB4D2BD7A-3A5-HDB2DBD6BC2A2C3AC2AC5-K3BD2BDBD2B4AC6A6-KD2(B2D)3BDB7AC2ACA4-KB6DBDB2D5AC3A2CA4-O3D2BD3B2DB6AC5A2-L-OBD2BD3B2(DB)2(AC)5AC3A2-L2(DB)2DB2(D2B)C3AC2BDC4A3-Q2B2DB4D4B3D4B2CA2C-LD3B2DBD3BD2B2(DB)2AC6A2-L2BAB3DBD5BDBD3AC3A2C2-IBD4BD3AC7AC4A2CA3-L2DBD2B2A2(C4A)CAC3AC3-I2D2(BD)AC3AC5AC4ACA5-2B2DBDAC2A3CAC4ACAC3A4-2(B2D)B11AC5A5-D2BC7A2C3AC6A7-GBD8ACA2C2(AC)2A9-G-AC3ACAC6AC2AC11-C2AC6AC4A-A13-A-2A2CAC3ACA-C16-A2-AC2A3-A18-3D3B4D17-J4B2DBD4B10-RDB2-2BD3BD5BD10-H2D-2(DB)D6B5A9-H2B3DB2D2BDB2AC5A8-H2DB3(D2B)3AC4AC2A6-K5BD3BDB3(AC)6A5-I2BD3BDB3DAC4ACA2C2A6-IB2D2B3DBDB4A3C2AC2A4-OLB2DBD6BC2A3C2(2AC)4-OD4BDBD4B12A2-L2OD2(3B2D)B3AC2AC5A3-L2B2DB2D6BC4AC6A4-QDBD3B2D2BD3BDBD2BD5A-L3(BD)B2D4BD3BD4A2C3A2-LDBA3BD3AC2ACAC3A2C4A4-ID2BDBDACA2C5A2CAC2A2C4-K2D2BDB6AC4A2C4A6-IBD3B2(2AC5AC)A4-2B2DB2D2AC7AC6AC5-D2B4AC6A2(2C2A)7-NB2A2(CA)C4AC3A2CACA8-GB18A10-GB4AC2ACAC2AC3A12-G2-AC6AC3A2C16-3(C2A)-CA17-2A4-A2C20-D5-D20-JDB5D2BD18-3JDBD3BDB12-B3-2B2D2J2BD2A2CA10-K2(2BD)BH3B6A11-IBD2B3DBDHD2AC3A-CAC8-I3(2BD)B2(CA)C6A7-LB2D4B2DB3A2(C2A)2CA5-OL2DB2D5BD3AC2AC4A5-OL2BD4BD3B2A3C2A2CAC6-W2(3BD)2BD8A2CA3-2O-OD7BDBD6AC5A3-2LI10BD2AC3A2CAC2A4-QDB7D4B2D4B5A2-L2IDA3D5BDB2DBDCAC4AC4-IBAB2DBC3ACAC7A2(CA)4-2KD4B2AC9A2C2ACA5-KI2D2BAC2AC8A2C4A4-I3BD2B3A2C6A2C5A5-K2(DB)D4ACA3C4A3C7-NBDCA2C14A9-GD5ACAC8ACA10-GA2C3A2(CA)C2A4C12-GF2ACA2C2(AC)2AC2A15-6AC6A16-A2-4A-C-AC19-AC3AC51-HD4BD-B21-H7B24-D3AC12-KDBD7-6A12-IKDBD2BH3-2(CA)5-A8-IKD3BD2BAC3AC6A8-I2K2B2(DB)2AC3AC6A7-2IK4D2(BD)B9AC8-IKBDB4D2BAC3A3CACA7-I6B3DB11A3-N3-I10B8A2CA3-L3-I3BD3B2DB11A3-L2M-B3D3BD4B2D2BDC4A6-3IBD6B2D2BD4(AC)5-3ID2B5A2CAC2AC6A6-2IKBDAC3AC6A2C4A5-I-K2BDB2AC11ACA7-K2BD2B4A3CA2C2ACAC8-ND4BCAC7A2C4A8-GBC2AC3A2C7A2C10-G2E3AC2A2C4A2(CA)12-E4A2CAC2AC4A15-2C2(2AC)2(AC)A16-2(C5A)19-2AC2A2C142-3A26-2CA44-H5-C2(2-2A)CAC13-2HD2(-A)-C2A2C4A11-2HBDBA2B2A2C3A2C2A10-2BD3BAB2(4AC)A9-KD2BD5B3AC5AC9-K6B2DB3C2ACAC2A9-KD4BD2BDC3A2(CA)2CA6-M2(DB)D6BD4B2A2C2A9-KDB3DBD6B2AC3A9-KBD2C9A2C4A10-2D3A2C2(AC)6ACA9-K3B2C4AC5AC3A9-C2BD5ACAC8A9-E2FBA3C2(AC)8A10-GECAC4ACAC6A13-E3C2A2C4AC2A14-2CAC4ACAC3A16-4ACA2C-3A18-3A3-ACA257-A3-C19-A5-6A15-3ACA-2C4AC2A14-ABCBA-AC3AC2AC13-GBA2B-2C2AC3ACA14-2AD2B4AC6A12-CADB2DC5AC4A8-5MCB3D2BD2B3AC2A12-AMBD2B2(3AC)AC2A11-CEAE2AC4AC6A11-EBCE3AC2A2CAC3AC11-ED6A2(C4A)10-GFB3AC6AC3AC11-2GF2AC3ACAC3A2CA13-EAC2A2C8A15-E3(AC)2AC4A16-6A2C3A18-C3AC2ACA23-4A290-CAC18-A5-3ACAC16-4A2-7AC15-A-2BA-A2C5A14-GA-DAC5A5C13-G2-B2DC3ACA2C2A15-E5B9A14-EC2ACAC8A16-E9ACAC13-G2-3C2(2AC)4A13-3G3A3CAC5A12-GEA-3A2CAC3A3C13-E3AC5ACAC2A15-4AC7ACA16-6A2C4A17-C3A2C4A20-2AC3A348-C26-AC3A20-A-8A19-DA-8A18-D2AC5ACA17-DCAC5AC3A16-G2F4A3CA2C18-2AC5AC2A17-GC10A16-C-4(AC)3A15-2A-CAC5AC2A15-2A2C4A2(C2A)16-2A4CAC3AC17-C4AC5A19-2AC3A435-2C21-A4-2ACAC19-2A-FC5A22-EC2A2CA21-2E7A19-EFC7AC17-8AC2AC17-C-A2C5AC17-EA-C3AC4A17-2(AC)7A19-AC7A21-C4A521-3A25-2(C2A)23-C5A22-F2(AC)3A18-3E2AC5A17-ECE4A2(CA)19-E2ACA2C2AC19-2C7A22-4A25-A583-AC25-4AC23-CAC2A25-3A26-A-AC24-A215-
