model
size = 24 24 18, scale = 0.05, origin = -y
material 
  colors = A:#202020 B:#FFD319 C:#FF901F D:#FF2975 E:#F222FF F:#8C20FF G:#01CDFE H:#6498CC
voxels
27-18F2(6-18E)2(6-18D)2(6-18C)2(6-18B)345-3(12A12-)4A4F4A12-4AE2AE4A12-4AD2AD4A12-4AC2AC4A12-4A4B4A4(12-12A)2(300-11(12A12-)12A)297-2(9(3A12-3A6-)2(18A6-)18A9-2(12A12-)12A225-)9(3A12-3A6-)2(18A6-)18A9-2(12A12-)12A222-3A8(18-6A)18-75A3-2(18A6-)18A219-3A8(18-6A)18-75A-2(A-18A-A2-)D-18A-D2-C20-C2-B20-B169-3A8(18-6A)18-77AB18AB4AF18AF4AC18AC5(4A20-)3A22-AD22-DC22-C24-3A8(18-6A)18-77AB18AB4AF18AF4AC18AC5(4A20-)3A22-AD22-DC22-CB22-B3A8(18-6A)18-75A-2(A-18A-A2-)D-18A-D2-C20-C2-B20-B169-3(3A8(18-6A)18-75A3-2(18A6-)18A219-)3A8(18-6A)18-75A3-2(18A6-)18A222-18F2(6-18E)2(6-18D)2(6-18C)2(6-18B)366-18F6-E2F14HE6-E16BE2(6-D16GD)6-18C6-C16GC2(6-18B)363-
