model
size = 32 25 32, scale = 0.05, origin = -y
material 
  colors = A:#0A0 B:#050 C:#222 D:#111 E:#040 F:#960 G:#777 H:#888 I:#444 J:#630 K:#E00 L:#EEE M:#FF0
voxels
32-32A736-3(32A768-)32A102-2(6D8-6D12-)6D2-4B2-6D12-6D-2B2E2B-6D19-3(B-2E-B26-)BK2EKB26-2B2E2B28-2B367-32A70-6D8-6D13-2(5C8-5C14-)5C2-4B2-5C14-5C-6B-5C13-6D-6B-6D19-2(6B26-)BK2BKB26-6B27-4B366-32A38-6D8-6D13-C3DC8-C3DC2(14-5C8-5C)14-5C-D4BD-5C14-5C-6B-5C14-C3DC-6B-C3DC13-6D-6B-6D19-F4BF2(26-6F)27-4F28-4F334-32A6-6D8-6D13-5C8-5C14-5C8-5C15-I3C8-3CI15-5C8-5C14-5C-6B-5C15-I3C-6B-3CI15-5C-6B-5C14-2(5C-6B-5C13-6D-6F-6D19-F4-F26-F4-F397-32A6-6D8-6D13-2(5C8-5C14-)5C8-5C13-2H4C8G5CH12-2H4CG6BG5CH13-2(5C-6B-5C14-))5C-6B-5C13-6D-6F-6D19-F4-F26-F4-F397-32A6-6D8-6D13-5C8-5C14-5C8-5C15-I3C8-3CI15-5C8-5C14-5C-6B-5C15-I3C-6B-3CI15-5C-6B-5C14-5C8-5C13-6D8-6D454-32A38-6D8-6D13-5C8-C3DC2(14-5C8-5C)2(14-5C-6B-5C)14-5C-6B-C3DC13-6D8-6D85-2J29-J2-J28-J2-J29-2J303-32A70-6D8-6D13-2(5C8-5C14-)5C-6B-5C14-5C-6B-5C13-6D-6B-6D19-C-2I-3(C26-C4-)C60-2D335-32A102-2(6D8-6D12-)6D3-2B3-6D12-6D2-4B2-6D19-4(6B26-)C-2D-C26-C-2D-C365-32A206-4B27-5(6B26-)C4BC27-C2LC334-7(32A207-2B28-3(E4BE27-4B27-)6B27-B2EB302-)32A207-2B28-3(E4BE27-4B27-)6B27-B2EB286-C15-32A74-2D8-2D20-2D8-2D89-2B28-3(E4BE27-4B27-)6B27-B2EB254-C47-32A42-2D8-2D21-C8-C22-C8-C21-2D8-2D25-2B29-3(4B27-E4BE27-)4B27-6B27-B2EB30-6(C31-)C79-32A10-2D8-2D21-C8-C2(22-H8-H)22-C8-C21-2D2-4B2-2D24-4B27-6(6B26-)6B27-B2EB302-32A10-2D8-2D21-C8-C22-HG6-GH22-H2G4-2GH22-C-6G-C21-2D-6G-2D23-6B26-3(6B27-4B27-)6B27-B2EB302-32A42-2D8-2D21-C8-C22-C8-C21-2D3-2G3-2D24-4B27-6B26-6B27-4B27-6B25-E6BE23-2E6B2E23-8B25-6B27-B2EB302-32A74-2D8-2D20-2D8-2D56-D2BD28-4B2(27-2B2E2B27-B2EB)26-M2B2E2BM26-B2EB27-6B27-B2EB302-32A175-2B29-4B27-2B2E2B5(26-B-2E-B)27-4B334-2(32A768-)
