model
size = 24 31 13, scale = 0.05, origin = -y
material 
  colors = A:#002 B:#00A C:#3F6 D:#001
voxels
2-20B4-20A4-8A5C7A4-6A9C5A4-4A13C3A4-4A14C2A4-3A15C2A4-3A12C5A4-2A10C8A2(4-2A8C10A)4-2A10C8A4-2A12C6A4-3A14C3A4-3A15C2A2(4-4A4C2D7C3A)4-6A9C5A4-8A5C7A4-6A8B6A4-6B8-6B5-5(2(BA)B8-2(BA)B6-)2(BA)B8-2(BA)B100-2B18-2B19(2-2A18-2A)2-B20-B148-2(BA)B8-2(BA)B75-2B20-4B20-3B17(A20-A2B)A20-AB195-2(BA)B8-2(BA)B75-B22-BA16(22-2A)22-AB22-B219-2(BA)B8-2(BA)B51-2(B18(22-2B)22-B243-2(BA)B8-2(BA)B27-B22-BA16(22-2A)22-AB22-B243-2(BA)B8-2(BA)B27-)B18(22-2B)22-B243-2(BA)B8-2(BA)B27-B22-BA16(22-2A)22-AB22-B219-2(BA)B8-2(BA)B27-2B21-B2A20-B3A16(20-4A)20-2ABA20-AB195-2(BA)B8-2(BA)B52-B20-B19(2-2A18-2A)2-B20-B148-2(BA)B8-2(BA)B77-20B4-7A5C8A4-5A9C6A4-3A13C4A4-3A4C3D6C4A4-2A2CDCD3CDCD4C3A4-2A3C2(D5C)3A3(4-A17C2A)4-A4C2D11C2A4-A2(4C2D)5C2A4-2A15C3A4-2A2C3D4C3D3C3A2(4-3A13C4A)4-5A9C6A4-7A5C8A4-8A3B9A4-6A2B3-3B6A4-6B8-6B4-2B2(AB)8-2(BA)2B5-4(2(BA)B8-2(BA)B6-)2(BA)B8-2(BA)B99-
