model
size = 19 32 5, scale = 0.05, origin = -y
material 
  colors = A:#000 B:#A00 C:#4E2B0F D:#EEE E:#341800
voxels
8-3A17-E586-2(AC)A15-3C17-C2(18-2E16-2E2(18-C))18-CE17-A15-7A10-3A5B3A7-2A9B2A5-2A11B2A3-2A13B2A2-A15BA-2A2B4DBD2B4DB3A2(2BD3B2(DB)D3BD2B2A)2BD3BDBD2B4D2(2B2A2BD3B2(DB)D3BD)2B3A2B4DBD2B4DB2A-A15BA2-2A13B2A3-2A11B2A5-2A9B2A7-3A5B3A10-7A13-2(AC)A14-E3CE15-2(2(2CE16-)2(E2C16-))2CE16-3C15-A3CA13-A5EA10-2A2C4EC2A7-2A3C4EC3A5-3A3C4EC4A3-4A8C5A2-4A8C5A-5A8C11A3C16A4(8C11A)8C6A-A2CA8C5A2-A2C14A3-A10C4A5-A9C3A7-3A6C2A10-7A13-A3CA15-3C17-CE17-C18-C17-2E18-2E17-C18-C17-2E18-CE17-C18-A15-7A10-3A5B3A7-2A9B2A5-2A11B2A3-2A2B10DB2A2-A2BA10D2BA-2A2BA10D2B3A3BA3D6A4B3(2A3BA3D10B)2A3BA10D3B3A2BA10D2B2A-A2BA10D2BA2-2AB10A2B2A3-2A11B2A5-2A9B2A7-3A5B3A10-7A14-3A17-E579-
