model
size = 31, scale = 0.05, origin = -y
material 
  colors = A:#080 B:#0B0 C:#0D0 D:#C36 E:#C00 F:#DDD G:#A00 H:#D00 I:#700
voxels
261-2D28-3D27-4DE26-3DE-D25-D2-E-D23-B2(-D)B3(ED25-4D)ED26-E4D25-DE3D-D24-DB3D-D24-4DB2D25-3DB2D25-E4D27-E2DE27-E-D2E28-DE29-E245-D154-4A26-6A23-11A20-11AB18-13A16-4(16A15-)16A17-13A19-11A20-11A21-D6A25-D4AD25-5D26-DE-2DE26-2EDE27-E-2E213-2(B30-)D121-9A21-11A19-13A16-8(16A15-)16A17-13A19-11A21-9A23-4D-D25-2D-3D26-E-D2E26-2ED2E28-2E2(30-E)58-5A26-5AB25-3(5A26-)5A59-B26-9AB20-11A19-13A16-8(16A15-)16A17-13A19-11A21-9A23-4D-D25-6D26-D-2DE26-E-D2E26-2ED2E28-2E30-E56-5(9A22-)9A24-4A25-9A20-13A16-2(16A15-)5(17A14-)17AB13-2(17A14-)17A13-B16A15-16A17-13A20-9A23-D4AD26-5D26-D-3D26-2ED2E26-E-3E26-E58-5(11A20-)11AB21-6A21-B-11A17-2(16A15-)4(17A14-)17A13-B6(17A14-)16A15-16A17-B11A22-6A25-6D25-E4D27-E-D2E26-2EDE27-E-2E54-2(13A18-)13A17-B2(13A18-)8AB4A19-11A19-13A16-16A15-12(17A14-)17AB13-16A17-13A19-11A22-2D2A2D25-E-3D28-3DE27-ED2E28-2E29-E24-13AB17-4(13A18-)13A19-11A17-16A15-15(17A14-)16A18-11A21-D6A25-2E4D25-E-4D28-2DE28-3E28-E23-5(15A16-)15A17-13A16-16A15-15(17A14-)16A17-13A19-D9A22-D2E4D25-2E3DE28-2DE28-3E28-E23-5(15A16-)15A2(15-16A)15-8(17A14-)17AB13-17A11-B2-17A14-17A2-B11-17A14-17A4-B9-17A9-B4-16A15-16A18-D9A22-DE5D25-2E4D26-E-3D28-EDE28-3E21-3(7A-7A16-)2(15A16-)15AB14-2(16A15-)2(17A14-)17A13-B17AB11-2B17A2B9-3B17A3B7-4B17A4B6-4B17A4B5-2B2GB17A5B4-2BG2B17A2BG2B3-2B2G2B17A2B2G2B-3B2G2B17A3B2G4B2G2B-17A-3BG8B-17A-3BG7B2-17A2-9B3-16A4-4B-3B3-16A4-3B3-B7-11A7-B13-DE5D25-EDE2(2D27-E-)2E53-5(15A16-)15A2(15-16A)15-2(17A14-)17A13-B17AB11-2B17A2B9-3B17A3B7-4B17A4B6-2B-B17AB2-B5-2B2-B17AB2-2B4-B3-B17A2(B3-)2B3-B17AB4-B-2B3-2B17A2B3-3B4-B-17A-B4-2B3-2B-17A-2B3-3B-2B2-17A2-2B2-5B3-16A4-B-2B-3B3-16A4-3B3-B6-B11A7-B13-3DE3D25-EDE2D27-2E2DE26-E-3E52-5(15A16-)15A2(15-16A)14-B15(17A14-)16A15-16A19-9A2B21-6D25-E4D27-E3DE26-5E53-3(13A18-)4AB8A18-4A-8A2(18-13A)16-16A15-17AB13-10(17A14-)17AB13-3(17A14-)16A17-13A19-B9A23-6D25-E4D27-E2DE27-4E27-E26-2(13A18-)13A17-B13A18-4AB3AB4A2(18-13A)16-16A15-15(17A14-)16A17-13A20-9A23-2DB3D25-2E3D27-E2DE28-D-E55-3(11A20-)4AB6AB19-3A2B2AB3A20-AB6A-BA20-11A17-16A15-6(17A14-)17AB13-8(17A14-)16A18-11A22-6A25-6D25-2E-D-E26-E-DE86-B4(9A22-)3A2BAB2A23-2B2A2(-B)21-11A18-B13A16-16A15-3(17A14-)17A13-B6(17A14-)17A13-B2(17A14-)16A17-13A19-11A24-2AD28-3D28-2DE29-D90-5A26-5AB25-2(5A25-B)AB2AB25-4B-2B23-B6A2B21-11A17-2(16A15-)11(17A14-)16A15-16A18-11A22-6A2-B23-D-3D27-D-2E28-D214-B30-2B28-7B23-2B4A3B22-9A20-13A16-2(16A15-)17A14-8(16A15-)16AB14-16A17-13A20-9A24-4A27-D-2DE29-E306-3B2-B24-5B-B23-8B23-9A21-4A3C4AB18-4A5C4A16-5A8C2A-B14-5A3CA4C2A16-5A8C2A2(16-6A5C4A)16-7A3C5A15-B3(15A16-)2B13A19-11A21-9A397-B29-3B2-B25-3B2-B24-7B23-2B4A2B23-B2A3CA23-3A5C3A20-2A8CA17-B-2(3A8CA19-)2(4A5C3A19-)5A3C4AB18-12A19-2AHIH3AHIHA20-A3H3A3HA20-11A22-6A26-4A430-2B29-2B2-B26-6B26-5B24-2B3C2B24-B5C24-B7CB22-9C20-B-B7CA23-B5CB25-5C27-3(3C28-)B-B24-4B3-4B488-2B29-2B2-2B25-6B25-3B-2B25-B3C2B24-B5C24-2(9C22-)8CB23-B5CB25-5C27-2(3C28-)CBC554-2B2-B26-3B-B26-6B24-4B-2B25-B3C2B24-B5C24-2(9C22-)9C23-B5CB25-5C27-CBC29-B617-B2-2B26-2(6B25-)B3C2B24-B5C24-2(9C22-)9C23-7B25-5B28-B648-B30-B-B28-3B-B26-B3C2B25-5C24-B7CB22-9C22-B8C24-5B28-B681-B-B25-2B2(-B)26-5B24-8B24-7B23-9B22-9B23-3B-4B739-B-B27-2B-B26-5B24-8B24-F5BF24-2B3-2B24-7B27-B30-B711-B-B28-4B26-6B23-8B24-F5BF24-2B3-2B25-F3BF28-B742-B-B28-3B26-5B-B23-8B24-F5BF24-FB3F2B25-F3BF25-F2-B2-2(F24-F5-)F708-B-B28-3B26-7B25-5F2(26-F3-F)571-
