model
size = 16 8 26, scale = 0.05, origin = -y
material 
  colors = A:#6C2B00 B:#FFF C:#CC9 D:#222 E:#E00
voxels
19-3E109-13A2-A3E11-2A3E11-2(A15-)2(2A15-)13A2-2A10C2A-2A12B2-2A12B-2AB3E9B-2A13B2(2-2A12B)3-2A10C2A2-A2C8A2CA-13A4(B-14A)B2-13AB3-A2C8A2CA2-AC10ACA-13A3(B-14A)B-12A-AB2-13AB3-AC10ACA2-AC10ACA-13A4(B-14A)B2-13AB3-ACA3D2(AD)2ACA2-AC10ACA-13A4(B-14A)B2-13AB3-AC4(AD)2ACA2-AC10ACA-13A4(B-14A)B2-13AB3-ACA3D2(AD)2ACA2-AC10ACA-13A4(B-14A)B2-13AB3-ACAD3A3D2ACA2-AC10ACA-13A3(B-14A)B-7A-6AB2-13AB3-AC10ACA2-AC10ACA-13A4(B-14A)B2-13AB3-AC2(A3D)2ACA2-AC10ACA-13A4(B-14A)B2-13AB3-ACAD3AD4ACA2-AC10ACA-13A4(B-14A)B2-13AB3-ACA2D2A2D3ACA2-AC10ACA-13A4(B-14A)B2-13AB3-ACAD3AD4ACA2-AC10ACA-13A4(B-14A)B2-13AB3-AC10ACA2-AC10ACA-13A4(B-14A)B2-13AB3-ACA3(D2A)CA2-AC10ACA-13A4(B-14A)B2-13AB3-ACAD2A2DAD2ACA2-AC10ACA-13A4(B-14A)B2-13AB3-ACAD2ADA2D2ACA2-AC10ACA-13A4(B-14A)B2-13AB3-ACA3(D2A)2(CA2-AC10ACA-13A4(B-14A)B2-13AB3-AC10A)CA2-A2C8A2CA-13A4(B-14A)B2-13AB3-A2C8A2CA2-2A10C2A-2A12B2-2A12B-2AB3E9B-2A13B2(2-2A12B)3-2A10C2A3-13A2-2A13-2A3E11-2(A15-)2(2A15-)13A19-3E109-3E122-
