model
size = 24 31 21, scale = 0.05, origin = -y
material 
  colors = A:#396 B:#500 C:#111 D:#EEE
voxels
2-20B4-4AB10AB4A4-3AB12AB3A4-2AB3A8B3AB2A4-2B3AB8AB3ABA4-8A2CAC4AB2AB4-3AB3A2(CA)C8A4-2AB6ACAC5AB2A4-2B7A2(CA)C4ABA4-8A5C6AB4-3AB2AD3AD9A4-2AB2(3AD)6AB2A4-2B2A2(4CA)C3ABA4-7ACA2(C2A)C3AB4-6A3(C2A)C4A4-5AC3A4C2AC4A4-6A3(C2A)C4A4-B6ACAC2AC6AB4-AB2A4CA4C2AC2ABA4-2AB14AB2A4-3AB12AB3A4-15AB4A4-5AB8AB5A4-B5ABA4BAB5AB5-B5AB4-B5AB6-2(BA)2B6-2B2(AB)124-B20-B3(2-A20-A)4(2-B20-A2-A20-B2(2-A20-A))2(2-A20-A)2-B20-B76-2(BA)B8-2(BA)B99-B21-B2(-A21-A)2(-B21-A-A21-B)3(2(-A21-A)-B21-A-A21-B)2(-A21-A)-B21-A-B21-B100-2(BA)B8-2(BA)B75-B22-BA22-AB2(22-2A22-2B)3(22-2A22-BA22-2A22-AB)22-2A22-2B22-AB22-B147-2(BA)B8-2(BA)B51-B22-2B2(22-2A22-BA22-AB)3(22-2A22-BA22-2A22-AB)22-AB22-B195-2(BA)B8-2(BA)B27-B2(22-BA)3(22-2A22-AB22-2A22-BA)22-2A22-AB22-2A22-2B22-AB22-B219-2(BA)B8-2(BA)B27-B22-BA2(22-2A)22-AB3(22-BA)2(22-2A22-AB22-2A22-BA)22-2A2(22-AB)22-B267-2(BA)B8-2(BA)B3-B22-BA22-2A22-AB22-2B22-AB2(22-BA22-2A)22-AB22-2A22-BA22-2A22-AB22-2A22-2B22-AB22-B291-2(BA)B8-2(BA)B3-2(B22-BA22-A)B22-2A22-2B2(22-2A)22-BA22-2A22-AB22-2A22-BA22-2A2(22-AB)22-B315-2(BA)B8-2(BA)B3-B22-2B22-BA22-2A22-AB22-2A22-BA22-AB2(22-2A)22-BA22-2A22-AB22-2A22-2B22-A23-B339-2(BA)B8-2(BA)B3-B14(22-2B)22-B23-B339-2(BA)B8-2(BA)B3-B22-2B22-BA22-2A22-AB22-2A22-BA22-AB2(22-2A)22-BA22-2A22-AB22-2A22-2B22-A23-B339-2(BA)B8-2(BA)B3-2(B22-BA22-A)B22-2A22-2B2(22-2A)22-BA22-2A22-AB22-2A22-BA22-2A2(22-AB)22-B315-2(BA)B8-2(BA)B3-B22-BA22-2A22-AB22-2B22-AB2(22-BA22-2A)22-AB22-2A22-BA22-2A22-AB22-2A22-2B22-AB22-B291-2(BA)B8-2(BA)B3-B22-BA2(22-2A)22-AB3(22-BA)2(22-2A22-AB22-2A22-BA)22-2A2(22-AB)22-B267-2(BA)B8-2(BA)B3-B2(22-BA)3(22-2A22-AB22-2A22-BA)22-2A22-AB22-2A22-2B22-AB22-B219-2(BA)B8-2(BA)B27-B22-2B2(22-2A22-BA22-AB)3(22-2A22-BA22-2A22-AB)22-AB22-B195-2(BA)B8-2(BA)B27-B22-BA22-AB2(22-2A22-2B)3(22-2A22-BA22-2A22-AB)22-2A22-2B22-AB22-B147-2(BA)B8-2(BA)B52-B20-B2(2-A20-A)2(2-B20-A2-A20-B)3(2(2-A20-A)2-B20-A2-A20-B)2(2-A20-A)2-B20-A2-B20-B100-2(BA)B8-2(BA)B76-B20-B3(2-A20-A)4(2-B20-A2-A20-B2(2-A20-A))2(2-A20-A)2-B20-B76-2(BA)B8-2(BA)B101-20B4-20A4-2A16B2A4-AB16ABA4-B3A11B4AB4-3AB11AB4A4-2AB4ACA2C5AB3A4-AB5A2(CA)C5AB2A4-B6ACAC8ABA4-5A2(CA)C9AB4-6A5C9A4-AB18A4-B17ABA4-4AC2(A4C)4AB4-3A2(C2A)CAC8A4-ABA3(C2A)C7A4-B2AC2A4C3AC4ABA4-3A3(C2A)C6AB4-6AC2ACAC8A4-3AC2A4CA4C5A4-20A4-8A4B8A4-7AB4-B7A4-3(BA)B6-3(BA)B5-2(BA)B8-2(BA)B6-2(BA)B8-2(BA)B123-
