model
size = 22 30 19, scale = 0.05, origin = -y
material 
  colors = A:#252525 B:#212121 C:#282828 D:#191919 E:#1D1D1D F:#FF0 G:#FFF H:#DADADA I:#A00 J:#000 K:#EAEA2C
voxels
28-10F12-10A12-4FAF3A2(F12-3A3(FA))F12-3AF2(A2F)12-4FAF3AF12-10A12-10F12-9AE12-E2B2E2BEBA12-2EAE3A2EB12-B3A2G4A12-EAGB2GBGAE12-2AGA2GAGAB12-2A6G2A12-A8G2(A12-AG2J2G2JG)B12-E8GA12-2A6G2A12-B2A4GAEA12-2BAB4ABE12-B2EA2BAE2A13-BCAB2ECA100-12D10-12F10-F10AF5(10-12A)10-F10AF10-12F10-5ABE4AB10-2AB3AEAE3A9-BA2BEABA2CE3A8-2(BA)2C2BACBCAE8-CACBABCE2CECAC8-BAC2(A2B)CBAEA8-B2ACBE2BCAE2AB8-CBAE2(BC)2ACA2C8-BAEC2BCE2B2CBC8-2A3BCABA2CE2A8-BAEACAE3CEBAC8-CAB3AEA2EBAEC8-E2AECEBC2E2ABA8-EBCE4A2CEBAC9-B2ACA2B4AE11-2ABAEA2E2A13-B2ABEA2C76-2D12-2D6-2A12-2A6-BF12-FE6-AF12-FB6-AF12-FA6-AF12-FB6-B2(F12-FA6-A)F12-FA6-2A12-AB6-CA12-AE6-CB12-BA6-EA12-2A6-CB12-BA6-AC12-AE6-AB12-2A6-BA12-BC6-EB12-AB6-BA12-BE6-2A12-2A6-AE12-2A6-BA12-AC6-EA12-2A6-EA12-AC6-EC12-AB7-CA10-2E9-ECEAE5ABE11-4EC4BE52-D16-D4-A16-A4-B16-E4-A16-E4-B4(16-C4-A)16-B4-E16-B4-A16-C4-A16-E4-E16-C4-A16-E4-B16-C4-E16-E4-B16-A4-A16-B4-C16-B4-A16-B4-E16-A2(4-A16-E)4-C16-C4-C16-A5-A14-E7-EA10-AC9-EAB2C2(AB)ECB12-2(AB)ECAB15-6D9-D18-D2-A18-A2-E18-A2-C18-B2-A18-C2-A18-E2-B18-A2-B18-E2-C18-C2-B18-C2-A18-E2-B18-A2-E2(18-C2-A)18-E2-C18-A2-A18-A2(2-E18-B)2-C18-C2-A18-A2-C18-A2-A18-E2(2-A18-A)3-A16-E5-B14-B7-2A10-2B10-AC6-AC13-D6-D8-D18-D2-E18-A2-A18-C2-B18-A2-E18-C2-E2(18-A2-A)18-A2-B18-A2-A18-A2-B18-C2(2-C18-B)2-A18-B2-C18-B3(2-A18-A)2-A18-E2-A18-A5(2-D18-D)3-A16-A5-B14-A7-A12-C9-AD8-DA11-D8-D6-D20-DA20-EA20-AB20-EB20-AB20-2C20-2B2(20-AE)20-CE20-AB20-CA20-AC20-2E20-BE20-2B20-EC20-2A20-AD20-D112-D16-D5-A14-E7-A12-B9-D10-D11-D8-D6-D20-DB20-AC20-2A20-AE20-2E20-EA20-CB20-BC20-AB20-EB20-AE20-EB20-A2(B20-C)B20-EC20-CA20-AD20-D157-D14-D7-A12-C9-D10-D27-D20-DA20-2A20-CA20-AC20-EB2(20-AE)20-EB20-AC2(20-AB)20-2A20-EA2(20-AB)20-AC20-BA20-CD20-D157-D14-D7-A12-A9-D10-D27-D20-DA20-EC20-EB20-CA2(20-AB)20-2B20-BA20-CB20-2B20-CE20-EB20-EC20-AB20-BA20-2E20-BA20-AD20-D157-D14-D7-A12-A9-D10-D27-D20-DB20-AB20-2A20-AB20-EB20-2B20-2E20-2B20-2C20-EA20-2B20-CB20-CE20-BE20-2B20-2A20-EA20-AD20-D157-D14-D7-A12-A9-D10-D27-D20-DC20-AB20-EB20-CB20-BA20-2B20-CB20-CE20-CB20-2C20-CE20-BE20-CE20-EC20-EB20-AE20-EA20-AD20-D157-D14-D7-2A10-AC10-D8-D28-D20-DB20-2A20-A2(E20-2E20-B)E20-BA20-EB20-2C20-2B20-CB20-BA20-EC20-AB20-AE20-BA20-CA20-AD20-D112-DA14-AD5-BA12-2B8-A-D6-D-B11-D8-D29-D18-D2-A18-B2-A18-A2-A18-B2-A18-E2(2-A18-B2-C18-B)2-A18-A2-C18-E2-C18-C2-E18-A2-E18-C2-A18-E2-A2(18-B2-C)18-A2-C18-B2-A18-C4(2-D18-D)2-D2A14-2AD4-C14-A7-C2AD6-D2AB10-D8-D51-D18-D2-B18-A2-C2(18-B2-A)18-C2-E18-A2-E18-E2-C18-A2-A18-E3(2-A18-A)2-C18-A2-A18-B2-C18-B2-A18-E2(2-A18-B)2-C2(18-A2-A)18-B2-C2(18-C2-A)18-C3-EB14-AC6-EACD6-DABC9-B10-A73-D16-D4-B16-A4-A16-B4-A16-C3(4-A16-A)2(4-A16-C)4-A16-A4-A16-H4-A16-A4(4-A16-C)4-H2(16-B4-A)16-A4-A16-H4-H16-A2(4-A16-B)4-B16-A5-BAE2AD4-D2A3E116-BD12-2D6-CA12-AE6-2A12-AE6-AI12-EA6-IA12-CA6-IA12-2A6-IA12-2H6-2A12-2B6-2A12-2H6-2I12-2B6-IA12-2H6-IA12-2A6-2I12-2F6-2A12-FC6-2A12-FA6-2H12-FA6-2A12-FA6-AF12-AB6-FK12-2C6-AF12-2A6-2A12-2H6-2H12-2A6-2A12-AC6-D2ABAD4-D2A2CA140-3D6-3D10-2CA6-ACA10-A2C6-C2A10-3A6-CAE2(10-I2A6-C2A)10-I2A6-A2H10-2CA6-A2B10-3A6-C2H10-I2A6-A2B10-ACA6-A2H10-3A6-3A10-I2A6-2AF10-ACA6-C2A10-3A6-C2A10-HCA6-ACF10-AHA6-C2A10-ACA6-A2C10-FAC6-C2A10-3A6-AHA10-AHAD4-D2AH10-H2AD4-DC2A10-ACAD4-DA2C167-19(D4-D16-)D4-D228-
