model
size = 9 27 9, scale = 0.05, origin = -y
material 
  colors = A:#000 B:#777 C:#040404 D:#222 E:#555 F:#010101 G:#444 H:#070 I:#888 J:#E00
voxels
184-E7-3D5-EBG2B5-GBG7-B62-D8-A7-A2C6-2AC6-3A6-2CF3(6-C2A)6-3C6-F2C6-CAF6-C2A6-3A6-3D6-G2B5-E2BGE3-2D3B2D2-7B2-BE4BG3-IG2BG5-B2E25-F7-F2A5-5A4-2DA2D2(4-5A)4-4A2(C4-C3A)2(F4-C3A)2(C4-C3A)C2(4-4AF)4-C4A4-5A4-DABAD4-E3BG3-7B2-D5BD-9B-E6B2-G6B3-E4B6-G7-2A7-F2A5-2(5A4-)D3AD4-5A3-3(C6A2-)7A2-C5AF2(2-C5AC)2-F5AC2(2-C5AF)2-F5AF2-7A2-DA3BAD2-E5BE2-6BG-D7BDE7B2E7BG-7B2-E5BE4-EBE6-FAF5-4AF2(4-5A)3-D5AD2-7A3(2-C6A)3(2-7A)2-F6A2-C5AC2(2-C6A)2-F6A2-7A2-D5BD2-E6B-E8BD7BDE7B2(E8B)E-6BG3-3EBE6-F7-2AC5-C3AC4-5A4-D3AD4-5A3-2(C6A2-)2(C5AF2-)F4(5AC2-C)5AC2-F6A2-6AF2-7A2-DA3BAD2-E5BE2-7B-D7BD9BE7BE-E5BE2-G4B2E4-EBE16-C7-3C6-2CAC4-2DA2D4-5A4-F2(4A4-C)3AF4-C3AC4-4AC4-CAJAC4-C3AC4-CAHAC4-C4A2(4-C3AF)4-5A4-DABAD4-5B3-E6B2-D5BD-8BE-E6B2-E5BG3-3BGE6-E44-D8-C7-2CA6-C2F6-F2C6-2AC6-3A6-ADA6-FDC6-AHC6-2AC6-C2A6-2CF6-3A6-3D6-BEB5-E3BE3-2D3B2D2-7B2-E5BE3-BE2BE5-G2B196-E7-3D5-E3BG5-EBE7-E22-
