model
size = 14 15 32, scale = 0.05, origin = -y
material 
  colors = A:#EEE B:#444 C:#222 D:#BBB E:#001 F:#FF3 G:#555 H:#3C0 I:#3CC J:#C0C K:#900 L:#306 M:#C33 N:#69F O:#00D P:#F39 Q:#800 R:#9FC S:#6CF
voxels
18-3(6A8-)2(6B8-)6B7-2(8B6-)8B7-6B63-6A7-8A6-8A8-4A162-3(8A6-)8A7-6D9-4D11-2D120-2(10A4-)10A5-A-4A2-A3(5-2D)4-2D7-6D118-3(11A3-)9A-2A2-11D4-2D6-D5-3D2-4D7-4D105-3(12A2-)9A-2A2-11D3-8D-2(2D4-)A2D7-4D105-12A2-12A-13A2-4A3-5A2-2D7-3D2-11D4-10D4-8D7-7D88-3(13A-)4A4-3A-2A-D8-3D2-2D-8D3-11D4-9D5-9D87-43AB2A4-3A-BA2-A7-2D3-2D8-D3-11D4-9D5-9D87-43AB2A5-2A-BA-B8-2DB3-D7-2D3-11D3-10D5-9D6-7D74-43AB2A5-3ABA-2B8-2B2-3B6C3B2-3B6-3B3-2B6C2B5-B6CB7-C4-C74-43AB2A5-3ABA-B10-B2-3B6C3B2-3B6-3B3-2BC-2C-C2B4-2B6C2B6-6C8-6C60-43AB2A6-2ABA-2(B10-B2-)3B6C3B2-3BC4-C3B3-2B6C2B4-2B6C2B5-G6CG6-8G45-43AB3A5-2ABA-B10-B2-2B8-2B3(2-3B6C3B)3-2B6C2B5-B6CB7-6C47-42AB3A5-2ABA-B10-B2-2B8-2B4(2-3B6C3B)3-BA6CAB5-8G46-13A-28A2E2A5-A2EA-2(2E8-2E2-)3E6-3(3E2-3E6C)3E3-2B6C2B6-6C48-12A2(-13A)-E2FA5-3FA-3I6-3I2-3L6-3L2-3E6-3E2-3O6-3O2-3J6C3J2-3E6C3E2-3B6C3B3-BG6CGB5-8G33-12A2-12A-13A-3EA5-3EA-3F6-3F2-3E6-3E2-Q2F6-3F2-3E6-3E2-3JC4-C3J2-3E6C3E2(2-3B6C3B)5-6C9-4G22-11A3-11A2-12A-3EA5-2E-A-3F6-3F2-3E6-3E2-Q2F6-3F2-3E6-3E2-3J6-3J2-3E6-3E2-3B6C3B2-2BA6CA2B4-G6CG7-G4CG21-10A4-10A3-12A-3EA5-2E-A-3F6-3F2-3I6-3I2-3E6-3E2(2-3H6-3H)2-3E6-3E2(2-3B6C3B)4-G6C8-G4CG9-4G8-2(10A4-)11A-3EA5-2E-A-3F6-3F2-3L6-3L2-3H6-3H2-2P8-2P2-2H8-2H2-2E8-2E2-3B6-3B3-2B6C2B5-G6CG6-G6CG20-10A4-10A3-11A2-3EA5-2E-A-3F6-3F2-3I6-3I2-3E6-3E2(2-3K6-3K)2-E2B8-E3-2B6-2B4-2B6C2B5-G6CG7-6C21-10A4-10A3-11A2-3EA4-A3E2-3F6-3F2-3E6-3E2-Q2F6-3F2-3E6-3E2-MEB6-BEM2-E2B6-2BE18-BC4-CB7-6C35-10A2(3-11A)2-3EA3-2A3E2-3F6-3F2-3E6-3E2-Q-F6-F-F2-3E6-3E2-REB6-BER2-E2B6-2BE74-10A2(3-11A)2-E2FA3-2A2FE2-3N6-3N2-K-K6-K-K2-E-E6-E-E2-3M6-3M2-SEB6-BES2-E2B6-2BE73-2(11A3-)11A2-3EA3-2A3E3(2-E-E6-E-E)2(2-3E6-3E)3-EB6-2BE3-B69-2(11A3-)11A2-BE-EA2-AB-2B2-B-E6-B-B2-B-2E4-2B-2(B2-)E4-2(B2-)B3E4-4B3-B2E4-3B4-2B6-2B74-2(11A3-)11A2-BE-B4AB-2B2(2-B)4-3(B2-)B4-B2-B3-5(3B4-)3B5-2B4-2B7-B4-B62-2(11A3-)11A2-2B-B4AB-2B3-2(B-B4-)B-6B-B3(4-10B)5-8B6-8B7-6B8-2B2-2B34-3(11A3-)2B-4B-3B3-B2-4B2-B4-2B-4B-2B3(4-10B)5-8B6-8B7-6B8-6B34-3(10A4-)2(2(2B2-)2B4-)3B-2B-3B5-2(8B6-)8B7-3(6B8-)6B10-2B23-3(8A6-)2(2B4-2B6-)3(8B6-)8B7-6B9-4B10-4B47-
