model
size = 30 32 28, scale = 0.05, origin = -y
material 
  colors = A:#B00 B:#A00 C:#800 D:#700 E:#D00 F:#050 G:#040 H:#070 I:#020
voxels
765-F920-2F16-H941-2H15-2F12-2H13-F2H942-3H11-3H16-ABD6A21-B2ABAED3A23-EB863-3H9-4H14-EAD7ACA18-4ABDAC2(DA)BAB20-2D834-2HA-D4A2-3H15-HAEC7A-3A15-2D2-DAC2ED3A17-ADAEABAE2B2CBC2B18-2DE2ADCD22-B779-2HCA22-FAEBDB3AD3ABH15-AED3AC2ACAEACA17-8ADADEADA11-AD2ACBE2DADBE2A4B15-AE2ADA2-A-A19-4B6-B741-HFH5F20-H4FG2ACFG19-2DEACAECADAB18-2(AED)B2AEABC15-CADE3AC2ABAB2E2A10-BAD2AEDCDE2AB2A-4B13-BDABAC2DAD2CD19-2B2A5B-2B20-7B712-H8F20-HEBA2DF2G2F18-EBEDEADE4ACD16-AE2ABAECDAE2BE15-2ACAD4AE2(2A-)A10-C3EADBEACA2BAC-4B13-D2AB4AED2A3B17-2B2AEABAD3B20-2CD2CAE683-7F21-3F2(GF)2G2F19-3EB2AE2AFA17-3AEBEABC3ABCE15-DBCDECD2EADACBA13-3ABCDC2ABADBCE2A11-2ABECE2ADBDE2ACB2CDAEC12-5AEB2(AD)C4B16-2(BDC)2D2AB20-3CDA2-CD652-6IF22-F3G2F2GF18-3FG5FG4F16-ECAB2CABEB2CAC15-AB2CAEAB2E2A2CEA13-A2EA2CEACEDBA2B2A12-2ABCBABED2A2D2(AE)A11-2ADADB3ABD3AD2ADBA10-AD-D2BA2B-ACA-ACBA3B14-2BAC2-AD2AB2AC18-C3-A-D2-B23-B209-G390-G26-I2G3IG21-2F4G3FHF17-2FG2F7G2F16-E4AE5ACAD14-4ACBC2EBD2B2C2A13-ABCAEACDCADCEABDA12-ABDCBC2ADABAEACADA11-AD5AC-4ACABCEA11-AD-D2ABA2-CBA2BA2DA2B13-4B2-CBAB2AC2A21-2EAE2C25-4B175-G29-G329-FG28-2GF27-GFG25-IGF3IG21-5F4G2F17-2F2GF2G2F2GFA17-C2BD2AE2(CA)BA15-ABEADBCD2EABAD2A14-ADEBA2EDC2ABADCA13-ACAEA3C4AED2(EA)11-AD2C8AEBDAE2A11-CE-2B2A2-ADE2D2EADA2B13-2B3-ACBEADCADE20-ECEACA25-CA-B26-2(2F28-2G28-)2F28-FG28-2G28-2F28-FG2(28-2F)28-GF28-2F28-FG28-GF28-FG28-F2G27-2GF26-2FGF26-I3G25-I2G4IG20-2(2FG)2(FG)F18-2F2GFG2F2GFH17-ACECB2AD3ABC17-CBEADAEADC3A16-2CAE3A2BDB2D2A14-3AEAC-AD2(AE)A2EA13-C3A-C-E2DE3AD2A11-2A-A4-AD2(AB)DE-BCDB17-D2(EB)AC3AEA18-2E2C-BAEA23-E2A2B115-G270-F2(29-G)29-F28-2G28-G2F27-G2F26-I3G25-IFG3I2G20-2F3GF4GF17-4FG2FG4FG2F15-BA2E2ADAD2ABAEH14-2(AD)A2D2ADA3EAEA13-2A2C4ADECAEB2A13-2A2CADCADEB2A2EABA12-ADAECA2DCAD2(EA)CEC9-ADA2B2AC-AEB5A-E2DB13-3B-DED3ADBDADC18-EDEAB2(CA)25-C3B114-G449-IFI27-3I25-IGF5I21-2(FG)F2G2F18-3FGF2GFG2FG2HF15-HA3EDCDA2CDAEF13-EAEBA2D-DAB2EAE2(AB)11-2AE3ACEC4AC3ACA11-C2A2CB-2BABEA2EC2A12-AC2A2D-D2A2D3AEBE2A8-A3BCAEC-ABECADC-2EAB13-4BCAB-B4A2DA18-EBA2-3A28-B623-I2G2I24-F5G3F18-3FGF3GF2GFHF16-FA3EAC2(DB)ACAF13-HBDEADAB2AC2ADC2DEAH7-2HFBEAC5ABADB2ACEABC2H8-DACADA2-A3DB3C2E-B8-A-AEDBEA2-AEC2EBAC2DEC8-AB-2BE2A2-3ADBA-4B14-3B2-D4AB24-ACBCA25-D2C625-I2G2I25-F3G2F21-H4FG2FG4H16-FAC2(BE)AD2ACEAH7-2F2H2-HFDB3AC3AECD2AEAFH2-HF-2F4HBCEAE3AD2(AB)AEADCA2(FH)6-2(AC)B3D3AE5ADAB8-2ADACBADECA2BABDCDBECA8-AEA-3CB3AC2DCAD3B16-3B-D2ADC-D23-CADA26-BAC656-2G27-G2A2G24-FABECAC20-3ACACD3C2AD17-2ADEAE2AC3AC2A12-ADEDCB2A3-EC2BCBC2E9-E3BE2(AC)3-2BA2CE2AB17-6B-4B19-6B2-A23-2B716-5G25-4AD23-3A2C4AB20-2ADCE2(AB)2A14-ADAB3ABEADC2AE3ACA9-D3BA2BA4CBCACDCA-A15-7B-5B20-4B748-G28-HAF25-2ABEA25-7A16-2AE3ACACDABCE2A2-2A9-5BCDC2BCABE3AEA-A15-10B804-3F27-3A27-ADA19-CAB3-2ACDBC2A3-2A11-4B2ADB2EACBCEBA-A17-7B835-BEF27-2AC21-4AD-EA4-ECB15-4B2-2A-3AE2A861-2F28-ED28-AC30-A2(EB)893-2H958-2H928-2H28-FH929-F29-H194-
