model
size = 32 24 26, scale = 0.05, origin = -y
material 
  colors = A:#069 B:#09C C:#DDD D:#EEE E:#444 F:#06C G:#39C H:#BEBED6 I:#099 J:#222 K:#F6C L:#3CF M:#0CC
voxels
49-AFB29-F2A701-AFB29-F2A733-AFB28-GF3A27-AI2A731-AGF2A27-IAI2A27-3A2B700-GF2A27-IAI2A26-4A2B26-FAFB2A699-2(IA)27-4A2B25-BFAFB2A25-BAB2A2B27-3AF150-6(2E30-)2E354-BFAFB3A24-BAB2A2BC24-5AFA25-A2BFG28-A31-2A25-2E3-FA25-2E3-AB24-DEG3-2A24-DEG3-2B24-DEG3-B24-2DEG29-DEG2(30-2E)328-3C19-13C18-B2A2B5AF2A18-ABA2B2A2BFG2AB17-AG2A2G3AIAI2AB17-3A2EI6A2BA18-2A2E2ABFAFB3A17-BADED2ABAB2A2BA18-2DED2B5AF19-J2DEG3-2BFG20-J2DEG2-B-BA21-J2DED5A23-2DED3AGF24-DEDFB28-2E30-2E317-8C6H17-2B2A2B5AF3A15-2BABA2B2A2BFG2AB14-IGIAG2A2G3AIAI2AB14-4A2-2EI6A2BA17-BADED2ABFAFB3A14-4B2DED2ABAB2A2B2A12-ABA-J2DED2B5AF2A13-B2A-J2DEDB2A2BFG2A18-J2DEDBA3B4A18-3DED5AFB20-J2DED3AGFA22-2DEDF-F2A24-DED2A28-2E285-8H23-H13C16-A-2B2A2B5AF3A14-A2BABA2B2A2BFG2A2B12-AIKIAG2A2G3AIAI2ABA12-A5-A2EI6A2BA2B15-B2DED2ABFAFB4AB11-5B2DED2ABAB2A2B2AB10-2(BA)-J2DED2B5AF4A10-2B2A-3DEDB2A2BFG2A2BA15-J2DEDBA3B6A16-J2DED5AFB2A18-J2DED3AGF-2A19-J2DEDFBF2AB22-2DED3AF26-2E282-C-11C17-9C-8C13-H8C2B5AF3A12-B2A2BABA2B2A2BFG2AB-A10-BAIKIAG2A2G3AIAI2AB3A9-A5-2A2EI6A2BA2B2A13-BADED2ABFAFB3A-3B8-A5B2DED2ABAB2A2B2ABGB8-2(BA)-J2DED2B5AF6A7-3B2A-J2DEDB2A2BFG2A2B2AB9-AB2-3DEDBA3B5A-2A14-J2DED5AFB4A16-J2DED3AGF4A19-2DED3-2A2B22-DED3AFB25-2EA254-6H19-7H6C2H16-H15C3H12-20C2H10-2B2A2BABA2B2A2BFG2A2B-A8-GBAIKIAG2A2G3AIAI2AB2A-A7-A5-K2A2EI6A2BA2B2A13-B2A2E2ABFAFB3A-3BA6-BA5BADED2ABAB2A2B2ABG2BA5-2BAB3A2DED2B5AF7AB5-3B2A-J2DEDB2A2BFG2A2B2ABFB5-B2A2B-J2DEDBA3B8A2B7-2BA2-J2DED5AFB4ALBA10-A2-A2DED3AGF6AB15-ABDEDFBF-A2B2A19-A-2E3AFBA23-B2E3AB250-7C18-9C4-4C14-20C12-22C10-2B2A2BABA2B2A2BFG2A2B2A8-GBAIKIAG2A2G3AIAI2AB4A7-A5-K4AI6A2BA2B2AB12-B2A2E2ABFAFB3A-3BAB5-BA5B2A2E2ABAB2A2B2ABG2B-2B3-2BAB3ABDED2B5AF7A2BAFB-A2B2A-B2DEDB2A2BFG2A2B2ABF2(B2A2B-)A2DEDBA3B8AB-AF5-2B2A-B2DED5AFB4ALB2A9-2A2-ADED3AGF6A2B15-2B2EFBF2(2A2B)17-2A2E3-FB3A21-3B3ABL25-A223-4H3C18-7H7-3C14-H19C12-22C10-2B2A2BABA2B2A2BFG2A2B2A8-GBAIKIAG2A2G3AIAI2ABA-2A7-A5-K4AI6A2BA2B2AB5-G6-B6ABFAFB3A-3BAB3-2ABA5B2A2E2ABAB2A2B2ABG2(2BA)BG2BAB3A2B2E2B5AF7A2BAFB-3B2A2BAB2EB2A2BFG2A2B2ABFB2A2B-B2A2B4A2EBA3B8A2BA2F3B-2B3ABMB2E5AFB4ALB2A3-FAB3-2A2-2A2E3AGF6A2BA5-2A7-2B2EFBF2(2A2B)F8-A7-3A6-4AB10-A8-3B3ABLBFB22-A3-2A2B2A28-3ABF28-2A2B30-3A116-4C3H19-8C4-C3H15-17CHC12-22C10-2B2A2BABA2B2A2BFG2A2B2A8-GBAIKIAG2A2G3AIAI2AB4A7-A5-K4AI6A2BA2B2AB12-B2A2E2ABFAFB3A-3BAB5-BA5B2A2E2ABAB2A2B2ABG2B-2B3-2BAB3ABDED2B5AF7A2BAFB-A2B2A2B2DEDB2A2BFG2A2B2ABFB2A2B-B2A2B2A2DEDBA3B8AB-AF5-2B3AB2DED5AFB4ALB2A9-2A2-ADED3AGF6A2B15-2B2EFBF2(2A2B)17-2A2E3-FB3A21-3B3ABL25-A224-6C21-13C16-H17CH12-20C2H10-2B2A2BABA2B2A2BFG2A2B-A9-BAIKIAG2A2G3AIAI2AB2A-A7-A5-K2A2EI6A2BA2B2A13-B2A2E2ABFAFB3A-3BA6-BA5BADED2ABAB2A2B2ABG2BA5-2BAB3A2DED2B5AF7AB5-3B2ABJ2DEDB2A2BFG2A2B2ABFB5-B2A2-AJ2DEDBA3B8A2B7-2B3AJ2DED5AFB4ALBA10-2A-A2DED3AGF6AB15-ABDEDFBF2-2B2A19-A-2E3AFBA23-B2E3AB278-12HC18-H6C2-8C13-2H18C12-B2A2BABA2B2A2BFG2AB-A11-AIKIAG2A2G3AIAI2AB3A9-A5-2A2EI6A2BA2B2A13-BADED2ABFAFB3A-3B8-A5B2DED2ABAB2A2B2ABGB8-BAB2AJ2DED2B5AF6A7-3BA2-J2DEDB2A2BFG2A2B2AB8-A4-DJDEDBA3B5A-2A14-J2DED5AFB4A16-J2DED3AGF5A18-2DED3-2A2B22-DED3AFB25-2EA282-C-8C21-11C5H16-16CH14-A2BABA2B2A2BFG2A2B13-IKIAG2A2G3AIAI2ABA12-2A4-A2EI6A2BA2B15-B2DED2ABFAFB4AB11-5B2DED2ABAB2A2B2AB10-BAB-AJ2DED2B5AF4A15-3DEDB2A2BFG2A2BA15-J2DEDBA3B6A16-J2DED4A-FB2A18-J2DED3AGF-2A19-J2DEDFBF2AB22-2DED3AF26-2E285-2C30-14C18-2C-11C15-2BABA2B2A2BFG2AB15-GIAG2A2G3AIAI2AB15-3A2-2EI6A2BA17-BADED2ABFAFB3A15-3B2DED2ABAB2A2B2A13-B2-J2DED2B5AF2A17-J2DEDB2A2BFG2AB17-J2DEDBAB-B4A18-3DED5AFB20-J2DED3AGFA22-2DEDF-F2A24-DED2A28-2E296-2H20-10H2CH18-H13C18-BA2B2A2BFG2AB19-2A2G3AIAI2A19-2A2EI6AB21-A2E2ABFAFB3A18-ADED2ABA-2AB20-2DED2B2A-2AF19-J2DEG3-2BFG20-J2DEG2-B-BA21-J2DED5A23-2DED3AGF24-DEDFB28-2E30-2E291-8C23-9C23-8C24-A2BFG2AB25-B58-2E3-GF25-2E29-DEG3-FB24-DEG29-DEG3-A24-2DEG29-DEG2(30-2E)322-3ABL3C24-ABA6C23-8C26-2BA119-6(2E30-)2E292-F2AB27-2AFB2A25-3ABLBF25-AB2A2BA27-4A605-GF2A27-F2A2B26-2AFB2A26-2ABLBF667-AGF2A27-F2A2B27-AFB2A669-AFB28-GF3A27-2A2B684-
