model
size = 32 30 31, scale = 0.05, origin = -y
material 
  colors = A:#FC0 B:#300 C:#EEE D:#777 E:#9E6D00 F:#7D9100 G:#BE4800 H:#6E041E I:#920316 J:#3DDA00 K:#5DB600 L:#020835 M:#500 N:#4A0525 O:#F93 P:#1DFF00 Q:#F00 R:#000 S:#052C2B T:#26062D U:#119613 V:#B6020F W:#DE2400 X:#F90 Y:#DA0107 Z:#095021 Aa:#19DC06 Ab:#000691 Ac:#15B90D Ad:#F09 Ae:#F08E00 Af:#F99 Ag:#FCC Ah:#FC3 Ai:#CF9 Aj:#FC9 Ak:#F33 Al:#CCC Am:#FFF An:#F6C Ao:#FF3 Ap:#F9F Aq:#F3C Ar:#F03 As:#FF9 At:#BBB Au:#CCF Av:#F39 Aw:#F9C Ax:#F0F Ay:#F66 Az:#F0C Ba:#F36 Bb:#FF0 Bc:#CFF Bd:#CC0 Be:#FFC Bf:#CC3 Bg:#F3F Bh:#F96 Bi:#FCF Bj:#0D731A Bk:#FC6 Bl:#CFC
voxels
64-Ag161-Au31-Ae122-2Ae125-Bc833-Ae676-2(2B22-2B6-)2B22-BM321-Bi548-4(B23-2B6-)B23-BM39-Ap93-Be736-M3(23-2B5-2B)23-BM869-2B23-2B5-MB23-2B5-2B23-2B197-Bd703-2(2B23-2B5-)MB23-2B32-Ai63-Bb804-2B23-2B5-MB23-BC133-A63-As703-2B23-2B5-2M23-2B66-Ak127-Ad3-Ad23-Af581-Ba30-AhBg64-BM24-B5-MB24-M99-Bh801-2B24-B5-MB24-B64-Ah707-An128-2B23-AqB5-MB24-M5-AqX24-C98-Ag31-Q35-Aj543-Ah120-Ar2-X34-2B23-AbB5-MB24-B5-BAg23-AoM168-Bl602-Az27-Ay30-Ar38-2B24-B5-2B24-BAb4-2B23-AiM168-As477-Ap59-Ak155-Af6-2B24-B2(5-MB24-M)126-Ax519-O95-Ad55-Ai70-2B24-B5-MB24-B5-2B24-M94-O549-Aj153-D70-MB2(24-B5-2B)24-M643-Al95-Ab90-Aw38-MB2(24-B5-2B)24-M798-Bf70-2B24-B5-MB24-B5-2B24-M641-Am159-Am67-2(2B24-B5-)2B24-B869-2(2B24-B5-)2B24-B7-Ao635-Ab95-Al88-Af40-RD23-2D5-RD19-A3-2D5-2R18-A4-2D740-Aj128-2(2D23-2D5-)2D23-2D154-Ab491-Ad95-O126-3(2R23-2R5-)2R23-2R138-Ab628-E69-3(2D23-2D5-)2D23-2D60-CD558-An146-E70-3(D15-A7-2D6-)D23-2D54-C6-D737-E38-A23-3(2D6-2D22-)2D79-Av585-A20-A72-A31-3A6-E23-3A3-E7-A16-4A3-CD6-DC15-4A3-CD6-DC16-2A4-CD6-DC22-2D25-4A50-S32-A521-A14-2D-4A8-AC4A10-2D-3AV2A6-8A8-DA-8A5-10A6-A-9A3-2AG9A5-A-12A-2AG2E7AE4-A-8A-7A3E7A5-D8A-6A4F3AF3A4-DC8A-6A2K2F3AC3A4-DC16AJK4AF3A4-DC10A2-2A-7AK2A7-10A2-2A-2A3-C2-2A8-13A8-2A7-7ALS6A18-6A-ASA-A31-4A32-A32-2A2(28-G2-A)E16-C-H8-E3-A28-F2-A31-A28-J2-A27-PJ-A22-2S7-A29-2A112-3AO2A9-3AO2A10-A3I3VX6-2A6GX7-2AIC-2ICVAX4-AOWD3GCGAX6-AIC-D3CIV2A2-3A6GCE2A4-AICA7CVA2-OW4G4EDEA3-2AIA8CIAO2A3G4EA3E2A2-A2HA8C2H2A13EA2-A3H8CNL2A2JK10FA2-A3H8C2L2A2PJ2K8FA2-2A2H7C2L2AOA2P2J4K3FAO3-A3N6C2LA2-AAaP4J5KA4-AOA2N4C2L2C2-2CAa2P3JD2KAO5-3AN3T2L2(2AC)AOA2P4JAO5-N-3A2T2L3A4C3AO2P2JAO10-O3AO2(2A2C)8A17-2AY4QAX22-AOYD3QCWAX20-2A2VY3QWCG2A19-O2I-VYQ2WGDGA18-2A3IVYQGA2GE2A17-A5H2Q6EA17-A2H2N2LU2JK3FA17-A2NT2LSU2PJ2KFA17-OAT2LSZU3P2JAO18-AT2LSZUAcAaP2JA19-2AL2SZUAcDAaPAO20-AO2SZUAc2AaAO22-2AZBj2UAcAO24-ABk5A115-C2I28-C4I10-5G11-7I8-3G4E9-9I6-2G7E8-9H6-D8E8-8HN2-LU2-K8F8-C4H3NT6-J2K5FC8-CH4NTCL6-D2J4K2F8-NC4N2T8-C3J2KD11-C2N2T2(2-2C)2-C3J21-C2-C28-C2AtC27-2C2-2C46-I44-Y3QW26-2VYQ2WG24-2IVYQ4G23-D2H2Q4E23-2N2LU2JKF23-T2LSU2PJC23-DLSZU3PJ24-CSZUAcAaD26-CZUAc110-
