model
size = 32 11 31, scale = 0.05, origin = -y
material 
  colors = A:#555 B:#111 C:#444 D:#FF0 E:#DDD F:#007 G:#FFF H:#777 I:#070 J:#E00 K:#C00 L:#F30 M:#FC3 N:#F60
voxels
11B12-9B10-B12-B10-3(2A6-B12-B-4A5-)3(2A21-4A5-)27A69-4(27A5-)4AJAB6AJ2(AH)2(AB)5A5-27A5-4AI2(AB)4AI2(AH)2(AB)5A2(5-27A)69-8(27A5-)5A18B4A69-8(27A5-)5ABK7B2(DB)M4B4A69-2(27A5-)B25AB5(5-27A)5-5ABL2B12D2B4A69-3(27A5-)B25AB4(5-27A)5-5ABN2BD4B2(DB)D4B4A69-4(27A5-)B25AB3(5-27A)5-5ABI9BD3B2EB4A69-5(27A5-)B25AB2(5-27A)5-5A18B4A69-5(27A5-)B25AB3(5-27A)8-4(2G2-)2E2-2E39-4(27A5-)B25AB4(5-27A)69-3(27A5-)B25AB5(5-27A)69-2(27A5-)B25AB6(5-27A)69-3(27A5-)B25AB4(5-27A)5-15AE11A69-4(27A5-)B25AB3(5-27A)5-7ACE11ACE5A6-2F10-2B30-2B17-5(27A5-)B25AB2(5-27A)5-7AC4AE7AC6A6-2F10-2B30-2B17-4(27A5-)27A4-2B25AB2(5-27A)5-7AC12AC6A11-3B55-4(27A5-)27A4-2B25AB2(5-27A)5-7AC7AE4AC6A69-5(27A5-)B25AB2(5-27A)5-7AC12AC6A18-2B30-2B17-4(27A5-)B25AB3(5-27A)5-7AC4AE7AC6A6-2F10-2B30-2B17-3(27A5-)B25AB4(5-27A)5-7AC12AC6A6-2F61-2(27A5-)B25AB5(5-27A)5-7AC7AE4AC6A69-3(27A5-)B25AB4(5-27A)5-7AC12AC6A18-2B4-3B23-2B17-4(27A5-)B25AB3(5-27A)5-7AC4AE7AC6A18-2B30-2B17-5(27A5-)B25AB2(5-27A)5-7AC12AC6A69-5(27A5-)B25AB2(5-27A)5-7AC12AC6A6-2F61-4(27A5-)B25AB3(5-27A)5-7ACE11ACE5A6-2F61-3(27A5-)B25AB5(5-27A)69-2(27A5-)B25AB6(5-27A)15-B53-8(27A5-)9A10C8A15-B53-8(27A5-)8AE10AE7A15-B53-5(27A5-)5A17B5A3(5-27A)67-
