model
size = 32 32 14, scale = 0.05, origin = -y
material 
  colors = A:#F60 B:#500 C:#111 D:#F63 E:#555
voxels
357-CA31-3C-4C24-3C-4C26-C-4C2(26-A2-3A)30-2A3(30-AD)31-D31-A309-25B998-6B12E10B994-2(6B15E11B992-)6B16E10B992-6B16E10B115-3(2D30-)2D31-D31-A32-C29-2(2C30-)2C587-6B15EC10B21-2(C31-)C27-2D2-4(C29-2D)2(C29-2A)3(C27-2C2A)8(C31-)C332-6B12E10B113-2D32-2(2D30-)2D32-A31-A29-2A3C25-2(2C2A28-)2C2A32-2A30-2A6(31-A)10(30-AC)14-25B147-2(2D30-)2D32-2D30-2A29-A3C24-3C-A27-2(C-)A29-C-A32-3A31-2A6(31-A)30-6(A31-)A3(29-3A)15-25B145-3(2D30-)D-3D29-3A24-2C3-A2C24-3C2-2(A31-)A2(32-2A)6(30-2A)30-5(3A29-)2A27-2A-2A3(28-4A)183-3(2D30-)4D25-2A-A-2A23-4C3-2A30-2(2A2C28-)2A2C30-3A29-4A28-5A27-3(3DA28-)2(2ADA28-)DAD3(2A27-A2D)2A25-4ADA29-3A30-2A3(31-A)307-2A2-3A23-2C2-2A-2A27-2(2A-2A4C23-)2A-2A4C28-4A28-2(5A22-2A3-)2(5D22-2A3-)5D24-2A-4AD24-2A-2D2AD26-3ADAD3(26-4A2D)30-AD31-A435-A28-3C4A-A26-C-2ACA5C21-C-2(2ACA5C23-)A-7A23-A-7A24-A-5A3(25-A-2A3D)29-D2A29-A2D4(30-2A)209-
