model
size = 21 12 28, scale = 0.05, origin = -y
material 
  colors = A:#050 B:#7A4F38 C:#3B2F2F D:#DDD
voxels
8-7A163-A19-3A18-3A16-7A142-3(3A18-)3A165-3A18-3A60-3A18-3A123-2(3A18-3A102-)3A144-3A81-3A18-2(3A123-3A18-3A81-)3A18-3A123-3A102-3A103-A19-3A18-3A16-7A14-7A37-3A18-3A58-4(7A14-)7A12-3A5D3A10-11A35-3A59-5A13-4(11A10-)3A5B3A9-2A2D5-2D2A8-4A5-4A34-3A38-5A14-9A10-4(13A8-)2A9B2A7-A2D9-2DA6-3A9-3A33-3A17-5A14-9A10-13A7-4(15A6-)A13BA5-AD13-DA4-2A13-2A31-5A14-9A11-11A9-13A6-4(17A4-)2A5B5C3B2A3-2AD13-D2A2-3A13-3A9-5A15-7A12-11A9-13A7-15A5-4(17A4-)A5B7C3BA3-AD15-DA2-2A15-2A8-7A13-9A11-11A9-13A7-15A4-4(19A2-)2A4B9C2B2A-2AD15-D5A15-3A6-9A11-11A9-13A7-15A5-17A3-4(19A2-)A4B11C2BA-AD17-D3A17-2A6-9A11-11A9-13A7-15A5-17A3-2(19A2-)19A-23A4B11C2B3AD17-D3A17-2A6-9A11-11A9-13A7-15A5-17A3-19A2-19A-44A4B11C2B3AD17-D3A17-2A6-9A11-11A9-13A7-15A5-17A3-2(19A2-)19A-23A4B11C2B3AD17-D3A17-2A6-9A11-11A9-13A7-15A5-17A3-4(19A2-)A4B11C2BA-AD17-D3A17-2A7-7A13-9A11-11A9-13A7-15A4-4(19A2-)2A4B9C2B2A-2AD15-D5A15-3A8-5A15-7A12-11A9-13A7-15A5-4(17A4-)A5B7C3BA3-AD15-DA2-2A15-2A30-5A14-9A11-11A9-13A6-4(17A4-)2A5B5C3B2A3-2AD13-D2A2-3A13-3A51-5A14-9A10-13A7-4(15A6-)A13BA5-AD13-DA4-2A13-2A73-5A14-9A10-4(13A8-)2A9B2A7-A2D9-2DA6-3A9-3A95-5A13-4(11A10-)3A5B3A9-2A2D5-2D2A8-4A5-4A116-4(7A14-)7A12-3A5D3A10-11A5-
