model
size = 21 12 28, scale = 0.05, origin = -y
material 
  colors = A:#222 B:#050 C:#7A4F38 D:#3B2F2F
voxels
8-7A163-A19-3A18-3A16-7A142-3(3A18-)3A165-3A18-3A60-3A18-3A123-2(3A18-3A102-)3A144-3A81-3A18-2(3A123-3A18-3A81-)3A18-3A123-3A102-3A103-A19-3A18-3A16-7A14-7A37-3A18-3A58-4(7A14-)7A12-11A10-11A35-3A59-5A13-11A3(10-2A5B4A)10-2AB5C3A9-4A5-4A8-4A5-4A34-3A38-5A14-9A10-13A3(8-A11BA)8-2A9CBA7-3A9-3A6-3A9-3A33-3A17-5A14-9A10-13A7-15A6-2A12BA6-2A11B2A6-2A12BA6-A13CA5-2A13-2A4-2A13-2A31-5A14-9A11-11A9-13A6-17A4-A15BA4-A12B4A4-3A13BA4-2A5C5D3CBA3-3A13-3A2-3A13-3A9-5A15-7A12-11A9-13A7-15A5-17A4-A15BA4-A11B5A4-A15BA4-A5C7D3CA3-2A15-2A2-2A15-2A8-7A13-9A11-11A9-13A7-15A4-19A2-2A16BA2-2A11B6A2-2A16BA2-2A4C9D2CBA-3A15-6A15-3A6-9A11-11A9-13A7-15A5-17A3-19A2-6A12BA2-6A6B7A2-6A12BA2-A5C10D2CA-2A17-4A17-2A6-9A11-11A9-13A7-15A5-17A3-19A2-6A12BA2-6A6B7A-7A12B4A5C10D2C2(4A17-)2A6-9A11-11A9-13A7-15A5-17A3-19A2-6A12BA-7A6B15A12B4A5C10D2C2(4A17-)2A6-9A11-11A9-13A7-15A5-17A3-19A2-6A12BA2-6A6B7A-7A12B4A5C10D2C2(4A17-)2A6-9A11-11A9-13A7-15A5-17A3-19A2-6A12BA2-6A6B7A2-6A11B2A2-A5C10D2CA-2A17-4A17-2A7-7A13-9A11-11A9-13A7-15A4-19A2-6A12BA2-6A7B6A2-6A11B2A2-A5C9D2C2A-3A15-6A15-3A8-5A15-7A12-11A9-13A7-15A5-17A4-5A11BA4-5A7B5A4-5A11BA4-A5C7D3CA3-2A15-2A2-2A15-2A30-5A14-9A11-11A9-13A6-17A4-5A11BA4-5A8B4A4-5A11BA4-2A5C5D3CBA3-3A13-3A2-3A13-3A51-5A14-9A10-13A7-15A3(6-4A6B5A)6-A13CA5-2A13-2A4-2A13-2A73-5A14-9A10-13A8-3A8B2A8-3A7B3A8-3A6B4A8-2A9C2A7-3A9-3A6-3A9-3A95-5A13-11A3(10-2A2B7A)10-2AB5C3A9-4A5-2ABA8-4A5-4A116-4(7A14-)7A12-11A10-11A5-
