model
size = 15 8 16, scale = 0.05, origin = -y
material 
  colors = A:#111 B:#EEE C:#0CF
voxels
34-CA3-CA8-2C3-2C66-3(A9-A109-A9-A4-)6(A9-A109-)A9-A64-5A-5A6(4-A)4-5A-5A17-2(2A3-2A-)2(2A-2A3-)3A5-3A141-2B3-2B8-2B3-2B83-2B3-2B7-4B-4B6-4B-4B7-2B3-2B68-2B3-2B7-4B-4B6-4B-4B7-2B3-2B64-
