model
size = 16 32 16, scale = 0.05, origin = -y
material 
  colors = A:#6C0 B:#0C3 C:#D00 D:#CFF E:#39F F:#0FC G:#633 H:#66F I:#CC0 J:#CF0
voxels
16-16A983-2C494-2C14-2C7-16A438-4C12-4C13-2C14-2C7-16A-14A374-2(6C10-)6C11-2(4C12-)4C13-2C7-16A-14A3-3(12A4-)12A215-5(6D10-)6D9-C6DC8-8C9-6C10-6C11-4C12-4C13-2C7-16A-14A3-3(12A4-)12A135-6G4(10-6B)9-2(D6BD8-)8D9-2(6D10-)6D9-8C8-8C9-6C10-6C11-4C13-2C23-16A-14A3-3(12A4-)12A102-2(8E8-)G6EG4-2F2-8B4-2H2(2-8B4-2B)2-8B2(4-14B)3-2B6F2B-2(2B4-D6FD2-)2H4-D6FD2-2F4-8C8-8C9-6C10-6C53-16A-14A3-3(12A4-)12A5-3(3G4-3G6-)2(3E4-3E6-)3E4-3E7-2(8E8-)G6EG4-2F2-8B4-2H2(2-8B4-2B)2-8B2(4-14B)3-2B6F2B-2B4-D6FD2-2B5-6F3-2H5-6F3-2F4-8C8-8C9-6C69-16A-14A3-3(12A4-)12A5-3(3G4-3G6-)2(3E4-3E6-)3E4-3E7-2(8E8-)G6EG4-2F2-8B4-2H2(2-8B4-2B)2-8B2(4-14B)3-2B6F2B-2B4-D6FD2-2B5-6F3-2H5-6F3-2F5-6C10-6C85-16A-14A3-3(12A4-)12A5-3G4-3G6-3I4-3I38-3E4-3E56-6D9-3(D6BD8-)D6BD9-D4B12-4D11-6D12-2F13-J2-J11-2D2-2D117-16A-14A3-3(12A4-)12A5-3G4-3G6-3G4-3G90-2D13-4D11-3(D4BD10-)D4BD11-4D45-2F151-16A-14A3-3(12A4-)12A5-3G4-3G6-3G4-3G121-3(4D12-)4D61-2F151-16A-14A3-3(12A4-)12A265-2F151-16A-14A3-3(12A4-)12A418-16A-14A481-
