model
size = 23 12 29, scale = 0.05, origin = -y
material 
  colors = A:#CA1515 B:#BBB C:#AE1212 D:#EEE
voxels
6-2A3(DA)D2A12-2A7D2A12-3A5-3A12-4A3-4A14-7A17-5A151-2(3A2B5-2B3A8-)4AB5-B4A8-5AB3-B5A10-4A3B4A12-5AB5A15-5A127-2(2A2B9-2B2A6-)3A11-3A6-3A11-3A8-A11-A10-2(A11-)5AB5A15-5A103-2(2AB13-B2A4-)3A13-3A4-3A13-3A6-A13-A8-2A11-2(2A9-)2A12-4AB4A16-5A80-A2B13-2BA4-ADB13-BDA2(4-2AB13-B2A)5-AB13-BA6-ADA11-ADA7-2(3A9-)6AB6A12-9A77-2(2AB15-B2A2-)2A17-2A3-A17-A4-A17-A5-2AB11-B2A6-2ADA9-AD2A2(7-4A)10-5AB5A15-5A56-2(AB17-BA2-)A19-A2-A19-A3-A17-A4-A17-A5-3AB9-B3A6-3ADA7-AD3A8-6AB6A12-9A53-2AB17-B4AB17-B2A-A19-A2-A19-A3-A17-A4-A17-A5-A15-A6-4AB7-B4A8-6AB3AD2A12-9A53-AB19-B2AB19-B3A19-2A-A19-A2-2A17-2A3-A17-A4-2A15-2A5-3A11-3A8-3ABA3-AB3A12-4AB4A17-3A33-AB19-B2AB19-B3A19-4A19-2A-2A17-2A2-2A17-2A3-2A15-2A4-4A11-4A6-5AB3-B5A10-3ADABAD3A15-5A32-AB19-B2AB19-B3A19-4A19-2A-2A17-2A2-2A17-2A3-2A15-2A4-4A11-4A6-4A7-4A10-4A3B4A14-7A18-3D10-A3(B19-B2A)B19-BA-AB17-BA2-AB17-BA3-AB15-BA4-2A2B11-2B2A6-2A2B7-2B2A10-2A7B2A14-3AD3A18-3D10-AB19-B2AB19-B3A19-4A19-2A-2A17-2A2-2A17-2A3-2A15-2A4-4A11-4A6-4A7-4A10-4A3B4A14-7A18-3D10-2A2(B17-B4A)19-2A-A19-A2-2A17-2A3-A17-A4-2A15-2A5-3A11-3A2(7-4A)10-3A2(BA)B3A15-5A33-2(AB17-BA2-)A19-A2-A19-A3-A17-A4-A17-A5-A15-A6-3A11-3A8-3AB5-B3A12-4AB4A17-3A34-2(2AB15-B2A2-)2A17-2A2-2A17-2A3-2A15-2A4-2A15-2A5-A15-A6-3A11-3A8-2A2(B3A)B2A12-9A55-2(AB15-BA4-)A17-A4-A17-A5-A15-A6-A15-A7-2AB9-B2A8-2AB9-B2A10-5AB5A14-7A56-AD2B11-2BDA4-2A2B11-2B2A2(4-3AB11-B3A)5-2AB11-B2A6-2AB11-B2A7-2(3A9-)2A9-2A11-5AB5A14-7A56-CDADB9-BDADC4-C2ADB9-BD2AC5-3A11-3A6-3A11-3A7-2(2A11-2A8-)2(3A9-)6AB6A11-11A16-3A58-C2(DA)9B2(AD)C4-2C3A9B3A2C6-3A4-B4-3A8-3A4-B4-3A9-2(2A4-B4-2A10-)2A4-B4-2A11-11A13-9A78-C3(DA)D3A3(DA)DC4-4CD9AD4C8-4(11A12-)11A13-9A15-7A79-C2(DA)D2A3D2A2(DA)DC4-7CD3CD7C11-4(D3-D18-)4D127-C3(AD)5A3(DA)C4-19C235-C2(AD)A5D2(AD)AC6-17C236-C2ADAD5ADAD2AC6-17C237-C2ADA5DAD2AC8-15C239-C2AD5AD2AC10-13C241-C2A5D2AC12-11C243-9C14-9C237-
