model
size = 11 28 11, scale = 0.05, origin = -y
material 
  colors = A:#CAAD5F B:#FFD724 C:#004383 D:#AAA E:#65924D F:#BBB G:#EEE
voxels
26-3B7-10(5B6-)3E3(2B6-2BE)2B6-3E2B8(6-5B)7-3D29-5D5-8(2B3A2B4-)3(EB3A2B4-)2(2B3A2B4-)EB2(3A2B4-2B)3(3A2B4-EB)5(3A2B4-2B)3-2B5-D3BD7-3D8-3F6-2D3B2D3-2(2B5A2B2-)2B5AG2(B2-2B5AC)2(B2-BC5AC)B2-EC5A2B2-BC2(5A2B2-2B)5AGB2-2B5ACB2-BG5ACB2-BC5ACB2-EC5ACB2-BC5ACB2-2B5A2B2(2-BC5ACB)2-E2(C5ACB2-B)G2(5A2B2-2B)5-2B3-DB3FBD5-D3-D6-F3-F4-2DB3DB2D2-B7AB-2B7A3B8AG2(2B8AC)2BC7ACBEC7AC2BC7A3B2(C7A2BE)2B6AG3B7AC2BG3(7A3BC)7AC3B7ACBE2(C7AC2B)C7ACBEC7AC2BG7AG3B7A4B7-2B-DB5FBD3-D5-D4-F5-F3-DB5DBD-2B7A4B7A3B8AG2(2B8AC)BE2(C7AC2B)2(C7A2BE)C7A2BG2B6AG3B7AC2BG7AC2BC7ACBEC7AC2BC7AC3B2(7ACBEC)2(7AC2BC)7ACBEG7AG3B7A4B7-2BDBF2-4FBD-D3-6F2-F5-F3-DB5DBD-2B7A4B7A3B8AG2(2B8AC)BE2(C7AC2B)2(C7A2BE)B7A2BG2B6AG3B7AC2BG7AC2BC7ACBEC7AC2BC7AC3B7A2B2(EC7ACB)EC7AC2BC7ACBEG7AG3B7A4B7-2BDBF2-5FD-D3-F-2(F2-)F5-F3-DB5DBD-2B7A4B7A3B8AG2(2B8AC)BE2(C7AC2B)C7ACBEC7A2BEB7A2BG2B6AG3B7AC2BG4(7AC2BC)7A2BEC7ACBE2(C7AC2B)C7ACBEG7AG3B7A4B7-2BDBF2-4FBD-D3-6F2(3-F)4-2DB3DB2D2-B7AB-2B7A3B8AG2(2B8AC)2BC7ACBE2(C7AC2B)C7A2BEB7A2BE2B6AG3B7AC2BG7ACBEC7ACBEB2(7AC2BC)7A2BE2(C7AC2B)C7ACBEC7AC2BG7AG3B7A4B7-2B-DB5FBD3-D5-D6-3F6-2D3B2D3-2(2B5A2B2-)2B5AG2(B2-2B5AC)2(B2-BC5AC)B2-EC5A2B2-BC2(5A2B2-2B)5AGB2-2B5ACB2-BG3(5ACB2-BC)5ACB2-2B5A2B2(2-BC5ACB)2-E2(C5ACB2-B)G2(5A2B2-2B)5-2B3-DB3FBD5-D3-D17-5D5-8(2B3A2B4-)3(EB3A2B4-)3(2B3A2B4-)EB3A2B4-2B3(3A2B4-EB)5(3A2B4-2B)3-2B5-D3BD7-3D30-3B7-10(5B6-)3E3(2B6-2BE)2B6-3E2B8(6-5B)7-3D15-
