model
size = 24 15 6, scale = 0.05, origin = -y
material 
  colors = A:#A00 B:#960 C:#9CF D:#FFF E:#500
voxels
32-9A3(15-A7DA)16-7A232-3(9A15-)9A16-7A255-A9-A13-A9E2(A13-A9C)A13-11A16-4(5A19-)5A20-3D21-3D88-2(A11-)A11E2(A11-AC-9C)A12-A9CA13-3A5C2A14-3A5C2A12-5B5C4B5-10B5C19B5C10B2(-2B-B-2B-D3CD2(-B-2B))-2B-B-2B-5D-B-2B2(-B)2-2B-B-2B2-3D2-B-2B-B9-2B21-2(A11-)A11E2(A11-A11C)A12-A9CA13-2A7CA14-2A7CA12-4B7C4B4-9B7C18B5C10B2(-2B-B-2B-D3CD2(-B-2B))-2B-B-2B-5D-B-2B2(-B)2-2B-B-2B2-3D2-B-2B-B9-2B22-A9-A13-A9E2(A13-A9C)A13-11A15-4(7A17-)7A19-3D21-3D82-
