model
size = 17 23 23, scale = 0.05, origin = -y
material 
  colors = A:#E00 B:#D00 C:#100 D:#222 E:#800
voxels
23-5A384-9A10-5A366-11A7-9A10-2(5A12-)5A315-11A6-11A8-2(7A10-)7A11-5A12-5A280-13A5-11A7-2(9A8-)9A9-7A10-7A12-3A264-13A4-13A5-2(11A6-)11A7-9A8-9A10-5A82-2(A16-)A146-13A4-13A5-2(11A6-)11A7-9A8-9A9-7A12-3(3A14-)3A15-A14-2(5A12-)5A127-13A4-13A5-2(11A6-)11A7-9A8-9A9-3A-3A11-5(5A12-)5AB11-2(5A12-)5A110-13A4-13A5-2(11A6-)11A7-9A8-9A9-7A11-2(5A12-)5A9-11A5-A3B5A3BA8-3(5A12-)5A13-3A95-11A5-13A5-2(11A6-)11A7-9A8-9A10-9(5A12-)5A111-11A6-11A7-2(9A8-)9A9-7A9-4B4A9-2B5A10-4(9A8-)9A9-7A8-3C5A3C4-5C5A5C2-3C9-3C-2C13-4C13-3C2(15-2C)15-C21-9A7-11A8-2(7A10-)7A11-AB3A10-4B2A3B8-2B4A3B9-B5AB9-3(AB5ABA8-)AB5ABA9-B5AB8-3C5A3C4-5C5-5C2-3C9-3C-2C13-4C13-3C15-C57-5A10-9A10-2(5A12-)5A11-3B2A11-4B2A3B8-2B4A3B10-5A11-4(7A10-)7A181-5A13-2(3A14-)3A12-3B3AB10-3BA3B11-2(2B2AB12-)5A12-C3AC12-E3AE11-E5AE181-4(5A12-)5A11-2B3A2B12-4(3A14-)3A217-5(5A12-)B3AB13-2(3A14-)3A251-4(5A12-)5A13-2(3A14-)3A268-3(5A12-)5A13-2(3A14-)3A285-3(5A12-)5A13-3A14-3A302-5A12-5A11-7A11-B3AB13-3A319-5A13-4A11-7A12-3A320-3A12-2(7A10-)7A333-7A2(10-2(A2D)A)10-7A328-
