model
size = 16 28 19, scale = 0.05, origin = -y
material 
  colors = A:#C30 B:#F30 C:#EEE D:#C96 E:#996 F:#FFC G:#930 H:#FCC I:#CC9 J:#F60 K:#888 L:#963 M:#AAA N:#663 O:#FC9 P:#C99 Q:#966 R:#CCC S:#400 T:#444 U:#777 V:#999 W:#300 X:#BBB Y:#630 Z:#633 Aa:#800 Ab:#111 Ac:#555 Ad:#500 Ae:#600 Af:#A00 Ag:#700 Ah:#660 Ai:#C63 Aj:#666 Ak:#333 Al:#222
voxels
151-X14-3R13-3X3(13-3V)13-3X14-X271-R14-3R13-3M2(13-3V)13-3K13-3U4(13-3K)13-3M13-3X13-3M14-X207-M14-3M2(13-3U)13-3M13-3X125-3V13-3X13-3R12-I3K189-3V13-3U13-3M188-I3M13-3R12-I3V12-I176-3V13-3Ac188-I15-I3R12-I3M12-2I14-I14-2I-C2-C9-I6C10-2I128-M15-Aj172-2(C6Ac9-)C5PC9-C5VC9-I5UC9-I5VI9-I3MC2IC8-IM2CMIC9-2IX2C-C9-IRIC-C42-8Ab8-8Ab42-3VW11-4KW11-W3AjS11-W3MS11-W3XS11-W3MS11-Ae3X2(W11-Ae3M)W11-Ae3XS11-Ae3MS11-4XS9-C7P8-2(C7PC7-)C4(8I8-)8I7-C5MCMC7-I4PC3P2I5-C8R23-9N7-9N8-7Y2(2(9-7W)2(9-7S))2(9-7S)9-7Ad9-7Ae9-7Ad8-8OC7-9OC6-9FC6-9HC3(6-10F)5-C9FC5-C10F3-4C9P2C3-C10RC9-3I-I7-2(10T6-)9Ah5(7-9G)7-9A6(7-9G)7-9A5-12O4-13O4-12H3-11HC4-13F4-12F3-12FC3-13FC3-C11FC-3C11PC3-C10RC13-2I4-13T4-12T5-10G5(5-11A)5-11J4(5-11A)2(5-11B)5-11A4-12I4-13I3-11OKDC-C12HC3-13HC2-13HC-I12H2C-C13HC-CI12HC-C12DC2-3C10MC4-C8-I5-13K3-13K5-10Ag6-10G5-11G4(5-11A)5-11J5-11A2(5-11B)2(5-11J)5-11A4-12E2D2-13EC2-C12DC2-C11DC3-C12DC2-C10DK3C-C10D3C2-C11D2C-2I11DCK2C2Q10ECI-13C6-C-C11-13K3-13K4-11Aa5(5-11A)2(5-11J)2(5-11A)4(5-11B)4-13ED2-12EDC2-C12DC2-C11DC3-C10D2C3-C12DC-2C12DC2-C11D2C-2C11DCK2C2Q10EKI2-12C20-13E3-13E4-11G4(5-11A)5-11B5-11J5(5-11B)2(5-11A)4-2(13LC-I)2(12EC2-C)11EK2(I2-C12E)IC-C12EIC-I2QD9QMC-C2QE8Q2PC2-9CIC-C19-13U3-13U4-11Af2(5-11A)3(5-11B)5-11J5-11A4(5-11B)2(5-A10B)C4-L9N2DC-C2L10NP3-IED8L2C2-C2ED8LH2(I2-C2ED8LF)I2-C2ED7L2FI2-2CKD7L2FI3-CQDH6L2FMC2-CQED5ND3PC3-2CM5CM-2C20-11Q5-11Q6-9Aa5(7-9A)7-9J7-9B2(7-9A)3(7-9B)C6-8BADC4-CE7Z2O4-2CE7Z2O5-CDO6NHF4-2CDH6N2H3-IKC2(DH5NH2F4-2C)DHF3NDH2F3-3CDHF3NDH2F4-2CDHF3NDH2FC4-2CDP3NED2PC5-CMRK3CMRKC10-2C9-QY2G2YZAkAl7-QY2G2YZAkAl8-2(4AGAG9-)2(AB4AG9-)A2B3AG9-4JAJA9-BAB2JAG9-A2B3AG9-A2BABAG9-5BAG9-4BJBG9-JBABJ2B9-JBAB2AB9-A2G2Ai2A2D7-IOE2DOIO6-CDIOE2DOIO6-2COHE3DOH7-C2HE3D2H5-C-CHF3EDHF5-3CHF3EDHF6-2CH2F2EDHF5-K-CH2F2EDHF7-CH2F2QDHF7-CD2P2QEDP7-CMR4CMR12-C11-Q2G2YZAk9-Q2G2YZAk10-2(3AGA11-)2(B4A11-)2B3A11-3JAJ11-AB2JA11-2B3A11-2BABA11-4BA11-A2B2(JB11-BAB)2A11-AG3AiD9-D2O2DO9-CD2O2DOH9-CHF2D2H9-C2H2DHF9-C2F2D3(HF8-2C2F2I)HF9-C2F2MDP9-CK3PMR9-CR4M27-2G2YZ11-2G2YZ206-D13-4D10-COD3C10-D2O2CO10-DKF2CHC10-4CHF9-C2F2CHF9-C2F2IHF8-2C2F2IHF9-C2F2IHC11-F2MDC10-5C12-KM270-C14-3C-C31-C15-C14-2C4(13-3C)54-
