model
size = 31 30 32, scale = 0.05, origin = -y
material 
  colors = A:#111 B:#FC0 C:#300 D:#EEE E:#777 F:#500 G:#F93 H:#60C I:#F90 J:#CF9 K:#F09 L:#F3C M:#39F N:#F99 O:#F33 P:#FC9 Q:#FCC R:#FC3 S:#FF3 T:#FF9 U:#FF0 V:#888 W:#F03 X:#F3F Y:#F6C Z:#CCC Aa:#F9F Ab:#F0C Ac:#FFF Ad:#F9C Ae:#FC6 Af:#CC0 Ag:#FFC Ah:#F96 Ai:#F00 Aj:#FCF Ak:#CC3 Al:#F0F Am:#CCF An:#F36 Ao:#F66 Ap:#F39 Aq:#CFF Ar:#CFC
voxels
71-H3-Z47-Q40-Z3-H34-Ab34-R216-Ah552-O125-I158-O58-Q30-Ai33-K453-Ac154-Ac20-BL3(29-2B)29-GB57-2M121-Aj561-2(2B29-)2BO28-2(AB29-)AB14-H14-2B21-J7-2B17-R9-M-GB21-U627-I25-2C3-2B24-2C3-AB2-AbX10-Ao8-2CF3-AB-N13-W6-3C4-AB21-3CF4-AB4EA2E16CF5-AB4EA2E6CF2C2(FC)DC7-AB4EA2E2C7FD12-AB4EA24-2B29-GB89-Aq497-I30-2B24-2C3-AB24-2C3-EB9-Ak-EJ10-3C2-2AB10-Ad3-W7-3C3-2ABA12-N7-4C3-3AD3EA2E8-HL2-5C4-DA2D3EA2E12-3C6-2AHD3EA2E7-JS13-AJ4EA24-A30-2B12-G16-G14-Al67-N443-B30-2(AB29-)D6(B28-2A)B28-EAB29-A30-A3-2E25-B30-B495-B30-AB29-D2(B28-2A)B28-A2B6-N21-4(2AB28-)2AB29-EDB28-A4-D25-A30-B495-G30-AB29-A9(B28-2A)-B28-2(A30-)B495-2B2(29-AB)3(28-2AB)28-2(3AB27-)3AB5-B21-2(2AB28-)2A-B28-2(A30-)B6-H147-BL3(29-2B)29-GB215-B30-ADB28-A2(B28-2A)B28-4(3AB27-)3AB5-B21-2AB28-2A-B28-2(A30-)B92-3(2B29-)3(A30-)B30-2B29-GB153-B30-AB29-E2(B28-2A)B28-5(3AB27-)2AB28-DAB29-A30-G30-Ae61-I30-2B29-7(A30-)B30-GB153-B30-AB29-A2(B28-2(3AB27-)2A)B28-D2(AB29-)3(B30-)I30-2B29-A30-E2(29-2A)29-3A28-DA29-2AH29-AJ29-A30-2B29-G123-B30-G30-B30-AB28-2AB28-EAB28-2(2AB2-B25-)EAB2-B26-2(A30-)G3-D26-2(B30-)2B29-A30-D29-3(3A28-)3(2A29-)E2A29-2(A30-)B30-B123-2(B30-)7(AB29-)B30-B61-B30-AB29-D2(29-2A)29-AB5(29-2A)30-E2(30-A)30-B154-B30-G30-B30-3(AB29-)2B29-2(B30-)B61-G30-AB29-A9(29-2A)2(30-A)30-B216-4(2B29-)GB90-2B61-2B29-AB29-A9(29-2A)2(30-A)30-B216-GB4(29-2B)90-3B60-B2(30-A)9(29-2A)2(30-A)30-B154-3(2B29-)3(AB29-)3(2B29-)2B60-2B29-A30-E8(29-2A)29-D2A29-2(A30-)Ae123-IB29-2B2(29-AB)29-3(A30-)2(AB29-)2B29-2B60-BAB28-B2(30-A)29-A30-5(2A29-)DA30-2A29-A2(30-B)92-IB29-2B29-AB29-4(DB28-A)DB28-2A2(B29-A)B29-2B29-B2AAp27-2B29-B30-G2(30-A)29-2A29-EA2(29-2A)29-E3(A30-)G30-B92-B30-AB29-2A2(B28-A)4(DB28-A)DB28-2DB28-AD2(B29-A)B29-BA29-B61-2(B30-)7(A30-)B30-B123-B30-AB29-9(DB28-A)D2(B29-A)B29-GB91-B30-G30-B30-2A29-2(A30-)2(B30-)B154-G3-Y26-AB28-2A9(B28-AD)2(B29-A)B29-2B153-4(B30-)G216-B30-A29-2A9(B28-AD)2(B29-A)B29-2B185-D308-B30-AE28-D30-AE8(B28-AD)2(B29-A)B29-2B35-H458-B30-AE29-DE28-D30-7(ADB28-)DVB29-AB29-2B29-GB525-B30-AE29-DB28-AB29-5(ADB28-)D2(AB29-)B30-2B30-B45-TAr509-B26-C3-AE25-C3-DB25-C2-2(AB29-)2AE28-DA2DE22-Aa3-DA2DE26-AV2DE5-S21-2(B30-)2B531-K7-GAa46-B16-R8-2C3-B5-G7-K11-2C3-A24-F2C3-AB22-3C4-AB21-4C4-A-2B2EA2E11CF5C5-A5EA2E12CF2C7-A5EAEA8CQI12-A5EA24-G30-B110-P2-K567-B30-B23-2C5-A22-CFC3-Am-A4-2(EA)3C2F12C3-M-A4-2(EA)2CF2C2FC7F7-B4-2(EA)6CF2CL12-B4-EA24-B25-Ag35-U21-B32-Af28-T455-P86-P10-Y32-An10-B19-X10-3(B30-)B215-Ad402-
