model
size = 25 22 18, scale = 0.05, origin = -y
material 
  colors = A:#F08E00 B:#F5B200 C:#060808 D:#00D E:#9C0 F:#0D1111 G:#CF3 H:#9C3 I:#E64700 J:#020 K:#090D0D L:#918E00 M:#000 N:#050 O:#DAD600 P:#101616 Q:#99C R:#9E6D00 S:#FFFA00 T:#999 U:#6D6B00 V:#040 W:#484700 X:#0F9
voxels
262-R23-BRB2(22-3B)322-B23-2B498-2B74-B396-A24-2A24-B77-B73-3B21-3(5B20-)5B21-3B22-3A323-B23-3B21-5B19-2B3A2B18-B5AB17-2(2B5A2B16-)2B5A2B17-2B3A2B18-2B2A3B20-2BA297-3B21-B2A2B19-L5AL17-B7AB15-2B7A2B14-11A2(14-B9AB)15-B7AB16-B7AB17-2B3A2B19-5B270-BA3B18-BL5ALB16-B7AB15-11A8-3DS2-11A2-S3D3-2D3-11A3-2D8-B11AB13-2(B9AB14-)B9AB15-B7AB17-2B3A2B20-BHB221-E3AE19-B5AB17-B7AB15-11A13-13A6-X5D13A5DX2-4DB11AB4D8-2(B11AB12-)B11AB13-B9AB14-11A15-9A17-IABHBAI219-E3AE18-2B5A2B15-B9AB13-13A12-13A7-3DS-13A-S3D3-2D2-B11AB2-2D8-3(B11AB12-)B11AB13-11A15-9A17-IABHBAI218-HE3AEH17-B7AB15-B9AB13-13A12-13A11-2(15A10-)E13AE10-E13AE11-B11AB12-B11AB13-11A14-C9AC15-CIABHBAIC186-A17-A12-HE3AEH17-B7AB15-B9AB14-12A12-B11AB11-2(15A10-)E13AE10-E13AE11-2(B11AB12-)C11AC11-2C11A2C10-K2CAIABHBAIA2CK10-2F2C7-2C2F10-3F9-3F2(11-C)12-C11-C84-2AO13-O2A7-2B2OEHE3AEHE2O2B9-W2B9A2BW11-B11AB12-13A10-E15AE8-17A9-15A2(10-E13AE)10-15A11-B11AB12-C11AC11-C13AC10-F2AC2ABHB2AC2AF10-F2ACP5-PC2AF10-FAF9-FAF10-PC11-CP2(11-C)59-A17-A6-2A15-2A12-HE2ABEH17-B7AB15-B9AB13-2(N11AN12-)J11AJ11-J13AJ10-E13AE11-2(B11AB12-)B11AB13-11A13-2C9A2C11-K2C-IABHBAI-2CK10-F2KC7-C2KF10-3F9-3F2(11-F)141-E3BE18-2B5A2B15-B9AB14-N9AN13-2(Q11AQ12-)J11AJ4(12-B11AB)13-11A15-9A17-IABHBAI219-5B19-B-3A-B17-B7AB15-N9AN2(14-M9AM)13-J11AJ2(12-B11AB)13-B9AB14-B9AB15-B7AB17-B5AB19-ABHBA220-5G19-B5-B18-L5AL17-B7AB15-2(M9AM14-)J9AJ3(14-B9AB)15-B7AB16-2B5A2B18-2BA2B22-H247-5G20-G3-G19-LG3TGL17-UB5ABU16-R7AR3(16-B7AB)16-2B5A2B17-B5AB19-B3AB21-BAB296-5G45-5B19-2BVAV3(2B18-2B3A)2B19-5B20-2BA2B22-A162-
