model
size = 18 22 25, scale = 0.05, origin = -y
material 
  colors = A:#800 B:#E00 C:#060808 D:#C63 E:#200 F:#0D1111 G:#EEE H:#500 I:#400 J:#888 K:#000 L:#090D0D M:#BBB N:#08B600 O:#000124 P:#F6F Q:#C30 R:#101616 S:#99C T:#A00 U:#F3C V:#444 W:#FC0 X:#484700
voxels
173-Q394-3D393-3D15-3D245-A17-3A109-3D15-3D263-2A17-B71-E17-A2-QDQ16-D265-P17-B17-X53-A17-3A-D12-K3A-D12-4E15-3E15-A53-2C15-LFL2(15-3F)16-R107-P2(17-B)16-OA-2A12-SOAB3A11-SK5A10-2K4A2B10-2B4A3B9-3B3A2B11-2BA4B11-6B14-2C2(15-CAC)15-L2(AF15-F)2C16-2C88-P17-B15-2BA3B11-2O6A9-2N8A8-2N8AB7-K10A7-B9AB7-B8A2B7-2B7AB9-B6A2B10-7A12-C2AC14-CAC15-LAC15-3F60-V17-V45-E15-2BA3B11-B6A2B8-B8AB7-J10AB6-T10AB6-3(B11AB5-)B10AB7-B9AB7-2B7AB10-7A13-CAC14-3C96-V17-J26-4H11-3B4A2B9-M8AM7-M10AM6-B11A4(B4-B12A)2(B5-B11A)B6-B9AB8-B7AB10-2IA4I13-R134-J4-GB7E8-G2-7AB4-J-2G10AB6-G11AB4-B12AB4-4(B13AB3-)B12AB4-B12AB5-B10AB7-B8A2B8-8A148-J4-G2B6A5-J2-G-9AB3-J-G-11AB-J3-U11AB4-B13AB3-W13A3(B2-B14A)B3-B13AB3-B14A4-12AB5-2B9AB8-9B152-G2B6A8-G-8A3BJ3-G-11AB5-U11AB4-B13A2(B2-T14A)2(B2-B14A)B3-B13AB3-15A3-13AB5-11AB7-10H152-G2B6A8-G-8A2B5-G-10A2B5-U11AB4-B13AB3-W13A3(B2-B14A)B3-B13AB3-B12ABA4-13A5-2B9AB8-9B152-GB7E8-G2-7AB6-2G10AB6-G11AB4-B12AB4-4(B13AB3-)B12AB4-B12AB5-B10AB7-B8A2B8-8A156-4H11-3B4A2B9-M8AM7-M10AM6-B11A4(B4-B12A)2(B5-B11A)B6-B9AB8-B7AB10-2IA4I13-R143-E15-2BA3B11-B6A2B8-B8AB7-J10AB6-T10AB6-3(B11AB5-)B10AB7-B9AB7-2B7AB10-7A13-CAC14-3C142-P17-B15-2BA3B11-2O6A9-2N8A8-2N8AB7-K10A7-B9AB7-B8A2B7-2B7AB9-B6A2B10-7A12-C2AC14-CAC15-LAC15-3F124-P2(17-B)16-O4A12-SOAB3A11-SK5A10-2K4A2B10-2B4A3B9-3B3A2B11-2BA4B11-6B14-2C2(15-CAC)15-L2(AF15-F)2C16-2C70-P17-B17-X53-A17-3A-D12-K3A-D12-4E15-3E15-A53-2C15-LFL2(15-3F)16-R88-2A17-B71-E17-A2-QDQ16-D246-A17-3A109-2(3D15-3D375-)3D394-Q222-
