model
size = 15 15 29, scale = 0.05, origin = -y
material 
  colors = A:#EEE B:#633 C:#963 D:#996 E:#100 F:#222 G:#663 H:#966 I:#333 J:#BBB K:#111 L:#999 M:#555 N:#C99 O:#CCC P:#C96 Q:#330 R:#444 S:#CC9 T:#888 U:#010 V:#FFF W:#993 X:#300 Y:#666 Z:#AAA
voxels
96-3A12-4A11-4A12-2A146-5A9-4L3A8-3(4K4A7-)4E4A8-3R3A10-4A87-2A10-7A7-5F4A6-5F5A5-5B5A4-6B5A4-6I5A5-5F5A5-5K4A7-4E4A8-3T2A69-7A7-5F4A5-6B5A4-6B6A3-6F4(6A3-6B)5A5-5F5A6-4E4A8-3T2A40-5A8-5R4A5-6B5A4-6H6A2-7H2(6A2-7C)7A-7C6A2-7G6A3-6G6A3-6B5A5-5K5A6-4E3A11-V26-7A7-5F5A4-6H6A2-7N6A2-7D7A-7W7A-7G2(7A-7C)7A-7J6A3-6O6A3-6I5A5-5K4A8-3Y2A11-3A10-4Z4A6-5B5A4-6D6A2-7S6A2-7D7A8B7A8U7A8E7A-7L7A-14A-13A3-6D5A5-5I4A8-3R3A10-4A9-4L4A5-6C5A4-6D6A2-7N7A-7D3(7A8E)7A8M7A-7O7A-7J6A3-6H6A4-5B5A6-4I3A10-4A9-4L4A5-6G5A4-6D6A2-7N6A2-7D7A8Q2(7A8E)7A8M2(7A-7C)6A3-6B6A4-5B5A7-3R3A11-2A10-4V4A6-5F5A4-6H6A2-7L6A2-7P7A-7P7A8B7A8Q7A-7O7A-7S7A-7C6A3-6B5A5-5F4A8-3Y3A24-6A7-5I4A5-6H5A4-6H6A2-7N6A2-2(7D7A-)2(7C7A-)7C6A3-6B6A4-5B5A6-4K4A9-2J2A26-4A9-4J4A6-5F5A4-6G5A4-6D6A2-7P6A2-7G2(6A2-7B)6A3-6B6A3-6G5A5-5B4A8-3M3A54-5A9-4L4A6-5F5A4-6C2(5A4-6B)6A3-6B6A3-6G2(5A5-5B)4A7-4M3A11-2A71-5A9-5J2A7-6M3A6-6X3A6-6B4A5-6I4A5-6B3A7-4F4A8-3T3A11-2A103-A12-5A10-V5A8-2J5A9-J5A9-2O4A10-4A130-5A9-4L3A8-3(4K4A7-)4E4A8-3R3A10-4A87-2A10-7A7-5F4A6-5F5A5-5B5A4-6B5A4-6I5A5-5F5A5-5K4A7-4E4A8-3T2A69-7A7-5F4A5-6B5A4-6B6A3-6F4(6A3-6B)5A5-5F5A6-4E4A8-3T2A40-5A8-5R4A5-6B5A4-6H6A2-7H2(6A2-7C)7A-7C6A2-7G6A3-6G6A3-6B5A5-5K5A6-4E3A11-V26-7A7-5F5A4-6H6A2-7N6A2-7D7A-7W7A-7G2(7A-7C)7A-7J6A3-6O6A3-6I5A5-5K4A8-3Y2A11-3A10-4Z4A6-5B5A4-6D6A2-7S6A2-7D7A8B7A8U7A8E7A-7L7A-14A-13A3-6D5A5-5I4A8-3R3A10-4A9-4L4A5-6C5A4-6D6A2-7N7A-7D3(7A8E)7A8M7A-7O7A-7J6A3-6H6A4-5B5A6-4I3A10-4A9-4L4A5-6G5A4-6D6A2-7N6A2-7D7A8Q2(7A8E)7A8M2(7A-7C)6A3-6B6A4-5B5A7-3R3A11-2A10-4V4A6-5F5A4-6H6A2-7L6A2-7P7A-7P7A8B7A8Q7A-7O7A-7S7A-7C6A3-6B5A5-5F4A8-3Y3A24-6A7-5I4A5-6H5A4-6H6A2-7N6A2-2(7D7A-)2(7C7A-)7C6A3-6B6A4-5B5A6-4K4A9-2J2A26-4A9-4J4A6-5F5A4-6G5A4-6D6A2-7P6A2-7G2(6A2-7B)6A3-6B6A3-6G5A5-5B4A8-3M3A54-5A9-4L4A6-5F5A4-6C2(5A4-6B)6A3-6B6A3-6G2(5A5-5B)4A7-4M3A11-2A71-5A9-5J2A7-6M3A6-6X3A6-6B4A5-6I4A5-6B3A7-4F4A8-3T3A11-2A103-A12-5A10-4V2A8-5J2A9-4J2A9-4O2A10-4A65-
