model
size = 15 15 30, scale = 0.05, origin = -y
material 
  colors = A:#EEE B:#336 C:#100 D:#369 E:#001 F:#96C G:#6CC H:#222 I:#639 J:#39C K:#969 L:#99C M:#333 N:#3CC O:#36C P:#555 Q:#939 R:#111 S:#9CC T:#004 U:#366 V:#69C W:#999 X:#777 Y:#339 Z:#636 Aa:#C9C Ab:#66C Ac:#033 Ad:#CCC Ae:#6FF Af:#444 Ag:#FFF Ah:#CCF Ai:#036 Aj:#6CF Ak:#888 Al:#002 Am:#303 An:#003 Ao:#039 Ap:#669 Aq:#63C Ar:#BBB
voxels
82-A12-2X3A10-2H4A8-3R4A9-2R4A9-2H4A10-Ar3A146-2AgA12-2Ad2A11-2Ad2A12-2A146-3Ak2A9-4M3A8-4Am4A7-4R2(4A7-4E)4A8-3R3A10-2Ad2A87-2A10-4M3A7-5B4A6-5B5A5-5B5A4-6B5A4-6T5A5-5Al5A5-5T4A7-4H4A8-3X2A69-4Ac3A7-5Ai4A5-6D5A4-6Ab6A3-6Q6A3-6I6A3-6D2(6A3-6U)5A5-5D5A6-4B4A8-3W2A40-2W3A8-4B5A5-5O6A4-5V7A2-6L7A2-6Q7A2-6K8A-6K7A2-6P7A3-5U7A3-5J6A5-4D6A6-3B4A11-A26-3H4A7-4I6A4-5F7A2-6L7A2-6F8A-6Af8A-6X8A-6P8A-6B8A-6D7A3-5N7A3-5J6A5-4B5A8-2Ak3A11-3A10-3B5A6-4F6A4-5Aa7A2-6L7A2-6P8A7C8A7E8A7C8A-6C8A-6B8A-6G7A3-5G6A5-4D5A8-2H4A10-Ag3A9-3B5A5-5F6A4-5Ah7A2-6S8A-6M8A7E3(8A7C)8A-6B8A-6G7A3-5S7A4-4Ap6A6-3B4A10-Ag3A9-3B5A5-5D6A4-5G7A2-6G7A2-6B8A7E3(8A7C)8A-6B8A-6S7A3-5L7A4-4Aq6A7-2H4A11-2A10-3B5A6-4D6A4-5N7A2-6Ae7A2-6D8A-6R8A7E8A7C8A-6M8A-6K8A-6Aa7A3-5F6A5-4I5A8-2H4A24-2H4A7-4B5A5-5J6A4-5Aj7A2-6N7A2-6I8A-6Z8A-6W8A-6Q8A-6F7A3-5V7A4-4O6A6-3B5A9-Ad3A26-Ag3A9-3B5A6-4D6A4-5J6A4-5N7A2-6V7A2-6K7A2-6Z7A2-6I7A3-5Ab7A3-5O6A5-4Ao5A8-2T4A54-2X3A9-3B5A6-4Y6A4-5J6A4-5O6A4-5Y2(7A3-5B)6A5-4Y6A5-4B5A7-3Ac4A11-2A71-2W3A9-3H4A7-2(4B5A6-)4T6A5-4An6A5-4H5A7-3B5A8-2M4A11-2A103-A12-2X3A10-2H4A8-3R4A9-2R4A9-2H4A10-Ar3A161-2AgA12-2Ad2A11-2Ad2A12-2A146-3Ak2A9-4M3A8-4Am4A7-4R2(4A7-4E)4A8-3R3A10-2Ad2A87-2A10-4M3A7-5B4A6-5B5A5-5B5A4-6B5A4-6T5A5-5Al5A5-5T4A7-4H4A8-3X2A69-4Ac3A7-5Ai4A5-6D5A4-6Ab6A3-6Q6A3-6I6A3-6D2(6A3-6U)5A5-5D5A6-4B4A8-3W2A40-2W3A8-4B5A5-5O6A4-5V7A2-6L7A2-6Q7A2-6K8A-6K7A2-6P7A3-5U7A3-5J6A5-4D6A6-3B4A11-A26-3H4A7-4I6A4-5F7A2-6L7A2-6F8A-6Af8A-6X8A-6P8A-6B8A-6D7A3-5N7A3-5J6A5-4B5A8-2Ak3A11-3A10-3B5A6-4F6A4-5Aa7A2-6L7A2-6P8A7C8A7E8A7C8A-6C8A-6B8A-6G7A3-5G6A5-4D5A8-2H4A10-Ag3A9-3B5A5-5F6A4-5Ah7A2-6S8A-6M8A7E3(8A7C)8A-6B8A-6G7A3-5S7A4-4Ap6A6-3B4A10-Ag3A9-3B5A5-5D6A4-5G7A2-6G7A2-6B8A7E3(8A7C)8A-6B8A-6S7A3-5L7A4-4Aq6A7-2H4A11-2A10-3B5A6-4D6A4-5N7A2-6Ae7A2-6D8A-6R8A7E8A7C8A-6M8A-6K8A-6Aa7A3-5F6A5-4I5A8-2H4A24-2H4A7-4B5A5-5J6A4-5Aj7A2-6N7A2-6I8A-6Z8A-6W8A-6Q8A-6F7A3-5V7A4-4O6A6-3B5A9-Ad3A26-Ag3A9-3B5A6-4D6A4-5J6A4-5N7A2-6V7A2-6K7A2-6Z7A2-6I7A3-5Ab7A3-5O6A5-4Ao5A8-2T4A54-2X3A9-3B5A6-4Y6A4-5J6A4-5O6A4-5Y2(7A3-5B)6A5-4Y6A5-4B5A7-3Ac4A11-2A71-2W3A9-3H4A7-2(4B5A6-)4T6A5-4An6A5-4H5A7-3B5A8-2M4A11-2A36-
