model
size = 24 23 20, scale = 0.05, origin = -y
material 
  colors = A:#F33 B:#C33 C:#700 D:#933 E:#100 F:#D00 G:#800 H:#900 I:#C00 J:#A00 K:#500 L:#600 M:#300 N:#B00 O:#400 P:#200 Q:#C30 R:#870E1D S:#F9F
voxels
249-4A19-3(6A18-)6A19-4B15-C23-3(2A22-)CA22-CB267-4A19-6B2(18-6A)18-A5B19-4B15-2B4(22-CA)266-6A17-8B15-2(10B14-)2(10A14-)10A12-3CB5C3A12-2A-8A13-2A2-6A14-3(2A22-)CA72-2E5-2E15-2D5-2D2(15-2A5-2A)15-2D5-2A15-2A2-2A-2A16-8A15-10A13-11B2(A12-11F)A11-12D2B10-12B2A11-12A11-12CA11-13A11-12A12-11A13-2A4-2A16-2(2A22-)CB48-2E5-2E15-2D5-2D2(15-2A5-2A)15-2B2-2B-2B15-9A15-10A13-12A11-14A10-12B2A10-S11P2A9-13E2AB8-13K3A9-12B2A10-12C2(2A10-12B)A11-12A12-11A13-2A4-2A16-2A22-CB48-2E5-2E15-2A5-2D2(15-2A5-2A)15-9B15-10A13-12A11-14A9-16A8-13B3A8-S12E3A8-13E2AB8-13O2(3A8-13B)3A8-J15A9-12C2A10-12CA11-11CA12-2L9A13-2C22-2C120-9A15-10A13-12A11-14A9-16A8-16A7-18A6-14B4A6-17DB6-14B4A2(6-18A)7-16A8-16A9-14A11-12A13-10A16-6B136-9A13-13A10-15A9-13B3A8-13B3A7-14B4A7(6-18A)7-16A8-16A9-14A11-12A14-8A114-4A17-10A11-14A9-12B4A7-17LA5-19HA2(4-16C4A)5-15B5A3(4-20A)5-2(18A6-)18A7-16A9-14A11-12A13-10A17-4A91-6A16-10A11-14A9-12D4A6-16N3A6-15C4A5-15M4A4-16J5A3-J4(20A4-)20A5-18A6-18A7-16A9-14A11-12A13-10A16-6A90-6A16-10A10-16A6-14G5A5-16F3A5-19HA4-16O4A4-16F5A3-16C5A4(4-20A)5-18A6-18A7-16A8-16A9-14A12-10A16-6A90-6A16-10A10-16A6-14G5A5-16I3A5-16J4A4-16G4A4-16F5A3-16G5A3(4-20A)3R-20A2-R2-18A3-R2-18A7-16A8-16A9-14A12-10A16-6A90-6A16-10A11-14A9-12D4A6-16I3A6-15K4A5-15E4A4-16I5A3-16G5A4(4-20A)5-18A6-18A7-16A9-14A11-12A13-10A16-6A91-4A17-10A11-14A9-12B4A7-15C3A5-16N4A4-19HA4-19LA5-15B5A3(4-20A)5-2(18A6-)18A7-16A9-14A11-12A13-10A17-4A113-9A13-13A10-15A9-13B3A8-15DA7-2(14B4A6-)5(18A6-)18A7-16A8-16A9-14A11-12A14-8A135-9A15-10A13-12A11-14A9-16A8-16A7-18A6-14B4A6-13B5A3(6-18A)7-16A8-16A9-14A11-12A13-10A16-6A136-2A5-JA15-9A15-10A13-12A11-14A9-2(16A8-)S11M4A8-12E4A8-12C4A8-16A2(8-12B4A)9-14D10-13D11-11CA12-2C-8A13-2C22-2K48-2E5-2E15-2B5-2B15-2A5-2A15-2A5-2D15-2B2-2B-2B15-9A15-10A13-12A11-14A10-11B3A10-S10E3A9-12E4A8-12M4A9-2(14A10-)13DA10-11B2A11-11BA12-11A13-2A4-2A16-2A22-A23-C25-2E5-2E15-2R5-2R15-2A5-2A15-2A5-2B15-2B5-2B15-2A2-2A-2A16-8A15-10A13-10B2A12-10F2A12-10J2A11-11K3A10-11B3A11-12A11-11C2A11-13A11-12A12-11A13-2A4-2A16-2(2A22-)2A48-2E5-2E15-2B2(5-2B15-2A5-2A15-2A)5-2A41-6A17-8B15-10Q2(14-9BA)14-10A14-9BA12-2C3B4C2BA12-11A13-3A-6A14-4A20-3(2A22-)CD42-
