model
size = 14 12 20, scale = 0.05, origin = -y
material 
  colors = A:#9F6 B:#FF3 C:#111 D:#EEE E:#0FF F:#39C G:#C6F H:#F90 I:#C0C J:#100
voxels
74-J181-C2(167-I)125-3(I13-)I81-2(F3-F2(9-E3-E)9-E3GE4(9-5A)65-)F3-F37-6(4(5A9-)5A107-)4(5A9-)5A20-2(C13-)C16-F3-F2(9-E3-E)9-E3GE4(9-5A)6-C55-C2-F3-F2(9-E3-E)9-E3GE4(9-5A)6-C2-2C-2C6-C2-12C3-3C21-C2-F3-F21-5(9B5-)9B4-C2(9B5-)9B18-C45-3B10-5B8-2(7B7-)7B8-5B6-C3-3B7-C13-C72-3(5D9-)5D8-2D3-2D7-2D3-2D93-3H11-3H25-J-J23-J5-J34-
