model
size = 16 31 31, scale = 0.05, origin = -y
material 
  colors = A:#222 B:#FF3 C:#F90 D:#F93
voxels
295-5A2(10-6A)11-4A430-4A6(9-7A)9-6A380-6A7(7-9A)7-8A9-7A345-7A8-9A7-5(10A6-)2(9A7-)8A9-7A328-4A-3A8-9A6-3(11A5-)11A3(6-10A)6-9A7-8A10-5A40-7A10-6A10-5A11-2(6A10-)6A2(11-5A)12-4A75-7A8-3(9A7-)9A6-11A2(4-12A)5-5A-5A3-7A-5A3-13A3(5-11A)6-9A8-7A37-11A6-10A6-9A7-2(10A6-)10A2(7-9A)7-2(10A6-)10A5-11A2(3-13A)2-14A2-3(15A-)48A-7A2(2-6A)3-5A3-6A-6A2-14A4-11A5-11A6-9A8-7A11-3A23-12A4-2(12A3-)14A2-14A2(3-13A)2(4-12A)4-13A2(2-14A)3(-15A)-104A2-14A3-5A2-6A3-5A2-7A-6A2-14A4-11A5-10A8-8A9-5A21-13A3-13A2-14A2-2(15A-)14A3(2-B13A)2-2(B14A-)B15AB14A-8(B15A)B7A3-5AB7A4-4A-B6A3-5A2-B6A-6A2-14A2-13A5-10A7-9A9-6A20-6A-7A2-6A-15A-23A2(-15A)-B14A3(-15A)-89A-14A2-14A3-2(12A4-)11A6-2(11A5-)12A3-5A2-B5A3-5A2-7A-6A2-13A5-11A6-9A8-7A10-5A4-6A4-5A-6A3(3-13A)3-6A-6A3-6A-B5A2(3-13A)3-14A2(3-13A)2(4-12A)4-11A4(6-10A)6-9A7-9A8-9A7-9A6-11A5-4A-B6A3-5A2-7A-6A2-13A4-12A5-10A12-3A14-2A3-5A5-5A-5A2(5-11A)2(5-5A-5A)5-6AB4A2(5-11A)5-6AC4A5-6A3(D4A6-5A)D2(4A7-4AC)4A7-4AD2(4A7-4AC)2(3A9-3AC)4A8-3AC4A8-9A6-11A5-4A-B6A3-5A2-7A-6A2-13A4-12A5-10A13-3A14-A3-5A6-4A-5A2(5-11A)2(5-5A-5A)6-5AB4A2(6-10A)6-5AC4A6-5AD2(3A7-5AC)3A7-5A5(D3A8-4A)C3A9-3AD2(3A9-3AC)4A8-9A6-10A6-4A-B5A4-5A2-7A2-5A2-13A4-12A5-10A13-3A14-A3-4A3(7-9A)2(7-4A-4A)7-5AB3A7-9A2(8-4AD3A)8-8A8-5AD2A8-5AC2(2A8-5AD)2A8-4AC3A8-4AD2A9-5AD2(A10-4AC)2A9-4AD2A9-3AD4A7-4AD4A7-10A6-4A-B5A4-5A2-6A3-5A2-7A-5A4-12A5-3A3-4A13-3A14-A3-4A3(7-9A)2(7-4A-4A)7-5AB3A7-9A8-8A8-4AD3A8-8A4(9-7A)9-3AC3A9-3AD2A2(10-6A)10-2(7A9-)3AC4A7-9A7-10A6-4A-B4A5-5A2-6A3-5A2-6A2-5A4-5A2-5A5-3A3-4A13-3A14-A3-4A2(7-9A)6-10A2(6-5A-4A)6-6AB3A7-9A8-4AC3A8-4AD3A8-7A4(10-6A)10-3AD2(2A10-3AC)2A10-6A10-7A9-3AC3A9-3AC4A7-4AD4A7-10A6-4A-B4A5-5A2-6A3-5A2-6A2-5A4-5A2-5A5-3A3-4A13-3A14-A3-4A2(7-9A)2(6-10A)6-5A-4A6-6AB3A6-10A7-9A8-4AD3A8-4AC2A3(10-6A)5(10-3AC2A)10-2(3AD3A9-)3AC4A7-9A7-10A6-4A-B5A4-5A2-6A3-5A2-7A-5A4-12A5-3A3-4A13-3A14-A3-5A2(6-10A)2(5-11A)5-5A-5A5-6AB4A5-11A6-10A7-4AD4A7-2(4AD3A8-4AC3A8-)4AC3A9-3AC3A9-7A9-3AC2(3A9-3AD)3A9-3AC3A9-8A8-9A6-10A6-4A-B5A4-5A2-6A3-5A2-13A4-12A5-10A13-3A14-A3-5A6-10A3(5-11A)5-5A-5A5-5A-B5A3(4-12A)4-6AC4A5-6AC4A6-5AC3A7-5AD4A7-4AD4A3(7-9A)8-2(7A9-)2(8A8-)9A6-11A5-4A-B6A3-5A2-7A-6A2-13A4-12A5-10A13-3A14-A3-6A2(4-12A)2(3-13A)3-6A-6A3-6A-B6A4(2-14A)2-13A4-12A3(5-11A)2(6-10A)6-2(9A7-)9A8-9A7-9A6-11A5-4A-B6A3-5A2-7A-6A2-13A4-12A5-10A12-3A14-2A3-5A-A2-12A-A-13A-A-7A-5A-A-13A-25A-B14A-137A-14A2-14A3-12A4-13A4-12A4-2(14A2-)12A3-5A-B6A3-5A2-7A-6A2-13A4-12A5-10A7-8A10-5A5-6A-15A3(-7A)-15A-16A-14A2-3(B14A-)B14A5(B15A)B8A-6AB7A2-6AB7A3-5AB6A4-2(5AB7A3-)2(5AB9A-)5A-B6A3-5A2-B5A3-5A2-7A-6A3-11A6-10A7-9A8-7A10-5A6-13A5(2-14A)4(3-13A)2(2-14A)-15A-136A3-5A-7A4-4A-7A3-5A2-7A-6A3-13A3-12A5-10A7-9A9-6A22-12A3-13A3-11A5-3(13A3-)13A4(4-12A)3-13A4-12A2(3-13A)3-14A5(-15A)-7A2-6A-7A3-5A2-6A3-5A2-7A-6A3-13A4-11A5-10A8-8A9-5A23-2(10A6-)9A7-2(10A6-)10A2(7-9A)7-2(11A5-)11A6-10A3(5-11A)2(4-12A)3-13A4-13A2(2-14A)3(2-6A)3-5A3-6A-6A3-13A4-11A5-11A6-9A8-7A11-3A25-7A10-6A10-5A11-2(6A10-)6A2(11-5A)12-4A75-7A8-3(10A6-)10A5-11A2(4-12A)2(4-6A-5A)4-12A3(5-11A)6-9A8-7A312-4A-3A8-9A6-3(11A5-)11A3(6-10A)6-9A7-8A10-5A314-7A8-9A7-5(10A6-)2(9A7-)8A9-7A331-6A7(7-9A)7-8A9-7A348-4A6(9-7A)9-6A395-5A2(10-6A)11-4A149-
