model
size = 30 31 23, scale = 0.05, origin = -y
material 
  colors = A:#2A4A5B B:#E3E3E3 C:#959595 D:#46647C E:#5E5E5E F:#BBB
voxels
571-2A24-2A2-2A24-2A603-2A22-2A4(4-DA22-AD)4-2A22-2A63-2A24-2A2(2-DA24-AD)2-2A24-2A543-2A22-2A4-DA22-AD124-DA22-AD4-2A22-2A3-2A24-2A2-DA24-AD62-DA24-AD2-2A24-2A484-3(A22-A5-DA22-AD184-DA22-AD3-DA24-AD122-DA24-AD-3A24-6A24-3A423-)A22-A5-DA22-AD184-DA22-AD3-DA24-AD122-DA24-AD-3A24-6A24-3A393-A22-A6-A22-A5-2A22-2A4-DA22-AD124-DA22-AD4-2A22-2A3-2A24-2A2-DA24-AD62-DA24-AD2-2A24-2A-3A24-6A24-3A393-A22-A6-A22-A5-2(2A22-2A4-)4(DA22-AD4-)2A22-2A4-2A22-2A3-2(2A24-2A2-)2(DA24-AD2-)2A24-2A2-3(2A24-2A-3A24-6A24-3A393-A22-A6-A22-A5-7(2A22-2A4-)2A22-2A3-5(2A24-2A2-))4(2A24-2A-3A24-6A24-3A363-2(A22-A6-)A22-A5-7(2A22-2A4-)2A22-2A3-5(2A24-2A2-))2A24-2A-3A24-6A24-3A306-2A14-2A10-4A14-4A7-5A14-5A6-3A18-3A6-A22-A5-7(2A22-2A4-)2A22-2A3-5(2A24-2A2-)2A24-2A-4A22-8A22-4A2-2A22-2A6-4A14-4A10-2A14-2A194-2A10-2A14-2(4A10-)6A10-6A8-4A14-4A8-2A2F14-2E2A7-3A18-3A5-4A18-4A3(4-3A21-2A)3-3(3A22-3A2-)3A22-3A-4A22-7A3(24-6A)24-7A22-10A18-14A14-8A2-6A14-6A6-2(6A10-)4A10-4A14-2A10-2A110-A4-A22-3A4-3A18-5A4-5A16-4A6-4A16-2A10-2A16-2F10-2E16-2B10-2C12-2(2AFB14-CE2A8-)2(AF2B14-2CEA8-)AF2B14-2CEA5-4A21-3(3A2-3A22-)3A-4A22-7A3(F22-E6A)F22-E7A22-4A4-2A2F14-2E2A8-4A14-4A8-6A10-6A12-4A6-4A2(16-5A4-5A)18-3A4-3A22-A4-A26-2A26-6A22-10A20-4A2-4A20-2AF4-E2A20-2FB4-C2E20-3B4-3C20-3B4-A2C18-2B10-2C16-2B10-AC2(16-2B10-2C)16-2A10-2C12-AF2A14-C3A8-4A14-4A8-4A14-3AE8-2A2B14-A2CE8-4B14-3CE4(8-4B14-4C)8-2F2B14-2C2E12-2B10-2C16-2F10-2E16-2A10-2A18-2AF4-E2A20-4A2-4A2(20-10A)22-6A26-2A27-2(4A26-)AFEA26-FBCE26-2B2C26-2BAC26-2B2A23-3(3B4-3A20-)B2A4-A2C20-3A4-3C18-2A10-2C16-2A10-CA2(16-2B10-2A)16-2B10-AC2(16-2B10-2C)16-BA2(10-2C16-2B)10-2C18-2(3B4-3C20-)2FB4-C2E23-FBCE26-AFEA3(26-4A)266-2B2A26-2BCA26-B3A26-4A26-3AC23-3A4-3C20-A2B4-3C20-3B4-2CA2(20-3B4-3A)20-2BA4-2AC2(20-3A4-3C)20-3A4-2AC20-2BA4-A2C23-B3A2(26-2B2C)566-AB3(2C26-2B)CA26-B3A2(26-4A)26-2A2C2(26-4A)253-
