model
size = 13 5 6, scale = 0.05, origin = -y
material 
  colors = A:#444 B:#111
voxels
-6A-5A2-2(3A3-)A3BA-A3B2(A2-2(A4B))A53-4(A11-A52-)A11-A
