model
size = 19 18 24, scale = 0.05, origin = -y
material 
  colors = A:#0D0 B:#111 C:#0B0 D:#080 E:#444 F:#100
voxels
83-5B12-2A5-2A48-A7-A11-A5-A12-A-3A-A13-A3-A223-5A13-7A11-3(9A10-)9A11-7A13-5A166-5A12-9A10-2A5-2A9-2A7-2A4(8-A9-A)8-2A7-2A9-2A5-2A11-7A14-3A110-5A12-2A5-2A2(9-A)8-A9-A7-4(A11-A6-)A11-A7-A9-A8-2(A9-)A7-A11-3A-3A15-A73-5A12-2A5-2A2(9-A)7-A11-A6-A11-A5-3(A13-A4-)A13-A5-A11-A6-A11-A7-A9-A8-2(A9-)A7-A11-7A69-7A10-2(2A7-)A11-A6-A11-A5-5(A13-A4-)A13-A5-A11-A7-A9-A8-2(A9-)A8-A9-3A3-3A13-3A35-3A13-3A3-3A2(9-A)7-A11-A5-A13-A4-A13-A3-4(A15-A2-)2A13-2A4-A11-A6-A11-A7-A9-A8-2(A9-)A7-A11-7A32-5A12-2A5-3A7-2A10-A5-A13-A4-A13-A3-5(A15-A2-)A15-A3-A13-A5-A11-A6-A11-A7-A9-A8-2(A9-)9A30-7A10-2(2A7-)A11-A5-A13-A4-A13-A3-A15-A2-A15-A-B2(17-2B)17-B-A15-A3-A13-A4-A13-A5-A11-A6-A11-A7-2(A9-)9A30-7A10-2(2A7-)A11-A5-A13-A4-A13-A3-A15-A2-A15-A-B2(17-2B)17-B-A15-A3-2(A13-A4-)A13-A5-A11-A6-2A9-2A8-2A5-2A12-5D13-7A10-2(2A7-)A11-A5-A13-A4-A13-A3-A15-A2-A15-A-B17-2B17-B-A15-A2-A15-A3-3(A13-A4-)A13-A5-2A9-2A8-2A5-2A12-5D14-5A12-2A5-2A8-2A9-2A6-A11-A5-A13-A3-3(A15-A2-)A15-A3-5(A13-A4-)A13-A5-A11-A7-2CBA3-AB2A12-3D32-9A2(9-A)7-A11-A5-A13-A4-A13-A3-2(A15-A2-)A15-A3-5(A13-A4-)A13-A5-A11-A7-C3BA-A3BA13-D34-7A10-2(2A7-)A11-A6-A11-A5-A13-A4-A13-A3-A15-A3-6(A13-A4-)A13-A5-A11-A7-2CB2A-2AB2A13-D35-5A12-2A5-2A2(9-A)7-A11-A6-A11-A5-3(A13-A4-)A13-A5-5(A11-A6-)2A9-2A8-2CA3-3A13-3E53-6A11-2A6-2(A9-)A8-2(A9-A7-3(A11-A6-)A11-A7-)2A7-2A10-2C3-2C14-EFE71-7A11-A7-A10-A7-2(A9-)7(A8-A9-)A8-2A7-2A10-A5-A13-C3-C15-3E71-7A2(12-A5-A)11-7(A7-A10-)A7-A11-A5-A12-A5-A13-C3-C15-EFE74-B15-3A-3A6(12-A5-A)11-A7-A10-A7-A11-A5-A13-2(A3-A14-)C3-C15-3E73-3B14-2A3-2A3(12-A5-A)13-A3-A13-2(A5-A12-)2A3-2A12-2A3-2A13-2(A3-A14-)5A15-3A92-3B14-2A3-2A3(12-A5-A)13-2(A3-A14-)2A2-A15-3(3A16-)3A131-B15-3A-3A3(12-A5-A)13-A3-A14-2A2-A16-2A206-3B14-2A3-2A12-A5-A11-A7-A10-2A5-2A12-A3-A14-5A224-3B13-3A3-3A10-A7-A29-A7-A11-A5-A13-5A159-
