model
size = 20 24 26, scale = 0.05, origin = -y
material 
  colors = A:#050 B:#222 C:#111 D:#040 E:#960 F:#777 G:#888 H:#444 I:#630 J:#E00 K:#EEE L:#FF0
voxels
129-2A17-4A15-2A2D2A5(14-A-2D-A)15-4A248-6C2(8-12C)2-4A2-12C-2A2D2A-6C7-3(A-2D-A14-)AJ2DJA14-2A2D2A16-2A269-6C8-6C-2(5B8-5B2-)5B2-4A2(2-5B)-6A-5B-6C-6A-6C7-2(6A14-)AJ2AJA14-6A15-4A248-6C8-6C-B3CB8-B3CB2(2-5B8-5B)2-5B-C4AC-5B2-5B-6A-5B2-B3CB-6A-B3CB-6C-6A-6C7-E4AE2(14-6E)15-4E16-4E208-6C8-6C-5B8-5B2-5B8-5B3-H3B8-3BH3-5B8-5B2-5B-6A-5B3-H3B-6A-3BH3-5B-6A-5B2-2(5B-6A-5B-6C-6E-6C7-E4-E14-E4-E247-6C8-6C-2(5B8-5B2-)5B8-5B-2G4B8F5B3G4BF6AF5BG-2(5B-6A-5B2-))5B-6A-5B-6C-6E-6C7-E4-E14-E4-E247-6C8-6C-5B8-5B2-5B8-5B3-H3B8-3BH3-5B8-5B2-5B-6A-5B3-H3B-6A-3BH3-5B-6A-5B2-5B8-5B-6C8-6C300-6C8-6C-5B8-B3CB2(2-5B8-5B)2(2-5B-6A-5B)2-5B-6A-B3CB-6C8-6C49-2I17-I2-I16-I2-I17-2I229-6C8-6C-2(5B8-5B2-)5B-6A-5B2-5B-6A-5B-6C-6A-6C7-B-2H-3(B14-B4-)B36-2C269-6C2(8-12C)3-2A3-12C2-4A2-6C7-4(6A14-)B-2C-B14-B-2C-B355-4A15-5(6A14-)B4AB15-B2KB337-7(2A16-3(D4AD15-4A15-)6A15-A2DA317-)2A16-3(D4AD15-4A15-)6A15-A2DA178-B53-3(2C8-)2C53-2A16-3(D4AD15-4A15-)6A15-A2DA158-B53-2C8-2C9-B8-B10-B8-B9-2C8-2C13-2A17-3(4A15-D4AD15-)4A15-6A15-A2DA18-6(B19-)B53-2C8-2C9-B8-B2(10-G8-G)10-B8-B9-2C2-4A2-2C12-4A15-6(6A14-)6A15-A2DA192-2C8-2C9-B8-B10-GF6-FG10-G2F4-2FG10-B-6F-B9-2C-6F-2C11-6A14-3(6A15-4A15-)6A15-A2DA212-2C8-2C9-B8-B10-B8-B9-2C3-2F3-2C12-4A15-6A14-6A15-4A15-6A13-D6AD11-2D6A2D11-8A13-6A15-A2DA232-3(2C8-)2C32-C2AC16-4A2(15-2A2D2A15-A2DA)14-L2A2D2AL14-A2DA15-6A15-A2DA188-
