model
size = 12 23 11, scale = 0.05, origin = -y
material 
  colors = A:#C6C B:#111 C:#E00 D:#90C E:#0C0 F:#06F G:#C3F H:#888
voxels
11(11A-)2(2A10-)2A6-C3-2A5-3C2-2A6-C3-7(2A10-)2(11A-)2(11AH)11A-2(10A2-)4(11A-)2(AB6-B3-)AB5-CBC2(2-AB5-3C)2-AB2(10-AG)10-AB10-AG2(10-2A)10-2(11A-)11AH10A2-7(11A-)2(AB10-)AB6-C3-AB5-3C2-AB6-C3-2(AB10-AD10-)AB2(10-2A)10-2(11A-)2(11AH)11A-2(11AC)4(11A-)AB5-3F2-6(AB10-)AD10-AB10-AD2(10-2A)10-11(11A-)AB5-3F2-AB6-F3-4(AB10-)4(AD10-)2(2A10-)11(11A-)AB5-3F2-5(AB10-)2(AG10-)2(AB10-)2(2A10-)11(11A-)6(AB10-)AG3(10-AB)2(10-2A)10-11(11A-)AB5-3E2-5(AB10-)2(AG10-)2(AD10-)2(2A10-)11(11A-)AB5-3E2-AB6-E3-4(AB10-)2(AD10-)2(AB10-)2(2A10-)11(11A-)AB5-3E2-7(AB10-)2(AD10-)2(2A10-)11(11A-)12(2A10-)
