model
size = 14 14 7, scale = 0.05, origin = -y
material 
  colors = A:#EEE B:#100 C:#F0C
voxels
25-3A10-2A9-5A9-4A11-2A164-6A7-6A8-5A-2A7-3A-2A9-4A11-3A11-2A30-2A11-3A11-2A20-2A9-6A10-6A8-7A7-7A2(8-6A)9-6A9-5A11-4A9-2AB2A9-5A30-3A-3A6-4AC4A5-2A-7A4-2A2(2-7A4-A)3-6A4-2A2-7A4-A3-6A4-A4-5A3-2A6-4A2-A6-5A-2A5-6A7-C2A24-3A8-7A9-6A8-7A7-7A2(8-6A)9-6A9-5A11-4A9-2AB2A9-5A47-2(5A9-)5A10-5A9-6A9-5A10-4A12-2A30-A2(12-2A)6-4A9-3A10-4A10-5A10-4A11-2A29-2A-2A9-4A71-
