model
size = 25 31 21, scale = 0.05, origin = -y
material 
  colors = A:#F66 B:#003 C:#00C
voxels
433-2(4A3CA17-)4AC3A17-2ACAC3A17-3A2C3A17-8A17-3A3-2A17-2AB3-BA443-4AC2A18-2ACAC2A18-3A2C2A18-A2(C2A)18-2A3C2A18-7A16-6(11A14-)4A3B4A14-2A2B3-2B2A267-4(5A20-)2(3A2C20-)3A2C17-2AB5-B2(2A14-CA7-2A14-2A7-)2A14-CA7-2A14-5(A10-A13-)AB9-A13-3A5-4A12-4A5-4A12-3AB5-B4A11-3AB5-B4A115-2(5B20-)5A20-5A18-4(2A5-2A16-)CA5-CA16-2A5-CA16-CA5-CA14-AB9-BA12-C11-C12-A11-A12-C11-C12-B11-A12-C11-A11-6(2A12-A10-)3(5A5-5A10-)5A5-5A9-5AB5-B5A87-2(2B5-2B16-)2A5-2A16-2A5-2A14-4(2A9-2A12-)2C9-2A12-2A9-2A12-2C9-2A11-2(A13-A10-C13-C10-)A13-A10-C13-C8-10(2A15-A7-)2A15-AB6-6AB5-B5AB60-2(B9-B14-)A9-A14-A9-A13-4(A11-A12-)C11-C12-A11-A12-C11-C10-AB13-2A8-C15-C8-A15-B8-B15-C8-A15-A8-C15-C7-5(A17-A6-)6(B17-B6-)B5AB5-B5AB59-2(B11-B12-)A11-A12-2(A11-)4(A13-A10-)C13-C10-A13-A10-C13-C9-A15-B2(8-C15-C8-A15-A)8-C15-C7-4(A17-A6-)B17-B179-3B5AB5-B6A2B32-2(B11-B12-)A11-A12-2(A11-)4(A13-A10-)C13-C10-A13-A10-C13-C8-AB15-BA6-C17-C6-A17-A6-C17-C6-B17-A6-C17-C5-4(A19-A4-)B19-B178-B5A2B7-2B5AB31-2(B13-B10-)A13-A10-A13-A9-4(A15-A8-)C15-C8-A15-A8-C15-C7-A17-B2(6-C17-C6-A17-A)6-C17-C5-3(A19-A4-)B19-B227-2B5AB9-B6AB5-2(B13-B10-)A13-A10-A13-A9-4(A15-A8-)C15-C8-A15-A8-C15-C7-A17-A6-C17-C6-A17-A6-B17-C6-A17-A6-C17-C5-2(A19-A4-)B19-B252-B5AB11-B5AB5-2(B13-B10-)A13-A10-A13-A9-4(A15-A8-)C15-C8-A15-A8-C15-C7-A17-A6-C17-C6-A17-B6-C17-C6-A17-A6-C17-C5-A19-A4-B19-B277-B5AB11-B5AB5-2(B13-B10-)A13-A10-A13-A9-4(A15-A8-)C15-C8-A15-A8-C15-C7-A17-A6-B2(17-C6-A17-A6-C)17-C5-2(A19-A4-)B19-B252-B5AB11-B5AB5-2(B13-B10-)A13-A10-A13-A9-4(A15-A8-)C15-C8-A15-A8-C15-C7-A17-B2(6-C17-C6-A17-A)6-C17-C5-3(A19-A4-)B19-B227-2B5AB9-B6AB6-2(B11-B12-)A11-A12-2(A11-)4(A13-A10-)C13-C10-A13-A10-C13-C8-2B15-B2(A6-C17-C6-A17-)B6-C17-C5-4(A19-A4-)B19-B178-B6AB7-2B5AB32-2(B11-B12-)A11-A12-2(A11-)4(A13-A10-)C13-C10-A13-A10-C13-C9-2(A15-A8-C15-C8-)A15-A8-C15-C7-4(A17-A6-)B17-A7(24-B)4-2B6AB5-B5A3B33-2(B9-B14-)A9-A14-A9-A13-4(A11-A12-)C11-C12-A11-A12-C11-C10-AB13-AB8-B2(15-C8-A15-B8-C)15-C7-4(A17-A6-)B17-A24-A4(18-7A)18-6A6-B6AB5-B5A62-2(2B5-2B16-)2A5-2A16-2A5-2A14-4(2A9-2A12-)2C9-2C12-2A9-2A12-2C9-2C11-2(A13-A10-C13-C10-)A13-A10-C13-C8-2A15-4(A7-A16-)A7-B16-5(A7-BA10-A4-)A6-2B5AB5-B5A64-2(5B20-)5A20-5A18-4(2A5-2A16-)CA5-2A16-2A5-2A16-2C5-AC14-AB9-2B12-B2(11-C12-A11-A12-C)11-C10-2A13-5(A9-A14-)3(A9-6A5-A3-)A9-6A5-A2-2A10-4AB5-B4A190-2(3C2A20-)3(2AC2A20-)2ACAC20-2A2CA17-2AB5-B2A14-2C7-AC14-2A7-AB14-BA7-2A14-2A7-2A14-CA7-2A12-2A2(11-A)4(12-A11-A)12-A2(11-5A5-4A)11-4AB5-B3A11-4AB5-B2A391-3(7A18-)AC5A18-2AC4A18-3AC3A15-3A7-4(2A13-2A8-)2A2(13-4A5-3A)13-3AB5-B2A590-4A2C3A16-A2C2A2CAC16-A2(2C2A)16-AC3AC2AC16-2A3C4A16-9A16-3A3B3A16-2AB3-B2A158-
