model
size = 30 14 12, scale = 0.05, origin = -y
material 
  colors = A:#222 B:#EEE C:#2D2D2D D:#7C1F16 E:#C7802D F:#E2943B G:#252525 H:#777
voxels
34-21B8-23B7-23B8-19A12-2C9-4A112-H2(29-B)81-21B8-23B7-23B8-19A12-2C9-4A112-H2(29-B)109-3B9(EF)E3B5-2B21D3B4-26B5-22A8-6C4-8A12-2A2G-GC7-3G13-3A3-GC23-GA4-G2C29-C59-B29-B79-B11(FE)F3B2-2B24D2B2-2B25AB3-26A4-C6A5C7A4C7-5AD4AG5C2ACG10-4ADBD8AC14-GC2ADBD6AC16-4C3B4AC19-3CDBDG3A22-5CGA27-2CAB27-2A49-2B12(EF)EB-2BD25CB-2BA25-B2-2A24-A3-CA21-A2C4-2A17-2A2C7-2A15-2AB10-C14-2AB12-G9-5AB24-4A26-3AB26-3A27-2A47-2BEFBFEBE3BEBE2BFBF2B2(EB)EF3BD4CD2C2(DC)2(3DC)D2C3DC3BA26-2B2A25-2A-2C22-3AC2-2A18-4AC5-GA16-3AB9-C14-3AB11-C9-6AB13-G9-4AB25-4A26-3AB26-3A27-2A17-BE3(FB)F2BEFBF2BEBE2BF3BFEF2BD2(C2D)CD3C2(2D2C)D2C2(DC)D2BA26-2BDA25-2A-2C22-3AC2-2A18-4AC5-2A16-3AB8-GA14-3AB11-C9-6AB13-C9-4AB25-4A26-3AB26-3A27-2A17-BF4(EB)EFE2BFBF2B3(EB)EFE2B2(DC2DC)2(D3C)DCD2C3DCD2BA26-2BDA25-2A-2C22-3AC2-2A18-4AC5-2A16-3AB8-GA14-3AB11-C9-6AB13-C9-4AB25-4A26-3AB26-3A27-2A17-2B3(FB)F3BF2BEBE2BFBFEBEFE3BD4CD2C2(DC)2(3DC)2D2(CD)C3BA26-2B2A25-2A-2C22-3AC2-2A18-4AC5-GA16-3AB9-C14-3AB11-C9-6AB13-G9-4AB25-4A26-3AB26-3A27-2A18-2B12(FE)FB-2BD25CB-2BA25-B2-2A24-A3-CA21-A2C4-2A17-2A2C7-2A15-2CB10-C14-2AB12-G9-5AB24-4A26-3AB26-3A27-2A49-B11(EF)E3B2-2B24D2B2-2B25AB3-26A4-C6A4C8A4C7-5AD4AG4C3ACG10-4ADBD8AC14-GC2ADBD6AC16-4C3B4AC19-3CDBDG2A23-5CGA27-2CAB27-2A50-3B9(FE)F3B5-2B21D3B4-26B5-22A8-6C4-8A12-2A2G-GC7-3G13-3A3-GC23-GA4-G2C29-C59-B29-B77-
