model
size = 30 32 21, scale = 0.05, origin = -y
material 
  colors = A:#002 B:#900 C:#005 D:#FF9
voxels
5-5(20A10-)7AD5AD6A10-5A3D2AD2A3D3AB10-4A4D5A4D2AB10-5A3D2(AD)A3D3A2(B10-B6A2(D5A))B10-B7A5D6AB10-B9AD9A10-B19A10-20A10-2AD5AD2A3DA4DA10-2AD5AD2ADAD4ADA10-2AD5AD2A3D4ADA10-6A3D9ADA10-2AD5AD9ADA10-4A5D9ADA2(10-20A)9-B8A4B8A9-B7AB4-B7A10-6AB6-B6A10-B178-4(A20-2A7-)10(A20-AB7-)8(A20-2A7-)A20-2A6-B2(A20-AB7-)B20-AB7-BA6B6-9B156-7(A21-2A6-)9(B21-2A6-)6(A21-2A6-)2(A21-AB6-)2(B21-AB6-)B21-A7-B7AB6-B7AB126-5(A22-A6-)8(A22-B6-)8(A22-A6-)A22-B6-A29-B148-B8AB6-B8AB95-A22-A6-B6(22-A6-A)6(22-A6-B)6(22-A6-A)22-A6-B22-B6-A29-B207-11B6-11B64-A22-A6-B22-A6-A22-A5-3(CA22-AC4-)6(CA22-AB4-)8(CA22-AC4-)BA22-B6-A29-B207-B9AB6-B9AB64-A22-A6-B22-B6-A22-A5-B5(A22-AC4-C)4(A22-AC4-B)5(A22-AC4-C)A22-AC4-BA22-AB4-CA22-AC4-BA22-B6-A29-B236-B10AB6-B10AB33-A22-A6-B22-B6-A22-A5-BA22-AB4-CA22-AC4-B2(A22-AC4-C)4(A22-AB4-C)4(A22-AC4-C)2(A22-AC4-BA22-AB4-C)A22-AC4-BA22-B6-A29-B236-B10AB6-B10AB33-A22-A6-B22-B6-A22-A5-BA22-AB2(4-CA22-AC4-BA22-AC)6(4-CA22-AC)3(4-BA22-AB4-CA22-AC)4-BA22-B6-A29-B266-12B6-12B3-A22-A6-B22-B6-A22-A5-2(BA22-AB4-CA22-AC4-)B2(A22-AC4-C)2(A22-AC4-B)A22-AC4-C4(A22-AB4-CA22-AC4-B)A22-B6-A29-B266-B10AB6-B10AB3-A22-A6-B22-B6-A22-A5-2(BA22-AB4-CA22-AC4-)BA22-AC2(4-CA22-AB)2(4-BA22-AC)4-C4(A22-AB4-CA22-AC4-B)A22-B6-A29-B266-B10AB6-B10AB3-A22-A6-B22-B6-A22-A5-2(BA22-AB4-CA22-AC4-)BA22-AC2(4-CA22-AB)2(4-CA22-AC)4-C4(A22-AB4-CA22-AC4-B)A22-B6-A29-B266-B10AB6-B10AB3-A22-A6-B22-B6-A22-A5-2(BA22-AB4-CA22-AC4-)5(CA22-AC4-)2(CA22-AB4-CA22-AC4-)2(BA22-AB4-CA22-AC4-)BA22-B6-A29-B266-12B6-12B3-A22-A6-B22-B6-A22-A5-BA22-AB5(4-CA22-AC)4(4-BA22-AC)2(4-CA22-AC4-CA22-AB)4-CA22-AC4-BA22-AB4-CA22-AC4-BA22-B6-A29-B237-B9AB6-B8ACB34-A22-A6-B22-B6-A22-A5-CA22-AB3(4-CA22-AC)4(4-CA22-AB)5(4-CA22-AC)2(4-CA22-AB4-CA22-AC)4-BA22-B6-A29-B237-B9AB6-B8ACB34-A22-A6-B22-B6-A22-A5-5(CA22-AC4-)6(BA22-AC4-)4(CA22-AC4-)CA22-AB4-CA22-AC4-BA22-B6-A29-B208-B8AB6-B8AB65-A22-A6-C5(22-A6-A)6(22-B6-A)8(22-A6-A)22-B6-A29-B208-B8AB6-B8AB65-7(A22-A6-)9(B22-A6-)4(A22-A6-)2(A22-B6-)B179-9B6-9B97-5(A20-A8-)8(A20-B8-)10(A20-A8-)B20-A29-B68-B6AB6-B6AB128-23(A20-A8-)B20-A29-B39-7B6-7B160-20A3(10-14AD5A)10-20A10-2A2DA2D2(3AD)5A10-2A2DA2D3AD8AB10-3ADAD4A2D5ABAB10-3A3D4AD4A2(BA)B10-10A3D2A2(BA)B10-17ABAB10-7A3D9AB10-7ADAD5A3B2A10-7A3D10A10-16A2B2A10-10A2DA2D5A10-3A4D3A2DA2D2A2BA10-3AD7ADAD6A10-3AD7A3D2A2B2A10-3AD16A10-3AD11A4BA10-3AD4A4B8A10-7AB4-BA6B10-6AB6-B6A10-BA3BAB6-BA3B2A10-B5AB6-B5AB185-
