model
size = 27 4 27, scale = 0.05, origin = -y
material 
  colors = A:#EEE B:#F93 C:#F60 D:#B00 E:#E00 F:#900 G:#FF0 H:#CF0 I:#500 J:#D00
voxels
10-7A20-7A71-13A14-4A5-4A67-15A12-2A11-2A64-19A8-3A13-3A61-21A6-2A17-2A60-21A6-A3-D3ED3-3ED4-A10-5D3-4D17-2H5-2H11-23A4-2A3-D3ED3-3ED4-2A9-2DH-D3-D-HD17-H7-H10-25A2-2A4-D3ED3-3ED5-2A8-5D3-3JD36-25A2-A23-A56-25A2-A23-A55-29A2(2-8C)3-2A54-28A3-C6BC2-C6BC4-A17-2A35-28A3-C6BC2-C6BC4-A7-2A7-4A34-2(28A3-C6BC2-C6BC4-A5-5A6-5A13-2(2G8-))28A3-C6BC2-C6BC4-A6-3A8-3A34-29A2(2-C6BC)3-2A7-A47-25A2-A2(2-8C)3-A56-25A2-A23-A56-25A2-2A21-2A57-23A4-2A4-F14-2A59-21A6-A4-2FI5FI6-A60-8AI-11A6-2A4-2FIFI4F5-A61-19A8-3A10-F2-3A64-15A12-2A11-2A67-13A14-4A5-4A71-7A20-7A64-
