model
size = 21 23 21, scale = 0.05, origin = -y
material 
  colors = A:#933 B:#693400 C:#963 D:#040 E:#036 F:#06F G:#3D2300 H:#050 I:#070 J:#633 K:#009 L:#EEE M:#9CF N:#F96 O:#960 P:#E00 Q:#251300 R:#111 S:#66C
voxels
238-2(7B14-)7B245-8(7B14-)7B12-5BA5B2(10-11B)202-5B16-5B13-8(11B10-)11B9-3B7E2(3B8-3B7-)3B199-9B12-9B10-8(5B5A3B8-)3B6AK3B7-3B7E-E2(3B6-3B9-)3B55-D19-3D17-5D16-DHIHD75-13B8-9BA3B7-8(2B11A2B6-)2B4AK6A2B5-3BE3F-6E2(3B4-3B11-)3B115-5D16-DHIHD54-13B8-9BA3B6-2B12A7(3B4-B13A)3B4-B9AK3A3B3-2BAEFL3CFL-F3E2(3B2-3B13-)3B135-5D16-DHIHD32-15B6-10BA4B5-8(B13A3B4-)BAK11A3B3-BAE-L8C2F2E2(2B2-2B15-)2B156-5D17-DID12-15B6-B10A4B4-8(2B14A3B2-)2B14A3B-2B2E2F9CLF2E4B5-7C5-4B8-N8-2B10-R104-Q41-H19-DHD11-17B4-2B9A6B3-7(2B16AB2-)B17AB2-B4AG9AK2AB-2BEFL10CF-FE4B5-7C5-4B6-4CO6-2B9-NSN18-NPN18-3P19-N62-G15-2D3-H3-2D28-17B4-2B5A2B2A6B3-5(B2(7A2B)2-)3(B8AB7A2B2-)B8AB4AJ2A2B-2B2F6CB5C2FE4B5-O2CD3C5-4B6-2CH2C6-2B10-4(G20-)G14-D5-G5-D8-2D4-G4-2D9-HD7-DH11-2D5-2D8-8B-8B4-2B5AB-BA6B3-8(B7AB-B6A2B2-)BAK5AB-B3AG2AKB-2BF-5CJBA4CFE-4B5-2CDMD2C5-4B6-CHMHC6-2B9-3(GMG18-)GMG13-D4-GMG4-D8-D2-Q-GIG-Q2-D8-ID2-2G-2G2-DI9-ID2H3-2HDI11-IH5-HI8-17B4-2B5A2B2A6B3-5(B2(7A2B)2-)3(B8AB7A2B2-)B4AGJ2AB7A2B-2B2F6CB5CL2E4B5-3CD2CO5-4B6-2CH2C6-2B10-4(G20-)G14-D5-G5-D8-2D4-G4-2D9-HD7-DH11-2D5-2D8-17B4-2B5A2B2A6B3-5(B2(7A2B)2-)3(B16A2B2-)B4A2J10A2B-2BE2F10C2F2E4B5-7C5-4B6-5C6-2B136-G15-2D3-H3-2D29-15B6-B9A5B4-2B15A7(2B2-B16A)2B2-B4A2J8AKA2B-2B3EF9CL-2E4B5-O6C5-4B17-2B115-Q41-H19-DHD12-15B6-B9A5B5-8(B14A2B4-)BAKA2J9A2B3-2BE-F9CF2E2(2B2-2B15-)2B156-5D17-DID13-13B8-B8A4B6-2B10A5B7(4-B13A3B)4-B5AG7A3B3-2BAE2FL2COL2C2FE2(3B2-3B13-)3B135-5D16-DHIHD33-13B8-2B7A4B7-B10A4B7(6-B12A2B)6-B8AK3A2B5-B2A2E5F-2FE2(3B4-3B11-)3B115-5D16-D3ID56-9B12-2B5A2B10-2B8A3B7(8-B11AB)8-B4AK3J3AB7-2BA3E-5EJ2B2(6-3B9-3B)55-D19-3D17-5D16-DHIHD79-5B16-5B13-3B5A3B8(10-2B7A2B)9-BAB7E2(3B8-3B7-)3B242-8(7B14-)7B12-2B7A2B2(10-11B)432-2(7B14-)7B196-
