model
size = 23 28 29, scale = 0.05, origin = -y
material 
  colors = A:#933 B:#630 C:#400 D:#040 E:#050 F:#070 G:#200 H:#633 I:#9CF
voxels
402-D21-3D19-3(5D18-DEFED639-)5D19-DFD363-2(7B16-)7B225-DED156-8(7B16-)7B14-5BA5B2(12-11B)224-E112-5B18-5B15-8(11B12-)11B11-3B7C2(3B10-3B7-)3B223-E22-E87-9B14-9B12-8(5B5A3B10-)3B6AG3B9-3B7C-C2(3B8-3B9-)3B245-E22-E62-13B10-9BA3B9-8(2B11A2B8-)2B4AG6A2B7-3B4C-6C2(3B6-3B11-)3B267-E62-13B10-9BA3B8-2B12A7(3B6-B13A)3B6-B9AG3A3B5-2BA8C-4C2(3B4-3B13-)3B266-E61-15B8-10BA4B7-8(B13A3B6-)BAG11A3B5-BAC-13C2(2B4-2B15-)2B266-E61-15B8-B10A4B6-8(2B14A3B4-)2B14A3B3-2B17C2(2B2-2B17-)2B219-2(E22-)E60-17B6-2B9A6B5-7(2B16AB4-)B17AB4-B4AG9AG2AB3-2B4C-9C-2C2(2B2-2B17-)2B186-2D8-E22-E54-2D50-17B6-2B5A2B2A6B5-5(B2(7A2B)4-)3(B8AB7A2B4-)B8AB4AH2A2B3-2B8CB8C2(2B2-2B8-D8-)2B12-D5(22-E)11-D10-E11-2D9-E12-ED8-F13-2D18-D21-2D20-DE20-2D28-8B-8B6-2B5AB-BA6B5-8(B7AB-B6A2B4-)BAG5AB-B3AG2ACB3-2BC-5CHBA3C-2C-2(2B2-2B7-DAD7-)2B11-DID4(20-EIE)2(10-D9-EIE)10-FD8-EFE11-FD6-EF-FE8-D2-F3E2-2E3-2E7-D5-4E5-2E5-DF15-E4-DF16-5EF28-17B6-2B5A2B2A6B5-5(B2(7A2B)4-)3(B8AB7A2B4-)B4AGH2AB7A2B3-2B4C-3CB8C2(2B2-2B8-D8-)2B12-D5(22-E)11-D10-E11-2D9-E12-ED8-F13-2D18-D21-2D20-DE20-2D28-17B6-2B5A2B2A6B5-5(B2(7A2B)4-)3(B16A2B4-)B4A2H10A2B3-2B17C2(2B2-2B17-)2B186-2D8-E22-E54-2D51-15B8-B9A5B6-2B15A7(2B4-B16A)2B4-B4A2H8AGA2B3-2B14C-2C2(2B2-2B17-)2B219-2(E22-)E61-15B8-B9A5B7-8(B14A2B6-)BAGA2H9A2B5-2BC-13C2(2B4-2B15-)2B266-2(E22-)E16-13B10-B8A4B8-2B10A5B7(6-B13A3B)6-B5AG7A3B5-2BA4C-8C2(3B4-3B13-)3B312-E16-13B10-2B7A4B9-B10A4B7(8-B12A2B)8-B8AG3A2B7-B2A7C-3C2(3B6-3B11-)3B313-E18-9B14-2B5A2B12-2B8A3B7(10-B11AB)10-B4AG3H3AB9-2BA3C-5CH2B2(8-3B9-3B)291-E22-E20-5B18-5B15-3B5A3B8(12-2B7A2B)11-BAB7C2(3B10-3B7-)3B269-E22-E88-8(7B16-)7B14-2B7A2B2(12-11B)270-E318-2(7B16-)7B271-DED617-5D19-DFD594-5D18-DEFED593-5D18-D3FD549-D21-3D19-5D18-DEFED124-
