model
size = 13 22 14, scale = 0.05, origin = -y
material 
  colors = A:#630 B:#111 C:#F96 D:#888 E:#930
voxels
175-C344-B3(11-B273-B11-2B)6(11-B273-B)11-B-2(2A7-2A2-)5(2A7C2A2-)2(11A2-)11A6-3C9-5C8-2(CB)C3(8-5C)17-6B-51B-6B-AE7-2A2-2A7-EA3(2-2A7-2A)2-2A7-AE2-2A7-2A2-E10A2(2-11A)6-3C9-5C8-2(C-)C9-3C11-C46-5(2D5-)2D162-3C11-C12-C110-
