model
size = 6 32 12, scale = 0.05, origin = -y
material 
  colors = A:#3D1E00 B:#E87700 C:#A16031
voxels
61-18(4A2-)4A74-20(4A2-)4A62-4A-126A-4A56-4A-126A-4A3-2A51-4A-126A-4A3-2A10-6(2B4-)2B2(3-4A-126A-4A3-2A8(4-2B))3-4A-126A-4A3-2A10-6(2B4-)2B3-4A-126A-4A3-2A51-4A-121A4CA-A2CA3-2A51-4A-115A4CA67-4A-110A2C2A24-
