model
size = 11 31 11, scale = 0.05, origin = -y
material 
  colors = A:#070 B:#330 C:#960 D:#800
voxels
3-18(5A6-)5A137-18(7A4-)7A5-5A6-5A114-18(9A2-)9A3-7A4-7A6-3A8-3A92-209A-9A2-9A4-5A6-5A7-3A63-3A15-209A-9A2-9A3-7A4-7A5-5A7-4(3A8-)3A7-A3CA7-3C4-209A-9A2-9A3-7A4-7A5-5A7-4(3A8-)ADA7-A3CA7-3C4-209A-9A2-9A3-7A4-7A5-5A7-4(3A8-)3A7-A3CA7-3C4-209A-9A2-9A4-5A6-5A7-3A63-3A16-18(9A2-)9A3-7A4-7A6-3A8-3A94-6(7A4-)3(B5AB4-)B5AC7(4-B5AB)2(4-7A)5-5A6-5A116-6(5A6-)5B6-C2BCB6-3BCB2(6-C4B)6-4BC6-3B2(CB6-C2B)CB6-BC2BC6-5B2(6-5A)135-
