model
size = 23 12 29, scale = 0.05, origin = -y
material 
  colors = A:#CA1515 B:#111 C:#444 D:#FFB11B E:#EEE
voxels
6-2A3(BA)B2A12-2A7B2A12-3A5-3A12-4A3-4A14-7A17-5A151-2(3A2B5-2B3A8-)4AB5-B4A8-5AB3-B5A10-4A3B4A12-5AB5A15-5A127-2(2A2B9-2B2A6-)3A11-3A6-3A11-3A8-A11-A10-2(A11-)5AB5A15-5A103-2(2AB13-B2A4-)3A13-3A4-3A13-3A6-A13-A8-2A11-2(2A9-)2A12-4AB4A16-5A80-2(A2B13-2BA4-)2AB13-B2A4-2AB13-B2A5-AB13-BA6-ABA11-ABA7-2(3A9-)6AB6A12-9A77-2(2AB15-B2A2-)2A17-2A3-A17-A4-A17-A5-2AB11-B2A6-2ABA9-AB2A2(7-4A)10-5AB5A15-5A56-2(AB17-BA2-)A19-A2-A19-A3-A17-A4-A17-A5-3AB9-B3A6-3ABA7-AB3A8-6AB6A12-9A53-2AB17-B4AB17-B2A-A19-A2-A19-A3-A17-A4-A17-A5-A15-A6-4AB7-B4A8-6AB3AB2A12-9A53-AB19-B2AB19-B3A19-2A-A19-A2-2A17-2A3-A17-A4-2A15-2A5-3A11-3A8-3ABA3-AB3A12-4AB4A17-3A33-AB19-B2AB19-B3A19-4A19-2A-2A17-2A2-2A17-2A3-2A15-2A4-4A11-4A6-5AB3-B5A10-3A2(BA)B3A15-5A32-AB19-B2AB19-B3A19-4A19-2A-2A17-2A2-2A17-2A3-2A15-2A4-4A11-4A6-4A7-4A10-4A3B4A14-7A18-3A10-A3(B19-B2A)B19-BA-AB17-BA2-AB17-BA3-AB15-BA4-2A2B11-2B2A6-2A2B7-2B2A10-2A7B2A14-3AB3A18-3A10-AB19-B2AB19-B3A19-4A19-2A-2A17-2A2-2A17-2A3-2A15-2A4-4A11-4A6-4A7-4A10-4A3B4A14-7A18-3A10-2A2(B17-B4A)19-2A-A19-A2-2A17-2A3-A17-A4-2A15-2A5-3A11-3A2(7-4A)10-3A2(BA)B3A15-5A33-2(AB17-BA2-)A19-A2-A19-A3-A17-A4-A17-A5-A15-A6-3A11-3A8-3AB5-B3A12-4AB4A17-3A34-2(2AB15-B2A2-)2A17-2A2-2A17-2A3-2A15-2A4-2A15-2A5-A15-A6-3A11-3A8-2A2(B3A)B2A12-9A55-2(AB15-BA4-)A17-A4-A17-A5-A15-A6-A15-A7-2AB9-B2A8-2AB9-B2A10-5AB5A14-7A56-A3B11-3BA4-2A2B11-2B2A2(4-3AB11-B3A)5-2AB11-B2A6-2AB11-B2A7-2(3A9-)2A9-2A11-5AB5A14-7A56-ACA2B9-2BACA4-3A2B9-2B3A5-3A11-3A6-3A11-3A7-2(2A11-2A8-)2(3A9-)6AB6A11-11A16-3A58-2(AC)A9B2(AC)A4-5A9B5A6-3A4-B4-3A8-3A4-B4-3A9-2(2A4-B4-2A10-)2A4-B4-2A11-11A13-9A78-4(AC)3A4(CA)4-4AB9AB4A8-3AB3DB3A12-2ABD3BDB2A12-ABD5BDBA12-B9EB12-ABD5BDBA13-ABD3BDBA15-AB3DBA79-3(AC)2A3C2A3(CA)4-19A234-2A2(CA)C5A2(CA)C2A4-19A235-2A2(CA)5C2(AC)2A6-17A236-3ACAC5ACAC3A6-17A237-3ACA5CAC3A8-15A239-3AC5AC3A10-13A241-3A5C3A12-11A243-9A14-9A237-
