model
size = 32, scale = 0.05, origin = -y
material 
  colors = A:#111 B:#D00 C:#F66 D:#F93 E:#500 F:#030 G:#E00 H:#00D I:#001 J:#F96 K:#FF6 L:#909 M:#00F N:#FF9 O:#09F P:#800 Q:#FF0 R:#0B0 S:#066 T:#F6F U:#0FF V:#00B W:#700 X:#93F Y:#633 Z:#600 Aa:#630
voxels
494-3E28-2(5E27-)5E28-3E422-D32-D40-3(F28-F2-)F3-G16C3-G4-F2-F3-17C8-F7-4C6-J5C17-3C6-3CJ2C18-2C6-3CJ2C2(19-13C)19-C6-6C18-2C6-2C2J2C17-CJC6-6C16-2CJC3(6-6C15-5C)6-CJ4C15-CJ3C6-3CJ2C15-CJ2CJ6CJ5C15-C-C2-2C2-2(C-)2C-C15-3C2(2-CJ)2C2-2C15-C2-C-2C-J2-C4-C15-C3-4C3-C4-C15-C2-C-2C-C2-J4-J15-C-C2-2C2-C-C4-C14-3C-6C-3C2-3C12-2(C-)C2-2C2-2(C-)2C2(-C)10-28D89-C9-F21-CD5-F2-G21-D6-G2-G28-G34-G3-14CJ2C3-C4-G2-G3-C15-C8-G2-F3-C15-C8-F22-7(C31-)5(C15-)J5(15-C)2(31-2(C15-)C)2(31-C)76-8DJ14DJ4D67-F28-F2-G28-G4-H19-2C3-H4-G21-DC5-G25-D5-G2-G3-17C3-C4-G6-C6-Z8-C11-G3-C6-P8-C8-G2-F3-C6-P8-C8-F13-P8-C22-P8-2(C31-)C21-2Q8-C31-C15-C6-M8-C15-C6-R8-3(C15-)J7(15-C)31-2(C15-)3(C31-)C76-20DJ7D67-F28-F2-G-H24-H-G2-G28-G2-F-H19-2C3-H6-H19-CD3-H-F2-F3-6CJ2CJ9C-C7-2(G3-C24-G2-)F3-C24-F6-C38-P3(31-Q)24-C31-C6-V24-C6-R24-3(C31-)C95-C188-2(D5I)DI6DID5ID67-F28-F4-H24-H33-G31-F-32H5-15C2J4C4-F6-C6-Z17-G6-C6-P20-F3-C6-P17-F6-C6-P24-C6-P88-C5-2Q24-C31-C6-M24-C6-R24-5(C31-)C220-DI5DI3DID2IJ3D2IDI3DID67-F28-F2-G-H26-G2-G28-G2-F36-2DC7DJ2D2J4DC4-F2-F3-C2-L16-C7-G3-C14-Y-Y2-C4-G2-G3-C14-S-S2-C4-G2-F3-C14-S-S2-C4-F6-C14-3S2-C11-C15-B3-J11-C15-B-O-J11-C13-O3BO-J11-C15-O3-C11-C14-MVM2-C11-C14-3W2-2(J11-C19-)2(C11-C19-)J11-J2(19-C11-C)19-6(C31-)C8-DI5DI3D2(ID)I2D2(ID)I3DID67-F28-F2-G-H24-H-G34-G28-G6-C15DJ3DC4-G2-G3-C19-C4-G6-J3-L15-C7-G23-C4-G2-F23-C4-F26-J11-C19-J31-J25-O5-2(C11-C19-)2(C31-)C3(11-C19-J2(31-C))3(31-C)8-D4I2DI3DIDI2D2I2DIDI3DID99-F-H24-H-F2(2-G28-G)6-CD4C12DJDC7-G3-C-4L14-C4-G2-G3-C2(-L)15-C4-G2-F3-C3-L15-C4-F26-2(J31-)C31-C11-J2(19-J11-C)19-C11-C19-2(J31-)C31-2(C11-C19-)J11-J19-C31-C11-C19-2(C31-)2(J31-)C11-C19-C8-DI2DJ2DI3DIDI6DIDI3DID101-H24-H4-2(F28-F2-)F3-C2D3C6D2J6D2(C4-F2-F3-C2-3L14-)C4-F9-2L15-C31-J31-C11-C19-2(C31-)C11-J19-C11-C19-J31-C18-3E10-C11-C5-5E9-2(C16-7E8-)J11-C4-7E8-J31-C11-C19-C31-J11-C19-2(C31-)C11-C19-C40-DI5DI3DIDI6DIDI3DID101-H24-H72-2(CD)3C13DC11-C-L-3L13-C11-C4-L14-2(J11-C19-)4(C11-C19-)C11-C6-E-E10-C11-C6-EJE3-R2-G3-C11-C6-EJE10-C11-C6-3E10-3(C11-C19-)J4(11-C19-C)11-J4(19-C11-C)19-C8-DI5DI3DIDI6DIDI3DID101-H24-H72-2C18DC7-C3-CL18-2J6-C3-C21-C32-D175-E-E35-R2-G399-C19-C40-DI5D5IDIDJ4DID5ID101-H24-H4-F28-F2-F10-7A11-F2-F3-CDC2D11A4DC4-F2-F3-C-L2-7E8-2C3-F2-F3-C4-2E3-2E10-C2-F11-E5-E11-D13-E5-E25-2E3-2E25-EAE-EAE25-7E27-E-E29-A-A35-R2-G431-C19-C8-28D99-F-H24-H-F2-G26-H-G2-G10-7A11-G6-C4D11A4DC7-G3-C4-7A8-2C3-G2-G3-C4-2AL-N2A10-C2-G2-F8-A-D-N-A11-C-F11-A5-A11-D13-2A3-2A25-3A-3A25-7A27-A-A29-A-A35-R2-G460-25DJ2D67-F28-F2-G-H24-H-G4-H29-G10-7A9-H-G2-G3-2CD2C11AC-D2C7-G3-2C-15A-2C4-G6-C-5A-2N9A-C7-G4-5A2-D2-9A5-G2-F3-6A2-N2-10A4-F6-7A3-11A2-D7-9A-13A2-D6-23A8-6(25A7-)25A8-23A9-23A10-21A11-21A12-19A14-17A16-15A19-11A23-7A47-6DJ7DJ13D67-F28-F2-G-H24-H-G2-G28-G4-H8-7A11-F2-F-H6-11A7-H11-15A7-F2-G5-5AN-L9A6-G2-G4-5A4-D9A5-G2-F3-6A5-10A4-F6-7A3-11A2-D7-9A-13A2-D6-23A8-6(25A7-)25A8-23A9-23A10-21A11-21A12-19A14-17A16-15A19-11A23-7A59-3D80-F28-F4-H24-H4-G31-F10-7A13-10H11A11H-F6-15A10-G5-5A2LN9A14-5A2-N2-9A8-F3-6A5-10A4-F6-7A3-11A10-9A-13A2-C6-23A-CD5-3(25AD6-25A7-)25AD7-23A9-23AD9-21A11-21AD11-19A14-17A2D14-15AD18-11AD22-7AD26-3CD28-3D80-F28-F2-G-H24-H-G2-G28-G13-7A11-F2-F8-11A19-15A7-F2-G5-5A3N9A6-G2-G4-5A5N9A5-G2-F3-6A5N10A4-F6-7A3N11A10-9AN13A2-C6-23A-CD5-3(25AD6-25A7-)25AD7-23A9-23AD9-21A11-21AD11-19A14-17A2D14-15AD18-11AD22-7AD26-4D111-F28-F2-G-H24-H-G34-G10-7A11-G2-G8-11A12-G6-15A7-G8-17A9-G4-19A5-G2-F3-21A4-F6-21A10-23A9-23A8-2(25A7-)5A3B10A3B4A7-5A5B6A5B4A7-4A6B6A6B3A7-4A5B8A5B3A7-3A6B8A6B2A8-2A5B10A5BA9-A6B10A6B9-6B12A6B8-6B12A6B7-6B14A6B6-5B16A5B5-6B15A-6B4-5B3-11A4-5B3-6B5-7A6-6B2-5B8-4D8-5B4-3B20-3B100-F-H24-H-F2-G28-G2-G10-7A11-G11-11A12-G6-15A7-G2-G5-17A6-G2-F4-19A5-F6-21A11-21A10-23A9-23A8-25A7-5AB14AB4A7-4A4B10A4B3A7-4A6B6A6B3A2(7-3A8B4A8B2A)7-2A8B6A8BA2(8-8B8A8B)7-8B10A8B6-8B10A8B5-8B12A8B4-8B12A8B3-8B14A8B-8B2-11A3-16B4-7A5-8B-6B7-4D7-6B4-4B18-4B8-B20-B72-H24-H4-F28-F2-F10-7A11-F2-F8-11A9-F2-F6-15A7-F2-F5-17A6-F7-19A12-21A11-21A10-23A9-23A8-25A7-4A2B14A2B3A7-3A5B10A5B2A7-3A7B6A7B2A7-2A9B4A9BA7-A11B2A11B7-A10B4A10B7-11B4A11B6-10B6A10B5-10B8A10B4-10B8A10B3-10B10A10B-11B10A21B12A20B11A-19B3-7A4-9B-7B16-7B2-E-5B16-5B-E2-E3-2B18-2B3-E68-H24-H47-7A23-11A19-15A16-17A14-19A12-21A11-21A10-23A9-23A8-25A7-4A2B14A2B3A7-3A5B10A5B2A7-3A7B6A7B2A7-2A9B4A9BA7-A11B2A11B7-A10B4A10B7-11B4A11B6-10B6A10B5-10B8A10B4-10B8A10B3-10B10A10B-11B10A21B12A20B11A-19B3-7A4-9BE7B6-3D7-7BE3-5B16-5B8-2B18-2B72-H24-H4-F31-F10-7A14-F8-11A12-F6-15A10-F5-17A14-19A12-21A11-21A10-23A9-23A8-25A7-4A2B14A2B3A7-3A5B10A5B2A7-3A7B6A7B2A7-2A9B4A9BA7-A11B2A11B7-A10B4A10B7-11B4A11B6-10B6A10B5-10B8A10B4-10B8A10B3-10B10A10B-11B10A21B12A20B11A-19B3-7A4-9B-7B6-3D7-7B2-E-5B16-5B-E2-E3-2B18-2B3-E66-F-H24-H4-G28-F2-G10-7A11-F11-11A9-F2-G6-15A7-F2-G5-17A6-F2-F4-19A12-21A11-21A10-23A9-23A8-25A7-4A2B14A2B3A7-3A5B10A5B2A7-3A7B6A7B2A7-2A9B4A9BA7-A11B2A11B7-A10B4A10B7-11B4A11B6-10B6A10B5-10B8A10B4-10B8A10B3-10B10A10B-11B10A21B12A20B11A-19B3-7A4-9BE7B16-7BE3-5B16-5B8-2B18-2B38-F31-G-H24-H-F4-H24-H-G2-G10-7A11-G11-11A12-G6-15A7-G8-17A6-G2-G4-19A5-F2-F3-21A11-21A10-23A9-23A8-25A7-4A2B14A2B3A7-3A5B10A5B2A7-3A7B6A7B2A7-2A9B4A9BA7-A11B2A11B7-A10B4A10B7-11B4A11B6-10B6A10B5-10B8A10B4-10B8A10B3-10B10A10B-11B10A21B12A20B11A-19B3-7A4-9B-7B6-3D7-7B2-E-5B16-5B-E2-E3-2B18-2B3-E34-F28-F2-G28-G2-G-H24-H4-F-H8-7A9-H-G4-H6-11A9-G2-F6-15A7-G2-G5-17A9-G4-19A5-G2-F3-21A4-F6-21A10-23A9-23A8-25A7-5AB14AB4A7-4A4B10A4B3A7-4A6B6A6B3A2(7-3A8B4A8B2A)7-2A8B6A8BA2(8-8B8A8B)7-8B10A8B6-8B10A8B5-8B12A8B4-8B12A8B3-8B14A8B-8B2-11A3-16B4-7A5-8B-6B18-6B4-4B18-4B8-B20-B38-F28-F2(31-G)13-7A9-H3-2H-H6-11A7-H-F9-15A16-17A6-G7-19A5-G2-F3-21A4-F6-21A10-23A9-23A8-2(25A7-)5A3B10A3B4A7-5A5B6A5B4A7-4A6B6A6B3A7-4A5B8A5B3A7-3A6B8A6B2A8-2A5B10A5BA9-A6B10A6B9-6B12A6B8-6B12A6B7-6B14A6B6-5B16A5B5-6B15A-6B4-5B3-11A4-5B3-6B5-7A6-6B2-5B8-3D9-5B4-3B20-3B68-F28-F2-G31-G28-G2-F10-7A11-F3-7H-11A2-9H-F6-15A7-F2-G5-17A6-G2-G4-19A8-F3-21A4-F6-21A10-23A9-23A8-6(25A7-)25A8-23A9-23A10-21A11-21A12-19A14-17A16-15A19-11A23-7A142-F28-F2-G28-G31-G2-G10-7A23-11A9-F2-G6-15A16-17A6-G2-G4-19A5-G2-F3-21A4-F6-21A10-23A9-23A8-6(25A7-)25A8-23A9-23A10-21A11-21A12-19A14-2A3M7A3M2A16-2AT9AU2A19-TAO7AU-O17-O3TO5AO3UO19-O9-O20-MVM7-MVM19-3I7-3X72-F2-F28-G2-G31-G28-G31-G2-G28-G2-G17-3K11-F6-3K7-5K7-G8-5K6-5K7-F8-5K6-5K16-5K-5E-3K18-3K-7E24-9E22-2(11E21-)5E-5E2(21-11E)22-9E24-7E22-2(Aa-)5E2(-P)19-M-M7-M-M19-M-M2-3K2-M-M19-2(M-)5K2(-M)23-5K27-5K28-3K23-O9-O203-F2(2-F28-G)2-F31-F28-G2-F28-G31-F78-5E26-7E24-9E22-4(11E21-)11E22-9E24-7E26-5E460-4(F31-)F142-5E26-7E24-4(9E23-)9E24-7E26-5E366-
