model
size = 29 32 32, scale = 0.05, origin = -y
material 
  colors = A:#EEE B:#D00 C:#222 D:#C93F3F E:#888 F:#DDD G:#555 H:#070 I:#06F J:#AAA K:#3CF L:#010 M:#777 N:#0FF O:#90F P:#3F3 Q:#BBB R:#FC3
voxels
419-3C25-2C-2C23-2C-C-2C21-2C2(-C)-2C20-4(C-)C20-2C2(-C)-2C21-2C-C-2C23-2C-2C25-3C372-7C19-13C14-5C7-5C2(11-4C)9-3C15-3C7-3C17-3C5-3C19-3C4-2C21-2C3-3C21-3C2(2-2C23-2C)-2C2(25-4C)12-D12-4C11-3D11-4C12-D12-2(4C25-)2C-2(2C23-2C2-)3C21-3C3-2C21-2C4-3C19-3C5-3C17-3C7-3C15-3C9-2(4C11-)5C7-5C14-13C19-7C138-7A19-6A-6A15-4A7-4A12-4A11-4A9-3A15-3A8-2A17-2A7-2A19-2A5-3A19-3A2(4-2A21-2A)3-2A23-2A2-2A11-A11-2A2-2A10-A-A10-2A2-A10-A3-A10-A2-2A10-A-A10-2A2-2A11-A11-2A2-2A23-2A3-2(2A21-2A4-)3A19-3A5-2A19-2A7-2A17-2A8-3A15-3A9-4A11-4A12-4A7-4A15-6A-6A19-7A198-3A24-3A-3A20-2A7-2A16-2A11-2(2A13-)2A11-2A15-2A10-A17-A9-A19-A8-A19-A7-2(A10-)A6-A9-3A9-A5-2A8-2A-2A8-2A4-A8-2A3-2A8-A4-2A8-2A-2A8-2A5-A9-3A9-A6-2(A10-)A7-A19-A8-A19-A9-A17-A10-2A15-2A11-2(2A13-)2A11-2A16-2A7-2A20-3A-3A24-3A230-A27-3A24-3A-3A20-2A7-2A17-A11-A15-2(A13-)A15-A11-A17-A10-A17-A9-A8-3A2(8-A)7-2A-2A7-A7-2A6-2A3-2A6-2A5-2A7-A5-A7-2A5-2A6-2A3-2A6-2A7-A7-2A-2A7-2(A8-)3A8-A9-A17-A10-A17-A11-A15-2(A13-)A15-A11-A17-2A7-2A20-3A-3A24-3A27-A260-A25-7A20-2A7-2A17-A11-A15-2(A13-)A15-A11-A17-A10-A17-A9-A8-3A2(8-A)7-2A-2A7-A8-A6-2A3-2A6-A7-2A6-A5-A6-2A7-A6-2A3-2A6-A8-A7-2A-2A7-2(A8-)3A8-A9-A17-A10-A17-A11-A15-2(A13-)A15-A11-A17-2A7-2A20-7A25-A317-3A24-3A-3A20-3A5-3A17-2A9-2A15-2(A13-)2A13-2A12-A15-A11-2A6-3A6-2A10-A6-2A-2A6-A9-2A5-2A3-2A5-2A8-A6-A2-G2-A6-A8-2A5-2A3-2A5-2A9-A6-2A-2A6-A10-2A6-3A6-2A11-A15-A12-2(2A13-)A13-A15-2A9-2A17-3A5-3A20-3A-3A24-3A346-A27-3A25-2A-2A22-2A5-2A18-2A9-2A16-A11-A15-A13-A14-A5-3A5-A13-A5-2A-2A5-A11-2A4-2A3-2A4-2A9-2A5-A2-G2-A5-2A9-2A4-2A3-2A4-2A11-A5-2A-2A5-A13-A5-3A5-A14-A13-A15-A11-A16-2A9-2A18-2A5-2A22-2A-2A25-3A27-A376-A27-3A25-2A-2A22-2A5-2A19-A9-A17-A11-A16-A4-3A4-A15-A4-2A-2A4-A13-3(2A3-)2A11-2A4-A2-G2-A4-2A11-3(2A3-)2A13-A4-2A-2A4-A15-A4-3A4-A16-A11-A17-A9-A19-2A5-2A22-2A-2A25-3A27-A434-A26-5A22-2A5-2A19-A9-A17-A11-A16-A4-3A4-A15-A4-A3-A4-A14-A3-A2-C2-A3-A13-2A3-A-CGC-A3-2A13-A3-A2-C2-A3-A14-A4-A3-A4-A15-A4-3A4-A16-A11-A17-A9-A19-2A5-2A22-5A26-A491-3A25-2A-2A22-2A5-2A19-A9-A18-A3-3A3-A17-A3-AC-CA3-A15-2A2-AC3-CA2-2A14-A3-A2-G2-A3-A14-2A2-AC3-CA2-2A15-A3-AC-CA3-A17-A3-3A3-A18-A9-A19-2A5-2A22-2A-2A25-3A520-A26-5A22-2A5-2A19-2A7-2A18-A3-3C3-A17-A2(3-C)3-A16-A2-C5-C2-A15-2A2-C2-G2-C2-2A15-A2-C5-C2-A16-A2(3-C)3-A17-A3-3C3-A18-2A7-2A19-2A5-2A22-5A26-A548-5A23-3AE3A21-2A5E2A19-2A2E3C2E2A17-2A2EC3-C2E2A16-2AEC5-CE2A16-A2EC2-G2-C2EA16-2AEC5-CE2A16-2A2EC3-C2E2A17-2A2E3C2E2A19-2A5E2A21-3AE3A23-5A258-A28-A287-5A24-2AE2A23-A5-A21-A2-3G2-A18-2A2-5G2-2A16-2A-7G-2A16-AE-7G2-A16-2A-7G-2A16-2A2-5G2-2A18-A2-3G2-A21-A5-A23-2AE2A24-5A257-3A26-A-A27-A259-3B25-BAEAB23-B5-B21-B7-B19-B3-3L3-B17-BA3-3L3-AB16-BE2-B-L-K3-B16-BA3-3L3-AB17-B9-B19-B7-B21-B5-B23-BAEAB25-3B257-5A25-A-A26-A-A27-A28-A201-3B25-BAEAB23-B2HJHJB21-B7-B19-B3-3L3-B17-BA4-L4-AB16-BE2-B3-K3-B16-BA2-B3-K2-AB17-B9-B19-B7-B21-B5-B23-BAEAB25-3B257-5A2(24-A3-A)25-A-A26-A-A27-A28-A143-3B25-BAEAB23-BJF-FHB21-B2-F-F2-B19-B3-3L3-B17-BA4-L4-AB16-BE10-B16-BA2-B3-K2-AB17-B2-B3-K2-B19-B7-B21-B5-B23-BAEAB25-3B257-5A4(24-A-C-A)25-ANA26-ANA27-A28-A85-3B25-BAEAB23-B2(HJ)HB21-B7-B19-B9-B17-BA9-AB16-BE10-B16-BA9-AB17-B2-B3-K2-B19-B7-B21-B5-B23-BAEAB25-3B257-5A24-A3C3(A24-ACPC)A24-ANQNA24-A-N-A25-AKA26-A-A27-A56-3B25-BAEAB23-BH2JHJB21-B2-M-M2-B19-B2-5I2-B17-BA2-5I2-AB16-BE2-5I3-B16-BA9-AB17-B2-B3-K2-B19-B7-B21-B5-B23-BAEAB25-3B257-5A24-A3C2(A24-ACPC)A24-ACQCA24-ANQNA24-A-N-A24-A3-A24-A-K-A25-A-2(A27-)BAB25-BAEAB23-BJ2HJHB21-B2-M-M2-B19-B2-5I2-B17-BA2-5I2-AB16-BE2-5I3-B16-BA9-AB17-B2-B3-K2-B19-B7-B21-B5-B23-BAEAB25-3B258-3A25-2AC2A3(24-A-C-A)2(24-A-N-A)24-A-B-A24-A3-A24-A-K-A24-2A-2A25-B-B25-BAEAB23-BJ2HJHB21-B7-B19-B9-B17-BA9-AB16-BE10-B16-BA9-AB17-B2-B3-K2-B19-B7-B21-B5-B23-BAEAB25-3B259-A28-A27-A-A25-5(A3-A24-)A-B-A24-A3-A24-A-K-A24-B3-B24-BAE-B23-BJ2HJHB21-B2-M-2M-B19-B3-R-2O2-B17-BA3-R-2O2-AB16-BE5-2O3-B16-BA2-B6-AB17-B2-B3-K2-B19-B7-B21-B5-B23-BAEAB25-3B317-A27-A-A25-2A-2A4(24-A3-A)24-A-B-A24-A3-A24-B-K-B24-BAK-B23-BH2JHJB21-B7-B19-B9-B17-BA9-AB16-BE10-B16-BA2-B6-AB17-B6-K2-B19-B7-B21-B5-B23-BAEAB25-3B346-A28-A27-A-A25-4(A3-A24-)A-B-A24-B3-B24-BAE-B23-B4HJB21-B-2(M2-)B19-B9-B17-BA9-AB16-BE2-B7-B16-BA2-B-F-K2-AB17-B6-K2-B19-B7-B21-B5-B23-BAEAB25-3B404-A27-A-A26-A-A25-3(A3-A24-)2(B-)B24-BAB-B23-B2H2JHB21-B7-B19-B3-2C4-B17-BA9-AB16-BE2-B-F-K3-B16-BA3-3FK2-AB17-B9-B19-B7-B21-B5-B23-BAEAB25-3B433-A28-A27-A-A25-2A-2A24-A3-A24-B3-B24-BAE-B23-B2(JH)JB21-B-2(M2-)B19-B3-2C4-B17-BA9-AB16-B3-B3FK3-B16-BA3-3F3-AB17-B9-B19-B7-B21-B5-B23-BAEAB25-3B491-A28-A27-A-A25-BA2-B24-BAE-B23-B2HJ2HB21-B7-B19-B3-2C4-B17-BA9-AB16-B2-7F2-B16-BA2-5F2-AB17-B9-B19-B7-B21-B5-B23-BAEAB25-3B549-A27-BAB25-BAEAB23-B2(HJ)HB21-B-2(M2-)B19-B3-2C4-B17-BA3-3F3-AB16-B2-7F2-B16-BA-7F-AB17-B2-5F2-B19-B7-B21-B5-B23-BAEAB25-3B577-3B25-BAEAB23-BHJ2HJB21-B7-B19-B3-2C4-B17-BA2-5G2-AB16-B2-F5GF2-B16-BA-7F-AB17-B2-5F2-B19-B7-B21-B5-B23-BAEAB25-3B578-D26-2DA2D23-D2HJ2HD21-D-2(M2-)D19-D2-5F2-D18-D-F5-F-D17-DA-F5-F-AD17-D2-5F2-D18-D9-D19-D7-D21-D5-D23-2DA2D26-D607-3D24-2DHJH2D21-D7-D20-D7-D19-2(D9-D18-)D9-D19-D7-D20-D7-D21-2D3-2D24-3D636-D26-2DA2D23-D-A3-D21-D2(-A)3-D20-DA-A4-D19-2D2(-A)4-D19-DA-A4-D20-D2(-A)3-D21-D-A3-D23-2DA2D26-D275-
