model
size = 11 29 31, scale = 0.05, origin = -y
material 
  colors = A:#FF0 B:#F60 C:#D00 D:#F30 E:#F63 F:#0F3 G:#FC0 H:#F90 I:#090 J:#008 K:#EEE L:#963 M:#222 N:#555 O:#F0F
voxels
4-IFI8-FAF8-GFG8-AFA8-AIA270-FGAIAGF5-A3IA6-5J6-G3IG6-F3IF6-2AG2A6-IGFGI246-BAB3FBAB2-9F2-IG5IGI3-7F3-IA5IAI3-A5FA3-F7IF2-2(GFAF)G5-GFG225-2B2(EA)E2B2-9G2-9F2(2-9J)2-9G2-9A2-9F3-7A6-AFA225-BE5BEA2-9A2-9F2-9J2-A7JA-11G11I11G-9A3-3AG3A5-5A202-2BE3BE2B2-9F2-9A2-A7FA2-9J-11A11F11A11G11A-9A3-3AG3A201-3BEBE3B2-9A2-9F2(2-9J)-11I11A11G22A-9A3-2(A2G)A190-2(9B2-)9A2-9F2-9J-11A11I44A-9A3-3AG3A179-3H3-3H2-9E2-9D2-9A2-9F2-9J-11G11A11G33A-9A3-2(A2G)A168-3L3-3L2-9B2-9D2-9B2-9A2-9F2-9A-11G55A-9A3-3AG3A157-3L3-3L2-2HB3-B2H2-4ED4E2-9D2-9C2-9I2(2-9F)-66A-9A3-A5GA146-3M3-3M2-3L3-3L2-4BD4B2-9D2-9C2-9I2-9F2-9A-11F44A3G5A3G-9A3-7A135-3M3-3M2(2-3L3-3L)2-4BE4B2-9E2-9D2-9C2-9I2-9F-66A3G5A3G-9A3-A5GA158-7H3-9B2-9D2-9B2-9C2-9I2-9F-77A-9A3-3AG3A158-7E3-9D2(2-9B)2-9C2-9I2-9F-G9AG66A-9A3-2(A2G)A147-7B3-9E2-9D2-9B2-9C2-9F2-9A2-9F-66A-9A3-7A4-3AG3A136-3HB3H3-9B2-9D2(2-9B)2-9C2(2-9G)-66A-9A3-7A4-7E5-G3AG137-7B3-9E2-9D2(2-9B)2-9C2-2G5A2G2-9A-44A-9A2-9B3-7H5-2(5B6-)5H6-2ED2E6-D3ED104-HB3HBH4-7B3-9E2-9D3(2-9B)2-2G5A2G2-2A5B2A-22A-9A2-9E2-9H4-3(5E6-)5B6-5C6-5H6-2DE2D104-7B3-9B2-9E2(2-9D)2(2-9B)2(2-2G5A2G)2-9A2-9H2-9B3-7E5-2(5B6-)2(5H6-5C6-)5H6-2DE2D93-3HB3H4-7B3-2(9B2-9E2-9B2-9D2-)9E2-9E3-7B5-5E6-5D6-5C6-D3CD3(6-5C)6-5H7-3D94-B5HB4-3HB3H4-7E3-2(9B2-)9D2-9B2-9E2-9B3-7E4-7H5-5B6-5E6-5D5(6-5C)6-5E6-2(ED)E115-2(H2B)H4-B5HB4-7H4-7B4-7D4-7B4-7E4-7H4-EC3ECE5-5B6-5D7(6-5C)6-5D128-HBH7-H3BH6-2BH2B7-HBH8-BDB8-DED8-3B8-3H8-3C7-5B2(6-5C)3(6-5K)2(6-5C)6-2(DE)D217-D8-3(5C6-)5K6-5M6-5K2(6-5C)7-DED227-3(5C6-)3(5K6-)5C6-2DO2D238-3D7-5(5C6-)2DE2D260-3D7-2CD2C2(6-5D)7-3D272-3N9-N9-3N9-N285-N9-3N9-N296-N10-N71-
