model
size = 30 30 29, scale = 0.05, origin = -y
material 
  colors = A:#DDD B:#222 C:#111 D:#555 E:#777 F:#444 G:#888 H:#AAA I:#BBB J:#007 K:#800
voxels
180-2B6(26-4B)26-2B545-2A16D2A9-A20DA8-22D4-2B2-22A2-4B2-A20CA2-4B2-ACH16CHC3(A2-4B2-A20C)A2-4B2-A3C14H3C2(A2-4B2-A20C)A2-4BH2ACH16CHC2AH4B3A20C3A2B2-26A4-8A10D8A4-6A14D6A4-26A4-D10A4-10AD4-D9A-4A-9AD4-D8A-6A-8AD4-D7A-8A-7AD4-D6A-10A-6AD4-D5A-12A-5AD4-D4A-14A-4AD4-D3A-16A-3AD4-3A-18A-3A4-2A-20A-2A5-24C66-24C3-2B-24A-4B26A4BD24AD5(4B2D22A2D)4BD24AD4(4B26A)2B2-3(26A4-)2(11A4-)10A-4A-10A4-9A-6A-9A4-2(8A-)8A4-7A-10A-7A4-6A-12A-6A4-5A-14A-5A4-4A-16A-4A4-3A-18A-3A4-2A-20A-2A5-C4H5G6E6DFC63-2B-24C-4B-24A-13(4B26A)2B2-2(26A4-)2(11A4-)10A-4A-10A4-9A-6A-9A4-2(8A-)8A4-7A-10A-7A4-6A-12A-6A4-5A-14A-5A4-4A-16A-4A4-3A-18A-3A4-2A-20A-2A5-C3H5G6E6D2FC33-2B26-4B-24C-4B-24A-14(4B26A)2B2-26A2(4-11A)4-10A-4A-10A4-9A-6A-9A4-2(8A-)8A4-7A-10A-7A4-6A-12A-6A4-5A-14A-5A4-4A-16A-4A4-B2A-18A-3A4-2A-20A-2A5-C2H5G6E6D3FC33-2B26-4B-24C-4B-24A-14(4B26A)2B2-26A4-11A4C11A4-10AC4AC10A4-D8AC6AC8AD4-2(8AC)8A4-7AC10AC7A4-6AC12AC6A4-B4AC14AC5A4-B3AC16AC4A4-B2AC18AC3A4-2AC20AC2A5-CH5G6E6D4FC3-2B2(26-4B)-24C-4B-24A-15(4B26A)2B2-26A2(4-D24AD)3(4-26A)4-B25A2(4-B24AB)4-26A5-C5G6E6D5FC3-2B2(26-4B)-24C-4B-24A-15(4B26A)2B2-26A2(4-D24AD)2(4-26A)4-B25A4-B24AB2(4-B25A)4-26A5-C4G6E6D6FC3-2B2(26-4B)-24C-4B-24A-4(4B26A)2BI2(B26AB2I)B26ABI2B7(26A4B)26A2B2-26A2(4-D24AD)3(4-26A)2(4-25AB)2(4-26A)5-C3G6E6D6FDC3-2B2(26-4B)-24C-4B-24A-4(4B26A)2BI2(B26AB2I)B26ABI2B6(26A4B)26A2B-B26A2B2-26A2(4-D24AD)7(4-26A)5-C2G6E6D6F2DC3-2B2(26-4B)-24C-4B-24A-4(4B26A)2BI2(B26AB2I)B26ABI2B7(26A4B)26A2B2-26A2(4-D24AD)3(4-26A)2(4-B25A)2(4-26A)5-CG6E6D6F3DC3-2B2(26-4B)-24C-4B-24A-15(4B26A)2B2-26A2(4-D24AD)3(4-26A)4-25AB4-B24AB4-25AB4-26A5-C6E6D6F4DC3-2B2(26-4B)-24C-4B-24A-15(4B26A)2B2-26A2(4-D24AD)7(4-26A)5-C5E6D6F5DC33-2B26-4B-24C-4B-24A-14(4B26A)2B2-2(26A4-)2(D24AD4-)6(26A4-)26A5-C4E6D6F5DEC33-2B26-4B-24C-4B-24A-14(4B26A)2B2-2(26A4-)2(D24AD4-)2(26A4-)B25A4-26A4-25AB4-B25A4-26A5-C3E6D6F5D2EC63-2B-24C-4B-24A-13(4B26A)2B2-4(26A4-)D24AD3(4-26A)4-B25A4-26A4-B24AB4-26A5-C2E6D6F5D3EC66-24C3-2B-24A-12(4B26A)2B2-5(26A4-)D24AD3(4-26A)4-25AB4-B25A4-B24AB4-26A5-CE6D6F5D4EC66-24C6-24A3-2B10(26A4B)26A2B2-4(26A4-)11A4C11A4-10AC4AC10A4-D15AC8AD4-2(8AC)8A4-7AC10AC7A4-6AC12AC6A4-5AC14AC5A4-4AC16AC4A4-3AC18AC3A4-2AC23A5-C6D6F5D5EC66-24C6-24A5-26A4-26A2-2B6(26A4B)26A2B2-6(26A4-)2(11A4-)10A-4A-10A4-9AC6A-9A4-2(8A-)8A4-7A-10A-7A4-6A-12A-6A4-5A-14A-5A4-4A-16A-4A4-3A-18A-3A4-2A-20AC2A5-C5D6F5D5EGC96-24A5-15(26A4-)2(11A4-)10A-4A-10A4-9A-6A-9A4-2(8A-)8A4-7A-10A-7A4-6A-12A-6A4-5A-14A-5A4-4A-16A-4A4-3A-18A-3A4-2A-20A-2A5-C4D6F5D5E2GC97-2A18D2A7-A22DA5-A24DA13(4-26A)2(4-11A)4-10A-4A-10A4-9A2-5A-9A4-2(8A-)8A4-7A-10A-7A4-6A-12A-6A4-5A-14A-5A4-4A-16A-4A4-3A-18A-3A4-2A-20A2-A5-C3D6F5D5E3GC186-24A5-H24AH4-26A2(4-D24AD)2(4-2D22A2D)4(4-2D3AC2B2F2D2E2D2F2BC3A2D)2(4-2D22A2D)4-2D9A4-9A2D4-2D8A-4A-8A2D4-2D7A-6A-7A2D4-D7A-8A-7AD4-D6A-10A-6AD4-6A-12A-6A4-5A-14A-5A4-4A-16A-4A4-3A-3A3J6A3J3A-3A4-2A-20A-2A5-24C249-18A449-B29-B310-5(A20EA8-)22A417-B220-4(A20EA8-)3(A20-A8-)A20EA8-22A417-B160-22A2(8-A20EA)7(8-A20-A)8-22A417-B160-22A9(8-A20-A)8-22A417-K160-22A9(8-A20-A)8-2A18-2A578-22A874-
