model
size = 30 17 9, scale = 0.05, origin = -y
material 
  colors = A:#099 B:#BBB C:#096 D:#09C E:#0CF F:#9FF G:#EEE H:#DDD I:#111
voxels
221-A2(508-2A)28-2(10A20-)9A20-8C21-9C233-9B21-9B19-14B9-FG5-14B8-3F5-12A2D10-F5-12A2D8-5D3-12A2D9-DI2D15A2D12-D3-C8A21-9C148-B28-2B12-2E13-3B5-A5-2E11-9B-3A3-3E9-14B2A-3E9-2H15B3E4-F5GH16B2E4-3F14A3-4DE7-13A5-4D2E4-2D3-A14-4D3E4-4D9A5-A2D4-2E6-D3AC4A3-4A6-3E9-9C11-E12-4C13-2E11-4C27-2C29-C116-2(9B21-)12B9-FG7-12B8-3F7-10A2D10-18A2D8-2D3-15A2D9-4D15A2D12-D12A21-9C314-FG27-3F7-2A20-F7-10A10-5D5-10A11-DI2D4-10A15-D3-9C21-9C353-2A509-A288-
