model
size = 11 28 11, scale = 0.05, origin = -y
material 
  colors = A:#FFECB1 B:#CAAD5F C:#E83015 D:#AAA E:#BBB F:#EEE
voxels
26-3C7-22(3A2C6-)5C7-3A29-5D5-2C3B2C3(4-2A3B2A)4-CA3B2(2A4-4AB)AC4-C5A8(C4-6A)C2(4-C6A)4-7A2(4-C3AB2A)4-2A3B2A4-2A3BAC4-CA3-AC5-5A7-3D8-3E6-2D3A2D3-CA5BAC2(2-2A5B2A)2(2-CA5B2A)2-C4A2B2A2-5A2B2A2-C8A3(2-9A)3(2-C7AC)2-8A2(C2-C7A)C2(2-C8A)2(2-C4A2B2A)2-AF5B2A2-2A5BAC2-CA5-AC3-2A3E2A5-D3-D6-E3-E4-2DA3DA2D2-C7BC-2A7B3A9BAC9B4A5B2(2AC6A2B)2(3AC5A2B)9A6(2B3AC5A)2B9A2B2A2C5A2B2AC6A2(2B2A2C5A)2B2(2AC3A5B)2A2CA7-AC-2A5E2A3-D5-D4-E5-E3-DA5DAD-CA7BAC2A7B2A2(C9BA)C2A5B3AC5(2A5B2A2C)2A5B3AC2A5B6A5(5B3AC2A)5B3(9A2B)2(2AC3A5B)2A2CA7-AC2AE2-4E2A-D3-6E2-E5-E3-DA5DAD-CA7BAC2A7B3A9BAC9B2(2C2A5B2AC3A5B3AC2A5B2A)4(2C2A5B2A)C3A8(5B6A)5B3ACA7-AC2AE2-5EA-D3-E-2(E2-)E5-E3-DA5DAD-CA7BAC2A7B3A9BCA9BC3A5(5B2A2C2A)3(5B2AC3A)5B6A5(5B2AC3A)3B8A2(3B5AC2A)5B3AC2A5B3ACA7-AC2AE2-4E2A-D3-6E2(3-E)4-2DA3DA2D2-C7BC-2A7B3A9B2A9B2C2A5B3AC2A2(3B8A)2(3B4AC3A)3B8A5(3B4AC3A)2(3B4A2C2A3B5AC2A)2(3B4A2C2A)5B3AC2A5B3ACA7-AC-2A5E2A3-D5-D6-3E6-2D3A2D3-CA5BAC2(2-2A5B2A)2(2-2A5BAC)2-2A3B3AC2-2A3B4A2-8AC3(2-9A)3(2-C7AC)2-C8A2(2-C7AC)2(2-8AC)2(2-2A3B3AC)2-2A5BFA2-CA5B2A2-CA5-AC3-2A3E2A5-D3-D17-5D5-2C3B2C3(4-2A3B2A)4-2A3BAC4-2A2B3A4-CA2B3A4-C5AC8(4-C6A)2(4-6AC)4-7A2(4-2A2B2AC)4-2A2(3B2A4-CA)3-AC5-5A7-3D30-3C7-22(2C3A6-)5C7-3A15-
