model
size = 31 15 20, scale = 0.05, origin = -y
material 
  colors = A:#111 B:#EEE C:#E00 D:#0FF
voxels
37-20A11-20A383-20A11-20A2(414-20A11-A18-A)414-20A11-A-16A-A13-2(4A2(B5A)15-)2(3A10B3A15-)4A10B2A15-3A11B2A15-3ABD2A7B2A2(15-3A4C6B3A)15-7AC8A15-8AC7A2(15-16A)13-3A14-3A11-A-16A-A13-16A6(15-A6-2A6-A)15-16A15-A14-A4(15-16A)2(13-3A14-3A11-A-16A-A13-16A6(15-A6-2A6-A)6(15-16A))13-3A14-3A11-A-16A-A13-16A15-A6-2A6-A13-2BA6-2A6-A2B9-4BA6-2A6-A4B8-3BA6-2A6-A3B9-3BA6-2A6-A3B11-BA6-2A6-AB14-5(16A15-)16A13-3A14-3A11-A-16A-A13-16A15-A6-2A6-A13-2BA6-2A6-A2B8-5BA6-2A6-A4B5-6BA6-2A6-A6B-8BA6-2A6-A7B-2B4-BA6-2A6-AB4-2B8-5(16A15-)16A2(13-3A14-3A11-A-16A-A13-16A15-A6-2A6-A13-2BA6-2A6-A2B9-4BA6-2A6-A4B5-2(2B-)A6-2A6-A2(-2B)3-6BA6-2A6-A6B3-2B3-BA6-2A6-AB3-2B9-3(16A15-)7A2-7A2(15-16A))13-3A14-3A11-A-16A-A13-16A15-A6-2A6-A13-2BA6-2A6-A2B8-5BA6-2A6-A4B5-6BA6-2A6-A6B-8BA6-2A6-A7B-2B4-BA6-2A6-AB4-2B8-5(16A15-)16A13-3A14-3A11-A-16A-A13-16A15-A6-2A6-A13-2BA6-2A6-A2B9-4BA6-2A6-A4B8-3BA6-2A6-A3B9-3BA6-2A6-A3B11-BA6-2A6-AB14-5(16A15-)16A2(13-3A14-3A11-A-16A-A13-16A6(15-A6-2A6-A)6(15-16A))13-3A14-3A11-A-16A-A13-16A6(15-A6-2A6-A)15-16A15-A14-A4(15-16A)13-20A11-A-16A-A13-2(4A2(B5A)15-)2(3A10B3A15-)4A10B2A15-3A11B2A15-3ABD2A7B2A2(15-3A4C6B3A)15-7AC8A15-8AC7A2(15-16A)13-20A11-A18-A414-20A11-A18-A408-
