model
size = 25, scale = 0.05, origin = -y
material 
  colors = A:#DF7B33 B:#BE682B C:#9A5423 D:#F58738 E:#1A1A1A
voxels
236-DEB21-BDEAD19-2BCE3B18-7E18-D2AEDBC19-DCEBD21-BEC420-3BE3A17-2BADEBCDA15-ED2C3-BDCE14-EBC5-CAE14-EC7-DE14-2E7-2E14-EA7-CE14-EAD5-2BE14-EACA3-BCAE15-C2ADE2(CB)17-3BEBCA319-CBEDA18-ADBDECD2B15-AC7-2D13-EB9-DE12-2(A11-)CD11-DB10-AD11-2D10-2E11-2E10-AD11-AC10-BA11-DC11-B11-C12-EC9-BE13-BA7-CB15-DACAE2(BD)18-CBE2C244-2ADECDB16-DBA5-CAD13-DC9-CD11-ED11-BE10-D13-A9-2C13-DA2(8-C15-D)8-E15-E8-B15-A8-D15-D8-CD13-CD9-D13-D10-EB11-AE11-DB9-2C13-CAC5-2BD16-2BAEACA193-DCAECDC16-CB7-CA13-C11-D11-A13-D9-E15-E8-C15-A7-B17-A6-A17-B6-D17-A6-E17-E6-B17-A6-C17-D6-B17-D7-A15-C8-E15-E9-B13-2(D11-)C13-AD7-DB16-CADEBAC144-ABEAC17-CAC5-2AC13-D11-B11-A13-D9-E15-E7-C17-A6-B17-D6-A17-D5-B19-A4-A19-A4-E19-E4-B19-A4-C19-A5-A17-D6-B17-A6-D17-B7-E15-E9-D13-D11-A11-B13-BCD5-3A17-BDEAB118-BD2CEC2DB14-DC9-BD11-A13-B9-A15-B7-E17-E6-B17-D5-C19-A4-B19-B4-D19-B4-B19-D4-E19-E4-A2(19-C4-D)19-B4-B19-A5-D17-A6-E17-E7-D15-B9-C13-A11-DC9-2B14-BDBCE2(BA)92-ADAEBDA16-CD7-DA12-2D11-2B9-C15-C7-E17-E6-B17-A5-C19-A4-B19-A3-B21-D2-B21-A2-A21-A2-E21-E2-C21-C2-B21-A2-B21-C3-A19-D4-B19-D5-C17-D6-E17-E7-B15-C9-BD11-AB12-BD7-DC16-ABCEACD67-B2DAEAC2A14-BC9-AD11-B13-A9-D15-A7-E17-E5-C19-D4-B19-A3-C21-C2-B21-A2(2-D21-C)2-E21-E2-B21-A2-A21-A2-B21-A2-C21-D3-C19-A4-D19-D5-E17-E7-A15-B9-B13-B11-AB9-CA14-CA2CEB3A44-BEB18-A3C3-2DBC13-C11-C10-DC13-AC7-C17-B6-E17-E5-B19-D3-A21-C2-B21-B2-D21-A2-C21-B-D23-BE23-EC23-A-A21-D2-D21-A2-A21-B2-C21-C3-B19-A5-E17-E6-A17-B7-DC13-AC10-C11-D13-BCBA3-A2CD18-DEC21-ADEAC17-C2A5-B2D12-CD11-CA9-D15-B7-A17-A5-E19-E4-C19-A3-A21-C2-B21-D2-A21-A-B23-2C23-DE23-EA23-BD23-B-A21-D2-C21-C2-D21-B3-C19-A4-E19-E5-C17-C7-D15-C9-2A11-BA12-ADB5-A2B17-BAE2B19-ACDEDBC16-CA7-2B12-AB11-BD9-A15-B7-B17-D5-E19-E4-A19-A3-D21-A2-A21-D-B23-CD23-2A23-BE23-EA23-AC23-DB23-A-B21-A2-C21-B3-C19-C4-E19-E5-A17-A7-D15-A9-CB11-AC12-DA7-BD16-DBCEB2C18-C2BE2BD16-CD7-BC12-DC11-CD9-A15-A7-C17-B5-E19-E4-B19-D3-B21-D2-A21-D-D23-AC23-CA23-DE23-EA23-BC23-AD23-C-B21-D2-B21-A3-A19-D4-E19-E5-D17-D7-D15-C9-CA11-DA12-AC7-2A16-3CED2B18-CBDECBD16-2B7-2B12-BA11-CB9-A15-D7-B17-C5-E19-E4-D19-A3-D21-D2-C21-A-C23-CD23-2A23-DE23-EA23-CD23-AD23-D-A21-C2-B21-D3-A19-B4-E19-E5-C17-D7-A15-A9-AB11-BA12-2A7-BD16-ABAE2DA19-BCECA17-B2C5-CAC12-AD11-BD9-B15-C7-D17-B5-E19-E4-D19-B3-C21-B2-B21-B2-D21-B-B23-AD23-DE23-ED23-2A23-A-C21-C2-B21-A2-A21-D3-C19-A4-E19-E5-A17-C7-D15-B9-2B11-BA12-DAC5-C2B17-DBECB21-AEC18-ABDC3-A3D13-A11-A10-DA13-2A7-B17-C6-E17-E5-D19-B3-D21-C2-A21-B2-B21-A2-C21-D-C23-AE23-EA23-D-C21-C2-D21-A2-B21-B2-C21-A3-D19-D5-E17-E6-B17-A7-2B13-CA10-C11-D13-2BAD3-C2DB18-BEB44-C3AECD2A14-DA9-2C11-C13-D9-C15-D7-E17-E5-C19-A4-A19-C3-A21-A2-D21-D2-D21-C2-C21-B2-E21-E2-D21-C2-C21-A2(2-B21-D)3-D19-C4-C19-A5-E17-E7-D15-A9-D13-A11-CD9-BA14-2B2CE2(CD)67-ADCEBDC16-BD7-2D12-CA11-BC9-B15-C7-E17-E6-B17-B5-C19-C4-B19-B3-A21-A2-A21-C2-D21-D2-E21-E2-C21-B2-D21-D2-A21-B3-B19-C4-A19-C5-B17-A6-E17-E7-C15-B9-BA11-2B12-BC7-2D16-B2DE2DA92-DADCEDACB14-CA9-CD11-A13-C9-A15-A7-E17-E6-D17-C5-D19-B4-D19-C4-A19-C4-B19-B4-E19-E4-D19-C4-C19-D4-A19-D4-B19-B5-D17-B6-E17-E7-B15-B9-D13-B11-CA9-AC14-ABCDEB2CB118-2AEBC17-DBC5-DBA13-C11-A11-C13-A9-E15-E7-A17-B6-D17-C6-A17-A5-C19-B4-A19-B4-E19-E4-C19-A4-B19-D5-A17-D6-D17-B6-C17-B7-E15-E9-D13-C11-B11-A13-B2C5-ACD17-CBE2D144-DBAEBAC16-BA7-AC13-2(C11-)C13-A9-E15-E8-A15-C7-D17-C6-D17-A6-C17-D6-E17-E6-B2(17-B6-A)17-C7-D15-B8-E15-E9-D13-D11-C11-B13-2B7-2D16-CABE2DB193-CABECBC16-CDC5-BDA13-BA9-BC11-EB11-BE10-B13-C9-2C13-2C8-C15-A8-D15-C8-E15-E8-A15-D8-B15-A8-CD13-BA9-C13-D10-EB11-CE11-AB9-2A13-A2C5-CAB16-CACEDCB244-2BEAD18-CB2DEADAB15-2A7-2A13-EA9-CE12-2(D11-)CA11-AB10-DB11-AC10-2E11-2E10-2B11-DB10-AB11-2A11-D11-A12-EA9-DE13-DA7-DC15-B3AEA3B18-DAECB319-3CEACA17-DABCE2DCD15-ECDA3-2ACE14-E2A5-ABE14-EB7-DE14-2E7-2E14-EA7-AE14-EDB5-ABE14-EADA3-2DAE15-2CBCEDCDB17-D2CEDBC420-AEC21-BDECA19-2ACEC2A18-7E18-2ADEB2D19-DCEDC21-BEC236-
