model
size = 32 28 32, scale = 0.05, origin = -y
material 
  colors = A:#222 B:#050 C:#FC0 D:#B00 E:#700 F:#A00 G:#500 H:#D00 I:#111
voxels
335-2C1349-2(F31-)D51-B7-B23-B30-B31-B9-B22-B8-B23-B6-B25-B4-B29-2B16-A28-A2-2A26-AI3-2A24-AI5-2A22-AI7-4A17-2AI12-3A12-2A17-2A9-2A21-2A5-2A25-5A27-4A196-2(F31-)H2(31-F)50-2B7-B22-B9-B21-2B8-B22-2B32-B6-B25-4B-B27-3B-B13-C4A10-2B10-4A2C6A8-B9-5AC2-C7A14-7AC3-C26AC5-C23A2C7-2C20AC11-2C16A2C14-2C12A2C18-2C8A2C22-2C4A2C26-4C132-2(D31-)H31-E31-H31-D183-B31-2B-B27-6B13-7A7-B3A7-7AC30A2C4-22A4-C7-18A16-14A20-10A25-4A29-2A229-2(F31-E31-)D214-B31-B4-2B25-2B2-2B14-14A2B14A-32ACA8-A3-4A3-A8-2A-C13-2A14-C309-D32-D31-F31-E30-D31-D246-B6-B23-2B6-2B12-12A2B2-2B12A2-13A4B13A2-2A9-2A4B2A9-2A2-2A9-3A2B3A9-2A2-C11-6A11-C14-6A27-4A227-2(F31-)2(E31-)D276-2B8-2B21-B8-B14-9A2B5-B9A5-10A2B4-2B10A3-3A7-2AB4-B2A7-3A2-3A7-2A2B2-2B2A7-3A3-A8-2A6B2A8-A4-C9-2A4B2A9-C15-2A2B3A25-6A27-4A131-2(D31-)E31-G2(31-D)275-2B10-B20-B10-B14-7AB8-B7A7-8AB8-B8A5-2(3A5-2AB6-B2A5-3A4-)2A6-2AB6-B2A6-2A4-2A7-2AB4-B2A7-2A4-C9-A2B2-2B2A8-C14-2A4B2A23-9A129-2(D31-)E2(31-D)307-B12-B17-2B12-B14-5AB10-B5A9-6AB10-B6A7-3A3-2AB8-B2A3-2(3A5-)2(AB8-BA5-3A4-3A5-)2AB6-B2A5-3A5-A6-2AB6-B2A6-A6-C7-2AB4-B2A7-C14-3A4B2A25-6A98-D31-E31-G31-F338-B14-B15-2B14-B14-3AB12-B3A11-5AB10-B5A9-3A2-AB10-BA2-3A7-3A3-AB10-BA3-3A6-2A4-AB10-BA4-2(2A6-2A5-AB8-BA5-)2A6-C6-2AB6-B2A6-C14-2A6B2A24-6A28-2A35-2(D31-)E31-F31-D339-B2(14-2B)14-B14-3AB12-B3A11-4AB12-B4A9-3A2-AB10-BA2-3A8-2A3-AB10-BA3-2A7-3A3-AB10-BA3-3A6-3A3-AB10-BA3-3A7-2A4-AB8-BA4-2A8-A5-2AB6-B2A5-A8-C6-2A2B2-2B3A5-C16-3A2B3A26-4A2-2(D31-)2(E31-)F370-2B14-B16-B14-2B14-2AB12-B2A13-3AB12-B3A11-3A-AB10-BA-3A10-2A2-AB10-BA2-2A9-3A2-AB10-BA2-3A8-2A3-AB10-BA3-2(2A8-2A4-AB8-BA4-)2A8-C5-2A2B4-2B2A4-A17-2A4B3A5-C18-6A-D31-E31-G31-F31-D370-2B14-B16-2B13-2B14-2AB12-B2A13-3AB12-B3A12-2A-AB10-BA-2A11-2A2-AB10-BA2-2A10-2A2-AB10-BA2-2A9-3A2-AB10-BA2-3A8-3A3-AB8-BA3-3A9-A4-AB8-BA4-A10-A4-2AB6-B2A4-A10-C6-A6B2A5-C18-6A-D31-E2(31-D)402-2B14-B16-B14-2B14-2AB12-B2A13-3AB12-B3A2(12-2A-AB10-BA-2A)11-2(2A2-AB10-BA2-2A10-)2(2A3-AB8-BA3-2A10-)2A3-2A2B4-2B2A3-2A11-C5-2A4B3A4-C19-6A-F30-E31-D436-B2(14-2B)14-B15-2AB12-B2A14-2AB12-B2A13-2(2A-AB10-BA-2A12-)2A-AB10-BA-2A11-3A-AB10-BA-3A10-2A3-AB8-BA3-2A10-2A3-2AB6-B2A3-2A10-2A4-2A2B2-2B3A3-2A11-C5-3A2B2AD5-C20-5AG2(31-D)436-B14-B15-2B14-B16-AB12-B2A2(14-3AB10-B3A)13-4AB10-B4A12-2A-2AB8-B2A-2(2A12-2A2-AB8-BA2-)2A12-2A2-2AB6-B2A2-2A12-2A3-2A6B3A2-2A13-C5-6AD4-C21-5AE31-D467-3B12-2B17-2B11-B17-2AB10-B3A15-3AB8-B2AGA14-4AB8-B4A14-2A-AB8-BA-AGA13-2A-AB8-BA-AGA2(12-2A2-2AB6-B2A2-2A)12-2A3-2A2B2-2B2A3-2A12-2A4-3A2B4A3-2A13-C6-5AE4-C25-AD502-B10-B19-3B9-2B17-2(3AB8-B3A16-)4AB6-B4A15-2A-2AB6-B2A-3A13-2A2-A2B4-2BA2-AGA13-2A2-2AB4-B2A2-AGA12-3A2-2A6B2A2-2A14-2A3-3A2B4A2-2A14-A5-6AE4-A14-C11-D4-C529-2B8-B21-3B7-3B18-3AB6-B3A17-4A2B4-2B4A2(16-2A-2A2B2-2B2A-2A)15-2(2A3-2A4B2A3-2A14-)2A3-7AH3-2A14-2A4-6AF3-2(2A14-)2A15-C14-AC530-2B6-2B22-3B5-2B21-3A6B3A19-5A4B5A17-3A-3A2B3A-3A16-2A3-2A2B2A2(3-2A16-2A3-6A)E2-3A14-2A5-4A-D3-2(2A14-)2A15-A14-2A15-C14-C533-2B2-2B25-3B2-3B22-5A2B5A19-3A-6A-3A18-2A3-4A3-2A17-3A3-4A3-3A16-2A4-4A4-2A16-2A9-E2-2A15-3A12-2A16-2A12-2A17-A13-C17-C549-2B27-7B24-10A21-3A2-2A2-3A19-3A3-2A3-3A18-2A10-2A17-3A10-3A3(16-2A12-2A)17-2A11-C18-C609-10A21-3A6-3A20-2A8-2A19-3A8-3A3(18-2A10-2A)18-2A11-A18-2A11-C18-C610-8A23-3A4-3A21-3A6-3A20-2A8-3A3(18-2A10-2A)19-C10-C20-C641-8A23-3A4-3A21-3A6-3A3(20-2A8-2A)20-A10-A20-C10-C662-8A23-3A4-3A22-2A6-3A20-3A6-3A2(20-2A8-2A)21-C8-C696-6A24-3A4-3A2(22-2A6-2A)22-A8-A22-C8-C728-6A25-3A2-3A23-3A4-3A22-2A6-2A23-C6-C762-4A26-3A2-3A24-2A4-2A24-A6-A24-C6-C792-8A24-2A4-2A25-C4-C826-2A2C2A27-C2-C558-
