model
size = 23 25 31, scale = 0.05, origin = -y
material 
  colors = A:#111 B:#FF9 C:#A00 D:#F00 E:#777 F:#DDD G:#FC3 H:#EEE I:#FCD021
voxels
217-2A20-4A20-2A21-2A436-A20-4A18-3(6A17-)6A18-4A410-4A18-6A16-3(8A15-)8A16-6A18-5A19-2A364-6A16-8A15-8A14-10A13-10A14-9A14-8A15-8A16-6A19-2A341-6A16-8A14-5(10A13-)10A14-8A16-6A19-2A318-6A16-8A14-10A12-4(12A11-)12A12-10A14-9A15-6A19-2A296-4A17-8A14-10A12-6(12A11-)12A12-10A14-8A18-2A295-7A14-10A12-12A11-12A10-3(14A9-)14A10-13A10-12A12-11A13-8A17-4A272-4A17-9A12-12A11-12A10-14A9-14A8-16A8-3(14A9-)14A10-12A12-10A15-6A270-7A14-10A12-12A10-14A9-14A8-3(16A7-)16A8-15A8-14A9-14A11-10A14-8A268-8A13-12A10-14A9-14A8-16A7-2(16AE5-E)2(16A7-)16A8-15A8-14A10-12A13-8A267-10A12-12A10-14A9-15A7-16A6-18A5-17A2(E5-E16A)E6-16A7-16A8-14A10-12A12-10A16-4A246-10A12-12A10-14A8-16A6-4(18A5-)E16AE6-2(16A7-)16A9-12A12-10A15-6A245-10A12-12A10-14A8-16A6-4(18A5-)E17A2(5-E16AE)3(6-16A9-12A12-10A15-6A245-10A12-12A10-14A8-16A6-6(18A5-)E16AE)6-16A9-12A12-10A15-6A14-3A6C3A11-A3C4B3CA10-2AC-2G2B2G-C2A9-AC10-CA8-AC12-CA6-AC14-CA5-AC14-CA4-AC16-CA22-A31-10A12-12A10-14A8-16A7-16A6-5(18A5-)E16AE6-16A9-12A12-2A6-IA21-A12-2A2C6B2C2A9-ACG8BGCA9-AC2-6BG-CA8-AC12-CA6-AC14-CA5-A16-A4-AC16-CA3-A18-A2-AC18-CA22-CA6-10A12-12A10-14A9-15A7-16A6-4(18A5-)18A6-16AE7-14A10-12A13-A6-IA16-2A4-2A9-2AC10BC2A7-ACG10BGCA7-AC2-8B2-CA6-AC5-4B5-CA5-A16-A4-AC16-CA3-A18-A2-AC18-CA-A20-A23-C7-8A13-12A10-14A9-14A8-2(16A7-)16A6-18A5-18A6-17A7-14A10-13A9-AB9AC2A9-3AB5A2B3A9-5A7BCA9-A12BA8-A-G10B-GA6-AC3-8B3-CA5-A6-4B6-A4-AC16-CA3-A18-A3-C18-C2(A-C20-)C31-8A14-10A12-12A10-14A9-14A8-3(16A7-)16A8-15A8-14A10-12A10-2A9B3A9-AC8B2ACA9-A12BA8-AC12BCA7-A2-10B2-A6-A4-8B4-2(A5-)6B5-A4-C18-C3-C18-C23-C22-C55-6A15-10A12-12A11-12A10-5(14A9-)14A10-13A10-12A10-AC10BCA9-A12BA8-AC12BCA7-A-12B-A6-AC2-10B2-CA5-A4-8B4-A5-C5-6B5-C150-A2FA17-8A14-10A12-12A11-12A10-3(14A9-)14A10-12A10-2AB10A11-AB9A11-A12BA9-A12BA8-A-12B-A7-A-12B-A6-C3-10B3-C5-C4-8B4-C12-4B179-A4FA16-8A14-10A12-4(12A11-)2(2A8B2A11-)A10BA11-A10BA10-A12BA9-A12BA8-C-12B-C7-C2-10B2-C10-10B14-8B17-4B202-A4FA16-8A14-4(10A13-)2A6B2A13-A8BA12-C10BA11-C10BA10-C-10B-C9-C-10B-C11-10B13-10B14-8B16-6B248-F2CFA17-AF2CFA16-2(AF4AFA15-)C6AC14-CA6BAC13-C8BC14-8B-2(C12-10B)13-10B14-8B15-8B16-6B19-2B297-2C20-A2CA18-CA2CAF16-C6BC5(15-8B)16-6B17-6B19-2B387-6B16-8B15-8B16-D4BD18-4B17-3A2B3A15-8A454-4D17-D2B2D2BD16-6D524-H2DH18-DH2DHD17-6D525-2D19-D4-D18-4D309-
