model
size = 18 25 32, scale = 0.05, origin = -y
material 
  colors = A:#111 B:#FCD021 C:#F00 D:#DDD E:#777 F:#933 G:#444 H:#700
voxels
332-2C286-2A15-4A15-2A16-2A341-A15-4A13-3(6A12-)6A13-4A320-4A13-6A11-3(8A10-)8A11-6A13-5A14-2A284-6A11-8A10-8A9-10A8-10A9-9A9-8A10-8A11-6A14-2A266-6A11-8A9-5(10A8-)10A9-8A11-6A14-2A248-6A11-8A9-10A7-4(12A6-)12A7-10A9-9A10-6A14-2A231-4A12-8A9-10A7-6(12A6-)12A7-10A9-8A13-2A230-7A9-10A7-12A6-12A5-3(14A4-)14A5-13A5-12A7-11A8-8A12-4A212-4A12-9A7-12A6-12A5-14A4-14A3-16A3-3(14A4-)14A5-12A7-10A10-6A210-7A9-10A7-12A5-14A4-14A3-3(16A2-)16A3-15A3-14A4-14A6-10A9-8A208-8A8-12A5-14A4-14A3-16A2-2(16A2E)2(16A2-)16A3-15A3-14A5-12A8-8A207-10A7-12A5-14A4-15A2-16A-35A2(2E16A)E-16A2-16A3-14A5-12A7-10A11-4A191-10A7-12A5-14A3-16A-72AE16AE-2(16A2-)16A4-12A7-10A10-6A190-10A7-12A5-14A3-16A-72AE17AE16A2E16AE-16A4-12A7-10A10-6A190-10A7-12A5-14A3-16A-108AE16AE-16A4-12A7-10A10-6A68-2B16-2B102-10A7-12A5-14A3-16A-108AE16AE-16A4-12A7-10A10-6A14-2B14-2(6B12-)2(7B11-)6B13-5B64-10A7-12A5-14A3-16A-108AE16AE-16A4-12A7-10A10-6A12-6B11-8B10-9B2(8-10B)9-8B10-8B11-6B14-2B30-10A7-12A5-14A3-16A2-16A-90AE16AE-16A4-12A7-D8BA10-6B11-8B9-5(10B8-)10B9-8B11-6B28-10A7-12A5-14A4-15A2-16A-90A-16AE2-14A5-12A8-A7BD9-8B9-10B8-10B7-3(12B6-)12B7-10B8-10B9-8B12-4B12-8A8-12A5-14A4-14A3-2(16A2-)16A-36A-17A2-14A5-13A6-10A9-D6BD10-9B8-10B7-5(12B6-)12B7-10B9-8B12-5B11-8A9-10A7-12A5-14A4-14A3-3(16A2-)16A3-15A3-14A5-12A7-9AD9-D6BD9-10B8-11B6(6-12B)7-10B9-8B11-6B12-6A10-10A7-12A6-12A5-5(14A4-)14A5-13A5-12A8-8AD9-D7B9-10B8-11B6(6-12B)7-10B9-8B11-6B13-4A12-8A9-10A7-12A6-12A5-3(14A4-)14A5-12A6-12A7-10A9-D6AD11-6B11-9B8-10B7-5(12B6-)12B7-10B9-8B12-5B30-6A11-8A9-10A7-5(12A6-)12A7-10A9-D6AD11-6D12-6B11-8B9-10B8-11B4(6-12B)7-10B8-10B9-8B12-4B49-6A11-8A9-5(10A8-)10A9-AD4ADA11-2D2H2D31-4B13-6B11-8B9-2(10B8-)2(11B7-)10B8-10B9-8B11-6B85-A2G2A12-2A2G2A11-3(8A10-)3A2F3A11-AD2FDA13-D2FD84-8B10-9B3(8-10B)9-8B10-8B11-6B14-2B124-2G15-A2GA14-A2FA139-7B4(10-8B)11-6B12-6B14-2B320-6B11-C6BC11-C4BCB12-4B12-3A2B3A10-8A353-C4BC11-C6BC11-6C409-4C13-C3B2C12-6C427-4C14-4C133-
