model
size = 22 31 17, scale = 0.05, origin = -y
material 
  colors = A:#111 B:#FC0 C:#693 D:#9C3 E:#6C3 F:#F63 G:#F33 H:#F90 I:#C33 J:#CC3 K:#C63 L:#FF0 M:#CC0 N:#963 O:#A00 P:#0C3 Q:#933
voxels
340-4D22-D15-2IKNK16-3B2H2B14-10B13-5D5B12-6C4D12-2(2GQ)3C13-4B5G14-5B2HB19-2B126-A2-L18-A2-A34-A13-A7-A22-3(A21-)A44-A21-A65-3D21-7D14-7C3D12-KN2IKNK2C12-H4B2HBKB2I10-11B2H10-7D6B8-6C-C4D11-3GQ3-4C11-7B4G11-7B2H2B12-5E5B14-4C3E19-C78-A4-A2-A13-A4-A2-A12-A4-A2-2A12-A4-A2-A5-A7-A4-2A-A4-LA8-A10-2A9-A9-PA10-A9-A11-A8-2A20-AO2(12-A8-A)12-A-2A2-A2-2A11-A-A4-A2-2A8-2D3AD2(3-A)10-9D-2A10-8C6D7-H2KN2IKNK4C8-2BH4B2-B2K3I10-3B4-3B3H8-3D6-5B8-2C8-4D8-3G7-4C8-3B7-4G8-4B6-4B9-7E-4B11-6C4E15-3F3C19-F56-L21-A18-A-2A3-A2-2A10-P-2A3-A2-A11-A-2A3-2A-2(A5-)A-2A4-P-A3-2A6-A-2A4-A-A3-A8-A6-A-A2-A9-A6-2(A-)2A9-A6-2(A-)A10-A6-A-A2-A9-A5-2A-A2-A9-A2-A-2A2-A2-2A11-A-A4-A2-2A7-3D3AD2(3-A)8-2CD9-2A8-IKC10-4D5-2HK10-3C5-3BH10-2I2K5-DB12-3HB4-2C12-4B4-2G13-2D5-2B13-2C6-2B12-2G7-2B10-3B7-2E10-2B8-4C7-3E10-6F-4C12-5B3F19-2B31-A-2A18-A-2A17-3(A21-)A7-A-A11-A7-4(A-A12-3A4-)A-A12-3A3-2A-A12-3A19-A-A19-3DA19-2C20-IK12-3D4-3H12-3C4-3B12-I2KI4-2D13-2HB4-2C13-3B4-2G14-DE4-2B14-2C4-2B14-GF5-B13-3B6-2E11-BL7-3C9-2E10-3F5-4C10-6B-3F15-3J3B30-2(A21-)2A19-O2A19-AO197-A20-3D20-2C20-2I15-2D2-B2H15-2C2-L-B15-KI3-D16-H2B2-C16-3B2-2G16-E3-2B16-C4-2B14-GF4-2E14-2B4-2C14-LB6-2C11-2E7-4F8-3C9-3B4-4F14-3J-3B17-MJ10-2A20-2A24-2(2A20-)3(2A15-2A3-)2A15-2A130-3D-2D17-2C19-3I15-3D-B17-3C2L17-K2I-ED17-2B-2C17-2B2-G17-2E2-B17-2C2-LB16-F4-2E15-B4-2C14-LB20-EC6-3F9-3C7-5B5-4F13-3J-4B16-MJ13-2A20-2A153-2(2A15-2A3-)3(2A16-2A2-)2A15-2D2-2A17-C20-2I18-D2B18-2C2LB17-2I-ED17-2B-2C17-2B-FG18-E2-B18-C2-L17-2F3-E16-B4-2C15-B5-F14-EC6-F13-CK6-2B10-2F10-6J3-3B14-2M2JMJ56-2A20-2A21-AO20-2A168-2A19-2D21-C20-2I18-D2BH17-2CL-B17-2I-ED17-2B-2C17-2B-FG18-E-2B18-C2-L18-F3-E16-B4-2C15-B5-F14-EC6-F13-CK6-2B10-2F10-6J4-2B14-2M2JMJ12-2A20-2A109-3(2A20-)2A36-2(2A20-)2A19-2D21-C20-2I17-2D2B18-2C2LB17-2I-ED17-2B-2C17-2B-FG18-E2-B18-C2-L17-2F3-2E15-B4-2C15-B5-F14-EC6-2F12-CK6-3B9-2F10-6J2-4B15-M2JMJ51-2A20-2A153-2A3-2A14-2A4-2A19-2A20-2A14-3D3-A16-2C20-2I15-3D-B2H15-3C-L17-K2I2-D16-H2B2-C17-2B2-G17-E3-2B16-C3-LB16-F4-2E14-2B4-2C14-LB6-C12-2EC6-3F9-3C8-4B5-4F13-3J-3B17-MJ9-2A2-A17-2A2-A40-2A21-6(2A20-)2A85-2D2(-A)16-2C20-2I15-2D2-B2H15-2C2-L2B15-KI3-2D15-H2B2-2C15-3B2-2G15-DE3-2B15-2C4-2B14-GF4-2E14-2B5-CE13-LB6-2C10-3E7-4F8-2C10-3B4-4F14-3J4B18-J13-A21-L20-3(A21-)A7-A13-A7-A-A19-3(A-A12-A6-)A-A12-A5-2A-A12-A-2A5-A12-A-2A16-2DA-A17-2C20-IK12-4D3-H-H12-3C4-B-B12-I2K5-2D12-3HB4-2C13-3B4-2G13-2DE4-2B14-2C4-2B13-2GF6-B12-2B7-2E10-2BL7-3C8-3E10-4F-F2-3C12-5B4F18-2B36-L21-A18-A-A4-A14-A-A4-A2-2A10-A6-2A-2(A5-)A7-P-A3-2A6-A7-O-A3-A15-A-A2-A9-A6-2(A-)2A9-A6-2(A-)A10-A6-A-A2-A9-A5-2A-A2-A9-A2-A-2A2-A2-2A8-A2-A-2(A3-)2A6-2D2-3A4-A3-A5-2C2D8-A2-2A5-IK2C8-3DAD5-2H2K8-4C6-B-H9-3IK6-2DB11-3H5-2CD11-4B4-2GC11-3D6-BG11-3C6-2B11-3G7-2B10-2B8-3E9-2B9-4C5-3E11-6F-3C14-4B3F19-B37-A4-L16-A4-A2-A12-A4-A3-A12-A4-A2-2A4-A7-A4-2A-A4-L2(A7-)A3-2A9-A9-PA10-A9-A11-A8-2A11-A8-AO2(12-A8-A)12-A-2A5-2A11-A-2(A3-)2A10-3A4-A3-A8-8D-A2-2A7-8C6D8-2KN2IKNK4C9-BH4B2HB2K2I10-11B3H8-5D3-3B-2B8-4C5-4D9-4G5-4C9-5B4-4G10-4B4-H3B11-6E4B12-6C4E18-2C107-A2-L18-A2-A26-A7-P21-A22-O3(21-A)22-A21-A86-6D16-5C3D14-N2IKN2C14-4B2-3K12-4B-6BH12-5DB-4B11-5C5D12-2GQ2G5C12-5BQ4G12-6B2H2B14-3E4B17-C2E500-4B17-5B2H15-5E4B15-3C4E15-3F2C17-3B2F18-4B20-2B118-
