model
size = 26 16 20, scale = 0.05, origin = -y
material 
  colors = A:#562E17 B:#84492C C:#000 D:#FEEA41 E:#037C30 F:#A9523A G:#822D1B H:#94453E I:#A17A43 J:#8E695F K:#01512E L:#FFF M:#259A3E
voxels
135-C25-C51-2(C25-)C6-3A23-A-A23-3A251-C84-2A47-C255-C23-2CA23-3C5-4A22-2(A2-A18-4C)22-3C23-C205-AC22-2CBC21-C2BC5A-3A13-C3B15A7-5C14A7-5C5B9A8-4C4B3A4-3A11-4A3-A200-7A16-C2-B6A16-C2AB14A7-6C4-2B7A7-12C3A11-C2F2B7D7A7-C4B6DB8A6-C4B5L10A7-2C2B2AB5A3-2A11-2A2-2A-2A21-A134-A17-2AC4A16-C2-7B15-CB2A4B3-8A7-12C7A7-12C3A4-A5-C4F8D4AH3A5-C12B4AH3A6-C9B6AB4A6-C3B2A3B10A8-3C2-3E2A-A15-2C2-3E125-2C6A15-5C4B2A13-2C2A7B2A12-C2B2A4B3-8A6-13C7A6-13C4A-3A5-C-3F8D8A5-C12B9A5-C11B9A6-C7B-2B9A7-A2BAK3E2B8A8-4A-3E5A18-K2EA3-A68-11A15-A6B4A11-C4A6B7A7-2C10B7A6-C8B4-7A6-13C7A5-14C9A3-C6F7D9A4-C12B9A5-C11B9A6-C6B2-2B9A7-A4B3E2B9A7-3A2C2E-11A12-M2KA47-5G2A2G2(16-A9B)G3A8-C4A12BA6-2C17BA5-C19BA6-14CI3B-A5-15C4IB5A-C6F6D2J4IB5A-C14B4IB5A2-2C20BA5-C6B2-11BA6-C4B3E11BA6-3CKB2E-11A11-M2KMA47-2(GA)G2AGAG2A13-C12BA12-C12BA7-6C12BA6-C18BA5-C19BA5-15CI3B-A5-15C4IB5A-C6F6D2J4IB5AC15B4IB5A-3C15BH4B2A3-3C5B2-2BC8B2A5-A4B2E-11BA6-3A2B3E12A9-3ECEA47-GA3G2A5G13-A12BA12-13BA7-2C3A7B8A5-C12B8A4-C13B8A3-15C5A-4A2-14C5A-2A2BA-C6F6DJ5A-2A2BAC14B5A-2A2BA-3C15BH-4BA3-4C13B-4BA4-C5B3E6BH-5A5-5A-E-B11A12-E2-A6-C2-A36-12A13-A12BA12-13BA7-2C3A7B6A-A5-C12B6A-A4-C13B8A3-15C10A2-14C8A2BA-C6F6DJ8A2BAC14B8A2BA-3C15B2H4BA3-5C17BA4-C9BD3BJ2H4BA5-3CAC3A4B4AB3A15-2BA4-C2-A15-2AC18-2G5A2G2AG13-C12BA12-C12BA7-6C6B6A-A5-C12B6A-A4-C13B8A3-15C5A-4A-CF13C8A2BA-C6F6DJ8A2BAC14B8A2BA-3C15B2H4BA3-6C-15BA4-C8B4D2J3H3BA5-3AC4A4B4AB3A15-B2A4-C2-A15-2AC18-AG5AG2A2G13-C12BA12-13BA7-2C3A7B8A5-C12B8A4-C13B8A3-15C5A-4A2-14C8A2BA-C6F6DJ8A2BAC14B8A2BA-3C9B-5B2H3B2A3-4C17B2A5-A4BC6B2J3H2BA6-8AB11A15-A6-C2-A36-5G3A2GAG13-A12BA12-13BA7-2C3A7B8A5-C12B8A4-C13B8A4-14C10A4-12C8AB2A2-C4F7DJ8AB2A-C13B8AB2A2-2C9B-5B2H3BA5-2C18BA6-A8BC3BJ3H2BA6-5A2E-12A12-E-A47-11AG10-C2-C5A4B4A12-C5A4B4A7-2CA3C6B7A6-C12B7A5-C13B7A6-13C10A3-13C8ABA3-C4F7DJ8ABA3-C12B8ABA4-C9B-5B2H2B2A5-4C15B2A6-3C4BEBE8B2A6-3CAK3E11A12-EKEA52-4A22-4A16-C9A11-2C13A10-C5B11A9-C12B2(6A8-12C)9A4-C3F9D9A4-C12B9A5-C9B-5B2HB2A6-C5BH11BA8-A4B-BEBC7BA8-2AC2B3E10A11-M4KA119-2C9A14-C5B11A9-C12B2(6A8-4C6-CB)6A7-C2F-9D9A4-C12B7A7-C9B-5B3A8-C14B4A8-A3BH2BE5B5A8-3A2B3E5A16-2EMCEA3-A116-4C6A15-C10A15-C10B7A2(7-CBC2B6-CB6A)8-2C2B8D7A7-2C2B6D-B7A8-CA3B4L9A9-A3B2-2B10A8-3C4BE9A10-2CAB3EA2-A18-K2EMA155-A16-CA6C3A14-3C7AC7A8-3C5ACAC7A10-6C11A9-C6AB-B7A10-3AC2AB-8A10-3C4A-A4-3A10-6A22-2A2E25-E40-
