model
size = 21 32 31, scale = 0.05, origin = -y
material 
  colors = A:#900 B:#030 C:#E00 D:#BBB E:#3F9 F:#000 G:#FC0 H:#CCF I:#999 J:#66C K:#002
voxels
199-B20-A629-B19-2BF18-2AF19-AF19-B587-B20-BA18-4A17-3A18-2BA19-BA522-2(3A18-)2BA18-2B2A16-5A17-4A17-2B2A17-2BA19-2A19-A61-3A18-3A271-B19-2BF18-2AF17-3A2F15-4B3F15-3B2(3F14-4A)3F13-B-3B3F13-5B2(4F12-5A)4F13-4B3F15-3B2F17-2A2F18-AF12-G-K-G-2BF-G-K-G6-5G3B2F5G7-7A6F8-7A5F10-6B5F11-5B3F14-4A3F15-3A2F17-2BF164-3B2F15-4B2(3F14-4A)2(4F12-5B)2(4F11-6A)2(5F10-6B)5F9-2(7A6F8-)7B5F9-7B4F10-7A4F10-2HJ-3A2F-J2H7-2(GI)2G2BF2G2(IG)5-B5G3B2F5G5-9A7F6-8A7F6-8B6F8-7B2(5F10-6A)5F11-5B4F13-4B2F141-4B3A13-5B4A2(12-9A)11-2(6B5A10-)12A8-13A2(8-7B6A)7-15A6-15A2(5-9B7A)6-13A8-10A10-2B3G4B3A3G6-3BG5B4AG3A2(4-17A)4-9B7A6-8B7A6-14A8-13A8-7B5A10-6B5A11-9A14-5A98-5B4A11-6B5A10-11A9-13A2(8-7B6A)2(8-13A)8-7B6A7-8B7A5-3(2(17A4-)2(9B8A4-))2(17A4-)9B7A6-8B6A8-13A9-11A12-4B2A77-5B4F11-6B5F9-2(7A6F8-)2(7B6F8-)7A6F8-7A6F7-8B7F6-8B7F5-2(9A8F4-)9B9F2-10B2(2(9F2-10A)2(9F2-10B))8F3-10A8F4-9A2(8F4-9B)7F6-8A7F7-7A6F9-6B5F12-4B2F56-5B4F11-6B5F9-2(7A6F8-)7B6F8-7B2(6F7-8A)7F6-8B7F5-9B2(8F4-9A)8F3-3(2(10B9F2-)2(10A9F2-))10B8F4-9B8F4-9A8F5-8A7F7-7B6F9-6B4F15-2A37-5B4A10-7B6A2(8-13A)7-2(8B7A6-)15A5-16A5-9B8A4-9B8A3-18A3-19A2(2-10B9A)2(2-19A)2(2-10B9A)2-19A-20A2(-11B9A)-20A2-19A2(2-10B9A)2-18A4-17A5-8B7A7-7B6A9-10A33-5B4A10-7B6A8-13A7-15A2(6-8B7A)5-16A5-17A2(4-9B8A)3-2(19A2-)2(10B9A2-)19A-20A-11B10A11B52A11B10A11B51A-11B9A2-10B9A2-19A3-17A4-9B7A6-8B6A9-11A31-6B4F10-7B2(6F7-8A)2(7F5-9B)2(8F4-9A)8F4-9B8F3-10B8F3-2(10A9F2-)10B9F-11B2(9F-11A)2(2(10F11B)2(10F11A))2(10F11B)2(9F2-10A)8F4-9B8F5-8B7F7-7A5F12-4A3F12-6B5F9-7B6F7-8A7F5-9A7F5-2(9B8F4-)9A8F3-10A2(8F3-10B)2(9F2-10A)2(9F-11B)9F-3(2(11A10F)2(11B10F))11A9F2-10A9F3-9B8F4-9B7F6-8A6F10-5A4F11-6B5A9-7B6A7-15A5-16A5-9B8A4-9B8A2(3-18A)3-2(10B9A2-)19A2-19A-11B9A-3(11B52A11B10A)11B30A2-19A3-9B8A4-9B8A5-14A9-11A9-7B5A8-8B6A7-2B13A5-2B14A5-9B8A3-10B8A3-3B15A3-3B16A2(2-10B9A)2-3B16A-4B6AB2(9A-11B)10A2(2(4B17A)2(11B10A))2(4B17A)11B10A11B9A-4B16A2-3B16A2-10B8A4-9B8A5-B14A8-11A9-7C5E8-8C6E7-8C2(7A5-9C)2(8E3-10C)8A3-10C9A2(2-10C9E)2-10C2(9A-11C)9E-11C10E2(2(11C10A)2(11C10E))2(11C10A)11C10E11C9E-11C2(9A2-10C)8E4-9C8E5-8C7A8-6C5A10-6C5E9-7C6E7-8C2(7A5-9C)8E4-9C8E2(3-10C8A)3-10C8E3-10C9E2(2-10C9A)2(-11C9E)-3(2(11C10A)2(11C10E))11C9A2-10C9A3-9C8E4-9C7E6-8C6A9-6C4A11-6D5E9-7D6E7-8D7A6-8D7A5-2(9D8E4-)9D8A4-9D8A3-10D8E3-10D9E2(2-10D9A)2-10D2(9E-11D)2(2(10A11D)2(10E11D))2(10A11D)10E11D9E2(2-10D9A)3-9D8E5-8D7E7-7D6A10-5D3A13-5D4E10-7D6E7-8D6A7-8D7A6-8D2(7E5-9D)2(8A4-9D)2(8E3-10D)2(9A2-10D)9E2-10D9E-11D9A-11D10A2(2(11D10E)2(11D10A))11D9E-11D9E2-10D9A2-10D8A4-9D8E5-8D7E7-7D5A13-3D2A14-5C4E10-7C6E8-7C2(6A7-8C)2(7E6-8C)2(7A5-9C)8E4-9C8E3-10C8A3-10C9A2(2-10C9E)2-10C2(2(9A-11C)2(9E-11C))9A-11C9A2(2-10C9E)2-10C8A4-9C8A5-8C7E7-7C6E9-6C4A33-5C4E10-7C6E2(8-7C6A)8-7C2(6E7-8C)7A6-8C7A5-9C7E5-9C8E4-9C8A3-10C9A3(2(2-10C9E)2(2-10C9A))2-10C9E2-10C8E4-9C8A4-9C7A6-8C6E9-6C5E12-4C3A34-5D4E11-6D5E9-2(7D6A8-)2(7D6E8-)7D6A7-8D7A6-8D7E5-9D8E2(4-9D8A)3-2(2(10D9E2-)2(10D9A2-))2(10D9E2-)10D9A2-10D8A2(4-9D8E)4-9D7A6-8D7A7-7D5E11-5D4E54-5D4E11-6D5E10-6D5A9-7D6A2(8-7D6E)2(8-7D6A)7-8D6E7-8D7E5-2(9D8A4-)2(9D8E4-)2(9D8A4-)9D8E4-9D8E3-10D9A3-9D8A2(4-9D8E)2(4-9D8A)4-9D7E6-8D7E7-7D6A8-7D5A11-5D3E77-4C3E13-5C4E11-6C5A10-6C5A9-2(7C6E8-)2(7C6A8-)7C6E7-8C7E6-8C7A5-9C8A2(4-9C8E)4-9C8A4-9C7AE4-2C3G4C3E3G2E4-3CG5C4EG3E2(4-9C8A)2(4-9C8E)4-9C2(7A6-8C)6E8-7C5E10-6C5A11-5C4A97-4C3E14-4C3E13-5C4A12-5C4A11-2(6C5E10-)6C5A10-6C6A2(8-7C6E)7-2(8C7A6-)8C7E6-8C6E7-8C4A2E7-C2HJ2-2CAE-J2H6-C2(GI)2G2CE2G2(IG)5-C5G3C2E5GE2(4-9C8A)5-8C7E6-8C6E8-7C6A8-7C5A10-6C5E11-5C4E13-4C3A141-3D2E16-3D2A15-4D3A2(14-4D3E)14-4D2(3A12-6D)2(5E10-6D)2(5A10-6D)4E14-3D2E17-2D2A18-D13-G-K-G2-DE-G-K-G6-5G3D2E5G6-8D6A8-7D6A9-6D5E10-6D4E12-5D4A13-4D3A15-3D2E247-2(3D2E16-)2(3D2A16-)3D2E16-3D2E15-4D2A15-4D3A15-3D2(2E17-2D)2(A19-D)E17-3D2E13-6D4A11-6D4A13-4D2E16-3D2E18-D356-DA19-DE18-2DE17-3D2(2A17-2D)E18-2DE19-D545-D19-2DE18-2D2(A19-D)E607-DE19-DA19-D430-
