model
size = 19 32 32, scale = 0.05, origin = -y
material 
  colors = A:#200 B:#000 C:#200F00
voxels
27-2(4B15-)2(4A15-)4A16-2A489-5(6B13-)6A13-7(7A12-)6A14-5A15-3A35-3C16-3C15-5C13-7C12-7C11-9C9-11C7-13C5-16C4(2-17C)4-13C27-5(8B11-)A6BA8(11-8A)2(12-7A)10-12A9(6-13A)3-C2-14A2(-2C-15A)-2C17AC-C15A5-13C7-5(10B9-)A8BA9-A6BA-A9-10A3(9-2A7-A)10-A7-A10-A7-3A8-A2(7-3A7-2A)7-3A7-A8-3A6-2A9-2A6(6-A11-A)6-A11-2A2-C2(2-A11-2A-2C)-2A11-2A-2C-A13-A-2C2A13-2AC-CA13-AC3-C13-C6-4(11B8-)12B7-A9B2A7-A6BA-3A7-12A4(7-2A7-3A)8-A3(7-3A7-2A)7-3A7-A8-3A6-2A9-2A2(6-A11-A)6-2(A11-2A5-)2(A11-2A2-C2-)2(A11-2A-2C2-)A11-2A-2C-2A11-2A-2C-A13-A-2C2A13-2AC-CA13-AC3-C13-C5-4(12B7-)11BAB6-2A9B2A6-2A6BA-3A6-13A6-2(3A7-)7(2A7-3A7-)A8-3A6-2A9-3A4(5-A11-2A)2(2-C2-A11-2A)3(-2C2-A11-2A)-2C-2A11-2A-2C-A13-A-2C2A13-2AC-CA13-AC3-C13-C5-5(12B7-)2A9BA7-2A6BA-3A6-13A2(6-3A7-3A)6(7-2A7-3A)7-A8-3A6-2A9-3A3(5-A11-2A)2(2-C2-A11-2A)4(-2C2-A11-2A)-2C-2A11-2A-2C-A13-A-2C2A13-2AC-CA13-AC3-C13-C5-5(12B7-)2A9BA7-2A6BA-2A7-12A7-3A7-2A2(7-3A)6(7-2A7-3A)7-A8-3A6-2A9-3A2(5-A11-2A)2(2-C2-A11-2A)5(-2C2-A11-2A)-2C-2A11-2A-2C-A13-A-2C2A13-2AC-CA13-AC3-C13-C5-5(12B7-)2A9BA7-2A6BA-2A7-12A2(7-3A7-2A)2(8-2A7-2A)8-4(2A7-3A7-)A8-3A6-2A9-3A2(5-A11-2A)2-C7(2-A11-2A-2C)-2A11-2A-2C-A13-A-2C2A13-2AC-CA13-AC3-C13-C5-5(13B6-)2A10BA6-2A7B-2BA6-13A2(6-3A7-3A)2(7-2A)4(8-2A7-2A)8-2A7-3A7-A8-3A6-2A9-3A3(5-A11-2A)6(-2C2-A11-2A)-2C-2A11-2A-2C-A13-A-2C2A13-2AC-CA13-AC3-C13-C5-5(13B6-)2A10BA6-2A7B-2BA6-13A2(6-3A7-3A)7-2A7-3A2(7-2A)4(8-2A7-2A)8-A8-2A7-2A9-2A2(6-A11-A)6-A11-2A5-5(A11-2A-2C2-)A11-2A-2C-2A11-2A-2C-A13-A-2C2A13-2AC-CA13-AC3-C13-C5-5(13B6-)2A10BA6-2A7B-2BA6-13A6-2(3A7-)2(2A7-3A7-)5(2A7-2A8-)A8-2A7-3A8-2A6-2A10-4(A6-A11-)2(A2-2C2-A11-)2(2A-2C2-A11-)2A-2C-2A11-2A-2C-A13-A-2C2A13-2AC-CA13-AC3-C13-C6-3(12B7-)12B6-B2A10B6-2A10BA6-2A7B-2BA6-13A3(7-2A7-3A)2(7-2A)8-2A7-2A4(9-10A)8-12A7-2A9-5(A7-A10-)A2-C4-2(A10-A2-2C3-)A2(10-2A-2C2-2A)11-A-2C4A11-2AC-CA13-AC3-C13-C65-9B8-2BA7BA7-3A9BA6-3A6B-2BA6-13A2(7-2A7-3A)8-A7-3A8-2A6-2A2(9-10A)11-6A12-8A10-8(10A9-)10A3-C5-11A2-2C3-A10-A2-2C3-A10-2A-2C3-A11-A-2C4A11-2AC-CA13-AC3-C13-C65-9B8-ABA7BA7-3A9BA6-3A6B-2BA6-13A2(7-2A7-3A)8-2A6-3A8-2A5-3A10-6ABA11-7A53-2A16-4A15-4A14-2(6A13-)7A2(11-8A)10-10A9-2(10A3-2C4-)11A2-2C4-12A-2C17AC2-2C13AC4-14C65-9B8-ABA7BA7-3A9BA6-3A6B-2BA6-13A2(7-2A7-3A)8-2A6-3A8-6A-3A10-8A11-8A234-3(C16-C-)2C15AC4-13C84-9B8-ABA7BA7-3A9BA6-3A6B-2BA6-13A7-2A2(7-3A)6-3A8-2A6-3A8-6A-3A10-6ABA11-8A147-2C16-4C14-6C12-8C9-12C5-3(16C3-)16C102-9B8-ABA7BA7-3A9BA6-3A6B-2BA6-13A7-2A2(7-3A)6-3A8-2A4-A-3A8-10A10-8A12-6A411-9B8-ABA7BA7-3A9BA6-3A6B-2BA6-13A7-2A2(7-3A)6-3A8-2A4-A-2A9-10A10-8A428-10B8-2A8BA7-2A10BA6-2A7B-2BA6-13A7-2A2(7-3A)6-3A8-2A4-A-2A9-10A10-8A427-A10B8-A9BA7-A11BA6-A8B-2BA6-A-11A7-2A2(7-3A)6-3A8-2A4-A-2A9-10A10-8A427-A10B8-A9BA7-A11BA6-A8B-2BA2(6-13A)7-12A8-10A9-10A10-8A369-3(13B6-)A12B2(6-A11BA)6-A8B-2BA2(6-13A)7-12A8-10A9-10A387-3(13B6-)A12B2(6-A11BA)6-A8B-2BA2(6-13A)7-12A8-10A10-8A388-3(13B6-)3(A11BA6-)A8B-2BA2(6-13A)7-12A8-10A406-3(13B6-)3(A11BA6-)A8B-2BA2(6-13A)8-10A11-6A408-3(13B6-)3(A11BA6-)A8B-2BA6-13A7-12A9-8A427-2(12B7-)A11B2(7-A10BA)7-4A7BA7-A7B-2BA7-12A10-6A447-2(12B7-)3(A10BA7-)4A7BA8-A8BA9-9A13-4A449-2(10B9-)3(A8BA9-)3A6BA10-2A5BA11-7A468-2(8B11-)3(A6BA11-)2A5BA13-A2B2A14-4A470-2(6B13-)3(A4BA13-)2A2B2A15-2A483-
