model
size = 23 16 10, scale = 0.05, origin = -y
material 
  colors = A:#111 B:#FF3
voxels
68-2A645-19A348-B3ABA3B2A4BAB3AB346-2(A2B)AB4AB2ABAB3ABA322-A21-2A2(2BA)B4AB2ABAB3ABA45-13(2A21-)2A3(BA)3B2(2AB)AB3ABA22-2A183-A21-AB3(21-2B)21-BA21-2A3(BA)B4AB2AB2(A2B)A22-2A321-AB3ABAB4AB2ABA5BA22-2A322-B3ABA3B2A4B3(AB)23-2A323-19A2-
