model
size = 31 29 26, scale = 0.05, origin = -y
material 
  colors = A:#00FFFA B:#F00 C:#E900FF D:#000 E:#A64500
voxels
40-B11-B976-B17-B11-B19-B788-B13-2(B15-)B73-B21-B7-B23-B694-B11-B198-B23-B633-B9-B260-B25-B233-3B2(28-3D28-D-D)28-D-D2(28-B-B)28-D-D118-2B5-2B292-B25-B110-B30-A29-3D26-A-3C-A24-2A3C2A24-BA3CAB24-2B3C2B24-AB3CBA24-2A3C2A25-A3CA25-2A3C2A24-2A3C2A26-3D89-2B-2B324-B27-B76-B3CB26-A3CA25-2D3-2D23-2(A2C3-2CA22-)BAC3-CAB22-B2A3-2AB22-3A3-3A23-2A3-2A24-CA3-AC24-2A3-2A23-3A3-3A23-2D3-2D26-3A56-2B2-B2-2B117-A3-A27-3B28-B-B28-3B28-3A3(28-ABA)15-B12-ABA12-B15-3A25-B2C3-2CB22-A2C3-2CA22-D7-D21-2(AC7-CA20-)2(BA7-AB20-)2A7-2A21-2(C7-C22-)C7-C21-2A7-2A21-D7-D23-7A26-3A23-2B9-2B362-BA3-AB12-B11-2A3-2A11-B11-C7-C22-C7-C21-D9-D20-E9-A19-AC9-CA2(18-BA9-AB)18-2A9-2A19-2(C9-C20-)C9-C19-2A9-2A19-D9-D21-9A23-7A20-B13-B360-A7-A22-A7-A11-B8-BC9-CB8-B9-AC9-CA2(18-D11-D)18-A11-A17-2A11-2A16-BA11-AB2(16-2A11-2A)17-C11-C17-2A11-2A16-2A11-2A17-D11-D19-11A21-9A18-B15-B358-B9-B20-A9-A19-C11-C10-B7-C11-C7-B9-D13-D15-2B13-2B15-D13-D15-AC13-CA2(14-BA13-AB)4(14-2A13-2A)15-D13-D17-13A19-11A17-B15-B78-2(A11-A18-)A11-A49-B11-B18-B11-B112-A9-A20-A9-A18-BC11-CB16-AC11-CA9-B6-D13-D6-B9-D13-D15-2(BA13-AB14-)BA13-AB15-5(C13-C16-)D13-D17-13A19-11A16-B17-B46-A11-A3(18-B11-B)4(18-A11-A)3(18-B11-B)18-A11-A17-C13-C16-C13-C2(15-D)9-B4-C15-C4-B8-BA15-AB12-BA15-AB13-6(D15-D14-)2(D15-)15A17-13A15-B17-B46-A11-A18-B11-B49-B11-B18-A11-A2(18-B11-B)18-A30-3(A11-A18-)A11-A16-BC13-CB14-AC13-CA14-D15-D13-BC15-CB9-3ABC15-CB3A6-A-ABC15-CBA-A6-3A-D15-D-3A5-B3DBC15-CB3DB4-BD-DBC15-CBD-DB4-B3DBC15-CB3DB5-3A-D15-D-3A6-2(A-)D15-D2(-A)6-3A-D15-D-3A11-15A17-13A14-B19-B45-A11-A3(18-B11-B)4(18-A11-A)3(18-B11-B)18-A11-A17-C13-C16-C13-C2(15-D)9-B4-C15-C4-B8-BA15-AB12-BA15-AB13-6(D15-D14-)2(D15-)15A17-13A14-B19-B14-B11-B49-2(A11-A18-)A11-A49-B11-B18-B11-B112-A9-A20-A9-A18-BC11-CB16-AC11-CA10-B5-D13-D5-B10-D13-D15-2(BA13-AB14-)BA13-AB15-5(C13-C16-)D13-D17-13A19-11A14-B21-B355-B9-B20-A9-A19-2(C11-)B6-C11-C6-B10-D13-D15-2B13-2B15-D13-D15-AC13-CA2(14-BA13-AB)4(14-2A13-2A)15-D13-D17-13A19-11A14-B21-B356-A7-A22-A7-A14-B5-BC9-CB5-B12-AC9-CA2(18-D11-D)18-A11-A17-2A11-2A16-BA11-AB2(16-2A11-2A)17-C11-C17-2A11-2A16-2A11-2A17-D11-D19-11A21-9A16-B19-B350-B7-BA3-A2(B7-)B8-2A3-2A8-B14-C7-C22-C7-C21-D9-D20-A9-A19-AC9-CA2(18-BA9-AB)18-2A9-2A19-2(C9-C20-)C9-C19-2A9-2A19-D9-D21-9A23-7A17-B19-B234-B5-B25-B3-B27-3A28-ABA19-B8-ABA8-B19-3A25-B2C3-2CB22-A2C3-2CA22-D7-D21-2(AC7-CA20-)2(BA7-AB20-)2A7-2A21-2(C7-C22-)C7-C21-2A7-2A21-D7-D23-7A26-3A20-B17-B322-B17-B81-B3CB26-A3CA25-2D3-2D23-2(A2C3-2CA22-)BAC3-CAB22-B2A3-2AB22-3A3-3A23-2A3-2A24-CA3-AC24-2A3-2A23-3A3-3A23-2D3-2D26-3A51-B17-B323-B15-B84-B30-A29-3D26-A-3C-A24-2A3C2A24-BA3CAB24-2B3C2B24-AB3CBA24-2A3C2A25-A3CA25-2A3C2A24-2A3C2A26-3D83-B15-B325-B13-B177-3B2(28-3D28-D-D)28-D-D2(28-B-B)28-D-D114-B15-B357-B11-B115-B3-B393-B13-B390-B9-B21-B7-B23-B5-B423-B13-B876-
