model
size = 22 16 4, scale = 0.05, origin = -y
material 
  colors = A:#0FF B:#080818
voxels
5-2A10-2A9-4A2-4A12-4A2-4A6-2A2(2-2A10-2A2-4A)2-14A2-4A2-14A2-46A2-4A2-6A2-4A4-4A2-6A2-4A6-14A8-14A10-2A6-2A12-2A6-3(2A10-)4A2-4A12-4A2-4A6-2A2(2-2A10-2A2-4A)2-14A2-4A2-14A2-46A2-4A2-6A2-4A4-4A2-6A2-2(4A6-14A8-14A10-2A6-2A12-2A6-2(2A10-)2A8-2(2A10-)4A2-4A12-4A2-4A6-2A2(2-2A10-2A2-4A)2-14A2-4A2-14A2-46A2-4A2B6A2B4A4-4A2B6A2B)4A6-14A8-14A10-2A6-2A12-2A6-2(2A10-)2A8-2A10-2A4-
