model
size = 27 18 4, scale = 0.05, origin = -y
material 
  colors = A:#F0F B:#181808
voxels
10-9A8-5A17-10A17-5A5-4A3-4A2-4A10-4A3-4A2-4A13-4A4-4A15-4A4-4A7-89A4-4A4-15A4-4A4-61A3-21A6-21A12-9A18-9A9-5A17-10A17-5A5-4A3-4A2-4A10-4A3-4A2-4A13-4A4-4A15-4A4-4A7-89A4-4A4-15A4-4A4-2(61A3-21A6-21A12-2(9A18-)9A9-5A17-10A17-5A5-4A3-4A2-4A10-4A3-4A2-4A13-4A4-4A15-4A4-4A7-89A4B4A4B15A4B4A4B)61A3-21A6-21A12-2(9A18-)9A9-
