model
size = 30 31 32, scale = 0.05, origin = -y
material 
  colors = A:#F00 B:#F0F C:#180808 D:#080818 E:#180818 F:#F9E9E9
voxels
42-6A24-6A852-AF26AF2AF26AFA870-AF26A2(F2A)7C9A3E4DAFA3-2(8C8-4E4D6-)3(2C4B2C10E4B2D6-)3(6C2B2E4B2E2B6D6-)3(8C2(2B2D2E)4D6-)3(2C20B2D6-)3(2C2(4B4D)4B2D6-)3(2C20B2D6-)2(4C16B4D6-)4C16B4D8-2(4C2E8B4E2D10-)4C2E8B4E2D14-2(2C10E18-)2C10E9-AF26AF5A7C9A3E4D3A3-2(8C8-4E4D6-)3(2C4B2C10E4B2D6-)3(6C2B2E4B2E2B6D6-)3(8C2(2B2D2E)4D6-)3(2C20B2D6-)3(2C2(4B4D)4B2D6-)3(2C20B2D6-)2(4C16B4D6-)4C16B4D8-2(4C2E8B4E2D10-)4C2E8B4E2D14-2(2C10E18-)2C10E9-34A7C9A3E4D3A3-2(8C8-4E4D6-)3(2C4B2C10E4B2D6-)3(6C2B2E4B2E2B6D6-)3(8C2(2B2D2E)4D6-)3(2C20B2D6-)3(2C2(4B4D)4B2D6-)3(2C20B2D6-)2(4C16B4D6-)4C16B4D8-2(4C2E8B4E2D10-)4C2E8B4E2D14-2(2C10E18-)2C10E9-AF26A2(F2A)7C9A3E4DAFA3-2(8C8-4E4D6-)3(2C4B2C10E4B2D6-)3(6C2B2E4B2E2B6D6-)3(8C2(2B2D2E)4D6-)3(2C20B2D6-)3(2C2(4B4D)4B2D6-)3(2C20B2D6-)2(4C16B4D6-)4C16B4D8-2(4C2E8B4E2D10-)4C2E8B4E2D14-2(2C10E18-)2C10E9-2(AF26AF2AF26AFA870-)60A871-AF24AFA2-28A2(872-AF24AFA2-AF24AFA)872-28A2-28A872-2AF22AF2A2-28A873-2(AF22AFA4-AF22AFA874-)26A4-26A875-AF20AFA6-24A876-AF20AFA6-AF20AFA876-24A6-AF20AFA876-2AF18AF2A6-24A877-AF18AFA8-AF18AFA878-22A8-AF18AFA878-2AF16AF2A8-22A879-AF16AFA10-AF16AFA880-20A10-2AF14AF2A881-AF14AFA12-18A882-2AF12AF2A12-2AF12AF2A883-16A14-2AF10AF2A885-2AF8AF2A16-14A887-2AF6AF2A18-2A2F4A2F2A889-3A2FAF3A20-4A2F4A880-
