model
size = 31 31 32, scale = 0.05, origin = -y
material 
  colors = A:#00F B:#F0F C:#180808 D:#080818 E:#180818 F:#F9E9E9
voxels
31-AF27AF2AF27AFA880-7A24-7A921-3A2FA2F3A20-4A3F4A918-2AF7AF2A18-2A2F5A2F2A916-2AF9AF2A16-15A914-17A14-2AF11AF2A912-2AF13AF2A12-2AF13AF2A911-AF15AFA12-19A910-21A10-2AF15AF2A909-AF17AFA10-AF17AFA908-2AF17AF2A8-23A907-23A8-AF19AFA907-AF19AFA8-AF19AFA906-2AF19AF2A6-25A905-25A2(6-AF21AFA905-AF21AFA)6-25A904-27A4-27A2(903-AF23AFA4-AF23AFA)902-2AF23AF2A2-29A901-29A2-29A2(901-AF25AFA2-AF25AFA)901-AF25AFA2-29A900-62A2(899-AF27AF2AF27AFA)899-AF27AF2AFA4D4E8A8C2AFA3-2(4D4E8-8C7-)3(2D4B10E2C4B2C7-)3(6D2B2E4B2E2B6C7-)3(4D2(2E2D2B)8C7-)3(2D20B2C7-)3(2D2(4B4D)4B2C7-)3(2D20B2C7-)2(4D16B4C7-)4D16B4C9-2(2D4E8B2E4C11-)2D4E8B2E4C15-2(10E2C19-)10E2C10-34A4D4E8A8C4A3-2(4D4E8-8C7-)3(2D4B10E2C4B2C7-)3(6D2B2E4B2E2B6C7-)3(4D2(2E2D2B)8C7-)3(2D20B2C7-)3(2D2(4B4D)4B2C7-)3(2D20B2C7-)2(4D16B4C7-)4D16B4C9-2(2D4E8B2E4C11-)2D4E8B2E4C15-2(10E2C19-)10E2C10-AF27AF4A4D4E8A8C4A3-2(4D4E8-8C7-)3(2D4B10E2C4B2C7-)3(6D2B2E4B2E2B6C7-)3(4D2(2E2D2B)8C7-)3(2D20B2C7-)3(2D2(4B4D)4B2C7-)3(2D20B2C7-)2(4D16B4C7-)4D16B4C9-2(2D4E8B2E4C11-)2D4E8B2E4C15-2(10E2C19-)10E2C10-AF27AF2AFA4D4E8A8C2AFA3-2(4D4E8-8C7-)3(2D4B10E2C4B2C7-)3(6D2B2E4B2E2B6C7-)3(4D2(2E2D2B)8C7-)3(2D20B2C7-)3(2D2(4B4D)4B2C7-)3(2D20B2C7-)2(4D16B4C7-)4D16B4C9-2(2D4E8B2E4C11-)2D4E8B2E4C15-2(10E2C19-)10E2C10-
