model
size = 27 26 32, scale = 0.05, origin = -y
material 
  colors = A:#171828 B:#00FF8C C:#081808 D:#009F79
voxels
64-3(7C20-)7C555-2(17A10-)8A-8A11-7A-7A12-7A-7A13-6A-6A14-6A-6A15-5A-5A16-5A-5A17-4A-4A19-3A-3A21-2A-2A392-21A2(6-10AB10A)7-3(9AB9A8-)9AB9A9-2(8AB8A10-)8AB8A11-7AB7A12-7AB7A13-6AB6A15-5AB5A17-4AB4A20-2A-2A284-4(21A6-)21A7-3(19A8-)19A9-2(17A10-)17A11-15A12-15A13-13A15-5AB5A17-4AB4A19-3A-3A228-23A4-23A5-5(21A6-)21A7-2(19A8-)19A9-17A10-17A11-2(15A12-)15A13-13A15-5AB5A17-4AB4A19-3A-3A174-3(6A11B6A4-)3(5A13B5A4-)6A11B6A5-5A5BA5B5A6-6A4BA4B6A6-8A2BA2B8A7-2(19A8-)19A9-17A10-17A11-15A12-15A13-13A15-5AB5A17-4A-4A20-2A-2A147-5A2B11-2B5A2-5A2B11-2B5A3-4A2B11-2B4A4-3A2B13-2B3A2(4-4AB13-B4A)4-4A2B11-2B4A4-5A2(B5-)B5A4-5A2B4-B4-2B5A5-5A3B2-B2-3B5A6-5A11B5A7-2(6A3BA3B6A8-)19A9-17A10-17A11-15A12-15A13-13A15-5AB5A18-3AB4A20-2A-2A120-2(5AB13-B5A2-)5AB13-B5A3-3A2B13-2B3A5(4-4AB13-B4A)4-4A2B11-2B4A5-3A2B11-2B3A6-4A3B3-B3-3B4A7-3A3B3-B3-3B3A2(8-6A3BA3B6A)9-17A10-17A11-15A13-13A14-13A15-5AB5A18-3A-3A22-A-A94-3(4AB15-B4A2-)3A2B15-2B3A2(2-4AB15-B4A)3-2(3AB15-B3A4-)2(4AB13-B4A4-)4AB13-B4A5-3AB13-B3A6-4AB11-B4A7-3A3B3-B3-3B3A8-4A2B3-B3-2B4A9-5A3BA3B5A10-6A2BA2B6A11-15A12-15A13-13A15-5AB5A17-4A-4A20-2A-2A93-5(3AB17-B3A2-)3A2B15-2B3A2(2-4AB15-B4A)3-2(3AB15-B3A4-)4AB13-B4A5-3AB13-B3A6-4AB11-B4A7-3AB11-B3A8-4AB9-B4A8-4A3B2-B2-3B4A9-4A2B2-B2-2B4A11-5A2BA2B5A12-15A13-13A14-6AB6A16-4A-4A19-3A-3A22-A-A66-4AB17-B8AB17-B4A-3AB17-B3A3(2-A2B19-2BA)3(2-3AB17-B3A)3-2AB17-B2A4-2A2B15-2B2A4-3AB15-B3A5-3AB13-B3A6-3AB13-B3A7-3AB11-B3A8-3A2B4-B4-2B3A9-2A2B4-B4-2B2A10-4A4BA4B4A11-4A3BA3B4A12-15A13-13A15-5AB5A17-4AB4A20-2A-2A23-A-A39-2A2(2B19-2B4A)2B19-2B2A-3(AB21-BA2-)A2B19-2BA2-2AB19-B2A2(2-3AB17-B3A)3-2(2AB17-B2A4-)2A2B15-2B2A5-2AB15-B2A7-2(2AB13-B2A8-)3A2(B5-)B3A9-2A3B3-B3-3B2A11-3AB2-BAB2-B3A12-4A3BA3B4A13-13A14-13A15-5AB5A18-3A-3A22-A-A39-2A4(B21-B4A)B21-B2A-3(AB21-BA2-)A2B19-2BA2-2AB19-B2A3-2(2AB17-B2A4-)2AB17-B2A5-2AB15-B2A6-3AB13-B3A7-2AB13-B2A8-3AB11-B3A9-2A2B4-B4-2B2A10-4AB2-BAB2-B4A11-3A4BA4B3A13-13A14-13A15-5AB5A17-4A-4A20-2A-2A38-2A5(B21-B4A)B21-B2A-4(AB21-BA2-)2AB19-B2A3-AB19-BA4-AB19-BA5-AB17-BA6-A2B15-2BA7-AB15-BA8-2AB13-B2A9-A2B11-2BA10-3A2(B4-)B3A11-2A2B3-B3-2B2A12-4A3BA3B4A13-3A3BA3B3A15-5AB5A17-4A-4A19-3A-3A37-2A2(B21-B4A)B21-B3AB23-B3A2(B21-B4A)B21-B2A-3(AB21-BA2-)2AB19-B2A3-AB19-BA4-AB19-BA5-AB17-BA6-AB17-BA7-AB15-BA8-2AB13-B2A9-AB13-BA10-2AB11-B2A10-2A2B4-B4-2B2A11-3AB2-BAB2-B3A13-2A4BA4B2A14-6AB6A16-4A-4A19-3A-3A37-2A2(B21-B4A)B21-B3A2(B23-B2A)B23-B3AB21-B2A-4(AB21-BA2-)AB21-BA3-AB19-BA4-AB19-BA5-AB17-BA6-A2B15-2BA7-AB16-A8-2AB13-2BA9-AB13-BA11-A2(B5-)B2A11-2AB3-BAB3-B2A13-2(A5B)A14-6AB6A16-4A-4A18-4A-4A21-3A12-2A2(B21-B4A)B21-B3A2(B23-B2A)B23-B3AB21-B4AB21-B2A-4(AB21-BA2-)AB21-BA3-AB19-BA4-AB19-BA5-A2B15-2BA6-2AB16-2A7-2AB13-2BA8-2AB13-B2A9-2AB11-B2A11-2A2(B4-)B3A11-2A11B2A13-7A2-4A15-5A3B3A17-4AD4A20-5A11-2A2(B21-B4A)B21-B2A-2(B23-B2-)2(2B21-2B2-)2B2(21-B4-B)21-B3(4-2B19-2B)5-3B15-3B6-3B16-2B7-3B13-B-B8-3B13-3B10-2B11-3B11-2B11-3B12-6B-6B14-6B3-4B15-4BAB-2BAB16-4B2A-4B20-4B23-3D23-5A11-2A2(B21-B4A)B21-B3A2(B23-B2A)B23-B3AB21-B4AB21-B2A-4(AB21-BA2-)AB21-BA3-AB19-BA4-AB19-BA5-A2B15-2BA6-3AB13-2B2A7-2AB13-2BA8-3AB11-B3A9-2A2(B5-)B2A11-2A2(B4-)B3A11-2A5BA5B2A13-6AB6A15-5A-5A17-4A-4A21-3A12-2A2(B21-B4A)B21-B3A2(B23-B2A)B23-B3AB21-B2A-4(AB21-BA2-)AB21-BA3-AB19-BA4-AB19-BA5-AB17-BA6-A2B15-2BA7-2AB13-2BA8-2AB13-2BA9-2AB11-B2A11-A2(B5-)B2A11-2AB4-A4-B3A12-A11BA14-6AB6A15-5A-5A18-3A-3A37-2A2(B21-B4A)B21-B3AB23-B3AB21-B2A-5(AB21-BA2-)2AB19-B2A3-AB19-BA4-AB19-BA5-AB17-BA6-AB17-BA7-AB15-BA8-2AB13-B2A9-AB13-BA10-2A2B9-2B2A11-A2B9-2BA12-2A2(B4-)B2A13-2A9B2A15-5AB5A17-4A-4A64-8(AB21-BA2-)2AB19-B2A3-3(AB19-BA4-)2AB17-B2A5-AB17-BA6-2AB15-B2A7-AB15-BA8-2A2B11-2B2A9-A2B11-2BA10-3A2B2-3B2-2B3A11-2A2B2-3B2-2B2A13-2AB2-3B2-B2A15-2A2BA-A2B2A16-5A-5A18-3A-3A65-3(AB20-2BA2-)3(AB21-BA2-)2AB19-B2A3-3(AB19-BA4-)AB19-BA5-AB17-BA6-AB17-BA7-2(AB15-BA8-)2AB13-B2A9-2A2B9-2B2A11-A2B4-B4-2BA12-3A4BA4B3A13-2A9B2A14-3A2BABA2B3A16-4A-4A18-4A-4A21-A-A68-8(AB19-BA4-)AB19-BA5-AB17-BA6-AB17-BA7-3(AB15-BA8-)2AB13-B2A9-AB13-BA10-2A2B4-B4-2B2A11-A2B3-BAB3-2BA12-3A3BABA3B3A13-2A3BA-A3B2A15-5A-5A17-4A-4A21-A-A95-3(2AB17-B2A4-)AB19-BA4-AB19-BA5-5(AB17-BA6-)2AB15-B2A7-AB15-BA8-A2B13-2BA9-A3B9-3BA10-A3B9-3BA11-A2B4-B4-2BA12-3AB2-3B2-B3A13-2A9B2A14-6AB6A16-4A-4A18-4A-4A21-A-A123-6(AB17-BA6-)AB17-BA7-3(AB15-BA8-)AB15-BA9-AB13-BA10-2AB11-B2A11-A-2B3-B3-2B-A12-2A2B3-B3-2B2A12-2A2B2-3B2-2B2A13-2AB2-3B2-B2A15-2A2BA-A2B2A16-5A-5A18-3A-3A22-A-A150-3(AB16-2BA6-)2AB15-B2A6-2AB15-B2A7-3(AB15-BA8-)AB15-BA9-2(AB13-BA10-)A2B11-2BA10-3AB3-3B3-B3A11-2A2B2-3B2-2B2A12-4AB-BAB-B4A14-2A2BA-A2B2A16-2A2BA-A2B2A18-3A-3A21-2A-2A23-A-A178-3(AB15-BA8-)2AB13-B2A8-2AB13-B2A9-3(AB13-BA10-)AB13-BA11-AB11-BA12-A2(B5-)BA12-A2B3-3B3-2BA12-3AB-2(BA)B-B3A13-2A3BA-A3B2A14-3A2BABA2B3A16-3A-B-3A19-3AB3A22-A-A24-A-A206-4(AB13-BA10-)AB13-BA11-3(AB11-BA12-)A2B3-3B3-2BA12-2AB3-3B3-B2A12-2A2B2-BAB2-2B2A13-2A3B3A3B2A14-3A2BABA2B3A16-4A-4A19-3A-3A22-A-A24-A-A261-3(AB11-BA12-)A13-A12-AB11-BA13-AB9-B2(A14-A2B7-2B)A14-2A9B2A15-A9BA16-2A2BABA2B2A17-4AB4A19-3A-3A21-2A-2A23-A-A316-4(A11-A14-)AB9-BA15-A9-A2(16-2A7-2A)17-3A3-3A18-3A3-3A19-3A-3A21-2A-2A23-A-A398-4(4C3-4C16-)A9-A17-A7-A18-A7-A19-3A-3A21-2A-2A23-A-A417-
