model
size = 15 12 5, scale = 0.05, origin = -y
material 
  colors = A:#936 B:#C03 C:#C06 D:#F06 E:#F36 F:#F39 G:#939 H:#C0C I:#C09
voxels
37-I13-C-C11-D3-D9-A5-2(A7-)A5-G3-F-F3-G5-A-E3-E-A7-A5-A56-I13-C-C11-F3-F9-E5-E2(7-G)5-D4-F4-D3-G4-F-F4-G3-D3-A-A3-D5-C-E3-E-C7-A5-A26-H13-HIH11-2CB2C9-E2B-2BE7-2EB3-B2E5-2DB2-H2-B2D3-2DB2-3H2-B2D-2AB3-BAB3-B2A-2AB-BA-AB-B2A3-2AB2A-2AB2A5-3A3-3A7-C5-C26-I13-C-C11-F3-F9-E5-E2(7-G)5-D4-F4-D3-G4-F-F4-G3-D3-A-A3-D5-C-C3-C-C7-A5-A56-I13-C-C11-D3-D9-A5-2(A7-)A5-G3-F-F3-G5-A-E3-E-A7-A5-A34-
