model
size = 17 14 5, scale = 0.05, origin = -y
material 
  colors = A:#111 B:#0F6 C:#936 D:#F06 E:#C06 F:#F36 G:#C09 H:#C03
voxels
59-A15-A-A13-A3-A11-A5-A9-2(A7-)A3-A-A3-A7-A-A3-A-A9-A5-A98-B15-B-B13-B3-B11-B5-B9-2(B7-)B4-A4-B5-B4-B-B4-B5-B3-B-B3-B7-B-B3-B-B9-B5-B47-A15-3A13-2AG2A11-2AEBE2A9-2AHB-2B2A7-2AFB3-BF2A5-2ADB5-BD2A3-2AD2(B3-)BD2A-2ACB3-3B3-BC2A-2ACB-B3AB-BC2A3-2ACBC3ACBC2A5-2AC2A-2AC2A7-3A3-3A9-A5-A47-B15-B-BA12-B3-B11-B5-B9-2(B7-)B4-A4-B5-B4-A-A4-B5-B3-B-B3-B7-B-B3-B-B9-B5-B98-A15-A-A13-A3-A11-A5-A9-2(A7-)A3-A-A3-A7-A-A3-A-A9-A5-A56-
