model
size = 17 14 5, scale = 0.05, origin = -y
material 
  colors = A:#C6C B:#111 C:#222 D:#936 E:#F06 F:#C06 G:#F36 H:#C09 I:#C03 J:#0F6
voxels
59-A15-A-A13-A3-A11-A5-A9-2(A3-)A7-A3-A-A3-A7-A-A3-A-A9-A5-A98-B15-B-B13-B3-B11-B5-B9-2(B7-)B4-A4-B5-B4-B-B4-B5-B3-B-B3-B7-B-B3-B-B9-B5-B47-A15-3A13-2AH2A11-2AFBF2A9-2AIB-BJ2A7-2AGB3-BG2A5-2AEB5-BE2A3-2AE2(B3-)BE2A-2ADB3-BCB3-BD2A-2ADB-B3AB-BD2A3-2ADBD3ADBD2A5-2AD2A-2AD2A7-3A3-3A9-A5-A47-C15-C-C13-C3-C11-C5-C9-2(C7-)C4-A4-C5-C4-A-A4-C5-C3-C-C3-C7-C-C3-C-C9-C5-C98-A15-A-A13-A3-A11-A5-A9-2(A3-)A7-A3-A-A3-A7-A-A3-A-A9-A5-A56-
