model
size = 32 4 4, scale = 0.05, origin = -y
material 
  colors = A:#FFC
voxels
-511A
