model
size = 21 25 15, scale = 0.05, origin = -y
material 
  colors = A:#777 B:#BA9425 C:#C6AB40 D:#B9B9B9
voxels
491-5A495-5A3-5A7-3A2-A3-A2-3A7-5A3-5A490-A-A2-5A2-2(A-A510-A-A9-)A-A490-A11-A7-3A9-3A7-A11-A469-A13-A27-A13-A467-A15-A25-A15-A465-A17-A-3A15-3A-A17-A484-2(A-A15-A-A504-)A-A15-A-A197-A3-A15-A5-A13-2(A7-)A3-A9-A3-4(A2-A17-)A65-3(A17-A2-)A17-A-3A15-3A27-3BCBC3B12-2B4C3B12-3B2(C2B)12-3B3C3B12-3B2(C2B)12-2B4C3B12-3BCBC3B13-D5-D14-DA3-AD15-D3-D9-5A3-3D3-5A2-A3-A9-A3-A2-5A9-5A44-2A15-4A2(-A15-A-2A)-A15-A-4A15-3A64-A17-A198-A3-A15-A5-A13-2(A7-)A3-A9-A3-4(A2-A17-)A65-4(A17-A2-)A17-A22-
