model
size = 21 22 15, scale = 0.05, origin = -y
material 
  colors = A:#FFC30F
voxels
428-5A432-5A3-5A7-3A2-A3-A2-3A7-5A3-5A427-A-A2-5A2-2(A-A447-A-A9-)A-A427-A11-A7-3A9-3A7-A11-A406-A13-A27-A13-A404-A15-A25-A15-A402-A17-A-3A15-3A-A17-A421-2(A-A15-A-A441-)A-A15-A-A46-A3-5A3-A7-A13-A5-A15-A3-A17-A65-4(A17-A2-)A17-A65-3(A17-A2-)A17-A-3A15-3A25-5A3-5A8-3(A3-)A8-5A3-5A25-3A15-4A2(-A15-A-2A)-A15-A-4A15-3A63-3A15-4A2(-A15-A-2A)-A15-A-4A15-3A64-A17-A47-A3-5A3-A7-A13-A5-A15-A3-2(A17-A65-4(A17-A2-))A17-A22-
