model
size = 20 32 32, scale = 0.05, origin = -y
material 
  colors = A:#FC0 B:#FF0 C:#FF3 D:#F63 E:#FF6 F:#F90 G:#D00 H:#F60 I:#100 J:#CF0 K:#993 L:#E00 M:#FC3 N:#B00 O:#A00 P:#FC6 Q:#800
voxels
28-3(4B16-)4G16-4A16-CKCD516-4(6B14-)6G14-BAKBAB14-A2CKBD14-2C2BAJ14-2BABFK14-2A2FCB14-ECFBAC15-AKFA16-DCB16-AC2A15-FAEB2C13-FAECACF12-BACE2ABFA10-D2(AB)A2BFDBA8-AB2ACDBFC3B8-2(B2A)B4AB8-FAEFBE2B3AD8-2ABAFBA2BADC8-2B2AFDBADHF2A7-AHACFAE2BCABA7-DC2ABEFBCDB2A7-AB2AC2(AH)A2EA7-B2AC2D4AEAE7-B2A2BA2E2BA2C7-2A3BD3BEAFE7-ABA5BDACEF7-2BAD3AC4AF7-14B9-4(8B12-)G6AG12-B7A12-7AD12-7AM12-C7A12-7AC12-E6AB12-K6A12-F8A11-7ABA11-B7AD11-B6AF2A9-10AD8-B2A7-2A8-2(3A7-)2(FA8-2AB7-)2A3-2A5-C7-B-2A8-C6-2A11-C3(6-A12-A)6-DA11-A6-A12-AB4-2A12-AB4-DA12-AB4-2B12-A2B7-3(10B10-)B-8B10-G8AG10-B7-AD10-A7-2A10-A7-AC10-F7-A11-A7-C11-A7-A11-D7-D11-A7-AH9-BA7-2A9-DA7-2A9-B8-AC8-DA8-2AC7-BA9-AB7-BA9-AC7-BA9-2A7-2A10-C7-2A10-A7-C11-A6-CA11-C6-A12-2A4-FA12-2A4-2A12-AB4-CA12-AB2(4-2A12-2A)4-2A13-B3-2BA13-3B5-3(11B9-)2B-8B9-G9AG9-2A7-2A9-2A7-AJ9-BA8-M9-BA7-AC10-A7-A11-A7-B11-E7-2A10-A7-AC9-EA7-AC8-P2A7-3A7-DA9-AC2(7-2A9-2A)7-BA9-AC7-EA9-2A6-H2A10-2A5-E2A10-AB5-CA11-2A4-C2A11-AC4-3A11-2A4-F2(A12-AD4-E)A12-2A4-CA12-2A4-BA12-AB4-2A13-AB2-2BA13-3B5-3(12B8-)2B-9B8-G10AG8-2A7-3A8-CA7-2A9-2A7-AJ8-3A7-AB8-DBA7-J9-2AK7-CA8-BEA7-AB8-B2A7-2AC7-B2A7-3A7-F2A7-3A7-2A9-AC6-M2A9-3A5-3A9-3A5-F2A9-2AD5-H2A9-3A5-E2A10-2A5-E2A10-AB5-BA11-2A4-B2A11-AC4-H2A11-AB4-FA12-2A4-CA12-AB4-2A12-2A4-EA2(12-2A4-2A)13-AB-3BA13-3B5-3(12B8-)2B-9B8-G10AG8-BA7-3A8-BA7-2AC8-2A2(7-2A8-BCA)7-AB8-2AC7-CAB7-F2A7-2AB2(7-3A)7-H2A7-4A5-4A7-4A5-3A9-2AC5-M2A9-2AH5-3A9-2AB5-F2A9-3A5-3A9-2AE5-3A10-AB5-F2A10-AE5-2A11-AD4-B2A11-2A4-BA12-AB4-CA12-2A4-DA12-AB4-2A12-2A4-EA12-AB4-BA12-2A4-2A13-2B-3BA13-3B5-3(12B8-)2B-9B8-G10AG8-2A7-3A8-2A7-2AK8-BA7-AC9-BA7-2A9-2A7-KB8-D2A7-J2A7-B2A2(7-3A)7-2AC2(7-3A)C5-4A7-3AF5-3A9-3A5-B2A9-2AF5-D2A9-2AB5-3A9-2AB6-2A9-2AC6-2A10-AC6-2A10-2A5-2A11-AE4-3A11-AC4-FA12-AB4-EA12-2A4-EA12-AB4-BA12-2A4-EA12-AD4-2A12-2A4-2A13-2B-3BA13-3B5-3(12B8-)2B-9B8-G10AG8-2A7-3A8-BA7-2AK8-BA7-AB9-2A7-AB9-CA7-B10-AC7-DB9-BA7-AB8-B2A7-AB8-3A7-2A8-3A7-4A6-3A8-A2H6-2A9-2AF6-DA9-2AE6-CA9-2AB6-2A9-2AB5-3A10-AC5-B2A10-2A5-CA11-2A4-D2A11-AE5-A12-2A4-CA12-AB4-2A12-2A4-BA12-AB4-EA12-AB4-2A12-AD4-2A13-2B-3BA13-3B4-3(13B7-)G2B-9B7-12AG2(7-3A)7-M2A7-2AB8-2A7-AB9-BA7-AB10-A7-B11-A7-A10-2A7-AH9-FA7-AC9-BA7-AB9-BA7-2A9-PA8-H8-2A9-AF7-CA9-AE7-CA9-AB7-2A9-AH7-2A10-C7-BA10-A7-A11-AC5-2A11-AE5-DA11-2(AB5-A12-)2A4-2A12-AB4-EA12-2A4-BA12-AB4-BA12-A2B-3BA13-3B4-3(13B7-)G2B-9B7-12AG2(7-3A)7-J2A7-3A7-M2A7-AJ10-A7-2A10-D7-A11-A7-J11-D7-A11-2A5-AF11-A6-A2H9-2A7-A3(B9-)F9-AF8-B9-BC8-A9-2B7-HA9-AB7-BA9-2A7-BA9-2E7-BE9-2A6-AFB9-AE6-2EC9-CB6-2HA9-DB6-ABA9-AB6-BAB9-2A6-E2B9-ABA5-3A9-ADA5-3A9-BADB2-2B2A10-A-3B4-3(13B7-)G2B-9B7-12AG7-J2A2(7-3A)7-2AD7-JCA7-AJ10-F7-AB10-A7-J11-A7-A12-6AB13-JAC2AJB14-JAHCA13-AB5ABH11-B6ADA11-B7AD11-8AF11-D6A2F11-9A11-B7-C11-C7-H11-A7-D11-A7-A11-C7-B11-A7-A11-B7-A11-A7-B11-D2(7-A11-A)7-A2B4-3B2A8-A4B5-3(12B8-)G2B-7BG8-12A8-C2A7-2A8-C2A7-AC8-3A2(7-2A10-A)7-A12-7A13-E4AB15-E3A16-5A15-4AB15-4AH15-C3AB14-5AB14-C4AF13-F6A2(B12-7A)B12-A3-3AB12-D2(6-B12-A)6-B12-B6-B12-D6-A2(12-B6-B)12-A6-2B7-3BA7-A5B5-3(11B9-)G2B-6BG9-11A9-3A7-C9-3A7-A9-BCA7-J11-F6-AE11-9A12-F5AH13-ECKCAB15-4A16-H3A16-3AB2(16-B2AE)2(15-B4A)B14-B4AF14-B5A14-5AB14-5AE13-H5AC13-A5-B13-C5-A13-B5-B13-A5-A13-B5-D2(13-A5-A)B9-2BA6-A5B6-3(11B9-)G2B-6BG9-11A9-3A7-A9-D2A7-A9-3A6-AD11-2A5-AJ11-B6AH13-E5A15-3AE17-2A18-BA18-FE17-F2A17-B2A17-3A2(F16-E2A)F15-E4A15-B4AB14-E4AD14-C4AC14-5AB14-B5A3(14-I4AI)14-5AD13-B6A10-2BA6-A4B7-2(11B9-)10BG9-G2B-6BA9-11A9-B2A7-A9-J2A7-D9-B2A6-2A11-FA-4AJ12-B7A13-CAKJ2C15-4A17-BD2(18-FB)18-AD18-2B18-AD2(18-BA)17-AB2F16-ADFB16-AF2D16-AFBC16-B2IB16-INLI15-I2LNLI14-I2LOLI14-IQ2LOI15-IONI15-BA2IA12-2B7A3B8-2(11B9-)10BG9-G2B-6BA9-10AC9-3A7-K9-D2A6-AC9-B2A6-AF11-2A-5A12-B6AB13-5AH15-2ABA257-2I17-INLI15-ILGLNI14-IGLOLI14-IONLOI15-I2NI17-2I15-9B8-12B8-G11B8-G10BG8-A3B-6BA9-11A9-C2A7-D9-3A6-AK9-ABA-A4-AJ11-8A12-B6AB13-BCFDAB15-DFBE395-7B9-12B8-G10BG8-A10BA8-A3B-6BA9-11A9-3A7-A9-E2A6-AK10-KA-A4-AC11-7AB13-E5A450-13B7-G11BG7-A11BA7-A3B-7BA7-C12A8-3A7-AC8-C2A6-AF10-2A-A4-AH11-8A13-2BCFDA450-14B6-G12BG6-A12BA6-A3B-8BA6-12A-K6-C3A7-AC8-D2A6-2AF9-2A-A4-AH12-F6A469-14B6-G12BG6-A12BA6-C3B-8BK6-13AC6-E12AC7-11AC9-K8AJ12-EFADJBH469-14B6-G12BG6-A12BA6-A3B-8BC6-C12AK6-14A7-D10AK9-DEK6AK14-D2A471-14B6-G12BG6-A12BA6-C3B-8BA6-13AC6-14A7-12A9-ECKE3AHAD14-ECA471-14B6-G12BG6-A12BA6-A3B-8BC6-13AK6-D12AD7-F10AD10-E2A2E2AJA488-14B6-G12BG6-A12BA6-A3B-8BA6-C13A6-14A7-C11A11-CJCAKCA489-14B6-G12BG6-G12BA6-A3B-8BM6-13AM6-BJ10AC9-C2A2EHCA2C509-2(12B8-)G10BG8-A2B-7BA8-B11A8-2J8ACK10-CHAMA2BC510-2(12B8-)G10BG8-A10BA8-C11A8-DC7ABKM12-2EDBA512-2(10B10-)G8BG10-A8BA10-B9A10-CJDAE2CKAD531-2(8B12-)G6BG12-A6BA12-8A12-CJ2(CA)EM533-3(6B14-)G4BG14-6A14-2ACH2C527-
