model
size = 20 32 32, scale = 0.05, origin = -y
material 
  colors = A:#FC0 B:#FF0 C:#FF3 D:#F63 E:#FF6 F:#F90 G:#D00 H:#F60 I:#100 J:#CF0 K:#993 L:#E00 M:#FC3 N:#B00 O:#A00 P:#FC6 Q:#800
voxels
28-3(4B16-)4G16-4A16-DCKC514-4(6B14-)6G14-BABKAB14-DBK2CA14-JA2B2C14-KFBA2B14-BC2F2A14-CABFCE15-AFKA17-BCD17-2ACA15-2CBEAF14-FCACEAF12-AFB2AECAB9-ABDF2B2(AB)AD8-3BCFBDC2ABA8-B4A2(B2A)B8-D3A2BEBFEAF8-CDA2BABFAB2A7-2AFHDABDF2A2B7-ABAC2BEAFCAHA7-2ABDCBFEB2ACD7-A2E2(AH)AC2ABA7-EAE4A2DC2AB7-2CA2B2EA2B2AB7-EFAE3BD3B2A7-FECAD5BABA7-F4AC3ADA2B5-15B9-4(8B12-)G6AG12-7AB12-D7A12-M7A12-7AC12-C7A12-B6AE13-6AK12-8AF11-AB7A11-D7AB10-2AF6AB10-D10A9-2A7-2AB2(7-3A)2(7-B2A8-AF)7-C5-2A3-2A7-C8-2A-B7-C11-2A3(6-A12-A)6-A11-AD5-BA12-A5-BA12-2A4-BA12-AD2-3BA12-2B6-3(10B10-)8B-B10-G8AG10-DA7-B10-2A7-A10-CA7-A11-A7-F11-C7-A11-A7-A11-D7-D10-HA7-A10-2A7-AB9-2A7-AD9-CA8-B8-C2A8-AD7-BA9-AB7-CA9-AB7-2A9-AB7-C2(10-2A7-A)11-C7-C11-AC2(5-2A12-A)F4-BA12-2A4-BA12-AC2(4-2A12-2A)4-B13-2A2-2B14-A2B5-3(11B9-)8B-2B9-G9AG9-2A7-2A9-JA7-2A9-M8-AB9-CA7-AB10-A7-A11-B7-A10-2A7-E2(10-CA7-A)E8-3A7-2AP7-CA9-AD2(7-2A9-2A)7-CA9-AB7-2A9-AE6-2A10-2AH5-BA10-2AE5-2A11-AC5-CA11-2AC4-2A11-3A4-DA12-AF4-DA2(12-AE4-2A)12-AC4-BA12-AB4-A13-2A2-2B14-A3B3-3(12B8-)9B-2B8-G10AG8-3A7-2A9-2A7-AC9-JA7-2A9-BA7-3A9-J7-ABD8-AC7-K2A8-BA7-AEB7-C2A2(7-2AB7-3A)7-2AF7-CA9-2A6-3A9-2AM5-3A9-3A5-D2A9-2AF5-3A9-2AH5-2A10-2AE5-BA10-2AE5-2A11-AB5-CA11-2AB4-BA11-2AH4-2A12-AF4-BA12-AC4-2A12-2A4-2A12-AE4-2A12-2A4-A13-2A2-2B14-A3B3-3(12B8-)9B-2B8-G10AG8-3A7-AB8-C2A7-AB9-2A7-2A9-2A7-ACB8-BA7-ACB7-BAC7-C2A7-B2A7-2AF2(7-3A)6-4A7-2AH6-4A7-4A5-C2A9-3A5-H2A9-2AM5-B2A9-3A5-3A9-2AF5-E2A9-3A5-BA10-3A5-EA10-2AF5-DA11-2A5-2A11-2AB4-BA12-AB4-2A12-AC4-BA12-AD4-2A12-2A4-BA12-AE4-2A12-AB4-B13-2A2-2B14-A3B3-3(12B8-)9B-2B8-G10AG8-3A7-2A8-K2A7-2A9-CA7-AB9-2A7-AB9-BK7-2A8-2AJ7-2AD7-3A7-2AB7-C2A7-3A6-C3A7-3A6-F3A7-4A5-3A9-3A5-F2A9-2AB5-B2A9-2AD5-B2(2A9-3A5-C)A10-2AB5-2A10-2AB5-EA11-2A5-CA11-3A4-BA12-AF4-2A12-AE4-BA12-AE4-2A12-AB4-DA12-AE4-2A12-2A4-B13-2A2-2B14-A3B3-3(12B8-)9B-2B8-G10AG8-3A7-2A8-K2A2(7-AB9-BA)7-2A10-B7-AC9-BD7-CA9-BA7-AB9-BA7-2AB8-2A7-3A6-4A7-3A6-2HA8-3A6-F2A9-2A6-E2A9-AD6-B2A9-AC6-B2A9-2AC5-CA10-3A5-2A10-2AB5-2A11-AC5-EA11-2AD4-2A12-2A4-BA12-AC4-2A12-2A4-BA12-AB4-BA12-AE4-DA12-2A4-B13-2A2-2B14-A3B3-3(13B7-)9B-2BG7-G12A2(7-3A)7-B2A7-2AM8-BA7-2A9-BA7-AB10-B7-A11-A7-A10-HA7-2A9-CA7-AF9-BA7-AB9-2A7-AB9-H8-AP8-FA9-2A7-EA9-AC7-BA9-AC7-HA9-2A7-C10-2A7-A10-AB6-CA11-A6-EA11-2A5-BA11-AD5-BA12-A5-2A12-A5-BA12-2A4-2A12-AE2(4-BA12-AB)2-2B14-A3B3-3(13B7-)9B-2BG7-G12A3(7-3A)7-2AJ8-JA7-2AM8-2A7-A11-A7-D11-J7-A11-A7-D11-FA5-2A10-2HA6-A10-BA7-2A2(9-B)8-FA9-F8-CB9-B8-2B9-A8-BA9-AH7-2A9-AB7-2E9-AB7-2A9-EB7-EA9-BFA6-BC9-C2E6-BD9-A2H6-BA9-ABA6-2A9-BAB5-ABA9-2BE5-ADA9-3A5-DAB9-3A3-2B2-A10-2A2B4-3(13B7-)9B-2BG7-G12A7-3A7-2AJ7-D2A7-3A8-JA7-ACJ8-BA7-F11-J7-A11-A7-A12-B6A13-BJ2ACAJ14-ACHAJ13-HB5ABA11-AD6AB11-D7AB11-F8A11-2F6AD11-9A11-C7-B11-H7-C11-D7-A11-A7-A11-B7-C11-A7-A11-A7-B11-B7-A11-A7-D2(11-A7-A)7-4BA8-2A3B5-3(12B8-)G7B-2BG8-12A8-2A7-2AC8-CA7-2AC8-2A7-3A8-2A7-A11-A7-A12-7A14-B4AE15-3AE15-5A15-B4A15-H4A15-B3AC15-B5A14-F4AC13-B6AF2(12-B7A)12-B3A3-A12-B6-D2(12-B6-A)12-B6-B12-A6-D2(12-B6-B)12-B6-A11-BA7-AB3(9-11B)9-G6B-2BG9-11A9-C7-3A9-A7-3A9-J7-ACB9-EA6-F11-9A12-H5AF14-BACKCE15-4A16-3AH16-B3A2(16-E2AB)16-4AB14-B4AB14-F4AB14-5AB14-B5A14-E5A14-C5AH13-B5-A13-A5-C13-B5-B13-A5-A13-D5-B2(13-A5-A)12-BA6-AB3(9-11B)9-G6B-2BG9-11A9-A7-3A9-A7-2AD9-DA6-3A9-JA5-2A12-H6AB13-5AE15-E3A17-2A18-AB18-EF18-2AF17-2AB16-F3A2(16-F2AE)16-4AE14-B4AB14-D4AE14-C4AC14-B5A14-5AB3(14-I4AI)14-D5A14-6AB12-BA6-AB2(9-11B)9-G10B9-A6B-2BG9-11A9-A7-2AB9-D7-2AJ9-2A6-2AB10-J4A-AF12-7AB13-2CJKAC15-4A17-DB2(18-BF)18-DA18-2B18-DA2(18-AB)17-2FBA16-BFDA16-2DFA16-CBFA16-B2IB16-ILNI15-ILN2LI14-ILO2LI14-IO2LQI15-INOI16-A2IAB13-B7A2B2(9-11B)9-G10B9-A6B-2BG9-C10A9-K7-3A9-CA6-2AD9-FA6-2AB10-5A-2A12-B6AB13-H5A15-AB2A257-2I17-ILNI15-INLGLI14-ILOLGI14-IOLNOI15-I2NI17-2I15-8B11-12B8-11BG8-G10BG8-A6B-3BA8-11A9-D7-2AC9-KA6-3A9-JA4-A-ABA10-8A12-B6AB13-BADFCB15-EBFD395-6B12-12B8-G10BG8-A10BA8-A6B-3BA8-11A9-A7-3A9-KA6-2AE9-CA4-A-AK11-B7A13-5AE435-4B12-13B7-G11BG7-A11BA7-A7B-3BA7-12AC7-CA7-3A9-FA6-2AC9-HA4-A-2A11-8A13-ADFC2B450-14B6-G12BG6-A12BA6-A8B-3BA6-K-12A7-CA7-3AC7-F2A6-2AD9-HA4-A-2A11-6AF470-14B6-G12BG6-A12BA6-K8B-3BC6-C13A6-C12AE7-C11A9-J8AK11-HBJDAFE470-14B6-G12BG6-A12BA6-C8B-3BA6-K12AC6-14A7-K10AD9-K6AKED13-2AD472-14B6-G12BG6-A12BA6-A8B-3BC6-C13A6-14A7-12A9-DAH3AEKCE13-ACE472-14B6-G12BG6-A12BA6-C8B-3BA6-K13A6-D12AD7-D10AF9-AJ2A2E2AE489-14B6-G12BG6-A12BA6-A8B-3BA6-13AC6-14A7-11AC10-ACKACJC490-14B6-G12BG6-A12BG6-M8B-3BA6-M13A7-C10AJB8-2CACH2E2AC509-2(12B8-)G10BG8-A7B-2BA8-11AB8-KC8A2J10-C2BAMAHC510-2(12B8-)G10BG8-A10BA8-11AC8-MKB7ACD11-ABD2E513-2(10B10-)G8BG10-A8BA10-9AB10-DAK2CEADJC531-2(8B12-)G6BG12-A6BA12-8A12-ME2(AC)JC533-3(6B14-)G4BG14-6A14-2CHC2A527-
