model
size = 22 12 20, scale = 0.05, origin = -y
material 
  colors = A:#FC0 B:#070 C:#39C D:#3CC E:#C0C F:#C0F
voxels
120-EF20-FE20-EF20-FE194-A4-A233-2A8-2A11-2A6-2A11-2A8-2A2(10-A)185-2A10-2A30-2A10-2A2(8-A12-A)161-2A12-2A28-2A12-2A6-A14-A182-A14-A28-A14-A203-A15-2A26-A15-2A202-A16-A26-A16-A201-4(2A16-2A2-)A18-A156-2A16-2A-DBA16-AB2CBA16-AB2D2A16-2AC-A18-A2-A18-A134-2A16-2A-CBA16-AB2DBA16-AB2C2A16-2AD-A18-A2-A18-A134-4(2A16-2A2-)A18-A157-A16-A26-A16-A202-A15-2A26-A15-2A203-A14-A28-A14-A204-2A12-2A28-2A12-2A3(6-A14-A)139-2A10-2A30-2A10-2A5(8-A12-A)97-3A6-3A32-3A6-3A6(10-A)144-8A16-4A16-8A16-4A15-A8-A82-2A19-A2-A17-A4-A15-A2-2A2-A16-3(A2BA18-)A2BA16-A2-2A2-A15-A4-A17-A2-A19-2A10-
