model
size = 32 9 32, scale = 0.05, origin = -y
material 
  colors = A:#008 B:#500 C:#555 D:#222 E:#633 F:#F30 G:#FC0 H:#F00 I:#D00 J:#F03 K:#111 L:#B00
voxels
140-2G4-2G24-2G4-2G216-HF4-HF24-FH4-FH216-IF4-FL23-I2-B2-J2-F22-3(F2-)I23-2J4-FI152-2D4-2D23-4D2-DA2D21-D4-2D4-D20-D4-2D4-D21-D2AD2-D2AD23-2D4-2D120-2D4-2D22-2D2-4D2-2D19-D12-D18-D12-D19-2D2-D2KD2-2D22-2D4-2D88-2A4-2A23-4A2-4A21-A4-2B4-A19-B12-B18-B12-B19-A4-2B4-A21-4A2-4A4(23-2A4-2A56-2A4-2A23-3(A2-)A21-A4-2B4-A19-B12-B18-B12-B19-A4-2B4-A21-3(A2-)A)23-2A4-2A56-2A4-2A23-3(A2-)A20-2A4-2B4-2A17-B14-B16-B14-B17-2A4-2B4-2A20-3(A2-)A23-2A4-2A56-2A4-2A22-2A2-A2B2A-2A18-2A8-A3-2A13-3B16-3B10-3B16-3B13-2A12-2A18-2A2-A2BA2-2A22-2A4-2A55-4A2-4A20-6A2B6A14-4A3-3A2B4A2-4A9-2B6-9A5-2B8-2B6-9A5-2B9-4A3-3A2B4A2-4A14-2A-3A2B3A-2A20-4B2-4B53-5A2B5A16-4A-A2-A2BA2-6A10-2A5-A2-A2BA2-2A4-2A7-B7-A2-4A2-2A2(6-B)7-A2-4A2-2A6-B7-2A5-A2-A2BA2-2A4-2A10-4A-A2-A2BA2-6A16-2B2-4B2-2B49-8A2B8A12-2A3-A4C2B4CA3-2A8-2A5-A4C2B4CA5-2A5-B7-A4C2A4CA7-B4-B7-A4C2A4CA7-B5-2A5-A4C2B4CA5-2A8-2A3-A4C2B4CA3-2A12-3AB-2C-2B-2C-B3A19-2C4-2C17-10A2B10A9-2A4-A4C2B4CA4-3A5-2A6-A4C2B4CA6-2A3-B8-A4C2E4CA8-B2-B8-A4-2E4-A8-B3-2A6-A4-2E4-A7-A6-2A4-A10-A4-3A8-5AB10-B5A41-24B6-3B5-12B5-3B3-2B7-12B7-AB-B9-A4C2E4CA9-2B9-A4-2E4-A9-B-2B7-A10-A7-2B3-3B5-A10-A5-3B6-7B10-7B40-24B6-3B5-12B5-3B3-2B7-12B7-AB-B9-A4C2E4CA9-2B9-A4-2E4-A9-B-2B7-A10-A7-2B3-3B5-A10-A5-3B6-7B10-7B41-10A2B10A9-2A4-A4E2B4-A4-2(2A6-)A4-2B4-A6-2A3-B8-A4-2E4-A8-B2-B8-A4-2E4-A8-B3-2A6-A-2D3-4EA2(6-2A)4-AK2-D6-A4-2A9-5AB10-B5A44-8A2B8A12-2A3-A4E2B4EA3-2A8-2A5-A4-2B4-A5-2A5-B7-A4-2A4-A7-B4-B7-A4-2A-E2-A7-B5-2A5-A-2D-2A4EA5-2A8-2A3-A4-2B4-A3-2A12-3AB4-2B4-B3A49-5A2B5A16-4A-A2EA-BA2E6A10-2A5-3(A2-)2A4-2A7-B7-3(A2-)2A2(6-B)7-2(A2-)AE-2A6-B7-2A5-A2DA2-A2E2A4-2A10-4A-3(A2-)6A16-2B2-4B2-2B53-4A2-4A20-2(2A-)2B6A14-4A3-2A3-4A2-4A9-BA6-2A3-4A5-2B8-BA6-2A3-4A5-2B9-4A3-2A3-4A2-4A14-2(2A-)2B6A20-4B2-4B55-2A4-2A22-2A2-A2BA2-2A18-2A12-2A13-3B16-3B10-3B16-3B13-2A12-2A18-2A2-A2BA2-2A22-2A4-2A56-2A4-2A23-3(A2-)A20-2A4-2B4-2A17-B14-B16-B14-B17-2A4-2B4-2A20-4(3(A2-)A23-2A4-2A56-2A4-2A23-3(A2-)A21-A4-2B4-A19-B12-B18-B12-B19-A4-2B4-A21-)3(A2-)A23-2A4-2A56-2A4-2A23-4A2-4A21-A4-2B4-A19-B12-B18-B12-B19-A4-2B4-A21-4A2-4A23-2A4-2A88-2A4-2A22-2A2-A2BA2-2A19-B12-B18-B12-B19-2A2-A2BA2-2A22-2A4-2A120-2A4-2A23-4A2-4A21-B4-2B4-B20-B4-2B4-B21-4A2-4A23-2A4-2A152-2D4-2D23-2(D2-)D-AD22-3(D2-)D23-2D4-2D108-
