model
size = 24 32 30, scale = 0.05, origin = -y
material 
  colors = A:#111 B:#FCFAF2 C:#F7D94C D:#113285
voxels
301-A23-A21-2A23-3A670-A23-A21-2A23-3A647-2A-A19-2A-2A18-2A2-A19-3A20-2A22-5A20-3A601-2A19-3A-2A18-2A-2A17-7A17-4A-A17-6A18-6A20-3A21-A-2A503-A22-2A24-2A2(18-7A)16-7A2(18-5A)18-3A-2A17-7A17-8A16-7A17-2A-3A455-A20-6A3(17-7A)16-3(9A15-)3(8A16-)9A15-8A2(15-9A)5(16-8A)16-7A17-4A241-3A18-7A16-9A14-10A2(13-11A)8(13-9B2A)3(13-A8B2A)5(13-11A)13-10A16-5A190-5A16-2(10A13-)12A3(11-13A)9(11-12BA)2(11-A11BA)6(11-13A)12-11A17-5A139-6A16-9A14-11A12-12A10-4(15A9-)3(14BA9-)3(A13BA9-)2(D13BA9-)2(14BA9-)A13BA4(9-15A)3(10-14A)12-11A17-3A91-6A18-8A14-11A11-14A5(9-15A)4(9-14BA)3(9-A13BA)9-D13B3(A9-14B)A6(9-15A)2(10-14A)14-7A-A17-4A66-8A2(13-12A)10-15A8-15A9-4(16A8-)3(15BA8-)2(D14BA8-)3(A14BA8-)2(15BA8-)A14BA6(8-16A)9-15A9-13A13-9A15-A2-4A17-A2-3A18-A23-11A12-13A11-13A9-3(16A8-)16A5-3C2(16A8-)3(15BA8-)2(D14BA8-)3(A14BA8-)2(15BA8-)A14BA6(8-16A)9-14A10-13A13-7A19-5A19-3A21-A19-14A11-13A10-15A8-17A7-16A8-2(17A4-3C)17A5-2C17A9(7-16BA)2(7-A15BA)6(7-17A)8-14A10-14A12-7A2-A-A13-4A6-A58-14A10-15A8-17A2(6-18A)5-C18A2-4C18A3-3C18A4-2C18A8(6-17BA)3(6-A16BA)6-18A5(7-17A)7-16A9-14A11-8A-A17-4A2-A23-A36-16A8-17A2(6-18A)3-3C18A2-3C-18A-5C18A-4C-18A3-3C18A5-C7(17BA6-)4(A16BA6-)18A6-18A7-17A2(6-18A)7-17A7-16A9-15A10-9A-A15-A-4A20-2A-2A19-A2-A14-17A7-17A6-18A4-2C18A3-3C18A2-4C2(18A6C)18A2-4C18A4-2CA16BA5-CA16B3(A6-17B)6(A6-A16B)A5(6-18A)7-17A7-16A9-15A10-9A-A2-A11-6A-2A3-A15-2A-A4-A16-3A13-17A2(6-18A)4-2C18A3-3C18A2-4C2(18A6C)18A2-4C18A4-2CA16BA5-CA16B3(A6-17B)6(A6-A16B)A5(6-18A)7-17A7-16A9-15A10-9A-A2-A11-6A-2A3-A15-2A-A4-A16-3A14-16A3(6-18A)3-3C18A2-3C-18A-5C18A-4C-18A3-3C18A5-C7(17BA6-)4(A16BA6-)18A6-18A7-17A2(6-18A)7-17A7-16A9-15A10-9A-A15-A-4A20-2A-2A19-A2-A14-17A7-17A3(6-18A)5-C18A2-4C18A3-3C18A4-2C18A8(6-17BA)3(6-A16BA)6-18A5(7-17A)7-16A9-14A11-8A-A17-4A2-A23-A37-15A8-4(17A7-)2(17A4-3C)17A5-2C17A9(7-16BA)2(7-A15BA)6(7-17A)8-14A10-14A12-7A2-A-A13-4A6-A59-13A10-14A9-4(16A8-)16A5-3C2(16A8-)3(15BA8-)3(A14BA8-)2(D14BA8-)2(15BA8-)A14BA6(8-16A)9-14A10-13A13-7A19-5A19-3A21-A21-12A11-13A10-14A9-6(16A8-)4(15BA8-)3(A14BA8-)D14B2(A8-15B)A8-A14BA6(8-16A)9-15A9-13A13-9A15-A2-4A17-A2-3A18-A25-8A14-11A12-12A10-6(15A9-)3(14BA9-)2(D13BA9-)3(A13BA9-)3(14BA9-)5(15A9-)15A2(10-14A)14-7A-A17-4A68-5A17-8A14-10A12-13A10-5(15A9-)3(14BA9-)2(D13BA9-)3(A13BA9-)2(14BA9-)A13BA4(9-15A)3(10-14A)12-11A17-3A119-3A17-7A15-9A13-5(13A11-)9(12BA11-)2(A11BA11-)5(13A11-)13A12-11A17-5A165-2A19-6A16-9A14-4(11A13-)8(9B2A13-)3(A8B2A13-)5(11A13-)10A16-5A214-2A21-5A17-7A3(16-8A)16-3(9A15-)3(8A16-)9A15-8A2(15-9A)5(16-8A)16-7A17-4A289-A22-2A24-2A2(18-7A)16-7A2(18-5A)18-3A-2A17-7A17-8A16-7A17-2A-3A552-2A19-3A-2A18-2A-2A17-7A17-4A-A17-6A18-6A20-3A21-A-2A598-2A-A19-2A-2A18-2A2-A19-3A20-2A22-5A20-3A393-
