model
size = 22 23 25, scale = 0.05, origin = -y
material 
  colors = A:#111 B:#FCFAF2 C:#FEDFE1 D:#AAA
voxels
114-4A6-A476-A2-2A17-A4-A-A389-3(2A20-)2A19-3A-A22-A-3A21-A364-2(4A18-)4A19-3A-A15-A-A2-2A15-A-A3-4A10-A8-A-A366-3(2A2-2A16-)A-3A14-8A13-3A-A3-3A11-A8-2A367-3(5A17-)5A13-9A12-2A4-6A16-13(4A18-)4A19-2A59-10A12-2(11A11-)8(12A10-)12A3(11-11A)12-4(9A13-)9A14-7A15-5A18-5A12-12A10-13A9-14(14A8-)14A9-2(12A10-)12A11-10A13-8A14-8A11-20(14A8-)14A9-12A11-11A8-20(16A6-)15A8-14A9-12A7-17A5-10(18A4-)18A7(5-17A)5-16A6-16A7-14A9-12A7-18A3-19A3-5(20A2-)20A4(3-19A)4-18A4-17A4(6-16A)6-3(15A7-)14A9-12A6-19A3-7(20A2-)20A3(3-19A)4-18A4-17A6-7(15A7-)14A9-12A6-20A2-20A-110A2(-21A)2-2(19A3-)19A4-17A5-17A6-7(15A7-)14A9-12A6-20A-132A-21A2-20A2-2(19A3-)19A4-17A5-16A7(7-15A)7-14A9-12A7-152A-21A2-3(19A3-)18A5-17A5-16A7(7-15A)7-14A10-11A7-19A-132A-21A2-3(19A3-)18A5-17A5-16A7(7-15A)7-14A10-11A8-18A3-20A-131A2-3(19A3-)18A5-17A5-16A5(7-15A)7-2(14A8-)14A10-11A9-16A5-18A2-9A5(2B20A)2B10A-9A2B9A3-8A2B8A4-8A2(2B8A5-7A)2B7A6-7A2B7A7-3(6A2B6A8-)2(6AB7A8-)2(14A8-)14A10-11A9-16A5-18A3-8A6(2B9A2-9A)2B9A3-8A2B8A4-8A2(2B8A5-7A)2B7A6-7A2B7A7-5(6A2B6A8-)2(14A8-)14A10-11A10-15A6-17A3-7A6(4B8A2-8A)4B8A3-7A4B7A4-7A2(4B7A5-6A)4B6A6-6A5(4B5A8-5A)4B5A8-7AB6A2(8-14A)10-11A11-13A7-16A5-6A9(6B5A4-7A)6B5A5-6A6B4A6-6A2(6B3A8-5A)4(6B3A9-4A)5B4A9-4A5B4A9-13A10-10A12-13A8-14A7-4A11(4B2CD4A6-5A)2(4B2CD3A9-3A)2(4B2CD3A8-4A)4B3C2(3A8-4A7B)3A9-4A5B4A10-10A14-7A45-2A20-2A10-A9(9-2A8-3A)3(9-2A)8-3A9-A10-2A9-A11-A9-3(A21-)A12-2A6-2A13-7A-A14-5A90-11(2A20-)A21-A159-
