model
size = 21 13 30, scale = 0.05, origin = -y
material 
  colors = A:#222 B:#FCFAF2
voxels
77-3A11-7A182-2(7A14-)B5AB15-B3AB16-2(AB)A16-2ABA20-B140-11A10-10A11-AB7AB2(11-10A)11-9A12-4AB3A15-AB3AB117-7A3-3A2(8-13A)8-2(12A9-)11A10-2(10A11-)2A2B5A13-8A74-7A5-3A2(6-15A)6-2(14A7-)2(13A-A6-)13A9-9AB11-10A12-5A55-5A9-3A6(4-17A)5-15A6-11AB2A8-11A11-9A50-5A10-4A2-4A9-6A2-5A4(-A)-5A2(2-4A9-6A)3-4A8-6A3-18A3-9A-7A5-15A6-14A8-4AB3ABA12-3A35-4A11-4A2-2A11-6A4(2-2A12-5A)2(3-A12-5A)3-17A5-16A6-7A2B5A8-3A3B3-A27-5A11-8A12-9A14-7A3(14-4A-2A)14-4A2-A14-4A2-18A4-17A5-15A7-2(3AB)4A25-4A13-7A13-8A2(14-7A)3(14-4A-2A)14-4A-19A3-18A5-15A7-13A24-4A14-6A14-7A15-6A2(14-7A)2(14-4A-2A)14-4A-2(5AB)7A3-18A5-15A6-4A6B4A9-AB13-3A15-5A15-6A16-5A3(15-6A)15-4A-A15-3A2-6AB3AB8A3-17A6-15A6-14A9-4AB4A6-3A15-5A15-6A16-5A3(15-6A)15-3A2-A15-3A2-7ABAB9A3-17A5-16A6-14A8-3A4B5A4-3A15-5A15-6A16-5A2(15-6A)2(15-3A2-A)15-3A2-8AB10A3-17A5-15A7-14A8-12A4-3A15-5A15-6A16-5A15-4A-3(A15-3A2-)A15-3A3-6ABAB8A4-17A5-15A7-14A8-A2B4A2B3A5-3A13-7(3A2-A15-)2A4-5AB3AB7A4-17A5-15A7-14A8-3A4B2A8-3A13-3(3A2-2A14-)2(3A2-A15-)2(2A4-A14-)2A4-4AB5AB6A5-15A6-15A7-13A10-4A13-2A11-4A4-A14-2A5(4-A12-4A)4-A12-3A2(6-15A)7-13A8-7AB2A31-2A10-7(3A6-A11-)3A6-14A8-13A8-11A13-A3B2A32-3A10-A2(7-2A9-3A)5(8-A9-3A)8-13A9-11A12-B5A17-BA34-3A10-A7-4A6-4A7-4A5(5-4A10-2A)5-4A10-10A12-2A3B3A73-3A10-2A6-4A9-A7-14A9-5(9A12-)9A13-5AB2A73-A13-A7-2A10-A8-2A8-3A10-4AB3A199-A13-A7-2A10-A8-2A8-3A10-A4B3A199-A13-A7-2A10-A8-2A8-3A10-AB6A199-A13-A7-2A10-A8-2A8-3A10-2AB5A199-A13-A7-2A10-A8-2A8-3A10-AB6A199-A13-A7-2A10-A8-2A8-3A10-A4B3A199-A13-A7-2A10-A8-2A8-3A10-4AB3A221-2A10-A8-2A8-3A10-8A196-
