model
size = 22 17 22, scale = 0.05, origin = -y
material 
  colors = A:#FFF B:#0052FF C:#008FFF D:#00B1FF E:#0039FF F:#EA00FF G:#B80CFF H:#890CFF I:#750CFF J:#5E0CFF K:#0078FF L:#4100FF M:#0063FF N:#0028FF
voxels
31-4A348-4A368-8A364-12A361-14A13-15(F2EF18-)F2EF12-16A10-2B4A2B14(14-GB4ABG)14-2B4A2B9-18A8-2(M8AM12-)12(H8AH12-)M8AM12-M8AM8-6A6-6A7-K2A6-2A2(K10-K10A)K2(10-I10AI)10-I3A4-3A7(I10-I10A)I3(10-K10AK)6-5A10-5A5-C2A8-2A3(C8-C3A6-3A)C8-J2A-6A-2A7(J8-J12A)J3(8-C12AC)8-C2A8E2AC5-5A10-5A5-5(C2A8-2AC8-)CA-A6-A-A9(C8-C12A)C8-C2AEA4EAE2AC4-5A12-5A3-5(D3A8-3AD6-)L3A8-3A5(L6-L14A)L4(6-D14AD)6-D3AEA4EAE3AD3-5A12-5A3-5(D2A10-2AD6-)D3A8-3AD4(6-N14AN)6(6-D14AD)3-5A12-5A3-5(D2A10-2AD6-)D3A8-3AD4(6-N14AN)5(6-D14AD)6-D4A6B4AD3-5A12-5A3-5(D3A8-3AD6-)L3A8-3A5(L6-L14A)L4(6-D14AD)6-D3A8B3AD4-5A10-5A5-5(C2A8-2AC8-)CA-A6-A-A9(C8-C12A)C8-C2A8B2AC5-5A10-5A5-C2A8-2A3(C8-C3A6-3A)C8-J2A-6A-2A7(J8-J12A)J3(8-C12AC)8-C3AB4AB3AC2(6-6A)7-K2A6-2A2(K10-K10A)K2(10-I10AI)10-I3A4-3A7(I10-I10A)I2(10-K10AK)10-K2AB4AB2AK7-18A8-2(M8AM12-)12(H8AH12-)M8AM12-M8AM9-16A10-2B4A2B14(14-GB4ABG)14-2B4A2B11-14A13-15(F2EF18-)F2EF14-12A364-8A359-
