model
size = 22 17 23, scale = 0.05, origin = -y
material 
  colors = A:#FF0061 B:#B80CFF C:#890CFF D:#5E0CFF E:#750CFF F:#0063FF G:#0052FF H:#0039FF I:#0028FF J:#4100FF K:#EA00FF L:#0078FF M:#00DFFF N:#00C3FF O:#008FFF P:#00B1FF Q:#00F5FF R:#1A1B26
voxels
9-4A368-8A364-12A361-14A359-16A11-6Q16-6M16-6N16-6P16-6O16-6L16-6F16-6G16-6H16-6I16-6J16-6D16-6E16-6C16-6B16-6K10-18A8-3Q4-3Q12-10M12-10N12-10P12-10O12-10L12-10F12-10G12-10H12-10I12-10J12-10D12-10E12-10C12-10B12-10K7-2(7A6-)12Q10-12M10-12N10-4P4-4P10-3O6-3O10-4L4-4L10-12F10-12G10-12H10-12I10-12J10-12D10-12E10-12C10-12B10-12K6-6A8-6A5-2(3Q8-)2(3M8-)2(3N8-)2(3P8-)2(3O8-)4L6-4L8-14F8-14G8-14H8-14I8-14J8-14D8-14E8-14C8-14B8-14K5-5A10-5A5-2Q10-2Q8-2M10-2M8-2N10-2N8-2P10-2P2(8-3O)2(8-3L)8-14F8-14G8-14H8-14I8-14J8-14D8-14E8-14C8-14B8-3K8R3K4-6A10-6A4-2Q10-2Q8-2M10-2M8-2N10-2N8-2P10-2P8-2O10-2O2(8-3L)8-14F8-14G8-14H8-14I8-14J8-14D8-14E8-14C8-14B8-3KRK4RKR3K4-5A12-5A3-3Q10-3Q6-3M10-3M6-3N10-3N6-3P10-3P6-3O10-3O6-4L8-4L6-16F6-16G6-16H6-16I6-16J6-16D6-16E6-16C6-16B6-4KRK4RKR4K3-5A12-5A3-3Q10-3Q6-3M10-3M6-3N10-3N6-3P10-3P6-3O10-3O6-4L8-4L6-16F6-16G6-16H6-16I6-16J6-16D6-16E6-16C6-16B6-16K3-5A12-5A3-3Q10-3Q6-3M10-3M6-3N10-3N6-3P10-3P6-3O10-3O6-4L8-4L6-16F6-16G6-16H6-16I6-16J6-16D6-16E6-16C6-16B6-5K6R5K3-5A12-5A3-4Q8-4Q6-4M8-4M6-4N8-4N6-4P8-4P6-4O8-4O6-4L8-4L6-16F6-16G6-16H6-16I6-16J6-16D6-16E6-16C6-16B6-4K8R4K4-5A10-5A5-2(3Q8-)2(3M8-)2(3N8-)2(3P8-)2(3O8-)2L-L6-L-2L8-14F8-14G8-14H8-14I8-14J8-14D8-14E8-14C8-14B8-3K8R3K5-5A10-5A5-2(3Q8-)4M6-4M8-4N6-4N8-4P6-4P8-3O-6O-3O8-14L8-14F8-14G8-14H8-14I8-14J8-14D8-14E8-14C8-14B8-2(4KR)4K2(6-6A)7-3Q6-3Q10-12M10-12N10-12P10-12O10-4L4-4L10-12F10-12G10-12H10-12I10-12J10-12D10-12E10-12C10-12B10-3KR4KR3K7-18A8-10Q12-10M12-10N12-10P12-10O12-10L12-10F12-10G12-10H12-10I12-10J12-10D12-10E12-10C12-10B12-10K9-16A10-8Q14-8M14-8N14-8P14-8O14-8L14-8F14-8G14-8H14-8I14-8J14-8D14-8E14-8C14-8B14-8K11-14A13-4Q18-4M18-4N18-4P18-4O18-4L18-4F18-4G18-4H18-4I18-4J18-4D18-4E18-4C18-4B18-4K14-12A364-8A368-4A361-
