model
size = 26 31 26, scale = 0.05, origin = -y
material 
  colors = A:#1A1A1A B:#434343 C:#00FF15 D:#777
voxels
36-6A20-C2A2(CAC20-3A)2CA20-3ACAC20-C2A3C20-6A618-6A20-AC2A2C20-AC2ACA20-C3A2(CA20-AC2A)2C20-6A641-12A2(14-2AC6AC2A)14-9A2(C2A14-2AC6A)C2A14-12A18-2BCB22-2(BC)22-C3B563-4A2(6-4A12-C3A)3(6-3AC12-C3A)6-3AC12-4A6-4A14-BCB4-2BC16-CBC4-BCB16-3B4-C2B16-10A17-8A20-C3B22-2(BC)22-2BCB432-2A12-2A10-CA12-AC2(10-2A12-2A10-CA12-2A)2(10-3A)11-2B10-2B12-CB10-CB12-BC10-BC13-2A8-2A14-3A6-3A15-4B2-BC2B16-2(CB)2-2BCB16-BC2B2-3BC18-6A404-2A14-2A8-CA14-2A3(8-2A14-AC)8-CA14-AC8-2A14-2A9-C14-B10-B14-C10-B14-B10-2A12-2A11-2A10-2A13-CB8-2B14-2B8-BC14-2B8-2B15-2A6-2A17-8A18-2BC3BCB350-6(2A16-2A6-)2A16-2A7-B16-C8-C16-B8-B16-B8-2A14-2A9-A14-A10-2B12-CB10-BC12-BC10-CB12-2B11-2A10-2A13-3A6-3A15-BA6BA2B16-4(BC)323-6(2A18-2A4-)2A18-2A5-B18-B6-B18-C6-C18-B7-A16-A8-A16-A9-B14-B10-C14-B10-B14-C10-2A12-2A11-2A10-2A12-C3B6-4B14-CB6-2B18-3BC2B20-6A271-2A20-2A5(2-CA20-AC)2-3A18-3A4-B18-B6-C18-B6-B18-C6-A18-A6-AB16-2A7-C16-B8-B16-C8-B16-B9-A14-A10-AB12-2A11-3B8-3BC12-2B8-BC15-BC2B2-2BCB16-4A2-4A19-4A246-2A20-2A2-CA20-AC3(2-2A20-2A)2-2A20-AC2-2A20-2A3-C20-B4-B20-C4-B20-B4-2A18-2A5-A18-A6-2B16-BC6-CB16-2B6-2B16-2B7-A16-A9-A14-A2(10-3B)11-CB10-2B13-3B6-3B14-3A6-3A16-2AC2BC2A72-4A22-AC2A2(22-4A)90-2A20-2A2-CA5(20-AC2-2A)20-2A3-B20-C4-C20-B4-B20-B4-A20-A4-2A18-2A5-B18-B6-B18-C6-C18-B7-A16-A8-2A14-2A8-BAB12-BAB9-2B12-BC12-CB8-BC14-2A8-2A15-AC6BCA20-2A22-B5A20-5AB19-8A18-B7A19-6A20-2(2AB)22-2A38-2A3(22-4A)3(21-B4A)22-2A2-B20-B4-B20-C4-C20-B2(4-A20-A)5-B18-B6-C18-B6-B18-C6-A18-A7-A16-A8-2B14-BC9-C14-B11-2B10-2B12-2A10-2A14-A2B4-2BA18-6A19-5(8A18-)8A19-6A36-2A3(22-4A)21-B4A21-D4A21-B4A22-2A-B22-B2-C22-B2-B22-C3-2(A20-A4-)CB18-2B4-2B18-BC4-2B18-2B5-A18-A7-A16-A8-CB14-2B9-B14-C11-2B10-2B12-2A10-BA13-ACB6-BCA17-4A2B19-8A17-2(10A16-)C8AB16-10A17-B7A19-6A21-BACA11-2A22-2ACA22-4A22-2ACA21-B2ACA21-D2ACA21-BAC2A22-2A-C22-B2-B22-C2-B22-B3-2(A20-A4-)B20-C4-C20-B4-B20-B5-A18-A7-A16-A8-2B14-2B9-C14-B11-B12-C2(12-A)13-A2B6-2BA16-8A18-B7A17-3(10A16-)10A17-8A18-7AC20-4A11-2A22-2ACA22-AC2A22-A2CA21-BAC2A21-DA2CA21-BAC2A22-2A-B22-C2-C22-B2-B22-B3-2(A20-A4-)B20-B4-B20-C4-C20-B5-A18-A7-A16-A8-2B14-2B9-B14-C11-C12-B2(12-A)13-A2B6-2BA16-8A18-8A17-10A16-9AB2(16-10A)17-8A18-8A20-4A11-2A3(22-2ACA)21-B4A21-B2ACA21-BAC2A22-2A-B22-B2-B22-C2-C22-B3-2(A20-A4-)2B18-2B4-CB18-2B4-2B18-BC5-A18-A7-A16-A8-2B14-BC9-C14-B11-2B10-2B12-2A10-2A13-ACB6-BCA17-6A19-7AC17-3(10A16-)B9A17-8A19-6A21-2ABA11-2A3(22-4A)3(21-5A)22-2A2-B20-B4-C20-B4-B20-C2(4-A20-A)5-C18-B6-B18-C6-B18-B6-A18-A7-A16-A8-CB14-2B9-B14-C11-2B10-2B12-2A10-2A14-A2B4-2BA18-6A19-B7A3(18-8A)18-7AB18-8A19-C5A37-6(2A20-2A2-)2A20-2A3-C20-B4-B20-C4-B20-B4-A20-A4-2A18-2A5-B18-C6-C18-B6-B18-B7-A16-A8-2A14-2A8-BAB12-BAB9-CB12-2B12-CB8-BC14-2A8-BA15-AC6BCA20-AB22-6A20-6A19-8A18-8A19-6A20-6A22-AB39-3(2A20-2A2-)3(2A20-AC2-)2A20-2A3-B20-C4-C20-B4-B20-B4-2A18-2A5-A18-A6-2B16-2B6-2B16-BC6-CB16-2B7-A16-A9-A14-A2(10-3B)11-2B10-BC13-3B6-3B14-2AB6-3A16-2AC2BC2A72-4A22-3AC22-B3A22-4A90-2(2A20-2A2-)BA20-2A2-2A20-AC2-2A20-2A2-2A20-AC2-3A18-3A4-B18-B6-B18-C6-C18-B6-A18-A6-2A16-2A7-B16-B8-C16-B8-B16-C9-A14-A10-2A12-2A11-3B8-4B12-CB8-2B15-BC2B2-2BCB16-4A2-4A19-4A247-2A18-2A4-2A18-AC4-BA4(18-AC4-2A)18-2A5-B18-B6-C18-B6-B18-C7-A16-A8-A16-A9-C14-B10-B14-C10-B14-B10-2A12-2A11-2A10-2A12-C3B6-3BC14-2B6-BC18-2BC3B20-6A273-2(2A16-2A6-)BA4(16-2A6-2A)16-2A7-C16-B8-B16-C8-B16-B8-2A14-2A9-A14-A10-2B12-BC10-CB12-CB10-BC12-2B11-2A10-2A13-3A6-3A15-BA6BA2B16-4(CB)325-2(2A14-2A8-)BA4(14-2A8-2A)14-2A9-B14-C10-C14-B10-B14-B10-2A12-2A11-2A10-2A13-2B8-2B14-CB8-2B14-2B8-BC15-2A6-2A17-8A18-BC3BC2B352-3(2A12-2A10-)3(2A12-AC10-)3A10-3A11-2B10-2B12-BC10-BC12-CB10-CB13-2A8-2A14-3A6-3A15-C3B2-2BCB16-BC2B2-2(BC)16-2BCB2-4B18-6A406-4A6-4A3(12-4A6-3AC)3(12-4A6-4A)14-C2B4-BCB16-BCB4-CBC16-2BC4-3B16-10A17-8A20-BC2B22-2(CB)22-3BC434-12A14-A2C9A14-AC10A2(14-AC9AC)14-A2C8AC14-12A18-BC2B22-2(CB)22-3BC557-
