model
size = 25 28 18, scale = 0.05, origin = -y
material 
  colors = A:#F90 B:#888 C:#FF0 D:#E00 E:#D00 F:#008
voxels
34-7C16-2C7-2C12-2C11-2C9-C15-C7-C5-8B4-C5-C6-8B5-C4-C6-8B5-C3-C7-8B6-C2-C7-8B6-C-C3-5B9-5C-3(2C3-5B11-C3-)2C3-5B9-C-C3-2C3-5B10-2(2C3-)5B11-C3-C-C7-8B6-C2-C7-8B6-C3-C6-8B5-C4-C6-8B2(5-C)5-8B4-C7-C15-C9-2C11-2C12-2C7-2C16-7C719-6D18-7D668-7D18-D5FD667-2D5-2D16-DF5-FD665-2D7-2D15-FD5-DF664-DF9-FD14-D7-D663-DFD9-DFD12-2D7-2D661-DFD11-DFD10-2D9-2D2(660-DF13-FD10-D11-D)660-DFE11-EFD10-DE9-ED661-EF11-FE12-E9-E662-EFE9-EFE12-2E7-2E663-EFE7-EFE14-2E5-2E665-EF7-FE16-E5-E641-2E7-FE14-EFE5-EFE16-E5-E616-2E7-FE14-EFE5-EFE16-E5-E43-7A16-11A12-15A9-17A7-19A5-21A4-21A3-23A2-23A-175A-23A2-23A3-21A4-21A5-19A7-17A9-15A12-11A14-EF7AFE16-E5-E59-
