model
size = 32 18 11, scale = 0.05, origin = -y
material 
  colors = A:#309 B:#111 C:#444 D:#E00 E:#0C9 F:#00E G:#6F3 H:#EEE I:#0CF J:#FF0
voxels
10-2(20B12-)20F12-10AI9A13-9A4I6A15-10A3I3A17-11AI3A18-10A3I22-10A26-5A90-11G85-11G67-8B18D2B4-28B4-28F4-17AI10A4-17A4I7A5-19A3I5A7-19AI5A9-AH15A3I3A12-HAH17A15-AH15A18-H13A20-12A20-H11AG20-2(11A21-)11AG22-9A24-8A2-3B26D2B-31B-2F27ABF-18A10C3A2-17A11C2A3-17A10CA6-15A10CA9-AH11A9CA12-HAH7A9CA15-AH5A9CA18-H4A8CA20-3A8CA20-H2A8CAG20-2(2A8CA21-)2A8CAG22-8CA24-7CA-2B4D2(3BD)B3(D3B)4D33BF18A10DABF18AB10-C2A-17AB10-C2A3-15A2B9-C2A5-3AEAE9A9-CA10-H-2EAE5AB8-CA12-2(H-)2E3AB8-CA16-H-3EA8-CA18-H2-2E7-CA21-2E7-CA20-HAE7-CAG20-2(2E7-CA21-)2E7-CAG20-2E7-CA21-2E7-CA-B5D10(BD)B4D33BF18A9BDABF18AB10-C2A-17AB10-C2A3-15A2B9-C2A5-2A2EAE9A9-C2A9-H-2EAE5AB8-CA12-2(H-)2E3AB8-CA16-H-3EA8-CA18-H2-2E7-CA21-2E7-CA20-HAE7-CAG20-2E2(7-CA21-DE)7-CAG20-DE7-CA21-2E7-C2GB5D10(BD)B4D33BF18A9BDABF18AB10-C2A-17AB10-C2A3-15A2B9-C2A5-2A2EAE9A9-C2A9-H-2EAE5AB8-C2A11-2(H-)2E3AB8-C2A15-H-3EA8-C2A17-H2-2E7-CA21-2E7-CA20-HAE7-CAG20-2E7-CA21-DE7-CA21-JE7-CAG20-DE7-CA21-2E7-C2HB7DBD3B7(DB)4D33BF18A9BDABF18AB10-C2A-17AB10-C2A3-15A2B9-C2A5-2A2EAE9A9-C2A9-H-2EAE5AB8-CA12-2(H-)2E3AB8-CA16-H-3EA8-CA18-H2-2E7-CA21-2E7-CA20-HAE7-CAG20-2E2(7-CA21-DE)7-CAG20-DE7-CA21-2E7-C2G2B6DBDB3DB3(D3B)4D33BF18A10DABF18AB10-C2A-17AB10-C2A3-15A2B9-C2A5-3AEAE9A9-CA10-H-2EAE5AB8-CA12-2(H-)2E3AB8-CA16-H-3EA8-CA18-H2-2E7-CA21-2E7-CA20-HAE7-CAG20-2(2E7-CA21-)2E7-CAG20-2E7-CA21-2E7-CA2-3B26D2B-31B-2F27ABF-18A10C3A2-17A11C2A3-17A10CA6-15A10CA9-AH11A9CA12-HAH7A9CA15-AH5A9CA18-H4A8CA20-3A8CA20-H2A8CAG20-2(2A8CA21-)2A8CAG22-8CA24-7CA4-8B18D2B4-28B4-7F20BF2(4-28A)5-27A7-25A9-AH21A12-HAH17A15-AH15A18-H13A20-12A20-H11AG20-2(11A21-)11AG22-9A24-8A11-2(20B12-)20F12-10AI9A13-9A4I6A15-10A3I3A17-11AI3A18-10A3I22-10A26-5A91-10G86-10G64-
