model
size = 17 6 14, scale = 0.05, origin = -y
material 
  colors = A:#600 B:#BBB C:#AAA D:#111
voxels
7-2(CB)C6-CBC14-B2A2-2(CB)C7-C4AB3AB8-2(AD)CAD2C9-2(3AB)45-2ACBC2A10-2ABCB2A10-2ACBC2A58-BCA7-A2B4-CBA7-ABC4-BCA7-ACB54-C13-C2-B13-B2-C13-B52-2(A2(15-2A)15-A51-)C15-CB15-BC15-C51-B15-BC15-CB15-B51-C15-CB15-BC15-C2(51-A2(15-2A)15-A)52-C13-C2(2-B13-B)54-B11-B4-C11-C4-B11-B56-2(B9AB6-)C9AC20-
