model
size = 32 18 11, scale = 0.05, origin = -y
material 
  colors = A:#81C7D4 B:#FCFAF2 C:#787D7B D:#F7D94C E:#3A8FB7 F:#BDC0BA G:#005CAF H:#58B2DC I:#111 J:#C1328E K:#FF007F L:#0B346E M:#F75C2F
voxels
10-2(20B12-)20F12-10AH9A13-9A4H6A15-10A3H3A17-11AH3A18-10A3H22-10A26-5A90-11G85-11G67-8B18D2B4-28B4-28F4-17AH10A4-17A4H7A5-19A3H5A7-19AH5A9-AB15A3H3A12-BAB17A15-AB15A18-B13A20-12A20-B11AG20-2(11A21-)11AG22-9A24-8A2-3B26D2B-31B-2F27ABF-18A10C3A2-17A11C2A3-17A10CA6-15A10CA9-AB11A9CA12-BAB7A9CA15-AB5A9CA18-B4A8CA20-3A8CA20-B2A8CAG20-2(2A8CA21-)2A8CAG22-8CA24-7CA-2B4D2(3BD)B3(D3B)4D33BF18A10KABF18AI10-C2A-17AI10-C2A3-15A2I9-C2A5-3AEAE9A9-CA10-B-2EAE5AI8-CA12-2(B-)2E3AI8-CA16-B-3EA8-CA18-B2-2E7-CA21-2E7-CA20-BAE7-CAG20-2(2E7-CA21-)2E7-CAG20-2E7-CA21-2E7-CA-B5D10(BD)B4D33BF18A9JKABF18AI10-C2A-17AI10-C2A3-15A2I9-C2A5-2A2EAE9A9-C2A9-B-2EAE5AI8-CA12-2(B-)2E3AI8-CA16-B-3EA8-CA18-B2-2E7-CA21-2E7-CA20-BAE7-CAG20-2E2(7-CA21-DE)7-CAG20-DE7-CA21-2E7-C2GB5D10(BD)B4D33BF18A9JKABF18AI10-C2A-17AI10-C2A3-15A2I9-C2A5-2A2EAE9A9-C2A9-B-2EAE5AI8-C2A11-2(B-)2E3AI8-C2A15-B-3EA8-C2A17-B2-2E7-CA21-2E7-CA20-BAE7-CAG20-2E7-CA21-DE7-CA21-ME7-CAG20-DE7-CA21-2E7-C2LB7DBD3B7(DB)4D33BF18A9JKABF18AI10-C2A-17AI10-C2A3-15A2I9-C2A5-2A2EAE9A9-C2A9-B-2EAE5AI8-CA12-2(B-)2E3AI8-CA16-B-3EA8-CA18-B2-2E7-CA21-2E7-CA20-BAE7-CAG20-2E2(7-CA21-DE)7-CAG20-DE7-CA21-2E7-C2G2B6DBDB3DB3(D3B)4D33BF18A10KABF18AI10-C2A-17AI10-C2A3-15A2I9-C2A5-3AEAE9A9-CA10-B-2EAE5AI8-CA12-2(B-)2E3AI8-CA16-B-3EA8-CA18-B2-2E7-CA21-2E7-CA20-BAE7-CAG20-2(2E7-CA21-)2E7-CAG20-2E7-CA21-2E7-CA2-3B26D2B-31B-2F27ABF-18A10C3A2-17A11C2A3-17A10CA6-15A10CA9-AB11A9CA12-BAB7A9CA15-AB5A9CA18-B4A8CA20-3A8CA20-B2A8CAG20-2(2A8CA21-)2A8CAG22-8CA24-7CA4-8B18D2B4-28B4-7F20BF2(4-28A)5-27A7-25A9-AB21A12-BAB17A15-AB15A18-B13A20-12A20-B11AG20-2(11A21-)11AG22-9A24-8A11-2(20B12-)20F12-10AH9A13-9A4H6A15-10A3H3A17-11AH3A18-10A3H22-10A26-5A91-10G86-10G64-
