model
size = 30 27 7, scale = 0.05, origin = -y
material 
  colors = A:#555 B:#888 C:#AAA D:#777 E:#FF0 F:#200 G:#444 H:#FC0
voxels
6-BD3BD9BD2B13-2DBD4B2(DB)2D2B15-BD2BD9B17-3(3EF)18-6(EF)18-3(3EF)19-10B20-4C2B4C18-DCD3C2B6C16-BD12B16-CD4C2B4CDC15-D6C2B3CD3C14-B2D11BDB14-CD5C2B3CD3C13-2CDCD3C2B5CD2C12-2DBD11BD2B12-8C2B3CD4C11-C3D5C2B6CD2C10-13BC6B5-2A3-BCB2(2C2B)3CB2CBCB3-5B2-BC2(B2C)4B2CBD2(CB)2-BC2BC4B2(CBD)2C2B3CB2CBC6B2-B2CBC2(B2C)B2GBCDB2CBCBDCB4-2(B2CBC)BG2-G2(BC)2BCB2CB4-4BCB2C2BG4-G2(2BC)4B7-BCB2CBG6-GBC2BCB2(10-5B)11-18A13-D15A15-14A17-2(F10AF18-)F10AF19-10A20-10A18-2(14A16-)13AC15-2(16A14-)16A13-2(18A12-)18A11-20A10-20A5-2A3-20A3-5A2-20A2-33A2-26A4-12A2-12A2(4-11A)7-3AC3A6-7A10-4A12-4A11-C16-A13-D2A10-3A15-2A10-2A17-2(E10-E18-)E10-E77-A12-C16-A12-A16-A12-D15-2(D14-C14-)C14-A13-C16-D12-A16-C12-A16-A66-2A26-AC3A24-10A16-6AD2-5A16-5A4-C4A16-5A4-2AD2A16-3ADA7-3A15-2A10-AD2A12-2A2D11-A16-A13-D2A10-3A15-2A10-2A17-E10-E18-F10-F18-E10-E77-A12-A16-C12-A16-A12-A15-2(D14-A14-)D14-A13-A16-D2(12-A16-A)66-CA26-5A24-3AC6A16-6AC2-5A16-4AD2(4-5A16-5A)7-3A15-AD10-CADA12-2A2D11-A16-A13-3A10-3A15-2A10-2A17-2(E10-E18-)E10-E77-A12-A2(16-C12-D)15-C2(14-A)14-D14-A14-D13-A16-A12-D16-C12-A16-A66-2A26-AC3A24-3A2D5A16-6AD2-D4A2(16-5A4-5A)16-2A2DA7-3A15-2A10-4A12-AC2D11-18A13-16A15-14A17-2(F10AF18-)F10AF19-10A20-10A18-14A16-13AD16-C13A15-2C14A2(14-16A)13-2(18A12-)18A11-20A10-20A5-2A3-20A3-5A2-20A2-33A2-26A4-12A2-12A4-C10A4-11A7-3AC3A6-7A10-4A12-2ADA11-2BD9BD3BDB13-2B2D2(BD)4BDB2D15-9BD2BDB17-3(F3E)18-6(FE)18-3(F3E)19-10B20-2CEH2BHE2C18-6C2B3CDCD16-12BDB16-CD2CEH2BHE2CDC15-3CD3C2B6CD14-BD11B2DB14-3CDCEH2BHE3CDC13-2CD5C2B3CDCD2C12-2BD11BDB2D12-4CDCEH2BHE6C11-2CD3CE2C2B2CE2C3DC10-2(6BG)6B5-2B3-BCB2CBE2C2B2CEB2CBCB3-2ABCB2-2(BC)DB2C4FACB2CBCB2-9BCB2CB3C2B2C2(DBC)4BCB2-BCDBCB2CBDCB2G2(B2C)BCB2CB4-B2CBCBE2(CB)G2-G2(BC)EBCB2CB4-4BCBGC2BG4-G2BCGBC4B7-BCBECBG6-GBCEBCB2(10-5B)5-
