model
size = 16 22 20, scale = 0.05, origin = -y
material 
  colors = A:#84492C B:#000 C:#94453E
voxels
213-7A9-7A5(8-8A)9-5A12-4A145-4(A15-)A286-3A8-8A3(7-9A)5-11A5-2(8A9-)7A8-8A8-2A14-2A-6A10-6A143-3A13-3A7-9A2(6-10A)4-A-10A2(3-13A)7-8A14-2A6-5A3-2A6-4A4-2A6-10A6-9A44-2(A-3A11-)3(6A10-)2A-3A9-3A-3A7-5A-3A4(3-13A)2(2-14A)2-13A3-5A5-3A2(3-13A)4-12A4-11A27-A15-2(2A2-3A9-)3(3A-3A9-)3A-3A5-2A2-3A-3A5-7A-3A4(3-13A)2(2-14A)2-13A3-7A3-3A2(3-13A)4-12A4-11A25-3A13-9A2(5-11A)2(5-5A3-3A)5-4A3-4A5-2A2-A2-4A5-11A2(3-13A)5(2-14A)2-7A3-4A2-29A4-12A4-11A24-4A12-11A3(4-12A)4-5A-6A4-4A2-6A4-12A3-13A2(2-14A)2(-15A)-9A2-4A3(-15A)-5A2-14A-7A4-4A-7A4-12A24-3A8-12A-2A2(-15A)3-2(6A-)8A-6A-7A2-6A-11A-3A3-5A2-2A-3A2-6A2-2A-3A2-10A2(-15A)-13A2-59A-22A2(4-12A)23-4A8-31A-15A3-13A-7AB-6A-8A-6A-15A3-5A2(2-6A)2-7A-117A-22A2(4-12A)23-4A8-35A2B10A3-4A2B7A-6ABA-6A-8A-6A-7A-B6A3-5A3(2-6A)2-14A2-124A2(4-12A)5-3A15-4A13-3A-6A2(3-A3-9A)3-2A2-9A2(4-5A-6A)4-12A3-13A5(2-14A)4(4-12A)4-3(10A6-)2A15-4A8-12A-15A-5AB12A3-13A2(-8A-6A)-15A3-13A3(2-14A)6(-15A)-13A2(4-12A)5-3A15-4A8-31A-2A3B10A3-4A3B6A3(-15A)3-13A2(2-14A)-125A4-7A3-2A4-12A5-3A16-3A8-3A-11A2(-15A)3-7A-5A-7AB2(2-5A-8A)2-5A3-13A2-15A-40A4(-15A)-35A4-7A-4A4-12A6-2A16-3A10-A-10A2(4-12A)6-5A-4A6-4A2-4A6-3AB2-4A6-4A2-4A5-12A2-14A2-40A4(-15A)-35A4-7A-4A4-6A-4A24-4A12-8A6-11A5-7AC-2A5-11A5-6A2BA-A5-5ABA3-A5-6A4-A4-7A4-A3(4-12A)3-5(14A2-)29A4-7A-4A4-7A-3A60-4A11-5A11-AC3A10-2A2B2A10-ABA2BA10-6A6-10A3(5-11A)2(4-12A)4-14A2(2-8A-5A)2-8A-15A-4A4-7A-4A92-2(A14-)3(5A11-)5A6-10A5-11A5-7A-3A5-11A4-12A4-3(13A3-)12A4-12A5-7A-3A7-5A111-3(5A11-)5A2(12-4A)13-3A2(9-7A)2(5-11A)2(8-8A)2(9-7A)9-5A22-
