model
size = 11 14 19, scale = 0.05, origin = -y
material 
  colors = A:#D9CDC1 B:#FFF
voxels
90-2(8A3-)8A4-7A6-5A7-4A90-2(10A-)10A3-8A4-7A5-6A2-A9-10A2-9A11(-10A)2-A9-10A2-9A9(-10A)2-9A-10A2-A9-8(10A-)6A3-A-10A2-9A2(-10A)2-A9-5(10A-)8A-A3(-10A)2-3A2-2(4A-)5A-4A-5A-10A12-10A2(-10A2-9A)-8A-A3-8A-10A2-9A-5A-4A3(B10A)11-11A-10A3(3-8A2-9A)3-8A2-4A-4A3(B10A)11-11A-10A4(3-8A2-9A)3(B10A)11-11A-10A4(3-B7A2-9A)2-9A-B-8A-10A11-11A-10A4(3-8A2-9A)3(B10A)11-11A-10A4(3-8A2-9A)B10AB7A2-AB10A2-A9-10A-10A2-9A-10A2(2-7A-A-8A-A)2-7A-A-2(10AB)7A-2AB10A2-A9-2(10A-)A-8A-10A-A-6A4(-A-8A)-A2-9A-10A-7A-2A-10A2-A9-2A9-8(10A-)10A2-9A2(-10A)2-A9-2A10-9A8(-10A)-7A-2A2-9A-10A2-A9-2A10-A5(9-2A)9-2(9A2-)9A3-8A2(2-9A)90-2(9A2-)9A3(6-5A)93-3(5A6-)5A7-4A8-3A2-
