model
size = 20 28 20, scale = 0.05, origin = -y
material 
  colors = A:#327345 B:#000
voxels
-99A4B3(12A8B)12A84B8A3(8B12A)8B4(16A4B)4A8B3(4A16B)4A8B10700A
