model
size = 26 31 26, scale = 0.05, origin = -y
material 
  colors = A:#252525 B:#EEE C:#00FF98 D:#F00 E:#8700FF F:#F70 G:#F90 H:#FB0 I:#FD0 J:#BFFF00 K:#00FF48 L:#FF3700 M:#FF5900 N:#0CFF00 O:#00A1FF P:#50F Q:#A500FF R:#005DFF S:#D4864E T:#FF6 U:#D4AB8E
voxels
36-6A20-BAB2AB20-2(2AB)20-2A3BA20-2(2AB)20-BA3BA20-6A618-6A20-BA3BA20-B3ABA20-B2A2BA20-B3ABA20-BA3BA20-6A641-12A14-A2B6ABAB14-9ABAB14-10ABA2(14-9ABAB)14-12A18-4D22-4L22-4M563-2(4A6-4A12-B3A6-4A12-)2(B3A6-4A12-)4A6-4A14-3D4-3D16-3L4-3L16-3M4-3M16-10F17-8G20-4H22-4I22-4J432-2A12-2A3(10-BA12-AB)10-2A12-AB10-BA12-AB2(10-3A)11-2D10-2D12-2L10-2L12-2M10-2M13-2F8-2F14-3G6-3G15-4H2-4H16-4I2-4I16-4J2-4J18-6N404-2A14-2A8-2A14-AB3(8-2A14-2A)8-2A14-AB8-2A14-2A9-D14-D10-L14-L10-M14-M10-2F12-2F11-2G10-2G13-2H8-2H14-2I8-2I14-2J8-2J15-2N6-2N17-8K18-8C350-2A16-2A5(6-2A16-AB)6-2A16-2A7-D16-D8-L16-L8-M16-M8-2F14-2F9-G14-G10-2H12-2H10-2I12-2I10-2J12-2J11-2N10-2N13-3K6-3K15-CT6CT2C16-8O323-6(2A18-2A4-)2A18-2A5-D18-D6-L18-L6-M18-M7-F16-F8-G16-G9-H14-H10-I14-I10-J14-J10-2N12-2N11-2K10-2K13-3C6-4C14-2O6-2O18-6R20-6P271-2(2A20-2A2-)2A20-AB2-SA2(20-AB2-2A)20-AB2-3A18-3A4-D18-D6-L18-L6-M18-M6-F18-F6-2G16-2G7-H16-H8-I16-I8-J16-J9-N14-N10-2K12-2K11-3C8-4C12-2O8-2O15-2R2E2-2E2R16-3PE2-E3P19-4E246-2A20-2A2-2A20-AB2-2A20-2A2-SA3(20-2A2-2A)20-2A3-D20-D4-L20-L4-M20-M4-2F18-2F5-G18-G6-2H16-2H6-2I16-2I6-2J16-2J7-N16-N9-K14-K2(10-3C)11-2O10-2O13-R2E6-2ER14-2PE6-E2P16-2E4Q2E72-4A22-AB2A2(22-4A)90-2(2A20-2A2-)2A20-AB2-SA3(20-AB2-2A)20-2A3-D20-D4-L20-L4-M20-M4-F20-F4-2G18-2G5-H18-H6-I18-I6-J18-J7-N16-N8-2K14-2K8-CTC12-CTC9-2(2O12-)RE8-ER14-PE8-EP15-E8QE20-2A22-B5A20-5AD19-8A18-D7A19-6A20-2(2AB)22-2A38-2A3(22-4A)3(21-S4A)22-2A2-D20-D4-L20-L4-M20-M4-F20-F4-G20-G5-H18-H6-I18-I6-J18-J6-N18-N7-K16-K8-2C14-2C9-O14-O11-RE10-ER12-2P10-2P14-E2Q4-2QE18-4ABA19-5(8A18-)8A19-6A36-2A22-4A2(22-AB2A)21-SAB2A21-UAB2A21-SAB2A22-2A-D22-D2-L22-L2-M22-M3-F20-F4-G20-G4-2H18-2H4-2I18-2I4-2J18-2J5-N18-N7-K16-K8-2C14-2C9-O14-O11-RE10-ER12-PE10-EP13-E2Q6-2QE17-5AB19-8A17-2(10A16-)B8AB16-10A17-B7A19-6A21-DABA11-2A22-4A22-AB2A22-4A21-S4A21-U4A21-SAB2A22-2A-D22-D2-L22-L2-M22-M3-F20-F4-G20-G4-H20-H4-I20-I4-J20-J5-N18-N7-K16-K8-2C14-2C9-O14-O11-2(R12-)P12-P13-E2Q6-2QE16-8A18-B7A17-3(10A16-)10A17-8A18-7AD20-4A11-2A22-2ABA2(22-AB2A)21-SAB2A21-UA2BA21-SAB2A22-2A-D22-D2-L22-L2-M22-M3-F20-F4-G20-G4-H20-H4-I20-I4-J20-J5-N18-N7-K16-K8-2C14-2C9-O14-O11-2(R12-)P12-P13-E2Q6-2QE16-8A18-8A17-10A16-9AB2(16-10A)17-8A18-8A20-4A11-2A3(22-2ABA)21-S2ABA21-U2ABA21-S4A22-2A-D22-D2-L22-L2-M22-M3-F20-F4-G20-G4-2H18-2H4-2I18-2I4-2J18-2J5-N18-N7-K16-K8-2C14-2C9-O14-O11-RE10-ER12-PE10-EP13-E2Q6-2QE17-6A19-7AB17-3(10A16-)D9A17-8A19-6A21-2ABA11-2A22-2ABA2(22-4A)21-S4A21-S2ABA21-SAB2A22-2A2-D20-D4-L20-L4-M20-M4-F20-F4-G20-G5-H18-H6-I18-I6-J18-J6-N18-N7-K16-K8-2C14-2C9-O14-O11-RE10-ER12-2P10-2P14-E2Q4-2QE18-6A19-B7A3(18-8A)18-7AB18-8A19-B5A37-2A20-2A5(2-2A20-AB)2-2A20-2A3-D20-D4-L20-L4-M20-M4-F20-F4-2G18-2G5-H18-H6-I18-I6-J18-J7-N16-N8-2K14-2K8-CTC12-CTC9-2(2O12-)RE8-ER14-PE8-EP15-E8QE20-AB22-6A20-6A19-8A18-8A19-6A20-6A22-AB39-5(2A20-2A2-)2A20-AB2-2A20-2A3-D20-D4-L20-L4-M20-M4-2F18-2F5-G18-G6-2H16-2H6-2I16-2I6-2J16-2J7-N16-N9-K14-K2(10-3C)11-OE10-2O13-R2E6-2ER14-2PE6-E2P16-2E4Q2E72-4A22-3AD22-B3A22-4A90-3(2A20-2A2-)2(DA20-2A2-)2A20-2A2-3A18-3A4-D18-D6-L18-L6-M18-M6-F18-F6-2G16-2G7-H16-H8-I16-I8-J16-J9-N14-N10-2K12-2K11-3C8-4C12-2O8-2O15-2R2E2-2E2R16-3PE2-E3P19-4E247-2(2A18-2A4-)DA18-2A3(4-DA18-AB)4-2A18-2A5-D18-D6-L18-L6-M18-M7-F16-F8-G16-G9-H14-H10-I14-I10-J14-J10-2N12-2N11-2K10-2K13-3C6-4C14-2O6-2O18-6R20-6P273-2A3(16-2A6-DA)16-AB6-DA16-2A6-2A16-AB6-2A16-2A7-D16-D8-L16-L8-M16-M8-2F14-2F9-G14-G10-2H12-2H10-2I12-2I10-2J12-2J11-2N10-2N13-3K6-3K15-CT6CT2C16-8O325-2A14-2A8-2A4(14-AB8-DA)14-AB8-2A14-2A9-D14-D10-L14-L10-M14-M10-2F12-2F11-2G10-2G13-2H8-2H14-2I8-2I14-2J8-2J15-2N6-2N17-8K18-8C352-3(2A12-2A10-)2(DA12-2A10-)2A12-2A2(10-3A)11-2D10-2D12-2L10-2L12-2M10-2M13-2F8-2F14-3G6-3G15-4H2-4H16-4I2-4I16-4J2-4J18-6N406-3(4A6-4A12-)3(4A6-3AB12-)4A6-4A14-3D4-3D16-3L4-3L16-3M4-3M16-10F17-8G20-4H22-4I22-4J434-12A14-A2B8AB14-AB9AB14-AB8A2B14-AB8ABA14-A2B7ABA14-12A18-4D22-4L22-4M557-
