model
size = 24 26 24, scale = 0.05, origin = -y
material 
  colors = A:#93E9FF B:#F96 C:#FF3 D:#F09 E:#0F3 F:#FC3 G:#F9C H:#F9F I:#CC9 J:#FF9 K:#FCF L:#FC6 M:#CF9 N:#F6C O:#F3C P:#F69 Q:#F99 R:#F30 S:#F93 T:#F33 U:#F03 V:#FC0 W:#FF6 X:#F00 Y:#CF6 Z:#F0C Aa:#F39 Ab:#CF0 Ac:#CFC Ad:#CC6 Ae:#F66 Af:#FFF Ag:#FCC Ah:#FC9 Ai:#FF0 Aj:#CCF Ak:#F90 Al:#CCC Am:#F60 An:#FFC Ao:#F63 Ap:#F0F Aq:#F36 Ar:#CF3 As:#CFF At:#F3F Au:#CC0 Av:#555 Aw:#F6F Ax:#CC3 Ay:#F06 Az:#EEE Ba:#0F9 Bb:#222 Bc:#444 Bd:#111 Be:#001 Bf:#888 Bg:#09C Bh:#0C3
voxels
606-2Ba145-CAkAmAaAtQ18-KMAlHAtY18-QAdTNWX18-AjTLAcAdB18-IAjAyMDAc18-GZAoTWAa18-Ad2YLApH426-IAhZSAuH18-FCYAbKAq16-PUNYAaAwAkVXAw14-CAcAoUAe2OAeGAn14-GPRPAmAhBXLAy14-KBLIAhCAkVAuW14-RQAiBAhYAnDAfAn14-Aj2VMJUAtLAiAl14-WXAmPIPDAyJL16-AlCFIOAy18-TGNBAkAr350-TCAxAhAiIAqAuAcQ2HUP10-LOAi2JFAtAfAgVAuNAcR10-IUArIAbNPAiF2XAcPAr10-AbFCFAgAoZJGAuAwMBAq10-AgTKNAyRAaAbArSAnTQAt10-AxAqAuAoILAeAgAsFAyLVP11-AiKRAsAiAmAyHAkWIX11-ArFAkLAgVMIDMAnAbAuAa10-CMOAiApAmAlAsNAdAlAgSAe11-WBVAeAlAfAgOTLAxF11-AuAoAkAmAxTAqApJAjQAiAkM10-KApAnAlAhLAoAeAdZAuArMAl11-BAtTWAyRAxZYVCAd323-HAgAdAt6-HAxPAe10-AqAtZAt6-NAwCX10-VAjCW6-AcAfGV10-AeAqKAd6-MHKD10-XAfQD6-TAuRL10-VAaAjW6-LXAjAy11-AiIAp6-IAwW11-LQGAw6-AbAnSAr10-AyAxAdAm6-AgAyCAd11-HApG6-AxWO11-ArAqAwHAsAjZFIHAiAnUAh10-AdVNAsAlIAaMAbDArAlFY11-AeRAgSGAeWAgNCLT11-AhXAtSAbAdAmAoAxOKQAqP297-YAhS10-AsAfAa8-AaYAh10-AlAqAe8-AeApAa10-SAoAm8-AmPK10-AbRM8-AhRAn10-AwJAl8-AhArAs10-OQAf10-V10-Ah10-IAtU10-CXAo8-FPJ10-YBR9-ZAn10-UAc9-AoAaAxWT6-AnAfPAaQ8-RAeAwApLQVAjAgBAiAlAoIHY10-AfAwIVXZAtMArLZB10-AiMHAmAbXAuYAjPCQAcMAcB14-SAaAqC278-JAu12-AjC8-AdK12-IY8-ZAk12-GU8-CO12-AdP8-KB12-ApI8-QAk12-AwB9-An12-N9-IAt12-RP8-GD12-AtC9-O12-At9-ApAkAhAm8-OAeWK8-AwTJMAt6-AoBFAdR10-IAlDPAfUPAxAqZAkAm10-RAlFAfOIAeJBAhAoAcAnAx2W9-SNAqAkBFAnQWRAgAtKAp273-JL12-DAh8-IAi12-NAh8-FV12-OJ8-NAm12-JI8-AoAl12-AdF8-RT12-ZN9-L12-C9-AiAy12-KR8-VAo12-QL9-Y12-Aj9-AlGAf10-UIV8-TNHAq8-ApAbGAm10-AuAtFB4-AyAkBS10-AyHXPMAcWZAiAoIAnUAhApT8-AoQAwZWAaAnYJApAsAtAcAaAwL15-AaAb255-Ai14-G8-J14-K8-Ab14-R8-Ag14-Aj8-Ay14-W8-I14-S9-Ah12-H9-Ag14-O8-Ap14-U9-I12-Ae9-AxF12-XT8-AhNAa10-ZVAq10-KUC6-BAeAc10-AcRAnP2K4-AnUXAgLF8-AfLAsIQAnVUDAqAfAcVFAyM11-BAjAsAmAbArAfAoPD251-Ak14-Ak8-O14-An8-B14-At8-Ak14-D8-An14-O8-At14-Ak9-Am12-Z9-O14-As8-Ak14-Al9-Af12-F9-AsAq12-GAb8-AlAoAf10-KArAw10-AeAl8-AfR10-AbJFSAf6-XHAjHAh8-AwQAmAbHIAt2AhQAuVAuWDC8-OYAxAwAuGAtCAaVKDXSNY246-WAkAi14-ArOAy4-AnOF14-AsUAr4-AlBM14-HFAd4-LAkW14-DTAi4-QAnAo14-NAqAh4-AuAtAp14-OAiY7-Ar12-Af7-AnOU14-AdMP4-AfAkAc14-ZWR7-P12-Q7-ZAsBZ12-AxKApAq4-AcAlQAaAp10-AeHQBAt8-AwAm8-IX8-FAbXAmNGN6-HF2VIAcZ4-GAwAuMRHAcAjAoAxXJ2AuNDAeGPAa4-ArOSAlAtAsMIYAwGAbVXAoLXAdBAe13-AfL229-WAiAk14-IWP4-SFT14-BAcZ4-CMAs14-MAfAa4-OWAl14-P2Ae4-UAoS14-CFAm4-FApAb14-GAmM7-F12-Ae7-AqUO14-RKAf4-AiAcAh14-AjCAq7-Ad12-Al7-MBYT12-AfSAtR4-WQUAjW10-AtAqCAjJ8-SAo8-AuP8-ApXIYCZN6-FXZRUAfY4-BAuBAaOAcAoIAfArAgDAgNAwAaJFAaX4-USMAeUAgRAbAeCSArFAoAnAeQTAiB10-LAgFKAbUGR226-GAkAe14-AxMAp4-HTAm14-AiPB4-2AsM14-ArCU4-Ag2Al14-CGAc4-2SAf14-2KP4-2AbAq14-AuRB7-Ah12-W7-AjOR14-AkWV4-BAhJ14-OSX7-An12-Am7-G2YAs12-GAkOS4-LUXVY10-JHAnUF8-GWAp6-AuKQ8-AfIAcJNApBAd4-AnXAnYAgDTM4-AiBAaAnJAwUTAwCAtAhAtAwAsXSOAqAd4-JMHAxHAmAcAjOKPAaDAnVBAbAkAiT5-PNAwQGPZAhAuZKOAyUAcAlTF221-AtAeNP12-SAdWAy4-WAmJB12-AbZAdI4-AdMHQ12-AlCDAs4-DAlQV12-AjKWAg4-WAfZX12-BQ2Ap4-ApAqAkAu12-XAjAwAe4-AwAoDS12-GIAmAx4-AmRArF12-L2GAh4-GJUAk12-AuAdHW4-HQAbM12-AfApAsAc4-AsYSAdW10-SAiAwAgAf4-AgXAhTSW8-AfFJNSAe4-SBAaAjCAdAuAg4-BKAeAkAbRAbF4-AbAcKZODVAyXAkAgBUAnFMAgAtAlAm4-AlAaAnYUWAnIAuOAxXAcAsAmAdAyAtAjAx4-AjHAsAaFApAfAsSBAiGPVAxTIWBK5-NVAeTAwAoAgFAkArLBUKAjAsAdX14-AnC123-2Ba80-AgNGT12-XAdTN4-ApJArL12-GApLAc4-AeHAsAy12-LAwIM4-AxQHAo12-AuNAbT4-AhZDY12-AfRAgL4-WAkNG12-AiAtAxI4-AcDON12-JAtAiAb4-AfAr2J12-AbWArAg4-AeUAdH12-AgAdCAx4-FAbZQ12-AyDKAi4-AmSCZ2Q8-AdAfIWAuAr4-AxAhKAkZAjP6-AfApAeAsApKC4-KAaQDAk2ITPArGH2AeAwFAgAwAkK4-CKAjArDGBAjIAsArAsXFNAmApAmOAu4-AgAnIUArAdMZBHAsAgVAmRAxAeGBK4-AtAsGAbUApPYMDHSDAxAtKAxH2Ak4-AjVAdSAbAwCAaPNDAbLKAtCAhAsAnO11-AeCONAlAy120-BaBfBa80-FGFBH10-NMApHAb4-NArGAkQ10-AcAlPAqAw4-AoAsArAnZ10-MAfRVO4-RHAsAtAk10-TAqArAeAh4-LDH2D10-LAoAqXC4-AiNDOAr10-IRAtVY4-VONAkU10-AbJPDU4-AmJOTAb10-AgQZLP4-AlAdJAsS10-AxYAaAyI4-TZAdAlAh10-AiXAeAyB4-LCZSAaZS6-AdAjArBAmArM4-AyKCAbKYAbNXAcAmRAwApWCAcMAdP4-AoQKAwAnAaAlOBAgMArAfAwSKAaAlAiC4-YAjQOAsAeAjJAcFAlAqHNCAuHAfAhG4-GIAjAhVAmBAdAaGAfAtAuROKNAqYK4-NGICUAhXZHArAqPXAtUAkAcAoApR4-JAdGYJAhGCNAsAoZAwAtFOMRPAj6-AdUAnJLKAcHRAaAnWTBTJ15-DJ97-BaBfBa81-JFRD2RB6-UAoAbAoAyAhAa4-QGJArLAjM6-PRAwRAyYAe4-YArQUAiWP6-ILOJArApAm4-XAsYAbVSC6-BAiAhQAdPM4-BHXSAmCG6-MVCYAiRAl4-AcDBAhAlOK6-PAmYXAhArAf4-AaNAcAaTUR6-CAlUBY2Aq4-HOAaKLFAj6-GTPAcApAtAo4-NJHAnAyTW6-KLIAa2PR4-AcAdNAsAoAqS6-RAyBHRZJ4-MZAcVYAiCNSMAiLAhAjAoMNArAaQ4-TCMUGF2OAhWQIJWYPAcAqAeY4-LKTJNMUJAaAoAxAbISGCMAtAmX4-IQLAnJWFAdKApHAgFCNGTPMB4-AbAjIAxHAoTZAnBAqAxNOJKLZAlAc4-AgIAbAwQApAqCAsUVAiAoUHRIAaAfAa4-AxGAgAfZBAiKVAcAeArRFQAjAbAeAqH6-AxHAkUFQUPXCLTZWAgAm13-AjJBVKAi94-BaBfBa81-QTR2BZNApL2GCAlAaAoPAaAxOAuCAh2-VAqJU2AcAoAeAuArHKLKRIAeHAkK2Y2-XAiQAcAaAgRAxAf2As2QAnLBAmAqTAkUAp2-AuFYPHFLAhAiHAgAjAuAsAi2MVAsO2P2-SMXBNGAiWJDSI3VPAlAeAlBIR2-FWBQAcArVAcAbNAbGAnUAmCAfXSAkBAr2-AkAoAcVMAsAmAfAgOAlAdAfJAlGAqVAbAnMAq2-MApAaXTHAlAeAyJAjApAoAnTKAoDAwAtPAt2-AdBHAuLDTFIAdBAwZAxL2RLODCP2-TUNSINLAmAsZXNAcAwAyAjJAyAhOGZ2-Aj2AcFAbOAyAxAgCGRAgAfAoWQAyCAkKAa2-ZPMAkAgJAoKApKLAtFHYSYArYTRAe2-YBTMAxAdYCAeQAuAtGAuGCXAdUAsAjAm2-AaQLAdAiZGAgAxAjAfWArXNOBAiPAlWM2-AeVITArCNAtAhIAiAdAsAwJUAcAhI2SAl2-AmXAbAjCKJAjWGJDHAnHFAaYBAbCAf2-AhAuAgZKQHAqAcAdAbWDAyQTHApMAwOAq3-SAxYAuAjQ2AfApAgApNWZAqN2POU8-IZAaAeAwAyAwOAnAkAiAc90-BaBfBa60-ApSBAdAuTKAgAtAfAhNUAmAhBAuR4-AnApBAbAcZSAqCFAtAqYJPAlCQKLAhAu-OBcAwUAlAaCFAiAgGWAoApHITYVAkAiAhBcAaUBcAmAcAjHKAkFAtArAdRPQBLUXOVJBcAiFZGPBNQ2MAjAsDJRZMAyPAuBAmIOQTBcHBXAcAjAdWAqHWQArAkPAoISAkAlFBcAxAqBcAsQGMITAoAfDApYAqDCYBFAnTNBcHAiFAgVLTGAjApAaNAwXAtAr2GMAkAtLAoAnAqFBcSXAuLAdZBAiOAmBPUKNPMDAyRBcVMBcAbAuAfIApYUQJGAcZAbRJCAdOAoLBcAeWAsAlSAiAbAwAaAcAxAdH2AaSAjHGTAkYAiOXAoBcAjFJAgNAePHZAsHAeAhWQKAjTGVBcVApBcBAkAbAxRAmBAqCAgNAmAaSZRZAsNAmBcDBNXMAgAiAtAhQVKSAcMKCAkAjYAlJAlAsLUBcGAdAyArAtAhVAeQAbMAlAnODWAaSHTBcAyAcBcLTICWJ2XAjAlTAfAsUArSAeAbQLBcAyPAdAuAjAsKAdIAuVIAjLAqVFUCAmAwZAyAbAr-ZAfZAgAuDFSDGBIAoUTAbOAhOAkAoAw3-AiYApKWNFLAdXAbRJAqSU2AhDY5-AaAeAkApAoAkAyApGAgJAnAiAhFJCAr13-4Be21-2Be22-2Ba23-2Ba22-Ba14-AgBNAxHArAeAqIAyAeJVNAeAuGAd6-SUAcAiAsAqAxAoAsArFAbAmJAmVAdT4-AaAwAbAcMArAgAtAhRAgAdAmAgAlHAhAnApAjGL-AtBbAmAl16AZKBbAfAjBbGAj16AYRBbHAqAcHB16AAaAjAmAuAfBbAsX16AAeWBbXAaBbAgG16AAmSBbAwAiLSL16AAhCLAnQBbAbAu16AAhOBbAyAxBbAlAf16AJUBbWHAgAjAi16AIFYAnAqBbBJ16AFTBbAlVBbXAb16ANAqBbLAeArGAg16AAoAiJQXBbLAy16ARFBbAuVBbAuI16ALMBbVDAuAfAs16AAiWZAn-KAiAg16AVAoAk3-JApAeAnSAsAcQAxAqAfXCSAnYCSAmAp5-AeAmAtAbAgAaAxAiAfAqVAgAhAxGKAbAl14-2(2Be22-)2Ba21-2Ba23-Ba15-BVAnAkAiAuAyAoJZAdD2NPBAuR6-UAnAlAnFSAyApIYZNJAoCAcXAr5-CAcAfLAtMFArBFAaCOHRGAaAwAqAk4-GP16AAtAn4-KBAE12AEAPAt4-RQ16AZD4-AjV16AAaO4-WX16AAeAk4-SAu16AAmT4-CS16AMAs4-OF6AE2AE6A2Al4-UAk16AAfS4-FM16AAqAb4-TAd16AAoAw4-AqT16ARO4-AiAj16AJAh4-FZ16AQC4-MY6AE2AE6A2Y4-WAa16AXU4-AoAeKOBAdAoAlYHLApWAnAkApAkGBP5-AmQJMTRAfAaQAyAwAdAxDBOArAc84-BaBfBa65-BhBg-BhBg8-Af33-16Av8-Av-12E-Av8-Av3E8D3EAv8-Av2E2D6-2D2EAv8-Av2ED-6D-D2EAv8-AvED-2D4E2D-DEAv8-AvE2D8E2DEAv8-Av5E-2E-5EAv8-AvE3Az6E3AzEAv8-Av5Az4E5Az3(Av8-AvAz3Bd2Az2E2Az3BdAz)Av8-Av5Az4E5AzAv8-AvE3AzE-2E-E3AzEAv8-16Av132-2(BaBfBa620-)BaBfBa39-
