model
size = 20 24 4, scale = 0.05, origin = -y
material 
  colors = A:#EEE B:#222
voxels
22-8(BA)3-B2-A2-B4-A2-B2(2-A)2-B2-A4-B2-A2-B3-A2-B-B4-A-A2-B4-B2-A-A4-B-B2-A5-2(B-)B4-2(A-)A6-A-A2-B2-A2-B-B6-B2-A-A2-B-B2-A7-2(B-)B2-2(A-)A8-2(A-)A2-2(B-)B9-A2-B2-A2-B10-BA-A2-B-BA11-B-B2-A-A12-A-A2-B-B13-AB2-AB14-BA2-BA14-A-AB-B14-B-BA-A15-B2-A16-A2-B16-B2-A68-A18-2BAB14-ABA-BA14-BA2-AB14-AB2-BA14-BA3-B14-2(A4-AB12-AB4-BA12-B)A4-AB12-AB5-A12-B6-B12-A6-AB10-AB6-BA10-BA6-AB10-AB7-A10-B2(8-BA)9-BA6-BA11-BA4-BA13-BA2-BA14-3(AB)15-2(AB)8-B18-2ABA14-B6A12-B2AB3AB12-3AB2-2A12-BA4-ABA10-B2A4-2AB10-ABA4-3A10-B2A4-2AB10-ABA4-ABA10-BAB5-AB10-2A6-2A10-BA6-ABA8-BAB7-ABA6-BAB8-2AB6-ABA8-ABA6-BAB9-A8-B10-BA6-BA11-BA4-BA12-AB4-AB13-AB2-2A14-BAB3A48-A16-B-3A8(BA)2B8(AB)3A-7(BA)B3A3-2A7(BA)4-3A6(BA)B4-6(BA)B3A4-3A6(BA)B4-B-2A5(BA)-A6-5(AB)2A7-A-5(AB)-B6-B-5(BA)-A7-B-4(BA)-A8-A-3(AB)2A-B8-BA-3(AB)-BA9-B-3(BA)-A10-5(AB)11-4(AB)12-4(BA)13-3(BA)14-3ABAB15-A2-B48-
