model
size = 32, scale = 0.05, origin = -y
material 
  colors = A:#444 B:#0FC C:#F0F D:#222 E:#111
voxels
366-4D26-3D2-3D25-2D2-2D27-4D29-2D925-4B27-6B25-3(2B4-2B24-)2B4-2B25-6B27-4B700-4A26-8A23-10A21-12A20-12A19-14A2(18-6A2-6A)18-14A19-12A20-12A21-10A23-8A26-4A541-2B27-8B22-12B19-14B18-14B13-24B12-16B12-3B-B14AB-3B11-2B6A2C6A2B14-2B6A2C6A2B15-2(16B16-)16B17-14B18-14B19-12B22-8B27-2B444-6A24-10A20-14A17-16A16-16A15-18A11-B22AB10-20A10-B2AB16AB2AB10-20A10-3B18A3B10-20A12-20A13-18A14-18A15-16A16-16A17-14A20-10A24-6A407-12A19-14A17-16A15-18A13-20A12-20A10-2(B22AB9-22A9-)2B20A2B9-2(22A10-)22A11-20A12-20A13-18A15-16A17-14A19-12A22-8A373-14A16-18A14-18A13-20A11-22A10-2(22A9-B22AB9-)22A9-2B20A2B9-4(22A10-)22A11-20A13-18A14-18A16-14A19-12A22-8A346-4A20-20A12-20A11-2(22A10-)2(22A9-B22AB9-)22A9-2B20A2B9-5(22A10-)22A11-20A12-20A13-18A16-14A19-12A23-6A284-2A30-2A22-18A12-22A10-22A11-C18AC12-C18AC10-2(B22AB9-22A9-)2B20A2B9-7(22A10-)22A11-20A13-18A16-14A20-10A26-2A286-2A22-18A12-3(22A10-)22A8-5(26A6-)26A8-22A11-20A2(11-22A11-C18AC)11-22A11-20A13-18A15-16A17-14A23-4A284-4A21-18A12-22A11-C18AC11-22A10-22A8-26A7-3(C22AC8-)C22AC7-26A8-22A11-20A2(11-22A11-C18AC)11-22A10-22A11-20A13-18A16-14A22-6A279-12A17-18A12-3(22A10-)22A8-26A7-3(C22AC8-)C22AC7-26A8-22A11-20A2(11-22A11-C18AC)11-22A10-22A12-18A14-18A16-14A20-10A212-14A19-12A20-12A17-18A12-22A11-C18AC11-22A10-22A8-5(26A6-)26A8-22A11-20A2(11-22A11-C18AC)12-C18AC11-22A12-18A14-18A16-14A20-10A43-C30-C14-3(4A28-)4A23-14A19-12A20-12A17-18A12-3(22A10-)22A5-160AE30A2E4-22A4-2E5-20A2(5-2E4-22A4-2E5-C18AC)5-2(2E4-22A4-)2(2E6-18A6-)2E8-14A8-EB9-12A9-BE30-2EC28-CE13-6A25-8A25-6A27-4A23-14A19-12A20-12A17-18A12-22A11-C18AC11-22A10-22A5-64A-2(D28AD2-)D28AD-AD28AD2A4-22A4-A6-20A2(11-22A11-C18AC)12-C18AC11-22A12-18A14-18A16-14A19-12A42-C30-C12-8A23-2(10A22-)A2-4A2-A20-2(4A-)4A19-12A20-12A17-18A12-3(22A10-)22A5-32A-D28AD-AD28ADA-2(D28AD2-)D28AD-A4-22A4-2A5-20A5-A5-2(22A11-C18AC11-)22A10-22A12-18A14-18A16-14A19-12A86-8A23-2(10A22-)10A20-14A19-12A20-12A17-18A12-22A11-C18AC12-C18AC11-22A5-32A-D28AD2-D28AD-AD28ADA-2(D28AD2-)D28AD-A4-22A4-A5-22A11-C18AC11-22A11-C18AC12-C18AC11-22A12-18A14-18A16-14A19-12A86-3(8A24-)8A21-14A19-12A20-12A17-18A12-3(22A10-)22A5-32A-2(D28AD2-)D28AD-AD28ADA-D28AD2-D28AD-A2-26A2-A5-2(22A11-C18AC11-)22A10-22A12-18A14-18A16-14A20-10A87-8A25-2(6A26-)6A22-14A19-12A20-12A18-16A13-22A11-2(C18AC12-)C18AC6-33AD28ADA-3(D28AD2-)D28AD-A-28A-2A2-26A2-A5-22A11-C18AC11-22A11-C18AC12-C18AC11-22A12-18A14-18A16-14A20-10A88-3(6A26-)6A22-14A19-12A20-12A18-16A13-4(22A10-)22A5-A4-22A4-2A4-22A4-5A2(-22A-8A)-22A-5A-28A-A3-26A8-2(22A11-C18AC11-)22A10-22A12-18A14-18A16-14A22-6A92-2(2A30-)2A28-6A22-14A19-12A20-12A18-16A13-22A11-4(C18AC12-)C18AC6-A4-22A4-2A4-22A4-5A-22A-8A-22A-4A2-28A5-26A8-22A11-C18AC11-22A11-C18AC12-C18AC11-22A12-18A14-3A2-8A2-3A19-8A26-4A125-2(2A30-)2A24-14A19-12A20-12A18-16A13-8(22A10-)22A6-3A-4A-C10AC-4A-3A3-28A5-26A8-2(22A11-C18AC11-)22A10-22A12-18A14-18A19-8A219-2A25-2(12A20-)12A18-16A13-22A11-5(C18AC12-)C18AC11-2(22A10-)4A2-C8AC2-4A7-7A2C10A2C7A5-26A8-2(22A11-C18AC11-)22A9-24A11-18A14-18A19-8A246-2(12A20-)12A18-5A6D5A13-9(22A10-)4A2-C8AC2-4A7-7A2-10A2-7A5-6A2C10A2C6A8-5(22A10-)22A12-18A14-18A19-8A246-2(12A20-)3A6D3A20-3A6-3A14-24A7-3(26A6-)26A7-24A8-24A9-22A10-22A9-4AC2-C8AC2-C4A6-6AC2-10A2-C6A5-6A2C10A2C6A7-3(24A8-)24A9-22A11-20A13-18A305-2(12A20-)A-A6-A-A47-4A-12A-4A9-24A8-24A7-2(26A6-)26A7-24A9-3A4C8A4C3A10-2A6C6A6C2A9-2A2C3-3C4A3C3-2C2A6-6AC2-10A2-C6A5-26A7-2(24A8-)24A9-22A10-22A11-A18-A336-2(12A20-)A10-A48-3A-12A-3A11-22A9-2(24A8-)24A7-26A7-24A9-2AD4-D6AD4-D2A10-AD6-D4AD6-DA9-AD9-2A9-DA6-3AD7C2D2A2D7CD3A5-2A6DA3D2A3DA6D2A7-A9D4A9DA8-24A9-22A11-20A12-20A370-8A22-12A20-A10-A52-12A16-4A-10A-4A11-22A10-22A9-24A7-26A7-24A8-A2D6-D4AD6-2DA8-AD8-4A8-DA18-4A20-7A2-2A2-7A13-4DA3-2A3-A4D15-3D3-4A3-3D12-24A10-20A13-18A14-18A403-8A23-2A6-2A55-8A23-10A17-20A12-8A4E8A11-9A4E9A9-11A2E11A9-22A19-4A28-4A29-2A22-5A3-2A3-5A15-3A10-3A46-20A13-18A15-16A436-8B2(24-B6-B)24-8B23-10A19-7A2E7A15-7AE2-E7A14-7AE2-E7A12-10A2E10A11-20A20-4A29-2A30-2A151-6B4-6B628-3A2E3A2(24-2AE2-E2A)18-9A2E9A20-4A29-2A30-2A827-3A2E3A2(24-2AE2-E2A)25-2A2E2A28-2A30-2A527-
