model
size = 15 31 15, scale = 0.05, origin = -y
material 
  colors = A:#CC543A B:#43341B C:#CB4042 D:#855B32
voxels
381-2A12-4(5A10-)5C355-3A11-7A7-3(9A6-)2A3-4A6-9A6-2C5-2C338-3A11-8A6-10A4-11A4-5A-5A4-3A3-5A4-2A5-4A4-2A6-3A4-CA7-AC336-7A7-10A4-11A3-12A3-4A3-6A2-3A5-5A2-3A6-A-2A2-2A9-2A2-CA9-AC334-9A6-10A4-11A3-13A2-3A5-5A2-2A7-A-2A2-3A8-2A2-2A9-2A2-C11-C334-9A5-11A3-12A2-14A-5A7-2A-3A9-2A-5A7-6A10-2ACA11-AC6-21(3B12-)3B9-4AD4A5-11A3-12A2-14A-4A8-2A-3A9-6A10-4A11-2AC13-C6-21(3B12-)3B9-4AB4A5-5A-5A3-2(6A-)14A-3A2(9-6A)10-4A11-2AC13-C6-21(3B12-)3B8-10A4-12A2-2(14A-)4A8-2(6A9-)5A11-2AC13-C333-9A4-12A3-13A-14A-5A6-9A7-6A9-6A10-2ACA11-AC333-9A5-11A3-3(13A2-)3A-A5-3A2-3A8-2A2-2A9-2A2-C11-C335-8A6-9A4-4(13A2-)4A6-3A2-2A8-3A2-CA9-AC338-3A8-8A6-10A5-4(11A4-)2A5-4A4-CA7-AC351-5A10-2(8A7-)8A2(6-9A)6-2A3-4A6-2CA3-A2C368-4A11-5(5A10-)5C5-
