model
size = 4 32 4, scale = 0.05, origin = -y
material 
  colors = A:#05B400 B:#000 C:#BABABA D:#F00
voxels
25-AD2-2C122-2C102-2(2B2-)2C3(2-2B)-4C-25(2A2-)2(2B2-)2C3(2-2B)-4C-24(2A2-)2A-
