model
size = 22 27 22, scale = 0.05, origin = -y
material 
  colors = A:#777 B:#555 C:#444
voxels
513-8C14-8C542-8C14-8C80-21(A2B2A2BA14-)A2B2A2BA12-2C8A2C10-2C8A2C12-8C56-21(2B8A2B10-)2B8A2B9-C12AC8-C12AC9-2C8A2C12-8B33-21(14A8-)14A7-C14AC6-C14AC7-C12AC9-12B30-21(B14AB6-)B14AB5-C16AC4-C16AC5-C14AC7-14B28-21(B16AB4-)B16AB3-C18AC2-C18AC3-C16AC5-16B27-21(B16AB4-)B16AB3-C18AC2-C18AC3-C16AC5-16B26-21(20A2-)20A2(-C20A2C20AC-C18AC3-18B25-21(B18AB2-)B18AB)2(-C20A2C20AC-C18AC3-7B4A7B11-4C10-21(20A2-)20A)2(-C20A2C20AC-C18AC3-7B4A7B11-4C10-21(B18AB2-)B18AB)-C20A2C20AC-C18AC3-18B25-21(20A2-)20A-C20A2C20AC-C18AC3-18B26-21(B16AB4-)B16AB3-C18AC2-C18AC3-C16AC5-16B27-21(B16AB4-)B16AB3-C18AC2-C18AC3-C16AC5-16B28-21(B14AB6-)B14AB5-C16AC4-C16AC5-C14AC7-14B30-21(14A8-)14A7-C14AC6-C14AC7-C12AC9-12B32-21(2B8A2B10-)2B8A2B9-C12AC8-C12AC9-2C8A2C12-8B36-21(A2B2A2BA14-)A2B2A2BA12-2C8A2C10-2C8A2C12-8C51-
