model
size = 24 24 28, scale = 0.05, origin = -y
material 
  colors = A:#111 B:#FCC C:#EEE D:#300 E:#FFF
voxels
249-6C4(18-2C2-2C)450-6C115-4C451-4(2C2-2C18-)2C2-2C19-C2-C427-6C3(18-C4AC)18-C5A18-6A18-C4AC425-2A5CA15-3(7A-2A14-)2(10A14-)10A15-8A17-6A330-A21-3A5-2A14-3A5C2A13-8A-3A12-8A-3A11-9A-4A10-14A11-12A12-12A13-10A14-10A16-6A20-2A236-6A16-10A13-12A11-14A10-9AC4A9-3(10A-5A8-)2(16A8-)16A9-14A10-14A11-12A13-10A16-6A6-E179-6A16-10A12-14A10-14A9-16A8-16A7-5(18A6-)18A7-16A8-16A9-10AB3A10-14A2-E9-10A4-E11-6A140-2A18-10A12-14A9-16A8-16A7-3(18A6-)18A5-20A4-20A5-3(18A6-)16A2D7-11A3B2DE7-13A3D2E7-12A2D3E9-10A18-2A116-6A15-12A11-14A9-16A7-2(18A6-)18A5-5(20A4-)20A5-18A6-16A2D6-12A4B2DE6-13AB2D2E7-12A2D3E8-12A15-6A90-6A16-10A12-14A9-16A7-18A6-18A5-20A4-20A3-5(22A2-)22A3-20A4-17AB2D5-12A4B2DE5-14AB3DE6-13A3D2E7-14A12-10A16-6A65-8A15-10A12-14A9-16A7-18A6-18A5-20A3-7(22A2-)22A3-17AB2D5-12A5BDE5-14A2B2DE6-13AB2D2E7-14A12-10A15-8A42-4A17-10A13-12A10-16A7-18A6-18A5-20A3-2(22A2-)22A-47A-23A-21AB2A-20ABA2-19ABDA2-18AB2DA3-13A5B2D5-12A4B2DE5-12A3B3DE6-16A10-12A13-10A17-4A19-6A16-10A13-12A10-16A7-18A6-18A5-20A3-22A2-22A-23A-93AB23AB2A-19A2BA2-18A2BDA3-13A5B2D5-12A5BDE5-12A4B2D7-16A10-12A13-10A16-6A18-6A16-10A12-14A9-16A7-18A5-20A4-20A3-22A2-22A-144A-22A2-18A2BDA3-13A5BDA4-13A3B4A5-12A3B3A7-16A9-14A12-10A16-6A18-6A16-10A12-14A9-16A7-18A5-20A4-20A3-22A2-22A2(-23A)-96A-22A2-18A2BDA3-13A5BDA4-13A3B4A5-12A3B3A7-16A9-14A12-10A16-6A18-6A16-10A13-12A10-16A7-18A6-18A5-20A3-3A7B12A2-3A7B12A-4A7B17A7B12A-4A7B11A2-AB6A3B21A3B12A-8A3B13A-7A3B12A2-14A6BDA3-13A5BDA5-12A5BDE5-12A4B2D7-16A10-12A13-10A16-6A19-4A17-10A13-12A10-16A7-18A6-18A5-20A3-2(3A7B12A2-)3A7B12A-4A7B17A7B12A-2D6A3B12A-8A2(3B12A2-7A)3B12A2-14A5B2DA3-13A5B2D5-12A4B2DE5-12A3B3DE6-16A10-12A13-10A17-4A42-8A15-10A12-14A9-16A7-18A6-18A5-2A7B11A3-4(3A7B12A2-)D6A3(3B12A2-7A)3B12A3-13A5B2D5-12A5BDE5-12A4B2DE6-11A3B2D2E7-14A12-10A15-8A65-6A16-10A12-14A9-16A7-18A6-18A5-20A4-20A3-5(22A2-)22A3-20A4-20A5-18AC5-12A3B3DE6-11A2B3D2E7-14A12-10A16-6A90-6A15-12A11-14A9-16A7-2(18A6-)18A5-5(20A4-)20A5-2(18A6-)18AC6-11A3B2D2E7-10AB3D3E8-12A15-6A116-2A18-2D8A12-14A9-16A8-16A7-3(18A6-)18A5-20A4-20A5-3(18A6-)18A7-16AC7-13A3D2E7-13AD3E9-10A18-2A140-6A16-10A12-14A10-14A9-16A8-16A7-5(18A6-)18A7-16A8-16A9-14A10-13AD3E9-10A4-E11-6A186-6A16-10A13-12A11-14A10-14A9-5(16A8-)16A9-14A10-14A11-12A13-10A16-6A6-E229-2A20-6A16-10A14-10A13-12A12-12A11-14A10-14A11-12A12-12A13-10A14-10A16-6A20-2A308-6A17-8A15-5(10A14-)10A15-8A17-6A378-6C18-C4A19-3(6A18-)6A19-4A427-6C5(18-2C2-2C)19-4C226-
