model
size = 32 17 32, scale = 0.05, origin = -y
material 
  colors = A:#96C
voxels
10-A176-2(2A29-)2A30-A113-A453-A31-A4-A26-A4-A28-A2-A3-2A23-A63-A350-2A6-A23-2A5-2A22-A4-A26-A3-2A2-2A24-A-A3-2A24-A31-A242-A75-A10-A20-2A-A4-A-2A20-2A-A3-2A26-A27-A3-2A2-A27-A3-A24-2A8-A201-2A60-A-A28-2A45-A40-2A21-4A2-2A5-A17-A2-2A8-2A17-A3-A2-2A27-A2-2A-2A21-2A7-2A168-A29-A2-2A27-A3-A28-A-2A28-3A83-3A21-3A3-2A23-A2-2A7-2A18-A3-A2-A4-A20-4A2-A-2A22-2A7-A169-A31-3A27-2A2-A28-A2-A29-3A74-A5-4A21-4A2-2A-2A21-2(A2-)A4-2A19-A2-2A-2A3-2A20-3A4-3A233-3A28-3A-A27-3A-A28-3A6-A35-A30-3A3-4A22-A-2A2-2A-A22-2(A2-)A3-2A20-4A2(2-2A)21-3A4-2A236-2A28-2A-A3-A24-A2-A3-A25-2A37-A3-3A29-3A2-5A22-A2(-2A)2-A22-4A-2A2-2A21-4A2-3A-A28-3A236-2A29-A2-A4-A23-3A3-A5-A25-A4-2A26-3(A-)A2-3A24-3(A-)3A16-A6-3A-2A2-2A22-3A2-2A-2A28-3A269-3A4-A24-A-A3-2A2-2A20-2A3-7A25-4A3-A24-5A2-A-4A17-3A4-2(A-)2A-2A16-A6-3A2(-2A)28-4A29-2A240-2A6-2A21-A-A6-2A21-2A7-2A26-2A2(-A)25-A2-2A-A-3A21-4A-2A-A2-2A25-A-A2-2A28-A-2A29-3A248-2A23-A6-2A22-2A6-2(2A26-A3-)2A-2A23-2A2-3A2-A23-A5-A2-A28-A2-A29-3A249-2(2A30-)2A64-2A30-A-A29-A2-A28-A2-A6-A10-2A10-3A11-4A-A25-2A4-A233-A97-2(A30-A-)A15-3A11-A-A15-3A11-3A7-A9-2A18-3A6-2A-2A18-3A9-A238-A31-2A26-2A-3A26-A-3A27-A2-2A28-2A-2A4-2A7-A14-5A4-A7-4A13-8A7-2A-A13-6A9-4A14-5A2-2A25-6A184-A26-2A3-A25-7A16-2A8-4A-A15-4A7-5A16-3A8-5A16-2A12-A-2A28-A-3A3-A8-3A12-2A2-5A8-A-A13-2A14-2A15-3A31-5A211-2A23-A6-4A19-3A7-2A-2A16-A2-A8-A-2A15-A2-A9-A-2A14-3A-A10-4A15-2A12-5A13-2A12-9A9-2A13-6A27-4A31-2A238-A31-A9-A16-5A9-3A16-2A-A10-A-A14-2A-2A10-A2-A14-3A11-A2-A5-A23-2A4-3A26-5A-2A25-6A27-4A295-3A13-A17-2A11-3A13-2A2-A11-A2-A14-2A13-A-2A28-4A314-2(A31-)A19-2A45-A17-A12-A-2A13-A14-2A-A28-4A30-A245-A3-A25-3A3-A-A23-3A5-A30-2A31-2A30-3A18-A10-2A-3A27-2(A-)A28-2A32-A247-A-2A23-4A-2A-A21-3A2-A-4A21-5A2-2A2-A23-2A6-2A30-A-A29-A2-A28-A3-A28-A2-A29-2A-A28-4A30-2A181-2A30-5A21-7A4-A19-A-A2-A2(-2A)-A19-2(A-)A3-5A21-3A7-A21-2A8-3A19-2A8-A2-A28-A3-A28-2(A-)A27-2A-2A28-6A27-7A30-2A144-A24-3A3-A-6A17-A2-5A7-A16-4A3-3A5-2A19-A-A3-7A18-A2-A28-2A-A8-2A18-3A9-4A16-3A9-A-3A15-3A9-2A2-4A12-A12-2A3-A2-2A23-3A-5A24-5A29-2A138-3A4-5A-A17-A2-A4-A2-2(A-)3A13-2A2-A-3A-A7-A14-3A2-7A4-3A17-2A-A4-7A17-A-2A28-A-2A27-2A-A10-4A3-A10-4A10-8A10-4A10-2A15-4A12-2A15-A15-3A31-5A129-A-2A9-2A17-A2-5A5-3A-6A12-3A-A5-A-2A2-A-3A11-5A5-3A3-2A2-2A16-3A-2A-9A16-3A9-4A15-3A29-A30-2A2-A12-3A12-A2-2A11-3A13-2A-A13-2A13-4A13-2A35-3A83-A45-2A16-2A11-8A5-9A10-4A2-2A5-A-A2-A-4A3-A5-6A6-A2-2(A-)2A-5A8-A9-8A2-2A27-5A2-2(2A11-)4A14-3A28-2A-2A13-3A10-2A2-2A13-5A8-A3-A14-2A12-A-2A14-4A9-2A-2A16-2A86-A12-A-A16-A12-2A17-A-A10-6A8-5A2-A15-2A6-A-2A-A3-2A10-A-3A6-A3-2A-9A5-3A10-2A-A-3A2-3A19-2A5-2(A2-)A25-7A12-A30-3A17-2A8-3A-A17-2A8-A3-A48-3A8-2A-2A17-A9-A59-A31-2A28-A-2A11-A-A3-A10-A2-2A9-2A-2A6-2A5-2A-3A11-A15-5A7-2A3-A-6A-A7-A12-3(A-)2A2-2A26-2A30-3A2-A28-2A14-2A28-A-2A28-A3-A50-A8-2A-A27-2A59-A2(30-2A)31-2A22-A7-3A16-A4-A19-2A2(2-A)2-3A28-2A4-2A24-A4-2A26-4A12-A15-3A13-A29-2(A-)2A30-2A49-A11-2A25-3A2-A25-2A158-2A13-A7-A-A21-A6-2(2A29-)3A2-2A27-4A77-2A125-A30-2A22-
