model
size = 21 24 25, scale = 0.05, origin = -y
material 
  colors = A:#33C B:#639 C:#09F D:#96F
voxels
99-D20-D190-B248-2D19-2D2(B18-D-)2(B18-2D)B104-B20-B21-B20-B206-2D6(B18-D-)B18-2DB19-DB42-2B22-B16-B41-2B-B183-2D19-4(D-B18-)2D19-D-B18-2(D2-B17-)D-B19-DB20-C2B17-C-4B15-CB2-B38-4B183-2D19-2(D-B18-)2D2(18-A-D)18-A2-DB17-D2-B17-D3-B16-D2-2B16-D2-B17-DC-B17-D-CB-B16-C3-B16-CB20-B-2B183-2DB18-D-B18-2D2(18-A-D)18-A2-DB16-A3-B16-A4-B15-A4-2(B16-D3-)B16-D2-B17-D3-CB15-D-2C2B16-C-CB18-B-B184-2(2D19-)2D18-A-D19-2D18-A2-DB16-A3-B15-A4-2B15-A-2A-4(B16-D3-)2B15-D2-B18-3CB205-5(2D19-)D-B17-A2-B16-A2-AB16-A-A2-B16-2A3B18-D2-2(B16-D3-)2B16-2CB227-2(2D19-)D-A18-D2A39-2DB18-D-B16-2A2-B16-A2-D18-AC2-B17-D3B16-D4-B15-D4-B16-4B19-B207-2D19-2(D-A18-)D2A40-D19-D-B16-2A2-B16-A2-D17-A2-D18-D2-2B16-D4-B15-D2-B-B16-2B-B248-2DA18-D-A12-C5-D-A11-B2C5-A12-B2C18-B2C4-2D12-BC4-A-2(D17-A2-)D17-A3-B16-A4-B16-D-3B16-2B2-B20-B228-D19-D-A11-B2C4-D-A11-B-C5-2A10-B2-C17-B2-C3-2D12-B2-C3-A-D11-B2C4-A-2(D17-A2-)D17-A3-B17-D3B19-2B263-2B6-D12-2(B-C4-D-A11-)B-C3-3DA10-B2-C3-D-2A9-B3-C3-DA11-BA-C4-2A12-2C5-2(2AD18-)2AD306-2B19-B-C5-D12-B-C3-2D2A11-BA4-D-2A9-2B-C4-D2-A8-B2A2-C3-D3A8-BA-AC17-3C342-D14-B5-D13-B-C3-2D2(12-B2-C3-DC)10-2B2-C5-3A7-B2(A-)C5-A-A7-2B2-AC5-3A9-3C6-3A19-3A18-3A3(19-2A)226-2D20-D13-2B4-2D12-B2-C3-DC9-2B-B2(2-C)-C8-B-2B2-C3-2C-C7-2B2-A-C3-2C2-A7-BA-AC4-2C2-A8-3C7-2(3A19-2A19-)2A18-A-A18-3A205-2(2D19-)DC13-BC3-C-C8-5B-C3-C-C8-B2-A2-C3-4C7-BA2-A-C3-4C8-BCA3C5-2C10-C94-2A2(18-A-A)18-2A55-A40-A43-A23-3(2C19-)2C8-2B8-C-C8-4B-BC3-2C8-2B2-2B-C14-B2-A2-C14-B2CB2-C2(18-3C)90-3A17-A2-A18-3A53-3AC38-A3-C18-A20-A96-B9-2C11-2B6-2C8-2(B2-)BC14-5B2C14-2C2-B2(-C18-C)-C18-3C68-3A18-A-A18-3A54-3AC38-A2-2C18-A116-2B21-2B7-2C7-2B2-B7-C8-2(B-)B7-C9-2C2(4-C)14-3C3-C14-C-C18-C-C19-2C47-2A18-A2-A17-4A33-2(A-C18-)A2-C17-A2-C18-2A116-2B19-B-2B16-B3-B7-C8-B2-2B7-2C8-C10-2C18-C-C13-3C2-2C14-C-C19-2C46-3A17-A2-A18-3A34-2AC18-A-C17-2A2-C17-2A-C18-2A136-2B-B17-B2-2(B20-)B5-3C19-C-C14-3C-3C14-C-C19-2C45-4A16-A3-A16-2A-2A16-3A15-2AC17-A2-C17-2A-2C18-A160-2(2B19-)B5-3C12-B5-C2-C11-B4-5C15-2(C-)2C15-3C66-3A16-2A2-A15-2A3-A14-3A2-A15-2A-2A15-2A-C17-3AC19-A207-4C17-C-2C17-2(2C19-)2C85-4A16-A3-A15-A4-A15-A3-A15-5A18-A229-2C18-3C18-2C129-A17-4A16-5A16-4A17-3A94-
