model
size = 21 17 17, scale = 0.05, origin = -y
material 
  colors = A:#630 B:#F90 C:#FFF D:#FC0 E:#FF9 F:#111 G:#DDD H:#BBB I:#300
voxels
7-7D14-7D326-4D5-4D8-4D5E4D322-2D11-2D6-2D3E2CD2C3E2D321-D2-F10-D6-DECF9CED320-2D2-2F9-2D3-ABDEC2F8CEDBA-AB17-B4(AB19-BA19-)AB19-B2A17-2A-2B15-2B3-AB2-3A9-A5-BAB3ABABG3(BA)8-3A14-D4-2F9-D3-BAE3C2F8CEAB-BA17-A4(BA19-AB19-)BA19-A2B17-2B-2A15-2A3-BA2-3A9-B5-AB5ABABGH2(AB)8-3A4-GH8-D5-2F8-D3-ABE4C2F7CEBA-AB17-B4(AB19-BA19-)AB19-B2A17-2A-2B15-2B3-AB2-3A9-A5-BA-3A2(BA)BGHABA8-3A5-GH7-D6-2F7-D3-BAE5C2F6CEAB-BA17-A4(BA19-AB19-)BA19-A2B17-2B-2A15-2A3-BA2-3A9-B5-AB5A2(BA)GHBAB8-3A5-GH7-D7-A7-D3-ABED5CI5CDEBA-AB17-B4(AB19-BA19-)AB19-B2A17-2A-2B15-2B3-AB2-3A9-A5-BA-3A2(BA)BGHABA8-3A5-GH7-D6-2F7-D3-BAE5C2F6CEAB-BA17-A4(BA19-AB19-)BA19-A2B17-2B-2A15-2A3-BA2-3A9-B5-AB5A2(BA)GHBAB8-3A5-GH7-D5-2F8-D3-ABE4C2F7CEBA-AB17-B4(AB19-BA19-)AB19-B2A17-2A-2B15-2B3-AB2-3A9-A5-BA-3A2(BA)BGHABA8-3A5-GH7-D4-2F9-D3-BAE3C2F8CEAB-BA17-A4(BA19-AB19-)BA19-A2B17-2B-2A15-2A3-BA2-3A9-B5-AB5ABABGH2(AB)8-3A4-GH8-2D13-2D3-ABDE11CEDBA-AB17-B4(AB19-BA19-)AB19-B2A17-2A-2B15-2B3-AB2-3A9-A5-BAB3ABABG3(BA)8-3A15-D13-D6-DE11CED321-2D11-2D6-2D3E2CD2C3E2D322-4D5-4D8-4D5E4D326-7D14-7D322-
