model
size = 32 5 20, scale = 0.05, origin = -y
material 
  colors = A:#111 B:#03F C:#E00 D:#EEE
voxels
6-10A3-10A8-10A3-10A9-A6BDBA3-A2(CD)4CA4-6A5BDBD5A2CDCD3C5A5-A4B2(DB)A3-A2(CD)4CA35-2(A128-A62-)16(A128-A30-)A64-
