model
size = 32 5 20, scale = 0.05, origin = -y
material 
  colors = A:#111 B:#EEE
voxels
6-10A3-10A8-10A3-10A9-7AB2A3-2ABAB5A4-11ABAB7ABAB8A5-5ABAB2A3-2ABAB5A35-2(A128-A62-)16(A128-A30-)A64-
