model
size = 32 5 20, scale = 0.05, origin = -y
material 
  colors = A:#0F3 B:#111 C:#EEE
voxels
6-10A3-10A8-10A3-10A9-A6BCBA3-A2(BC)4BA4-6A5BCBC5A2BCBC3B5A5-A4B2(CB)A3-A2(BC)4BA35-2(A128-A62-)16(A128-A30-)A64-
