model
size = 32, scale = 0.05, origin = -y
material 
  colors = A:#633
voxels
-2048A29(30(30-2A)30-34A)30(30-2A)30-33A
