model
size = 27 29 7, scale = 0.05, origin = -y
material 
  colors = A:#EEE B:#306 C:#0FF D:#111 E:#90F F:#0CF G:#0FC H:#3F6 I:#005 J:#004 K:#09C L:#0C9 M:#099 N:#096 O:#30C P:#396 Q:#6FC R:#0F9 S:#036 T:#3C6 U:#3FC V:#06F W:#06C X:#C30 Y:#008 Z:#F96 Aa:#069 Ab:#3C9 Ac:#09F Ad:#006 Ae:#AAA
voxels
223-6EQ5E14-2E2C6E3CE12-6E3Q2E3C2E10-2H2E3H3Q2E3C2E10-2(2H3E)2FC5G9-2E2C3EH2E2FC5G8-3EU2E7HE6G7-3EUEC7H2FEK3G8-2EK2E6HQHFK2EUE8-EG4E4KU3K3EU10-3HU9KEFEG10-3HC2G7KEFE12-2HE2G2E4G3EG12-7E4GF2E14-KE2HE4FEF2G15-E2H3EHKUEG17-9E21-E2U316-12B14-14B12-16B10-17B10-16B2G9-16B2G8-17B2GH7-17B3G8-17BUB8-17BU10-3H14B10-3H13B12-2H13B12-14B14-11B2G15-10BG17-8BH21-3B288-14F12-2F12B2F10-2F14B2F8-2F16B2F7-F17B2F7-F16B4G5-2F16B2G2H5-H17B2G2HG4-H17B5G4-2F19BKF5-F18B2U6-F4H14B2F7-4H13B2F8-4H13BFG9-H14B2F10-HF11B2G2C11-2F10BG2H13-2Q8B2HG15-Q3F3B3FG18-FHFQ2KF22-3F234-14C12-16C10-18C8-2(20C7-)H20C5-22C5-2(23C4-)23C5-19C2U6-20CK7-19C8-2H16CG9-H16C10-H12C2G2H11-12C2GH13-11C2G15-10CG18-7C22-3C42-2J17-2J5-JK2G15-JQ2J4-QK3G13-Q2J2G4-JQ3G12-JFJK2G5-Q3GQ10-2JFJGJ7-JK2J2-QK2QKJ2-J2FKG9-6J4K7J9-2J14AJH8-QJ16A2J6-2Q18AFC5-2K19AJ4-KJ20A2J3-KJ21AJC-2K22A2J-2(QJ23AKJ)KJ23AJC-2J19A3UC2-2J21AJC3-KJ19AJC4-KJ18AGKC5-HJ17AGK6-2J13A2G3HJ7-KJ12A2G3H9-2QK10A2G2J11-QK10A2GH13-K2J7AJ2G16-3J3AJ2K20-HJK2J14-2I17-2I5-I2AI15-I2AI4-I3AI13-I3AI4-I3AI12-I4AI5-I3AI10-I4AI7-I2AI2-6I2-4AI9-I2A2I6A2I3AI9-I16AI8-Q18AI6-2Q19AI5-2K19AI4-I22AI3-I23AI-I24AI-I2(25A2I)25AI-I23AI2-I23AI3-I21AI4-I21AI5-I19AI6-I19AI7-I17AI9-3K13AI11-2K12AI13-KI9A2I16-2I5A2I20-5I14-2D17-2D5-D2CD15-D2AaD4-D2CMD13-D2MAaD4-D2AcMD12-DC2MAaD5-D2MAaD10-D2Ac2CD7-DMAaD2-6D2-D2AcCD9-5D3W2TS6D9-2DM4L2W2TSY4RD8-D3M4L2W2TS5Y2D6-D3MP4L2W5S2Y2SRD5-DM3P4L2W4RS2Y2SRD4-D8P3W4R6SRD3-D8P3M4PS3T2S2RD-DF7OMZ2XM3P4Ab5T-D2F5OM2Z3XM2O2P2Ab5T2D2F2L3OMZ3DXM2O2P7L2D2F2L2AdOMZ4XM2O2P7LD-D2FLAeODOMZ2XM2OD3O5LD2-D2F2L3DL3M2O4DO4RLD3-DF2L3D3L3NDA2DO4RD4-DF2LDAD3L3NDA2DO4RD5-DMLAeAD3L4NDN4CRD6-DM2LDL9N4CRD7-DM3L9N4CD9-D2M2F3V5N3CD11-DMF5V6FD13-2D5V4F2D16-2D2V3F2D20-5D11-
