model
size = 15 24 16, scale = 0.05, origin = -y
material 
  colors = A:#FFF B:#3F0 C:#001 D:#100
voxels
245-A3-A10-5A9-7A8-7A9-5A11-A-A222-C-C11-5C11-CAC12-3A311-2A-2A10-D-A-D2(10-2(A-)A)11-3C12-3C280-3A-3A8-3(A-)A9-2(2A-2A10-)2(A-)A11-3A2(12-ACA)250-3A-3A2(8-2(A2-)A)8-3(A-)A7-2A2(-A)-2A7-3A-3A8-2A-A-2A10-A-A12-3A220-B5-B8-3A-3A8-2(A2-)A8-A-3A-A8-2A3-2A7-2(A-A3-A-A6-)A2-3A2-A7-2C3A2C8-2C3-2C9-5A11-3A190-B5-B8-2A3-2A7-2(A2-3A2-A6-)A-A3-A-A2(6-2A5-2A)2(6-A-A3-A-A)6-A-5A-A7-A-3A-A8-7A23-7B7-9B2(5-3B)3-3B7-3B-3B9-6B9-3B-B11-B-3B9-6B9-3B-3B8-3B-3B7-3B2(3-4B)5-B2-3A2-B7-A5-A7-A-5A-A6(6-2A5-2A)6-A-A3-A-A7-A-3A-A9-5A9-8B5-2B-5B2-B3-B2-B5-2(B2-)B-B7-3(B-)B9-B-2B-B9-B-3B11-3B2(-B9-B-2B)2-B8-3(B-)B7-B-2(B2-)2B3-2B2-2(B3-)3A3-B5-A2-3A2-A6-A-A3-A-A7(6-2A5-2A)6-9A8-5A9-7B6-2B-5B-2B3-B2-B5-2(B2-)B-B7-3(B-)B9-B-2B-B9-B-3B11-3B2(-B9-B-2B)2-B8-3(B-)B7-B-B3-B-2B3-2B-B4-B3-3A3-B5-A-5A-A8(6-2A5-2A)6-A-5A-A7-7A8-7B7-9B2(5-3B)3-3B7-3B-3B9-6B9-3B-B11-B2-2B9-2B-3B9-7B8-3B2(-B)7-B-B3-B-2B3-2B-B5-A2-3A2-A6-A-5A-A3(6-2A5-2A)5-3(2A7-2A4-)2(A-A5-)2A5-2A6-A-A3-A-A7-7A156-2B7-2B4-2B7-2B5-4A-4A6-A2(-2A)-A6-2(2A5-)A-A5-A-A4(4-2A7-2A)4-2(A-A5-)A-A3-A-A6-2A-3A-2A8-2A-2A190-5A8-2A-3A-2A6-A-A3-A-A6-2(2A5-)3(2A7-2A4-)2A7-2(2A5-)2A6-A-A3-A-A7-A-3A-A9-5A191-3A10-2A3-2A7-A2-3A2-A6-A-A3-2(A-A5-)A-A4-A-A5-A-A4-2A7-2A4-2(A-A5-)A-A3-A-A7-A-3A-A9-2A-2A12-A207-5A9-2(A2-)A7-4A-4A6-2(2A5-)2(A-A5-)3A3-3A6-A-A3-A-A6-A2-3A2-A7-A5-A9-5A235-5A10-2A-2A9-8A6-A-5A-A6-A2-3A2-A6-2A-3A-2A7-2A-A-2A9-5A35-
