model
size = 24 27 16, scale = 0.05, origin = -y
material 
  colors = A:#161616 B:#565957 C:#3A3C3A D:#262626 E:#2C2F2C F:#515551 G:#070707 H:#0F0F0F I:#000 J:#4E4E4C K:#3F3F3F L:#464643 M:#323232 N:#4A4C46 O:#1F1F1F
voxels
487-C23-3C23-N597-2C527-L2B20-BCNBL19-BDLNB18-CBJDNB-K15-B2CBJBICB16-2B4CB18-H4B21-H338-BN22-EJ2C19-F2HIB18-FE3HGF17-F2E2HA16-3LFEHG16-BL3BHG16-2FCN3B-C13-ECLEDLNF3C12-CJBLBJDN2BK2B10-JMBLD2BJBIDBI14-BGDBJLD2J16-BCIDMKJC17-6B244-B21-4B19-6B17-6BC16-BC3BCK16-2BLCBAFB15-2BHGO2CJ16-BEO2HGB16-NF2AHIGH14-A2EC2AG2H14-A4E2BHM14-6A4B13-C7AB2DC10-KCD7AB2DB10-B2C7ADBFA10-2BJB6AD2B12-JK2B2A2DA3B13-HKBCBA2BCB15-ILJ4BK18-DHLEI127-A2D20-E4D18-C5D16-2CBC3D16-2C4BCF15-2C5BL15-2C4BKBL14-4C2BABL14-2CF2-LHFB14-CLJ4-F2C14-CB2A3-BC15-C4A-CBC12-9A2B11-3AE2(3AB)12-2A2E5A2BC12-2AE-4AEACJC9-K2ADE2-3ABA2DC8-NJDAFDE2-AE3DJN8-I2BAF2D2EBC2A2B9-B2J4A4DABE12-JM4AD3AIG12-NMH5A3IG13-M3H2DHIG17-2I2DI80-ADE21-A2DK18-CE3ADF16-2C4AFD15-2C2D2AFM14-N2C2-2DAC14-J2C4-D2C13-J2C5-2C13-J2C6-2C12-J2C6-2C13-KCA6-CF12-2C3A4-JF12-AC5A2-3C10-5A2E-2A-CF10-3A4EB-D2AF11-2A2E3-BF2AC11-2A-E5-BANC11-A2-E5-BAC2DC7-2CA-J2E3-EBA2DH8-ID2F3DE2BCDADB9-BF2A7D2ABC10-2J2A3-3DAGD12-CM7AGHE13-MHI4A2GH15-H2I2D2I56-2(A22-E)3AF16-2CE4AF15-2C2A3-FD14-2CJ3A-FD13-3CJ3-AFDC12-3C6-DC12-3C7-CJ12-2C7-F2B11-2C8-CB12-CA7-C2B11-C4A5-CB12-2A-3A3-CB10-4A3E-2A2-2B9-3A5E2-2A2B9-2A-2E3-LE-2AB10-A2-E5-F2A2B10-A2-E5-BA2CDC7-C-A2-KE3-EB2ADGD7-IDA2FD2E2BCDADBC8-BJA2F4DE2DA-C10-JMA-6D2AEG11-H3A3-D2A2E13-HI5A2GE15-3ID2I2G19-DI34-AM21-E2A19-C-E3AF16-2CEA2-AF15-2C2A3-FD13-3C-3A-FD13-3C4-AFDC12-2C7-DB12-2C9-B11-2C9-2B11-C10-B11-2CA8-FB11-C4A6-B11-C2A-3A4-G10-3A4E-2A2-HG9-3A5E2-2A-H9-2A-2E3-LB-2AJ10-A2-E5-F-A2B9-2A2-E5-B-2CDC7-MA3-FE3-EB-A2DG6-BFDAF2-2E2BC-ADBCG7-BJA2F2D2BE4DC10-J2AF7DAEG11-H2A2-3D2A2E12-3H6ADE15-3ID2I2G18-ID2I33-2A21-E2A19-C-E3AF16-BCEA-2AF15-2B2A3-FD13-3B-3A-FD13-3B4-AFDC12-3B6-DH12-2B9-F11-2B9-2F11-B10-B11-2BA8-FB11-B4A6-H11-C2A-3A4-2G9-3A4E-2A2-2G9-3A4EF2-2AEH9-2A-2E3-2B-2AE10-A2-E5-L-A2B9-2A2-E5-B-2CDC7-CA3-JE3-EB-A2DG6-BFDAF2-2EB2F-ADBCG7-BFA2F2DCBE4DC10-J2AF7DAEG11-H2A2-3D2A2E12-2H7A3E14-3ID2I2GE17-ID2I56-EA22-E2ACF16-BCE4AF15-2BE4AFD14-3B4AFD13-4B2-KJFD13-3B6-DC13-2B7-KB12-B9-B12-2B8-BJ12-BA8-I12-B4A5-2H12-2A-3A4-H10-4A3E-2A2-2H9-3A5E2-2A2H9-2A-2E3-EL-2AH10-A2-E5-F2AB11-A2-E5-BAC-DC7-M-A2-FE3-EB2ADGD7-FDA2F-2E2BCDADBC8-BJA2F4DE2DA-C10-JMAF6D2AEG11-H3A3-D2A2E13-HI6AGE15-3ID2I2G19-DI57-A2C21-A3C19-LA4C16-2KC2AKF15-B2KBK2CFA14-CBK2BFLCA14-2CL3-MGB14-2B6-BK13-2B7-2K12-BC8-K13-NC7-LC12-2B3A4-KCJ11-AC5A3-BJ10-4A3E3A-CN10-3A4EF-3ACH10-2A2E3-BE2ABJ10-2A-E5-BANB11-A2-E5-BA-2DC7-CDA2-2E3-EBA2DG8-ID2F3DE2BCDADB9-BF2AC6D2ABC10-2J2A3-3DA-E12-2M8ADE13-MHI4A2GH15-H2IDG2I103-DC21-2CBC19-B2CJBF16-K3B3C16-L3B2F2C15-K2B2FMGI15-K2B-M2AG15-KL4-HGB14-KL6-2B14-K6-LB14-K-2A3-JBK14-K4A2-LK12-9A2K12-2A2EAEB3AKJ11-2A2E3AB2A2K11-3AE-4AEAF2C10-2ADE3-A-BA2DC8-CJDAFDE3-E3DJN8-GNBAF2DE2BCDA2B9-B2J4A4DABL12-JM4A2D2AIG12-NMH6A3G13-M2HG2DGIG17-2I2D2I195-3B19-3B2FM17-2BF2M2H16-2BFM3HG16-2B3GHIG15-2BH5GK14-2BMH2GOGD15-2BK2AOGJB13-A2E5AFB12-2A2EAEKAI2B13-7AK2B13-CAE5AE2DC10-3DAE5AB2DBC9-BCK8ACKA10-2BJB2AEAB2A2B12-JEB3A2DABKB13-DKBC3ANCB15-IG2J2BFK17-I2DHIA265-2F2M19-2M3H18-FM3G2H17-FH4G17-FMH2GOA17-BGIG2O16-2E2BG2OG15-4EBFGD15-2ELN3B-C13-ECELDLN2B3C11-CJBEB2ANBLD2B10-JMBHDE2ABEDCI12-B-BND2EBDJM15-FBKG2DMCN16-2F5B20-K387-G42-2LB20-2L2BN18-FBCNBJB17-2BDLNFJKC14-2CBJDNFBK15-BN2BJBICB16-2B4CB18-H4BF19-I2H109-
