model
size = 31 14 29, scale = 0.05, origin = -y
material 
  colors = A:#FF6905 B:#0A0000 C:#A0A0A0 D:#8F8F8F E:#F6D644 F:#828282 G:#6F6F6F H:#F28214 I:#F2AB14 J:#F29114 K:#FAEB88 L:#FDF4B9 M:#F3BC27 N:#A8A8A8 O:#FF5705 P:#A3A3A3 Q:#B9E7FD R:#B9B9B9 S:#4AA7F6 T:#1352F1 U:#FF3A05 V:#1224B0 W:#F23914 X:#ED2707 Y:#030303
voxels
103-P2(DN)DGNCDF20-BCNBGF3BGC20-BDBCBP2(BC)D20-BNBPBC2(BD)G20-BCBNBDBCBNR20-BDBGBD3BGB20-DCGDCPDGCDC235-CDC9-CDC16-3B9-CBD16-BDB9-CBF16-BPB9-CBD16-BRB9-CBC16-3B9-3B16-P2C9-CGF232-DC13-CF14-CB13-2C14-NB13-CD14-DB13-2C14-CB13-CD14-DB13-BC14-2C13-CG230-2C15-2C12-BC15-CD12-BC15-CF12-G2(C15-CB12-B)C15-CB12-CD15-2C228-FD17-CD10-CB17-CF10-2B17-CD10-BC17-2B10-2B17-BF10-CB17-2B10-FC17-CF226-2C19-2C8-BC19-2B8-2B19-2B8-RB19-2B8-2B19-2B8-BC19-2B8-CD19-2C224-CD21-CD6-CB21-CF6-GB21-2C6-2C21-2C6-RB21-CF6-CB21-CG6-RC21-CD222-2C2(23-2C4-BC)23-CD4-BC23-CB2(4-BC23-2B)4-GD23-CF220-GC25-2C2-2B25-2B2-PB25-2B2-2B25-2B2-DB25-CF2-2B25-2C2-NC25-CG219-C27-D2-B27-P2-N27-F2-B27-B2-N27-B2-B27-B2-C27-D219-D27-F2-D27-G2-P27-D2-D27-N2-G27-F2-N27-G2-D27-F219-G27-C2(2-B27-B)2-B27-F2(2-B27-B)2-D27-R219-P27-D2-B27-P2-D27-C2-C27-B2-D27-F2-C27-B2-P27-N219-D27-C2-B2(27-B2-P27-B2-D)27-B2-G27-D219-P27-R2-C27-C2-N27-F2-F27-D2-C27-G2-N27-C2-D27-G219-C27-R2-B27-B2-D27-C2-B27-R2-B27-P2-B27-B2-P27-C219-R27-C2-B27-B2-G27-R2-B27-C2-F27-R2-B27-B2-G27-D219-D27-G3(2-B27-B)2-C27-B2-B27-B2-C27-C219-P27-D2-G27-C2-F27-D2-C27-F2-F27-G2-C27-C2-F27-N131-8B3-8B9-7B3-2B-2B3-7B4-4B9-B-B9-4B2-FBY10-3B10-YBF3-2B11-B11-2B3-D2B23-2BC3-2B23-2B3-C2B23-2BP3-2B23-2B3-C2B23-2BD2-BYB23-3B2-4B21-BY2B3-7B13-7B6-5B13-5B10-CFG2(DC)N3-RPRCGDNC9-DCGBA6BF-G6BABRCD4-DCBTSQL5-BC-CB5-LQSTBCF2-G2ATSQL6-BNB6-LQST2AG2-R2ATSQL6-3B6-LQST2AD2-G2ATSQL7-B7-LQST2AG2-C2AVTSQ15-QSTV2AD2-F2AVTSQ15-QSTV2AF2-G2AVTSQ15-QSTV2AD2-F2AVTSQ15-QSTV2AC2-C2AVTSQ15-QSTV2AG2-FBAVTSQ15-QSTVA2C3-CFB3A4B7-4B4AGP6-DCNC4B7-4BGNDR10-DNCNDPRD3-2(ND)CNCF9-PDCB4A3BP-P3B4ABPRC4-FGB4AEIJ2-BG-CB2-JIE4ABFD-2B6AEIJ3-BCB3-JIE6A4B6AEIJ3-3B3-JIE6A4B6AEIJ4-B4-JIE5(6A4B6ALEI9-IEL)6A2B-CB5ALEI9-IEL5ABD3-DCB6A9B6A2CD6-FDCFD2C9BCFDCFCN10-GFRDGRCN3-2(RC)RFND9-DCRB6ACD-FB6ABDCD4-GCB7AH2AC-G2AH7ABCN-2B9AH2ABGB2AH9A2B-V9AHA-3B-AH9AV2-V9AHA2-B2-AH4(9AV2-V9AJH5-HJ)9AV-2B9AJH5-HJ9A2B-GB8AJH5-HJ8ACF3-CDB8A5B8ACGP6-CGPGDFDNFPG2(CN)FGNCDCND10-RPDCFCRD3-2(CD)FGCF9-CFDB6ABC-PB6ABPRG4-3B10AG-G10A3B2-BS12AC12ASB3-S10AW3AW10AS4-T10AWXAXW10AT4-T10A2WX2W10A3(T4-T11AWXW11A)T3-BT12AW12ATB2-2B12AW12A2B3-NCB21A2CF6-GFDCFNFCGF2(DN)CPCFPCDCF10-PRGFCDCR3-FRGFCRFD9-DCRB6ABD-GB6ABRCF5-2B10AC-C10A2B5-Q11AC11A2(Q6-Q23A)Q5(6-S23AS)5-BSQ21AQSB4-2BQ21A3B6-CDCGDCDPDNCFCDNDFCD2(GC)10-RGNDGCRN3-GDCGPDRC9-2BCB2E4ABC-FB4A2EBC2B6-BL2KE6AG-R6AE2KLB7-L2KE7AG7AE2KL8-L2KE15AE2KL6(8-QLKE15AEKLQ)9-LK2E13A2EKL8-B-L2K2E11A2E2KL2B7-2BG2FCG2(CF)CDC2(F2C)N2B10-2BCNFDCD3-RCDPDC2B10-3B2MIJHABG-PBAHJI2M3B10-E2MIJHAOC-GOAHJI2ME11-K2EMIJHAOBCBOAHJIM2EK10-2KEMIJHAOUBUOAHJIME2K5(10-LKEMIJHAOUXUOAHJIMEKL)10-LKEMIJ2HAOUOA2HJIMEKL11-KEMIJ2HAOUOA2HJIMEK13-KEMIJHAOUOAHJIMEK12-3BCGPDCNDF2(CD)NCG3B11-4BCFGC3-CFCG4B12-B2-IJHABC-RBAHJI2-B14-MIJHAOG-COAHJIM15-EMIJHAOBGBOAHJIME13-KEMIJHAOUB5(UOAHJIMEK12-KEMIJHAOUX)UOAHJIMEK13-EMIJ2HAOUOA2HJIME15-MIJ2HAOUOA2HJIM17-MIJHAOUOAHJIM16-2BCDC2(FP)2(FC)GD2B16-5B3-5B22-2B-2B27-B-B28-3B29-B272-13B9-
