model
size = 27 32 7, scale = 0.05, origin = -y
material 
  colors = A:#D550FF B:#000 C:#454545
voxels
699-3(A26-)A754-3B4(24-BAB)24-3B106-C26-C512-C32-2A18-3B3-5A12-4A3B3-21AB-B5-10A6-3AB-B7-10A4-3AB-B9-15AB-B18-6A3B25-C53-C25-3C24-3C25-17(C26-)C2-A22-3C-2A22-C2-5A17-A3B2-23A3B2-21AB-2B4-10A6-3AB-2B5-11A4-3AB-2B7-16AB-2B16-7A4B23-3C25-C53-C26-C512-C32-2A18-3B3-5A12-4A3B3-21AB-B5-10A6-3AB-B7-10A4-3AB-B9-15AB-B18-6A3B25-C701-2B3(24-BAB)2(24-3B)754-3(A26-)A83-
