model
size = 25 19 23, scale = 0.05, origin = -y
material 
  colors = A:#84492C B:#FEAE89 C:#000 D:#A17A43 E:#FEEA41 F:#A9523A G:#FF8CDF H:#562E17 I:#94453E J:#037C30 K:#8E695F L:#C34B29 M:#FFF N:#ED00A8 O:#1E1729
voxels
280-C-C423-C3-2B43-C-2C101-C295-C2-C19-2CAC-CB-B16-4C-C20-C2-OC2(23-2C)22-2C24-4C223-C20-4C2B18-4C3B17-2CA2C3B16-C2ACABAC7B10-C4A14B2(6-5CA13B)7-4C2A5B16-CBA2B3-B17-5C48-C147-4C19-4C2B18-C4A4B15-C4A5B15-C4ABA4B13-9CB2C8B5-14CA4CB5-C2F2A9E2K3IB2-4C4A6E3A2K2I2B5-C4A5MBA8B6-2CB4A2B-2B3-2B8-C-2B4AC2(20-5C)121-C23-2C21-6C2-B-B13-C3AB3C2-B13-C5A6B12-C6A6B12-8C3BCA7B5-9CB4CA4CB4-C4F10E2K3IB4-C16A3IB5-C19AB5-C8A10B6-C3B2A3JC16-C2BA2HLJC17-C-C3-2C23-C95-3C3-B18-2C-C2-B2-3B11-2CAB-2C7B10-C3AB2C8B8-2C5A10B7-C8A3-BA4B7-9C3B2C4A3B4-14C6DB4-C-3F8EK6DB4-C13A7DB4-C19AB5-C7A-A10B6-3BAH3JC9B7-3BA2H2LC2-2B12-2C-C4-C95-4C20-3C2B-4B14-2CA3B-B2-3B10-2C3A7B2AB-B7-C5A3BA2B4A2B6-2C9AB5A2B5-C8A4-5A2B5-14C5AB4-15C5D2B3-C6F7EK5D3B3-C13A5D3B4-C17A3B5-C6A2-A10B6-3BAH4J-9B6-3BA2H2LJ9B7-2C-C4-C72-2C20-3C2B3G17-2C2A8B11-3C4A2B-B3AB9-2C8AB4A2B7-C16AB5-2C17AB4-C10A2B7AB5-14CD3A-B4-15C4DA2B3-C6F6E2K4DA3B2-C14A4DA3B3-2C17A3B5-C6A2-A10B5-C3B2A3J2-9B6-3BA2H2L-10B6-C2-C4-C72-2C19-5C3BG17-2C5A4BG11-2C6AB-B3AG7-C-2C8AB5AG5-3C16AB5-C18AB4-C19AB4-15CD3A-B4-15C4DA2BG2-C6F6E2K4DA3B-C15A4DA3B2-3C15AIA3B4-3C5A2-A11B5-3B2A2J3-10B6-2BC2H2LJ10B14-C72-2C19-6C3G17-2C6A2G2B11-2C6AB-B3AB9-2C8AB5AB5-3C16AB5-C18A2B3-C19A2B2-16C3DA-2B3-15C4D-3B2-C6F6E2K4D-3B-C15A4D-3B2-3C15AI-3B4-4C6A2-5B-4B4-C3BCH4J6B-4B6-2B-2HLCJ10B13-2C7-N62-C-3C18-7C2B17-2C6A4B11-2C7A-3BAB9-2C8AB5AB5-3C16AB5-C18A2B3-C19A2B2-16C5D2B3-15C4D4B2-C6F6E2K4D4B-C15A5D2AB2-3C15A2I2AB4-6C2-3A11B3-2C3B-4CE11B4-C3B-2C2-11B6-3C2-2C3-2B4-N18-2B42-C-2C19-6C3B17-2C6A4B11-2C7A-BA3B9-2C14AB5-3C16AB5-C18A2B3-C19A2B2-16C4D-2B2-CF14C4D4B2-C6F6E2K4D4B-C15A5D2AB2-3C5AB9A2I2AB4-6C2B3A11B4-C3BC4BE11B6-2B3-13B16-2B4-N18-2B19-C24-2C19-5C2(BG)17-2C2AB3A2(BG)10-C-C7A-B3AG9-2C14AG5-3C16AB5-C18ABG3-C19A2B2-16C4D-2B2-16C4D4B-2C6F6E2K4D4B-C15A5D2AB2-3C15A2I2AB4-4C7A11B5-3B5CA11B6-2BC-3C11B11-3C8-N64-2C19-4C2BGBG16-3C2AB3A2(BG)10-C-C7A-AB2AB9-2C14AB6-2C16AB5-C18AB4-C19AB4-15C5DB6-13C4D3BG2(-C)4F7E2K4D4B2-C14A5D2AB3-2C15A2I2AB5-2C7AC11B5-3B4AC-11B6-2BC2HL-C10B14-C72-2C20-3C2B3G17-2C2AB3A2GBG10-3C7ABA2BAG9-2C14AG6-2C16AB5-C18AB4-C19AB5-14C5DB5-14C4D3BG2(-C)4F7E2K4D4B2-2C13A5DA2B4-C15A2IA2B5-C8AC10B6-3B4AJC10B7-2BA2H2LC10B9-C4-C47-C21-C-3C20-2C6B17-2C5A5B11-2C4AB2AB4AB9-2C14AB6-2C14A2(3B5-C16A)3B6-13C4DAB6-13C4D4B3-C3F9EK4D4B2-2C13A5D3B2-C-C15A2I3B5-C5AI2AC10B6-3B2A-AJC10B7-2BA2H2LC9B10-C4-C72-C23-CBC21-CBA4B-B14-2C2A6BA2B10-2C5AB2AB4AB7-2C13A4B2(5-C16A3B)6-13C3D2AB6-13C4D3B4-C2F-9EK4D4B2-2C15A3D3B2-3C16AI3B5-C8AC10B5-C3BAH2AJC9B7-3BA2H2LC2-2B12-2C-C4-C97-C23-CB21-2C2B5-3B10-3C3ABC7B9-C5ABAB5A2B8-C6A3B5A2B8-C4A3BAB5A2B7-CAC2A2CB6C2D2A2B5-CAC2A9C3DA2B5-3C2A9E3DA2B5-3C2A7E7AB4-2C-CBA6M8AB4-C3-BAMA2-2AC9B7-3B4AJC8B10-BA2H2LC19-C4-C146-C20-4CB2C17-C3A9B2(11-C3A10B)10-3CAC5B2CBD4B7-3CA4B5C3D3B6-C-C2A2B6A6B2(8-C2A2B5A7B)4-C4-B3AC2AC2B3-3B9-2B2ACAC19-2C2HLC20-C3-C193-3C21-3C22-2CB-C21-C10B13-3C13B7-C-CA5BA8B9-CA14B10-CB-C5B16-4C-2C-B17-3C-C47-2C273-C22-C-C21-2C-CB-B17-2(C-)C22-C24-C2-C21-2C2(-C)21-3C22-C325-2B188-
