model
size = 30 8 32, scale = 0.05, origin = -y
material 
  colors = A:#FFC B:#FFF C:#F39 D:#444 E:#F00 F:#222 G:#001
voxels
78-2A28-C29-2A140-2A29-C28-2A209-2CA28-A210-2D28-2D209-A29-A177-2(4AB25-)4AB27-A117-5A-A21-2B4A2BAB20-2B4A2B2A20-3C3A2B2A22-C4A27-A85-9A2BE17-3B7A2BE17-3B9AE17-12AE18-2C6AGA22-5A-G25-B54-12AE16-2(4B8AF17-)13AE17-2B6A4B19-B6A3B22-CA3B26-A-A22-13AE15-13AF16-D12AF16-D13AE16-3B6A4B18-2B6A3B20-3C4A23-2(C-)A-A20-14AE14-15AE14-2D13AE14-2DC12AE15-2C9AGA18-C4AC3A-G20-3B2-A24-B-B24-B7AB2A-A17-B7AB3A2B16-8AB3A2B16-9A2C3A16-C4A3CA2C21-3AC2-A24-B56-B4A25-B7AB2A19-6ACAB2A19-2B4AC2A2C19-2B4A2-A22-B2A28-A57-4A25-7A23-6AC2-B20-3BC3D2-A21-2BCD27-BA28-A57-4A26-A4B15-2D6-7A4-B10-D7-4A3C4-A9-3A8-2A2C16-A10-A18-CA98-A3B3-A19-7A3-2DB9-D7-5A2C4-D10-A7-D2AB18-B136-2A15-2C2-A-2A6-D11-2(A3-)A-AB5-CD11-B2-3A2-D2-B18-B3-D29-2D90-2C15-2A12-A3-A11-D6-2A-A2-3A2-B11-DC5-BA-A3-D3-B18-B2-D2-2D135-A3-3BA10-D9-B2D3-7A7-A10-D4-2C5A7-B18-B2AD113-4A8-2D15-4BA9-D10-B4-7A6-3A9-A4-3C4A7-A16-2C2A8-AC18-A86-4A24-7A20-B2-C6A20-A2-3DC3B25-DC2B27-AB29-A56-4AB19-2AB7AB19-2ABAC6A19-2C2AC4A2B21-A2-4A2B26-2AB28-A49-A-2A2(B7AB16-2B3A)B8A16-3A2C9A19-2CA3C4AC21-A2-C3A28-B47-E14A15-E15A14-E13A2D14-E12AC2D16-AG9A2C18-G-3AC4AC23-A2-3B27-B-B17-E13A17-F13A16-F12AD15-E13AD16-4B6A3B18-3B6A2B22-4A3C23-2(A-)C-C18-E12A18-F8A4B17-F8A4B16-E13A17-4B6A2B19-3B6AB23-3BAC26-A-A21-E2B9A18-E2B7A3B17-E9A3B17-E12A19-AG6A2C21-G-5A27-B55-A-5A22-BA2(2B4A2B20-2A)2B3A3C23-4AC27-A117-2(B4A25-)B4A27-A179-A29-A209-2D28-2D209-A2C28-A132-
