model
size = 16 32 16, scale = 0.05, origin = -y
material 
  colors = A:#E25C29 B:#200000 C:#AE4E07 D:#743104 E:#6D2904 F:#4C1702 G:#782F04 H:#A34806 I:#974206 J:#803704 K:#8C3D05 L:#571D02 M:#360B01 N:#411101 O:#9A4106 P:#2B0500 Q:#461A01 R:#622303 S:#7F4504
voxels
5-8B457-2DEQ11-M4QF9-8B458-2RDL11-3F3N9-6B2N8-6B2N442-R2DL10-2R4A2L7-2F6A2L2(6-F8BN)425-4D10-2D4ADL7-L8AL5-F10AM2(4-11BN)409-3I10-8D7-L8AD5-L10AL4-L10AM3-13BM2-13BM407-4D10-2D4A2D7-L8AF5-L10AL3-F12AB2(2-13BM)327-I4(2O13-E)2O12-6D8-2D6A2D5-L10AF3-L12AM2-L12AB-2(F14BM)7-P15(15-C)14-3C2(13-3H)13-3I12-I3GE11-EGKGE11-E3KE11-E3JE11-E2DJE10-ED2A3D8-2D6ADF5-D10AF3-D12AM-D14A2(M7BC7B)M6-3P16(13-3C)12-2(5H11-)5I10-E5GE9-EG3KGE9-E5KE9-E5JE9-E4DJE9-ES3A2D8-2D6ADF5-D10AF3-D12AM-B14A2(M6B3C6B)M6-3P16(13-3C)12-2(5H11-)5I10-E5GE9-EG3KGE9-E5KE9-E5JE9-EJ2D2JE9-ED2A2DF8-2D6ADF5-D10AF3-D12AF-B14A2(F6B3C6B)F7-P15(15-C)14-3C2(13-3H)13-3I12-I3GE11-EGKGE11-G3KE2(11-G3JG)10-E5DF8-2D6ADF5-D10AF3-D12AF-B14A2(F7BC7B)F326-3(2EI13-)3E13-3G12-5DF8-2D6ADF5-D10AF3-L12AF2-L12AF-2(15BF)406-3DF10-2D4ADF7-D8AF5-L10AF3-M12A2(F2-13B)F421-6D2E7-D8AF5-D10AF4-P10AF3-13BF2-13BF423-3DE10-2D4A2E7-D8AF5-M10AB2(4-12B)440-3DE10-FD4A2Q7-BM6A2F2(6-10B)3-
