model
size = 21 17 17, scale = 0.05, origin = -y
material 
  colors = A:#BBB B:#003 C:#FFF D:#AAA E:#006 F:#111 G:#DDD H:#300
voxels
7-2(7A14-)7A305-4A5-2(4A8-4A5D)4A301-2A11-2A6-2A3D2CA2C3D2A6-2A3D5A3D2A300-A2-F10-A6-ADCF9CDA6-AD11ADA299-2A2-2F9-2A3-2BADC2F8CDA2(2B-)AD11ADA-3B8(19-2B)19-3B17-2B-2B15-2B3-2B2-3E9-B4-4B3E3BG6B8-3E14-A4-2F9-A3-2BD3C2F8CD2(2B-)AD11ADA-3B8(19-2B)19-3B17-2B-2B15-2B3-2B2-3E9-B4-4B3E4BGA4B8-3E4-GA8-A5-2F8-A3-2BD4C2F7CD2(2B-)AD11ADA-3B8(19-2B)19-3B17-2B-2B15-2B3-2B2-3E9-B4-4B3E5BGA3B8-3E5-GA7-A6-2F7-A3-2CD5C2F6CD2(2C-)AD11ADA-3C8(19-2C)19-3C17-2C-2C15-2C3-2C2-3E9-C4-4C3E5CGA3C8-3E5-G2(A7-)E7-A3-2CDA5CH5CAD2(2C-)AD11ADA-3C8(19-2C)19-3C17-2C-2C15-2C3-2C2-3E9-C4-3C-3E2(-C)-GA3C8-3E5-GA7-A6-2F7-A3-2CD5C2F6CD2(2C-)AD11ADA-3C8(19-2C)19-3C17-2C-2C15-2C3-2C2-3E9-C4-4C3E5CGA3C8-3E5-GA7-A5-2F8-A3-2BD4C2F7CD2(2B-)AD11ADA-3B8(19-2B)19-3B17-2B-2B15-2B3-2B2-3E9-B4-4B3E5BGA3B8-3E5-GA7-A4-2F9-A3-2BD3C2F8CD2(2B-)AD11ADA-3B8(19-2B)19-3B17-2B-2B15-2B3-2B2-3E9-B4-4B3E4BGA4B8-3E4-GA8-2A13-2A3-2BAD11CDA2(2B-)AD11ADA-3B8(19-2B)19-3B17-2B-2B15-2B3-2B2-3E9-B4-4B3E3BG6B8-3E15-A13-A6-AD11CDA6-AD11ADA300-2A11-2A6-2A3D2CA2C3D2A6-2A3D5A3D2A301-4A5-2(4A8-4A5D)4A305-2(7A14-)7A301-
