model
size = 32 24 16, scale = 0.05, origin = -y
material 
  colors = A:#005 B:#9CF C:#004 D:#FF0 E:#111 F:#00B G:#00E H:#008 I:#FF9 J:#FF6 K:#AAA L:#CF6 M:#00D N:#777 O:#CC0 P:#FF3
voxels
15-K2NK732-2K374-G2F12-2FG12-FG3-G10-GD-DGF9-F-4DID8-GI5DG8-G-I3-D-F6-G-D3-I-G8-F2-I3D-G6-G2-2DID-F8-F-D3-D-F6-F-D3-D-F8-G-I3DIDF6-F-I3DIDG8-G2-D-I2-F6-G2-I-D2-G8-D2FGF2GFD6-DF2GFG2FD75-2(2EH4EH)2E14-2(2EH4EH)2E191-A172-2CG2FC2A6-2AC2FG2C9-CFG3AGCA6-ACGDADGFC7-CM-4DID2C4-ACGI5DMA6-CGAI2ACDAFC4-AFADC2AIAGA6-CFA-I3DAGCA2-ACG2A2DIDAFA6-CFADCACDAFCA2-ACFADCACDAFA6-CG-I3DIDFC4ACFAI3DIDGA6-CG2ADAI2AGC4ACG2AIAD2AGA6-AD2FGF2GFP5ACPF2GFG2FDA7-24A8-11A2-11A9-H3EA4EH2EH4EA3EH10-H20EH9-11D2-6D4(13-11A2-6A)14-10A2-7AC2A3(10-10A2-10A)10-5A4-6A2-5A10-7AC2A5C7A10-8ACA3C9A9-9AC2A2C10A7-10AC15A6-11A3C12A6-11A2C13A6-12A2C12A6-C25A5-28A5-26A5-28A4-28A7-E20-E10-E20-E9-11D2-10D9-2(A9BA2-A4B4A10-)A9BA2-A4B3A2-A8-A9BA2-A5B3A-A8-4AC2(5BA2-A5BC4A8-5A)5BA2-A5B5A8-5A5BA2-A5B5A3(8-24A)7-26A6-26A5-C27A2(4-28A)4-C27A4-28A5-26A4-30A3-28A6-E22-E8-E22-E7-DJ5-3A2D2-2D3AJ4DJD6-2A4-A4BA2-A4BA-BA-2A6-2A4-A4BA2-A4BA2(-2A)6-2A4-A4BA2-A4BA4-2A6-7A4BA2-A4B4AC2A6-6AC4BA2-A4BC6A6-7A4BA2-A4B7A6-6AC4BA2-A4BC6A6-7A4BA2-A3BAC6A6-7AC4B2A4BC7A6-7A12-7A6-26A5-C27A5-C25A5-C27A4-C27A3-2(30A2-)30A4-26A4-30A2-30A3-HE24-EH4-HE24-EH5-JD6-2A2D2-2D7-ADJ5-4A2C3A3BA2-A2B4-2C3A5-4A2C3A3BA2-A2B4-2C4A4-6AC2A3BA2-A2B3-C2AC3A4(4-C8A3BA2-A2B3-7A)4-C7AC3BA2-A2BA2C7A4-C7AC4B2A3BAC8A4-C8A8-11A4-9A10-9A3-10A2-6A2-10A2-A2C27A4(2-30A)2-C29A3(2-30A)3-2(E26-E4-)2D9-2D2-2D8-A2D4-4AC5A2BA2-AB6-C2(-3A4-C9A2BA2-A2B5-A)-3A4-10A2BA2-A2B5-A-3A3-11A2BA2-A2B5-A-4A2-11A2BA2-A2B5-6A2-11A2BA2-A2BC4-6A2-11A2BA2-A2BA4-6A2-11A3B2A3BC10A2(2-C29A4(2-30A))2(2-30A)2(2-E28-E)3-2DA8-2D2-2D8-A2D4-3A7-2BA2-AB8-3A4-C2A7-2BA2-A2B7-3A4-C2A6-C2BA2-A2B7-3A4-3A6-C2BA2-A2B7-3A3-3A7-C2BA2-A2B7-4A2-3A3-4AC3(2BA2-A2B7-2(4A2-)5A)3B2A3BC10A2-4A2-24A5(2-30A)2-12A6-12A2-C11A6-12A2-30A3(2-C29A)2(2-E28-E)3-2D9-2D2-2D8-A2D4-J2A8-BA2-AB9-AJ4-D2A7-2BA2-A2B8-AD4-D2A6-C2BA2-A2B8-AD4-J2A6-C2BA2-A2B8-AJ3-D2A7-C2BA2-A2B8-2AD2-D2A3-4AC2BA2-A2B8-2AD2-D3A2-5A2BA2-A2B7-3AD2-J3A2-5A2BA2-A2B7-3AJ2-J3A2-5A3B2A3B5A2-3AJ2(2-D3A2-18A2-3AD)2-J3A2-18A2-3AJ3(2-D3A2-18A2-3AD)2-D3A2-5A8-5A2-3AD2-D3A2-7A4-7A3(2-3AD2-D3A2-18A)2-3AD2-D3A2-5A8-5A2-3AD2-2A26-2A2-AE26-EA3-JDA-3A4-2D2-2D8-ADJ4-10A2BA2-AB8-2(3A4-C9A2BA2-A2B7-)3A4-10A2BA2-A2B7-3A3-3(C10A2BA2-A2B7-4A2-)C10A2BA2-A2B7-3AC2-C10A3B2A3B10AC2-C10A8-11A2-12AC3-BC12A2-30A2-11A-6A-11A2(2-30A)2(2-11A8-11A)3(2-30A)2-11A8-11A2(2-E28-E)4-D9-2D2-2D7-A2D6-2(8AC2BA2-A2B6-4A5-)9A2BA2-A2B6-4A4-10A2BA2-A2B6-4A3-2(11A2BA2-A2B6-5A2-)10AC2BA2-A2B6-5A2-10AC2BA2-A2B6-4AC2-10AC3B2A3B10AC2(2-11A8-11A)2(2-11A-6A-11A)2(2-30A)-D11A8-11AD-12A6-12A3(2-30A)2-11A-6A-11A2(2-E28-E)3-3D5-5D2-2D8-2D5-9A3BA2-A2B7-2(2A5-8AC3BA2-A3B6-)3A4-8AC3BA2-A3B6-3A4-8A2C2BA2-A2BC6-3A4-9AC2BA2-A2BC6-3A4-8A2C2BA2-A2BC6-3A4-8ACHCBA2-ABCH6-3A4-9A3CB2AB3C9A4-10AC6-11A4-11A2C2-2C11A4-12AC2-C12A3(4-28A)2-F30AF2-4(28A4-)28A3-AE26-EA2-AE26-EA4-J11D2-11DJ4(6-12A2-12A)6-7AC4A2-4AC7A6-7A2C3A2-3A2C7A6-7A2C2BA2-A2B2C7A6-7A4CA2-A4C7A6-7A2-2C4A2C2-7A6-9A8C9A6-10A6C2(10A6-10A-4C-)10A6-C25A6-26A4-FAC24ACAF4-5(26A6-)E24-E6-E24-E7-2(J2D)12-2(2DJ)3(8-6A12-6A)8-6A12-C5A8-6A12-2(C2A)8-3AC2AC10-2C5A8-5A5C4-5C5A8-3AC2A-3C4-3C-CAC3A8-6A12-C5A8-7AC-C4-C-2C6A8-4AC3A3C2-4C7A8-6AC2A-4C-C8A8-7ACA-4C-2ACA4CA8-AC8A2C7AC4A8-2A2C6ACAC4A2C5A6-FH2C2A2C4AC2AC4AC3A2CHF6-2A2C2AC3AC2AC6A3CA8-4ACAC3AC2AC5AC2ACA8-5A2(C4AC2A)HCA8-6AL3AC2AC3AL5CA8-10AC13A8-E-CE4-C2-2L2-C4-EC-E8-E-CE4-C2-2O2-C4-EC-E519-3A20-3A9-2A16-2A2(14-A)17-A12-A19-H10-H20-D10-D14-2EA-4EH2E2D2EH4E-A2E9-EA-4EHE4KEH4E-AE5-
