model
size = 22 31 30, scale = 0.05, origin = -y
material 
  colors = A:#111 B:#3CC
voxels
77-3(B21-)B857-B659-B21-B65-B21-B153-B21-B351-2(B21-)B43-2(B21-)B131-2(B21-)B373-4(B21-)B109-B43-B21-B43-B351-B21-B197-2(B21-)B395-B21-B197-B21-B175-B43-B197-B21-B219-B197-2(B21-)B175-B21-B65-B153-B21-2(B197-)5(B21-)B109-2(B21-)B175-2(B21-)B109-4(B21-)B175-3(B21-)B153-2(B21-)B106-7A16-5A17-5A19-A2(21-B)175-B21-B109-5(B21-)B148-11A11-11A12-9A13-9A14-7A17-3A130-2(B21-)B153-B21-B213-2(13A9-)13A10-11A11-11A12-9A15-5A2-B16-B4-B16-B43-B21-B175-B21-B234-2(A13-A7-)A13-A8-A11-A9-A11-A7-2B-A9-A12-9AB14-5A19-2(B21-)B175-B21-B255-2A13-2A5-2A13-2A6-3(A13-A7-)BA11-A10-A9-A12-9A16-3A196-B21-B277-3(2A13-2A5-)2A13-2A6-A13-A7-2A11-2A8-A2(10-2A)7-2A13-7A172-3(B21-)B175-B78-3A13-3A4-3(2A13-2A5-)2A13-2A6-2A11-2A8-A2(10-2A)7-2A12-9A17-A131-B21-B153-B65-B21-B78-2(3A13-3A3-)3A13-3A4-2A13-2A-B3-2A13-2A6-2A11-2A7-2A10-3A8-3A7-3A11-2A5-2A15-5A107-B21-B175-3(B21-)B100-3A13-3A-2B3A13-3A2-B3A13-3A4-2A13-2A2B3-2A13-2A5-3A11-3A6-2A10-3A8-3A7-3A10-3A5-3A14-5A85-B21-B219-B144-3(3A13-3A3-)3A13-3A4-2A13-2A5-3A11-3A6-2A10-3A8-3A7-3A10-3A5-3A13-7A18-3(B21-)B197-2(B21-)B144-2(3A13-3A3-)3A13-3A4-2(2A13-2A5-)3A11-3A6-2A10-3A8-3A7-3A10-3A5-3A14-5A261-B21-B188-2(3A13-3A3-)3A13-3A4-2A13-2A5-2A13-2A6-2A11-2A7-2A10-3A8-3A7-3A11-2A5-2A15-5A239-B21-B210-3A13-3A4-3(2A13-2A5-)2A13-2A6-2A11-2A8-A2(10-2A)7-2A12-9A17-A219-3(B21-)B189-3(2A13-2A5-)2A13-2A6-A13-A7-2A11-2A8-A10-2A10-11A13-7A194-2(B21-)B65-B21-B167-2A13-2A5-2A13-2A6-2(A13-A7-)A13-A8-A11-A10-A9-A12-9A16-3A152-2(B21-)B300-15A7-2(15A6-B)-13A9-13A10-11A12-9A15-5A129-2(B21-)B345-2(13A9-)13A6-2B2-11A11-11AB11-9A15-5A129-B21-B390-11A11-11A12-9A13-9A2-B11-7A2-2B13-3A130-B21-B414-7A16-5A17-5A18-2(BAB19-)3B20-5(B21-)B428-
