model
size = 22 30 23, scale = 0.05, origin = -y
material 
  colors = A:#F60 B:#E00 C:#6C0 D:#90C E:#111 F:#FF0 G:#EEE
voxels
252-2E19-2(E2-E18-)E2-E19-2E15-2E8-2E9-E2-E6-E2-E7-3(E4-)E6-3(E4-)E7-E2-E6-E2-E9-2E8-2E209-AF6AFA12-F3A2F3AF78-A2B5ABA12-2B2(AB)A3B10-2FA2BF2AFB2A2F8-2B10-2B6-FA2B10-2BAF4-3BC4-2E4-C3B4-B3C3-E2-E3-3CB11-E2-E18-E2-E19-2E15-2E8-2E9-E2-E6-E2-E7-3(E4-)E6-3(E4-)E7-E2-E6-E2-E9-2E8-2E188-2(2AF)2A13-2(10A12-)3(10G12-)10A11-12A9-5AF2AF5A8-2ABACF2AFCAB2A5-5ABACF2AFCAB5A2-4A3C2D2E2D3C4A2-2B3A3DE2-E3D3A2B2-2BC4DCE2-EC4DC2B4-3D3CE2-E3C3D6-D4CFA2EAF4CD6-DC3E6A3ECD6-FE2-E6AE2-EF2(6-E4-E4AE4-E)6-CE2-E6AE2-EC6-2C2E8A2E2C6-3CF8AF3C7-2CF8AF2C9-CF8AFC11-2F6A2F101-8A13-2(10A12-)3(10G12-)10A11-12A9-14A8-14A5-20A2-9A2E9A2(2-8AE2-E8A)3-C6AE2-E6AC4-D7A2E7AD4-D2A3E6A3E2AD4-DAE2-E6AE2-EA2(D4-DE4-E4AE4-E)D4-DAE2-E6AE2-EAD4-D2A2E8A2E2AD4-D16AD5-C14AC7-C12AC9-CF8AFC11-3F4A3F99-A10-A141-14A8-14A7-16A4-20A2(2-9A2E9A)3-B7A2E7AB4-B16AB3-B18AB2-B2A3E8A3E2AB2(2-2DA4E6A4EA2D)2-2D2A2E8A2E2A2D3-D16AD4-18A4-D16AD5-2C12A2C7-2C10A2C9-2C8A2C13-6F79-A10-A141-2A10-2A7-3A10-3A5-4A10-4A3-5A10-5A2-5A10-4AC2-C4A10-5A2(2-CB3A10-3A2B)2(2-B4A10-4AB)3(2-5A10-5A)3(2-C4A10-4AC)3-D3A10-3AD5-D2A10-2AD7-2C10A2C10-2C6F2C76-2A10-2A7-2A12-2A6-F14-F5-2A14-2A4-BA14-AB4-BF14-FB4-BA14-AB4-2B2A10-2A2B4-2B2A10-2ABC3-5A10-3A2C2(2-5A10-5A)2-C4A10-5A2-C4A10-4AB-2C4A10-4A4B4A10-4A3B5A10-5ABD5A10-5A2D5A10-5ADC2(5A10-5A2C)5A10-5AC6A10-6A-5A10-5A3-4A10-4A5-2D12A2D8-DC3A2F3ACD12-C2A2F2AC54-A14-A6-A14-A5-5(2A14-2A4-)4A10-4A4-4A10-3AC3-5A10-3A2C-6A2(10-12A)10-5AC6A10-12A10-5AC6A10-6AB4(5A10-5A2B)5A10-5AB6A10-6A2B4A10-4A2B-B4A10-4AB3-4A10-4A5-B14AB7-6A2F6A10-D2CA2FA2CD53-A14-C6-A14-C5-CA14-2A4-2A14-AC4-CA14-AC4-2A14-2A4-2A14-AC4-4A10-4A3-5A10-5A2-5A10-5A-C5A10-6AC5A3(10-5AC6A)10-6AC5A10-6AB4(5A10-5A2B)5A10-5AB6A10-6A2B4A10-4A2B-B4A10-4AB2-B4A10-4AB3-AB14ABA6-C5A2F6A9-2ADCA2FACD2A14-C2FC34-A14-C6-A14-C5-CA4(14-2A4-2A)14-2A4-4A10-4A3-5A10-5A2-5A10-5A-6A2(10-12A)10-5A2C5A10-5AC6A10-5A2C5A2(10-12A)10-6AB5A10-5A2B2(5A10-5ABC)5A10-12A10-6A-C4A10-5A2-B4A10-4AB3-2B14A2B5-B14AB8-12A13-D4AD32-7(B16-B4-)4B10-4B3-5B10-5B2-5B10-5B-6B5(10-12B)10-7B5A10-5A7B2(10-12B)2(10-6BC5B)10-12B10-6B-5B10-5B2-5B10-5B3-6B6A6B5-5B6A5B8-3B6A3B12-B2C4AB31-7(B16-B4-)4B10-4B3-5B10-5B2-5B10-5B-6B5(10-12B)10-7B5A10-5A7B5(10-12B)10-6B-5B10-5B2-5B10-5B3-6B6A6B5-5B6A5B8-C2B6A3B12-B6AB31-3(B16-B4-)2(B16-C4-)2(B16-B4-)4B10-4B3-5B10-4BC2-5B10-5B-6B2(10-6BC5B)10-5BC6B2(10-12B)10-5BCB5A10-5A7B4(10-12B)10-5BC6B10-6B-5B10-5B2-5B10-5B3-6B6A6B5-5B6A5B8-3B6A3B12-B3A3CB31-2(A16-A4-)5(A16-C4-)4A10-4A3-C4A10-5A2-C4A10-5A-2C4A8(10-12A)2(10-5A2C5A)10-6AC5A10-12A10-6A-5A10-5A2-5A10-3A2C3-C16AC5-16A8-12A13-4A2C54-C16-A4-B16-C4-B16-B4-A16-A2(4-B16-B)4-2B2A10-2A2B3-3B2A10-2A3B2(2-2B3A10-3A2B)3(2-B4A10-4AB)-2B4(4A10-4A4B)4A10-4ABC6A10-5AC6A2(10-12A)10-5AC-5A10-5A2-5A10-5A3-A2B12A2BA6-B3D6A3DB9-4D4A4D14-C2AC187-2(2B2A10-2A2B4-)2(B3A10-3AB4-)4A10-4A4-3A12-3A3-B3A12-3AB-2B4(3A12-3A4B)3A12-3A2B5A2(12-10A)12-4A3C3A12-4AC-4A12-4A3-3A12-3A5-2B12A2B7-B3D6A3DB10-2D2C2A2C2D206-2(2B2A10-2A2B4-)3(4A10-4A4-)3A12-3A3-B3A12-3AB2-B3A12-3AB-2B3(3A12-3A4B)3A12-3A2B5A12-10A12-5A-4A12-4A2-C3A12-4A2-2B2A12-2A2B3-B2A12-2AB5-2BD10AD2B8-D2C6A2CD12-3C2F3C208-5(3B10-3B6-)7A2-7A4-B8A2-8AB2-B8A2-8AB-2B5(8A2-8A4B)8A2-8A2B-B8A2-8AB2-2B7A2-7A2B3-B2D5A2-5A2DB5-2D5A2-5A2D7-2D10A2D10-2C2F2A2F2C231-9(B10-)B9-2D4A2-4A2D5-A4D4A2-4A4DA10(2-9A)2(2-B8A2-8AB)2-B2D6A2-6A2DB3-2D6A2-6A2D5-2D5A2-5A2D7-DC4A2-4ACD9-CF8AFC13-FD2A2F233-3BAD2CDA3B10-BA3D2C3DAB10-B4D2C4DB10-BD8ADB10-B10AB9-2D4A2-4A2D8-2D4A2-4A2D5-2(D8A2-8AD2-)3(2D7A2-7A2D2-)2D7A2-7A2D3-D7A2-7AD4-2D6A2-6A2D5-DC5A2-5ACD7-2C4A2-4A2C9-C4A2-4AC12-2F2CA2DF320-2DA6CA2D2(10-D10CD)10-D10AD7-4(2D14A2D4-)D16AD4-D16AD5-2C12A2C6-2C12A2C7-C12AC9-C2F5A2CFC12-2FAFCA2F386-A10CA10-D4C2A4CD8-D2(4AC)4AD6-D14A2(D6-DC12AC)D6-2C12A2C7-C12AC8-C12AC9-2CA6FA2C11-CAFCF3CAC14-D2FDFC453-4CFDF5C10-AC2FAF3CFCA10-2CFCF2CFD3C10-2FDFAF3CDCF10-2CF2CACFC2FC10-2A2D2FCFC3A11-2FA2(DC)A2F13-5FD2F161-
