model
size = 32 5 32, scale = 0.05, origin = -y
material 
  colors = A:#FC3
voxels
76-8A24-8A25-6A57-8A24-8A25-6A56-10A20-14A18-5A4-5A18-14A49-16A15-5A8-5A14-3A12-3A14-18A17-12A17-18A13-3A3-8A3-3A12-2A6-4A6-2A12-20A14-5A6-5A14-7A6-7A11-3A-14A-3A10-2A3-12A3-2A10-10A2-10A2(12-3A)2(12-5A)9-3A-4A8-4A-3A8-2A3-3A8-3A3-2A8-2(7A10-)3A14-3A10-5A14-5A7-3A-3A12-3A-3A6-2A2-3A12-3A2-2A6-7A12-7A8-3A16-3A8-5A16-5A5-3A-3A14-3A-3A4-2A2-3A14-3A2-2A4-6A16-6A6-3A18-3A6-5A18-5A4-2A-3A16-3A-2A4-A3-2A16-2A3-A4-5A18-5A5-3A20-3A5-4A20-4A3-2A-3A18-3A-2(2A2-)2A18-2(2A2-)6A18-6A4-2A22-2A5-3A22-3A3-2A-2A20-2A-2A2-A2-2A20-2A2-A2-5A20-5A3-2A24-2A3-4A22-4A2-2A-2A20-2A-2A2-A2-2A20-2A2-A2-4A22-4A3-2A24-2A3-4A22-4A2(-2A)22-2A-4A2-A22-A2-2A-4A22-4A3-2A24-2A3-3A24-3A2(-2A)22-2A-4A2-A22-A2-7A22-5A2-A26-A3-3A24-3A2(-2A)22-2A-3A2-2A22-2A2-6A22-5A2(2-A26-A3-3A24-3A2(-2A)22-2A-3A2-2A22-2A2-5A24-4A)2-A26-A3-3A24-3A2(-2A)22-2A-3A2-2A22-2A2-6A22-5A2-A26-A3-3A24-3A2(-2A)22-2A-4A2-A22-A2-7A22-5A2-A26-A3-4A22-4A2(-2A)22-2A-4A2-A22-A2-2A-4A22-4A3-2A24-2A3-4A22-4A2-2A-2A20-2A-2A2-A2-2A20-2A2-A2-4A22-4A3-2A24-2A4-3A22-3A3-2A-2A20-2A-2A2-A2-2A20-2A2-A2-5A20-5A3-2A24-2A4-4A20-4A3-2A-3A18-3A-2(2A2-)2A18-2(2A2-)6A18-6A4-2A22-2A5-5A18-5A4-2A-3A16-3A-2A4-A3-2A16-2A3-A4-5A18-5A5-3A20-3A6-5A16-5A5-3A-3A14-3A-3A4-2A2-3A14-3A2-2A4-6A16-6A6-3A18-3A8-5A14-5A7-3A-3A12-3A-3A6-2A2-3A12-3A2-2A6-7A12-7A8-3A16-3A10-5A12-5A9-3A-4A8-4A-3A8-2A3-3A8-3A3-2A8-2(7A10-)3A14-3A12-7A6-7A11-3A-14A-3A10-2A3-12A3-2A10-10A2-10A2(12-3A)14-18A13-3A3-8A3-3A12-2A6-4A6-2A12-20A14-5A6-5A16-16A15-5A8-5A14-3A12-3A14-18A17-12A21-10A20-14A18-5A4-5A18-14A41-
