model
size = 29 32 23, scale = 0.05, origin = -y
material 
  colors = A:#EEE B:#FC3 C:#9CF
voxels
267-A2B24-3AB3A21-4A3BABA17-10ABA17-11B2A15-10B5A15-2B3-4B5A22-3B4A23-4B2A24-5B25-3B27-2B572-6A21-3A5B3A16-9AB3A15-10AB4A13-4A-12A12-2B3-12A12-B16A13-7B10A19-3B6A21-2B6A22-2B-3BA23-6B24-5B25-3B433-4A22-7A16-A-13A14-15A13-17A10-19A10-5A2-12A8-7A2-3A-8A8-6A5-2A-6A9-2B4A4-4A-4A10-B5A4-4A-4A10-8BA2-4A-3A18-2B2-7A19-2B-7A20-6B2A21-7BA22-3B-2B25-4B372-5A23-6A21-9A17-12A-2A13-16A12-10AC7A9-4A5-13A8-2A5-8A-4A9-2A4-9A-5A5-3A6-14A6-A2B5-14A16-13A7-B4-3B2-11A8-9BA-10A9-3B3-4B4A3-2A18-2B-3A-4A18-7B3A20-2(2B-)3A21-3B-3B24-5B27-2B312-4A24-7A20-9A19-11A16-13A-2A12-17A10-4A2-14A9-2(4A-17A7-)4A-18A4-25A5-B3A-19A5-B2A-2A2B15A5-2B-6B14A6-6B-5B11A7-3B5-5B8A17-6B6A17-6B-3A20-5B-3A20-7BA23-5B27-2B283-2A25-5A23-7A20-9A18-10A19-9A18-9A20-8A21-7A22-7A13-2A7-7A11-6A3-9A11-6A3-2B7A10-7A3-2B5A12-6A4-6B13-6A5-3B12-9A20-7A21-B7A19-3B6A19-4B5A20-6B3A22-5BA25-3B282-2A25-4A23-5A22-6A21-7A2(22-6A)23-5A24-4A25-2A48-3A3-2A20-5A2-2B20-5A2-B20-5A2(23-6A)3(22-6A)23-5A22-3B4A22-2BABA25-2(BA)26-2B334-3A24-5A23-5A24-4A25-3A135-4A25-2(4A24-)5A23-6A22-6A23-6A22-5A23-5A24-5A23-B4A24-B3A25-3B26-3B557-2B54-4A25-4A23-6A23-5A23-6A22-2(5A23-)6A23-B4A23-2(2B2A25-)2BA27-2B585-3A26-2(4A24-)3(5A23-)B5A23-B4A23-AB2A24-B4A23-2B3A24-2B2A26-3B614-3B25-2A26-4A24-3(5A23-)B4A23-AB4A23-5A23-2(B3A25-)B2A26-B2A614-A27-3A25-2(4A24-)B2(4A23-AB3A24-)AB2A24-2(BA)25-2(B2A26-)2A615-2A26-2(3A25-)4A24-B3A24-5A23-2(B3A24-A)BA25-B3A25-B2A26-3A614-2A26-4A24-B3A24-AB3A24-4A23-A2(B3A24-AB2A24-)B3A25-B2A26-3A26-2A616-2B25-3A25-B3A24-AB2A24-2(BA)24-AB3A23-B2(3A25-B3A24-)4A25-3A643-ABA26-ABA24-AB2A25-A-A24-A2(B3A24-3A25-)B2CA24-4A25-3A26-2A616-B27-ABA24-AB2A25-ABA2(25-B3A24-3A)25-B2CA24-4A25-3A26-3A643-AB27-2A25-ABA25-B3A24-4A24-B3A24-3A25-B2CA24-4A24-B3A25-3A26-2A616-AB27-AB25-ABA25-2(BA)24-3AB25-3A24-4A24-B3A25-3A24-2(B2A25-A)BA672-A27-BAB25-3AB24-B3A24-AB2A24-BA2(B26-2A)24-2(ABA26-)AB672-BA26-ABA25-BAB26-BAB24-BAB25-3A26-3A24-A27-2AB26-2AB728-BA27-BA52-2ABA26-AB82-2A728-AB28-BA52-2A27-2AB97-
