model
size = 29 32 23, scale = 0.05, origin = -y
material 
  colors = A:#EEE B:#FC3 C:#9CF
voxels
281-2BA24-3AB3A20-ABA3B4A19-AB10A16-2A11B15-5A10B14-5A4B3-2B15-4A3B22-2A4B23-5B25-3B26-2B580-6A20-3A5B3A18-3AB9A15-4AB10A13-12A-4A12-12A3-2B12-16AB11-10A7B13-6A3B20-6A2B21-A3B-2B22-6B23-5B25-3B430-4A25-7A20-13A-A14-15A13-17A12-19A10-12A2-5A10-8A-3A2-7A9-6A-2A5-6A10-4A-4A4-4A2B10-4A-4A4-5AB10-3A-4A2-A8B10-7A2-2B18-7A-2B20-2A6B21-A7B22-2B-3B23-4B373-5A24-6A22-9A17-2A-12A14-16A12-7AC10A9-13A5-4A8-4A-8A5-2A8-5A-9A4-2A9-14A6-3A7-14A5-2BA7-13A17-11A2-3B4-B8-10A-A9B9-2A3-4A4B3-3B10-4A-3A-2B19-3A7B19-3A2(-2B)21-3B-3B22-5B24-2B320-4A23-7A22-9A19-11A15-2A-13A13-17A11-14A2-2(4A7-17A-)4A6-18A-4A6-25A4-19A-3AB6-15A2B2A-2AB7-14A6B-2B6-11A5B-6B7-8A5B5-3B8-6A2(6B19-3A-)5B21-A7B22-5B24-2B293-2A26-5A23-7A22-9A21-10A20-9A22-9A21-8A22-7A7-2A13-2(7A5-6A11-)9A3-7A10-7A2B4-6A12-5A2B4-6A13-6B4-9A12-3B7-7A22-7AB22-6A3B21-5A4B20-3A6B21-A5B24-3B293-2A27-4A26-5A25-6A24-7A23-2(6A24-)5A25-4A27-2A5-3A25-5A20-2A2-5A20-2B3-5A20-B3-6A23-4(6A24-)5A24-4A3B24-ABA2B24-2(AB)26-2B357-3A26-2(5A25-)4A26-3A90-4A25-4A26-4A25-5A2(24-6A)23-6A2(25-5A)24-5A25-4AB25-3AB2(26-3B)540-2B56-2(4A25-)6A24-5A24-6A2(25-5A)24-6A24-4AB26-2A2B25-2A2B26-A2B26-2B570-3A25-4A26-4A3(25-5A)24-5AB24-4AB26-2ABA25-4AB25-3A2B25-2A2B25-3B598-3B28-2A26-4A3(25-5A)25-4AB24-4ABA24-5A26-3AB25-3A2(B26-2A)B600-A27-3A2(26-4A)25-4AB25-3ABA25-4A26-3ABA25-2ABA26-2(AB)2(26-2AB)27-2A599-2A2(27-3A)26-4A26-3AB25-5A26-3AB25-3ABA26-ABA26-3AB26-2AB26-3A599-2A26-4A26-3AB25-3ABA25-4A26-3ABA25-2(2ABA26-3AB26-)2AB26-3A27-2A598-2B28-3A26-3AB26-2ABA26-2(AB)25-3ABA26-3AB25-3AB27-3A26-3AB26-4A26-3A627-ABA26-ABA27-2ABA26-A-A26-3ABA2(26-3A)B27-3A26-A2CB26-4A26-3A27-2A599-B27-ABA27-2ABA26-ABA2(26-3AB27-3A)26-A2CB26-4A2(26-3A)628-BA27-2A28-ABA26-3AB26-4A26-3AB27-3A26-A2CB26-4A26-3AB26-3A27-2A598-BA27-BA28-ABA26-2(AB)26-B3A26-3A27-4A26-3AB26-3A28-2AB26-2ABA26-ABA658-A27-BAB26-B3A26-3AB26-2ABA27-BAB26-B2A27-2A29-ABA26-ABA27-BA658-AB27-ABA27-BAB26-BAB28-BAB27-3A26-3A30-A27-B2A26-B2A717-AB27-AB58-AB2A26-BA88-2A718-BA26-AB60-2A26-B2A103-
