model
size = 25 25 3, scale = 0.05, origin = -y
material 
  colors = A:#FC9 B:#E00 C:#D00
voxels
9-7A16-11A12-15A9-17A7-19A5-21A4-21A3-23A2-23A2(-87A)-23A2-23A3-21A4-21A5-19A7-17A9-15A12-11A16-7A116-B10-B13-B9-2B13-B2-9B2(13-B2-2(B3-)B)13-B2-B-5B-B13-B2-2(B3-)B9-2B2(2-B)2(3-B)10-2B-B2-10B10-5B21-3B2-7B14-B3-B5-B11-4B3-B5-B14-2B2-7B39-B3-7B13-B225-C10-C13-C9-2C13-C2-9C2(13-C2-2(C3-)C)13-C2-C-5C-C13-C2-2(C3-)C9-2C2(2-C)2(3-C)10-2C-C2-10C10-5C21-3C2-7C14-C3-C5-C11-4C3-C5-C14-2C2-7C39-C3-7C13-C118-
