model
size = 25 28 25, scale = 0.05, origin = -y
material 
  colors = A:#111 B:#FC3 C:#0F6
voxels
236-3A21-5A19-2(7A18-)7A19-5A21-3A495-7A17-9A15-6(11A14-)11A15-9A17-7A394-5A18-9A15-11A13-13A12-13A11-4(15A10-)15A11-13A12-13A13-11A15-9A18-5A319-7A16-11A13-13A11-15A10-15A9-6(17A8-)17A9-15A10-15A11-13A13-11A16-7A268-7A16-11A13-13A11-15A9-17A8-17A7-6(19A6-)19A7-17A8-17A9-15A11-13A13-11A16-7A219-5A17-11A13-13A11-15A9-17A7-2(19A6-)19A5-4(21A4-)21A5-2(19A6-)19A7-17A9-15A11-13A13-11A17-5A193-9A14-13A11-15A9-17A7-19A6-19A5-8(21A4-)21A5-19A6-19A7-17A9-15A11-13A14-9A167-7A16-11A12-15A9-17A7-19A6-19A5-21A4-21A3-6(23A2-)23A3-21A4-21A5-19A6-19A7-17A9-15A12-11A16-7A142-9A14-13A11-15A9-17A7-19A5-21A4-21A3-8(23A2-)23A3-21A4-21A5-19A7-17A9-15A11-13A14-9A119-3A18-11A13-13A10-17A7-19A6-19A5-21A3-3(23A2-)23A-75A-3(23A2-)23A3-21A5-19A6-19A7-17A10-13A13-11A18-3A96-5A17-11A12-15A9-17A7-19A5-21A4-21A3-2(23A2-)23A-125A-2(23A2-)23A3-21A4-21A5-19A7-17A9-15A12-11A17-5A94-7A16-11A12-15A9-17A7-19A5-21A4-21A3-23A2-23A-175A-23A2-23A3-21A4-21A5-19A7-17A9-15A12-11A16-7A93-7A16-5AC5A12-7AC7A9-8AC8A7-9AC9A5-10AC10A4-10AC10A3-11AC11A2-11AC11A-12A2(C24A)C112A-23A2-23A3-21A4-21A5-19A7-17A9-15A12-11A16-7A93-7A16-11A12-15A9-17A7-19A5-21A4-21A3-23A2-23A-175A-23A2-23A3-21A4-21A5-19A7-17A9-15A12-11A16-7A94-5A17-11A12-15A9-17A7-19A5-21A4-21A3-2(23A2-)23A-125A-2(23A2-)23A3-21A4-21A5-19A7-17A9-15A12-11A17-5A96-3A18-11A13-13A10-17A7-19A6-19A5-21A3-3(23A2-)23A-75A-3(23A2-)23A3-21A5-19A6-19A7-17A10-13A13-11A18-3A119-9A14-13A11-15A9-17A7-19A5-21A4-21A3-8(23A2-)23A3-21A4-21A5-19A7-17A9-15A11-13A14-9A142-7A16-11A12-15A9-17A7-19A6-19A5-21A4-21A3-6(23A2-)23A3-21A4-21A5-19A6-19A7-17A9-15A12-11A16-7A167-9A14-13A11-15A9-17A7-19A6-19A5-8(21A4-)21A5-19A6-19A7-17A9-15A11-13A14-9A193-5A17-11A13-13A11-15A9-17A7-2(19A6-)19A5-4(21A4-)21A5-2(19A6-)19A7-17A9-15A11-13A13-11A17-5A219-7A16-11A13-13A11-15A9-17A8-17A7-6(19A6-)19A7-17A8-17A9-15A11-13A13-11A16-7A268-7A16-11A13-13A11-15A10-15A9-6(17A8-)17A9-15A10-15A11-13A13-11A16-7A-2(B20-2(B-))B20-5B22-2(B24-)B23-3B143-5A18-9A15-11A13-13A12-13A11-4(15A10-)15A11-13A12-13A13-11A15-9A18-5A394-7A17-9A15-6(11A14-)11A15-9A17-7A495-3A21-5A19-2(7A18-)7A19-5A21-3A311-
