model
size = 31 27 15, scale = 0.05, origin = -y
material 
  colors = A:#E0BEA5 B:#946A6A C:#FDEFDA D:#FFF E:#887C7C F:#FCE0B6 G:#774949 H:#553E3E
voxels
813-DF674-2DC161-B2D643-3F25-AC-F2E29-E42-FB26-DFB25-ADBC25-3CE642-3ADB26-C2AEB12-2DBE11-CE10-3F3B24-B2A2B25-FC-E24-CBC572-E29-DE28-BE27-3BE8-3A2-FD2A7-2ECBE9-4C11-4CE23-A3C2A25-2CA568-2D27-DE-AB-2A22-EDA22-DB4-EAB18-2D4B5-B14-F2A6B20-BF3A2B26-3E-E631-AE2-B2-2D21-EAH2-C-D3A16-4D2AB4-2E16-2D6B18-4AD2AB19-F2AB5AB21-C4A2BA24-AE-A569-D29-3B28-BAH4-B2A2D17-2BAG5-2C3AB13-2AD3GB7-D2C13-AC2B23-2A4C21-2AB4CA23-4C28-A539-2BE27-BDAH22-A2E-2B2AH17-2D3CE5-BG9-D-BF2D-BAB10-G8-2CADBFAB-3B5-ACG15-2B2E8-C301-DF29-CF2D96-D133-2D25-FE29-BFG27-2BA2G22-5B2AH19-2D2B2A3E3G16-2F5ACE18-3D-B3AFCE19-DCDA-BACB25-E-A341-2CD28-3FA29-B2-A29-BAD28-2B2D29-B2D31-C7-D29-DAE-AD18-EFC25-F3DBAE28-BAG28-2BG20-2ACBC2DE19-B4C4DA21-B3D2C24-DB2C373-A30-CA32-A29-FC30-2CA29-BCA28-3BA10-AD26-A2-2ADF12-AC2EFC9-4E-2F2B5A2D3F2ACE21-B-2B3-3B52-2C655-C12-A2F16-B10-4C2-2FB-4D3C2-2C11-2AC-F2AFD5A4C2F16-2B-4BABAE23-4C737-BAB2C2A23-F3C3A3C24-B2A2D802-3C28-2C480-
