model
size = 31 25 15, scale = 0.05, origin = -y
material 
  colors = A:#FDEFDA B:#E0BEA5 C:#946A6A D:#FFF E:#887C7C F:#FCE0B6 G:#774949 H:#553E3E
voxels
720-D31-D743-F30-A-AD520-D30-2A30-BA30-F103-AC21-2D-D-2AC24-D2ACA578-ABE29-2B2A29-EA12-4A23-4A2C24-A2B2C25-2A-E24-3A329-2AE29-2D147-E29-DE28-CE27-A2CE8-3B2-F3A7-2E2AE10-3A11-4AE23-B3A2B25-2AB418-D-A2(30-2A)50-DE28-EDB22-AC4-EBC18-4A2C5-C14-FB3A4C20-CF3B2C26-3E-E516-B30-2F20-BE9-EA17-EBH24-3AD2BC22-AD6C18-4BA2BC19-F2BC5BC21-A4B2CB24-BE-B507-D29-3C28-CBH8-FA16-2ABG10-C13-ABD3GC23-BA2C23-2B4A21-2BC4AB23-4A28-B477-2CE27-CDBH22-2AE-2C2BH17-4A2E5-CG12-F2D-2AC10-G11-DCFBC-3C5-2EG16-C2E8-A270-2A2D96-D133-2D25-FE29-CFG27-2CB2G22-3A2C2BH19-D3A2B3E3G16-2F5BAE18-3D-C3BFAE20-ADB-CBAC25-E-B278-F2AD28-2AFB29-A2-B29-CBD28-2C2D29-C2D31-A7-DF28-DBE-BA18-EFA25-F3DCBE28-CBG28-2CG20-B2ACA2DE19-C4A4DB21-C3D2A24-DC2A311-B30-AB32-B29-FA30-2AB29-CAB28-3CB11-D26-BF-2BDF12-BA2EFA9-3AE-6A3B2D3F2BAE21-C-2C3-3C52-2A593-A31-C10-4A2-2FC-4D3A2-2A11-2BA-A2BFD5B4A2F16-2A-4CBCBE23-4A675-CBC2A2B23-4A3B3A24-A2B2D740-3A28-2A449-
