model
size = 31 32 18, scale = 0.05, origin = -y
material 
  colors = A:#FCE0B6 B:#FFF C:#E0BEA5 D:#FDEFDA E:#946A6A F:#887C7C G:#553E3E
voxels
468-B29-B25-D4-B30-B880-2B153-2B680-3B120-3B28-4B150-5B617-A29-3B28-4B87-D6B24-D7B24-2D4B87-3B2-B24-D6B24-7B185-2B147-5B27-4B215-A29-2(3A28-)4A26-D4A26-6A24-D7A23-8A22-2D6AB22-4D3A3B21-2D7AB22-D6A21-3D10A17-D2AD7A4B17-DA12B17-3D8-A2B54-3B25-6B-B23-8B29-B86-2B2-3B23-2A5B-B23-BA5B240-A2-3A2-2C20-2A2-G2A2-AC20-AD2-3AC2-C23-D4AC24-E5AC23-E7AC22-D9A21-10A20-11A18-B-11A-A15-BAB14A14-18A13-16A2B13-AD14A2B13-BD2AD-5AB-3AB15-3D9-A3B20-6B23-2A6B2A20-2BA5B2AB21-B31-A5-3B22-2A4BAB22-3A4B2A23-A-4B2A22-B3A-2A2B56-C29-5C25-E6C24-E2C-4C22-CE6-C22-C7-2C19-2C2A6-2AC18-C2AD6-2A2C16-C2AD2-3A2-2A3C15-CA2D-5A2-4C15-2A3-6A2-A2C15-2A2-8A-A2C14-13A-2AC13-4A-13AB12-D14A-3AB10-D2B18A10-2B6A2-A3-8A9-2B6A2-A3-3A-4A9-2B2A3-2A-A2-3A2-2ABA9-2B2A2-9A2-3AB10-2B5AD11A2B11-2B3A-7A-D2A3B12-2BA2-7B3-B19-3A3B4A21-4AB-2ADA21-4A-3A24-3A2-4A21-9A22-9A23-7A24-6A2B56-C29-4AC26-4AC25-E2A-DAC24-E6-C30-C20-3AE6-CAC18-C3A6-3AC16-C3A2-3D2-C3AC15-C2AD-2D3E2-C2AC15-2A3-2D2F2D2-C2A15-2A2-E6FG-3A14-4AE2FAEBE2F-3A13-4A-2F5AE2F4A12-4AF10A-3AB10-5AE15A10-5AE2A2-A3-8A9-B7A2-A3-3A-4A9-B3A3-2A-A2(2-3A)B9-B3A2-9A2-3AB10-D20A11-D4A-7A-D3A2B12-B2A2-7B3-AB19-2A3B4A21-4AB-2ADA21-4A-3A24-3A2-4A21-9A22-9A23-B6A24-B2A2-3A25-C28-E2A5C22-2E5A3C23-E3AC20-C5-EAD3A19-E5-EC2-2F3-3(C15-)C2-C9-3A14-2CA-AC6-C-2AC14-C2A-C7-C4A13-2C3AD8-C4A12-2C3A10-C4A10-2C4A10-C4A10-B4AE9-E3AB2A8-B5AE2-G2EFE3-F3AB2A7-6A-2FA3B4FE4ABA7-B4AF-9AFE4A2B7-B3A-A-9A2FA-3AB7-B2A2-4A2-A3-3A2-3AB7-B2A3-6A-4A3-4A7-B2A4-9A4-2A2B7-D3A2-12A2-2AB9-D5A-7A-D4AB11-4B11-2A3B18-7A24-6AF22-2A3FA2F25-6AD22-9A23-8A23-7A24-B2A2-2A24-CAC-2CA23-E7AC21-4E-3ACEC18-BC4-2F2A3-C16-E7-3F4-2C14-E14-A2(C14-)2AC13-BA13-2AC12-C2A-A2C6-2A-2A2C10-E3A-AC7-C2A-2AC10-E2A2-A9-CA-4A8-2C2A-A11-C-4A7-AC3A-A11-C2-3AB6-2B3A-AE10-C2-3A2B4-AB3A2-E11-CA2-3AB4-4A2-AE12-E2-3AB4-3A3-AC-EA2B2AB2F2-E3-3A4-ABA3-AC-EB5ABF2-F3-3A4-2BA4-11AB2A4-AB4-2BA4-14A3-2AB5-BA4-13A4-3A5-D2A3-2AB2A5-3A4-AB7-D6A-7A2D5A2B7-5BA2-7A2-2(BA)2B17-6A25-4A3F23-A34-EAD24-7A24-A6-A23-2(A2-)A24-B2A2-2A23-C8A21-E9AC19-EAF3-2A3-AC17-EAF-FE2-FA3-AC15-E2C7-A3-2(EAC13-)2AC13-2C13-2AC12-E2A13-2AC11-E2A-A10-3A-2A10-EA-2A2C8-3A-3A8-C2A-2AC9-C3A-2AB6-C2A2-AC11-C2A-2AB5-4A2-AC12-2A2-3A4-3A3-AE11-E2A2(2-4A)3-AE12-2(EA3-2AB2-3A3-AE13-)EA4-AB2-3A3-2A4-2BDFB4-EA4-AB2-3A3-2A2EA2B3FA2B-2FA4-AB2-B2A4-3AB2FA-3A3B2A4-AB3-2A4-2ABAF8AB2A3-2AB3-D2A2-3A2B12A3-AB5-3A-2A2B-7AD2B2A-3AB6-2B4A2-6AD3-2B2A2B9-B6-6A5-2B18-5A2D59-EA24-7A24-A6-A23-A5-2A23-B6A23-4A-5A20-E2A-AG2A2-A19-EA3-AEAC3-C18-C-3F2E2A2C-AC16-A13-A14-C2A14-C12-C3A12-A-2AC10-E2A14-3AC10-EA-A12-F2A-AC8-C5A11-AF2A-C7-CA-2ACA12-F4AC6-C2-3A13-FE2A-AC4-2A2-2AC13-FEA3-AC2-3A3-AC13-2CA3-AC2-2A3-2AC13-ECA4-B2-2A3-A2C14-CA4-AB-A4-AC15-CA5-B2(-A4-ACE14-CA4-2A)-A4-2AE13-ACA4-A2-BA3-4A3-A5F3-4A2(3-B)A2-3AB2-B6A3-B3A2-AB3-D6A3-8A2-2B4AB5-2B2A2B3-F5AD4-2B2AB8-A7-E5A6-2B17-5AD62-D23-2A4-D24-A5-AD23-A5-2A23-B-3ADA23-4A-D4A20-E2A-A2(-2A)19-EA-3A-2AC2-A18-C-A2DE-3ED-2A16-C-C9-E-A14-C2AC11-E-C12-C3AC11-EA-C11-C4A12-EA-C9-C4AC12-4AC8-C3AC14-4AC6-C3AC15-E5A4-C5A16-E4A3-2A-4A16-E2A-2A2-A3-2AC16-3A2-2A-A3-2AC16-2A2(4-B2A3-2A17-CA)4-3A3-2A17-3A3-3A2-3A17-3A3-A-A2-4A16-3A3-B-A2-4A16-3A2-AB-2A-4A4-B5AD5-5AB3-6A4-7A5-5A5-4A5-AF5A5-5B20-D24-AE4-D24-A36-A24-2A4-D24-2A4-A24-A5-A24-B2-AD-F23-4A-D4A20-C2A-A2(-2A)19-EA-3A-D2A2-A18-C-2ADE-E2DA-2A16-C-CDC6-ED-C14-C3A11-A-C12-C4A11-EA-A11-C4A12-2A-A9-C4AC12-E4A8-C3AC14-D4A6-5A15-E5A4-5AC16-E4A3-2A-3AC16-E2A-2A2-A3-3A16-E2A2-2A-A3-2AC16-EA4-3A3-2A17-EA4-B2A3-AC17-CA4-3A3-AC17-C2A3-3A2-2AC17-C2A3-B-A2-2A2C16-3A3-A-A2-2ADC16-3A2-AB2(-2A)DA4-B5AD5-5AB3-5AD4-7A5-AB3A5-2A2B5-A-5A5-2B2AB20-E24-AE4-D24-A36-D24-CA4-D24-2A4-D24-A5-A24-A2-2D25-4A2-E3A20-C4A-E5A18-C4AD-G5A18-C2AGD3-DBD3A16-C2AD8-D2A15-3AD10-3A13-C2AD11-E3A12-CA2D12-DB2A10-CBA15-D2B9-CBDA16-DBA7-2AB2D17-DBA5-GABAD18-5A2-5AD18-AD9ADA18-7A2-2AG19-E2A2-BA3(2-3A19-E3A-2A)-3AD19-4A-B5AD19-4A-A-3A2D19-AG3AD-3ABD19-AG2AD3-2ABD6-6AD7-4D4-AB7-2C5A7-2D17-CF2A25-AE2A-2D24-C62-C4AD24-6AD24-7A26-4F24-3A3-E2A21-C3AE2-E3A20-2ADE3-2E3A18-CAG8-D2A16-2AB10-2A16-AB11-B2A14-AB13-2B13-GB16-B44-D30-D19-B6-G-B20-BA4-AG2AD21-B2A-5A21-D8AG21-4AB4AG2(21-AD6A2D)21-4AD3A2D22-3AD-2A2D22-2(AD)-B2A23-B2D3-2B23-2D5-B8-6AD9-D16-CF3A28-FE25-CE3A2D25-CF2A29-2E28-3AD26-A2C3D24-2CABCBD85-C2E4-DA21-2E7-BA19-AE9-BA18-B11-BA16-A13-B108-D81-B7-B22-2B3-A2BG22-B2A2-2BA23-BAD2-2BD24-3D-BA25-DAD-BA24-3A2-BA25-DA2-BA26-A2-2BD72-A3D27-C2(AD)56-EA2DG27-2D60-C2D513-G24-B5-2B24-D3-2B22-A2D4-B25-D3-2B25-GB3-B25-GB2-2B26-B3-B369-
