model
size = 31 15 32, scale = 0.05, origin = -y
material 
  colors = A:#E2E2E2 B:#E3E3E3 C:#030303 D:#060606 E:#BABABA F:#090909 G:#040404 H:#080808
voxels
-E103-B5-B24-B5-B291-E29-E201-2A26-7A24-8A24-6A335-5A24-10A20-12A19-4A4-4A20-10A23-6A302-10A19-2B3A3-5A2(B17-B2A8-2A)B17-B4A4-4A20-9A271-8A20-2B10A2B16-3BA8-2A2B15-2B12-2B15-2B11-A2B15-2B2A7-3AB18-11A268-B10AB17-3B2A6-2A3B14-A2B12-2B14-AB14-BA13-AB13-2B15-2BA9-AC2B17-12A238-8A20-2B10A2B15-A3B10-3B14-AB14-BA13-A15-BA13-AB14-BA14-2BA10-C2B17-12A236-B10A18-3B2A6-2A3B14-A2B12-2BA13-A15-BA13-A16-A13-AB14-BA14-2BA10-C2B17-12A209-3A23-2B10AB17-3B9-A3B14-AB14-B2(A12-BA16-)A13-AB14-BA14-2BA10-C2B17-12A207-8A20-2B4A-5A2B15-A2B11-3B14-AB14-B2(A12-BA16-)A13-AB14-BA14-2BA9-AC2B17-12A206-10A18-3B2A6-2A2B15-A2B12-2B14-A15-B2(A13-A16-)A13-AB13-2BA14-2E2A8-A3E17-2E8AE206-B10AB17-3BA8-A3B14-AB13-2BA13-A15-BA13-A16-A13-A15-CA13-E2C12-C2E14-E2C2A6-2ACE15-4G2E6A2E4G13-4G10-4G14-3G10-3G114-4A23-B10AB17-2BC10-3A14-AB14-2A13-A15-2A13-A16-A13-AC14-BE13-E2C11-2AE15-E3C2A4-2AC4D12-5DC2E4A2E5CD11-3D-2D8-DC-2CD12-5D8-D3CD14-3D10-3D81-8A20-2B4A2-5A17-2BC10-3A14-AB2(14-A)15-AB13-A15-AB13-EC14-AE14-E2C10-2AE14-D13C4D11-2D2C2-2CE4AE3C2-C2D10-DC3-2D6-2D3-CD12-5D8-D3CD14-3D10-3D16-D12-D50-9A20-2B2A6-4A16-2B11-3A14-A2(B2(14-A))C14-A14-E2C12-AE15-E3C8-C2AE14-D13C4D12-DCD-DC2E4A2E2D-3D11-3D2-D8-2D2-2D12-5D8-5D14-3D10-3D80-10A19-ABA7-4A16-2A12-2A15-A13-2A15-A14-A15-A13-2A15-EA11-3A16-E3C6-2CAE16-3F10C3F14-D3FDE6AED3FD13-D3FD8-D3FD14-3H10-3H111-10A19-ABA8-3A16-2A12-A16-2(A13-2A15-)2A12-2A15-2AC10-2A17-2EB2C3-3CBE20-E8CE18-3F-E6AE-3F15-3F10-3F114-3A24-B10A19-ABA8-3A16-2A11-2A2(16-2A12-A)16-2A11-2A17-A2C8-C2A18-2B8CBA20-B8AB22-8A148-5A23-B4A-5A19-AC9-2A18-A11-2A2(17-A12-A)17-2A10-2A17-2A2C6-2CA20-B8CB22-8A179-6A22-4A3-4A19-2A9-2A18-2A10-2A17-A11-2A17-2A10-2A17-2A9-C2A18-A3C4-3CA20-B8AB22-8A179-6A22-4A3-4A20-2A8-2A3(18-2A10-A)19-AC7-C2A19-A9CA21-B8AB22-8A179-6A23-3A4-3A20-2A8-2A2(19-A9-CA)19-AC8-2A19-A2C5-C3A20-9A16-2B6-6A211-6A23-3A4-3A20-2A7-2A20-2(AC8-CA19-)AC7-CA18-2B2A3C-3C2A15-5B2-7A2-3B12-3B5-6A3-4B9-2B17-3B9-B163-6A23-3A-A-3A22-2A2-A3-2A21-AC2-A3-CA21-AC6-CA20-A3C4-C2A20-12A16-B2-B3-3A3-2(3B30-)3B8-B20-2B8-B21-2B6-2B21-2B78-2A-2A25-3A-4A23-A2CBC-CA22-A3CB3CA22-AC5-CA21-2A2(3CA)21-11A2(32-B)72-B29-B23-B109-2A-3A24-A2B-3B24-3B-4B23-3BA4B23-B5AB27-A173-B23-B169-2B5-2B23-B5-2B231-B23-B140-2B-3B22-4B3-4B21-2B5-2B230-2B23-2B144-B22-3B5-3B21-2B5-2B230-B24-3B137-3B-3B22-4B3-3B22-B7-B229-2B25-2B2-B27-B105-2(2B5-2B22-)B7-B257-B-2B27-2B105-3B-3B23-3B3-3B290-EB27-B2E29-E
