model
size = 31 15 32, scale = 0.05, origin = -y
material 
  colors = A:#F30 B:#F33 C:#444 D:#888 E:#DDD F:#555 G:#BBB
voxels
-A103-B5-B24-B5-B291-A29-A201-2A26-7A24-8A24-6A335-5A24-10A20-12A19-4A4-4A20-10A23-6A302-10A19-2B3A3-5A2(B17-B2A8-2A)B17-B4A4-4A20-9A271-8A20-2B10A2B16-3BA8-2A2B15-2B12-2B15-2B11-A2B15-2B2A7-3AB18-11A268-B10AB17-3B2A6-2A3B14-A2B12-2B14-AB14-BA13-AB13-2B15-2BA9-AC2B17-12A238-8A20-2B10A2B15-A3B10-3B14-AB14-BA13-A15-BA13-AB14-BA14-2BA10-C2B17-12A236-B10A18-3B2A6-2A3B14-A2B12-2BA13-A15-BA13-A16-A13-AB14-BA14-2BA10-C2B17-12A209-3A23-2B10AB17-3B9-A3B14-AB14-B2(A12-BA16-)A13-AB14-BA14-2BA10-C2B17-12A207-8A20-2B4A-5A2B15-A2B11-3B14-AB14-B2(A12-BA16-)A13-AB14-BA14-2BA9-AC2B17-12A206-10A18-3B2A6-2A2B15-A2B12-2B14-A15-B2(A13-A16-)A13-AB13-2BA14-2B2A8-2A2B17-11A206-B10AB17-3BA8-A3B14-AB13-2BA13-A15-BA13-A16-A13-A15-CA13-A2C12-C2A14-B2C2A6-2ACA15-4F10A4F13-4F10-4F14-3F10-3F114-4A23-B10AB17-2BC10-3A14-AB14-2A13-A15-2A13-A16-A13-AC14-2B13-A2C11-2AB15-B3C2A4-2AC4D12-5DC8A5CD11-3D-2D8-DC-2CD12-5D8-D3CD14-3D10-3D81-8A20-2B4A2-5A17-2BC10-3A14-AB2(14-A)2(15-AB13-A)C14-AB14-B2C10-3A14-D13C4D11-2D2C2-2C6A3C2-C2D10-DC3-2D6-2D3-CD12-5D8-D3CD14-3D10-3D16-D12-D50-9A20-2B2A6-4A16-2B11-3A14-A2(B2(14-A))C2(14-A)2C12-2A15-B3C8-C3A14-D13C4D12-DCD-DC8A2D-3D11-3D2-D8-2D2-2D12-5D8-5D14-3D10-3D80-10A19-ABA7-4A16-2A12-2A15-A13-2A15-A14-A15-A13-2A15-2A11-3A16-B3C6-2C2A16-3E10C3E14-D3ED8AD3ED13-D3ED8-D3ED14-3G10-3G111-10A19-ABA8-3A16-2A12-A16-2(A13-2A15-)2A12-2A15-2AC10-2A17-3B2C3-3CBA20-B8CB18-3E-8A-3E15-3E10-3E114-3A24-B10A19-ABA8-3A16-2A11-2A2(16-2A12-A)16-2A11-2A17-A2C8-C2A18-2B8CBA20-B8AB22-8A148-5A23-B4A-5A19-AC9-2A18-A11-2A2(17-A12-A)17-2A10-2A17-2A2C6-2CA20-B8CB22-8A179-6A22-4A3-4A19-2A9-2A18-2A10-2A17-A11-2A17-2A10-2A17-2A9-C2A18-A3C4-3CA20-B8AB22-8A179-6A22-4A3-4A20-2A8-2A3(18-2A10-A)19-AC7-C2A19-A9CA21-B8AB22-8A179-6A23-3A4-3A20-2A8-2A2(19-A9-CA)19-AC8-2A19-A2C5-C3A20-9A16-2B6-6A211-6A23-3A4-3A20-2A7-2A20-2(AC8-CA19-)AC7-CA18-2B2A3C-3C2A15-5B2-7A2-3B12-3B5-6A3-4B9-2B17-3B9-B163-6A23-3A-A-3A22-2A2-A3-2A21-AC2-A3-CA21-AC6-CA20-A3C4-C2A20-12A16-B2-B3-3A3-2(3B30-)3B8-B20-2B8-B21-2B6-2B21-2B78-2A-2A25-3A-4A23-A2CBC-CA22-A3CB3CA22-AC5-CA21-2A2(3CA)21-11A2(32-B)72-B29-B23-B109-2A-3A24-A2B-3B24-3B-4B23-3BA4B23-B5AB27-A173-B23-B169-2B5-2B23-B5-2B231-B23-B140-BA-A2B22-4B3-4B21-2B5-2B230-2B23-2B144-B22-3B5-3B21-2B5-2B230-B24-3B137-2BA-A2B22-4B3-3B22-B7-B229-2B25-2B2-B27-B105-2(2B5-2B22-)B7-B257-B-2B27-2B105-2BA-A2B23-3B3-3B290-AB27-B2A29-A
