model
size = 23 32 31, scale = 0.05, origin = -y
material 
  colors = A:#FDEFDA B:#FFF C:#F63C9E D:#887C7C E:#FCE0B6 F:#101111 G:#946A6A H:#553E3E I:#2A0E0E J:#100 K:#FF9D9D L:#774949 M:#FBD091 N:#F9C16D O:#B76907 P:#784204 Q:#411101 R:#2B0500 S:#200000 T:#360B01
voxels
203-3E40-E2-3E16-7EJ15-7EA14-7E2A13-6E4A13-3E7A13-2E8A12-3E6AIA12-3E6A2I13-E8AI13-2(10A12-E)10A12-11A12-7AD3A12-5A2D4A14-2AD3I3A15-2DI4AI17-I4AI18-4AI226-A-D19-4E17-D-2E18-7E16-8E14-8EA14-7E2A13-6E4A12-4E7A3(12-3E8A)12-2E9A12-E10A11-EM10A11-E11A11-M2(11A12-)11A13-10A14-9A16-I6A17-6A200-D2-3D15-2GD-D2AD15-3D-4A16-DAD4EA14-2EA5EA14-8EA14-7E2A14-5E4A13-3E7A2(12-3E8A)12-M2E8A12-ME9A11-3E9A10-4E9A10-3E9A3(C10-12A)2(C11-11A)C11-12A12-DADI7A11-D-D2I7A14-2I4DADA9-2D3-DI7D111-D22-2D16-3G2D2AD15-3GD4AD12-4GAD5A2(13-D9A)2(14-2E7A)13-3E7A11-A2E9A2(11-3E8AC)11-2ME8AC11-M2E2(8AC10-4E)8AC10-3E9A2(C9-13A)C7-A-13AC10-8A5C11-7A5C11-10A2C11-D9A2C11-2DAD8A8-D-2DI6D4A8-3DI8DA2D112-2D15-3G-5D14-3GD3A2D13-4G6A12-4G7A12-G2(10A13-)E9A13-2E8A8-2(E-)3E8A8-A6E7AC9-A4E8A2(C10-3E9A)3(C10-4E8A)C10-3E9AC9-13AC8-14AC8-10A5C2(7-9A7C)7-10A6C8-9A6C8-2A2D9A2C8-6D9A8-7D8A90-D16-G-D-4D14-3G6D13-4G5AD11-6G6A12-4G7A9-A-2G10A9-14A8-A3-2E9A7-A2-5E8A2(7-8E7AC)8-6E8AC8-A3(4E9AC9-)4E9AC10-3E9AC10-2E10AC9-D12AC8-14AC7-9A7C7-6A10C7-I5A10C6-I7A9C5-I-7A9C8-9A6C8-15A7-AD14A64-D3-L14-3G4DLH14-3G4D2A14-3G2AD3A14-3G6A11-5G7A11-4G8A9-A3G10A8-15A7-2A5E9A7-A7E7AC6-9E7AC6-A8E7AC7-A6E8AC8-5E9A2(C8-A3E10A)C8-D2(3E10AC9-)D12A2(C9-13A)C6-7A10C2(6-5A12C)5-8A10C4-9A10C4-AI8A9C5-18A6-17A61-G-2DL-LH14-3G3DL2A14-3G3D3A14-3G6A13-4G6A11-5G7A10-3G10A9-D13A8-15A7-2A4E9AC6-EA6E8AC6-8E8AC6-A7E8AC7-6E9AC8-4E10A2(C8-14A)C7-15AC8-14A2(C9-13A)C8-14AC6-5A12C6-4A13C5-5A13C2(4-8A11C)4-9A10C2(4-18AC)19-3H20-L3H16-2DL2H2A14-2G2D5A13-4G6A12-5G6A10-HD5G6A10-D2A3G7A10-D12A9-D13A8-14AC6-16AC5-2E2A4E9AC6-EA5E9AC6-2A5E9AC7-A3E11AC7-15A2(C8-14A)C7-15A4(C6-16A)C5-6A12C2(4-6A13C)3-8A12C4-7A12C4-8A11C2(4-18AC)19-4H16-D-L4H16-2D2H3A13-H4D5A2(12-D3G7A)11-DA3G7A9-2D12A9-D13A9-D12AC4-18AC5-E16AC4-2E16A2(C5-17A)C6-16AC7-15A2(C8-14A)C7-15A4(C6-16A)C5-6A12C4-6A3(13C3-7A)13C4-7A12C2(4-18AC)16-2L5H16-DL5H16-2DH4A14-4D5A12-4D7A11-D11A10-D12A8-2D13A8-15A4-18A2(C3-19A)C4-E17AC3-AE2(17AC5-)17A4(C7-15A)2(C6-16A)C6-D15AC5-17AC5-7A11C4-7A12C3-8A12C3-7A13C2-8A13C2-9A12C2-20AC-21AC16-L6H16-2D5H16-2D5A14-H2D6A12-H3D7A12-D10A11-H11A5-6D11AC5-2D15AC3-D18A3(C3-19A)C2-20AC3-19AC4-18A5(C6-16A)C6-D15AC6-16AC5-I16AC4-I11A7C4-8A11C3-9A11C2(2-8A13C)2-9A12C2(-21AC)16-7H16-2D5H15-2D6A13-2H2D6A12-H2D8A11-H11A10-H11AC7-D-D12AC7-2D13AC2-5D15AC2-2D18A2(C2-20A)C-21AC2-20AC4-18AC5-3AB13AC5-5B12AC6-4B12AC6-3B13AC6-AB14A2(C6-16A)C5-17AC4-13A6C2(3-13A7C)2(2-9A12C)2-10A11C2(-21AC)16-7H16-2D5H15-3D5A13-H3D6A13-HD8A12-HD9A9-4D9AC7-2D13AC6-D15AC3-3D16AC2-2A-17A2(C2-20A)C-21AC2-20AC4-18AC5-BA3B2(12AC4-6B)13A4-6B13A5-4B14A2(5-B17A)5-17AC4-15A4C2(3-14A6C)2(2-10A11C)2-14A7C2(-21AC)16-7H16-2D5H14-H2D6A13-H2D7A13-HD8A12-H2D8A6-2H-5D8AC6-DA4D10AC4-2D16AC-3D18AC-D20AC22A3(C-21A)C3-19AC4-5B13AC2(4-6B13A)4-5B14A4-2BAB15A5-B17A4-2B17A5-17AC4-16A3C4-15A4C3-16A4C2(2-14A7C)2-17A4C2(-21AC)2(17-6H)16-D6A13-H2D7A13-2D8A12-HD8AC6-H-2H4D8AC6-H6D9AC4-2D16AC-2DH18ACD21A2(C22A)2(C-21A)C2-4A2B14AC3-A5B14A3-7B13A3-6B14A3-6B12AFA4-3B16A4-IB17A4-3B16A4-B5A2F11A4-D4A4F9AC4-5A4F7A3C3-7A2F8A3C3-16A4C2-17A4C2-19A2C2-20AC-21AC17-D5H17-3HA2H16-D6A14-2D7A12-H2D8A9-H-H2D8AC7-2H4D9AC4-3H5D10AC5-H16AC5D17AC2DAD18A3(C22A)C-21AC-7AB14A2-4A4B2(13A3-7B)11A2F3-5B12AF-F4-4B13AJF5-I2B15A5-2B2A4F10A4-B-2AEF2-2F9A4-B3A2(F4-F8AC4-4A)2F2-2F8AC3-6A4F8A2C3-18A2C3(2-20AC)2(17-D5H)16-D6A14-2D7A12-H2D8A9-3H3D7AC7-2H3DB9AC6-H2D13A2(C5-H16A)C4-D17AC3-19AC22AC46A-6A3B13A2-5A3B13A3-7B12AF3-6B12A2F3-5B12AF-F4-4B12AJ6-4B2A3F9A8-2A4-F9A3-3B2A6-F8A2-4B2AE5-F8A2-3B3AF5-F8A2-2B4A6-F8A3-B4AFR3-F8AC3-6A4F9A2(C3-19A)C2-20AC16-4D3H16-2DA4H14-2D7A12-DHD8A11-DH2D8A9-2H3DB7AC7-2H2D3B8AC6-H3D12AC6-H2D13AC-2G-2H16AC4G18AC4G19A3G66A-6A3B13A2-5A3B13A4-6B11AJF4-4B12AF6-A3B12AF6-2AB14AJ6-AB3A2-IF9A4-B2-2A5-F8A3-2B-2AE5-F8A3-K2B2AE6-F7A2-3B3AE6-2F6A2-3B4A5-FA2F5A2-2B4A6-F7AC3-B5AJ2-2F8AC3-7AJF10A2(C3-19A)C14-7D2H14-4D2A3H13-HB8A13-HD8A12-GHB8A9-5DB7AC8-3H2D2B7AC7-2H2D4B7AC6-2H3D2AB9A5-2HA2D13A-G2-5D14A4GA5D13A3G3A3D37A-22A-3AB2A3B13A3-BA5B13A5-A4B11AJF5-A3B11AF7-AB13AF8-B5A2I7AJF6-4A3-2I8A4-B4AE5-F7A4-B-3A6-F7A4-B3AE7-F6A3-KB3AE8-F5A2-K2B3AE6-F2-F4A2-K2B3AE5-6F2AC-K2B5A4-5F4AC-KFBF4A3J10AC-K2B18AC-2IB18AC15-6D2H14-5D2A2H13-GHD7A12-2GDB7A12-2GD8A12-GD2B7A9-4D3B7A9-G2D4B7A8-HG2D4B7A5-H-HG4D2B8A5-H3GDBD2B9A-3G2D2G2D4B9A-2GB6D3B10A-2A8B12A2-7B13AB3-7B11A2B4-DI4B11A2B6-4B11AJF5-A4B10AF7-2B6AE6AF8-AB3A2E-I6A2F6-4AE4-I7A4-B4AE5-F7A4-BAB2A7-F6A4-4BA8-F5A4-BAB2A9-F4A4-B3A11-F3A3-B-D3A11-FAC3-B-D3AD2-2F4-2F2AC3-F-3B6A4F4AC3-B-3B14AC3-5B14AC16-2G5D15-5DA2D14-H3D5A11-G-G2D7A10-4GDB7A10-3G2DB7A10-HG2D2B7A9-DGD4B7A9-4D3B7A9-2DFD3B7A4-D4-3DF2B3AB4A3-2ID3-5DB2A3B3A-I11D2(B4A)-10BD-10A-9B11A2B3-2AI5B7A2-ABH4-AD4B9A-2BF6-6B8ABFJ6-6B9AF7-ABA2B9AF8-AB2ABA3-I2E3A2F6-2B2A6-2IE4A6-2BAE6-IF5A4-B-2BA8-F5A4-G3BA9-F4A4-G3B11-F3A5-3AE11-F2A6-3A11-D2A5-2B2ADHQF6-H2DA5-BD3B3A2F2-2FAD2A5-6B4A2F6A3-7B13A18-5D16-7D15-H3D4A13-2G2DB5A10-D3G2D2B5A10-D2GF4B5A10-3DF4B5A10-2D5B6A10-2G2-2B7A9-2G-F-3B6A9-3G2D6B3A9-GDG2D7B2A2-I3DB7DB2A3B3A2-G5B3DED10A2-A2B-5B8A2J2H3-2A6B8A9-AD4B8A3BF7-5B6A2BJFJ6-8B5ABF-F6-10B-3AF-J6-5B7-E2AJF6-2BABE8-E3A6-2BAE8-I4A6-2BAE8-2F3A6-2BE10-2FDA5-3B12-F2D5-2BE13-DA5-3BE11-2DA5-3B2ANO7-H2DA6-2BE2BA2Q4-F3DA6-6B2AOFTR4DA6-7B5AB2DBA18-2G3D17-G5D16-3D4B15-3D5B11-4D5B3A10-5D5B3A10-2F2D2BF3B3A11-2F6B2A2B11-D2F9B11-2D6B2A2B10-3D8B2A10-G2-D7B2A3-G2EAD3G2D8B2A3-G3B4D2-A4B5A3-6BDB3A4B2AH2A3-2AI5B4A4BJ8-AD4B5A3BHJH8-4B6A2BJ-2F6-9B3A2BF-J6-6B-2B-4AF8-G2B2-B-B2-2E3AF8-3B9-E2AF7-3B10-E2A7-BE12-EA6-3B12-ED6-2BE12-2D5-2BE13-2D5-3BE11-D2A5-3BDN-P7-H2DA6-2B-K2EOP4-H3DB6-3BKAEHEOP2-A3DA6-5BF2B2E6DB41-D-3D16-2G2D3B16-2G5B11-5D7B10-J2FD-BF6B10-4F2B-6B12-2FB-FB-4B11-J2F9B12-FEF8B10-2D2E2B-6B10-3D-3B2-4B10-5D4B-3B4-BEA4E2D-8BA4-4B3D4B2-2B-3B4-2A12B3-2H6-AD-10B11-D6BA4BJ2-H7-G7BA2B-BF-J6-G13BF10-8B-B2ABF10-2B6-E-A2BF8-2B9-E3B8-2B10-2EB22-E6-2B14-A5-3B13-AB5-3B13-AD6-2B13-AB6-2B12-A2D7-BK-E8-A2DB8-B2KEH3EMNA2D2B22-D18-G4D15-4GD3B14-5G4B13-2D3G-4B11-3FDBF6B10-2(FD)2B-B-4B11-FD2BF3-4B12-D4B-5B12-2F6B-2B13-3F2-5B12-DF2D4-3B12-5D6B4-E5-4D-D2-5B4-AE3BD5B4-4B6-BE8B4-J2H6-A11B12-BD10B14-10BF9-13BF11-3BE-4BA2BF10-3B5-E-3BF9-B10-2BF9-B10-E2B22-B22-E6-B15-A2(6-2B13-AD)6-2BF12-AK7-BK11-A2D6-4B2-3EM2E2AD2B22-G19-G3D16-3GD2BD16-3GD3B14-D3G5B13-FDBF2BF3B12-HFDB-6B12-FBF4-3BF13-D2B2-2B-2B13-D3B-B18-F-7B14-2FD6B13-4D6B10-DGB2D-D6B6-2EB3D2BDB-6B6-E-EBD5B4-B2H7-11B12-A11B13-7B-3BF11-11BF11-4B2-6BF11-2B5-B-3BF10-B8-3BF20-3B22-B45-E22-A7-B13-A2(D7-F14-)K7-3B5-EM2E2ADB43-D2E17-G3-DB16-2G2-D2B13-2D3GBF-2B12-2FD2F2B3FB13-DFB-2BF3B13-3F-BF3B15-2B2-3B2F14-6B17-7B16-F2D6B14-3D5B14-2D-2D4BF8-EDEGED3-4B2D9-E2D4B-3B2D8-13BJ10-B2-3B-5BJ10-6B-5BF10-A5BE5BF10-A12BF10-3B5-5BF10-B8-4B20-3B91-2(D22-)K31-B7-2N2E2D43-EGDB18-EGKDB17-GE3DB14-DGI2BF3B14-5F2(-F)14-HFD2B2F2B14-2F2BDF2B15-FB3FB17-4B2-3B14-4B-4B14-FD2B-4B14-2F2D5B13-F3DFD2B2F9-E3-E2D3-2D-D10-D5B2(D-)2D10-9BDB13-11B10-A12B11-4BE7B11-13B11-2B5-5B20-4B20-B93-D22-K112-G2K21-EB19-KD2B16-E6B19-4F17-B3FBD18-EF2BF14-2F2-F2BF15-DBEF2BFBE14-D5BF2B14-FED3BF2B14-4F5B14-3DSFD3F13-F2D3F2D-D10-BEF2BE7D10-B2F4BE2DB2D10-11B-A9-B-10B12-4B2EI4B15-9B18-3BEB21-B24-B273-E2B19-4B42-EF2H19-DF2D19-3F40-E2(F2B)15-2D2(F2B)17-FDBFBD15-D3-4F14-E3DS3FJ13-F3E2D2E2D10-B2-3K5E2B11-FA2B3KEB2-E11-5BI2A2E12-3B4-BA2E13-B5-B2EAE20-B-E23-A22-B184-
