model
size = 13 17 16, scale = 0.05, origin = -y
material 
  colors = A:#F90 B:#EEE C:#BBB D:#FC6
voxels
83-7(3C10-)3C48-5C10(8-5A)4(8-2AB2A)10-B21-9C12(4-9A)2(4-2A5B2A)6-5B18-11C4(2-A3D7A)2-A6D4A6(2-A3D7A)2-11A2(2-A10B)3-2B2-5B9-2B5-11C4(2-A3D7A)2-A6D4A2(2-A3D7A)3(2-A3D6AB)2-A3D6A2B-10A2B2(-A11B)2-11B5-B2-2B3-13C157A11B2(A12B)3-B-7B2-13C156A2(12BA)12B3-B-7B2-13C143AB12A2(12BA)12B3-B2(-2B)4-13C65A7(B12A)2(12BA)11B5-6B-B2-13C156A2(12BA)12B3-4B3-2B3-11C5(2-11A)7(-B11A)2(-BA9BA)-10B6-6B5-11C9(2-11A)3(-B11A)2(-BA9BA)-11B6-5B6-9C12(4-9A)2(4-2A5B2A)6-5B21-5C14(8-5A)100-3C88-3C127-3C88-3C57-
