model
size = 24 26 3, scale = 0.05, origin = -y
material 
  colors = A:#EEE B:#5DAC81 C:#00AA90 D:#7DB9DE E:#E195A9 F:#F596AA G:#111 H:#855B32 I:#D0587C J:#E03C8A K:#F7D94C L:#B9887D M:#FBE251 N:#F17C67
voxels
9-6A16-10A13-12A11-14A10-14A9-5A6G5A8-16A7-18A6-3AEAE6AEAE3A6-2AEIAI6AIAIE2A3-5AEIAI6AIAIE6AF3AEIAI6AIAIE3AF2AF4AEAE6AEAE4A2(F2AF20A)F6ADAG8AGAD5ABCB3ADGD6ADGD3ABCB2-B3A3G6A3G3AB4-B18AB4-2B16A2B4-3B14A3B4-C2B14A2BC7-B12AB10-3B8A3B13-B6CB16-3B2C3B67-2F21-2(E2FE20-)E2FE17-3(D8-D14-)D2-4H2-D7-3A4-D2-H2NH2-D4-4A-A4-D2-H2NH2-D4-A-2A-A4-D2-4H2-2(D4-A-2A-A4-D8-)D4-A-4A2-D12-D2-3AC2B18-2BC27-C16-C7-B14-B7-CB14-BC7-16B10-2C8B2C14-8C273-K8-L2JL8-K2-K8-J2MJ8-K11-J2MJ20-L2JL187-C4BC14-14B13-2(2BC)2B80-
