model
size = 32 14 4, scale = 0.05, origin = -y
material 
  colors = A:#FF3 B:#FFC C:#009 D:#00C E:#FF9 F:#FFF G:#006 H:#FF6 I:#FF0 J:#003 K:#002EFF L:#00E M:#00D N:#06F O:#A1FFFF P:#06C Q:#000ADC R:#03F S:#03C T:#008 U:#09F V:#B1F0FF W:#6FF X:#00B Y:#00A Z:#036 Aa:#039
voxels
365-A4-A81-OF20-FO9-VFB16-BFV11-PBEHK10-KHEBP13-NEHAQ8-QAHEN15-LHAIQ6-QIAHL17-MAIK6-KIAM19-XID6-DIX21-2C6-2C23-TA4-AT57-A4-A250-C4-C19-GCDM2N2L4-2L2NMDCG10-RJF2EHAI2M4-2MIAH2EFJR6-ZAaSFB2EHAIDM4-MDIAH2EBFSAaZ2-CD3F2B2EHAICA4-ACIAH2E2B3FDCG2F3B3EHAIGA4-AGIAH3E3B2FGJGCDCSNP2DCGJA4-AJGC2DPNSCDCGJ270-D2WD26-GJH2CHJG23-CGJA2YAJGC19-ARDCGJI2TIJGCDRA15-ADKDCGJB2JBJGCDKDA13-ALDKDCGJE2-EJGCDKDLA11-AULDKHAI6-IAHKDLUA9-AOU2BE12-E2BUOA7-F3B18-3BF3-
