model
size = 28 17 7, scale = 0.05, origin = -y
material 
  colors = A:#FCF078 B:#FFEA3F C:#FDEF5B D:#FED638 E:#FAA821 F:#F9C12C G:#FEF6A1 H:#002 I:#00B J:#005 K:#004 L:#EF7F1B M:#001 N:#E00 O:#007 P:#00D Q:#00A R:#008 S:#00E
voxels
8-D10-D15-BD10-DB13-CBD10-DBC11-ACB12-BCA9-SAC14-CAS7-S2A16-2AS5-PSA18-ASP3-2PG20-G2P-3I22-5IG22-G2I-2I22-2I287-C14-C11-AC14-CA9-2ACB12-BC2A6-PG2AC14-C2AGP4-2G2A16-2A2G4-2GA18-A2G4-QG20-GQ4-Q22-Q345-B12-B13-CBD10-DBC11-ACBDF8-FDBCA9-2ACBDFE6-EFDBC2A7-Q2ACBDF8-FDBC2AQ6-QRACBD10-DBCARQ7-2RCB12-BC2R9-R2O12-2OR11-2O12-2O13-O12-O211-D3-L2-L3-D16-DF2EL2-L2EFD15-BDN2E4-2ENDB13-CB3NE4-E3NBC13-BDNE6-ENDB15-DF8-FD2(16-J10-J)244-J2-J23-EL2-LE21-2EL2-L2E19-FEHL2-LHEF17-2F2H4-2H2F17-FKH4-HKF18-2K6-2K17-2J8-2J300-4K24-M2HM24-4M23-HM2-MH415-H2-H24-M2-M208-
