model
size = 18 21 5, scale = 0.05, origin = -y
material 
  colors = A:#F2E100 B:#F00 C:#0F0F0F D:#070707 E:#593621
voxels
206-2A16-2A160-2A15-4A13-6A11-8A9-10A8-10A7-12A6-6A5DA5-3A4B4CD2A4-3A4B4CD2A3-2(4A4B4CD3A2-)3AD4C4B4A-4A2(D4C4B9A)5D4B9A5D65A2(6-2A)43-4A13-6A11-8A10-8A9-10A8-10A7-12A6-12A5-2(2A10-2A4-)2A10-2A3-3(3A10-3A2-)3(16A2-)16A186-E6-E118-E6-E244-7(E6-E10-)E6-E77-
