model
size = 14 28 15, scale = 0.05, origin = -y
material 
  colors = A:#111 B:#222 C:#050 D:#020 E:#080 F:#E00
voxels
87-A9(12-2A)12-3A11-5(3A12-)2A134-A11(12-2A)12-3A11-6(3A12-)2A91-A2(12-2A)12-AB11-2AB11-3A2(11-2AB)2(11-3A)3(B10-3A)B9-4AB9-5A11-7(3A12-)2A62-A2(12-2A)11-3A11-2AD11-2AB11-3A11-2AF11-2AB2(11-3A)B10-3AC10-3AB10-3AC9-4AB9-5A11-8(3A12-)2A33-A12-2A2(12-AB)2(11-3A2(11-2AB))2(11-3A)3(B10-3A)C9-4AB9-5A11-6(3A12-)2AB2(12-3A)12-2A18-A12-2A11-2AD11-2AB8(11-3A)B10-3AC2(10-3AB)9-4AB9-5A11-5(3A12-)2(2AB12-3A12-)3A12-2A3-A12-2A3(2(11-2AB)11-3A)11-3(3AB10-)3AB9-4AB9-5A11-4(3A12-)3(2AB12-3A12-)2A3-A12-2A3(11-3A)2(11-2AD11-2AB11-3A)11-3(3AB10-)3AC9-4AB9-5A11-5(3A12-)2(2AB12-3A12-)3A12-2A3-A12-2A3(2(11-2AB)11-3A)11-3AB10-3AC2(10-3AB)9-4AB9-5A11-4(3A12-)3(2AB12-3A12-)2A3-A12-2A11-2AD11-2AB8(11-3A)B10-3AC2(10-3AB)9-4AB9-5A11-5(3A12-)2(2AB12-3A12-)3A12-2A3-A12-2A3(2(11-2AB)11-3A)11-3AB10-3AC10-3AB10-3AC9-4AB9-5A11-6(3A12-)2AB2(12-3A)12-2A32-A2(12-2A)11-3A11-2AD11-2AB11-3A11-2AE11-2AB2(11-3A)B10-3AC10-3AB10-3AC9-4AB9-5A11-8(3A12-)2A61-A12-2A2(11-3A2(11-2AB))2(11-3A)3(B10-3A)B9-4AB9-5A11-7(3A12-)2A3-2(3A11-)3A70-A2(12-2A)9(10-4A)10-5A9-5A10-A-3A9-A2-3A8-A3-3A7-A4-3A6-A5-3A5-A6-2A5-A12-2(3A11-)3A98-A9(10-4A)10-5A9-5A4(12-3A)12-2A33-3(3A11-)
