model
size = 32, scale = 0.05, origin = -y
material 
  colors = A:#FFDBB1 B:#B3997C C:#8B8B8B D:#7C7C7C E:#878787 F:#000 G:#F7F7F7 H:#707070 I:#0008FF J:#F00 K:#8F8F8F L:#78FF00
voxels
153-4A28-4A138-18C13-20C11-22C10-8C6F8C10-7CF6CF7C10-22C10-10C2F10C10-9CF2CF9C10-22C10-2(4C5F)4C10-5CF3CF2CF3CF5C10-5C2(FC)F2C2(FC)F5C10-5CF3CF2CF3CF5C10-6C3F4C3F6C10-22C10-5CF10CF5C11-5C2F6C2F5C13-18C265-3(28A4-)5A2(2-2A)2-4A3-6A4-5A2(2-2A)2-3A2(-K)-5A6-16A5-3A6-12A7G9A6-10A3G2I2G7A6-12AG2J2GIG9A6-10AG2I2GIG7A6-12A3G2I2G9A6-10A7G7A6-5(3A10(-A)-4A4-)28A6-11(A-)2A391-26A5-3(28A4-)5A2(2B2A)2B4A3B6A4-5A2(2B2A)2B3A2(BA)B5A5-B16A5B3A3(B5-28A5-B24A)B5-5(3A10(BA)B4A4-)3A10(BA)B4A5-2A10(-A)-3A389-5(28A4-)28A5-B24AB5-2(28A6-B22AB6-)28A5-B24AB5-6(28A4-)3A10(BA)B4A6-11(A-)2A327-26A5-5(28A4-)2(4(28A6-B22AB6-)6(28A4-)3A10(BA)B4A5-2A10(-A)-3A325-6(28A4-))4(28A6-B22AB6-)7(28A4-)3A10(BA)B4A6-11(A-)2A230-28A4-28A3-6(30A2-)4(30A4-B24AB4-)7(30A2-)4A10(BA)B5A4-2A10(-A)-3A229-28A4-28A3-6(30A2-)4(30A3-B26AB3-)7(30A2-)4A10(BA)B5A3-3A10(-A)-4A228-28A4-28A3-6(30A2-)4(30A3-B26AB3-)8(30A2-)30A4-26A197-2(28A4-28A3-6(30A2-)4(30A3-B26AB3-)8(30A2-)30A3-28A196-)11A5-12A4-28A3-22(30A2-)30A3-3A10(BA)B4A6-11(A-)2A166-9A7-12A4-28A3-23(30A2-)30A4-2A10(BA)B3A7-11(A-)2A134-8A8-12A4-28A3-23(30A2-)30A3-28A6-11(AB)2A8-11(A-)2A102-8A4-4A5-7A4-28A3-23(30A2-)30A3-28A5-26A7-11(AB)2A8-11(A-)2A70-7A4-5A4-8A4-28A3-24(30A2-)30A4-26A6-26A7-11(AB)2A8-11(A-)2A38-7A3-6A3-9A4-28A3-24(30A2-)30A3-28A5-26A6-26A7-24A9-22A7-7A3-18A4-28A3-24(30A2-)30A3-28A5-2(26A6-)26A8-22A7-7A3-6A3-9A4-28A3-25(30A2-)30A4-2(26A6-)26A7-24A6-7A4-5A4-8A4-28A3-25(30A2-)30A4-2(26A6-)26A7-24A6-8A4-4A5-7A4-28A3-28(30A2-)30A3-28A4-8A8-12A4-28A3-29(30A2-)30A3-9A7-12A4-28A3-29(30A2-)30A3-11A5-12A4-28A3-29(30A2-)30A3-3(28A4-28A2-960A2-)28A4-28A2-960A64-163A2H22A2H6AH24AH582AH24AH6A2H22A2H99A64-131A2H22A2H5AH2-22D2-H4AH-2D20A2D-H5A2D22A2D16(6AD24AD)6A2D22A2D5AH-2D20A2D-H4AH2-22D2-H5A2H22A2H67A65-30A-3A2L60A2(30B2A)2B26-2B2A2B3-20E3-2B2A2B2-2E18A2E2-2B2A2B-2E20A2E14(-2B2A2B-E22AE)-2B2A2B-2E20A2E-2B2A2B2-2E18A2E2-2B2A2B3-20E3-2B2A2B26-2B2(2A30B)A-30A-
