model
size = 24 23 32, scale = 0.05, origin = -y
material 
  colors = A:#FF9 B:#FC3 C:#F00 D:#111 E:#FC6 F:#FC9
voxels
347-2C20-C4-C19-4C452-4A18-8A15-10A13-12A13-10A15-8A18-4A401-10A12-3(14A10-)14A11-12A13-10A17-4A354-8A13-14A9-4(16A8-)16A9-14A12-10A349-12A10-16A7-4(18A6-)18A7-16A9-14A346-14A8-18A5-3(20A4-)20A5-18A6-18A8-14A345-6A4-6A7-18A5-20A3-22A2-22A3-20A4-20A5-18A7-16A343-6A6-6A5-20A3-3(22A2-)22A3-20A4-20A5-8A2-8A342-5A8-5A2(4-9A)2(2-10A)-48A-2(22A2-)10A2-10A3-7A6-7A340-5A10-5A3-8A6-8A-10A3(4-20A)4-10A-9A4-9A2-8A6-8A3-6A8-6A340-4A12-4A3-7A8-7A-9A4(6-18A)6-9A-7A8-7A2-6A10-6A2(339-4A12-4A3-6A10-6A-8A4(8-16A)8-15A10-7A-5A12-5A)339-4A12-4A3-7A8-7A-8A4(8-16A)8-15A10-7A-5A12-5A339-5A10-5A3-7A8-7A-9A3(6-18A)6-17A8-8A-7A8-7A2-5A12-5A339-5A10-5A3-8A6-8A-9A6-19A4-20A4-19A6-18A6-9A-7A8-7A3-5A10-5A340-6A8-6A3-9A4-9A2(2-10A)-11A2-22A2-11A-22A2-9A-2A-9A2-8A6-8A3-6A8-6A341-7A4-7A5-20A3-5(22A2-)22A3-7A-4A-7A37-2B302-18A5-20A3-4(22A2-)22A3-20A5-18A10-2B6AB17-2B2A2B301-16A6-6(20A4-)20A5-18A10-B8AB16-6AB301-14A8-18A6-18A5-2(20A4-)20A5-18A6-18A7-16A10-B10AB14-8A18-4A21-F22-BEB20-B2E2B19-B-E-B21-E23-B21-BE3B19-BE3B20-3B65-12A10-16A8-16A7-3(18A6-)18A8-15A9-14A11-B10A-B13-8A18-4A21-B22-3B20-5B19-2(B-)B21-E23-B21-BE3B19-BE2(3B20-)B3-B42-8A13-14A10-14A9-2(16A8-)16A9-2(14A10-)B12AB12-10A15-8A17-6A162-5B21-B22-3B20-2B-2B20-3B19-8A15-10A13-B10AB12-B11A11-3(B12AB10-)B12AB11-12A13-10A15-8A17-6A257-B5-B16-B-5A2B14-2B7A2B14-B8A2B11-B10ABAB11-4(12A12-)12A13-10A15-8A18-4A283-6A17-8A15-10A14-10AB4(12-12A)13-10A14-10A15-8A18-4A284-4A19-6A17-8A15-5(10A14-)10A15-8A17-6A330-6A17-8A16-8A15-2(10A14-)10A15-8A16-8A17-6A20-2A332-6A17-4(8A16-)8A17-6A18-6A20-2A356-6A17-8A16-8A17-C4AC19-4A18-3D2A3D16-8D426-4A18-C2A2C2AC17-6C500-2C20-6C18-6C177-
