model
size = 32 7 32, scale = 0.05, origin = -y
material 
  colors = A:#0A0202 B:#F1F4FA C:#D4D6DC D:#E2E5EB
voxels
13-8A23-6(8A24-)2(B6-B24-)B2-2C2-B24-B2D2C2DB24-B2-2C2-2(B24-B6-)B21-6(3AB6-B3A18-)3AB6-B3A16-6(5A8-5A14-)5A8-5A13-6(3A14-3A12-)3A14-3A11-6(3A16-3A10-)3A16-3A9-6(2A20-2A8-)2A20-2A7-6(2A22-2A6-)2A22-2A5-7(3A22-3A4-)6(2A24-2A4-)2A24-2A3-20(2A26-2A2-)2A26-2A-2A55(28-4A)28-2A-20(2A26-2A2-)2A26-2A3-7(2A24-2A4-)6(3A22-3A4-)3A22-3A5-6(2A22-2A6-)2A22-2A7-6(2A20-2A8-)2A20-2A9-6(3A16-3A10-)3A16-3A11-6(3A14-3A12-)3A14-3A13-6(5A8-5A14-)5A8-5A16-6(14A18-)14A9-
