model
size = 30 10 31, scale = 0.05, origin = -y
material 
  colors = A:#844010 B:#53280A C:#A96148 D:#D0FCFA E:#AAF0F5 F:#E4FDFD
voxels
131-2(8A22-)8A229-2(3A8-3A16-)3A8-3A224-2(2A14-2A12-)2A14-2A221-2(2A16-2A10-)2A16-2A219-2(A20-A8-)A20-A217-2(A22-A6-)A22-A215-2(2A22-2A4-)2A22-2A214-2(A24-A4-)A24-A213-2(2(A26-A2-)A26-A212-)2(A26-A2-)A26-A211-7(A2(28-2A)28-A210-)A2(28-2A)28-A211-2(2(A26-A2-)A26-A212-)2(A26-A2-)A26-A213-2(A24-A4-)A24-A214-2(A24-A4-)A24-A155-B22-B5-4(2B22-2B4-)2B22-2B5-B22-B67-2(B20-B8-)B20-B7-2(C22-C6-)C22-C7-2(B20-B8-)B20-B9-2(B18-B10-)B18-B9-C20-C3(8-F20-F)8-C20-C9-B18-B10-B18-B11-2B14-2B12-2B14-2B11-C18-C5(10-F18-F)10-C2B14-2BC11-2(2B14-)3B8-3B14-2C3B8-3B2C6(12-FD14-DF)12-2C3B8-3B2C14-3B8-3B19-B6-B19-3C2B4-2B3C16-2DE3B2-3BE2D16-2DE8B4(E2D16-2DE2-4B2-)E2D16-3C8B3C19-8B82-C6-C22-2C4-2C4(22-2EC2-C2E)22-2(2C-)2C41-
