model
size = 13 18 32, scale = 0.05, origin = -y
material 
  colors = A:#7B9095
voxels
13-3(A3-)2A3(3-A)377-2(3(A3-)3(2A2(3-A)3-)A182-)3(A3-)3(2A2(3-A)3-)2(A169-3(A3-)4(2A2(3-A)3-))2(A169-3(A3-)3(2A2(3-A)3-)A182-3(A3-)3(2A2(3-A)3-)A169-3(A3-)4(2A2(3-A)3-))2(A169-3(A3-)3(2A2(3-A)3-))2A3(3-A)2(169-3(A3-)3(2A2(3-A)3-)A182-3(A3-)3(2A2(3-A)3-)A)182-3(A3-)2(2A2(3-A)3-)A182-3(A3-)3(2A2(3-A)3-)2(A182-3(A3-)2(2A2(3-A)3-))2A3(3-A)182-3(A3-)2(2A2(3-A)3-)A182-3(A3-)3(2A2(3-A)3-)2(A182-3(A3-)2(2A2(3-A)3-))A195-2(3(A3-)2(2A2(3-A)3-)A182-)3(A3-)2(2A2(3-A)3-)A3(195-3(A3-)2A3(3-A))195-
