model
size = 20 12 30, scale = 0.05, origin = -y
material 
  colors = A:#BB1313 B:#191919 C:#1E1E1E D:#B81212 E:#D7387F F:#379D30 G:#D97708 H:#124BC6 I:#2B7F26 J:#C73473 K:#B05E06 L:#1146B8 M:#1A1A1A
voxels
26-8C213-CM4C232-2C6-2C2(10-BC6-CB)10-BCK2IL2JCB11-CG2FH2EC13-G2FH2E130-2C2A6-2A2C6-2B2A6-2A2B7-B2A6-DAB8-B4AD5AB8-2B3AD4A2B9-BC6ACB11-8C15-2B91-CAD10-2AC4-B2A10-2AB5-2(BA10-AB6-)B2A8-2AB7-B2A6-DAB9-B8AB11-3B2A3B15-2B71-CA12-AC4(4-BA12-AB)5-BA10-AB7-BD8-AB9-B8AB11-8B67-CA14-AC3(2-BA14-AB)3-BD12-DB4-BA12-AB5-BA10-AB7-BAD6-2AB9-2B4ADA2B12-6B48-CA14-AC2-BD3(14-AB2-BA)14-AB3-BA12-AB4-BA12-AB5-B2A8-ADB7-2B8A2B10-8B46-C2(A16-A2C)A16-AC-2(CA14-AC2-)CA14-AC3-BA12-AB5-BA10-AB7-B2AD4-3AB9-3B4A3B13-4B28-G3(A16-A2G)A16-AG-KA14-AK2-CD14-AC3-BA12-AB5-BA10-AB7-B2A6-2AB9-2B6A2B12-6B27-FA16-D3(2FA16-A)F-IA14-AI2-CA14-AC3-BA12-AB4-B2A10-DAB5-2B2A6-2A2B8-2B2AD3A2B12-6B16-AD9-HA16-A2HD2(16-A2HA)16-AH-LA14-AL2-CA14-AC3-BA12-AB4-B2A10-2AB5-2B2D6-2A2B8-2B5AD2B12-6B16-DA9-E3(A16-A2E)A16-AE-JA14-AJ2-CA14-AC3-BA12-AB5-BA10-AB7-B2A6-2AB9-2B6A2B12-6B27-C2(A16-A2C)A16-AC-2(CA14-AC2-)CA14-AC3-BA12-AB5-BA10-AB7-B3A4-3AB9-3B3AD3B13-4B29-CA14-AC2-BD3(14-AB2-BA)14-AB3-BA12-AB4-BA12-AB5-B2A8-2AB7-2BAD3AD2A2B10-8B47-CA14-AC3(2-BA14-AB)3-BD12-AB4-BA12-AB5-BA10-AB7-B2A6-2AB9-2B4ADA2B12-6B48-CA14-DC3-3(BA12-AB4-)BA12-AB5-BA10-AB7-BA8-AB9-B8AB11-8B67-CA14-AC3-BAD10-2AB5-2(BA10-AB6-)B2A8-2AB7-BDA6-2AB9-B8AB11-3B2A3B15-2B70-C3A10-3AC3-3B2A6-2A3B6-B2A6-2AB8-B3A4-3AB8-2B5AD2A2B9-2B6A2B11-8B15-2B90-C2AD2A6-3ADAC3-5B3AD2A5B7-2B6A2B10-3BAD2A3B11-8B13-6B128-C5AD10AC3-16B9-6B15-4B169-CD5ADA2D2AD3AC3-16B203-C16AC3-2B3EBH2(BF)BG3B203-C3A2D9ADAC3-2B2(EB)H2(BF)BG3B203-2C8AD5A2C4-B3EBH2BF2BG2B205-CAD12AC5-BE3BH2(BF)BG2B205-C9AD4AC5-BE3BH2(BF)B2GB205-2C4AD6AD2C6-12B207-2C10A2C8-10B209-3C3AD2A3C11-6B207-
