model
size = 7 32 27, scale = 0.05, origin = -y
material 
  colors = A:#BBB B:#306 C:#309 D:#EEE E:#FF3 F:#FF9 G:#30C H:#6FF
voxels
94-2(B6-)H208-3B4-BCB213-B3CB2-B3CB198-2(2(B3CB2-)B3CB205-2(B3CB2-)B3CB191-)2(2(5B2-)B3CB205-)5B2-B3CB212-5B2-5B4-17(D6-)D41-B5(6-C)6-B3-14B2-17(3A4-)3A5-D6-D26-3B5(4-3C)4-3B2-7BE5B2E-3A-F2-19(3A4-)ADA5-D11-5B5(2-5C)2-2BG2B-E5B2E4BG2ED3ADEFD3ADF-18(D3AD2-)D3AD3-DA2(D5-)3B5(4-3C)4-BGB2-7BE5BEF-3A-E2-19(3A4-)ADA5-D13-B5(6-C)6-B3-14B2-17(3A4-)3A5-D6-D74-5B2-5B4-17(D6-)D88-5B2-B3CB212-2(5B2-)B3CB205-2(5B2-)2(B3CB219-2(B3CB2-)B3CB205-2(B3CB2-))B3CB219-5B2-B3CB213-3B4-BCB215-2(B6-)H115-
