model
size = 17 24 14, scale = 0.05, origin = -y
material 
  colors = A:#C6F B:#FCF
voxels
8-A-A44-4(A-)A8-4(A-)A6-13A5-2A3BA3B2A5-2A4BA4B2A5-2(A4B)A5-2A4BA4B2A5-5BA5B6-3BABA5B6-5(BA)B6-11A2(6-2(A4-)A)6-11A4(6-5BA5B)5-6(AB)A5-11A6-5(A-)A210-2(11A6-)11A11(380-A9-A6-A9-A)158-13A4-A11-A2-3A11-4A5(15-2A)-A11-A-2A-A11-A-4A11-3A19-3(A11-A4-)A11-A55-A11-A5-5(A-)A5-13A4-6(A-)A8-2(A-)A6-
