model
size = 31 13 7, scale = 0.05, origin = -y
material 
  colors = A:#FFADAD B:#E00
voxels
31-B30-B-9A22-A7BA21-5(BA)21-BA2B3A2B3(A22-AB5AB)A22-A2B3A2BA22-4(AB)A22-A7BA22-B8A20-B62-B3A3B4A2(20-B10A)20-11A3(20-B9AB)20-11A20-B10A20-B4A3B3A20-B3A3B4A50-B30-2B3ABAB4A3(20-11A)20-2B8ABA3(-B2A)-B3A2-13A3(-B2A)-BA3-2B8A2B4(2A-B)A2-2(11A20-)5ABAB3A20-B3ABAB4A19-B62-11B4(20-2B8AB)4(-B2A)-B2-2B8AB18-B-2B8AB4(-B2A)-B2-2(2B8AB20-)11B20-11B50-B30-2B3ABAB4A3(20-11A)20-2B8A2B4(2A-B)A2-13A3(-B2A)-BA3-2B8ABA3(-B2A)-B3A2-2(11A20-)5ABAB3A20-B3ABAB4A19-B62-B3A3B4A2(20-B10A)20-11A3(20-B9AB)20-11A20-B10A20-B4A3B3A20-B3A3B4A50-B30-B-9A22-2A5B2A21-5(BA)21-BA2B3A2B3(A22-AB5AB)A22-A2B3A2BA22-4(AB)A22-2A5B2A22-B8A20-
