model
size = 4 4 32, scale = 0.05, origin = -y
material 
  colors = A:#EEE B:#F60 C:#AAA D:#888 E:#DDD F:#960 G:#E00 H:#693 I:#F93 J:#F63 K:#B00 L:#993 M:#690
voxels
-FIGIJGFJGB2GBGI5-3(2E2-2E10-)2A2-2A10-2(2A-4A9-)2A-4A5-A2(3-2A-4A2(2-A))2-8A2(2-A)2-8A-2A2-A2-5(8A-2A2-2A-)2(8A-2A-3A-)8A-2A-12A-2A-15A-64AC15ADC2AC3AC6ACFDCAD2ACD2A2CACDLGDCB2ADG2A2DCD2FBHDH2AHB2AFBDFHBM3B2A2F2ABK2BF
