model
size = 13 32 13, scale = 0.05, origin = -y
material 
  colors = A:#3668FF B:#303030 C:#537EFF
voxels
316-A3B9-2(BA)B9-3B10-AB2A347-3B8-3(AB)A6-B2A2-ABA5-3A2-2AB5-B2A2-ABA5-ABA2-2AB6-A2BAB9-A2BA306-3(AB)A6-B5A2B4-B8A4-3A6-B3-B2A6-A3-4A5-B3-B7-2A3-AB6AB5-AB4ABA7-ABA154-9(B12-)A10-5C7-B6AB4-B8A4-9AB2-BA3-A4-A2-2A3-A4-B2-BA8-A3-A8-B3-B8A4-AB6AB6-A2BABA61-6(C12-)2(AC10-B)-A2(10-B-B)10-B-2B8-2BA3(2B8-2B-)2B8-2AC2A7-2C4AC5-B8A4-9AB2-B10A2-2A8-B-B2A8-5A8-AB-BA8-A3-9AB3-B9A4-AB4ABA8-2B2(11-2C)10-3C5(10-CAC)9-2C2A9-2(C3AB8-)A7(3-B8-B)3-B8-2AC2A7-2C4AC5-8AB3-B10A2-10AB-B2A8-5A8-A2B2A8-5A8-2A-B10A3-9AB4-B6AB7-4B9-CAC10-CAC9-2C2A4(C8-C3A)C8-C4A8-4AB8-B3AB7-B5A8(B6-B5-)B6-A-4CA6-2C4AC5-B7AB3-B9AB2-B9AB-B3(2A8-A2B)2A8-AB-B9AB3-B9A4-2B4ABA7-4B10-2(2C11-)2C10-3C5(10-CAC)A8-C3AB8-C2(AB)8-A7(3-B8-B)3-B8-2AC2A7-2C4AC5-B7AB3-11A2-B9AB-3A8-2AB2A8-AB3A8-2A-BA8-B2-11A3-B8AB4-B4ABAB7-3B63-5(C12-)AC10-2BA10-B-AB9-B6(-2B8-2B)-2B8-2A-2A7-2(C2A)C6-8A4-B7AB4-10A2(2-BA8-B2-2A8-A)3-B8AB3-9A5-ABA2BAB152-5(B12-)B3(11-2B)11-2A10-5C7-B5A2B4-9A4-B7AB3-4A6-A3-B2A6-B2-4A6-A3-B2A6-B3-9A4-B7AB6-2(BA)B295-3BA7-2B3ABAB4-AB5ABA4-B2A3-2AB4-3A5-A4-B2A3-2AB4-ABA3-ABA4-BAB3ABAB5-BA3BAB320-ABA10-3BA7-AB3-BA6-BA3-AB6-AB3-2A7-AB2-A9-ABA361-ABA10-3BA9-2(AB)10-2B57-
