model
size = 3 32 32, scale = 0.05, origin = -y
material 
  colors = A:#903 B:#EEE C:#111 D:#BBB
voxels
39-9(A2B)66-9(A2B)60-3(A2B)9(2A-)3(A2B)45-2(A2B)15(2A-)2(A2B)33-2(A2B)19(2A-)2(A2B)24-A2B10(2A-)AD-3(2AB)9(2A-)A2B18-A2B10(2A-)AD-5(2AB)9(2A-)A2B15-A2B9(2A-)AD-7(2AB)8(2A-)A2B12-A2B10(2A-)AD-2(2AB)2(2A-)AD-3(2AB)8(2A-)A2B9-A2B10(2A-)AD-2(2AB)2(2A-)AD-3(2AB)8(2A-)A2B6-A2B7(2A-)AD-12(2AB)9(2A-)A2B3-A2B7(2A-)AD-11(2AB)10(2A-)2(A2B)8(2A-)AD-10(2AB)11(2A-)2(A2B)12(2A-)3(CA-)2A3(-CA)11(-2A)-2(A2B)8(2A-)AD-3(2AB)2(CAB)2A4(BCA)3(B2A)8(-2A)-2(A2B)8(2A-)AD-3(2AB)3(CAB)2(2ABCAB)2(2AB)9(2A-)2(A2B)8(2A-)AD-4(2AB)2(CA3(B2A)B)9(2A-)2(A2B)12(2A-)2(CA-2A-)3(CA-)11(2A-)2(A2B)12(2A-)4(CA-)AD-2(CAB)2(2AB)9(2A-)2(A2B)12(2A-)CD-2(CAB)2A3(BCA)3(B2A)8(-2A)-2(A2B)9(2A-)AD-11(2AB)9(2A-)A2B3-A2B7(2A-)AD-8(2AB)13(2A-)A2B3-A2B7(2A-)AD-4(2AB)17(2A-)A2B6-A2B6(2A-)AD-8(2AB)12(2A-)A2B9-A2B7(2A-)AD-11(2AB)8(2A-)A2B12-A2B9(2A-)AD-8(2AB)7(2A-)A2B15-A2B13(2A-)AD-4(2AB)7(2A-)A2B18-A2B23(2A-)A2B24-A2B21(2A-)A2B30-2(A2B)17(2A-)2(A2B)39-2(A2B)13(2A-)2(A2B)51-2(A2B)9(2A-)2(A2B)27-
