model
size = 9 32 9, scale = 0.05, origin = -y
material 
  colors = A:#960 B:#0F3 C:#080
voxels
238-2(A8-)A7-3A6-A2-C5-A225-2(A8-)A32-A8-A56-A134-2(A35-)B5-A2-B5-A15-C4-3(A8-)2A7-16(A8-)A7-2A3(8-A)6-5A3-2A2(3-A)2-B-2A2-A-3B-A2-A-3B-2A4-B3-A94-A125-A23-A20-B2-A5-B116-C116-2(A8-)A5-2(A8-)A7-C6-A8-A239-2(A8-)A287-A8-3A6-A-A5-2A-A5-A290-C2-
