model
size = 32, scale = 0.05, origin = -y
material 
  colors = A:#00BEDD
voxels
7-20A5-128A2-3(28A4-)28A6-3(24A8-)24A10-3(20A12-)2(20A6-128A2-3(28A4-)28A6-3(24A8-)24A10-2(20A12-))20A12-61(20A6-128A2-3(28A4-)28A6-3(24A8-)24A10-3(20A12-))20A6-
