model
size = 32 17 32, scale = 0.05, origin = -y
material 
  colors = A:#FFE000 B:#111
voxels
5-24A2(3-32A-30A3-28A5-26A7-24A8-24A4-6A3(2B4A)2B6A-4A3(4B2A)4B4A3-2A2B3(2A4B)2A2B2A5-4(2B4A)2B7-24A8-24A4-32A-30A3-28A5-26A)7-24A4-32A-30A3-28A5-26A7-29(24A8-24A4-32A-30A3-28A5-B24AB7-24A8-2(24A4-32A-30A3-28A5-26A7-))24A8-24A4-32A-30A3-28A5-B24AB7-24A8-24A4-32A-30A3-28A5-26A7-24A4-
