model
size = 32 32 19, scale = 0.05, origin = -y
material 
  colors = A:#F0C B:#00D
voxels
194-5B18-5B5(4-2B-2B18-2B-2B)5-4B18-4B742-3B20-3B5-5B18-5B3-5(B4AB18-B4AB2-)B4AB18-B4AB3-B3AB18-B3AB5-4B18-4B6-4B18-4B646-3B20-3B5-B3AB18-B3AB3-B4AB7(18-5AB2-B5A)18-5AB2-2B3AB18-B3A2B3-B3AB18-B3AB5-4B18-4B582-3B20-3B5-B3AB18-B3AB3-2(B5A18-5AB2-)7(A28-A2-)B5A18-5AB2-B4AB18-B4AB3-B3AB18-B3AB5-4B18-4B518-3B20-3B5-B3AB18-B3AB3-2(B5A18-5AB2-)A28-A2-A28-A-B5(A28-A2B)A28-AB-A28-A2-B5A18-5AB2-B4AB18-B4AB3-B3AB18-B3AB4-5B18-5B484-5B18-5B4-B3AB18-B3AB3-B5A18-5AB2(2-A28-A)-B2(A28-A2B)A28-AB-A28-A-B3(A28-A2B)A28-AB-A28-A2-B5A18-5AB2-B4AB18-B4AB3-5B18-5B453-3B20-3B4-2B3AB18-B3A2B2-B5A18-5AB2(2-A28-A)-B9(A28-A2B)A28-AB-A28-A2-B5A18-5AB2-2B3AB18-B3A2B3-5B18-5B420-5B18-5B3-B4AB18-B4AB2-B5A18-5AB2-2(A28-A-B2(A28-A2B)A28-AB-)A28-A-B3(A28-A2B)A28-AB-6A18-6A3-B3AB18-B3AB3-2(A2B)18-2(2BA)3-4(B26-B4-)B26-B5-B24-B6-2B22-2B7-2B20-2B9-2B18-2B11-2B16-2B13-2B14-2B15-16B42-2B-2B18-2B-2B3-B4AB18-B4AB2-B5A18-5AB2-A28-A-B11(A28-A2B)A28-AB2-B4A18-4AB3-5AB18-B5A3-B3AB18-B3AB3-AB26-BA3-3(B26-B4-)B26-B5-B24-B6-2B22-2B7-2B20-2B9-2B18-2B11-2B16-2B13-2B14-2B15-16B18-12B12-5B18-5B3-B4AB18-B4AB2-B5A18-5AB2-A28-A-B2(A28-AB-A28-A-B2(A28-A2B))A28-AB-A28-A-BA28-A2BA28-AB-6A18-6A3-B3AB18-B3AB3-AB3AB18-B5A3-B26-B3-2A26-2A2-2A26-2A3-A26-A4-2A24-2A5-2A22-2A6-ABA20-ABA7-ABA18-ABA9-2BA16-A2B11-2BA14-A2B13-2BA12-A2B15-3BA2B4A2BA3B17-4(2B-)2B11-2B-2B18-2B-2B3-B4AB18-B4AB2-B5A18-5AB2-A28-A-B11(A28-A2B)A28-AB2-B4A18-4AB3-5AB18-B5A3-B3AB18-B3AB3-AB26-BA3-3(B26-B4-)B26-B5-B24-B6-2B22-2B7-2B20-2B9-2B18-2B11-2B16-2B13-2B14-2B15-16B18-12B12-5B18-5B3-B4AB18-B4AB2-B5A18-5AB2-2(A28-A-B2(A28-A2B)A28-AB-)A28-A-B3(A28-A2B)A28-AB-6A18-6A3-B3AB18-B3AB3-2(A2B)18-2(2BA)3-4(B26-B4-)B26-B5-B24-B6-2B22-2B7-2B20-2B9-2B18-2B11-2B16-2B13-2B14-2B15-16B43-3B20-3B4-2B3AB18-B3A2B2-B5A18-5AB2(2-A28-A)-B9(A28-A2B)A28-AB-A28-A2-B5A18-5AB2-2B3AB18-B3A2B3-5B18-5B452-5B18-5B3-B4AB18-B4AB2-B5A18-5AB2(2-A28-A)-B2(A28-A2B)A28-AB-A28-A-B3(A28-A2B)A28-AB-A28-A2-B5A18-5AB2-B4AB18-B4AB3-5B18-5B485-3B20-3B5-B3AB18-B3AB3-B4AB18-B4AB2-B5A18-5AB2(2-A28-A)-B5(A28-A2B)A28-AB-A28-A2-B5A18-5AB2-B4AB18-B4AB3-B3AB18-B3AB5-3B20-3B518-3B20-3B5-B3AB18-B3AB3-B4AB18-B4AB2-B5A18-5AB7(2-A28-A)2-B5A18-5AB2-B4AB18-B4AB3-B3AB18-B3AB5-3B20-3B582-3B20-3B5-B3AB18-B3AB3-2B3AB18-B3A2B7(2-B5A18-5AB)2-2B3AB18-B3A2B3-B3AB18-B3AB5-3B20-3B646-3B20-3B6-4B18-4B5-B3AB18-B3AB3-B-3AB18-B3A-3(B2-B4AB18-B4A)B2-B-3AB18-B3A-B3-B3AB18-B3AB5-4B18-4B6-3B20-3B742-3B20-3B6-B-2B18-2B-B5-2(2B-2B18-2B-2B4-)2B-2B18-2B-2B5-B-2B18-2B-B6-3B20-3B611-
