model
size = 32 30 19, scale = 0.05, origin = -y
material 
  colors = A:#EEE B:#FF0 C:#111 D:#BE8111 E:#FF3 F:#E00 G:#FF6 H:#F66 I:#FF9 J:#C93 K:#C96 L:#DDD
voxels
15-10(2A30-)2A637-4A9(28-A2DA)28-4A29-2A604-6A9(26-2A3DA)26-6A27-4A29-2A571-8A9(24-3A4DA)24-8A25-6A27-4A29-2A538-10A9(22-4A5DA)22-10A23-8A25-6A27-4A29-2A505-12A9(20-5A5D2A)20-12A21-10A23-8A25-6A27-4A29-2A472-14A18-6A7DA8(18-6A6D2A)18-14A19-12A21-10A23-8A25-6A27-4A29-2A440-15A16-7A7D2A8(16-7A6D3A)16-16A17-14A19-12A21-10A23-8A25-6A27-4A29-2A408-15A16-7A7B3A8(14-8A6B4A)14-18A15-16A17-14A19-12A21-10A23-8A25-6A27-4A29-2A376-15A16-7A9BA14-8A7(6B5A12-9A)6B5A12-20A13-18A15-16A17-14A19-12A21-10A23-8A25-6A27-4A29-2A344-15A16-7A9BA14-8A10BA12-9A6(11BA10-10A)11BA10-22A11-20A13-18A15-16A17-14A19-12A21-10A23-8A25-6A27-4A29-2A312-15A16-7A9BA14-8A10BA12-9A11BA10-10A5(12BA8-11A)12BA8-24A9-22A11-20A13-18A15-16A17-14A19-12A21-10A23-8A25-6A27-4A29-2A280-15A16-7A9BA14-8A10BA12-9A11BA10-10A12BA8-11A4(13BA6-12A)13BA6-26A7-24A9-22A11-20A13-18A15-16A17-14A19-12A21-10A23-8A25-6A27-4A29-2A248-15A16-7A9BA14-8A10BA12-9A11BA10-10A12BA8-11A13BA6-12A3(14BA4-13A)14BA4-28A5-26A7-24A9-22A11-20A13-18A15-16A17-14A19-12A21-10A23-8A25-6A27-4A29-2A216-15A16-7A9BA14-8A10BA12-9A11BA10-10A12BA8-11A13BA6-12A14BA4-13A14B2A2-A-12A14B2A2-A27B2A2-30A3-28A5-26A7-24A9-22A11-20A13-18A15-16A17-14A19-12A21-10A23-8A25-6A27-4A29-2A184-3BIBI2BGEI4E16-10B6EG14-11B6E2B12-I20B10-BD21B8-24BG6-B2D3B2A11B2A6B4-G4B5A9B5A5B2-BG3B7A2B3A2B7A4B-5B23A5B2(30AGB30A2B)30A2B29A-2B30A2BA-27A-E2B-27A-B2G2-26A2-2B-27A2-G2-27A2-G3-2(26A6-)26A7-25A7-5A5-15A8-2A8-4A-7A27-5A29-2A46-IE2G2BGIB2EI3E16-2EIBD2BGBD4E2IB14-G3EDB2C2BD2C2BGI2B12-EG3EDC2ACBC2AC5BG10-G3B3C4AC4A3C4B8-G2B2C2A2(C4A)C2A2CBEG6-BIBC5AC2A3C2AC5ACEGE4-G2BC7A2C3A2C7A2EIE2-GEBC22A3EG-I2BC23A5EB2C3A2H15A2H3A2C2BIB2CA4H6A3J4A4H3A2CEB2C3A3C6A3J4A3C3A2CB2GB2C3(AC)11A2(CA)C4AC2BC3AC2A2C11AC2A2C3A6C3A3C13A4C4AC2-C-C25AC3-E-C25AC3-G2-C18A5CAC5-CAC17AC3F3C5-C18AC6FC6-C17AC5F2C6-C11A7C4F3C6-C4AC5A2C3FCF8C7-C4A6C4F3C6AC7-C2A2C5-2C2F2C7A2(2C8-)4C-2C4AC27-2C2AC29-2C81-I2BG-G2E22-2(BIB2C)2BGI16-B2G2(BC2AC)3BG14-IB3C4AC4A3C2B12-B2C2A2(C4A)C2A2CB10-BC5AC2A3C2AC5ACB8-BC7A2C3A2C7ACB6-BC23ACB3-2BC25ACI2-2C3A2H15A2H3A2CB3-2CA4H6A3K4A4H3A2C2-2C3A3C6A3K4A3C3A2C4-2C2(AC)LC11A2(CA)C4AC2-C3AC2A2C11AC2A2C3A6C3A3C13A4C4AC2-C-C25AC5-C25AC6-C18A5CAC5-CAC17AC3F3C5-C18AC6FC6-C17AC5F2C6-C11A7C4F3C6-C4AC5A2C3FCF8C7-C3AC5-C4F3C6AC7-C2A2C5-2C2F2C7A2(2C8-)4C-2C4AC27-2C2AC29-2C114-2C3-2C24-C2AC-C2AC22-2(C4A)C21-2(C4A)C22-C2A3C2AC24-2C3-2C684-
