model
size = 19 19 28, scale = 0.05, origin = -y
material 
  colors = A:#EEE B:#00A C:#E00 D:#F63 E:#555 F:#008
voxels
19-20B5(17A2B)17A20B342-20B5(17A2B)17A20B171-B5(17A2B)4(A16-2B)A2CA3CA2(C2A)2CAB152-B5(17A2B)5(A16-2B)C3A2(CA)2C2(AC)3AB114-B2(17A2B)10(2A15-2B)C3A3CACA2CAC3AB76-B4(17A2B)10(2A15-2B)A2C3(AC)2AC2A2CAB57-B5(17A2B)10(2A15-2B)17AB23-2D17-2D32-B2(17A2B)2(A16-2B)A16-3(B18-)B118-3(2D17-)2D32-B2(17A2B)2(A16-2B)A16-3(B18-)B118-2(2D17-)2D70-B4(17A2B)2(5(A2D)AD2B)2(AD5(E2D)2B)2(A5(2DE)D2B)AD5(E2D)B-2D-2A4(-2D)5-2A2(17-2D)108-B9(17A2B)5(2AE)2AB-2D-2A4(-2D)5-2A17-2A146-B8(17A2B)5(2AE)2AB-2D-2A4(-2D)5-2A184-B7(17A2B)5(2AE)2AB-2D-2A4(-2D)191-B7(17A2B)17F2(B190-B8(17A2B)17A)2(B190-B7(17A2B)17A)2B17AB190-B4(17A2B)9A3C5A2(2BA2(3C5A))2(2BA2(6C2A))B190-B4(17A2B)9A3C5A2(2BA2(3C5A))2BA6C2A7CA2(B190-B5(17A2B)9A3C5A2BA2(3C5A)2(2BA3C5A3C3A2C))B190-B5(17A2B)9A3C5A2BA2(3C5A)2BA6C2A3C3A2CB190-B6(17A2B)9A3C5A2BA2(3C5A)2BA6C2A7CAB190-B6(17A2B)9A3C5A2BA2(3C5A)2BA3C5A5C3AB190-B6(17A2B)9A3CA4C2BA3C5A7CAB190-B7(17A2B)3A4C2A3C3A2C2BA6C2(2A3C)B190-B7(17A2B)A6C2A3C3A2CB209-
