model
size = 32 12 32, scale = 0.05, origin = -y
material 
  colors = A:#101010 B:#EC0000
voxels
15-4A27-2(4A48-8B-10A-8B6(4-A26-A)4-8B-10A-8B48-)4A28-4A15-A8-12A8-A-2A8B12A8B2A2-2(3A2-2A-12A-2A2-3A4-)2(3A2-2A-A4-2A4-A-2A2-3A4-)3A2-2A-12A-2A2-3A4-3A2-2A-12A-2A2-3A2-2A8B12A8B2A-A8-12A8-A15-4A28-4A15-A8-12A8-A-2A8B12A8B77A4-2A4-22A4-2A4-77A8B12A8B2A-A8-12A8-A15-4A28-4A15-A8-12A8-A-2A8B12A8B77A4B2A4B22A4B2A4B77A2(8B12A8B2A-A8-12A8-A15-4A28-4A15-A8-12A8-A-2A8B12A8B2A-5(30A2-)30A-2A)8B12A8B2A-A8-12A8-A15-4A28-4A15-A8-12A8-A-2A8B12A8B196A2(8B12A8B2A-A8-12A8-A15-4A28-4A15-A8-12A8-A-2A8B12A8B66A-B28AB2-B28AB-66A)8B12A8B2A-A8-12A8-A15-4A28-4A15-30A2(-96A-B28AB2-B28AB-96A-30A15-4A47-9A12-9A)3(-11A10-75A-B28AB2-B28AB-96A-30A15-4A47-9A12-9A)-11A10-75A-B28AB2-B28AB-96A-30A15-4A14-10A12-10A-9A12-9A-11A10-75A-B28AB2-B28AB-96A-30A-42A12-10A-9A12-9A-11A10-75A-B28AB2-B28AB-96A-30A-32A33-4(9A12-9A-11A10-75A-B28AB2-B28AB-96A-30A15-4A47-)9A12-9A-96A-B28AB2-B28AB-96A-30A15-4A28-4A15-30A-96A-B28AB2-B28AB-96A-30A2(15-4A28-4A15-A8-12A8-A-2A8B12A8B66A-B28AB2-B28AB-66A8B12A8B2A-A8-12A8-A)15-4A28-4A15-A8-12A8-A-2A8B12A8B196A2(8B12A8B2A-A8-12A8-A15-4A28-4A15-A8-12A8-A-2A8B12A8B2A-5(30A2-)30A-2A)8B12A8B2A-A8-12A8-A15-4A28-4A15-A8-12A8-A-2A8B12A8B77A4B2A4B22A4B2A4B77A8B12A8B2A-A8-12A8-A15-4A28-4A15-A8-12A8-A-2A8B12A8B77A4-2A4-22A4-2A4-77A8B12A8B2A-A8-12A8-A15-4A28-4A15-A8-12A8-A-2A8B12A8B2A2-2(3A2-2A-12A-2A2-3A4-)2(3A2-2A-A4-2A4-A-2A2-3A4-)3A2-2A-12A-2A2-3A4-3A2-2A-12A-2A2-3A2-2A8B12A8B2A-A8-12A8-A15-4A14-
