model
size = 25 16 22, scale = 0.05, origin = -y
material 
  colors = A:#7B90D2 B:#005CAF C:#FFF D:#211E55 E:#111 F:#FCFAF2 G:#A5A051 H:#E83015
voxels
25-FCEC4-CECF3D12-3(EC4-CE17-)EC4-CE265-FCEC4-CECF3D12-3(EC4-CE17-)EC4-CE290-3E6-EC4D10-FCE6-E2(CF3D10-FC8-)CF3D10-FCEC4-CECF3D10-FCEC2-2FCECF3D262-E12-D4B2A5-2E4-2E5-3(D4B2A18-)D4B2A3-2(FCEC4-CECF3D10-)FCEC3-FCECF3D230-4A4-E16-2(4A21-)2(4A16-D4B)2A18-D4B2A3-FCE6-ECF5D8-FCEC4-CECF5D8-FCEH-3FCECF2(5D20-)5G24-E103-4(5A20-)4A21-2(4A18-3B)2A20-3B2A3-FCEC4-CECF4-B8-F3H3-FCECF4-B20-5G21-2E-E203-3(5A20-)4A18-3B4A17-4B2A5-2(E6-)B8-FC-H-3FCECF5G21-E2-E253-2(5A20-)5A17-3B5A15-2G3B2A3-FCEC4-CECF5G8-FCEC3-FCEC2-4E328-4A16-D4B5A12-3GD4B5AFCEC4-CECF4D4B2A3-FCEH-3FCECF3D330-5A12-3G5-5A15-D4B4A-FCEC4-CECF4D4B2A3-FCEC4-CECF3D305-2(5A20-)5A15-D4B4A-FCEC4-CECF4D4B2A3-FCEC-3FCECF3D330-2(5A15-D4B)4A-FCEC4-CECF3D330-2(5A15-D4B)2A3-FCEH4-CECF3D305-2A23-5A15-D4B4A-FCEC4-CECF3D10-FCEC-3FCECF3D280-5A11-5G4-5A11-5D4B4A-FCEC4-CECF4D4B2A2(3-FCEC)F3D305-5A11-5G4B4A-FCEC3-FCEC5D4B2A3-FCEC-3FCEC234-3(5A20-)5A16-4B4A-FCEC4-CEC5G4B2A3-F3H3-FCEC4-E254-5A20-4A21-4A17-4B4A3-EH5-E6-4B2A3-FCH4-FCEC5G14-4F3-2E-E104-5(5A20-)2(5A15-D4B)2A18-D4B2A3-FCEC4-CECF4D4B2A3-FCEH4-CECF4D16-2F2-5G21-E2-E104-5(4A21-)4A15-2D4B4A-FCE6-2(ECF3D10-FCEC4-C)ECF3D15-4F27-5G21-4E86-E6-E5-D4B2A5-2E4-2E5-3(D4B2A18-)D2(4B2A3-FCEC4-CECF4D)4B2A3-FCEC4-CECF3D210-3E6-EC4D10-FCE6-E2(CF3D10-FC8-)CF3D10-FCEC4-CECF3D10-FCHC4-CECF3D13-H246-
