model
size = 32 24 6, scale = 0.05, origin = -y
material 
  colors = A:#050 B:#070 C:#020 D:#080 E:#010 F:#040 G:#F60 H:#700 I:#0A0 J:#F90 K:#FF0 L:#EEE M:#111
voxels
18-2(A-)A23-2A5-A2(B24-A6-)A24-8A-4C19-5D3AC4AC18-7D5AIAC17-5E2D4A2(IA)C16-7D3AIA-AI2A15-6ED2AIA3-AIA9-A5-7DAIA4-3A8-4A3-6ED2A17-A-A3-7DA20-4A6ED2A4-A18-6D6A-2A4-5G8-6C3A2-3A4-2G2J2KG3-10A2C9-2G4J3K2-9H4A9-2G2J2KG3-4(HL)H3A11-5G2-E14A17-AE12A19-6AMLAML4A22-8A24-A-5A-A216-B2C2A27-BFB2A-2FA29-CBA29-2BA24-4AB27-4AB57-B2A-2A2C24-2AB-2CBA28-2C2A84-A2C33-A31-A288-3CB28-A2CA28-5AC3A23-AB2A2-C2A23-2A4-3A23-2A2-A2B25-CA2-A2B25-2A2-A2F24-3A-4A24-2A2CB3A28-B3A27-2C2A23-ABAC-ACBA21-2A2C2F-FCFA22-A2CAF27-A2-A191-B6-A24-B2-2AB-A25-C-2AB27-C2A2B2C2-BAC20-7A2-2FBA19-9A5-CA16-5A2C2A5-BA16-2A-6A23-2(2A2-3A25-)2A2-3A24-3A-4A2BF21-2A2CB3A4-2B15-2A5-B3A21-2A2-6A23-9A21-4A2F2(CF)A22-A2BA3FCF23-A2-AB2CBAC28-AB-A28-AB123-A6-A24-A2-2AB-A24-2A-2AB26-8A2-B2A19-8A2-4A18-10A5-2A15-10A5-BA9-A5-10A15-2ABA3-8A18-A-A3-4AB3A20-BC11A4-A18-3AF8A-2A17-2A2CB4A2-B2A14-6A2CB3A20-13A19-FC10A19-14A19-2A2B8A19-3A2BAB8A22-AB6A24-A-3A2B27-2(A-)A24-2A5-2A2(24-A6-A)24-5A2BA-4A19-5A2B7A18-9A2B4A17-16A16-12A-4A15-11A3-3A9-A5-10A4-B2A8-4A3-9A17-A-A3-8A20-13A4-A18-12A-2A17-9A2-3A14-12A20-13A19-12A18-15A17-14A19-15A22-8A24-A-5A-A25-2(A-)A10-
