model
size = 30 26 21, scale = 0.05, origin = -y
material 
  colors = A:#FF0 B:#111 C:#EEE D:#FC9 E:#444 F:#F93 G:#E00 H:#00F
voxels
406-AE2A26-B2AB588-2A3(BA)B2A19-2A3(BA)3B28-2A28-EA28-2A27-4A26-4A27-EA28-2A28-B500-2A3(BA)B2A19-E3(AB)A3B3(28-2A)27-E3A26-4A27-AB28-A530-2B28-2B126-4A26-B2AB588-2A28-2A748-2B28-2B693-3A27-3A22-2A3(BA)22-2A2(BA)EA687-3A27-3A22-2ABAB3A22-EA2E2(BA)687-3A27-E2A747-3B27-3B747-3A27-E2A710-AB2AE5AE7A10-5ABE11A2BE8-3AB3A2E5AB4A3BA7-AB15A2B5A5-4AE2A2B4A2E3A2B2A2EA5-2ABE5AE9A2B4A5-15A2B2A2BABAE6-2AB2A2BA3B3A2B3A3B2A6-EAB2A2BA3B8A3BAE7-2AE3B6AEA2BAE2ABA8-2AEB8AEA2BAE2ABA9-7A2B2AE4ABE2A10-3AE2BA2EAB6AE2A11-6A2E5A2E3A13-5A6-2AB2A15-2BE8-ABA17-B10-B254-5AE3AEAB2AB5A8-7AE15A6-E24A5-25AB3-26AB3-B27A2-28A2-27AB2-B26AB3-26A4-26A5-24A6-AB22A7-E21A8-20A2B9-2(9AB)11-4B3A4-E6A13-3B2A6-4AE15-3A8-3A17-A10-B77-3A8-3A16-3A8-2AB15-6AE5AB4A13-2A2B11ABA11-20A8-23A6-25A5-26A3-27A3-B27A2-28A2(2-27AB)3-26A4-25AE5-24A6-2B22A7-E21A8-B19A2B9-19AB11-7A4-7A13-4AE6-5A15-B2A8-3A17-A10-B77-3A8-3A16-3A8-3A15-17A12-18A11-21A7-25A4-AC3AC20A3-2(2AC)22A2-5AC22A2-28A2-5A3C2A2C16A2-9AC17AB2-B4A3C19AB3-27A3-E3A2C6A2C13A4-26A4-2B6AC16A6-B22AE6-B19A2BA8-19AB11-7A4-7A13-5A6-5A15-2AB8-3A17-A10-E77-3A8-3A16-3A8-3A14-4AC13A10-22A6-26A3-28A2-28A-36AC23AB35A3C2A2C17AB9AC17A2B6A3C19A2B29AE-5A2C6A2C13A2-28A3-9AC16A4-26A5-21A2BA6-21A2BE7-B9A4B8A9-E8A2-2B7A11-4A2BA4-B6A13-B2A2B6-2A2BE15-2AE8-3A17-A10-A17-3A8-3A16-3A8-3A14-4AC13A10-7A7C8A6-9A7C10A3-10A7C11A2-10A7C11A-10A9C17AC2A11C18A12C2(16A14C17A13C)10A-5A14C9A2-6A13C9A3-B6A11C8A4-7A3CA4CA2C8A5-11A2C11A6-24A7-3A5C14A9-3A2C4A2-9A11-3AC3A4-7A13-5A6-5A15-3A8-3A17-A10-A17-3B8-3B16-BAB8-BAB14-3BE10BA3B10-2B6A6DAE4A2B6-2B8A6DE7A2B3-B10A6D10AB2-BE7AEA6DAEB2ABAE2AB-B10A8D2ABAB2AE2A2B9A10D5AE2AE2BEAE5A12D8A2B4A3B3D2G4D2G2D3BAE3A2B2AE3A3DG2D4G2DG3D4AEA2BAE2A3B6D2B5D3B2A2EA2B6A7D2B7D6AB-B2AEA2BD3BDB2FBD3BD2B4AB2-B5A2DBHBD4BDBHB2D2AE2AB3-BAE4ACHB6DCHB4AEAB4-B3AE2A3BA4DA3B2(AE)2AB5-B2A2E6A2D6AE3AB6-B6A2(E2A)E3A2(E2A)B7-2BA5F2A2B2A5FA2B9-B2A3F2AB2-B2A3F2AB11-B2AF2AB4-BEAF2AB13-B2AEB6-B3AB15-BAB8-BEB17-B10-B209-3B28-BAB10-B2AB57-3B13-3B41-3B6-2B5-3B2(20-2B)-3B-B2FB-3B-2B15-BHB-4B-BHB18-CHB6-CHB18-3B6-3B376-3B9-4B12-2B2DB9-B2D2B10-B3AB11-B2AB10-B2AB13-BAB10-B2AB659-3B9-4B12-2B2DB9-B2D2B10-BAEAB11-BAEB10-BAEB13-BAB10-BEAB532-
