model
size = 22 14 19, scale = 0.05, origin = -y
material 
  colors = A:#111 B:#FF3 C:#BBB
voxels
2-5C8-5C2(4-5A8-5A)5-3A10-3A6-3A10-3A202-7C6-7C2(2-7A6-7A)3-5A8-5A4-5A8-5A5-3A10-3A180-7C6-7C4(2-7A6-7A)3(3-5A8-5A178-9C4-9C9B4-18B4-9B-7B6-7B2-7B6-7B3-5B8-5B4-2B-2B8-2B-2B5-3B10-3B7-B12-B114-9C4-9C9A4-18A4-9A-7A6-7A2-7A6-7A)3-5A8-5A178-9C4-9C9A4-18A4-9A-7A6-7A2-7A6-7A3-5A8-5A5-3A10-3A157-9C4-9C9A4-18A4-9A-7A6-7A2-7A6-7A3-5A8-5A4-5A8-5A5-3A10-3A6-2(3B10-3B28-)3B10-3B25-9C4-9C9A4-18A4-9A-2(7A6-7A2-)7A6-7A3-2(5A8-5A4-)5B8-5B5-3A10-3A5-5B8-5B5-3A10-3A6-4B8-5B5-3A10-3A3-9C4-9C9A4-18A4-9A-4(7A6-7A2-)6A2(8-5A3-7B6-7B3-5A)8-5A4-6B6-7B3-5A8-5A3-7C6-7C7(2-7A6-7A)3(-9B4-9B-7A6-7A)2-7C6-7C7(2-7A6-7A)3(-9B4-9B-7A6-7A)3-5C8-5C7(4-5A8-5A)3(3-7B6-7B3-5A8-5A)4-5C8-5C7(4-5A8-5A)3(3-7B6-7B3-5A8-5A)5-3C10-3C7(6-3A10-3A)3(5-5B8-5B5-3A10-3A)182-2(3B10-3B28-)3B10-3B25-
