model
size = 22 14 18, scale = 0.05, origin = -y
material 
  colors = A:#111 B:#FF3 C:#BBB
voxels
4-3A10-3A5-3C10-3C7(6-3A10-3A)2(6-3B10-3B6-3A10-3A)6-3B10-3B5-5C8-5C2(4-5A8-5A)5-3A10-3A6-3A10-3A202-7C6-7C2(2-7A6-7A)3-5A8-5A4-5A8-5A5-3A10-3A180-7C6-7C4(2-7A6-7A)3(3-5A8-5A178-9C4-9C9B4-18B4-9B-7B6-7B2-7B6-7B3-5B8-5B178-9C4-9C9A4-18A4-9A-7A6-7A2-7A6-7A)3-5A8-5A178-9C4-9C9A4-18A4-9A-7A6-7A2-7A6-7A3-5A8-5A5-3A10-3A157-9C4-9C9A4-18A4-9A-7A6-7A2-7A6-7A3-5A8-5A4-5A8-5A5-3A10-3A135-9C4-9C9A4-18A4-9A-2(7A6-7A2-)7A6-7A3-5A8-5A4-5A8-5A5-2(3B10-3B6-3A10-3A6-)3B10-3B6-3A10-3A3-9C4-9C9A4-18A4-9A-4(7A6-7A2-)6A3(8-5A4-5B8-5B4-5A)8-5A3-7C6-7C7(2-7A6-7A)3(2-7B6-7B2-7A6-7A)2-7C6-7C7(2-7A6-7A)3(2-7B6-7B2-7A6-7A)3-5C8-5C7(4-5A8-5A)3(4-5B8-5B4-5A8-5A)4-5C8-5C7(4-5A8-5A)3(4-5B8-5B4-5A8-5A)2-
