model
size = 23 32 15, scale = 0.05, origin = -y
material 
  colors = A:#3CF B:#CFF C:#C60 D:#D00 E:#BBB F:#360 G:#390
voxels
120-5A18-5A662-5A18-5A16-9A14-9A16-5A18-5B593-5A16-9A14-9A13-11A12-11A13-9A14-9B16-5B547-5A17-7A14-11A12-11A11-13A10-13A11-11A12-11B14-7B17-5B18-5B479-3B18-7A15-9A13-11A12-11A11-13A10-13A11-11A12-11B13-9B15-7B16-7B18-3B89-3B20-3B43-3D181-3(3C20-)3C42-5B16-9A13-11A11-13A10-13A9-15A8-15A9-13A10-13B11-11B13-9B14-9B16-5B19-2(3B20-)3B19-5B18-5B19-3D19-5D111-2(3C20-)3C19-3(5C18-)5C19-3C18-7B15-9A13-11A11-13A10-13A9-15A8-15A9-13A10-13B11-11B13-9B14-9B15-7B17-2(5B18-)5B17-7B16-7B17-5D17-7D87-3C19-2(5C18-)5C17-3(7C16-)7C17-C2FGC17-7B15-9A13-11A11-13A10-13A9-15A8-15A9-13A10-13B11-11B13-9B14-9B15-7B17-2(5B18-)5B17-7B16-7B17-5D17-7D19-E-E20-E-2E19-E2-2E17-3C2-2E15-5C2-2E6-3E5-5C3-2E4-2E7-5C4-2E2-2E7-7C4-4E8-2(7C16-)7C17-CGFGC17-7B15-9A13-11A11-13A10-13A9-15A8-15A9-13A10-13B11-11B13-9B14-9B15-7B17-2(5B18-)5B17-7B16-7B17-5D17-7D87-3C19-2(5C18-)5C17-3(7C16-)7C17-CFGFC18-5B16-9A13-11A11-13A10-13A9-15A8-15A9-13A10-13B11-11B13-9B14-9B16-5B19-2(3B20-)3B19-5B18-5B19-3D19-5D111-2(3C20-)3C19-3(5C18-)5C19-3C20-3B18-7A15-9A13-11A12-11A11-13A10-13A11-11A12-11B13-9B15-7B16-7B18-3B89-3B20-3B43-3D181-3(3C20-)3C65-5A17-7A14-11A12-11A11-13A10-13A11-11A12-11B14-7B17-5B18-5B524-5A16-9A14-9A13-11A12-11A13-9A14-9B16-5B593-5A18-5A16-9A14-9A16-5A18-5B662-5A18-5A588-
