model
size = 19 32 4, scale = 0.05, origin = -y
material 
  colors = A:#750787 B:#004DFF C:#008026 D:#FFED00 E:#FF8C00 F:#E40303 G:#FFEFD9 H:#FFF5E9 I:#F2CA05
voxels
384-2(3A16-)2(3B16-)2(3C16-)2(3D16-)2(3E16-)3F16-3F386-2(3A16-)2(3B16-)2(3C16-)2(3D16-)2(3E16-)3F16-3F393-2(3A3-3A10-)2(3B3-3B10-)2(3C3-3C10-)2(3D3-3D10-)2(3E3-3E10-)3F3-3F10-3F3-3F19-9(G18-H18-)G18-H3A3-3A9-G3A3-3A9-H3B3-3B9-G3B3-3B9-H3C3-3C9-G3C3-3C9-H3D3-3D9-G3D3-3D9-H3E3-3E9-G3E3-3E9-H3F3-3F9-G3F3-3F9-I18-
