model
size = 30 8 11, scale = 0.05, origin = -y
material 
  colors = A:#1A1B26 B:#FFD900 C:#FF211F D:#4100FF E:#FF482D F:#FFE866 G:#FF722D H:#EA00FF I:#B80CFF J:#890CFF K:#750CFF L:#5E0CFF M:#FF5D2D N:#FFE033
voxels
-C26-C2-A26-A-2A3(26-4A)26-2A-A26-A2-C26-C2-CA24-AC2-2A24-2A-3A3(24-6A)24-3A-2A24-2A2-CA24-AC2-C2A22-2AC2-3A22-3A-4A22-4AF3A22-3A2F3A22-3AF4A22-4A-3A22-3A2-C2A22-2AC2-C3A20-3AC2(2-4A20-4A-5A3(20-10A)20-5A-4A20-4A2(2-C3A20-3AC))2-4A20-4A-5A20-5AN4A20-4A2N4A20-4AN5A20-5A-4A20-4A2(2-C3A20-3AC)2-4A20-4A-5A3(20-10A)20-5A-4A20-4A2-C3A20-3AC2-E3A20-3AE2-4A20-4A-5A3(20-10A)20-5A-4A20-4A2-E3A20-3AE3-M2A20-2AM3-4A20-4A-5A20-5AB4A20-4A2B4A20-4AB5A20-5A-4A20-4A3-M2A20-2AM5-G22AG5-26A2-5AHIJKL10DLKJIH70AHIJKL10DLKJIH5A2-26A5-G22AG7-22A7-24A3-5A20-6AB2A22B2(2AB)2A22B2AB6A20-5A3-24A7-22A4-
