model
size = 30 8 11, scale = 0.05, origin = -y
material 
  colors = A:#1A1B26 B:#FFD900 C:#FFB12D D:#FF211F E:#FF482D F:#FFE866 G:#FF722D H:#FF5D2D I:#FFE033
voxels
-D26-D2-A26-A-2A3(26-4A)26-2A-A26-A2-D26-D2-DA24-AD2-2A24-2A-3A3(24-6A)24-3A-2A24-2A2-DA24-AD2-D2A22-2AD2-3A22-3A-4A22-4AF3A22-3A2F3A22-3AF4A22-4A-3A22-3A2-D2A22-2AD2-D3A20-3AD2(2-4A20-4A-5A3(20-10A)20-5A-4A20-4A2(2-D3A20-3AD))2-4A20-4A-5A20-5AI4A20-4A2I4A20-4AI5A20-5A-4A20-4A2(2-D3A20-3AD)2-4A20-4A-5A3(20-10A)20-5A-4A20-4A2-D3A20-3AD2-E3A20-3AE2-4A20-4A-5A3(20-10A)20-5A-4A20-4A2-E3A20-3AE3-H2A20-2AH3-4A20-4A-5A20-5AB4A20-4A2B4A20-4AB5A20-5A-4A20-4A3-H2A20-2AH5-G22AG5-26A2-5A20C70A20C5A2-26A5-G22AG7-22A7-24A3-5A20-6AB2A22B2(2AB)2A22B2AB6A20-5A3-24A7-22A4-
