model
size = 19 32 16, scale = 0.05, origin = -y
material 
  colors = A:#2A1F15 B:#CA7A2C
voxels
40-15A3-17A2-17A44-4A15-4A16-2A17-2A986-A4-A14-4A564-2A4-2A11-3A2-A-A12-6A525-3(A6-A11-)2A4-2A3(505-3(A6-A11-)A6-A)159-17A-76A-17A215-4(A6-A11-)A6-A178-B15-B-20A3(17-2A)17-A-A15-A3(2-17A)2-7A3-7A4-ABA7-ABA24-15A8-B5-B12-B5-B11-3A3-AB2(11-2A4-2A)2(11-A6-A)234-20A2(17-2A)16-2A-2A14-4(A2-A15-)A2-A6-3A6-A2-2A2-9A2-2A2-17A3-15A7-A6-2A11-A5-A11-3A3-3A10-2A4-2A291-20A17-2A16-2A-A15-A2-2A14-A2-A15-A3-A14-A3-5(A13-A4-)15A7-2A5-2A11-A5-A11-A-A3-3A11-2A3-2A13-2A-A16-3A255-20A17-A-3(A15-A2-)A15-A3-A14-A3-5(A13-A4-)3A3-4A2-3A7-2A5-2A11-A5-A11-3A3-3A11-2A3-2A13-2A-2A15-3A255-20A17-A-3(A15-A2-)A15-A3-A14-A3-5(A13-A4-)3A4-3A2-3A7-AB-A3-BA11-B5-B11-ABA3-ABA309-20A2(17-2A)16-2A-7(A15-A2-)A13-3A3-15A9-A335-B15-B-20A3(17-2A)16-A2-A15-A2-A7-9A2-17A2-3A10-4A2-5A2-10A2-17A3-13A10-A374-17A-A17-2A16-40A-4A4-9A2-5A2-A16-2A12-5A2-10A7-2A17-A18-A373-
