model
size = 32 23 3, scale = 0.05, origin = -y
material 
  colors = A:#F60 B:#EEE C:#BBB D:#111
voxels
365A3DA3D25A2DA4D25A3D2(AD)26AD3AD26A2(DA)3D25A4DA2D25A3DA3D60A-30A3-114A-3A-39A2(-8A)-41A-15A-36A2C5AC2A2C2A4C2A3C3A3C9AB6AC5AC3ACA2(C3A)4CABA2C26A2CB13A2C4A2C10AB4AC3A2C2AC5AC12AB26A3C2ABA2C11A2C4A2C9AB8A3C119A-69A-12A-4A-12A3-78A199-C25-2B4-2(2B2-)4B2-2(3B3-)2B4-2B2-2B-3B3-5B-5B2-5B-6B-2B7-2B4-2(2B2-)4B2-B2-2B5-2(3B3-)2B2-4B2-2B-4B2-3B3-3B4-2B2-4B2-2B-2B4-2B2-B-2B2-B2-5B-5B2-2B4-5B-5B3-3B2-4B4-4B2-3B3-3B258-
