model
size = 22 25 27, scale = 0.05, origin = -y
material 
  colors = A:#222 B:#111 C:#444 D:#555 E:#EEE
voxels
242-B20-3B18-2B-B18-B2-B18-B441-B20-3B18-4B18-2B-2(B18-B2-)B18-B376-B18-B-2B3(18-4B)18-2B-2(B18-B2-)2B16-2B3-2(B16-B4-)B16-B246-C16-C3-2(2C16-2C2-)2B16-2B5(2-B18-B)2-2B16-2B3-B16-B2(4-2B14-2B)4-3B12-3B5-2B12-2B7-2B10-2B2(8-3B)9-2B8-2B139-2(2C14-2C4-)2C14-2C3-2C16-2C2(2-2B16-2B)3(2-B18-B)3-B16-B3(4-2B14-2B)2(4-3B12-3B)5-3B10-3B7-2B10-2B9-2B8-2B10-2B2A4-2A2B11-10B15-4B78-2C12-2C6-2C12-2C5-3(2C14-2C4-)5(B16-B4-)2(2B14-2B4-)2B14-2B5-B14-B6-2B12-2B6-3B10-3B7-2B10-2B9-2B8-2B10-2BA6-A2B11-B8AB13-8B16-4B57-2C10-2C7-3C10-3C3(6-2C12-2C)6-C14-C5-5(2B14-2B4-)2B14-2B5-B14-B3(6-2B12-2B)7-2B10-2B2(8-3B)9-2BA6-A2B11-B2A4-2AB13-8A15-6A58-3C4-3C10-4C6-4C2(8-2C10-2C)7-3(2C12-2C6-)B14-B5-2B14-2B4-2B14-2B5-3(B14-B6-)3(2B12-2B6-)2B12-2B7-3B8-3B9-2BA6-A2B11-B2A4-2AB13-8A15-6A62-2C16-10C11-4C4-4C9-4C6-4C2(8-3C)8-2C10-2C7-2(2C12-2C6-)5(2B12-2B6-)3B10-3B7-2B10-2B2(8-3B)2(8-B12-B)9-2BA6-A2B11-B2A4-2AB13-8A15-6A17-4A82-8C13-10C11-4C4-4C9-2(3C8-)2(2C10-2C8-)2C10-2C7-3B10-3B6-3B10-3B7-3(2B10-2B8-)3B8-3B9-2B8-2B10-2BA6-A2B12-2A4-2A14-2A4-2A13-B2A4-2AB13-8A15-6A17-4A106-4C16-8C13-3C4-3C11-3C6-3C10-2C8-2C9-2(2C10-2C8-)2(2B10-2B8-)3B8-3B9-2B8-2B9-3BA6-A3B9-2BA6-A2B11-B2A4-2AB12-B2A4-2AB13-2(2A4-2A14-)8A15-6A17-4A149-6C14-4C2-4C11-3C6-3C3(10-2C8-2C)10-BA8-AB2(10-2B8-2B)10-2BA6-A2B10-2B2A4-2A2B11-B2A4-2AB13-2(3A2-3A14-)8A15-6A16-6A17-4A171-6C15-8C13-3C4-3C11-3C6-3C2(10-2C8-2C)10-BA8-AB10-2B8-2B11-BA6-AB12-BA6-AB13-2A4-2A14-3A2-3A15-2(6A16-)6A17-4A216-4C16-8C14-8C13-3C4-3C11-3C6-3C11-C8-C12-B8-2(B12-BA6-A)B12-B2A4-2AB13-2A4-2A15-2A2-2A2(16-6A)17-4A260-4C16-8C14-3C2-3C13-2(2C6-2C12-)B8-2(B12-BA6-A)B13-2A4-2A14-2A4-2A15-2A2-2A2(16-6A)17-4A281-6C15-3C2-3C13-3C4-3C12-2C6-2C3(12-BA6-AB)13-2A4-2A14-3A2-3A15-6A16-6A17-4A304-4C16-8C14-2C4-2C13-2C6-2C2(12-BA6-AB)13-2A4-2A14-2A4-2A15-2A2-2A2(16-6A)17-4A305-2C18-6C15-3C2-3C13-3C4-3C13-2(A6-A14-)2A4-2A14-3A2-3A15-6A16-6A17-4A347-6C15-3C2-3C14-2C4-2C14-A6-A2(14-2A4-2A)15-2A2-2A2(16-6A)17-4A348-4C17-6C15-2C4-2C2(14-2A4-2A)15-2(2A2-2A16-)6A16-6A369-4C17-6C15-3C2-3C14-2A4-2A14-3A2-3A15-2A2-2A2(16-6A)17-4A371-2C18-6C16-2C2-2C16-A4-A16-2A2-2A3(16-6A)17-4A391-6C16-2C2-2C2(16-2A2-2A)2(16-6A)17-4A413-2(6C16-)2A2-2A2(16-6A)17-4A436-4C18-C2EC17-2(6A16-)6A18-2A437-3(4B18-)4B19-2A482-2D20-2D362-
