model
size = 13 32 28, scale = 0.05, origin = -y
material 
  colors = A:#222 B:#111
voxels
57-4B8-6B6-3B2-3B5-2B4-2B5-2B4-3B2(3-2B6-2B)4-B6-2B4-2(2B5-)B2(5-2B)4-B7-B4-B8-4B11-B243-4B8-6B7-7B5-3B-4B2(5-8B)5-7B58-6B5-50B2-11B2-5B-5B2-4B-B-4B2-5B-5B3-10B3-9B4-9B2(5-8B)6-6B7-6B73-3B9-B3-2B7-B4-2(B6-)2(B5-B6-)B5-7B56-13B3(11-2B)10-4(B2-B9-)2(B3-B8-)B3-B7-2(B5-B6-)B6-B4-B7-6B74-2B9-2B2-2B7-B4-2(B6-)2(B5-B6-)B5-7B55-14B4(11-2B)10-2(B2-)4B3-2(B2-)6B-B2-B3-4B2-2(B3-)3B2-B3-B8-B3-B7-2(B5-B6-)B6-B4-B7-6B74-A10-5A8-A4-3(A6-A5-)A7-6A43-6B6-B6-7B4(11-2B)2-7B2-2B2-B4-2B2-2(B-)B6-A2(B2-)B4-B-B2-2(B3-)B-2(B3-)3B2-2(B3-B8-)B4-B6-B5-2(B6-)2B3-B9-3A63-A10-4A8-A4-A7-A4-A6-A5-A6-2A4-A8-5A42-12A-A10-A-A3(11-2A)2-7A2-2(2A-A7-A-)2A2-A6-2(A-)A2-A5-2(A-)2(A3-)A-A2-A4-A-A2-A3-A4-2(A3-)A8-A4-A7-A4-2(A6-)A4-A8-5A61-A11-4A8-A4-A7-A4-A6-2A4-A7-3A2-A10-3A42-12A2(-A10-A)-A2-2A7-2A2-7A2-3(2A-A7-A-)2A2-A6-3(A-)A6-2(A-)A2-A5-2(A-)2(A3-)2(A2-)A3-3A2-2(A3-A8-)A4-A7-2(A5-)A7-5A62-A10-4A8-A4-A7-A4-A6-A5-A7-3A2-A10-3A30-7A5-A7-4A-A10-A-A2-2A6-2(A-)A2-5A2-4(2A-A7-A-)2A2-A7-2A2(-A)6-2(A-)A2-A5-2(A-)2(A3-)2(A2-)A3-3A2-2(A3-A8-)A4-A7-2(A5-)A7-5A61-A10-5A8-A4-2(A6-A5-)A6-3A3-A9-4A30-11A2(-A10-A)-A2-7A2-4(2A-A7-A-)2A-A8-3A2-A7-2A-A2-A5-2(A-)A3-A4-2(A-)A4-2A-2(A2-)A5-A2-2(A3-A8-)A4-A7-2(A5-)A7-5A61-2A9-2A2-A8-A4-2(A6-A5-)A6-2A4-A8-5A17-8A4-A8-3A-A10-A-A2-7A2-2(2A-A7-A-)4A2(7-A-2A-A)8-3A2-A7-3A3-A6-2A-A3-A4-2(A-)A4-A3-2(A-)A5-3A-A3-A8-A3-2A7-A4-2(2A5-)7A7-5A73-4A8-A4-4(A6-A5-)A6-7A5-A11-A-9A-A10-A-A2-6A2-2(A-)A6-A2-2(2A-A7-A-)4A7-A-2A-A8-2A-2A8-2A-3A7-2A-4A6-2A-3A-2A3-A-A2(2-3A)-A3-4A5-A4-4A4-A5-7A7-5A98-5A7-2(A5-A6-)A6-3(A4-A7-)A3-A-8A3-A9-A-A2-6A2-2(A-)A6-A2-2(2A-A7-A-)4A7-2(A-)2A8-2A-2A8-2A12-A3-A12-A13-3A3-2A6-7A7-5A9-4A111-4A8-A4-A6-2(A5-)3(A7-A4-)A7-A3-A8-A3-A9-A2-A-6A2-A2-2A6-3(A-)A6-A2-2(2A-A7-A-)A-A9-2A11-2A212-5A7-2(A5-)3(A7-A4-)A8-2(A2-A9-)A2-A-5A3-A2-2A5-2(A2-)2A6-A2(-2A)7-3A-2A7-2(A-)2A7-2A12-A214-4A7-2A4-2(A6-)A4-A7-A4-A8-3(A2-A9-)A-A3-3A4-A-A2-A3-2A2-A2-2A6-A-A2-2A7-3A-2A7-2A2-2A7-2A12-A214-3A8-2A3-2A2(6-A)4-A7-A3-2(A9-A2-)A9-A-A11-2A3-3A5-2A2-A3-2A2-2(3A-A6-A-)A2(2-2A7-2A)12-A215-A10-5A7-2(A5-)A7-A4-A8-2(A2-A9-)A-A11-2A3-5A3-2A2-A2(3-2A)2-A5-3(A-)A6-3(A-)A2(7-2A2-2A)8-2(A3-2A7-)A11-2A188-3A8-2A3-2A5-A7-A4-A8-2(A2-A9-)A-A11-2A3-5A3-2(2A2-A5-A2-)4A6-3(A-)A7-2A2(-A)7-2A2-2A7-2A3-2A7-A3-A-A6-A4-2A6-A4-3A4-2A5-3A2-2A8-4A163-5A7-A5-2A4-A7-A4-A8-A2-A9-A-A11-2A3-5A3-2A2-A5-2(A2-2A-A6-)2(A-)3A7-2A2(-A)7-2A2-2A7-2A2(3-2A7-A)3-A-A6-A4-A-A4-2A5-2A4-2A6-6A8-4A163-5A7-A5-2A4-A7-A4-A8-A-2A9-A-A4-3A4-2A2(3-A)3-3A-A5-A2-2A-A6-A2-4A3(7-2A2-2A)7-2A3-A7-2A11-2A4-2(2A5-)2A4-2A5-3A2-2A8-3A-A9-3A163-5A7-2(A5-)A7-A3-A9-A2-A3-2A5-3A2-A2-2A3-2(3A-A5-A2-)A-2A7-2(A-)2(2A7-2A2-)2A8-A3-2A7-A3-2A6-2A3-3A5-2A4-2A5-A12-A8-A2-2A8-4A176-5A7-2(A5-)A7-A3-2(A4-)A2-A3-A-A4-A-A2-2(A3-)3A-2(A5-A2-2(A-))A6-2(2A2-2A7-)2A2(3-2A7-A)3-A-A5-2A4-2(2A5-)2A4-A7-2A2-2A8-4A11-A177-5A7-2(A5-)A7-2(A4-A3-)A2(-2A)2(2-A)-A2(5-A-A3-2A)6-2A3-2A6-2A3-A7-2A16-2A7-A4-2A6-A4-2(2A5-)2A4-A6-2A3-2A7-3A-2A8-4A190-3A9-A3-2A2(6-A)4-2(A3-)A4-A2-A-2A2-A3-A-A4-A-A3-2A5-A-A2(3-2A6-2A)51-2(A5-)2A5-2A4-A7-2A2-2A8-4A10-3A202-5A8-A4-2(A6-)A4-A2-4A2(-A4-A)-A3-2A5-A-A3-2A6-2A89-A8-A2-2A8-4A11-A216-5A8-A4-A6-A-3A2-A5-2A3-A-A5-2A4-2A359-2A9-2A2-2A7-A-2A-A6-3A2-3A384-4B9-3B-B7-2B2-2B6-2(2B4-)3B2(4-2B)6-2B3-2B6-2B3-3B5-2B4-2B5-2B4-3B4-2B5-2B4-2B5-3B2-3B6-6B8-4B198-
