model
size = 19 32 3, scale = 0.05, origin = -y
material 
  colors = A:#FFF B:#800080 C:#A3A3A3 D:#000 E:#FAFAFA F:#F2CA05
voxels
365-3(3B3-3B10-)3(3A3-3A10-)3(3C3-3C10-)2(3D3-3D10-)3D3-3D25-9(A18-E18-)A18-E3(3B3-)A3(3B3-)E3(3B3-)4A2(3-3A)3-E3(3A3-)4A2(3-3A)3-E3(3C3-)A3(3C3-)E3(3C3-)A3(3D3-)E3(3D3-)A3(3D3-)F395-3(3B16-)3(3A16-)3(3C16-)2(3D16-)3D19-
