model
size = 17 21 17, scale = 0.05, origin = -y
material 
  colors = A:#89916B B:#EEA9A9 C:#DB4D6D D:#BBB E:#FFF F:#E16B8C G:#AAA H:#111 I:#DDD J:#0D5661
voxels
119-6(3C14-)3C201-3(3C14-)3C5(15-FG)4(14-3C)133-3C14-3C3(15-FG)2(15-ED)15-C2(D15-E)D3(15-FG)2(14-3C)116-3C15-FG9(15-ED)14-2HD15-ED15-FG14-3C67-5(AB)A5-AB9-AB3-CB11-B2A-3C12-B2-FG2(12-A2-ED12-B2-ED)12-I2-ED12-B2-ED12-A2-ED12-B2-E2(D11-3A2H)D11-3A-ED12-B2-FG12-A-3C11-2B-CB11-B2A2-AB9-AB5-5(AB)A6-5(BA)B5-BA9-BA3-CA11-A2B2-FC12-A2-EG12-B2-ED12-A2-ED12-2D-ED12-2I-ED12-B2-ED12-A2-ED12-B2-ED12-A-2(2HD11-3A)-ED11-3A-ED12-A2-EG12-B2-FC11-2A-CA11-A2B2-BA9-BA5-5(BA)B6-5(AB)A5-AB9-AB3-CB11-B2A2-FC12-B2-EG12-A2-ED12-2D-ED12-2I-ED12-B2-ED12-A2-ED12-B2-ED12-A-2HD12-B-2H3(D11-3A-E)D12-B2-EG12-A2-FC11-2B-CB11-B2A2-AB9-AB5-5(AB)A6-5(BA)B5-BA9-BA3-CA11-A2B2-FC12-A2-EG12-B2-ED12-2D-ED12-2I-ED12-A2-ED12-B2-ED12-A-2HD12-B-2HD12-A2-3(ED11-3A-)ED12-A2-EG12-B2-FC11-2A-CA11-A2B2-BA9-BA5-5(BA)B6-5(AB)A5-AB9-AB3-CB11-B2A2-FC11-2B2-CG12-A2-ED12-2D-ED12-2I-ED15-ED12-A2-ED14-AJD12-A2-ED15-3(ED11-3A-)ED15-CG12-A2-FC11-2B-CB11-B2A2-AB9-AB5-5(AB)A6-5(BA)B5-BA9-BA3-CA11-A2B2-FC12-A2-EG12-B2-ED12-2D-ED12-2I-ED12-A2-ED12-B2-ED12-A-2HD12-B-2HD12-A2-3(ED11-3A-)ED12-A2-EG12-B2-FC11-2A-CA11-A2B2-BA9-BA5-5(BA)B6-5(AB)A5-AB9-AB3-CB11-B2A2-FC12-B2-EG12-A2-ED12-2D-ED12-2I-ED12-B2-ED12-A2-ED12-B2-ED12-A-2HD12-B-2H3(D11-3A-E)D12-B2-EG12-A2-FC11-2B-CB11-B2A2-AB9-AB5-5(AB)A6-5(BA)B5-BA9-BA3-CA11-A2B2-FC12-A2-EG12-B2-ED12-A2-ED12-2D-ED12-2I-ED12-B2-ED12-A2-ED12-B2-ED12-A-2(2HD11-3A)-ED11-3A-ED12-A2-EG12-B2-FC11-2A-CA11-A2B2-BA9-BA5-5(BA)B6-5(AB)A5-AB9-AB3-CB11-B2A-3C12-B2-FG2(12-A2-ED12-B2-ED)12-I2-ED12-B2-ED12-A2-ED12-B2-3(ED11-3A-)ED12-B2-FG12-A-3C11-2B-CB11-B2A2-AB9-AB5-5(AB)A55-3C15-FG11(15-ED)15-FG14-3C116-3C14-3C3(15-FG)2(15-ED)15-C2(D15-E)D3(15-FG)2(14-3C)133-3(3C14-)3C5(15-FG)4(14-3C)201-6(3C14-)3C133-
