model
size = 31 26 31, scale = 0.05, origin = -y
material 
  colors = A:#F00 B:#0F6 C:#F09 D:#FF0 E:#0FF F:#30F G:#93F
voxels
170-C27-C-3C-3(C24-3(C-))C26-C-C28-3C26-C5-C24-C-3C-C24-3(C-)C26-3C29-C432-3B26-3BD3B24-2B3D2B22-2CDBD-DBD2C20-C2(-DBD)-C20-2CDBD-DBD2C20-C-2BD-D2B-C22-2B3D2B22-2CD5BD2C20-C-DB3DBD-C20-2CDBD-DBD2C20-C-2B3D2B-C22-7B55-G-3G-G424-3B7-3B18-B2D7-2DB17-CBD9-DBC17-B2D7-2DB16-2CBDB7-BDB2C15-C3B7-3BC16-CB2D7-2DBC15-2CBD9-DB2C16-B2D7-2DB17-CBDB7-BDBC17-3B7-3B21-7A21-E-G7AG-E21-3(G-)G24-G-3G-G391-2(2B13-)CBD13-DBC2(13-2B)13-C2D13-2D2(C12-C-D13-D-)C12-C2D13-2DC2(13-2B)13-CBD13-DBC13-2BA12-2B16-3A7-3A17-E3A7-3AE17-E-G7AG-E20-G7AG54-7F266-11(B17-B12-)BA15-AB14-A13-A14-E-2A11-2A-E14-2E2A7-2A2E18-2A7-2A22-7A23-F7AF23-3F-3F234-B19-B9-7(CB19-BC8-)CB19-BC9-2(B19-B10-)B19-B11-2A15-2A11-E2A15-2AE11-E-2A11-2A-E14-2A11-2A16-2E2A7-2A2E16-2E11A2E20-2F3-2F171-B21-B7-2(CB21-BC6-)CD21-DC192-CD21-D2(C6-CB21-B)C7-B21-B9-A19-A9-E2A17-2AE10-EA15-AE13-2(A15-)2A11-2A16-4A7-4A19-F7AF23-2F3-2F139-5(B23-B6-)B23-B37-6(B23-B6-)BA21-AB8-A19-A9-EA19-AE9-EA17-AE11-A17-A12-EA15-AE12-E3A11-3AE14-2E11A2E19-4(F-)F107-2(B23-B5-5(CD23-DC4-)CD23-DC5-)B23-B7-A21-A7-EA21-AE7-EA19-AE9-A19-A10-EA17-AE10-E3A13-3AE12-2E13A2E16-E-9F-E104-2(B25-B3-CD25-DC126-CD25-DC3-)B25-B5-A23-A6-2A21-2A8-A19-A10-A19-A11-A17-A12-2A15-2A13-E15AE16-E2-2F3-2F2-E104-2(B25-B3-5(CD25-DC2-)CD25-DC3-)B25-B5-A23-A5-EA23-AE5-EA21-AE6-EA21-AE8-A19-A9-E2A17-2AE9-E-17A-E12-2E2-3F-F-3F2-2E133-5(B25-B4-)B25-B35-6(B25-B4-)B25-B5-A23-A5-EA23-AE6-A21-A7-EA21-AE8-A19-A9-E2A17-2AE9-E-6A5-6A-E12-2E-2F-5A-2F-2E20-5F448-2(B27-B2-)B27-B3-A25-A3-EA25-AE3-EA23-AE4-EA23-AE6-A21-A7-E2A19-2AE7-2E6A7-6A2E11-E2-2F7A2F2-E19-F5-F385-2(B27-B2-)B27-B-CD27-DC-B27-B3-A25-A4-A25-A5-A23-A6-A23-A7-A21-A8-2A19-2A10-5A9-5A13-E-F-9A-F-E18-F-5F-F384-B27-B-C2(D27-D2C)D27-DC-B27-B3-A25-A3-EA25-AE3-EA23-AE4-EA23-AE6-A21-A7-E2A19-2AE7-2E5A9-5A2E11-E-2F9A2F-E18-F-F3-F-F384-B27-B-CD27-DC31-CD27-D2CB27-BC2-A25-A3-EA25-AE4-A23-A5-EA23-AE6-A21-A7-E2A19-2AE8-E5A9-5AE12-E3-9A3-E18-4(F-)F384-B27-B-C2(D27-D2C)D27-DC-B27-B3-A25-A3-EA25-AE3-EA23-AE4-EA23-AE6-A21-A7-E2A19-2AE7-2E5A9-5A2E11-E-2F9A2F-E18-F-F3-F-F384-2(B27-B2-)B27-B-CD27-DC-B27-B3-A25-A4-A25-A5-A23-A6-A23-A7-A21-A8-2A19-2A10-5A9-5A13-E-F-9A-F-E18-F-5F-F446-2(B27-B2-)B27-B3-A25-A3-EA25-AE3-EA23-AE4-EA23-AE6-A21-A7-E2A19-2AE7-2E6A7-6A2E11-E2-2F7A2F2-E19-F5-F45-5(B25-B4-)B25-B35-8(B25-B4-)B25-B5-A23-A5-EA23-AE6-A21-A7-EA21-AE8-A19-A9-E2A17-2AE9-E-6A5-6A-E12-2E-2F-5A-2F-2E20-5F15-B25-B3-5(CD25-DC2-)CD25-DC3-B25-B3-7(CD25-DC2-)CD25-DC3-B25-B5-A23-A5-EA23-AE5-EA21-AE6-EA21-AE8-A19-A9-E2A17-2AE9-E-17A-E12-2E2-3F-F-3F2-2E40-B25-B3-CD25-DC126-CD25-DC3-B25-B3-CD25-DC188-CD25-DC3-B25-B5-A23-A6-2A21-2A8-A19-A10-A19-A11-A17-A12-2A15-2A13-E15AE16-E2-2F3-2F2-E43-B23-B5-5(CD23-DC4-)CD23-DC5-B23-B5-7(CD23-DC4-)CD23-DC5-B23-B7-A21-A7-EA21-AE7-EA19-AE8-EA19-AE10-A17-A11-E3A13-3AE12-2E13A2E16-E-9F-E74-5(B23-B6-)B23-B37-8(B23-B6-)BA21-AB8-A19-A9-EA19-AE10-A17-A11-EA17-AE12-A15-A13-E3A11-3AE14-2E11A2E19-4(F-)F449-B21-B8-B21-B7-CD21-DC7-B21-B9-A19-A9-E2A17-2AE9-E-A15-A-E12-2(A15-)2A11-2A15-E4A7-4AE18-F7AF23-2F3-2F451-B19-B9-CD19-DC8-CD19-DC9-B19-B11-2A15-2A11-E2A15-2AE12-E2A11-2AE14-E2A11-2AE17-2A7-2A18-2E11A2E20-2F3-2F483-B17-B11-CB17-BC10-CD17-DC11-BA15-AB14-A13-A15-E2A11-2AE16-E2A7-2AE17-2E2A7-2A2E19-F7AF22-F7AF23-3F-3F454-B13-B16-B13-B15-BD13-DB13-CBD13-DBC2(13-2B)16-3A7-3A17-E3A7-3AE17-E-G7AG-E21-7A24-7F25-F3-F487-2B9-2B18-2B9-2B17-C-DB7-BD-C16-C2DB7-B2DC17-3B7-3B21-7A21-E-G7AG-E21-G-3G-G584-3B23-C3-2BD2B3-C19-C-2BD-D2B-C19-2C-B5DB-2C18-C2-7B2-C52-7G647-C29-C-C27-5C27-3C293-
