model
size = 31 26 30, scale = 0.05, origin = -y
material 
  colors = A:#0089A7 B:#E83015 C:#000 D:#D0104C E:#FFB11B F:#00896C G:#0C4842
voxels
446-C5EC24-2E3C2E2(24-EC3FCE)675-7C2(24-7B)24-7C24-3(DC)D24-7C25-5E25-2E3C2E29-C549-3C7-3C2(18-3B7-3B)18-3C7-3C21-7A21-C2-7A2-C21-C5BC24-7B24-2C3FAC24-C5FC515-2C13-2C2(14-2B13-2B)14-3C12-2C16-3A7-3A17-C3A7-3AC17-C-C7AC-C20-C7AC2(22-E7BE)23-E5CE483-C17-C2(12-B17-B)12-2C15-2C14-A13-A14-2C2A11-2A2C14-BC2A7-2ACB16-C-2A7-2A-C18-CB7ABC20-CB7ABC21-C7BC23-C5EC451-C19-C2(10-B19-B)10-C19-C11-2A15-2A11-C2A15-2AC11-2B2A11-2A2B13-B2A11-2AB15-C-2A7-2A-C16-C-11A-C18-C9BC23-5C451-C21-C2(8-B21-B)8-C21-C9-A19-A9-C2A17-2AC9-2BA15-A2B11-BA15-AB13-B2A11-2AB14-B4A7-4AB15-C-CB7ABC-C19-9B448-C23-C2(6-B23-B)6-2C21-2C8-A19-A9-CA19-AC9-BA17-AB10-BA17-AB11-BA15-AB12-B3A11-3AB13-2C-11A-2C17-C9BC447-C23-C2(6-B23-B)6-C23-C7-A21-A7-CA21-AC7-BA19-AB8-BA19-AB9-BA17-AB10-B3A13-3AB11-BC-13A-CB16-C9BC446-C25-C2(4-B25-B)4-C25-C5-A23-A5-C2A21-2AC5-2BA19-A2B7-BA19-AB9-BA17-AB10-B2A15-2AB11-BC15ACB15-C11BC445-C25-C2(4-B25-B)4-C25-C5-A23-A5-CA23-AC5-BA21-AB6-BA21-AB7-BA19-AB8-B2A17-2AB9-2B17A2B12-C-C11BC-C443-C25-C2(4-B25-B)4-C25-C5-A23-A5-CA23-AC5-BA21-AB6-BA21-AB7-BA19-AB8-B2A17-2AB9-2B6A5-6A2B12-C-C3B5A3BC-C20-5C417-C27-C2(2-B27-B)2-C27-C3-A25-A3-CA25-AC3-BA23-AB4-BA23-AB5-BA21-AB6-B2A19-2AB7-2B6A7-6A2B10-BC-C2B7A2BC-CB18-C5EC416-C27-C2(2-B27-B)2-C27-C3-A25-A3-CA25-AC3-BA23-AB4-BA23-AB5-BA21-AB6-B2A19-2AB7-2B5A9-5A2B10-BC-CB9ABC-CB17-C2E3C2EC105-2(2D25-2D2-)2D25-2D157-3(C27-C2-)2(B27-B2-)2(C27-C3-A25-A3-CA25-AC3-BA23-AB4-BA23-AB5-BA21-AB6-B2A19-2AB7-2B5A9-5A2B10-BC-CB9ABC-CB17-CEC3FCEC105-2(2D25-2D2-)2D25-2D126-C27-C5(2-B27-B)2-)C27-C3-A25-A3-CA25-AC3-BA23-AB4-BA23-AB5-BA21-AB6-B2A19-2AB7-2B5A9-5A2B10-BC-CB9ABC-CB17-CEC3FCEC43-2(C27-C2-)3(2D25-2D2-)4(C27-C2-)6(B27-B2-)C27-C3-A25-A3-CA25-AC3-BA23-AB4-BA23-AB5-BA21-AB6-B2A19-2AB7-2B5A9-5A2B10-BC-CB9ABC-CB17-C2E3C2EC12-C27-C2-B27-B-2C27-3C2(2D25-2D2C)2D25-2D3C27-2C-9(B27-B2-)C27-C3-A25-A3-CA25-AC3-BA23-AB4-BA23-AB5-BA21-AB6-B2A19-2AB7-2B6A7-6A2B10-BC-C2B7A2BC-CB18-C5EC14-C25-C4-B25-B2-4C23-5C2(2DC23-C2D2C)2DC23-C2D5C23-4C2-9(B25-B4-)C25-C5-A23-A5-CA23-AC5-BA21-AB6-BA21-AB7-BA19-AB8-B2A17-2AB9-2B6A5-6A2B12-C-C3B5A3BC-C20-5C15-C25-C4-B25-B4-2C23-2C3-2(2DC23-C2D2-)2DC23-C2D3-2C23-2C9(4-B25-B)4-C25-C5-A23-A5-CA23-AC5-BA21-AB6-BA21-AB7-BA19-AB8-B2A17-2AB9-2B17A2B12-C-C11BC-C71-C25-C4-C25-C3-2(2D25-2D2-)2D25-2D3-8(C25-C4-)2(B25-B4-)C25-C5-A23-A5-C2A21-2AC5-2BA19-A2B7-BA19-AB9-BA17-AB10-B2A15-2AB11-BC15ACB15-C11BC134-2(2D25-2D2-)2D25-2D221-C23-C2(6-B23-B)6-C23-C7-A21-A7-CA21-AC7-BA19-AB8-BA19-AB9-BA17-AB10-B3A13-3AB11-BC-13A-CB16-C9BC135-2(2D25-2D2-)2D25-2D221-C23-C2(6-B23-B)6-2C21-2C8-A19-A9-CA19-AC9-BA17-AB10-BA17-AB11-BA15-AB12-B3A11-3AB13-2C-11A-2C17-C9BC448-C21-C2(8-B21-B)8-C21-C9-A19-A9-C2A17-2AC9-2BA15-A2B11-BA15-AB13-B2A11-2AB14-B4A7-4AB15-C-CB7ABC-C19-9B450-C19-C2(10-B19-B)10-C19-C11-2A15-2A11-C2A15-2AC11-2B2A11-2A2B13-B2A11-2AB15-C-2A7-2A-C16-C-11A-C18-C9BC24-3C454-C17-C2(12-B17-B)12-2C15-2C14-A13-A14-2C2A11-2A2C14-BC2A7-2ACB16-C-2A7-2A-C18-CB7ABC20-CB7ABC22-7B25-C3EC454-2C13-2C2(14-2B13-2B)14-2C13-2C16-3A7-3A17-C3A7-3AC17-C-B7AB-C20-B7AB2(22-C7BC)23-CE3CEC366-C3-C25-CG3-GC23-C2G3-2GC21-C3G3-3GC19-3C7-3C2(18-3B7-3B)18-3C7-3C20-C7AC20-C2-7A2-C21-7B23-C7BC23-EC3FCE24-EC3FCE399-C29-CAC27-C3AC26-C3AC25-C5BC23-2(C7BC22-)C7BC23-3(DC)D24-2C3E2C24-CE3CEC24-EC3FCE167-
