model
size = 19 32 19, scale = 0.05, origin = -y
material 
  colors = A:#909 B:#960 C:#963
voxels
370-A16-5A14-5A13-7A13-5A14-5A16-A454-3A14-7A11-9A10-9A9-2(11A8-)11A9-9A10-9A11-7A14-3A282-2(A18-)A3(17-2A)17-6A11-9A9-11A8-11A7-4(13A6-)13A7-11A8-11A9-9A12-5A304-2(A18-)A13-5BA11-9A9-11A7-13A6-13A5-4(15A4-)15A5-13A6-13A7-11A9-9A12-5A249-A37-A13-B4-A12-3B3-A9-9BA8-11A7-13A5-2(15A4-)15A3-2(17A2-)17A3-2(15A4-)15A5-13A7-11A9-9A13-3A225-3B16-3B15-5B13-7B12-7B10-11B7-13A5-15A4-15A3-6(17A2-)17A3-15A4-15A5-13A7-11A10-7A166-3B16-3B15-5B14-5B13-7B9-A2-7B9-2A4BA4B8-2A9B8-A11B7-13A5-15A3-3(17A2-)17A-19A-3(17A2-)17A3-15A5-13A7-11A9-9A14-A93-3B16-3B15-2(5B14-)5B13-2(7B12-)7B11-9B10-2B5A2B10-9B8-13B5-15A4-15A3-17A2-17A-95A-17A2-17A3-15A4-15A5-13A8-9A12-5A16-B18-B17-3B16-3B15-2(5B14-)5B13-2(7B12-)7B11-3(9B10-)2B5A2B9-11B7-13B5-15A3-2(17A2-)17A-95A-2(17A2-)17A3-15A5-13A7-11A11-5A15-3(3B16-)3B15-2(5B14-)5B13-2(7B12-)7B11-2(9B10-)9B9-2B7A2B8-11B7-13B5-15A3-17A2-17A-133A-17A2-17A3-15A5-13A7-11A10-7A15-B18-B17-3B16-3B15-2(5B14-)5B13-2(7B12-)7B11-3(9B10-)2B5A2B9-11B7-13B5-15A3-2(17A2-)17A-95A-2(17A2-)17A3-15A5-13A7-11A11-5A91-3B16-3B15-2(5B14-)5B13-7B3-A8-7B12-7B11-9B2-A7-2B5A2B2-A7-9B2-A5-13BA2(4-15A)3-17A2-17A-95A-17A2-17A3-15A4-15A5-13A8-9A12-5A148-3B16-3B2(15-4B)14-7B8-A3-5BCB8-A2-4BABC2B7-A2-9B7-A-11B6-14A5-15A3-3(17A2-)17A-19A-3(17A2-)17A3-15A5-13A7-11A9-9A14-A183-A23-3B11-2(A3-5B10-)2(A2-7B9-)A11B7-13A5-15A4-15A3-6(17A2-)17A3-15A4-15A5-13A7-11A10-7A281-B4-A12-3B3-A9-9BA8-11A7-13A5-2(15A4-)15A3-2(17A2-)17A3-2(15A4-)15A5-13A7-11A9-9A13-3A261-2(A18-)A6-A11-A5B-A10-9A9-11A7-13A6-13A5-4(15A4-)15A5-13A6-13A7-11A9-9A12-5A356-5A12-9A9-11A8-11A7-4(13A6-)13A7-11A8-11A9-9A12-5A395-3A14-7A11-9A10-9A9-2(11A8-)11A9-9A10-9A11-7A14-3A454-A16-5A14-5A13-7A13-5A14-5A16-A123-
