model
size = 32 32 6, scale = 0.05, origin = -y
material 
  colors = A:#FC0 B:#00D C:#FFD800 D:#F00 E:#83FF00 F:#FF9400 G:#00E5FF H:#8CA1FF
voxels
5-24A7-24A8-24A6-28A4-28A2-4A6(24-8A)2-11B2-7B2-2(8A-13B-8B-)2(8A-2(3B2-)3B6-3B-)3(8A-2(3B2-)3B-8B-)8A-2(3B2-)3B6-3B2(-8A-2(3B2-)3B-8B)-8A-2(3B2-)3B-7B2-6(8A24-)4A2-28A4-28A6-2(24A8-)24A6-28A4-28A2-4A6(24-8A)2-7B2-11B2-2(8A-8B-13B-)2(8A-3B6-2(3B2-)3B-)3(8A-8B-2(3B2-)3B-)8A-3B6-2(2(3B2-)3B-8A-8B-)2(3B2-)3B-8A2-7B-2(3B2-)3B-6(8A24-)4A2-28A4-28A6-3(24A8-)24A6-28A4-28A2-4A6(24-8A)2-7B2-11B2-2(8A-8B-13B-)2(8A-3B6-2(3B2-)3B-)3(8A-8B-2(3B2-)3B-)8A-3B6-2(2(3B2-)3B-8A-8B-)2(3B2-)3B-8A2-7B-2(3B2-)3B-6(8A24-)4A2-28A4-28A6-24A8-24A6-28A4-28A2-68A23(4D4F4C4E4G4H8A)4D4F4C4E4G4H68A2-3(28A4-)28A2-68A23(4D4F4C4E4G4H8A)4D4F4C4E4G4H68A2-28A4-28A6-24A8-24A6-28A4-28A2-4A6(24-8A)2-11B2-7B2-2(8A-13B-8B-)2(8A-2(3B2-)3B6-3B-)3(8A-2(3B2-)3B-8B-)8A-2(3B2-)3B6-3B2(-8A-2(3B2-)3B-8B)-8A-2(3B2-)3B-7B2-6(8A24-)4A2-28A4-28A6-24A8-24A4-
