model
size = 30 31 10, scale = 0.05, origin = -y
material 
  colors = A:#777 B:#FF0 C:#004 D:#007 E:#002 F:#005 G:#FF9B00 H:#A06000 I:#888
voxels
304-9H5-8H8-11B2-G9B5-2(G13B-G10B4-)2(G3B-)G3B9-3B4-2(G3B-)G3B2-7H3B3(4-2(G3B-)G3B2-10B)4-2(G3B-)G3B9-3B4-3(G3B-)G10B4-3(G3B-)G9B5-3(G3B-)G8B675-8A2(22-8I)22-8A830-3A6-3A2(18-3I6-3I)18-3A6-3A827-2A10-2A2(16-2I10-2I)16-2A10-2A412-2A26-6A22-10A18-6A2-6A14-6A6-2(6A10-)6A7-5A14-5A2(6-3A18-3A)5-4A18-4A3(4-3A20-3A)3-4A20-4A3(2-3A3-2E12-2E3-3A)-4A3-2E12-2E3-7A3(24-6A)24-7A22-10A18-14A14-8A2-8A10-2(8A6-)8A10-8A2-8A14-14A18-10A22-6A26-2A26-6A22-10A18-6A2E6A14-6A2E2C2E6A10-6A3E2CFD3E6A7-5A2E2CE2CFDE2C2E5A6-3A2E3CFEC2FDE3CF2E3A6-3A2E2C2FEC2FDE2C2F2E3A5-4A2EC3FEC2FDEC3FEC4A4-3A2(EC)3FEC2FDEC3FE3C2(2A4-3A2(EC)3FEC2FDEC3FECFC)2A3-4A2(EC)3FEC2FDEC3FECFC2(3A2-3AECFEC3FEC2FDEC3FECFE)3A2-3AECF3(EC2FD)ECFE3A-4AECF3(EC2FD)ECFE7A3(ECF3(DEC2F)DE2FDE6A)ECF3(DEC2F)DE2FDE7A2E3(DEC2F)DEC2E10A2E2(C2FDE)C2FD2E14A2EFDEC2FDECF2E8A2-8A3EC2FD3E8A6-8A2EFD2E8A10-8A2E8A14-14A18-10A22-6A26-2A26-6A22-10A18-14A14-18A10-22A7-2(24A6-)24A5-3(26A4-)26A3-3(28A2-)28A-240A2-26A6-22A10-18A14-14A18-10A22-6A26-2A26-6A22-10A18-6AFE6A14-6A2FDC2E6A10-6A2F3D3C2E6A7-5A2F5D5C2E5A6-3A2F7D7C2E3A6-3AF8D8CE3A5-4AF8D9C4A3(4-3AF9D9CEC2A)3-4AF9D9CEC3(3A2-3AF10D10CE)3A-4AF10D10CE7A3(F11D11CE6A)F11D11CE7A2F9D9C2E10A2F7D7C2E14A2F5D5C2E8A2-8A2F3D3C2E8A6-8A2FDC2E8A10-8AFE8A14-14A18-10A22-6A26-2A26-6A22-10A18-6A2-6A14-6A6-2(6A10-)6A7-5A14-5A2(6-3A18-3A)5-2A9H5-8H2A4-2A11B2-G9BA2(4-G13B-G10B)3-A2(G3B-)G3B9-3BA2-A2(G3B-)G3B2-7H3B2(A2-A2(G3B-)G3B2-10B)A-2A2(G3B-)G3B2-10B4A2(G3B-)G3B9-3B4A3(G3B-)G10B4A3(G3B-)G9BE4A3(G3B-)G8B-7A22-10A18-14A14-8A2-8A10-2(8A6-)8A10-8A2-8A14-14A18-10A22-6A286-9H5-8H8-11B2-G9B5-2(G13B-G10B4-)2(G3B-)G3B9-3B4-2(G3B-)G3B2-7H3B3(4-2(G3B-)G3B2-10B)4-2(G3B-)G3B9-3B4-3(G3B-)G10B4-3(G3B-)G9B5-3(G3B-)G8B274-
