model
size = 30 31 24, scale = 0.05, origin = -y
material 
  colors = A:#2A4A5B B:#4B4B4B C:#46647C
voxels
333-9B6-8B7-11B3-10B4-2(14B2-11B3-)2(4B-)4B10-3B4(3-2(4B-)4B3-10B)3-2(4B-)4B10-3B2(3-2(4B-)4B2-11B)3-2(4B-)4B2-9B785-2A24-2A2-2A24-2A603-2A22-2A4(4-CA22-AC)4-2A22-2A63-2A24-2A2(2-CA24-AC)2-2A24-2A543-2A22-2A4-CA22-AC124-CA22-AC4-2A22-2A3-2A24-2A2-CA24-AC62-CA24-AC2-2A24-2A484-3(A22-A5-CA22-AC184-CA22-AC3-CA24-AC122-CA24-AC-3A24-6A24-3A423-)A22-A5-CA22-AC184-CA22-AC3-CA24-AC122-CA24-AC-3A24-6A24-3A393-A22-A6-A22-A5-2A22-2A4-CA22-AC124-CA22-AC4-2A22-2A3-2A24-2A2-CA24-AC62-CA24-AC2-2A24-2A-3A24-6A24-3A393-A22-A6-A22-A5-2(2A22-2A4-)4(CA22-AC4-)2A22-2A4-2A22-2A3-2(2A24-2A2-)2(CA24-AC2-)2A24-2A2-3(2A24-2A-3A24-6A24-3A393-A22-A6-A22-A5-7(2A22-2A4-)2A22-2A3-5(2A24-2A2-))4(2A24-2A-3A24-6A24-3A363-2(A22-A6-)A22-A5-7(2A22-2A4-)2A22-2A3-5(2A24-2A2-))2A24-2A-3A24-6A24-3A306-2A14-2A10-4A14-4A7-5A14-5A6-3A18-3A6-A22-A5-7(2A22-2A4-)2A22-2A3-5(2A24-2A2-)2A24-2A-4A22-8A22-4A2-2A22-2A6-4A14-4A10-2A14-2A194-2A10-2A14-2(4A10-)6A10-6A2(8-4A14-4A)7-3A18-3A5-4A18-4A3(4-3A21-2A)3-3(3A22-3A2-)3A22-3A-4A22-7A3(24-6A)24-7A22-10A18-14A14-8A2-6A14-6A6-2(6A10-)4A10-4A14-2A10-2A110-A4-A22-3A4-3A18-5A4-5A16-4A6-4A3(16-2A10-2A)12-4(4A14-4A8-)4A14-4A5-4A21-3(3A2-3A22-)3A-4A5(22-8A)22-4A4-2(4A14-4A8-)6A10-6A12-4A6-4A2(16-5A4-5A)18-3A4-3A22-A4-A26-2A26-6A22-10A20-4A2-4A4(20-3A4-3A)18-2A10-2A16-2A10-2A11-7B10-6B7-7B12-5B4-9B12-6B3-7B14-6B3-4BA2B14-3A3B4(3-4BA2B14-6B)3-4BA2B14-3A3B2(3-4BA2B14-6B)3-4BA2B14-4B12-2(2A10-2A16-)2A10-2A18-3A4-3A20-4A2-4A2(20-10A)22-6A26-2A27-6(4A26-)4A23-3A4-3A20-3A4-3A13-9BA4-A8B7-10B7-7B4-12B7-8B3-9B10-8B3-4B-4B10-2A3-3B4(3-4B-4B10-8B)3-4B-4B10-2A3-3B2(3-4B-4B10-8B)3-4B-4B10-6B14-2(3A4-3A20-)3A4-3A23-4(4A26-)4A266-4A26-4A16-9B-4A-8B7-11B3A10B4-14B2A11B3-12B4-11B3-4B-4BA2B4-3A5-3B4(3-4B-4BA2B4-A10B)3-4B-4BA2B4-3A5-3B2(3-4B-4BA2B4-11B)3-4B-4BA2B4-9B17-2(4A26-)4A466-9B6-8B7-11B3-10B4-14B2-11B3-14B2A11B3-2(4B-)4B2A8-3B4(3-2(4B-)4B2A-10B)3-2(4B-)4B2A8-3B2(3-2(4B-)4B2A11B)3-2(4B-)4B2A9B244-
