model
size = 30 31 9, scale = 0.05, origin = -y
material 
  colors = A:#2A4A5B B:#959595 C:#4B4B4B D:#E3E3E3 E:#5E5E5E F:#BBB G:#46647C
voxels
431-8A2(22-8G)22-8A830-3A6-3A2(18-3G6-3G)18-3A6-3A827-2A10-2A2(16-2G10-2G)16-2A10-2A412-2A26-6A22-10A18-6A2-6A14-6A6-2(6A10-)6A7-5A14-5A2(6-3A18-3A)5-4A18-4A3(4-3A20-3A)3-4A20-4A3(2-3A3-2E12-2E3-3A)-4A3-2E12-2E3-7A3(24-6A)24-7A22-10A18-14A14-8A2-8A10-2(8A6-)8A10-8A2-8A14-14A18-10A22-6A26-2A26-6A22-10A18-6A2E6A14-6A2E2B2E6A10-6A3E2BFD3E6A7-5A2E2BE2BFDE2B2E5A6-3A2E3BFEB2FDE3BF2E3A6-3A2E2B2FEB2FDE2B2F2E3A5-4A2EB3FEB2FDEB3FEB4A4-3A2(EB)3FEB2FDEB3FE3B2(2A4-3A2(EB)3FEB2FDEB3FEBFB)2A3-4A2(EB)3FEB2FDEB3FEBFB2(3A2-3AEBFEB3FEB2FDEB3FEBFE)3A2-3AEBF3(EB2FD)EBFE3A-4AEBF3(EB2FD)EBFE7A3(EBF3(DEB2F)DE2FDE6A)EBF3(DEB2F)DE2FDE7A2E3(DEB2F)DEB2E10A2E2(B2FDE)B2FD2E14A2EFDEB2FDEBF2E8A2-8A3EB2FD3E8A6-8A2EFD2E8A10-8A2E8A14-14A18-10A22-6A26-2A26-6A22-10A18-14A14-18A10-22A7-2(24A6-)24A5-3(26A4-)26A3-3(28A2-)28A-240A2-26A6-22A10-18A14-14A18-10A22-6A26-2A26-6A22-10A18-6AFE6A14-6A2FDB2E6A10-6A2F3D3B2E6A7-5A2F5D5B2E5A6-3A2F7D7B2E3A6-3AF8D8BE3A5-4AF8D9B4A3(4-3AF9D9BEB2A)3-4AF9D9BEB3(3A2-3AF10D10BE)3A-4AF10D10BE7A3(F11D11BE6A)F11D11BE7A2F9D9B2E10A2F7D7B2E14A2F5D5B2E8A2-8A2F3D3B2E8A6-8A2FDB2E8A10-8AFE8A14-14A18-10A22-6A26-2A26-6A22-10A18-6A2-6A14-6A6-2(6A10-)6A7-5A14-5A2(6-3A18-3A)5-4A18-4A4-3A20-3A4-2A11C-9C3A4-2A11C-8C-3A3-3A10C2-8C-4A2-3A22-2(3A2-3A3(3C-)3C7-)3A-4A3(3C-)3C7-7A3(4(-3C)8-6A)-3(2C2-)2C9-7A22-10A18-14A14-8A2-8A10-2(8A6-)8A10-8A2-8A14-14A18-10A22-6A346-11C-9C9-11C-8C10-10C2-8C40-6(3(3C-)3C15-)3(2C2-)2C282-
