model
size = 30 31 24, scale = 0.05, origin = -y
material 
  colors = A:#777 B:#39C C:#F3C D:#F6F E:#888 F:#FCC G:#FFF H:#F3F I:#FF3 J:#FCF K:#FF0 L:#FF6 M:#F90 N:#F66 O:#FFC P:#FC6 Q:#FC9 R:#FF9 S:#F0C T:#F09
voxels
154-D7CG2-2(H2C6-)C9BC-L3B4-D2BH5-C2BC5D3BP-O2BC2-J3B5-L2BMJ6-K2B2-C2BG-3B6-2(DBC)6-2BK2-6BL6-CBKO3BI4-DBN3-4BM7-CBF-K3BT3-GBQ3-H3B8-CBF3-3BH2-GBQ2-F4BH7-CBF4-C3B-NBD2-6BK6-HBG5-G2BGCBR-3BI-3BL5-J2B6-IBK2BI-2BG3-3B6-3BI5-F3BK2BC4-J2BC5-F11B19-I9B10-NPBK9-I3FI12-IJ2B5-JNG21-BI3-DBIGBK-2BC3BL-2B2CBCH4B2M2-CG2-2BLBR-BG-C-BH3(2-B)O3-DBI-2B2(-BC)-FK-C3(2-B)C4-F2-2B2(-CB)-BQ-B2-BJ-BM-CB6-2BF-GB-RB-BC-BO-BP-CB-DB5-2BF2-IC2-C-BH2-3CH2-NCHCL4-BG28-BK-SJ26-CGH624-2A24-2A2-2A24-2A603-2A22-2A4(4-EA22-AE)4-2A22-2A63-2A24-2A2(2-EA24-AE)2-2A24-2A543-2A22-2A4-EA22-AE124-EA22-AE4-2A22-2A3-2A24-2A2-EA24-AE62-EA24-AE2-2A24-2A484-3(A22-A5-EA22-AE184-EA22-AE3-EA24-AE122-EA24-AE-3A24-6A24-3A423-)A22-A5-EA22-AE184-EA22-AE3-EA24-AE122-EA24-AE-3A24-6A24-3A393-A22-A6-A22-A5-2A22-2A4-EA22-AE124-EA22-AE4-2A22-2A3-2A24-2A2-EA24-AE62-EA24-AE2-2A24-2A-3A24-6A24-3A393-A22-A6-A22-A5-2(2A22-2A4-)4(EA22-AE4-)2A22-2A4-2A22-2A3-2(2A24-2A2-)2(EA24-AE2-)2A24-2A2-3(2A24-2A-3A24-6A24-3A393-A22-A6-A22-A5-7(2A22-2A4-)2A22-2A3-5(2A24-2A2-))3(2A24-2A-3A24-6A24-3A363-2(A22-A6-)A22-A5-7(2A22-2A4-)2A22-2A3-5(2A24-2A2-))2A24-2A-3A24-6A24-3A386-2(A6-A22-)A5-7(2A22-2A4-)2A22-2A3-5(2A24-2A2-)2A24-2A-3A24-6A24-3A306-2A14-2A10-4A14-4A7-5A14-5A6-3A18-3A29-A5-7(2A22-2A4-)2A22-2A3-5(2A24-2A2-)2A24-2A-4A22-8A22-4A2-2A22-2A6-4A14-4A10-2A14-2A194-2A10-2A12-D3C12-4AH2C6-C4B12-3AD2BH5-C2BC2D14-J3B5-L2BMJ2A16-BA5-DBC2-C18-2A4-CBK20-4A3(3-CBFA21-2A)3-HBG22-3A2-J2B22-3A2-A2B22-C2A2-AFB22-3A-3AI23-6A24-5AJ24-I3ADB24-2M2ACG24-O3ADBI23-C4AF2A20-ACB6A2BFA14-A2-ADB2A2-A2BF2A14-2ANCHCL4-BG5A10-6A7-BK-SJ2A10-4A10-CGH-2A10-2A110-A4-A22-3A4-3A18-5A4-5A12-D3C10-4A2-H2C6-C4B12-2A-D2BH5-C2BC2D12-2AJ3B5-L2BMJ2-2A11-A2-B6-2(DBC)A17-A5-CBKO2B17-2A5-CBFAKB16-3A5-CBF3A17-2A5-CBF4A17-A5-HBGA21-3A2-J2B22-3A2-A2B22-C2A2-AFB22-3A-3AI23-7A23-5AJN23-I3ADBI23-2M2ACGA23-O3ADBI23-C2A2-F-A2BA14-ABMACB6-2BFA14-ACBADB5-2BF2A14-2ANCHCL4-BG3-4A6-4A11-BK-SJ5A4-5A12-CGH-5A4-5A18-3A4-3A22-A4-A26-2A26-6A22-10A20-4A2-4A14-D5C8-2A4-H2C6-C6B9-A3-D2BH5-C2BC4D9-B2-J3B5-L2BMJ4-2A8-B-3B6-2(DBC)-2A11-3BL6-CBKO3BIA12-BM7-CBF-K3BT12-B8-CBF3-3B12-BH7-CBF4-C13-2BK6-HBG4A14-3BL5-J2B4A14-A3B6-3BI2A14-AJ2BC5-F5B14-4A7-I4B14-ANPBK7-2AIF14-AIJ2B5-JNG3A14-4ABI3-DBIGBKA14-H4B2M2-CG-A2BL14-AB2ABO3-DBIA2BA14-AB2ABC4-F2-2B-CB10-BJ-BM-CB6-2BF-GB10-BP-CB-DB5-2BF2-IC10-CH2-NCHCL4-BG5-3A4-3A13-BK-SJ2(2-4A)14-CGH3-10A20-10A22-6A26-2A27-2(4A26-)4A17-D7CG2A2(H2C6-)C9BCAL3B4-D2BH5-C2BC5D3BPAO2BC2-J3B5-L2BMJ6-K2B2AC2BG-3B6-2(DBC)3-3A4-A6BL6-CBKO3BI-3A4-2A4BM7-CBF-K3BT3A4-2AH3B8-CBF3-3BH2A4-AF4BH7-CBF4-C3BA4-A6BK6-HBG4-AG10-IA3BL5-J2B4-2A10-2A-3B6-3BI2-2A10-2A-J2BC5-F7B10-2A11-I6B10-2A-NPBK9-I3F10-2A-IJ2B5-JNG3-2A10-2A4-BI3-DBIGBK-2B10-BCH4B2M2-CG2-2BLBR10-BA-B2-BO3-DBI-2B-BC10-BA-B2-BC4-F2-2B-CBACB-BQ-B2ABJ-BM-CB6-2BF-GBARB-BC-BOABP-CB-DB5-2BF2-IC2AC-BH-A3CH2-NCHCL4-BG8-4A16-BK-SJ5-4A17-CGH6-2(4A26-)4A137-D7CG2-2(H2C6-)C9BC-L3B4-D2BH5-C2BC5D3BP-O2BC2-J3B5-L2BMJ6-K2B2-C2BG-3B6-2(DBC)6-2BKA-6BL6-CBKO3BI4-DBNA2-4BM7-CBF-K3BT3-GBQA2-H3B8-CBF3-3BH2-GBQA-F4BH7-CBF4-C3B-NBDA-6BK6-HBG5-G2BG4-3BI-3BL5-J2B6-IBK4-2BG3-3B6-3BI4-AFB4-BCA3-J2BC5-F10B4-3A13-I9B4-3A3-NPBK9-I3FI2A4-3A3-IJ2B5-JNG5-3A4-3A6-BI3-DBIGBK-2BC2B4-B2CBCH4B2M2-CG2-2BLBRABG4-H2A2(B2-)BO3-DBI-2B-BCABC4-C2A2(B2-)BC4-F2-2B2(-CB)ABQAB2-BJ-BM-CB6-2BF-GB-RBABCABO-BP-CB-DB5-2BF2-IC2-CABHA-3CH2-NCHCL4-BG28-BK-SJ26-CGH207-D7CG2-2(H2C6-)C9BC-L3B4-D2BH5-C2BC5D3BP-O2BC2-J3B5-L2BMJ6-K2B2-C2BG-3B6-2(DBC)6-2BK2-6BL6-CBKO3BI4-DBN3-4BM7-CBF-K3BT3-GBQ3-H3B8-CBF3-3BH2-GBQ2-F4BH7-CBF4-C3B-NBD2-6BK6-HBG5-G2BGCBRA3BI-3BL5-J2B6-IBK2BIA2BG3-3B6-3BI5-F3BK2BC4-J2BC5-F11B3A16-I9B4A6-NPBK9-I3FI2-4A6-IJ2B5-JNG8-4A9-BI3-DBIGBK-2BC3BLA2B2CBCH4B2M2-CG2-2BLBR-BGACABH3(2-B)O3-DBI-2B2(-BC)AFKAC3(2-B)C4-F2-2B2(-CB)-BQ-B2-BJ-BM-CB6-2BF-GB-RB-BC-BO-BP-CB-DB5-2BF2-IC2-C-BH2-3CH2-NCHCL4-BG28-BK-SJ26-CGH83-
