model
size = 13 32 11, scale = 0.05, origin = -y
material 
  colors = A:#020E69 B:#8B0202 C:#0098FE D:#0DA1DB E:#718480 F:#74837E G:#059CED H:#7C7E79 I:#72837E J:#977168 K:#6C8683 L:#0DA1DD M:#678984 N:#449A9C O:#628B88 P:#58C9CC Q:#3D9D9F R:#38A1A2 S:#688884 T:#7E7E77 U:#847B72 V:#3B9FA1 W:#59908D X:#59908E Y:#539392 Z:#5E8D8B Aa:#59C9CC Ab:#5DCACE Ac:#10A4D4 Ad:#069CEC Ae:#0BA1DE Af:#1FACB1 Ag:#A16C62 Ah:#3A9FA1 Ai:#5B8E8D Aj:#8B776F Ak:#8D766F Al:#817C76 Am:#658986 An:#92746A Ao:#58908E Ap:#4C9795 Aq:#B86054 Ar:#77817B As:#678986 At:#5E79A7 Au:#27A9AC Av:#3F9D9D Aw:#5BC9CC Ax:#5BC9CE Ay:#1AABBB Az:#17A7C4 Ba:#13A6CE Bb:#10A4D3 Bc:#17A9C4 Bd:#1AABBD Be:#2EA6A9 Bf:#409C9D Bg:#459A9A Bh:#628B89 Bi:#5D8E8B Bj:#429C9C Bk:#18A9C0 Bl:#12A6CE Bm:#12A6CF Bn:#17A9C2 Bo:#9C6F65 Bp:#638B88 Bq:#10A2D4 Br:#0A9FE5 Bs:#867972 Bt:#77817C Bu:#35A2A4 Bv:#36A1A4 Bw:#17A7C5 Bx:#3B98AB By:#76817C Bz:#897771 Ca:#987167 Cb:#519393 Cc:#6A769D Cd:#569290 Ce:#4F9595 Cf:#4E9595 Cg:#549290 Ch:#608D89 Ci:#62C9CC Cj:#5EC9CC Ck:#90746C Cl:#31A4A6 Cm:#40BFC4 Cn:#5BC7CA Co:#5BCACE Cp:#62CACE Cq:#5DC9CC Cr:#0B9FE2
voxels
342-2(5A8-)5A358-2A3-2A5-4(9A4-)9A5-7A19-3(2A3-2A6-)2A3-2A5-8(3A3-3A4-)3A3-2A5-3A3-2A6-2A4-A6-2(2A4-)3(3A3-3A4-)4(4A-4A4-)4A-4A3-2(11A2-)3(2A7-2A2-)A-A2-2A-2A4-AyAzAcLBaBbAcBcBd4-9C2(4-4A-4A)2(3-5A-4A)3-AAf3A-4A3-AgBe2(-2A)-MBf2-HA2(-2A)-ABg2-IA2(-2A)-AN2-MA2(-2A)-AR2-BhA2(-2A)-AAh2-AiA2(-2A)-AR2-Bi4A-4AI2-Bj4A-4AO2-J-3A-4AO2-5A-5A2-5A-3A-A2-A-3A-4A3-5A-5A2(2-3(2A-)2A)2-2A2-A-A3(2(2-2A)2-3A)2-2A2-A3-3A2-2A3(2-A9-A)2-A8-2A2-2A7-2A2-BkBl7-BmBn2-3C5-3C2-2A2-3(A-)2(A2-2A2-A-A3-)A2-BBo2-A-A2-BpB2-BAj2-A-A2-2J2-2B2-A-A2-AM5(2-B3-A-A3-B)2-B3-A-A3-I2-B3-A-A3-O2-JA2-A-A2-2K2-AgA2-A-A2-2S2-BA2-A-A2-AT2-2U2-A-A2-AAk2-Bs3-A-A2-AH2-Al3-A-A2-ABt-AT3-A-A3-H-AI3-A5-I-BAm3-2A4-E-AnBu3-2A4-AoB2Ap9-QBTA9-VBMA9-WB2N9-F2BV9-E2-Bv9-K2-E9-X2-Bw9-Bx2-2C7-2C2-2A2(4-A2(2-2A))4-A2-2A2-AjA4-A2-2Aq2-ByA4-A2-QB2-EA2-A-A2-HB2-YA2-A-A2-VB2-YA2-A-A2-2Ar2-Z3-A5-Bz2-O3-A5-U2-As3-A4-ACa2-H3-A5-F2-An3-A4-CbB2-W3-A4-2B2-Z3-A5-B2-2(B3-A-A3-B-A)B5-A3-2(B-AB9-)B-2B9-4B9-3B4(11-2B)10-4B2(9-3BE)9-2B-At9-Cc2-C9-C3(2-2(2A-)2(A-)A)2-2(2A-)2(A-)Cd2-2A2-2(A-)AQ4-2A2(-A)-2A4-3A3-A-A3-4A2-A2-2A2(2-4A2-A-3A)2-4A2-2(A-)A2-4A4-2AF2-2A-A5-2A2-WA-2(A2-)2Au2-ZA-2(A2-)AQ2-AfA2-A-A2-AAv2-AhA2-A-A2-ACe-AN3-A-A2-ACf-AY3-A-A3-X-ACg3-A-A3-Am-KAv3-A-A3-SFE4-3A3-A2F11-KAs11-ChCi11-CjAl11-XJ11-AiCkA9-AAoBR9-ClAk2B9-PB-At9-Aa2-C9-C3-4(2A-A-4A4-)4A-4A4-A-2A-4A4-2A-A8(-4A4-4A)-4A3-5A-5A2-5A-3A-A2-5A2(-2A)2(2-3(2A-)2A)2-A2-2A2(-2A2-A)-2A2(3-4A3-3A)3-2AAwA4-2A3-ACmAbCn9-2AbAP9-Co2ACp9-AaA-Ax9-AaA-Cq8-AAw2-AxG7-GCr2-2C7-2C4-7(3A-3A6-)3A-3A31-2(3A3-3A4-)3A3-3A5-3(2A3-2A6-)2A2(3-3A4-3A)3-3A2(3-4A)2-4A2(2-5A)-5A2-5A-5A3(2-11A)2-P6A-3A2-P3A4-3A2-2A5-4A2-3A4-L3A2-ALAeG3-L2Ad4-3C3-3C290-3(2A5-2A4-)2A3-4A4-9A4-2(8A5-)8A6-AeBrDBq2GC6-7C385-3D10-3D18-
