model
size = 16 31 10, scale = 0.05, origin = -y
material 
  colors = A:#FBFB92
voxels
471-2A14-2A7-3(3A13-)3A14-2A14-2(A15-)A308-2(4A12-)4A38-3A8-3A-2A2(-A8-6A)-2A8-5A-2A8-4A-3A7-5A-3A7-4A2(2-3A8-3A)2-4(3A8-2A3-)3A159-3A13-5A-3A2(7-9A)2(8-8A)9-7A20-5A6-6A-2A7-3(A-)4A6-3A2(-A)-2(2A6-4(A-))2(2A6-3A2(-A)-)2A6-2(3A-)2A2(6-4A2(-2A))6-7A-2A6-4A2(-2A)6-4A2-4A6-4A2-5A4-5A2-5A4-4A3-5A4(4-4A)2(4-3A5-4A)4-3A5-5A3-3A5-5A2-4A5-6A-4A5-2A2-A-5A5-2A3-2A2-2A6-A7-4(2A6-)2A7-7A-A7-8A5-A-2A6-2(2A-)A-2A2(6-A2-2A-A2-A)2(6-2(2A-)A2-A)2(6-A2-4A-2A)3(6-A2-3A2-2A)5-2A2-3A3-A5-2A2-4A2-A5-2A3(2-A)5-2A2(2-A)2-2A4-2A-2(2A2-A3-A4-A2-)2(2A2-)A4-2(A-)A3(2-2A)2(-2A4-A2(2-2A))-2A4-A3-A-3A-2A4-A3-4A2-2A4-A3-A-2A2-2A4-A4-3A2-2A4-A9-2(2A4-2A8-)2A5-A8-A2(6-2A)6-4A-3A-A4-A-2A6-2A4-A-2A6-A2-4A2(2-A6-A3-3A)2-A2(6-A3-2A-3A)5-2A3-2A-2A2(7-A2-6A)7-2A-6A7-2A-7A5-2A2-4A-2A5-2A2-A2-4A5-2A2-A2-2A-2A3(4-A3-A2-A3-A)3-2(2A2-)A3-2A2(2-2(A3-)2A3-A)2-2(A3-)2A3-4A3-A3-2A3-A-A4-2(A3-2(2A4-))A3-2A10-A4-A10-A4-2A9-A4-2A8-2A5-A8-2A5-2A6-2A4-A-2A6-2A3-2A2-A6-2A-3A3-A6-A3-3A2(-A)4-2A3-2A-4A4-A-5A-2A6-A-7A7-9A7-7A-A8-5A-2A8-4A2-2A9-3A2(2-3A7-4A)2(2-4A5-5A)2-5A4-A2(2-2A)-2A4-A2(2-2A)2-A3-5(2A2-)A3-2(2A3-A2-2(A3-))2A3-4A3-A3-2A4-A-2(A3-)2(2(2A4-)A3-)2A3(10-A4-A)10-A4-2A8-2A5-2A6-2A4-A-2A6-A4-2A-2A6-2A-4A2-A5-2A3-2A-3A5-A-4A-3A6-6A-A9-5A12-A118-2A6-3A4-3A5-6(4A4-)A-2A4-2A-2(2A2-)A4-A2(2-2A)2-A4-A3-2A-A3-A4-A3-A-2A3-2(A4-)2(2A2(4-A)4-)2A2(4-A)10-A4-2A9-A2(4-2A8-2A)5-A7-2A4-A-A12-2A-2A6-2A2(-3A)6-5A-4A6-5A219-2A6-3A4-3A5-2(4A4-)4A3-5A4-5A2-5A4-6A-5A2(4-2A2-4A2-2A)4-2A2(2-A)2-2A4-2(2A3-)2A4-A-A7-2A5-2A7-2A5-3A5-2A6-2A5-3A20-A-2A6-2A-A2-3A7-4A284-2A7-A6-2A7-2A4-3A2(6-4A2-4A)3(6-10A)2(7-9A)13-2A4-
