model
size = 13 12 32, scale = 0.05, origin = -y
material 
  colors = A:#FFF B:#111 C:#DC9FB4 D:#F596AA E:#E16B8C F:#222 G:#DB4D6D H:#E79460 I:#9E7A7A J:#8E354A K:#89916B L:#DDD23B M:#B07736 N:#B4A582 O:#3A3226 P:#00896C Q:#777 R:#D7B98E S:#EEA9A9 T:#555 U:#E9CD4C V:#CAAD5F W:#656765 X:#C99833 Y:#954A45 Z:#D19826 Aa:#373C38 Ab:#DB8E71 Ac:#096148 Ad:#D0104C Ae:#B19693 Af:#D9AB42 Ag:#77428D Ah:#444 Ai:#2EA9DF Aj:#EEE Ak:#A5A051 Al:#7BA23F Am:#5B622E An:#877F6C Ao:#F4A7B9 Ap:#E9A368 Aq:#F75C2F Ar:#6E75A4 As:#FAD689 At:#08192D Au:#BC9F77 Av:#C7802D Aw:#6C6024 Ax:#4A593D Ay:#005CAF Az:#E87A90 Ba:#FC9F4D Bb:#574C57 Bc:#5E3D50 Bd:#DCB879 Be:#74673E Bf:#7DB9DE Bg:#897D55 Bh:#B35C37 Bi:#B28FCE Bj:#B481BB Bk:#AAA Bl:#BF6766 Bm:#C1328E Bn:#86C166 Bo:#305A56 Bp:#592C63 Bq:#562E37 Br:#ED784A Bs:#D75455 Bt:#52433D Bu:#B17844 Bv:#8D742A Bw:#F7D94C Bx:#5DAC81 By:#B47157 Bz:#A35E47 Ca:#0D5661 Cb:#854836 Cc:#B55D4C Cd:#86A697 Ce:#4B4E2A Cf:#FFC408 Cg:#2D6D4B Ch:#91989F Ci:#563F2E Cj:#E3916E Ck:#4F4F48 Cl:#33A6B8 Cm:#6E552F Cn:#572A3F Co:#BDC0BA Cp:#D9CD90 Cq:#7D532C Cr:#B54434 Cs:#F7C242 Ct:#6699A1 Cu:#91AD70 Cv:#F6C555 Cw:#86473F Cx:#227D51 Cy:#DAC9A6 Cz:#D05A6E Da:#A8D8B9 Db:#7D6C46 Dc:#867835 Dd:#9B90C2 De:#876633 Df:#0B346E Dg:#0B1013 Dh:#96632E Di:#6A8372 Dj:#E83015 Dk:#255359 Dl:#3F2B36 Dm:#64363C Dn:#6C6A2D Do:#F8C3CD Dp:#24936E Dq:#4D5139 Dr:#376B6D Ds:#BEC23F Dt:#C78550 Du:#42602D Dv:#B1B479 Dw:#FBE251 Dx:#F05E1C Dy:#60373E Dz:#268785 Ea:#00AA90 Eb:#646A58 Ec:#A0674B Ed:#43341B Ee:#577C8A Ef:#BBB Eg:#1E88A8 Eh:#66BAB7 Ei:#C46243 Ej:#51A8DD Ek:#66327C El:#B68E55 Em:#E2943B En:#B5495B Eo:#947A6D Ep:#3C2F41 Eq:#CA7A2C Er:#E98B2A Es:#FB9966 Et:#4E4F97 Eu:#D7C4BB Ev:#E8B647 Ew:#ECB88A Ex:#20604F Ey:#B5CAA0 Ez:#535953 Fa:#36563C Fb:#FCFAF2 Fc:#EB7A77 Fd:#787D7B Fe:#888 Ff:#566C73 Fg:#9B6E23 Fh:#70649A Fi:#707C74 Fj:#2E5C6E Fk:#336774 Fl:#58B2DC Fm:#A5DEE4 Fn:#808F7C Fo:#261E47 Fp:#26453D Fq:#533D5B Fr:#2B5F75 Fs:#838A2D Ft:#BA9132 Fu:#884C3A Fv:#78552B Fw:#81C7D4 Fx:#8F77B5 Fy:#CA7853 Fz:#465D4C Ga:#C1693C Gb:#8F5A3C Gc:#CC543A Gd:#A96360 Ge:#994639 Gf:#554236 Gg:#CB4042 Gh:#985F2A Gi:#B9887D Gj:#F17C67 Gk:#9F353A Gl:#855B32 Gm:#405B55 Gn:#8B81C3 Go:#211E55 Gp:#62592C Gq:#82663A Gr:#FFBA84 Gs:#516E41 Gt:#DDD Gu:#78C2C4 Gv:#FFFFFB Gw:#0F4C3A Gx:#9A5034 Gy:#72636E Gz:#69B0AC Ha:#939650 Hb:#CB1B45 Hc:#734338 Hd:#0089A7 He:#6D2E5B Hf:#7B90D2 Hg:#616138 Hh:#6A4C9C Hi:#C18A26 Hj:#90B44B Hk:#FFB11B Hl:#C73E3A Hm:#A28C37 Hn:#EFBB24 Ho:#F0A986 Hp:#F9BF45 Hq:#E1A679 Hr:#904840 Hs:#0F2540 Ht:#AF5F3C Hu:#E03C8A Hv:#6F3381 Hw:#8A6BBE Hx:#F19483
voxels
42-AjBbClAiDlF7-2B3AhF7-2B3FCk9-KEx74-DkBoGmEy8-BpBqCkOEzO7-AjBoBb2BcAa7-FaBoCmHBdCn8-DmAb2N9-BrAbBsC9-2Fc2C9-RDmC10-RSDo47-F2DpGpAnEy2Be5-Fd6-Cl5-Aj6-T5-Ac2-DqDr2-Ff5-DoBuRDtDrBvRAo5-DoBuBrDtAc-Ap7-HFgBwAn-C7-HRBw-Bs8-CpDwU-C10-DxAq34-ArGqGrCqCrDt2CsCt4-Bp7-Dk4-Aj2-BwGs3-Dy4-H-Dk2-Dz-K5-BhCu4-EaBr5-DxEb3-Bx-Ap5-2Ap3-K-C5-AoAn2-Gv-By7-Gw2-CoPAd45-Bo2EcCwECwGxEdCx4-Bi7-At4-Bq-BwBdAnDz2-Fi4-AuEe4-Bi-K4-H6-AvA4-H5-KBr5-2Aw4-NAe5-AvBp3-PAu11-PAv45-AyBzCw3ACzBzCx4-Ay7-Ca3-F-AtGzHaDaFkBj-O3-ADb6-2Ac3-2Cb6-KC3-CbDb6-KA4-Dc5-FmAp5-U5-PAw57-EhCrE3AEHcFn4-Bi7-Ay3-F-Fo2CaDpAtBj-Ck3-ABd6-BjAc3-AFp6-BxDx3-AFp6-HdEi3-IDw6-AwA4-U5-HeK57-ArCrE3A2GFn4-Ar7-Ay4-AtEjFqFrDzAtEkAgDy3-AFs7-Eb3-ADd7-El3-ABq6-BiCe3-BlBm6-AcH11-P57-BqEcDE2DEGCf4-Ag7-Ay4-AgBfAgHfAyFoAgBj-Bk2-AHg7-ExH2-BsDy7-AwA2-ACk7-El3-DcF6-EbEm11-Ft57-BjEe4D2EX4-Ag8-Bi3-Ch-BjFqAtDf2Dd-O2-A-Ek6-BiH2-EmO7-BnA2-BuBc7-DbC2-FaT6-FmBh3-K7-U58-Ee4E2AAfW3-Bp8-Ay3-Bt-AaDlAr2DfEj-Q2-A-Cn6-AtBd2-2Ac7-BnEo2-CdDl7-BnA2-Dw7-KEl3-Bx7-K58-2Bz3E2AFuAg3-Bp8-Ag3-Bq-AjAaEpDgFkEh-Fd2-A-Ch6-DfAn2-HjAh7-DnEo2-U8-HkA2-An7-AwFg3-U7-N4-Cu6-FHm45-Ff3E2D2EDg4-Bm7-Dd3-W-WFiBbFw2Da-Ar2-A-Ch6-LDh2-CeAa7-MDh2-Aw8-CqA2-Fs7-AnFy3-U7-Au4-Dc5-AeBtBv4-NO4-IFlAe32-Et5D2EDi4-Bm8-O2-B-FhCnFxCtBnDv2-Q-A-Bb6-M-Cc-CsCv7-Ga-A-2Dh5-EuA-A2-HnDa4-2A-Cw3-Ce4-3A-A3-EvBkCz2-A2-Au4-A-YEv-A2-C5-CuAH-HBsDe6-Fj-CmCpEmA8-Et3D2G2DDn4-Bm8-Ca2-B-ClEpAiAlBgM2-Bk-Cr-Dg6-Gc-Fy-BzCv6-DjGd-A-GeGa5-Eu2-A2-EiAk5-Dj-A3-YBw5-Cj-C3-Y-A3-Di-H4-Fr2-Bn-Et2-P5-N2-Cd-EvAv6-PFeAqBhBy9-ArG2D4GLAi3-Fb8-Dg2-Co-LFzDuAlErGcFu-Ar-En-Di7-BeEo-GAz6-Hr-2A-EnGi6-Gj2A2-CZ5-Ew-Cc3-A-A3-Du2-Ab3-A2-Di-Ba2-Ab5-K2-Db3-Aq5-YEa2-BlBxBu8-IAe10-Ca3D4GBaHs2-Ef6-AzD-Fw2-Bt-CjLCyEwEr2-HtBn-Cz-Gl8-By-GGi8-2A-AAz6-Dj2A2-G-A3-ACj-Cc3-C2-3A3-Bh4-Ce2-A3-De5-Ce4-I-J5-CCdJAoC-H20-CqG2D2GEuHxBaHw2-Ef4-CiD2A2-Hv-Hu-CjGlEw4-Cf-ChCz-Gj8-AAuAGh8-2A-ACs5-4A2-I-2(A3-)A2-A-2A2-A2-Ap4-Bd-J-I3-I4-Au-DmGkIJBvGk6-U25-DrCq2D2GGfCiEsBf2-Bm3-GdE3A2-Cg-CxDCjGh5-Cf-ChEAz9-2CA9-2A-A7-3A2-3A4-A-Ap4-By4-A2-Cp4-BsGeAoS2C2R5-CBdAeSI-DcBh31-AaEd2Gg2AzGfCiGbHqEjAi-Bm-3AE3A2-CgB-A7-Hp-Bb3A8-2CA9-2A-3A5-3A2-A-A4-A-By4-CbCABlSCA-J4-Cb-CBlSI-Av6-Bh37-CxHoBaCiDjEsGbCiEqBa2AiBf2-7A2-AiBc-A7-A-Bb2A9-2CA9-CA-3A4-4A3-DeP3-JA-Bv4-Ei-AdAeBlJ-FtJ5-AqN4-Bu44-Fz2BaEdMEsFvEr2EqCgFxBf2-7A2-EkBc-Az7-A-Ez2A9-AAq2C8-C2(A-)N5-AAvC3-Y-CA3C-Au5-AeHlAoCJ-Cm56-EpCtXZHiM2ZFv2MAlAaHh2-3A-2A2-A2Q-E3-A2-3AQAdA9-AR2Ao7-3A2-2N4-SIBrC4-NAe3CBlJ7-Cc61-F2Dq2CfVAfX3MCgWB-2A3-A2-A-WBA2-7A-TH10-EnUJAb7-AvCA2-2AbS2-AJIDe5-YAd2CACA69-BEhLBg2BeAfX2MZCgWB-5A-2A-2WBA10-QHA9-HTAAd7-AdCA2-AbBvIC3AJAq6-IJ2A71-BkClDsVBeAkVXZ2AsAx-B2-3A5-2AaB-A8-2BkEaAq9-2Cd-AdC6-2CA2-CcS5CSC6-Y75-CtL2AfBgAf3Z2Ax-B-A6-X2Ax-B-A8-Q-BCu8-RFl2-IYK4-HbBxAdA3-YH2PEgFjEgCm82-AkAfAsAfBgAs3X4-WVCv3-As2Cy2Ax-BO9-Ah-BGy8-EgB2-CpB6-BEf4-8B84-3VAsCy6-ODs2AkVCvAsLVFhAj2-B8-2F2-TGu7-2B2-Bt2B5-BGt5-7B95-QBf2AmL2Bg2LCn3-BT6-AjF3-BT6-2F4-2B4-B-Ah5-7B96-Bf3Am2DvAkDu5-T4-DsL-F3-2B6-2F4-BtT4-FeF6-6B97-BAlAm2AlAm7-AhBcDnAlAkLBoF5-BF4-2F5-BOCoGoGnFb-Q7-Co4B82-
