model
size = 13 12 32, scale = 0.05, origin = -y
material 
  colors = A:#FFF B:#111 C:#E16B8C D:#DC9FB4 E:#222 F:#8E354A G:#CA7A2C H:#F596AA I:#B5495B J:#AAA K:#FC9F4D L:#CC543A M:#D0104C N:#E1A679 O:#555 P:#8A6BBE Q:#3A3226 R:#86473F S:#9E7A7A T:#DB4D6D U:#572A3F V:#465D4C W:#7BA23F X:#78552B Y:#B07736 Z:#E9A368 Aa:#91989F Ab:#CB1B45 Ac:#373C38 Ad:#B1B479 Ae:#86C166 Af:#888 Ag:#33A6B8 Ah:#C73E3A Ai:#D75455 Aj:#227D51 Ak:#EEE Al:#707C74 Am:#5B622E An:#F4A7B9 Ao:#E98B2A Ap:#B68E55 Aq:#854836 Ar:#BBB As:#3F2B36 At:#D19826 Au:#563F2E Av:#BA9132 Aw:#D7C4BB Ax:#E87A90 Ay:#66BAB7 Az:#444 Ba:#562E37 Bb:#B47157 Bc:#0B346E Bd:#7DB9DE Be:#DCB879 Bf:#B17844 Bg:#EFBB24 Bh:#6E552F Bi:#6C6024 Bj:#0B1013 Bk:#43341B Bl:#F0A986 Bm:#FB9966 Bn:#CB4042 Bo:#734338 Bp:#6699A1 Bq:#B481BB Br:#C46243 Bs:#777 Bt:#3C2F41 Bu:#9F353A Bv:#C99833 Bw:#516E41 Bx:#A35E47 By:#4E4F97 Bz:#FB966E Ca:#51A8DD Cb:#724938 Cc:#808F7C Cd:#EEA9A9 Ce:#656765 Cf:#A36336 Cg:#B55D4C Ch:#BEC23F Ci:#994639 Cj:#BC9F77 Ck:#F7C242 Cl:#096148 Cm:#81C7D4 Cn:#376B6D Co:#DDA52D Cp:#78C2C4 Cq:#B35C37 Cr:#E79460 Cs:#42602D Ct:#787D7B Cu:#4A593D Cv:#884C3A Cw:#855B32 Cx:#9B90C2 Cy:#B4A582 Cz:#64363C Da:#F8C3CD Db:#5E3D50 Dc:#C1328E Dd:#A5A051 De:#724832 Df:#FFBA84 Dg:#CAAD5F Dh:#8F77B5 Di:#0F2540 Dj:#A8D8B9 Dk:#DAC9A6 Dl:#0C4842 Dm:#622954 Dn:#0D5661 Do:#255359 Dp:#D05A6E Dq:#C7802D Dr:#9A5034 Ds:#A0674B Dt:#9B6E23 Du:#7D6C46 Dv:#E83015 Dw:#DDD23B Dx:#897D55 Dy:#6E75A4 Dz:#DB8E71 Ea:#574C57 Eb:#CA7853 Ec:#867835 Ed:#F19483 Ee:#261E47 Ef:#336774 Eg:#6C6A2D Eh:#C78550 Ei:#954A45 Ej:#E2943B Ek:#B19693 El:#62592C Em:#2E5C6E En:#ED784A Eo:#646A58 Ep:#2EA9DF Eq:#FFC408 Er:#96632E Es:#F05E1C Et:#89916B Eu:#A8497A Ev:#0F4C3A Ew:#113285 Ex:#6A4C9C Ey:#EBB471 Ez:#F9BF45 Fa:#91AD70 Fb:#554236 Fc:#69B0AC Fd:#6F3381 Fe:#592C63 Ff:#577C8A Fg:#D7B98E Fh:#4A225D Fi:#305A56 Fj:#BF6766 Fk:#939650 Fl:#E9CD4C Fm:#E8B647 Fn:#535953 Fo:#877F6C Fp:#F75C2F Fq:#52433D Fr:#A28C37 Fs:#A96360 Ft:#82663A Fu:#1E88A8 Fv:#8D742A Fw:#AB3B3A Fx:#F6C555 Fy:#B9887D Fz:#986DB2 Ga:#F17C67 Gb:#211E55 Gc:#AF5F3C Gd:#FFB11B Ge:#947A6D Gf:#4B4E2A Gg:#90B44B Gh:#838A2D Gi:#66327C Gj:#FBE251 Gk:#91B493 Gl:#2D6D4B Gm:#26453D Gn:#405B55 Go:#F7D94C Gp:#7D532C Gq:#08192D Gr:#FEDFE1 Gs:#4F4F48 Gt:#70649A Gu:#5DAC81 Gv:#8F5A3C Gw:#EB7A77 Gx:#D9CD90 Gy:#B54434 Gz:#36563C Ha:#FCFAF2 Hb:#876633 Hc:#8B81C3 Hd:#B5CAA0 He:#60373E Hf:#005CAF Hg:#2B5F75 Hh:#ADA142 Hi:#967249 Hj:#985F2A
voxels
43-WChAyVUAc7-3EAz2B7-AzEJAk2B86-2Cx2AjAy8-BqAl2AkAlAc7-2JCeBaAlQ7-GbCyCfEhCgEi8-FCfEjBrA8-EkBbCfCgD8-CzBbGcEkDa8-2ARS10-AMAn46-QBcAd2AjAeAyBt5-Dc6-Al5-B6-Ce5-E2-AeDdEl-Bu6-DeGdAd-Be-Da6-F-Ap-Ge-Cz6-A-BeYDf-Da7-BfGfYBgAq8-BhGgBcBiZ45-As2AdAtGBvChBt5-Dh6-Aa5-B2-BgGhDj2-Gi4-Em-Ad3-Bw-Cg4-2Ci4-CjEn5-A-Ck3-BiBr6-ACk3-BiBu6-AGj3-GkD7-Bi3-Eo44-AaGlAt2G2NBvEp4-Aa8-Bt3-B2-2EqBgClDl-Ba4-BeW5-BfBu4-RBk5-BfAn4-A-Er4-EsBu4-A-Gm3-DnCj6-ZBy3-2Et56-AgG2BlBz2AuGCa4-Af8-Ex3-Af-WAdBgGoClDo-Ex3-DqAp6-DgAn3-I-Ds5-CoAn4-FEy5-DuCz4-AAp5-CyD5-Av5-Bi56-CaAu2LDvLAuBmCa4-Dm8-P3-B-W2CcBw2Dn-P3-CqAm6-BkD3-AGp6-CoD3-A-Ez5-FaD4-SBe5-FaD11-Bh56-GqBxBnBoGrHFbBzBp4-Ew8-Aa3-Af-WDjCcFc2Do-Fd3-EyAj6-CkA3-BoDw6-BwA3-A-Dk5-FeA4-ABe5-FeA68-FfAw2BnCHFbLCm4-Fh8-Aa3-Dm-AmAeCcDlBcBp-As3-ErCs6-AyA3-Dr-Dg5-AyA3-D-Dk5-CtA4-ADu5-AfF68-FiTH3AHDsBq4-Fh7-Bq3-B2-AdCuDjCaPVBq3-D-Dw6-ClBr2-A2-Dw5-DyEh3-2DL5-AaFj5-CyAg4-JA11-EDq55-Bw2C3ACFkGs3-Af8-Ba3-Af3-CuBpGtUEaBa3-D2-Cv5-CnA2-D2-Cw6-Fm3-AnD-Au4-FnFo5-AiFc4-JA11-AfGw54-FdAe2C3ACFk4-By8-Fq3-Ec3-AjAgPU-Fq3-Ec2-C4-Ac-A2-F2-Fs5-OCo3-SA-C4-BqDt5-ABw4-CtA5-FEv4-JF11-EuZ41-DbGyC4ACAe4-Ee8-Q3-Gz3-2EfAsAl-Q3-R2-C4-Ac-A2-M2-A5-JDt3-FABo5-BjAp5-2Ft4-CtA5-AqBg4-CtA5-FpEb4-ArAn5-DzR4-FuZ28-BtHCH2CACAm4-Bj7-By3-Hc4-CsEfAsAa-Q2-F2(-A)4-U-De2-MF-H5-AaDe4-ACb5-AjDr5-AhH4-AyA5-DHd4-FnA5-FBa4-OA5-AiCl4-CnA5-AvBhDc3-FgBu6-BbEl7-BpCTH4CBg3-Bt8-By3-Ee-2ABmAdAgBjP-E2-FjM-2A4-Dh-A2-MD-H5-DhA4-A-A4-DdAb4-A-Dv4-DdA5-CjBp2-A-ByA5-FvBa-FxCbA-A5-BrCk-FxBeA-Cq5-Ec-FfCnCrFzFl7-EbAqBfAhEsAq3-AeCTH2CHBxCo3-Bj2-CDv4-Ar3-Dy-A2-WVBjP-E2-CdM7-V-A2-MFD6-CuR4-3A4-CwA4-F-Eg4-EzA4-Em-Eg2-2A-A5-CDx-Cw3-A5-Ap-Am4-Cq6-F2-A-Bh8-SM-BbAq2-PDfHBnAx2CH2Bx3-P2-AFsG4-Ar2-Bc2A3-2VCs-Ar2-CdF7-Eg-A2-FAD6-HiA4-3A4-HjA4-Z2-4A-A4-Fu2-3A2-A5-Dz-Cw4-A5-Fm5-Fo7-AbS-CDcBf9-Ai5-PDf2AwAxC2HTDl3-EpA-2ALY3-Fz2-Ee-A4-WCs-Q2-MD7-Fy-A2-2(DA)5-GaA4-DA5-GaA4-Z-A3-A-A4-M2(2-A)-A5-Cf2-FwAx-Cb7-SAb3-Ej9-BoRApEn15-BpLBoAwT2H2THhAc-PCa-3AAxY3-Hg-AsHf-A4-WAu-He-CrMD7-Fy-A2-2DFA5-FwA4-Cd-A4-AxA4-Fr-A2-2AC5-S-A2-A-Fv6-Cr2Ab-A-Aq8-AbCdCDuAi27-UAgLCvBoT2H2TDsU-PFi-A-2AHAx2-Cx-P3-A4-AuCCc-BhF2D7-AxA2-FAD6-2A4-Z2A3-A-A4-Cd-A2-A-D6-Ah-C-A-Ai7-I-C2-A8-2IA2Bb27-BdAgLBzLEdBn2AwEd2Bk-Bd3-3A2-A2-EaBc4-4A-A-EaBcF2A7-AAn2-A2D6-2A4-ZCg4-A-M4-M-A2-A-Hb6-BrDSC2-Ha8-AbICbBf41-UAe2BlLEdBnAwBzBlBkCh-Bd6-3A2-DiBs7-2A2-AsGx2A7-A-A2-FSCj6-AD4-FrF5-S6-I2A2-AhFp7-3ARC11-CiR41-AaAt2BmGvL2CvBz2KCu-As9-A-DyE9-2AAcGu2A8-AEb2-AFCq6-AD4-2AhA3-FlDz6-F-ACI2Av7-2ACDp55-AkDx3NBl2LNBkKVQAc10-AOE11-EOEiA8-AAi2-CZDqA5-2F4-3A3-AhAi7-A3CI11-Ci55-AkDx4NKBmKGKVJAk9-A-JO10-AAzBFgA8-ACr2-IAqAiA5-Dp5-4A-S2Av7-2A3I67-AkAe3N4K2GBd-2Ce8-A-Bs2O8-A-EBCpF8-DCp2-FIC5-RI5-C4AIAbR8-2AI69-AmGAoBm2K2Ao2GBd2-UG8-Bs2JO9-OE-2Cp8-BhE2-FCbDtC4-RAb5-AvEoBiDrDpIAh82-2X2KAoGYAt2Cm2-U2GX6-Q2-J9-BE-BEw8-Ev3-Eu2B4-BxGnAp5-5BDmCn84-4G2YCmQ2-JWAoGX3-DkDiQ2-JO8-B2-2B7-2B3-2ArB4-3B5-6B86-AoGAt2Bv5-Bj2X2GAtBvAtDiAc3-O7-AzB3-2E6-2B3-BArB4-2B6-6B96-AlDg2GX2Y2Ag4-ODbX5-E4-2E5-2B5-EAfE2-B-B6-EAzE3B98-Ao2GXAmBdAl5-Db-ChGVAm2Bs5-2E4-2B5-BAzQE3B8-2E2B82-
