model
size = 16 31 10, scale = 0.05, origin = -y
material 
  colors = A:#FFE21D B:#FFD725 C:#F9496B D:#FF716D E:#FEEA33 F:#D7FD54 G:#FEE528 H:#C5F855 I:#FCFC55 J:#FE4934 K:#FEB50B L:#D6FE64 M:#48D878 N:#48CD68 O:#FDFE68 P:#FFA64B Q:#FFEA46 R:#FBF736 S:#A34686 T:#FDC826 U:#FF4408 V:#3249B8 W:#FDFA49 X:#FE773A Y:#FA555C Z:#FDA308 Aa:#2F38A1 Ab:#74D18D Ac:#84E576 Ad:#FF3F47 Ae:#FC6549 Af:#FF5A45 Ag:#002E6B Ah:#D8B817 Ai:#FF8418 Aj:#FBA715 Ak:#FF7A28 Al:#FF9946 Am:#B64D85 An:#2D1260 Ao:#72F486 Ap:#FF6562 Aq:#206ACC Ar:#FF9726 As:#66E069 At:#6ECF4C Au:#6C489B Av:#2495CD Aw:#3AC6D0 Ax:#4BCBB4 Ay:#FCCA38 Az:#67E377 Ba:#5AAE2E Bb:#FF8848 Bc:#04328A Bd:#E8FA68 Be:#3AA735 Bf:#E2FE49 Bg:#F62934 Bh:#990927 Bi:#0D4C9C Bj:#204BA5 Bk:#8ED347 Bl:#FF692D Bm:#FFB763 Bn:#037695 Bo:#16BAD3 Bp:#BBFA56 Bq:#50D490 Br:#613691 Bs:#6C7BC7 Bt:#B3F467 Bu:#FFB359 Bv:#FF3638 Bw:#2672C5 Bx:#4BB59A By:#B1F549 Bz:#FC5818 Ca:#FBFB92 Cb:#FFB645 Cc:#FD2724 Cd:#CE1B27 Ce:#070B36 Cf:#FEDA37 Cg:#4DB36F Ch:#9ABB1A Ci:#FFA824 Cj:#FFA86F Ck:#7ED656 Cl:#76FA9A Cm:#B5FD76 Cn:#FF892E Co:#FF9368 Cp:#294BB3 Cq:#86E669 Cr:#FEFC28 Cs:#FFB916 Ct:#57E893 Cu:#71EBB6 Cv:#CDFE86 Cw:#B6FE88 Cx:#88F774 Cy:#216AC0 Cz:#39C6A5 Da:#C4C654 Db:#FFB626 Dc:#FB7253 Dd:#AC5276 De:#51346D Df:#012A87 Dg:#3086A9 Dh:#1D95B9 Di:#0A8797 Dj:#68CC86 Dk:#D6EC4B Dl:#93DB38 Dm:#EAF533 Dn:#FE9513 Do:#FFD456 Dp:#DF202C Dq:#5F002D Dr:#330036 Ds:#26338E Dt:#040434 Du:#5FB869 Dv:#CE181D Dw:#52094F Dx:#046DB1 Dy:#017CB5 Dz:#098FB0 Ea:#DCF132 Eb:#FFA78D Ec:#FF6558 Ed:#6F1654 Ee:#90F16C Ef:#6FE7B2 Eg:#84F4B2 Eh:#073399 Ei:#19B3AB Ej:#87E88C Ek:#97E66E El:#A6E465 Em:#ECFF73 En:#98C92B Eo:#CCC610 Ep:#D2395F Eq:#32094E Er:#4A49A7 Es:#FCFF78 Et:#6C9F4E Eu:#D5E336 Ev:#FFB539 Ew:#E34E5D Ex:#6646A7 Ey:#C8E854 Ez:#AEFFA2 Fa:#FFE053 Fb:#FF7B18 Fc:#FF562B Fd:#FC4925 Fe:#B3C31B Ff:#FB1812 Fg:#FF720E Fh:#FF8537 Fi:#635B4C Fj:#FFC74B Fk:#151F70 Fl:#8BD896 Fm:#9B1D4A Fn:#1492C9 Fo:#84FF93 Fp:#A5FB95 Fq:#63CBE2 Fr:#17996A Fs:#6CDC76 Ft:#EB9C2C Fu:#CFF433 Fv:#054A9A Fw:#A5DA67 Fx:#8BB45B Fy:#8AF467 Fz:#66EA98 Ga:#FED848 Gb:#6FD667 Gc:#20C8CC Gd:#F22D15 Ge:#84EF89 Gf:#A74459 Gg:#2E2467 Gh:#23A0A8 Gi:#FD3726 Gj:#C8F96F Gk:#D7D419 Gl:#8EF1A4 Gm:#34ABD4 Gn:#07AFD1 Go:#65CE50 Gp:#48B4CE Gq:#34BEC9 Gr:#93C46E Gs:#B5EB54 Gt:#F3AE39 Gu:#8BE955 Gv:#B72652 Gw:#238594 Gx:#2AC99C Gy:#AD1B2A Gz:#D5D659 Ha:#FFC813 Hb:#FF4E0E Hc:#27739C Hd:#32B4B3 He:#90D377 Hf:#50AA34 Hg:#0997BA Hh:#046B99 Hi:#36D6AD Hj:#A9FC71 Hk:#EAD79E Hl:#95F7A5 Hm:#4DD48E Hn:#96DA68 Ho:#A4DE36 Hp:#6A5570 Hq:#B5D54C Hr:#C99C37 Hs:#F7D423 Ht:#479FAB Hu:#061D62 Hv:#CCD34A Hw:#0BA6C4 Hx:#22C5BB Hy:#5AE095 Hz:#63AC40 Ia:#0180B9 Ib:#1E62A1 Ic:#DEF664 Id:#F43420 Ie:#D2FF8E
voxels
471-ArFt14-2Ar7-AzFzAc13-Bp2H13-F2H13-Cr2R14-RT14-Ci15-Bl15-Fd308-CwCmEeCw12-CvLBtEj12-2CaBdL38-AzNAc8-3Ct-CtEe-Da8-HlFoAo2AzF-H8-Cw2Bp2FCr-RCs8-2Bp2FB-TCs8-GCrEsR-2DnAr7-Aj2AyEB-2BlBz7-FbBbBzDb2-2JDp8-IdFfBu2-FmEdEh8-DpGiCj2-DsBjEh8-BhCd3-DsBjAw8-2De3-GnBoGc8-HcDx3-ClFoAo8-2Gn3-ClFoHj159-GmAvDh13-GmAvDhAxEf-EiGhAw7-EgCuBxEfAb2CgEg2Cu6-Hl2EzCwCmEeCwEzFp8-Ie2CvLBtEjCwCv8-EsO2CaBd2LI9-W2O2WCfW20-2Az2CqBk6-2M2CtMCq-2Ah7-Ac-Ao-Cx-Cr2AhCh6-2CkBp-Bf-A-2K6-Gk-Bp-Bf-Cs-2K6-K-I-O-P-2Cn6-2AjT-Q-Bl-GiCn6-2FbAi-Aj-Cc-DvEw6-3U-PDwEd-2Bc6-2FfBzJ-DwEd-2Bc6-DqBhGvFm-DyDg-2Aw6-2An2GgEh2Bo-HiAw6-HhDx2Fn-GcCl-AoCq6-DzBo2Fn2-ClFoHjCq6-ClCuHiCu2-2LBfRGk4-2HFp2Ge2-IWIRT4-HBfEmL3-GaFjFaDoCb4-BGaFjEm4-2BmCjP4-CbAl2Fh4-CjCoAfDc4-2HkBm5-DAdBgC4-2EbCo5-SCEcC4-ApSC5-3AmDdS3-CSC5-2Ex2ErCp2-BrSAuDd5-3AqCyDxHh-EhBiBwAq5-2Fq2-Dz-FrBnGhGmAq5-EfEg3-2Cg2-CuFl6-Gl7-2Fp6-CvCa6-CvCm6-EmO6-2L7-3EOWQCf-W7-2E3GQTB5-Ej-GoAt6-NM-2M-Ac-2Ch6-Hf2-ByCx-G2-Ch6-Du2-2By-G2-Z6-DuK-BfCr-Cs2-Fg6-2K-AG-Ci2-Cn6-Z2-DbCsXAi-BhCn6-Ai2-2Al2Bv-BhCd6-Ae2-AkBlBg2-DrDt6-Ep2-GiCcFk2-FiDt6-Dq2-2FmHg2-FiDi5-BnFi2-FkDsHg3-Di5-2Bn2-BoAq2Ao2-Gb5-2Bn2-Bo2-Ao2-En5-2Du2-Eg2-L2-EoGk4-EyBt-GjCm2-W3-T4-Ey2-2Bd2-Fj3-Ar4-B2-OBd2-PBu2-Ak4-Cb-X-Do2-2Eb2-AfY2-FhAl-2Bm4-D2-2Y2-2Ap-CoCj4-C2-2C2-2Ap-2D4-Am3-C-Gf2C-2D4-Ex3-2AaGfDe2-DdAu4-Cy3-Bj-AgEh2-2Aq4-Gp4-3Ag2-AvBw4-Ef9-FlGq4-2Gl8-EkAb4-2Gj8-2Bt5-Dk8-L6-2R6-GQ6-GB2A-3A-B4-Fs-HfBe6-CgN4-Cq-BeBa6-Hz2-HyGeEaE2-Ba6-Ch3-ByTE2-K6-Eo3-CrCiCs2-Ak6-Fg3-GP-2UAk6-Fg3-EvX-UDpFd5-FhBz3-EvCc-DvBh7-Fc2-GdAkEdDrDwDr7-Cd2-GdBgBiDfBcFi7-AnDf-AnEdBi3Dy7-AnDf-AnDsAxEi2DzBx5-DiBn2-IaDxEfEe-2Bk5-DiGx2-Bo2-EeEaDlBk5-EtN2-Eg2-2Ea-2Ah4-Fe3-Cm2-O3-Dn4-Fe3-I2-Fj3-Fg4-K3-I2-Bb3-Bl3-2Aj2-2Fa2-Co3-AfAe2-Bz3-Bm3-EcAp3-Bg2-Ec3-Co3-2Y3-Gy2-Ec3-Ap3-2Ep3-DrFk2Ew3-Ap3-BrAu3-Fk-Gf4-S3-BjCp4-BiGg4-Cp3-IbDh4-AgDt4-Cp3-GhAx10-Hd4-Fl10-Ab4-FlEl9-Ek4-AxHe8-IcH5-Cf8-IO5-BA6-AB4-Gb-2Be6-CgN3-DlEk2-Ba6-AtN-FzEzG3-Ba6-Ch3-FyGFa2(-Ha)4-ZAh3-BfCi-Dn2CiZ4-Z-2ZAyBP-AkAi6-Fb-ZAiAjAy2FcU7-2Cj2AiHbAl2CcDv7-FcAeFdJUHbBh-Dw8-Dp2BgFdCd-DfBi8-AnEqDwAn2-DyDx9-FvBiBj2-HwDzEi7-DgFvBiBj2-2CkBk7-2CzHxGc2-2CkBkDl5-BkGbAcAoCl2-DmEa2Eu5-FeEtByFCm2-2DmB2U4-Fe2-FO2-2Cb-CnBl4-K2-2I2-2Al2-Bb3-XP2-DoQ2-2Dc2-2J2-2X2-Bm3-EcEb3-Ff2-Gd3-Co3-2D3-Bh2-Bg3-Ad3-2Am3-DqEq2Dv3-Ad3-2Au4-Eq-Dq3-S3-BjBw4-2Ce4-Cp3-HcDg4-CeDt4-Cp3-GwBx10-Hd4-Ab10-Dj4-He10-Fw4-Gr10-Ey4-DaCf8-CfDk5-BA6-AB4-As-2Be6-N4-2Dl-BeEn6-BaN-FzFyDmBy2-En5-HrBa3-FyDm-QIA5-Ah-EoEsFBf-ArKB6-ZTBQEG-Ar9-AjDnAiHsAy12-Ak118-EEu6-EtFuF4-EvDbBz5-EuEtFuF4-EvPAkX4-DoCaQI4-Al2BbX4-PBuCbDo4-Dc2AeEw4-Bb-2Bu4-DJ-DpCc2-2J2-Ae4-D2-2Cd2-2J2-Bv4-Am3-DeBr-Gy3-Bv4-Ex3-Ds-DrDq3-Am4-Bw4-CeDt4-V4-Dg4-2Ce4-Cy4-Bx4-HuFr4-Ht4-Du10-Dj4-2Fx9-Fw4-2Gz8-DkEy4-HvGa8-CfDk5-T7-AT4-As-N12-GuAs-NAt6-BaM-MAzGu-3At6-En2Bq2Cx-Fu2HF6-EoHoBq2F219-BuP6-AfAeAd4-XBbP5-2Af2Ad4-2YDAe4-2Af2Ad3-J2YDBv4-AuSBrSHp2-GvEpCDcBv4-2Er3AaDf-EqDeS2Dd4-2Bw2-2BcAgBs2-2V4-DgAv2-Gw2AgFv2-2V4-BxAb2-Bx2-Di2-2Dh4-2Dj3-GxFs3-AxDj4-Fx-Gs7-ElFw5-2Bd7-DkHq5-2QB5-EsQ6-2A5-2AB20-As-MN6-AsM-M2-AsAtGo7-As2BqCx284-2D7-Aa6-2C7-2Aa4-2BrAu6-2CyBsAv2-2Bs2V6-2AvGpFq2-2Bs2V6-AbGr3CzFrEiGq2Aw6-AcHn2AcEjFsHmBq2Ax6-2ElBtGs3Da2AbEk7-WR2Gt2FtEEmH7-2E2Db2AyEOI13-2A4-
