model
size = 32 25 28, scale = 0.05, origin = -y
material 
  colors = A:#0180B9 B:#FDFA49 C:#FCFC55 D:#017CB5 E:#B5EB54 F:#36D6AD G:#FEFC28 H:#FBFB92 I:#EED44B J:#FEE528 K:#238594 L:#6C9F4E M:#E2FE49 N:#CCD43A O:#0997BA P:#88F774 Q:#9FED61 R:#FED848 S:#16BAD3 T:#D6EC4B U:#FFE21D V:#0BA6C4 W:#046B99 X:#B3CD64 Y:#D5E336 Z:#B0C449 Aa:#EAF533 Ab:#22C5BB Ac:#4DB36F Ad:#99E45A Ae:#A9FC71 Af:#FDA308 Ag:#63CBE2 Ah:#8BB45B Ai:#B5D54C Aj:#CFF433 Ak:#046DB1 Al:#C8E854 Am:#FBF736 An:#5FB869 Ao:#07AFD1 Ap:#4BB59A Aq:#C8F96F Ar:#93C46E As:#D7FD54 At:#DCF132 Au:#20C8CC Av:#D2FF8E Aw:#DBF84D Ax:#FFEA46 Ay:#84E576 Az:#E8FA68 Ba:#FEEA33 Bb:#19B3AB Bc:#0A8797 Bd:#C4C654 Be:#CCD34A Bf:#86E669 Bg:#FE9513 Bh:#5AE095 Bi:#17996A Bj:#4DD48E Bk:#66EA98 Bl:#2AC99C Bm:#B3F467 Bn:#D5D659 Bo:#C5F855 Bp:#054A9A Bq:#1E62A1 Br:#FDC826 Bs:#72F486 Bt:#9CB241 Bu:#97E66E Bv:#9A7D61 Bw:#93D94F Bx:#D6FE64 By:#96DA68 Bz:#A4DE36 Ca:#FFC813 Cb:#AEFFA2 Cc:#71EBB6 Cd:#B1C84F Ce:#FF4408 Cf:#48D878 Cg:#FDFE68 Ch:#FEDA37 Ci:#FCFF78 Cj:#D8B817 Ck:#34BEC9 Cl:#2495CD Cm:#23A0A8 Cn:#FCCA38 Co:#FB1812 Cp:#7AC771 Cq:#50D490 Cr:#BBFA56 Cs:#FFA824 Ct:#ECFF73 Cu:#3086A9 Cv:#EAD79E Cw:#FEB50B Cx:#E4D227 Cy:#84F4B2 Cz:#CDFE86 Da:#FFB626 Db:#6A5570 Dc:#FFD725 Dd:#A5DA67 De:#68CC86 Df:#8BD896 Dg:#037695 Dh:#87E88C Di:#39C6A5 Dj:#55C878 Dk:#66E069 Dl:#B3C31B Dm:#B1F549 Dn:#FFC74B Do:#90F16C Dp:#67E377 Dq:#B5FD76 Dr:#8BE955 Ds:#7ED656 Dt:#FFB916 Du:#012A87 Dv:#27739C Dw:#84EF89 Dx:#76FA9A Dy:#90D377 Dz:#6CDC76 Ea:#6ECF4C Eb:#8ED347 Ec:#FFB539 Ed:#CCC610 Ee:#32B4B3 Ef:#A74459 Eg:#B6FE88 Eh:#FBA715 Ei:#0D4C9C Ej:#FC5818 Ek:#A6E465 El:#FF4E0E Em:#FFE053 En:#C99C37 Eo:#4BCBB4 Ep:#74D18D Eq:#F3AE39 Er:#F7D423 Es:#479FAB
voxels
499-2(6E26-)6ECr2(24-Aw3Ct3TAw)25-3Cg3Aa30-2Aa527-2(Bx15-)2(3M11-3M15-)4B9-4B13-2(3C3B9-3B3C11-)6C9-6C589-2(Bx15-)2(3M11-3M15-)4B9-4B13-2(3C3B9-3B3C11-)6C9-6C397-3FBd10-F17-3FBd10-F15-3Bs2Dx2Dw2BsP4-3Bh2P2(13-10P2Ae-Do2KAc2Ae)12-Cz3Eg2DqAe2(Dq2Ae)DqDo2AcCp2Bm12-Bo2AqAv2Cz8Bo3Cr4Bo2(11-As2AwAs4Az2MAz2BxAs7M)11-M9B4HCg6B11-2(B5C2B2Ci4HCg7B10-)10CCg3H6C2B237-8A3-4A15-2(3Ag11A5V13-)3Cb2S2V2BbS3AoS5V12-Ab3Au3DdI2BeBh4Au2Cc3AuAb2(11-6F2Bd2IAy9FBh)11-Bh2Bk4-Dw3P3BsBk2BjDx2Bs2Ay2(9-2Bu2P7-4PAy3-2Ae2Q)9-BuQ2Ae8-3AeDo3-2Ae2E2Al7-ECr19-Cr3T2(5-3TAs19-M3At)5-4M19-BAm2J2(5-4B19-B3Am)5-6C8-3CiC3-3C3B235-8A3-4A15-2(3Ag11A5V13-)3Cb2S2V2BbS3AoS5V12-Ab3Au3DdI2BeBh4Au2Cc3AuAb2(11-6F2Bd2IAy9FBh)11-Bh2Bk4-Dw3P3BsBk2BjDx2Bs2Ay2(9-2Bu2P7-4PAy3-2Ae2Q)9-BuQ2Ae8-3AeDo3-2Ae2E2Al7-ECr19-Cr3T2(5-3TAs19-M3At)5-4M19-BAm2J2(5-4B19-B3Am)5-6C8-3CiC3-3C3B178-8A24-8A14-21A11-2(A2Ag8-3A4-4A10-)Cu2Cb8-3Ao4-2V2Cu9-Bd-2Ab17-AbEf9-2(AnF19-2De2An7-)DfBh20-Ay2Dy2(7-DhDz20-E2Al)5-3Bu21-3Al5-3Ai22-2TY2(4-2YT22-2TI)4-2Aa23-2JCh2(4-2B23-3Ba)4-3C21-C2-B29-2C199-4AD6-D3A3-3D2A9-2(2A20-3A7-)2Cu20-Db2K7-AhCp20-Co2K2(5-2AcAn21-Ef2L)5-3Df22-2DyAr2(4-3Cv22-3X)4-2X23-3Al3-3N25-Bn3-2(3Y25-I2Y-)3Aa25-Ch2I2(-Ax2B25-3I)-B3C22-2C3I27-3C2B2(194-2DA3D17-D3A5-2(3D21-A2-A4-)3K22-3K4-3K22-3Db2(4-2AcAn22-3L)4-2An23-3Ar2(3-Bt2Ah25-X)3-Bt2X25-Al2Bn-Z2N25-3Bn2(-N27-3Be)-T28-2Y2(2Ax28-2I)Ax-2C26-2I-Ax2C25-3B)194-2Ak2D20-D2(3A4-2W23-)3A4-2Bq25-Bc4-2K25-K2(4-2Bi25-Ac)4-2L25-An2(3-3L25-Ah)3-Bt27-3Cd-Z28-2X2(-N28-2Be)-T28-2N2(AxT28-2Y)NBd28-2R2Bd27-3Ax2(194-2AkD22-2D2(A4-2W25-)A2(4-2Bq25-K)2(4-2Bi25-Ap)4-2L25-An3-2(3L25-3Ah-)Ar28-2Cd-X28-2X2(-Z28-2Av)YN28-2BnN2(29-3N)29-2ICjEn27-Em2R)194-2AkD22-3D2(4-2W23-2DA)4-2Bq25-K4-2Dv25-Es2(4-2K25-Df)3-L2Ac25-Cp3-2(L2Ac25-3Ah-)Ar28-2Cd-Cv28-2X2(-Z28-2Av)2Dl28-2Bn2(Cj29-2N)Cj29-2Cx2Cj2(27-3RBrEq)27-3R130-3D29-2(2W23-3D4-)2(2Bq25-Cu4-)2(2K25-Cb4-)2Ap25-Cb3-2(L2Ac25-3Ar-)3Ah25-3Ar-X28-2Z2(-Z28-2X)2Dl28-2Cv2(CjN28-2Z)Cj29-2CjCx29-2R2(ErBr27-3R)2(130-3DA28-2(3Ak21-D3A4-)2BpDu24-A4-3Bp24-A2(4-2Bc25-Cm)4-2Cm2(25-Ap4-2Ac)25-Ap3-Ah2Ea25-Cp2Ar-Eb27-3Bw2(-Z28-2X)-Dl2(28-2ZEdN)28-2Z2Ba28-2N2J28-2Cx2(2U27-3R))132-2D30-2(AkBp19-CuD2A7-)DuW21-3A6-Du22-2D2(Cm4-2BcW22-2W)Cm4-3Bb22-2Ei2(K4-2AnBl22-2Bp)K3-Eb2Bt25-Cp3-3Bw25-Bw2Cd2(-Ai27-3Ai)-Bz2(28-2N-N)28-2N-Ba28-2NJBa28-2Cx2(J-2J25-Dn2I)2(-U2J25-3R100-2D2A17-2A9-2(2D19-D-2A7-)WO2(20-O2Ak7-WBc)20-O2W7-WBc20-O2W7-2Bb21-2Dg5-2(2BvL22-3K4-)2Bt23-2BvDz3-Ai2Z25-Ek3-2(Aq2E25-E2Ai-)Bo27-3Al2(-Aw27-T2Y)-Ba28-2Y-Ba28-2X2(-J28-2I))-U2J25-3R101-3DA2D11-D3A11-2(D2Cl14-3D-A10-)2(3O17-2O10-)Bb2Ao18-V10-Bb2Ao18-V9-Ap-2Ab18-Ab2Dg2(7-ApDj20-Di2Ap)5-3Co22-2BvZ4-2Z23-3Bm2(3-Cz2Aq25-E)3-Bo2Bx25-Al2(3-M27-T)3-G2Aa25-3T-3G25-Ep2Eo2(-3Ba25-De2Ap)-J2-U24-3R2-2UJ99-Cl3A3D5-3D2A13-2(3Cl2A11-A2-A12-)5Ag12-3A12-5Ag12-3S12-2AoAb14-3SV11-2AoAb14-3SV10-Bl2-Ab16-FAb9-L-2Cf17-F-2Bd7-L-2Cf17-F-2Bd5-2Ej-Eb20-3Bd5-2CdAi22-3Cz2(4-2Bm23-3H)3-Aj2Bx25-Av2(3-3At25-Aw)3-3G25-Am3-G2I25-Ep2(4-2I25-Ar)4-3Ch22-2CnR4-6U5-3Bg89-13AD18-2(16A16-)2Ag4O4-A2OV2A16-2Ag2O7-2OV2Ao2(15-Ab3SAo9-Cy2S)13-2Bl4Ab10-Cy3F11-Dk2CfBh2CqBl11-2BkFAy10-Dk2CfBh2CqBl11-2BkFAy9-Bt-2Ad17-2Ay2Av5-2E-Q20-Aq2Av5-2(3E22-3H4-)3Dm22-3H2(4-2AjAl22-3Az)4-2AaG22-3B4-3G22-3G2(4-2IGU21-2GAx)6-Ch3U7-Af10-Cn2-Ch6-2U3Br2Cs2Bg3Af3BgEh3Cs3Da3Cn76-13AD18-2(16A16-)2Ag4O4-A2OV2A16-2Ag2O7-2OV2Ao2(15-Ab3SAo9-Cy2S)13-2Bl4Ab10-Cy3F11-Dk2CfBh2CqBl11-2BkFAy10-Dk2CfBh2CqBl11-2BkFAy9-Bt-2Ad17-2Ay2Av5-2E-Q20-Aq2Av5-2(3E22-3H4-)3Dm22-3H2(4-2AjAl22-3Az)4-2AaG22-3B4-3G22-3G2(4-2IGU21-2GAx)6-Ch3U7-Af10-Cn2-Ch6-2U3Br2Cs2Bg3Af3BgEh3Cs3Da3Cn114-5A27-5A25-2OA6O22-Ao2OW2OV3OS2(20-2Ab2BbBc2Bb2Ab2AuCy)20-5Ab3BlF3Cc17-Cb2DhBl6BjBlBj3Cc2Bk15-Cb2DhBl6BjBlBj3Cc2Bk12-3AdBu3BfDr2DkAc2Bi4-Dp2BhAy10-E-2Q17-2Aq2(2H7-2E20-Av)2H7-2E21-2H2(7-AlCp21-2Ct)7-2Aa21-2B7-GAa7-3J10-2(3G7-G-2GCi2HDn3BJ2Dc8-)3G8-U2DcCh2H2Dn3Cw2BgEl3Ce-3BrDc2Ch9-2BrDt2CwEh6AfEl4Ce2DaBrCn343-DjDp3Bf27-DjDp3Bf17-4AdBw2DrDv2BiAnBf2DsBf2QBm11-4Q6AdAn2LCp3Ad3Q-Aq2(10-Ad3By2E-Q3E9-2Aq)9-ByCq2SAp4-3Bz10-Bx2H2(8-Ee2CkDi3-At3Aj2Aa8-3As)8-Aa3Ai2YAaAt3Am2Aa8-3Am8-3GC2HC3B4J6-J-2G8-U2GC2HC3BU2JDt3AfCw2CaJG10-U2GC2HC3BU2JDt3AfCw2CaJG21-2BgCe3CoCe3Ca28-Ce2Ec345-DjDp3Bf27-DjDp3Bf17-4AdBw2DrDv2BiAnBf2DsBf2QBm11-4Q6AdAn2LCp3Ad3Q-Aq2(10-Ad3By2E-Q3E9-2Aq)9-ByCq2SAp4-3Bz10-Bx2H2(8-Ee2CkDi3-At3Aj2Aa8-3As)8-Aa3Ai2YAaAt3Am2Aa8-3Am8-3GC2HC3B4J6-J-2G8-U2GC2HC3BU2JDt3AfCw2CaJG10-U2GC2HC3BU2JDt3AfCw2CaJG21-2BgCe3CoCe3Ca28-Ce2Ec432-4Q3-2LDsE5QBm2(14-Q2E2Q9E3BmAq)12-2SAp2Bw7Bz2E3-2CrBo2(As11-2CkS3Ai6AjAwCg3-3Aw)As14-2YAaAt3-2AaC3CgG2AaAwAm23-Am3AfU2GJG24-3AfU2GJ25-3AfU2GJ70-
