model
size = 13 12 32, scale = 0.05, origin = -y
material 
  colors = A:#FFF B:#010101 C:#FDFDFD D:#FEFEFE E:#020202 F:#FCFCFC G:#B1B1B1 H:#F8F8F8 I:#F7F7F7 J:#070707 K:#B7B7B7 L:#D5D5D5 M:#F1F1F1 N:#B9B9B9 O:#040404 P:#2F2F2F Q:#0B0B0B R:#ECECEC S:#F2F2F2 T:#F4F4F4 U:#202020 V:#636363 W:#717171 X:#AEAEAE Y:#ADADAD Z:#B4B4B4 Aa:#131313 Ab:#EFEFEF Ac:#0C0C0C Ad:#7B7B7B Ae:#707070 Af:#060606 Ag:#4E4E4E Ah:#E2E2E2 Ai:#D9D9D9 Aj:#676767 Ak:#0A0A0A Al:#111 Am:#787878 An:#FAFAFA Ao:#B5B5B5 Ap:#A4A4A4 Aq:#D7D7D7 Ar:#080808 As:#212121 At:#9F9F9F Au:#C6C6C6 Av:#9A9A9A Aw:#E5E5E5 Ax:#F6F6F6 Ay:#585858 Az:#030303 Ba:#191919 Bb:#CCC Bc:#393939 Bd:#404040 Be:#9B9B9B Bf:#B3B3B3 Bg:#919191 Bh:#A8A8A8 Bi:#898989 Bj:#3D3D3D Bk:#B0B0B0 Bl:#C3C3C3 Bm:#C0C0C0 Bn:#E7E7E7 Bo:#E3E3E3 Bp:#505050 Bq:#222 Br:#D0D0D0 Bs:#050505 Bt:#282828 Bu:#F0F0F0 Bv:#9D9D9D Bw:#6D6D6D Bx:#D6D6D6 By:#343434 Bz:#CECECE Ca:#3F3F3F Cb:#CDCDCD Cc:#6B6B6B Cd:#EEE Ce:#101010 Cf:#BEBEBE Cg:#D8D8D8 Ch:#7F7F7F Ci:#E0E0E0 Cj:#A3A3A3 Ck:#989898 Cl:#5F5F5F Cm:#4F4F4F Cn:#535353 Co:#9E9E9E Cp:#545454 Cq:#C7C7C7 Cr:#BDBDBD Cs:#6E6E6E Ct:#121212 Cu:#6F6F6F Cv:#DBDBDB Cw:#B8B8B8 Cx:#303030 Cy:#8E8E8E Cz:#F9F9F9 Da:#FBFBFB Db:#1F1F1F Dc:#1B1B1B Dd:#808080 De:#D4D4D4 Df:#B6B6B6 Dg:#909090 Dh:#2D2D2D Di:#3C3C3C Dj:#666 Dk:#969696 Dl:#4D4D4D Dm:#1D1D1D Dn:#4C4C4C Do:#494949 Dp:#F5F5F5 Dq:#AAA Dr:#D1D1D1 Ds:#C2C2C2 Dt:#A9A9A9 Du:#979797 Dv:#DADADA Dw:#818181 Dx:#8C8C8C Dy:#373737 Dz:#CBCBCB Ea:#232323 Eb:#C8C8C8 Ec:#888 Ed:#DFDFDF Ee:#363636 Ef:#4A4A4A Eg:#7E7E7E Eh:#BBB Ei:#E9E9E9 Ej:#ABABAB Ek:#EBEBEB El:#878787 Em:#424242 En:#C9C9C9 Eo:#727272 Ep:#3E3E3E Eq:#929292 Er:#B2B2B2 Es:#CACACA Et:#767676 Eu:#1A1A1A Ev:#5D5D5D Ew:#353535 Ex:#2E2E2E Ey:#A7A7A7 Ez:#9C9C9C Fa:#747474 Fb:#E1E1E1 Fc:#5A5A5A Fd:#242424 Fe:#252525 Ff:#464646 Fg:#A6A6A6 Fh:#272727 Fi:#555 Fj:#EDEDED Fk:#7D7D7D Fl:#868686 Fm:#999 Fn:#0F0F0F Fo:#8D8D8D Fp:#D3D3D3 Fq:#0D0D0D Fr:#8A8A8A Fs:#E8E8E8 Ft:#A5A5A5 Fu:#484848 Fv:#8F8F8F Fw:#E6E6E6 Fx:#939393 Fy:#DDD Fz:#2A2A2A Ga:#DCDCDC Gb:#333 Gc:#CFCFCF Gd:#A0A0A0 Ge:#BFBFBF Gf:#797979 Gg:#757575 Gh:#7C7C7C Gi:#262626 Gj:#848484 Gk:#6C6C6C Gl:#646464 Gm:#595959 Gn:#565656 Go:#858585 Gp:#BCBCBC Gq:#3B3B3B Gr:#F3F3F3 Gs:#0E0E0E Gt:#313131 Gu:#696969 Gv:#C4C4C4 Gw:#EAEAEA Gx:#838383 Gy:#DEDEDE Gz:#686868 Ha:#161616 Hb:#A2A2A2 Hc:#323232 Hd:#737373 He:#171717 Hf:#3A3A3A Hg:#444 Hh:#828282 Hi:#ACACAC Hj:#BABABA
voxels
43-WChAyVUAc7-3EAz2B7-AzEJAk2B86-2Cx2AjAy8-BqAl2AkAlAc7-2JCeBaAlQ7-GbCyCfEhCgEi8-FCfEjBrA8-EkBbCfCgD8-CzBbGcEkDa8-2ARS10-AMAn46-QBcAd2AjAeAyBt5-Dc6-Al5-B6-Ce5-E2-AeDdEl-Bu6-DeGdAd-Be-Da6-F-Ap-Ge-Cz6-A-BeYDf-Da7-BfGfYBgAq8-BhGgBcBiZ45-As2AdAtGBvChBt5-Dh6-Aa5-B2-BgGhDj2-Gi4-Em-Ad3-Bw-Cg4-2Ci4-CjEn5-A-Ck3-BiBr6-ACk3-BiBu6-AGj3-GkD7-Bi3-Eo44-AaGlAt2G2NBvEp4-Aa8-Bt3-B2-2EqBgClDl-Ba4-BeW5-BfBu4-RBk5-BfAn4-A-Er4-EsBu4-A-Gm3-DnCj6-ZBy3-2Et56-AgG2BlBz2AuGCa4-Af8-Ex3-Af-WAdBgGoClDo-Ex3-DqAp6-DgAn3-I-Ds5-CoAn4-FEy5-DuCz4-AAp5-CyD5-Av5-Bi56-CaAu2LDvLAuBmCa4-Dm8-P3-B-W2CcBw2Dn-P3-CqAm6-BkD3-AGp6-CoD3-A-Ez5-FaD4-SBe5-FaD11-Bh56-GqBxBnBoGrHFbBzBp4-Ew8-Aa3-Af-WDjCcFc2Do-Fd3-EyAj6-CkA3-BoDw6-BwA3-A-Dk5-FeA4-ABe5-FeA68-FfAw2BnCHFbLCm4-Fh8-Aa3-Dm-AmAeCcDlBcBp-As3-ErCs6-AyA3-Dr-Dg5-AyA3-D-Dk5-CtA4-ADu5-AfF68-FiTH3AHDsBq4-Fh7-Bq3-B2-AdCuDjCaPVBq3-D-Dw6-ClBr2-A2-Dw5-DyEh3-2DL5-AaFj5-CyAg4-JA11-EDq55-Bw2C3ACFkGs3-Af8-Ba3-Af3-CuBpGtUEaBa3-D2-Cv5-CnA2-D2-Cw6-Fm3-AnD-Au4-FnFo5-AiFc4-JA11-AfGw54-FdAe2C3ACFk4-By8-Fq3-Ec3-AjAgPU-Fq3-Ec2-C4-Ac-A2-F2-Fs5-OCo3-SA-C4-BqDt5-ABw4-CtA5-FEv4-JF11-EuZ41-DbGyC4ACAe4-Ee8-Q3-Gz3-2EfAsAl-Q3-R2-C4-Ac-A2-M2-A5-JDt3-FABo5-BjAp5-2Ft4-CtA5-AqBg4-CtA5-FpEb4-ArAn5-DzR4-FuZ28-BtHCH2CACAm4-Bj7-By3-Hc4-CsEfAsAa-Q2-F2(-A)4-U-De2-MF-H5-AaDe4-ACb5-AjDr5-AhH4-AyA5-DHd4-FnA5-FBa4-OA5-AiCl4-CnA5-AvBhDc3-FgBu6-BbEl7-BpCTH4CBg3-Bt8-By3-Ee-2ABmAdAgBjP-E2-FjM-2A4-Dh-A2-MD-H5-DhA4-A-A4-DdAb4-A-Dv4-DdA5-CjBp2-A-ByA5-FvBa-FxCbA-A5-BrCk-FxBeA-Cq5-Ec-FfCnCrFzFl7-EbAqBfAhEsAq3-AeCTH2CHBxCo3-Bj2-CDv4-Ar3-Dy-A2-WVBjP-E2-CdM7-V-A2-MFD6-CuR4-3A4-CwA4-F-Eg4-EzA4-Em-Eg2-2A-A5-CDx-Cw3-A5-Ap-Am4-Cq6-F2-A-Bh8-SM-BbAq2-PDfHBnAx2CH2Bx3-P2-AFsG4-Ar2-Bc2A3-2VCs-Ar2-CdF7-Eg-A2-FAD6-HiA4-3A4-HjA4-Z2-4A-A4-Fu2-3A2-A5-Dz-Cw4-A5-Fm5-Fo7-AbS-CDcBf9-Ai5-PDf2AwAxC2HTDl3-EpA-2ALY3-Fz2-Ee-A4-WCs-Q2-MD7-Fy-A2-2(DA)5-GaA4-DA5-GaA4-Z-A3-A-A4-M2(2-A)-A5-Cf2-FwAx-Cb7-SAb3-Ej9-BoRApEn15-BpLBoAwT2H2THhAc-PCa-3AAxY3-Hg-AsHf-A4-WAu-He-CrMD7-Fy-A2-2DFA5-FwA4-Cd-A4-AxA4-Fr-A2-2AC5-S-A2-A-Fv6-Cr2Ab-A-Aq8-AbCdCDuAi27-UAgLCvBoT2H2TDsU-PFi-A-2AHAx2-Cx-P3-A4-AuCCc-BhF2D7-AxA2-FAD6-2A4-Z2A3-A-A4-Cd-A2-A-D6-Ah-C-A-Ai7-I-C2-A8-2IA2Bb27-BdAgLBzLEdBn2AwEd2Bk-Bd3-3A2-A2-EaBc4-4A-A-EaBcF2A7-AAn2-A2D6-2A4-ZCg4-A-M4-M-A2-A-Hb6-BrDSC2-Ha8-AbICbBf41-UAe2BlLEdBnAwBzBlBkCh-Bd6-3A2-DiBs7-2A2-AsGx2A7-A-A2-FSCj6-AD4-FrF5-S6-I2A2-AhFp7-3ARC11-CiR41-AaAt2BmGvL2CvBz2KCu-As9-A-DyE9-2AAcGu2A8-AEb2-AFCq6-AD4-2AhA3-FlDz6-F-ACI2Av7-2ACDp55-AkDx3NBl2LNBkKVQAc10-AOE11-EOEiA8-AAi2-CZDqA5-2F4-3A3-AhAi7-A3CI11-Ci55-AkDx4NKBmKGKVJAk9-A-JO10-AAzBFgA8-ACr2-IAqAiA5-Dp5-4A-S2Av7-2A3I67-AkAe3N4K2GBd-2Ce8-A-Bs2O8-A-EBCpF8-DCp2-FIC5-RI5-C4AIAbR8-2AI69-AmGAoBm2K2Ao2GBd2-UG8-Bs2JO9-OE-2Cp8-BhE2-FCbDtC4-RAb5-AvEoBiDrDpIAh82-2X2KAoGYAt2Cm2-U2GX6-Q2-J9-BE-BEw8-Ev3-Eu2B4-BxGnAp5-5BDmCn84-4G2YCmQ2-JWAoGX3-DkDiQ2-JO8-B2-2B7-2B3-2ArB4-3B5-6B86-AoGAt2Bv5-Bj2X2GAtBvAtDiAc3-O7-AzB3-2E6-2B3-BArB4-2B6-6B96-AlDg2GX2Y2Ag4-ODbX5-E4-2E5-2B5-EAfE2-B-B6-EAzE3B98-Ao2GXAmBdAl5-Db-ChGVAm2Bs5-2E4-2B5-BAzQE3B8-2E2B82-
