model
size = 25 32 28, scale = 0.05, origin = -y
material 
  colors = A:#C00 B:#F90 C:#C33 D:#F93 E:#111
voxels
786-3E293-3A5-3A3(14-11A)15-3(9A16-)9A17-7A20-3A567-4B5-4B12-13B5(12-3B7-3B)12-4B5-4B13-4B3-4B15-9B17-7B19-5B514-B3A9-3AB8-B15A2(B8-BA13-A)3(B8-B2A11-2A)B9-2A11-2A10-3A9-3A11-2A9-2A13-2A7-2A14-11A15-9A18-5A463-2(AB2C11-2CBA6-)4(AB15-BA6-)ABC13-CBA7-2(BC13-CB8-)2B13-2B8-3B11-3B9-2BD9-D2B11-4B5-4B13-11B16-7B437-ABC13-CBA5-BAB2C11-2CBAB5-3(A17-A6-)3(AB15-BA6-)AB15-BA7-B15-2(B8-BC13-C)B8-BAC11-CAB2(9-3A)11-13A13-11A409-BAB15-BAB4-BAB2C11-2CB5(AB4-BA17-)AB5-A17-3(A6-AB15-B)A7-B15-B8-BA13-AB8-BAC11-CAB9-ACD9-DCA11-13A16-5B387-BAB15-BAB3-AB-B2C11-2CB-BA3-3(B19-B4-)2(BA17-AB4-)BA17-AB5-2(A17-A6-)AB15-BA6-AB15-BA7-B15-B8-BA13-AB9-AC11-CA10-6A-A-6A12-11B383-2(AB)15-2(BA)2-AB-B2C11-2CB-2(BA2-AB19-)BA3-2(B19-B4-)2(BA17-AB4-)BA17-AB5-A17-2(A6-AB15-B)A7-B15-2(B8-BC13-C)B9-A2C9-2CA11-13B15-7A360-2(AB)15-2(BA)2-A-AB2C11-2CBA-A2-A21-2(A2-AB19-B)A3-3(B19-B4-)BA17-AB5-2(A17-A6-)AB15-BA6-AB15-BA7-B15-B8-BC13-CB9-AC11-CA11-13B14-9A359-ABA17-A2(BA-)AB2C11-2CBA-AB-2(A21-A2-)AB19-BA2-AB19-BA3-2(B19-B4-)BA17-AB4-BA17-AB5-2(A17-A6-)AB15-BA7-B15-B8-BC13-CB8-B2C11-2CB9-5B5-5B12-11A357-2(BA)17-ABA2BA-AB2C11-2CBA-A2BA21-AB-2(A21-A2-)AB19-BA2-AB19-BA3-B19-3(B4-BA17-A)B5-A17-A6-AB15-BA7-2(B15-B8-)BC13-CB9-4B7-4B12-11A357-2(BA)17-ABA2B2-AB2C11-2CBA2-2BA21-AB-3(A21-A2-)AB19-BA3-3(B19-B4-)BA17-AB5-A17-2(A6-AB15-B)A7-B15-B8-BC13-CB2(9-3B)12-11A357-2(BA)17-ABA2B2-AB2C11-2CBA2-2(2BA21-A)B-2(A21-A2-)AB19-BA2-AB19-BA3-2(B19-B4-)BA17-AB5-2(A17-A6-)AB15-BA7-B15-B8-BC13-CB2(9-3B)12-11A357-2(BA)17-ABA2B-BAB2C11-2CBAB-2B23-2(2BA21-A)B-2(A21-A2-)AB19-BA3-2(B19-B4-)BA17-AB5-2(A17-A6-)AB15-BA7-B15-B8-BC13-CB9-B2D9-2DB11-13A356-BAB19-BA2B-BAB2C11-2CBAB-2(2B23-)2BA21-AB-2(A21-A2-)AB19-BA2-AB19-BA3-B19-B4-BA17-AB5-2(A17-A6-)AB15-BA7-B15-B8-BC13-CB9-BD11-DB11-13A331-B2D19-2D2B2(AB)2C11-2C2(BA)2B-BAB2C11-2CBAB-2(2B5-C11-C5-)2BA21-AB-2(A21-A2-)AB19-BA2-AB19-BA3-B19-B4-BA17-AB5-A17-2(A6-AB15-B)A7-B15-B8-BC13-CB8-2BD11-D2B10-13A307-3C17-3C-B6D11-6D2BDBAB2C11-2CBABD4(2B2(AB)-C11-C-2(BA))B-2(AB)2C11-2C2(BA)2-2(AB)15-2(BA)2-2(AB)C13-C2(BA)3-2(BABC13-CBAB4-)BAB2C11-2CBAB5-ABAC11-CABA6-ABAC11-CABA7-2(BAC11-CAB8-)B2C11-2CB9-B2D9-2DB11-13A282-3AC15-C3A2-3A3C11-3C3A-B3AD3C9-3CD3A6B2CB9-B2C5B3-2B2AB9-B2A2B6-2B2A11-2A2B7-5(B2A11-2AB8-)B2A11-2AB9-2A11-2A10-2AB9-B2A11-3(AD9-DA12-)2(A11-)2A11-2A10-4B7-4B12-11A234-3B15-3B4-4B13-4B4-2A4C9-4C2A3-3A4C9-4C3A2-3A4C9-4C3A5-B2AB9-B2AB235-AB9-BA13-B9-B14-B9-B13-AB9-BA12-2(A11-)2A11-2A10-6B3-6B13-9A161-2A15-2A6-3A13-3A6-4A11-4A5-2(6B9-6B4-)6A9-6A4-6A9-6A6-4A9-4A261-2(B9-B14-)B9-B13-2(AB9-BA12-)A11-A12-13B16-5A89-2(3A11-3A8-)3A11-3A7-2(AD3A9-3ADA6-)AD3A9-3ADA5-6B9-6B4-6B9-6B6-2(4B9-)3B9-3B287-3(B9-B14-)B9-B13-AB9-BA12-AD9-DA12-13B110-3A2B7-2B3A2(8-A2D2B7-2B2DA)7-2(4A2B7-2B4A6-)5A9-5A7-2(4A9-)3A9-3A12-A9-A314-3(B9-B14-)B9-B13-AB9-BA12-3A7-3A15-7B114-4(4B7-4B10-)4B7-4B11-2B9-2B388-3B5-3B14-B-B5-B-B14-B-2(B2-)B-B14-3B2-B2-3B14-11B15-9B45-C24-C69-2E7-2E14-2E7-2E465-2A5-2A15-B9AB14-BA-5A-AB14-B9AB14-11B16-7B19-A3DA2(20-5A)20-A3DA20-A3CA21-3B544-2(9A16-)9A19-3D22-3D21-A3CA4(20-5A)21-3B544-9B17-7B20-3(3B22-)3B72-2(3D22-)3B597-3E22-3E23-E98-2(3B22-)3B11-
