model
size = 32 4 30, scale = 0.05, origin = -y
material 
  colors = A:#AAA B:#EEE C:#FC0
voxels
44-4A100-3A123-6A111-2A5-10A3BA21-7A2B75-7A-B15A18-13A71-27A8-5A3-14A70-28A6-8A2-15A69-29A4-15A8B4A67-30A4-6A17B4A67-31A2-2AB2A19B4A66-32A2-2AB2A19B5A17-C47-A2B9A9-11A2-5A7B5-7B6A13-8C43-A2B9A9-11A2-5A6B7-6B5A13-2C4-3C25-4C15-2B9A9-11A2-5A5B9-5B5A13-C6-2C24-6C14-2B9A9-11A3-4A5B9-5B5A13-C6-3C23-6C15-10A9-10A5-3A5B9-5B4A14-C6-3C23-6C16-9A9-10A5-3A5B9-3B5A15-C6-3C23-7C16-8A9-9A6-3A5B9-3BA2B2A15-C6-3C23-7C16-8A9-9A6-3A6B7-4BA2B2A15-9C26-4C16-9A9-8A7-5A5B5-5B3A19-6C47-25A8-5A15BA23-2C50-22A10-5A14B77-20A13-3A15B77-20A13-3A8B6A78-19A15-2A8B6A79-18A15-15A80-17A17-14A82-14A20-AB7A86-11A25-4A91-6A28-A82-
