model
size = 20 30 30, scale = 0.05, origin = -y
material 
  colors = A:#444 B:#555 C:#666 D:#933 E:#777 F:#800 G:#663 H:#888 I:#930 J:#111 K:#999 L:#333 M:#222 N:#B00 O:#AAA P:#C33 Q:#400 R:#F99 S:#E00
voxels
228-4D3(16-D2-D)17-2D556-B2G2CB13-ABCG2CBA9-4I4D6I6-13DI2(6-14D)6-2I11DI10-AB3CA414-6A11-12A8-3AB2G2CB3A7-4AB4-B4A4-2I4A5-D4ADI2-ID2ALA5-DAL2ADI2-2DA2L6-2D2LA2D2-IDA3L5-D3LADI2-2ID4A4-4A2DI5-AB2AB3C2ABA9-BAB4CBAB11-A2B3CBA14-4M333-10A9-3AB2G2EB3A7-B3AB4-B4A6-BA10-2A5-ABA10-ABA3-I3(BA12-ABD2-D)BAL10-LABD2-I2BA10-A2BI4-2AB8-B2A2(6-A2BA)7-2BA2B2-CBA2B9-3J4M3J11-2C3BEAC292-8A9-5ABC2E5A6-ABA8-ABA5-ABA10-A2(BA4-AB12-)BA2-IDB14-BDI2DB14-BD2(2I2B14-BA)2ID2B12-2BDI2-BA12-AB4-2AB10-B2A5-A2B8-2BA2(6-4J)7-HECA3BEACEH10-7CK270-12A7-2B2A6-2A2B5-AB12-BA4-AB12-BA3-AB14-BA2-2A14-2A-I2(2B14-BAID)2(2B14-BADI)2B14-BAI-2B14-BA2-3A12-3A3-2A12-2A4-3J10-3J5-KHEC6-CEHK7-KH2KOK2L2KHK10-8C249-14A5-A2B10-2BA4-AB12-BA3-AG14-GA2-AB14-BA2-A16-A-IB16-AID2(B16-A2D)B16-ADIB16-AD-B16-A2(2-2A14-2A)3-2J12-2J4-OKH10-HKC5-2(HK)6-2(KH)8-2CEHK2CECH12-6C230-14A5-AB12-BA3-AC14-CA2-AG14-G2(A2-A16-)A-IB16-AID2(B16-A2D)B16-ADIB16-AD-B16-A2-A16-A2-2A14-2A2-2J14-2J3-OK12-KC4-2HKH8-HK2H6-2C2E4-2E2H10-8C228-16A3-ACB12-BCA2-AC14-C3(A2-A16-)A-DB16-AID2(B16-A2D)B16-ADIB16-AD-B2(16-A2-A)16-A2-2J14-2J2-HO14-CH3-2HK10-K2H5-HCHE6-E3H8-3C2EKO3C12-6C209-16A3-AC14-C4(A2-A16-)A-DB16-AID2(B16-A2D)B16-BDIB16-BDAB16-B3A16-2A-A16-A2-J16-J2-HO14-CH3-2H12-HC5-3H8-3H7-E3C4-2C2E10-8C208-16A3-AC6-CE6-C2(A2-A7-GE7-)A-2B16-B3A16-2ADB16-BID2(B16-B2D)B16-BDI18-DA18-3A16-4A16-2A-J16-J2-HO14-CH2-HLH12-HLC3-E2H10-2HE6-2EC6-C2E9-CE8C207-16A3-AC5-BCEB5-C2(A2-A6-2GEG6-)A-2B6-2GCG6-B2A8-GC8-AD3(18-2D)18-DI18-DA18-2A18-3A16-2AMJ16-JM-H16-H2-HL14-LC3-E2H10-2HE5-C2E2(8-2EC)BGC2B2C13-4C171-A12-A5-AC5A2-5ACA3-AC4-AB2-BA4-CA2-AC5-G2-G5-CA-B2G5-G2-G5-2GA2B6-2GCG6-B2A8-GC8-AD3(18-2D)18-DI18-DA2(18-2A)18-AMJ16-JM-H16-H2-HL14-LC3-EH12-HE5-C2E8-2EC8-2E2B2-2B2C12-6C189-2(6A4-)A4-AB2-B3(A4-)BG2-GB4-A2-B2G5-G2-G5-2GAB7-2GCG7-2A18-AD3(18-2D)18-DI18-DA2(18-2A)18-AMJ16-JM-H16-H2-HL14-LC3-EH12-HE5-C2E8-2EC7-C2EB4-B3C11-6C69-NF11-FN4-3F11-3F3-3F11-3F4-2N11-2N45-7A2-7A4-A2BA-AB2-BA-A2BA4-AB4-G2AG4-BA2-B2G5-2GEG5-2GAB7-2GCG7-2A18-AD4(18-2D)18-DA2(18-2A)18-AMJ16-JM-H16-H2-HL14-LC3-EH12-HE5-CE10-EC7-C2EB4-B3C11-6C48-N2F11-2FN3-3F11-3F4-CF11-FC5-CF11-FC4-3F11-3F3-N2F3-2(2A2-)2FN9-6A3-B8-3AB2-B3A8-2B3AB2AB3A2B5-A2B2AB2GEGB2A2BA2-B2GB2A3-GE3-2AB2GA2B16-B2A18-AD4(18-2D)18-DA2(18-2A)18-AMJ16-JM-H16-H2-HL14-LC3-EH12-HE5-CE10-EC7-C2EB4-BE2C10-8C28-NF11-FN4-3F11-3F4-CEA10-FC4-IFCA10-2FI3-IFCB10-2FI4-3C10-FC4-2FCB10-3F4-N2B2-6A2-FN26-B18-AB-3A4-3A-2A2-B2GB3A6-3AB2GA4B12-3B3A16-2ADB16-B4(2D18-)DA2(18-2A)18-AMJ16-JM-H16-H2-HL14-LC3-EH12-HE5-CE10-EC7-C2E6-E2C10-8C27-3F11-3F4-C2E10-FC4-IFEA10-2FI4-2CA10-FC5-2CB10-FC4-IF2C10-2FI4-2CB10-FC4-2F2B3-4A3-3F44-2(3A-3A2-)B2GB3A6-3AB2GA4BA10-A3BA-A16-A-D3(B16-B2D)18-2D18-DA18-2A18-3A16-2AMJ16-JM-H16-H2-HL14-LC3-EH12-HE5-CE10-EC7-C2E6-E2C10-8C27-3F11-3F4-C2E10-FC4-IFEA10-2FI4-4C8-CFC5-2C2B8-BFC4-IF2C10-2FI4-2CB10-FC4-2F2B10-3F45-2A-8A-2A3-B2G-3AB4-B3A-2GA4B2A8-2A3BA-2A14-2A-D4(B16-B2D)B16-BDAB16-B3A16-4A16-2A-J16-J2-H16-C2-HL14-LC3-EH12-HE5-CE10-EC7-2CEB4-BE2C10-8C28-NFE10-FN4-2F3E8-E3F4-CE2C8-CFC4-IF3C8-C2FI3-IFC2B8-B2FI4-3CB8-BFC4-2FCB10-3F4-F2B10-2F46-2A-8A-2A3-BG2-3AB4-B3A2-GA4B2A8-2A3BA-2A14-2A-D2(2B14-2B2D)2(B16-B2D)B16-BD-B16-B2(2-A16-A)2-J16-J2-HO14-CH2-HL14-LC3-EH12-HE5-CE10-EC7-3C2B2-2B3C11-6C31-2E8-2E5-2F3E8-E3F3-2FE2C8-C3F4-4C8-CFC5-2C2B8-BFC4-2F2CB8-B3F3-NFCB10-2FN5-2B-2ABCEB2A-2B46-2A-8A-2A3-BG-B3A6-3AB-GA4BA10-A3BA2-A14-A2-D-B14-B-4(2D2B14-2B)D-B16-B2(2-A16-A)2-J16-J2-HO14-2C3-2H12-HC4-E2H10-2HE5-C2E8-2EC7-4CBGCB4C12-4C32-3(2E8-)2E6-2F3C6-2C2F4-3F3C6-2C3F3-2FC2B8-B3F4-F2CB8-B2F6-CB3AB2-B3ABC8-3ABCEB3A48-14A3-B2GB3A6-3AB2GA4B12-3BA2-A14-A2-D4(-B14-B-2D)2B14-2BD-2B14-2B2(2-2A14-2A)2-2J14-2J2-CO14-2C3-2H12-HC5-2H10-HC7-CEC6-CEC9-10C30-E8-E9-2(2E8-)3E6-3E8-3C6-3C8-4C4-4C8-4B4-4B8-C3B4-3BC9-3AB2-B3A8-2B2A-BCEB-2AB45-6A-4A-6A2-AGB2A8-2AB2G2-AB14-2B2-2A14-2A-D-B4A6-4AB-ID-B2ALA6-AL2A3(B-2D-B14-)B-D2-B14-B4-A14-A3-2A14-2A2-2J14-2J3-AK12-KC4-MHK10-KHC5-3H8-2HC7-4C2EKE4C10-8C31-E8-E9-2(2E8-)3E6-3E8-C-C6-C-C8-4C4-4C8-4B4-4B100-B4-5A8-2AB2A2-AG14-2G2-A2B3A6-3A3B2-2AB3AB4-B3AB2A-I-BA2Q2AG2-G2A2QAB-ID-BAFLFAB2-BAFLFAB-2D-BA2L2A4-2A2LAB-2D-BA12-AB-2D-2B12-2B-D2-B14-B4-A14-A4-2A12-2A4-2J12-2J4-AKH10-HKC5-HKH8-HKA7-CH2E4-2EHC9-10C50-EH6-HE9-2(3E6-3E8-)4C4-4C8-4C4-4C9-3B4-3B50-3B4-3B10-3AB2-B3A8-2B2A-BCEB-2A2B4-2A2BA3-GE3-A2B2A2-AG5-2GEG5-2G3-2B3AB2GCGB3A2B4-AB2-ABCG2C2(BA2-)I-BA3-AG2-GA3-AB-ID-BQ-S-AB2-BA-S-QB-2D-BA3FAB2-BA3FAB-2D-BA3LA4-A3LAB-2D-2B12-2B-I2-BA12-AB2(4-2A12-2A)5-2J10-2J6-CHE8-EHC7-AH2K4-2KHM9-2CEHKCHECH12-6C52-EH6-HE10-2E6-2E10-3E4-3E10-3C4-3C10-4C2-4C11-2B4-2B52-2B4-2B11-3AB2-B3A10-2A-BCEB-2A7-5A-2GEG-5A4-GB2A2-2GEG2-2ABG4-2B3AB2GCGB3A2B9-BCG2CB7-I7-G2CG7-ID7-B2-B7-2D-BQ3-AB2-BA3-QB-2D-BA3F2A2-2A3FAB-DI-2B12-2B-I3-2A10-2A6-AB10-BA6-A2B8-2BA6-3J8-3J7-CECA4-ACEA9-MCKOKLO2KC12-E4CE72-E2H4-2HE10-3E4-3E10-4E2-4E10-4C2-4C11-3C2-3C12-2BC2-C2B51-4B2-4B10-3AB2-B3A11-A-BCEB-A11-2A-2GEG-2A8-B3A-2GEG-3AB6-B3AB2GCGB3AB9-ABCG2CBA6-I7-G2CG7-ID2(7-B2-B7-2D)2-A3F2A2-2A3FA2-DI2-B4A4-4AB2-I3-2AB8-B2A7-2BA6-A2B8-2BAB4-BA2B9-3JM2-M3J10-A2C4B2CA12-COA3C93-2HKO2K2H12-3EHK3E12-3EH4E2(12-3CE4C)13-B4CB53-3B2-3B2(12-2ABCEB2A)12-AB2GEGBA11-2AB2GEGB2A9-3AB2GCGB3A9-2ABCG2CB2A5-I6-AG2CGA6-2I2(7-B2-B7-2D)6-2A2-2A6-2I3-4AB2-B4A3-I4-AB2AB2-B2ABA9-BAB4CBAB11-A2B2C2BA13-J4MJ15-4C115-HKO2KH14-2EHK2E14-2EH3E2(14-2CE3C)73-3B2-3B2(12-2ABCEB2A)13-B2GEGB14-BG2-GB9-5DBG2-GB5D3-D4-APCG2CDA4-P-I6-AD2CDA6-2I7-4D7-DI7-4D7-ID7-DBGD7-2I6-ADBGDA6-I-D5-DB2CBD5-D3-5D-4C-5D171-OK17-EHKE17-HE116-2BCE2B2(14-ABCEBA)15-2GEG16-G2-G11-3D2(2-G)2-3D5-5D-CGC2-5D3-2D3-PD4-2D3-PD-2D5-2D2-2D5-2DPD5-DR2-PD5-DR2D5-2D2-2D5-2D-DP3-2D4-DP3-2D3-5D6-5D5-3D8-3D163-
