model
size = 30 31 24, scale = 0.05, origin = -y
material 
  colors = A:#FFAE00 B:#2A4A5B C:#46647C D:#4B4B4B
voxels
154-9A2-2(3A6-)11A-4A4-4A5-13A-4A2-4A5-5A6-3A2-4A-3A6-6A6-3A2-7A6-8A4-3A3-5A7-3A-5A3-3A3-4A8-3A3-4A2-3A2-6A7-3A4-4A-3A2-7A6-3A5-7A2(-4A)5-3A6-6A-3A3-3A6-4A5-8A4-4A5-12A19-10A10-4A9-5A12-4A5-3A21-2A3-6A-7A-13A2-2A2-5A-2A-A-2A2(2-A)2-2A3-3A4(-2A)-3(A2-)2A4-A2-4(2A-)A2-2(2A-)2A6-3A7(-2A)5-3A2-2A2-A-2A2-4A2-5A4-2A28-2A-DA26-3A624-2B24-2B2-2B24-2B603-2B22-2B4(4-CB22-BC)4-2B22-2B63-2B24-2B2(2-CB24-BC)2-2B24-2B543-2B22-2B4-CB22-BC124-CB22-BC4-2B22-2B3-2B24-2B2-CB24-BC62-CB24-BC2-2B24-2B484-3(B22-B5-CB22-BC184-CB22-BC3-CB24-BC122-CB24-BC-3B24-6B24-3B423-)B22-B5-CB22-BC184-CB22-BC3-CB24-BC122-CB24-BC-3B24-6B24-3B393-B22-B6-B22-B5-2B22-2B4-CB22-BC124-CB22-BC4-2B22-2B3-2B24-2B2-CB24-BC62-CB24-BC2-2B24-2B-3B24-6B24-3B393-B22-B6-B22-B5-2(2B22-2B4-)4(CB22-BC4-)2B22-2B4-2B22-2B3-2(2B24-2B2-)2(CB24-BC2-)2B24-2B2-3(2B24-2B-3B24-6B24-3B393-B22-B6-B22-B5-7(2B22-2B4-)2B22-2B3-5(2B24-2B2-))3(2B24-2B-3B24-6B24-3B363-2(B22-B6-)B22-B5-7(2B22-2B4-)2B22-2B3-5(2B24-2B2-))2B24-2B-3B24-6B24-3B386-2(B6-B22-)B5-7(2B22-2B4-)2B22-2B3-5(2B24-2B2-)2B24-2B-3B24-6B24-3B306-2B14-2B10-4B14-4B7-5B14-5B6-3B18-3B29-B5-7(2B22-2B4-)2B22-2B3-5(2B24-2B2-)2B24-2B-4B22-8B22-4B2-2B22-2B6-4B14-4B10-2B14-2B194-2B10-2B12-4A12-4B3A6-5A12-3B4A5-6A14-4A5-5A2B16-AB5-3A2-A18-2B4-3A20-4B3(3-3AB21-2B)3-2(3A22-3B2-)B2A22-A2B2-B2A22-3B-3BA23-6B24-5BA24-A3B2A24-2A2B2A24-A3B3A23-A4BA2B20-B2A6B3AB14-B2-B2A2B2-B3A2B14-2B5A4-2A5B10-6B7-2A-DA2B10-4B10-3A-2B10-2B110-B4-B22-3B4-3B18-5B4-5B12-4A10-4B2-3A6-5A12-2B-4A5-6A12-2B4A5-5A2-2B11-B2-A6-6AB17-B5-6A17-2B5-3AB2A16-3B5-3A3B17-2B5-3A4B17-B5-3AB21-3B2-3A22-3B2-B2A22-A2B2-B2A22-3B-3BA23-7B23-5B2A23-A3B3A23-2A2B2AB23-A3B3A23-A2B2-A-B2AB14-2(B2A)6-3AB14-2(B2A)5-3A2B14-2B5A4-2A3-4B6-4B11-2A-DA5B4-5B12-3A-5B4-5B18-3B4-3B22-B4-B26-2B26-6B22-10B20-4B2-4B14-6A8-2B4-3A6-7A9-B3-4A5-8A9-A2-4A5-5A4-2B8-A-3A6-6A-2B11-4A6-8AB12-2A7-3A-5A12-A8-3A3-3A12-2A7-3A4-A13-3A6-3A4B14-4A5-3A4B14-B3A6-4A2B14-B4A5-6A14-4B7-5A14-B4A7-2B2A14-B4A5-3A3B14-4B2A3-6AB14-7A2-2A-B3A14-BA2B2A3-3AB2AB14-BA2B2A4-A2-2A-2A10-2(2A-)2A6-3A-2A10-2(2A-)2A5-3A2-2A10-2A2-5A4-2A5-3B4-3B13-2A-DA2(2-4B)14-3A3-10B20-10B22-6B26-2B27-2(4B26-)4B17-9A2B2(3A6-)11AB4A4-4A5-13AB4A2-4A5-5A6-3A2B4A-3A6-6A3-3B4-B7A6-8A-3B4-2B5A7-3A-5A3B4-2B4A8-3A3-4A2B4-B6A7-3A4-4AB4-B7A6-3A4-BA10-AB4A5-3A4-2B10-2B-3A6-4A2-2B10-2B-4A5-8A10-2B11-7A10-2B-4A9-4A10-2B-4A5-3A3-2B10-2B4-2A3-6A-2A10-9A2-2A2-5A10-AB-A2-2A3-3A2(-2A)10-AB-A2-2A4-A2-2A-2AB2(2A-)A2B2(2A-)2A6-3A-2(2AB2(2A-))2A5-3A2-2A2BA-2A-B4A2-5A4-2A8-4B16-2A-DA5-4B17-3A6-2(4B26-)4B137-9A2-2(3A6-)11A-4A4-4A5-13A-4A2-4A5-5A6-3A2-4A-3A6-6A6-3AB-7A6-8A4-3AB2-5A7-3A-5A3-3AB2-4A8-3A3-4A2-3AB-6A7-3A4-4A-3AB-7A6-3A5-4A4-4A-4A5-3A6-3A4-3A3-3A6-4A4-B2A4-2AB3-4A5-11A4-3B13-10A4-3B3-4A9-5A2B4-3B3-4A5-3A5-3B4-3B6-2A3-6A-5A4-12A2-2A2-5AB2A4-A2B2(A2-)2A3-3A2(-2A)B2A4-A2B2(A2-)2A4-A2-2(2A-)2(2AB)A2-2(2A-)2A6-3A2(-2A)2(B2A)3(-2A)5-3A2-2A2-AB2AB-4A2-5A4-2A28-2A-DA26-3A207-9A2-2(3A6-)11A-4A4-4A5-13A-4A2-4A5-5A6-3A2-4A-3A6-6A6-3A2-7A6-8A4-3A3-5A7-3A-5A3-3A3-4A8-3A3-4A2-3A2-6A7-3A4-4A-3A2-7A6-3A5-7AB4A-4A5-3A6-6AB3A3-3A6-4A5-8A4-4A5-12A3B16-10A4B6-4A9-5A2-4B6-4A5-3A8-4B9-2A3-6A-7AB13A2-2A2-5A-2ABAB2A2(2-A)2-2A3-3A3(-2A)B2AB3(A2-)2A4-A2-4(2A-)A2-2(2A-)2A6-3A7(-2A)5-3A2-2A2-A-2A2-4A2-5A4-2A28-2A-DA26-3A83-
