model
size = 30 31 24, scale = 0.05, origin = -y
material 
  colors = A:#777 B:#39C C:#888 D:#F3C E:#FF6 F:#FCC G:#FF0 H:#FC6 I:#FCF J:#F3F K:#FFF L:#FF9 M:#FF3 N:#FFC O:#F6F
voxels
216-EGL12-E4B8-5BE8-K6B9-5BD6-G7BG9-6B5-7BH11-6B3-H7B13-D5BD-7BK14-F13B17-12BDE16-15BJ14-18BF11-F7B-EH9B11-7B4-F8BM9-7BO5-L7B9-I7B6-I6B10-7BJ6-6B10-H18B12-17B15-ID11BJ20-MND3BDG729-2A24-2A2-2A24-2A603-2A22-2A4(4-CA22-AC)4-2A22-2A63-2A24-2A2(2-CA24-AC)2-2A24-2A543-2A22-2A4-CA22-AC124-CA22-AC4-2A22-2A3-2A24-2A2-CA24-AC62-CA24-AC2-2A24-2A484-3(A22-A5-CA22-AC184-CA22-AC3-CA24-AC122-CA24-AC-3A24-6A24-3A423-)A22-A5-CA22-AC184-CA22-AC3-CA24-AC122-CA24-AC-3A24-6A24-3A393-A22-A6-A22-A5-2A22-2A4-CA22-AC124-CA22-AC4-2A22-2A3-2A24-2A2-CA24-AC62-CA24-AC2-2A24-2A-3A24-6A24-3A393-A22-A6-A22-A5-2(2A22-2A4-)4(CA22-AC4-)2A22-2A4-2A22-2A3-2(2A24-2A2-)2(CA24-AC2-)2A24-2A2-3(2A24-2A-3A24-6A24-3A393-A22-A6-A22-A5-7(2A22-2A4-)2A22-2A3-5(2A24-2A2-))4(2A24-2A-3A24-6A24-3A363-2(A22-A6-)A22-A5-7(2A22-2A4-)2A22-2A3-5(2A24-2A2-))2A24-2A-3A24-6A24-3A306-2A14-2A10-4A14-4A7-5A14-5A6-3A18-3A6-A22-A5-7(2A22-2A4-)2A22-2A3-5(2A24-2A2-)2A24-2A-4A22-8A22-4A2-2A22-2A6-4A14-4A10-2A14-2A194-2A10-2A14-2(4A10-)6A10-6A2(8-4A14-4A)7-3A18-3A5-4A18-4A3(4-3A21-2A)3-3(3A22-3A2-)3A22-3A-4A22-7A3(24-6A)24-7A22-10A18-14A14-8A2-6A14-6A6-2(6A10-)4A10-4A14-2A10-2A110-A4-A22-3A4-3A18-5A4-5A16-4A6-4A3(16-2A10-2A)12-4(4A14-4A8-)4A14-4A5-4A21-3(3A2-3A22-)3A-4A5(22-8A)22-4A4-2(4A14-4A8-)6A10-6A12-4A6-4A2(16-5A4-5A)18-3A4-3A22-A4-A26-2A26-6A22-10A20-4A2-4A2(20-3A4-3A)16-EGL-3A4-3A-E4B8-5BE3A4-AK6B9-4B12-4BG9-4B12-2BH11-4B12-BA12-D3B12-2A12-F3B12-2A12-2(A2B15-4A8-)A2B15-BF2A8-AFB15-3BA8-2AB15-4BM7-2AB15-5B7-2AI2(15-5B7-3A)15-4B8-4A14-3BA12-2A12-BJ14-2A10-DG16-2A10-2A18-3A4-3A20-4A2-4A2(20-10A)22-6A26-2A27-4(4A26-)4A19-EGL4-4A4-E4B8-5BE3-4A-K6B9-5BD3A4-7BG9-6B3A4-5BH11-6B3A4-4B13-D5BDAB4-2BK14-F8B4-B2A15-5B7-DE-2A13-5B7-3BJA13-5B7-6BF11-F4B7-8B11-4B7-F8BM9-4B9-L7B9-I3B10-I6B10-3B10-A6B10-H2B10-6B12-2B10-5B25-3BJ16-3A4-3BDG18-3A4-3A23-4(4A26-)4A199-EGL12-E4B8-5BE8-K6B9-5BD3-3AG7BG9-6B3-2A7BH11-6B3-H7B13-D5BD-7BK14-F13B17-12BDEA15-15BJ14-18BF11-F7B-EH9B11-7B4-F8BM9-7B4-2AL7B9-I6B4-3AI6B10-6B4-3A-6B10-H5B4-9B12-5B4-8B15-IDB4-6BJ19-AMND3BDG21-4A349-EGL12-E4B8-5BE8-K6B9-5BD6-G7BG9-6B5-7BH11-6B3-H7B13-D5BD-7BK14-F13B17-12BDE16-15BJ14-18BF11-F7BAEH9B11-7B4AF8BM9-7BO3A2-L7B9-I7B3A3-I6B10-7BJ2A4-6B10-H18B12-17B15-ID11BJ20-MND3BDG188-
