model
size = 30 22 17, scale = 0.05, origin = -y
material 
  colors = A:#200 B:#400 C:#888 D:#500 E:#F99 F:#F96 G:#963 H:#960 I:#111 J:#E00 K:#DDD L:#FCF M:#FCC
voxels
223-2DB26-A2D2B24-BA2DADA23-B4ADA23-5ADA24-B2A2D26-2AD416-2AB2A24-3A3BD22-4A3B2A20-2(3B2A)B19-A2B7A2(B19-10A)B19-A3B2A2D2AB20-3B2A2DAB22-B3A2DA24-4AD324-2BAB3A22-4AB4A20-10AD18-AB9A2B17-2B9A3(2B17-B10A)2B17-11A2B17-2D8A3B18-D8A2B20-9A22-2AD4A263-2B2A3B21-11A18-12AB17-D10A2D16-3(2D10A3B15-)2B12AB15-2B10A3B15-12A3B15-A2D9A3B16-2D11A17-13A18-9ADA21-A2D4A203-2B5A21-2A2B7A18-13A16-13A2B15-2D11A2B14-3(3D10A4B13-)15A2B2(13-13A4B)13-B12A4B14-14AB15-B13AB16-11A2B18-3A2D3A3B21-3D3AB144-4AB23-6A3B19-13A16-D14A15-D14A14-3D14A13-3D14A12-4D15A11-4D12A3B11-D15A3B2(11-D17AD)12-B16A13-B16A14-B14A15-D11A2BA16-11A2B19-3D6A23-D4A114-5A2B21-DB5A4B18-11A2B16-D11A3B14-2D15A13-17A12-2(19A11-)2(16A3B11-)2(19A11-)D17AD12-17A13-17A14-D14A16-2D11A18-D10A21-A2B3AD85-3A24-6A3B19-2DB5A5B16-B11A3B14-2B11A4B13-17A12-2(19A11-)19A10-2(17A4B9-)21A10-19A2(11-D18A)12-17A13-17A14-3D10A2B16-2D10AB19-2A2B3A2D24-B2A56-5B22-10BA18-D12B16-B11A3B14-2B11A4B12-2(19A11-)D18A10-D20A2(9-17A4B)2(9-21A)10-19A11-B18A11-B16A2B12-16AB14-3D10A2B16-2D10AB18-3B8A22-2A3B54-5B2A21-7B4A18-8B3A2B16-12A3B14-D12A4B12-19A11-19A10-21A9-D20A9-D16A4B9-B16A4B3(9-21A)10-B18A11-B17AD12-17A14-D14A16-13A18-3B7AB21-B6A53-5B2A21-7B4A18-8B5A16-15A14-17A12-18AB11-19A10-21A9-B20A2(9-B16A4B)9-21A2(9-B20A)10-B18A11-B17AD12-17A14-15A16-13A18-3B8A21-B2A2D2A53-6BA21-7B4A18-8B4AB16-13A2B14-17A12-D18A11-D18A10-5(21A9-)B20A9-B20A10-19A11-19A12-16AD14-15A16-13A18-11A21-2A3BAD54-A4B22-B6A3BA18-B12A16-2B13A14-D16A12-D17AB11-D18A11-19A10-4(21A9-)21A10-19A11-D18A11-19A12-17A14-15A16-13A18-11A22-A3BA55-A5B22-6A3BA18-13A16-15A14-17A10-21AB2A5-25AB3-D27A2(-2A2B25A)2(-AB24ABAD)2-B26AD3-26A5-A2D19A2D9-18A12-B17A13-16A15-12A2B17-B10AB20-2A3B2AD24-2B2D25-6A22-2A6C2A19-D10CA17-2D11CA15-A14CA10-4A16C4A5-A2CF18CE2CA3-A2CEF18CFE2CA-A3CEF18CFE2CA-D2CE2A18C2AECA-ACEAFA18CAFAEA-ACE2AF18CF2AEA2-AC3E18CF2ECA3-A21CE2CB5-ABA18C3A9-A16CB12-A16CB13-A14CA15-A11C2B17-2A8CAB20-2A4C2A24-2A2D25-6A22-2A6F2A19-A10FA17-B11EFA15-2B11E2FA10-5A4E5J3E2F5A5-A2G-AE2FEJ2FM2FJ2E3FA-2GA3-AGF2-AE2F4EA5E3FA2-FGA-AG2F2-AEF2A3EA3E2A3FA2-2FG2AGF3-AEAILAE3AFALIA2FA3-FG2AG4-AEALIA4EFAILA2FA4-G2AG4-AEM2A5E2F2A3FA4-GA-AG3-AE3F5E7FA3-GA3-A3GAHF2A5E2F2A2FHA-2GA5-4A2H7E5F2H4A9-AHGH4EH5FHGHA12-AH2GHE6HFH2GHA13-AH2G2H4G2H2GHA15-A2H8G2HA17-2A2H4G2H2A20-2A4H2A24-4A237-A24-2A3-A3-2A18-AIKA-3A-AKIA17-AKIA5-AIKA18-2A7-2A49-2A7-2A250-
