model
size = 32 16 7, scale = 0.05, origin = -y
material 
  colors = A:#CCC B:#F90 C:#6FF D:#F9F E:#F00 F:#FFF G:#E00
voxels
119-E29-2(E-)E23-E3-E-3E2(-E)19-6(E-)E19-E2(-3E)GE-E19-5(E-)3E19-3E5(-E)19-3(E-)E3-3E21-2(E3-)E-E21-E7-E105-2F2G2F24-F8AF21-F10AF3-5(C-)C5-F5A2-5AF2-2(3C-C-)2C2-4AF4-F4A2-5C-8C-F3AF6-F3AF-13C2-F3A8-3AF-14C-2(G2A10-3A-13C2-)F3A8-3AF-14C-F3AF6-F3AF-13C3-4AF4-F4A2-3C-10C2-F5A2-5AF2-3(3C-)2C3-F10AF3-5(C-)C7-F8AF24-2F2G2F25-F2-2G2-F22-F-8A-F19-F-10A-F-2B5(-B)6-12A2-2B5(-B)-3BF4A-4G-4AF4B-B-3B-4B2-3A-G4-G-3A-6B-8B2-3AG6-G3A-15B-2(G3AG6-G4A16B)-3AG6-G3A-15B2-3A-G4-G-3A-4B-10B-F4A-4G-4AF4B-3B-6B3-12A2-2B5(-B)-3B-F-10A-F-2B5(-B)6-F-8A-F22-F2-2G2-F24-F2-2G2-F22-F-8A-F19-F-10A-F-2D5(-D)6-12A2-4D-D-3D-4D-F4A-4G-4AF6D-8D2-3A-G4-G-3A-14D3-3AG6-G3A-2(15D-G3AG6-G4A)15D2-3AG6-G3A-15D2-3A-G4-G-3A-14D2-F4A-4G-4AF4D-10D3-12A2-4D2(-3D)-2D2-F-10A-F-2D5(-D)6-F-8A-F22-F2-2G2-F24-F2-2G2-F22-F-8A-F19-F-10A-F-2B5(-B)6-12A2-2B5(-B)-3BF4A-4G-4AF4B-B-3B-4B2-3A-G4-G-3A-6B-8B2-3AG6-G3A-15B-2(G3AG6-G4A16B)-3AG6-G3A-15B2-3A-G4-G-3A-4B-10B-F4A-4G-4AF4B-3B-6B3-12A2-2B5(-B)-3B-F-10A-F-2B5(-B)6-F-8A-F22-F2-2G2-F25-2F2G2F24-F8AF21-F10AF3-5(C-)C5-F5A2-5AF2-6(C-)2C2-4AF4-F4A2-5C-8C-F3AF6-F3AF-13C2-F3A8-3AF-14C-2(G2A10-3A-13C2-)F3A8-3AF-14C-F3AF6-F3AF-13C3-4AF4-F4A2-3C-5C-4C2-F5A2-5AF2-2(3C-)2(C-)2C3-F10AF3-5(C-)C7-F8AF24-2F2G2F136-E29-3(E-)E3-E-E19-E-3E4(-E)19-2(3E-E-)E19-E-3E2(-E)-3E19-3E-E-5E-E19-2(E-)3E3(-E)19-3(E-)E3-E-E19-E-2(E3-)E-E19-E5-E104-
