model
size = 32 16 8, scale = 0.05, origin = -y
material 
  colors = A:#545454 B:#747474 C:#30CCFC D:#EC0000
voxels
144-15A17-8(A10-2A19-)15A177-15A17-8(A10-2A19-)15A103-4B26-8B23-10B21-2(5B2-)15A2-4B6-4B-2(15A2-3B8-4B)2A8-3A3-2(3B10-3B2A8-5A-)4B8-4B2A8-3A4-3B8-4B15A2-4B6-4B-15A3-2(5B2-)15A4-10B23-8B26-4B27-2B2A2B24-B8AB21-B10AB2-16C-B12AB-15A2-4AB4-B4A-15A-B3AB6-B3AB15A-B3A8-3AB2A8-3A3-2(4A8-19A-)B3A8-3AB2A8-3A3-B3AB6-B3AB15A2-4AB4-B4A-15A2-B12AB-15A3-B10AB2-16C3-B8AB24-2B2A2B25-B2-2A2-B22-B-8A-B19-B-10A-B6-3C10-12A2-15A-B4A-4C-4AB15AD-3A-C4-C-3A-15AD-3AC6-C3A-2A8D2(5AD4AC6-C6A8C)5AD-3AC6-C3A-2A8D5AD-3A-C4-C-3A-15ADB4A-4C-4AB15AD2-12A2-15A2-B-10A-B6-3C10-B-8A-B22-B2-2A2-B24-B2-2A2-B22-B-8A-B19-B-10A-B6-3C10-12A2-15A-B4A-4C-4AB15AD-3A-C4-C-3A-15AD-3AC6-C3A-2A8D2(5AD4AC6-C6A8C)5AD-3AC6-C3A-2A8D5AD-3A-C4-C-3A-15ADB4A-4C-4AB15AD2-12A2-15A2-B-10A-B6-3C10-B-8A-B22-B2-2A2-B25-2B2A2B24-B8AB21-B10AB2-16C-B12AB-15A2-4AB4-B4A-15A-B3AB6-B3AB15A-B3A8-3AB2A8-3A3-2(4A8-19A-)B3A8-3AB2A8-3A3-B3AB6-B3AB15A2-4AB4-B4A-15A2-B12AB-15A3-B10AB2-16C3-B8AB24-2B2A2B27-4B26-8B23-10B21-2(5B2-)15A2-4B6-4B-15A2-3B8-3B-15A2-3B8-4B2A8-3A3-2(3B10-3B2A8-5A-)4B8-4B2A8-3A4-3B8-4B15A2-4B6-4B-15A3-2(5B2-)15A4-10B23-8B26-4B22-
