model
size = 32 16 8, scale = 0.05, origin = -y
material 
  colors = A:#BBB B:#724832 C:#FFF D:#888 E:#444 F:#222
voxels
113-5(5A27-)3D2A27-3D2A130-3A29-3A118-3(5A27-)2(3D2A27-)5D27-5D130-3A29-3A150-3(5A27-)2(3D2A27-)5D27-5D130-3A29-3A74-2C2B2C24-C8BC21-C10BC3-5A2-5A4-C12BC2(2-5A)4-4BC4-C4B7A2-5A3-C3BC6-C3BCD5A2-5A3-C3B8-3BCD5A2-5A2(3-4B8-4BD5A2-3A2F)3-C3B8-3BC6D2-5A3-C3BC6-C3BC6D2-5A4-4BC4-C4B-6D2-5A4-C12BC9-3A7-C10BC10-3A8-C8BC24-2C2B2C25-C2-2B2-C22-C-8B-C19-C-10B-C2-15A2-12B3-15AC4B-4C-4BC16A-3B-C4-C-3B14A3E-3BC6-C3B14A3E4BC6-C4B13A3-4BC6-C4B13A4-3BC6-C3B7D2-5A4-3B-C4-C-3B-6D2-5A3-C4B-4C-4BC6D2-5A5-12B19-C-10B-C19-C-8B-C22-C2-2B2-C24-C2-2B2-C22-C-8B-C19-C-10B-C2-15A2-12B3-15AC4B-4C-4BC16A-3B-C4-C-3B14A3E-3BC6-C3B14A3E4BC6-C4B13A3-4BC6-C4B13A4-3BC6-C3B7D2-5A4-3B-C4-C-3B-6D2-5A3-C4B-4C-4BC6D2-5A5-12B19-C-10B-C19-C-8B-C22-C2-2B2-C25-2C2B2C24-C8BC21-C10BC3-5A2-5A4-C12BC2(2-5A)4-4BC4-C4B7A2-5A3-C3BC6-C3BC4A2D2-5A3-C3B8-3BC4A2D2-5A2(3-4B8-4BD3A2D2-3A2F)3-C3B8-3BC6D2-5A3-C3BC6-C3BC6D2-5A4-4BC4-C4B-6D2-5A4-C12BC9-3A7-C10BC10-3A8-C8BC24-2C2B2C102-5(5A27-)3D2A27-3D2A130-3A29-3A69-
