model
size = 32 16 8, scale = 0.05, origin = -y
material 
  colors = A:#555 B:#777 C:#14AC00 D:#8D0002
voxels
150-2A29-4A23-13A19-A11-A19-4(A11-2A18-)A11-A19-13A24-4A29-2A126-2A29-4A23-13A19-A11-A19-4(A11-2A18-)A11-A19-13A24-4A29-2A46-4A26-8A23-10A21-5A2-5A8-2A9-2(4A6-)4A8-3A8-17A4-3A8-5A11CA-C-3A10-4A11C7A10-4A11C3A-4A8-5A11C3A2-3A8-5A11C4A-4A6-4A-A11CA-C3-2(5A2-)13A6-10A8-4A11-8A10-2A14-4A27-2A2C2A24-A8BA21-A10BA19-A12BA7-2A3-3C3-4BA4-A4B-15A-A3BA6-A3B18A3B8-3B15AC-C3B8-4B16AC3B8-4B15A-A3B8-3B16A-A3BA6-A3B17A-4BA4-A4B-14AC2-A12BA-16A2-A10BA4-13A4-A8BA9-2A3-3C7-2A2C2A25-A2-2C2-A22-A-8B-A19-A-10B-A19-12B5-7A-3C2-A4B-4C-4B16A2-3B-C4-C-3B-16A-3BC6-C3B-14AC-C3BC6-C4B16AC3BC6-C4B12AD4-3BC6-C3B-12AD4-3B-C4-C-3B-17A4B-4A-4B15AC3-12B2-16A-A-10B-A3-13A3-A-8B-A5-7A-3C6-A2-2C2-A24-A2-2C2-A22-A-8B-A19-A-10B-A19-12B5-7A-3C2-A4B-4C-4B16A2-3B-C4-C-3B-16A-3BC6-C3B-14AC-C3BC6-C4B16AC3BC6-C4B12AD4-3BC6-C3B-12AD4-3B-C4-C-3B-17A4B-4C-4B15AC3-12B2-16A-A-10B-A3-13A3-A-8B-A5-7A-3C6-A2-2C2-A25-2A2C2A24-A8BA21-A10BA19-A12BA7-2A3-3C3-4BA4-A4B-15A-A3BA6-A3B18A3B8-3B15AC-C3B8-4B16AC3B8-4B15A-A3B8-3B16A-A3BA6-A3B17A-4BA4-A4B-14AC2-A12BA-16A2-A10BA4-13A4-A8BA9-2A3-3C7-2A2C2A27-4A26-8A23-10A21-5A2-5A8-2A9-2(4A6-)4A2(8-3A)-13A4-3A8-5A11CA-C-3A10-4A11C7A10-4A11C3A-4A8-5A11C3A2-3A8-5A11C4A-4A6-4A-A11CA-C3-2(5A2-)13A6-10A8-4A11-8A10-2A14-4A22-
