model
size = 32 14 5, scale = 0.05, origin = -y
material 
  colors = A:#0FF B:#FFF C:#FF0080 D:#9050C8
voxels
133-A20-A9-3A18-3A7-5A16-5A6-7A12-7A5-2(9A10-9A4-)8A12-8A4-6A16-6A104-2A16-2A10-2A-A16-A-2A7-4A-A14-A-4A6-5A-A12-A-5A5-7A-A10-A-7A4-11A6-11A3-7AD-2A-A4-A-2A-D7A2-9A-3A4-3A-9A-10A-2A6-2A-23A6-24A10-21A12-10A3-3A20-3A9-2A16-2A10-4A16-4A7-A-4A14-4A-A6-3A-3A12-3A-3A5-5A-3A10-3A-5A4-6A-3A8-3A-6A3-30A2-10A-8A-10A-12A2(2-A)2-24A-A4-A-23A-A6-A-21A-A8-A-18A-2A10-2A-17A14-9A36-3A18-3A7-5A16-5A6-2AB2A16-2AB2A5-2A2B3A14-3A2B2A4-A4B4A10-4A4BA3-A6B4A8-4A6BA2-A8B4A4-4A8BA-2A10B3A2-3A10B4A10B2A4-2A10B3A10B2A6-2A10B2A8B3A8-3A8B4A5B3A10-3A5B12A14-9A195-C2-C18-3C7-C2-C18-C2-C6-C-C19-C2-C6-2C20-3C7-C-C19-C2-C6-C2-C18-3C68-
