model
size = 26 32 26, scale = 0.05, origin = -y
material 
  colors = A:#8D8D8D B:#999
voxels
10-2B4A2B17-62(2B4A2B18-)2B4A2B16-31(AB8-BA14-)AB8-BA2(12-2A)31(10-2A12-2A)9-31(B16-B8-)B16-B7-31(B18-B6-)B18-B5-63(A20-B4-)A20-B3-32(A22-B2-)31(B22-B2-)B22-B-B63(24-2B)24-BA127(24-2A)24-AB63(24-2B)24-B-32(B22-B2-)31(A22-A2-)A22-A3-63(A20-A4-)A20-A5-31(B18-B6-)B18-B7-31(B16-B8-)B16-B9-31(2A12-2A10-)2(2A12-)31(AB8-BA14-)AB8-BA7-
