model
size = 16 29 12, scale = 0.05, origin = -y
material 
  colors = A:#111
voxels
324-8A7-2(10A6-)10A150-4(10A6-)10A7-8A184-2(8A8-)A2(6-A7-2A)5(6-2A)38-10A6-10A5-2(12A4-)3(2A8-2A4-)A-A6-3A4-12A5-10A8-3A109-6A9-8A7-2(10A6-)2A6-A71-3(2A6-)2A4-3(14A2-)3A8-3A4(2-2A10-2A)2-A-A9-2A3-2A8-2A4-A-8A-A5-10A7-8A9-7A9-6A10-6A9-8A8-8A7-10A6-3A4-3A5-A-A6-A-A4-2A8-2A101-2A6-2A3-3A11-6(4A12-)2A-A12-A2(2-2A10-2A)3-2A8-2A4-A-A6-A-A5-3A4-4A5-8A-A7-8A7-10A6-A-A4-A-A4(6-2A)5-2(2A8-2A4-)A10-A4-A10-A85-2A7-A3-2A12-4A12-3A2(14-2A)14-3A2(12-4A)12-2A-A12-A2(2-2A10-2A)3-2A8-2A4-2A8-2A5-8(2A6-)A8-A5-2(2A8-2A4-)2(A10-A4-)A10-A69-A8-A6-2A7-A3-A6(14-2A)14-3A12-2A-2(A12-A2-)2A10-2A3-A10-A2(4-2A8-2A)5-2(A8-A6-)A8-A5-2(2A8-2A4-)3(A10-A4-)A10-A69-2A7-A6-2A7-A3-A6(14-2A)14-3A12-2A-2(A12-A2-)2A10-2A3-A10-A4-2A8-2A4-2A8-A5-2A2(8-A6-A)8-A5-2(2A8-2A4-)4(A10-A4-)A10-A21-2(A8-A6-)A8-A19-2A12-4A3(13-3A)3(12-4A)12-2A-A12-A2(2-2A10-2A)3-2A8-2A4-2A8-2A5-A7-3(2A6-)2(A8-A6-)A8-A5-2(2A8-2A4-)3(A10-A4-)A10-A5-2(A8-A6-)A8-A35-3A4(10-4A-A)10-2(A-)2A10-3A-3(3A8-3A2-)3A8-3A3-2A8-2A4-A-A6-A-A5-2(2A6-)2(2A5-A-A6-)6(2A6-)A7-2A5-2A8-2A3(4-A10-A)4-2A8-2A4-A-A6-A-A5-A8-A52-4(14A2-)14A3-12A4-12A5-10A3(6-3A4-3A)6-4A2-4A7-4(3A2-3A8-)3A2-3A7-3A4-2A7-3A4-A-A5-A-A6-A-A4-2A8-2A4-A10-A4-2A8-2A4-A-8A-A5-10A170-3A11-4(6A10-)6A11-5A11-2(4A12-)4A11-6A10-6A9-8A7-A-6A-A5-A-A6-A-A4-2A8-2A4-A-8A-A5-10A83-
