model
size = 32 9 14, scale = 0.05, origin = -y
material 
  colors = A:#D477AC B:#74415E C:#BEBEBE
voxels
38-2(20A12-)20A3(22-10A)76-2(20A12-)20A3(22-10A)106-2(24A8-)2A9-13A19-2(12A20-)12A21-10A72-28A4-4A21B3A4-2A24-2A113-12A21-3A4C3A39-30A2-3A24B3A2-A27-2A144-3A6C3A37-6A3B2A2B2A2(BA)3B2(AB)8A27B4A29-2A143-4A5C3A20-3A6C3A5-6AB3AB2A3(BA)B3ABAB8A28B3A30-A143-12A20-4A6C2A5-6AB3AB2ABA2B2AB4AB9A28B3A30-A143-12A20-5A6CA5-6AB3AB2ABA3BA2B3AB9A28B3A30-A143-12A20-5A6CA5-6AB3AB2A3(BA)B3ABAB8A28B3A30-A143-12A20-4A6C2A5-6AB4A2B2A2(3BA)BAB8A27B4A29-2A143-4A3C5A20-3A6C3A6-30A2-3A24B3A2-A27-2A144-3A6C3A39-28A4-4A21B3A4-2A24-2A113-12A21-3A4C3A42-2(24A8-)2A9-13A19-2(12A20-)12A21-10A70-
