model
size = 31 32 17, scale = 0.05, origin = -y
material 
  colors = A:#C09 B:#F9F C:#FFF D:#FF0
voxels
8-6(15B16-15A16-)15B17-3(13A18-13B18-)13A18-13B17-15A14-19B12-19A12-19B13-17A15-15B16-15A18-11B20-11A21-9B49-B15-B14-A15-A14-B15-5(B14-17A14-B15A)B14-17A14-2B13A2B15-2(15A16-B13AB16-)15A11-4B-B13AB-4B6-25A6-3B19A3B6-25A7-2B19A2B8-23A9-3B15A3B12-17A15-2B11A2B17-13A19-B9AB22-7A18-4(B17-B12-A17-A12-)B17-2(B12-2A15-2A12-BA15-A)B13-2(A15-A14-B15-B14-)A15-A14-2(B15-)A13-A10-B5-B13-B5-B4-A4-2A13-2A4-A4-B25-B4-2A23-2A4-2BA21-A2B5-3A19-3A6-2B2A17-2A2B7-4A16-3A10-2B15-2B14-2A11-2A17-BA9-AB20-A7-A16-4(B19-B10-A19-A10-)B19-B11-2(A17-A12-B17-B12-)A17-A12-B17-B13-2(A15-A14-B15-B14-)A15-A8-B5-B15-B5-B2-A27-A2-B27-B2-2A25-2A3-BA23-AB4-3A21-3A4-B3A19-3AB5-4A17-4A7-2B2A15-2A2B11-2(A15-)B13-B17-2A9-2A14-4(B19-B10-A19-A10-)B19-B10-2A17-2A10-BA17-AB10-2A17-2A11-B17-B12-A17-A12-B17-B13-2(A15-A14-B15-B14-)A15-A8-B5-B15-B5-B2-A27-A2-B27-B2-A26-2A2-BA25-AB2-3A23-3A3-B2A21-2AB4-4A19-4A5-B3A17-3AB8-3A15-3A2(13-B)17-A11-A14-7(B19-B10-A19-A10-)B19-B11-A17-A12-B17-B12-A17-A12-B17-B13-A15-A7-B6-B15-B6-BA28-2AB28-ABA28-2A-B26-AB2-2A25-2A2-B2A23-2AB3-3A21-3A5-B3A17-3AB7-4A15-4A11-BA14-B16-A12-A13-7(B19-B10-A19-A10-)B19-B10-2A17-2A10-BA17-AB11-A17-A12-B17-B12-2A15-2A2(6-B)15-B6-2(BA28-2AB28-A)B-A26-2A2-BA25-AB3-2A23-2A4-B2A21-2AB6-2A19-2A10-BA15-AB14-2(A13-)7(B19-B10-A19-A10-)B19-B10-2A17-2A10-BA17-AB10-2A17-2A11-B17-B12-2A15-2A6-B5-BA15-AB5-2(BA28-2AB28-A)BA28-2A-B26-AB2-2A25-2A3-BA23-AB5-3A19-3A9-BA15-AB14-2(A13-)7(B19-B10-A19-A10-)B19-2(B10-2A17-2A10-BA17-A)B10-3A15-3A2(5-B)A15-AB5-2(BA28-2AB28-A)BA28-2A-B26-AB2-2A25-2A3-BA23-AB5-3A19-3A9-BA15-AB14-2(A13-)7(B19-B10-A19-A10-)B19-B10-2A17-2A10-BA17-AB10-2A17-2A11-B17-B12-2A15-2A6-B5-BA15-AB5-2(BA28-2AB28-A)B-A26-2A2-BA25-AB3-2A23-2A4-B2A21-2AB6-2A19-2A10-BA15-AB14-2(A13-)7(B19-B10-A19-A10-)B19-B10-2A17-2A10-BA17-AB11-A17-A12-B17-B12-2A15-2A2(6-B)15-B6-BA28-2AB28-ABA28-2A-B26-AB2-2A25-2A2-B2A23-2AB3-3A21-3A5-B2A19-2AB7-4A15-4A11-2(B15-)2(A13-)7(B19-B10-A19-A10-)B19-B11-A17-A12-B17-B12-A17-A12-B17-B13-A15-A8-B5-B15-B5-B2-A27-A2-B27-B2-A27-A2-BA25-AB2-3A23-3A3-B2A21-2AB4-4A19-4A5-B3A17-3AB8-3A15-3A2(13-B)17-2A9-2A14-4(B19-B10-A19-A10-)B19-B10-2A17-2A10-BA17-AB10-2A17-2A11-B17-B12-A17-A12-B17-B12-2A15-2A12-BA15-AB13-A15-A14-B15-B14-A15-A8-B5-B15-B5-B2-A27-A2-B27-B2-2A25-2A3-BA23-AB4-3A21-3A4-B3A19-3AB5-4A17-4A7-2B2A15-2A2B11-2A13-2A16-3B7-3B45-4(B19-B10-A19-A10-)B19-B11-2(A17-A12-B17-B12-)A17-A12-B17-B13-2(A15-A14-B15-B14-)A15-A9-B4-B15-2(B4-)A25-A4-B25-B4-2A23-2A4-2BA21-A2B5-3A19-3A6-2B2A17-2A2B7-4A15-4A10-2B15-2B14-4A7-4A76-4(B17-B12-A17-A12-)B17-2(B12-2A15-2A12-BA15-A)B13-A15-A14-B15-2(B14-2A13-2A14-BA13-A)B15-A13-A11-3B2-A13-B2-3B6-3A19-3A6-2BA19-A2B6-3A19-3A7-2B19-2B8-4A15-4A9-3B15-3B12-2(A15-)5B5-5B108-6(2B13-2B14-2A13-2A14-)2B13-2B14-3A11-3A14-2BA11-A2B15-2(2A11-2A16-BA11-AB16-)2A11-2A14-3BA11-A3B11-4A13-4A10-2BA15-A2B10-3A15-3A11-2B15-2B2(13-2A)15-6B3-6B16-5A5-5A141-10(13B18-13A18-)11BCB17-11ACDCA15-13BC3B14-17A15-7B-7B17-5A3-5A195-
