model
size = 31 32 17, scale = 0.05, origin = -y
material 
  colors = A:#688393 B:#120B05 C:#2A2826 D:#000 E:#FFF F:#DA3840 G:#FB922B H:#106295 I:#1615BE J:#FFE762
voxels
8-3(8ACE3BCA16-)3(8AC4BCA16-)4A7C2BCA16-3AC6BC2BCA16-2AC10BCA16-AC11BCA16-C4B3J2G3BCA16-C4B4G4BCA16-C5BG6BCA17-2(3B2E)2BC18-2B2(E2HEB)C18-2B2(EIHEB)C18-2B2(EI2EB)C18-2B3E3B3EBC18-3BE5BE3B18-6BC6B18-4B5C4B17-14BC14-A17BA12-2A15F2A12-2A15B2A13-A15BA15-15B16-15B18-11B20-11A21-9A49-3(A15-A14-)10(17A14-)AC15A14-AC15A15-2(C14A16-)2(C13AC16-)C13AC11-4A-C13AC-4A6-3A2B15A2B3A2(6-25A)7-23A8-23A9-21A12-17A15-AB11ABA17-13A19-11A22-7A18-9(A17-A12-)3(2A15-2A12-)2A15-2A13-5(A15-A14-)2(A15-)A13-A10-A5-A13-A5-2(A4-)2A13-2A2(4-A)25-A4-2A23-2A4-3A21-3A5-3A19-3A6-4A17-4A7-4A16-3A10-2A15-2A14-2A11-2A17-2A9-2A20-A7-A16-8(A19-A10-)A19-A11-5(A17-A12-)A17-A13-4(A15-A14-)A15-A8-A5-A15-A5-2(A2-A27-)A2-2A25-2A3-2A23-2A4-3A21-3A4-4A19-4A5-4A17-4A7-4A15-4A11-2(A15-)A13-A17-2A9-2A14-9(A19-A10-)2(2A17-2A10-)2A17-2A11-2(A17-A12-)A17-A13-4(A15-A14-)A15-A8-A5-A15-A5-2(A2-A27-)A2-A26-2A2-2A25-2A2-3A23-3A3-3A21-3A4-4A19-4A5-4A17-4A8-3A15-3A2(13-A)17-A11-A14-14(A19-A10-)A19-A11-3(A17-A12-)A17-A13-A15-A7-A6-A15-A6-2A2(28-3A)28-2A-A26-2A2-2A25-2A2-3A23-3A3-3A21-3A5-4A17-4A7-4A15-4A11-2A14-A16-A12-A13-15(A19-A10-)2A17-2A10-2A17-2A11-2(A17-A12-)2A15-2A2(6-A)15-A6-2A3(28-3A)28-2A-A26-2A2-2A25-2A3-2A23-2A4-3A21-3A6-2A19-2A10-2A15-2A14-2(A13-)15(A19-A10-)2(2A17-2A10-)2A17-2A11-A17-A12-2A15-2A6-A5-2A15-2A5-2A4(28-3A)28-2A-A26-2A2-2A25-2A3-2A23-2A5-3A19-3A9-2A15-2A14-2(A13-)15(A19-A10-)4(2A17-2A10-)3A15-3A5-A5-2A15-2A5-2A4(28-3A)28-2A-A26-2A2-2A25-2A3-2A23-2A5-3A19-3A9-2A15-2A14-2(A13-)15(A19-A10-)2(2A17-2A10-)2A17-2A11-A17-A12-2A15-2A6-A5-2A15-2A5-2A3(28-3A)28-2A-A26-2A2-2A25-2A3-2A23-2A4-3A21-3A6-2A19-2A10-2A15-2A14-2(A13-)15(A19-A10-)2A17-2A10-2A17-2A11-2(A17-A12-)2A15-2A2(6-A)15-A6-2A2(28-3A)28-2A-A26-2A2-2A25-2A2-3A23-3A3-3A21-3A5-3A19-3A7-4A15-4A11-2(A15-)2(A13-)14(A19-A10-)A19-A11-3(A17-A12-)A17-A13-A15-A8-A5-A15-A5-3(A2-A27-)A2-2A25-2A2-3A23-3A3-3A21-3A4-4A19-4A5-4A17-4A8-3A15-3A2(13-A)17-2A9-2A14-9(A19-A10-)2(2A17-2A10-)2A17-2A11-3(A17-A12-)2A15-2A12-2A15-2A13-2(A15-A14-)A15-A8-A5-A15-A5-2(A2-A27-)A2-2A25-2A3-2A23-2A4-3A21-3A4-4A19-4A5-4A17-4A7-4A15-4A11-2A13-2A16-3A7-3A45-8(A19-A10-)A19-A11-5(A17-A12-)A17-A13-4(A15-A14-)A15-A9-A4-A15-2(A4-)2(A25-A4-)2A23-2A4-3A21-3A5-3A19-3A6-4A17-4A7-4A15-4A10-2A15-2A14-4A7-4A76-9(A17-A12-)3(2A15-2A12-)2A15-2A13-2(A15-A14-)3(2A13-2A14-)2A13-2A15-A13-A11-3A2-A13-A2-3(3A6-3A19-)3A7-2A19-2A8-4A15-4A9-3A15-3A12-2(A15-)5A5-5A108-13(2A13-2A14-)3A11-3A14-3A11-3A15-2A11-2A3(16-2A11-AD)16-DA11-AD14-2(4A11-)4A13-4A2(10-3A15-3A)11-2A15-2(2A13-)2A15-6A3-6A16-5A5-5A141-15(13A18-)D12A18-D4A2(DA)D3A18-D2A3D3(AD)A18-D2A5(DA)18-2D2(AD)A3DADA18-DAD4AD3A2D17-2(AD)8ADAD15-A3D9AD3A14-2AD14A15-7A-7A17-5A3-5A195-
