model
size = 31 32 17, scale = 0.05, origin = -y
material 
  colors = A:#070707 B:#F60 C:#FF6 D:#FF0 E:#FFF199
voxels
8-2(3(ECD2B)16-)3(2CBAB)2(16-3(CDBAB))16-3(CB2AB)3(16-3(DB2AB))2(16-B2(3A2B)3AB)2(16-3(4AB))17-7(13A18-)13A17-15A14-2(19A12-)19A13-17A15-15A16-15A18-11A20-11A21-9A49-2(B15-E14-)B15-4(C14-B15A)3(D14-B15A)B14-B15AB2(14-B16A)2(14-17A)15-4(15A16-)15A11-4B-B13AB-4B3(6-25A)7-23A8-23A9-21A12-17A15-15A17-13A19-11A22-7B18-2(B17-C12-)A17-C2(12-A17-D)4(12-A17-B)4(12-2A15-2A)13-5(A15-A14-)2(A15-)A13-A10-B5-B13-B5-B4-A4-2A13-2A2(4-A)25-A4-2A23-2A4-3A21-3A5-3A19-3A6-4A17-4A7-4A16-3A10-2A15-2A14-2A11-2A17-2A9-2A20-B7-B16-2(D19-D10-)3(B19-B10-)3(A19-A10-)A19-A11-5(A17-A12-)A17-A13-4(A15-A14-)A15-A8-B5-B15-B5-B2(2-A27-A)2-2A25-2A3-2A23-2A4-3A21-3A4-4A19-4A5-4A17-4A7-4A15-4A11-2(A15-)A13-A17-2B9-2B14-2(C19-B10-)C2(19-A10-D)4(19-A10-B)19-A4(10-2A17-2A)11-A17-A12-A17-A13-4(A15-A14-)A15-A8-B5-B15-B5-B2(2-A27-A)2-A26-2A2-2A25-2A2-3A23-3A3-3A21-3A4-4A19-4A5-4A17-4A8-3A15-3A2(13-A)17-B11-B14-2(E19-B10-)4(C19-B10-)3(D19-B10-)2(B19-B10-)2(A19-B10-)A19-A10-A19-A11-3(A17-A12-)A17-A13-A15-A7-B6-B15-B6-BA2(28-3A)28-2A-A26-2A2-2A25-2A2-3A23-3A3-3A21-3A5-4A17-4A7-4A15-4A11-2A14-A16-B12-B13-2(B19-E10-)4(B19-C10-)3(B19-D10-)2(B19-B10-)2(B19-A10-)2(A19-A10-)2A17-2A10-2A17-2A11-2(A17-A12-)2A15-2A2(6-B)15-B6-BA3(28-3A)28-2A-A26-2A2-2A25-2A3-2A23-2A4-3A21-3A6-2A19-2A10-2A15-2A14-2(B13-)2(B19-C10-)A19-C2(10-A19-D)4(10-A19-B)6(10-A19-A)3(10-2A17-2A)11-A17-A12-2A15-2A6-B5-BA15-AB5-BA4(28-3A)28-2A-A26-2A2-2A25-2A3-2A23-2A5-3A19-3A9-2A15-2A14-2(B13-)2(D19-D10-)3(B19-B10-)10(A19-A10-)4(2A17-2A10-)3A15-3A2(5-B)A15-AB5-BA4(28-3A)28-2A-A26-2A2-2A25-2A3-2A23-2A5-3A19-3A9-2A15-2A14-2(B13-)2(C19-B10-)C2(19-A10-D)4(19-A10-B)6(19-A10-A)19-A3(10-2A17-2A)11-A17-A12-2A15-2A6-B5-BA15-AB5-BA3(28-3A)28-2A-A26-2A2-2A25-2A3-2A23-2A4-3A21-3A6-2A19-2A10-2A15-2A14-2(B13-)2(E19-B10-)4(C19-B10-)3(D19-B10-)2(B19-B10-)2(A19-B10-)2(A19-A10-)2A17-2A10-2A17-2A11-2(A17-A12-)2A15-2A2(6-B)15-B6-BA2(28-3A)28-2A-A26-2A2-2A25-2A2-3A23-3A3-3A21-3A5-3A19-3A7-4A15-4A11-2(A15-)2(B13-)2(B19-E10-)4(B19-C10-)3(B19-D10-)2(B19-B10-)2(B19-A10-)A19-A10-A19-A11-3(A17-A12-)A17-A13-A15-A8-B5-B15-B5-B3(2-A27-A)2-2A25-2A2-3A23-3A3-3A21-3A4-4A19-4A5-4A17-4A8-3A15-3A2(13-A)17-2B9-2B14-2(B19-C10-)A19-C2(10-A19-D)4(10-A19-B)4(10-2A17-2A)11-2(A17-A12-)2A15-2A12-2A15-2A13-2(A15-A14-)A15-A8-B5-B15-B5-B2(2-A27-A)2-2A25-2A3-2A23-2A4-3A21-3A4-4A19-4A5-4A17-4A7-4A15-4A11-2A13-2A16-2AB7-B2A45-2(D19-D10-)3(B19-B10-)3(A19-A10-)A19-A11-5(A17-A12-)A17-A13-4(A15-A14-)A15-A9-B4-B15-2(B4-)2(A25-A4-)2A23-2A4-3A21-3A5-3A19-3A6-4A17-4A7-4A15-4A10-2A15-2A14-3AB7-B3A76-2(C17-B12-)C2(17-A12-D)4(17-A12-B)17-A4(12-2A15-2A)13-2(A15-A14-)3(2A13-2A14-)2A13-2A15-A13-A11-3B2-B13-B2-3B3(6-3A19-3A)7-2A19-2A8-4A15-4A9-3A15-3A12-2(A15-)4AB5-B4A108-2(EB13-EB14-)4(CB13-CB14-)3(DB13-DB14-)2(2B13-2B14-)2(AB13-AB14-)3A11-3A14-3A11-3A15-4(2A11-2A16-)2A11-2A14-3BA11-A3B11-4A13-4A2(10-3A15-3A)11-2A15-2(2A13-)2A15-5AB3-B5A16-4AB5-B4A141-2(B2(DCE2B)DC18-)2(AB2CB)ABC2(18-2(ABDCB)ABD)18-2(2ABCB)3(2AB18-2(2ABDB))2AB2(18-2(3A2B)3A)2(18-2(4AB)3A)8(18-13A)17-15A15-17A14-8AB8A15-6AB-B6A17-4AB3-B4A195-
