model
size = 14 7 17, scale = 0.05, origin = -y
material 
  colors = A:#F6C555 B:#7DB9DE C:#1E88A8 D:#BBB E:#00896C F:#2EA9DF G:#0089A7 H:#005CAF I:#D0104C J:#006284 K:#24936E L:#336774
voxels
4-3A10-A2GLA9-A2GFA9-AG2FA9-AF2BA9-A2FBA10-3A8-4(A-5A-A5-)9A6-7A7-7A6-2A5(5-3A3-3A)5-3A4-2A5-3A13-6(2A12-)2A13-4(2A12-)6(A13-)3(2A12-)2A13-A13-5(2A12-)A13-2A12-A2(H12-D)C2(12-DB)2(12-2A)12-AH12-2I12-AI12-AC12-AB2(12-2A)12-DK12-DH12-DC12-AC12-DC12-2A12-A13-5(2A12-)A12-3(A13-)8(2A12-)2(A13-)A7(12-2A)3-2A5(5-3A3-3A)5-3A4-2A5-3A4-4(A-5A-A5-)9A6-7A7-7A9-3A10-AJ2(2EA9-AB)CEA9-ABECA9-AB2CA10-3A7-
