model
size = 20 16 21, scale = 0.05, origin = -y
material 
  colors = A:#FFAB2D B:#8B0000 C:#36BF36 D:#F00 E:#FFFF4B
voxels
106-5C314-11C91-7D211-13C10-2(6B14-)6B32-9D193-5A11-14C8-2(9B11-)9B7-17E6-11D12-5A155-5A13-9A8-15C6-2(13B7-)13B5-17E5-13D9-9A13-5A115-5A13-9A10-11A6-17C5-2(13B7-)13B5-17E4-15D7-11A10-9A13-5A75-5A14-7A11-11A8-13A4-18C4-2(15B5-)15B4-17E3-17D5-13A8-11A11-7A14-5A36-3A15-7A12-9A10-11A8-13A3-20C3-2(15B5-)15B4-17E2-19D4-13A8-11A10-9A12-7A15-3A16-5A13-9A10-11A8-13A6-15A2-20C2-3(17B3-)17E2-19D3-15A6-13A8-11A10-9A13-5A14-2(7A12-9A10-11A8-13A6-15A2-20C2-3(17B3-)17E2-19D3-15A6-13A8-11A10-9A12-7A13-)7A12-9A10-11A8-13A6-15A3-19C2-3(17B3-)17E2-19D3-15A6-13A8-11A10-9A12-7A14-5A13-9A10-11A8-13A6-15A3-19C2-3(17B3-)17E2-19D3-15A6-13A8-11A10-9A13-5A16-3A15-7A12-9A10-11A8-13A4-19C3-2(15B5-)15B4-17E2-19D4-13A8-11A10-9A12-7A15-3A36-5A14-7A11-11A8-13A5-18C3-2(15B5-)15B4-17E3-17D5-13A8-11A11-7A14-5A75-5A13-9A10-11A6-18C4-2(13B7-)13B5-17E4-15D7-11A10-9A13-5A115-5A13-9A8-17C4-2(13B7-)13B5-17E5-13D9-9A13-5A155-5A11-13C9-2(9B11-)9B7-17E6-11D12-5A192-11C12-2(5B15-)5B33-9D212-8C92-7D216-5C205-
