model
size = 32 14 32, scale = 0.05, origin = -y
material 
  colors = A:#C0C0C0 B:#FFFAFA C:#F00
voxels
224-64A320-3(C31-)C320-C31-C95-C31-C256-C31-C159-C31-C192-C31-C223-C31-C128-C31-C287-C31-C64-C31-C351-C31-C64-C31-C287-C31-C128-C31-C88-64A71-C31-C192-C31-C55-64A40-C31-C256-C31-C22-64A9-C31-C342-64A353-2B12-2B3-5B7-A2B12A2B3A5B14A5B3A2B12A2BA7-5B3-2B12-2B322-2B12-2B3-6B6-A2B12A2B3A6B12A6B3A2B12A2BA6-6B3-2B12-2B323-2B10-2B8-3B5-2A2B10A2B8A3B10A3B8A2B10A2B2A5-3B8-2B10-2B324-2B10-2B9-3B4-2A2B10A2B9A3B8A3B9A2B10A2B2A4-3B9-2B10-2B324-2(2B10-)3B3-2A2(2B10A)3B6A3B2(10A2B)2A3-3B2(10-2B)325-2B8-2B12-3B2-3A2B8A2B12A3B4A3B12A2B8A2B3A2-3B12-2B8-2B326-2B8-2B13-2B2-3A2B8A2B13A2B4A2B13A2B8A2B3A2-2B13-2B8-2B326-2B8-2B14-2B-3A2B8A2B14A2B2A2B14A2B8A2B3A-2B14-2B8-2B327-2(2B6-2B15-2B-4A2B6A2B15A2B2A2B15A2B6A2B4A-2B15-2B6-2B328-)2B6-2B15-2B-4A2B6A2B15A2B2A2B15A2B6A2B4A-2B15-2B6-2B329-2B4-2B15-2B2-5A2(2B4A2B15A)2B4A2B5A2-2B15-2B4-2B330-2B4-2B14-3B2-5A2B4A2B14A3B4A3B14A2B4A2B5A2-3B14-2B4-2B330-2B4-2B13-3B3-5A2B4A2B13A3B6A3B13A2B4A2B5A3-3B13-2B4-2B331-2B2-2B13-3B4-6A2B2A2B13A3B8A3B13A2B2A2B6A4-3B13-2B2-2B332-2B2-2B12-3B5-6A2B2A2B12A3B10A3B12A2B2A2B6A5-3B12-2B2-2B332-6B8-6B6-6A6B8A6B12A6B8A6B6A6-6B8-6B333-4B9-5B7-7A4B9A5B14A5B9A4B7A7-5B9-4B359-64A384-64A192-
