model
size = 19 31 24, scale = 0.05, origin = -y
material 
  colors = A:#AAA B:#0F6 C:#090 D:#0F3 E:#888 F:#FF0 G:#0C0 H:#FF9 I:#111 J:#9CF K:#6F3 L:#FF6
voxels
521-3A14-7A547-H18-F18-H531-3(F18-)H18-F493-H18-F18-L3(18-F)18-H474-2(F18-)F37-F18-H18-F474-2(H18-F18-)2(F18-)H493-F15-3AK3A12-3AK4A14-H18-H509-7A11-A3BH3B2A8-2A3-H3-2A13-H509-7A11-10A7-3A7B3A6-3A7-4A485-3A14-7A11-10A7-3ACA3C5A5-3ABDB3-4B2A4-3A10-2A465-5A13-7A11-10A8-4A3B5A6-2A3C5B4A4-2AB3D5-3B2A2-3A12-2A65-5A375-5A13-7A11-9A9-4A3B4A7-3A2C3B2C3A5-2A2C2D3B2-B3A3-2AB2D8-2B2A2-2A13-3A63-7A15-E321-3A15-5A13-7A11-9A9-4A3B4A7-4A-5B3A6-2A2C-5BC3A4-A2C2D-5B-B3A2-AB2D10-2BA-2A15-2A63-8A12-5E300-3A15-5A13-7A11-4AG4A10-3A3BC3A8-3A-3BC3A7-3AB-3B-B3A5-3ACB-3B-BC3A3-2A2CDB-3B2(-B)3A2-AB2D-B8-2B4A15-2A62-3A3-3A12-E3AE15-3E225-A-A2(16-3A)15-5A14-6A12-3A2G2A11-3A3B3A9-3AC3BC3A8-2AB-3BGB3A6-2A2B-6B2A5-3A2B-7B2A3-2A2C2B-7BC2A-2AB2D2B8-DB4A15-2A62-3A3-3A12-EA-A2E14-EAE17-11(I18-)I17-AJA16-AJA15-5A14-2AD3A12-2A-DG2A11-3AD2BC2A9-3ACD2BC3A8-2AB2D2BGB3A6-2A2B2D5B2A5-2A3B2D6B2A3-2AC3B2D6BC2A-2ABD-2B8-D2B3A16-A62-3A3-3A12-E3AE15-3E225-A-A2(16-3A)15-5A14-6A12-3AD3A11-3AD2B3A9-3ACD2BC3A8-2AB2D2BGB3A6-3AB2D5B2A5-3A2B2D6B2A3-3AC2B2D6BC2A-2A5B8-DB4A15-2A63-8A12-5E300-3A15-5A13-7A11-9A10-3A3B4A8-3AG4B3A7-3A2-5B3A5-3AB2-5BG3A3-3ACB2-5BD2C2A2-A4B8-2DB4A15-2A63-7A355-5A13-7A11-9A9-4A3B4A7-4A-4B4A6-3AB-4B2G3A4-2A2CB-4B2D2C2A2-A5B7-2DBA-2A15-2A65-3A376-5A13-7A10-10A9-5A2G4A7-4A2-2D2G3A5-2A3C4-2D2C2A3-2A4B6-2DB2A2-2A13-2A465-3A14-7A11-9A9-5A-5A7-2A4C-4C2A5-2A5B-4DB2A3-3A11-3A501-7A11-9A9-A2C9A6-2A2B6C4A4-3A8-4A521-7A11-A7CA9-2A7B3A6-3A7-3A541-7A11-9A9-11A61-
