model
size = 9 32 9, scale = 0.05, origin = -y
material 
  colors = A:#040 B:#030 C:#DDD D:#010 E:#E00
voxels
2-20(5A4-)5A5-3A94-2A3B19(2A2-2A3-)2A2-3A-3A2-7A3-4A84-2A5B20(4A5-)2A-2(2A3-)6A3-5A5-3A7-A58-A7B19(2A7-)3A5-4A5-2A-2(2A3-)2A-2A4-2(A-)A5-6(3A6-)3B3-A7B20(2A7-)3A5-2A-2(2A3-)A3-A2(4-2A-2A)5-5(A-A6-)B-B3-A7B19(2A7-)3A5-4A5-2A-2(2A3-)2A-2A4-2(A-)A5-6(3A6-)3B3-2A5B20(4A5-)2A-2A3-2A2-6A4-5A5-3A7-A59-2A3B7(2A2-2A3-)2A10(2-CA3-AC)2(2-2A3-2A)2-3A-3A2-7A4-4A85-7(5A4-)5C4-C3AC4-5A4-A3CA4-2DC2D4-5D4-A3CA4-ACECA4-A3CA4-5A4-5C3(4-5A)5-3A93-
