model
size = 33 28 18, scale = 0.05, origin = -y
material 
  colors = A:#9CF B:#EEE C:#DDD D:#111 E:#BBB F:#888 G:#555 H:#E00 I:#444 J:#777
voxels
79-7B24-11B21-4B5-4B19-3B9-3B17-2B13-2B15-3B13-3B14-2B15-2B13-3B15-3B5(12-2B17-2B)12-3B15-3B13-2B15-2B14-3B13-2B16-2B13-2B17-3B9-3B19-4B5-4B21-11B24-7B178-66B2A29C2(4AC27AC)4AC10A5C12AC4AC9A7C11AC4AC8A9C10AC4AC7A4CHCD4C9AC4AC7A3C2HC2D3C9AC4AC7A3C2H6C9AC4AC7A3C5H3C9AC4AC7A4C3H4C9AC4AC8A9C10AC4AC9A7C11AC4AC10A5C12A2(C4AC27A)C4A29C2A47B3-3B3-24B3-3B3-4B5-15B3-3B3-4B5-28B5-12B8E8B5-12BE6-E14B66-5B3(3-B)3-3B-2(B3-)6B3(3CB)3C3BC2(B3C)B561AB31A2B13A2GI3A2GI9A2B13A2GI3A2GI4A4FG2B13A2GI3A2GI4AF3BG2B26AF3BG2B11A6E9B4FG12BE-D2-D-E14B66-5B2(-B)-3B2(-B)-5B4(-B)-6B2(CB)C3B2(CB)C5B5(CB)561AB31A4(2B30AF)2B11A6E16B2F7EBE-J2-J-E14B-9E2-6E18-7E23-5B2(-B)2(3-2(B-)B)3(-B)-6B2(CB)3C2(BC)B3C3B5(CB)561AB31A4(2B29A2F)2B11A6E16B3F6BEB-J2-J-15B4E6CE-6E22-4E22-5B-B-3B2(-B)2(-3B)4(-B)-6BCBC3B2(CB)2(C3B)5(CB)462AB4(31A2B)4(29A2F2B)11A4EAE14A2B4F3B2E6B-2B-B2-3(B-)B2-BE3HEC4E25-H4-C2E23-5B3(3-B)3-3B-2(B3-)6B3(3CB)3C3BC2(B3C)B462AB4(31A2B)4(29A2F2B)11A4EAE14A2BFD2F11B2(-2B)3(-B)-2B-BED-H2E2-3E23-H-H29-66B561AB31A4(2B29A2F)2B31A2B4F11B-2B-B2-2B2-B-2B-BE3HE2-5E23-H30-66B561AB31A4(2B28A3F)2B31A2B3F5BD6B2(-2B)3(-B)-2B-B4E3-2E-2E54-66B561AB31A2B28A3(3F2B2AI3G14AE4C3A)3F2B2AI3G16AC8A2B2F12B3-B-B2-3(B-)2B-B-2E4-5E54-66B235A3C29A2(5C28A)5C29A3C33AB32AB17AB14AB16A2B9AC4A2B15A2B8ACAC3A3B13A3B7A11B11A24B7A6BD2A3F4B4-14B4-BDG4F4B4-14B4-BDGF7B4-14B4-BDGF30BDG4F34B8-3E134-7C24-11C21-13C19-15C9-C7-17C8-2E6-17C8-2EC4-6C6B7C7-2E5-6C6B7C7-CE3-C-6C6B7C7-2C2-CD7C6B7C7-2C3-C-2(6C6B7C7-2C5-)19C8-C6-17C16-16C18-15C11-D7-13C21-11C24-7C6-7D4(26-D5-D)26-7D145-7C24-11C21-13C19-15C17-17C16-17C8-D6-6(6C6B7C14-)19C15-17C16-16C18-15C19-13C21-11C24-7C2(323-7B24-11B21-10BA2B19-11BA3B17-12BA4B16-12BA4B15-6(13BA5B14-)13BA5B15-12BA4B16-12BA3B18-11BA3B19-10BA2B21-11B24-7B)323-7C24-11C21-13C19-15C17-17C16-17C15-6(5CB13C14-)5CB13C15-4CB12C16-4CB11C18-3CB11C19-2CB10C21-11C24-7C323-7B24-11B21-10BA2B19-11BA3B17-12BA4B16-12BA4B15-6(13BA5B14-)13BA5B15-12BA4B16-12BA3B18-11BA3B19-10BA2B21-11B24-7B290-7B24-11B21-4B5D4B19-3B9D3B17-2B13D2B15-3B13D3B14-2B15D2B13-3B15D3B5(12-2B17D2B)12-3B15D3B13-2B15D2B14-3B13D2B16-2B13D2B17-3B9D3B19-4B5D4B21-11B24-7B211-
