model
size = 32 9 14, scale = 0.05, origin = -y
material 
  colors = A:#4B4B4B B:#BEBEBE
voxels
38-2(20A12-)11A3(2BA)3(22-3(A2B)A)76-2(20A12-)11A3(2BA)3(22-3(A2B)A)106-2(24A8-)2A9-2A2(2BA)2B3A19-2(2A2(2BA)2B2A20-)2A2(2BA)2B2A21-3(A2B)A72-2(28A4-)2A24-2A113-2A2(2BA)2B2A21-3(A2B)A39-2(30A2-)A27-2A144-2A2(2BA)2B2A37-6A2(BA)3BA3B2A2B4AB39A29-2A143-2A2(2BA)2B2A20-2A2(2BA)2B2A5-6ABAB3A3(BA)B2AB3AB39A30-A143-2A2(2BA)2B2A20-2A2(2BA)2B2A5-7AB3A2BA3BAB2AB3AB39A30-A143-2A2(2BA)2B2A20-2A2(2BA)2B2A5-7AB4AB2A2BAB2AB3AB39A30-A143-2A2(2BA)2B2A20-2A2(2BA)2B2A5-6ABAB3A3(BA)B2AB3AB39A30-A143-2A2(2BA)2B2A20-2A2(2BA)2B2A5-6A2(BA)3B2(AB)2A2B2A3B39A29-2A143-2A2(2BA)2B2A20-2A2(2BA)2B2A6-2(30A2-)A27-2A144-2A2(2BA)2B2A39-2(28A4-)2A24-2A113-2A2(2BA)2B2A21-3(A2B)A42-2(24A8-)2A9-2A2(2BA)2B3A19-2(2A2(2BA)2B2A20-)2A2(2BA)2B2A21-3(A2B)A70-
