model
size = 32 23 14, scale = 0.05, origin = -y
material 
  colors = A:#4B4B4B B:#FFF C:#2A2A2A D:#C1C1C1 E:#E40303 F:#FF8C00 G:#FFED00 H:#008026 I:#004DFF J:#750787
voxels
38-4(20A12-)20A556-4(20A12-)20A586-4(24A8-)24A10-20B12-20B16(28-4B)8-4(28A4-)28A6-2B20-3B7-2B20-3B9-2(3DB)3D5B3(4-3B22-3B)2(4-3B22-3D4-3B22-2CD4-3B22-3D4-3B22-3B)4-3B22-3D4-3B22-DCD4-3B22-3D4-3B22-2(3B4-)4(30A2-)30A3-2B25-B4-2B25-B6-2B23-B8-2(DCDB)DCD2B10-B8-2(3DB)3D2B3(10-B20-B3(10-B20-D))10-B20-B10-B2-6A2(CA)3CA3C2A2C4AC134A-B28-B2-2B27-B4-B26-B5-2B11-D12-B5-2B2(3CB)3CD3(12-B18-B3(12-B18-C))12-B18-B12-B-6ACAC3A3(CA)C2AC3AC134A-B28-B2-B28-B3-B27-B4-B13-D12-B5-2B3(3CB)3(12-B18-B3(12-B18-C))12-B18-B12-B-7AC3A2CA3CAC2AC3AC134A-B28-B2-B28-B3-B27-B4-B13-D12-B5-2B3(3CB)3(12-B18-B3(12-B18-C))12-B18-B12-B-7AC4AC2A2CAC2AC3AC134A-B28-B2-B28-B3-B27-B4-B13-D12-B5-2B3(3CB)3(12-B18-B3(12-B18-C))12-B18-B12-B-6ACAC3A3(CA)C2AC3AC134A-B28-B2-B28-B3-B27-B4-B13-D12-B5-2B3(3CB)3(12-B18-B3(12-B18-C))12-B18-B12-B-6A2(CA)3C2(AC)2A2C2A3C134A-B28-B2-2B27-B4-B26-B5-2B11-D12-B5-2B3(3CB)3(12-B18-B3(12-B18-C))12-B18-B12-B5(2-30A)3-2B25-E4-2B25-F6-2B23-G8-2(DCDB)DCD2B10-H8-2(3DB)3D2B10-I20-B10-J20-D10-E20-D10-F20-D10-G20-B10-H20-D10-I20-D10-J20-D10-E20-B10-F20-D10-G20-D10-H20-D10-I20-B10-J5(4-28A)6-3B19-3B7-3B19-3B9-2(3DB)3D5B3(4-3B22-3B)2(4-3B22-3D4-3B22-2CD4-3B22-3D4-3B22-3B)4-3B22-3D4-3B22-DCD4-3B22-3D4-3B22-3B4-3B7-4(24A8-)24A11-19B13-19B16(28-4B)6-
