model
size = 15 16 30, scale = 0.05, origin = -y
material 
  colors = A:#D00 B:#222 C:#EEE D:#3FF E:#E00 F:#C3F
voxels
64-3(8E37-)8E38-3(C-)C8-7B216-C-8C5-10B6-8A8-5A187-12C3-12B4-10A6-7A9-5A172-11C3-13B3-11A5-9A7-6A10-4A157-14C-14B-13A3-11A5-8A8-6A155-14C-15B-13A3-11A5-9A6-8A155-5C5D4C5BA9B14A3-3A-7A5-2A-A-4A6-8A10-3A141-5C7D2C-15B14A3-11A5-10A5-8A9-5A10-5C126-3C9D2C15B14A2-12A4-11A4-10A7-6A11-3A126-4C9DC-15B5A4BAB3A2-12A4-11A4-10A6-8A9-5A126-3C9D2C15B5A6B3A2-12A4-11A4-10A6-8A8-6A10-5C110-4C9DC-12B-2B5A6B3A2-12A4-11A4-10A5-9A7-8A125-3C9D2C12B-2B5A6B3A2-12A3-12A4-11A4-9A7-8A8-7A9-5C95-4C9DC-11B-3B5A5B4A2-2(12A3-)12A4-10A6-6A-A2(8-7A)95-3C9D2C15B5A7B2A2-3(12A3-)11A6-9A6-8A8-7A8-A5C10-5A10-5C50-4C9DC-15B5A7B2A-14A2-3(12A3-)6A-4A6-3A3-3A6-5A2-A8-2A4-A8-2A2CA2(10-5A)37-3C9D2C15B5A7B2A-5AB8A-14A2-2(12A3-)12A4-2A-5A-A6-9A6-3(8A7-)7A35-4C9DC-15B5A7B2A3(-14A)2-3(12A3-)11A5-2(9A6-)8A7-8A9-5A22-3C9D2C15B5A7B2A-14A-A2(-12A)FA-14A2-9A-3A2-3A-5A-2A3-12A3-2A-6A-A4-11A4-10A5-3A4B3A6-2A5B2A8-5B6-4C9DC-15B5A7B2A-14A-12AFA-14A-3A2-9A-14A2-13A2-12A3-9A-2A3-11A4-2A6B3A4-2A-5B3A4-2A7B2A7-6B6-3C9D2C5B2DB4D3B5A7B2A2(-14A)-12AFA-14A-12AFA-3A8BAFA2-2AB5-2B3A2-2AB2(5-2B2A3-A2B)2(5-2BA4-A2B)5-2BA18-5C7D2C-15B6A6B2A2(-14A)-4A-9A-14A-12AFA-3A8B3A-3A2(7-B3A2-AB)2(7-B2A3-AB)7-BA4-AB7-BA19-4C7D3C15B4(14A-)13A2-14A-3A8B2(3A-2AB7-B)3A2-2(AB7-B2A3-)AB7-BA4-AB7-BA18-14C-15B3(14A-)13A2-9A-3A2-13A2-3A8B2(3A-2AB7-B)2(3A2-AB7-B)2A3-AB7-BA4-AB7-BA19-14C-14B-2(13A2-)4(12A3-)2A8B2A3-3(AB7-B3A2-)AB7-B2A3-AB7-BA4-AB7-BA20-12C3-12B2-13A2-A-10A3-12A3-5A-6A3-5A-2A-3A3-12A3-2A8B2(2A3-A2B5-2B)3A2(2-A2B5-B4A)2-A2B5-B2A4-A2B5-2BA20-12C3-12B3-3(11A4-)2(5A-5A4-)11A4-4A4B3(3A4-A7B)2(4A3-A7B)2A5-A7B2A21-10C5-10B10(5-10A)5-11A4-2A-6A6-8A23-4(C-)C6-9B6-10(8A7-)6AEA8-6A10-4A20-
