model
size = 14 32 28, scale = 0.05, origin = -y
material 
  colors = A:#888 B:#EEE C:#111 D:#CC0 E:#555 F:#F60 G:#006 H:#609
voxels
17-E632-2C12-2C427-7(12A2-)2(12B2-)3(12C2-)12C267-C2(12A2C)12AC-4(12A2-)4(2(12B2-)2(C10BC2-)12C2-12C267-C6(12A2C)12AC-)4(12B2-)12C2-12C268-6(12A2-)3C8AC4(2-12B)2(2-12C)3-2D2-2(D-)2D4-D2-2D-D2-D3-2D2-D2-2D-2D2-D2-2D3-D2-D-2D2-D4-D2-2D197-6(12A2-)3C6A3C2-12B-G12BG14B-12B2(2-12C)268-6(12A2-)3C6A3C2-12B-G12B2G12BG-12B2(2-12C)268-6(12A2-)3C6A3C4(2-12B)2(2-12C)268-3(12A2-)5AHC5A2-5ACH5A2-5AHC5A2-12C2(2-12B)2(2-5B2C5B)2(2-12C)256-E13-FCF2-FCF107-2F317-E13-FCF2-FCF426-12(E433-)E430-
