model
size = 31 32 12, scale = 0.05, origin = -y
material 
  colors = A:#070 B:#390 C:#100 D:#F00 E:#005 F:#EEE G:#010
voxels
453-2C20-2C7-2C19-3C7-3C18-3C7-3C17-3C9-3C16-3C9-3C15-3C28-3C405-7A23-8A21-5A26-3A7-2A18-3A8-3A17-2A10-2A15-2A12-3A13-2A14-3A11-2A16-2A10-3A17-2A8-3A18-3A6-3A20-2A6-2A21-3A29-2A28-4A27-4A28-2(3A3-2A23-)3A3-3A3(29-2A)31-2(2A29-)2A224-7A22-9A21-5A2-3A21-3A6-3A18-3A7-4A17-3A7-5A15-2A10-5A13-2A12-5A11-2A13-5A9-4A14-5A7-4A16-4A6-4A18-3A6-2A20-4A4-3A21-3A4-2(2A22-4A3-)3(2A23-3A3-)2(3A28-)4A28-3A29-3A28-6A13-3A10-5A13-3A11-4A13-3A145-6A23-9A20-11A20-4A2-3A21-4A5-2A19-4A6-3A18-3A7-5A15-3A9-5A13-3A11-5A11-3A12-5A9-4A14-5A7-4A16-4A6-4A18-4A4-4A19-4A4-3A21-3A4-2A22-3A4-2(2A23-3A3-)2A24-2A3-2A23-4A2-3A22-4A2-4A22-3A2-4A28-3A28-4A28-6A13-3A10-7A5-9A10-8A2-11A14-4A2-6A118-7A23-9A21-10A20-4A3-4A2(19-4A6-2A)18-3A8-3A17-2A9-4A14-3A11-4A12-3A13-4A9-4A15-3A8-4A16-4A7-3A17-5A5-3A18-5A4-3A20-4A4-3A21-4A3-2A22-4A2(3-2A23-3A)3-2A23-4A2-3A22-4A2-4A22-3A3-3A22-3A3-4A20-3A4-4A19-4A5-5A14-6A7-7A-13A10-21A13-13A-3A18-4A6-2A84-6A24-8A21-11A20-4A-6A20-3A3-5A19-4A4-4A18-4A5-5A17-3A7-5A14-4A8-6A12-4A2(10-5A)12-5A8-4A15-5A7-3A16-5A6-3A18-6A4-3A19-5A4-2A2(21-4A3-3A)22-3A3-3A22-3A3-2A23-5A-4A19-7A-4A18-8A2-4A17-3A-3A3-4A17-2A-4A3-5A18-4A5-4A15-6A6-6A3-5A-10A6-24A7-22A10-13A-7A28-3A56-2A22-9A21-10A21-11A20-3A-7A19-4A-2A-4A18-5A4-5A17-5A4-6A14-6A6-5A13-6A8-5A10-7A9-5A-2A6-6A12-5A8-6A13-5A6-5A16-6A4-4A18-5A4-3A20-4A3-4A21-2(3A3-3A22-)5A-3A21-6A-4A19-7A-4A18-8A-5A17-8A2-4A17-8A2-5A16-8A3-4A16-7A4-6A3-2A4-11A5-26A5-25A7-22A21-2A4-3A20-6A24-4A-3A22-9A22-10A21-10A20-3A-7A20-3A-8A19-3A-2A-5A18-4A4-5A17-4A6-5A13-6A8-5A12-5A9-5A-2A8-6A10-9A5-5A14-7A3-5A16-8A2-4A18-7A2-4A19-6A2-3A22-4A-3A23-8A22-5A-3A21-6A-4A19-7A-4A18-14A17-8A2-4A17-8A2-8A13-8A3-9A11-8A3-11A6-10A5-10A-2A-12A5-25A7-22A11-18A20-6B24-A6B23-A7B23-3B3C4B2(21-10B)20-11BA19-12B18-5BCBC6B16-6BCBC6B14-A2(4B3C)2B13-A4B4C3B5C3B2A8-4B6C3B6C4B2A2(5-4B7C3B7C5B)A3-5B7C3B7C6B2-A4B8C3B8C5B2-A4B8C4B7C5B2-A3B9C4B7C5BA-4B9C4B8C5B-4B8C6B7C5B-4B7C8B6C5B-4B6C2B6D2B4C6B-5B4C3B6D2BG3C6B-A10B8D10B2-A2(9B9D10B3-)10B8D9B5-9B8D9B5-10B6D9B8-21B11-A17B20-6B25-6B24-7B23-3B3C4B2(21-10B)2(20-11B)19-5BCBC6B16-6BCBC6BA14-4B3C4B5CB13-4B4C3B6C2B2A8-4B6C3B6C4B7-4B7C3B7C5B5-4B7C3B7C5B4-5B7C3B7C6B3-4B8C3B8C5B3-4B8C4B7C5BA2-3B9C4B7C5BA-4B9C4B8C5B-4B8C6B7C5B-4B7C8B6C5B-4B6C2B6D2B4C5B2-5B4C3B6D2BG3C4B4-10B8D9B4-9B9D10B3-9B9D8B5-10B8D8B6-9B8D9B5-10B6D9B8-21B12-17B2A50-3B27-5B26-B3-B25-2(8B23-)8B22-9B21-4B-B-5B18-2B2C2(B-)B3C2B16-2B3C-4B4C2B14-2B6C2BC2E3C2B12-2B7C2BC3E2C-B11-2B3C2E3C2BC3E3C3B8-3B2C4E2C2BC4E2C3B8-3B2C2E4C2BC4E2C4B6-3B2C3E4C2B2C3E2C-3B6-3B2C2E5C3BC3E3C4B4-3B2C3E4C4BC3E3C4B4-3BC4E3C-4B2C2E3C-3B4-3B2C2E4C6BCE5C3B4-3B3CE3C8B6C3B5-2B6C-9B4C4B5-3B3C-4B3D4B4C3B6-10B2DF2D9B8-8B2D3F2D8B10-6BD5FD7B12-5B2D3F2D6B14-5B2DF2D6B16-5B3D6B18-12B24-4B370-4C27-5C18-4C4-2CE2C17-2CE2C4-2CE3C16-C2EC6-C2E2C15-2C2EC6-C2E2C15-C2E2C6-2C2EC14-2C2EC7-5C14-C3EC7-5C14-5C8-4C15-3C331-
