model
size = 8, scale = 0.05, origin = -y
material 
  colors = A:#555 B:#FC3
voxels
2(3-4A)7(4-4A)2(4-A2BA)4-4B12-4B2(4-4A)3-6(2A2-)BA2-AB10-BA2-AB2(2-2A)2-6A-2A3(4-4A)4-2AB6-B2A4-5A2-12A6(6-2A)6-10A6(6-2A)6-11A5(4-4A)4-5A2-11A-8(2A2-)A3-5(2A2-)6A-
