model
size = 10 8 18, scale = 0.05, origin = -y
material 
  colors = A:#555 B:#777 C:#444 D:#888 E:#AAA F:#EEE
voxels
-9A140-10A-C2(9-2C)46-AE2D2E2DEAC9-2(C10-)2C9-B10-B15-AD6ADA6-C3-C6-C2-C10-2C9-2B10-B9-B-2B2-3AE2DE3A5-2C10-C2-C6-C3-C9-2B10-B-3B5-5B2-3ADAED3A4-2C2(10-C)9-C8-2B3-2B2-BFB4-5B3-2(AD)E2(AD)A14-2(2C9-)C9-B8-2B7-2B4-ADA2(ED)ADA70-AE2(AD)2(EA)2(70-AEAD2EDAEA)70-2(AE)AD2(EA)-C2(9-2C)46-ADA2DE2(DA)C9-2(C10-)2C9-B10-B15-2(AD)E2(AD)A6-C3-C6-C2-C10-2C9-2B10-B9-B-2B2-3A2DED3A5-2C10-C2-C6-C3-C9-2B10-B-3B5-5B2-3AEADE3A4-2C2(10-C)9-C8-2B3-2B2-BFB4-5B3-AD6ADA14-2(2C9-)C9-B8-2B7-2B4-AE2D2E2DEA
