model
size = 32 3 32, scale = 0.05, origin = -y
material 
  colors = A:#000 B:#E9E73A C:#D61E86 D:#761D51 E:#FFF F:#A21966 G:#D7C16E H:#3D98B8 I:#2CE8F4 J:#7D6F3B K:#B8E986 L:#344A57 M:#564B26 N:#63C64D
voxels
-36AL2H2I12A2I2HL42ABJ7A4C7AJB69AF4ABJ6AD4CD6AJB4AF64AF4A2B5ADF4CFD5A2B4AF64A2F3A2B4A2DEF2CFE2D4A2B3A2F64AC2F7A2DAEF2CFEA2D7A2FC65ACF4G3AE2AED2CDE2AE3A4GFC67AG4BGA2D10A2DAG4BG67AG2B3ABGDFDE6AEDFDGB3A2BG65ACB6ABDCFEAE2AEAEFCDB6ABC64AC2BC5AD2CFDE2AEDF2CD5AC2BC64AC2B2G2C2G2BFCF4DFCF2B2G2C2G2BC65AC6B5CAC2DCA5C6BC68AC3BCF4D6C4DFC3BC73AC2D5AF2CF5A2DC71AC2AC2FDA4E2A2C2A4EAD2FC2AC67AC3FDA2E2A2ED2CD2E2A2EAD3FC69ACF2DAE2ANAED2CDEAN2AEA2DFC71A2CDAE4AED2CDE4AEAD2C68AB4AMCD2E2A2ED2FD2E2A2EDCM4AB64A2B4AMJD4EDF2DFD4EDJM4A2B65AB3AM3J4D2F2L2F4D3JM3AB70A2JG3B2K2L2H2L2K3BG2J73A2JG2B2KDL2H2I2HLD2K2BG2J71AMJG2B2KDLH6IHLD2K2BGJM69AMJG3BKDLH2I4E2IHLDK3BGJM67AMJG3BKDL2HIEK2AKEI2HLDK3BGJM65AMJG3BKDALH2IE4AE2IHLADK3BGJM64AJG3BK3A2HIAEAB2AEAI2H3AK3BGJ64A4BK3ALH2IAEK2AKEA2IHL3AK4B64A4B3AL2HI3A4E3AI2HL3A4B64A2B4AL2H2I10A2I2HL4A2B64A
