model
size = 27 14 27, scale = 0.05, origin = -y
material 
  colors = A:#4A225D
voxels
10-7A20-7A341-13A14-13A17-7A20-7A286-15A12-15A14-11A16-11A18-7A20-7A230-19A8-19A10-15A12-15A14-11A16-11A18-7A20-7A175-21A6-21A8-17A10-17A11-15A12-15A14-11A16-11A18-7A20-7A121-21A6-21A7-19A8-19A9-17A10-17A12-13A14-13A15-11A16-11A19-5A22-5A67-23A4-23A5-21A6-21A7-19A8-19A10-15A12-15A13-13A14-13A16-9A18-9A20-5A22-5A12-25A2-25A4-21A6-21A7-19A8-19A9-17A10-17A11-15A12-15A13-13A14-13A16-9A18-9A10-25A2-25A3-23A4-23A5-21A6-21A7-19A8-19A9-17A10-17A12-13A14-13A15-11A16-11A9-25A2-25A3-23A4-23A5-21A6-21A7-19A8-19A9-17A10-17A11-15A12-15A13-13A14-13A7-54A-25A2-25A3-23A4-23A5-21A6-21A7-19A8-19A10-15A12-15A13-13A14-13A7-5(54A-25A2-25A3-23A4-23A5-21A6-21A7-19A8-19A9-17A10-17A11-15A12-15A6-)54A-25A2-25A3-23A4-23A5-21A6-21A7-19A8-19A10-15A12-15A13-13A14-13A8-25A2-25A3-23A4-23A5-21A6-21A7-19A8-19A9-17A10-17A11-15A12-15A13-13A14-13A8-25A2-25A3-23A4-23A5-21A6-21A7-19A8-19A9-17A10-17A12-14A13-14A14-11A16-11A9-25A2-25A4-21A6-21A7-19A8-19A9-17A10-17A11-15A12-15A13-13A14-13A16-9A18-9A11-23A4-23A5-21A6-21A7-19A8-19A10-15A12-15A13-13A14-13A16-9A18-9A20-5A22-5A14-21A6-21A7-19A8-19A9-17A10-17A12-13A14-13A15-11A16-11A19-5A22-5A68-20A7-20A9-17A10-17A11-15A12-15A14-11A16-11A18-7A20-7A122-19A8-19A10-15A12-15A14-11A16-11A18-7A20-7A178-15A12-15A14-11A16-11A18-7A20-7A233-13A14-13A17-7A20-7A290-7A20-7A334-
