model
size = 32 32 25, scale = 0.05, origin = -y
material 
  colors = A:#63F B:#CFF C:#FF9 D:#EEE E:#0FF F:#001 G:#6FF H:#FFF I:#9FF J:#06F K:#69F L:#9CF M:#39F N:#609 O:#66F P:#36F Q:#60F R:#60C S:#90F T:#90C U:#FF6 V:#6F6 W:#F0C X:#3CF Y:#C0C Z:#FF0 Aa:#30F Ab:#FCC Ac:#C6F Ad:#0E0 Ae:#309 Af:#3FF Ag:#99F
voxels
426-H991-U30-UEU30-U991-H709-7B24-8B2AIA19-4B4-2AI4A17-3B8-5A16-3B11-3A5(30-2A)29-N2A27-2J2N27-5J28-3J30-J118-U414-6B24-2B6AB2AI19-8B7A17-7B3-I5A16-4B7-6A15-4B9-5A28-4A3(29-3A)28-N3A27-J4A26-J3AN26-J3AJ28-3J30-J86-E30-3E30-E382-7B23-7B4AIA18-8B7A17-6B4-I5A16-4B7-6A15-4B10-4A28-4A4(29-3A)28-N3A27-J2AN26-2J2AJ28-3J30-J118-U414-7B23-8B3AIA18-8B3AI3A17-6B3-AI5A16-4B8-5A15-4B10-2(3A30-)3(2A30-)2(2A29-)2N29-2J29-J627-3(4B28-)4B924-3(4B28-)4B857-10A21-12A19-7(14A18-)14A19-12A20-12A21-10A120-6A25-3(8A24-)8A25-6A343-12A19-13A18-15A16-2(18A14-)18A15-5(16A16-)16A17-3(14A18-)14A19-5(12A20-)12A21-10A23-8A278-12A18-15A17-16A15-3(16ACA14-)18A14-18A15-4(16A16-)16A17-8(14A18-)14A19-12A20-12A22-8A246-12A18-16A15-16ACA11-H2-3(16ACA14-)18A14-18A15-4(16A16-)16A17-8(14A18-)14A19-12A20-12A22-8A243-18A14-18A11-Z2-16ACA10-ZEZ-16ACA11-Z2-2(16ACA14-)18A14-18A15-4(16A16-)16A17-8(14A18-)14A19-12A20-12A22-8A180-2H12-2L16-3K10-3K16-16A15-18A14-18A11-H2-4(18A14-)18A15-3(14ACA16-)14ALA13-2I2-13ALA-2I8-2I3D-14A-3D2I5-I6D14A6DI6-5D14A5D6-2I5D14A5D2I3-I6D-11A2CA-6DI-I2D-3D2-11A2CA2-3D-2D2(ID3-)11A2CA3-DI3-D3-ID4-11A2CA4-DI6-D5-11AC2A5-D13-10ACA20-12A22-8A27-2M30-2Aa2(30-2A)30-2Ae24-2H10-2L17-KGK10-KGK16-16A15-6(18A14-)18A15-14ACA16-G13ACG16-14AC2(A16-14AL)A17-4(14A18-)4(11A2CA18-)2(11AC2A18-)E12AE18-2(EA)E4A2(EA)E17-E2AE3-2M3-E2AE16-3E4-AaJ4-3E23-AAg30-2A121-12A18-16A15-5(18A14-)18A15-3(G13ACG16-)14ALA17-5(14A18-)4(11A2CA18-)2(11AC2A18-)E12AE18-E3AE4AE3AE18-2AE3-2M3-E2A17-E-E10-E-E178-12A18-16A16-16A15-2G14A2G14-2G14A2G15-G13ACG2(16-14ACA)3(16-G13ACG)17-3(14A18-)14A16-15AC2A15-14ACA16-12A3CA17-3(11A2CA18-)11AC2A19-12A20-12A21-3AE2AE3A246-10A20-9A2C3A17-G9A2C3AG3(16-GAG7A2C2(AG))17-AGA8CAGA2(18-4A6C4A)18-G4A4C4AG18-14A19-12A20-12A19-14A18-AC2(2A2F)4A16-8A2F8A15-AAb12AAbA16-3AC3A2F7A17-AC3A2F7A18-14A18-2A3W4A2W3A18-2A2FW4AWF3A19-AAfF6AF2A20-5A2E5A279-6Y25-8T24-8S24-8R24-8Q24-8A24-8P25-6M22-O2A-6X-2AO18-3O2-4E2-3O112-2F14-2F16-2F10-2F49-2F12-2F13-3F2(3-F3-2F)16-F3-4F3-F17-3F-3H4-3H-3F17-5H2-5H20-H2VAdH2-HAd2VH20-H2FVH2-HV2FH21-ZFV4-VFZ533-2(2K8-2K20-)2K8-2K428-U487-3H6-3H20-3L6-3L20-LAcL6-LAcL20-3K6-3K396-E30-3E30-E440-H550-U152-I287-I30-IEB30-I639-E30-3E30-E287-H703-I36-
