model
size = 31 32 17, scale = 0.05, origin = -y
material 
  colors = A:#A00 B:#B00 C:#500 D:#800 E:#700 F:#400 G:#D00 H:#200 I:#9CF
voxels
8-4(15H16-)4(15F16-)4(15C16-)15E17-3(13E18-)4(13D18-)13A17-15A14-2(19A12-)19B13-17B15-15B16-15B18-11G20-11G21-9G49-3(H15-H14-)17H4(14-17F)4(14-17C)3(14-17E)15-15E4(16-15D)11-4A-15A-4A6-5AI13AI5A2(6-25A)7-23B8-23B9-21B12-17B15-15G17-13G19-11G22-7G18-4(H17-H12-)4(F17-F12-)C17-C3(12-2C15-2C)12-2E15-2E13-3(E15-E14-)2(D15-D14-)2(D15-)D13-D10-A5-A13-A5-2(A4-)2A13-2A2(4-A)25-A4-2A23-2A4-3B21-3B5-BIB19-BIB6-2BIB17-BI2B7-4B16-3B10-2G15-2G14-2G11-2G17-2G9-2G20-G7-G16-4(H19-H10-)4(F19-F10-)C19-C11-3(C17-C12-)2(E17-E12-)E17-E13-E15-E4(14-D15-D)8-A5-A15-A5-2(A2-A27-)A2-2A25-2A3-2B23-2B4-BIB21-BIB4-B2IB19-B2IB5-B2IB17-B2IB7-4G15-3GB11-2(G15-)G13-G17-2G9-2G14-4(H19-H10-)4(F19-F10-)C19-C3(10-2C17-2C)11-2(E17-E12-)E17-E13-E15-E4(14-D15-D)8-A5-A15-A5-2(A2-A27-)A2-A26-2A2-2B25-2B2-BIB23-BIB3-BIB21-BIB4-B2IB19-B2IB5-2GIG17-GI2G8-3G15-3G2(13-G)17-G11-G14-4(H19-H10-)4(F19-F10-)4(C19-C10-)2(E19-E10-)E19-E11-E17-E3(12-D17-D)13-D15-D7-A6-A15-A6-2A2(28-3A)28-2A-B26-2B2-2B25-2B2-BIB23-BIB3-BIB21-BIB5-GI2G17-2GIG7-4G15-4G11-2G14-G16-G12-G13-4(H19-H10-)4(F19-F10-)4(C19-C10-)3(E19-E10-)2E17-2E10-2D17-2D11-2(D17-D12-)2D15-2D2(6-A)15-A6-2A2(28-3A)28-2AB28-2B-B26-2B2-2B25-2B3-2B23-2B4-3G21-3G6-2G19-2G10-2G15-2G14-2(G13-)4(H19-H10-)4(F19-F10-)4(C19-C10-)3(E19-E10-)2E17-2E2(10-2D17-2D)11-D17-D12-2D15-2D6-A5-2A15-2A5-2A2(28-3A)28-2AB28-3B28-2B-B26-2B2-2B25-2B3-2G23-2G5-3G19-3G9-2G15-2G14-2(G13-)4(H19-H10-)4(F19-F10-)4(C19-C10-)3(E19-E10-)2E17-2E3(10-2D17-2D)10-DID15-DID5-A5-2A15-2A5-2A2(28-3A)28-2AB28-3B28-2B-B26-2B2-2B25-2B3-2G23-2G5-3G19-3G9-2G15-2G14-2(G13-)4(H19-H10-)4(F19-F10-)4(C19-C10-)3(E19-E10-)2E17-2E2(10-2D17-2D)11-D17-D12-2D15-2D6-A5-2A15-2A5-2A2(28-3A)28-2AB28-2B-B26-2B2-2B25-2B3-2B23-2B4-3G21-3G6-2G19-2G10-2G15-2G14-2(G13-)4(H19-H10-)4(F19-F10-)4(C19-C10-)3(E19-E10-)2E17-2E10-2D17-2D11-2(D17-D12-)2D15-2D2(6-A)15-A6-2A2(28-3A)28-2A-B26-2B2-2B25-2B2-BIB23-BIB3-BIB21-BIB5-GIG19-GIG7-4G15-4G11-2(G15-)2(G13-)4(H19-H10-)4(F19-F10-)4(C19-C10-)2(E19-E10-)E19-E11-E17-E3(12-D17-D)13-D15-D8-A5-A15-A5-3(A2-A27-)A2-2B25-2B2-BIB23-BIB3-BIB21-BIB4-B2IB19-B2IB5-2GIG17-GI2G8-3G15-3G2(13-G)17-2G9-2G14-4(H19-H10-)4(F19-F10-)C19-C3(10-2C17-2C)11-3(E17-E12-)2E15-2E12-2D15-2D13-2(D15-D14-)D15-D8-A5-A15-A5-2(A2-A27-)A2-2A25-2A3-2B23-2B4-BIB21-BIB4-B2IB19-B2IB5-B2IB17-B2IB7-4G15-4G11-2G13-2G16-3G7-3G45-4(H19-H10-)4(F19-F10-)C19-C11-3(C17-C12-)2(E17-E12-)E17-E13-E15-E4(14-D15-D)9-A4-A15-2(A4-)2(A25-A4-)2A23-2A4-3B21-3B5-BIB19-BIB6-2BIB17-BI2B7-4B15-4B10-2G15-2G14-4G7-4G76-4(H17-H12-)4(F17-F12-)C17-C3(12-2C15-2C)12-2E15-2E13-2(E15-E14-)2E13-2E3(14-2D13-2D)15-D13-D11-3A2-A13-A2-3(3A6-3A19-)3A7-2B19-2B8-4B15-4B9-3B15-3B12-2(B15-)5G5-5G108-4(2H13-2H14-)4(2F13-2F14-)4(2C13-2C14-)2E13-2E2(14-3E11-3E)15-2E11-2E4(16-2D11-2D)14-2(4A11-)4A13-4A2(10-3A15-3A)11-2B15-2(2B13-)2B15-6B3-6B16-5B5-5B141-4(13H18-)4(13F18-)4(13C18-)4(13E18-)4(13D18-)13A17-15A15-17A14-17A15-7B-7B17-5B3-5B195-
