model
size = 31 32 17, scale = 0.05, origin = -y
material 
  colors = A:#FF0 B:#E00 C:#0B0 D:#111
voxels
8-15D12(16-2C11A2B)17-7(C11AB18-)C11AB17-2C11A2B14-2(4C11A4B12-)4C11A4B13-3C11A3B15-2C11A2B16-2C11A2B18-11A20-11A21-9A49-D15-D2(14-C15-B)12(14-3C11A3B)15-4(2C11A2B16-)2C11A2B11-4D-DC11A2B-4D3(6-7C11A7B)7-6C11A6B8-6C11A6B9-5C11A5B12-3C11A3B15-2C11A2B17-C11AB19-11A22-7D18-D17-D8(12-C17-B)4(12-2C15-2B)13-5(C15-B14-)C15-B15-C13-B10-D5-D13-B5-D4-C4-2C13-2B4-B4-C25-B4-2C23-2B4-3C21-3B5-3C19-3B6-4C17-4B7-4C16-3B10-2C15-2B14-2C11-2B17-CA9-AB20-D7-D16-D19-D8(10-C19-B)11-5(C17-B12-)C17-B13-4(C15-B14-)C15-B8-D5-D15-D5-D2(2-C27-B)2-2C25-2B3-2C23-2B4-3C21-3B4-4C19-4B5-3CD17-4B7-4C15-4B11-C15-B15-C13-B17-2D9-2D14-D19-D8(10-C19-B)3(10-2C17-2B)11-2(C17-B12-)C17-B13-4(C15-B14-)C15-B8-D5-D15-D5-D2(2-C27-B)2-C26-2B2-2C25-2B2-3C23-3B3-3C21-3B4-3CD19-4B5-4C17-4B8-3C15-3B13-C13-B17-D11-D14-D19-D14(10-C19-B)11-3(C17-B12-)C17-B13-C15-B7-D6-D15-D6-D3(C28-2B)-C26-2B2-2C25-2B2-3C23-3B3-2CD21-3B5-4C17-4B7-4C15-4B11-2C14-B16-D12-D13-D19-D14(10-C19-B)2(10-2C17-2B)11-2(C17-B12-)2C15-2B2(6-D)15-D6-D4(C28-2B)-C26-2B2-2C25-2B3-CD23-2B4-3C21-3B6-2C19-2B10-2C15-2B14-2(D13-)D19-D14(10-C19-B)3(10-2C17-2B)11-C17-B12-2C15-2B6-D5-CD15-2D5-D5(C28-2B)-C26-2B2-CD25-2B3-2C23-2B5-3C19-3B9-2C15-2B14-2(D13-)D19-D14(10-C19-B)4(10-2C17-2B)10-3C15-3B5-D5-CD15-2D5-D5(C28-2B)-C26-2B2-2C25-2B3-2C23-2B5-3C19-3B9-2C15-2B14-2(D13-)D19-D14(10-C19-B)3(10-2C17-2B)11-C17-B12-2C15-2B6-D5-CD15-2D5-D4(C28-2B)-C26-2B2-2C25-2B3-2C23-2B4-3C21-3B6-2C19-2B10-2C15-2B14-2(D13-)D19-D14(10-C19-B)2(10-2C17-2B)11-2(C17-B12-)2C15-2B2(6-D)15-D6-D3(C28-2B)-C26-2B2-2C25-2B2-3C23-3B3-3C21-3B5-3C19-3B7-4C15-4B11-C15-B15-2(D13-)D19-D14(10-C19-B)11-3(C17-B12-)C17-B13-C15-B8-D5-D15-D5-D3(2-C27-B)2-2C25-2B2-3C23-3B3-3C21-3B4-4C19-4B5-4C17-4B8-3C15-3B13-C13-B17-2D9-2D14-D19-D8(10-C19-B)3(10-2C17-2B)11-3(C17-B12-)2C15-2B12-2C15-2B13-2(C15-B14-)C15-B8-D5-D15-D5-D2(2-C27-B)2-2C25-2B3-2C23-2B4-3C21-3B4-4C19-4B5-4C17-4B7-4C15-4B11-2C13-2B16-2CD7-D2B45-D19-D8(10-C19-B)11-5(C17-B12-)C17-B13-4(C15-B14-)C15-B9-D4-D15-2(D4-)2(C25-B4-)2C23-2B4-3C21-3B5-3C19-3B6-4C17-4B7-4C15-4B10-2C15-2B14-3CD7-D3B76-D17-D8(12-C17-B)4(12-2C15-2B)13-2(C15-B14-)3(2C13-2B14-)2C13-2B15-C13-B11-3D2-D13-B2-3D3(6-3C19-3B)7-2C19-2B8-4C15-4B9-3C15-3B12-C15-B15-3CAD5-DA3B108-2D13-2D12(14-2C13-2B)2(14-3C11-3B)15-4(2C11-2B16-)2C11-2B14-2D2C11-2B2D11-4C13-4B2(10-3C15-3B)11-2C15-2B13-2C13-2B15-3C2AD3-D2A3B16-3CAD5-DA3B141-13D20(18-2C9A2B)17-3C9A3B15-4C9A4B14-4C4AD4A4B15-3C3AD-D3A3B17-2C2AD3-D2A2B195-
