model
size = 32 32 29, scale = 0.05, origin = -y
material 
  colors = A:#FFF B:#7DB9DE C:#A5DEE4 D:#EEE E:#7B90D2 F:#FCFAF2 G:#3A8FB7 H:#51A8DD I:#8B81C3 J:#6E75A4 K:#2EA9DF L:#4E4F97 M:#005CAF N:#DDD O:#9B90C2 P:#FFFFFB Q:#81C7D4 R:#77969A S:#1E88A8 T:#58B2DC U:#BDC0BA V:#261E47 W:#BBB X:#B28FCE Y:#FEDFE1 Z:#AAA Aa:#91989F Ab:#D7C4BB
voxels
269-A4-A60-2A61-A2-A795-A4-A27-A2-A26-A2-2A2-A25-A4-A25-A-A2-A-A25-A-2A-A27-4A28-A2-A28-4A29-2A154-C8-C56-C4-C24-A8-A20-2(A2-)2C2(2-A)19-C2-C4-C2-C21-A3-2C3-A23-C6-C25-C4-C314-2A2F2A26-7A24-8A22-6AF5A21-2AD4AD2A2(22-10A)23-3A2D3A24-C-4A-C19-C7-2A7-C15-A4-A-2CA3-A-A17-C3-C2(A-)CA2-C19-C4-2C4-C22-A3-A2-A22-5A2-AF3A18-F5A-A2-4AFA17-AF3A4-5A18-4AF4-5A18-9AF4A19-2AF7ADA20-2AD5AFD2A20-3AD2F6A21-F5AF3A25-C2-C219-A4DFA24-2A4D3A22-F8AFA21-AD7ADA20-2D3ABCB2A2D20-F3A2BA2B4A19-4AD3AD4A18-F13A17-14AF18-AF13A16-AF11A2(FA)14-3AF8AF5A14-F3AD2AD4A2D4A14-18A15-9AF5AD16-F3DAFD2A2DA2D2A16-AD12ADA16-9AD6A16-F5AD2AD5AF17-5AD2FD5A18-14A18-13AF18-14A19-F11A20-12A21-2F2A2D3AF26-2C156-2F4DF24-8A2D21-3A5C4A19-F8A2B2A17-A-6ACB2ABL2AF15-7ABCBABCJDFA15-4AGH2BA2B5A15-3F3ABD3AD5AF13-A3F2ACDAI8AF13-3AHSJB10AD2A12-2ADHAHCNAC4AEB2ADF11-8A3C10A11-10AC11A10-22A11-8AL11A12-20A13-17AFA12-19A13-20A13-2F16A14-16AFA15-17A14-F16AF14-17AF14-16AFA15-AF13AF17-F13A19-12A22-3(A-)F90-D3F2D25-9A22-AB3AC4A3D17-3AB7C3AFA15-3A3B5A3BA2D15-2AJ2B3ACB2ABL3A13-4A2EHEABCBABCJ4A12-3AEBHGH2BA2B5AFA11-2F4A2HBD3AD5AFDA10-4ATABCD2(AI)7AD2A9-3AQHSJB14A10-3AEHAHCNAC3ANEB5A9-7AKH3C2ACB7A9-8AKBA3C8AF9-23AF8-F9AL2AL10A8-24A8-2AD21A8-AF19AFA9-23A9-F2(21AF10-)F21A10-21AF10-22A10-20AF12-F18AF12-FA2F15A15-F14AF18-AF10A86-8DF21-2DCE2BC2B2CAF18-2ACBG2BC4ACG2D15-3ACB7CACGEF13-3AE4B5A3BAEA13-AFAHJ2B3ACB2ABL3AF11-5A2EHEABCBABCJ5A10-4AEBHGH2BA2B5AI2A9-7A2HBD3AD5AO3A8-5ATABCD2(AI)6AE2AF8-F3AQHSJB15A8-F3AEHAHCNAC3ANEB6A8-5AEAKH3C2ACB7AF8-D4AL2AKBA3C10A7-26A6-11AL2AL11A6-25AF6-26A7-24AF7-F23A2(8-22A2F)8-24A8-23A9-23A10-20A2(2F10-F19A)F13-18A16-F13A20-A-6A-A24-6D24-2D2A3KAD2F19-2D2CE2BC2B2CAD17-AEGCBG2BC4ACG2D13-2AMEGCB7CACGEA13-AIGE4B5A3BAEGA11-2ALAHJ2B3ACB2ABL3ALF10-5A2EHEABCBABCJ5A10-D3AEBHGH2BA2B5AIAF9-7A2HBD3AD5AO3A8-5ATABCD2IAI6AE3A8-4AQHSJB3I5AR5AD8-D3AEHAHCNIC3ANEB6A7-6AEAKH3C2ACB7AF7-F5AL2AKBA3C11A6-26A6-11AL2AL11A4(6-26A)6-25AF7-4(24A8-)23AF9-F21A10-F20AF12-17AF15-16A18-12A22-8D23-FBE5KBDF17-F3D2CE2BC2B2CAD15-2F2EGCBG2BC4ACG2D12-FAJMEGCB7CACGEMA11-2AIGE4B5A3BAEGAF10-DALAHJ2B3ACB2ABL3ALA9-6A2EHEABCBABCJ6A8-5AEBHGH2BA2B5AI3A8-D6A2HBD3AD5AO2AF7-6ATABCD2IAI6AE4A6-5AQHSJB3I5AR6AF6-5AEHMHCNIC3ANEB7A6-6AEMKH3C2ACB9A5-F6AL2MKBG3C11A5-8AG2M2K15A4-12A2LAL11AF4-28A4-F26AF4-28A5-27A5-26A6-F24AF6-25AF6-F25A6-25A2(8-24A)8-23A11-20A13-F17A16-F5A2F6A20-3DFDF2DFD21-ACBE5K2B2D16-3DG2CE2BC2B3CA-A13-2A2EGCBG2BC2BGBCGDEA11-2AJMEGCB7CBCGEMJA10-DAIGE4B5A3BAEG2A9-3ALAHJ2B3ACB2ABL3AL2A8-F5A2EHEABCBABCJ6A8-5AEBHGH2BA2B3AGAI2AD7-8A2HBD3AD2A2BAO4A6-6ATABCD2IAI3ABCAE4A6-5AQHSJB3I5ARC7A5-5AEHMHCNIC3ANEBC6A5-7AEMKH3C2ACB8AD5-F6AL2MKBG3C12A4-8AG2M2K15A4-10A2J2LAL12A5(4-28A)5-26A6-25AF3(6-26A)7-24A8-24A10-20A13-18A16-2(4AF)4A19-7DFDF2D18-2DACBE5K2BCD15-FDAEG2CE2BC2B3CGAF12-3A2EGCBG2BC2BGBCG2E2A10-2AJMEGCB7CBCGEMJF9-F2AIGE4B4C4BAEGO2A8-3ALAHJ4BAC4BL3ALAD7-7A2EHE2BC3BCJ7A6-6AEBHGH2BA2B3AGAI4A4-C9A2HBD3AD2A2BAO4A5-7ATABCD2IAI3ABCAE5A3-C6AQHSJB3I4AJRC7A4-6AEHMHCNIC3ANEBC8A2-8AEMKH3C2ACB10A3-8AL2MKBG3C12A3-9AG2M2K16A-C11A2J2LAL13A2-30AC-30A2-29AF2-30A3-28A3-C28AC2-29A4-28A5-26AF5-26A6-25AF7-24A8-F22AF10-AF16A2F14-16A18-3DF4DF3D18-FDACBE5K2BC2D14-D2FEG2CE2BC2B3CGADF11-3A2EGCBG2BC2BGBCG2E3A9-DAJMEGCB7CBCGEMJD9-F2AIGE4B4C4BAEGO2A7-4ALAHJ4BAC4B2(L3A)6-7A2EHE2BC3BCJ7AC5-D5AEBHGH2BA2B3AGAI4A5-9A2HBD3AD2A2BAO5A4-7ATABCD2IAI3ABCAE5AC3-6AQHSJB3I4AJRC7A3-7AEHMHCNIC3ANEBC6AF3-8AEMKH3C2ACB11A2-8AL2MKBG3C13A2-9AG2M2K16AC-11A2J2LAL12AF-31A-C30AC-2(30A2-)29AF3-28A4-28AC2-C2(28A4-)28A5-25AF6-F24AF7-F20A2FA10-18A2F13-17AF17-2D2FD4F3D18-2DACBE5K2BC2D14-2DAEG2CE2BC2B3CGADF11-F2A2EGCBG2BC2BGBCG2E2A9-2FAJMEGCB7CBCGEMJD9-D2AIGE4B4C4BAEGOAD7-4ALAHJ4BAC4BL3AL2AF5-C7A2EHE2BC3BCJ7A6-D5AEBHGH2BA2B3AGAI4AC4-9A2HBD3AD2A2BAO5A3-8ATABCD2IAI3ABCAE5A4-F5AQHSJB3I4AJRC7AC3-D5AEHMHCNIC3ANEBC7A2-C8AEMKH3C2ACB10A3-8AL2MKBG3C24AG2M2K16A2-11A2J2LAL13A2(2-30A)-C30AC-30A2-F2(29A3-)F27A4-28AC2-C28AC3-28A5-26A6-26A7-21A2FA9-F19AF13-5A2F11A17-D2F2D4F3D18-2DACBE5K2BC2D14-2DAEG2CE2BC2B3CGA2D10-4A2EGCBG2BC2BGBCG2EAD9-3AJMEGCB7CBCGEMJAF7-4AIGE4B4C4BAEGOAD6-5ALAHJ4B2C4B2(L3A)6-7A2EHE2BC3BCJ7A5-C6AEBHGH2BA2B3AGAI5A4-9A2HBD3AD2A2BAO5A4-D6ATABCD2IAI3ABCAE4AF4-D5AQHSJB3I4AJRC8A3-D5AEHMHCNIC3ANEBC7AC2-8AEMKH3C2ACB10AC-C8AL2MKBG3C13A2-9AG2M2K16A-12A2J2LAL14A-F29A2-31A-30A-C30AC-30A2-C28AC3-29A2-29A4-28A3-C28AC3-27AF5-26A6-26A8-F21A12-5A2F3AF7A16-5D5F4D16-4DC2B5K2BC3D12-4DEG2CE2BC2B3CG4D9-D2AX2EGCBG2BC2BGBCG2E2AD8-2APJMEGCB7CBCGEMJAD7-D2APIGE4B4C4BAEGO2AD5-D4ALAHJ4B2C4B2(L3A)D4-D4AW2A2EHE2BC3BCJ3AU3AD4-D4AUAEBHGH2BA2B3AGAIN3AD3-D9A2HBN3AD2A2BAOD4A3-D7ATABCD2IPI3ABCAEF4AD2-D6AQHSJB3I4AJRC7AD-CD6AEHMHCNIC3ANEBC7AD2CD2AP3AYEMKH3C2ACB10AD2CD6APL2MKBG3C5AF6AD2CD7ANG2M2K7ANP6AD2CD7ANWU2J2LAL2AZAaF7ADCQD8ADFD2NAbNU2N2D8ADQD9AP6AP13A3D28A2DCD28AD2CD28ADC-DF27AD2-CD27AC2-CDP26AC2-2DF25A2D2-3D25A2D3-CD25AC4-2D24A2D5-P2AP20APD7-5D13APF2DAD10-2D3A2F4AF6A2D15-6DF4DF2D16-4DC2B5K2BC3D12-4DEG2CE2BC2B3CG4D9-D2AX2EGCBG2BC2BGBCG2EAD9-2APJMEGCB7CBCGEMJAD7-D2APIGE4B4C4BAEGO2AD5-D4ALAHJ4B2C4B2(L3A)5-D4AW2A2EHE2BC3BCJ3AU3AD4-D4AUAEBHGH2BA2B3AGAIN3AD3-D9A2HBN3AD2A2BAOD4AD2-D7ATABCD2IPI3ABCAEF4AD2-D6AQHSJB3I4AJRC7AD-CD6AEHMHCNIC3ANEBC7AD2CD2AP3AYEMKH3C2ACB10AD2CD6APL2MKBG3C5AF6AD2CD7ANG2M2K7ANP6AD2CD7ANWU2J2LAL2AZAaF7ADCQD8ADFD2NAbNU2N2D8ADQD9AP6AP13A3D28A2DCD28AD2CD28ADC-DF27AD2-CD27AC2-CDP26AC2-2DF25A2D2-3D25A2D3-CD25AC4-2D24A2D5-P2AP20APD7-5D13APF2DAD10-2D3AF2AFA3F5A2D16-2DF7DFD18-2DACBE5K2BC2D14-2DAEG2CE2BC2B3CGA2D10-4A2EGCBG2BC2BGBCG2EAD9-3AJMEGCB7CBCGEMJ2A7-4AIGE4B4C4BAEGOAD6-5ALAHJ4B2C4B2(L3A)6-7A2EHE2BC3BCJ7A5-C6AEBHGH2BA2B3AGAI5A4-9A2HBD3AD2A2BAO5A4-D6ATABCD2IAI3ABCAE5A4-D5AQHSJB3I4AJRC8A3-D5AEHMHCNIC3ANEBC7AC2-8AEMKH3C2ACB10AC-C8AL2MKBG3C13A2-9AG2M2K16A-12A2J2LAL14A-30A2-F2(30A-)C30AC-30A2-C28AC3-29A2-29A4-28A3-C28AC3-28A5-26A6-26A8-22A12-5A3FA3F6A17-2(FD)6F2D18-D2FCBE5K2BCDF14-2DAEG2CE2BC2B3CGADF11-3A2EGCBG2BC2BGBCG2E2A9-F2AJMEGCB7CBCGEMJD9-D2AIGE4B4C4BAEGOAD7-4ALAHJ4B2C4BL3AL2AF5-C7A2EHE2BC3BCJ7A6-D5AEBHGH2BA2B3AGAI4AC4-9A2HBD3AD2A2BAO5A3-8ATABCD2IAI3ABCAE4AF4-6AQHSJB3I4AJRC7AC3-D5AEHMHCNIC3ANEBC7A2-C8AEMKH3C2ACB10A3-8AL2MKBG3C24AG2M2K16A2-11A2J2LAL13A2(2-30A)-C30AC-30A2-30A3-29A3-F27A4-28AC2-C28AC3-28A5-F25A6-25AF7-24A9-21A13-5A5F8A17-DF7D2FD18-2DACBE5K2BC2D14-2FAEG2CE2BC2B3CGA2D11-3A2EGCBG2BC2BGBCG2E3A9-DAJMEGCB7CBCGEMJD9-3AIGE4B4C4BCEGO2A7-4ALEHJ4B2C4BL3EL3A6-5A4EHE2BC3BCJ2BE4AC5-5A2EBHGH2BA2B3AGBI4A5-6AEBC2HBD3AD2A2BEO5A4-6AETCBCD2IAI3ABCJE5AC3-6AQHSJB3I4AJRCJ6A3-7AEHMHCNIC3ANEBCE6A3-8AEMKH3C2ACBKH2E7A2-8AL2MKBG3CG2HGL8A2-F8AG2M2K3HB2EJ9AC-11A2J4L2J10AF-31A-C30AC-2(30A2-)29AF3-28A4-28AC2-C2(28A4-)28A5-26A6-F24AF7-24A10-20A13-4A6F2AF5A17-4DF4D2FD18-2DACBE5K2BCD15-AFAEG2CE2BC2B3CG2D12-3A2EGCBG2BC2BGBCG2E2A10-2AJMEGCB7CBCGEMJA9-F2AIGE4B4C4BCEGO2A8-3ALEHJ4B2C4BL3EL2A7-5A4EHE2BC3BCJ2BE4A6-5A2EBHGH2BA2B3AGBI4A4-C6AEBC2HBD3AD2A2BEO4A5-6AETCBCD2IAI3ABCJE5A3-C6AQHSJB3I4AJRCJ6A4-6AEHMHCNIC3ANEBCE7A3-D6AEMKH3C2ACBKH2E6A3-8AL2MKBG3CG2HGL7A3-9AG2M2K3HB2EJ9A-C11A2J4L2J11A2-30AC-30A2(2-29AF)3-28A3-C28AC2-29A4-28A5-27A5-26A6-F25A7-24A8-24A10-20A14-3AF2A3FAF5A19-3D2M2V3D21-DCBE5K2BGD16-2DVG2CE2BC2B3CG-D13-2A2EGCBG2BC2BGBCGVED11-2AJMEGCB7CBCGEMJD10-DAIGE4B4C4BCEGOA9-3ALEHJ4B2C4BL3ELAF8-4A4EHE2BC3BCJ2BE3A8-D3A2EBHGH2BA2B3AGBI2AF7-5AEBC2HBD3AD2A2BEO2A2F6-5AETCBCD2IAI3ABCJE4A6-5AQHSJB3I4AJRCJ6A5-5AEHMHCNIC3ANEBCE5A5-7AEMKH3C2ACBKH2E5A5-7AL2MKBG3CG2HGL7A4-8AG2M2K3HB2EJ7AF4-10A2J4L2J10A5(4-28A)5-3(26A6-)25A7-25A8-23AF8-24A10-20A13-18A16-5A6F3A21-DJO3GJD23-MBE5KBMG17-2DJG2CE2BC2B3CG15-2D2EGCBG2BC2BGBCGLE12-2AJMEGCB7CBCGEMJ11-2AIGE4B4C4BCEGOD10-2ALEHJ4B2C4BL3ELA9-F3A4EHE2BC3BCJ2BE3A8-4A2EBHGH2BA2B3AGBI3A8-D3AEBC2HBD3AD2A2BEO2AF7-5AETCBCD2IAI3ABCJE2AFA6-5AQHSJB3I4AJRCJ5A6-5AEHMHCNIC3ANEBCE5A6-F5AEMKH3C2ACBKH2E4AF6-D5AL2MKBG3CG2HGL5AF5-8AG2M2K3HB2EJ8A4-10A2J4L2J10A4-27AF2(4-28A)5-27A5-3(26A6-)25A7-F24A8-23AF8-24A8-23A11-20A13-18A16-14A24-3O25-CBEL3KLGBC19-EM2CE2BC2B3CM17-2EGCBG2BC2BGBCGEJ13-AVMEGCB7CBCGEM13-AIGE4B4C4BCEGV11-2ALEHJ4B2C4BL3ELF10-3A4EHE2BC3BCJ2BE2A10-3A2EBHGH2BA2B3AGBI2A9-4AEBC2HBD3AD2A2BEO2AF8-4AETCBCD2IAI3ABCJE2AF8-F3AQHSJB3I4AJRCJ4A8-4AEHMHCNIC3ANEBCE4A7-6AEMKH3C2ACBKH2E4A7-6AL2MKBG3CG2HGL6A6-7AG2M2K3HB2EJ7A6-9A2J4L2J9A6-25AF6-F24AF6-F25A2(6-26A)7-24A8-F22AF2(8-24A)8-23AF9-22A10-22A12-18A15-16A18-12A54-BEK3GK2B21-G2CE2BC2B3CG18-EGCBG2BC2BGBCGJE15-MEGCB7CBCGEM13-AIGE4B4C4BCEG12-FALEHJ4B2C4BL3EL11-3A4EHE2BC3BCJ2BE2A10-3A2EBHGH2BA2B3AGBI2A9-4AEBC2HBD3AD2A2BEO2A9-4AETCBCD2IAI3ABCJE2AF8-4AQHSJB3I4AJRCJ3AF8-F3AEHMHCNIC3ANEBCE3AF7-6AEMKH3C2ACBKH2E3AF7-F5AL2MKBG3CG2HGL5A7-7AG2M2K3HB2EJ7A6-9A2J4L2J9A6-26A6-F2(25A7-)24A8-22A2F8-24A8-2(23A9-)23A10-22A10-F21A11-20A13-18A15-16A21-A3F2A60-3K26-CD2BC2BDC22-CBG2BC2BGBCG2E18-CB7CBCGE16-GE4B4C4BCEG15-EHJ4B2C4BL3E13-AD4EHE2BC3BCJ2BED12-FD2EBHGH2BA2B3CGBID11-3AEBC2HBD3AD2C2BEODA10-3AETCBCD2IA2I2CBCJEDF10-3AQHSJB3IA3IJRCJADA10-F2AEHMHCNI3CINEBCE3A9-5AEMKH6CBKH2E3A9-5AL2MKBG3CG2HGL5A8-6AG2M2K3HB2EJ6A8-8A2J4L2J7AF8-24A8-F23A8-23A9-F22A9-22AF10-22A10-AF20A10-F21A10-21A12-20A12-AF18A13-AF16A15-16A17-14A149-BG2BC2BGB23-B7CB21-4B4C4BC17-E-J4B2C4BL3E15-L3EHE2BC3BCJ2BE15-EMBHGH2BA2B3CGB15-AEBC2HBD3AD2C2BE14-ADETCBCD2IA2I2CBCJ14-ADQHSJB3IA3IJRCJD13-FD2(MH)CNI3CINEBCEDA11-2ADAEMKH6CBKH2E2A11-4AL2MKBG3CGHMGL4A10-5AG2M2KMHMB2MJ5A11-6A2J4L2J6A12-F17AFA12-18A2F2(12-20A)13-2(18A14-)F17A14-17AF15-17A15-F2(15A17-)F12AF19-12A21-A5-A2-A155-C29-HCDCH24-BRB4C2BRB21-BL2B2C4BL20-AEHE2BC3BCJ20-BHGH2BA2B3CG20-DHBD3AD2CDB20-BCD2IA2I2CBC18-HSRB3IA3IJRC18-H-HCAI3CIAEBC17-A4-B5CB4-A14-2A6-CAC5-DA14-3A12-2AF14-3A2D2(2-D)2-2D3A15-11AD4A3(16-16A)16-F15A17-2(14A18-)13AF18-F13A19-12A20-4AF6AF21-F5AF3A24-F-A2-A251-A3CA26-2BHDH2B26-2BC2B26-H2BA2B2CA23-BD3ADHC23-CDICACIDC24-3IA3I26-I3CI28-CAC22-A31-2A12-DA17-2A2(D-)D2(A-)2D2A17-F5AD3A2(DA)18-3AF2(3AD)2A18-2AD2AFD3A2D2A18-2AD3AF2AF3AF18-3AD2AF7A19-AD7AD2A20-11AF20-12A21-3A2(F2A)F23-4(A-)A410-BDB28-2BA2B27-DAHAD27-MCACM28-BAB30-D121-A5-A4-A21-A2-A-A2-2A21-A2-3A3-A-A20-2(A2-)A-A2-A20-A-A3-A2-A-A21-A-2(A2-)A25-A-A2-A24-A-2(A2-)A27-A240-
