model
size = 19 32 19, scale = 0.05, origin = -y
material 
  colors = A:#EEE B:#BBB C:#DDD D:#D00 E:#800 F:#C30 G:#AAA H:#888 I:#777 J:#555 K:#444
voxels
39-27(14A5-)14A62-14A4-27(16A3-)16A4-14A25-12C6-12A2C4-5(13A3C3-)4(13A2CA3-)18(16A3-)16A4-14A6-12A7-C10GB6-12A2B4-4(13A3B3-)13A2BC3(3-13A2BA)20(3-16A)4-14A6-12A7-CG8HGB6-12A2B4-13A3B3-2(13A3BEDF)13A3B3-13A2BC3(3-13A2BA)20(3-16A)4-14A6-12A7-CGH6IHGB6-12A2B4-13A3B3-2(13A3BEDF)13A3B3-13A2BC3(3-13A2BA)20(3-16A)4-14A6-12A7-CGHI4JIHGB6-12A2B4-4(13A3B3-)4(13A2BC3-)15AC19(3-16A)4-14A6-12A7-CGHIJ2KJIHGB6-12A2B4-8(13A3B3-)13A2BC7(3-13A2BA)12(3-16A)4-14A6-12A7-CGHIJ2KJIHGB6-12A2B4-13A3B3-2(13A3BEDF)2(13A3B3-)2(13A3BEDF)13A3B3-13A2BC7(3-13A2BA)12(3-16A)4-14A6-12A7-CGHI4JIHGB6-12A2B4-13A3B3-2(13A3BEDF)2(13A3B3-)2(13A3BEDF)13A3B3-13A2BC7(3-13A2BA)12(3-16A)4-14A6-12A7-CGH6IHGB6-12A2B4-8(13A3B3-)8(13A2BC3-)15AC4(3-16A)3-10A5CA6(3-16A)4-14A6-12A7-CG8HGB6-12A2B4-16(13A3B3-)13A2BC3-13AB2A3(3-13A2BA)3-10A5CA3-13A2BA3-13ABCA4(3-16A)4-14A6-12A7-C10GB6-12A2B4-13A3B3-3(2(13A3BEDF)2(13A3B3-))2(13A3BEDF)13A3B3-13A2BC3-13AB2A3(3-13A2BA)3-10A5CA3-13A2BA3-13ABCA4(3-16A)4-14A6-12A7-C11B6-AC12B4-2AC4B3A6B3-2(2AC4B3A6BEDF)2(2AC4B3A6B3-)2(2AC4B3A6BEDF)2AC4B3A6B3-2AC7A6B3-2(10A6BEDF)2(10A6B3-)2(10A6BEDF)10A6B3-10A5BC3-10A4B2A3(3-10A5BA)3-10A5CA3-10A5BA3-10A4BCA4(3-16A)4-14A6-12A25-AC12B4-2AC4B3A6B3-2(2AC4B3A6BED-)2(2AC4B3A6B3-)2(2AC4B3A6BED-)2AC4B3A6B3-2AC7A6B3-2(10A6BED-)2(10A6B3-)2(10A6BED-)10A6B3-10A4B2C3-10A4B2A3(3-10A4BCA)3-10A5CA6(3-16A)4-14A62-4(AC12B5-)A5C3(8B5-5AC)8B5-5A5C7(4B5-9AC)4B5-9A5C11(5-14A)103-2(2E2-)3E8-2(2E2-)3E50-2E2-3E12-2E2-2(3E54-3E16-)3E350-2(2D2-)3D8-2(2D2-)3D50-2D2-3D12-2D2-2(3D54-3D16-)3D350-2(2F2-)2F9-2(2F2-)2F51-2F2-2F13-2F2-2(2F55-2F17-)2F290-
