model
size = 3 23 32, scale = 0.05, origin = -y
material 
  colors = A:#111 B:#950000 C:#8A0000 D:#141414 E:#AB0000
voxels
4-2(C2-)2(E2-)2(B2-)2(E2-)E95-A2-A59-A2-D-6A-A53-A-12ADAD-A50-A-3A9-6A-A47-A-DAD9-3ADAD-A47-A-3A9-6A-A47-A-3A4D2(AD)4ADAD-D50-A-9ADA2DAD-D53-A-6ADA2DAD-A53-D-3ADA2DAD3A-A50-A-6ADAD6A-A50-A-3ADAD9A-D53-A-2(3ADAD)-D53-A-DAD3ADA2DAD-A50-A-DAD3ADAD6A-A50-D-15A-A53-A-6ADAD-A53-A-3ADA2DAD3A-A50-A-3ADA2DAD6A-A50-A-12A-A50-D-3ADAD9A-A47-A-12ADAD-A47-C-9C9A-A44-C-3CEC2ECE6C6A-A41-B-B2(C2B)CBEC2ECE3C3A-A41-B-ECEB3(C2B)CBECE3C-A41-B-B4(C2B)CBEC2ECE-C41-B-B6(C2B)CB-E38-E2-E-B5(C2B)CB3C-E35-B2-B-B4(C2B)CBECEBCB-B2-C32-C2-B-B2(C2B)CB3CBC2BCB-2(B2-)E34-
