model
size = 32 29 20, scale = 0.05, origin = -y
material 
  colors = A:#444 B:#555 C:#111
voxels
361-2C2-C4-C2-2C18-2C2-6C2-2C18-2A-3A2C3A-AB17-5ABA2CB6A15-6A2B2CB6AB14-B2A-4A2C2B2A-3A13-A2B2-4A2C2ABA2-3A12-3A3-3A2C3A3-3A13-AB4-2A2C2A4-AB21-A2CA477-2C29-4C28-4C26-2A4C2A2(24-8C)25-2(A4CA26-)A4CA27-4C442-4(2A4C2A24-)BA4C2B23-3A4C2BA22-B2(2AC)ABA21-AB7AB2A20-B4A2-2AB2A20-4A4-3AB20-3C6-3C20-4C4-4C2(20-B3A4-4A)20-B4A2-5A21-9AB23-2A4C2A25-A4CA27-4C343-2B11AB18-A2B-6A-2AB19-3A6-A2B3(20-3A6-3A)19-B2A8-2AB18-B2A8-3A18-BA10-AB18-3A8-2AB18-CAC8-CAC18-CA10-AC2(18-BA10-2A)18-B2A8-3A18-AB2A6-4A19-B4A2-5A21-10A23-B7A25-A4CA310-A3-6A3-A18-5A4-4AB18-2A10-2A18-BA10-2A18-2A10-2A17-ABA10-3A2(16-BA12-2A)16-B2A10-2AB16-BA12-2A2(16-CA12-AC)2(16-BA12-2A)16-BA12-AB2(16-3A10-3A)17-4A6-2A2B18-B4A4-5A19-3A-4A-3A22-2A4C2A26-4C250-3A2-3A20-6A4-6A3(16-2A12-2A)15-A-A12-A-A2(14-2A)15-B14-A15-BA3(14-2A)2(14-CA14-AC)2(14-BA14-2A)14-BA14-AB14-BA14-2A12-4A14-4A10-2AB2A12-5A2(10-6A)11-3AB2A-6A-2A2B2A16-3A6-2AB22-2A4C2A246-4A4-4A17-5A8-5A8(14-2A)14-BA3(14-2A)14-A16-A13-2A16-2A2(12-CA16-AC)2(12-2A16-2A)12-BA16-AB9-A3BA16-5A2(6-2A2-A16-A2-2A)7-A3-A14-A3-A8-2A2-4A-6A-4A2-AB8-9A6-7A2B9-ABA-2AB8-B2A-2BA10-A5-3A4C2AB5-A206-4A6-4A16-AB2A10-3AB14-B16-A14-A16-B14-A16-A13-2A2(16-AB12-BA)16-AB2(12-2A16-2A)2(12-C18-C)11-2(2A18-AB10-)BA18-AB7-B2A-A18-A-3A2(4-A3-A18-A3-A)5-B2-3A14-3A2-A6-A3-3A12-3A3-B7-A3-16A3-A8-A3-A-2A8-2A-A3-A8-A-2A-AB2A2-2C2-AB2A-BA-A8-2A7-AC2-CA7-AB17-AC2-CA148-AB3A8-4AB13-A-2A12-2A-A13-A16-A14-A16-A13-2(2A16-2A12-)2A16-A2(B12-B18-)A12-A18-A11-2(2C18-2C10-)2A18-AB10-2A18-AB6-A2(B-)A18-A-B-2B2-2(A-)A20-2(A-)A2-A3-A20-A3-2(A2-)2A20-2A2-A3-A2-3A16-3A2-A4-A3-3A14-3A3-A5-A3-2A2-3A4-3A2-2A3-A6-A4-2A-A2-4A2-A-2A4-A7-B3-3A3-A2-A3-A2B3-B8-3AB2-2B2A4-2A2B2-4A8-A7-BA4-AB7-A8-A22-A106-4A12-3AB3(12-2A16-2A)12-A18-B12-B18-A12-A18-B12-A18-A12-B18-A11-2A18-2A10-2C18-2C10-C20-C10-A20-B9-BA20-AB5-2B-BA20-2A-AB2(-A)-2A20-2A-A-2B2-3A20-3A2-2A2-A24-A2-A-A2-3A18-3A2(2-A)3-2A18-2A2(3-A)3-2A16-2A3-A5-A3-A2-4A4-4A2-A3-A6-B4-2A3-2A2-2A3-2A4-A7-3A2B3A-A4-A-A3BAB2A8-A7-2A4-2A7-A8-A7-B6-B7-A8-A22-B74-3A14-3A12-BA16-2A2(12-A18-A)3(12-A18-B)12-A18-A11-2(2A18-2A10-)C20-C10-C20-C9-2A2(20-AB8-BA)20-2A4-BA-3A20-3A-A2B-A26-A-AB-A26-A-BA2-A24-A2-BA3-A22-A3-A-B3-A20-3(A3-)3A-2A8-2A-3A3-A5-B3-4A-A6-A-4A3-A7-2A2-BA3-A4-A3-2A2-2A7-2A-AB-A2B-B4-B-3B-2B-2A6-2A7-B6-2(B7-A)7-A6-A7-B74-2(BA16-2A12-)A18-A3(12-A18-B)12-B18-B12-B18-A11-2(2A18-2A10-)C20-C9-2C20-2C8-2A20-AB7-B2A20-2AB3-A3B2A20-3A4B2(2A26-2A2B)A28-ABA-2A24-2A-BA2-2A22-2A2-2A3-2A20-2A3-A-B3-3A16-3A2(3-A)3-7A6-7A3-A5-B4-2A2-A6-A2-2A4-A6-A-2A4B-A6-A-3B3A-B6-4A4-2A6-AB4-3AB5-2B2A6-A6-B6-2ABA4-B-A7-A6-B7-A-A40-BA16-2A12-B-A14-A-B12-BA16-2A2(12-2A16-AB)12-2A16-2A12-2A16-AB12-B18-A12-A18-A11-2A18-2A10-C20-C9-2C20-2C8-2A20-2A7-B2A20-2AB6-BA22-2A5-B2A22-3A3-B3A22-3AB-B2A26-2AB3A26-2ABA-A26-A-BA2-A24-A2-A-B2-A22-A2-A3-2(A2-)3A10-3A2(2-A)5-A2-2A3-A8-A3-2A2-A6-A-2A3B2-A6-A2-B4A-B5-5A3-2B-A4-B-AB3-B3AB4-AB2A6-2A4-2A6-2(BA)3-BA-A7-2A4-2A7-A-2A2-A28-A8-3(2A14-)AB14-BA14-AB14-2A14-A2(B14-A16-)A13-2A16-AB12-BA16-AB12-2A16-2A11-2A18-2A10-CA18-AC10-C20-C9-2A20-2A7-BA22-2A6-BA22-AB6-B2A20-3A4-B4A20-4AB-BA-3A20-3A-A2B3-A22-A3-B2A2-2A20-2A2-ABA-2A-4A14-4A-2A2(-A)2-A2-3A12-3A2(2-A)3-A2-A-2A-A10-A-2A-A2-A5-A2-2A3-A8-A3-2A2-A6-A-4A3-2A4-2A3-4A-B5-8ABA-A4-A-9AB4-2(AB)6-A-C2-C-A6-2ABA3-2A-A7-A-C2-C-A7-A-2A2-B11-AC2-CA11-A8-4A10-4A15-3A10-2AB16-2A12-AB15-B-A12-A-B14-BA14-AB14-BA2(14-2A)14-AB14-2A14-AB13-2A16-2A12-2A16-2A11-CA18-AC10-CA18-AC9-3A18-3A7-2(BA22-2A6-)B2A20-3A4-5A20-4AB-B2-3A20-3A2-2B2-3A3-A12-A3-3A2-B6A3-2A10-2A3-7A2-5A3-2A6-2A3-5A2-A-A2-6A12-6A2-2(A3-)3A-A10-A-3A3-A5-2(A3-)2A6-2A2(3-A)6-A-2A2BA3-AC2-CA3-B4A-B6-4A3-2A2-4C2-2A3-4A5-4A6-BA-2C-2A6-4A4-A-A8-2A2C2B8-A-A15-2A2C2A21-5A2-2A2-5A17-A-4A2-4A-B18-B2A8-2AB17-2BA10-A2B16-3A10-2AB16-BA12-2A16-A14-B15-2A14-AB2(14-2A)13-2A16-2A12-CA16-AC11-CA18-AC9-A-A18-A-A8-BA20-AB7-BA22-2A6-B2A20-2AB4-5A20-3A2B-A2-3A3-A12-A3-3A2-B3A-2A2-3A10-3A2-2A-4A2-3A3-4A6-4A3-3A2-2B3-3A-2A-3AB2-4A-2A-3A3-A-A3-4A-4A4-4A-4A2(3-A)4-A3-2A6-2A3-A4-A5-A9-A4CA9-A6-A-2A2B2A4-2C4-B3ABA-B6-2A6-4A2-3AB6-AB7-B9-A2CA9-A19-2C57-12A20-5A2C5A20-4AB2C5B20-5A2C5A19-2A2B6A4B17-2B3A6-2AB2A16-3A10-2AB2(16-2A12-2A)15-3A12-3A14-CA14-AC13-C2A14-2AC11-A-A16-A-A10-3A16-3A9-B22-A8-BA20-2A4-6A20-5AB6A4-A10-A4-5ABA2-4A3-A-A6-A-A3-4A2-2B3-3A2-5AB2-6A2-3A3-B-A3-10A2-10A2(3-A)2(4-2A3-2A)4-B5-A9-A4CA9-A7-2A-B3A10-4A-AB8-A-A3-4AB2-5A3-A-B8-B10-2C10-A114-A2CA123-2B2C2A24-4A2CA3B20-6A2C4ABA15-2A-14A-AB9-4A2-2A10-2A2-4A5-4A2-3A10-3A2-4A4-3C2-C-A12-A-C2-3C4-3C2-CA14-AC2-3C4-2A2-A-A14-A-A2-AB3-B2(A2-)A14-2(A2-)A2(B2-)B3A16-4A2-B-2A2-2A20-2A2-2BA-4A20-4A-BA3-2A20-2A3-2B4-2A2(4-A-A)4-2A4-B-AB3-2A2(2-5A)2-2(2A3-)B4-8A2C8A4-A5-B4-A-A3-4A3-A-A4-B7-B3-2BA10-3A3-A8-A-2A3-4A2CA2BA3-AB-2(B8-A)2CA8-AB8-B22-A330-BA2-5B2CBA2BA2-2B9-2A2B2A-5A2CB3AB-4ABA6-3AB2A-12A-5AB5-5C2-4A6-4A2-5C4-5C2-2AB8-3A2-5C4-3BA3-AB10-2A3-3AB3-2A2B4-B12-A4-4A2-3A4-2A12-2A4-2AB-5A-3A14-3A-AB5A2-6A12-6A2-2B-AB3-4A12-4A3-2A2-2BA3-3A12-3A3-3A4-BA2-5A-2A2C2A-5A2-2A6-B2A2-3A-8A-3A2-A2B7-BA2B-6A2-6A-4A9-3B3-A3B2CB3A3-2BA9-2A20-2B9-A20-B397-A2-2A6-2B2-A15-3A-4A2C4A-3A14-2C-A2CA4CA2CA-2C13-3C2-2CB5A2C2-3C11-3AB2-3B4-3A2-2ABA10-ABA2-2A2B4-4A2-3A9-B2A3-2A8-2A3-3A7-2ABA2-AB2A6-4A2-4A5-3AB3-4A6-4A3-4A5-3A3-A2B2A4-5A3-3A7-3A2-4B2A2-3A2BA2-3A9-B5A3B5AB5A2B11-BA3-4A2C4A3-2A21-2C239-
