model
size = 31 27 31, scale = 0.05, origin = -y
material 
  colors = A:#4A225D
voxels
12-2(7A24-)7A765-2(13A18-)13A21-2(7A24-)7A670-2(17A14-)17A16-2(13A18-)13A21-2(7A24-)7A576-2(19A12-)19A13-2(17A14-)17A16-2(13A18-)13A21-2(7A24-)7A482-2(21A10-)21A11-2(19A12-)19A14-2(15A16-)15A18-2(11A20-)11A22-2(7A24-)7A388-2(23A8-)23A9-2(21A10-)21A11-2(19A12-)19A14-2(15A16-)15A18-2(11A20-)11A22-2(7A24-)7A294-2(25A6-)25A7-2(23A8-)23A9-2(21A10-)21A12-2(17A14-)17A15-2(15A16-)15A18-2(11A20-)11A22-2(7A24-)7A200-2(27A4-)27A5-2(25A6-)25A8-2(21A10-)21A11-2(19A12-)19A13-2(17A14-)17A16-2(13A18-)13A19-2(11A20-)11A23-2(5A26-)5A108-2(27A4-)27A5-2(25A6-)25A7-2(23A8-)23A9-2(21A10-)21A11-2(19A12-)19A14-2(15A16-)15A17-2(13A18-)13A20-2(9A22-)9A24-2(5A26-)5A14-2(29A2-)29A3-2(27A4-)27A5-2(25A6-)25A8-2(21A10-)21A11-2(19A12-)19A13-2(17A14-)17A15-2(15A16-)15A17-2(13A18-)13A20-2(9A22-)9A12-2(29A2-)29A3-2(27A4-)27A5-2(25A6-)25A7-2(23A8-)23A9-2(21A10-)21A11-2(19A12-)19A13-2(17A14-)17A16-2(13A18-)13A19-2(11A20-)11A11-2(29A2-)29A3-2(27A4-)27A5-2(25A6-)25A7-2(23A8-)23A9-2(21A10-)21A11-2(19A12-)19A13-2(17A14-)17A15-2(15A16-)15A17-2(13A18-)13A9-93A-2(29A2-)29A3-2(27A4-)27A5-2(25A6-)25A7-2(23A8-)23A9-2(21A10-)21A11-2(19A12-)19A14-2(15A16-)15A17-2(13A18-)13A9-5(93A-2(29A2-)29A3-2(27A4-)27A5-2(25A6-)25A7-2(23A8-)23A9-2(21A10-)21A11-2(19A12-)19A13-2(17A14-)17A15-2(15A16-)15A8-)93A-2(29A2-)29A3-2(27A4-)27A5-2(25A6-)25A7-2(23A8-)23A9-2(21A10-)21A11-2(19A12-)19A14-2(15A16-)15A17-2(13A18-)13A10-2(29A2-)29A3-2(27A4-)27A5-2(25A6-)25A7-2(23A8-)23A9-2(21A10-)21A11-2(19A12-)19A13-2(17A14-)17A15-2(15A16-)15A17-2(13A18-)13A10-2(29A2-)29A3-2(27A4-)27A5-2(25A6-)25A7-2(23A8-)23A9-2(21A10-)21A11-2(19A12-)19A13-2(17A14-)17A16-2(13A18-)13A19-2(11A20-)11A11-2(29A2-)29A3-2(27A4-)27A5-2(25A6-)25A8-2(21A10-)21A11-2(19A12-)19A13-2(17A14-)17A15-2(15A16-)15A17-2(13A18-)13A20-2(9A22-)9A13-2(27A4-)27A5-2(25A6-)25A7-2(23A8-)23A9-2(21A10-)21A11-2(19A12-)19A14-2(15A16-)15A17-2(13A18-)13A20-2(9A22-)9A24-2(5A26-)5A15-2(27A4-)27A5-2(25A6-)25A8-2(21A10-)21A11-2(19A12-)19A13-2(17A14-)17A16-2(13A18-)13A19-2(11A20-)11A23-2(5A26-)5A109-2(25A6-)25A7-2(23A8-)23A9-2(21A10-)21A12-2(17A14-)17A15-2(15A16-)15A18-2(11A20-)11A22-2(7A24-)7A202-2(23A8-)23A9-2(21A10-)21A11-2(19A12-)19A14-2(15A16-)15A18-2(11A20-)11A22-2(7A24-)7A296-2(21A10-)21A11-2(19A12-)19A14-2(15A16-)15A18-2(11A20-)11A22-2(7A24-)7A390-2(19A12-)19A13-2(17A14-)17A16-2(13A18-)13A21-2(7A24-)7A484-2(17A14-)17A16-2(13A18-)13A21-2(7A24-)7A579-2(13A18-)13A21-2(7A24-)7A675-2(7A24-)7A756-
