model
size = 29 32 21, scale = 0.05, origin = -y
material 
  colors = A:#090909
voxels
180-A15-A12-A15-A11-5(3A13-3A10-)2(4A11-)2(3A11-3A12-)4A9-4A13-4A7-4A15-13A17-11A20-2(7A22-)7A21-9A19-11A18-11A19-9A20-9A22-5A25-A107-2A15-2A10-2A15-2A9-3A15-3A2(8-4A13-4A)2(8-5A11-5A)7-4(6A11-6A6-)2(7A9-7A6-)2(8A7-)8A5-8A8-10A-10A8-21A9-2(19A10-)19A11-2(17A12-)17A13-15A14-15A15-13A17-11A18-11A20-7A73-4A13-4A8-4A13-4A7-2(6A11-6A6-)7A9-7A6-7A9-7A5-4(8A9-8A4-)3(9A7-9A4-)9A7-9A5-8A-5A-8A2(6-23A)7-2(21A8-)21A9-19A10-19A11-18A11-17A12-17A13-3(15A14-)15A15-13A18-9A42-8A7-7A2(7-8A)6-8A7-8A5-2(9A7-9A4-)2(10A5-10A4-)10A5-10A3-3(11A5-11A2-)2(12A3-12A2-)2(12A3-)2(25A4-)25A5-2(23A6-)23A7-2(21A8-)21A9-19A10-19A11-17A12-17A13-2(15A14-)15A15-13A18-9A12-5(3A2(5-2A)6-2A4-)3A2(5-2A)6-2A3-2(4A2(5-2A)6-3A2-)5(4A5-3A3-3A6-3A2-)4A5-9A6-3A2-4A5-9A6-3A3-3A5-9A6-2A2(4-3A5-9A5-3A)5-2A19-2A6-3A18-2A6-3A17-3A7-2A17-2A2(8-2A16-3A)9-2A14-3A10-3A13-3A11-4A10-3A12-2A-2A7-2A-2A12-5A7-5A13-4A7-4A14-4A7-4A16-2A7-2A10-6(3A7-2A3-2A8-2A2-)3A7-2A3-2A8-2A-4A4(7-2A3-2A8-7A)7-7A8-3A-3(3A7-7A8-2A2-)3A7-7A8-2A3-2(2A7-7A8-A4-)2A21-2A4-4A19-2A5-3A18-2A6-3A18-2A7-2(2A17-2A8-)2A17-2A9-2A15-2A10-4A13-2A10-5A9-5A11-4A9-4A12-4A9-4A13-3A9-3A15-2(2A9-)2A8-2A3-2A9-A2-2A8-2A3-2A9-A-3A8(8-2A3-2A9-5A)3(8-7A9-5A)8-7A9-2A-2A8-7A9-3(A2-3A23-)A2-3A22-2A3-2A22-A4-3A20-2A5-2(3A18-2A6-)3A18-2A7-2A17-2A8-3A16-2A9-3A15-2A9-4A11-4A10-4A11-3A12-3A11-3A13-2A11-2A14-2A11-2A7-2A9-2A3-2A9-4A6(9-2A3-2A10-3A)2(9-3A2-2A10-3A)3(9-7A10-3A)9-7A9-4A9-2A3-2A9-4A10-A3-A9-5A24-6A23-3A-2(3A21-3A2-)3A21-3A3-3A20-2A4-4A19-2A4-4A18-3A5-3A18-2A6-3A18-2A7-3A16-3A7-4A15-2A9-3A13-3A10-3A13-3A11-2(2A13-)A13-A14-A13-A7-2A7(9-2A3-2A10-3A)2(9-7A10-3A)2(9-A-5A10-3A)9-7A10-3A9-A-5A10-3A10-A3-A10-4A10-A3-A9-5A24-6A23-3A-2A23-2A2-3A22-2A2-3A21-3A3-3A20-2A4-4A19-2A4-4A18-3A5-3A18-2A6-3A18-2A7-3A16-3A7-4A15-2A9-3A13-3A10-3A13-3A11-2(2A13-)A13-A14-A13-A7-2A7(9-2A3-2A10-3A)9-7A10-3A9-3A-3A3(10-3A9-7A)9-4A9-7A10-3A10-A3-A10-4A10-A3-A10-2A-A24-2(2A2-2A23-)2A2-3A21-3A3-2A21-2A4-3A20-2A4-4A19-2A5-2(3A18-2A6-)3A18-2A7-2A17-2A8-2A17-2A9-4A2(11-A-2A11-3A)11-A-A13-2A11-2A14-2A11-2A7-3A7(8-2A3-2A10-4A)4(8-7A10-4A)8-7A9-5A8-7A9-2A-2A9-A3-A10-A2-2A9-A3-A9-2A3(2-3A21-3A)3-2(2A21-2A4-)3A20-2A5-3A19-A2(6-3A18-2A)7-2A18-A8-2A17-2A9-4A13-2A10-5A9-5A11-4A9-4A12-4A9-4A13-3A9-3A15-2(2A9-)5A5-2A3-2A9-A-6A6(5-2A3-2A9-8A)3(5-7A9-8A)5-2A-4A9-2A-2(5A5-7A9-A2-)2(5A6-A3-A10-A2-)5A21-A2-5A21-A3-4A20-A4-2A-A19-2A4-4A19-2A5-3A19-A2(6-3A18-2A)7-2A18-2A7-2A17-2A9-A16-2A10-5A10-4A11-4A9-4A13-2(3A9-3A14-)3A9-3A16-A9-A11-2A7-2A3-2A8-A3-5(5A5-2A3-2A8-2A2-)5A5-2A4-A2(8-2A2-5A5-7A)8-2A2-5A5-2A-4A8-2A2-5A5-7A7-3A2-5A5-2A-4A7-3A2-5A5-7A7-2(3A2-5A6-A3-A8-)3A3-4A2(19-2A4-2A-A)19-2A4-4A19-2A5-2(3A19-A6-)3A18-2A6-3A18-2A7-3A16-2A9-2A16-A10-2A15-2A11-4A10-3A13-4A7-4A14-4A7-4A15-3A7-3A16-3A7-3A17-2A7-2A12-10A6(3-2A7-2A4-11A)4-A4(7-2A4-16A)7-2A4-15A-9A4(4-25A)4-2A-22A4-25A5-3(23A6-)3A-19A7-21A8-2A-16A-A9-19A11-17A13-15A14-2A-12A15-A-11A16-13A18-9A20-9A15-8A3-10A7-9A3-11A5-10A3-4A-6A3(5-10A3-11A)4-11A3-11A3(4-25A)4-15A-9A4(4-25A)4-4A-20A5-2(3A-19A6-)2(23A6-)23A7-21A8-21A9-19A10-19A11-17A13-15A15-13A16-13A18-9A21-7A23-5A19-6A3-8A12-6A3-9A9-8A3(3-10A7-9A)3-10A6-10A3-10A3(6-23A)6-14A-8A6-9A-4A-8A3(6-23A)3(6-3A-19A)2(6-4A-18A)7-21A8-21A9-19A11-17A13-15A15-13A16-13A17-11A19-9A23-3A81-2A5-4A18-2A5-4A17-4A3-6A16-4A3-6A15-5A3-7A13-6A3-7A12-7A3-8A11-7A3-8A10-20A8-2(22A7-)8A-4A2-7A7(7-22A)7-12A-8A9-11A-7A11-17A12-17A13-15A15-13A17-11A19-9A22-5A256-A3-2A21-3A3-4A17-2(5A3-6A15-)5A3-6A14-16A12-11A-6A10-13A-6A3(9-20A)9-12A-7A3(9-20A)11-16A13-15A14-15A15-13A17-11A19-9A22-5A25-3A370-4A3-5A17-4A3-5A16-5A3-6A15-10A-3A14-17A6(11-18A)12-16A13-15A15-6A-6A16-6A-6A18-3A3-3A21-A5-A485-2A6-2A18-3A6-3A17-4A4-4A17-4A3-5A16-6A-6A15-2(7A-8A13-)2(7A-2A2-4A13-)7A-8A13-7A-7A15-6A-5A18-4A3-4A18-2A7-2A599-2(A7-A20-)2A5-2A18-4A5-3A17-5A3-5A15-6A3-6A14-6A3-6A15-5A3-5A2(16-4A5-4A)17-A9-A328-
