model
size = 31 18 29, scale = 0.05, origin = -y
material 
  colors = A:#FFF B:#FCFAF2 C:#0B1013 D:#EEE E:#62592C F:#876633 G:#78552B H:#947A6D I:#985F2A J:#F9BF45 K:#6E552F L:#43341B M:#222 N:#3C2F41
voxels
183-2(2C29-)2C30-5(2C29-)2C28-BC27-2BC21-7B2C22-7C188-2C2(29-BC)30-5(BC29-)BC28-BC27-2BC20-8B2C21-8C188-2C2(29-BC)30-5(BC29-)BC28-BC27-2BC18-10B2C19-10C188-2C2(29-BC)30-5(BC29-)BC28-BC27-2BC17-11B2C18-11C19-2G4F25-6B4E27-4B3H28-3B2G29-BF30-2(BH29-)BH30-5(BE29-)BF28-BF27-2BG15-13B2G16-11C2H13-3E3F23-2H12B17-2B12-4B31-3B2(31-B)2(30-B)31-5(B30-)B29-B28-2B15-14B17-7CE4F46-12B15-2G2B12-4B9-EG2B18-3B2(31-B)2(30-B)31-5(B30-)B29-B28-2B13-16B15-5C4G51-6B6A17-2B12-4A11-2B18-3A6-E24-A5-H25-B3-H26-B2-G27-B2-E28-B-E28-4(B30-)B29-B28-2B11-18B7-I2JMNHI2E2FHG55-12A17-2B12-4A11-DB18-3A31-A31-2(B30-)B31-B30-3(B-H28-)B-F28-B-E27-B2-2E24-2B4-E6-18B7-F2GKLI62-12A17-2A12-4A12-D18-3A2(31-A)2(30-A)31-5(A30-)A29-A28-2A11-D17A75-12A17-2A12-4A31-3A2(31-A)2(30-A)31-5(A30-)A29-A28-2A11-D17A75-12A17-DA12-4A31-3A2(31-A)2(30-A)31-5(A30-)A29-A28-2A12-D16A75-12A17-2D12-4A31-3A2(31-A)2(30-A)31-5(A30-)A29-A28-2A12-D16A75-D11A18-D12-4A31-3A2(31-A)2(30-A)31-5(A30-)A29-A28-2A12-D16A75-D11A31-4A31-3A2(31-A)2(30-A)31-5(A30-)A29-A28-2A13-D15A75-2D10A31-4A31-3A2(31-A)2(30-A)31-5(A30-)A29-A28-2A13-2D14A75-2D10A31-4A31-3A2(31-A)2(30-A)31-5(A30-)A29-A28-2A14-D14A76-2D9A31-4A31-3A2(31-A)2(30-A)31-5(A30-)A29-A28-2A14-2D13A77-4D6A31-4A31-3A2(31-A)2(30-A)31-5(A30-)A29-A28-2A15-D13A79-3D2AD2A31-4A31-3A2(31-A)2(30-A)31-5(A30-)A29-A28-2A15-D13A81-2DAD2A31-D2(3A31-)2(A31-2(A30-))3(A30-)A29-A28-2A16-2D11A82-3DAD31-D3A31-D2A2(31-A)2(30-A)31-5(A30-)A29-A28-2A18-D10A84-3D31-2D2A31-D2A2(31-A)2(30-A)31-5(A30-)A29-A28-2A18-2D9A119-3D31-2D2(A31-)2(A30-)A31-5(A30-)A29-A28-2A19-3D7A153-3D2(31-A)2(30-A)31-5(A30-)A29-A28-2A22-D6A155-2(D31-)A30-D30-A31-D5(30-A)29-A28-DA22-3D2ADA187-D2(31-2(D30-)A)2(30-A)30-D29-A28-2D24-5D250-D30-D31-3(D30-)A2(30-D)29-D28-2D27-2D313-5(D30-)D29-D28-2D65-
