model
size = 29 32 20, scale = 0.05, origin = -y
material 
  colors = A:#050505
voxels
243-2A26-3A4-3A18-4A4-4A17-5A2-5A17-5A-6A16-13A15-3(16A13-)16A14-14A15-13A17-11A18-11A19-3A3-3A277-6(5A7-5A12-)6A5-6A12-6A5-6A11-7A5-7A3(10-8A3-8A)10-9A-9A10-19A11-2(17A12-)17A13-15A15-13A17-11A19-2(9A20-)9A19-2(11A18-)11A19-9A20-9A22-5A25-2A27-A49-2(19A10-)19A9-4(21A8-)21A7-6(23A6-)23A7-2(21A8-)21A9-2(19A10-)19A11-2(17A12-)17A13-15A14-15A15-13A17-11A18-11A20-7A22-7A23-5A16-A28-A27-3(2A20-A6-)2A20-A5-7(3A20-2A4-)3A20-2A5-2(2A20-A6-)2A19-2A7-A19-2(A8-2A18-)A9-A17-A10-2A16-A11-A15-2A11-A15-A12-A14-2A2(13-A)14-3A10-2A2(14-5A5-5A)15-4A5-4A18-2A5-2A21-A5-A14-2A27-2A20-A6-2A20-A5-4(3A20-2A4-)3A20-2A3-5(4A20-3A2-)4A20-3A3-2(3A20-2A4-)3A19-3A5-2A19-2(2A6-3A18-)2A7-2A17-2A8-3A16-2A8-3A15-3A9-2A15-2A10-2A14-3A11-2A13-2A12-4A10-3A13-2(4A7-4A14-)4A7-4A15-3A7-3A18-A7-A12-5(3A20-2A4-)3A20-2A3-8(4A20-3A2-)4A20-3A3-3A20-2A2(4-3A19-3A)5-2(3A18-2A6-)3A17-3A7-3A16-2A2(8-3A15-3A)9-2A14-3A10-3A13-3A11-4A10-3A12-2A-2A7-2A-2A12-5A7-5A13-4A7-4A14-4A7-4A16-2A7-2A10-6(3A22-2A2-)3A22-2A-4A4(22-7A)22-3A-3(3A22-2A2-)3A22-2A3-2(2A22-A4-)2A21-2A4-4A19-2A5-3A18-2A6-3A18-2A7-2(2A17-2A8-)2A17-2A9-2A15-2A10-4A13-2A10-5A9-5A11-4A9-4A12-4A9-4A13-3A9-3A15-2(2A9-)2A24-A2-2A24-A-3A11(24-5A)24-2A-2A24-3(A2-3A23-)A2-3A22-2A3-2A22-A4-3A20-2A5-2(3A18-2A6-)3A18-2A7-2A17-2A8-3A16-2A9-3A15-2A9-4A11-4A10-4A11-3A12-3A11-3A13-2A11-2A14-2A11-2A7-2A25-4A11(26-3A)2(25-4A)24-5A24-6A23-3A-2(3A21-3A2-)3A21-3A3-3A20-2A4-4A19-2A4-4A18-3A5-3A18-2A6-3A18-2A7-3A16-3A7-4A15-2A9-3A13-3A10-3A13-3A11-2(2A13-)A13-A14-A13-A7-2A13(26-3A)25-4A24-5A24-6A23-3A-2A23-2A2-3A22-2A2-3A21-3A3-3A20-2A4-4A19-2A4-4A18-3A5-3A18-2A6-3A18-2A7-3A16-3A7-4A15-2A9-3A13-3A10-3A13-3A11-2(2A13-)A13-A14-A13-A7-2A11(26-3A)25-4A26-3A25-4A25-2A-A24-2(2A2-2A23-)2A2-3A21-3A3-2A21-2A4-3A20-2A4-4A19-2A5-2(3A18-2A6-)3A18-2A7-2A17-2A8-2A17-2A9-4A2(11-A-2A11-3A)11-A-A13-2A11-2A14-2A11-2A7-3A11(25-4A)24-5A24-2A-2A24-A2-2A23-2A3(2-3A21-3A)3-2(2A21-2A4-)3A20-2A5-3A19-A2(6-3A18-2A)7-2A18-A8-2A17-2A9-4A13-2A10-5A9-5A11-4A9-4A12-4A9-4A13-3A9-3A15-2(2A9-)5A21-A-6A9(21-8A)21-2A-5(5A21-A2-)5A21-A3-4A20-A4-2A-A19-2A4-4A19-2A5-3A19-A2(6-3A18-2A)7-2A18-2A7-2A17-2A9-A16-2A10-5A10-4A11-4A9-4A13-2(3A9-3A14-)3A9-3A16-A9-A11-2A22-A3-9(5A20-2A2-)4(5A19-3A2-)5A19-3A3-4A2(19-2A4-2A-A)19-2A4-4A19-2A5-2(3A19-A6-)3A18-2A6-3A18-2A7-3A16-2A9-2A16-A10-2A15-2A11-4A10-3A13-4A7-4A14-4A7-4A15-3A7-3A16-3A7-3A17-2A7-2A12-A21-15(2A4-4A19-)2A4-2A-A19-2A4-4A19-2A5-3(3A19-A6-)3A18-2A7-2A18-A8-2A18-A9-2A16-A11-A15-A13-3A10-2A14-2A-2A5-5A15-A-2A5-4A16-4A5-4A18-2A5-2A20-2A5-2A15-4A14-3A7-4A4(15-4A5-5A)9(15-4A4-6A)15-4A4-4A-A15-4A5-2(3A-A15-3A6-)2(5A15-3A6-)5A13-5A7-5A11-5A8-5A11-5A9-4A2(10-5A)9-5A11-5A7-5A13-4A7-4A15-13A16-13A18-9A21-7A23-5A19-3A11-3A12-3A11-4A9-5A3(11-5A7-6A)9(11-5A6-7A)3(11-5A6-3A-3A)2(11-5A6-4A-2A)10-6A7-6A10-5A8-2(6A9-)5A9-5A11-4A9-4A13-4A8-3A15-3A7-3A16-13A17-11A19-9A23-3A80-2(13A16-)13A14-4A9-2A14-4A2(9-3A12-5A)2(9-4A10-6A)9-5A8-9(7A9-6A7-)7A8-7A7-7A8-6A9-6A8-5A11-5A8-4A12-5A8-4A13-4A8-3A15-13A17-11A19-9A22-5A141-4A22-7A22-11A18-11A16-13A16-3(3A8-3A15-)3A8-4A13-4A8-4A12-5A8-5A10-7(6A8-6A9-)6A8-6A11-4A8-4A13-4A8-3A14-4A8-3A15-13A17-11A19-9A22-5A25-3A229-4A25-4A24-6A22-9A19-11A17-12A17-13A2(15-14A)14-17A6(11-18A)12-16A13-15A15-13A16-13A18-4A-4A21-2A3-2A243-
