model
size = 25 31 27, scale = 0.05, origin = -y
material 
  colors = A:#003B5C B:#6C3 C:#DDD D:#888 E:#BBB
voxels
212-2A21-6A18-8A16-10A15-11A13-12A13-5A19-4A21-2(3A22-)2A2(22-3A)23-A330-2A22-4A21-5A18-8A16-10A15-11A13-12A13-5A-7A12-4A5-4A11-4A7-4A10-2(3A9-)3A10-3A8-4A21-4(3A22-)A-A2(23-2A)24-2A201-2(8A17-)8A16-10A14-2(12A13-)5A3-4A13-3A6-4A11-4A7-4A10-3A9-3A5-B2A2-2A10-3A5-B6A11-2(3A4-B5A12-)3A6-4A13-2A6-3A14-3A5-3A15-3A4-3A17-2(A4-2A18-)A4-A-A17-A5-2A17-A5-A-A16-A6-A-A14-2A7-2A14-2A7-3A13-A9-3A11-2A10-3A9-2A12-4A5-3A14-10A18-5A14-3A5-4A2(13-3A6-3A)13-2A7-3A13-2A8-3A11-3A9-2A11-2A2(10-3A8-4A)11-A-A2(4-B5A13-2A)4-B4A14-2A4-B4A15-2(2A3-B3A16-)2A3-B2A17-2A4-3(2A18-2A3-)2A19-2(A4-2A18-)2A4-2A17-A6-2A15-2A7-2A14-2A7-A-A13-2A8-A-A11-2(A-A9-)A-A11-A-2A5-2A-A13-2A-8A16-6A13-2A10-2A11-2(2A10-)3A10-2A9-4A10-3A2(8-3A12-2A)7-4A12-A-A6-3A2(14-2A4-B4A)15-A4-2(B3A16-2A3-)2(B2A17-2A3-)BA19-A3-B2A18-2A2-B2A18-2A3-BA3(19-A3-2A)19-2A3-2A18-2A3-A-A17-2A4-A-A16-2A5-A-A15-A7-2A14-2A8-2A12-A-A9-2A10-A-A10-4A7-A-A13-11A16-7A9-4(4A12-2A7-)4A13-2A5-2(5A13-2A4-B)3A16-2A3-BA-A16-2(2A3-B2A17-)2A3(3-BA19-A)3-BA19-2A2-B2A18-2A3(2-B2A19-A)3-BA19-2(2A2-3A18-)2A3-2A18-2A4-2A17-2A5-2A16-2A6-2A14-2A7-A-A13-2A8-A-A11-2A10-A-2A8-A-A11-2A-3A2-5A14-9A7-4A14-A6-2(4A14-2A5-)3A15-2A5-3A15-2A2(4-B2A17-A)4-B2A17-2A3-B2A18-3(A2-2BA19-)2(2A-2BA19-)2A2-BA19-2A2(2-B2A19-A)2-2(B2A19-2A-)B2A19-2A2-B2A19-A2-3A18-2A3-2A18-2A4-2A17-2A5-2A16-2A6-2A14-2A7-3A13-2A8-3A11-2A10-4A7-2A-A11-5A3-5A14-9A7-3(2A16-2A5-)2A16-2A4-B2A17-A4-2(B2A17-2A3-)BA18-2A2(2-2BA19-A)2-4(2BA19-2A-)2BA20-A-2B2A19-A2-2(B2A19-2A-)B2A20-A-B2A20-A2-B2A19-A2-3A19-A2-A-A18-2A3-3A17-2A5-2A16-2A6-2A14-2A8-A14-2(2A22-)2A55-2(2A17-A5-)2(2A17-A4-B)2A17-2A3-B2(2A17-2A2-2B)3(A19-A2-2B)A19-2A4(-2BA20-A)-2B2A19-A-2B2A19-2A3(-B2A20-A)2(2-B2A19-A)2-3A19-A3-3A18-A176-3A17-A5-2A17-3(A4-BA18-)2A5(2-2BA19-A)2-2BA19-2A4(-2BA20-A)-2B2A19-A-2B2A19-2A2B2(2A20-A-B)2A20-A-2B2(2A19-A2-B)21-A24-A176-2A18-A5-2(A18-A4-B)A18-A3-2BA18-2A2-2BA19-A3-D3(A19-A2-EB)2(A19-2A-EB)4(A20-A-EB)2(2A19-2A2B)2A20-A2B2A20-A-B2A20-2(A-2B2A19-)A2-B21-A24-A176-2A2(18-A4-BA)2(18-A3-2BA)18-2A2-2BA19-A3-D3(A19-A2-CB)2(A19-2A-CB)4(A20-A-CB)2A19-A-CB2A19-2A3(2B2A20-A)2(-2B2A19-A)2-B21-A24-A176-2A2(18-A4-BA)2(18-A3-2BA)18-2A2-2BA19-A3-D4(A19-A2-CB)A19-2A4(-CBA20-A)-CB2A19-A-CB2A19-2(2A3(2B2A20-A)2(-2B2A19-A)2-B21-A24-A176-2A2(18-A4-BA)2(18-A3-2BA)18-2A2-2BA19-A3-DA19-A2-C3(BA19-A3-)BA19-2A2-DA20-A-C2(BA20-A2-)DA20-2(A-CB2A19-))2A3(2B2A20-A)2(-2B2A19-A)2-B21-A24-A176-2A18-A5-A18-A4-B2(A18-A3-2B)A18-2A2-2BA19-A3-D3(A19-A2-CB)2(A19-2A-CB)4(A20-A-CB)2A19-A-CB2A19-2A3(2B2A20-A)2(-2B2A19-A)2-B21-A24-A176-2A18-A5-2(A18-A4-B)A18-A3-2BA18-2A2(2-2BA19-A)3-D2(A19-A2-CB)2(A19-2A-CB)A20-A2-D3(A20-A-CB)2(2A19-2A2B)2A20-A2B2A20-A-B2A20-A-2B2(2A19-A2-B)21-A24-A176-3A17-A5-2A17-A5-2(A18-A4-B)2(A18-2A2-2B)4(A19-A2-2B)A19-2A4(-2BA20-A)-2B2A19-A-2B2A19-2A2B2(2A20-A-B)2A20-2(A2-B2A19-)A2-2A20-A24-A177-2A16-2A3(5-2A17-A)4-B2A17-A4-B2(A18-2A2-2B)3(A19-A2-2B)A19-2A4(-2BA20-A)-2B2A19-A-2B2A19-2A3(-B2A20-A)2-B2A2(19-A2-3A)19-A3-3A18-A177-4(2A16-2A5-)2(2A17-A4-B)2A17-2A3-B2A17-2A2(2-2BA19-A)2-5(2BA19-2A-)2B2A19-A2-2(B2A19-2A-)B2A20-A-B2A20-A2-B2A19-A2-3A19-A2-A-A18-2A3-3A17-2A5-2A16-2A6-2A14-2A8-A14-2(2A22-)2A23-A31-2(4A14-A6-)3A15-A6-2(3A15-2A5-)3A16-2(A4-B2A17-)2A3-B2A17-2A3(2-2BA19-A)2-2BA19-2A-2B2(A19-2A2-B)2(2A19-A2-B)2A19-2A-B2A19-2A2-BA2(19-2A2-2A)19-2A3-2A18-2A4-2A17-2A5-2A16-2A6-2A14-2A7-A-A13-2A8-3A11-2A10-4A7-2A-A11-5A3-5A14-9A8-3(4A12-2A7-)3A13-2A7-3A13-A-A2(5-4A14-2A)5-3A15-2A4-B3A16-2(2A3-B2A17-)2A3(3-BA19-A)3-BA19-2A2-B2A18-2A2-B2A19-A3-BA3(19-A3-2A)19-2A2-2A19-2A3-2A18-2A4-2A17-2A5-2A16-2A6-2A14-2A7-A-A13-2A8-A-A11-2A10-A-2A7-2A-A11-2A-3A2-2A-2A14-9A11-3A8-3A11-3A9-2A10-4A9-2(2A9-4A10-)A-A8-4A11-2A7-4A12-2A7-4A13-2A5-4A14-2A4-B4A15-A4-3(B3A16-2A3-)B2A17-2A3-B-A17-2A3-B2(2A18-2A3-)3(2A19-A3-)2A19-2A3-2A18-2A3-A-A17-2A4-A-A16-2A5-A-A15-A7-2A14-2A8-2A12-A-A9-2A10-A-A10-4A7-A-A13-11A16-7A2(15-2A4-4A)15-A6-3A14-2A6-3A14-A-10A13-A8-3A11-2(3A9-)3A10-3A8-4A11-3A6-4A12-3A2(4-B5A13-2A)4-B4A14-A-A3-B4A14-A-A4-A-A16-2A4-3A16-2A4-2A17-3A2(3-2A18-2A)3-2A19-2(A4-2A18-)A5-2A17-A6-2A15-2A7-2A14-2A7-A-A13-2A8-A-A11-3A2(9-A-A)11-A-2A5-2A-A13-2A-8A16-6A18-5A20-6A18-7A17-8A16-10A15-11A13-12A13-4A4-5A11-4A7-3A11-3A9-3A10-2(3A9-)3A11-2A9-3A11-A-A7-3A12-A-A6-4A12-3A6-3A14-3A5-3A15-2A5-2(3A16-2A4-)3A2(17-A5-2A)17-A5-A-A16-A6-A-A14-2A7-2A14-2A7-3A13-2A8-3A12-2A2(9-3A)11-4A5-3A14-10A18-5A119-2A22-4A20-7A17-9A15-11A14-11A13-13A12-5A3-5A11-4A6-5A10-3A8-2(4A9-)3A9-3A22-2A23-2A2(22-3A)3(23-2A)24-A405-2A22-4A20-7A17-9A15-11A14-11A13-5A20-3A21-2(3A22-)3(2A23-)A243-
