model
size = 31 28 22, scale = 0.05, origin = -y
material 
  colors = A:#F7A8B8 B:#55CDFC C:#EEE D:#111 E:#FC3
voxels
75-2B2-2B4(25-2A2-2A)2(25-2C2-2B)25-C4-B25-C2(30-A)491-2(2B2-2B25-)2A2-2A25-2A2-2A769-2(2B2-6B21-)2A2-3A3C21-2A2-3A5C19-2(2A2-3A4C-C18-)2B2-2(3B-)B18-2(2B2-)5B18-2B2-2B4-B-B19-B2-2B4-B21-A2-A5-2(A30-)A482-2(B2-5B4-3B16-)A2-5A4-3C19-3A2(-A)2(C-)C19-3(A-)A2(C-)C14-4A2(-A)-3A2C2-C14-4B3(-B)-2B3-B15-3B3(-B)-2B2-B16-2B2-2(3(B-)4B-B19-)2(A-)6A-A19-3A-6A-A20-A2(2-2A)-A20-A2-2A2-4A20-B2-B4-3C20-B8-2C386-2(9B5-2B-5B9-)2(9AC4-2C-5C9-)9AC3-8C10-A3-5AC3-8C10-B3-B3CB2C2-4C4B10-B3-B3CB2C2-2C6B11-B-2B3CB2C2-4C4B11-4B3CB2C2-4C4B12-2CA-5A2-7A13-2CA-4A-2A-6A13-2C6A-2A-6A14-C-A-3A-2A-5A18-3B-9C18-4B5C2-2C18-4B7C20-2B-BC3-3C30-A292-2(B18-2B-B8-)A18-2C-C8-5A14-2CAC8-A2-2A14-2C-C9-A2-A14-2C-C9-B2-C9-C4-3B10-B2-2(C9-C4-3B11-B-)C9-C4-3B12-C-2A6-2A4-3A12-C-2A4-A-2A4-3A12-C2-A4-A-2A4-A-A13-C3A3-4A4-3A13-4B2-B4C3-3C14-7B4C-3C-C15-6BC2-7C15-2B2-2B-8C18-10A-A20-10A21-A239-2(B21-3B6-)A21-3C6-2A19-A3C6-A-A18-A-C7-A2-A17-A-C7-B2-C17-3B7-B2-2C16-3B8-B2-C16-3B9-B-C16-3B9-C-C16-2A11-2C16-2A11-3C14-C-A11-C-C14-C-A12-2B14-2C13-2B13-C-C13-B-B5-2C4-2C-C13-B-3B2-4C3-C-C15-16A15-3A-7A2-2A17-2A-10A20-10A198-2(B22-5B3-)A22-5C3-2A2(2C18-A5C3-A-)2C18-AC-3C4-2BC18-2B-3B4-2BC18-2(B-)B5-B-BC17-B-B7-2B2C17-3B8-C-C18-2A8-3C17-A-A8-3C17-2A10-C-C16-2A10-3B16-2C10-3B15-C-C11-B-B14-C-C11-B-B13-C-C13-A-A12-A-A13-A-3A7-3A-A15-A-14A15-3A5-A4-2A18-12B26-B138-2(BC26-B2-)2A26-C2-2A26-C3-2A25-C3-2A22-4C4-B22-2B-B4-B21-3B-B4-2B20-5B4-2B21-4B5-2C20-3A6-2C19-A-2A6-C-C18-4A6-C-C18-3A8-2B18-2C9-2B17-2C10-B-B16-2C11-2B15-C-C11-A-A14-2A12-A-A13-3A13-A-A11-CA-A13-A2-6A-3A2C-A15-2B-10B-2B16-14B19-10B23-6B2(25-6D)12-2(B28-B-)A28-A-2A27-A-2A-A24-CA-4A24-CA2-3B24-2(2B2-2B-B23-)2B3-3B23-2B3-C-C22-2A6-C21-A-A6-2C20-A-A6-2C19-A2-A7-B19-C-C2(8-2B18-3C)9-B17-C-C10-2C16-3A10-2C16-2A12-CA13-2A-A12-C2A10-3A-A13-B-2B10-3B15-B-2B7-3B-B16-5B4-5B18-5B2-5B19-5D2-5D19-4D4-4D9-2(B27-B2-)2(A27-A2-)2(2A26-A2-)B-2B2(24-B3-B-B)23-2B3-B2-B22-2B4-3C22-2A4-3C22-A5-2C-C21-A6-C-C20-2A6-3B20-2C7-2B20-2C7-B-B19-2C7-3B18-2C9-2C18-2A9-C-C17-2A9-3C16-2A11-2C14-2A-A12-2B13-3B13-B-B12-B-B14-3B10-B-B15-3B10-2B2(17-2D9-3D)8-2(B28-B-)2(A28-A-)3A25-C2(A-)A25-A2-B27-B3-B-B24-B3-B-B23-2B4-2B23-2B4-C-C22-A5-C-C22-A2(6-2C21-2A)6-B-B3(20-C8-2B)19-2C9-2C18-2A9-2C18-A11-C18-A11-2C16-2A11-2B15-2B13-2B14-2(2B13-)2B15-2B12-2B15-2D12-2D15-2D12-D8-B28-3B28-2BA28-3A28-5A25-C3A2-A24-C2AB2-B24-4B2-B2(24-3B2(-B))23-B-2B-A2-3(A22-3A3-A-)A21-A-A2(5-B-B20-3C)5-B-B20-2C7-2B19-C-C7-C-C2(18-2A9-2C)18-2A10-C17-2A11-2B16-2B12-B15-2B13-2(2B14-)B14-B15-D13-2D15-2D12-2D7-2B28-3B28-B2A28-4A27-2A-A27-4A26-A2-2B26-2B-2B25-3(B-)B24-2(B-)3B24-3B2-2A24-2A3-2A23-A-A3-A-A22-3A3-3A22-2A5-2B22-2C5-2B21-C-C6-2(2B20-2C7-)2C19-A-A8-C19-2A9-2C18-2A10-C17-2A11-2B16-2B12-B16-B13-2B14-2B13-2B14-B2(15-D14-D)8-2(2B26-2C-)2A26-2A-2A25-3A2(-A)24-3A2-2A24-3A2-2(2B24-2B3-)2B23-B-B4-BC22-2B2(5-2A22-2A)5-2A21-2A7-A21-2A2(7-2B20-2C)7-2B20-C9-B19-2C9-2C18-2A9-2C18-A10-2C18-A11-C17-2A11-2B16-2B12-B16-B13-2B14-2B13-2B14-B2(15-D14-D)9-2B24-2C3-2B24-AC2(3-2A24-2A)3-2A24-A4-2A23-CA5-B23-3(2B5-BC22-)B6-2A22-A7-A21-2(2A7-AC20-)A8-2B2(20-C9-B)19-2C9-2B18-2C9-2C18-2A10-C18-A2(11-2C16-2A)11-2B16-B2(13-2B14-2B)2(14-B)2(15-D14-D)10-2(2B22-2C5-)3(AC22-CA5-)2A22-CA5-2B22-B6-2B21-2(2B7-2B20-)2B2(7-2A20-2A)7-2A20-A9-A19-2A3(9-2B18-2C)9-B-B17-C3(11-2C16-2A)11-2C15-2A13-2B14-2(2B13-)B-B14-2(2B12-2B15-)2D12-2D15-2D12-2D11-2B21-3C5-2B3-3C8-2C5-3C5-AC3-3C8-3C3-C2-A5-2(AC3-3C8-3C3-C-A6-)AC3-3C8-2C4-C-A6-2B4-2C8-CB3-2B-B6-2B4-2(2C8-CB3-B-B7-B-B3-)2C9-B3-2B9-AC3-2(2C9-C3-2A9-A2C2-)2C9-2C-3A9-A2C-2C10-3CA-A9-B-4B10-5C11-5B10-5C11-3B-B9-6C11-2B12-6C11-C-2C13-A-A12-3C13-2A13-3C12-3A13-3C12-A-A14-2B11-3C15-3B10-C-C15-3B10-2C17-2B10-2C2(17-2D10-2D)11-6B10-2C2-7C3-2B2-3BC-C7-C-9C2(3-2A-5A-A7-A3-3C3-A)3-2A-4A-2A7-A3-3C2-A5-6A2-A7-A2-4C2-A5-4B3C2-C6-C2-3B3-B5-4B3C2-C6-C2-2B2(-B)6-5B2C2-C6-C2-3B2-B7-4B2C2-C6-2C-3B2-B7-6A2-A6-2A-3A2-A7-3A-2A2-A6-2A-3A2-A8-2A-3A-A6-2A2(2-A)9-2A-A-3A6-2A5-A9-3B2-3B6-3B3-2B9-3B2-3B7-2B3-2B10-2B-4B5-B-2B2-2B11-7B5-2B-B2-2B11-2CA-2AC5-3C5A12-CA-2AC6-2C4A13-CA-2A7-2CA-2A13-C4A7-2C4A14-5B6-5C16-4B6-4C18-2(3B6-3C19-)3D6-3D19-3D7-2D12-6B-2C5-12C5-6B3C5-2C6-4C5-2A2-2(2A-)A3-2A6-4A5-2A2-2(2A-)A3-3A5-4A5-2A2-2(2A3-)3A5-4A10-A3-3A2-3A4-4A2(11-C4-2C-3CB4-4B)10-C5-2C-3CB4-4B10-C5-2C-3CB4-3B11-A5-2A-3A5-3A11-2(A2-)2A-3A5-3A11-3(A-)6A5-2A12-3(A-)6A2-2A-2A13-2B-B-6B3(-B)14-2B-B-8B-3B14-2B-B-5B2(-2B)15-2B-B-5B2-B-2B16-2(A-)2A-2A2-A-A17-2(A-)2A-3A2(-A)17-12A-A19-10A21-4B6C21-3(4B5C22-)9D22-9D18-2B3C2B4C-6C13-B4-2B4C-3C2-C13-A4-A-3A-4A2(2-A14-A3-A-3A-A-2A)2-A14-2A2-A2-2A-A-4A4(15-2C-2C2-C2-B-4B)15-2A-2A2-A3-3(5A15-5A2-2A2-)3A-A15-5B2-2B2-3B-B17-3B2-2B2-3B19-3B2-2B2-3B20-2B2-7B20-2A2-6A21-2A2-6A22-7A24-7A148-2DEDE2D24-2DEDE2D19-5B-6B5-C13-5B-B-2B-B3-3C2(13-5A-A-2A-A3-3A)14-4A-A-2A-A3-3A14-2(A-2A-)A4-A2(15-C-C2-C-2C-B4-B)15-C-C2-4C2B4-B17-C2-4C2B22-A2-2A-3A3(25-2A2-2A)3(25-2B2-2B)25-2B2(29-2A)264-
