model
size = 24 32 32, scale = 0.05, origin = -y
material 
  colors = A:#222 B:#888 C:#777 D:#111 E:#555 F:#DDD
voxels
559-10A14-10A275-3A11-2A9-3A8-3A10-A-8A-3A13-11A14-10A10-A4-9A11-2A2-8A13-A3-7A9-2A2-A3-7A10-A-3A2(3-5A11-5A)4-3A13-5A3-A4-A10-5A6-3A10-14D5(10-14A)11-12A14-8A17-6A203-3A15-2A4-5A10-5A4-6A7-7A7(4-20A)5-3(18A6-)18A7-16A8-D14AD5(8-16A)9-14A11-12A13-10A15-8A177-2A18-2A3-4(A18-A4-)6(2A16-2A4-)2A16-2A5-3(A16-A6-)D4A8-4AD2(6-5A8-5A)2(6-18A)7-2(16A8-)16A9-14A11-12A13-10A129-A18-A3-4(2A18-2A2-)2A18-2A3-9(2A16-2A4-)2(A18-A4-)D4A10-4AD2(4-5A10-5A)4-6A8-6A5-7A4-7A6-18A7-16A8-16A9-14A11-12A14-8A106-A10(18-2A2-2A)18-2A3-2(A18-A4-A18-E4-)2(A18-A4-)D2A14-2AD4-3A14-3A4-3A14-2AE4-6A8-6A4-7A6-7A5-18A6-18A7-16A8-16A9-14A11-12A15-6A83-A3(18-6A)18-3A-4(2A18-2A2-)3(A20-A2-)A20-E3(2-A20-A)2-A20-E2-A20-A2-D3A14-3AD2-4A14-4A2-4A14-3A3-5A12-3AE4-5A10-5A4-20A5-18A6-18A7-16A8-16A9-14A11-12A16-4A58-2A5(20-4A)20-2A-5(A20-A2-)A20-E3(2-A20-A)2-A20-E2-A20-A2-D2A16-2AD2-3A16-3A2-3A16-AE3-5A12-4A3-6A10-4AE2(4-20A)5-18A6-18A7-16A8-16A9-14A12-10A55-A12(22-2A)3(22-EA)22-2A22-AD3A16-3AD4A16-8A16-2A2-6A12-3AE3-6A10-5A3-21A2(4-20A)5-18A6-18A7-16A9-14A11-12A30-A23-A16(22-2A)22-AD3A16-3AD4A16-8A16-AE2-4A16-2A2-5A14-3A3-5A12-5A2-22A3-20A4-20A5-18A6-18A8-14A11-12A30-A18(22-2A)22-AD3A16-3AD4A16-8A16-9A14-4A-6A12-5A2(2-22A)3-20A4-20A5-18A7-16A10-12A6-A23-A18(22-2A)22-AD3A16-3AD4A16-5A-2A16-2A-6A14-11A12-30A-22A2-22A3-20A5-18A7-16A9-14A6-A23-4(A20-A2-)A20-A-A13(22-2A)22-AD2A18-2AD3A18-6A18-7A16-10A12-30A-22A2-22A3-20A5-18A7-16A9-14A6-11(A20-A2-)A20-A-A7(22-2A)22-AD2A18-2AD3A18-6A18-7A16-9A14-5A-2(22A2-)22A3-20A5-18A7-16A9-14A6-10(A20-A2-)A20-A-A21-A-A7(22-2A)22-ADA20-AD3A18-6A18-7A16-4A-4A14-4A3(2-22A)3-20A5-18A7-16A10-12A7-9(A20-A2-)A20-A-A10(22-2A)22-ADA20-AD3A18-6A18-3A-3A16-3A2-5A12-5A2-22A3-20A4-20A5-18A8-14A11-12A7-6(A20-A2-)A20-A-A13(22-2A)22-ADA20-AD3A18-6A18-3A-4A14-4A2-5A12-5A3-20A4-20A5-18A7-16A9-14A12-10A7-A20(22-2A)22-ADA20-AD3A18-3A-2A18-2A2-4A14-4A3-4A12-4A4-20A5-18A6-18A7-16A10-12A14-8A9-10(A20-A2-)A9-3F8-A2-A8-F3-F7-A2-A20-A2-A9-F-F8-2(A2-A20-)A2-A5-3(F2-)F5-A2-A8-2(F2-)F5-A2-A5-2(F2-)4F5-A2-A2(5-F)2-F5-A2-A5-3(F2-)F5-A2-D20-D2(2-3A16-3A)3-3A14-3A5-3A12-3A2(6-18A)7-16A9-14A12-10A16-6A10-A20-A2-A9-2B9-A2-A6-8B6-A2-A5-10B5-A2-A4-12B4-2(A2-)9(16B2(2-A)2-)2(C14BC2(2-A)2-16B2(2-A)2-)2(16B2(2-A)2-)16B2-A2-DA-16B-AD2-3A16B3A3-2A16-2A5-4A10-4A6-18A7-2(16A8-)16A9-14A13-8A18-4A12-A7-4B7-A4-A5-8B5-2(A4-)B2C4B2CB2(4-A)3-B2C6B2CB3-A4-A2-B2C8B2CB2-A4-A2-6B2E6B2-A4-A2-2B10E2B2-A4-A2-6B2E6B2-A4-A2-14B2-A4-A2-4B2C2B2C4B2-A4-A2-B5C2B5CB2-A4-A2-2C2BEC2BCE2B2C2-A4-A2-5BE2BE5B2-A4-A2-14B2-A4-A2-B4C4B4CB2-A4-A2-C4A4B4AC2-A4-A2-14B2-A4-A2-A4CA2BA4CA2-A4-A2-C4AC2BC4AC2-A4-A2-B4C4B4CB2-A4-A2-14B2-A4-D2-14B2-D4-3A14B3A4-3A14-3A5-18A7-16A8-16A9-14A10-14A11-12A15-6A36-4(A7-2A7-A6-)A6-4A2(6-A)5-2A2-2A5-A6-A16-A6-A2(2-5A)2-A6-A-2A3-4A3-2A-A6-A-A5-2A5-A-A6-A5-6B5-2(A6-)4B2(6-A)5(7-2B7-A6-A)-A4-A2-A4-A-A6-A2-4A4-4A2-2(A6-A16-)A6-D16-D5-2A16-2A4-4A12-4A5-18A7-16A8-16A9-14A11-12A13-10A305-4B21-2B253-20A4-20A6-15A10-14A11-12A13-10A633-20A4-20A9-10A15-8A17-6A660-2(18A5-20A725-)18A6-18A727-16A7-18A728-14A8-18A728-14A9-16A730-12A11-14A731-12A12-12A198-
