model
size = 12 20 32, scale = 0.05, origin = -y
material 
  colors = A:#030730 B:#250BCC C:#CCC D:#07CCC6 E:#CC7406 F:#CC1F05 G:#11CC03 H:#60CC28
voxels
14-2(6B6-)6D6-6D7-5D174-2(6B6-)6C6-HC2HCH6-HCH2CH6-3(CH)C5-4HCHC5-6C6-6C7-A2CA2(8-4C)9-3C9-3A78-8B2(4-2B)4-C6BC2(4-2C)4-CH2(4-HC4-2C)4-HC4-C2A2-2AC4-2A4CAC5-2A3C2A2(5-2C3A2C)5-3C2A2C2(5-7A)7-2A55-9B3-B6-2B3-CB-3A2BC3-C2-3A-2C3-C-5AHC3-C-4A-HC3-C2-3A-HC3-A6-AC3-A6-2A3-CA4-2CA2(3-CA4-CAC)2(3-3C)3-5A-3A3-9A4-7A51-10B2-2B-5A-B2-CB-5ABC3-C6A-C3-C3A-2A2(-C3-C6A)-C3-A-5A-A3-A-4A2-A3-C2-3A-CA3-C-4A2-AC2-C-4A2(2-C)A-4A-2C2-7A2-2A-10A3-2A4-3A50-10B2-B-7AB2-CB7A2(C2-C-A5-A)C2-C-A4-2AC2-C2A4-3A2-A-2A2-4A2-A-6A-2A-C7A-2C2(-C7A2-C)-2C2A2-2A-AC-2CA3-2A-CA-3A4-4A2-2A5-2A50-10B2-B-7AB2-CB7A3(C2-C-A5-A)C2(2-A-A5-2A)2-A-A4-2A-A-C-A4-2A2C-C-2(A4-A2-2(C-))A4-A2-C-2CA4-2A-C2(-A)5-3A-3A5-3A49-10B2-2B7AB2-CB7AC2-2(2CA6-AC-)3A6-AC2-2A6-A2-3A5-3A2(-A)2(5-2(A-)C-A)2(5-A2(-C)-A)5-A-C-2CA5-A-C2(-3A5-3A)50-10B2-B7A2B2-C7AC3-CA2(6-AC2-2A)3(6-2A2-2A)6-2A-C2A6-2A-C-A5-2A2(C-)A5-A2(-C)-A5-A-C-2CA5-A-C-ACA5-A2C2-2A5-3A2-2A5-2A10-A28-10B2-B8AB2-9AC2-2A6-AC5(2-2A6-2A)-C2A6-2A2(-C2A6-AC)2-CA6-AC2-CA5-A-C2-CA5-2AC2-3A3-4A2-3A3-3A4-3A3-A6-A4-A16-10B2-B8AB2-9AC3(2-2A6-2A)G-3(2A6-2A2-)CA6-2A2-CA6-AC2-CA5-A-C2-CA5-2AC2-C2A4-A2C2-C3A3-2AC2-D4AD2(2AD4-3A2D)2A6-2A2D2A7-D2-A5-10B2-B8AB2-10A2(2-2A6-2A)G-2A6-AG2-2A6-2AG-2(2A6-2A2-)CA6-2A2-CA5-2A3-C-A4-A2C2-C7ADC2-CE6AD3-2D6AD3-CD6AC4-DA-4AD5-A-4A6-6A7-3DA5-10B2-B-7AB2-10A2-2A7-2G-2A7-G2-3(2A7-2G-)2A7-A2-CA5-2A3-CEA4-AC3-CD6AD4-C6AC3-D7AC3-D3A3-AC3-2D2A2-2AD4-7A6-3AD2A7-3D2A8-3D5-10B2-2B2A5-B2-10A2-A8-AG-A8-G2-A8-AG2(-A8-2G)-2A7-A2-CDA4-2A3-CD6AD4-D5A2(ED4-DE4A)ED4-D2E2A2ED4-D6ED6-4A8-4D29-10B2-2B7-B2-2A7-2(A2-A8-)AG-A8-G2-A8-AG-2A7-A3-A6-2A3-DA4-2A4-D6AD4-C2E3AED5-6E6-6E7-4E8-4E53-11B-B8-2B-3(A8-A2-)A8-AG-A8-A3-A7-A3-AB5-2A3-D2A3-AD4-CD5AC5-2E2A2EC7-3A89-11B-BA7-AB2(-A9-A)-2(A8-A2-)2A7-A2-2AB5-2A3-DA4-2AD3-C6AD5-DE3AED6-5E100-11B-B9-B3(-A9-A)-A8-A3-A7-A2-2AB5-2A3-D2A3-2AD3-C6AE5-3EA3E7-3E101-11B-B9-B3(-D9-A)-A8-2A2-A5-B2A2-ADA2-B-2AD3-C6A2D4-E4A2E5-6E112-11B-B9-B-D9-D2(-D9-A)-D8-2A-2AB5-2A3-D2A3-2AD3-DE5AD5-7E122-13BDA8-B2DA8-D-D8-BD-D9-A-D8-2A-D-A4-2AD3-D6A2D3-D2E3A2E6-5E123-13BAB8-BD10-D-D9-D-D8-2D-D7-AD2-2D2A2-3AD3-DE5AED4-7E7-3E124-13BA9-BD10-D-D9-D-D8-2D-DF6-AD2-2D6AFD3-D2E3A2E6-5E135-13B10-BD10-3D8-2D-D8-C3-C2F2-3FD3-2D5F2D4-7E7-3E136-13B10-BD10-3D8-2D-D6-2FD2-9F4-7F7-3F149-13B10-BD10-3D8-D2-DF5-F2D2-9F5-6F159-13B9-2BD9-D-2D8-D2-2DF3-2F2D3-4F-3F5-5F160-11B-B9-B-D9-D-2D7-2D2-D2F3-2FD4-7F7-3F161-11B-B8-2B-D8-BD-2D7-D3-D7FD4-7F7-2F162-10B2-2B7-B2-DB7-D3-D7-D3-2D5F2D4-D5F173-9B3-B6-2B3-D6-DC3-D6-D4-2D5FD5-2D3FD173-2(8B4-)DB4-DC4-2DB3-2D5-2DF4D6-4D173-
