model
size = 12 11 9, scale = 0.05, origin = -y
material 
  colors = A:#96C B:#93F C:#DDD D:#93C E:#888 F:#AAA G:#939 H:#EEE I:#960 J:#F96 K:#777 L:#FCF M:#F3F N:#111 O:#FFF P:#444 Q:#001 R:#555 S:#BBB
voxels
16-2(A2-A8-)4A8-4A92-E2-E8-K2-K7-A-2B-A6-A4-A6-6A89-AP4-P3(A4-B6-)A5-6B65-B6-A4-A6-A16-A6-A5-A4-B5-2A4-GA6-B3G66-A6-A4-A6-A5-B4-B5-B6-A4-2B4-GB3-2K-3DG-2E-FMF6-FM2FMF6-FMF2IR6-R2I26-A6-A16-AC4-CA5-E4-B5-2B4-GA6-2D2G42-O6-O3(4-A6-A)4-AC4ECA4-BC2N-NCA5-6D68-2H8-I4JI6-2H2L2H6-CF2CSC6-5CH104-2L9-Q2-Q76-
