model
size = 32 30 30, scale = 0.05, origin = -y
material 
  colors = A:#E4AB00 B:#4D9DE0 C:#2ACE79
voxels
615-B30-2A341-2(A2B29-BA926-2B29-)A2B28-ABA29-BA895-2B29-A2B28-3A29-2BA889-C4-2B24-AC3-A2B28-4A28-2BA889-2C3-2B16-B7-A2C2-A2B24-CA2-4A27-A2BA28-2BA4-A2C28-A2C29-C781-AB6-2AC3-2B16-BA5-3AC2-A2B16-B6-2CA2-4A27-4A28-2BA4-3C27-A3C28-2CA750-B30-AB5-A3C2-2B16-3A4-2(AC)2-A2B16-2B5-3CA-4A27-4A28-3B3-A2C23-B4-2A2C28-2CA745-C4-2B24-CA3-A2B4-A3C3-B17-3A3-3A2C-A2B17-BA3-A3CA-2A2B23-2CA-5A27-2(BA)-A3C23-2B2-ACA2C27-2CA746-AC4-B25-CA3-ABA3-A3C21-3A3-3A2C-A2B17-2BA2-A2C5A2B23-2C7A27-B3A-A3C22-3BA-2CA2C27-2CA715-A31-AC3-AB25-CA2-2AB3-A3C18-C3-3A2-3A2C2-2B18-2BA-A2C4A3B18-B3-3C7A24-CA-4A-A3C22-3BA-4C28-2CA716-A31-AC3-2B25-2A2-A2B3-3C19-C2-4A-4ACA-2B18-2AB3A2C2A-3B18-2BA-4C6A23-2CA-2B2A-A2C23-3B2A4C24-BA-3CA717-A30-AC3-AB25-2A2-2ABA2-4C18-CA2-A-6A2C-2B19-6A-4A2B19-2BA3C6AB23-2C7A3C23-2B3A4C23-2BA-3CA29-C688-A30-AC2-A2B25-2A2-2AB2-4C19-CA-2A-5A2C-2B19-6A2-3A2B19-2B2A2C6AB22-3C7A3C21-CA-B3A4C24-BA-3CA28-2C688-AC30-AC2-A2B25-2A-2A2B-4C20-C2(A-)5A2C-2B18-A-6A-3A2B20-2B2A2C5AB22-A3CA2B3A3C20-2CA3B4A2C24-B2A2C2A25-A2-2C689-AC30-AC-A2B26-2A-2AB2-3C21-C3A-4A2C-2B18-C7A-3A2B20-3B2A2-4AB23-AC4A-2A3C20-A2CAB4A3C21-C2-B2A2C2A25-A2-2CA689-AC30-2A-A2B25-5A2B-3C21-3AB-5ACA-B19-C6A2-2A2B21-3BA3-2A2B21-2B6A-2A2C22-2CAB4A2C22-2C-BA3C2A25-A4CA690-AC29-5AB26-5ABA4C21-4A-4A2C-B19-CABA-3A-2A2B22-B3A2-2A2B22-B9A2C22-2C6A2C22-2CABA2C3A25-A3C2A509-2BA27-2B2A27-2BA27-2B2A28-2A57-AC29-5AB26-5AB-3C22-4A-3A2C22-CABA2(-2A)2B21-AB3A2-2A2B22-2B2A-5A2C23-C6A2C23-CABA2C3A26-3C2A448-BA28-2BCB27-3B28-2BC26-4BC25-4BCB24-4AC58-2A29-4A2B26-A-2A2BA2C23-3A-3A2C23-C2A2-A-2A2B22-5A-2A2B23-2B2A-4A2C23-6A3C24-ABA2C3A26-3CA417-2BC29-2BA27-3BA27-2B2CB26-2B3C25-2B2(CB)21-2A3(BC)29-CB56-3A29-4AC26-5ABA2C23-3A2-2A2C24-C2A-A-2A2B22-C4A2-A2B24-2B2A-3AC25-B4A2C26-BA2C2A28-2CA354-A31-BA29-2BC28-3BC27-4BA27-5B25-BC3BC20-2ABC3BCBC24-BC3B29-BC57-2A29-4A2B26-4A2B2C24-2A2-A3CA23-4A-2CA2B23-C4A-A2B25-B6AC26-4A2C26-BA4C28-2CA322-BA2(30-2B)29-4B27-5B27-4BA26-C3BC20-A-B2-2B2(CB)21-A-AC3BCB23-A2-CBC89-2A29-2A3B27-2A2BAC26-4A3CA24-4A2CA2B24-C5A2B25-BAB4A27-4A2C27-A4C28-2CA30-A259-BA2(30-BC)30-B2C28-2B2C27-3B2C27-4BA20-A4-4BCB20-2A-AC5B22-2A2-2(CB)C23-2(2A30-)A31-A30-A2B29-A2BAC2(27-3A2C)A2B24-C5A2B25-2AB4A28-B2A2C27-B2A2C28-3A259-A30-AB30-2B30-3B2(28-4B)27-5B26-4B2A22-2BC5B25-A2(CB)C23-2A-AC-C25-2A29-3A29-3(AB30-)ABAC27-3A3C27-2A2CA2B25-CAB2A2B26-AB4A28-4AC27-5A289-2A30-BC30-B2C28-2B2C2(27-4BC)25-C5B24-2BC4BA25-3(BC)25-A2(BC)B29-B25-3(2A30-)AB30-AB2(29-3A)2CA27-4A2B26-C3A2B27-AB3A27-5A322-2A28-3BCB25-5BCB26-4BC28-3BC27-C3BC26-3(BC)25-2B2(CB)A25-A2(BC)B29-B121-2A30-AB29-3A29-2A2C28-A3C28-A2CA2B27-C2A2B26-4A354-3A27-A4CB27-A3CB28-A2CB3(27-A3C)2-B29-BCA28-CBC183-2(2A30-)2(AC30-)3A29-2A385-4AB31-2B31-2(B30-)B65-C29-2BA30-B248-3(A31-)
