model
size = 32 22 16, scale = 0.05, origin = -y
material deform = 1, fade = true, lighting = smooth, roughness = 0.3, metalness = 0.6
  colors = A:#EEE B:#222 C:#FFF D:#111 E:#444 F:#F93 G:#777
voxels
205-6E25-2(2EA)2E24-E6AE23-2(3EA)2E22-3E4A3E22-2(3EA)2E23-E6AE24-2(2EA)2E25-6E347-4B16-3D7-8B7-3D3-3DE6-10B6-E3D2-3DE5-12B5-E3D-4D6-12B6-4D-2D7-12B7-2D2-2D5-16B5-2D8-2(18B14-)18B362-2D22-2D5-3DE8-4B8-E3D4-D2-E6-2B4C2B6-E2-2(D3-)2E3-2B-C4AC-2B3-2E3-D2-D3-EB3-BAC6ACAB3-BE3-D-D3-2E4-B10AB4-2E3-2D2-3E4-B10AB4-3E2-2D2-2E3-2B12A2B3-2E2-4D-E2-B16AB2-E-3D4-E2-B16AB2-E11-B16AB14-18B298-2D22-2D6-D-D20-D-D5-F3-E7-4B7-E3-F4-F3-EB2-4B-2C-4B2-BE2(3-F)2-2CB2-B4CB2AB4CB2-B2C2(2-F)2-C2B2-B12AB2-2BC2-F-F2-CB3-2B12A2B3-BC2-FD2-CB2-3B12A3B2-BC2-2D2-2CB-B16AB-B2C2-2D2-EB-B18AB-BE2-3D3E-B18AB-3E2D7-B16AB14-3B12A3B17-12B269-4D18-4D6-D2-E18-E2-D5-D4-B2-12B2-B4-D4-F-2CB8-2C8-B2C-F4-FC2AB-7B2A7B-B2ACF4-FC2AB-B14AB-B2ACF3-2F2AB-B16AB-B2A2F2(-F)2AB-B16AB-B2AF-2F-F3AB18AB3AF-FD-2CAB20ABA2C-2D-E-C2B18A2BC-E-3D-2E2-B16AB2-2E-2D7-B16AB15-3B10A3B19-10B208-2DE16-E2D9-D2CE16-E2CD8-F-CE16-EC-F7-D-2CB2-12B2-B2C-D5-D-C2AB-6B2C6B-B2AC-D4-F-C2A2B14A2B2AC-F4-FC-2AB16AB2A-CF3-F-C-AB18ABA-C-F2-DC3AB18AB3ACD2-DC26ACD-DC28ACDF-3C22A3C-F2D2E3B18A3B2E2D6-B18AB12-5B10A5B17-B8AB22-10B25-4B29-2B30-2B84-2DE16-E2D9-F2CE16-E2CF8-F2-CB14-BC2-F8-F3C16B3CF7-DC3AB4C6A4CB3ACD5-D-C22AC-D4-FC-22A-CF3-D-C-22A-C-D2-DC26ACD2-FC26AC2(F-)C26AC-2F2-C-22A-C2-FD2-3B20A3B2-3DE3-B18AB3-E2D6-2B16A2B14-3B10A3B17-2B10A2B19-4B4A4B22-3B2A3B25-2B2A2B27-4B51-2DE16-E2D10-FCE16-ECF9-F2-CB4-6B4-BC2-F8-F-3C4B6C4B3C-F7-F-F2A4C8A4C2AF-F5-2(D-C22AC-D4-)DC-22A-CD4-F26AF3-2F26A2F2-2F26A2F-F2-C-22A-C2-FD2-3B20A3B2-3DE3-B18AB3-E2D6-2B16A2B14-B14AB17-B12AB19-2B8A2B22-B6AB25-B4AB27-4B29-2B20-2DE16-E2D10-DCE16-ECD9-D-2CB4-6B4-B2C-D8-DCA2C4B6C4B2CACD7-D-C2A5C6A5C2AC-D6-D-C20AC-D5-D-C-20A-C-D4-DC2-20A2-CD4-DC-22A-CD3-D-C24AC-D2-DC26ACD-D2-C-22A-C2-2D2-3B20A3B2-3DE3-B18AB3-E2D6-2B16A2B14-B14AB17-B12AB19-2B8A2B22-B6AB25-BC2ACB27-4B29-2B20-2DE16-E2D10-FCE16-ECF10-F-CB4-6B4-BC-F10-FC-CB-2B2C2-2C2B-BC-CF9-2FA2C-B-C6AC-B-2CA2F7-D-C3A4C6A4C3AC-D5-2(D-C-20A-C-D4-)FC-22A-CF3-F-C24AC-F2-2F26A2F-F2-2C22A2C2-FD2-3BC18AC3B2-3DE3-B2C14A2CB3-E2D6-2BC14AC2B14-B2C10A2CB17-BC10ACB19-2B2C4A2C2B22-B2C2A2CB25-BC2ACB27-4B29-2B20-2(2DE16-E2D10-)F-CB4-6B4-BC-F10-FD-B3-B6CB3-B-DF9-2(DC)-3BC6AC3B-2(CD)7-D-CD2C3-C6AC3-2CDC-D6-F-C3A3C8A3C3AC-F5-D-C-20A-C-D4-D-C22AC-D2(4-FC24ACF)2-2F2-CB2C16A2CBC2-2FD2-2B-B2C14A2CB-2B2-D-DE3-B2AC12AC2AB3-ED7-2B-C12AC-2B14-B-2C8A2C-B17-B-2C6A2C-B19-3BC4AC3B23-BC2ACB26-BC2ACB27-4B29-2B52-2DE16-E2D10-D-E5-6G5-E-D10-F-E4-B-4C-B4-E-F9-2(D-)B2-B-C4AC-B2-B2(-D)8-FCDC-2B-C6AC-2B-CDCF8-FCA2C3-C6AC3-2CACF6-2F-C2A4C8A4C2AC-2F4-D-C3A3C10A3C3AC-D4-DC6AC10AC6ACD4-F-4B3C10A3C4B-F3-D6-3C10A3C6-D2-D-2B-B2-2C10A2C2-B-2B-D3-E3-3B-D10AD-3B3-E10-B-2C8A2C-B17-B2-C6AC2-B19-B2-C4AC2-B21-2B-C2AC-2B24-B-2C-B26-B4CB27-4B115-2DE16-E2D10-D-E4-8G4-E-D9-D2-E3-GC-4C-CG3-E2-D8-F2(-D)2-G-6C-G2-2(D-)F8-F-C-3D-3C2A3C-3D-C-F8-F-C3D-C8AC-3DC-F6-2F-2C3D-C8AC-3D2C-2F4-D-2C4D-C8AC-4D2C-D4-D3-4D-C8AC-4D2(3-D)2-B5D-C8AC-5DB2(2-D)2E3-3D-C8AC-3D3-2ED10-2D2C6A2C2D18-2D-2C4A2C-2D19-3DC4AC3D21-2D-C2AC-2D23-2D-2C-2D25-2D2-2D27-4D179-2DE5-6D5-E2D10-D-E4-G-4C-G4-E-D10-D-E3-GC-4C-CG3-E-D9-D2-E3-D2-4C2-D3-E2-D7-D2-E3-D-8C-D3-E2-D6-D2-E3-D-8C-D3-E2-D5-D2-D4-B-C6AC-B4-D2-D4-D2-E4-B-C6AC-B4-E2-D4-D2E5-B-C6AC-B5-2ED12-B-C6AC-B21-B-C4AC-B22-2B-C2AC-2B24-BC2ACB26-B-2C-B27-B2-B29-2B244-2D5-8D5-2D10-2DE4-DC4ACD4-E2D9-2D2E3-2DC4AC2D3-2E2D7-3DE4-D8CD4-E3D6-3DE4-D2-4C2-D4-E3D5-3DE4-DC-6C-CD4-E3D4-2D2E4-DC-6C-CD4-2E2D13-D-6C-D22-D8CD23-D-C2AC-D25-DC2ACD27-4D28-D2-D29-2D286-2D28-2D2A2D26-D4AD25-D6AD23-D2C4A2CD21-D10CD20-DA8CAD21-D8CD23-D6CD25-D4CD26-6D27-4D29-2D175-
