model
size = 13 24 32, scale = 0.05, origin = -y
material deform = 1, fade = true, lighting = smooth, roughness = 0.3, metalness = 0.6
  colors = A:#BA7F38 B:#D8B37B C:#B28065 D:#FCC E:#100 F:#080000 G:#6F2900 H:#FC0
voxels
56-5C8-5B8-5A9-3A219-C-C9-3(5C8-)5B9-5(3A10-)4(2A11-)A37-5F5(8-5E)21-2(C-)C3(7-6C)7-B4DB3(8-A3BA)8-6(A2BA9-)AB2A9-4A8-6A7-6F7-6E3(7-E4BE)7-6E20-3(C-)C3(5-8C)5-B6DB6-2(A4BA7-)2(6A7-)6A8-5A4(7-6A)7-7A6-5ABA5-FE6F5-EF6E3(5-EB4EBE)5-8E17-2C4(-C)3(3-10C)3-B8DB4-A6B2A3-2AB4-B2A3(3-3A4-3A)5(4-2A4-3A)4-2A4-ABA2(4-2A)2(4-3F)3-2EF4-F2E4(3-3E4-3E)16-4(C-)C4-3(10C3-)B8DB3-A8BA3-AB6-BA3-2A6-2A3-FA6-2A3-2A7(6-2A4-A)6-A4-2F6-2F5(3-2E6-2E)16-2C4(-C)3(3-10C)3-B8DB3-A8BA3-FB6-BA3-FA2(6-2A3-2A)7(6-2A4-A)6-A4-2F6-2F5(3-2E6-2E)16-4(C-)C4-3(10C3-)B8DB3-A8BA3-AB6-BA3-2A6-2A3-FA6-2A3-2A7(6-2A4-A)6-A4-2F6-2F5(3-2E6-2E)16-2C4(-C)3(3-10C)3-B8DB3-A8BA3-AB6-BA3(3-2A6-2A)2(4-A6-2A)4-4(A6-A5-)A6-A4-2F6-2F5(3-2E6-2E)16-4(C-)2C3(3-10C)3-B8DB3-A8BA3-AB6-BA3-2A6-2A3-2A6-A4-2A7(6-A5-A)6-A4-2F6-2F5(3-2E6-2E)16-2C2(-C)-2C3(4-9C)4-B7DB4-A7B3(A4-2A6-)8(A5-A6-)A5-F6-F5(5-E6-E)43-2(9C4-)B7DB4-A7B3(A4-2A6-)8(A5-A6-)A6(5-F6-F)43-9C4-B7DB2(4-A7BA)3(4-2A6-A)9(5-A6-A)2(3-G-A6-A)2(-G)-A6-A-G2-GB6-AG4-H6AH6-6A31-9C4-B7DB2(4-A7BA)2(4-2A6-A)9(5-A6-A)3(5-8A)5-H7A5-G6AH55-10C3-B8DB3-A8BA4-A7B2(A4-2A6-)6(A5-A6-)A3(5-8A)5-H6-A12-H2(5-G)13-G55-2(10C3-)B8DB3-A8BA4-A7BA4-2A4(6-A5-A)6-A3(5-8A)5-A6-A5-H6-H32-2G2-2G82-10C3-B8DB2(3-A8BA)4-A7BA4-2A2(6-A5-A)6-A2(5-8A)5-A6-A5-H6-H45-G4-G21-4G83-10C3-B8DB2(3-A8BA)4-A7B2(A5-A6-)A5-8A5-A6-A5-H6-H32-6G33-5G96-4(C-)2C3-10C3-B8DB2(3-A8BA)3-2A7BA5-A6-A5-A6BA5-8A5-H6-H19-6G160-2C4(-C)3-B8DB4(3-A8BA)3-2A7BA4-A7BA5-H6AH19-6G172-2C3(-C)-2C2-B9DB2(2-A9BA)3(3-A8BA)4-9A19-6G185-5(C-)C2-B9DB3(2-A9BA)2(3-A8BA)4-9A210-2C5(-C)-B10DB3(-A10BA)-A9BA3-2A7BA5-7A211-5(C-)2C-B10DB3(-A10BA)-2A9BA3-A7BA5-7A211-2C4(-C)-2CB11DBA2(11B2A)10BA-2A9BA3-A7BA5-7A211-6(C-)CB11DBA2(11B2A)11B3A9BA3-A7BA5-7A211-2C4(-C)-2CB11DBA2(11B2A)11B3A9BA3-A7BA5-7A211-6(C-)14CB11DBA11B2A11BA-A9BA3-A7BA5-7A212-6(C-)13CB11DBA11BA-A9BA2-A9BA3-A7BA5-7A213-4(C-)C3-11C2-B9DB3(2-A9BA)3-A7BA5-7A226-10C2-11C2-B9DB2-A9BA3-A7BA4-2A5B2A6-5A240-9C4-2B5D2B2(4-2A5B2A)5-7A224-
