model
size = 20 24 10, scale = 0.05, origin = -y
material deform = 1, fade = true, lighting = smooth, roughness = 0.3, metalness = 0.6
  colors = A:#D00 B:#EEE C:#00F D:#222
voxels
150-2A18-2A356-5A14-7A12-8A12-3(9A11-)9A12-6A16-4A91-B10-B2(6-5B)3-7B4-7B-8B4-7B-9B2-9B-7B4-7B2-7B4-7B3-2(5B6-)B10-B32-5A13-8A12-9A10-4(11A9-)11A10-9A12-7A14-5A70-3B8-3B2(4-7B)-8B3-8B-9B2(2-18B)2-9B-7B3-8B2-2(7B4-)3B8-3B13-2A15-6A13-8A11-10A10-11A9-11A2(8-12A)9-11A10-9A12-7A14-5A69-5B6-5B3-7B4-7B-9B4(2-18B)2-9B-7B4-7B3-5B6-5B12-2A15-6A13-9A10-10A10-11A9-11A2(8-12A)9-11A10-9A11-8A14-5A69-5B6-5B3-7B4-7B-9B4(2-18B)2-9B-7B4-7B3-5B6-5B29-6A13-8A11-10A10-4(11A9-)11A10-9A12-7A14-5A69-5B6-5B3-7B4-7B-9B4(2-18B)2-9B-7B4-7B3-5B6-5B30-5A14-7A12-9A10-10A10-3(11A9-)11A10-8A13-6A16-4A89-5C6-5C3-3CD3C4-3CD3C2-2C3D2C4-2C3D2C2-C5DC4-C5DC2-2C3D2C4-2C3D2C2-3CD3C4-3CD3C3-5C6-5C51-3A15-6A13-8A12-9A3(10-10A)11-9A12-7A14-5A151-D10-D7-3D8-3D7-D10-D113-4A14-6A14-7A12-8A12-9A11-8A12-8A14-5A17-A338-3A16-5A3(14-6A)15-5A307-
