model
size = 7 11 32, scale = 0.05, origin = -y
material deform = 1, fade = true, lighting = smooth, roughness = 0.3, metalness = 0.6
  colors = A:#630 B:#EEE C:#111 D:#D00 E:#E00 F:#996 G:#633 H:#444 I:#930 J:#999
voxels
15-2(2(BD)B3-DBD59-)2(2(BD)B2-2(BD)B65-)5(2(BD)B72-)2(BD)B4-C67-2(BE)B3-3C66-2(BE)B3-3C4-3C59-2(BE)B2(2-C2A2C)2-5A51-2(BE)B2-C3AC2-5A2-AHCHA51-2(BE)B2(2-5A)2-AHCHA51-2(BE)B2-5A2-G4A2-5A2-ACHCA44-2(BE)B2-4AI2-5A2-G3AI2-4AI44-2(BE)B2(2-5A)2(2-4AI)2-A2HCA37-2(BE)B2-G4A2(2-5A)-2C4A2-5A2-AC2HI2-5A2-2(AC)A2-2(FC)F2-5F2-2(BE)B2-G4A2-4AI-2C2(4A3C)4A2-A3CA2-A3-G2-A-C-A2-F3-J2-J3-F2-2(BE)B2(2-5A)2(3C4A)3C3A2C-A3CA2-G3-G2-A3-A2(2-F3-F)2-2(BE)B2(2-5A)2-G4A3C4AC-5A2-G3C2(A2-A3-)A2(2-F3-F)2-2(BE)B2-C3AC3(2-5A)2-2(AG)A2-2A2GA2-AG3A2-5A2-FJ3F2-3FJF2-2(BE)B2-5C3-3C5-C53-2(BE)B3-3C66-2(BD)B4-C67-4(2(BD)B72-)2(BD)B2-2(BD)B65-2(BD)B2-2(BD)B64-
