model
size = 18 32 7, scale = 0.05, origin = -y
material deform = 1, fade = true, lighting = smooth, roughness = 0.3, metalness = 0.6
  colors = A:#CA7A2C B:#985F2A C:#E89701 D:#B07736 E:#C7802D F:#A36336 G:#967249 H:#9B6E23 I:#C1693C
voxels
29-2B16-2B15-B35-C51-D53-D35-C18-BC17-D36-F17-A35-A34-C17-A17-C17-B34-A9-G2-2G-B10-G-G4-A11-G2-G-A42-B15-ACA14-CB15-3B15-BF15-2AF15-2BD15-DC15-BD15-ACA2(16-BF)17-AC16-AF17-AD16-A2I15-A2BD15-2AC15-2AD15-BABC14-CADF14-2AD15-ABA15-ABC14-2AB14-C2BD13-2A2BC7-2G2-DC2B2A7-E2G2D2A2BCF7-DECAC2BABI8-G5E2DF11-E27-2ACBA11-4AICF10-2B2F14-2BF14-CBFC14-2AF15-3A14-2ACF13-C2AC14-3AB14-3AD15-2AB15-2AF16-A2F15-2C2A15-C3A14-4A14-3AI15-2AID14-B3A14-B2AG14-3AD14-C2A14-3AD13-4AD12-5A13-5A6-D-D2-B5AD6-4D7A7-EDB8A7-E2B5AIG11-D2-E-I21-C4AC10-C6A10-3AID2A10-3A2FBC10-4AB13-B4A13-5A2(12-5AB)11-B3A2B13-C2AB14-B2A2B13-B5A13-4AC13-C3A2C13-3A2CA12-5AB13-5A13-C4A13-2B4A12-2B3AB12-5A13-B2AFE12-2B2AB12-3B2AB11-5A2B5-E4-C5AB6-E3-AC5AB6-3D7A2C6-G9AC7-E10A7-D4EDED2B20-CBEAF11-2A2BCBC10-C2AC14-ABF14-2A2F14-CAF15-3A14-4A13-C2AE14-C3A14-3AB15-BAB15-B2A16-2AB15-2ABC15-AB2C2(14-4A)14-G4A2(14-3AB)14-3AC14-2AF14-B3A13-AB2AC12-5A7-ED4-5A6-2ED2-C5AC6-E3D6AB7-2DC7AB7-G2C7A9-E3-E2-C22-B15-FAB14-2A15-A2B15-AB15-C2A15-ABC15-HC15-AH15-2AH16-AF16-BH17-HA16-2A17-AB16-AFB15-2AHE15-C2(HA15-B)2AC14-3AE14-AHA15-AHF15-C2A14-BAH14-3AH13-C3AE6-GE-D2-2B2FH7-E4D3BAEF7-2DC4AFBA8-E2C2BDAEH12-E3-E75-B16-E34-A34-B16-B54-C36-F2(C36-)F34-B35-C17-B34-B16-AB25-G2(-D)3-F9-E5-E13-D-B31-
