model
size = 12 8 10, scale = 0.05, origin = -y
material deform = 1, fade = true, lighting = smooth, roughness = 0.3, metalness = 0.6
  colors = A:#E00 B:#EEE
voxels
15-4B8-4B68-4B8-4B79-B4-B6-6B7-4A8-4A54-B6-B4-B6-B5-A4-A6-A4-A7-4A8-4A29-B8-B2-2B6-2B3-A6-A4-A6-A5-A4-2A6-A3-3A6-5A8-2A5-B8-B2-2B6-2B3-A6-A4-A6-A5-A6-A2B3-A5-3B4-A-A2-A7-A-2A3-B8-B2-2B6-2B3-A6-A4-A6-A5-A6-A2B3-A6-2B4-A-A2-A7-A-2A3-B8-B2-2B6-2B3-A6-A4-A6-A5-A4-2A6-A3-3A6-5A8-2A2(6-B)4-B6-B5-A4-A6-A4-A7-4A8-4A31-B4-B6-6B7-4A8-4A53-
