model
size = 7 30 20, scale = 0.05, origin = -y
material deform = 1, fade = true, lighting = smooth, roughness = 0.3, metalness = 0.6
  colors = A:#FFC408 B:#724938 C:#FBE251
voxels
4-A285-A5-2(3A4-)3A5-2(A6-)A139-A6-A5-3A4-3A3-4(5A2-)5A3-3A4-3A5-2(A6-)A104-A6-A5-3A4-3A3-2(5A2-)5A-28A-5A2-5A3-3A4-3A5-A6-A90-A5-3A4-3A3-5A2-5A-70A-5A2-5A3-3A4-3A5-A69-A5-3A3-5A2-5A-42A-4(5A2-)5A-C5AC21A-5A3-3A5-A55-A5-3A3-5A2-5A-21A-2(5A2-)5A3-5(3A4-)3A3-5A2-5A-21A-5A3-3A5-A47-3A3-5A2-5A-14A-2(5A2-)5A3-2(3A4-)3A5-3(A6-)A5-2(3A4-)3A3-5A2-5A-14A-5A3-3A5-A34-A5-3A3-5A-14A-5A2-5A3-3A4-3A5-A6-A34-2(A6-)A5-2(3A4-)3A3-5A-14A-5A3-3A32-3A3-5A-14A-5A2-5A3-3A5-A6-A76-A6-A5-3A3-5A-7AC5AC2-3A5-A20-A5-3A3-5A-7A-5A3-3A4-3A5-A104-A5-3A3-5A-7A-5A3-3A19-A5-3A3-5A2-5A3-3A5-A6-A118-A5-3A3-5A2-5A3-3A19-A5-3A3-5A3-3A5-A139-A5-3A3-5A2-5A4-A13-B5-3B4-ABA5-A153-A5-3A3-5A4-A13-B5-3B5-B160-A5-3A3-5A3-3A194-A4-5A3-3A200-3A4-3A5-A195-A5-3A5-A202-A6-A209-A3-
