model
size = 18 11 21, scale = 0.05, origin = -y
material deform = 1, fade = true, lighting = smooth, roughness = 0.3, metalness = 0.6
  colors = A:#777 B:#444 C:#1E88A8 D:#211E55 E:#9B90C2 F:#F75C2F G:#52433D H:#77428D I:#2EA9DF J:#F7C242 K:#00AA90 L:#555
voxels
23-D4C3E10-D2(4C3E11-)4C2E14-2CE119-2DC4A3E8-D-C4AE-E8-2D2C2A2(-E)9-D-3C4E9-D2C3-2E11-4C2E99-3DA4-2A2E6-D-D6A3E6-D-D6AE-E7-D-B5A2E8-D-5BE-E9-D2-2B2-E11-5CE58-2G20-2D2A6-3AI4-D-D2A4-3ABI5-2D2A3-3A2-I5-D-B7A2E6-D-B6AE-E7-D-2B2AB2-E9-2D-2B-2E12-4C39-4G20-D2A9-AI4-DB2A6-2ABI4-DB2A5-3ABI5-2D2A3-4ABI5-2D8A-I6-D-B5A2(-E)7-3D4B-2E10-D4CE36-5G21-CA10-AI4-C2A8-2AI4-CBA7-2ABI4-DB2A5-3ABI4-D-B2A3-3AB-I5-D-B6AE-I7-D-D4A2-E9-2D4C2E34-5G21-2C12-AI2-2CA10-ABI3-CA9-2AI4-CBA7-2ABI4-CB2A5-3ABI5-DB2A3-3ABI6-4D4A-B2I8-3D2C3E33-4G23-C13-AI2-CA11-ABI2-CBA9-2A2I3-CBA7-2ABI4-2CA7-2ABI5-CBA5-2ABI6-C-D6AB-I7-5DB4I13-L16-4G25-C13-AK2-CA11-ABK2-2CA9-2ABK3-C2A7-3AK4-2CA7-2ABI5-2CA5-2ABI6-C-C6AB-I7-4C2B4I12-2L15-3G27-C13-AK2-CA11-A2K2-2CA9-2A2(K4-2CA7-2AB)K5-2CA5-2ABK6-3C6AB2K8-3CBJ3K13-L14-5G27-H12-AK3-HA11-AK4-HA9-ABK4-HBA7-2ABK4-2C2A5-2AB-K5-2C2A3-2AB-K7-3C4AB-K9-2CHF2J2K26-5G30-HA10-AK4-H2A8-ABK4-2HA7-2ABK4-2H2A5-2AB-K5-HB2A3-3ABK6-H-H6AB-K7-H-2B2F2BJK9-3H2F2J26-5G31-HBA8-ABJ4-2H2A6-2ABJ4-2H2A5-2AB-J4-H-H8ABJ6-2H7AB-J7-2HB4AB-J9-H-B2FB-J11-2H2F2J24-5G34-HBA5-2ABJ6-2H2A3-3ABJ6-2H7AB-J6-H-B6ABJ8-HBF4AB-J8-2H-3FB-J11-4F2J42-3G36-H2B5A2BJ7-H-B5A2BJ8-H2F4AB-J8-H5F2B2J9-5FB2J10-5F2J14-2F75-B7-H9BJ7-2H-5B2-J9-5F3J11-4F2J13-3FJ100-2(2B7-)9B-B9-2B3-3B12-3F137-2B6-3B7-11B11-3B155-4B4-3B8-9B171-10B9-7B173-7B12-5B169-
