model
size = 29 11 30, scale = 0.05, origin = -y
material deform = 1, fade = true, lighting = smooth, roughness = 0.3, metalness = 0.6
  colors = A:#630 B:#AAA C:#FF6 D:#444
voxels
11-9C19-9C18-2C9-2C15-2(C6-)C13-C6-3C6-C12-C5-2(CD)C5-C12-C5-5C5-C12-C2(3-3C)3-C12-C2-C9-C2-2(C13-)C15-2C9-2C106-4(7A22-)7A193-4(4A5-4A16-)4A5-4A188-4(3A11-3A12-)3A11-3A185-4(2A15-2A10-)2A15-2A183-4(2A17-2A8-)2A17-2A181-4(2A19-2A6-)2A19-2A179-4(2A21-2A4-)2A21-2A178-4(A23-A4-)A23-A177-4(2A23-2A2-)2A23-2A2(176-4(A25-A2-)A25-A)175-2A4(25-4A)25-2A5(174-A4(27-2A)27-A)174-2A4(25-4A)25-2A175-2(4(A25-A2-)A25-A176-)4(2A23-2A2-)2A23-2A177-4(A23-A4-)A23-A178-4(2A21-2A4-)2A21-2A179-4(2A19-2A6-)2A19-2A181-4(2A17-2A8-)2A17-2A181-A3(-A16-2A7-2A)-A16-2A8-A-A16-2A183-4(A-17A10-)A-17A185-4(16A13-)16A105-9B18-13B15-15B13-4(17B12-)17B13-15B15-13B18-9B10-
