model
size = 28 28 11, scale = 0.05, origin = -y
material deform = 1, fade = true, lighting = smooth, roughness = 0.3, metalness = 0.6
  colors = A:#49341A B:#E4C358 C:#696A6D D:#FFF
voxels
208-4A23-A4DA21-5AD2A20-3A3D2A20-5AD2A21-A4DA23-4A632-3(20C8-)20C149-7B4-7B9-5(9B2-9B8-)9B2-9B9-8B2-8B11-6B4-6B102-B2-B22-3B2-3B18-5B2-5B15-6B2-6B14-6B2-6B41-6B4-6B9-C-8B2-8B-C6-C2(2-7B)2-C6-C20-C6-C-7B4-7B-C7-9B2-9B8-9B2-9B9-8B2-8B37-9B2-9B7-6(10B2-10B6-)10B2-10B7-9B2-9B9-8B2-8B11-6B4-6B46-4B22-8B18-12B15-14B13-16B12-16B11-18B10-18B7-3(C-20B-C4-)C22BC5-2(22B6-)22B7-20B7-22B5-6(24B4-)24B5-22B6-22B7-9B2-9B10-6B4-6B46-4A23-6A20-10A17-12A15-14A14-14A13-16A8-C3-16A3-3(C4-C2-18A2-)C6-7(20A8-)20A7-2(22A6-)22A7-20A8-20A9-18A12-5A4-5A75-4A23-6A20-10A17-12A15-14A14-14A13-16A7-2C3-16A3-2(2C2-)2(18A2(2-2C)2-)18A2-2C5-7(20A8-)20A7-2(22A6-)22A7-20A8-20A9-18A12-5A4-5A76-2A22-A-6A-A18-10A17-12A15-14A14-14A13-16A7-C4-16A4-3(C2-C3-18A3-)C5-8(20A8-)20A7-22A7-2(20A8-)20A9-18A12-5A4-5A103-4A22-8A19-10A17-12A15-14A14-14A7-2C2(4-16A4-4C)3-18A3-4C3-18A3-2C5-18A9-10(20A8-)20A9-18A11-16A14-3A6-3A131-6A21-8A19-10A17-12A15-14A7-C6-14A6-3(2C5-16A5-)C6-16A12-16A11-9(18A10-)18A11-16A13-14A213-8A19-10A17-12A8-C3(6-14A6-2C)6-14A6-C7-2(14A14-)14A13-7(16A12-)16A13-14A15-12A300-4A23-6A21-8A19-4(10A18-)10A17-5(12A16-)12A17-10A19-8A150-
