model
size = 26 22 26, scale = 0.05, origin = -y
material deform = 1, fade = true, lighting = smooth, roughness = 0.3, metalness = 0.6
  colors = A:#0E0 B:#FC9 C:#FF9 D:#630 E:#111 F:#669 G:#F60 H:#600 I:#F93 J:#FF3 K:#F96 L:#EEE
voxels
146-L509-14(14D12-)14D193-12(16D10-)2(D14CD10-)D14CD11-14D167-10(16D10-)16D9-D16B3(D8-DC14AC)D9-D14CD11-14D115-16B9-11(18B8-)18B7-2(2(D2C14A2CD6-)2DC14AC2D8-D14CD11-D12CD13-12D66-12B12-16B9-18B7-11(B2C14AC2B6-))2(2(D2C14A2CD6-)2DC14AC2D8-D14CD11-D12CD13-2D8C2D16-8D18-8B16-12B12-16B9-18B7-11(B2C14AC2B6-))2(D2C14A2CD6-)2DC14AC2D8-D14CD11-D12CD13-2D8C2D16-8D18-8B16-12B12-16B9-18B7-4(B2C14AC2B6-)B2C14AC2B-J4-6(B2C14AC2B6-)2(D2C14A2CD6-)2DC14AC2D8-D14CD11-D12CD13-2D8C2D16-8D18-8B16-12B12-16B9-18B7-3(B2C14AC2B6-)B2C14AC2B-J-4B4(2C14AC9B)2C14AC5B3-2(B2C14AC2B6-)2(D2C14A2CD6-)2DC14AC2D8-D14CD11-D12CD13-2D8C2D16-8D18-8B16-12B12-16B9-18B7-3(B2C14AC2B6-)B2C14AC2B-J-4B2C14AC6BI2B2(2C14AC3B2(I2B))2C14AC3BI5B2C14AC5B3-2(B2C14AC2B6-)2(D2C14A2CD6-)2DC14AC2D8-D14CD11-D12CD13-2D8C2D16-8D18-8B16-12B12-16B9-18B7-4(B2C14AC2B6-)B2C14AC2B-J4-6(B2C14AC2B6-)2(2(D2C14A2CD6-)2DC14AC2D8-D14CD11-D12CD13-2D8C2D16-8D18-8B16-12B12-16B9-18B7-11(B2C14AC2B6-))2(D2C14A2CD6-)2DC14AC2D8-D14CD11-D12CD13-2D8C2D16-8D18-8B16-12B12-16B9-18B7-7(B2C14AC2B6-)B2C2(14AC2B5-EBEC)14AC2B6-B2C14AC2B2(6-D2C14A2CD)6-2DC14AC2D8-D14CD11-D12CD13-2D8C2D16-8D42-12B12-16B9-18B7-7(B2C14AC2B6-)B2C14AC2(2B5-EB2E14AE)2B6-B2C14AC2B2(6-D2C14A2CD)6-2DC14AC2D8-D14CD11-D12CD13-12D66-12B12-16B10-17B8(8-BC14ACB)2(7-EBE14AEB)8-BC14ACB7-2(DBC14ACBD6-)2DC14AC2D8-D14CD11-D12CD13-12D90-16B9(10-B14AB)9-EB14ABE8-EB14ABE9-4(B14AB10-)D14CD11-14D116-9(14B12-)14B11-E14BE10-E14BE11-4(14B12-)14D142-4(14B12-)14B43-4G22-4G17-D4E2(4G5E12-5E)4-5E2(12-14E)39-4H4-4H222-F10-2(F14-F10C)F14-12F44-4G22-3(4G17-5E)21-6E307-12F14-7F2-K-F2(14-12F)517-2(K571-)L451-
