model
size = 12 18 32, scale = 0.05, origin = -y
material deform = 1, fade = true, lighting = smooth, roughness = 0.3, metalness = 0.6
  colors = A:#005451 B:#FF3232 C:#FFF D:#919191
voxels
15-5C7-5B7-5A176-5C7-5B6(7-5A)8-3A9-3A10-A70-3B9-3B7-7C5-7B9(5-7A)6-4(5A7-)5B7-5A7-A3BA5-9C3-9B3(3-9A)2(3-3A4-2A)6(3-3A)2(4-2A3-3A)4-3(2A3-2A5-)BA3-AB2(5-2A3-2A)4-9C3-9B3(3-9A)9(3-2A5-2A)3-2A6-A3-BA5-AB2(3-2A5-2A)2-11C-11B3(-11A)3(-2A7-2A)3(2-A7-2A)2-4(A7-A3-)B7-B2(3-A7-A)2-11C-11B3(-11A)2(-2A8-A)2(-2A7-2A)3(2-A7-2A)2-3(A7-A3-)B7-B2(3-A7-A)2-11C-11B3(-11A)2(-2A8-A)3(-2A7-2A)2(2-A7-2A)2-2(A7-A3-)B7-B3(3-A7-A)2-11C-11B3(-11A)2(-2A8-A)3(-2A7-2A)2(2-A7-2A)2-A7-A3-B7-B4(3-A7-A)2-11C-11B3(-11A)2(-2A8-A)2(-2A7-2A)3(2-A7-2A)2-B7-B5(3-A7-A)2-11C-11B3(-11A)2(-2A8-A)-2A3(7-2A2-A)7-2A2-B7-AB2-6(A7-A3-)10C2-10B3(2-10A)5(2-2A5-3A)2-BA5-2AB2-2A5-3A2-6(2A5-2A3-)10C2-10B7(2-10A)2-B8AB2(2-10A)2-2(9A3-)8A5-7A5-7B5-7A4-3C2DC3DC2-10B6(2-10A)2-B8AB2(2-10A)2-9A3-9A4-7A5-7B5-7A28-2C2DC3D2C2-10B7(2-10A)2-9A3-9A4-8A4-7B5-7A52-2(2C2D)2C2-10B6(2-10A)2-9A3-9A4-8A4-7A76-2(2C2D)2C2-10B6(2-10A)3-2(8A4-)7B88-2(2C2D)2C2-10B5(2-10A)3-2(8A4-)7A100-2(2C2D)2C2-10B4(2-10A)2-9A4-8A4-7B111-3C2(2D2C)-11B2(-11A)2(2-10A)2-9A4-8A122-2C4DC3DC-11B3(-11A)2-9A3-9A5-5A124-11C-11B3(-11A)2-9A4-8A133-12C12B12A2(-11A)2-9A5-6A134-12C12B24A-10A3-9A5-5A135-12C12B24A-10A4-7A7-3A136-12C12B23A2-10A4-6A147-11C-11B2(-11A)2-9A6-5A147-11C-11B2(-11A)3-8A6-4A149-10C2-10B2(2-10A)3-8A159-9C3-9B2(3-9A)5-6A161-8C4-8B4-8A4-7A173-7C5-7B5-7A6-5A172-
