model
size = 25 32 21, scale = 0.05, origin = -y
material deform = 1, fade = true, lighting = smooth, roughness = 0.3, metalness = 0.6
  colors = A:#222 B:#963 C:#EEE D:#444 E:#888 F:#111 G:#777 H:#E00
voxels
166-H25-F25-3(H747-2(H25-))H773-F798-4(2D22-)2D23-D799-H49-11(G24-)G95-2(B-)B20-6F19-2(B-)B299-E23-13(3E22-)3E23-G69-BF5B18-F6BF17-3(B-)B323-H348-GEG23-D45-BF2BFB18-F6B3F16-3(B-)2B18-7A16-2A7-2A12-2A11-2A9-A15-A7-A17-A5-A19-A4-A19-A3-A21-A2-A21-A-A2(23-2A)11-F11-2A10-FHF10-2A11-F11-2(2A23-)A-A21-A2-A21-A3-A19-A4-A19-A5-A17-A7-A15-A9-2A11-2A12-2A7-2A16-7A45-GEG23-D24-H19-3B2FBF3B15-F7B3F14-4(B-)2B17-7A16-2A7D2A12-2A3DC2-C-3D2A9-A3D3(2-C)3DA7-A2D-4(C2-)2DA5-A2D3-C2-2(C-)C3-C2DA4-AD-2(C2-)2(C-)2(C2-)DA3-A2D2(2-C)-2C-C2-C3-2DA2-ADC3-C2-3(C-)C3-C-DA-A2D-2C2-2C3(-C)2-2C2-2D2AD4-3C3(-C)-2C5-D2AD5C2-C-3C-C2-5CD2AD5-2C-2CH2C-2C5-D2AD3-2C2-C-3C-C-2C4-D2AD-2C3-4(C-)C2-4CD2A2D4-5(C-)C4-2DA-AD2(2-2C)-2C2-C-2C2-DA2-A2DC3-4(C-)C3-C2DA3-AD3-C2-2(C-)C2-C3-DA4-A2D-C3-2(C-)C3-C-2DA5-A2D3-2(C2-)C3-2DA7-A3D-2(C2-)C-3DA9-2A3D2-C2-3D2A12-2A7D2A16-7A44-G3EG21-DED22-HEH19-2BF3B3FB14-F10BF14-4(B-)2B16-7A16-2A7-2A12-2A11-2A9-A15-A7-A17-A5-A19-A4-A19-A3-A21-A2-A21-A-A2(23-2A)11-F11-2A10-FHF10-2A11-F11-2(2A23-)A-A21-A2-A21-A3-A19-A4-A19-A5-A17-A7-A15-A9-2A11-2A12-2A7-2A16-7A45-GEG23-D24-H19-3B2FBF3B15-F9BF14-4(B-)2B320-H348-GEG23-D45-BF2BF3B16-F7B2F16-3(B-)2B296-E23-13(3E22-)3E23-G69-BF5B18-F5B2F17-3(B-)B323-H49-11(G24-)G95-2(B-)B20-6F19-2(B-)B324-D23-4(2D22-)2D798-F773-3(2(H25-)H747-)H25-F25-H341-
