model
size = 30 10 28, scale = 0.05, origin = -y
material deform = 1, fade = true, lighting = smooth, roughness = 0.3, metalness = 0.6
  colors = A:#52433D B:#6E552F C:#555
voxels
71-8B22-B6AB23-A4BA2(24-BA2BAB)23-B2A2B2AB22-B6AB24-4B114-8C22-8C202-8B22-8A19-3C8A3C16-3C8A3C19-8A22-8B140-3B6-3B18-3A6-3A16-2C3A6-3A2C14-2C3A6-3A2C16-3A6-3A18-2BA6-A2B136-3B10-3B14-3A10-3A12-2C3A10-3A2C10-2C3A10-3A2C12-3A10-3A14-2BA10-A2B133-2B14-2B12-2A14-2A10-2C2A14-2A2C8-2C2A14-2A2C10-2A14-2A12-BA14-AB131-2B16-2B10-2A16-2A9-C2A16-2AC8-C2A16-2AC9-2A16-2A10-BA16-AB129-B20-B8-A20-A7-CA20-AC6-CA20-AC7-A20-A8-B20-B128-B20-B8-A20-A6-2CA20-A2C4-2CA20-A2C6-A20-A8-B20-B127-2B20-2B6-2A20-2A5-C2A20-2AC4-C2A20-2AC5-2A20-2A6-2B20-2B126-B22-B6-A22-A5-CA22-AC4-CA22-AC5-A22-A6-B22-B125-2B22-2B4-2A22-2A3-C2A22-2AC2-C2A22-2AC3-2A22-2A4-2B22-2B2(124-B24-B4-A24-A3-CA24-AC2-CA24-AC3-A24-A4-B24-B)123-2B24-2B2-2A24-2A-ACA24-AC2ACA24-ACA-2A24-2A3-3(B24-B124-B24-B4-A24-A3-CA24-AC2-CA24-AC3-A24-A4-)B24-B125-B22-B6-A22-A5-CA22-AC4-CA22-AC5-A22-A6-B22-B126-2B20-2B6-2A20-2A5-C2A20-2AC4-C2A20-2AC5-2A20-2A6-2B20-2B127-B20-B8-A20-A6-2CA20-A2C4-2CA20-A2C6-A20-A8-B20-B128-B20-B8-A20-A7-CA20-AC6-CA20-AC7-A20-A8-B20-B128-B20-B8-A20-A2(8-C20-C)8-A20-A8-B20-B128-3B16-3B8-3A16-3A2(8-2CA16-A2C)9-2A16-2A10-2B16-2B160-A-B14-B-A2(10-2CA14-A2C)10-A-B14-B-A220-A-2C12-2C-A10-A-2C12-2C-A253-3C8-3C16-3C8-3C167-12A19-3(10A20-)2A6C2A2(20-10A)19-12A20-8A24-4A13-
