model
size = 16 30 15, scale = 0.05, origin = -y
material deform = 1, fade = true, lighting = smooth, roughness = 0.3, metalness = 0.6
  colors = A:#DDD B:#FFF C:#BBB D:#AAA E:#888 F:#111 G:#444 H:#222 I:#555 J:#777
voxels
264-A111-A270-C16-A14-2A14-A15-CD14-A-A12-B3A12-B2A14-BDA14-C32-A14-A15-2A14-BA13-C16-2(A15-)A62-A47-A14-A15-A2-A12-DA15-2A13-4A12-D3A13-2AC10-A-4A12-D3A12-4A11-5A11-6A11-5A12-3A12-CA-2A11-B3A13-3AB11-2C2A13-C3A10-CBCA13-B2AB12-BC2A13-AB14-AB13-D-A12-CAD13-C2A13-2(AD)12-2D-A11-4ADA11-3A13-2A2CA12-3AD10-2AD4A11-5A10-6A10-5A10-A-4AB10-C2(5A10-)6AD10-5A10-A-4AC10-2C5A10-C2(A-)A9-2C4AC10-C4AD8-A-C4AD8-7A11-3AC11-6A11-4A12-4A13-4A11-3A12-3AD12-4A12-C3A11-2C3ADA10-C4AD9-2C2ADA9-3C6AC8-D-3AC8-3A-2A12-D4A10-C5A11-6A9-7AC9-C5A9-DC6A2(8-8A)D7-8A8-5A2-A9-8A6-C8AC6-AB-6A8-C7A8-D7A10-7A-A6-5AB11-4AD9-AB4A13-3AC10-4A2(D11-2A2-)A10-3A2-DA9-3A2-A10-2(3A2-3A8-)3A2-2A8-A-CA2-3A7-4A2-ABD8-3A2-3A8-3A2-2AD7-4A2-A10-3A2-A-2A7-3A2-3AC8-2A2-3A8-A-A2-4A6-4A2-3A7-C3A2-3A8-3A2-4A8-2A2-3A8-3A2-4A6-4A2-3ABA8-A2-2A10-2A2-3AB9-A2-3A8-3A2-4A8-DA2-2A8-C3A2-ABC9-DC2-A11-6A10-A3-AD10-A4-2A8-2A4-A9-2A4-C10-A4-2A8-2A4-AC2(8-2A4-2A)C8-A4-A7-4A4-2A8-2A4-2AD6-3A4-2AD8-A4-3A7-BA4-3AD5-3A4-3AB5-3A4-4A5-3A4-3A5-4A4-2A6-4A4-2ADC5-3A4-4A6-2A4-4A-B3-3A4-3A6-3A4-3A5-2ABA4-3A6-2BA4-4A5-3A4-2AB6-3A4-3A6-3A4-2A9-A4-ABA8-6A10-A3-AD10-B4-C2(10-A4-A)9-BA4-ACA7-2A4-AB7-B2A4-A9-2A4-2A8-2A4-3A7-2A4-3A8-D4-2A9-D4-3A7-2A4-2A9-A4-3A7-BA2(4-2A7-3A4-2AD6-3A)4-AF7-3A4-2AEA5-2AC4-3A7-2A4-2A8-2A4-3A8-A4-2A9-A4-2AB6-3A4-2A7-3A4-2A8-2A4-AB7-3A4-2A10-3AB12-B2-B12-A2-2D11-C2-BC10-2A2(2-2A10-BA)2-2A10-2A2-2AC8-C2A2-2A9-3A2-3A8-C2A2-2AD9-EA2-2AC10-A2-3AB6-AB2A2-3A8-3A2-3AD7-A-A2-3AC6-4A2-3A7-CE2A2-2AC8-F2A2-A2E4-A-2A2FA2-AF7-5A2-2FIE6-2(A2-)4A7-A-A2-3AB4-B-4A2-3A7-4A2-2AB9-2A2-2A10-2A2-2ACA9-A2-2AB6-5A2-2A6-A-4A2-AB11-BAD13-DAD13-B2A2(13-BAD)AB11-B3AB10-B5A2(10-6A)C8-C6AC9-E5AI9-E6A7-AC5A11-6A9-8A7-C7A9-7AD9-DE3AD10-G3AE12-E2AG9-A2F2AF2-D7-C-2C2A2FAB7-6A-A7-C5A-A9-C6A10-4A10-7AC10-5AC9-A-5A9-6A29-3(A15-)A-A13-3A11-C5A11-C3A11-6AB8-B6A10-I5G10-6AB12-2A12-2CA-B9-C6A9-B-4AC9-C6A12-2AD12-G3AB12-GAE9-A3FAE13-C2A3HB7-A2-3A-2A6-A-4A-2CB8-3A13-5A9-2B3A-A10-AC3AB10-C5A10-2B2A2B110-A14-C2A12-5A10-6A26-6A13-A15-A12-AIHAHD11-B2ADB10-B3AD13-CAC12-3A14-2A10-A3HAD14-2A3DA7-A-4A2-A8-C4A11-C3AC11-C4A11-B2A-B12-3A12-B4A12-2A158-4B62-A13-AIAJA12-3A13-2AC13-2(2A14-)2A10-4B2A14-3A2BC7-B3-2A11-C-3A12-AE2A12-2EAC12-E2A13-3A13-B2A13-2A238-2(AJ)A12-3A13-2A15-A2(15-B)14-2B15-2B3(14-A)-BA14-B14-AC13-A2B14-A254-A3B13-2B2(15-B)79-A29-B89-
