model
size = 30 27 30, scale = 0.05, origin = -y
material deform = 1, fade = true, lighting = smooth, roughness = 0.3, metalness = 0.6
  colors = A:#C60 B:#EEE
voxels
41-8A772-8A799-14A794-18A791-20A789-7A8-7A15-4(8A22-)8A644-2(6A12-)3(2A8-2A18-)3(12A18-)12A581-6A14-6A10-3(A12-A16-)4A6-4A16-A3B6-3BA17-A2B6-2BA18-A10BA2(18-12B)521-5A16-5A9-6(A14-)3A10-3A14-2AB10-B2A15-AB10-BA16-A3B6-3BA2(16-14B)17-12B18-12B460-5A18-5A7-3(A16-A12-)2A14-2A12-2A14-2A13-2(A14-)A2B10-2BA14-5B6-5B14-2B3A6-3A2B15-B3A6-3AB16-B3A6-3AB17-12A18-12A400-4A20-4A6-3(A18-A10-)3A14-3A10-A2B14-2BA11-AB14-BA12-A2B12-2BA12-4B10-4B12-2B2A10-2A2B13-B2A10-2AB14-B2A10-2AB15-4A6-4A16-14A17-2(12A18-)12A310-4A20-4A6-3(A18-A10-)2A16-2A2(10-AB16-BA)10-A2B14-2BA11-2(3B12-)2BA12-A2B13-BA12-AB14-BA12-AB15-3A8-3A16-2A2B6-2B2A17-2(A2B6-2BA18-)A2B6-2BA19-10B20-10B250-4A22-4A4-3(A20-A8-)3A16-3A8-2AB16-B2A9-AB16-BA10-A2B14-2BA11-2(3B12-)2BA12-A2B13-BA12-AB14-BA12-AB15-2A10-2A16-2AB8-B2A17-2(AB8-BA18-)AB8-BA19-3B4-3B20-3B4-3B21-8B22-8B191-4A22-4A4-3(A20-A8-)2A18-2A8-2A18-2A9-A18-A10-AB16-BA11-2B14-2B12-2B14-2B13-3(B14-)B15-A12-A16-2A10-2A17-2(A10-A18-)A10-A19-2B6-2B20-2B6-2B21-BA4-AB22-BA4-AB23-6A24-6A132-4A22-4A4-3(A20-A8-)2A18-2A8-2A18-2A9-A18-A10-AB16-BA11-2B14-2B12-2B14-2B13-3(B14-)B15-A12-A16-2A10-2A17-2(A10-A18-)A10-A19-B8-B20-B8-B21-B6-B22-B6-B23-A4-A24-6A25-4A26-4A73-2(4A22-4A4-3(A20-A8-)2A18-2A8-2A18-2A9-A18-A10-AB16-BA11-2B14-2B12-2B14-2B13-3(B14-)B15-A12-A16-2A10-2A17-2(A10-A18-)A10-A19-B8-B20-B8-B21-B6-B22-B6-B23-A4-A24-2A2-2A25-A2BA26-A2BA27-2B28-2B14-)4A22-4A4-3(A20-A8-)2A18-2A8-2A18-2A9-A18-A10-AB16-BA11-2B14-2B12-2B14-2B13-3(B14-)B15-A12-A16-2A10-2A17-2(A10-A18-)A10-A19-B8-B20-B8-B21-B6-B22-B6-B23-A4-A24-6A25-4A26-4A73-4A22-4A4-3(A20-A8-)2A18-2A8-2A18-2A9-A18-A10-AB16-BA11-2B14-2B12-2B14-2B13-3(B14-)B15-A12-A16-2A10-2A17-2(A10-A18-)A10-A19-2B6-2B20-2B6-2B21-BA4-AB22-BA4-AB23-6A24-6A132-4A22-4A4-3(A20-A8-)3A16-3A8-2AB16-B2A9-AB16-BA10-A2B14-2BA11-2(3B12-)2BA12-A2B13-BA12-AB14-BA12-AB15-2A10-2A16-2AB8-B2A17-2(AB8-BA18-)AB8-BA19-3B4-3B20-3B4-3B21-8B22-8B192-4A20-4A6-3(A18-A10-)2A16-2A2(10-AB16-BA)10-A2B14-2BA11-2(3B12-)2BA12-A2B13-BA12-AB14-BA12-AB15-3A8-3A16-2A2B6-2B2A17-2(A2B6-2BA18-)A2B6-2BA19-10B20-10B251-4A20-4A6-3(A18-A10-)3A14-3A10-A2B14-2BA11-AB14-BA12-A2B12-2BA12-4B10-4B12-2B2A10-2A2B13-B2A10-2AB14-B2A10-2AB15-4A6-4A16-14A17-2(12A18-)12A310-5A18-5A7-3(A16-A12-)2A14-2A12-2A14-2A13-2(A14-)A2B10-2BA14-5B6-5B14-2B3A6-3A2B15-B3A6-3AB16-B3A6-3AB17-12A18-12A401-5A16-5A9-6(A14-)3A10-3A14-2AB10-B2A15-AB10-BA16-A3B6-3BA2(16-14B)17-12B18-12B461-6A14-6A10-3(A12-A16-)4A6-4A16-A3B6-3BA17-A2B6-2BA18-A10BA2(18-12B)522-2(6A12-)3(2A8-2A18-)3(12A18-)12A583-7A8-7A15-4(8A22-)8A646-20A791-18A794-14A788-
