model
size = 32 31 32, scale = 0.05, origin = -y
material deform = 1, fade = true, lighting = smooth, roughness = 0.3, metalness = 0.6
  colors = A:#005 B:#020 C:#09F D:#070 E:#050
voxels
30-2D925-3D29-3DCA990-23(2A31-CA958-A31-)2A31-CA2E29-2E925-A-2E28-2A2B28-2E2B30-2B893-2E29-E3B28-EBA2B28-2BAB30-2B860-E30-E3B29-BA2B28-B2A2(2B28-4B30-2B892-3B29-BA2B28-2BA)BD28-3BD30-2D892-3B29-BABD28-2BAD29-3D
