model
size = 30 19 12, scale = 0.05, origin = -y
material deform = 1, fade = true, lighting = smooth, roughness = 0.3, metalness = 0.6
  colors = A:#BBB B:#E83015 C:#FFF D:#FFFFFB E:#AAA F:#888 G:#444 H:#DDD I:#EEE
voxels
34-D6H10D4H2D7-D6H11D2H3D7-2D4H2D9-4D10-6D11-2D12-4D27-2D180-I2(29-G)144-D6H10D4H2D7-D6H11D2H3D7-2D4H2D9-4D10-6D11-2D12-4D27-2D180-I2(29-G)173-D6A2(2EA)2E9AD5-D9A12C2AD6-23B7-7B8F8B7-2F4B4F5H2F4B9-A2F2B2FA3F5H2F2B10-2A4F3AF-5H15-8A3-3H17-6A25-5A27-2A88-G29-G141-2D2A2E2A10E2A5E2AD2-2D2A22CAD3-2B23AB4-2BA22-B4-2FA20-3F4-ABA19-3F5-ABA9-F5-6F6-A2B5A-5A3-2AG10-A3B12AGA12-A4B8AG2A14-2A5B6A17-2A6B3AG18-3A4B3A20-3A2B5A21-4A-3AG22-2A2-3A109-D3AE2AE12AE5AE2A2D-A25CAD-B26AB2-BA25-B2-FA25-F2-BA24-2A2-BA21-4A3-BA18-3G7-BA15-B2G10-BA13-B2G12-BA11-B2G14-BA10-BG16-BA8-B2G18-A7-2(BAG27-)2(2B28-)B49-D2AEA2EA12E2AEAE2AEA2D28CDB6AB2A2(BA)2(3BA)BA3B2A2B28-BFA27-2FB26-3AB23-4A-AB20-2AG5-GB18-AG8-AB16-AG11-B14-AG13-B11-2AG15-B10-AG17-B10-A18-G8-BAG27-2(2B28-)B29-B19-DAEA4E5A2E6A5EAEA2D28C2D3A2(2BA)B3A2(2B2A)2(BA)B2A2(2B28-)2F28-2A24-4A-A21-2AG5-G19-AG8-A17-AG10-G15-AG12-A12-3A15-B10-AG17-B10-A18-G8-BAG18-G8-2(2B28-)B29-B19-DAEA4E5A2E6A5EAEA2D28C2D3A2BABA2BA2(B3A)2(BA)3B2A2(2B28-)2F28-2A24-4A-A21-2AG5-G19-AG8-A17-AG10-G15-AG12-A12-3A15-B10-AG17-B10-A18-G8-BAG18-G8-2(2B28-)B29-B19-D2AEA2EA12E2AEAE2AEA2D28CDB6AB2A2(BA)2(3BA)2(BA)B2A2B28-BFA27-2FA26-4A23-4A-2A20-2AG5-GA18-AG8-2A16-AG11-B14-AG13-B11-2AG15-B10-AG17-B10-A18-G8-BAG27-2(2B28-)B29-B19-D3AE2AE12AE5AE2A2D-A25CAD-B26AB2-BA25-B2-FA25-F2-BA24-2A2-BA21-4A3-BA18-3G7-BA15-B2G10-BA13-B2G12-BA11-B2G14-BA10-BG16-BA8-B2G18-A7-2(BAG27-)2(2B28-)B50-2D2A2E2A10E2A5E2AD2-2D2A22CAD3-2B23AB4-2BA22-B4-2FA21-2F4-ABA19-3F5-ABA9-F5-6F6-A2B5A-5A3-2AG10-A3B12AGA12-A4B8AG2A14-2A5B6A17-2A6B3AG18-3A4B3A20-3A2B5A21-4A-3AG22-2A2-3A112-D6A2(2EA)2E9AD5-D9A12C2AD6-23B7-7B9F7B7-2F4B4F5H2F5B8-A2F2B2FA3F5H2F2B10-2A4F3AF-5H15-8A3-3H17-6A25-5A27-2A88-G29-G140-
