model
size = 19 21 11, scale = 0.05, origin = -y
material deform = 1, fade = true, lighting = smooth, roughness = 0.3, metalness = 0.6
  colors = A:#FF0 B:#FF3 C:#111 D:#555 E:#222 F:#888
voxels
35-3C18-C214-2A9-3C4-3A17-A99-A-A3-C18-C64-3(A18-)A19-3(A18-)A35-3A9-C6-3A7-3C7-A6-3C84-4A2-A-A2-2C6-4A4-A9-5A4-A8-6A4-2(A7-8A3-)2(A7-9A2-)3(A8-8A2-)A7-D8A10-D2(8A11-)8A10-10A9-10A2C7-8A11-7A14-4A16-2A17-4A2-2A-A2C7-4A2-2A-A8-5A3-A-A7-6A3-2(A-A6-8A2-)A-A2(6-2B7A2(-A))7-B7A-3A7-8A-3A6-D8A-3A7-8A2-D8-8A2-D6-2D8A2-D8-8A2-D7-2(13A6-)8A11-7A14-4A16-2A17-4A2-2A-A9-4A3-A-A8-5A3-A-A7-6A3-A-A6-8A2-A-A6-2B6A2-A-A2(6-3B6A2(-A))7-2B6A-3A7-B7A-3A6-D8A-3A7-8A11-8A9-2D8A11-8A10-2(5A3B5A6-)5A3B11-7A14-4A16-2A18-3A2-2A11-4A4-A9-5A4-A8-6A4-A7-8A3-A7-2B6A3-2(A7-3B6A2-)A8-2B6A2-A8-B7A2(2-A8-8A)2(11-8A)11-4A3BA10-4A5BA9-4A5B2A8-4A4B11-5A2B14-4A16-2A24-2A12-A18-A14-2A-EA14-A2-AE14-B2-EA14-B2-AE15-B-EA-F5(14-A2-2A)13-2(A-)2A12-A2-A-2B11-A4-3B11-A5-B12-4A3B34-2A44-F109-C18-C269-F90-C18-E322-C2(18-E)18-C304-C18-E17-CE351-
