model
size = 18 32 14, scale = 0.05, origin = -y
material deform = 1, fade = true, lighting = smooth, roughness = 0.3, metalness = 0.6
  colors = A:#FF0 B:#CC3 C:#111 D:#222 E:#777 F:#888
voxels
288-3A12-21A-4A3B9A691-2C17-C17-D17-CDC17-2(C500-D74-)D17-C463-2C17-D92-D443-CD17-2C111-C17-C425-C102-C16-CD28-C278-3B12-7B9A5B-2B10A4B40-3(C17-)C101-CD16-2(C17-)C254-3B12-2BA3B12-7B9A5B-2B10A4B3-12A2B5-F2-6A9-C3-4A14-3BA14-4B2(15-3B)16-BA2(16-2A)17-3A3-C8-2A2-4A10-2A4-2A17-E4-13(2A12-2A2-)2A12-2A-3B12-3A3B12-2BA3B11E3BA-13A3B3-14A5-C-7A2-F8-7A2-3C6-2A3B2A4-CD5-A5BA5-C6-5BA4-2C6-5BA4-D7-A3B2A3-CD7-6A3-C8-6A3-CD7-6A3-2C7-6A13-4A15-2A9-3(AD12-DA2-CD12-DC2-)AD12-DA-CAD12-DAC2AD12-D2ACAD12-DAC2AD12-D5A12-6A12-3B2AE2(12-3B3A)12-6A12E3A-16A3-14A8-3(6A12-)3(A3B2A12-)3(4A2B12-)6A12-6A13-4A15-2A9-2(AD12-DA2-)2(CD12-DC2-AD12-DA2-)CD12-DC-2(2AD12-D2ACAD12-DAC)2(3A12-3B)2AE3(12-3B3A)12E3A-16A3-3A3B8A6-2A2B4A10-2A2B4A2(11-7A)12-6A12-4A2B3(12-3A3B)12-4A2B12-6A13-4A15-2A9-11(2A12-2A2-)2(2A12-2B2-)2A12-2B-2(3A12-3B)3A12E3A-4A3B9A3-2A5B7A8-2(3B3A12-)2B4A2(12-6A)12-4A2B3(12-3A3B)12-4A2B12-6A13-4A15-2A260-2(3A12-3B)18A-4A3B9A3-2A5B7A8-3B3A13-2B2A14-B3A14-4A15-3A15-2AB3(16-2B)17-3B12-2E2-F3A10-2E4-2A17-E3-
