model
size = 31 31 8, scale = 0.05, origin = -y
material deform = 1, fade = true, lighting = smooth, roughness = 0.3, metalness = 0.6
  colors = A:#EEE B:#C30 C:#888 D:#777 E:#222 F:#444 G:#0C6 H:#AAA I:#111 J:#FF6 K:#DDD L:#39C M:#F90 N:#96C
voxels
97-23E8-E21AE8-EA2-2A-A2(-2A)2-2A2(-A)E8-E3A-A3-2(2A-)3(A-)AE8-EA3-2(A-)2(2A-)A-A2-2AE8-EA-3A-A2(-2A)4(-A)E8-E2(2A2-)A3-2A2-A3-AE8-E21AE8-23E605-7A21-13A16-17A13-19A11-21A9-23A7-25A5-27A4-27A3-2(29A2-)29A-217A-2(29A2-)29A3-27A4-27A5-25A7-23A9-21A11-19A13-17A16-13A21-7A24-2A3I2A21-5A3I5A16-7A3I7A13-5A3B3I8A11-6A3B3I9A9-7A3B3I10A7-4A7B3I11A5-5A7B3I10B2A4-5A7B3I10B2A3-2(6A7B3I10B3A2-)6A7B3I10B3A-7A7B3A10B11A6BA3IA9B2(11A5BA5IA8B)4A12BA3IAIA25BA3IA27B3A14B-2(29B2-)29B3-27B4-27B5-25B7-23B9-21B11-19B13-17B16-13B21-7B24-2E3I2E21-3A2E3I2E3A16-5A2E3I2E5A13-6A2E3I2E6A11-7A2E3I2E7A9-8A2E3I2E8A7-9A2E3I2E9A5-10A2E3I2E10A4-10A2E3I2E10A3-2(11A2E3I2E11A2-)11A2E3I2E11A-12A2E3-2E24AE-3I-E2(24A-5I-)12AB-4B5AN-3IAI-N5A4B-B-5B4ANAN-3I-N6A3B2(-B)-4B5ANAN3-NAN5A4B2(-B)-4B5A3(NA)N5A4B-B3-5B6A2(NA)N6A3B-B3-B-5B15A5B-B3-B-5B13A5B-B5-B-5B11A5B-B7-B-6B7A6B-B9-B-17B-B11-B-15B-B13-2(B-)9B2(-B)15-7(B-)B17-6(B-)B21-3(B-)B24-2E3-2E21-D2F2E3-2E2FD16-C2D2F2E3-2E2F2DC13-2C2D2F2E3-2E2F2DC12-H2C2D2F2E3-2E2F2D2CH9-2H2C2D2F2E3-2E2F2D2C2H7-K2H2C2D2F2E3-2E2F2D2C2HK5-2K2H2C2D2F2E3-2E2F2D2C2H2K4-2K2H2C2D2F2E3-2E2F2D2C2H2K3-2(A2K2H2C2D2F2E3-2E2F2D2C2H2KA2-)A2K2H2C2D2F2E3-2E2F2D2C2H2KA-2A2K2H2C2D2F2E3-2E2F2D2C2H2K4A2K2H2C2D2FE5-E2(2F2D2C2H2K4A2K2H2C2D2F2-3I2-)2F2D2C2H2K2A2-M-2J2G2LN3-2IA3-N2L2G2J-M5-M2J2G2L-N7-2N2L2G2JM5-M-2J3G2L-N5-N-2L3G2J-M5-M-2J2G3L3(-N)-3L2G2J-M7-M2J3G3L2(-N)-3L3G2JM7-M-M2J3G9L3G2JM-M7-M-3J4G5L4G3J-M9-M-3J11G3J-M11-M-4J7G4J-M13-M-M11JM-M15-2(M-)7J2(-M)17-6(M-)M21-3(M-)M114-D2F7-2FD16-C2D2F7-2F2DC13-2C2D2F7-2F2DC12-H2C2D2F7-2F2D2CH9-2H2C2D2F7-2F2D2C2H7-K2H2C2D2F7-2F2D2C2HK5-8(2K2H2C2D2F7-2F2D2C2H2K4-)2K2H2C2D2F7-2F2D2C2H2K6-J-2GL13-L2G-J9-J2G-L11-L-2GJ9-J-3G-L9-L-3G-J9-J-2GL-L7-L-L2G-J11-J3GL-L5-L-L3GJ13-J3G4(L-)L3GJ13-J-J4G2(-L)-4GJ-J13-J-J11GJ-J15-2(J-)7G2(-J)19-4(J-)J23-3(J-)J176-D11-D16-C2D11-2DC13-2C2D11-2DC12-H2C2D11-2D2CH9-10(2H2C2D11-2D2C2H8-)2H2C2D11-2D2C2H10-G17-G13-G15-2(G13-G-)G13-2(G15-)G13-G17-G11-G19-G-G5-G-G21-4(G-)G23-3(G-)G297-2C15A2C12-2F2AFA2(F2A)2F2AFAF12-CAFA3F2(2AF)3(AF)12-3F2(AF)2(2AF)AFA2FC12-F3AFA2(F2A)3(FA)F12-C2F2(2A2FA3F)12-C17AC6(12-2C15-2C)471-
