model
size = 22 32 3, scale = 0.05, origin = -y
material deform = 1, fade = true, lighting = smooth, roughness = 0.3, metalness = 0.6
  colors = A:#222 B:#00D C:#888 D:#FF3 E:#EEE F:#777 G:#555 H:#E00 I:#111 J:#3CF K:#444 L:#06F M:#0A0
voxels
2-18A3-24(20A2-)12A5G3A2-12AG3IG3A2-12AGICIG3A2-12AG3IG3A2-12A5G3A2-20A3-18A4-18A3-3(A18CA2-)A18BA2-A5B3(EB)E6BA2-A6B3(EB)E5BA2-A18BA2-A2BEL10EKE2BA2-A2BLEL8E3K2BA2-A2BEL10EKE2B2(A2-A18B)A2-A2B4D4B2D3BD2B2(A2-A5BD3B3(D2B))A2-A5B2(DB)3(D2B)A2-A3B3D3B3(D2B)A2-A5B2(DB)2(3(D2B)2A-A5BD3B)D2BDB2D2B4A2B4D4B2D3BD2B4A2(18BA-2A)18B2A-A3(BJ)7B4HB2A-A3BJBJ6BH2B2HB2A-A5BJ7B4HB2A-A18BA2-A18CA2-A6C6A6CA3-18A4-18A3-2AF5A4F4A2F2A2-3AF3A6F3A2F2A2-20A25(2-A18-A)2-20A2-3AF3A6-5AMA3-18A2-
