model
size = 32 10 8, scale = 0.05, origin = -y
material deform = 1, fade = true, lighting = smooth, roughness = 0.3, metalness = 0.6
  colors = A:#222 B:#EEE C:#B00 D:#F60 E:#FF0 F:#888 G:#AAA H:#BBB I:#555 J:#111
voxels
8-H16-H13-H16-H359-A3(30-2A)30-A161-A28-A-CA28-AC2A28-4A28-2ACA28-AC-A28-A69-24A6-28A3-E28AC2-E4AI2AI12AI2AI5A-C30A2C30AC-E4AI2AI12AI2AI5A2-C28AC3-28A6-24A8-DCD2C15B3CD6-EDC4DC6BCB3C2BC5DE4-CEDE2D3C6BC2D3C3D4E3-2(CE)2D2C9BC4DEC6E2-3ED2C2(4BC)2B2C6D4E2-CEC3D3C8B2C2D3(CD)2CE2-4EDF2DF2C8B2CF2(D2E)2D3-DC2D4C6BC5B2(C2D)CD4-2CD2C5BC10BC2D2E2C6-C19B4C106-7(4F12-)4F109-H16-H110-3(2G14-)2G110-H16-H13-HJH14-HJH13-G16-F12(14-2G)14-G16-G13-HJH14-HJH6-
