model
size = 28 32 19, scale = 0.05, origin = -y
material deform = 1, fade = true, lighting = smooth, roughness = 0.3, metalness = 0.6
  colors = A:#F90 B:#EEE C:#111 D:#BBB
voxels
8-7(12A16-)3A6B3A16-2A2(2BC)2B2A16-A2(2B2C)2BA16-2B2C4B2C2B17-10B75-8B19-10B17-C4B2C4BC16-2C2B4C2B2C16-B2CB4CB2CB16-AB8CBA16-2AB6CB2A16-3A6B3A2(16-12A)16-A9-2A211-11(A12-A14-)2B10-2B15-2C8B2C17-10B17-CB2A4B2ABC15-BC10-C2(B14-B12-)B6(14-A12-A)14-14A15-2A6-4A16-A8-3A16-A10-A126-11(A14-A12-)A14-A13-B12-B14-BC10-CB13-AB12-B9(A12-A14-)A2(12-2A)13-2(A12-A14-)2A10-2A15-A10-A97-11(A16-A10-)A16-A11-2(A14-A12-)A14-A11-9(A16-A10-)2A14-2A11-2(A14-A12-)2A12-2A13-2A10-2A15-A10-A68-10(A18-A8-)A18-A9-A16-A10-A16-A11-A14-A11-A16-A10-A16-A9-8(A18-A8-)2(2A16-2A8-)2A16-2A9-2A14-2A11-2A12-2A13-2A10-2A15-A10-A40-11(A18-A8-)A18-A9-2(A16-A10-)A16-A9-A17-2A8(8-A18-A)5-2(4A18-4A2-)3A20-3A4-3A16-3A8-2A14-2A11-2A12-2A13-2A10-2A39-11(A18-A8-)A18-A9-A16-A10-A16-A9-2A16-2A8(8-A18-A)32-A25-3A25-4A24-2A-3A20-3A4-3A16-3A8-2A14-2A11-3A10-3A14-A10-A12-11(A18-A8-)A18-A9-A16-A10-A16-A9-2A16-2A7(8-A18-A)144-2A24-2A-3A20-3A4-3A16-3A8-3A12-3A11-2(3A10-)11(A18-A8-)A18-A9-A16-A10-A16-A9-2A16-2A7(8-A18-A)172-2A23-3A-3A20-3A4-3A16-3A8-4A10-4A9-11(A18-A8-)A18-A9-A16-A10-A16-A9-2A16-2A7(8-A18-A)172-2A23-3A-3A20-3A4-2A18-2A8-3A12-3A9-11(A18-A8-)A18-A9-A16-A10-A16-A9-2A16-2A7(8-A18-A)172-2A23-3A-3A20-3A4-3A16-3A8-4A10-4A9-11(A18-A8-)A18-A9-A16-A10-A16-A9-2A16-2A7(8-A18-A)144-2A24-2A-3A20-3A4-3A16-3A8-3A12-3A11-2(3A10-)11(A18-A8-)A18-A9-A16-A10-A16-A9-2A16-2A8(8-A18-A)32-2A2(24-4A)24-2A-3A20-3A4-3A16-3A8-2A14-2A11-3A10-3A14-A10-A12-11(A18-A8-)A18-A9-2(A16-A10-)A16-A9-A17-2A8(8-A18-A)5-2(4A18-4A2-)3A20-3A4-3A16-3A8-2A14-2A11-2A12-2A13-2A10-2A39-10(A18-A8-)A18-A9-A16-A10-A16-A11-A14-A11-A16-A10-A16-A9-8(A18-A8-)2(2A16-2A8-)2A16-2A9-2A14-2A11-2A12-2A13-2A10-2A15-A10-A41-11(A16-A10-)A16-A11-2(A14-A12-)A14-A11-9(A16-A10-)2A14-2A11-2(A14-A12-)2A12-2A13-2A10-2A15-A10-A70-11(A14-A12-)A14-A13-A12-A14-2A10-2A13-2(2A12-)9(A14-A12-)2A12-2A13-2(A12-A14-)2A10-2A15-A10-A99-11(A12-A14-)2A10-2A15-5A3BD3A17-4A3BD2A17-12A15-9(A12-A14-)3A8-3A15-2A8-2A2(16-A10-A)128-7(12A16-)4A2(BD)4A16-3A5BD3A2(16-4A2(BD2A))17-3ABDA2BDA74-3ABDA2BDA17-2(4A2(BD2A)16-)3A5BD3A16-4A2(BD)4A3(16-12A)16-5A2-5A16-4A4-4A16-3A6-3A204-
