model
size = 28 32 19, scale = 0.05, origin = -y
material deform = 1, fade = true, lighting = smooth, roughness = 0.3, metalness = 0.6
  colors = A:#F90 B:#555 C:#EEE D:#BBB
voxels
8-2(12A16-)5A2B5A2(16-7AB4A)16-5A2B5A16-12A16-2A2(B3A)BA16-2AB3A2B2ABA16-2(AB)2A3(BA)16-B3ABAB2A2BA17-10A75-8A19-3AB2AB3A17-5ABAB4A16-6A2B4A16-4A2BAB4A16-12A16-2A2(B3A)BA16-2AB3A2B2ABA16-2(AB)2A3(BA)16-B3ABAB2A2BA16-A9-2A211-11(A12-A14-)2A10-2A15-12A17-10A17-12A15-2A10-2A8(14-A12-A)14-14A15-2A6-4A16-A8-3A16-A10-A126-11(A14-A12-)A14-A13-A12-A14-2A10-2A13-2(2A12-)9(A14-A12-)2A12-2A13-2(A12-A14-)2A10-2A15-A10-A97-11(A16-A10-)A16-A11-2(A14-A12-)A14-A11-9(A16-A10-)2A14-2A11-2(A14-A12-)2A12-2A13-2A10-2A15-A10-A68-10(A18-A8-)A18-A9-A16-A10-A16-A11-A14-A11-A16-A10-A16-A9-8(A18-A8-)2(2A16-2A8-)2A16-2A9-2A14-2A11-2A12-2A13-2A10-2A15-A10-A40-11(A18-A8-)A18-A9-2(A16-A10-)A16-A9-A17-2A8(8-A18-A)5-2(4A18-4A2-)3A20-3A4-3A16-3A8-2A14-2A11-2A12-2A13-2A10-2A39-11(A18-A8-)A18-A9-A16-A10-A16-A9-2A16-2A8(8-A18-A)32-A25-3A25-4A24-2A-3A20-3A4-3A16-3A8-2A14-2A11-3A10-3A14-A10-A12-11(A18-A8-)A18-A9-A16-A10-A16-A9-2A16-2A7(8-A18-A)144-2A24-2A-3A20-3A4-3A16-3A8-3A12-3A11-2(3A10-)11(A18-A8-)A18-A9-A16-A10-A16-A9-2A16-2A7(8-A18-A)172-2A23-3A-3A20-3A4-3A16-3A8-4A10-4A9-11(A18-A8-)A18-A9-A16-A10-A16-A9-2A16-2A7(8-A18-A)172-2A23-3A-3A20-3A4-2A18-2A8-3A12-3A9-11(A18-A8-)A18-A9-A16-A10-A16-A9-2A16-2A7(8-A18-A)172-2A23-3A-3A20-3A4-3A16-3A8-4A10-4A9-11(A18-A8-)A18-A9-A16-A10-A16-A9-2A16-2A7(8-A18-A)144-2A24-2A-3A20-3A4-3A16-3A8-3A12-3A11-2(3A10-)11(A18-A8-)A18-A9-A16-A10-A16-A9-2A16-2A8(8-A18-A)32-2A2(24-4A)24-2A-3A20-3A4-3A16-3A8-2A14-2A11-3A10-3A14-A10-A12-11(A18-A8-)A18-A9-2(A16-A10-)A16-A9-A17-2A8(8-A18-A)5-2(4A18-4A2-)3A20-3A4-3A16-3A8-2A14-2A11-2A12-2A13-2A10-2A39-10(A18-A8-)A18-A9-A16-A10-A16-A11-A14-A11-A16-A10-A16-A9-8(A18-A8-)2(2A16-2A8-)2A16-2A9-2A14-2A11-2A12-2A13-2A10-2A15-A10-A41-11(A16-A10-)A16-A11-2(A14-A12-)A14-A11-9(A16-A10-)2A14-2A11-2(A14-A12-)2A12-2A13-2A10-2A15-A10-A70-11(A14-A12-)A14-A13-A12-A14-2A10-2A13-2(2A12-)9(A14-A12-)2A12-2A13-2(A12-A14-)2A10-2A15-A10-A99-11(A12-A14-)2A10-2A15-5A3CD3A17-4A3CD2A17-12A15-9(A12-A14-)3A8-3A15-2A8-2A2(16-A10-A)128-7(12A16-)4A2(CD)4A16-3A5CD3A2(16-4A2(CD2A))17-3ACDA2CDA74-3ACDA2CDA17-2(4A2(CD2A)16-)3A5CD3A16-4A2(CD)4A3(16-12A)16-5A2-5A16-4A4-4A16-3A6-3A204-
