model
size = 29 24 19, scale = 0.05, origin = -y
material deform = 1, fade = true, lighting = smooth, roughness = 0.3, metalness = 0.6
  colors = A:#693 B:#100 C:#363 D:#933 E:#963 F:#FFF G:#EEE H:#BBB I:#393 J:#360
voxels
154-10A17-6(14A15-)14A17-10A423-12A16-15A14-17A5(11-18A)2(12-17A)13-16A13-14A334-13A14-C16A11-7(20A9-)20A2(10-19A)11-18A12-16A13-14A246-14C14-17A10-3(21A8-)C20A2(8-21A)8-22A7-C21A7-22A2(8-21A)9-C18A10-19A11-17A13-16A15-12A159-15C13-CA15C10-C18A2C7-5AB7A6B3A7-4AB2A6B6D2AC7-6AB6D6E4A6-7AB6E5B4A6-8A5B10A3(6-23A)6-12A5B3A2BA7-C8A7C2(BA)CA7-7A2C3FBH2BFB2GBA8-7AC3F2BGBFB2GBA8-9AC2F2B2FBC2GA9-C5A2B2A4C2B2CA11-7A2B4AB2ACA12-8A4BC3A16-11A102-13B14-17C10-C3A16C8-6A2B13AC6-6AB7A6B3A6-5AB2A6B6D4A5-C6AB6D6E4A5-8AB6E5B4A5-C8A5B10A5-24A5-23AC6-23A6-C11A5B3A2BA6-10A7C2(BA)CA6-8A2C3FBH2BFB2GBA7-8AC3F2BGBFB2GBA7-C9AC2F2B2FBC2GA8-7A2B2A4C2B2C2A9-8A2B4AB2AC2A10-9A4BC4A12-2AC10AC2A18-7A75-B11AB14-2C13A3C9-AC18AC7-C5A2B13AC6-6AB7A6B3AC4-C5AB2A6B6D4A4-8AB6D6E3AC4-C8AB6E5B5A3-10A5B10AC4-C23A5-24A5-C23A5-13A5B3A2B2A5-C9A7C2(BA)C2A5-8A2C3FBH2BFB2GB2A5-C8AC3F2BGBFB2GBAC6-10AC2F2B2FBC2G2A7-C6A2B2A4C2B2C2A9-8A2B4AB2AC2A10-9A4BC3BAC10-18A13-3ACA2B3AC3A71-2B11A2B13-B15A2C9-2C18AC7-6A2B14A6-C5AB7A6B4A4-6AB2A6B6D3AC4-C7AB6D6E5A3-9AB6E5B4AC3-C9A5B11A3-25AC3-C24A5-25A4-C12A5B3A3BA4-11A7C2(BA)3C4-C8A2C3FBH2BFB2GBHA5-9AC3F2BGBFB2G2BA6-C9AC2F2B2FBC2GBA7-7A2B2A4C2B4CA8-C7A2B11A9-9A4B6A10-C18A11-2(AC)A3C2(BACA)C69-B13AB13-C15A2C9-2B18AC7-C5A2B14A6-C5AB7A6B3AC4-C5AB2A6B6D4AC3-8AB6D6E4AC3-C8AB6E5B4AC3-10A5B10AC3-C25A3-24AC5-C24A4-13A5B3A3BC4-C10A7C2(BA)2CA4-9A2C3FBH2BFB2GBH2A4-C8AC3F2BGBFB2G2B2A5-10AC2F2B2FBC2GBAC6-C6A2B2A4C2B4C2A7-8A2B10AC9-C8A4B7A9-18AC11-C6A2CBAB5AC12-2(AC)A2C5-2(CA)40-B13AB13-B15A2C9-2C18AB7-B5A2B14A6-C5AB7A6B4AB3-9C6B6D4A2C2-9C6D6E4ACB2-9CB6E5B4A2C2-9CA5B10AC3-9C16AC3-9C17A4-8C16AC4-8C5A5B3A3BA4-8C3A7C2(BA)2CAC3-8CA2C3FBH2BFB2GBH2A4-7C2AC3F2BGBFB2G2BAC5-6C4AC2F2B2FBC2GB2A6-B4C2A2B2A4C2B4CAC7-4C4A2B12A8-B2C6A4B6AC9-3C9AC7A10-BC7ACB6AC12-3CACA2C2-3(AC)A39-B13CB13-B16CB9-2BC17AC7-4C2A2B11A2IB6-B4CAB7A6B5C3-9C6B10DCB2-B8C6D10E2C2-9CB6E9BCB2-B8CA5B10A2C2-9C16AB3-B8C16AC4-8C16AB4-B7C5A5B3A3BAC3-8C3A7C2(BA)2C2A3-B7CA2C3FBH2BFB2GBH2AC3-7C2AC3F2BGBFB2G2B3A4-B5C4AC2F2B2FBC2GB2AC5-3B2C2A2B2A4C2B4C3A6-2B2C4A2B12A8-B2C6A4B5A3C8-B2C9AC5A2C10-2C7A2B6A2C11-B2C3A2C2-B6C15-3C6-4C11-2B11C2B13-2B13C2BC9-4B16AB7-B3C2A2B11A2IB6-5CAB7A6B2C3B3-B8C6B11DB2-9C6D10E2B2-B8CB6E11B2-9CA5B11AB2-B8C17AB2-B8C16AB4-B7C16AB4-8C5A5B3A5B3-B7C3A7C2(BA)2C2AC2-B7CA2C3FBH2BFB2GBH2AC3-B6C2AC3F2BGBFB2G2B2AC4-6C4AC2F2B2FBC2GB2AC5-3B2C2A2B2A4C2B4C2AC6-2B2C4A2B12AC7-B2C6A4B5A3C8-B2C9AC5ACB10-BC6AC2B6A2C11-CB5CB2-B5CB14-2(CB)C4-2(CB)C12-B11CB14-2B13C3B9-4B16AB7-4C2A2B11A2IB6-B4CAB7A6B2C3B3-B5AB2A6B11DB2-B7AB6D10E3B-B8AB6E12B-B9A5B11A2B-B25AB2-B24AB4-B23AB4-B12A5B3A5B3-2B9A7C2(BA)3CAB2-2B7A2C3FBH2BFB2GBHBA2C2-2B7AC3F2BGBFB2G2BGA2C3-B9AC2F2B2FBC2G2BA2C4-3B4A2B2A4C2B5CAB6-2B6A2B12AC7-B8A4B5A2CB8-B11AC5A3C9-B7A2C7ACB11-B6C4B6C14-2(BC)B4-2(BC)B12-13B14-2B13A3B9-2B17A2B7-B5A2B11A2IB6-B5AB7A6B2C3B4-C4AB2A6B11D4-C6AB6D10EB4-C7AB6E10BE3-C8A5B11AB3-C25A3-C23A2B4-C22AB5-C11A5B3A5B4-2C8A7C2(BA)3CAB4-C6A2C3FBH2BFB2GBHBACB4-C6AC3F2BGBFB2G2BGACB4-C8AC2F2B2FBC2G2BACB5-CB4A2B2A4C2B5CAC7-B6A2B4AB2A2C2BAB7-B8A4BC4B2AB9-4B7AC7AB10-3B6AC7AB12-2B4A4B5AB14-5B4-5B41-13C14-2C13ACB10-3C2A2B10A2C2B7-2C3AB7A6B2C3B5-C3AB2A6B11D5-C5AB6D10EB4-C7AB6E10BE3-C8A5B11AB3-C25A3-C24A5-C23AB4-2C10A5B3A3BA2B3-2C8A7C2(BA)3CAB4-C6A2C3FBH2BFB2GBHB2CB5-CB4AC3F2BGBFB2G2BG2CB5-CB6AC2F2B2FBC2G2B2CB6-C4A2B2A4C2B5CAB7-B6A2B4AB2A2C2BAB8-2C6A4BC4B2AB10-2C8AC6AB12-C7A2C5AB14-C5A3-4AB99-15C13-C15A2B9-2CAB7A6B3C2B6-C2AB2A6B11D6-C4AB6D9E2B5-C6AB6E10BE4-C7A5B10A2B4-C24A4-C23A6-C21AB6-2C9A5B3A3B2A6-2C6A7C2(BA)3CJC5-2C4A2C3FBH2BFB2GBH2BG6-B5AC3F2BGBFB2G2BGBG6-B7AC2F2B2FBC2G2B2G7-BC3A2B2A4C2B6C9-C5A2B4AB2A2C2BA9-2C6A4BC4B2A12-C8A2C5A14-7A2-5A156-A2B14AB9-CA2B7A6B2CAB8-CABA7C11D7-4AB6D10B7-6AB6E9BE6-7A6E10B2(6-23A)6-12A3B5A3B6-11A5B3A4BA6-8A7CBAB4CJC5-6A2C3FBH2BFB2GBH2BG7-5AC3F2BGBFB2G2BGBG7-7AC2F2B2FBC2G2B2G9-3A2B2A4C2B6C10-5A2B4AB2C2A2BA10-C6A4BC4BA13-C6A3-C4A193-9A14-7A10B11-2A6B11D10-AB6D-9B11-2A6B11E11-2A6E10B13-A5B10A16-12A22-5A18-6A2(-3A)13-2A7CBAB6C10-A2C3G4BGB2G4BG10-2AC3G4BGB2G4BG12-2AC2G2B2GBC2G2B2G12-2B2A4C2B6C15-2B4AB2C2A2B18-4B-4B281-10D48-10E20-9B20-9A21-7A23-5A49-5C3-5C16-GBG2B3-GBG2B16-G2BGB3-G2BGB16-2G2BG3-2G2BG17-4C3-5C176-
