model
size = 16 30 32, scale = 0.05, origin = -y
material deform = 1, fade = true, lighting = smooth, roughness = 0.3, metalness = 0.6
  colors = A:#FFF B:#D1E1F0 C:#888 D:#C1C1C1 E:#555
voxels
21-2(5B11-)5B28-3A12-2(5A11-)5A12-3A332-2(5B11-)5B3(27-5A10-7A8-9A7-9A8-7A10-5A)27-5A2(11-2AD2A)11-2(AD)A11-5A9-9B2(7-2B5A2B)9-5E3(9-9A6-3(11A5-)11A6-9A9-5C)9-4(9A7-)9D6-11B5-B2A5B2AB5-B9AB6-2E5A2E6-11A5-11A4-13A3-13A4-11A5-11A6-2C5A2C6-11A5-11A4-13A3-13A4-11A5-11A7-C5A2C6-11A5-11A4-13A3-13A4-11A5-11A6-2C5A2C6-4(11A5-)11D5-11B5-BA7BAB5-B9AB6-E7AE6-11A2(4-4A5-4A2-5A5-5A-5A5-5A2-4A5-4A4-3A5-3A6-CA5-AC6-3A5-3A)4-4A5-4A2-5A5-5A-5A5-5A2-4A5-4A4-3A5-3A6-CA5-2AC8(5-3A)2(5-3D)4-5(13B3-BA9BAB3-B11AB4-E9AE4-13A3(2-4A7-4A-4A2(7-9A)7-4A2-3A7-3A4-CA7-AC4-3A7-3A)3(3-3A7-3A)3-3D7-3D3-)13B3-BA9BAB3-B11AB4-E9AE4-13A2-4A7-4A-4A2(7-9A)7-4A2-3A7-3A4-CA7-AC4-3A7-3A2-4A6-5A-5A2(5-11A)5-5A2-4A5-4A4-C2A5-2AC4-4A5-4A2-5A5-5A-5A2(5-11A)5-5A2-4A5-4A4-C2A5-2AC4-4(4A5-4A3-)4D5-4D4-11B5-BA7BAB5-B9AB6-E7AE6-11A4-3A7-3A2-4A7-4A-4A7-4A2-3A7-3A4-2A7-2A6-C7-C6-2A7-2A2(4-4A5-4A2-5A5-5A-5A5-5A2-4A5-4A4-3A5-3A6-CA5-AC6-3A5-3A)6(5-3A)2(5-3D)5-11B5-BA7BAB5-B9AB6-E7AE6-11A4-3A7-3A2-4A7-4A-4A7-4A2-3A7-3A4-2A7-2A6-C7-C6-2A7-2A2(4-13A2-15A-15A2-13A4-11A6-C7AC6-11A)3(5-11A)5-11D5-11B5-BA7BAB5-B9AB6-E7AE7-10A5-2A7-3A4-2(2A7-4A3-)2A7-3A5-A7-2A2(7-C6AC7-10A5-12A2(3-13A)4-12A5-10A)7-C6AC4(7-9A)7-9D6-11B5-BA7BAB5-B9AB6-E7AE7-10A5-2A7-3A4-2A7-3A3-3A7-3A4-2A7-3A5-A7-2A7-C6AC7-5(10A6-)10A7-8C7-4(10A6-)9A7-9A8-7C9-7A2(9-3AD3A)9-2ADAD2A9-D5AD7-10B6-BA6BAB6-B8AB7-E6AE8-9A6-11A5-11A4-12A5-11A6-9A8-7A9-C5AC9-8A7-10A6-10A7-8A8-8A40-8A7-10A6-10A7-8A8-8A102-10B6-BA6BAB6-B8AB7-E6AE8-9A6-11A5-11A4-13A4-11A6-9A8-7A10-5A10-2(7A9-)7A10-5A75-6A10-6A11-4A120-10B6-BA6BAB6-B8AB7-E6AE8-9A6-11A5-11A4-13A4-11A6-9A8-7A10-5A12-2C282-10B6-BA6BAB6-B8AB7-E6AE8-2(9A6-11A4-13A3-13A4-11A6-9A8-7A10-5A12-3A281-11B5-BA7BAB5-B9AB6-E7AE7-)10A5-11A4-13A3-13A4-11A6-9A7-8A10-5A12-3A280-13B3-BA9BAB3-B11AB4-E9AE5-11A4-2(13A3-)13A4-11A6-9A7-8A9-6A12-3A280-13B3-BA9BAB3-B11AB4-E9AE4-4(13A3-)12A5-11A6-9A8-6A11-4A279-15B-BA11BAB-B13AB2-E11AE3-13A2-2(15A-)15A2-13A3-12A6-9A8-7A10-4A279-15B-BA11BAB-B13AB2-E11AE2-4(15A-)15A2-13A4-11A7-7A10-4A279-15B-BA11BAB-B13AB2-E11AE2-4(15A-)15A2-13A4-11A6-9A9-4A279-15B-BA11BAB-B13AB2-E11AE2-4(15A-)15A2-13A4-11A6-8A10-4A279-15B-BA11BAB-B13AB2-E11AE3-13A2-2(15A-)15A2-13A3-12A5-10A8-6A11-3A281-13B3-BA9BAB3-B11AB4-E9AE4-4(13A3-)12A5-10A7-8A9-5A296-13B3-BA9BAB3-B11AB4-E9AE5-11A4-2(13A3-)12A5-10A7-8A8-7A12-2A298-11B5-B2A5B2AB5-B9AB6-2E5A2E7-9A6-2(11A5-)10A7-8A9-7A10-4A314-9B2(7-2B5A2B)9-5E10-7A8-2(9A7-)8A9-7A10-5A326-
