model
size = 16 23 32, scale = 0.05, origin = -y
material deform = 1, fade = true, lighting = smooth, roughness = 0.3, metalness = 0.6
  colors = A:#442240 B:#99C C:#999 D:#99F E:#222 F:#888 G:#90F H:#969 I:#F0F
voxels
198-4B11-B4E2(B10-BE2-E)B10-B4EB11-4B43-C4DC42-6E10-6A12-2C14-2C316-E4AE10-AE2AEA12-3(2C14-)2C124-DA2-AD10-D4-D43-A2CA13-2A76-E4AE10-6A11-2(4B12-)4B13-3(2C14-)2C46-2B13-4B11-DA2-AD9-2A4-2A27-2B108-E4AE10-6A2(10-D4BD)11-4(4B12-)4B13-2C30-2B13-4B11-DA2DAD9-2A4D2A11-2C14-2C108-E4AE10-6A4(10-D4BD)11-3(4B12-)4B13-2C14-2B13-4B11-D4AD9-8A10-4C12-4C13-2C92-E4AE10-6A7(10-D4BD)11-4B12-4B13-2B12-2(6A10-)6A11-2(D2CD12-)4C91-E4AE10-6A11-5(4B12-)4B11-D4BD11-4B12-4B11-6A10-6A11-I2AI11-6A10-6A11-D2AD12-4C13-2D76-E4AE10-AE2AEA12-4(2C14-)2C13-3(4B12-)4B11-6A11-2(I2AI12-)I2AI11-6A11-D2AD12-4C12-D2CD13-2H60-E4AE10-6A76-4(2C14-)2C12-6A10-6A11-I2AI11-6A10-6A11-D2AD12-4C12-D2CD13-2H61-4E157-2E14-2E12-3(6A10-)B4AB10-D4AD11-4C12-D2CD13-2H222-2A14-2E13-D2AD11-D-2A-D9-A6-A3(8-8A)9-B4AB9-A2B2A2BA203-2A2(14-2E)13-D2AD11-D4AD9-A6-A10-I2AI12-I2AI10-8A9-B4AB10-2B2A2B188-2(2A14-)2A29-D2AD11-D4AD9-A6-A3(8-8A)9-B4AB9-A2B2A2BA187-2A61-D2AD11-D4AD9-A6-A10-I2AI12-I2AI10-8A9-B4AB10-2B2A2B12-2A222-2B13-D2AD10-C6AC7-DA6-AD7-2(8A8-)8A9-B4AB9-A2B2A2BA11-2A222-2B12-BD2ADB9-C6AC7-D8AD5-2(B10AB4-)3B6A3B5-B-B4AB-B8-CB2ABC12-2A222-2B12-BD2ADB9-C6AC7-D8AD5-B-8A-B3-CB-8A-BC3-B-B6AB-B5-B-B4AB-B8-CB2ABC12-2A201-3A6-3A3-3AEA-2B-AE3A-3A2EAD2BDA2E3A-14A3-12A4-B-8A-B3-C2-8A2-C3-B-B6AB-B5-B-B4AB-B8-CB2ABC12-2A202-G8-G5-GAG2-2B2-GAG3-G3AGD2BDG3AG3-G10AG5-G8AG5-B-8A-B3-C2-8A2-C3-B-B6AB-B5-B-B4AB-B8-CB2ABC12-2A14-2A186-H8-H5-3H2-2B2-3H3-2(HA)HD2BD2(HA)H3-2H8A2H5-H8AH5-B-8A-B3-C2-8A2-C3-B-B6AB-B5-B-B4AB-B8-CF2AFC12-2A14-2A186-G8-G5-GAG2-2B2-GAG3-G3AGD2BDG3AG3-G10AG5-G8AG5-B-8A-B3-C2-8A2-C3-B-B6AB-B5-B-BA2-AB-B8-CF2-FC12-2A14-2A185-3A6-3A3-2AEA2-2B2-AE2A-2A2E2AD2BD2A2E2A-14A3-12A4-B-8A-B3-C2-8A2-C3-B-B6AB-B5-B-BA2-AB-B8-CF2-FC12-2A14-2A204-D4BD10-D4AD9-D6AD7-D8AD5-B-8A-B3-C2-8A2-C3-B-B6AB-B5-B-BA2-AB-B8-CF2-FC12-2(2A14-)2A188-6D9-DB4ABD8-D6AD7-D8AD5-B-8A-B3-C2-8A2-C3-B-B6AB-B5-B-BA2-AB-B8-CA2-AC11-C2AC13-2A14-2A203-DBF2CFBD7-DC6ACD6-D8AD5-B-8A-B3-C2-8A2-C3-B-B6AB-B5-B-BA2-AB-B8-CA2-AC11-C2BC13-2A14-2A205-F2CF9-DBE4AEBD5-2D8A2D4-B-8A-B3-C2-8A2-C3-B-B6AB-B5-B-BA2-AB-B8-CA2-AC11-C2BC13-2A14-2A205-F2CF12-A2-A8-DB2E4A2EBD3-C12A2(C2-)8A2-C3-B-B6AB-B5-B-BA2-AB-B8-CA2-AC11-C2BC13-2A14-2A205-F2CF12-4A12-F2AF7-C4E4A4EC3-B10AB4-3B6A3B5-B-BA2-AB-B8-CA2-AC11-C2BC13-2A14-2A205-F2CF12-A2EA12-F2EF12-4A8-D2EI4EI2ED5-D8AD7-DBA2-ABD9-CA2-AC11-C2BC13-2A14-2A205-F2CF12-A2-A12-F2-F12-4A25-D8ED7-D6AD9-CA2-AC11-C2BC13-2A14-2A205-F2CF12-A2-A12-F2-F12-4A42-D6ED9-C4AC11-C2BC13-2A14-2A7-
