model
size = 28 32 18, scale = 0.05, origin = -y
material deform = 1, fade = true, lighting = smooth, roughness = 0.3, metalness = 0.6
  colors = A:#AAA B:#111 C:#EEE D:#222 E:#FC9 F:#FF0 G:#888 H:#BBB I:#777 J:#C96 K:#DDD
voxels
7-6A21-2(6A22-)4(6B22-)4B2F22-2B3FB2(22-2B2F2B)22-B2FBFB22-3F2BF22-2FBF2B22-2F2(2BFB22-2(2BF)22-2(F2B)22-BF)2B2F22-2BFB2F22-5FB3(22-6B)2(22-6D)3(22-6C)3(22-6A)23(22-6B)2(22-6D)3(22-6C)2(22-6A)20-3A5D2A18-10A20(18-2B6A2B)3(18-2B6C2B)2(18-2D6C2D)3(18-10C)18-2A4-K-2A18-2A6-2A16-3A8D3A14-14A3(14-2B10A2B)17(14-3B9A2B)14-3B9C2(2B14-2B10C)2B2(14-2D10C2D)3(14-14C)14-2A3-C-2K3-2A14-2A10-2A14-2A11DA14-14A3(14-B12AB)17(14-3B10AB)14-3B8AC3(AB14-B11C)AD14-D11CAD14-12CAK2(14-12CAC)14-A2-C2-K2C2-C2A14-A11-2A13-2A12D2A12-16A3(12-B4A6B3A2B)17(12-4BA6B3A2B)12-4BA2B2C2BACA2(2B12-B13C)2B2(12-D13CBD)12-A13CBK2(12-14CBC)12-A2-C3-C2-C3-2A12-A13-2A12-A14DA12-16A3(12-B2A2B6A2BA2B)12-5B6A2BA2B12-5B6E15(2BA2B12-5B6A)2BA2B12-5B4A4CA2B2(12-B14CB)2(12-D14CD)12-15CK12-16C12-3C3H4C3H3C12-A2-3I4-K2I2-A12-A14-A11-2A14D2A10-18A3(10-BA2B10A4B)10-5B9A4B10-4B10E4B10-5B7A6B14(10-5B9A4B)10-5B8A2C3B2(10-B15C2B)2(10-D15CBD)2(10-16CBC)10-4CHC2H2C2HCH2CBC10-A2-CI-2IC-2I-IC-2A10-A15-2A10-2A14D2A10-18A10-BAB12A2B11-BAB12A2B2A9-BAB12A2BAG2A7-5B10A2B2AGA7-4B8E3A2B3A3G5-5B7A6B5G5-5B9A4B3-3GA3-5B9A4B3-2GAG3-5B9A4B5-2(GA)-5B9A4B6-AG2A5B9A4B7-AGA5B9A4B7-2AG5B9A4B7-A2G4(5B9A4B7-AGA)5B9A4B7-GAG5B9A4B6-A2GA5B9A4B5-AG2A-5B8ACB2CB3-3AG3-B16CB3-2AGA3-B16C3B3A5-D16C3A3G5-D16CA3G7-17C2A2G7-17CAG9-4C2HCH2CHC2H4C10-A-2C2I-I2-I-2I2-CA10-A16-A10-2A14D2A10-18A10-2B13A2B11-2B13A2B2A9-2B13A2B4A7-5B10A2B4AI6-4B8E3A2B3A2EG5-5B7A6B2G2AG5-2(5B9A4B3-4A3-)5B9A4B5-G3A-5B9A4B6-4A5B9A4B7-3A5B9A4B8-2A5B9A4B7-3A2(5B9A4B7-2AG)5B9A4B7-3A5B9A4B8-AG5B9A4B7-3A5B9A4B6-4A5B9A4B5-4A-5B9AC3B3-4A3-B16CB3-4A3-B16C3B3A5-D16C3AE2G5-D16C4A7-17C2A2G7-17CAG9-5C2(2HC)2H5C10-A-C2-2IC2I-2I4-A10-A16-A10-2A14D2A10-18A10-2B13A2B11-2B13A2B2A9-2B13A2B4A7-2B13A2B4AI6-2B2A8E3A2B3A2EG5-2B10A6B2G2AG5-2(2B12A4B3-4A3-)2B12A4B5-4A-2B12A4B6-4A2B12A4B7-3A2B12A4B8-2A3(2B12A4B7-3A)2B12A4B7-2AG2B12A4B8-AG2B12A4B7-3A2B12A4B6-4A2B12A4B5-4A-2B12AC3B3-4A3-B15C2B3-4A3-B15C4B3A5-D15CB3AE2G5-D15C2(B3AG7-16C)BAG9-7C4H5CBC10-A-C2-2CIC2I5-2A10-A15-2A10-2A14D2A10-18A2(10-B13AB2AB)A9-2(B13AB2AB3A7-)B5A6E2(2AB)2A3G5-B11A6B3GAG5-2(B13AB2AB3-4A3-)B13AB2AB5-4A-B13AB2AB6-4A8(B13AB2AB7-3A)B13AB2AB6-4AB13AB2AB5-4A-B13AC2AB3-4A3-B15CAB3-4A3-B15C4B3A5-D15CAB2A3G5-D15CAB3A7-16CAB2AG7-16CABG9-5C2(2HC)2H3CAC10-A-C2-3(2I-)C-2A10-A15-2A10-2A14D2A10-18A4(10-B13AB2AB)10-B5A6E2(2AB)10-B11A6B14(10-B13AB2AB)10-B13AC2AB10-B15CAB10-B15C2B2(10-D15CAD)2(10-16CAC)10-4C2HCH2CHC2H2CAC10-A3-2I-I2-I-2I2-2A10-A15-2A11-2A12D2A12-16A4(12-B13A2B)12-B2A8E3A2B12-B10A5B14(12-B12A3B)12-B12AC2B2(12-B14CB)2(12-D14CD)2(12-16C)12-3CHC3HC2HCH3C12-A-CI-3I-2I-I2-A12-A14-A12-2A12D2A12-16A4(12-B13A2B)12-B2A8E3A2B12-B10A5B15(12-B12A3B)2(12-B13C2B)2(12-D13CBD)2(12-14CBC)12-3C3HC2HC3HCBC12-A-C3I-2I-3I-2A12-A13-2A13-A10D3A14-14A4(14-B12AB)14-BA8E3AB14-B9A4B15(14-B11A2B)2(14-B11C2B)2(14-D11CAD)2(14-12CAC)14-7CH4CAC14-A4-C-I-C2-2A14-A11-2A14-2AG6D5A14-14A4(14-2B10A2B)14-2B10E2B14-2B8A4B6(14-2B10A2B)2(14-2B2J8A2B)14-BF2J8AFB14-2F2J8AFB14-FB2(10AFB14-2F)2(10AFB14-2B)10A2(2B14-2BA9C)2B14-2DE9C2D14-2DA9C2D2(14-2CA11C)14-2CA4CH6C14-3A4-I4-2A14-3A9-2A16-2(10A18-)4(2B6A2B18-)2B6E2B6(18-2B6AFB)2(18-BF6ABF)18-2F6A2F18-FB6ABF18-BF6A2B18-2B6AFB18-2B2(6A2F18-2F)2(6A2B18-2B)A5C2B18-2BA5C2B18-2DE5C2D18-2DA5C2D2(18-2CA7C)18-2CA2CH4C18-3A2-I2-2A18-3A5-2A14-
