model
size = 3 31 3, scale = 0.05, origin = -y
material deform = 1, fade = true, lighting = smooth, roughness = 0.3, metalness = 0.6
  colors = A:#111 B:#AAA C:#09F
voxels
82-B-3B-C5-B25(2-A)2-B-4BCB3C-C83-B-3B-C4-
