model
size = 30 23 9, scale = 0.05, origin = -y
material deform = 1, fade = true, lighting = smooth, roughness = 0.3, metalness = 0.6
  colors = A:#F90 B:#FF3 C:#111 D:#777 E:#EEE F:#AAA G:#555 H:#690
voxels
245-16A2(EA)9-16A5EA9-14A2E2AE3A19-2(3AE)3A20-3A4E4A20-A2(E3A)22-2E2AE3A20-CDA5E2A22-2AEAE2A24-5A3(26-4A)27-2A131-2F11-3F16-F12-F14-2F13-2F10-17CF5C8-22A7-24A2(6-25A)6-24A18-13A18-11A19-10A19-2D2(9A21-)8A21-CD3(7A23-)7A24-5D67-3(CD4-D)C9-2(6D-)6D12-3D10-D-2D13-3D12-3D8-16C3D6C5-17A3D5A5-26A4-27A4-26A5-26A6-24A16-14A16-13A17-D12A18-11A20-10A19-D3A5-2A20-3A2(5-2A21-2A)5-2A22-D5-D4(6-B)7-3(3B4-)3B3-H-4(5B2-)H2-3(3B4-)3B3-H3-3(B6-)B3-2C28-2C-C19-7C3-A2C24A3-28A2-2(28A3-)27A5-3A3(GA)G15A15-15A16-G13A15-D14A16-G13A17-11ADA16-D3A7-ADA17-G2A7-ADA18-2A7-AD19-2A7-AD20-D7-D4(4-3B)5-4(5B2-)H-2(3(5B2-)5B-3H)-3(3B4-)3B2-3C27-4C19-7C3-27A3-28A2-29A2-28A3-27A5-3A3(GA)G15A15-15A16-G13A15-D14A16-G13A17-11ADA16-D3A7-ADA17-G2(2A7-ADA18-)2A7-ADA19-D7-DA4-3(B6-)B7-3(3B4-)3B3-H-4(5B2-)H2-3(3B4-)3B3-H3-3(B6-)B3-2C28-2C-C19-7C3-A2C24A3-28A2-2(28A3-)27A5-3A3(GA)G15A15-15A16-G13A15-D14A16-G13A17-11ADA16-D3A7-ADA17-G2A7-ADA18-2A7-AD19-2A7-AD20-D7-D65-3(CD4-D)C9-2(6D-)6D12-3D10-4D13-D-D12-3D8-16C3D6C5-17A3D5A5-26A4-27A4-26A5-26A6-24A16-14A16-13A17-D12A18-11A20-10A19-D3A5-2A20-3A2(5-2A21-2A)5-2A22-D5-D99-2F11-3F16-F12-F14-2F13-2F10-17CF5C8-22A7-24A2(6-25A)6-24A18-13A18-11A19-10A19-2D2(9A21-)8A21-CD3(7A23-)7A24-5D250-2AB3AB9A2(EA)9-4A2(BA)B7A5EA9-4AB3AB7AE2A2EA19-5AE3AEA20-4A4E3A20-2(3AE)A22-2AE2A2EA20-CDA5E2A22-2AEAE2A24-5A3(26-4A)27-2A36-
