model
size = 31 30 6, scale = 0.05, origin = -y
material deform = 1, fade = true, lighting = smooth, roughness = 0.3, metalness = 0.6
  colors = A:#FFF B:#2C3B6D C:#000 D:#D7D7D7 E:#34499B
voxels
78-2(2AD28-)3(3AD27-)3AD26-4AD26-3A2D25-4A2D25-3A3D24-13A3D15-14A3D13-15A3D2-E7B3-14A3D3-E7B2-14A3D4-E7B-16A3D3-2(E7B-17A3D2-)E7B-16A3D3-E7B-15A3D4-2(E7B-16A3D3-)E7B-15A3D4-E7B-14A3D5-2(E7B-15A3D4-)E7B3-12A3D5-8E69-2(2AD28-)3(3AD27-)3AD26-4AD26-3A2D25-4A2D25-3A3D24-13A3D15-14A3D13-15A3D2-E7B3-14A3D3-E7B2-14A3D4-E7B-16A3D3-2(E7B-17A3D2-)E7B-16A3D3-E7B-15A3D4-2(E7B-16A3D3-)E7B-15A3D4-E7B-14A3D5-2(E7B-15A3D4-)E7B3-12A3D5-8E68-3(4C27-2(C3AC26-)3(C4AC25-)C4A2(C24-C5A)2(C23-C6A)9C14-C16AC13-C17AC-8C2-C18A2C8BC-C17A3C8B2C17A2C-C8BC19A3C2(8BC20A2C)8BC19A3C8BC18A2C2(-C8BC19AC)-C8BC18A2C-C8BC17A2C2(2-C8BC18AC)2-C8B3C15AC3-C8BC-16C5-8C37-)4C27-2(C3AC26-)3(C4AC25-)C4A2(C24-C5A)2(C23-C6A)9C14-C16AC13-C17AC-8C2-C18A2C8BC-C17A3C8B2C17A2C-C8BC19A3C2(8BC20A2C)8BC19A3C8BC18A2C2(-C8BC19AC)-C8BC18A2C-C8BC17A2C2(2-C8BC18AC)2-C8B3C15AC3-C8BC-16C5-8C22-
