model
size = 30 24 13, scale = 0.05, origin = -y
material deform = 1, fade = true, lighting = smooth, roughness = 0.3, metalness = 0.6
  colors = A:#222 B:#CF0 C:#777
voxels
122-4(A24-A4-)A24-A544-A24-A5(4-BA22-AB)4-A24-A484-A24-A2(4-BA22-AB)3-2(A26-A2-)A26-A3-2(BA22-AB4-)A24-A424-A24-A2(4-BA22-AB)3-A26-A-A2(28-2A)28-A-A26-A3-2(BA22-AB4-)A24-A364-A24-A2(4-BA22-AB)3-A26-A-2A26-2ACA26-ACA28-ACA26-AC2A26-2A-A26-A3-2(BA22-AB4-)2A22-2A5-A22-A6-2A20-2A7-2(A20-A8-)2A18-2A9-2A16-2A11-A16-A12-2A14-2A13-3A10-3A16-4A4-4A21-6A14-A24-A4-BA22-AB3-A26-A-A28-ACA26-A3(2C28-)2CA26-ACA28-A-A26-A3-BA22-AB4-2A22-2A5-A22-A6-2A20-2A7-2(A20-A8-)2A18-2A9-2A16-2A11-A16-A12-2A14-2A13-3A10-3A16-4A4-4A21-6A14-A24-A4-BA22-AB3-A26-A-A28-2A2(28-AC28-CA)28-2A28-A-A26-A3-2B22-2B4-2B22-2B5-B22-B6-2B20-2B7-2(B20-B8-)2B18-2B9-2B16-2B11-B16-B12-2B14-2B13-3B10-3B16-4B4-4B21-6B14-A24-A4-BA22-AB3-A26-A-A28-ACA26-A3(2C28-)2CA26-ACA28-A-A26-A3-BA22-AB4-2A22-2A5-A22-A6-2A20-2A7-2(A20-A8-)2A18-2A9-2A16-2A11-A16-A12-2A14-2A13-3A10-3A16-4A4-4A21-6A14-A24-A2(4-BA22-AB)3-A26-A-2A26-2ACA26-ACA28-ACA26-AC2A26-2A-A26-A3-2(BA22-AB4-)2A22-2A5-A22-A6-2A20-2A7-2(A20-A8-)2A18-2A9-2A16-2A11-A16-A12-2A14-2A13-3A10-3A16-4A4-4A21-6A44-A24-A2(4-BA22-AB)3-A26-A-A2(28-2A)28-A-A26-A3-2(BA22-AB4-)A24-A424-A24-A2(4-BA22-AB)3-2(A26-A2-)A26-A3-2(BA22-AB4-)A24-A484-A24-A5(4-BA22-AB)4-A24-A544-4(A24-A4-)A24-A452-
