model
size = 32 32 30, scale = 0.05, origin = -y
material deform = 1, fade = true, lighting = smooth, roughness = 0.3, metalness = 0.6
  colors = A:#66F B:#60F C:#99F D:#EEE E:#C6F F:#BBB G:#111 H:#F9F I:#F0C
voxels
513-F991-F927-F95-F63-F863-F63-F95-F768-11A21-11A20-F2(11A21-)2(11A20-F11A21-)11A757-2(11A21-11A20-F)2(11A21-)11A20-F11A21-11A757-3(11A21-11A20-F)2(11A21-)11A10(22-10A)22-3(2A30-)BA30-5C17-5C8(5-13A2B3A2B7A)2(4-14A2B3A2B7A)2(3-F14A2B3A2B7A4-14A2B3A2B7A)3-F14A2B3A2B7A4-11A21-11A10(22-10A)22-3(HA30-)BA30-5C17-5C8(5-13A2B3A2B7A)2(4-14A2B3A2B7A)5(2-2C14A2B3A2B7A)4-11A21-11A10(22-10A)22-2(HA30-)2A62-5C17-5C8(5-13A2B3A2B7A)2(4-14A2B3A2B7A)5(2-2C14A2B3A2B7A)4-11A21-11A10(22-10A)22-2A30-2A94-5C17-5C8(5-13A2B3A2B7A)2(4-14A2B3A2B7A)5(2-2C14A2B3A2B7A)3-C11A20-C11A5(22-D9A)2(15-4B3-D9A)3(15-4B3-10A)15-4B28-4B99-5C17-5C8(5-13A2B3A2B7A)2(4-14A2B3A2B7A)5(2-2C14A2B3A2B7A)3-C11A20-C11A5(22-D9A)2(2(15-4B3-D9A)15-4B3-10A2(15-4B3-10B)15-4B28-4B131-6(E12A2B3A2B7A5-)13A2B3A2B7A5-13A2B3A2B7A4-7(14A2B3A2B7A3-C)11A20-C11A3(22-G9A)2(22-D9A))2(15-4B3-D9A)3(15-4B3-10A)15-4B28-4B131-6(E12A2B3A2B7A5-)13A2B3A2B7A5-13A2B3A2B7A4-3(14A2B3A2B7A3-C)3(14A2B3A2B7A2B-C)14A2B3A2B7A2B2(IC11A15-4B)3(3-G9A15-4B)4(3-D9A15-4B)3-10A15-4B3-10A22-10A2(182-6(E12A2B3A2B7A5-)13A2B3A2B7A5-13A2B3A2B7A4-14A2B3A2B7A3-C2(14A2B3A2B7A3-B)2(14A2B3A2B7A2B-C)2(14A2B3A2B7A2BIC)11A15-4BIC11A8(15-4B3-10A)15-4B3-10B22-10B)182-6(E12A2B3A2B7A5-)13A2B3A2B7A5-13A2B3A2B7A4-3(14A2B3A2B7A3-C)3(14A2B3A2B7A2B-C)14A2B3A2B7A2B2(IC11A15-4B)3(3-G9A15-4B)4(3-D9A15-4B)3-10A15-4B3-10A22-10A182-6(E12A2B3A2B7A5-)13A2B3A2B7A5-13A2B3A2B7A4-7(14A2B3A2B7A3-C)11A20-C11A3(22-G9A)4(22-D9A)3(22-10A)182-6(E12A2B3A2B7A5-)13A2B3A2B7A5-13A2B3A2B7A4-7(14A2B3A2B7A3-C)11A20-C11A3(22-G9A)4(22-D9A)2(22-10A2(22-10B)150-5C17-5C8(5-13A2B3A2B7A)2(4-14A2B3A2B7A)5(2-2C14A2B3A2B7A)3-C11A20-C11A7(22-D9A))3(22-10A)150-5C17-5C8(5-13A2B3A2B7A)2(4-14A2B3A2B7A)5(2-2C14A2B3A2B7A)4-11A21-11A10(22-10A)22-2A30-2A94-5C17-5C8(5-13A2B3A2B7A)2(4-14A2B3A2B7A)5(2-2C14A2B3A2B7A)4-11A21-11A10(22-10A)22-2(HA30-)2A62-5C17-5C8(5-13A2B3A2B7A)2(4-14A2B3A2B7A)2(3-F14A2B3A2B7A4-14A2B3A2B7A)3-F14A2B3A2B7A4-11A21-11A10(22-10A)22-3(HA30-)BA317-3(11A21-11A20-F)2(11A21-)11A10(22-10A)22-3(2A30-)BA317-2(11A21-11A20-F)2(11A21-)11A20-F11A21-11A757-11A21-11A20-F2(11A21-)2(11A20-F11A21-)11A852-F63-F95-F863-F95-F63-F478-
