model
size = 32, scale = 0.05, origin = -y
material deform = 1, fade = true, lighting = smooth, roughness = 0.3, metalness = 0.6
  colors = A:#9CF B:#222 C:#888 D:#777 E:#400 F:#555 G:#444 H:#AAA I:#E00 J:#111 K:#BBB L:#A00 M:#B00 N:#D00 O:#800 P:#DDD Q:#F63 R:#700 S:#FF0 T:#3CF U:#6F9 V:#FC0 W:#C00
voxels
494-2(NQ)27-NQ2-NQ26-Q4-N26-N4-Q26-QN2-QN27-2(QN)764-4I27-I4NI25-IN4MNI24-8E24-INM2EMNI24-IN4MNI25-I4NI27-4N700-4L26-2L4M2L23-2LM4NM2L21-L2MN4KN2ML20-LMN6KNML19-LMN8KNML18-4E6K4E2(18-LMN8KNML)19-LMN6KNML20-2L8N2L21-LM6NML23-2L4M2L26-4L541-2E27-B6EB22-H2B6E2BH19-2H2B6C2B2H18-2H10C2H17-2(3H10C3H16-)3H10C3H15-6E6C6E14-18H15-2(16H16-)16H17-14H18-14H19-12H22-8H27-2H444-6E24-FB6EBF20-3FB6CB3F17-2FH10CH2F16-F14CF15-2F14C2F14-F16CF13-2(2F16C2F12-)7E6C7E12-F18CF2(12-2F16C2F)13-F16CF14-2F14C2F15-F3C8A3CF16-2F12D2F17-3F8D3F20-4F2D4F24-6F377-B6EB22-DFB6EBFD19-3HB6EB3H17-4CB6CB4C15-4H10C4H13-20C12-20C11-2(22C10-)F20CF10-8E6C8E10-F20CF3(10-22C)11-20C12-D5C8A5CD13-18D15-16D17-14D19-12D22-8D312-B6EB22-2FB6EB2F19-3DB6EB3D16-5HB6EB5H14-5CB6CB5C13-5H10C5H11-22C10-22C9-2(24C8-)2F20C2F8-9E6C9E8-2F20C2F3(8-24C)9-22C10-2D18A2D11-20D13-18D14-18D16-14D19-12D22-8D278-2HBEB2EBEB2H19-3FB6EB3F16-5DB6EB5D13-6HB6EB6H12-2(6CB)6C11-6H10C6H9-2(24C8-)24C7-2(G24CG6-)10E6C10E3(6-G24CG)7-2(24C8-)3D18A3D9-22D11-20D12-20D13-18D16-14D19-12D23-6F246-2HKB6EBK2H16-5FB6EB5F13-6DB6EB6D11-7HB6EB7H10-7CB6CB7C9-7H10C7H8-24C7-3(G24AG6-)G24AG5-11E6A11E4-IG24AGI5-3(G24AG6-)G24AG7-3D18A3D8-24D9-22D10-22D11-20D13-18D16-14D20-10F26-2F215-2H2KB6EB2K2H15-5FB6EB5F13-6DB6EB6D11-7HB6EB7H9-C7AB6AB7AC7-2(G24AG6-)G24AG5-MG24AGI4-IG24AGM4-MG24AGI4-11E6A11E4-IG24AGI4-MG24AGM4-IG24AGI4-MG24AGI5-G24AG6-G3D18A3DG6-G24DG7-24D9-22D11-20D13-18D15-16D17-14F21-8F211-2H2KHB6EBH2K2H13-6FB6EB6F11-7DB6EB7D9-8HB6EB8H7-G8AB6AB8AG6-G24AG5-M26AI4-I26AM4-I26AI4-M26AM3-3(E28AE2-)E28AE3-I26AI4-MG24AGM4-IG24AGI4-MG3D18A3DGM5-G24DG6-G24DG7-24D9-22D11-20D13-18D15-16F18-12F24-I2MI180-H3K3B6E3B3KH11-7FB6EB7F9-8DB6EB8D8-8HB6EB8H7-G2A7B6N7B2AG5-M3A3BW3B6N3BW3B3AM4-I3A20B3AI4-M3A20B3AM3-7(E4A20B4AE2-)EAG2A20B2AGAE3-MG2A20B2AGM4-IG2D20B2DGI4-MG2D20B2DGI5-G2D20B2DG7-2D20B2D8-2D20B2D9-22D11-DG16DGD14-16F17-14F21-IMI2MIMI151-I8-I17-2(HK)BKB2E2B2E2(BK)HKH11-7FH6EH7F9-7C2H6E2H7C7-G3A6B6E6B3AG6-G2AB18-B2AG5-I3AB18-B3AI4-M3AB18-B3AM3-E4AB6-6B6-B4AE2-E4AB5-B6AB5-B4AE2-E4AB4-10A4-B4AE2-E4A2(B-)B10A2(B-)2(B4AE2-E4AB3-B10AB3-)B4AE2-E4AB3-3B6A3B3-B4AE2-E4A2(B-)3B6A3B2(-B)4AE2-EAG2AB3-3B6A3B3-B2AGAE2-EAG2AB4-2B6A2B4-B2AGAE3-MG2DB5-8B5-B2DGM4-IG2DB2-B3-6B3-B2-B2DGM5-G2DB18-B2DG6-G2DB4-B8-B4-B2DG7-2D2B16-2B2D9-22D11-20D13-18F16-14F20-2(MI)2M2(IM)57-4C89-I8-I16-2HK3BKBE4BEBK3BK2H9-8FHE4BEH8F8-DH7JE4BE7JHD7-G2A2J-4J6E4J-2J2AG5-M3AB18-B3AM4-I3AB18-B3AI3-E4AB18-B4AE2-E4AB6-6B6-B4AE2-E4AB5-B6AB5-B4AE2-E4AB4-B8AB4-B4AE-I5AB-I-B10AB-I-B5A3I4AB3-B10AB3-B4A4I3A2B3-B10AB3-2B3A3I4A2B3-3B6A3B3-2B4AI-E3A2B-I-3B6A3B-I-2B3AE2-EAGA2B3-3B6A3B3-2BAGAE2-EAGA2B4-2B6A2B4-2BAGAE2-EAG2DB5-8B5-B2DGAE3-IG2DB2-B3-6B3-B2-B2DGI4-MG2DB18-B2DGI5-G2DB4-B8-B4-B2DG7-2D2B16-2B2D8-6D12B6D9-22D12-F16AF15-16F18-2(IM)4I2(MI)24-4E27-2C2-2C86-I-I8-I-I14-H2K2(BK)2B4-2B2(KB)2KH9-8FHE-2B-EH8F7-D2A7JE4BE7J2AD6-GAB6-J6EJ6-BAG5-I2AB7-2N2B2N7-B2AI4-MAGB7-2N2B2N7-BGAM3-E2AGB7-BK2BKB7-BG2AE2-E2AGB7-6B7-BG2AE2-E2AGB6-8B6-BG2AE-I3AGB5-10B5-BG3A3I2AGB2-L-12B-L2-BG2A2I2-OAGB4-12B4-BGAO4-OAGB4-12B4-BGAO2-2I2AGB4-3B6A3B4-BG2A2IQ3AGB2-L-3B6A3B-L2-BG3AQ-EA2GB4-3B6A3B4-B2GAE2-EA2GB5-2B6A2B5-B2GAE2-EAGDB6-B6AB6-BDGAE3-MGDB3-D3-6D3-D3-BDGM4-IGDB20-BDGM5-G2D5-D8-D5-2DG6-GDB-D16-D-BDG7-5DB12-B5D9-5D12B5D11-2F16A2F14-16F18-IM3I2B3IMI23-2E2-2E25-2C4-2C25-G4-G26-F4-F22-2(I-)F4-F2(-I)14-HKH2(BK)2B4-2B2(KB)HKH9-8FHB4-BH8F7-G2A2(2JH)JE4BEJ2(H2J)2AG6-GAB6-J2E2-2EJ6-BAG5-I2AB7-2L2-2L7-B2AI3-E2AGB7-2N2-2N7-BG2AE2-E2AGB7-IK2-KI7-BG2AE2-E2AGB7-6B7-BG2AE-I3AGB6-8B6-BG3A3IOAGB5-10B5-BGAO2I2-OAGB2-I-12B-I2-BG2(AO4-OA2B4-12B4-2B)AO4-OA2B2-LI3B6A3BIL2-2BAO2-2I2AB3-I-3B6A3B-I3-B2A3I2AG2B3-L3B6A3BL3-2BG2AI-EA2GB-RLR-2B6A2B-RLR-B2GAE2-EA2GB-L4-B6AB4-L-B2GAE2-EA2GB-R-L3-6B3-L-R-B2GAE3-I2GB-L16-L-B2GI5-2GH-R3-L8-L3-R-H2G6-2GB-L16-L-B2G7-2GEA2E12-2EAE2G9-G4A12-4AG11-GF16AFG14-16F18-IM2I4B2IMI23-E4-E25-C6-C85-I-I8-I-I14-H2K2(BK)B6-2(BK)B2KH9-8FB6-B8F7-G2A6J8B6J2AG5-M2AB6-J6EJ6-B2AM4-M2AB7-LN2-NL7-B2AM3-E2AB8-2N2-2N8-B2AE2-E2AB8-IK2-KI8-B2AE2-E2AB4-14B4-B2AE-2I2AB4-B2-8B2-B4-B2A2I2-OAB3-LI-10B-IL3-BAO4-EAB3-I-12B-I3-BAE3-IOAB5-12B5-BAOI2-QOAB5-12B5-BAOQ3-OAB5-3B6A3B5-BAO4-OAB5-3B6A3B5-BAO2-2I2AB5-3B6A3B5-B2A2I-E3G6-2B6A2B6-3GE2-E3G7-B6AB7-3GE2-2E2G4-I3-6B3-I4-2G2E3-E2G22-2GE4-2EG6-L8-L6-G2E5-EG22-GE7-4E16-4E9-22E10-2G18A2G11-20F16-IM8IMI23-6E25-C6-C85-I-I8-I-I14-H2K2(BK)B6-2(BK)B2KH9-8FB6-B8F7-GA2B5J8B5J2BAG5-I2AB6-J6EJ6-B2AI4-I2AB7-2L2-2L7-B2AI3-E2AB8-2N2-2N8-B2AE2-E2AB8-BK2-KB8-B2AE2-E2AB8-6B8-B2AE-2I2AB7-8B7-B2A2I2-OAB6-10B6-BAO4-EAB5-12B5-BAE3-IOAB5-12B5-BAOI2-IOAB5-12B5-BAOI3-OAB5-3B6A3B5-BAO4-OAB5-3B6A3B5-BAO2-2I2AB5-3B6A3B5-B2A2I-E3G6-2B6A2B6-3GE13-B6AB21-L3-6B3-L52-L8-L80-9EH2EH9E10-2G18A2G11-20F17-M3I2M3IM55-2C4-2C25-G4-G26-F4-F22-2(I-)F4-F2(-I)14-HKH2(BK)2B4-2B2(KB)HKH9-8FHB4-BH8F7-GA2B6JE4BE6J2BAG6-GAB6-J6EJ6-BAG5-M2AB7-2L2-2L7-B2AI3-E2AB8-2N2-2N8-B2AE2-E2AH8-2I2-2I8-H2AE2-E2AB8-B-2B-B8-B2AE-I3AB7-8B7-B3A3I2AB6-10B6-B2A2I2-EAB5-12B5-BA2(E4-E2B5-12B5-2B)E4-OB6-3B6A3B6-BO2-2IAB6-3B6A3B6-BA3IE2G6-3B6A3B6-2GEI11-2B6A2B23-B6AB21-I3-6B3-I52-L8-L80-5EH10EH5E10-2G18A2G11-FG16FGF17-M3I2M3IM56-2C2-2C86-I-I8-I-I14-H2K2(BK)3B2-3B2(KB)2KH9-8FH2E2-2EH8F7-GA2BH5J2E2B2E5JH2BAG6-GAB6-J6EJ6-BAG5-I2AB20-B2AM4-MAB22-BAI3-E2AG22-G2AE2-E2AB8-6B8-B2AE2-E2AB7-8B7-B2AE-I3AB6-10B6-B3A3IA2B5-12B5-2BA2I2-B7-12B7-B4-B7-12B7-B2-2IB6-I12AI6-B3IEG6-L12AL6-GEI9-IB10ABI18-L-2B6A2B-L18-I2-B6AB2-I18-L-2L6B2L-L20-L8-L22-L8-L81-20E12-5G10A5G12-20F84-4C89-I8-I16-2HK5B2E2B2E5BK2H9-8FH6EH8F8-2D7J6E7J2D7-GHJ20-JHG5-M2AG20-G2AI4-IAB22-BAI3-E2AB9-4B9-B2AE2-E2AB8-B4AB8-B2AE2-E2AB7-B6AB7-B2AE2-EAB7-2B6A2B7-BAE-IA2E6-4B4A4B6-2EAILE8-4B4A4B8-ELIE8-4B4A4B8-E2IE8-4B4A4B8-EI10-4B4A4B20-4B4A4B21-3B4A3B23-2B4A2B25-6B148-18E14-3G12B3G18-10G182-I8-I17-H2KH3B6E3BH2KH11-4F4H6E4H4F9-2D7J6E7J2D7-GHJ20-JHG6-GAG20-GAG5-IAB22-BAM4-MAB8-6B8-BAI3-E2AB7-2B4G2B7-B2AE2-E2AB6-2B6A2B6-B2AE2-EAE6-G2B6A2BG6-EAE2-3E5-G12AG5-3E-I8-G12AG8-I9-3(G12AG18-)G12AG19-G10AG21-G8AG23-G6AG25-6G117-16E16-2G12B2G19-10G23-2V-2U-2T151-I8-I17-2H2K3B2E2B2E3B2K2H11-4F4H6E4H4F9-2D7J6E7J2D8-2H20-2H7-GAG20-GAG5-MAB22-BAI4-IAH22-HAI4-MAB7-8G7-BAM3-EIE7-G8AG7-EIE2-3E6-G10AG6-3E10-G12AG9-L8-G12AG8-L9-3(G12AG18-)G12AG19-G10AG21-G8AG23-G6AG25-6G117-2EH10EH2E16-2G12B2G19-10G23-2V-2U-2T179-2HK3B6E3BK2H13-3F4H6E4H3F11-D5JHJ6EJH5JD9-2H2J16-2J2H7-GA2E18-2EAG6-GB22-BG5-MAG22-GAM4-IAE8-F4AF8-EAI4-M2E7-2F4A2F7-2EI13-3F4A3F21-2F8A2F10-I9-2F8A2F9-I10-2(2F8A2F20-)GF8AFG20-2F8A2F21-F8AF23-2F4A2F25-6G150-14E18-G12BG20-10G211-2HKHB2E2B2EBHK2H15-2F4H6E4H2F13-DG5B6E5BGD11-HGE16-EGH9-G2E18-2EG7-2(GE22-EG6-)GE8-F4AF8-EG15-2F4A2F23-3F4A3F21-2F8A2F10-L9-2F8A2F9-LI9-2F8A2F9-IL2I7-2F8A2F7-2IL10-GF8AFG20-2F8A2F21-F8AF23-2F4A2F25-6G151-3EH4EH3E20-12B243-H2KB6EB2KH16-2F4H6E4H2F13-GA3E2B6E2B3EAG11-G2AE14-E2AG10-2GE16-E2G9-G8-6D2(8-G)7-D6GD7-G15-DG6AGD21-DGD6ADGD19-DG10AGD3(18-2D10A2D)11-L6-2D10A2D6-L11-2(2D10A2D18-)DG2D6A2DGD19-DGD6ADGD21-DG6AGD23-D6GD25-6D88-10E22-10G245-2HBEB2EBEB2H19-G3A6E3AG16-3GJ2B6E2BJ3G13-2G16-2G12-2G16-2G83-6C25-C6AC23-C8AC21-C10AC20-C10AC12-2(LI)-ILIC10ACILI-2(IL)4-I2-LIL-IC10ACI-LIL2-I12-C10AC20-C10AC21-C8AC23-C6AC25-6C153-8E24-8G248-B6EB22-3G6E3G19-G12-G16-3G12-3G116-6C25-C6AC23-C8AC21-5(C10AC20-)C10AC21-C8AC23-C6AC25-6C155-4E28-4G282-8G22-5G2-5G151-6C25-C6AC23-C8AC21-5(C10AC20-)C10AC21-C8AC23-C6AC25-6C506-6G154-6H25-H6AH23-H8AH22-H8AH21-H10A2(H20-H4A2J4A)H20-H10AH21-H8AH22-H8AH23-2H4A2H26-4H699-6K25-K6AK23-K8AK22-K3A2J3A2(K22-K2AJ2-J2A)K22-K3A2J3AK22-K8AK23-K6AK25-6K762-6P25-PJ4AJP24-P2A2S2A2(P24-PAS2-SA)P24-P2A2S2AP24-PJ4AJP25-6P365-
