model
size = 26 18 32, scale = 0.05, origin = -y
material deform = 1, fade = true, lighting = smooth, roughness = 0.3, metalness = 0.6
  colors = A:#161616 B:#858585 C:#FFF89D D:#C9C986 E:#CECE8C F:#C3BB77 G:#0F0F0F
voxels
35-2(8C18-)2(8A18-)8A19-6A21-4A279-2(10C16-)10A16-4A2F4A17-3A2F3A18-3A2F3A19-2A2F2A2(20-2F2-2F)251-12C14-C10BC4(14-12A)14-5A2F5A15-2(2A2F)2A18-2F2A2F124-6A20-6C20-6A11-2E20-2E33-14C12-C12BC6(12-14A)13-12A15-10A69-8A2(18-A6-A)11-D2(6-A)6-D2-2ED20-D2E-D22-D6-16C10-C14BC6(10-4AB6FB4A)11-A12-A13-12A42-8A18-A6-A10-E7-A6-A7-E3-F5-A8-A5-F3-2ED4-A8-A4-D2E-2ED20-D2E-D22-D6-16C10-C4B6F4BC3(10-4AF6-E4A)10-F3AF6-E3AF2(10-4AF6-E4A)11-A12-A13-12A17-6A19-A6-A18-A6-A10-ED20-DE3-F20-F3-2ED18-D2E-2ED20-D2E-D22-D6-16C10-C4B6F4BC2(10-4AF6-E4A)2(10-F3AF6-E3AF)2(10-4AF6-E4A)11-A2-F6-E2-A13-3A6-3A16-A6-A18-A6-A10-D22-D2-E2D18-2DE3-F20-F3-2ED18-D2E-2ED20-D2E-D22-D6-16C10-C4B6F4BC10-4AF6-E4A3(10-F3AF6-E3AF)2(10-4AF6-E4A)11-A2-F6-E2-A13-3A6-3A15-A8-A16-A8-A9-2D20-2D-2E2D18-2D2E2-F20-F2-3ED18-D5ED20-D2E-D22-D6-16C10-C4B6F4BC5(10-4AF6-E4A)11-3AF6-E3A12-A2-F6-E2-A13-3A6-3A8-E6-A8-A6-E3-F5-A8-A5-F3-DE5-A8-A5-ED-2E2D18-2D2E2-F20-F2-3ED18-D5ED20-D2E-D22-D7-14C12-C3B6F3BC6(12-3AF6-E3A)12-2A-F6-E-2A7-D5-3A6-3A5-D2-ED5-A8-A5-DE3-F5-A8-A5-F3-DE5-A8-A5-ED-2E2D18-2D2E2-F20-F2-3ED18-D5ED20-D2E-D22-D8-12C14-C2B6F2BC7(14-2AF6-E2A)8-2D4-3A6-3A4-2D-2ED5-A8-A5-D2E2-F5-A8-A5-F3-DE5-A8-A5-ED-2E2D18-2D2E2-F20-F2-2E2D18-2D4ED20-D2E-D22-D6-16C10-2C3B6F3B2C5(10-4AF6-E4A)11-3AF6-E3A13-3AE4-E3A8-2D2(4-4A)4-2D-2ED2(6-A)6-D2E2-F2(6-A)6-F3-DE20-ED-2E2D18-2D2E2-F20-F2-2E2D18-2D4ED20-D2E-D22-D5-18C8-C5B6F5BC2(8-5AF6-E5A)8-2(5AF6-E6A7-)5AF6-E5A8-5AF6-E5A11-4A4E4A8-2D20-2D-2E2D18-2D2E2-F20-F3-DE20-ED-2E2D18-2D2E2-F20-F2-2E2D18-2D4ED20-D2E-D22-D4-19C7-C6B6F5BC3(7-6AF6-E5A)7-6AF6-E6A6-6AF6-E5A5-E2-5AF-4B-E5A2-E3-F2-16A2-F3-DE20-ED-2E2D18-2D2E2-F20-F3-2D20-2D-2E2D18-2D2E2-F20-F2-2E2D18-2D3E2D20-2DE-D22-D4-19C7-C6B6F5BC2(7-6AF6-E5A)7-6AF6-E6A6-6AF6-E6A4-D-6AF-4B-E5A2-D2-ED-5AF-4B-E5A-DE3-F2-16A2-F3-DE3-14A3-ED-2E2D18-2D2E2-F20-F3-2D20-2D-2E2D18-2D2E-DF20-FD-E2D20-2DE-2D20-2D2-D22-D4-20C6-C6B6F6BC6-2(6AF6-E5A7-)6AF6-E6A6-6AF6-E6A4-D-6A8B5A2-D-2ED-5A8B5A-D2E2-F2-16A2-F3-DE3-14A3-ED-2E2D3-12A3-2D2E2-F20-F3-2D20-2D-E3D18-3DE-2D20-2D2(2-D22-D)30-20C6-C6B6F6BC6-2(6AF6-E5A7-)6AF6-E6A6-6AF6-E6A4-D-6A8B5A2-D-2ED-5A8B5A-D2E2-F2-16A2-F3-DE3-14A3-ED-2E2D3-2A2G8A3-2D2E-DF20-FD2(2-2D20-2D)2-D22-D82-20C6-C6B6F6BC6-6AF6-E5A7-6AF6-E2(6A6-6A8B)6A4-D-6A8B5A2-D-2ED-5A8B5A-D2E2-F2-16A2-F3-DE3-14A3-ED2-ED4-A2(G2A)GAG2A4-DE2-DF20-FD2-2D20-2D2-D22-D108-20C6-C6B6F6BC2(6-6AF6-E6A)6-6A8B6A4-D-6A8B6A-D2-D-6A8B6A-D-2ED-5A8B5A-D2E-DF2-16A2-FD2-2D3-14A3-2D2-2D4-4A2(G3A)4-2D2-2D20-2D160-20C6-C18BC6-6A8B6A5-E6A8B5AGE3-DE6A8B6AED2-D-6A8B5AG-D2-D-6A8B6A-D2-ED-5A8B5A-DE2-DF2-16A2-FD2-DE3-14A3-ED2-D5-3AG2A3(GA)5-D186-20C6-C18BC6-6A8B6A5-E6A8B6AE3-DE6A8B5AGE2(D2-D-6A8B6A-)D2-2D-5A8B5A-2(2D2-)16A2-2D7-14A13-2AG9A192-20C6-C18BC6-6A8B6A5-E6A8B6AE3-DE6A8B5AGE2(D2-D-6A8B6A-)2(D2-)5A8B5A2-D6-16A11-14A13-A2(G2A)4GA192-20C6-C18BC6-6A8B5A7-3(6A8B6A6-)6A8B5A8-5A8B5A9-16A11-14A13-A4G2AG4A192-20C6-C18BC6-3(6A8B5A7-)6A2(8B5A8-5A)8B5A9-16A11-14A13-7A3G2A193-18C8-C16BC6(8-18A)9-16A11-14A13-2AGAG5AGA193-18C8-C16BC6(8-18A)9-16A11-14A13-3AG6AGA193-18C8-C16BC5(8-18A)9-16A10-16A11-14A13-4(AG)2AGA194-16C10-C14BC7(10-16A)11-14A13-8A2G2A194-16C10-C14BC6(10-16A)11-14A12-14A14-10A196-14C12-C12BC7(12-14A)13-12A222-12C14-C10BC6(14-12A)15-10A250-10C16-C8BC5(16-10A)17-8A269-
