model
size = 23 30 29, scale = 0.05, origin = -y
material deform = 1, fade = true, lighting = smooth, roughness = 0.3, metalness = 0.6
  colors = A:#465D4C B:#444 C:#E2943B D:#777 E:#888 F:#E8B647 G:#BBB H:#555
voxels
329-9A13-5(11A12-)11A13-9A15-7A17-5A404-A13-A8-2A11-2A8-3A9-3A4(8-15A)2(8-3A9B3A)8-7AB7A9-6AB6A11-5AB5A12-5AB5A15-5A357-8(2A13-2A6-)2(2A2B9-2B2A6-)3A11-3A7-2A11-2A9-A11-A10-2(A11-)5AB5A15-5A310-A17-A8(4-2A15-2A)2(4-2AB13-B2A)4-3A13-3A5-2A13-2A7-A13-A8-2A11-2(2A9-)2A12-4AB4A16-5A264-10(A17-A4-)2(A2B13-2BA4-)2AB13-B2A4-2AB13-B2A5-AB13-BA6-ABA11-ABA7-2(3A9-)6AB6A12-9A262-A10(17-2A2-2A)2(B15-B2A2-2A)17-2A3-A17-A4-A17-A5-2AB11-B2A6-2ABA9-AB2A2(7-4A)10-5AB5A15-5A240-10(A19-A2-)2(AB17-BA2-)A19-A2-A19-A3-A17-A4-A17-A5-3AB9-B3A6-3ABA7-AB3A8-6AB6A12-9A237-2A19-3A5(B19-B2A)B19-B3A3(19-4A)B17-B4AB17-B2A-A19-A2-A19-A3-A17-A4-A17-A5-A15-A6-4AB7-B4A8-6AB3AB2A12-9A214-2A19-3A2(B19-B2A)4(D19-D2A)B19-B2AB19-B3A19-4A19-3AB19-B2AB19-B3A19-2A-A19-A2-2A17-2A3-A17-A4-2A15-2A5-3A11-3A8-3ABA3-AB3A12-4AB4A17-3A171-A21-3A19-3AB19-B2(2AD19-D)2(2AB19-B2AD19-D)2AB19-B3A19-4A19-3AB19-B2AB19-B3A19-4A19-2A-2A17-2A2-2A17-2A3-2A15-2A4-4A11-4A6-5AB3-B5A10-3A2(BA)B3A15-5A32-C7(21-2C)A19-ACA3(B19-B2AD19-D2A)D19-D2AB19-B3A19-4A19-3AB19-B2AB19-B3A19-4A19-2A-2A17-2A2-2A17-2A3-2A15-2A4-4A11-4A6-4A7-4A10-4A3B4A14-7A18-3C10-C7(21-2C)A19-ACAB19-B2(2AD19-D)2(2AB19-B2AD19-D)2AB19-B3A19-4A19-3A3(B19-B2A)B19-BA-AB17-BA2-AB17-BA3-AB15-BA4-2A2B11-2B2A6-2A2B7-2B2A10-2A7B2A14-3AC3A18-3C148-A21-3A19-3A3(B19-B2AD19-D2A)D19-D2AB19-B3A19-4A19-3AB19-B2AB19-B3A19-4A19-2A-2A17-2A2-2A17-2A3-2A15-2A4-4A11-4A6-4A7-4A10-4A3B4A14-7A18-3C171-2A19-3A2(B19-B2A)4(D19-D2A)B19-B2AB19-B3A2(19-4A)2(B17-B4A)19-2A-A19-A2-2A17-2A3-A17-A4-2A15-2A5-3A11-3A2(7-4A)10-3A2(BA)B3A15-5A193-2A21-2A19-3A5(B19-B2A)B19-B3A3(19-4A)B17-B2A-AB17-B2(G2-A19-)A3-A17-A4-A17-A5-A15-A6-3A11-3A8-3AB5-B3A12-4AB4A17-3A218-10(2A17-2A2-)2AB15-B2A2-2AB15-B2(AG2-2A17-)2A3-A16-2A4-A16-2A5-A15-A6-3A11-3A8-2A2(B3A)B2A12-9A262-9(A17-A4-)2(AB15-BA4-)2(A17-A4-)2A15-2A5-A15-A7-2AB9-B2A8-2AB9-B2A10-5AB5A14-7A355-5(A17-A4-)A3B11-3BA4-2A2B11-2B2A2(4-2A-B11-B3A)5-2AB11-B2A7-AB11-BA2(9-2A)10-2A9-2A12-4AB4A17-3A472-CDE2B9-2BEDC4-C2A2B9-2B2AC5-2A12-3A6-2A12-3A7-2A11-2A9-A11-A10-2A9-2A11-5AB5A13-9A492-C2(DE)9B2(ED)C4-CF3A9B3AFC6-3A4-B4-3A8-3A4-B4-3A9-2(2A4-B4-2A10-)2A4-B4-2A11-11A14-7A493-C3(DE)D3E3(DE)DC4-2(CF)C9A2(CF)C8-3A2(HB)H3A12-3A5H3A12-2A7H2A12-2A2(H2B)H2A13-A7HA14-9A515-C2(DE)D2E3D2E2(DE)DC4-3(CF)7C3(FC)11-2(G-)G18-5G17-7G16-2(G2-)G16-7G539-C3(ED)5E3(DE)C4-2C2(FC)F5C2(FC)F2C649-C2(ED)E5D2(ED)EC6-2C2(FC)5F2(CF)2C650-C2EDED5EDED2EC6-3CFCF5CFCF3C651-C2EDE5DED2EC8-3CFC5FCF3C653-C2ED5ED2EC10-3CF5CF3C655-2CE5DE2C12-3C5F3C657-9C14-9C237-
