model
size = 23 13 29, scale = 0.05, origin = -y
material deform = 1, fade = true, lighting = smooth, roughness = 0.3, metalness = 0.6
  colors = A:#FBE251 B:#E83015 C:#444 D:#FFF E:#FFFFFB F:#111 G:#FCFAF2 H:#DA2B14
voxels
29-2(2A7B2A12-)3A5-3A12-4A3-4A14-7A17-5A174-2(3A2C5-2C3A8-)4AC5-C4A8-5AC3-C5A10-4A3C4A12-5AC5A15-5A150-2(2A2C9-2C2A6-)3A11-3A6-3A11-3A8-A11-A10-2(A11-)5AC5A15-5A126-2(2AC13-C2A4-)3A13-3A4-3A13-3A6-A13-A8-2A11-2(2A9-)2A12-4AC4A16-5A103-2(A2C13-2CA4-)2AC13-C2A4-2AC13-C2A5-AC13-CA6-ACA11-ACA7-2(3A9-)6AC6A12-9A100-2(2AC15-C2A2-)2A17-2A3-A17-A4-A17-A5-2AC11-C2A6-2ACA9-AC2A2(7-4A)10-5AC5A15-5A79-2(AC17-CA2-)A19-A2-A19-A3-A17-A4-A17-A5-3AC9-C3A6-3ACA7-AC3A8-6AC6A12-9A76-2AC17-C4AC17-C2A-A19-A2-A19-A3-A17-A4-A17-A5-A15-A6-4AC7-C4A8-6AC3AC2A12-9A76-AC19-C2AC19-C3A19-2A-A19-A2-2A17-2A3-A17-A4-2A15-2A5-3A11-3A8-3ACA3-AC3A12-4AC4A17-3A56-AC19-C2AC19-C3A19-4A19-2A-2A17-2A2-2A17-2A3-2A15-2A4-4A11-4A6-5AC3-C5A10-3A2(CA)C3A15-5A55-AC19-C2AC19-C3A19-4A19-2A-2A17-2A2-2A17-2A3-2A15-2A4-4A11-4A6-4A7-4A10-4A3C4A14-7A18-3B33-A3(C19-C2A)C19-CA-AC17-CA2-AC17-CA3-AC15-CA4-2A2C11-2C2A6-2A2C7-2C2A10-2A7C2A14-3AB3A18-3B33-AC19-C2AC19-C3A19-4A19-2A-2A17-2A2-2A17-2A3-2A15-2A4-4A11-4A6-4A7-4A10-4A3C4A14-7A18-3B33-2A2(C17-C4A)19-2A-A19-A2-2A17-2A3-A17-A4-2A15-2A5-3A11-3A2(7-4A)10-3A2(CA)C3A15-5A56-AC17-CA2-AC17-C2(G2-A19-)A3-A17-A4-A17-A5-A15-A6-3A11-3A8-3AC5-C3A12-4AC4A17-3A57-2AC15-C2A2-2AC15-C2(AG2-2A17-)2A3-A16-2A4-A16-2A5-A15-A6-3A11-3A8-2A2(C3A)C2A12-9A78-2(AC15-CA4-)A17-A4-A17-A5-A15-A6-A15-A7-2AC9-C2A8-2AC9-C2A10-5AC5A14-7A79-A3C11-3CA4-2A2C11-2C2A2(4-2A-C11-C3A)6-AC11-CA8-AC11-CA2(9-2A)10-2A9-2A12-4AC4A17-3A81-3B2C9-2C3B4-B2A2C9-2C2AB5-2A12-3A6-2A12-3A8-2(A11-A10-)2A9-2A11-5AC5A14-7A79-5B8-6B4-B4-9C5B4-2B3A9C3A2B6-3A4-C4-3A8-3A4-C4-3A9-2A4-C4-2A10-2A4-C4-2A11-A4-C4-A13-9A16-5A80-2(19B4-)5B9A5B9-2A2EA2E2A14-A2(EFC)EA14-A2(E2F)EA14-A7EA14-2A2EA2E2A15-7A102-19B6-15D6-19B11-2E-2E17-2(2(E2-)E16-)7E17-2E-2E126-19B6-15D6-19B235-17B8-13D8-17B236-17B9-12D8-17B237-15B11-10D10-15B239-13B13-8D12-13B241-11B35-4BHBH4B243-9B37-9B237-
