model
size = 4 32 4, scale = 0.05, origin = -y
material deform = 1, fade = true, lighting = smooth, roughness = 0.3, metalness = 0.6
  colors = A:#DC0000 B:#9BADB7 C:#000 D:#FFF E:#FBF236 F:#AC3232 G:#99E550
voxels
2-2AB2C2B2CB-2B2-EB2-BC2-2B-2(4C4B)-20(2A2-)2A-B2C2B2CB-2B2-FB2-GB2-2B-2(4C4B)-21(2A2-)2A-5C2DCB3(2D2B)2DBC2DCB2DEC2DCB2DB88A5C2DCB3(2D2B)2(2DBC2DCB)2DB88A
