model
size = 29 15 5, scale = 0.05, origin = -y
material deform = 1, fade = true, lighting = smooth, roughness = 0.3, metalness = 0.6
  colors = A:#F0C B:#EEE
voxels
11-3(3B2-3B21-)3B2-3B369-3(7A19-13A14-17A11-19A9-21A7-7A9-7A5-5A15-5A4-3A19-3A3-3A21-3A2(2-2A23-2A)-2A2(25-4A)67-)7A19-13A14-17A11-19A9-21A7-7A9-7A5-5A15-5A4-3A19-3A3-3A21-3A2(2-2A23-2A)-2A2(25-4A)27-
