model
size = 23 11 29, scale = 0.05, origin = -y
material deform = 1, fade = true, lighting = smooth, roughness = 0.3, metalness = 0.6
  colors = A:#8F563B B:#663931 C:#FFF D:#D9A066
voxels
9-5A245-11A12-2A7-2A218-13A10-2A9-2A216-15A8-2A11-2A214-17A6-A15-A213-17A5-2A15-2A212-17A5-2A4-7A2(4-2A)15-2A189-17A5-2A2-4A3C4A2-2A4-2A6-DBD6-2A12-BDB7(20-3A)13-17A5-A3-AC7ACA2-2A3-2A4-BD5BDB3-3A2-A5-DBD3CDBD5-A8-3A3C3A15-2A3C2A16-2A3C2A17-3(A3CA18-)5A12-5A7-5A5-A3-2A7-2A3-A3-2A4-D2B4-BD4-2A2-A5-B2C6B5-A8-A3CB3CA15-4(A5CA16-)A2CB2CA16-3A-3A11-4A9-4A5-A3-AB7-B2(A3-)2A4-2B5-2B4-2A-2A5-D2B3-BCD5-2A7-AC2B-2BCA15-A2C2BC3(A16-A5C)A16-A2CB2CA16-A2B-2BA11-4A9-4A5-A3-AB7-B2(A3-)2A4-DB5-BD4-2A-A6-2B5-2B6-A7-AB5-BA15-A2B2-BA16-AC3BC2(A16-A2CB2C)A17-2(BC)B18-2B-2B12-4A9-4A5-A3-AB7-B2(A3-)A2(5-2B)5-A-A6-DB5-BD6-A7-AB5-BA15-AB3-BA16-AB2-2BA16-ACB-BCA17-2B-2B18-2(BC)B18-2B-2B12-4A9-4A5-A3-AB7-B2(A3-)A5-DB5-BD5-A-A6-2B5-2B6-A7-AB5-BA15-2(AB3-BA16-)AB3-BA17-B3-B18-5B18-2B-2B12-4A9-4A5-A3-AB7-B2(A3-)A2(5-2B)5-A-A6-DB5-BD6-A7-AB5-BA15-2(AB3-BA16-)AB3-BA17-2B2-B18-BCB-B18-2B-2B12-4A9-4A5-A3-AB7-B2(A3-)A5-DB5-BD5-A-A6-2B5-2B6-A7-AB5-BA15-2(AB3-BA16-)AB3-BA17-3B-B18-BC3B18-2B-2B12-4A9-4A5-A3-AB7-B2(A3-)A2(5-2B)5-A-A6-DB5-BD6-A7-AB5-BA15-3(AB3-BA16-)A2(B-)BA17-3B-B18-2B-2B12-4A9-4A5-A3-AB7-B2(A3-)2A4-DB5-BD4-2A-A6-2B5-2B6-A7-AB5-BA15-3(AB3-BA16-)AC2B-BA17-BC3B18-2B-2B12-4A9-4A5-A3-2A7-2A3-A3-2A4-2B5-2B4-2A-2A5-D2B3-BCD5-2A7-ACB3-BCA15-A2(B-)BA16-A5BA16-AC2B-BA16-A3CBCA16-A2CB2CA16-A2B-2BA11-5A7-5A5-A3-2A7-2A3-A3-2A4-DB2-2B-BD4-2A2-A5-BC2B-2BCB5-A8-A2C3B2CA15-A2(CB)CA16-A5CA16-A3CBCA16-A5CA16-A2CB2CA16-3A-3A11-17A5-2A2-AC7ACA2-2A3-3A3-BD2B2CBDB3-3A2-A5-DBDCBCDBD5-A8-3A3C3A15-2A3C2A16-2A3C2A17-3(A3CA18-)5A12-17A5-2A2-4A3C4A2-2A4-2A6-DBD6-2A4-A7-BDB7-A12-6(3A20-)3A13-17A5-2A4-7A2(4-2A)15-2A4-A17-A166-17A5-ACA13-ACA2(4-2A15-2A)166-17A6-ACA11-ACA6-2A13-2A6-A15-A168-15A8-2A11-2A8-A13-A193-13A10-2A9-2A10-A11-A195-11A12-4A3-4A222-5A239-
