model
size = 24 22 24, scale = 0.05, origin = -y
material deform = 1, fade = true, lighting = smooth, roughness = 0.3, metalness = 0.6
  colors = A:#3F9 B:#CF3 C:#F96 D:#0C0 E:#00F F:#D00 G:#03F H:#777 I:#AAA J:#444
voxels
368-8E496-8E518-2ED6-3E14-8D493-E3D7-3E11-3DA4-A3D15-6A468-2E2D11-2E9-2D2A7-A2D12-10A18-2B446-E2D13-E8-3A11-AD9-5A3-6A13-8B442-E2D15-E6-D2A13-AD7-5A6-5A10-12B16-4C419-E2D17-E4-2DA15-2D6-4A9-3A9-14B13-8C417-ED18-E4-DA17-D5-4A11-3A8-5B5-4B12-10C415-E2D19-E2-2DA17-2D4-3A13-2A7-5B7-4B10-12C16-4F70-E23-D23-A275-ED20-E2-DA19-D3-3A14-3A6-4B9-3B10-5C3-4C15-6F69-D47-B275-ED20-2E-DA19-D3-3A15-2A6-3B11-2B9-5C5-4C13-8F68-A47-C275-ED21-E-DA19-D3-2A16-2A5-4B11-3B8-4C2-3G2-3C13-3F3G2F19-3G46-B23-C23-F23-J10(23-H)11-ED10-H10-E-DA9-H9-D3-2A8-H7-2A5-4B5-H5-3B8-4C2-GIG2-3C13-3FGAG2F19-GIG22-H347-ED21-E-DA19-D3-2A16-2A6-3B11-2B9-4C2-3G2-3C13-3F3G2F19-3G370-ED21-E-DA19-D3-3A15-2A6-3B11-2B10-4C5-3C15-6F393-ED20-E2-2D18-2D4-2A14-2A7-4B9-3B10-5C3-4C16-4F395-ED19-E3-DA17-D5-3A13-2A8-4B7-3B12-10C416-ED19-E3-2D16-2D6-3A11-2A9-5B5-4B13-8C418-ED17-2E4-DA15-D7-4A9-3A10-12B16-4C421-ED15-2E6-DA13-D9-5A5-4A13-8B443-2ED13-2E8-2D11-D12-12A16-2B448-ED11-E11-3D6-3D15-6A471-2ED7-2E14-8D152-
