model
size = 30 32 26, scale = 0.05, origin = -y
material deform = 1, fade = true, lighting = smooth, roughness = 0.3, metalness = 0.6
  colors = A:#FF6A1A B:#717171 C:#FFF D:#000 E:#E75C17 F:#CFCFCF G:#B34512 H:#EDEDED I:#F5590C J:#D15315
voxels
550-2(4C2D4C20-)10C861-H6AH22-8A22-5AE2A23-6A861-HA8-AH2(18-2A8-2A)20-2(8A22-)8A23-2AE3A769-2A12-2A14-AI12-2A14-2A12-2A16-2(2A8-2A18-)11AE18-9AI2A21-6A738-H16-H12-A16-I12-A16-E13-2A12-AE14-EA12-2A14-4A8-4A15-3A8-3A18-10A20-10A21-2AE5A676-2(A18-A10-)A18-A11-2(2A14-2A12-)3(3A12-)3A13-5A6-5A15-4A6-4A17-E11A20-5AE2A23-6A615-HA20-2A7-A20-A8-A20-A9-2(2A16-2A10-)3A14-3A11-2A14-2A12-4A10-3AI13-3A10-3A15-4A6-4A17-2(3AI)4A19-8AIA583-G22-H6-2A20-2A7-A20-A8-A20-A9-2(A18-A10-)2A16-2A11-A16-A2(12-2A14-2A)13-E2A10-3A15-4A6-4A17-12A21-E5A525-F22-F4(6-A22-A)7-A20-A8-A20-E8-2A18-2A9-A18-A11-2(2A14-2A12-)3A12-3A13-3A10-2AE15-4A6-4A18-10A22-AI4A464-H24-G5-4(A22-A6-)I22-I7-2(A20-A8-)2A18-2A9-A18-A10-2A16-2A11-A16-A12-2A14-2A2(12-3A)13-4A8-4A16-3A6-3A20-7AE433-G24-H4-A24-A5-A22-A6-A22-A5-2(A24-A4-)A24-A5-A22-A6-A22-A7-A20-A8-A20-A9-2A16-2A10-2A16-2A11-2A14-2A12-2AI12-3A13-3A10-I2A16-2A8-AI19-10A372-H24-G4-F24-F2(4-A24-A)5-A22-A6-A22-A5-2(A24-A4-)A24-A5-A22-A6-A22-A7-2(A20-A8-)EA18-2A9-A18-A10-2A16-2A11-2A14-2A11-G3A12-3AG10-2G-2A10-2A-2G14-4A4-4A22-4A315-G24-H2(4-A24-A)4-2A22-2A4-A24-A5-A22-A6-A22-A5-2(A24-A4-)A24-A5-2(A22-A6-)2A20-2A7-A20-A2(8-2A18-2A)9-2A16-2A10-3A14-3A9-GF3A12-3AFG8-G2FJ2A10-2AJ2FG8-G2J2-3A6-E2A2-2JG16-6A283-F26-F3-3(A24-A4-)2A22-2A4-A24-A5-A22-A5-2A22-2A3(4-A24-A)5-2(A22-A6-)2A20-2A7-A20-A2(8-2A18-2A)8-3A16-3A8-J3A14-3AJ8-J-3A12-3A-J7-JF3-2A10-2A3-FJ6-JF4-3A6-3A4-FJ6-2J7-2AE3A7-2J4-D26-D-3D24-3D-D26-D32-F26-F2-F26-F62-H26-G3-4(A24-A4-)4(2A22-2A4-)2(A24-A4-)A24-A5-A22-A6-E22-A6-2A20-AI7-A20-A8-IA18-2A8-2A18-2A8-3A16-3A9-3A14-3A11-3A12-3A14-2A10-2A17-3A6-3A21-6A12-3D2(24-6D)24-3D-F26-F62-F26-F2-H26-G3-5(A24-A4-)2A22-2A5-A22-A6-A22-A5-2A22-2A3(4-A24-A)5-2(A22-A6-)2A20-2A7-A20-A8-2A18-2A8-2A18-AE9-2A16-2A10-2AI14-3A11-3A12-3A14-2A10-2A17-3A6-3A21-6A13-D26-D-3D24-3D-D26-D152-G26-H3-F24-F3(4-A24-A)4-2A22-2A5-2(A22-A6-)A22-A5-A24-E2(4-A24-A)5-A22-A6-A22-A7-2(A20-A8-)2A18-2A9-A18-A10-2A16-2A11-2A14-2A2(12-3A)14-2A10-2A17-4A4-4A22-4A315-H24-G5-2(A22-A6-)2A20-2A7-A20-A7-A22-A6-A22-A5-2(A24-A4-)A24-A5-E22-A6-A22-A7-A20-A8-A20-A9-2A16-2A10-IA16-2A11-2A14-2A2(12-3A)13-3A10-3A16-2A8-AI19-AE6A2E373-G22-H8(6-A22-A)7-2(A20-A8-)2A18-2A9-A18-A10-2A16-2A11-A16-A12-2A14-2A2(12-3A)13-4A8-4A16-3A6-3A20-8A404-H22-G6-F22-F7-A20-A8-A20-A7-3(A22-A6-)A22-A7-2(A20-A8-)2A18-2A9-A18-A11-2(2A14-2A12-)E2A12-2AE13-3A10-3A15-4A6-4A18-10A22-E3AIA466-G20-H5(8-A20-A)9-2(A18-A10-)2A16-2A11-A16-A2(12-2A14-2A)13-3A10-3A15-4A6-4A17-12A21-6A526-H20-G8-F20-F8-AB18-BH2(8-AB18-BA)9-2(2A16-2A10-)3A14-3A11-2A14-2A12-4A10-4A13-3A10-3A15-4A6-4A17-12A19-9AI615-HB16-BH2(10-AB16-BA)11-CAB12-BAC12-2AB12-B2A2(12-3A2B8-2B3A)13-5A6B4AE15-4A2B2-2B4A17-12A20-E2AE4A23-3AE2A618-2(A2B12-2BA12-)A2B12-2BA13-2(2C2B8-2B2C14-)AC2A8B2ACA15-ACA8BACA17-AI8CIA19-10A21-6AIA678-AC2B8-2BCA2(14-2C2B8-2B2C)16-2(2C8B2C18-)12C19-10A20-10A739-2(2C8B2C18-)2C8B2C19-CD2C2A2CDC20-3C4A3C22-6A282-
