model
size = 23 30 23, scale = 0.05, origin = -y
material deform = 1, fade = true, lighting = smooth, roughness = 0.3, metalness = 0.6
  colors = A:#444 B:#888 C:#222 D:#111
voxels
97-12(13A10-)6AD6A9(10-5ACBC5A)193-18(A13-A8-)A12-2A2(8-2A12-A)8-6ACBC5A10-5ACBC5A168-18(2A15-2A4-)3A14-2A3(4-3A13-3A)4-3A2-3ACBC8A7-5ACBC5A144-18(A19-A2-)A18-2A2-2A17-2A3-2(A17-A4-)A17-A5-7ACBC7A8-5ACBC5A121-21(A19-A2-)A19-A3-A17-A5-A15-A7-6ACBC6A120-21(A19-A2-)A19-A3-A17-A5-A15-A7-6ACBC6A9-5ACBC5A75-22(A19-A2-)A19-A3-A17-A5-A15-A7-A13-A9-5ACBC5A75-21(A19-A2-)2A18-A2-A19-A3-A17-A5-A15-A7-A13-A9-5ACBC5A75-12(A19-A2-)A19-A-2B19-4B19-2B-6(A19-A2-)2A18-A2-A19-A3-A17-A5-A15-A7-A13-A9-5ACBC5A51-2A12(19-4A)19-2A-A19-A-2B19-2B-2(A19-A2-)A19-A-2A19-4A19-2A-2(A19-A2-)2A18-A2-A19-A3-A17-A5-2A14-A7-A13-A9-5ACBC5A51-2B12(19-4B)19-2B-A19-A-2B19-2B2A19-2A2B3(19-4B)19-2B2A19-2A-A19-A2-2A18-A2-A19-A3-A17-A5-2A14-A7-2A12-A9-5ACBC5A51-2B12(19-4B)19-2B-A19-A-2B19-2B2A19-2A2B3(19-4B)19-2B2A19-2A-A19-A2-2A18-A2-A19-A3-A17-A5-2A14-A7-A12-2A9-5ACBC5A28-2A13(19-4A)19-2A-A19-A-2B19-2B-2(A19-A2-)A19-A-2A19-4A19-2A-3(A19-A2-)A19-A3-A17-A5-A15-A7-A13-A9-5ACBC5A30-13(A17-A4-)A17-A3-A19-A-2B19-4B19-2B-7(A19-A2-)A19-A3-A17-A5-2A14-A7-A13-A9-5ACBC5A29-18(A19-A2-)3(C19-C2-)3(A19-A2-)A19-A3-A17-A5-2A14-A7-A13-A9-5ACBC5A29-5(A19-A2-)A-A17-12(A2-A19-)A2-C19-C2-D19-D2-C19-C4(2-A19-A)3-A17-A5-2A14-A7-6ACBC6A9-5ACBC5A8-10(2A14-3A2-A-)2A14-3A2(2-A)14-3A2-A18-2A6(2-A19-A)2-C19-C2-D19-D2-C19-C4(2-A19-A)3-A17-A5-A4-3A3-2A3-A7-6ACBC6A28-5A9(12-2(A2-)2A2-A)12-2(A2-)A-3A12-4A8(2-A19-A)2-C19-C2-D19-D2-C19-C2-2A18-3(A2-A19-)A3-2A16-A5-7ACBC7A8-5ACBC5A29-2A2-2A7(10-A3-A2(2-2A))9-2A3-A2-2A2-3A8-2A3-A2(2-2A)10-A3-A2-4AB11-5A6(2-2A18-A)2-A18-2A2-A19-A2-C19-C2-D19-D2-C19-C3(2-A19-A)2-A15-2A2-A3-3A7-A4-4A7-5ACBC5A52-C2A2-2A8-A2-2A6(C2-C5-A8-A4-)C2-C14-A4-C2-C5-A8-A4-C2-C3-2A9-A4-C2-C-3B11-3BAC2-C16-A2(2-C)2(2B15-2BC2-C)2(5B9-5BC2-C)5B9-5BC2(2-3C15-3C)2-2CD14-AD2C2-3D15-3D2-3C15-3C2(2-3A15-3A)3-2A15-2A4-4AC2A2CB2C2AC4A4-8ACBC8A7-5ACBC5A55-2A2-A5-2A-2A12-A5-2A15-A6-A15-B6-A14-B7-A14-A7-A13-AB7-BA11-2A9-A11-A22-A10-A9-3B10-A3B5-2B-B11-4B5-2(3B11-3B6-)3B10-4B5-4B10-B-3B4-4B10-5B6-2(C13-C8-)A13-A7-2D13-2D6-2C13-2C6-2A13-2A7-A13-A8-A13-A9-5ACBC5A103-3A5-3A14-2(A5-A16-)B5-B15-2B5-2B14-2B5-2B13-3B6-2B11-3B7-3B10-3B7-3B9-2(4B7-)4BC7-C4B6-4BC7-C4B8-2(2BC7-C2B10-)B2C7-2CB11-2C7-2C12-2C7-2CB9-2(C13-C8-)D-C11-D8-3D9-3D8-3C9-3C8-2AC9-3A8-2AC10-2A8-2AC2A2C-2C2AC2A10-4ACBC4A106-C5DC9(16-2C3D2C)15-3(3C3D3C14-)3C3D3C13-4C3D4C11-2(5C3D5C10-)4C5D4C10-2C9D2C10-13D11-11D12-11C12-3A2CB2C3A2(12-4ACBC4A)121-
