model
size = 30 29 32, scale = 0.05, origin = -y
material deform = 1, fade = true, lighting = smooth, roughness = 0.3, metalness = 0.6
  colors = A:#050 B:#111 C:#0A0 D:#360 E:#393 F:#0E0 G:#6F3 H:#070 I:#6C0 J:#6C3 K:#3C3 L:#363 M:#0C0 N:#396 O:#9F3 P:#040 Q:#060 R:#0D0 S:#222 T:#9F9 U:#0F6 V:#FF0 W:#0B0 X:#063 Y:#6C9 Z:#6F9 Aa:#0F9 Ab:#3F3 Ac:#093 Ad:#3F6 Ae:#CF6
voxels
-2GCQGQCJAPGJCAQ2L2I2QJAJQH2JLO2JOJ2CD2J2KEO2EOE2K2JD2CJO2JO4JK2JD2J2O6D2O2JD2JK6JO2E5S2O6E2O5S2EO2JEOKOE4BSOKDO2EODKOS4BEOKO2EOKEOBS3B2ED4OD2E3BSBOEKOE2J2DO20BO2D4J2DK20BK2D2JODJDKBS5BS4BS5BSBKDJD2O2YKABS3BS8BS3BSBAK2Y2OAYKYS18BSYKYAOAYJEAS5BS6BS5BSAEJYANYE2Y20B2YEYN2TEDE20BEDE2T2JEDET4D2Y6B2Y4DTEDE2J3T2XTXE4W6B4WEXT2X4TET2XTXT3DE6BE3DTXT2XTET4K4W4T6B4T4W4K2J2K2BS2B2SB2X2D2XB2S2BS2B2K4J2E5B3S2X2D2X3S5B2E2JM2OE8BAa4AbAa8BE2OCEO2E4BS3B2Aa2D2Aa3BS4B2EO5E8BEAa2OCE8B4E2ODE8BEAb2EAbE8BEDCOM2DET2PC3TOEC2XAbEOTGTE2PTEDGME2WDC2WQWGW2GK2X2GXWGWT2WDGWGEA2G2AC2AG2(AC)AGCA3J3(QG)JC2A2GAGA2(QC)A2GC2ACGCJC2A2C2(AJ)2G3A3GCGA3JQC2QCACQCA2GQ2GJAIO2JOJ2CD2J2KEO2EOE2K2JD2CJO2JO4JK2JD2J2O4DLD2O2JD2LK6JO2E5S2O4ELE2O5S2EO2JEOKOE4BSOK2LELODKOS4BEOKH2EOKEOBS3B2ED4OD2E3BSBO2HOE2J2DO9BL10BH2D4J2DK20BKLD2JODJDKBS5BS4BS5BSBKDJD2O2YKABS3BS8BS3BSBAK2Y2OAYKYS18BSYKYAOAYJEAS5BS6BS5BSAEJYANYE2Y20B2YEYN2TEDE20BEDE2T2JEDET4D2Y6B2Y4DTEDELJ3T2XTXE4W6B4WEXT2X4TET2XTXT3DE6BE3DTXT2XTET4K4W4T6B4T4W4KGJ2K2BS2B2SB2X2D2XB2S2BS2B2K4J2E5B3S2X2D2X3S5B2E2JM2OE8BAa4AbAa8BE2OMEO2E4BS3B2Aa2D2Aa3BS4B2EO5E8BEAa2OAaE8B4E2ODE8BEAbLEAbE8BEDLOM2DET2PE3TOEAb2XAbEO3TE2PTELDMEW3D2WTWEWXKDX3IXWEIT2W2D2WEADIADA2D2IA2I2ADAL2HAIA3IA2LA3I2A2DI2A2I2A3H3AHA2D2HD2AG3A2IA3IAID3A4D3AIA2D2HALIALAIAL3A3IA5HL2DI2DL3G3A9C8A9C3A28-AV3(28-2A)28-AV28-AAe2(28-2A)2(28-AN28-NA)3(28-2A)28-AF28-2F28-FM3(28-2M)28-MA28-2A28-60AI31ALH3AL3AH2(2AP)2ALI6A2HIA28-AAc28-A2(V28-F)2(V28-U)V28-NAe28-2A28-AN28-NA5(28-2A)28-AF2(28-2F)28-FA28-AM28-2M28-MA28-2A28-AM28-M29AI60ALA2HAHGAQ2A4G2APAP5A3HAQC2(28-CV)28-UAd28-FV28-FU28-U2(V28-A)C28-2C28-CR28-2R28-RN28-2N28-NA2(28-2A)28-AR28-2R28-RC28-2C28-CZ28-ZA28-2A28-AU28-U30AG58AQLAPHAGAQH5AH4ALPHA2G3AIQA28-AF28-FV28-UAc28-FV28-FA28-AV2(28-2A)28-AU28-2U28-UR28-RA28-2A28-AE28-EA28-2A28-AR28-RU4(28-2U)28-UN28-NF28-F60AG28AQAF2HAHG4ALQ2AH2FALP2(AH)2AI4A26-2A2(V28-A)Ad28-MV28-AAc28-A2(V28-U)A28-AC28-CR28-2R28-RA28-AD28-DE28-EN28-ND28-DR28-2R28-RD28-DA28-AE28-EN28-NE28-2E28-I59AQG28AIAH2AQ3AIA2HQA4LHL2AHAGH2(AI)A28-2A2(28-AV28-NV)28-CV28-2F28-FC28-CA28-AR28-2R28-RA2(28-2A)28-AE28-EA28-AR28-2R28-RA28-AD28-DF28-2F28-FC28-CN28-I91AH2AQA2P5AQ2AF2LAGH2(GA)IAPI2A26-2AM28-MA28-AV28-2A28-AV28-NM28-MF28-FD28-DA28-AC28-CA28-AR28-RA2(28-2A)28-AE28-EA28-AG28-CA28-2A28-AC28-2C28-CF28-FA28-31AG29AG28AIGH2A2HAI2P4AQ3APLA2PG2AI2AP2A26-2AM28-MA28-2A28-AC28-CN28-NF28-FM28-2M28-MA28-2A28-AC28-CA28-2A28-AZ28-ZN28-NA28-AC28-CG28-2A28-AD28-DF28-2F28-FA28-AC28-C59AI31AH2A2HAI2A2P3LQLAL2P2AGAIPALP2A26-2AM28-MV28-MN28-NA28-AN28-NV28-NF28-FA3(28-2A)28-AM28-2M28-MA3(28-2A)28-AN28-NG28-AD28-DA3(28-2A)28-30AI60AG3(HA)IA2LA2P2Q3AP2L2A2GPGAP2A26-2AM28-MV28-KV28-AV28-R2(V28-F)N28-NF28-FA28-AK28-KA28-AR28-2R28-RN28-NR28-2R28-RZ28-ZA28-AG28-AF28-FA28-2A28-AM28-MR28-I29AIG59ALHA2HAIALAH2PG2P5AL2AIA2(P2A)26-2A2(V28-K)A28-AV28-AF2(28-FV)28-2F28-FA28-2A28-AU28-UC28-CR28-RA28-AN28-NC28-CZ28-2Z28-ZA28-AG28-FN28-NA28-AM28-MA28-30AIG28AQ29AGLH2AHAH2I2PQ2ALAPAF2A2HI2AP2AG3A24-3AM28-MV28-2A28-AV28-ND28-DV28-RF28-2F28-FK28-KA28-AU28-UC28-2C28-CZ28-2Z28-ZC28-CA28-2A28-AN28-NG28-2F28-FD28-DM28-MF28-F30AG28AG29AQL2(H2A)2PIQAH2ALAF3QAI3AFAGP3A24-3AV28-MV28-2A28-AV28-AD28-D2(V28-C)K28-KC28-CF28-FU28-UA28-AZ28-ZA28-AN28-NA28-AF28-2F28-FD28-2D28-DG28-CD28-DA28-2A28-30AQG58AQGH3AP2J2A3H2PA2Q2AH2QA2QFAQPMAC24-CAMA2(28-AV)28-CV28-KV28-ZV28-EC28-CF28-FC28-CK28-2K28-KC3(28-2C)28-CN28-NC2(28-2C)28-CF28-FG28-2A28-AD28-DA28-31AG58APL2A2PLHL3AHPIH3A2LHIH3AQAHGM2A24-2AMU28-UA28-AV28-AK28-KV28-DE28-EK2(28-2K)28-KU28-UF28-F2(A28-AC28-C)A28-AF28-FM28-MD28-DE28-EG28-2C28-CM28-MD28-I29A2(IG28A)PLA2L2A2L4AHIH4AHLI6AHGM2A24-2AMU28-UA28-2A28-AK28-KD28-DE28-EK2(28-2K)28-KU28-UF28-F2(A28-AC28-C)A28-AF28-FM28-MD28-DE28-EC28-CG28-CM28-MD28-D89APH6AL3AHAI5AH3I2AG3AGMAC24-CAMA28-2A28-AC28-CK28-KZ28-ZE28-EC28-CF28-FC28-CK28-2K28-KC3(28-2C)28-CN28-NC2(28-2C)28-CF28-FA28-AG28-AD28-DA28-AG29AG58APHIAP3ALH2AFI2AHGAHA2HLALGIQ2G3A24-3AM28-MA2(28-2A)28-AD28-DC28-2C28-CK28-KC28-CF28-FU28-UA28-AZ28-ZA28-AN28-NA28-AF28-2F28-FD28-2D28-DC28-CD28-DG28-2A28-AG29AG28AI30AH2IPA2HL3HPL3AQG3AHLIPGFGAL3A24-3AM28-MA28-2A28-AN28-ND28-DR28-RF28-2F28-FK28-KA28-AU28-UC28-2C28-CZ28-2Z28-ZC28-CA28-2A28-AN28-NF28-2F28-FD28-DG28-MF28-FG89AQLPI2HAL3APAL2QAFHA2QLAP2GQAL2A26-2AK28-2K28-KA28-2A28-AF3(28-2F)28-FA28-2A28-AU28-UC28-CR28-RA28-AN28-NC28-CZ28-2Z28-ZA28-AF28-FN28-NA28-AG28-MA28-31AG28AI30ALQPA2HALHAIALQ3A4QHLPIAFQ4A26-2AM28-MK28-KA28-AR28-RF28-2F28-FN28-NF28-FA28-AK28-KA28-AR28-2R28-RN28-NR28-2R28-RZ28-ZA28-2A28-AF28-FA28-2A28-AM28-MG28-R59AI29AILPIAH2ALAIA2QF3QG3A2HPIAFQ4A26-2AM28-2M28-MN28-NA28-AN28-2N28-NF28-FA3(28-2A)28-AM28-2M28-MA3(28-2A)28-AN28-NA28-AD28-DA2(28-2A)28-AG28-30AQG28AI30ALPIFH2A2LAPA2QFAG3ALAPI2AQAHI2A26-2AM28-MA28-2A28-AC28-CN28-NF28-FM28-2M28-MA28-2A28-AC28-CA28-2A28-AZ28-ZN28-NA28-AC28-CA28-2A28-AD28-DF28-2F28-FA28-AC28-QG28AI29AQG28AIP2AHFAGPA2LP4AG5AP2A2(HA)I2A26-2AM28-MA2(28-2A)28-AN28-NM28-MF28-FD28-DA28-AC28-CA28-AR28-RA2(28-2A)28-AE28-EA28-AC28-CA28-2A28-AC28-2C28-CF28-FA28-AG28AI29AQG31A2HAGILP2AP3AGQ2A2LPI5HAIA28-2A28-AN28-NA28-AN28-NC28-CF28-2F28-FC28-CA28-AR28-2R28-RA2(28-2A)28-AE28-EA28-AR28-2R28-RA28-AD28-DF28-2F28-FC28-CN28-N29AI2(G29A)2HAHAI2QP2AH3GA3F2LPH3AH2AL2A26-3A28-2A28-AM28-MA28-2A28-AU28-2U28-UA28-AC28-CR28-2R28-RA28-AD28-DE28-EN28-ND28-DR28-2R28-RD28-DA28-AE28-EN28-NE28-2E28-E29AIG58AI3AHAI3AP2GQ2HA3PHALGAQA2GALA28-AF28-FU28-UF28-2F28-FA3(28-2A)28-AU28-2U28-UR28-RA28-2A28-AE28-EA28-2A28-AR28-RU4(28-2U)28-UN28-NF28-F30AG58AIGFAH4IAPAQP2AHP4H2L3GPF2AC28-2C28-CU28-UF28-2F28-FU28-UA28-2A28-AC28-2C28-CR28-2R28-RN28-2N28-NA2(28-2A)28-AR28-2R28-RC28-2C28-CZ28-ZA28-2A28-AU28-U29AI30AG34AH2AHAQIP3H2ALA3PQGQHL3A28-2A28-AF28-2F28-FU28-2U28-UN28-NA28-2A28-AN28-NA5(28-2A)28-AF2(28-2F)28-FA28-AM28-2M28-MA28-2A28-AM28-M29AIG28AIG31A2L5AQAIPH4A2P2ALAG3ALI2A9C8A9C3A8(28-2A)2(28-AN28-NA)3(28-2A)28-AF28-2F28-FM3(28-2M)28-MA28-2A28-31AG28AIG29AGP2ALI4AGAL5AL2A2QG4AIA
