model
size = 16 14 31, scale = 0.05, origin = -y
material deform = 1, fade = true, lighting = smooth, roughness = 0.3, metalness = 0.6
  colors = A:#EEE B:#3CF C:#F90 D:#111 E:#F96 F:#555 G:#AAA H:#F9C I:#F9F
voxels
4-8C8-2B4C2B10-B2CE11-3AE2A10-2AE3A11-2AEA13-EA122-10C6-10B7-8B4(8-8A)9-A-2A-A2(10-6B)12-2B57-12C4-12B5-2B7AB4(6-10A)10-2A-2A7-3B4A3B7-8B9-6B12-2B30-2A8-14C2-14B3-12B4(4-12A)5-10A5-4B5A3B4-4B4A4B5-10B7-8B9-6B12-2B7-16C-5B4C5B2-5B4-5B4(2-5A4-5A)3-2(4A4-)2B2A4-2A2B4-3BA4-A3B2(4-4B)5-3B4-3B7-2B4-2B20-16C5B6C5B-4B6-4B2-B4A4-4AB3(2-5A4-5A)5-2A4-3A5-B3A4-3AB4-2B2A4-2A2B4-3B6-3B4-2B8-2B5-B8-B19-8C2H2(6C5B)-4B6-4B4(2-5A4-5A)3-2(4A4-)B3A4-3AB4-FB2A4-2ABF4-F2B6-2BF2(4-B10-B)18-8C2HI5C5B6C5B-4B6-4B4(2-5A4-5A)3-2(4A4-)B3A4-3AB4-FB2A4-2ABF4-F2B6-2BF2(4-B10-B)18-9C2I5C5B6C5B-4B6-4B2(2-B4A4-4AB)2(2-5A4-5A)5-2A4-3A5-B3A4-3AB4-2B2A4-2A2B4-3B6-3B4-2B8-2B5-B8-B19-16C-5B4C5B2-4B6-4B4(2-5A4-5A)3-2(4A4-)B3A4-3AB4-2B2A4-2A2B5-3B4-3B6-B8-B36-14C2-14B3-3B6-3B8(4-4A)5-3A4-3A7-2A4-2A25-2(6B10-)6B40-C8BC5-3B6-3B4(4-4A)5-3A4-3A6-3A4-3A7-2(2A4-2A8-)G6BG9-6B10-6B56-C5BE2BC6-CB6-BC5-2AB6-B2A5-AB6-BA6-AB6-BA7-2A4-2A9-A4-A9-8B8-D6BD9-D4-D72-C2BEBE3BC6-CB6-BC5-2AB6-B2A5-AB6-BA7-2A4-2A9-A4-A9-2A4-2A8-8B9-6B11-4B12-4D57-C2(BE)4BC6-CB6-BC5-2AB6-B2A5-AB6-BA7-2A4-2A9-A4-A9-2A4-2A8-B-4B-B10-4B89-C8BC5-B3A4-3AB2(4-4A)5-3A4-3A6-3A4-3A7-2A4-2A9-A4-A9-G-4B-G9-D4BD70-5C-2B-5C3-12B4-4A4-3AB4(4-4A)5-3A4-3A6-3A4-3A7-2A4-2A9-6B10-D4BD11-4D55-6C2B6C2-14B3-B10AB3(4-12A)5-10A7-G6AG10-4B87-6C2B6C2-14B2-B12AB2-14A3-12A4-12A6-8A8-D6AD9-D4BD11-4D71-6C2B6C2-14B2-B12AB2(2-14A)4-10A7-8A9-6A11-4B87-6C2B6C2-14B2-B12AB2-14A3-12A5-10A7-8A8-G6AG10-4D87-6C2B6C2-14B2-B12AB3-12A4-12A5-10A7-8A8-D6AD9-D4-D86-6C2B6C2-14B3-B10AB2(4-12A)5-10A7-8A10-4A103-6C2B6C3-12B2(4-12A)5-10A7-8A9-6A119-5C2B5C4-12B4-12A5-10A7-8A9-6A11-4A120-5C2B5C4-12B5-10A7-8A9-6A11-4A136-5C2B5C5-10B7-8A9-6A11-4A13-2A138-4C2B4C7-8B9-6A11-4A13-2A155-3C2B3C9-6B11-4A13-2A172-2C2B2C11-4B13-2A189-4C13-2B199-
