model
size = 32 31 14, scale = 0.05, origin = -y
material deform = 1, fade = true, lighting = smooth, roughness = 0.3, metalness = 0.6
  colors = A:#996 B:#888 C:#444 D:#777 E:#111 F:#222 G:#AAA H:#F69 I:#F6C
voxels
43-10B22-10A20-14A2(18-6ADC6A)2(18-5A2D2C5A)18-4A3D3C4A18-3A3D2A3C3A18-2A3DAFEA3C2A18-A2D2A2F2E2A2CA18-ADA4F4EACA18-2A5F5E2A18-A2D4F4E2CA18-A3D3F3E3CA18-2A3D2F2E3C2A18-2A4DFE4C2A2(18-3A4D4C3A)2(18-4A3D3C4A)2(18-5A2D2C5A)2(18-6ADC6A)18-14A18-6A2B6A18-5AB2-B5A18-4AB4-B4A18-2A2B6-2B2A19-12B27(20-12A)20-5A2B5A20-4AB2-B4A20-3AB4-B3A18-2B2A7-3A2B18(16-4A7-5A)11-5B4A7-5A5B9(6-9A7-10A)7-8A7-9A13-3AB6-B3A17-B3A8-3AB6(16-4A8-4A)15-11(5A8-5A14-)5A8-5A9-B5-4A8-4A5-B4-2A3-5A8-5A3-2A4-3A-6A8-6A-3A4-10A8-10A4-7A-2A8-2A-7A4-6A3-A8-A3-6A4-5A18-5A4-6A3-A8-A3-6A4-7A-2A8-2A-7A4-10A8-10A5-9A8-9A10-4AB8-B4A14-B3A10-3AB9(14-4A10-4A)13-7(5A10-5A12-)5A10-5A15-2(2A10-)B7-2A10-2A7-B2-A7-2A10-2A7-A2-2A5-3A10-3A5-2A2-3A3-A16-A3-3A2-6A18-6A3(2-5A20-5A)2-6A18-6A2-7A16-7A3-9A10-9A7-5AB10-B5A11-B3A12-3AB32(12-4A)2(12-A2-A)15-A12-A9-B30-B2A7-A12-A7-4A28-5A26-8A22-11A20-11A22-11A20-12A20-6A-6A18-6A3-7A14-7A5-6AB12-B6A9-B3A12-3AB30(12-4A)4(12-A2-A)38-B30-BA30-3A28-4A28-6A24-4AG4A22-5AG4A22-10A22-11A20-12A20-6A2-6A16-6A5-6AB12-B6A9-B3A12-3AB30(12-4A)2(12-A2-A)12-A18-A38-B30-BA30-2A30-3A28-2AG2A26-2AG5A22-10A22-5AG4A22-4AG5A22-11A20-6A2-5A18-5A5-6AB12-B6A9-B3A12-3AB32(12-4A)2(12-A2-A)38-B30-BA30-3A28-4A28-2AG3A24-3AG5A22-10A22-5AG4A22-4AG5A22-10A22-5A2-3A2-A16-A2-3A5-6AB12-B6A9-B3A12-3AB32(12-4A)12-2A-A12-A-2A15-A12-A9-B30-B2A7-A12-A7-4A28-5A26-8A22-11A20-5AG5A22-4AG6A20-12A20-13A18-7A2-7A14-7A5-6AB12-B6A10-B2A12-2AB9(14-3A12-3A)13-15(4A12-)4A15-A12-A9-BA7-A12-A7-AB2A7-A12-A7-5A5-2A12-2A5-7A3-A16-A3-11A18-13A2(20-12A)20-13A18-7A-7A16-7A3-8A12-8A7-4AB12-B4A13-B2A10-2AB6(16-3A10-3A)15-2(4A10-4A14-)4A10-4A13-8(5A10-5A12-)5A10-5A7-BA5-3A10-3A5-AB2-3A3-4A10-4A3-3A2-4A-5A10-5A-4A2-10A10-10A2-8A-A10-A-8A2-7A16-7A2-6A18-6A2-7A16-7A2-8A-A10-A-8A3-9A10-9A6-2(7A10-)4AB10-B4A14-B3A8-3AB6(16-4A8-4A)15-11(5A8-5A14-)5A8-5A9-6B4A8-4A6B8(4-10A8-10A)5-2(9A8-)7A8-7A13-3AB8-B3A17-2B10A2B2(18-14A)17-4(16A16-)6A2I8A16-5A2HI8A16-5A2H9A10(16-16A)12-24A7-5(26A6-)12A2B12A2(6-10A)7-9A6-9A10-7A6-7A15-2AB8-B2A9-
