model
size = 28 28 17, scale = 0.05, origin = -y
material deform = 1, fade = true, lighting = smooth, roughness = 0.3, metalness = 0.6
  colors = A:#FF9 B:#EBD15F C:#A8A8A8 D:#5E6E86 E:#ADB57B F:#9C9 G:#8F8F8F H:#6B8F6B I:#6E6E6E J:#B33E3E K:#B32121 L:#B36969
voxels
361-2(C27-)C83-2(C27-)C418-15(2AE25-)2AE333-2(2AE25-)2A12(D25-BA)2(D25-2A)E25-2AE150-2(2A2B)18-2B8-2AB13-2A13-BA10-B17-A8-B19-2B5-A21-2AE2-A22-2AD2-B22-BADK2A22-CADJ2(2A22-CAD-2A22-CADI2A22-CADG)2A22-CAD4(-2A22-CAF)2-B22-BAF2-A22-2AD3-A21-2AE4-B19-2B7-B17-A10-2A13-BA13-2B8-2AB17-2(2A2B)20-2(2A2B)18-2B8-2AB13-2A13-BA10-B17-A8-B19-2B5-A21-2AE2-A22-BAD2-B22-CADJ2A22-CADL2(AB22-CAD-AB22-CADGAB22-CADC)AC22-CAD-AB22-CAF2(-AB22-CAH)-2A22-CAH2-B22-CAF2-A22-BAD3-A21-2AE4-B19-2B7-B17-A10-2A13-BA13-2B8-2AB17-2(2A2B)20-2(2A2B)18-2B8-2AB13-2A13-BA10-B17-A8-B19-2B5-A21-2AE2-A22-BAD2-B22-CAD-2A6(22-CAD-AB)22-CAD-AC22-CAD3(-AB22-CAF)-2A22-CAH2-B22-CAF2-A22-BAD3-A21-2AE4-B19-2B7-B17-A10-2A13-BA13-2B8-2AB17-2(2A2B)20-2(2B2A)18-2A8-2BA13-2B13-AB10-A17-B8-A19-2A5-B21-2AE2-B22-BAD2-A22-CADI2A2(22-CADGAB22-CAD-AB22-CADIAB)22-CADGAC22-CAD3(-AB22-CAF)-2A22-CAF2-A22-CAF2-B22-BAD3-B21-2AE4-A19-2A7-A17-B10-2B13-AB13-2A8-2BA17-2(2B2A)20-2(2A2B)18-2B8-2AB13-2A13-BA10-B17-A8-B19-2B5-A21-2AE2-A22-BAD2-B22-CADG2A2(22-CADCAB22-CAD-AB22-CADGAB)22-CADCAC22-CAD-AB22-CAF2(-AB22-CAH)-2A22-CAH2-B22-CAF2-A22-BAD3-A21-2AE4-B19-2B7-B17-A10-2A13-BA13-2B8-2AB17-2(2A2B)20-2(2B2A)18-2A8-2BA13-2B13-AB10-A17-B8-A19-2A5-B21-2AE2-B22-BAD2-A22-CAD-2A6(22-CAD-AB)22-CAD-AC22-CAD-AB22-CAF-AB22-CAH-AB22-CAF-2A22-CAH2-A22-CAF2-B22-BAD3-B21-2AE4-A19-2A7-A17-B10-2B13-AB13-2A8-2BA17-2(2B2A)20-2(2A2B)18-2B8-2AB13-2A13-BA10-B17-A8-B19-2B5-A21-2AE2-A22-BAD2-B22-CADI2A2(22-CADGAB22-CAD-AB22-CADIAB)22-CADGAC22-CAD-AB22-CAF2(-AB22-CAH)-2A22-CAH2-B22-CAF2-A22-BAD3-A21-2AE4-B19-2B7-B17-A10-2A13-BA13-2B8-2AB17-2(2A2B)20-2(2B2A)18-2A8-2BA13-2B13-AB10-A17-B8-A19-2A5-B21-2AE2-B22-BAD2-A22-CADG2A2(22-CADCAB22-CAD-AB22-CADGAB)22-CADCAC22-CAD3(-AB22-CAF)-2A22-CAF2-A22-CAF2-B22-BAD3-B21-2AE4-A19-2A7-A17-B10-2B13-AB13-2A8-2BA17-2(2B2A)20-2(2A2B)18-2B8-2AB13-2A13-BA10-B17-A8-B19-2B5-A21-2AE2-A22-BAD2-B22-CAD-2A6(22-CAD-AB)22-CAD-AC22-CAD-AB22-CAF2(-AB22-CAH)-2A22-CAH2-B22-CAF2-A22-BAD3-A21-2AE4-B19-2B7-B17-A10-2A13-BA13-2B8-2AB17-2(2A2B)20-2(2A2B)18-2B8-2AB13-2A13-BA10-B17-A8-B19-2B5-A21-2AE2-A22-BAD2-B22-CADI2A2(22-CADGAB22-CAD-AB22-CADIAB)22-CADGAC22-CAD3(-AB22-CAF)-2A22-CAH2-B22-CAF2-A22-BAD3-A21-2AE4-B19-2B7-B17-A10-2A13-BA13-2B8-2AB17-2(2A2B)20-2(2A2B)18-2B8-2AB13-2A13-BA10-B17-A8-B19-2B5-A21-2AE2-A22-2AD2-B22-B3(ADG2A22-CADC2A22-CAD-2A22-C)3(AF-2A22-C)AF2-B22-BAF2-A22-2AD3-A21-2AE4-B19-2B7-B17-A10-2A13-BA13-2B8-2AB17-2(2A2B)175-2(2AE25-)2A12(D25-BA)2(D25-2A)E25-2AE333-15(2AE25-)2AE530-2(C27-)C83-2(C27-)C226-
