model
size = 4 32 12, scale = 0.05, origin = -y
material deform = 1, fade = true, lighting = smooth, roughness = 0.3, metalness = 0.6
  colors = A:#322316 B:#56402C C:#342518 D:#493626 E:#352416 F:#332316 G:#26201A H:#2C1E12 I:#000 J:#533D29 K:#5F4530 L:#5E442F M:#352518 N:#352519 O:#332317 P:#473524 Q:#473525 R:#513C29 S:#4C3827 T:#5D432D U:#362619 V:#352517 W:#523C29 X:#58422F Y:#58412C Z:#292420 Aa:#342417 Ab:#453323 Ac:#56402D Ad:#57402C Ae:#4A3726 Af:#5C432E Ag:#5C4430 Ah:#312215 Ai:#362519 Aj:#5C432D Ak:#2B2622 Al:#563F2B Am:#533E2B An:#0A0603 Ao:#5E4530 Ap:#3A2A1C Aq:#55402C Ar:#412E1F As:#453324 At:#5D4430 Au:#342418 Av:#2F2114 Aw:#564130 Ax:#55402D Ay:#523E2A Az:#523D2B Ba:#4E3A28 Bb:#342317 Bc:#39281A Bd:#412F20 Be:#57412D Bf:#443323 Bg:#57422E Bh:#352618 Bi:#3F2E1F Bj:#503C2A Bk:#533F2D Bl:#59422D Bm:#58412E Bn:#503C2C Bo:#644C37 Bp:#5D442D Bq:#322215 Br:#2C1E11 Bs:#2D1F12 Bt:#2E1F12 Bu:#302013 Bv:#322214 Bw:#322F2C Bx:#35312E By:#323130 Bz:#32312F Ca:#010100 Cb:#302215 Cc:#48443F Cd:#46413C Ce:#322C27 Cf:#553F2C Cg:#563F2A Ch:#56412D Ci:#513C28 Cj:#5B432F Ck:#4D3927 Cl:#281D13 Cm:#5B422E Cn:#3C2A1C Co:#1E150D Cp:#221910 Cq:#19120C Cr:#19130D Cs:#56402B Ct:#3A291C Cu:#3A291B Cv:#5B4533 Cw:#36281C Cx:#57412C Cy:#33261B Cz:#5B4634 Da:#38271A Db:#382719 Dc:#3F2D1E Dd:#57412F De:#3D2C1D Df:#39291B Dg:#362719 Dh:#362618 Di:#5A422D Dj:#5A422E Dk:#5E4631 Dl:#604631 Dm:#614732 Dn:#5F4732 Do:#443324 Dp:#5D442E Dq:#604630 Dr:#5E442E Ds:#140E08 Dt:#1A120A Du:#302114 Dv:#2F2013 Dw:#2F2113 Dx:#2E2013 Dy:#302113 Dz:#322216 Ea:#312114 Eb:#312214 Ec:#565656 Ed:#505050 Ee:#4D4D4D Ef:#515151 Eg:#2A241E Eh:#2C251E Ei:#17100A Ej:#1B130B Ek:#2F2014 El:#2F2115 Em:#332418 En:#312315 Eo:#37261A Ep:#543D29 Eq:#5A412B Er:#40372F Es:#393027 Et:#413C37 Eu:#4A4744 Ev:#46433F Ew:#30271E Ex:#251B11 Ey:#261C12 Ez:#302B25 Fa:#2C2620 Fb:#140F0A Fc:#130E09 Fd:#1B1612 Fe:#181410 Ff:#4B3828 Fg:#4B3727 Fh:#2F2721 Fi:#4E3A2B Fj:#5A4431 Fk:#483525 Fl:#56412E Fm:#4F3C2B Fn:#4B3826 Fo:#543E29 Fp:#553F2B Fq:#4F3A26 Fr:#513D2A Fs:#523C2A Ft:#4E3A27 Fu:#2E2116 Fv:#1F160E Fw:#59412B Fx:#58412D Fy:#58402C Fz:#37271A Ga:#402D1E Gb:#3E2C1D Gc:#322315
voxels
8-AgEoFEAgUFEAtAi2(OEAoU)FEFsCDzE100-AqMGcEAqMBvERMBvEFtVEbEAzAaEaEBaFBuE100-BdAuAAsAqAuAAsCx2-AeR2-AeAm2-SAz2-SFrFBuBiBaAhBtBi12-FkAuAhDbBnMOCuFgNAaBc72-RMOAsCs2-Dk2(R2-Af)2(Ck2-Y)Ch2-BjChAvBtBj2(AeAvBrBf)FnAhDvBcAmADuDcX2-CvAwCBqDAwCBqV68-RMOArY2-DlEp2-LW2-LJ2-BlW2-BlJ2-BFp2-2B2-BgB2-BgAz2-BeAm2-2Ac2-CwAw2-DAEkHAp53-Ee7-Ec6-AlAiBbGaAl2-K2(W2-L)Fu2-YAn2-Y2(J2-B)Fo2(2-BP)2-BeAm2-QAb2(2IDCe)2-CqAEiDsCo4ACA2-5(C3-)Z3-A7-2(2A2-)EtBy2-AAk2-ErBw3-A2-FyUBbAr2(T2-K)Fw2-LCl2-BAn2-BJ2-BFq2-BP2-2(B3-)DAb2-DAbCaI2(DG2-)QG2-VG-2AHA2-2(G3-H3-)H3-Z3-Fd3-Fb3-EzA2-ExEg2-EuBy2-CcAk2-CcBw2-2A2-FxUBbGb2(Bp2-K)Eq2-LFv2-AdAn2-AdJ2-BCi2-BP2-2(B3-)DP2-DAbCaI2(DG2-)QG2-VG-2AHA2-2(G3-H3-)H3-Z3-Fe3-Fc3-FaA2-EyEh2-EvBz2-CdAk2-CdBx2-2A2-CmAiAaArDr2(2-KT)2-LCl2-DiAn2-AdJ2-BCi2-BCg2(2-BP)2-XAy2-QAb2IDFh2IDZ2-CrAEjDtCpC3ACA2-5(C3-)Z3-A7-2(2A2-)EwBz2-HAk2-EsBx3-A2-CmNOCnDq2-DmT2-KT2-LJ2-DjW2-AdJ2-AcCg2-Ac2(Al2-X)Ay2-XAy2-DdAx2-CyAx2-QAElHAp53-Ef7-Ed6-BoNAaCnDp2-Dn2(Aj2-Ag)2(Aj2-Bm)Af2-BkAfEnDxBk2(CfCbBsBh)BaFDwDgFlEmFDeFj2-CzAxNFQFfUAV68-BdMFFzBoNFDo2(At2-S)2(Ao2-S)CjAaAhApCjADyDh12-FmNFDfBnNFDaFiAiOCt72-
