model
size = 22 25 15, scale = 0.05, origin = -y
material deform = 1, fade = true, lighting = smooth, roughness = 0.3, metalness = 0.6
  colors = A:#1D2455
voxels
221-2(20A2-)20A3-18A5-16A6-16A356-20A-44A-2(20A2-)20A3-18A4-18A5-2(16A6-)16A7-2(14A8-)14A9-12A72-2(9A2-)20A-88A-20A2-20A-44A-4(20A2-)20A3-18A5-3(16A6-)16A7-14A8-14A9-12A12-8A15-6A9-2(9A2-)20A-88A-20A2-20A-44A-5(20A2-)20A3-2(18A4-)18A5-2(16A6-)16A7-14A9-12A11-10A7-2(9A2-)20A-88A-20A2-20A-44A-5(20A2-)20A3-3(18A4-)18A5-2(16A6-)16A7-14A9-12A6-7(2(9A2-)20A-88A-20A2-20A-44A-5(20A2-)20A3-3(18A4-)18A5-2(16A6-)16A7-14A8-14A5-)2(9A2-)20A-88A-20A2-20A-44A-5(20A2-)20A3-3(18A4-)18A5-2(16A6-)16A7-14A8-14A36-2A10-9A3(-2A-18A)-2A-9A10-2(2A20-)2A11-4(8A-2A-8A2-)8A-2A-8A11-2A20-2A12-3(18A4-)18A5-2(16A6-)16A7-14A8-14A366-3(2A20-)2A13-2(16A6-)16A47-
