model
size = 18 12 18, scale = 0.05, origin = -y
material deform = 1, fade = true, lighting = smooth, roughness = 0.3, metalness = 0.6
  colors = A:#005 B:#004 C:#00B
voxels
23-8B190-8B207-10B205-12B9-4(6A12-)6C4(12-6A)12-6C26-2(4B6-)4(2A6-2A8-)2C6-2C4(8-2A6-2A)8-2C6-2C10-6A7-3B10-3B4-4(A10-A6-)C10-C4(6-A10-A)6-C10-C7-10A4-4B10-4B3-4(A10-A6-)C10-C4(6-A10-A)6-C10-C7-10A4-6(3B12-3B2-4(A12-A4-)C12-C4(4-A12-A)4-C12-C5-12A3-)4B10-4B3-4(A10-A6-)C10-C4(6-A10-A)6-C10-C7-10A5-3B10-3B4-4(A10-A6-)C10-C4(6-A10-A)6-C10-C7-10A2(6-4B)2(6-2A)3(8-2A6-2A)8-2C6-2C4(8-2A6-2A)8-2C6-2C10-6A9-12B9-4(6A12-)6C4(12-6A)12-6C28-10B202-
