model
size = 21 32 3, scale = 0.05, origin = -y
material deform = 1, fade = true, lighting = smooth, roughness = 0.3, metalness = 0.6
  colors = A:#500 B:#D00 C:#FC9 D:#FFF E:#111 F:#633
voxels
9-11(3C18-)3C33-15A5-17A3-19A-210A-19A2-19A3-17A5-15A7-13A9-11A14-CFC8(18-3C)17-5C15-7C12-11C9-E11BE7-E13BE5-E15BE3-E17BE-E9(19B2E)19BE-E17BE2-E17BE3-E15BE5-E13BE7-E11BE9-11E14-11(3C18-)3C33-15A5-17A3-6A3DA3D6A-7A3DA3D14A3DA3D32A2(3D18A)3D39A2(3D18A)3D14A-19A2-6A3DA3D6A3-5A3DA3D5A5-4A3DA3D4A7-13A9-11A5-
