model
size = 27 11 29, scale = 0.05, origin = -y
material deform = 1, fade = true, lighting = smooth, roughness = 0.3, metalness = 0.6
  colors = A:#00F B:#09F C:#700 D:#D00 E:#066 F:#800 G:#00B H:#033 I:#AAA J:#0F3 K:#001 L:#FF9 M:#060 N:#FC9 O:#F6F P:#FC6 Q:#FCF R:#A00 S:#500 T:#633 U:#600 V:#222 W:#CC6 X:#630 Y:#FF3 Z:#FF6 Aa:#B00 Ab:#FF0 Ac:#60F Ad:#609 Ae:#603 Af:#111 Ag:#010 Ah:#0B0
voxels
18-E-E24-T-T2(24-E-E)24-3E25-D26-D-B22-B3DB24-B25-AGA24-3C212-B397-U-U3(24-R-R)24-3R25-N26-N-B22-B3NB24-B25-AGA24-3S212-B121-T-T3(24-A-A)24-3A25-Y26-Y-B22-B3YB24-B25-AGA24-3D212-B101-Ac-Ac3(24-C-C)24-3C25-P26-P-B22-I3PB24-B25-AGA24-3K212-I393-T-T24-Ac-Ac2(24-D-D)24-3D25-J26-J-B22-B3JB24-B25-AGA24-3V34-Ad-Ad3(24-H-H)24-3H25-O26-O-B12-B9-B3OB24-B25-AGA24-3Af212-B697-C-C8-X-X3(13-C-C8-A-A)13-3C8-3A14-Z10-N15-Z-I8-N-B11-B3ZI6-B3NB13-B10-B14-AGA8-AGA13-3K8-3V7-4(E-E24-)3E25-Aa26-Aa-I22-B3AaB-B10-B11-B25-AGA24-3S212-B115-U-U3-X-X3(18-A-A3-F-F)18-3A3-FLF19-J5-L20-J-B3-L-B16-B3JB-B3LB18-B5-B19-AGA3-AGA18-3W3-3C9-Ad-Ad3(24-H-H)24-3H25-L26-L-I22-B3LB4-B5-B13-B25-AGA24-3C45-Ae-Ae3(24-C-C)24-3C25-Q26-Q2(-B)20-I3QB24-B25-AGA24-3Ag212-B96-4(A-A24-)3A25-J26-J-I22-I3JI24-I25-AGA24-3F212-I101-X-X3(11-M-M10-A-A)11-M-M10-3A11-3M11-O13-P12-O-B11-P-I8-B3OB9-I3PI10-B13-I2(11-AGA)10-3K11-3S16-T-T3(24-A-A)24-3A25-Q26-Q-B16-B5-B3QB3-I20-B25-AGA24-3K38-Ae-Ae3(24-A-A)24-3A25-D26-D-B8-B13-B3DB24-B25-AGA24-3W18-U-U3(24-F-F)24-3F25-Ab26-Ab-B22-B3AbB-B22-B25-AGA24-3Ah212-B91-
