model
size = 32 31 29, scale = 0.05, origin = -y
material deform = 1, fade = true, lighting = smooth, roughness = 0.3, metalness = 0.6
  colors = A:#C31518 B:#1ABAFF
voxels
296-3A10-3A15-3(5A8-5A14-)5A8-5A15-3A10-3A751-5A8-5A13-7A6-7A11-6(9A4-9A10-)9A4-9A11-7A6-7A12-7A6-7A13-5A8-5A15-3A10-3A526-8A4-8A11-10A2-10A9-24A8-24A7-5(26A6-)26A7-4(24A8-)24A9-10A2-10A12-6A6-6A14-6A6-6A15-4B8-4B16-4B8-4B334-9A2-9A11-22A9-24A7-26A6-26A5-7(28A4-)28A5-3(26A6-)26A7-24A9-22A11-20B12-20B13-18B15-7B2-7B17-4B6-4B207-9A2-9A11-22A9-24A7-26A5-13(28A4-)28A5-26A7-24A2(8-24B)9-22B10-22B11-20B14-16B18-12B20-12B82-7A2-7A12-24A8-24A7-26A5-3(3A22-3A4-)3A22-3A3-4(4A22-4A2-)4A22-4A3-7(3A22-3A4-)3A22-3A5-2(5B16-5B6-)5B16-5B7-7B10-7B8-2(7B10-)5B10-5B13-4B10-4B14-4B10-4B75-24A7-26A6-26A5-3A22-3A4-2A24-2A3-7(3A24-3A2-)4(2A26-2A2-)2A26-2A3-4(A26-A4-)4B20-4B4-4B20-4B5-3B20-3B6-5B16-5B7-4B16-4B8-4B16-4B9-3B16-3B10-3B16-3B43-9A2-9A10-24A7-26A5-2(2A24-2A4-)2A24-2A3-2(2A26-2A2-)2A26-2A-3A3(26-6A)26-3A-6(2A26-2A2-)2A26-2A3-2(A26-A4-)2(3B22-3B4-)3B22-3B5-3B20-3B6-3B20-3B7-2(2B20-2B8-)2B20-2B42-20A10-24A133-2A26-2A2-2A26-2A-3A6(26-6A)26-3A-6(2A26-2A2-)2A26-2A3-3(2B24-2B4-)3B22-3B5-2B22-2B6-2B22-2B7-B22-B8-B22-B12-16A14-20A230-2A8(28-4A)28-2A-5(A28-A2-)3B24-3B3-2(2B24-2B4-)3B22-3B4-3B22-3B5-2(2B22-2B6-)2B22-2B11-16A14-20A262-2A8(28-4A)28-2A-4(A28-A2-)2(2B26-2B2-2B26-2B3-B26-B3(4-2B24-2B)5-B24-B6-B24-B11-16A328-2A8(28-4A)28-2A-3(A28-A2-))2(2B26-2B2-)2B26-2B3-4(2B24-2B4-)2B24-2B10-16A328-2A9(28-4A)2(28-2A-2(A28-A2-)2(2B26-2B2-)2B26-2B3-4(B26-B4-)B26-B12-12A362-2A8(28-4A))28-2A-2(A28-A2-)2(2B26-2B2-)2B26-2B3-4(B26-B4-)B26-B13-10A363-2A8(28-4A)28-2A-2(A28-A2-)2B26-2B2-2B26-2B3-5(B26-B4-)B26-B13-10A363-2A7(28-4A)28-2A-3(A28-A2-)2B26-2B2-2B26-2B3-B26-B5(4-2B24-2B)13-10A22-10A331-2A6(28-4A)28-2A-4(A28-A2-)2B26-2B3-2(B26-B4-)2(2B24-2B4-)2B24-2B5-B24-B6-B24-B46-10A299-2A6(28-4A)28-2A-5(A28-A2-)2B26-2B3-2(B26-B4-)2(2B24-2B4-)2B24-2B5-B24-B6-B24-B46-10A299-2A28-5A4(26-6A)26-3A-5(2A26-2A2-)2A26-2A3-3(2B24-2B4-)3B22-3B4-3B22-3B5-2(2B22-2B6-)2B22-2B46-10A22-10A236-10(2A26-2A2-)2A26-2A3-2(A26-A4-)3(2B24-2B4-)3B22-3B5-2B22-2B6-2B22-2B7-B22-B8-B22-B47-10A22-10A21-12A204-13(2A24-2A4-)3B22-3B4-3B22-3B5-2B22-2B3(6-3B20-3B)7-2B20-2B8-2B20-2B79-10A21-12A20-12A19-14A17-3A10-3A15-2(3A12-)3A16-3A8-14(2A22-2A6-)3(5B16-5B6-)5B16-5B7-4B16-4B8-4B16-4B9-3B16-3B10-3B16-3B81-8A23-10A21-12A19-14A17-16A15-18A12-22A9-2(8A8-)7A10-7A8-4A16-4A11(8-3A18-3A)2(8-7B10-7B)9-3(6B10-)6B11-5B10-5B12-5B10-5B13-4B10-4B14-4B10-4B115-8A23-10A21-12A18-16A15-18A13-5(20A12-)6A8-6A12-5A10-5A2(12-4A)7(12-3A14-3A)12-20B13-18B14-18B15-16B17-14B18-14B19-12B20-12B151-6A25-8A23-10A21-12A19-14A17-10(16A16-)16A17-2(14A18-)14A19-12B20-12B21-10B23-8B314-4A27-6A25-8A23-10A21-9(12A20-)12A21-10A23-8A570-4A27-6A25-4(8A24-)8A25-6A26-6A493-
