model
size = 25 6 26, scale = 0.05, origin = -y
material deform = 1, fade = true, lighting = smooth, roughness = 0.3, metalness = 0.6
  colors = A:#0F6 B:#3F9 C:#F0F D:#F63 E:#FF3 F:#0F9 G:#66F H:#39F I:#0FF J:#F9F K:#FCF L:#FF6 M:#FF0 N:#F90 O:#F93
voxels
61-2C22-C2-C21-C2-C22-2C46-7B18-7A116-11B14-11A112-4B7-4B10-4A7-4A109-3B11-3B8-3A11-3A107-3B13-3B6-3A13-3A105-3B15-3B4-3A15-3A104-2B17-2B4-2A17-2A103-2B19-2B2-2A19-2A102-2B19-2B2-2A19-2A101-6(2B21-2B2A21-2A100-)2B21-2B2A21-2A101-2B19-2B2-2A19-2A102-2B19-2B2-2A19-2A103-2B17-2B4-2A17-2A104-3B15-2BF4-3A15-3A105-3B13-2BF6-3A13-3A107-3B10-F3B8-3A10-4A83-2D12-2E8-K2DK2B6-2FG2EG6-2D2G2DA6-AEF2N2E5-2D2G2D8-EM2OME6-K2DK10-G2EG8-2D12-2E34-2I-8B2F-2H8-I2-I-8A-H2-H7-I2-I10-H2-H8-2I12-2H41-2C22-J2BJ20-2C2L2C19-2C2L2C20-J2CJ22-2C12-
