model
size = 13 22 16, scale = 0.05, origin = -y
material deform = 1, fade = true, lighting = smooth, roughness = 0.3, metalness = 0.6
  colors = A:#FF0 B:#080 C:#E00
voxels
251-5A36-4(B12-)B298-B12-B298-B285-B12-B127-5A166-B12-B99-9A177-B12-B85-11A189-B12-B72-11A202-2(B12-)B45-13A227-2(B12-)B19-13A5-2(3C10-)3C219-B12-B6-6A-6A5-2(C-C10-)C-C239-13A5-2(3C10-)3C239-13A274-11A275-11A276-9A41-
