model
size = 26 31 26, scale = 0.05, origin = -y
material deform = 1, fade = true, lighting = smooth, roughness = 0.3, metalness = 0.6
  colors = A:#BBB B:#888 C:#09F D:#F90
voxels
36-5B20-7D747-8B17-9B17-2B-3B-2B745-9B16-B9CB15-B2(DC)A2(CD)2B14-B-7D-2B16-2(7D19-)7D20-5D22-3D342-B250-7B16-B2AC5AC3B12-2B3C2A-2A4CB11-2B2DC2A-3A2DCB11-2B-D3A-3AD-2B11-B2-DC2A-3AD17-DC5ACD17-2D5A2D17-3DCAC3D18-7D21-3D251-2B10-3B11-2B10-BCB11-2B10-3B247-3A5-3B13-2AC2A5-2ACAB10-B3C2A6-A3CB9-B2CDA7-AB2CB9-B3D2A6-A4B11-2D2A5-2A2B14-DCA5-AC2B14-DC3A-3ACB16-D2C3A2CD18-2D3C3D19-5D224-2B10-3B10-BCB10-A2CB9-3B10-4B271-2A9-2A11-BACA9-ACAB8-B3CA9-A3CB7-BD2CA9-A2CDB7-B-DCA9-ACD11-2DCA7-2ACD12-DCA7-AC2D13-DC2A3-2AC2D14-2DC5A2CD16-2D5C2D19-5D151-5B20-7B19-7B14-3B2-7B-4B9-3B2-7B-4B14-7B20-5B250-2A11-2A9-BACA11-AC2B7-B2CA11-A3CB6-BDCA11-AC2D9-DCA10-ACD10-DCA9-ACD11-2DCA7-A2CD12-D2CA5-A2CD14-D2C5A2CD16-3D4C2D20-4D73-5A19-9A17-9A16-4A3-4A14-4A5-4A11-2BC3A5-2A2CB10-2BC3A5-2A2CB12-5A3-5A15-9A18-7A20-5A224-A13-A9-B2A13-3AB5-B2CA13-A2CB5-B2DCA12-ACDB6-2DCA11-AC2DB7-D2CA9-A2CD10-D2CA7-A2CD12-D2C2A3-2A2CD14-2DC5AC2D17-6AD20-5A20-7A18-9A16-AC2A3-2ACA14-3A7-3A13-3A7-3A12-3(ACA9-ACA11-)AC2A7-2ACA12-4A5-4A14-4A3-4A16-2AC3AC2A19-5A223-A15-A7-B2A15-2AB4-B3CA14-A2CB3-BD2CA13-A2CDB5-D2CA11-2ACD8-D2CA9-2ACD10-D2CA7-A2CD12-D2CA5-A2CD14-D2A5-3A16-2A5-2A17-2A5-2A16-ACA5-ACA14-ACA7-ACA13-2A9-ACA10(11-2A)12-2A9-ACA12-ACA7-ACA14-AC2A3-2ACA16-2AC3AC2A19-5A222-2A15-2A5-BACA15-ACAB3-B2CA15-A3CB2-BD2CA14-AC2DB4-DC2A12-ACD8-D2CA9-2AC2D9-D2CA7-A2C2D11-DCA7-ACD14-2A7-2A15-2A7-2A14-ACA7-ACA12-ACA9-ACA3(11-2A)12-A11-3(A13-AB10-)2A12-A2(11-2A)11-ACA9-ACA12-ACA7-ACA14-AC2A3-2ACA16-9A245-2A17-2A3-BACA17-ACAB-B3CA16-ACDB-B2DCA15-ACD-B4-DC2A12-A2CD7-D2CA9-2AC2D9-2DA9-ACD13-A9-2A13-2A9-2A12-ACA9-ACA2(11-2A)11-3(A13-AB9-B)A14-2(B9-BA13-A)B10-A13-AB10-2A11-2A12-2A9-ACA12-3A7-3A15-9A19-5B245-B2A19-2DB-B2CA18-A2C2BDCA17-ACDB3-DCA15-ACD6-2D2A11-2A2D9-DA11-AD12-A11-A13-A11-A12-2(2A11-)2(A13-AB9-B)A14-3(B9-B15-)B9-BA14-B9-BA13-AB10-2A12-A2(11-2A)12-3A7-3A14-4A3-4A17-7B270-B2A19-3D2B2CA17-A3C2BD2CA16-ACDB2-3DC2A11-3A3D6-2DA11-A2D2(11-A)13-A11-A12-2A11-2A10-BA13-AB9-BA14-5(B9-B15-)B9-B2(A13-AB10-)2A11-2A12-2A9-2A14-3A5-3A17-8B295-B2A18-3AB-B2CA17-A2CB-BCDC3A11-3AC2D3-D-3DA11-A3D10-A11-A13-A3(11-2A)10-BA13-A6(B9-B15-)B9-BA14-B9-BA13-AB10-2A11-2A12-2A9-3A13-3A6-2A16-9B270-2A19-2A2-BCA18-A2CB-B2CA17-A2CB-B2DC3A11-3AC2DB2-D-3DA11-A3D10-A11-A13-A11-A12-2A11-2A10-BA13-AB9-B15-B9-B2(A14-B8-BC)A14-AB7-BC3(A13-ACB8-B)A13-AB10-2A11-ACB11-2A9-3A13-3A5-3A16-2B5A2B19-5B221-A19-A3-BACA18-3A2B2CA17-A3C2BD2CA15-AC2DB3-3D2A11-2A2D9-DA11-AD12-A11-A13-A11-A12-2A11-2A10-2(BA13-AB9-)BA14-B8-3(BCA13-ACB7-)BCA13-ACB8-BA13-ACB9-A13-AB10-2A11-2A12-2A9-ACA13-12A16-A5CA19-7B219-B2A17-3AB-B3CA16-A2CB-BD2CA15-AC2DB3-D2CA13-A2CD6-2DC2A10-AC2D9-DCA10-AD12-2A10-A13-2A10-A12-ACA10-2(2A11-)2A10-2(BA13-AB9-)3(BA13-ACB8-)BA12-ACB9-BA12-ACB10-2A11-ACB10-ACA9-ACA12-ACA7-ACA14-11A17-B5CB20-5B194-B2A17-2AB3-B2CA16-ACB3-B2CA15-ACDB3-BD2CA13-ACD7-D2CA11-A2CD8-2DCA9-AC2D11-2A9-2A14-A9-A15-A9-2A13-2A9-2A12-3(2A11-)2A10-2(BCA12-AB9-)2(BCA11-ACB9-)BA12-2(ACB10-2A11-)2A12-2A9-2A14-11A16-A7CA18-7B194-3A15-3A2(B3-B2CA15-A2C)B3-B2DCA13-A2CDB5-D2CA11-A2CD8-D2CA9-A2CD10-2DCA7-2A2D13-2A7-2A16-A7-2A15-2A7-ACA13-ACA7-ACA13-3A8-2A12-2A2(11-2A10-BCA)3(11-ACB9-BCA)11-ACB10-ACA10-2A12-2A9-2A13-AC3A4-3A15-2A2C4ACA18-A5CA20-5B170-2A15-2A5-BACA15-ACAB3-B3CA13-A3CB3-B2DCA13-A2CDB6-DCA11-A2CD8-D2CA9-A2CD10-D2C2A5-2A2CD12-2DCA5-A2CD15-2A5-3A17-A5-ACA15-3A5-ACA15-2A6-A2CA13-ACA7-ACA13-2A2(9-2A12-ACA)10-2AB10-2A11-ACB9-B2CA10-2A10-BACA9-ACA12-ACA7-3A14-3A5-3A15-2AC5ACA18-A5CA19-7A170-2B13-2A7-BACA13-ACAB5-B2CA13-A2CB5-B2DCA11-A2CDB5-B2DC2A9-2AC2D9-DC2A7-2A2CD10-2DC2A5-2A2CD12-2D2C2A-2A3CD15-DC7AD17-7A19-8A16-8AC2A15-2A6-ACA14-ACA7-ACA13-2A2(9-2A12-ACA)10-2AB10-2A11-ACB9-B2CA10-2A11-ACA9-3A12-ACA7-2A15-ACA5-2A17-AC6A19-A4C2A20-5A122-B10-B12-3A10-2A9-2BC2A10-ACAB7-B2CA11-A2CDB6-B2D2A9-2A3D9-DCA9-AC2D10-D2CA7-A2CD12-D2CA5-A2C2D13-D2C5A2C2D15-D3CA2C3D17-2(6A20-)AC2ACA19-3A2-3A17-3A5-2A15-3A7-2A14-2A9-A14-2A9-2A12-2A11-A12-3(2A11-)A13-2A8-2A15-2A6-2A17-2A4-2A19-6A21-4A23-3A98-B7-B14-3BA7-A3B10-B3CA7-2A2CB9-B3CA7-2A2CDB8-3B2A7-2AC2D11-BCA7-ACB13-BC2A6-ACB13-2BCA5-AC2B14-B2C2A-2A2CB16-2B2CA3CB18-7B72-4B22-B2-B21-B4-B19-B6-B17-B8-B16-B8-B15-2(B10-B14-)B10-B15-B8-B17-B6-B19-B4-B21-4B126-2B2-B18-3B2A2-A4B12-2B2C2A4-A3CB11-D3CA5-A3CD11-2D2CA5-A3CD13-DCA5-AC3D13-2D2A3-2ACD15-2DC2A-3A2D16-DC5ACD17-3DCAC3D19-6D539-7B16-3B3C2A2C3B13-B4C4A3CB13-5B3A5B13-4B5A5B14-2B5A2B18-BC3AC2B18-7B19-7B21-3B566-9B16-BD7CDB15-11D19-3D22-2(5D21-)5D635-
