model
size = 30 8 19, scale = 0.05, origin = -y
material deform = 1, fade = true, lighting = smooth, roughness = 0.3, metalness = 0.6
  colors = A:#001 B:#9CF C:#EEE D:#111
voxels
91-4(A26-A2-)A26-A92-4(A26-A2-)A26-A119-2(A2-D26-)2(A2-A26-)A149-A2-D2(26-A2-A)3(26-A182-A26-A2-A)26-A152-D29-A26-A2-A26-A122-3(A26-A2-)3(A26-A92-4(A26-A2-))A26-A92-2(A26-A2-)D2(26-A2-A)3(26-A92-4(A26-A2-)A)26-A4-9A6-9A5-11A4-11A3-13A2-13A3-12A2-13A3(3-27A)2-28A4-9B6-9B5-11B4-11B3-2(13B2-)A12B2-13B3(A-A27B)A-28A4-9A6-9A5-11A4-11A3-4ACAC6A2-4ACAC6A-4ACAC7A2-3ACAC7A-3ACAC12ACAC8A2(-29A)31-
