model
size = 30 13 6, scale = 0.05, origin = -y
material deform = 1, fade = true, lighting = smooth, roughness = 0.3, metalness = 0.6
  colors = A:#EEE
voxels
133-3A26-4(5A25-)5A26-3A177-3A26-4(5A25-)5A26-3A137-2A19-4A5-5A14-6A4-8A3-3A5-7A4-26A4-27A2-28A3-2(26A4-)7A4-3A5-7A4-5A16-5A4-2A21-3A34-5A18-3A4-7A14-6A2-10A11-7A2-10A-4A2-11A2-119A-28A2-10A2-3A2-11A2-9A9-10A2-7A14-7A2-4A19-5A3-5A18-2A5-7A14-6A2-10A11-7A2-11A-3A2-11A2-119A-28A2-10A2-3A2-11A2-9A9-10A2-7A14-7A2-4A19-5A34-2A19-4A5-5A14-6A5-7A3-3A5-7A5-25A5-26A2-A-26A4-2(25A5-)6A4-3A5-7A5-4A16-5A5-A21-3A32-
