model
size = 23 31 12, scale = 0.05, origin = -y
material deform = 1, fade = true, lighting = smooth, roughness = 0.3, metalness = 0.6
  colors = A:#E00 B:#D00 C:#222 D:#111 E:#400 F:#BBB G:#700 H:#EEE
voxels
333-A22-B540-A22-10(B21-BA21-A)185-B19-A2-A19-A-10(BA19-AB2A19-2A)BA19-AB-A19-A141-B17-A3-2A17-2A2-BA17-2A-10(3A17-3AB2A17-2AB)3A17-3A-2A17-2A3-A17-A97-B15-A5-2A15-2A3-8(B2A15-2AB2-3A15-3A2-)B2A16-A3(B2-3A15-3A2-B2A15-2A)B2-3A15-3A3-2A15-2A53-A11-A9-BA11-2A7-3A11-3A5-3(B3A11-3AB4-4A11-4A4-)B3A11-3AB4-E3A11-3AE4-C3A11-3AC2(4-4A11-4A4-B3A11-3AB)4-4A11-4A4-4A11-3AB4-4A11-4A4-B2A13-2AB4-A17-A4-B3A11-3AB4-4A11-4A4-E3A11-3AE4-C3A11-3AC4-4A11-3AB4-4A11-4A4-B3A11-3AB4-4A11-4A32-A7-A12-3A7-3A9-B3A7-4A8-2(4A7-)2(AB3A7-3ABA6-B4A7-4AB6-)AB12-ABA6-B4A7-4AB6-AB3A7-3ABA6-BE3A7-3AEB6-EC3A7-3ACE6-C4A7-4AC2(6-AB3A7-3ABA6-B4A7-4AB)6-AB3A7-3ABA6-BG3A7-3AGB6-HF13-FH29-CD3A7-3ADC6-B4A7-4AB6-AB3A7-3ABA6-EC3A7-3ACE6-CB3A7-4AC6-B4A7-4AB6-AB3A7-3ABA6-B4A7-4AB12-5A16-9A13-AB7ABA11-2(AB9ABA10-BAB7ABAB10-)AEGA5-AGEA10-BHF7-FHB10-H11-H10-FHF7AFHF10-EGE7AEGE10-CDC3A-3ACDC10-AB2A5-2ABA10-2(BA)5-2(AB)10-AB3A3-3ABA10-BAB3A-3ABAB10-AB4A-4ABA10-BAB3A-3ABAB10-AGE7AEGA10-FHF7AFHF13-7A17-5A14-CDC7ACDC10-BAB7ABAB10-GBC7ACBG10-DCB7ABCD2(10-AB9ABA10-BAB7ABAB)14-BADAB17-BABCBAB16-ABCDCBA16-BADCDAB16-A2(DC)DA16-B2(GE)GB16-G2(FH)FG16-F5-H62-3(HF)H16-CDC-CDC16-3(AB)A16-B5-B16-A5-A16-BA3-AB16-ABA-ABA16-B2A-2AB16-ABA-ABA16-B6A16-GE3AEG16-F2(AB)AF18-3A18-D2(AB)AD16-G2(BA)BG16-DABCBAD16-ABADABA16-B2(CD)CB16-ABADABA16-BABCBAB16-3(AB)A316-A3-A18-B3-B19-B-2(B20-3A20-BA)B20-ABA21-A527-B-B20-A-A21-2(A22-B22-)A573-B-B20-3A21-A22-B22-A310-
