model
size = 23 32 24, scale = 0.05, origin = -y
material deform = 1, fade = true, lighting = smooth, roughness = 0.3, metalness = 0.6
  colors = A:#FCFCFC B:#FC0000 C:#C40000 D:#DAD45E
voxels
516-3D19-2(5D18-)5D19-3D19-2B-2B17-2B3-2B14-2B7-2B52-71A19-2A644-71A19-3A21-2A21-3A19-2A-3(A19-A2-)A19-A484-70A3(21B2A)21BA-4(A19BA2-)A19CA3-2(A17-A4-)A17-A393-70A3(21-2A)21-A-4(A19-A2-)A19-A3-3(A17BA4-)A17C3(A4-A17-)A602-3(A17-A4-)3(A17BA4-)A17CA5-2(A15-A6-)A15-A603-2(A17-A4-)A17-A5-3(A15BA6-)A15CA7-3(A13-A8-)A13-A9-3(13A10-)13A491-2(A15-A6-)A15-A7-3(A13BA8-)A13BA9-3(13A10-)13A584-2(A13-A8-)A13-A9-3(A11BA10-)A11-A677-AB9-BA10-2AB7-B2A10-A11BA701-B9-B12-2B7-2B725-2B7-2B724-3B7-3B722-3B9-3B3(721-2B11-2B)698-2B11-2B8-2(2B11-2B698-)2B11-2B8-2B11-2B698-2B11-2B699-B11-B10-B11-B700-2B9-2B723-2B9-2B74-
