model
size = 30 17 12, scale = 0.05, origin = -y
material deform = 1, fade = true, lighting = smooth, roughness = 0.3, metalness = 0.6
  colors = A:#EEE B:#FFF C:#CE3925 D:#BBB E:#777977 F:#AAA G:#DCDCDC H:#444 I:#E3E3E3 J:#B6B6B6
voxels
34-I2(FJ)2F5(AI)FJ2FAI7-A2F2(JF)11AFJ3A7-2A2FJF2A9-4A10-6A11-2A12-4A27-2A180-A2(29-H)84-A2(FJ)2F5(IA)FJ2FIA7-A2F2(JF)11AFJ3A7-2A2FJF2A9-4A10-6A11-2A12-4A27-2A180-A2(29-H)113-IG6C10G4C2GI5-10A12B3A6-23C7-F6C2E5F2E7C7-2E4C4E5F2E4C9-D2E2C2ED3E2FE2F2E2C10-2D4E3DE-3FEF15-6DCD3-5F15-4DCD5-2F18-5D27-2D88-H29-H81-IAG8BE6BE8BA2-4A22B2A3-2C23AC4-2FA22-C4-2EA20-3E4-DCA19-3E5-DCA9-D5-D5E6-D2C5A-2A3D3-AFH10-D3C6A5DAHF12-D4C5A3DH2F14-2DCE3C2A3DF17-2D2CE3C2DFH19-2D4C3D22-2DC5D23-2D-2(DH)26-3D49-A3BE4GEG2B6EB2G2E2GE2BIA-A25B2A-C26AC2-FA25-C2-EA25-E2-EA24-2D2-EA18-3C4D3-EA16-2C3H7-EA14-2C2H10-EA12-2C2H12-EA11-C2H14-E10-2CH26-C2H27-2(CH28-)C48-IBCE2G2B2GE4(GB)2(2GB)2GCB2A28BAC5AC2A2(CA)2(3CA)C2A3C2ACF28-CEA27-EFA26-ADEA23-4D-FA20-2DH5-EA18-DH8-FA16-DH11-E14-DH13-E11-ADH15-E9-CAH27-CD28-CH28-C29-C18-ABC2GB2EB2G3(BE)B2GBE2BEBGCBIA28B4A2(2CA)C3A2(2C2A)C2ACAC2A2(CF28-)EF28-DF24-4D-F21-2DH5-F19-DH8-F17-DH10-C15-DH12-F12-A2D15-E9-CAH17-D9-AD28-AH28-C29-C18-IBC2GB2EB2G3(BE)B2GBE2BEBGCB2A28B4A2CACA2CA2(C3A)CAC2A3C2A2(CF28-)EF28-DF24-4D-F21-2DH5-F19-DH8-F17-DH10-C15-DH12-F12-A2D15-E9-CAH17-D9-AD28-AH28-C29-C18-ABCE2G2B2GE4(GB)2(2GB)2GCBIA28BAC5AC2A2(CA)2(3CA)2C2(AC)2ACF28-CEA27-EFA26-ADEA23-4D-FA20-2DH5-EA18-DH8-FA16-DH11-E14-DH13-E11-ADH15-E9-CAH27-CD28-CH28-C29-C18-I3BE4GEG2B6EB2G2E2GE2B2A-A25B2A-C26AC2-FA25-C2-EA25-E2-EA24-2D2-EA18-3C4D3-EA16-2C3H7-EA14-2C2H10-EA12-2C2H12-EA11-C2H14-E10-2CH26-C2H27-2(CH28-)C49-AI9BE6BE8BI2-4A22B2A3-2C23AC4-2FA22-C4-2EA20-3E4-DCA19-3E5-DCA9-D5-D5E6-D2C5A-2A3D3-AFH10-D3C6A5DAHF12-D4C5A3DH2F14-2DCF3C2A3DF17-2D2CF3C2DFH19-2D4C3D22-2DC5D23-2D-2(DH)26-3D52-AG6C10G4C2GA5-10A12B3A6-23C7-F6C2E5F2E7C7-2E4C4E5F2E4C9-D2E2C2ED3E2FE2F2E2C10-2D4E3DE-3FEF15-6DCD3-5F15-4DCD5-2F18-5D27-2D88-H29-H80-
