model
size = 27 27 24, scale = 0.05, origin = -y
material deform = 1, fade = true, lighting = smooth, roughness = 0.3, metalness = 0.6
  colors = A:#639 B:#222 C:#555 D:#111 E:#5A2C87 F:#777 G:#7138AB H:#BBB I:#888 J:#444 K:#DDD L:#AAA M:#CC3
voxels
99-A28-A51-A-2A23-A908-B2(25-2B)24-2(2B25-)2B24-3B24-2B25-2B132-A24-3AE3A4-2A2-2A-A8-2(3A24-)3A13-A9-2A142-2(2B24-3B24-)2(2B24-)3B24-3(2B25-)2B24-2B25-2B131-4A-EA-AE4A-2A9-10A2(2-3A)5-7A6-A2-3A8-7A6-9A5-5AEG9-A-6A3-E6A9-2AE4A4-5A16-E2A6-AE16-A43-2B24-3B2(24-2B)24-3B24-2B342-3AE12AG4A7-17A-2A6-11AE3A2(-A)7-G2(9A-)3A3-10A-A2-9A-A2-10A-A2-AG9A2-AE5A2-A7-7A6-4A4-2B8-3A14-2(2B25-)2B447-2A3-6AG2A-A2-GA5-5A-10A-A2-2A5-17A4-A5-25A2-27A-25A2-7A5-3A2-8A2-G6A2-6B3-A-2A7-AEA4-6B3-A-EA16-2B474-2A-A4-A-5A2-3A7-3A-16A-A4-21A-2A3-24A3-2(25A2-)9A3-2A2-8A4-6A-8B7A5-2A-3A-8B3-4A12-8B469-A2(-2A)E2A3-4A-5A4-AE23A2-25A2-21A-3A2-2(G20A-4A-)10A-A-2A2-4A-4A2-7A10B-2A-3A5-4A-10B-4AE11-10B17-10B18-8B19-8C391-A-12A-5A4-2A-21A4-E23A3-20A-2A4-20A-4A-21A-4A2-9A2-3A3-3A-4A3-7A9B2(-2A)5-7A9B-3AGA11-3(10B17-)10C18-8B364-A-8AE-2A-6A4-2(24A3-)25A2-E24A2-25A2-8A3-A5-8A3-6A10B-6A4-6A10B2-5A10-3(10B17-)10C17-2B6C2B18-8B20-6B311-3A-2A2(-A)2-2A-2AG2-A4-20A2-2A3-20A2-2A-A3(-20A2-4A)2-8A8-3A2-2A4-E6A9B-2A2-2A5-2A-A-10B2-E3A11-10B17-D8BD17-10B17-10C17-2B6C2B17-10B18-8B20-6B22-4F23-4D229-A-A2-4A2-A-A3-6A2(4-23A)4-25A2-E24A2-9A-15A3-8A8-8A3-E7A6B2H7A5-A-4A9B3-2AE11-3(10B17-)10C17-2B6C2B17-D8BD2(17-10B)18-8F20-6D21-6B201-A-7A6-A-3A2-2A2-25A2-G23A3-26A2-26A-25A2-9A7-9A3-8A6-2H2-5A4-3AE3AB2(2-2B)2-A14-2(4B2I4B17-)10B17-10C17-DB6CBD3(17-10B)18-8F19-8D19-8B20-2(6B21-)6B22-4B96-7A-G2-9A7-21A4-2(24A3-)25A2-8A-16A2-9A6-9A4-7AH6-2H6A5-7AB6-2B-3AG12-2B6-2B17-D8-D17-D3B2I3BD17-4B2I4B2(17-10B)17-D8BD17-10B17-10F18-8D3(19-8B)20-2(6B21-)2B2-2B2(21-2C2-2C)13-A2E4AEA3-4A-4A4-12A-10A4-2(24A3-)25A2-G7A2-16A2-8A3-A4-9A3-7AH2-A3-H7A6-6A9-6A119-4B2I4B3(17-10B)17-10F17-B8DB18-4(8B19-)2(C6BC19-)CK4BKC19-CK4-KC11-11A-2AG3A-2A6-21A-A4-21A-2A2(3-24A)3-15A-8A3-8A2-4A3-7A4-6A2C2-3A-2C-5A5-6A2C6-2C-4A10-2A2C2(6-2C17-DC)6-2C17-DJ6-JD17-2B6-2B3(17-2D6-2D)17-10D17-B8DB18-4(8B19-)8B20-6B22-4B41-4A-4AE-9A7-20A-2A4-23A3-24A3-2(25A2-)8A-6A-9A3-E6AC2-3A-2C-5A6-3A-2AC3-A2-2C6A11-AC2(6-2C17-2C)6-2C17-2J6-2J17-DB6-BD3(17-2D6-2D)47-4B22-6B20-3(8B19-)8B20-6B22-4B43-2A3-3A-4AG-AGA8-20A7-22A3-23A4-E22A4-14A-11A-13A3-9A3-7AH2-3A-2H6A5-2AG2A-2C6-2C-AG2A12-2C6-2C237-2B23-2B2L2B20-BH4BHB19-2(2BD)2B19-2(2BM)2B19-8B21-4B67-A-4A3-7A2-5A5-23A4-21A6-2(22A5-)22A-A2-23AE5-12A-9A5-4A5-2A5-5A336-H6-H150-3A-A2-5A-6A5-22A4-23A4-24A3-25A-26A3-23A5-22A7-5A-3A3-4AG3A361-H8-H123-2A2-A4-3AG3A5-A-A2-17A5-22A3(2-A3-16A2-3A)2-A4-15A2-3A2-A7-20A9-E4AE10AE495-4A-2A2-6A10-8AG8A8-4A-E13A8-3(17A10-)AGA2-E11A-A3-2A13-13A11-AG7A-AEA-A496-EA8-3A14-2A-2A4-4A16-3A3-5A9-6A3-E-A-6A8-G8A2EA-6A8-A-4AG6A-5A-A13-6A-7A-A16-8A-2A13-2(2A3-)A558-A2-A-3A17-E-A2-7A8-A-A6-A2-E-5A10-A4-4A-G7A14-A-A2-4AGAEA543-
