model
size = 32 13 26, scale = 0.05, origin = -y
material deform = 1, fade = true, lighting = smooth, roughness = 0.3, metalness = 0.6
  colors = A:#FC6400 B:#101010 C:#ECECEC
voxels
42-7A25-7A26-5A28-3A283-7A25-7A26-5A28-3A313-2(2B6A3B21-)3B5A2B23-8B25-6B28-3B246-2(3B11A2B16-)3B10A3B17-3B8A3B19-3B6A4B19-5B3A5B20-11B24-5B180-2(B16AB14-)B16AB15-B14AB16-2B13AB17-B12AB19-B10A2B20-3B5A2B24-6B148-3(B17AB13-)B16AB14-B16AB15-B14AB17-2B11AB20-B9AB21-2B6A2B24-6B115-B19A4B8-B19AB11-B19AB12-2(B17AB13-)B16AB15-B14AB17-2B11AB20-B9AB21-3B5A2B25-5B82-B21A4B6-B20AB10-B20A2(B11-B19A)B11-B18A2B12-B16A2B14-B14AB17-2B11AB19-B10A2B20-11B78-B23A4B4-B22AB9-2(B21A10-)B21A11-B20A11-B18A2B12-B16AB15-B14AB17-B12AB19-5B3A5B24-3B50-B24A4B3-B23A8-B23A9-2(B21A10-)B21A11-B20A12-B17AB13-B16AB15-2B13AB18-3B6A4B22-6B49-B25A4B2-2(B23A8-)B22AC9-B21A10-B20AC11-B20A12-B18A13-B16AB15-B14AB17-3B8A3B21-8B47-B27A5B25A6-B24AC7-B23A8-B22AC9-B21A10-B20AC11-B20A12-B18A13-B16AB15-3B10A3B19-3B5A2B25-5B16-B28A4B25A6-B24AC7-B23A8-B22AC8-B22A10-B20AC11-B20A12-B18A13-B17A15-3B11A2B19-2B6A3B23-6B16-B28A4B24AC6-B24AC7-B23A8-B22AC8-B22A10-B20AC11-B19AC12-B18A13-B17A15-3B11A2B19-2B6A3B23-6B16-B28A4B25A6-B24AC7-B23A8-B22AC8-B22A10-B20AC11-B20A12-B18A13-B17A15-3B11A2B19-2B6A3B23-6B16-B28A4B24AC6-B24AC7-B23A8-B22AC9-B21A10-B20AC11-B19AC12-B18A13-B17A15-3B10A3B19-3B5A2B25-5B16-B27A5B25A6-B23A2C7-B22AC8-B22AC9-B20AC10-2B19AC12-B19A12-B18A13-2B14A2B16-2B10A2B20-4B3A3B26-3B18-B25A4B2-B23A8-B22AC8-B23A9-B21A10-B21A11-B19AC12-B18A13-B16AB15-B14AB17-3B8A3B21-8B48-B24A4B3-B23A8-B23A9-2(B21A10-)B21A11-B20A12-B17AB13-2B14A2B15-2B13AB18-3B6A4B22-6B50-B21A5B5-B20AB10-B21A3(11-B20A)12-B17AB14-B14A2B16-B12AB19-B11AB20-11B80-B20A4B7-2(B19AB11-)B19AB12-2(B17AB13-)B16AB15-B14AB17-2B11AB20-B8A2B22-8B82-B20A3B8-B19AB11-B19AB12-2(B17AB13-)B16AB15-B14AB17-2B11AB20-B9AB21-3B5A2B25-5B84-B16A3B12-2(B16A2B13-)2B14A2B14-3B13A2B15-2B13AB17-2B11AB20-3B5A3B21-10B24-6B117-B14A2(B16-2B13A)B17-2B2(11AB19-B)10A2B20-3B5A3B24-5B182-2B2(11AB19-B)10A2B20-B8A2B21-2B6A3B21-4B3A3B24-6B216-2(2B6A3B21-)3B5A2B23-8B25-6B28-3B241-
