model
size = 26 18 32, scale = 0.05, origin = -y
material deform = 1, fade = true, lighting = smooth, roughness = 0.3, metalness = 0.6
  colors = A:#16361E B:#858585 C:#947F59 D:#968767 E:#48D6C3 F:#44D8B8 G:#46D2B8 H:#39DFBB I:#0C2910
voxels
35-2(8C18-)2(8A18-)8A19-6A21-4A279-2(10C16-)10A16-4A2D4A17-3A2D3A18-3A2D3A19-2A2D2A2(20-2D2-2D)251-12C14-C10BC4(14-12A)14-5A2H5A15-2(2A2H)2A18-2D2A2D124-6A20-6C20-6A11-2F20-2F33-14C12-C12BC6(12-14A)13-12A15-10A69-8A2(18-A6-A)11-E2(6-A)6-E2-GFE20-EFG-E22-E6-16C10-C14BC6(10-4AB6DB4A)11-A3-6D3-A13-12A42-8A18-A6-A10-F7-A6-A7-F3-H5-A8-A5-H3-2FE4-A8-A4-E2F-GFE20-EFG-E22-E6-16C10-C4B6D4BC3(10-4AD6-D4A)10-D3AD6-D3AD2(10-4AD6-D4A)11-A2-D6-D2-A13-12A17-6A19-A6-A18-A6-A10-FE20-EF3-H20-H3-2FE18-E2F-GFE20-EFG-E22-E6-16C10-C4B6D4BC2(10-4AD6-D4A)2(10-D3AD6-D3AD)2(10-4AD6-D4A)11-A2-D6-D2-A13-3A6-3A16-A6-A18-A6-A10-E22-E2-F2E18-2EF3-H20-H3-2FE18-E2F-GFE20-EFG-E22-E6-16C10-C4B6D4BC10-4AD6-D4A3(10-D3AD6-D3AD)2(10-4AD6-D4A)11-A2-D6-D2-A13-3A6-3A15-A8-A16-A8-A9-2E20-2E-GF2E18-2EFG2-H20-H2-G2FE18-E2F2GFE20-EFG-E22-E6-16C10-C4B6D4BC5(10-4AD6-D4A)11-3AD6-D3A12-A2-D6-D2-A13-3A6-3A8-F6-A8-A6-F3-H5-A8-A5-H3-EF5-A8-A5-FE-GF2E18-2EFG2-H20-H2-G2FE18-E2F2GFE20-EFG-E22-E7-14C12-C3B6D3BC6(12-3AD6-D3A)12-2A-D6-D-2A7-E5-3A6-3A5-E2-FE5-A8-A5-EF3-H5-A8-A5-H3-EF5-A8-A5-FE-GF2E18-2EFG2-H20-H2-G2FE18-E2F2GFE20-EFG-E22-E8-12C14-C2B6D2BC7(14-2AD6-D2A)8-2E4-3A6-3A4-2E-GFE5-A8-A5-EFG2-H5-A8-A5-H3-EF5-A8-A5-FE-GF2E18-2EFG2-H20-H2-GF2E18-2EF2GFE20-EFG-E22-E6-16C10-2C3B6D3B2C5(10-4AD6-D4A)11-3AD6-D3A13-2(2A8-)2E2(4-4A)4-2E-GFE2(6-A)6-EFG2-H2(6-A)6-H3-EF20-FE-GF2E18-2EFG2-H20-H2-GF2E18-2EF2GFE20-EFG-E22-E5-18C8-C5B6D5BC2(8-5AD6-D5A)8-2(5AD6-D6A7-)5AD6-D5A8-5AD6-D5A11-4A4F4A8-2E20-2E-GF2E18-2EFG2-H20-H3-EF20-FE-GF2E18-2EFG2-H20-H2-GF2E18-2EF2GFE20-EFG-E22-E4-19C7-C6B6D5BC3(7-6AD6-D5A)7-6AD6-D6A6-6AD6-D5A5-F2-5AD-4B-D5A2-F3-H2-16A2-H3-EF20-FE-GF2E18-2EFG2-H20-H3-2E20-2E-GF2E18-2EFG2-H20-H2-GF2E18-2EF2G2E20-2EG-E22-E4-19C7-C6B6D5BC2(7-6AD6-D5A)7-6AD6-D6A6-6AD6-D6A4-E-6AD-4B-D5A2-E2-FE-5AD-4B-D5A-EF3-H2-16A2-H3-EF3-14A3-FE-GF2E18-2EFG2-H20-H3-2E20-2E-GF2E18-2EFG-EH20-HE-G2E20-2EG-2E20-2E2-E22-E4-20C6-C6B6D6BC6-2(6AD6-D5A7-)6AD6-D6A6-6AD6-D6A4-E-6A8B5A2-E-GFE-5A8B5A-EFG2-H2-16A2-H3-EF3-14A3-FE-GF2E3-12A3-2EFG2-H20-H3-2E20-2E-G3E18-3EG-2E20-2E2(2-E22-E)30-20C6-C6B6D6BC6-2(6AD6-D5A7-)6AD6-D6A6-6AD6-D6A4-E-6A8B5A2-E-GFE-5A8B5A-EFG2-H2-16A2-H3-EF3-14A3-FE-GF2E3-2A2I8A3-2EFG-EH20-HE2(2-2E20-2E)2-E22-E82-20C6-C6B6D6BC6-6AD6-D5A7-6AD6-D2(6A6-6A8B)6A4-E-6A8B5A2-E-GFE-5A8B5A-EFG2-H2-16A2-H3-EF3-14A3-FE2-FE4-A2(I2A)IAI2A4-EF2-EH20-HE2-2E20-2E2-E22-E108-20C6-C6B6D6BC2(6-6AD6-D6A)6-6A8B6A4-E-6A8B6A-E2-E-6A8B6A-E-GFE-5A8B5A-EFG-EH2-16A2-HE2-2E3-14A3-2E2-2E4-4A2(I3A)4-2E2-2E20-2E160-20C6-C18BC6-6A8B6A5-F6A8B5AIF3-EF6A8B6AFE2-E-6A8B5AI-E2-E-6A8B6A-E2-FE-5A8B5A-EF2-EH2-16A2-HE2-EF3-14A3-FE2-E5-3AI2A3(IA)5-E186-20C6-C18BC6-6A8B6A5-F6A8B6AF3-EF6A8B5AIF2(E2-E-6A8B6A-)E2-2E-5A8B5A-2(2E2-)16A2-2E7-14A13-2AI9A192-20C6-C18BC6-6A8B6A5-F6A8B6AF3-EF6A8B5AIF2(E2-E-6A8B6A-)2(E2-)5A8B5A2-E6-16A11-14A13-A2(I2A)4IA192-20C6-C18BC6-6A8B5A7-3(6A8B6A6-)6A8B5A8-5A8B5A9-16A11-14A13-A4I2AI4A192-20C6-C18BC6-3(6A8B5A7-)6A2(8B5A8-5A)8B5A9-16A11-14A13-7A3I2A193-18C8-C16BC6(8-18A)9-16A11-14A13-2AIAI5AIA193-18C8-C16BC6(8-18A)9-16A11-14A13-3AI6AIA193-18C8-C16BC5(8-18A)9-16A10-16A11-14A13-4(AI)2AIA194-16C10-C14BC7(10-16A)11-14A13-8A2I2A194-16C10-C14BC6(10-16A)11-14A12-14A14-10A196-14C12-C12BC7(12-14A)13-12A222-12C14-C10BC6(14-12A)15-10A250-10C16-C8BC5(16-10A)17-8A269-
