model
size = 29 3 29, scale = 0.05, origin = -y
material deform = 1, fade = true, lighting = smooth, roughness = 0.3, metalness = 0.6
  colors = A:#222 B:#555
voxels
11-2(7A22-)7A19-2(4A5-4A16-)4A5-4A14-2(3A11-3A12-)2(3A11-)2(2A15-2A10-)2A15-2A9-2(2A17-2A8-)2A17-2A7-2(2A19-2A6-)2A19-2A5-3(2A21-2A4-)2(A23-A4-)A23-A3-3(2A23-2A2-)5(A25-A2-)A25-A-2A2(25-4A)25-3A14(27-2A)27-3A2(25-4A)25-2A-6(A25-A2-)2(2A23-2A2-)2A23-2A3-3(A23-A4-)2(2A21-2A4-)2A21-2A5-2(2A19-2A6-)2A19-2A7-2(2A17-2A8-)2A17-2A9-2(A16-2A10-)A16-2A9-6A8-5A9-7A8-5A10-6A8-5A15-2(10A19-)10A23-2B26-B2AB26-2B14-
