model
size = 29 3 29, scale = 0.05, origin = -y
material deform = 1, fade = true, lighting = smooth, roughness = 0.3, metalness = 0.6
  colors = A:#222 B:#F0C C:#555
voxels
11-7A22-3(BA)B22-7A19-4A5-4A16-AB2A5-2ABA16-4A5-4A14-3A11-3A12-ABA11-ABA12-2(3A11-)2A15-2A10-BA15-AB10-2A15-2A9-2(2A17-2A8-)2A17-2A7-2A19-2A6-BA19-AB6-2A19-2A5-3(2A21-2A4-)A23-A4-B23-B4-A23-A3-3(2A23-2A2-)A25-A2-B25-B4(2-A25-A)-2A25-2ABA25-AB2A25-3A3(27-2A)27-AB27-BA4(27-2A)27-AB27-BA3(27-2A)27-3A25-2ABA25-AB2A25-2A-4(A25-A2-)B25-B2-A25-A3(2-2A23-2A)3-A23-A4-B23-B4-A23-A3(4-2A21-2A)5-2A19-2A6-BA19-AB6-2A19-2A7-2(2A17-2A8-)2A17-2A9-A16-2A10-B16-AB10-A16-2A9-6A8-5A9-2ABAB2A8-2(AB)A10-6A8-5A15-10A19-AB6ABA19-10A23-2C26-C2AC26-2C14-
