model
size = 31 32 17, scale = 0.05, origin = -y
material deform = 1, fade = true, lighting = smooth, roughness = 0.3, metalness = 0.6
  colors = A:#111 B:#444 C:#888 D:#AAA E:#555 F:#E00 G:#0D0 H:#777
voxels
441-9A5(22-A6-A23-A6-2A)22-A6-A23-9A17-2(B30-)B12-8B10-2B29-9B461-9A4(22-A6EA23-A6E2A)3(22-A6E2A)22-9A91-2B3DC2DCD17-B30-B182-4(9A22-)9A84-7B24-8A23-2(9A22-)4(8A23-9A22-)2(9A22-)8A49-B7-B22-B7-7BCB14-2B6-B22-9B182-5(9A22-)8B54-7B24-8A23-2(9A22-)3(8A16-7B9A15-7B)8A23-3(9A22-)9A56-B30-4BC3DCDC2DCD15-DB30-B151-BDB28-5(9A22-)8B23-6B25-7B24-8A23-2(9A22-)8A16-7B2(9A15-7C8A16-7C)9A15-7B8A23-3(9A22-)8A26-B30-B22-B7-4BD2(C2D)CD2CD7-2B6-B22-9B27-9C2(28-3C)22-9C22-BAB28-7AH23-4(9A22-)8B23-6B25-7B24-8A23-2(9A22-)8A16-7B2(9A15-7C8A16-7C)9A15-7B8A23-3(9A22-)9A25-2(B30-)5BCB24-B22-B7-B64-2A29-3A22-9A22-BAB28-7AH23-4(9A22-)8B23-5BD25-7B24-8A23-2(9A22-)9A15-7B2(8A16-7C9A15-7C)8A16-7B9A22-8A23-2(9A22-)8A26-2(B30-)4B2(2DC)D2(C2D)14-B30-B27-9C2(28-3C)22-9C22-BAB28-7AH23-4(9A22-)8B23-6B25-7B24-8A23-2(9A22-)9A15-7B2(8A16-7C9A15-7C)8A16-7B9A22-8A23-2(9A22-)9A25-B30-B22-B7-4BC2DCD3(C2D)5-B6-DB22-9B64-2A29-3A22-9A22-BAB28-7AH23-4(9A22-)8B23-6B25-7B24-8A23-9A22-8A23-9A15-7B2(8A16-7C9A15-7C)8A16-7B9A22-8A23-2(9A22-)8A26-2(B30-)4B2(DC)2DCDC2DC3D12-B30-B27-9C2(28-3C)22-9C22-BAB28-7AH23-4(9A22-)8B23-6B25-7B24-8A23-9A22-8A23-9A15-7B2(9A15-7C8A16-7C)9A15-7B2(8A23-9A22-)9A25-B30-B22-B7-4BDC2DCD2CD2(C2D)4-2B6-B22-9B95-3A22-9A22-BAB28-7AH23-4(9A22-)8B23-5BD25-7B24-8A23-9A22-8A23-9A15-7B2(9A15-7C8A16-7C)9A15-7B2(8A23-9A22-)8A26-2(B30-)6BC24-B30-B27-9C2(28-3C)22-9C22-BAB28-7AH23-4(9A22-)8B23-6B25-7B24-8A23-9A22-8A23-9A15-7B2(9A15-7C8A16-7C)9A15-7B2(8A23-9A22-)9A48-B7-B22-B7-4B2DCD2(C2D)CDC2D4-2B5-DB22-9B27-8B2(29-2B)23-8B23-BDB28-5(9A22-)8B23-6B25-7B24-8A23-9A22-8A23-9A15-7B7A2E2(15-7B8A16-7B8AE)15-7B2(8A23-8AE22-)9A56-B30-5B2DCD2(C2D)CDC2D11-B30-B182-3(9A22-)7G2A22-9A22-8B54-7B24-2(8A23-9A22-)4(7AE23-9A22-)7AE23-9A91-3BCBC21-B30-B182-9A27-4A22-9A29-2A22-9A84-7B24-8A23-9A22-E5AGA2(23-2A2F2AG2A22-EA2F2AGE)23-2A2F5A2(22-EA2FAGAE23-2A2FAG3A)22-E6AE23-2AEA3E2A17-2(B30-)B12-2B2(DC)2DCDC2DCD3-2B29-9B461-9A23-5A-A2(23-2A2-2A-2A23-A2-2A-E)23-2A2-5A2(23-A2-A-AE23-2A2-A-3A)23-6AE23-2A2(-A)-2A93-2BCD3(C2D)CD978-6B70-
