model
size = 28 28 32, scale = 0.05, origin = -y
material deform = 1, fade = true, lighting = smooth, roughness = 0.3, metalness = 0.6
  colors = A:#F60 B:#630 C:#F90 D:#930 E:#100 F:#E00 G:#EEE H:#D00
voxels
238-A26-A3-A23-A2-A24-A2-A-A22-2(2(A2-)A21-)A2-A-A22-A2-A24-A3-A24-A503-A26-A3-A23-A2-A24-A2-A-A22-2(2(A2-)A21-)A2-A-A22-A2-A24-A3-A24-A474-3A24-6A21-2(8A20-)9A18-11A2(17-9A-A)17-11A18-9A19-8A20-8A21-6A23-4A361-2A24-5A21-3A3-3A18-3A6-3A16-2A3(8-3A14-3A)5(8-4A13-3A)8-3A15-2A8-3A15-3A6-3A17-3A4-3A19-8A302-4A22-3A2-3A18-3A5-4A15-2A8-4A13-2A11-3A2(12-2A)11-2A14-A11-2A14-2A10-5(2A14-2AC9-)2A14-2A11-2A13-2A11-2A12-2A13-2A10-2A15-2A7-3A17-8A248-2A23-3A-4A18-2A8-2A15-A12-2A12-A14-A11-A15-2A9-2A16-2A8-A17-2AC7-A18-C8-5(A27-)A17-2AC7-2A16-2A8-2A16-A10-2A14-2(2A11-)3A14-2A6-3A19-6A218-7A19-2A7-4A13-2A12-2A11-2A14-2A9-2A16-2A7-2A18-2A6-A19-2AC5-A19-2B6-4(A27-)2(A20-C6-)A19-D7-A19-2D6-A19-2A7-A17-A10-A15-2(2A11-)2A15-3A4-5A19-4A189-12A14-2A11-3A11-2A14-2A9-A17-2A7-A19-2A5-A20-A-C4-A20-2B5-4(A27-)A20-2B5-A21-2C4-2(A27-)A20-D6-A21-2D5-A19-2A7-A17-A10-A15-A12-3A9-3A16-10A161-5A18-6A3-5A12-2A14-A10-A16-3A7-A19-2A5-A20-A-C4-A20-AB4-A21-A-B2(3-A22-2B)3-A21-3B3-A21-2B4-A21-3B3-A23-2C2-2(A27-)A28-A27-A21-AD5-A18-2A8-A17-A10-2A12-3A13-5A3-5A19-4A134-10A15-2(3A10-)2A15-2A8-A18-3A5-A20-CA5-A20-C-C3-A21-3C3-A21-2B4-4(A27-)A22-2AC2-A24-C2-A27-2(A22-F4-)A28-A21-AD4-A20-A7-A18-2A8-2A14-2A12-3A8-4A16-8A131-12A13-3A12-2A10-A16-2A8-A18-3A5-A20-A-C3-A21-2B4-A26-3(A27-)2(A23-2B2-)A25-C-A24-E2-A23-E3-A23-H3-A23-E4-A27-A22-3D3-A20-2A6-A18-2A8-A16-2A10-3A3-4A3-3A15-10A129-14A11-3A14-2A8-A17-A-A6-A19-A-A4-A21-C-C2-A22-2B3-3(A27-)A24-C2-A23-2C2-A23-3C-A25-C-A24-E2-A23-GF2-A23-HF2-A23-GE2-A27-A23-3D2-A21-2A5-A20-A7-A18-A9-3A3-7A2-3A13-5A2-5A127-15A11-2A15-2A7-2A17-A-A5-A20-A-AC3-A21-2B3-A22-B-B2-A22-3B4(2-A23-2B)2-A23-2(C-)A23-A2C-A23-2E2(2-A24-G)2-A24-E2-A23-3D-A23-2A3-A22-2A3-A21-A6-2A18-A9-2A3-9A2-2A12-4A6-4A126-16A9-3A15-3A6-A19-2A5-A20-A-AC2-A22-C-C2-A22-2B3-A26-4(A27-)A24-B2CA24-2C-3(A27-)A24-3D-2(A23-2A2-)A23-2AC2-A21-2A5-A8-4A7-A8-3A3-2A4-3A3-2A11-3A8-4A125-16A9-3A15-3A6-A19-A-A4-A20-A2-C2-A22-3C2-A26-3(A27-)A24-2B-A24-BC-A24-C-CA25-C-2(A27-)A24-3DA24-2A-A24-2A2-A23-A-C-A23-2A3-A21-2A5-A7-6A6-2A7-3A2-2A2-2B2-3A2-2A11-2A10-3A124-18A8-2A16-A-A5-2A19-A-A3-A21-A2-C2-A22-2B2-4(A23-3B-)A24-3BA24-2B-A24-2C-A25-2CA27-A24-3D2(A24-2A-)2(A24-A-C)-A23-2A2-A22-2A4-2A6-3A2B3A5-2A7-2A3-A2(2-B)2-2A3-A10-3A4-2B4-4A18-2B54-B26-2B20-18A7-3A16-A-A5-A20-A-A3-A21-A2-C2-A22-3C-5(A27-)A24-B2-A24-C2-A24-2C-A24-3C4(A24-2A-)A24-2A2-A23-2A2-A22-2A4-A7-2A4B2A5-2A6-3A2-2A-B4-B-3A2-A10-2A4-B2-B4-3A17-B2-B25-2B25-3B25-B21-18A7-3A16-A-A5-A20-A-A3-A21-A2-C2-A22-3C-5(A27-)A24-B2-A24-C2-A24-2C-A24-3C4(A24-2A-)A24-2A2-A23-2A2-A22-2A4-A7-2A4B2A5-2A6-3A2-2A-B4-B-3A2-A10-2A4-B2-B4-3A17-B2-B25-2B26-B48-18A8-2A16-A-A5-2A19-A-A3-A21-A2-C2-A22-2B2-4(A23-3B-)A24-3BA24-2B-A24-2C-A25-2CA27-A24-3D2(A24-2A-)2(A24-A-C)-A23-2A2-A22-2A4-2A6-3A2B3A5-2A7-2A3-A2(2-B)2-2A3-A10-3A4-2B4-4A18-2B104-16A9-3A15-3A6-A19-A-A4-A20-A2-C2-A22-3C2-A26-3(A27-)A24-2B-A24-BC-A24-C-CA25-C-2(A27-)A24-3DA24-2A-A24-2A2-A23-A-C-A23-2A3-A21-2A5-A6-7A6-2A7-3A2-2A2-2B2-3A2-2A11-2A10-3A125-16A9-3A15-3A6-A19-2A5-A20-A-AC2-A22-C-C2-A22-2B3-A26-4(A27-)A24-B2CA24-2C-3(A27-)A24-3D-2(A23-2A2-)A23-2AC2-A21-2A5-A6-6A7-A8-3A3-2A4-3A3-2A11-3A8-4A125-15A11-2A15-2A7-2A17-A-A5-A20-A-AC3-A21-2B3-A22-B-B2-A22-3B4(2-A23-2B)2-A23-2(C-)A23-A2C-A23-2E2(2-A24-G)2-A24-E2-A23-3D-A23-2A3-A22-2A3-A21-A6-2A18-A9-2A3-9A2-2A12-4A6-4A127-14A11-3A14-2A8-A17-A-A6-A19-A-A4-A21-C-C2-A22-2B3-3(A27-)A24-C2-A23-2C2-A23-3C-A25-C-A24-E2-A23-GF2-A23-HF2-A23-GE2-A27-A23-3D2-A21-2A5-A20-A7-A18-A9-3A3-7A2-3A13-5A2-5A129-12A13-3A12-2A10-A16-2A8-A18-3A5-A20-A-C3-A21-2B4-A26-3(A27-)2(A23-2B2-)A25-C-A24-E2-A23-E3-A23-H3-A23-E4-A27-A22-3D3-A20-2A6-A18-2A8-A16-2A10-3A3-4A3-3A15-10A131-10A15-2(3A10-)2A15-2A8-A18-3A5-A20-CA5-A20-C-C3-A21-3C3-A21-2B4-4(A27-)A22-2AC2-A24-C2-A27-2(A22-F4-)A28-A21-AD4-A20-A7-A18-2A8-2A14-2A12-3A8-4A16-8A135-5A18-6A3-5A12-2A14-A10-A16-3A7-A19-2A5-A20-A-C4-A20-AB4-A21-A-B2(3-A22-2B)3-A21-3B3-A21-2B4-A21-3B3-A23-2C2-2(A27-)A28-A27-A21-AD5-A18-2A8-A17-A10-2A12-3A13-5A3-5A19-4A161-12A14-2A11-3A11-2A14-2A9-A17-2A7-A19-2A5-A20-A-C4-A20-2B5-4(A27-)A20-2B5-A21-2C4-2(A27-)A20-D6-A21-2D5-A19-2A7-A17-A10-A15-A12-3A9-3A16-10A187-7A19-2A7-4A13-2A12-2A11-2A14-2A9-2A16-2A7-2A18-2A6-A19-2AC5-A19-2B6-4(A27-)2(A20-C6-)A19-D7-A19-2D6-A19-2A7-A17-2A9-A15-2(2A11-)2A15-3A4-5A19-4A194-3A22-9A17-2A8-3A14-A12-2A12-A14-2A10-A16-A9-2A16-2A8-A17-2AC7-A18-C8-5(A27-)A17-2AC7-2A16-2A8-2A16-A10-2A14-2(2A11-)3A14-2A6-3A19-6A248-4A22-3A2-3A18-3A5-4A15-2A8-4A13-2A11-3A2(12-2A)11-2(2A14-2A10-)5(2A14-2AC9-)2A14-2A11-2A13-2A11-2A12-2A13-2A10-2A15-2A7-3A17-8A304-2A24-5A21-3A3-3A18-3A6-3A16-2A3(8-3A14-3A)5(8-4A13-3A)8-3A15-2A8-3A15-3A6-3A17-3A4-3A19-8A386-3A24-6A21-2(8A20-)9A18-11A2(17-9A-A)17-11A18-9A19-8A20-8A21-6A23-4A263-
