model
size = 31 7 31, scale = 0.05, origin = -y
material deform = 1, fade = true, lighting = smooth, roughness = 0.3, metalness = 0.6
  colors = A:#111 B:#888 C:#444
voxels
75-2(B-)B57-2(B-)B118-2(7A21-B-B7AB-B21-)7A83-2(4A5-4A16-B-4A5-4A-B16-)4A5-4A78-4(3A11-3A14-)3A11-3A75-2(2A15-2A11-B2A15-2AB11-)2A15-2A73-4(2A17-2A10-)2A17-2A71-2(2A19-2A7-B2A19-2AB7-)2A19-2A69-4(2A21-2A6-)2A21-2A68-2(A23-A5-BA23-AB5-)A23-A67-4(2A23-2A4-)2A23-2A66-2(A25-A3-BA25-AB3-)A25-A66-4(A25-A4-)A25-A65-2(2A25-2A-B2A25-2AB-)2A25-2A2(64-4(A27-A2-)A27-A64-2(A27-A-BA27-AB-)A27-A)64-4(A27-A2-)A27-A64-2(2A25-2A-B2A25-2AB-)2A25-2A65-4(A25-A4-)A25-A66-2(A25-A3-BA25-AB3-)A25-A66-4(2A23-2A4-)2A23-2A67-2(A23-A5-BA23-AB5-)A23-A68-4(2A21-2A6-)2A21-2A69-2(2A19-2A7-B2A19-2AB7-)2A19-2A71-4(2A17-2A10-)2A17-2A71-A-A16-2A9-2ABA16-2AB8-2A-A16-2A9-2ABA16-2AB9-A-A16-2A73-4(A-17A12-)A-17A75-2(16A14-B16A-B13-)16A51-9C22-C7AC18-2(B-)C7AC-B20-C3A5C18-2(B-)C7AC-B20-C7AC22-9C121-3C104-
