model
size = 29 7 30, scale = 0.05, origin = -y
material deform = 1, fade = true, lighting = smooth, roughness = 0.3, metalness = 0.6
  colors = A:#963 B:#444
voxels
132-3B108-4(7A22-)7A77-4(4A5-4A16-)4A5-4A72-4(3A11-3A12-)3A11-3A69-4(2A15-2A10-)2A15-2A67-4(2A17-2A8-)2A17-2A65-4(2A19-2A6-)2A19-2A63-4(2A21-2A4-)2A21-2A62-4(A23-A4-)A23-A61-4(2A23-2A2-)2A23-2A2(60-4(A25-A2-)A25-A)59-2A4(25-4A)25-2A5(58-A4(27-2A)27-A)58-2A4(25-4A)25-2A59-2(4(A25-A2-)A25-A60-)4(2A23-2A2-)2A23-2A61-4(A23-A4-)A23-A62-4(2A21-2A4-)2A21-2A63-4(2A19-2A6-)2A19-2A65-4(2A17-2A8-)2A17-2A65-A-A16-2A7-2ABA16-2A7-2A-A16-2A7-2ABA16-2A8-A-A16-2A67-4(A-17A10-)A-17A69-4(16A13-)16A47-9B2(20-B7AB)20-B3A5B2(20-B7AB)20-9B10-
