model
size = 23 16 22, scale = 0.05, origin = -y
material deform = 1, fade = true, lighting = smooth, roughness = 0.3, metalness = 0.6
  colors = A:#9CF B:#555 C:#EEE D:#888 E:#444 F:#BBB G:#9CC H:#DDD I:#777 J:#AAA
voxels
24-20A3-20A302-20A3-20A324-22A-22A323-2A18-2A-2A18-2A3-6(18A5-)18A164-2A18-2A-2A18-2A3-5(A16-A5-)18A5-18A71-E22-I22-D22-J22-C2A18-2A-2A18-2A3-5(A16-A5-)18A5-18A48-C22-E22-B22-I22-D22-J2A18-2A-2A18-2A3-5(A16-A5-)18A5-18A25-2(C22-)2(E22-)B22-I22-D2A18-2A-2A18-2A3-5(A16-A5-)18A5-18A2-D2(22-C)3(22-E)22-B22-I2A18-2A-2A18-2A3-5(A16-A5-)18A5-18A2-D2(22-C)22-F4(22-E)2A18-2A-2A18-2A3-5(A16-A5-)18A2-B2-18A2-D22-C22-F4(22-C)23-2A18-2A-2A18-2A3-4(A16-A5-)A16-A2(2-B2-18A)2-D22-F4(22-C)46-2A18-2A-2A18-2A3-4(A16-A5-)A16-A2(2-B2-18A)2-F4(22-D)69-2A18-2A-2A18-2A3-2(A16-A5-)A16-A-B2(3-A16-A-H)3-18A2-F2-18A2-2(B22-)B115-2A18-2A-2A18-2A3-A16-A5-2(A16-A-B3-)A16-A-H3-A16-A-F3-18A-2H2-18A2-B22-B138-2A18-2A-2A18-2A3-2(A16-A5-)2(A16-A-F3-)A16-A-B3-18A2-H2-18A2-H161-2A18-2A-2A18-2A3-A16-A5-A16-A-F3-G2(16-A5-A)16-A2(-B3-18A)164-2A18-2A-2A18-2A3-A16-A-F3-2(G16-A5-A16-A5-)18A5-18A164-2A18-2A-2A18-2A3-2(A16-A5-)G2(16-A5-A)16-A2(5-18A)2(164-2A18-2A-2A18-2A3-5(A16-A5-)18A5-18A)164-2A18-2A-2A18-2A3-18A5-12AG5A5-11AGAG4A5-12AG5A3(5-18A)164-22A-22A323-
