model
size = 16 32 16, scale = 0.05, origin = -y
material deform = 1, fade = true, lighting = smooth, roughness = 0.3, metalness = 0.6
  colors = A:#6E552F B:#3A3226 C:#555 D:#777 E:#43341B F:#985F2A
voxels
391-2(2D14-2D478-)2D13-4D12-4D13-2D461-4C2(12-C2-C)12-4C429-2A13-4A11-A4-A9-2A4-2A8-2A4-2A9-A4-A11-4A13-2A382-2A13-A2-A11-C4-C9-A6-A7-A8-A6-A8-A7-A6-A9-C4-C11-A2-A13-2A365-4A11-C4-C9-2C4-2C7-3(A8-A6-)A8-A7-2C4-2C9-C4-C11-4A77-2B14-2F94-2F8(14-2B)14-2D13-4C11-A-2E-A9-A2-2E2-A7-A3-2E3-A5-C4-2E4-C3-DC10-CD2-DC10-CD3-C10-C5-A8-A7-A6-A9-A4-A11-4C13-2D30-2B13-4B12-4F13-2(2F14-2B14-)2F13-4F8(12-4B)12-4D12-C2EC10-2A4E2A7-A2-4E2-A6-A2-4E2-A4-DC3-4E3-CD-D14-2D14-D-DC10-CD4-A8-A6-A8-A7-2A4-2A10-C2-C12-4D13-2D14-2B13-4B12-4F13-2(2F14-2B14-)2F13-4F8(12-4B)12-4D12-C2EC10-2A4E2A7-A2-4E2-A6-A2-4E2-A4-DC3-4E3-CD-D14-2D14-D-DC10-CD4-A8-A6-A8-A7-2A4-2A10-C2-C12-4D13-2D30-2B14-2F94-2F8(14-2B)14-2D13-4C11-A-2E-A9-A2-2E2-A7-A3-2E3-A5-C4-2E4-C3-DC10-CD2-DC10-CD3-C10-C5-A8-A7-A6-A9-A4-A11-4C13-2D333-4A11-C4-C9-2C4-2C7-3(A8-A6-)A8-A7-2C4-2C9-C4-C11-4A365-2A13-A2-A11-C4-C9-A6-A7-A8-A6-A8-A7-A6-A9-C4-C11-A2-A13-2A382-2A13-4A11-A4-A9-2A4-2A8-2A4-2A9-A4-A11-4A13-2A429-4C2(12-C2-C)12-4C461-2D13-4D12-4D13-2D103-
