model
size = 15 27 4, scale = 0.05, origin = -y
material deform = 1, fade = true, lighting = smooth, roughness = 0.3, metalness = 0.6
  colors = A:#DDD B:#111
voxels
-14A349-7A7-9A4-13A350-7A7-9A2(4-13A-15A5-5A8-9A4-13A-285A2-11A6-A4B2A7-A7BA)4-13A-15A
