model
size = 31 14 26, scale = 0.05, origin = -y
material deform = 1, fade = true, lighting = smooth, roughness = 0.3, metalness = 0.6
  colors = A:#09F B:#EEE C:#CFF D:#9CF E:#03C F:#69C G:#33F H:#06C
voxels
38-2(17B14-)17B15-2(B30-)B247-2(15B16-)15B356-17B2(14-B15AB)14-2(B15A15-)B277-19B2(12-BAB15AB)2(13-AB15AB)14-B14A-B14-B14A16-11B203-21B2(10-2B2AB13ABAB)12-2AB13ABA13-2AB13ABA14-2(AB13AB15-)2B8A6B16-B8A22-B149-23B2(8-2B4AB11AB3AB)9-2(B4AB11AB3A10-)B-2(3AB11AB2A13-)B2AB11A3B14-2AB11AB18-B11-B135-25B2(6-2BAB4AB9AB4A2B)8-2(AB4AB9AB4AB9-)2B4AB9AB3A-B9-2B4AB9AB3A11-2B4AB9AB2AB12-B4AB9AB2A13-B2-2AB9AB19-AB9AB102-31B-3B3AB4AB5AFAB4AB2A2B3-2B3AB4AB5AFAB4AB2AB6-3AB4AB5AFAB4AB2A7-3AB4AB5AFAB4AB2A8-2(2AB4AB5AFAB4AB10-)BAB4AB5AFAB3A2B11-AB4AB5AFAB3A14-B4AB5AFAB2A18-2AB5AFAB2A20-B7-B72-31B-2B5AB2A10B3AB3A2B3-B5AB2A10B2(3AB)5-5AB2A10B3AB3A6-5AB2A10B3AB3A7-4AB2A10B3AB2A8-4AB2A10B3AB2A9-2(B2A)10B3A2B11-2AB2A10B3AB13-AB2A10B2A-B13-AB2A10B2A16-B2-10B72-31B-2B6A2B2D6CD4B4A2B3-B6A2B2D6CD4B4AB5-6A2B2D6CD4B4A6-6A2B2D6CD4B4A7-5A2B2D6CD4B3A8-5A2B2D6CD4B3A9-B3A2B2D6CD4B2AB10-3A2B2D6CD4B2A12-2A2B2D6CD4B14-2A2B2D6CD4B16-2BED6CD3B20-8E42-31B-2B6AB2D8CDB6A2B3-B6AB2D8CDB6AB5-6AB2D8CDB6A6-6AB2D8CDB6A7-5AB2D8CDB5A8-5AB2D8CDB5A9-B3AB2D8CDB4AB10-3AB2D8CDB4A12-2AB2D8CDB2A14-2AB2D8CDB2A16-B2D8CDB19-3E6C2E23-6E12-31B-2B6ABD10CB6A2B3-B6ABD10CB6AB5-6ABD10CB6A6-6ABD10CB6A7-5ABD10CB5A8-5ABD10CB5A9-B3ABD10CB4AB10-3ABD10CB4A12-2ABD10CB2A14-2ABD10CB2A16-BD10CB19-E9CE21-9E11-13BGBG2BG3BG8B-2B6AB11CB6A2B3-B6AB11CB6AB5-6AB11CB6A6-6AB11CB6A7-5AB11CB5A8-5AB11CB5A9-B3AB11CB4AB10-3AB11CB4A12-2AB11CB2A14-2AB11CB2A16-B11CB19-E9CE21-9E11-12B5(GB)G8B-2B6AB3C5B3CB6A2B3-B6AB3C5D3CB6AB5-6AB3C5D3CB6A6-6AB3C5D3CB6A7-5AB3C5D3CB5A8-5AB3C5D3CB5A9-B3AB3C5D3CB4AB10-3AB3C5D3CB4A12-2AB3C5D3CB2A14-2AB3C5D3CB2A16-B3C5D3CB19-E2C5D2CE21-9E11-10BGBG3BG2BGBG9B-2B6AB3C5B3CB6A2B3-B6AB3C5D3CB6AB5-6AB3C5D3CB6A6-6AB3C5D3CB6A7-5AB3C5D3CB5A8-5AB3C5D3CB5A9-B3AB3C5D3CB4AB10-3AB3C5D3CB4A12-2AB3C5D3CB2A14-2AB3C5D3CB2A16-B3C5D3CB19-E2C5D2CE21-4EH4E11-31B-2B6AB3C5B3CB6A2B3-B6AB3C5D3CB6AB5-6AB3C5D3CB6A6-6AB3C5D3CB6A7-5AB3C5D3CB5A8-5AB3C5D3CB5A9-B3AB3C5D3CB4AB10-3AB3C5D3CB4A12-2AB3C5D3CB2A14-2AB3C5D3CB2A16-B3C5D3CB19-E2C5D2CE21-3E3H3E11-31B-2B6AB4C4B3CB6A2B3-B6AB4C4D3CB6AB5-6AB4C4D3CB6A6-6AB4C4D3CB6A7-5AB4C4D3CB5A8-5AB4C4D3CB5A9-B3AB4C4D3CB4AB10-3AB4C4D3CB4A12-2AB4C4D3CB2A14-2AB4C4D3CB2A16-B4C4D3CB19-E3C4D2CE21-4E2H3E11-31B-2B5AFB11CB6A2B3-B5AFB11CB6AB5-5AFB11CB6A6-5AFB11CB6A7-4AFB11CB5A8-4AFB11CB5A9-B2AFB11CB4AB10-2AFB11CB4A12-AFB11CB2A14-AFB11CB2A16-B11CB19-E8C2E21-8E12-31B-2B6ABD9CD2B5A2B3-B6ABD9CD2B5AB5-6ABD9CD2B5A6-6ABD9CD2B5A7-5ABD9CD2B4A8-5ABD9CD2B4A9-B3ABD9CD2B3AB10-3ABD9CD2B3A12-2ABD9CD2BA14-2ABD9CD2BA16-BD8CDE2B18-2E6C2E23-6E13-31B-2B5A2B2D7C2DBAB4A2B3-B5A2B2D7C2DBAB4AB5-5A2B2D7C2DBAB4A6-5A2B2D7C2DBAB4A7-4A2B2D7C2DBAB3A8-4A2B2D7C2DBAB3A9-B2A2B2D7C2DBAB2AB10-2A2B2D7C2DBAB2A12-A2B2D7C2DBAB14-A2B2D7C2DBAB15-3BD6CDE2B21-7E43-31B-2B4AB2ABD6C2D2(B3A)2B3-B4AB2ABD6C2D2(B3A)B5-4AB2ABD6C2D2(B3A)6-4AB2ABD6C2D2(B3A)7-3AB2ABD6C2DB3AB2A8-3AB2ABD6C2DB3AB2A9-BAB2ABD6C2DB3A3B10-AB2ABD6C2DB3AB13-B3AD6C2DB2A-B13-B3AD6C2DB2A19-10B72-31B-2B3AB4A9B5ABA3B3-B3AB4A9B5ABA2B5-3AB4A9B5ABA7-3AB4A9B5ABA8-2AB4A9B5AB9-2AB4A9B5AB10-2B4A9B5AB11-B4A9B4A13-B4-B7AB2A20-B7AB2A28-B76-25B2(6-BAB5AB8AB5A2B)7-2(2B5AB8AB5AB8-)2B5AB8AB4A-B9-B5AB8AB4A11-B5-B8AB3AB17-B8ABA20-B8-B30-B107-23B2(8-B5AB10AB3A2B)9-5AB10AB3A11-5AB10AB3A12-2(4AB10AB2A13-)B3-B10ABAB17-B10-B169-21B2(10-B3AB12ABA2B)11-3AB12ABA13-3AB12ABA14-2(2AB12AB15-)16B200-19B2(12-BAB14A2B)13-AB14AB14-AB14AB15-2B13-B16-B30-B207-
