model
size = 8 14 8, scale = 0.05, origin = -y
material deform = 1, fade = true, lighting = smooth, roughness = 0.3, metalness = 0.6
  colors = A:#0A0 B:#111
voxels
56-B6A2B6AB88-B6A2B6AB81-B4AB2-B4AB-16A-B4AB2-B4AB51-B2AB4-B2AB3-6A2-6A-16A-6A2-6A3-B2AB4-B2AB21-2B6-2B5-4A4-4A3-6A2-6A-16A-6A2-6A3-4A4-4A5-3(2B6-)2B5-4A4-4A3-6A2-6A-16A-6A2-6A3-4A4-4A5-2B6-2B21-B2AB4-B2AB3-6A2-6A-16A-6A2-6A3-B2AB4-B2AB51-B4AB2-B4AB-16A-B4AB2-B4AB33-
