model
size = 22 25 20, scale = 0.05, origin = -y
material deform = 1, fade = true, lighting = smooth, roughness = 0.3, metalness = 0.6
  colors = A:#FFE2C5 B:#563F2E C:#EEE D:#FFFFFB E:#00AA90 F:#F8B09C G:#111
voxels
229-4A17-6A17-4A19-2A459-4A17-6A17-4A19-2A458-6B15-2BA2-A2B14-3A2-3A15-6A17-4A19-2A372-2B18-B4FB15-BF4-FB13-2BA4-A2B12-B2A4-2AB13-2A4-2A14-2A4-2A15-2A2-2A17-4A19-2A123-B14-B7-5B4-5B146-2B19-4B16-3B2A3B13-2B2A2-2A2B11-3BA4-A3B2(10-B2A6-2AB)11-2A6-2A12-2A6-2A13-2A4-2A15-2A2-2A17-4A19-2A64-2A13-A5-4A5-A7-14A8-3A-6A-3A9-5A2-5A102-4B17-6B14-4B2A4B11-4BA2-A4B10-2BA6-A2B10-B2A6-2A2(B10-BA8-A)B2(10-2A8-2A)10-3A6-3A9-4A6-4A8-6A2-6A7-16A6-2A3-5A-3D-2(A6-A5-4AD3-C)A6-2A3-A5-3D-A6-3A3-4A3-3A7-A5-2A5-A8-2A3-4A3-2A10-10A38-2B18-6B15-3B2A3B13-4B2-4B11-4B4-4B9-4B6-4B8-2BA8-A3(2B8-2B10-)2B9-2A8-2A9-2(3A8-)2A10-2A2(8-3A)7-2(5A6-)6A4-6A5-A-A3D6A3CA-A4-A-C3-D4ACE-EC-A4-2AC3-D4ACE-EC2A5-2A3D6A3C2A6-A-12A-A6-A14-A7-A12-A9-5A2-5A15-2A18-2B2A2B15-2B4A2B13-B3A2-3AB11-B10-B9-2(3B8-)2B10-2B7-3B10-3B2(6-2B12-2B)7-B12-B8-BA10-AB8-2A10-2A7-B2A10-2AB6-3A10-3A5-4A10-4A4-A2-2A8-2A2-A4-A-A3C7A2CA-A4-A-CE-ECA2-2AEGEC-A4-A-CE-EC5AEGEC-A4-3A3C7A2C3A5-A-12A-A6-A14-A7-A12-A8-2(2A10-)10A13-2B4-2B13-2B6-2B11-2B8-2B9-2B10-2B8-2B10-2B7-B14-B6-B14-B5-2B14-2B5-2B12-2B6-2B12-2B7-B12-B7-BA12-AB6-BA12-AB5-2A14-2A2(4-A16-A)3-2A-A2C2A5-A2DA-2A2-A2-CEGEA5-D2ED2-A2-2A-CEGEA5-D2ED-2A3-A-A2C2A5-A2D2-A4-A16-A5-A14-A6-A14-A7-2(2A10-)10A12-2B6-2B11-2B8-2B9-2B10-2B8-B12-B7-B14-B6-B14-B5-2(B16-B4-)2B14-2B5-2(B14-B6-)B14-B5-2B14-2B2(4-A16-A)3-A18-2(A2-)A2DA2(12-2(A2-)D2ED)12-A2-A3-2DA12-A3-A16-A5-A14-A6-2(A14-A7-A12-A9-12A10-2B8-2B9-2B10-2B8-B12-B7-B14-B6-B14-B5-3(B16-B4-)B16-B5-2(B14-B6-)B14-B5-2B14-2B4-A16-A3-A18-A2-A18-A-2A18-4A18-2A-A18-A2-A18-A3-A16-A4-2A14-2A5-)A14-A7-A12-A9-12A11-2B6-2B11-2B8-2B9-2B10-2B8-B12-B7-B14-B6-B14-B5-2(B16-B4-)2B14-2B5-2(B14-B6-)B14-B5-2B14-2B2(4-A16-A)3-A18-2(A2-)A2DA2(12-2(A2-)D2ED)12-A2-A3-2DA12-A3-A16-A5-A14-A6-A14-A7-A12-A9-12A12-2B4-2B13-2B6-2B11-2B8-2B9-2B10-2B8-2B10-2B7-B14-B6-B14-B5-2B14-2B5-2B12-2B6-2B12-2B7-B12-B7-BA12-AB6-BA12-AB5-2A14-2A2(4-A16-A)3-2A-A2C2A5-A2DA-2A2-A2-CEGEA5-D2ED2-A2-2A-CEGEA5-D2ED-2A3-A-A2C2A5-A2D2-A4-A16-A5-A14-A6-A14-A7-2(2A10-)10A14-2B2A2B15-2B4A2B13-B3A2-3AB11-B10-B9-2(3B8-)2B10-2B7-3B10-3B2(6-2B12-2B)7-B12-B8-BA10-AB8-2A10-2A7-B2A10-2AB6-3A10-3A5-4A10-4A4-A2-2A8-2A2-A4-A-A3C7A2CA-A4-A-CE-ECA2-2AEGEC-A4-A-CE-EC5AEGEC-A4-3A3C7A2C3A5-A-12A-A6-A14-A7-A12-A8-2(2A10-)10A16-2B18-6B15-3B2A3B13-4B2-4B11-4B4-4B9-4B6-4B8-2BA8-A3(2B8-2B10-)2B9-2A8-2A9-2(3A8-)2A10-2A2(8-3A)7-2(5A6-)6A4-6A5-A-A3D6A3CA-A4-A-C3-D4ACE-EC-A4-2AC3-D4ACE-EC2A5-2A3D6A3C2A6-A-12A-A6-A14-A7-A12-A9-5A2-5A15-2A63-4B17-6B14-4B2A4B11-4BA2-A4B10-2BA6-A2B10-B2A6-2A2(B10-BA8-A)B2(10-2A8-2A)10-3A6-3A9-4A6-4A8-6A2-6A7-16A6-2A3-5A-3D-2(A6-A5-4AD3-C)A6-2A3-A5-3D-A6-3A3-4A3-3A7-A5-2A5-A8-2A3-4A3-2A10-10A104-2B19-4B16-3B2A3B13-2B2A2-2A2B11-3BA4-A3B2(10-B2A6-2AB)11-2A6-2A12-2A6-2A13-2A4-2A15-2A2-2A17-4A19-2A64-2A13-A5-4A5-A7-14A8-3A-6A-3A9-5A2-5A169-2B18-B4FB15-BF4-FB13-2BA4-A2B12-B2A4-2AB13-2A4-2A14-2A4-2A15-2A2-2A17-4A19-2A123-B14-B7-5B4-5B254-6B15-2BA2-A2B14-3A2-3A15-6A17-4A19-2A252-
