model
size = 24 20 24, scale = 0.05, origin = -y
material deform = 1, fade = true, lighting = smooth, roughness = 0.3, metalness = 0.6
  colors = A:#DDD B:#777 C:#111
voxels
274-2(4A17-10A425-)4A17-10A12-2A10-2A399-4A17-10A12-2A10-2A9-A14-A395-10A12-2A10-2A9-A14-A7-A16-A371-8A14-2A8-2A10-2A12-2A7-A16-A5-A18-A349-2A18-4A2-4A12-2A10-2A8-2A14-2A5-A18-A3-A20-A345-8A14-2A8-2A10-2A12-2A7-A16-A5-A18-A3-A20-A199-6B18-6B19-4B92-10A12-2A10-2A8-2A14-2A5-A18-A3-A20-A-A22-A196-2B6-2B14-10B15-8B17-6B19-4B23-4A16-4A4-4A10-2A12-2A7-A16-A5-A18-A3-A20-A-A22-A195-2B8-2B12-3B6-3B13-10B14-10B15-8B18-8A15-3A6-3A10-2A12-2A7-A16-A5-A18-A3-A20-A-A22-A195-B10-B12-2B8-2B12-3B6-3B13-10B14-10B16-B9A14-2A8-2A10-2A12-2A6-2A16-2A3-2A18-2A-2A20-3A22-A155-2C37-B12-B2(10-2B)11-2B8-2B12-3B6-3B13-10B15-2B2(9A13-3A3-2B3-3A9-A6-2B6-A6-2A7-2B7-2A3-2A8-2B8-2A-2A9-2B9-3A10-2B10-A11-5(2B22-)2C21-4C21-2C13-B12-B2(10-2B)10-3B8-3B11-3B6-3B12-12B13-3B)9A14-2A8-2A10-2A12-2A6-2A16-2A3-2A18-2A-2A20-3A22-A155-2C37-B12-B2(10-2B)10-3B8-3B11-3B6-3B12-12B13-3B8A15-3A6-3A10-2A12-2A7-A16-A5-A18-A3-A20-A-A22-A194-B12-B2(10-2B)10-3B8-3B11-3B6-3B12-12B13-3B7A16-4A4-4A10-2A12-2A7-A16-A5-A18-A3-A20-A-A22-A194-B12-B2(10-2B)11-2B8-2B12-3B6-3B13-10B15-2B7A17-10A12-2A10-2A8-2A14-2A5-A18-A3-A20-A-A22-A195-B10-B12-2B8-2B12-3B6-3B13-10B14-10B16-6B20-8A14-2A8-2A10-2A12-2A7-A16-A5-A18-A3-A20-A196-2B8-2B12-3B6-3B13-10B14-10B15-8B18-4B24-2A18-4A2-4A12-2A10-2A8-2A14-2A5-A18-A3-A20-A197-2B6-2B14-10B15-8B17-6B19-4B69-8A14-2A8-2A10-2A12-2A7-A16-A5-A18-A200-6B18-6B19-4B140-10A12-2A10-2A9-A14-A7-A16-A397-4A17-10A12-2A10-2A9-A14-A422-4A17-10A12-2A10-2A197-
