model
size = 18 8 8, scale = 0.05, origin = -y
material deform = 1, fade = true, lighting = smooth, roughness = 0.3, metalness = 0.6
  colors = A:#111 B:#FC0 C:#EEE
voxels
9-2B2(13-6A11-2(2AC)2A2(10-3A2C3A)10-BAC2ACAB11-B4AB13-B2AB)15-2B13-2A4-2A9-A-2A2-2A-A8-A-6A-A11-4A82-4A4-4A5-2(2A-2A4-)2A-3A2-3A-2A4-AB2-6A2-BA3-2B12-2B57-4A6-4A3-A2-B2A4-2AB2(2-A)3-2A4-2A3-A2-A4-6A4-A-B7-2A7-B56-4A6-4A3-A2-B2A4-2AB2(2-A)3-2A4-2A3-A2-A4-6A4-A-B7-2A7-B57-4A4-4A5-2(2A-2A4-)2A-3A2-3A-2A4-AB2-6A2-BA3-2B12-2B60-2A4-2A9-A-2A2-2A-A8-A-6A-A11-4A79-
