model
size = 16 32 13, scale = 0.05, origin = -y
material deform = 1, fade = true, lighting = smooth, roughness = 0.3, metalness = 0.6
  colors = A:#EEE B:#0FF C:#111 D:#0C3 E:#020
voxels
100-2(5B11-)5B379-5C75-5B9-2(2B5A2B7-)2B5A2B9-5A362-7C10-5C43-5B10-7B7-2(3B7AB5-)3B7AB7-7A10-5A345-9C8-7C27-3B11-7B8-7BAB6-2(3B7AB5-)3B7AB6-9A8-7A11-3A329-11C6-3C3A3C10-3B12-5B9-7BAB6-8B2AB4-2(5B7AB3-)5B7AB4-11A6-9A9-5A12-19(3A13-)3A9-11C6-2C5A2C9-B3-B10-2B3-2B8-3B3-BAB6-4B3-B2AB4-2(5B3-4AB3-)5B3-4AB4-4A3-5A5-3A3-6A5-2A3-2A2-2A6-A3-A4-3A4-A3-A5-2D4-17(A3-A11-)A3-A8-11C6-2C5A2C9-B3-B10-2B3-AB8-3B3-2AB6-4B3-3AB4-2(5B3-4AB3-)5B3-4AB4-4A3-5A5-3A3-6A5-2A3-2A2-2A6-E3-A4-3A4-A3-A5-2D4-17(A3-A11-)A3-A8-11C6-2C5A2C9-B3-B10-2B3-AB8-3B3-2AB6-4B3-3AB4-2(5B3-4AB3-)5B3-4AB4-4A3-5A5-3A3-6A5-2A3-2A2-2A6-A3-A4-3A4-A3-A5-2D4-17(A3-A11-)A3-A8-11C6-3C3A3C10-3B12-2B2AB9-4B3A2B6-5B5AB4-2(6B6AB3-)6B6AB4-11A6-9A9-5A12-19(3A13-)3A10-9C8-7C27-3B11-3B2A2B8-4B4AB6-2(5B5AB5-)5B5AB6-9A8-7A11-3A331-7C10-5C43-5B10-B5AB7-3B6A2B5-3B7AB5-3B6A2B7-7A10-5A347-5C75-5B9-2(3B4A2B7-)3B4A2B9-5A459-2(5B11-)5B375-
