model
size = 32 27 3, scale = 0.05, origin = -y
material deform = 1, fade = true, lighting = smooth, roughness = 0.3, metalness = 0.6
  colors = A:#777 B:#EEE C:#746327 D:#555 E:#904840
voxels
599-D3-C26-2(D-)3C26-3D2C28-D-D28-2CD28-3C30-C70-2C2(10B23-)16(7A3B23-)5ADA2BC23-3AD-DA3C23-3A3D2C25-3AD-D27-A2CD2E26-3C2-2E26-C4-2(2E31-)2C599-D3-C26-2(D-)3C26-3D2C28-D-D28-2CD28-3C30-C70-2C
