model
size = 32 32 13, scale = 0.05, origin = -y
material deform = 1, fade = true, lighting = smooth, roughness = 0.3, metalness = 0.6
  colors = A:#EEE B:#111 C:#BBB
voxels
781-6C25-2C4-2C23-2C6-2C21-2C8-2C19-2C10-2C2(18-C12-C)1010-C12-C18-9(C12-C1010-)C12-C978-C12-C18-C12-C9-129A2(2B2A)B3ABAB3AB2ABA2(B2A)BAB3AB2A2(BAB3A)4BA2(B2A)BAB3AB2A4(BA)3BAB2A2(BA)2B2ABAB3AB2AB2(A2B)3(AB)2ABA2B3(AB)A2(2B2A)B3ABA3B2A2B2(2AB)2(AB)33AB4A2B2(2AB)7AB2A2(BA)3B2AB3AB2ABAB2AB7AB2A2(BA)B4A2B2(2AB)A3B8AB2A3BA2B2(3AB)2ABAB2AB7AB2A2(BA)B4A3B2A2B2A3B7A3B2(AB)A3B35A3B6ABAB3A2B2(2AB)AB2AB5AB6A3(BA)2(B2ABA)B2AB5AB6A3(BA)B2ABA3B2A3B2(6AB)3(AB)2(2ABAB)AB5A3B5AB3AB2A2B2A3B2(2AB)130A9-5(C12-C18-)C12-C41-
