model
size = 7 32 7, scale = 0.05, origin = -y
material deform = 1, fade = true, lighting = smooth, roughness = 0.3, metalness = 0.6
  colors = A:#EEE B:#399 C:#FF0 D:#09F E:#F90 F:#F0F G:#6F3 H:#30F I:#F09 J:#0FF
voxels
-2(5D2-)5A2-5A3-2(3F4-)2(3A4-)3C4-3C5-2(A6-)E136-9D4BDA5B2A5BA-2(F3BF2-)2(5A2-)2(5C2-)2(5A2-)5E3-3E2(4-3A)2(4-3G)5-2(A6-)H80-9D4BDA5B2A5BAF5B2F5BF14A14C-2(5A2-)2(2EB2E2-)2(A2B2A2-)2G2BG2-2G2BG3-2(3A4-)2(3H4-)3A4-3A5-2(I6-)A38-9D4BDA5B2A5BAF5B2F5BF2A2B5A2B3A14C14A2EB4E-E2B2E2(2-A2B2A)2(2-2G2BG)2(2-5A)2-HB3H3-HBH2(4-3A)2(4-3I)4-ABA5-3(A6-)J6-J3-9D4BDA5B2A5BAF5B2F5BF2A2B5A2B3A14C-2(5A2-)2(5E2-)2(A2B2A2-)2G2BG2-2G2BG3-2(3A4-)2(3H4-)3A4-3A5-2(I6-)A38-9D4BDA5B2A5BA-2(F3BF2-)2(A2B2A2-)2(5C2-)2(5A2-)5E3-3E2(4-3A)2(4-3G)5-2(A6-)H81-2(5D2-)5A2-5A3-2(3F4-)2(3A4-)3C4-3C5-2(A6-)E136-
