model
size = 32, scale = 0.05, origin = -y
material deform = 1, fade = true, lighting = smooth, roughness = 0.3, metalness = 0.6
  colors = A:#555 B:#EEE C:#000 D:#AAA E:#222 F:#C03 G:#777 H:#F9F I:#60C J:#E00 K:#080 L:#0B0 M:#00B N:#C99 O:#C9F P:#444
voxels
32-96A896-1024A-3(30A2-)2(30A-992A-)30A-ABD24BKBDB2ABD2B3E6BFB2E7BJ3BDB2ABD2B3EFBF2BFBF2E2BIBK3B2EBDB2ABD2B3EF2BM2(BF)2E2BI3BJB2EBDB2ABD2B3E2B2LMBLF2E2BI3B2I2EBDB2ABD2B3E4B2MBF2E3BFJI2B2EBDB2ABD2B3EBCFLJL2B2E2BJFBI2F2EBDB2ABD2B3E2BC3BFB2EBJ3BIKBKEBDB2ABD2B3E3B4CB2E3BK7BDB2ABD2B12E3BKB6EBDB2ABD5B9E12BDB2ABD26BDB2AB28DB2A30B2A10B2G6BG11B2A4B2G3B3G2BGBG13B2A3BG2B2(G3B)G5BG9B2A30B2A2B7(2AB)2A5B2A30B2A3B2A25B2(2A2BA27B)2A3B2A25B2A30B2APBP2B18DBJBE3B2A30B162A20(30-2A)3-2A25-2(2A2-A27-)2A3-2A25-3(2A30-)65A-63A928-32A-63A928-2(63A-32A-3C9(-2C)897-)96A928-96A2(-2C2-8(2C-)2C897-32A-63A)928-32A-29A2-32A-6C6(-2C)-5C897-32A-30A-32A-6C6(-2C)-5C897-32A-29A2-32A29-2C897-63A-32A-3C9(-2C)897-62A2-32A-3C9(-2C)897-63A-32A928-96A-3C7(-2C)-5C897-96A-3C7(-2C)903-5A2H25A-63A26-2(C-)C897-5A2H25A2-29A-32A-2C2-2C-14C-2C903-4AH2AH24A-63A-2C2-2C-14C-2C3(-C)897-2A2H4A2H53A-32A928-2A2H4A2H64AD3E2C3ED12A928-32A-30A-10AD8CD12A928-32A2-40AD8CD12A928-32A-30A-10AD8CD8A2O2A928-74AD8CD7A2NO2A928-63A-10A10D7A2N3A928-
