model
size = 30 15 12, scale = 0.05, origin = -y
material deform = 1, fade = true, lighting = smooth, roughness = 0.3, metalness = 0.6
  colors = A:#60C B:#B00 C:#CC6
voxels
6-4BA10-A4B9-2A2BA10-A2B2A8-2BA3BAB8ABA3BA2B5-2B2A4B3(A2B)A4B2A2B3-B2A4(BA)6B4(AB)2AB2-3BA2B3A4B2A4B3A2BA3B-2AB2A2B5ABA2BAB5A2B2AB3ABA2B4A2BAB4ABA2B4A2B2(AB)2(2AB)ABA4B2A4B2(AB)2AB2A3B3AB2A2B3AB2AB3A2B2AB3A3B2A5B4ABA2BAB4A5B2AB-2(BA)2(2B3AB3A)2B2(AB)2-AB4ABA12BAB4ABA3-A2(B4A)4B2(4AB)A5-A3BAB2A2B4A2B2ABA3BA153-A4(28-2A)28-A241-A26-A2-A26-A-2A4(26-4A)26-2A-A26-A2-A26-A153-A24-A3-2A24-2A2-2A24-2A-3A4(24-6A)24-3A-2A24-2A2-2A24-2A3-A24-A95-A22-A5-2A22-2A3-3A22-3A2-3A22-3A-4A4(22-8A)22-4A-3A22-3A2-3A22-3A3-2A22-2A5-A22-A66-2A20-2A5-3A20-3A3-4A20-4A2-4A20-4A-5A20-10A20-5AB4A20-4AB5A20-10A20-5A-4A20-4A2-4A20-4A3-3A20-3A5-2A20-2A38-5A10-5A8-24A5-4A18-4A3-5A18-5A2-5A18-5A-6A4(18-12A)18-6A-5A18-5A2-5A18-5A3-4A18-4A5-24A8-2(5A10-)2A3B10-3B2A8-7ABA6BAB7A5-4A18-4A3-5A18-5A2-5A18-5A-6A4(18-12A)18-6A-5A18-5A2-5A18-5A3-4A18-4A5-7ABA6BAB7A8-2A3B10-3B2A2(10-2BA2B)8-7ABA6BAB7A5-4A18-4A3-5A18-5A2-5A18-5A-6A18-12A18-6AB5A18-5AB6A18-12A18-6A-5A18-5A2-5A18-5A3-4A18-4A5-7ABA6BAB7A8-2(2BA2B10-)5B10-5B8-7A10B7A5-26A3-5A18-5A2-5A18-5A-6A18-12A18-6AB5A18-5AB6A18-12A18-6A-5A18-5A2-5A18-5A3-4A18-4A5-7A10B7A8-2(5B10-)2BA2B10-2BA2B8-7A3BA2BA3B7A5-26A3-5A18-5A2-5A18-5A-B5A18-5AB6A2(18-12A)18-6AB5A18-5AB-5A18-5A2-5A18-5A3-4A18-4A5-7A3BA2BA3B7A8-2(2BA2B10-)2B2AB10-B2A2B8-7A10B7A5-26A3-28A2-7A4C6A4C7A-7A6C4A6C13A3(8C2A8C12A)8C2A8C6A-6A6C4A6C6A2-7A4C6A4C7A3-26A5-7A10B7A8-2B2AB10-B2A2B5-
