model
size = 30 15 12, scale = 0.05, origin = -y
material deform = 1, fade = true, lighting = smooth, roughness = 0.3, metalness = 0.6
  colors = A:#03C B:#63C C:#300
voxels
6-B4A10-4AB9-A2CAB10-BA2CA8-2BA2C2(AB)6A2(BA)2CA2B5-B2CA2B3C3A2B3A3C2BA2CB3-A3C2(A2C)2A4C2A2(2CA)3CA2-3AB2ACA2B2AB2CB2A2BAC2AB3A-B2AC2BCA2B3AB2AB3A2BAC2BC2AB2CACABCA2BC2BA2CA2BC2BACBACA2CB2(AC)BCB2C3AC2AC3A2C2(BC)ACABAC8A2(CA)2B2(AC)8ACA2B3A2(CA)CB3A2B3AB2(CA)C3A2B-ACA2B2ABACB6ABCAB2A2BACA2-ACBAC2A2(2C4A)2C2ACABCA3-CAB5ACB6ABC5ABAC5-ABC4A2C6A2C4ACBA153-C28-CB28-2B28-BA28-AC28-C241-B26-B2-B26-B-AB26-B2AB26-B3A26-3AC26-C2AB26-BA-B26-B2-B26-B153-C24-C3-2A24-2A2-AC24-CA-2AC24-C5A24-5AB24-B4AB24-B5A24-3A-AB24-BA2-AB24-BA3-C24-C95-A22-A5-AB22-BA3-3A22-3A2-2AC22-C2A-3AB22-B4(6AC22-C)3A-2AB22-B2A2-2AC22-C2A3-AC22-CA5-B22-B66-AB20-BA5-2AC20-C2A3-3AC20-C3A2-3AC20-C3A-4AB20-B3(8AC20-C)9A20-5A-4A20-4A2-3AB20-B3A3-3A20-3A5-AC20-CA38-2BACB10-BCA2B8-5A2CA3B2C3BA2C5A5-3AC18-C3A3-4AB18-B4A2-4AC18-C4A-6A18-11AB18-B10AC18-C10AB18-B10AC18-C5A-5A18-5A2-5A18-5A3-3AC18-C3A5-2AB2(A2B)C4BC2(2BA)B2A8-2(CBABC10-)ABACA10-ACABA8-8AC2B2A2BC8A5-4A18-4A3-5A18-5A2-5A18-5A-6A4(18-12A)18-6A-5A18-5A2-5A18-5A3-4A18-4A5-8AC2B2A2BC8A8-ABACA10-ACABA10-BCBAB10-BABCB8-7ACB2A2C2ABC7A5-4A18-4A3-5A18-5A2-5A18-5A-6A4(18-12A)18-6A-5A18-5A2-5A18-5A3-4A18-4A5-7ACB2A2C2ABC7A8-BCBAB10-BABCB10-4CA10-A4C8-7ACBAC2BCABC7A5-4ACA2(2BC)2A2(C2B)AC4A3-5A18-5A2-5A18-5A-6A4(18-12A)18-6A-5A18-5A2-5A18-5A3-4A18-4A5-7ACBAC2BCABC7A8-4CA10-A4C10-ABC2B10-2BCBA8-7ACABC2ACBAC7A5-26A3-5A18-5A2-5A18-5A-6A4(18-12A)18-6A-5A18-5A2-5A18-5A3-4A18-4A5-7ACABC2ACBAC7A8-ABC2B10-2BCBA10-2CBCA10-ACB2C8-8AC6BC8A5-26A3-28A2-7A4B6A4B7A-7A6B4A6B13A3(8B2A8B12A)8B2A8B6A-6A6B4A6B6A2-7A4B6A4B7A3-26A5-8AC6BC8A8-2CBCA10-ACB2C5-
