model
size = 30 15 12, scale = 0.05, origin = -y
material deform = 1, fade = true, lighting = smooth, roughness = 0.3, metalness = 0.6
  colors = A:#C96 B:#60F C:#FCF
voxels
6-2B3A10-3A2B9-BAB2A10-2ABAB8-3A2(2BA)2B2A2(2BA)2B3A5-B7A2(2B2A)2B7AB3-BA2BA5B3A2B3A5BA2BAB2-2B2AB2A5BA2BA5B2AB2A2B-A3BABA3B2AB4AB2A3BABA3BA2B4AB2ABAB2A2B2ABAB2AB4A2B3ABA3B2(AB)A4B2(AB)A3BAB3A2BAB4ABAB2A4B2ABAB4ABA2B5A2(2B2A)2(B2A)2B2A2B5A-3A2BA2B2A2(2BA)2B2A2BA2B3A2-2(BA)B4ABA6BAB4A2(BA)B3-A2BAB2ABA8BAB2ABA2BA5-2(BA)2(2BA3BA)2B2(AB)153-A4(28-2A)28-A241-A26-A2-A26-A-2A4(26-4A)26-2A-A26-A2-A26-A153-A24-A3-2A24-2A2-2A24-2A-3A4(24-6A)24-3A-2A24-2A2-2A24-2A3-A24-A95-A22-A5-2A22-2A3-3A22-3A2-3A22-3A-4A4(22-8A)22-4A-3A22-3A2-3A22-3A3-2A22-2A5-A22-A66-2A20-2A5-3A20-3A3-4A20-4A2-4A20-4A-5A4(20-10A)20-5A-4A20-4A2-4A20-4A3-3A20-3A5-2A20-2A38-5A10-3(5A8-24A5-4A18-4A3-5A18-5A2-5A18-5A-6A4(18-12A)18-6A-5A18-5A2-5A18-5A3-4A18-4A5-24A8-3(5A10-))2(5A8-24A5-26A3-5A18-5A2-5A18-5A-6A4(18-12A)18-6A-5A18-5A2-5A18-5A3-4A18-4A5-24A8-3(5A10-))5A8-24A5-26A3-28A2-7A4C6A4C7A-7A6C4A6C13A3(8C2A8C12A)8C2A8C6A-6A6C4A6C6A2-7A4C6A4C7A3-26A5-24A8-5A10-5A5-
