model
size = 30 15 12, scale = 0.05, origin = -y
material deform = 1, fade = true, lighting = smooth, roughness = 0.3, metalness = 0.6
  colors = A:#69C B:#00A C:#C0C
voxels
6-ACA2C10-2CACA9-B4C10-4CB8-A2CABAC2BAC2ACA2BCABA2CA5-BCACB3ABAB4CBAB3ABCACB3-8AC2ABA2BAB2AC8A2-3AC6ABAB2CBAB6AC3A-3BCAC2B2CA2(2CB)2CA2C2BCAC3BAB2A2B2ABC2BA4BA2BCB2A2B2ABA3B2CBCAC2(2ABAB)2ACACB2C4B4AC4A4C2A4C4AC4A2(BA)B2AB5A2B2A2B5AB2A2(BA)-5ABCB3A6C3ABCB5A2-CB3ABABCB8ABCBAB3ABC3-4A2CB2A2C4A2C2AB2C4A5-BCAC5AB4AB5ACACB153-A4(28-2A)28-A241-A26-A2-A26-A-2A4(26-4A)26-2A-A26-A2-A26-A153-A24-A3-2A24-2A2-2A24-2A-3A4(24-6A)24-3A-2A24-2A2-2A24-2A3-A24-A95-A22-A5-2A22-2A3-3A22-3A2-3A22-3A-4A4(22-8A)22-4A-3A22-3A2-3A22-3A3-2A22-2A5-A22-A66-2A20-2A5-3A20-3A3-4A20-4A2-4A20-4A-5A4(20-10A)20-5A-4A20-4A2-4A20-4A3-3A20-3A5-2A20-2A38-5A10-5A8-24A5-4A18-4A3-5A18-5A2-5A18-5A-6A4(18-12A)18-6A-5A18-5A2-5A18-5A3-4A18-4A5-24A8-2(5A10-)2CABC10-CBA2C8-7AB3A2C3AB7A5-4A18-4A3-5A18-5A2-5A18-5A-6A4(18-12A)18-6A-5A18-5A2-5A18-5A3-4A18-4A5-7AB3A2C3AB7A8-2CABC10-CBA2C10-2C3B10-3B2C8-8AC2B2C2BC8A5-4A18-4A3-5A18-5A2-5A18-5A-6A4(18-12A)18-6A-5A18-5A2-5A18-5A3-4A18-4A5-8AC2B2C2BC8A8-2C3B10-3B2C2(10-C3BC)8-7AC2AB2CB2AC7A5-26A3-5A18-5A2-5A18-5A-6A4(18-12A)18-6A-5A18-5A2-5A18-5A3-4A18-4A5-7AC2AB2CB2AC7A8-2(C3BC10-)A3BA10-A3BA8-8ABC4BCB8A5-26A3-5A18-5A2-5A18-5A-6A4(18-12A)18-6A-5A18-5A2-5A18-5A3-4A18-4A5-8ABC4BCB8A8-2(A3BA10-)2BCAB10-BAC2B8-8AB2C2B2CB8A5-26A3-28A2-7A4B6A4B7A-7A6B4A6B13A3(8B2A8B12A)8B2A8B6A-6A6B4A6B6A2-7A4B6A4B7A3-26A5-8AB2C2B2CB8A8-2BCAB10-BAC2B5-
