model
size = 30 15 12, scale = 0.05, origin = -y
material deform = 1, fade = true, lighting = smooth, roughness = 0.3, metalness = 0.6
  colors = A:#0C6 B:#309 C:#500
voxels
6-3B2A10-2A3B9-2(AB)A10-2(AB)A8-BA2B3A2BAB2ABA2B3A2BAB5-3A2(3BA)4B2(A3B)3A3-BAB2AB16AB2ABAB2-2BA2(2B2A)6B2(2A2B)A2B-A2B3AB5A2B2A2B5AB3A2BABA3B5A2BAB2ABA2B5A3BAB2(2A2B)AB3(A2B)ABA2(2B2A)5BA2BAB4A2B4ABA2BA6BA4B3AB10AB3A4BAB-2A2BA4B2(2A2B)2A4BA2B2A2-A4B2(2A6B)2A4BA3-BA2(B3A)2B2A2B2(3AB)AB5-BA2BAB2(2A3B)2ABA2BAB153-A4(28-2A)28-A241-A26-A2-A26-A-2A4(26-4A)26-2A-A26-A2-A26-A153-A24-A3-2A24-2A2-2A24-2A-3A4(24-6A)24-3A-2A24-2A2-2A24-2A3-A24-A95-A22-A5-2A22-2A3-3A22-3A2-3A22-3A-4A4(22-8A)22-4A-3A22-3A2-3A22-3A3-2A22-2A5-A22-A66-2A20-2A5-3A20-3A3-4A20-4A2-4A20-4A-5A4(20-10A)20-5A-4A20-4A2-4A20-4A3-3A20-3A5-2A20-2A38-5A10-5A8-24A5-4A18-4A3-5A18-5A2-5A18-5A-6A4(18-12A)18-6A-5A18-5A2-5A18-5A3-4A18-4A5-24A8-2(5A10-)5B10-5B8-7A2BA4BA2B7A5-4A18-4A3-5A18-5A2-5A18-5A-6A4(18-12A)18-6A-5A18-5A2-5A18-5A3-4A18-4A5-7A2BA4BA2B7A8-2(5B10-)3A2B10-2B3A8-7AB2A4B2AB7A5-4A18-4A3-5A18-5A2-5A18-5A-6A4(18-12A)18-6A-5A18-5A2-5A18-5A3-4A18-4A5-7AB2A4B2AB7A8-3A2B10-2B3A2(10-5B)8-7A10B7A5-26A3-5A18-5A2-5A18-5A-6A4(18-12A)18-6A-5A18-5A2-5A18-5A3-4A18-4A5-7A10B7A8-2(5B10-)BA3B10-3BAB8-9A6B9A5-26A3-5A18-5A2-5A18-5A-6A4(18-12A)18-6A-5A18-5A2-5A18-5A3-4A18-4A5-9A6B9A8-BA3B10-3BAB10-2B2AB10-B2A2B8-7A4B2A4B7A5-26A3-28A2-7A4C6A4C7A-7A6C4A6C13A3(8C2A8C12A)8C2A8C6A-6A6C4A6C6A2-7A4C6A4C7A3-26A5-7A4B2A4B7A8-2B2AB10-B2A2B5-
