model
size = 30 15 12, scale = 0.05, origin = -y
material deform = 1, fade = true, lighting = smooth, roughness = 0.3, metalness = 0.6
  colors = A:#099 B:#3C0 C:#0CC
voxels
6-CB3A10-3ABC9-BC3A10-3ACB8-4AB2(4AC)4AB4A5-ABC3ACBCABC2BCBACBC3ACBA3-A3CB3AC2B6A2BC3AB3CA2-2ACBCAC3ABC4ACB3ACACBC2A-2(BC)2ABACA2CBA2BAB2CACAB2ACBC2BA2CA2BCB2(2ACBC)2ABC2BA2CABCAB2ACAC2AB3A2B3AB2ACAC2ABA2CA2B2AB2A2C2BA2CA2B2C2AB2A2BA2C2(AB)2C3ABABC2ACBAB3A2C2(BA)C-BA2C4A3C6A3C4A2CAB2-B2(AC)A2C3BAB2ABA3B2C2(AC)AB3-AB3A2CACAB4ABACA2C3ABA5-4C2(BCA)C2BC2(ACB)4C153-A4(28-2A)28-A241-A26-A2-A26-A-2A4(26-4A)26-2A-A26-A2-A26-A153-A24-A3-2A24-2A2-2A24-2A-3A4(24-6A)24-3A-2A24-2A2-2A24-2A3-A24-A95-A22-A5-2A22-2A3-3A22-3A2-3A22-3A-4A4(22-8A)22-4A-3A22-3A2-3A22-3A3-2A22-2A5-A22-A66-2A20-2A5-3A20-3A3-4A20-4A2-4A20-4A-5A4(20-10A)20-5A-4A20-4A2-4A20-4A3-3A20-3A5-2A20-2A38-5A10-3(5A8-24A5-4A18-4A3-5A18-5A2-5A18-5A-6A4(18-12A)18-6A-5A18-5A2-5A18-5A3-4A18-4A5-24A8-3(5A10-))2(5A8-24A5-26A3-5A18-5A2-5A18-5A-6A4(18-12A)18-6A-5A18-5A2-5A18-5A3-4A18-4A5-24A8-3(5A10-))5A8-24A5-26A3-28A2-7A4B6A4B7A-7A6B4A6B13A3(8B2A8B12A)8B2A8B6A-6A6B4A6B6A2-7A4B6A4B7A3-26A5-24A8-5A10-5A5-
