model
size = 20 32 20, scale = 0.05, origin = -y
material deform = 1, fade = true, lighting = smooth, roughness = 0.3, metalness = 0.6
  colors = A:#FEBFC7 B:#7D0028 C:#9AA9BC D:#FF7200 E:#8214D4 F:#ED00A8 G:#71F7B2 H:#FDA228 I:#FDCCAB J:#FFA5A5 K:#1E2C51 L:#FFF1E9 M:#9AD0FF N:#FEEA41 O:#3588FE P:#C34B29 Q:#84492C R:#1DE188 S:#B80027 T:#C2C3C7 U:#9F0E65 V:#118452 W:#EA0019
voxels
7-8B11-2(8B12-)2(2I4J2I12-)2(4I2J4I10-)2(14D6-)2(6B2(2-2B)6-)2(2B18-)2(2B4-2B2-2B8-)2(2L2M2K2L2E2K2E6-)2(2M2O2K2M6E6-)2(2L2M2K2L4E8-)2(2E4L4E10-)2(8E12-)2(8D12-)2(2D2R2D2S12-)2(8D12-)3(8B12-)2(2J2I4J12-)2(2J4I2J12-)2(6D2H12-)4(4H2D2H12-)2(6D2H12-)6(8E12-)4(8F12-)2(8D12-)2(2W2D2G2D12-)2(8D12-)4(8B12-)2(2J2I4J12-)2(2J4I2J12-)2(6D2H12-)4(4H2D2H12-)2(6D2H12-)6(8E12-)4(8F12-)2(8D12-)2(2W2D2G2D12-)2(8D12-)8B12-8B8-2(16B4-)2(2(4I8A4I4-)2(2I2J8A2I2J4-)2(2H2D8A2H2D4-)2(2H2D8B2H2D4-)4(2H2D8C2H2D4-)6(4E8C4E4-)2(4F8C4F4-)2(4F8B4F4-)2(4D8A4D4-)2(2N2D8A2H2D4-)2(4D8A4D4-)4(16B4-))2(2I12A2J4-)2(2J12A2J4-)2(2D12A2D4-)2(2D14B4-)2(2D12C2B4-)2(2D12C2D4-)6(2E12C2E4-)2(2F12C2E4-)2(2F12B2F4-)2(2D12A2D4-)2(2D12A2B4-)2(2D12A2D4-)4(16B4-)2(2I12A2J4-)2(2J12A2J4-)2(2D12A2D4-)2(2D14B4-)2(2D12C2B4-)2(2D12C2D4-)6(2E12C2E4-)2(2F12C2E4-)2(2F12B2F4-)2(2D12A2D4-)2(2D12A2B4-)2(2D12A2D4-)16B4-16B2-40B4(2J16A2I)2D16A4D16A2D2(2H18B)2(2H14C2G2B)2(2D14C2G2B)2(2E16C2L)2(2E16C2M)2(2E16C2L)2(2F16C2E)2(2F16B2E)2D16A4D2(16A2D2V)2(16A4D)16A2D80B4(2J16A2I)2D16A4D16A2D2(2H18B)2(2H14C2G2B)2(2D14C2G2B)2(2E16C2L)2(2E16C2M)2E16C2L2E3C2K6C2K3C2L2(2F16C2E)2(2F16B2E)2D16A4D2(16A2D2V)2(16A4D)2(16A2D80B2(2I16A2J)2I16A4I16A2I2D16A4D16A2D2(2H14B2G2B)2(2H12C2G4-)2(2D12C2G4-)2(2E14C2O2M)2(2E16C2O)2E16C2M2E3C2(2K2C)2K3C2M2(2F16C2L)2(2F16B2E)2D2(16A4D)2(16A2G2D)16A4D)16A2D80B2J16A4J2(16A2J2I)16A2J2D2(14A2G4D)2(12B2G2-2B2D)3(12C2G4-2D)12C2G4-2(2E14C4K)3(2E16C2K)2E3C2(2K2C)2K3C2K2(2F16C2L)2(2F16B2E)2D16A4D2(16A2D2N)2(16A4D)16A2D80B2J16A4J2(16A2J2I)16A2J2D2(14A2G4D)2(12B2G2-2B2D)3(12C2G4-2D)12C2G4-2(2E14C4K)3(2E16C2K)2E3C10K3C2K2(2F16C2L)2(2F16B2E)2D16A4D2(16A2D2N)2(16A4D)16A2D80B4(2J16A2I)2(2H12A4G2D)2(2H10B2G6-)2(2H10C2G6-)2(2H10C4G2-2B)2(2E14C2G2L)2(2E16C2M)2E16C2L2E3C10K3C2L2(2F14C2F2E)2(2F14B2F2E)2D2(16A4D)2(16A2U2D)16A4D16A2D80B4(2J16A2I)2(2H12A4G2D)2(2H10B2G6-)2(2H10C2G6-)2(2H10C4G2-2B)2(2E14C2G2L)2(2E16C2M)2(2E16C2L)2(2F14C2F2E)2(2F14B2F2E)2D2(16A4D)2(16A2U2D)16A4D16A2D40B2-2(16B4-)2(2(2I12A2J4-)2(2I12A2P2I2-)2(2H8A6G2D2-)2(2H6B2G6-2B2-)4(2H4C4G10-)2(2E8C6G2E2-)2(2E14C2E2-)2(2E12C2F2E2-)2(2F10C2Q2F2E2-)2(2F12B2F4-)2(2D12A2D4-)2(2K12A2D4-)2(2D12A2D4-)4(16B4-))2(2I2J8A4J4-)2(4J8A2P2J4-)2(4D4A8G2D2-)2(2D4B2G12-)2(2D2B2G14-)2(4D2G10-2B2-)4E2C2O2K6G2K2-4E2C2O2K2G4N2K2(2-4E4C2E2C2M2C2E)2(2-4E8C2F2Q2E)2-2(2F2E6C6F4-)2(4F6B6F4-)2(4D8A4D4-)2(2D2T8A2D2N4-)2(4D8A4D4-)4(16B4-)2(2I2J8A4J4-)2(4J8A2P2J4-)2(4D4A8G2D2-)2(2D4B2G12-)2(2D2B2G14-)2(4D2G10-2B2-)4E2C2O2K5GN2K2-4E2C2O2K2G4N2K2(2-4E4C2E2C2M2C2E)2(2-4E8C2F2Q2E)2-2(2F2E6C6F4-)2(4F6B6F4-)2(4D8A4D4-)2(2D2T8A2D2N4-)2(4D8A4D4-)16B4-16B8-2(8B12-)2(2I4J2I12-)2(4I2J4I10-)2(14D6-)2(6B2(2-2B)6-)2(2B18-)2(2B4-2B2-2B8-)2(2L2M2K2L2E2K2E6-)2(2M2O2K2M6E6-)2(2L2M2K2L4E8-)2(2E4L4E10-)2(8E12-)2(8D12-)2(2D2R2D2S12-)2(8D12-)8B12-8B6-
