model
size = 30 15 12, scale = 0.05, origin = -y
material deform = 1, fade = true, lighting = smooth, roughness = 0.3, metalness = 0.6
  colors = A:#063 B:#C6F C:#FF0
voxels
6-3A2B10-2B3A9-AB3A10-3ABA8-3B2A2B2ABA2BAB2A2B2A3B5-2B2AB4ABA4BAB4AB2A2B3-2A2(6BABA)6B2A2-B3ABAB5A4B5ABAB3AB-2A2BA2(B2A)2B4A2B2(2AB)A2B2AB2A4B5AB4AB5A4B2A2B4AB5ABAB2ABAB5AB4AB3A2(2BA)4B4A4B2(A2B)6A2B2AB3A3B2A3B3AB2A2B3A-B4A2(BA)10B2(AB)4AB2-4AB2ABA3(B2A)BAB2AB4A3-BA2B4A2(2B2A)2B4A2BAB5-3A2B4A6B4A2B3A153-B28-BA28-2A28-AB28-2B28-B241-B26-B2-B26-B-2A2(26-4A)26-3AB26-B3A26-2A-B26-B2-B26-B153-A24-A3-AB24-BA2-AB24-BA-2AB24-B5A24-6A24-5AB24-B4AB24-B2A-AB24-BA2-2A24-2A3-B24-B95-A22-A5-2A22-2A3-3A22-3A2-2AB22-B2A-3AB22-B7A3(22-8A)22-4A-2AB22-B2A2-2AB22-B2A3-2A22-2A5-A22-A66-AB20-BA5-3A20-3A3-3AB20-B3A2-3AB20-B3A-4A3(B20-B8A)B20-B9A20-5A-4A20-4A2-3AB20-B3A3-2AB20-B2A5-2A20-2A38-B4A10-4AB8-2A4BA3BA2BA3BA4B2A5-3AB18-B3A3-5A18-5A2-5A18-5A-6A18-11A3(B18-B10A)B18-B5A-4AB18-B4A2-5A18-5A3-3AB18-B3A5-2A3B2A2(BA)2B2(AB)2A3B2A8-A4B10-4BA2(10-5A)2(8-24A5-4A18-4A3-5A18-5A2-5A18-5A-6A4(18-12A)18-6A-5A18-5A2-5A18-5A3-4A18-4A5-24A8-3(5A10-)5A)8-24A5-4A3B2(AB)A2B2(AB)A3B4A2(3-5A18-5A2-5A18-5A-6A4(18-12A)18-6A-5A18-5A2-5A18-5A3-4A18-4A5-24A8-3(5A10-)5A8-24A5-26A)3-28A2-7A4C6A4C7A-7A6C4A6C13A3(8C2A8C12A)8C2A8C6A-6A6C4A6C6A2-7A4C6A4C7A3-26A5-24A8-5A10-5A5-
