model
size = 30 15 12, scale = 0.05, origin = -y
material deform = 1, fade = true, lighting = smooth, roughness = 0.3, metalness = 0.6
  colors = A:#C0C B:#700 C:#6C6
voxels
6-2(BC)A10-A2(CB)9-ABCBA10-ABCBA8-C2(BA)2BC8AC2B2(AB)C5-ABAC2BCB2AB4AB2ABC2BCABA3-2A2B2A3B2AB4AB2A3B2A2B2A2-BC3A2(CA2B)2A2(2BAC)3ACB-A2BAC2A2(CA)B6AB2(AC)2ACA2BABC3B2(3AC)A2CA2(C3A)3BC2(B2A)B3(AC)6A3(CA)2(B2A)3BC4(AB)AC2BC4(AB)AC4B2CACB3C3AB4CB3A3CBCA2CB-CB6AC3B4A3BC6ABC2-CA2(BC)A3BACA2CACA3BA2(CB)AC3-B2(CA)BAB3AC2BC3A2(BA)CACB5-BC2B4A2CA2BA2C4A2BCB153-A28-AC28-CA2(28-2A)28-A241-A26-A2-A26-A-2A26-2A2B26-2BAB26-BABC26-CBAC26-CA-A26-A2-A26-A153-A24-A3-2A24-2A2-2A24-2A-3A24-3AC2A24-2AC3A24-3ACAC24-CAC3A24-3A-2A24-2A2-2A24-2A3-A24-A95-B22-B5-AB22-BA3-2AB22-B2A2-3A22-3A-C3A22-3AC4A2(22-8A)22-4AC3A22-3AC-3A22-3A2-3A22-3A3-2A22-2A5-A22-A66-2A20-2A5-2AC20-C2A3-4A20-4A2-4A20-4A-5A20-9AC20-C9A2(20-10A)20-5A-4A20-4A2-3AC20-C3A3-3A20-3A5-2A20-2A38-AC3A10-3ACA8-2AB3A2B2(2AC)2A2B3AB2A5-4A18-4A3-4AC18-C4A2-5A18-5A-5AB18-B5AC4AC18-C4ACB5A18-5ABC5A18-5AC5AB18-B5A-4AB18-B4A2-5A18-5A3-3AC18-C3A5-3AC4ABC4ACB4AC3A8-3ABA10-AB3A2(10-5A)8-24A5-4A18-4A3-5A18-5A2-5A18-5A-2(6A18-6AC5A18-5AC)6A18-6A-5A18-5A2-5A18-5A3-4A18-4A5-24A8-3(5A10-)5A8-24A5-4A18-4A3-5A18-5A2-5A18-5A-6A4(18-12A)18-6A-5A18-5A2-5A18-5A3-4A18-4A5-24A8-3(5A10-)5A8-24A5-26A3-5A18-5A2-5A18-5A-2(6A18-6AC5A18-5AC)6A18-6A-5A18-5A2-5A18-5A3-4A18-4A5-24A8-3(5A10-)5A8-24A5-26A3-5A18-5A2-5A18-5A-6A4(18-12A)18-6A-5A18-5A2-5A18-5A3-4A18-4A5-24A8-3(5A10-)5A8-24A5-26A3-28A2-7A4B6A4B7A-B6A6B4A6B6ABC5A8B2A8B5AC6A8B2A8B6AC5A8B2A8B5ACB5A8B2A8B5AB-6A6B4A6B6A2-7A4B6A4B7A3-26A5-24A8-5A10-5A5-
