model
size = 30 15 12, scale = 0.05, origin = -y
material deform = 1, fade = true, lighting = smooth, roughness = 0.3, metalness = 0.6
  colors = A:#090 B:#F36 C:#909
voxels
6-2C2AC10-C2A2C9-4CB10-B4C8-3B8A2B8A3B5-2(A2C)2ABAB4ABAB2A2(2CA)3-C2ACB3A2CAC4ACA2C3ABC2AC2-BA2(C2A)3BCB2CBC3B2(2AC)AB-2A3B3AC2AB2A2B2AB2AC3A3B2(2AC)B2(C2A)2(3C2A)C2ACB2(C2A)2B6ACAB4ABAC6A2B4AB2C4ACB8ABC4A2CB2ACB4AC2BCAB6ABAC2BC4ABC-B2(CA)C2AC3A4B3AC2A2(CA)CB2-5A4B4A2B4A4B5A3-3A2B2ACBACA2BACABC2A2B3A5-CBA2BACAB6ABACA2BABC153-A4(28-2A)28-A241-A26-A2-A26-A-2A26-4A26-2ABA26-AB2A26-4A26-2A-A26-A2-A26-A153-A24-A3-2A24-2A2-2A24-2A-3A4(24-6A)24-3A-2A24-2A2-2A24-2A3-A24-A95-A22-A5-2A22-2A3-3A22-3A2-3A22-3A-2(C3A22-3AC4A22-4A)C3A22-3AC-3A22-3A2-3A22-3A3-2A22-2A5-A22-A66-2A20-2A5-3A20-3A3-4A20-4A2-4A20-4A-5A4(20-10A)20-5A-4A20-4A2-4A20-4A3-3A20-3A5-2A20-2A38-5A10-5A8-24A5-4A18-4A3-5A18-5A2-5A18-5A-6A18-12A18-6AB5A18-5AB6A18-12A18-6A-5A18-5A2-5A18-5A3-4A18-4A5-24A8-2(5A10-)4BA10-A4B8-7A2BCA2CAC2B7A5-4A18-4A3-5A18-5A2-5A18-5A-6A4(18-12A)18-6A-5A18-5A2-5A18-5A3-4A18-4A5-7A2BCA2CAC2B7A8-4BA10-A4B10-4CA10-A4C8-8ACAB2CBAC8A5-4A18-4A3-5A18-5A2-5A18-5A-2(6A18-6AC5A18-5AC)6A18-6A-5A18-5A2-5A18-5A3-4A18-4A5-8ACAB2CBAC8A8-4CA10-A4C10-2(BC)A10-A2(CB)8-7AC2BA2CA2BC7A5-26A3-5A18-5A2-5A18-5A-6A18-12A18-6AC5A18-5AC6A18-12A18-6A-5A18-5A2-5A18-5A3-4A18-4A5-7AC2BA2CA2BC7A8-2(BC)A10-A2(CB)10-2CACA10-ACA2C8-7AB2CB2AB2CB7A5-26A3-5A18-5A2-5A18-5A-C5A18-5AC6A2(18-12A)18-6AC5A18-5AC-5A18-5A2-5A18-5A3-4A18-4A5-7AB2CB2AB2CB7A8-2CACA10-ACA2C10-A3CB10-B3CA8-7A10C7A5-26A3-28A2-7A4B6A4B7A-B6A6B4A6B6AB6A2(8B2A8B12A)8B2A8B6AB5A8B2A8B5AB-6A6B4A6B6A2-7A4B6A4B7A3-26A5-7A10C7A8-A3CB10-B3CA5-
