model
size = 31 30 31, scale = 0.05, origin = -y
material deform = 1, fade = true, lighting = smooth, roughness = 0.3, metalness = 0.6
  colors = A:#FFF B:#FBFBFB C:#070707 D:#A0A0A0 E:#0A3D0B F:#181818 G:#1C1C1C H:#005AF8 I:#090909 J:#0A0A0A K:#535353 L:#030303 M:#606060
voxels
74-7A24-2(8A23-)7A26-3A772-3A24-11A2(19-12A)20-11A21-9A24-5A709-3C25-3A3B3A19-4(6A3B6A16-)6A3B6A18-4A3B4A21-9A23-2A3B2A24-2A3B2A25-2(A3BA26-)8(5A26-)5A27-3A242-4C-4C19-3A4B-4B3A14-4(5A4B-4B5A12-)5A4B-4B5A13-4A4B-4B4A16-5AB-B5A18-3A7B3A19-2A7B2A20-2A7B2A21-A7BA3(22-9A)23-6(7A24-)2(6AD24-)6AD175-4C7-4C14-2A4B7-4B2A11-4(3A4B7-4B3A10-)3A4B7-4B3A11-2A4B7-4B2A13-4AB7-B2(4A14-A12B)4A15-12B3A16-12B3A17-5(13A18-)13A19-11A21-2(9A22-)3(D7AD22-)8AD141-3C13-3C11-A3B13-3BA9-4(2A3B13-3B2A8-)2A3B13-3B2A9-A3B13-3BA11-2AB13-B2(2A12-A16B)2(2A12-2A15B)2A12-19A13-3(17A14-)17A15-4(15A16-)2(3D9A3D16-)3D9A3D17-2D9A2D19-11A108-2C17-2C9-A2B17-2BA7-4(2A2B17-2B2A6-)2A2B17-2B2A7-A2B17-2BA9-5(A2B16-BA10-)2(3A16-2A10-)3(3A16-A11-)4(3A15-2A11-)A2D15-DA11-A2(2D15-DA12-)A2D13AD2A12-19A13-16A74-2C19-2C7-A2B19-2BA5-4(2A2B19-2B2A4-)2A2B19-2B2A5-A2B19-2BA7-A3B17-B4(A8-A3B16-2B)A8-4A16-3A8-4A17-2A8-4A16-3A8-5(4A16-2A9-)4A5(16-2A10-3A)16-2A10-20A13-16A43-C22-C5-A2B22-BA4-A2B22-B2A2-2A2(2B22-B2A-3A)2B22-B2A2-2A2B22-B2A3-A2B22-BA5-3(A3B20-A6-)2(A3B19-BA6-)4(4A19-2A6-)2(4A19-A7-)4A3(19-A8-3A)18-2A3(8-3A17-3A)8-3A17-2A10-2A16-2A12-18A16-12A13-2C23-C4-A2B23-B3-A2(3B23-BA-2A)2(3B23-B4A)3B23-B2A2-3B23-BA3-A3B22-B2(4-A3B21-2B)2(4-A3B20-3B)5(4-4A20-3A)3-5A20-3A3-5A20-4A2-4A21-4A2-5A20-3A4-4A19-3A5-4A19-3A6-3A18-3A7-3A18-3A8-2A18-2A10-A17-2A12-2(2A14-)15A12-C24-C4-AB24-BA2-A2B24-BA-2A4(2B24-B4A)2B24-B2A2-A2B23-BA3-2(A2B22-2B4-)2(A2B21-3B4-)3(3A21-3A4-)3A21-3A3-4A21-4A2-4A21-4A-D4A21-3AK2D4A21-3AKD-4A20-5A2-4A20-4A4-3A20-3A5-3A19-4A6-2A19-3A8-2A18-2A10-A17-2A12-2(2A14-)15A12-C24-C4-CB24-BA2-A2B24-BA-2A3(2B24-B4A)2B24-B2A-A2B24-BA2-2A2B23-B2(A2-A3B22-2B)2(A2-A3B21-3B)A6(2-4A21-4A)-D4A21-3AK2D4A21-3AKD-2(4A20-5A2-)4A20-4A4-3A20-3A6-2A19-3A8-2A18-2A10-A17-2A12-2(2A14-)15A42-C25-C3-AB25-BA-2AB25-B4AB25-B2AHAB25-BAH-HB25-BH3-H25-H4-H2B23-H4-2AB22-A3(5-2AB21-2B)5-3A21-2A5-2(3A21-3A4-)3A21-3A3-4A21-4A2-4A21-4A-D4A21-3AK2D4A21-3AKD-4A21-4A2-4A20-5A2-4A20-4A4-3A20-3A6-2A20-2A8-2A18-2A10-A17-2A12-2(2A14-)15A42-C25-C3-AB25-BA-2A2(B25-B4A)B25-B2A-AB25-BA3-A25-B5-A24-A5-AB21-2B7-3(B21-B8-)A21-A8-A2(21-A7-2A)21-2A5-3A21-3A3-4A21-4A-D4A21-3AK2D4A21-3AKD-4A22-3A2-4A20-4A4-3A20-3A5-3A20-3A6-2A20-2A8-DA18-AD10-A17-2A12-2(2A14-)15A42-C24-BC3-AB24-2BA-2AB24-2B4AB24-2B2AHAB24-2BAH-HB24-2BH3-H24-BH5-HB22-BH5-AB21-BA7-3(B21-B8-)3(A21-A8-)A21-A7-2A21-2A4-4A21-3A3-4A21-4A2-4A20-5A2-4A20-4A4-3A20-3A6-2A20-3A5-F2A20-ACF6-DA20-AD8-DA18-AD10-A17-2A12-2A14-2A15-14A42-2C23-C4-A2B23-2BA-2A2(2B23-2B4A)2B23-2B2A-A2B23-2BA3-AB23-2B5-AB22-BA5-AB21-2B7-3(B21-B8-)3(A21-A8-)A21-A7-2A21-A6-3A20-3A5-2(3A20-4A4-)3A2(19-4A6-2A)19-3A6-F2A19-2ACF6-D2A18-2AD8-D2A16-2AD10-3A15-2A12-17A17-12A44-C23-C4-2AB23-B2A-3AB23-B6AB23-B3AH2AB23-B2AH-HAB23-BAH3-HB23-BH5-2B22-A7-4(B21-B8-)4(A21-A8-)A20-2A7-2A20-3A2(5-3A19-4A)6-2A19-4A6-2A18-4A7-2A18-4A6-FCA18-3ACF6-6A14-4A8-5A14-3A10-19A103-C23-C4-2AB23-B2A-3AB23-B6AB23-B4AHAB23-B3A-2AB23-B2A4-A23-BA6-B22-A7-4(B21-B8-)A20-2A2(8-A21-A)8-A20-2A7-2A20-3A6-2A19-4A2(6-3A17-5A)6-2(6A14-4A7-)6A14-4A6-2F5A14-3A2F7-5A14-3A9-21A133-C23-C5-AB23-B2A-3AB23-B6AB23-B3A2HAB23-B2AH2-HB23-BAH4-B23-BA6-B22-A7-4(B20-2B8-)2(3A18-2A8-)3A18-2A7-4A18-3A6-D2A19-AMD6-D2A18-2AMD6-D2A17-2LAMD6-3A17-2L2A7-3A17-2L2A8-2A-2C14-2L2A8-2A17-4A6-2F2A17-3A2F7-22A134-C20-C7-2C21-BC5-AB22-2BA3-2AB22-2B2A2-2AB22-2B2A3-AB22-2B2A4-A22-2BA5-A22-2BA6-B21-2B7-4(B20-2B8-)3A18-2A8-3A18-2A7-4A18-3A6-4A18-AD7-D3A18-AD7-D2A2E15-2EAD7-DA5E11-5EA7-2A8E5-8EA8-A9E3-9EA8-2A9E-9E2A8-23A8-23F164-2C19-C8-3B19-B6-2A3B19-BA5-2A3B19-B2A4-2A3B19-B2A5-A3B19-B2A6-2(3B19-BA7-)3B19-B4(8-3B17-3B)8-3A17-4A6-4A17-4A7-2(D2A17-2AD8-)D5A13-3AD8-2A2-15A2-2A8-A5-11A5-2(A8-)5A2(8-A)9-3A9-A8-2A9-A9-2A9-21A197-C18-C10-2B18-BA7-2(2A2B18-B2A6-)2A2B18-B2A7-A2B18-B2A8-2(2B18-BA9-)4B16-B2(A8-A5B13-3B)A7-2(2A5B13-3B2A6-)7A14-4A7-6A14-2A10-D4A12-3A2(D10-D19A)D10-A5-9A5-A18-5A329-2C16-2C10-7(3B16-2BA8-A)4B15-2BA7-2(2A5B13-3B2A6-)2A5B13-3B2A7-A5B13-3BA8-6A14-3A9-5A14-2A11-19A18-7A24-7A391-C16-C12-2B16-B11-4(A2B16-B2A9-)A2B16-B2A10-2B16-BA11-3B15-B4(A10-A4B13-2B)A11-19A13-17A20-5A26-5A423-C16-C2(12-2B16-B)5(A11-2B16-B)A11-3B15-B2(A11-4B13-2B)A11-4B12-A2B13-16B16-15A21-5A27-3A454-2C16-2C10-3B16-2B9-4(A3B16-2BA8-)A3B16-2BA9-3B16-2B10-4B15-2B11-BC3A9B3ACB13-2ACA9BAC2A16-2A4(CA)C2A20-9B23-7A26-3A485-C18-C10-2B18-B9-4(A2B18-BA8-)A2B18-BA9-2B18-B10-8A6-7A11-6A7B6A14-A-5(AC)A-A18-5(AC)A22-3(AC)A26-ACA516-C17-2C10-2B5A8-4A2B9-3(A2B5A8-4A2BA8-)A2B5A8-AB2A2BA8-A2B5A8-AB2A2BA9-7B8-6B16-2A5B2A23-7A638-19C11-A8B3C8BA10-AB4-3B3C3B4-2(BA10-AB-2C-3B3C3B-2C-)2(BA10-AB4-BAB3CBAB4-)BA10-9A3C9A18-A3GA674-3C2(IC)I3C16-4A2B3(CI)C2B4A12-A4-A3(CI)CA4-A12-A-2C-A3(CI)CA-2C-A12-A-2C-A2ICIC2IA-2C-A12-A4-A-2(IC)I-A4-A12-6A-2(IC)I-6A20-CIC28-GIG675-2C3(G-)G2C20-2A3(G-)G2A22-3(G-)G20-2J2-3(G-)G2-2J16-2J2-3(G-)G2-2J22-3(G-G28-)G-G665-
