model
size = 31 30 31, scale = 0.05, origin = -y
material deform = 1, fade = true, lighting = smooth, roughness = 0.3, metalness = 0.6
  colors = A:#FFF B:#FBFBFB C:#820806 D:#070707 E:#A0A0A0 F:#03350B G:#181818 H:#1C1C1C I:#005AF8 J:#090909 K:#0A0A0A L:#535353 M:#030303 N:#606060
voxels
74-7A24-2(8A23-)7A26-3A772-3A24-11A2(19-12A)20-11A21-9A24-5A709-3D25-3A3B3A19-4(6A3B6A16-)6A3B6A18-4A3B4A21-9A23-2A3B2A24-2A3B2A25-2(A3BA26-)8(5A26-)5A27-3C242-4D-4D19-3A4B-4B3A14-4(5A4B-4B5A12-)5A4B-4B5A13-4A4B-4B4A16-5AB-B5A18-3A7B3A19-2A7B2A20-2A7B2A21-A7BA3(22-9A)23-6(7A24-)6A2(E24-2A3CA)E175-4D7-4D14-2A4B7-4B2A11-4(3A4B7-4B3A10-)3A4B7-4B3A11-2A4B7-4B2A13-4AB7-B2(4A14-A12B)4A15-12B3A16-12B3A17-5(13A18-)13A19-11A21-2(9A22-)3(E7AE22-)3A3C2AE141-3D13-3D11-A3B13-3BA9-4(2A3B13-3B2A8-)2A3B13-3B2A9-A3B13-3BA11-2AB13-B2(2A12-A16B)2(2A12-2A15B)2A12-19A13-3(17A14-)17A15-4(15A16-)2(3E9A3E16-)3E9A3E17-2E9A2E19-3A5C3A108-2D17-2D9-A2B17-2BA7-4(2A2B17-2B2A6-)2A2B17-2B2A7-A2B17-2BA9-5(A2B16-BA10-)2(3A16-2A10-)3(3A16-A11-)4(3A15-2A11-)A2E15-EA11-A2(2E15-EA12-)A2E13AE2A12-19A13-5A7C4A74-2D19-2D7-A2B19-2BA5-4(2A2B19-2B2A4-)2A2B19-2B2A5-A2B19-2BA7-A3B17-B4(A8-A3B16-2B)A8-4A16-3A8-4A17-2A8-4A16-3A8-5(4A16-2A9-)4A5(16-2A10-3A)16-2A10-20A13-5A7C4A43-D22-D5-A2B22-BA4-A2B22-B2A2-2A2(2B22-B2A-3A)2B22-B2A2-2A2B22-B2A3-A2B22-BA5-3(A3B20-A6-)2(A3B19-BA6-)4(4A19-2A6-)2(4A19-A7-)4A3(19-A8-3A)18-2A3(8-3A17-3A)8-3A17-2A10-2A16-2A12-18A16-3A7C2A13-2D23-D4-A2B23-B3-A2(3B23-BA-2A)2(3B23-B4A)3B23-B2A2-3B23-BA3-A3B22-B2(4-A3B21-2B)2(4-A3B20-3B)5(4-4A20-3A)3-5A20-3A3-5A20-4A2-4A21-4A2-5A20-3A4-4A19-3A5-4A19-3A6-3A18-3A7-3A18-3A8-2A18-2A10-A17-2A12-2(2A14-)5A7C3A12-D24-D4-AB24-BA2-A2B24-BA-2A4(2B24-B4A)2B24-B2A2-A2B23-BA3-2(A2B22-2B4-)2(A2B21-3B4-)3(3A21-3A4-)3A21-3A3-4A21-4A2-4A21-4A-E4A21-3AL2E4A21-3ALE-4A20-5A2-4A20-4A4-3A20-3A5-3A19-4A6-2A19-3A8-2A18-2A10-A17-2A12-2(2A14-)5A7C3A12-D24-D4-DB24-BA2-A2B24-BA-2A3(2B24-B4A)2B24-B2A-A2B24-BA2-2A2B23-B2(A2-A3B22-2B)2(A2-A3B21-3B)A6(2-4A21-4A)-E4A21-3AL2E4A21-3ALE-2(4A20-5A2-)4A20-4A4-3A20-3A6-2A19-3A8-2A18-2A10-A17-2A12-2(2A14-)5A7C3A42-D25-D3-AB25-BA-2AB25-B4AB25-B2AIAB25-BAI-IB25-BI3-I25-I4-I2B23-I4-2AB22-A3(5-2AB21-2B)5-3A21-2A5-2(3A21-3A4-)3A21-3A3-4A21-4A2-4A21-4A-E4A21-3AL2E4A21-3ALE-4A21-4A2-4A20-5A2-4A20-4A4-3A20-3A6-2A20-2A8-2A18-2A10-A17-2A12-2(2A14-)5A7C3A42-D25-D3-AB25-BA-2A2(B25-B4A)B25-B2A-AB25-BA3-A25-B5-A24-A5-AB21-2B7-3(B21-B8-)A21-A8-A2(21-A7-2A)21-2A5-3A21-3A3-4A21-4A-E4A21-3AL2E4A21-3ALE-4A22-3A2-4A20-4A4-3A20-3A5-3A20-3A6-2A20-2A8-EA18-AE10-A17-2A12-2(2A14-)5A7C3A42-D24-BD3-AB24-2BA-2AB24-2B4AB24-2B2AIAB24-2BAI-IB24-2BI3-I24-BI5-IB22-BI5-AB21-BA7-3(B21-B8-)3(A21-A8-)A21-A7-2A21-2A4-4A21-3A3-4A21-4A2-4A20-5A2-4A20-4A4-3A20-3A6-2A20-3A5-G2A20-ADG6-EA20-AE8-EA18-AE10-A17-2A12-2A14-2A15-4A7C3A42-2D23-D4-A2B23-2BA-2A2(2B23-2B4A)2B23-2B2A-A2B23-2BA3-AB23-2B5-AB22-BA5-AB21-2B7-3(B21-B8-)3(A21-A8-)A21-A7-2A21-A6-3A20-3A5-2(3A20-4A4-)3A2(19-4A6-2A)19-3A6-G2A19-2ADG6-E2A18-2AE8-E2A16-2AE10-3A15-2A12-7A5C5A17-3A7C2A44-D23-D4-2AB23-B2A-3AB23-B6AB23-B3AI2AB23-B2AI-IAB23-BAI3-IB23-BI5-2B22-A7-4(B21-B8-)4(A21-A8-)A20-2A7-2A20-3A2(5-3A19-4A)6-2A19-4A6-2A18-4A7-2A18-4A6-GDA18-3ADG6-6A14-4A8-5A14-3A10-8A5C6A103-D23-D4-2AB23-B2A-3AB23-B6AB23-B4AIAB23-B3A-2AB23-B2A4-A23-BA6-B22-A7-4(B21-B8-)A20-2A2(8-A21-A)8-A20-2A7-2A20-3A6-2A19-4A2(6-3A17-5A)6-2(6A14-4A7-)6A14-4A6-2G5A14-3A2G7-5A14-3A9-10A3C8A133-D23-D5-AB23-B2A-3AB23-B6AB23-B3A2IAB23-B2AI2-IB23-BAI4-B23-BA6-B22-A7-4(B20-2B8-)2(3A18-2A8-)3A18-2A7-4A18-3A6-E2A19-ANE6-E2A18-2ANE6-E2A17-2MANE6-3A17-2M2A7-3A17-2M2A8-2A-2D14-2M2A8-2A17-4A6-2G2A17-3A2G7-10A3C9A134-D20-D7-2D21-BD5-AB22-2BA3-2AB22-2B2A2-2AB22-2B2A3-AB22-2B2A4-A22-2BA5-A22-2BA6-B21-2B7-4(B20-2B8-)3A18-2A8-3A18-2A7-4A18-3A6-4A18-AE7-E3A18-AE7-E2A2F15-2FAE7-EA5F11-5FA7-2A8F5-8FA8-A9F3-9FA8-2A9F-9F2A8-23A8-23G164-2D19-D8-3B19-B6-2A3B19-BA5-2A3B19-B2A4-2A3B19-B2A5-A3B19-B2A6-2(3B19-BA7-)3B19-B4(8-3B17-3B)8-3A17-4A6-4A17-4A7-2(E2A17-2AE8-)E5A13-3AE8-2A2-15A2-2A8-A5-11A5-2(A8-)A3C2(A8-)A9-3C9-A8-2A9-C9-2A9-9A3C9A197-D18-D10-2B18-BA7-2(2A2B18-B2A6-)2A2B18-B2A7-A2B18-B2A8-2(2B18-BA9-)4B16-B2(A8-A5B13-3B)A7-2(2A5B13-3B2A6-)7A14-4A7-6A14-2A10-E4A12-3A2(E10-E19A)E10-A5-3A3C3A5-A18-A3CA329-2D16-2D10-7(3B16-2BA8-A)4B15-2BA7-2(2A5B13-3B2A6-)2A5B13-3B2A7-A5B13-3BA8-6A14-3A9-5A14-2A11-19A18-7A24-2A3C2A391-D16-D12-2B16-B11-A2B16-B2A4(9-C2B16-BAC)10-CB16-BC11-C2B15-BC4(10-A4B13-2BA)11-19A13-2(5AC)5A20-C3AC26-5C423-D16-D12-2B16-B12-6(CB16-BC11-)C2B15-BC11-C3B13-2BC11-C3B13-BCA11-B2CB12-3C13-B3C9B3C16-3A2C5A2C3A21-C3AC27-3C454-2D16-2D10-C2B16-BC9-4(2C2B16-2BC8-)2C2B16-2BC9-C2B16-BC10-C3B15-BC11-CD3A9B3ADC13-2CDA9BAD2C16-2C4(DA)D2C20-C7BC23-2C3A2C26-3C485-D18-D10-CB18-C9-4(C2B18-BC8-)C2B18-BC9-CB18-C10-6C2A6-A6C11-6C7B6C14-C-5(CD)C-C18-5(CD)C22-3(CD)C26-CDC516-D17-2D10-CB5A8-4ABC9-C2B4CA8-4C2(2BC8-C2BC2ACA8-C2AC)2(2BC8-C2B4CA8-4C)2BC9-6CB8-6C16-2C5B2C23-7C638-19D11-CB4C3B3D3B4CBC10-CB4-C2B3D2BC4-2(2C10-CB-2D-C2B3D2BC-2D-)2(2C10-CB4-2CB3DB2C4-)2C10-9C3D9C18-C3HC674-3D2(JD)J3D16-5CB3(DJ)DB5C12-C4-C3(DJ)DC4-C12-C-2D-C3(DJ)DC-2D-C12-C-2D-C2JDJD2JC-2D-C12-C4-C-2(JD)J-C4-C12-6C-2(JD)J-6C20-DJD28-HJH675-2D3(H-)H2D20-2C3(H-)H2C22-3(H-)H20-2K2-3(H-)H2-2K16-2K2-3(H-)H2-2K22-3(H-H28-)H-H665-
