model
size = 19 28 19, scale = 0.05, origin = -y
material deform = 1, fade = true, lighting = smooth, roughness = 0.3, metalness = 0.6
  colors = A:#0FF B:#FFF C:#D00 D:#0A0 E:#AAA F:#F30 G:#E00 H:#CF3 I:#00FF26 J:#F0C K:#007
voxels
4-8A10-2A4-5A7-2A5-6A5-2A6-2A3(BA)3-A7-3A3B2A3-A7-2A2(2BA)2-2A7-2(3A3B2A2-A8-2A3(BA)2(2-A8-8A)2-A8-2A3(BA)2-A8-3A3B2A2-A8-2A2(2BA)2-A8-)3A3B2A2-2A7-2A3(BA)3-A7-8A3-A7-6A5-2A6-5A7-2A5-4A9-2A2-3A13-4A15-8A10-2A4-5A7-2A5-6A5-2A6-8A3-A6-11A-A6-13A6-12A2(8-11A)4(7-12A)7(7-9A2-A)7-9A2-2A2(6-9A3-A)6-7A5-2A5-6A7-2A5-4A9-2A2-3A13-4A20-2(3A16-5A14-6A13-8A10-2(11A8-)11A2(9-10A)4(8-11A)8-10(9A10-)7A12-6A14-4A53-)3A16-5A14-6A13-8A10-2(11A8-)11A9-9AD9-10A4(8-11A)8-2(9A10-)8AB7(10-9A)10-7A12-6A14-4A53-3A16-5A14-6A13-8A10-2(11A8-)11A9-9AH9-9AD4(8-11A)8-2(9A10-)8AB3(10-8AC)10-9A2(10-8AB)10-9A10-7A12-6A14-4A53-3A16-5A14-6A13-8A10-2(11A8-)11A2(9-9AD)8-10AD3(8-11A)8-2(9A10-)8AB4(10-8AC)2(10-8AB)10-9A10-7A12-6A14-4A53-3A16-5A14-6A13-8A10-2(11A8-)11A9-9AD9-9AJ2(8-10AD)2(8-11A)8-2(9A10-)8AB4(10-8AC)2(10-8AB)10-9A10-7A12-6A14-4A53-3A16-5A14-6A13-8A10-11A2(8-10AF)2(9-9AD)3(8-10AD)8-11A8-2(9A10-)8AB4(10-8AC)3(10-9A)10-7A12-6A14-4A53-3A16-5A14-6A13-8A10-11A2(8-10AF)9-9AD9-9AI8-10AD8-10AK8-10AD8-11A8-2(9A10-)8AB4(10-8AC)3(10-9A)10-7A12-6A14-4A53-3A16-5A14-6A13-8A10-2(11A8-)11A2(9-9AD)2(8-10AD)2(8-11A)8-2(9A10-)8AB3(10-8AC)4(10-9A)10-7A12-6A14-4A53-3A16-5A14-6A13-8A10-2(11A8-)11A9-9AG9-9AD8-10AD3(8-11A)8-2(9A10-)8AB2(10-8AC)5(10-9A)10-7A12-6A14-4A53-3A16-5A14-6A13-8A10-2(11A8-)11A2(9-9AD)4(8-11A)8-2(9A10-)8AB10-8AC6(10-9A)10-7A12-6A14-4A53-3A16-5A14-6A13-8A10-2(11A8-)11A9-9AD9-10A4(8-11A)8-2(9A10-)8AB7(10-9A)10-2(7A12-6A14-4A53-3A16-5A14-6A13-8A10-2(11A8-)11A2(9-10A)4(8-11A)8-10(9A10-))7A12-6A14-4A48-8A10-2A4-5A7-2A5-6A5-2A6-8A3-A6-11A-A6-13A6-12A2(8-11A)4(7-12A)7(7-9A2-A)7-9A2-2A2(6-9A3-A)6-7A5-2A5-6A7-2A5-4A9-2A2-3A13-4A15-8A10-2A4-5A7-2A5-6A5-2A6-2(8A3-A7-)8A2-2A7-3(8A2-A8-)11(2AE5A2-A8-)2AE5A2-2A2(7-2AE5A3-A)7-3AE2A5-2A6-5A7-2A5-4A9-2A2-3A13-4A116-6A13-6A402-
