model
size = 10 8 30, scale = 0.05, origin = -y
material deform = 1, fade = true, lighting = smooth, roughness = 0.3, metalness = 0.6
  colors = A:#FF5900 B:#FFF C:#101010 D:#F1D998 E:#787878 F:#E0E0E0 G:#989898 H:#404040 I:#1F1F1F J:#9191AE K:#40414E L:#535353 M:#575757 N:#000 O:#071 P:#A80000 Q:#393939
voxels
14-2(2D8-)2D70-E9-L59-J9-E9-F9-E59-E9-H9-E9-K39-2(E9-)F9-E59-E9-F2(9-E)39-2(E9-)H9-E59-E9-F2(9-E)39-K9-E9-F9-E59-E9-H2(9-E)39-2(E9-)F9-E59-E9-F9-E9-J39-L9-E9-H9-E59-E9-F2(9-E)39-2(E9-)F9-E59-E9-H9-E9-K39-J9-E9-F9-E59-E9-F9-E9-L49-E9-F9-E34-2(7C3-)5C2(B9C)B6C-3C2(-2C)5-2C2-7C14-5G4-A5BM3-A4BA5-4A45-6A4-A5BM3-A4BA5-APOA36-4A5-2(A4BA4-)A4BA5-4A36-4A3-I-A4BA2-IQ5BA4-A4BA5-4A36-4A3-I-A4BA2-I-A4BA4-A4BA5-4A36-4A5-6A4-2AB3A4-A4BA5-4A36-4D17-N8-AB2D6-4A36-4D17-N8-4D46-4D16-4D6-4D46-2(4D6-)4D53-
