model
size = 31 19 10, scale = 0.05, origin = -y
material deform = 1, fade = true, lighting = smooth, roughness = 0.3, metalness = 0.6
  colors = A:#603838 B:#734747 C:#E4E4E4 D:#161616
voxels
434-A170-2A29-A30-A2(29-2A)3(27-4A)8-A19-3A3-6A25-2A29-2A365-2A29-2A27-4A3(25-6A)3-A22-3A5-2A29-2A453-9A22-11A19-13A17-14A16-15A26-4A63-8A21-5A26-11A20-4AC5A22-2A3B3A24-5A170-8B22-A10B19-12AB17-13A2(B15-15A)B15-A4-11AB21-2A4-3A2B27-2A2B6A21-3AD27-11A20-11A21-8A24-5A169-9B21-12B18-3B10AB15-5B10AB14-6B10AB13-17AB12-5A2-12AB11-A8-4A2-4A28-11A21-5A26-11A20-4AC5A22-2A3B3A24-5A170-8B22-A10B19-12AB17-13A2(B13-17A)B11-5A4-11A11-2A9-2A4-2A392-9A21-12A18-14A16-15A13-3A-14A12-3A11-4A12-2A28-2A320-2A27-4A27-2(5A26-)5A3-A22-4A4-2A29-2A43-A29-2A193-A30-4A30-2(2A29-)2A3(27-4A)9-A17-3A5-6A25-2A29-2A72-2A184-
