model
size = 9 32 9, scale = 0.05, origin = -y
material deform = 1, fade = true, lighting = smooth, roughness = 0.3, metalness = 0.6
  colors = A:#222 B:#777 C:#AAA D:#444 E:#555 F:#888 G:#0A0 H:#500
voxels
246-BCB6-3B6-BCB257-2(CB)C3-2CBCB2C2-7B2-2CBCB2C3-2(CB)C32-3D20(6-3A)6-3D15-BCB4-2(2CBCB2C2-)B5CB2(2-2CBCB2C)3-2(CB)C6-B7-3E5-D3AD20(4-5A)4-D2A2D5-3C5-B3CB3-2B3DFB-3B2CD6B2CD7BC4B-3BC3B3-5B5-BGB6-3E5-D3AD20(4-5A)4-D2A2D5-CFC5-2CE2C3-C5DC-5CD3C2B3CDC2B3CBCB3C-2CBCB2C3-2(CB)C6-B7-3E5-D3AD20(4-5A)4-5D5-3C5-B3CB3-BF3D2B-2B2(3CD5B)CBC4B-2(BC)3B3-5B23-3D13(6-3A)6-AGA6-ADA6-AHA4(6-3A)6-3D15-BCB4-2CBDB2C2-2CBCBDC2-3(BC)B2(2-2CBCB2C)3-2(CB)C238-2(CB)C3-2CBCB2C2-7B2-2CBCB2C3-2(CB)C257-BCB6-3B6-BCB21-
