model
size = 30 16 32, scale = 0.05, origin = -y
material deform = 1, fade = true, lighting = smooth, roughness = 0.3, metalness = 0.6
  colors = A:#EEE B:#E00
voxels
36-18A12-18A398-7(26A4-)26A6-3(22A8-)22A126-6(6A14-6A4-)2(26A4-26A6-3(22A8-)22A126-6(4A18-4A4-))26A4-26A6-3(22A8-)22A124-6(4A5(22-8A)22-64A4-3(22A8-)22A12-14A16-14A68-)2(4A5(22-8A)22-64A4-3(22A8-)22A12-14A16-14A22-2A28-2A14-)4A5(22-8A)22-64A4-3(22A8-)22A12-14A16-14A68-4A5(22-8A)22-64A4-2(3(22A8-)22A12-14A16-14A70-6(4A18-4A4-)26A4-26A6-)2(3(22A8-)22A12-14A16-14A70-6(6A14-6A4-)26A4-26A6-)3(22A8-)22A12-14A16-14A72-2(6(6A10-6A8-)5(22A8-)22A128-)2(22A8-22A10-9(18A12-)18A130-)22A8-22A10-2(18A12-)6(2A14B2A12-)18A12-18A130-22A8-22A10-18A12-2A14B2A12-2A2BA2B3A2(BA)2B2(2A12-2A4(BA)2BA3B)2A12-2A6(BA)2B2A12-2A2(BA)B3A2(BA)2B2A12-2A14B2A2(12-18A)130-5(22A8-22A428-)22A8-22A429-20A10-20A425-
