model
size = 23 12 29, scale = 0.05, origin = -y
material deform = 1, fade = true, lighting = smooth, roughness = 0.3, metalness = 0.6
  colors = A:#111 B:#444 C:#222 D:#CB4042 E:#AB3B3A F:#C73E3A
voxels
6-2A3(FC)F2A12-2A7F2A12-3A5-3A12-4A3-4A14-3AC3A17-2AC2A151-2(3A2B5-2B3A8-)4AB5-B4A8-5AB3-B5A10-4A3B4A12-5AB5A15-2AC2A127-2(2A2B9-2B2A6-)3A11-3A6-3A11-3A8-A11-A10-2(A11-)5AB5A15-2AC2A103-2(CAB13-BAC4-)C2A13-2AC4-2CA13-A2C6-A13-A8-2A11-2(2A9-)2A12-4AB4A16-2AC2A80-2(A2B13-2BA4-)2AB13-B2A4-2AB13-B2A5-CB13-BC6-CBA11-ABC7-C2A9-2AC9-C5AB5AC12-4AC4A77-2(2AB15-B2A2-)2A17-2A3-A17-A4-A17-A5-2AB11-B2A6-2ABA9-AB2A2(7-4A)10-C4AB4AC15-2AC2A56-2(AB17-BA2-)A19-A2-A19-A3-A17-A4-A17-A5-3AB9-B3A6-3ABA7-AB3A8-6AB6A12-2(C3A)C53-2AB17-B4AB17-B2A-A19-A2-A19-A3-A17-A4-A17-A5-A15-A6-4AB7-B4A8-6AB3AB2A12-2(C3A)C53-AB19-B2AB19-B3A19-2A-A19-A2-2A17-2A3-A17-A4-2A15-2A5-3A11-3A8-3ABA3-AB3A12-AC2AB2ACA17-ACA33-AB19-B2AB19-B3A19-4A19-2A-2A17-2A2-2A17-2A3-2A15-2A4-4A11-4A6-5AB3-B5A10-3A2(BA)B3A15-2(CA)C32-AB19-B2AB19-B3A19-4A19-2A-2A17-2A2-2A17-2A3-2A15-2A4-4A11-4A6-4A7-4A10-4A3B4A14-7A18-FEF10-C3(B19-B2C)B19-BC-CB17-BC2-CB17-BC3-CB15-BC4-2C2B11-2B2C6-2C2B7-2B2C10-2C7B2C14-2C3A2C18-3E10-AB19-B2AB19-B3A19-4A19-2A-2A17-2A2-2A17-2A3-2A15-2A4-4A11-4A6-4A7-4A10-4A3B4A14-7A18-FEF10-2A2(B17-B4A)19-2A-A19-A2-2A17-2A3-A17-A4-2A15-2A5-3A11-3A2(7-4A)10-3A2(BA)B3A15-2(CA)C33-2(AB17-BA2-)A19-A2-A19-A3-A17-A4-A17-A5-A15-A6-3A11-3A8-3ABA3-AB3A12-AC2AB2ACA17-ACA34-2(2AB15-B2A2-)2A17-2A2-2A17-2A3-A16-2A4-A16-2A5-A15-A6-3A11-3A8-2A2(B3A)B2A12-2(C3A)C55-2(AB15-BA4-)A17-A4-A17-A5-A15-A6-A15-A7-2AB9-B2A8-ACBA7-ABCA10-C4AB4AC14-3AC3A56-C3B11-3BC4-CA2B11-2BA2(C4-C2AB11-B2A)C5-CAB11-BAC6-CAB11-BAC7-C2A9-2AC9-C2A7-2AC11-5AB5A14-3AC3A56-AED2B9-2BDEA4-3A2B9-2B3A5-3A11-3A6-3A11-3A7-2(2A11-2A8-)2(3A9-)6AB6A11-11A16-ACA58-A2(ED)9B2(DE)A4-AC3A9B3ACA6-7AB7A8-7AB7A9-2(6AB6A10-)6AB6A11-11A13-4AC4A78-A3(ED)E3D3(ED)EA4-2(AC)11A2(CA)8-3A2F2A3FA12-5A3(FA)12-3A2(FA)3FA12-2A3FAF4A12-2A3(FA)F2A13-A3F2A2FA15-7A79-A2(ED)E2D3E2D2(ED)EA4-3(AC)2A3C2A3(CA)234-A3(DE)5D3(ED)A4-2A2(CA)C5A2(CA)C2A235-A2(DE)D5E2(DE)DA6-2A2(CA)5C2(AC)2A236-A2DEDE5DEDE2DA6-3ACAC5ACAC3A237-A2DED5EDE2DA8-3ACA5CAC3A239-A2DE5DE2DA10-3AC5AC3A241-2AD5ED2A12-3A5C3A243-9A14-9A237-
