model
size = 30 14 12, scale = 0.05, origin = -y
material deform = 1, fade = true, lighting = smooth, roughness = 0.3, metalness = 0.6
  colors = A:#77969A B:#6699A1 C:#EEE D:#F75C2F E:#DDD F:#C7802D G:#E2943B H:#9B6E23 I:#EFBB24 J:#255359 K:#86A697 L:#D9AB42 M:#90B44B N:#B481BB O:#B1B479
voxels
34-10(EC)E8-11(CE)C7-11(CE)C8-19A12-2B9-4A112-I2(29-C)81-10(EC)E8-11(CE)C7-11(CE)C8-19A23-4A112-I2(29-C)109-E2C9(FG)F2CE5-EC21DCEC4-E23CEC5-20ALI8-4B-D4-8A12-2AB2(D-)D6-3B13-3A2(D-)D23-BA5D2B23-3(D-)B24-D-D26-D3-D-C29-C79-C4(GF)7HF2H2(GF)G2CE2-2C24DCE2-2C25AE3-22A4I4-B6A5B7A2BLI7-10A6B2A2B10-5AB9AB14-2B11AB16-3B2ABAB3AB19-4B2(AB)2A22-BA3B2A27-2BAC27-2A49-2C4(FG)6HFG2H3(FG)FC-2CD25BC-2CA25-C2-2A24-I3-BA21-3I4-2A17-AJBL7-2A15-2JC10-B14-2JC12-B9-4AJC24-2A2J26-KAJC26-KAJ27-KJ47-2C6(FG)2(2HFG)3(FG)CECD4BD2B2(DB)2(3DB)D2B3DBCECA26-CE2A25-AI-2B22-4I2-2A18-2AJLI5-BA16-3AC9-B14-3AC11-B9-K5AC13-B9-4AC25-K3A26-M2AC26-K2A27-2A17-C4(FG)F9H5(FG)ECD2(B2D)BD3B2(2D2B)D2B2(DB)DECA26-CEIA25-AI-IB22-4I2-IA18-2AJLI5-IA16-3AC8-IA14-3AC11-B9-O5AC13-B9-K3AC25-K3A26-K2AC26-K2A27-NA17-C4(GF)G9H5(GF)EC2(DB2DB)2(D3B)DBD2B3DBDECA26-CEIA25-AI-IB22-4I2-IA18-2AJLI5-IA16-3AC8-IA14-3AC11-B9-O5AC13-B9-K3AC25-K3A26-K2AC26-K2A27-NA17-2C6(GF)2(2HGF)3(GF)CECD4BD2B2(DB)2(3DB)2D2(BD)BCECA26-CE2A25-AI-2B22-4I2-2A18-2AJLI5-BA16-3AC9-B14-3AC11-B9-K5AC13-B9-4AC25-K3A26-M2AC26-K2A27-2A18-2C4(GF)6HGF2H3(GF)GC-2CD25BC-2CA25-C2-2A24-I3-BA21-3I4-2A17-AJBL7-2A15-2JC10-B14-2JC12-B9-4AJC24-2A2J26-KAJC26-KAJ27-KJ49-C4(FG)7HG2H2(FG)F2CE2-2C24DCE2-2C25AE3-22A4I4-B6A4B8A2BLI7-10A5B3A2B10-5A2B8AB14-2B11AB16-5B6AB19-7B2A23-6BA27-2BAC27-2A50-E2C9(GF)G2CE5-EC21DCEC4-E23CEC5-20ALI8-4B-D4-8A12-2AB2(D-)D6-3B13-3A2(D-)D23-BA5D2B23-3(D-)B24-D-D26-D3-D-C29-C77-
