model
size = 30 14 12, scale = 0.05, origin = -y
material deform = 1, fade = true, lighting = smooth, roughness = 0.3, metalness = 0.6
  colors = A:#A36336 B:#A7A7A7 C:#656765 D:#EEE E:#C7802D F:#E2943B G:#E83015 H:#535953
voxels
34-21B8-23B7-23D8-19A12-2B9-4A112-G2(29-D)81-21B8-23B7-23D8-19A12-2B9-4A112-G2(29-D)109-3B9(EF)E3B5-BD21BD2B4-26D5-22A8-6B4-2AB4AG12-2A2HAHB7-3H13-4A2-HB23-HA4-H2B29-C59-D29-D79-B11(FE)F3B2-BD24BDB2-2D25AD3-26A4-4B3A5C7A4B7-10AH3CBC2ABC10-15AB14-HC3A2G6AC16-4CH6AB19-6CH3A22-5CHA27-2CAD27-2A49-2B12(EF)EB-BDB25CB-2DA25-D2-2A24-A3-2B21-A2B4-2A17-2A2C7-2A15-2BD10-C14-2AD12-H9-5AD24-4A26-3AD26-3A27-2A47-2B13(EF)4B4CG2C2(GC)2(3GC)G2C3GCDBDA26-2D2A25-2A-2B22-3AB2-2A18-4AC5-HA16-3AD9-C14-3AD11-C9-6AD13-H9-4AD25-4A26-3AD26-3A27-2A17-B14(EF)3B2(C2G)CG3C2(2G2C)G2C2(GC)2BDA26-2DGA25-2A-2B22-3AB2-2A18-4AC5-2A16-3AD8-HA14-3AD11-C9-6AD13-C9-4AD25-4A26-D2AD26-D2A27-2A17-B14(FE)3B2(C2GCG)2(3CG)CG2C3GC2BDA26-2DGA25-2A-2B22-3AB2-2A18-4AC5-2A16-3AD8-HA14-3AD11-C9-6AD13-C9-4AD25-4A26-D2AD26-D2A27-2A17-2B13(FE)4B4CG2C2(GC)2(3GC)2G2(CG)CDBDA26-2D2A25-2A-2B22-3AB2-2A18-4AC5-HA16-3AD9-C14-3AD11-C9-6AD13-H9-4AD25-4A26-3AD26-3A27-2A18-2B12(FE)FB-BDB25CB-2DA25-D2-2A24-A3-2B21-A2B4-2A17-2A2C7-2A15-2BD10-C14-2AD12-H9-5AD24-4A26-3AD26-3A27-2A49-B11(EF)E3B2-BD24BDB2-2D25AD3-26A4-5B2A4C8A4B7-10AH3CB3ABC10-15AB14-HC3A2G6AC16-4CH6AB19-6CH2A23-5CHA27-2CAD27-2A50-3B9(FE)F3B5-BD21BD2B4-26D5-22A8-6B4-2AB4AG12-2A2HAHB7-3H13-4A2-HB23-HA4-H2B29-C59-D29-D77-
