model
size = 23 12 29, scale = 0.05, origin = -y
material deform = 1, fade = true, lighting = smooth, roughness = 0.3, metalness = 0.6
  colors = A:#0A795B B:#444 C:#CB3C3C D:#CB603C E:#945F41 F:#A53131 G:#FFD24D
voxels
6-2A3(CF)C2A12-2A7C2A12-3A5-3A12-4A3-4A14-7A17-5A151-2(3A2B5-2B3A8-)4AB5-B4A8-5AB3-B5A10-4A3B4A12-5AB5A15-5A127-2(2A2B9-2B2A6-)3A11-3A6-3A11-3A8-A11-A10-2(A11-)5AB5A15-5A103-2(2AB13-B2A4-)3A13-3A4-3A13-3A6-A13-A8-2A11-2(2A9-)2A12-4AB4A16-5A80-2(A2B13-2BA4-)2AB13-B2A4-2AB13-B2A5-AB13-BA6-ABA11-ABA7-2(3A9-)6AB6A12-9A77-2(2AB15-B2A2-)2A17-2A3-A17-A4-A17-A5-2AB11-B2A6-2ABA9-AB2A2(7-4A)10-5AB5A15-5A56-2(AB17-BA2-)A19-A2-A19-A3-A17-A4-A17-A5-3AB9-B3A6-3ABA7-AB3A8-6AB6A12-9A53-2AB17-B4AB17-B2A-A19-A2-A19-A3-A17-A4-A17-A5-A15-A6-4AB7-B4A8-6AB3AB2A12-9A53-AB19-B2AB19-B3A19-2A-A19-A2-2A17-2A3-A17-A4-2A15-2A5-3A11-3A8-3ABA3-AB3A12-4AB4A17-3A33-AB19-B2AB19-B3A19-4A19-2A-2A17-2A2-2A17-2A3-2A15-2A4-4A11-4A6-5AB3-B5A10-3A2(BA)B3A15-5A32-AB19-B2AB19-B3A19-4A19-2A-2A17-2A2-2A17-2A3-2A15-2A4-4A11-4A6-4A7-4A10-4A3B4A14-7A18-3C10-A3(B19-B2A)B19-BA-AB17-BA2-AB17-BA3-AB15-BA4-2A2B11-2B2A6-2A2B7-2B2A10-2A7B2A14-3AC3A18-3C10-AB19-B2AB19-B3A19-4A19-2A-2A17-2A2-2A17-2A3-2A15-2A4-4A11-4A6-4A7-4A10-4A3B4A14-7A18-3C10-2A2(B17-B4A)19-2A-A19-A2-2A17-2A3-A17-A4-2A15-2A5-3A11-3A2(7-4A)10-3A2(BA)B3A15-5A33-2(AB17-BA2-)A19-A2-A19-A3-A17-A4-A17-A5-A15-A6-3A11-3A8-3ABA3-AB3A12-4AB4A17-3A34-2(2AB15-B2A2-)2A17-2A2-2A17-2A3-2A15-2A4-2A15-2A5-A15-A6-3A11-3A8-2A2(B3A)B2A12-9A55-2(AB15-BA4-)A17-A4-A17-A5-A15-A6-A15-A7-2AB9-B2A8-2ABA7-AB2A10-5AB5A14-7A56-A3B11-3BA4-2A2B11-2B2A2(4-3AB11-B3A)5-2AB11-B2A6-2AB11-B2A7-2(3A9-)3A7-3A11-5AB5A14-7A56-CED2B9-2BDEC4-C2A2B9-2B2AC5-3A11-3A6-3A11-3A7-2(2A11-2A8-)2(3A9-)6AB6A11-11A16-3A58-C2(ED)9B2(DE)C4-CF3A9B3AFC6-7AB7A8-7AB7A9-2(6AB6A10-)6AB6A11-11A13-9A78-C3(ED)E3D3(ED)EC4-2(CF)C9A2(CF)C8-4(11A12-)11A13-9A15-7A79-C2(ED)E2D3E2D2(ED)EC4-3(CF)2C3F2C3(FC)9-3G2(-G)15-G2-2(G-)G16-3G-G-3G16-G3-G2-G15-2(G-)3G124-C3(DE)5D3(ED)C4-2C2(FC)F5C2(FC)F2C235-C2(DE)D5E2(DE)DC6-2C2(FC)5F2(CF)2C236-C2DEDE5DEDE2DC6-3CFCF5CFCF3C237-C2DED5EDE2DC8-3CFC5FCF3C239-C2DE5DE2DC10-3CF5CF3C241-2CD5ED2C12-3C5F3C243-9C14-9C237-
