model
size = 23 12 29, scale = 0.05, origin = -y
material deform = 1, fade = true, lighting = smooth, roughness = 0.3, metalness = 0.6
  colors = A:#222 B:#444 C:#EEE D:#E83015 E:#1B813E F:#2D6D4B G:#D75455
voxels
6-2A3(DG)D2A12-2A7D2A12-3A5-3A12-4A3-4A14-7A17-5A151-2(3A2B5-2B3A8-)4AB5-B4A8-5AB3-B5A10-4A3B4A12-5AB5A15-5A127-2(2A2B9-2B2A6-)3A11-3A6-3A11-3A8-A11-A10-2(A11-)5AB5A15-5A103-2(2AB13-B2A4-)3A13-3A4-3A13-3A6-A13-A8-2A11-2(2A9-)2A12-4AB4A16-5A80-2(A2B13-2BA4-)2AB13-B2A4-2AB13-B2A5-AB13-BA6-ABA11-ABA7-2(3A9-)6AB6A12-9A77-2(2AB15-B2A2-)2A17-2A3-A17-A4-A17-A5-2AB11-B2A6-2ABA9-AB2A2(7-4A)10-5AB5A15-5A56-2(AB17-BA2-)A19-A2-A19-A3-A17-A4-A17-A5-3AB9-B3A6-3ABA7-AB3A8-6AB6A12-9A53-2AB17-B4AB17-B2A-A19-A2-A19-A3-A17-A4-A17-A5-A15-A6-4AB7-B4A8-6AB3AB2A12-9A53-AB19-B2AB19-B3A19-2A-A19-A2-2A17-2A3-A17-A4-2A15-2A5-3A11-3A8-3ABA3-AB3A12-4AB4A17-3A33-AB19-B2AB19-B3A19-4A19-2A-2A17-2A2-2A17-2A3-2A15-2A4-4A11-4A6-5AB3-B5A10-3A2(BA)B3A15-5A32-AB19-B2AB19-B3A19-4A19-2A-2A17-2A2-2A17-2A3-2A15-2A4-4A11-4A6-4A7-4A10-4A3B4A14-7A18-3D10-A3(B19-B2A)B19-BA-AB17-BA2-AB17-BA3-AB15-BA4-2A2B11-2B2A6-2A2B7-2B2A10-2A7B2A14-3AD3A18-3D10-AB19-B2AB19-B3A19-4A19-2A-2A17-2A2-2A17-2A3-2A15-2A4-4A11-4A6-4A7-4A10-4A3B4A14-7A18-3D10-2A2(B17-B4A)19-2A-A19-A2-2A17-2A3-A17-A4-2A15-2A5-3A11-3A2(7-4A)10-3A2(BA)B3A15-A3CA33-2(AB17-BA2-)A19-A2-A19-A3-A17-A4-A17-A5-A15-A6-3A11-3A8-3ABA3-AB3A12-2ACABAC2A17-3C34-2(2AB15-B2A2-)2A17-2A2-2A17-2A3-2A15-2A4-2A15-2A5-A15-A6-3A11-3A8-2A2(B3A)B2A12-A7CA55-2(AB15-BA4-)A17-A4-A17-A5-A15-A6-A15-A7-2AB9-B2A8-ACBA7-ABCA10-2C3AB3A2C14-7C56-A3B11-3BA4-2A2B11-2B2A2(4-3AB11-B3A)5-CAB11-BAC6-CAB11-BAC7-C2A9-2AC9-C2A7-2AC11-2C3AB3A2C14-7C56-DFE2B9-2BEFD4-D2A2B9-2B2AD5-C2A11-2AC6-C2A11-2AC7-2(CA11-AC8-)C2A9-2AC9-C5AB5AC11-4C3A4C16-3C58-D2(FE)9B2(EF)D4-DG3A9B3AGD6-2C5AB5A2C8-2C5AB5A2C9-2(C5AB5AC10-)C5AB5AC11-C8A2C13-9C78-D3(FE)F3E3(FE)FD4-2(DG)D9A2(DG)D8-4(11C12-)11C13-9C15-7C79-D2(FE)F2E3F2E2(FE)FD4-3(DG)2D3G2D3(GD)31-A-A3D2A-2D12-3AD-DA-AD13-A-A3DA-AD13-A-A3-2A-D15-A108-D3(EF)5E3(FE)D4-2D2(GD)G5D2(GD)G2D235-D2(EF)E5F2(EF)ED6-2D2(GD)5G2(DG)2D236-D2EFEF5EFEF2ED6-3DGDG5DGDG3D237-D2EFE5FEF2ED8-3DGD5GDG3D239-D2EF5EF2ED10-3DG5DG3D241-2DE5FE2D12-3D5G3D243-9D14-9D237-
