model
size = 29 12 29, scale = 0.05, origin = -y
material deform = 1, fade = true, lighting = smooth, roughness = 0.3, metalness = 0.6
  colors = A:#FF0 B:#E00 C:#0E0 D:#06C E:#111 F:#EEE G:#777
voxels
75-F340-7A2B339-7A2B335-F3A9-3B17-7A2B20-7A2B275-2(3D15-3B11-D2A9-3B14-D2A9-3B17-7A2B246-)D18-2BF8-2D15-B11-2D15-B13-3D9-3B17-7A2B20-7A2B186-2D21-C7-D18-2B8-D18-2B9-3D12-3B14-2D9-B17-2D9-B19-D6A2B157-2D21-C7-D18-2B8-D18-2B9-3D12-3B14-2D9-B17-2D9-B19-D6A2B108-6E23-6E13-F2C21-C7-D18-2C8-D18-2C9-2D-G10-G2-B13-DG10-G2B14-DG10-G2B15-3D6A3B106-E6-2E20-E6-2E11-C24-2C3-2C21-C5-2C4-G10-G5-C7-C18-2C9-2D15-C11-2D15-C13-4D6-5B18-2D3AB23-2D3AB51-E7-EG18-GE7-EG10-C7-G9-G6-2C3-2C5-G9-G5-C5-2C5-G15-C7-C18-2C9-2D15-C11-2D15-C13-4D6-5B18-2D3AB23-2D3AB49-2E9-E17-2E9-E10-C24-2C3-2C21-C5-2C21-C7-C18-2C9-2C15-C11-2C15-C13-3C9-3C17-3D3A3B20-3D3A3B47-3(E10-E17-2(E10-)C24-2C3-2C21-C5-2C21-C7-C18-2C9-2C15-C11-2C15-C13-3C9-3C17-3C3F3C20-3C3F3C23-3F21-)E10-E17-2(E10-)C24-2DF2-2C21-D5-2C21-D7-C18-2D9-2C15-D11-2C15-D13-3C9-3D17-3B3A3D20-3B3A3D47-2E9-E17-2E9-E10-C24-2D3-2C21-D5-2C21-D7-C18-2D9-2C15-D11-2C15-D13-3C9-3D17-3B3A3D20-3B3A3D48-GE6-2EG18-GE6-2EG9-FB7-G9-G6-2D3-2B5-G9-G5-D5-2B5-G9-G5-D7-B18-2D9-2B15-D11-2B15-D13-4B6-5D18-2B3AD23-2B3AD52-6E23-6E14-2B21-D7-B18-2D8-B18-2D9-2B2-G9-G2-D13-B12-2D14-B12-2D15-3B6A3D156-2B21-D7-B18-2D8-B18-2D9-2B15-D13-B2G9-G2D14-B2G9-G2D15-3B6A3D156-2B21-D7-B18-2D8-B18-2D9-3B12-3D14-2B9-D17-2B9-D19-B6A2D159-2(B18-2D9-2B15-D11-2B15-D13-3B9-3D17-B8A20-B8A188-)3B15-3D11-3B9-A2D14-3B9-A2D17-B8A249-3B9-3AF16-B8A20-B8A278-3B9-3A17-B8A20-B8A281-B8A339-F279-
