model
size = 23 12 29, scale = 0.05, origin = -y
material deform = 1, fade = true, lighting = smooth, roughness = 0.3, metalness = 0.6
  colors = A:#405B55 B:#444 C:#562E37 D:#888 E:#777 F:#91989F G:#60373E
voxels
6-2(2A7C2A12-)3A5-3A12-4A3-4A14-7A17-5A151-2(3A2B5-2B3A8-)4AB5-B4A8-5AB3-B5A10-4A3B4A12-5AB5A15-5A127-2(2A2B9-2B2A6-)3A11-3A6-3A11-3A8-A11-A10-2(A11-)5AB5A15-5A103-2(2AB13-B2A4-)3A13-3A4-3A13-3A6-A13-A8-2A11-2(2A9-)2A12-4AB4A16-5A80-2(A2B13-2BA4-)2AB13-B2A4-2AB13-B2A5-AB13-BA6-ABA11-ABA7-2(3A9-)6AB6A12-9A77-2(2AB15-B2A2-)2A17-2A3-A17-A4-A17-A5-2AB11-B2A6-2ABA9-AB2A2(7-4A)10-5AB5A15-5A56-2(AB17-BA2-)A19-A2-A19-A3-A17-A4-A17-A5-3AB9-B3A6-3ABA7-AB3A8-6AB6A12-9A53-2AB17-B4AB17-B2A-A19-A2-A19-A3-A17-A4-A17-A5-A15-A6-4AB7-B4A8-6AB3AB2A12-9A53-AB19-B2AB19-B3A19-2A-A19-A2-2A17-2A3-A17-A4-2A15-2A5-3A11-3A8-3ABA3-AB3A12-4AB4A17-3A33-AB19-B2AB19-B3A19-4A19-2A-2A17-2A2-2A17-2A3-2A15-2A4-4A11-4A6-5AB3-B5A10-3A2(BA)B3A15-5A32-AB19-B2AB19-B3A19-4A19-2A-2A17-2A2-2A17-2A3-2A15-2A4-4A11-4A6-4A7-4A10-4A3B4A14-7A18-3C10-A3(B19-B2A)B19-BA-AB17-BA2-AB17-BA3-AB15-BA4-2A2B11-2B2A6-2A2B7-2B2A10-2A7B2A14-3AC3A18-3C10-AB19-B2AB19-B3A19-4A19-2A-2A17-2A2-2A17-2A3-2A15-2A4-4A11-4A6-4A7-4A10-4A3B4A14-7A18-3C10-2A2(B17-B4A)19-2A-A19-A2-2A17-2A3-A17-A4-2A15-2A5-3A11-3A2(7-4A)10-3A2(BA)B3A15-5A33-2(AB17-BA2-)A19-A2-A19-A3-A17-A4-A17-A5-A15-A6-3A11-3A8-3AB5-B3A12-4AB4A17-3A34-2(2AB15-B2A2-)2A17-2A2-2A17-2A3-2A15-2A4-2A15-2A5-A15-A6-3A11-3A8-2A2(B3A)B2A12-9A55-2(AB15-BA4-)A17-A4-A17-A5-A15-A6-A15-A7-2AB9-B2A8-2AB9-B2A10-5AB5A14-7A56-A3B11-3BA4-2A2B11-2B2A2(4-3AB11-B3A)6-AB11-BA8-AB11-BA2(9-2A)10-2A9-2A12-4AB4A17-3A58-CED2B9-2BDEC4-C2A2B9-2B2AC5-3A11-3A6-3A11-3A8-2(A11-A10-)2A9-2A11-5AB5A14-7A79-C2(ED)9B2(DE)C4-CG3A9B3AGC6-3A4-B4-3A8-3A4-B4-3A9-2A4-B4-2A10-2A4-B4-2A11-A4-B4-A13-9A16-5A80-C3(ED)E3D3(ED)EC4-2(CG)C9A2(CG)C9-2A2(FA)F2A14-2A5F2A14-A7FA14-A2(F2A)FA14-A7FA15-7A102-C2(ED)E2D3E2D2(ED)EC4-3(CG)7C3(GC)11-2(F-)F18-5F17-7F16-2(F2-)F16-7F125-C3(DE)5D3(ED)C4-2C2(GC)G5C2(GC)G2C235-C2(DE)D5E2(DE)DC6-2C2(GC)5G2(CG)2C236-C2DEDE5DEDE2DC6-3CGCG5CGCG3C237-C2DED5EDE2DC8-3CGC5GCG3C239-C2DE5DE2DC10-3CG5CG3C241-2CD5ED2C12-3C5G3C243-9C14-9C237-
