model
size = 26 20 30, scale = 0.05, origin = -y
material deform = 1, fade = true, lighting = smooth, roughness = 0.3, metalness = 0.6
  colors = A:#CC0 B:#888 C:#444 D:#CC9 E:#111 F:#EEE G:#555
voxels
348-6C20-6B20-6C20-6B410-6C20-6B20-6C20-6B384-6C2(20-6B)72-6B20-6C20-6B20-B4-B254-6C2(20-6B)178-2D22-2A2E2A20-BA2-AB176-6C2(20-6B)228-D4AD18-10A17-A6BA123-6C2(20-6B)278-D8AD14-14A17-A2-A73-6C2(20-6B)328-D12AD11-16A10-A-A2-A-2A-A2-A-A41-6B20-6B379-D14AD9-18A8-2(A-)2A6-2A2(-A)40-6B404-D16AD7-20A6-3(A-)3(2A-)2(A-)A13-6C20-6B402-AD18ADA4-22A4-4(A-)D-2A-D4(-A)12-6B428-D20AD3-24A3-2A2(-A)2-D4-D2-2(A-)2A12-6B428-D20AD3-24A3-A9-2A9-A12-6B427-D22AD2-24A2(2-A)2-F10-F2(2-A)11-6B427-D22AD-26A3-A3-12F3-A13-6E426-D24AD27A-A4-F10-F4-A-A10-2E2G2E426-D24ADE24AE4-4F2(-A)FG2(A-)4F14-2E2G2E426-D24ADE2A4E2(AE)14AE3-9EGF2(A-)F17-6E426-D24AD14AE12A-A4-F6-E3-F4-A-A10-6B427-D22AD-26A3-A4F2-A-2D-E2-4FA13-6B427-D22AD2-15AE8A2(2-A)2-F4-2F2-E-F2(2-A)11-6B428-D20AD3-24A3-A5-F3-2F3-E5-A12-6B428-D20AD3-24A3-2A2(-A)-3F2-3F-E-A-2A12-6C20-6B402-AD18ADA4-22A4-4(A-)D-2A-D-A-E2(-A)38-6B404-D16AD7-20A6-3(A-)3(2A-)A-E-A39-6B20-6B379-D14AD9-18A8-2(A-)2A6-2A2(-A)66-6C2(20-6B)328-D12AD11-16A10-A-A2-A-2A-A2-A-A119-6C2(20-6B)278-D8AD14-14A17-A2-A177-6C2(20-6B)228-D4AD18-10A17-A6BA227-6C2(20-6B)178-2D22-2A2E2A20-BA2-AB280-6C2(20-6B)72-6B20-6C20-6B20-B4-B36-
