model
size = 25 30 26, scale = 0.05, origin = -y
material deform = 1, fade = true, lighting = smooth, roughness = 0.3, metalness = 0.6
  colors = A:#050 B:#070 C:#EEE D:#777 E:#080 F:#C03 G:#001 H:#555 I:#FC0 J:#444 K:#F9F L:#E00
voxels
402-D665-A23-E2A2(22-3A)648-3A22-3A2(20-5A)20-E3A22-3A623-3A21-4A3(20-5A)21-3A22-3A423-3A18-8A16-B9A15-10A14-B11A4(13-12A)3(13-8A-3A)6(13-12A)15-9A17-8A17-7A19-5A199-A16-10A13-13A11-15A10-3AB11A10-2AB12A13(10-15A)10-B14A11-13A15-9A17-7A19-5A172-5A15-11A11-E2A-11A6(10-15A)10-E14A7(10-15A)9-J3(15A10-)14A11-B13A12-13A15-9A17-7A144-6A-A11-E-13A6(10-15A)2(10-K14A)2(10-15A)2(9-C15A)2(9-F15A)2(10-15A)9-J4(15A10-)B14A12-12A15-9A19-3A119-8A13-13A-A2(10-15A)10-G14A10-4(16A9-)K15A9-16A8-C16A8-G2(16A8-C)2(16A8-F)16A9-16A8-J3(16A9-)15A10-15A11-14A13-11A16-6A51-4A21-4A17-2A2-4A12-13A4(9-16A)9-G15A6(9-16A)2(8-C16A)2(8-F16A)2(9-16A)8-J4(16A9-)15A10-15A12-13A14-3AB5A48-5A20-5A14-11A12-13A4(9-16A)9-G15A2(9-16A)8-G15(16A9-)15A12-13A13-10A18-5A26-4A21-4A14-11A12-13A4(9-16A)9-G15A3(9-16A)8-G14(16A9-)15A12-13A13-B9A18-5A25-5A20-5A14-11A12-13A4(9-16A)9-G15A2(9-16A)8-G15(16A9-)15A12-B12A13-10A18-3ABA26-4A21-3AB17-2A2-2ABA12-13A9-E15A3(9-16A)2-L6C6(16A9-)2(16A8-C)2(16A8-F)2(16A9-)16A8-J4(16A9-)15A10-15A12-13A14-5AB3A116-8A13-E12A-A3(10-15A)10-G15A3(9-16A)9-K15A9-16A8-C16A8-G2(16A8-C)2(16A8-F)16A9-16A8-J3(16A9-)2(15A10-)B14A13-AB9A16-6A120-6A-A11-E-E12A6(10-15A)2(10-K14A)2(10-15A)2(9-C15A)2(9-F15A)2(10-15A)9-J4(15A10-)B14A13-11A15-B8A19-2AB123-5A15-E10A11-E2A-11A6(10-15A)10-E14A7(10-15A)9-J3(15A10-)14A11-14A12-13A15-9A17-7A149-A16-10A13-13A11-E14A10-AB13A10-2(15A2-D7-)12(15A10-)15A11-13A15-B8A17-7A19-2AB2A198-3A18-4A2B2A16-5AB4A15-B9A14-2B10A2-D10-4(12A13-)2(8A-3A13-)8A-2AB5(13-12A)13-10A2B15-2AB6A17-8A17-AB3ABA19-5A355-H40-4A21-4A3(20-5A)21-3A6-2D14-3A573-I7-H15-I3A22-3A20-E4A20-5A20-4A22-3A82-D514-3I22-IAI5-D16-IAI5-H16-3A5-D16-3A22-2AB22-A2B7-2D47-2CD23-2D23-H522-H124-C2D49-DH48-H647-2DH748-HD1072-
