model
size = 4 32 32, scale = 0.05, origin = -y
material deform = 1, fade = true, lighting = smooth, roughness = 0.3, metalness = 0.6
  colors = A:#000
voxels
52-32A92-32A84-56A65-2A-64A-2A53-24A-6(2A2-)2A-28A44-20A-2A2-2A30-2A2-2A-24A36-16A-2A2-2A46-2A2-2A-20A28-16A-2A62-2A-20A21-2A-12A-2A70-2A-16A-2A17-12A-2A78-2A-16A12-16A-2A78-2A-20A2(8-12A-2A86-2A-16A)4-12A3(-2A94-2A-28A)2(-2A94-2A5-24A)2(-2A94-2A-28A)-2A94-2A-16A4-2(12A-2A86-2A-16A8-)16A-2A78-2A-20A12-12A-2A78-2A-16A17-2A-12A-2A70-2A-16A-2A21-16A-2A62-2A-20A28-16A-2A2-2A46-2A2-2A-20A36-20A-2A2-2A30-2A2-2A-24A44-24A-6(2A2-)2A-28A53-2A-64A-2A65-56A36-
