model
size = 23 30 29, scale = 0.05, origin = -y
material deform = 1, fade = true, lighting = smooth, roughness = 0.3, metalness = 0.6
  colors = A:#EBB471 B:#444 C:#BC9F77 D:#6E552F E:#AA8F6B F:#888 G:#777 H:#855B32 I:#FFFFFB J:#E83015
voxels
329-9A13-5(11A12-)11A13-9A15-7A17-5A404-A13-A8-2A11-2A8-3A9-3A8-15A8-2A2(3CE)3C2A8-2A5(EC)E2A8-2AC2(E3C)EC2A2(8-3A9B3A)8-7AB7A9-6AB6A11-5AB5A12-5AB5A15-5A357-2(2A13-2A6-)AE13-2A6-AC13-CA6-AE13-EA6-ACE11-ECA6-AEC11-CEA6-A2C11-2CA2(6-2A2B9-2B2A)6-3A11-3A7-2A11-2A9-A11-A10-2(A11-)5AB5A15-5A310-A17-A4-2A15-2A4-AE15-2A4-AC15-CA4-AE15-E3(A4-AC15-C)A4-AE15-EA2(4-2AB13-B2A)4-3A13-3A5-2A13-2A7-A13-A8-2A11-2(2A9-)2A12-4AB4A16-5A264-3(A17-A4-)AC16-3(A4-AE15-EA4-AC15-C)2(A4-A2B13-2B)A2(4-2AB13-B2A)5-AB13-BA6-ABA11-ABA7-2(3A9-)6AB6A12-9A262-A17-2A2-AE17-CA2-AC17-CA2-AE17-E3(A2-AC17-C)A2-AE17-E2(A2-AC17-C)A2(2-2AB15-B2A)2-2A17-2A3-A17-A4-A17-A5-2AB11-B2A6-2ABA9-AB2A2(7-4A)10-5AB5A15-5A240-A19-4(A2-AC17-CA2-AE17-E)A2-AC17-C2(A2-AB17-B)2(A2-A19-)A3-A17-A4-A17-A5-3AB9-B3A6-3ABA7-AB3A8-6AB6A12-9A237-2A19-3A2(E19-E3(2AC19-C)2A)E19-E3AB17-B4AB17-B2A-A19-A2-A19-A3-A17-A4-A17-A5-A15-A6-4AB7-B4A8-6AB3AB2A12-9A214-2A19-3A5(E19-E2AC19-C2A)B19-B2AB19-B3A19-2A-A19-A2-2A17-2A3-A17-A4-2A15-2A5-3A11-3A8-3ABA3-AB3A12-4AB4A17-3A171-A21-3A19-3A3(C19-C2A)E19-E3(2AC19-C)2AE19-E2(2AC19-C)2(2AB19-B)3A19-4A19-2A-2A17-2A2-2A17-2A3-2A15-2A4-4A11-4A6-5AB3-B5A10-3A2(BA)B3A15-5A32-D7(21-2D)A19-ADA5(E19-E2AC19-C2A)B19-B2AB19-B3A19-4A19-2A-2A17-2A2-2A17-2A3-2A15-2A4-4A11-4A6-4A7-4A10-4A3B4A14-7A18-3D10-D7(21-2D)A19-ADAC19-C2(2AE19-E3(2AC19-C))2AE19-E4(2AB19-B)A-AB17-BA2-AB17-BA3-AB15-BA4-2A2B11-2B2A6-2A2B7-2B2A10-2A7B2A14-3AD3A18-3D148-A21-3A19-3A4(E19-E2AC19-C2A)E19-C2AC19-C2(2AB19-B)3A19-4A19-2A-2A17-2A2-2A17-2A3-2A15-2A4-4A11-4A6-4A7-4A10-4A3B4A14-7A18-3D171-2A19-3A3(C19-C2A)E19-E3(2AC19-C)2AE19-E2(2AC19-C)3A2(B17-B4A)19-2A-A19-A2-2A17-2A3-A17-A4-2A15-2A5-3A11-3A2(7-4A)10-3A2(BA)B3A15-5A193-2A21-AE19-3A2(C19-C2AE19-E2A)C19-C2AE19-C2AC19-C2AE19-E2AC19-C3AB17-B2A-AB17-B2(A2-A19-)A3-A17-A4-A17-A5-A15-A6-3A11-3A8-3AB5-B3A12-4AB4A17-3A218-2A17-2A2(2-AE17-E3(A2-AC17-C)A)2-AE17-EA2(2-2AB15-B2A)2(2-2A17-2A)3-2A15-2A4-2A15-2A5-A15-A6-3A11-3A8-2A2(B3A)B2A12-9A262-9(A17-A4-)2(AB15-BA4-)2(A17-A4-)2A15-2A5-A15-A7-2AB9-B2A8-2AB9-B2A10-5AB5A14-7A355-5(A17-A4-)A3B11-3BA4-2A2B11-2B2A2(4-3AB11-B3A)5-2AB11-B2A7-AB11-BA2(9-2A)10-2A9-2A12-4AB4A17-3A472-DGF2B9-2BFGD4-D2A2B9-2B2AD5-3A11-3A6-3A11-3A7-2A11-2A9-A11-A10-2A9-2A11-5AB5A13-9A492-D2(GF)9B2(FG)D4-DH3A9B3AHD6-3A4-B4-3A8-3A4-B4-3A9-2(2A4-B4-2A10-)2A4-B4-2A11-11A14-7A493-D3(GF)G3F3(GF)GD4-2(DH)D9A2(DH)D8-3(11A12-)11A13-9A14-9A515-D2(GF)G2F3G2F2(GF)GD4-3(DH)7D3(HD)10-3I-3I16-IJI-IJI16-7B15-B7-B561-D3(FG)5F3(GF)D4-2D2(HD)H5D2(HD)H2D649-D2(FG)F5G2(FG)FD6-2D2(HD)5H2(DH)2D650-D2FGFG5FGFG2FD6-3DHDH5DHDH3D651-D2FGF5GFG2FD8-3DHD5HDH3D653-D2FG5FG2FD10-3DH5DH3D655-2DF5GF2D12-3D5H3D657-9D14-9D237-
