model
size = 32, scale = 0.05, origin = -y
material deform = 1, fade = true, lighting = smooth, roughness = 0.3, metalness = 0.6
  colors = A:#D00 B:#003 C:#EEE D:#888 E:#E00
voxels
40-5A6B5A16-4AB6CB4A16-3ABCAC2ACACB3A16-3AB8AB3A16-2AB10AB2A16-AB12ABA16-BA4(C2A)CB16-B14CB16-16B119-2B28-6B22-2(14B18-)B2C8B2CB2(18-2C10B2C)23-4B764-4A27-6A25-3(8A24-)8A25-6A27-4A568-8(12A20-)12A19-3(14A18-)14A19-12A20-12A21-10A23-8A26-4A374-12(16A16-)16A15-18A14-18A15-2(16A16-)16A17-14A18-14A19-12A22-8A27-2A310-10(18A14-)4A12-2A13-4(5A12-3A12-)20A12-20A13-18A14-18A15-16A16-16A17-14A20-10A24-6A275-AE16-6(2A12-A17-)2(2A12-2A16-)2A12-3A15-2A11-4A15-3A2(10-4A14-4A)10-5A13-4A10-6A12-4A3(10-22A)11-20A12-20A13-18A15-16A17-14A19-12A22-8A241-2AE17-2A10-2A18-2A10-2A17-3A2(10-2A19-A)10-2A18-2A3(10-2A17-3A)9-2(5A15-4A8-)2(5A14-5A8-)6A13-5A8-7A12-5A3(8-24A)9-22A10-22A11-20A13-18A14-18A16-14A19-12A22-8A208-A3E18-2(2A8-AE20-)2A8-2A20-2A8-3A19-2A5(8-3A18-3A)8-4A16-4A7-5A16-5A6-6A14-6A6-7A13-6A6-8A12-6A2(6-26A)7-2(24A8-)24A9-22A11-20A12-20A13-18A16-14A19-12A23-6A176-A4E18-3A6-A2E20-3A6-2AE2(20-3A6-3A)20-3A5(6-4A18-4A)2(6-4A17-5A)6-6A15-5A5-8A13-7A4-9A12-7A5-3(26A6-)26A7-24A8-24A9-22A10-22A11-20A13-18A16-14A20-10A26-2A146-EA3E18-3A5-2(3A21-4A4-)2(4A20-4A4-)5(5A18-5A4-)3(5A17-6A4-)8A13-7A4-9A12-7A3(4-28A)5-2(26A6-)26A7-24A9-22A11-20A13-18A15-16A17-14A21-8A143-2A21-3A5-2(3A21-4A4-)2(4A20-4A4-)5(4A19-5A4-)4A18-6A4-4A18-6A3-2(5A18-7A2-)10A12-8A2-30A3-3(28A4-)28A5-26A6-26A7-24A9-22A11-20A13-18A15-16A18-12A24-4A113-2A21-3A5-2(3A21-4A4-)2(4A20-4A4-)4(4A19-5A4-)4A19-5A3-5A18-7A3(2-5A19-6A)2-10A12-8A3(2-30A)3-2(28A4-)28A5-26A7-24A8-24A9-22A11-20A14-16A17-14A21-8A111-2A21-3A5-2(3A21-5A3-)2(4A20-5A3-)4(4A19-6A3-)4A19-6A2-5A18-7A3(2-5A19-6A)2-6A17-7A4(2-30A)3-28A4-28A5-26A6-26A7-24A9-22A11-20A13-18A16-14A20-10A110-2A21-3A4-2(4A21-5A2-)2(5A20-5A2-)6(5A19-6A2-)5A19-6A-6A19-13A19-14A18-15A17-7A-3(30A2-)30A3-28A4-28A5-26A7-24A8-24A9-22A12-18A15-16A18-12A24-4A81-2A21-3A4-2(4A21-5A2-)2(5A20-5A2-)5(5A19-6A2-)5A19-6A-6A2(19-6A2C5A)19-6A2C6A18-6A2C7A17-6A2C30AC-2(30A2-)30A3-28A4-28A5-26A6-26A7-24A9-22A11-20A14-16A18-12A23-6A80-2A21-3A4-2(4A21-5A2-)2(5A20-5A2-)4(5A19-6A2-)5A19-6A-6A2(19-13A)19-6AC6A19-14A18-15A17-7AC7A14-42A-2(30A2-)30A3-28A5-26A6-26A7-24A9-22A11-20A14-16A17-14A21-8A79-2A21-3A4-2(4A21-5A2-)2(5A20-5A2-)4(5A19-6A2-)5A19-6A-6A3(19-13A)19-6A2C6A18-7AC7A17-15A14-42A3(-30AB)2(2-28A-B)3-26A2-B4-24A3-B5-22A4-B6-20A5-B7-18A6-B9-14A8-B12-8A11-C67-2A21-3A4-2(4A21-5A2-)2(5A20-5A2-)4(5A19-6A2-)5A19-6A-6A2(19-13A)19-7AC5A19-14A18-6AC8A17-6AC8A14-42A-2(30A2-)30A3-28A4-28A5-26A7-24A9-22A11-20A13-18A16-14A21-8A79-2A21-3A4-2(4A21-5A2-)2(5A20-5A2-)4(5A19-6A2-)5A19-6A-6A19-13A19-7AC5A19-13A19-14A18-15A17-15A14-9AC32A-2(30A2-)30A3-28A5-26A6-26A7-24A9-22A11-20A14-16A17-14A21-8A79-2A21-3A4-2(4A21-5A2-)2(5A20-5A2-)5(5A19-6A2-)5A19-6A-6A2(19-6A2C5A)19-6A2CD5A18-6A2CD6A17-6A2C7A14-9AC-2(30A2-)30A3-28A4-28A5-26A6-26A7-24A9-22A11-20A14-16A18-12A23-6A80-2A21-3A4-2(4A21-5A2-)2(5A20-5A2-)7(5A19-6A2-)5A19-13A19-8AD5A18-8AD6A17-7A-7A14-9A3(2-30A)3-28A4-28A5-26A7-24A8-24A9-22A12-18A15-16A18-12A24-4A81-2A21-3A5-2(3A21-4A4-)2(4A20-4A4-)4(4A19-5A4-)4A19-5A3-4(5A19-6A2-)6A18-4ADA2-7A17-6A2-7A14-9A2(2-30A)3-28A4-28A5-26A6-26A7-24A9-22A11-20A13-18A16-14A20-10A110-2A21-3A5-2(3A21-4A4-)2(4A20-4A4-)5(4A19-5A4-)4A2(19-5A3-5A)19-6A2-5A19-6A2-6A18-4ADA2-7A17-6A2-7A14-9A2-30A3-2(28A4-)27AB5-26A7-24A8-24A9-22A11-20A14-16A17-14A21-8A111-2A21-3A5-2(3A21-4A4-)2(4A20-4A4-)6(4A19-5A4-)4A2(19-5A3-5A)19-6A2-6A18-6A2-7A17-6A3-A3D2A14-8A4-28A2(4-27AB)5-25AB6-26A7-24A9-22A11-20A13-18A15-16A18-12A24-4A113-2A21-2A6-2(3A21-4A4-)2(4A20-4A4-)6(5A18-5A4-)5A2(18-5A3-6A)18-4AB4-A3DA18-4AB4-A3D2A17-4AB4-A3D23AB4-27AB5-25A2(B6-B24A)B7-24A9-22A11-20A13-18A15-16A17-14A21-8A144-A21-2A6-2(3A21-4A4-)4A20-4A4-5A19-4A6(4-5A18-5A)4-2(5A18-4A5-)5A18-3AB5-A3DA18-3DB6-A2D2A17-3DB6-A2D18A4DB6-B23A2B6-2B23AB7-B22AB8-B22AB9-22A10-22A11-20A13-18A16-14A20-10A26-2A147-A21-2A6-2(3A20-4A5-)2(5A19-3A5-)5(5A18-4A5-)5A17-5A5-5A2(18-4A6-4A)18-3AB6-BADA17-2(3DAB6-BAD18A)3DAB7-2(B22AB8-)B22AB9-B20AB11-20A12-20A13-18A16-14A19-12A23-6A177-A2(20-3A7-2A)20-7(3A7-4A18-)3A7-5A16-4A7-4A18-3A7-4A18-2AB8-B2A18-2A3(B8-BD18A3D)B8-B22AB9-B20AB10-B20AB11-B18AB13-18A14-18A16-14A19-12A22-8A164-A13-A17-A11-4(3A17-3A9-)3(3A18-2A9-)2(3A17-3A9-)2(4A16-3A9-)3A18-AB9-3A18-AB10-BA18-3(AB10-B18AD)AB10-2B18A2B11-B18AB12-2B16A2B13-B16AB15-16A17-14A19-12A22-8A196-A13-A17-2A4(11-21A)3(11-8A12-A)4(11-21A)11-A2B16A2B11-3B16A2B2(12-B18AB)2(12-2B16A2B)13-B16AB14-2B14A2B15-B14AB16-2B12A2B17-14A20-10A24-6A212-18A13-11(20A12-)A3B12A3BA14-2B12A2B16-B14AB15-B16AB14-B16AB15-2(B14AB16-)B14AB17-2B10A2B18-3B8A3B19-4B4A4B22-8A27-2A247-8(16A16-)16A22-4A26-8A23-A3C2A3CA21-3B2C2A2C3B20-3B6A3B18-3B12AB16-B14AB15-2B14A2B15-B14AB16-B14AB17-BC3B4A3BCB20-10B23-8B26-4B302-
