model
size = 31 32 32, scale = 0.05, origin = -y
material deform = 1, fade = true, lighting = smooth, roughness = 0.3, metalness = 0.6
  colors = A:#D4D4D4 B:#B8B8B8 C:#969696 D:#857777 E:#CDC8A9 F:#3D367E G:#000 H:#A7915B I:#58567E J:#7E5239
voxels
570-8D87-4A740-4A26-3(6A25-)6A26-4A708-6A24-8A22-10A20-6(12A19-)12A20-10A22-8A24-6A552-6A23-10A20-12A18-14A16-8(16A15-)16A16-14A18-12A20-10A23-6A458-8A21-12A18-14A16-16A15-AB12ACA16-8(C12AC17-)C12AC16-AB12ACA15-16A16-14A18-12A21-8A366-4A24-10A19-14A16-16A15-AB12ACA16-2(C12AC17-)C12AC16-6(BC12ACB15-)BC12ACB16-2(C12AC17-)C12AC16-AB12ACA15-16A16-14A19-10A24-4A275-4A24-10A19-14A16-16A16-2(C12AC17-)C12AC16-2(BC12ACB15-)BC12ACB14-2BC12AC2B3(13-2EC12AC2E)13-2BC12AC2B14-2(BC12ACB15-)BC12ACB16-2(C12AC17-)C12AC16-AB12ACA16-14A19-10A24-4A241-10A19-14A16-16A16-C12AC17-C12AC16-2(BC12ACB15-)BC12ACB14-2BC12AC2B12-2(3BC12AC3B11-)3(3EC12AC3E11-)3BC12AC3B11-3BC12AC3B12-2BC12AC2B14-2(BC12ACB15-)BC12ACB16-C12AC17-C12AC16-AB12ACA16-14A19-10A208-8A20-14A16-16A16-C12AC17-C12AC16-BC12ACB14-2BC12AC2B13-2BC12AC2B12-3BC12AC3B11-3BC12AC3B10-2(4BC12AC4B9-)3(4EC12AC4E9-)4BC12AC4B9-4BC12AC4B10-3BC12AC3B11-3BC12AC3B12-2BC12AC2B13-2BC12AC2B14-BC12ACB16-C12AC17-C12AC16-AB12ACA16-14A20-8A117-6D25-6A22-12A17-16A16-C12AC17-C12AC16-BC12ACB14-2BC12AC2B12-3BC12AC3B11-3BC12AC3B10-2(4BC12AC4B9-)4BC12AC4B8-5BC12AC5B3(7-5EC12AC5E)7-5BC12AC5B8-2(4BC12AC4B9-)4BC12AC4B10-3BC12AC3B11-3BC12AC3B12-2BC12AC2B14-BC12ACB16-C12AC17-C12AC16-16A17-12A22-6A85-10D21-10A19-14A16-16A16-C12AC16-BC12ACB14-2BC12AC2B12-3BC12AC3B11-3BC12AC3B10-4BC12AC4B9-4BC12AC4B8-3(5BC12AC5B7-)3(5EC12AC5E7-)2(5BC12AC5B7-)5BC12AC5B8-4BC12AC4B9-4BC12AC4B10-3BC12AC3B11-3BC12AC3B12-2BC12AC2B14-BC12ACB16-C12AC16-AB12ACA16-14A19-10A82-12D19-12A17-16A16-C12AC17-C12AC16-BC12ACB14-2BC12AC2B12-3BC12AC3B10-4BC12AC4B9-4BC12AC4B8-5BC12AC5B7-5BC12AC5B6-2(6BC12AC6B5-)3(6EC12AC6E5-)6BC12AC6B5-6BC12AC6B6-5BC12AC5B7-5BC12AC5B8-4BC12AC4B9-4BC12AC4B10-3BC12AC3B12-2BC12AC2B14-BC12ACB16-C12AC17-C12AC16-16A17-12A22-6A52-14D17-14A16-AB12ACA16-C12AC16-BC12ACB15-BC12ACB13-3BC12AC3B10-4BC12AC4B9-4BC12AC4B8-5BC12AC5B7-5BC12AC5B6-3(6BC12AC6B5-)3(6EC12AC6E5-)2(6BC12AC6B5-)6BC12AC6B6-5BC12AC5B7-5BC12AC5B8-4BC12AC4B9-4BC12AC4B10-3BC12AC3B13-BC12ACB15-BC12ACB16-C12AC16-AB12ACA16-14A19-10A49-16D15-16A16-C12AC17-C12AC16-BC12ACB14-2BC12AC2B12-3BC12AC3B10-4BC12AC4B8-5BC12AC5B7-5BC12AC5B6-2(6BC12AC6B5-)6BC12AC6B4-7BC12AC7B3(3-7EC12AC7E)3-7BC12AC7B4-2(6BC12AC6B5-)6BC12AC6B6-5BC12AC5B7-5BC12AC5B8-4BC12AC4B10-3BC12AC3B12-2BC12AC2B14-BC12ACB16-C12AC17-C12AC16-16A17-12A48-16D15-16A16-C12AC16-BC12ACB15-BC12ACB13-3BC12AC3B10-4BC12AC4B9-4BC12AC4B8-5BC12AC5B6-2(6BC12AC6B5-)6BC12AC6B4-2(7BC12AC7B3-)3(7EC12AC7E3-)7BC12AC7B3-7BC12AC7B4-2(6BC12AC6B5-)6BC12AC6B6-5BC12AC5B8-4BC12AC4B9-4BC12AC4B10-3BC12AC3B13-BC12ACB15-BC12ACB16-C12AC16-16A17-12A23-4A21-16D15-16A16-C12AC16-BC12ACB14-2BC12AC2B12-3BC12AC3B10-4BC12AC4B8-5BC12AC5B7-5BC12AC5B6-6BC12AC6B5-6BC12AC6B4-2(7BC12AC7B3-)7BC12AC7B2-2(3H5EC12AC5E3H-)3H5EC12AC5E3H2-2(7BC12AC7B3-)7BC12AC7B4-6BC12AC6B5-6BC12AC6B6-5BC12AC5B7-5BC12AC5B8-4BC12AC4B10-3BC12AC3B12-2BC12AC2B14-BC12ACB16-C12AC16-AB12ACA16-14A21-6A20-16D15-16A16-C12AC16-EC12ACE14-2EC12AC2E12-3EC12AC3E10-4EC12AC4E8-5EC12AC5E7-5EC12AC5E6-6EC12AC6E5-6EC12AC6E4-7EC12AC7E3-7EC12AC7E2-3H5EC12AC5E3H3-2(26G5-)26G3-3H5EC12AC5E3H2-7EC12AC7E3-7EC12AC7E4-6EC12AC6E5-6EC12AC6E6-5EC12AC5E7-5EC12AC5E8-4EC12AC4E10-3EC12AC3E12-2EC12AC2E14-EC12ACE16-C12AC16-AB12ACA16-14A20-8A19-16D15-16A16-C12AC16-EC12ACE14-2EC12AC2E12-3EC12AC3E10-4EC12AC4E8-5EC12AC5E7-5EC12AC5E6-6EC12AC6E5-6EC12AC6E4-7EC12AC7E3-7EC12AC7E2-3H5EC12AC5E3H3-26G2-29G2-G2-26G2-G3H5EC12AC5E3H2(J-7EC12AC7E-)2(J2-6EC12AC6E2-)2(J3-5EC12AC5E3-)J4-4EC12AC4E4-J5-3EC12AC3E5-J6-2EC12AC2E6-J7-EC12ACE7-J8-C12AC8-J7-AB12ACA7-J8-14A8-J11-8A19-16D15-16A16-C12AC16-EC12ACE14-2EC12AC2E12-3EC12AC3E10-4EC12AC4E8-5EC12AC5E7-5EC12AC5E6-6EC12AC6E5-6EC12AC6E4-7EC12AC7E3-7EC12AC7E2-3H5EC12AC5E3H3-2(26G5-)26G3-3H5EC12AC5E3H2-7EC12AC7E3-7EC12AC7E4-6EC12AC6E5-6EC12AC6E6-5EC12AC5E7-5EC12AC5E8-4EC12AC4E10-3EC12AC3E12-2EC12AC2E14-EC12ACE16-C12AC16-AB12ACA16-14A20-8A19-16D15-16A16-C12AC16-BC12ACB14-2BC12AC2B12-3BC12AC3B10-4BC12AC4B8-5BC12AC5B7-5BC12AC5B6-6BC12AC6B5-6BC12AC6B4-2(7BC12AC7B3-)7BC12AC7B2-2(5H3BC12AC3B5H-)5H3BC12AC3B5H2-2(7BC12AC7B3-)7BC12AC7B4-6BC12AC6B5-6BC12AC6B6-5BC12AC5B7-5BC12AC5B8-4BC12AC4B10-3BC12AC3B12-2BC12AC2B14-BC12ACB16-C12AC16-AB12ACA16-14A21-6A20-16D15-AD12ADA16-C12AC16-BC12ACB15-BC12ACB13-3BC12AC3B10-4BC12AC4B9-4BC12AC4B8-5BC12AC5B6-2(6BC12AC6B5-)6BC12AC6B4-2(7BC12AC7B3-)3(4H3BC12AC3B4H3-)7BC12AC7B3-7BC12AC7B4-2(6BC12AC6B5-)6BC12AC6B6-5BC12AC5B8-4BC12AC4B9-4BC12AC4B10-3BC12AC3B13-BC12ACB15-BC12ACB16-C12AC16-16A17-12A23-4A21-16D15-AD12ADA16-C12AC17-C12AC16-BC12ACB14-2BC12AC2B12-3BC12AC3B10-4BC12AC4B8-5BC12AC5B7-5BC12AC5B6-2(6BC12AC6B5-)6BC12AC6B4-7BC12AC7B3(3-4H3BC12AC3B4H)3-7BC12AC7B4-2(6BC12AC6B5-)6BC12AC6B6-5BC12AC5B7-5BC12AC5B8-4BC12AC4B10-3BC12AC3B12-2BC12AC2B14-BC12ACB16-C12AC17-C12AC16-16A17-12A48-16D15-2D12A2D14-3D12A3D15-C12AC16-BC12ACB15-BC12ACB13-3BC12AC3B10-D3BC12AC3BD9-D3BC12AC3BD8-5BC12AC5B7-5BC12AC5B6-2(6BC12AC6B5-)6BC12AC6B4-2(4H3BC12AC3B4H3-)4H3BC12AC3B4H4-2(6BC12AC6B5-)6BC12AC6B6-5BC12AC5B7-5BC12AC5B8-4BC12AC4B9-4BC12AC4B10-3BC12AC3B13-BC12ACB15-BC12ACB16-C12AC16-AB12ACA16-14A19-10A49-16D15-2D12A2D14-3D12A3D15-C12AC17-C12AC16-BC12ACB13-D2BC12AC2BD10-2D2BC12AC2B2D2(9-D3BC12AC3BD)8-5BC12AC5B7-5BC12AC5B6-6BC12AC6B5-6BC12AC6B4-2(4H3BC12AC3B4H3-)4H3BC12AC3B4H4-6BC12AC6B5-6BC12AC6B6-5BC12AC5B7-5BC12AC5B8-4BC12AC4B9-4BC12AC4B10-3BC12AC3B12-2BC12AC2B14-BC12ACB16-C12AC17-C12AC16-16A17-12A22-6A51-16D2(15-3D10A3D)14-4D10A4D15-C12AC16-BC12ACB13-D2BC12AC2BD10-2(2D2BC12AC2B2D9-)D3BC12AC3BD9-D3BC12AC3BD8-2(5BC12AC5B7-)5BC12AC5B6-2(3H3BC12AC3B3H5-)3H3BC12AC3B3H6-2(5BC12AC5B7-)5BC12AC5B8-4BC12AC4B9-4BC12AC4B10-3BC12AC3B11-3BC12AC3B12-2BC12AC2B14-BC12ACB16-C12AC16-AB12ACA16-14A20-8A82-14D19-G8AG19-2D10A2D15-4D10A4D15-C12AC17-C12AC14-2DBC12ACB2D10-3DBC12ACB3D2(9-2D2BC12AC2B2D)3(9-D3BC12AC3BD)8-5BC12AC5B6-2(3H3BC12AC3B3H5-)3H3BC12AC3B3H6-5BC12AC5B8-2(4BC12AC4B9-)4BC12AC4B10-3BC12AC3B11-3BC12AC3B12-2BC12AC2B14-BC12ACB16-C12AC17-C12AC16-16A17-12A111-14D19-G3C2A3CG19-6D2A6D19-2G2C2A2C2G17-8D2A8D15-C12AC14-3DC12AC3D10-3DBC12ACB3D2(9-2D2BC12AC2B2D)9-DF2BC12AC2BF3(D9-D3BC12AC3B)D7-2(3H3BC12AC3B3H5-)3H3BC12AC3B3H7-4BC12AC4B9-4BC12AC4B10-3BC12AC3B11-3BC12AC3B12-2BC12AC2B13-2BC12AC2B14-BC12ACB16-C12AC17-C12AC16-16A17-12A21-8A114-12D21-8G21-12D22-6G21-14D15-4D10A4D13-4D10A4D11-2(5D12A5D9-)3DBC12ACB3D10-F2BC12AC2BF10-2(DF2BC12AC2BFD9-)DF2BC12AC2BFD8-2(2HF2BC12AC2BF2H7-)2HF2BC12AC2BF2H8-2D2BC12AC2B2D9-2D2BC12AC2B2D11-2BC12AC2B14-2(BC12ACB15-)BC12ACB16-C12AC17-C12AC16-16A17-12A21-8A146-2(10D52-)10D21-3D4A3D19-5D4A5D13-2(9D4A9D9-)4DC12AC4D10-2(3FC12AC3F11-)3FC12AC3F10-D3FC12AC3FD8-2(HD3FC12AC3FDH7-)HD3FC12AC3FDH8-4DC12AC4D9-4DC12AC4D12-B15C15-BC12ACB16-2(C12AC17-)C12AC16-16A17-12A21-8A180-2(4D58-)4D27-4D24-10D17-18D11-22D9-22D11-4(18F13-)18F11-D-16FIF-D9-D-17FI-D2(9-22D)44-C12BC17-C12AC16-AB12ACA15-16A17-12A21-8A424-12D16-18D13-18D15-14F17-10FI3F17-11FI2F17-12FIF17-10FI2FI17-10F2I2F17-10F3IF14-20D11-20D44-16A15-16A16-14A19-10A23-6A459-6D22-12D19-12D22-3I2FI25-F3I2F25-2F3IF25-3F3I25-4F2I25-5FI25-6F20-16D79-12A20-10A23-6A291-
