model
size = 22 8 27, scale = 0.05, origin = -y
material deform = 1, fade = true, lighting = smooth, roughness = 0.3, metalness = 0.6
  colors = A:#111 B:#FF9 C:#FC0 D:#EEE
voxels
88-5A171-A3-A86-19A3-2(A21-)A18-A2-2A20-2(A21-)2(19A3-)C2(17B4-A)17B-A2-2A16B2(4-A17B)4-2(19A3-)C16A2(B4-17A)B-D2-3(17AB4-)2A2(CA)3C3(AC)4A3-19A3-C16A2(B4-17A)B-D2-3(17AB4-)2A3C3(AC)2AC5A3-19A3-C16A5(B4-17A)B4-2A4(CA)C2AC5A3-19A3-C16A5(B4-17A)B4-2A2(CA)3CA2CAC5A3-19A3-5(C16AB4-)17AB4-2(19A3-)6(17AB4-)2A2C10ACAC2A3-19A3-6(17AB4-)2A2(CA)2(3CA)2C3A3-19A3-5(C16AB4-)17AB4-2A2C2A4(CA)2C3A3-19A3-C16A3(B4-17A)B4-C16AB4-17AB4-2A7(CA)C2A3-19A3-C16A3(B4-17A)B4-C16AB4-17AB4-2A2C2A2(3CA)CAC2A3-19A3-C16A3(B4-17A)B4-C16AB4-17AB4-2(19A3-)C16A3(B4-17A)B4-C16AB4-17AB4-6A3CA3C6A3-19A3-C16A3(B4-17A)B4-C16AB4-17AB4-6A2(CA)C8A3-19A3-5(C16AB4-)17AB4-6A2(CA)3C6A3-19A3-6(17AB4-)6A3CAC8A3-19A3-6(17AB4-)2AC10AC5A3-19A3-C16A5(B4-17A)B4-2AC5A4C4(AC5A3-19A3-C16A5(B4-17A)B4-2AC5AC2AC)AC5A3-19A3-5(C17B4-)A17B4-2A5CA4CA5CA3-19A3-6(A21-)19A
