model
size = 20 32 11, scale = 0.05, origin = -y
material deform = 1, fade = true, lighting = smooth, roughness = 0.3, metalness = 0.6
  colors = A:#EEE B:#BBB C:#AAA D:#888 E:#777 F:#444 G:#0B0 H:#0A0 I:#603 J:#070 K:#0C0 L:#0E0 M:#00C N:#0F0 O:#B00 P:#0F3 Q:#050 R:#555 S:#CF3 T:#700 U:#040
voxels
44-12B7-6(14B6-14C6-)10(14B6-)14B7-12B105-15B5-16B4-3B12A2B3-6(2B14A2B2-2C14A2C2-)2B14A2B2-B-14A-B6(2-2B14A2B)2-2B2AB8AB2A2(2B2-2BAB-E6BE-BA)2B2-4B-E6BE-4B2-4B-EM2OSOME-4B2-B-2B-E3MO2ME-2B-B2(2-4B-8E-4B)2-4B10-4B2-15B5-B14AB4-B15AB3-6(B16AB2-C16AC2-)B16AB2-BF14AF6(B2-B16A)B2-B3AB8AB3A2(B2-B2AB-E6BE-B2A)2(B3-FAB-E6BE-B2A)B2-BFAB-E6BE-BAFB2-B2AB-E6BE-B2AB2-B2AB-8E-B2AB2-4B10-4B2-15B5-B14AB4-B15AB3-6(B16AB2-C16AC2-)9(B16AB2-)B3AB8AB3AB2-B3A2(B8AB3AB3-F2A)3(10B3AB2-B3A)10B3AB2-18B2-8B2-5B5-B7A2F5AB4-B15AB3-6(B16AB2-C16AC2-)16(B16AB2-)18B2-8B2-5B5-B7A2F5AB4-B15AB3-6(B16AB2-C16AC2-)4(B16AB2-)B16A3(B-F17A)B2-B16AB2-3(B15AF3-)4(B16AB2-)18B2-15B5-B14AB4-B15AB3-15(B16AB2-)4(B17AF-)2(B16AB2-)3(B15AF3-)2(B16AB2-)B16AB3-CB13AC3-B2-2R13B2-15B5-B14AB4-B15AB3-15(B16AB2-)B3AP2L6NP3AB2-B3A4L6G3AB2-B3A2H8G3AB2-B3AJ3H3JHGH3AB2-B3A10K3AB2-B3AJ4HGHGQJ3AB2-B3A3G7H3AB2-B3AJQ4J2GHL3AB2-B3AUG2J2H2J2L3A3(B2-B16A)B3-C14AC3-18B2-15B5-13BC2B4-7BA4BCAC2B3-5BA2BA4BCAC2B2-6BA2BA4BC3B2-7BA10B2-18B2-3B2A13B2-3B2A5B3A5B2(2-B6A3B2(3AB))2-3B2A9B3AB2-3B2A13B3(2-18B)2-3B10D5B2-2B12D4B2-2B2D10-D3B5(2-2B2D10-2D2B)2-2BTD2(10-2D2B2-2B2D)10-2D2B2-3B12D3B2(2-18B)3-16C3-18B2-15B5-13B-2B4-7BA4B-B-2B3-5BA2BA4B-B-2B2-6BA2BA4B-3B2-7BA10B2-18B2-3B2A13B2-3B2A5B2(3A5B2-B6A3B)2(3AB)2-3B2A9B3AB2-3B2A13B3(2-18B)2-3B10-5B2-2B12-4B2-2B13-3B8(2-2B14-2B)2-3B12-3B2(2-18B)22-2B-12B-2B49-2(D17-D2-)D17-D35-2F18-2F5-2(3I8-6F3-)3I-2(3I6-2F9-)3I382-
