model
size = 11 32 11, scale = 0.05, origin = -y
material deform = 1, fade = true, lighting = smooth, roughness = 0.3, metalness = 0.6
  colors = A:#111 B:#888 C:#633 D:#EEE E:#BBB
voxels
3-ED3E6-E2DED22(6-5A)6-4AC6-4CB6-CB2CB7-2CB50-E5-D4-D5-D15(4-A5-A)7(4-7A)4(4-6AB)5-A2B2C37-D7-E2-E7-E9(2-A7-A)6(2-2A6-A)6(2-2A3-4A)2-2A3-3AC2-2A3-4A2(2-8AC)2-8AB3-3A3CB5-BA3C25-D9-ED9-DA8(9-2A)9-6(4A7-)4A6(3-8A)3-4AB3A3-14A2C9A2C-9A2-8AC3-5A2B5-ABAC15-D9-2D9-DA8(9-2A)9-6(4A7-)4A5(3-8A)3-4AB3A3-8A3-4AB10AB21AC-9A3-5A2B5-4AB6-A2B5-A9-E3A7-D3A15(7-4A)4(3-8A)3-4AC3(3A3-4AB)21AC11A-8AC3-6AB5-4AC6-A3B4-A9-2D2A7-E3A15(7-4A)5(3-8A)3-4AB3A3-3ACB3A3-3A3(2C9A)2C-9A3-7A5-4AC6-ABC5-D9-2D9-DA14(9-2A)9-76A2(2C9A)CB9A2C-8AC2-2A2B5A3-A2B3AB5-2BAB16-D7-D2-D6-2E15(2-A6-2A)6(2-9A)5(2-8AC)3-A2B3AC5-2BCAB27-D5-D4-D5-E15(4-A5-A)7(4-7A)4-6AC4-6AB4-5ABA4-5ABC5-5B39-4DE6-DE3D22(6-5A)6-3A2B6-A2B2A6-B2A2B7-ABC48-
