model
size = 30 15 12, scale = 0.05, origin = -y
material deform = 1, fade = true, lighting = smooth, roughness = 0.3, metalness = 0.6
  colors = A:#FC3 B:#36F C:#BBB
voxels
6-4BA10-A4B9-A3BA10-A3BA8-BAB3AB10AB3ABAB5-2(BA)3BA4B2A4BA3B2(AB)3-3A2(BA)B3A6B3A2(BA)B3A2-5B2A4B6A4B2A5B-4B4(2A3B)2A4B2A2B3(AB)A8B3(AB)A2B2AB2A7B10A7B2A2(BA)4B3A2(2B2A)2B3A4BABA3B2ABAB5AB2AB5ABAB2A3B-4BABA3B2A4B2A3BABA4B2-A2B2(AB)A3BA4BA3B2(AB)A2BA3-A3BA2(4B2A)4BA3BA5-BA4B3A6B3A4BAB153-A28-AB3(28-2B)28-B241-A26-A2-B26-B-2B26-4B26-2B2A26-2A2B26-4B26-2B-A26-A2-B26-B153-A24-A3-AB24-BA2-2A24-2A-B2(2A24-2A2BAB24-BA2B)2A24-2AB-AB24-BA2-2A24-2A3-A24-A95-A22-A5-AB22-BA3-2AB22-B2A2-2AB22-B2A-B3(2AB22-B2A2B)3A22-3A2B3A22-3AB-2AB22-B2A2-2AB22-B2A3-AB22-BA5-B22-B66-AB20-BA5-2AB20-B2A3-3AB20-B3A2-3AB20-B3A-4AB20-B4AB2(3AB20-B3A2B)3AB20-B3AB5A20-5A-4A20-4A2-3AB20-B3A3-2AB20-B2A5-2A20-2A38-A4B10-4BA8-2A2B2(2A5B)2A2B2A5-3AB18-B3A3-4AB18-B4A2-4AB18-B4A-6A18-6AB2(4AB18-B4A2B)4AB18-B4AB5AB18-B5A-4AB18-B4A2-4AB18-B4A3-3AB18-B3A5-2A20B2A8-BA2BA10-A2BAB10-2B3A10-3A2B8-8A3B2A3B8A5-4A18-4A3-5A18-5A2-5A18-5A-6A18-6AB2(5A18-5A2B)5A18-5AB6A18-6A-5A18-5A2-5A18-5A3-4A18-4A5-8A3B2A3B8A8-2B3A10-3A2B10-B2ABA10-AB2AB8-7A3(B2A)B7A5-4A18-4A3-5A18-5A2-5A18-5A-B5A18-5A2B5A18-5AB6A18-6AB5A18-5A2B5A18-5AB-5A18-5A2-5A18-5A3-4A18-4A5-7A3(B2A)B7A8-B2ABA10-AB2A2(B10-B3A)B8-8A8B8A5-4ABA14BAB4A3-5A18-5A2-5A18-5A-B4(5A18-5A2B)5A18-5AB-5A18-5A2-5A18-5A3-4A18-4A5-8A8B8A8-2(B3AB10-)2(AB)A10-2(AB)A8-7A10B7A5-26A3-5A18-5A2-5A18-5A-2(6A18-6AB5A18-5AB)6A18-6A-5A18-5A2-5A18-5A3-4A18-4A5-7A10B7A8-2(2(AB)A10-)ABA2B10-2BABA8-7A2(2B2A)2B7A5-26A3-28A2-7A4C6A4C7A-B6A6C4A6C6A2(B6A8C2A8C6AB5A8C2A8C5A)B-6A6C4A6C6A2-7A4C6A4C7A3-26A5-7A2(2B2A)2B7A8-ABA2B10-2BABA5-
