model
size = 30 15 12, scale = 0.05, origin = -y
material deform = 1, fade = true, lighting = smooth, roughness = 0.3, metalness = 0.6
  colors = A:#9C0 B:#009 C:#008
voxels
6-ABCAB10-BACBA9-B4A10-4AB8-2AB2A2C2BAB2ABA2B2C2AB2A5-BC2(BA)5C4A5C2(AB)CB3-ABA3C2A2C2AC2BC2A2C2A3CABA2-BABCBA2CBAB6ABAB2CABCBAB-2(AB)C2A2(BAC)4B2(CAB)2ACBAB2AC2A3CB2C3(B2A)B2CB3C2AC5A3C3A2B6A2B3A3C4AC7AB3A6B3AB7AC2A2B5ABCBAC2ACABCB5A2B2A-A4CA2BAC8ACA2BA4CA2-CA4CB2CBAB4ABAB2CB4CAC3-2ACB6AC4AC6ABC2A5-CBC6ABA2BAB6ACBC153-A4(28-2A)28-A241-A26-A2-A26-A-2A4(26-4A)26-2A-A26-A2-A26-A153-A24-A3-2A24-2A2-2A24-2A-3A4(24-6A)24-3A-2A24-2A2-2A24-2A3-A24-A95-A22-A5-2A22-2A3-3A22-3A2-3A22-3A-4A4(22-8A)22-4A-3A22-3A2-3A22-3A3-2A22-2A5-A22-A66-2A20-2A5-3A20-3A3-4A20-4A2-4A20-4A-5A4(20-10A)20-5A-4A20-4A2-4A20-4A3-3A20-3A5-2A20-2A38-5A10-5A8-24A5-4A18-4A3-5A18-5A2-5A18-5A-6A4(18-12A)18-6A-5A18-5A2-5A18-5A3-4A18-4A5-24A8-2(5A10-)BAB2A10-2ABAB8-7ACACB2ABCAC7A5-4A18-4A3-5A18-5A2-5A18-5A-6A4(18-12A)18-6A-5A18-5A2-5A18-5A3-4A18-4A5-7ACACB2ABCAC7A8-BAB2A10-2ABAB10-3ACA10-AC3A8-7A2CAC2ACA2C7A5-4A18-4A3-5A18-5A2-5A18-5A-6A4(18-12A)18-6A-5A18-5A2-5A18-5A3-4A18-4A5-7A2CAC2ACA2C7A8-3ACA10-AC3A10-2BACA10-ACA2B8-7AC3A2B3AC7A5-26A3-5A18-5A2-5A18-5A-6A4(18-12A)18-6A-5A18-5A2-5A18-5A3-4A18-4A5-7AC3A2B3AC7A8-2BACA10-ACA2B10-BAB2A10-2ABAB8-7ACBAB2CBABC7A5-26A3-5A18-5A2-5A18-5A-6A4(18-12A)18-6A-5A18-5A2-5A18-5A3-4A18-4A5-7ACBAB2CBABC7A8-BAB2A10-2ABAB10-2(CA)B10-B2(AC)8-8A8B8A5-26A3-28A2-7A4B6A4B7A-7A6B4A6B13A3(8B2A8B12A)8B2A8B6A-6A6B4A6B6A2-7A4B6A4B7A3-26A5-8A8B8A8-2(CA)B10-B2(AC)5-
