model
size = 30 15 12, scale = 0.05, origin = -y
material deform = 1, fade = true, lighting = smooth, roughness = 0.3, metalness = 0.6
  colors = A:#399 B:#F00 C:#0FF
voxels
6-ABA2B10-2BABA9-3BAB10-BA3B8-5ABA3BA2BA3BAB5A5-2B2A2BAB2A6B2ABA2B2A2B3-2B2A3BAB10ABA3B2A2B2-ABA2B4A4B2A4B4A2BABA-3ABAB2AB5A2B5AB2ABAB6A5B3A2B4A2B3A5B4A4(BA)B2A6B2A6(BA)4BA2BAB2A4B2ABA2BA4BA2B5A3B4AB2AB4A3B5AB-B2ABAB2(4A2B)4ABAB2AB2-3A4BA2B8A2BA4B3A3-2(BA)2B2(2A4B)2A2B2(AB)5-A2B5A3B2A3B5A2BA153-A28-AB3(28-2B)28-B241-B26-B2-B26-B-A3(B26-B2A)B26-B3A26-2A-B26-B2-B26-B153-A24-A3-2A24-2A2-AB24-BA-2AB24-B5A24-5AB24-B4AB24-B5A24-3A-AB24-BA2-AB24-BA3-B24-B95-A22-A5-AB22-BA3-2AB22-B2A2-3A22-3A-3A4(B22-B6A)B22-B3A-2AB22-B2A2-2AB22-B2A3-2A22-2A5-B22-B66-AB20-BA5-2AB20-B2A3-4A20-4A2-3AB20-B3A-4A2(B20-B8A)B20-B9A20-10A20-5A-3AB20-B3A2-4A20-4A3-3A20-3A5-2A20-2A38-4BA10-A4B8-2A2BA2B3AB2AB3A2BA2B2A5-4A18-4A3-4AB18-B4A2-4AB18-B4A-5AB18-B10AB18-B11A18-11AB18-B11A18-6A-4AB18-B4A2-5A18-5A3-3AB18-B3A5-3A18B3A8-4BA10-A4B10-BA2BA10-A2BAB8-9A6B9A5-4A18-4A3-5A18-5A2-5A18-5A-6A4(18-12A)18-6A-5A18-5A2-5A18-5A3-4A18-4A5-9A6B9A8-BA2BA10-A2BAB10-4AB10-B4A8-11A2B11A5-4A18-4A3-5A18-5A2-5A18-5A-6A4(18-12A)18-6A-5A18-5A2-5A18-5A3-4A18-4A5-11A2B11A8-4AB10-B4A2(10-5B)8-7A3(B2A)B7A5-4AB2A12B2AB4A3-5A18-5A2-5A18-5A-6A4(18-12A)18-6A-5A18-5A2-5A18-5A3-4A18-4A5-7A3(B2A)B7A8-2(5B10-)A2BAB10-BA2BA8-7A3(B2A)B7A5-26A3-5A18-5A2-5A18-5A-6A4(18-12A)18-6A-5A18-5A2-5A18-5A3-4A18-4A5-7A3(B2A)B7A8-A2BAB10-BA2BA10-AB3A10-3ABA8-24A5-26A3-28A2-7A4C6A4C7A-7A6C4A6C13A3(8C2A8C12A)8C2A8C6A-6A6C4A6C6A2-7A4C6A4C7A3-26A5-24A8-AB3A10-3ABA5-
