model
size = 30 15 12, scale = 0.05, origin = -y
material deform = 1, fade = true, lighting = smooth, roughness = 0.3, metalness = 0.6
  colors = A:#063 B:#070 C:#008
voxels
6-2BCAC10-CAC2B9-BC3B10-3BCB8-4B2C2ABAB2CBAB2A2C4B5-CB3ABA2BCA4BAC2BAB3ABC3-ACA2CBAB3ACA2CAC3ABAB2CACA2-2BA2CB2A2C2(2AC)2A2C2AB2CA2B-B4AB3ABCAB4ABACB3AB4A6BAC2BABACA2CACABA2BCA5BC2ABCB5AB6AB5ABCB2AC4ABAB6AB2CB6ABAB6A2B2ABC6A2B6ACB2A2B2A-2C2A3B2(AC)2A2C2A2(CA)3B2A2C2-B2CBA3BCA3B2A3BAC3BAB2CB3-2(AC)2AB2AC2B2C2BC2AB2A2(CA)5-A3C3AB2C4A2CB3A3CA153-B28-2B28-BC28-CB28-BC28-C241-B26-B2-B26-B-AB26-B2(2AC26-C)3A26-4A26-2A-C26-C2-B26-B153-C24-C3-AB24-BA2-2A24-2A-2AB24-B2ACAB24-BAC2AB24-B2ACAC24-CAC2AC24-C2A-AB24-BA2-AB24-BA3-B24-B95-A22-A5-AB22-BA3-3A22-3A2-2AB22-B2A-B3A22-2(3AB)22-B2(6AC22-C)3AB2AC22-C2AB-2AB22-B2A2-3A22-3A3-AB22-BA5-B22-B66-2A20-2A5-3A20-3A3-3AC20-C3A2-3AC20-C3A-4AC20-C4AC3AB20-B3AC4AB20-B4AC3AC20-C3AC4AC20-C4A-3AB20-B3A2-3AB20-B3A3-3A20-3A5-2A20-2A38-A2BAB10-BA2BA8-3ABCBA2BC4BC2BABCB3A5-3AC18-C3A3-4AC18-C4A2-5A18-5A-5AB18-B2(10AC18-C)11A18-11AB18-B5A-4AC18-C4A2-4AB18-B4A3-3AC18-C3A5-2ABC2B2C2B4C2B2C2BCB2A8-C3BA10-A3BC2(10-5A)8-24A5-4A18-4A3-5A18-5A2-5A18-5A-6A4(18-12A)18-6A-5A18-5A2-5A18-5A3-4A18-4A5-24A8-3(5A10-)5A8-24A5-4A18-4A3-5A18-5A2-5A18-5A-6A18-12A18-6AB5A18-5AB6A18-12A18-6A-5A18-5A2-5A18-5A3-4A18-4A5-24A8-3(5A10-)5A8-24A5-4AB2C4BA2BA4B2CB4A3-5A18-5A2-5A18-5A-C5A18-5AC6A2(18-12A)18-6AC5A18-5AC-5A18-5A2-5A18-5A3-4A18-4A5-24A8-3(5A10-)5A8-24A5-26A3-5A18-5A2-5A18-5A-6A4(18-12A)18-6A-5A18-5A2-5A18-5A3-4A18-4A5-24A8-3(5A10-)5A8-24A5-26A3-28A2-7A4B6A4B7A-7A6B4A6B13A8B2A8B6AC5A8B2A8B5AC6A8B2A8B12A8B2A8B6A-6A6B4A6B6A2-7A4B6A4B7A3-26A5-24A8-5A10-5A5-
