model
size = 15 32 15, scale = 0.05, origin = -y
material deform = 1, fade = true, lighting = smooth, roughness = 0.3, metalness = 0.6
  colors = A:#111 B:#FFF C:#DDD D:#EEE
voxels
5-5B370-5B98-9B8-5C23(10-5A)8-9B8-5C82-11B5-9C23(6-9A)5-11B5-9C8-5A66-13B3-11C23(4-11A)3-13B3-11C6-7A9-5A51-13B3-11C23(4-11A)3-13B3-11C5-9A7-7A49-15B-13C23(2-13A)-15B-13C3-11A5-9A9-3C36-2(15B-13C23(2-13A)-15B-13C3-11A5-9A8-5C11-3B12-3B6-)15B-13C23(2-13A)-15B-13C3-11A5-9A8-5C11-3B12-BAB6-15B-13C23(2-13A)-15B-13C3-11A5-9A9-3C37-13B3-11C23(4-11A)3-13B3-11C5-9A7-7A50-13B3-11C23(4-11A)3-13B3-11C6-7A9-5A52-11B5-9C13(6-9A)2(6-AB5ADA)6-7A2D2(6-AB5ADA)6-A2B4ABA4(6-9A)5-11B5-9C8-5A68-9B8-5C13(10-5A)10-2B2(3A10-AB)A2D10-2BADA10-AB2AB10-2B3A4(10-5A)8-9B8-5C85-5B370-5B95-
