model
size = 30 15 12, scale = 0.05, origin = -y
material deform = 1, fade = true, lighting = smooth, roughness = 0.3, metalness = 0.6
  colors = A:#C36 B:#00E C:#005
voxels
6-BA3B10-3BAB9-B4A10-4AB8-4B2A2B8A2B2A4B5-A2BA3BA2B6A2BA3BA2BA3-2BA4BAB2(2A2B)2ABA4BA2B2-B2A2BAB3A3B2A3B3ABA2B2AB-2B4AB2A4B4A4B2AB4A3B3AB4A2BA6BA2B4AB3AB2(A2B)2A5B4A5B2A2BA2B3A2BABA3B3AB2AB3A3BABA2B4A2BABA16BABA2B2A-AB3A5BA2B2A2BA5B3ABA2-3A2B2A14B2A2B3A3-ABA5B3(A2B)A5BABA5-2B3(AB)3(2AB)2(AB)A2B153-A4(28-2A)28-A241-A26-A2-A26-A-2A4(26-4A)26-2A-A26-A2-A26-A153-A24-A3-2A24-2A2-2A24-2A-B2A24-2AB3A2(24-6A)24-3AB2A24-2AB-2A24-2A2-2A24-2A3-A24-A95-A22-A5-2A22-2A3-3A22-3A2-3A22-3A-4A4(22-8A)22-4A-3A22-3A2-3A22-3A3-2A22-2A5-A22-A66-2A20-2A5-3A20-3A3-4A20-4A2-4A20-4A-5A4(20-10A)20-5A-4A20-4A2-4A20-4A3-3A20-3A5-2A20-2A38-5A10-3(5A8-24A5-4A18-4A3-5A18-5A2-5A18-5A-6A4(18-12A)18-6A-5A18-5A2-5A18-5A3-4A18-4A5-24A8-3(5A10-))2(5A8-24A5-26A3-5A18-5A2-5A18-5A-6A4(18-12A)18-6A-5A18-5A2-5A18-5A3-4A18-4A5-24A8-3(5A10-))5A8-24A5-26A3-28A2-7A4C6A4C7A-B6A6C4A6C6AB6A2(8C2A8C12A)8C2A8C6AB5A8C2A8C5AB-6A6C4A6C6A2-7A4C6A4C7A3-26A5-24A8-5A10-5A5-
