model
size = 30 15 12, scale = 0.05, origin = -y
material deform = 1, fade = true, lighting = smooth, roughness = 0.3, metalness = 0.6
  colors = A:#0FF B:#F63 C:#603
voxels
6-ACBAB10-BABCA9-2ABAB10-BAB2A8-3ACAB2ACAC2BCAC2ABAC3A5-CBA2BC2(B2ABA)B2ABC2BABC3-2AC2B2ACBABC4ACBABC2A2BC2A2-A2BAC2ABAC2A4B2ACAB2ACA2BA-BC5A2BC3A4C3AC2B5ACBAC2A2CBACAB2A4B2ABACAB2C2ACABACBAB2(C2A)CB2AB2(C2A)CB2(ABC)AB5A2(BA)BC2AC2(BA)B5ABA2C6AC2(B2A)2B2(2AB)C6AC-BAB3AB5AB2CB5AB3ABAB2-BCB5AB2CA4CA2CB5ABCB3-ACB3CBA2CAC2ACA2CAB3CBCA5-2(CB)ACBA3B2A3B2(ABC)BC153-B28-BA28-2A28-AB28-BA28-A241-A26-A2-A26-A-2A4(26-4A)26-2A-A26-A2-C26-C153-A24-A3-2A24-2A2-2A24-2A-3A3(24-6A)24-5AB24-B2A-2A24-2A2-2A24-2A3-A24-A95-A22-A5-AB22-BA3-2AB22-B2A2-2AB22-B2A-4A22-8A22-7AC22-C7A22-8A22-4A-3A22-3A2-3A22-3A3-2A22-2A5-C22-C66-2A20-2A5-2AC20-C2A3-3AB20-B3A2-4A20-4A-5A20-10A20-9AB20-B9A20-9AB20-B4A-4A20-4A2-3AC20-C3A3-3A20-3A5-2A20-2A38-5A10-5A8-2AC8A2B8AC2A5-4A18-4A3-5A18-5A2-4AB18-B4A-6A4(18-12A)18-6A-5A18-5A2-5A18-5A3-3AB18-B3A5-4AB2ACAC4ACAC2AB4A8-2(2AB2A10-)5A10-2(5A8-24A5-4A18-4A3-5A18-5A2-5A18-5A-6A4(18-12A)18-6A-5A18-5A2-5A18-5A3-4A18-4A5-24A8-3(5A10-))5A8-24A5-4AB2ABAC6ACAB2AB4A2(3-5A18-5A2-5A18-5A-6A4(18-12A)18-6A-5A18-5A2-5A18-5A3-4A18-4A5-24A8-3(5A10-)5A8-24A5-26A)3-28A2-7A4B6A4B7A-7A6B4A6B13A3(8B2A8B12A)8B2A8B6A-6A6B4A6B6A2-7A4B6A4B7A3-26A5-24A8-5A10-5A5-
