model
size = 30 15 12, scale = 0.05, origin = -y
material deform = 1, fade = true, lighting = smooth, roughness = 0.3, metalness = 0.6
  colors = A:#444 B:#C09 C:#CC0
voxels
6-2B3A10-3A2B9-3BAB10-BA3B8-3B2A2(BA)B4A2(BA)B2A3B5-2(BA)6B2A2B2A6B2(AB)3-2AB3A4B8A4B3AB2A2-2(2AB)A3(2B2A)2BA2(B2A)-2BA5BA4BA2BA4BA5BA3BAB3AB2(A2B)4A2(2BA)B3A3(BA)2B2(AB)3AB4AB3A2(BA)2B2(AB)A2B5ABA8BAB5A2(2BA)2B2A2B4A6B4A2B2A2BAB-BA2BA2(B2A)2(2B2A)B2ABA2BAB2-2A2BABA2BAB2A2B2ABA2BABA2B2A3-BAB4A2B2(2AB)2A2B4ABAB5-4B2AB4A2B4AB2A4B153-B2(28-2B)28-BA28-AB28-B241-B26-B2-B26-B-AB26-B3A26-2A2B26-2BAB26-B2AB26-BA-B26-B2-B26-B153-B24-B3-AB24-BA2-AB24-BA-BAB24-BA2BAB24-BAB3A24-3AB2A24-2A2B2A24-2AB-2A24-2A2-AB24-BA3-B24-B95-B22-B5-AB22-BA3-2AB22-B2A2-3A22-3A-3AB22-2(B3A)22-2(3AB)22-B3AB2AB22-B2AB3AB22-B3A-2AB22-B2A2-2AB22-B2A3-AB22-BA5-B22-B66-AB20-BA5-2AB20-B2A3-3AB20-B3A2-3AB20-B3A-B3AB20-B3A2B4A20-4AB5A20-5AB3AB20-B3A2B3AB20-B3AB-3AB20-B3A2-3AB20-B3A3-2AB20-B2A5-AB20-BA38-ABA2B10-2BABA8-2A20B2A5-4A18-4A3-4AB18-B4A2-5A18-5A-6A18-11AB18-B5AB4AB18-B4AB5AB18-B10AB18-B5A-4AB18-B4A2-4AB18-B4A3-3AB18-B3A5-2A2BA5B4A5BA2B2A8-2A3B10-3B2A10-2B2AB10-B2A2B8-7A4B2A4B7A5-4A18-4A3-5A18-5A2-5A18-5A-B4(5A18-5A2B)5A18-5AB-5A18-5A2-5A18-5A3-4A18-4A5-7A4B2A4B7A8-2B2AB10-B2A2B10-BA3B10-3BAB8-7A10B7A5-4A18-4A3-5A18-5A2-5A18-5A-6A4(18-12A)18-6A-5A18-5A2-5A18-5A3-4A18-4A5-7A10B7A8-BA3B10-3BAB10-3B2A10-2A3B8-8A8B8A5-4A4BA3B2A3BA4B4A3-5A18-5A2-5A18-5A-B5A18-5A2B5A18-5AB6A18-6AB5A18-5A2B5A18-5AB-5A18-5A2-5A18-5A3-4A18-4A5-8A8B8A8-3B2A10-2A3B2(10-5B)8-8ABAB2ABAB8A5-26A3-5A18-5A2-5A18-5A-6A18-12A18-6AB5A18-5AB6A18-12A18-6A-5A18-5A2-5A18-5A3-4A18-4A5-8ABAB2ABAB8A8-2(5B10-)BA3B10-3BAB8-7A2BAB2ABA2B7A5-26A3-28A2-7A4C6A4C7A-B6A6C4A6C6A2B5A8C2A8C5AB6A8C2A8C6AB5A8C2A8C5A2B5A8C2A8C5AB-6A6C4A6C6A2-7A4C6A4C7A3-26A5-7A2BAB2ABA2B7A8-BA3B10-3BAB5-
