model
size = 30 15 12, scale = 0.05, origin = -y
material deform = 1, fade = true, lighting = smooth, roughness = 0.3, metalness = 0.6
  colors = A:#630 B:#200 C:#6FC
voxels
6-3A2B10-2B3A9-A2C2B10-2B2CA8-2CB2CACABAC2BCABACA2CB2C5-2ABA2B2(AC)6A2(CA)2BAB2A3-2B3ACAB3A2B2A2B3ABAC3A2B2-2ABA2(B2A)C6AC2(2AB)AB2A-AB2(AC)AB2ABA6CAB2AB2(AC)ABA3B2ACAC3(2A2B)2ACAC2A3BAC4AB2AC3(A2B)AC2AB4ACA2BABA2CB3ABC4BCB3AB2CABA2BABC2(A2CB)2(2AC)2A2(B2CA)CBA-3AB2(AC)2AB2A2C2AB2A2(CA)B3A2-BC2AB2CB12AB2CB2ACB3-BC2BABCAB2A4B2ABACBA2BCB5-B2C3B2(CA)C2A2(CA)C3B2CB153-B28-BA2(28-2A)28-AB28-B241-C26-C2-A26-A-2A26-2ACA26-ACAB26-BACA26-AC2A26-2A-A26-A2-A26-A153-B24-B3-2A24-2A2-AC24-CA-C2A24-2(2AC)24-2(C2A)24-2AC2AB24-B2AC2A24-2AC-2A24-2A2-2A24-2A3-A24-A95-C22-C5-2A22-2A3-3A22-3A2-3A22-3A-2(4A22-4AB2AC22-C2AB)4A22-4A-3A22-3A2-3A22-3A3-2A22-2A5-A22-A66-2A20-2A5-3A20-3A3-3AB20-B3A2-4A20-4A-B4A20-4AB4AC20-C4AB4A20-2(4AB)20-B4AB3AC20-C3AB-3AB20-B3A2-4A20-4A3-3A20-3A5-2A20-2A38-B4A10-4AB8-2AB4AC8AC4AB2A5-4A18-4A3-5A18-5A2-5A18-5A-C5A18-5AC6A18-6AB4AB18-B4AB5AB18-B5AC5A18-5AC-5A18-5A2-4AC18-C4A3-4A18-4A5-8AC6AC8A8-ABCAC10-CACBA10-A2CAC10-CA2CA8-9AB4AB9A5-4A18-4A3-5A18-5A2-5A18-5A-B5A18-5A2B5A18-5AB6A18-6AB5A18-5A2B5A18-5AB-5A18-5A2-5A18-5A3-4A18-4A5-9AB4AB9A8-A2CAC10-CA2CA10-3ACB10-BC3A8-7A2BAB2CBA2B7A5-4A18-4A3-5A18-5A2-5A18-5A-6A18-12A18-6AC5A18-5AC6A18-12A18-6A-5A18-5A2-5A18-5A3-4A18-4A5-7A2BAB2CBA2B7A8-3ACB10-BC3A10-2CA2B10-2BA2C8-8ABAB2ABAB8A5-4AB7A2B7AB4A3-5A18-5A2-5A18-5A-6A18-12A18-6AC5A18-5AC6A18-12A18-6A-5A18-5A2-5A18-5A3-4A18-4A5-8ABAB2ABAB8A8-2CA2B10-2BA2C10-BC2BA10-A2BCB8-7ABACA2CACAB7A5-26A3-5A18-5A2-5A18-5A-B5A18-5ABC2(5A18-5A2C)5A18-5ACB5A18-5AB-5A18-5A2-5A18-5A3-4A18-4A5-7ABACA2CACAB7A8-BC2BA10-A2BCB2(10-2AB2A)8-9AC4AC9A5-26A3-28A2-7A4B6A4B7A-B6A6B4A6B6ABC5A8B2A8B5AC6A8B2A8B6AC5A8B2A8B5ACB5A8B2A8B5AB-6A6B4A6B6A2-7A4B6A4B7A3-26A5-9AC4AC9A8-2AB2A10-2AB2A5-
