model
size = 30 15 12, scale = 0.05, origin = -y
material deform = 1, fade = true, lighting = smooth, roughness = 0.3, metalness = 0.6
  colors = A:#039 B:#36C C:#00F
voxels
6-ACABA10-ABACA9-2CA2C10-2CA2C8-3AC2(AB)3A2C3A2(BA)C3A5-BAC3BACA3C2A3CACA3BCAB3-3ACAB3C3(A2C)A3CBAC3A2-5A3C2(AC)A2C2(AC)A3C5A-2CAB2ACACBAC2B2C2BCABCAC2ABA2C3A2C2(BA)2B8A2B2(AB)2C3ABAB3AC4AC2A2C2AC4AC3ABABCB2CAC2ABCA2(2BC)2BACB2ACA2CBCB3ABAC2A2BC2A2C2AC2B2ACAB3AB-2B2ABAC6A2C6ACAB2A2B2-3A2CAC2A2B6C2B2ACA2C3A3-2A2(CA)2(2B4A)2B2(AC)2A5-B3C2BC3(A2C)AC2B3CB153-A4(28-2A)28-A241-A26-A2-A26-A-2A4(26-4A)26-2A-A26-A2-A26-A153-A24-A3-2A24-2A2-2A24-2A-3A4(24-6A)24-3A-2A24-2A2-2A24-2A3-A24-A95-A22-A5-2A22-2A3-3A22-3A2-3A22-3A-4A4(22-8A)22-4A-3A22-3A2-3A22-3A3-2A22-2A5-A22-A66-2A20-2A5-3A20-3A3-4A20-4A2-4A20-4A-5A4(20-10A)20-5A-4A20-4A2-4A20-4A3-3A20-3A5-2A20-2A38-5A10-3(5A8-24A5-4A18-4A3-5A18-5A2-5A18-5A-6A4(18-12A)18-6A-5A18-5A2-5A18-5A3-4A18-4A5-24A8-3(5A10-))2(5A8-24A5-26A3-5A18-5A2-5A18-5A-6A4(18-12A)18-6A-5A18-5A2-5A18-5A3-4A18-4A5-24A8-3(5A10-))5A8-24A5-26A3-28A2-7A4B6A4B7A-7A6B4A6B13A3(8B2A8B12A)8B2A8B6A-6A6B4A6B6A2-7A4B6A4B7A3-26A5-24A8-5A10-5A5-
