model
size = 30 15 12, scale = 0.05, origin = -y
material deform = 1, fade = true, lighting = smooth, roughness = 0.3, metalness = 0.6
  colors = A:#399 B:#C09 C:#0F0
voxels
6-2ABCA10-ACB2A9-BCABA10-ABACB8-B6AC2B4A2BC6AB5-2CBA2CB3ABC2ACB3AB2CAB2C3-2BCBA2CAC2A2C2B2C2ACA2CABC2B2-C2(3AB)2A6C2A2(B3A)C-CAB2AB3A2(BA)C2AC2(AB)3AB2ABACB2(A2C)ACBACAB2CBACABC2(A2C)ABACA2BA2C4ABA2CAB4A2CA2B2(AC)ABC2AB3ACACB2CBCAC3AB2ACB2(A2C)2(BAC)10A2(CAB)2CAC-CB2A2CAB4A4B4ABA2C2ABC2-4AC2A2(BAC)2B2(CAB)2AC4A3-C2A2BC2ABACB2ABCAB2AC2B2AC5-5ABCABC4ACBACB5A153-A4(28-2A)28-A241-A26-A2-A26-A-2A26-4A26-2ABA26-AB2A26-4A26-2A-A26-A2-A26-A153-A24-A3-2A24-2A2-2A24-2A-C2A24-2AC3A2(24-6A)24-3AC2A24-2AC-2A24-2A2-2A24-2A3-A24-A95-A22-A5-2A22-2A3-3A22-3A2-3A22-3A-C3A22-3AC4A2(22-8A)22-4AC3A22-3AC-3A22-3A2-3A22-3A3-2A22-2A5-A22-A66-2A20-2A5-3A20-3A3-4A20-4A2-4A20-4A-5A4(20-10A)20-5A-4A20-4A2-4A20-4A3-3A20-3A5-2A20-2A38-5A10-5A8-24A5-4A18-4A3-5A18-5A2-5A18-5A-6A4(18-12A)2(18-6A-5A18-5A2-5A18-5A3-4A18-4A5-24A8-3(5A10-)5A8-24A5-4A18-4A3-5A18-5A2-5A18-5A-2(6A18-6AC5A18-5AC)6A)18-6A-5A18-5A2-5A18-5A3-4A18-4A5-24A8-3(5A10-)5A8-24A5-26A3-5A18-5A2-5A18-5A-C5A18-5AC6A2(18-12A)18-6AC5A18-5AC-5A18-5A2-5A18-5A3-4A18-4A5-24A8-3(5A10-)5A8-24A5-26A3-5A18-5A2-5A18-5A-6A4(18-12A)18-6A-5A18-5A2-5A18-5A3-4A18-4A5-24A8-3(5A10-)5A8-24A5-26A3-28A2-7A4B6A4B7A-7A6B4A6B7A2(B5A8B2A8B5AB6A8B2A8B6A)-6A6B4A6B6A2-7A4B6A4B7A3-26A5-24A8-5A10-5A5-
