model
size = 30 15 12, scale = 0.05, origin = -y
material deform = 1, fade = true, lighting = smooth, roughness = 0.3, metalness = 0.6
  colors = A:#C33 B:#F66 C:#693
voxels
6-B3AB10-B3AB9-2A2BA10-A2B2A8-3CB2AB4A2C4AB2AB3C5-ABC2(AB)A2C2A2B2A2C2(AB)ACBA3-2AC2AB2ACBAC4ACABC2AB2AC2A2-B2A2BAC2ABC2A2B2ACB2ACA2B2AB-2C3BCBAC2A2C4A2C2ACABC3B2C6A3C2(AB)4A2(BA)3C6ABAC3BC2A3B6A3B2AC3BC2(AB)2AC2BC4ABA2CAB4AC2BC2(2AB)CACBAC3ACAB2ABAC3ACABCACBA-C3ACA2B2A2C4A2C2A2BAC3AC2-3ABCAB2C2(AB)2C2(BA)2CBACB3A3-2A3C3A3B4A3B3A3C2A5-B2(CA)2C2A6C2A2C2(AC)B153-A28-AB2(28-2B)28-BC28-C241-B26-B2-C26-C-AC26-C2AC26-C3A26-3AC26-C2AC26-CA-B26-B2-C26-C153-B24-B3-AC24-CA2-AC24-CA-2(2AB24-B2ABAC24-CAB)2AB24-B2A-AB24-BA2-2A24-2A3-B24-B95-B22-B5-AC22-CA3-3A22-3A2-2AC22-C2A-C2AC22-C2AC3AB22-B2(6AC22-C)3AC2AC22-C2AC-2AC22-C2A2-3A22-3A3-AB22-BA5-B22-B66-AC20-CA5-2AC20-C2A3-3AC20-C3A2-3AB20-B3A-B3AB20-B3A2B3AC20-C3AB5A20-5AB4A20-4A2B3AB20-B3AB-3AC20-C3A2-3AC20-C3A3-2AC20-C2A5-AC20-CA38-C2B2C10-2C2BC8-2A2(CB)CAC6ACA2(CB)C2A5-3AC18-C3A3-4AB18-B4A2-4AB18-B4A-C4AC18-C4ACB2(4AB18-B4A2B)4AB18-B4ABC4AC18-C4AC-4AC18-C4A2-4AC18-C4A3-4A18-4A5-2AC4BAC6BCA4BC2A8-C2BCB10-BC2BC10-C2BCA10-AC2BC8-8ACA4CAC8A5-4A18-4A3-5A18-5A2-5A18-5A-2(C5A18-5ACB5A18-5AB)C5A18-5AC-5A18-5A2-5A18-5A3-4A18-4A5-8ACA4CAC8A8-C2BCA10-AC2B2(C10-2(CA))C8-7AC2BC2AC2BC7A5-4A18-4A3-5A18-5A2-5A18-5A-6A18-12A18-6AC5A18-5AC6A18-12A18-6A-5A18-5A2-5A18-5A3-4A18-4A5-7AC2BC2AC2BC7A8-2(2(CA)C10-)2B2CA10-A2C2B8-7A3BC2BC3B7A5-4A3CA2C6B2CA3C4A3-5A18-5A2-5A18-5A-B5A18-5AB6A2(18-12A)18-6AB5A18-5AB-5A18-5A2-5A18-5A3-4A18-4A5-7A3BC2BC3B7A8-2B2CA10-A2C2B2(10-2(BC)B)8-7ABCB4ABCB7A5-26A3-5A18-5A2-5A18-5A-2(6A18-6AC5A18-5AC)6A18-6A-5A18-5A2-5A18-5A3-4A18-4A5-7ABCB4ABCB7A8-2(2(BC)B10-)CA2CA10-A2CAC8-7ACBC4BCBC7A5-26A3-28A2-7A4B6A4B7A-C6A6B4A6B6A2C5A8B2A8B5ACB5A8B2A8B5ABC5A8B2A8B5A2C5A8B2A8B5AC-6A6B4A6B6A2-7A4B6A4B7A3-26A5-7ACBC4BCBC7A8-CA2CA10-A2CAC5-
