model
size = 30 15 12, scale = 0.05, origin = -y
material deform = 1, fade = true, lighting = smooth, roughness = 0.3, metalness = 0.6
  colors = A:#C0C B:#F09 C:#555
voxels
6-3ABA10-AB3A9-AB3A10-3ABA8-A2B4A2BAB2ABA2B4A2BA5-2(2BA)B4A4B4AB2(A2B)3-2BAB2A2(2BA3BA)2B2ABA2B2-2B2ABA2BAB2A4B2ABA2BAB2A2B-AB4AB2A2B2A4B2A2B2AB4ABA2BAB2A2B2A3B4A3B2A2B2ABA2B2A2BABA5B6A5BABA2B2ABA2BABA3B3AB2AB3A3BABA2BA2(B3A)B5AB2AB5A2(B3A)-B2A2B6ABA2BAB6A2B2AB2-BA2B3A2(BA)B4A2(BA)B3A2BAB3-B3AB2AB4A2B4AB2AB3AB5-B4ABA2(2B2A)2BAB4AB153-A4(28-2A)28-A241-A26-A2-A26-A-2A4(26-4A)26-2A-A26-A2-A26-A153-A24-A3-2A24-2A2-2A24-2A-3A4(24-6A)24-3A-2A24-2A2-2A24-2A3-A24-A95-A22-A5-2A22-2A3-3A22-3A2-3A22-3A-4A4(22-8A)22-4A-3A22-3A2-3A22-3A3-2A22-2A5-A22-A66-2A20-2A5-3A20-3A3-4A20-4A2-4A20-4A-5A20-10A20-5AB4A20-4AB5A20-10A20-5A-4A20-4A2-4A20-4A3-3A20-3A5-2A20-2A38-5A10-5A8-24A5-4A18-4A3-5A18-5A2-5A18-5A-6A4(18-12A)18-6A-5A18-5A2-5A18-5A3-4A18-4A5-24A8-3(5A10-)5A8-24A5-4A18-4A3-5A18-5A2-5A18-5A-6A4(18-12A)18-6A-5A18-5A2-5A18-5A3-4A18-4A5-24A8-2(5A10-)A3BA10-A3BA8-8AB6AB8A5-4A18-4A3-5A18-5A2-5A18-5A-6A18-6AB2(5A18-5A2B)5A18-5AB6A18-6A-5A18-5A2-5A18-5A3-4A18-4A5-8AB6AB8A8-2(A3BA10-)2ABAB10-BAB2A8-7A2B6A2B7A5-26A3-5A18-5A2-5A18-5A-6A4(18-12A)18-6A-5A18-5A2-5A18-5A3-4A18-4A5-7A2B6A2B7A8-2ABAB10-BAB2A2(10-5A)8-24A5-26A3-5A18-5A2-5A18-5A-B5A18-5AB6A2(18-12A)18-6AB5A18-5AB-5A18-5A2-5A18-5A3-4A18-4A5-24A8-3(5A10-)5A8-11A2B11A5-26A3-28A2-7A4C6A4C7A-7A6C4A6C13A3(8C2A8C12A)8C2A8C6A-6A6C4A6C6A2-7A4C6A4C7A3-26A5-11A2B11A8-5A10-5A5-
