model
size = 30 15 12, scale = 0.05, origin = -y
material deform = 1, fade = true, lighting = smooth, roughness = 0.3, metalness = 0.6
  colors = A:#369 B:#800 C:#006
voxels
6-A2B2A10-2A2BA9-2ABCB10-BCB2A8-4ABC12ACB4A5-3AC3B12A3BC3A3-2AB2(AC)2A2C2B2A2B2C2A2(CA)B2A2-BABC4ABC2BC2AC2BCB4ACBAB-AB4A3(CBC2A)CBC4ABACBCABC6AB4AB6ACBACBCAB2ABAC4AC6AC4ACAB2ABAB2AC2A2(BACA)2B2(ACAB)2AC2ABCA2CB5ABCBA2CABCB5AB2CAC-BCA2B3AB2AB4AB2AB3A2BACB2-2(AB)A3CAC8ACA3C2(AB)A3-AB2ACB3ACB4ABC3ABC2ABA5-2B5A2B2A2C2A2B5A2B153-A28-AB28-2B28-BA28-2A28-A241-B26-B2-A26-A-BA26-A2BA26-AB2A26-2ABA26-A3B26-2B-B26-B2-A26-A153-B24-B3-2A24-2A2-2A24-2A-2(3A24-3AC2A24-2AC)2AC24-C2A-2A24-2A2-AC24-CA3-B24-B95-A22-A5-AB22-BA3-3A22-3A2-2AC22-C2A-C3A22-3A2C3A22-3AC4A22-4AC2AB22-B2A2C2AC22-C2AC-3A22-3A2-2AB22-B2A3-AB22-BA5-A22-A66-AB20-BA5-3A20-3A3-3AB20-B3A2-3AB20-B3A-C4A20-4AC5A20-9AB20-B9A20-5AC3AC20-C3AC-4A20-4A2-4A20-4A3-2AB20-B2A5-2A20-2A38-2CACA10-ACA2C8-2ACAB2ABAB4ABAB2ABAC2A5-3AC18-C3A3-5A18-5A2-5A18-5A-B4AC18-C4A2B5A18-5ABC4AC18-C4ACB4AC18-C4A2B4AC18-C4AB-5A18-5A2-5A18-5A3-3AB18-B3A5-2A2(BAC)A2C2B2CA2(CAB)2A8-2(2(BC)B10-)5A10-5A8-24A5-4A18-4A3-5A18-5A2-5A18-5A-B4(5A18-5A2B)5A18-5AB-5A18-5A2-5A18-5A3-4A18-4A5-24A8-3(5A10-)5A8-24A5-4A18-4A3-5A18-5A2-5A18-5A-C5A18-5AC6A18-6AB5A18-5AB6A18-6AC5A18-5AC-5A18-5A2-5A18-5A3-4A18-4A5-24A8-3(5A10-)5A8-24A5-7ABCA6BACB7A3-5A18-5A2-5A18-5A-B5A18-5A2B5A18-5AB6A18-6AB5A18-5A2B5A18-5AB-5A18-5A2-5A18-5A3-4A18-4A5-24A8-3(5A10-)5A8-24A5-26A3-5A18-5A2-5A18-5A-C5A18-5A2C5A18-5ACB5A18-5ABC5A18-5A2C5A18-5AC-5A18-5A2-5A18-5A3-4A18-4A5-24A8-3(5A10-)5A8-24A5-26A3-28A2-7A4B6A4B7A-C6A6B4A6B6A2C5A8B2A8B5ACB5A8B2A8B5ABC5A8B2A8B5A2C5A8B2A8B5AC-6A6B4A6B6A2-7A4B6A4B7A3-26A5-24A8-5A10-5A5-
