model
size = 30 15 12, scale = 0.05, origin = -y
material deform = 1, fade = true, lighting = smooth, roughness = 0.3, metalness = 0.6
  colors = A:#6F6 B:#09F C:#0CF
voxels
6-3ACB10-BC3A9-ABA2B10-2BABA8-CB4ACA3B2C3BAC4ABC5-AB3ABAC3A4C3ACAB3ABA3-BA2B2C3ABCB4ABCB3A2C2BAB2-2A2CB5ABCB2ABCB5AB2C2A-2AB2A2BAC5A2B5ACA2B2AB4AB3A7B4C7B3AB2A2C2(ABC)2(AC)AB2CB3(AC)BACBA2C2(ABC)3ABAB2A2B2ABAB3ACBACB3A2B3ABCABACB2ABCABACB3A2B2A-2ACA2B2C3AB4AB3A2C2BAC2A2-4ACB2A2BC2B2C2BC2B2ABC4A3-4AC2A2B2(2CB)2C2B2AC4A5-3A2(2B2A)2C2(2A2B)3A153-A28-AB28-BC28-CB28-2B28-B241-A26-A2-A26-A-2A26-3AB26-B2AB26-B3A26-4A26-2A-A26-A2-A26-A153-A24-A3-AC24-CA2-AB24-BA-2AB2(24-2(B2A)24-2(2AB))24-B2A-AC24-CA2-AC24-CA3-A24-A95-A22-A5-AC22-CA3-3A22-3A2-3A22-3A-C2AB22-B2AC4A2(22-8A)22-4AC2AB22-B2AC-2AB22-B2A2-3A22-3A3-AB22-BA5-A22-A66-AB20-BA5-3A20-3A3-4A20-4A2-4A20-4A-C4A20-4A2C4A20-4ACB3AC20-2(C3AB)20-B3A2C3AC20-C3AC-4A20-4A2-3AC20-C3A3-3A20-3A5-AC20-CA38-C3AC10-C3AC8-2A2C2(2AC)4A2(C2A)2C2A5-4A18-4A3-5A18-5A2-5A18-5A-5AC18-C5A2(B5A18-5AB6A18-6A)-5A18-5A2-4AC18-C4A3-4A18-4A5-3AC5ACA2BAC5AC3A8-2(2AB2A10-)5A10-5A8-24A5-4A18-4A3-5A18-5A2-5A18-5A-2(6A18-6AC5A18-5AC)6A18-6A-5A18-5A2-5A18-5A3-4A18-4A5-24A8-3(5A10-)5A8-24A5-4A18-4A3-5A18-5A2-5A18-5A-2(B5A18-5AB6A18-6A)B5A18-5AB-5A18-5A2-5A18-5A3-4A18-4A5-24A8-3(5A10-)5A8-24A5-4A2CB2ACAB2ABAC2AB2C4A2(3-5A18-5A2-5A18-5A-B5A18-5AB6A2(18-12A)18-6AB5A18-5AB-5A18-5A2-5A18-5A3-4A18-4A5-24A8-3(5A10-)5A8-24A5-26A)3-28A2-7A4B6A4B7A-7A6B4A6B13A8B2A8B6AB5A8B2A8B5AB6A8B2A8B12A8B2A8B6A-6A6B4A6B6A2-7A4B6A4B7A3-26A5-24A8-5A10-5A5-
