model
size = 30 15 12, scale = 0.05, origin = -y
material deform = 1, fade = true, lighting = smooth, roughness = 0.3, metalness = 0.6
  colors = A:#060 B:#6C6 C:#CF3
voxels
6-2B2AB10-B2A2B9-ACABC10-CBACA8-CB2C4AC2B2A2BC4A2CBC5-2(CA)2(B2A)CB2ABC2(2AB)2(AC)3-BACA3B5A4C5A3BACAB2-ABAC4ABAC6ACAB4ACABA-ACB3ABACA3B4A3BACAB3ABC3ABABC2ABAC2A4C2ACAB2ACBAB3A3C5ACB2A4B2ABC5A3C3AB2CBCBAB4A2B4ABABCB2CB2AC3B2(AC)2AB8AB2A2(CA)3BC-BC2(BA)3(B4A)2(BA)BCB2-CA2C3BACB8ABCA3B2CAC3-BAB2CAC2BABA2CABA2BCA2CBAB5-C2AB6AC2AC6AB2AC153-A4(28-2A)28-A241-A26-A2-A26-A-2A4(26-4A)26-2A-A26-A2-A26-A153-A24-A3-2A24-2A2-2A24-2A-3A4(24-6A)24-3A-2A24-2A2-2A24-2A3-A24-A95-A22-A5-2A22-2A3-3A22-3A2-3A22-3A-4A4(22-8A)22-4A-3A22-3A2-3A22-3A3-2A22-2A5-A22-A66-2A20-2A5-3A20-3A3-4A20-4A2-4A20-4A-C4A20-4A2C4A20-4AC5A20-5AC4A20-4A2C4A20-4AC-4A20-4A2-4A20-4A3-3A20-3A5-2A20-2A38-5A10-5A8-24A5-4A18-4A3-5A18-5A2-5A18-5A-C5A18-5AC6A18-6AB5A18-5AB6A18-6AC5A18-5AC-5A18-5A2-5A18-5A3-4A18-4A5-24A8-3(5A10-)5A8-24A5-4A18-4A3-5A18-5A2-5A18-5A-6A18-12A18-6AC5A18-5AC6A18-12A18-6A-5A18-5A2-5A18-5A3-4A18-4A5-24A8-3(5A10-)5A8-24A5-4A18-4A3(3-5A18-5A2-5A18-5A-6A4(18-12A)18-6A-5A18-5A2-5A18-5A3-4A18-4A5-24A8-3(5A10-)5A8-24A5-26A)3-28A2-7A4B6A4B7A-7A6B4A6B13A3(8B2A8B12A)8B2A8B6A-6A6B4A6B6A2-7A4B6A4B7A3-26A5-24A8-5A10-5A5-
