model
size = 30 15 12, scale = 0.05, origin = -y
material deform = 1, fade = true, lighting = smooth, roughness = 0.3, metalness = 0.6
  colors = A:#500 B:#F36 C:#6F3
voxels
6-BCABC10-CBACB9-3BCA10-AC3B8-2C9A2B9A2C5-2(CA)4(BA)2B4(AB)2(AC)3-BA2B4ACAC6ACAC4A2BAB2-2C2A2CABCB8ABCBA2C2A2C-CA2C2A2B2(4AB)4A2B2A2(2CA)CAC3AC2B8A2BC3A2(CA)C2AC2B2ABAB3AC2AC3ABAB2A2BC4AB2A3B5AB2CB5A3B2AB3ABAC2B7AC2BC7A2BCABA-CBACA3BABA6CABA3BACABC2-3ACACBA2B3A2C3A2BABCAC3A3-2A2(C2ABA)2C2(AB2AC)2A5-2B2A2CA3(B2A)BA2C2A2B153-A4(28-2A)28-A241-A26-A2-A26-A-2A4(26-4A)26-2A-A26-A2-A26-A153-A24-A3-2A24-2A2-2A24-2A-3A24-6A24-3AC2A24-2AC3A24-6A24-3A-2A24-2A2-2A24-2A3-A24-A95-A22-A5-2A22-2A3-3A22-3A2-3A22-3A-4A22-4AC3A22-3ACB3A22-3ABC3A22-3AC4A22-4A-3A22-3A2-3A22-3A3-2A22-2A5-A22-A66-2A20-2A5-3A20-3A3-4A20-4A2-4A20-4A-2(5A20-5AC4A20-4AC)5A20-5A-4A20-4A2-4A20-4A3-3A20-3A5-2A20-2A38-5A10-5A8-24A5-4A18-4A3-5A18-5A2-5A18-5A-2(B5A18-5AB6A18-6A)B5A18-5AB-5A18-5A2-5A18-5A3-4A18-4A5-24A8-3(5A10-)5A8-24A5-4A18-4A3-5A18-5A2-5A18-5A-C4(5A18-5A2C)5A18-5AC-5A18-5A2-5A18-5A3-4A18-4A5-24A8-3(5A10-)5A8-24A5-4A18-4A3-5A18-5A2-5A18-5A-6A18-6AC5A18-5ACB5A18-5ABC5A18-5AC6A18-6A-5A18-5A2-5A18-5A3-4A18-4A5-24A8-3(5A10-)5A8-24A5-26A3-5A18-5A2-5A18-5A-B5A18-5ABC5A18-5AC6A18-6AC5A18-5ACB5A18-5AB-5A18-5A2-5A18-5A3-4A18-4A5-24A8-3(5A10-)5A8-24A5-26A3-5A18-5A2-5A18-5A-C5A18-5A2C5A18-5AC6A18-6AC5A18-5A2C5A18-5AC-5A18-5A2-5A18-5A3-4A18-4A5-24A8-3(5A10-)5A8-24A5-26A3-28A2-7A4B6A4B7A-C6A6B4A6B6A2(C6A8B2A8B6AC5A8B2A8B5A)C-6A6B4A6B6A2-7A4B6A4B7A3-26A5-24A8-5A10-5A5-
