model
size = 30 15 12, scale = 0.05, origin = -y
material deform = 1, fade = true, lighting = smooth, roughness = 0.3, metalness = 0.6
  colors = A:#960 B:#200 C:#6C6
voxels
6-ABCBA10-ABCBA9-CABAC10-CABAC8-B2ABA3CABA2CABA3CAB2AB5-2CA2BACB3(C2A)CBCA2BA2C3-B2AC2ABA3CAC2ACA3CAB2AC2AB2-3BC3A2CABC4ACBA2C3AC3B-2(BA)5C2(BC)4B2(CB)5C2(AB)A2B2AB2ACBC2B4A2BCBC2AB2A2B2AC3A2C3ACAB4CBAC3A2C3AC3AB3A3C2ABA4CAB2A3C3AB3AC2B2C2A2BCA6CAC2B2A2C2BCA-AC3AC2(2AB)C2AC2(B2A)C3ACA2-C2ACAB2AC2B2A2C2A2BC2ABAC2AC3-B6ACABCB2ABCBAC6AB5-CB4A2(BA)B2A2(BA)B4ABC153-A4(28-2A)28-A241-A26-A2-A26-A-2A4(26-4A)26-2A-A26-A2-A26-A153-A24-A3-2A24-2A2-2A24-2A-3A4(24-6A)24-3A-2A24-2A2-2A24-2A3-A24-A95-A22-A5-2A22-2A3-3A22-3A2-3A22-3A-4A4(22-8A)22-4A-3A22-3A2-3A22-3A3-2A22-2A5-A22-A66-2A20-2A5-3A20-3A3-4A20-4A2-4A20-4A-5A4(20-10A)20-5A-4A20-4A2-4A20-4A3-3A20-3A5-2A20-2A38-5A10-3(5A8-24A5-4A18-4A3-5A18-5A2-5A18-5A-6A4(18-12A)18-6A-5A18-5A2-5A18-5A3-4A18-4A5-24A8-3(5A10-))2(5A8-24A5-26A3-5A18-5A2-5A18-5A-6A4(18-12A)18-6A-5A18-5A2-5A18-5A3-4A18-4A5-24A8-3(5A10-))5A8-24A5-26A3-28A2-7A4B6A4B7A-7A6B4A6B13A3(8B2A8B12A)8B2A8B6A-6A6B4A6B6A2-7A4B6A4B7A3-26A5-24A8-5A10-5A5-
