model
size = 30 15 12, scale = 0.05, origin = -y
material deform = 1, fade = true, lighting = smooth, roughness = 0.3, metalness = 0.6
  colors = A:#363 B:#609 C:#0B0
voxels
6-2BABA10-ABA2B9-2(AB)A10-2(AB)A8-A2BAB3ABAB2ABAB3ABA2BA5-2A2BAB2(2A4B)2ABA2B2A3-3B2AB3A10B3AB2A3B2-A2BA3BA12BA3BA2BA-2B2(AB)2A3BAB4ABA3B2A2(BA)2BA3BAB4AB3A2B3AB4ABA3B3(AB)2A2(2B5A)2B2A2(BA)2B2AB2A2B2A10B2A2B2AB2A2B3ABA2B2AB8AB2A2BAB3AB-11AB4AB11A2-2A5B2(AB)2A2B2A2(BA)5B2A3-2B5A2B8A2B5A2B5-BAB2A4BAB2ABA4B2ABAB153-A4(28-2A)28-A241-A26-A2-A26-A-2A4(26-4A)26-2A-A26-A2-A26-A153-A24-A3-2A24-2A2-2A24-2A-3A4(24-6A)24-3A-2A24-2A2-2A24-2A3-A24-A95-A22-A5-2A22-2A3-3A22-3A2-3A22-3A-4A4(22-8A)22-4A-3A22-3A2-3A22-3A3-2A22-2A5-A22-A66-2A20-2A5-3A20-3A3-4A20-4A2-4A20-4A-5A4(20-10A)20-5A-4A20-4A2-4A20-4A3-3A20-3A5-2A20-2A38-5A10-5A8-24A5-4A18-4A3-5A18-5A2-5A18-5A-6A4(18-12A)18-6A-5A18-5A2-5A18-5A3-4A18-4A5-24A8-3(5A10-)5A8-24A5-4A18-4A3-5A18-5A2-5A18-5A-6A4(18-12A)18-6A-5A18-5A2-5A18-5A3-4A18-4A5-24A8-2(5A10-)AB3A10-3ABA8-9AB4AB9A5-4A18-4A3-5A18-5A2-5A18-5A-6A4(18-12A)18-6A-5A18-5A2-5A18-5A3-4A18-4A5-9AB4AB9A8-AB3A10-3ABA10-B2ABA10-AB2AB8-7AB3A2B3AB7A5-26A3-5A18-5A2-5A18-5A-6A4(18-12A)18-6A-5A18-5A2-5A18-5A3-4A18-4A5-7AB3A2B3AB7A8-B2ABA10-AB2AB10-AB3A10-3ABA8-24A5-26A3-5A18-5A2-5A18-5A-6A4(18-12A)18-6A-5A18-5A2-5A18-5A3-4A18-4A5-24A8-AB3A10-3ABA2(10-5A)8-9AB4AB9A5-26A3-28A2-7A4C6A4C7A-7A6C4A6C13A3(8C2A8C12A)8C2A8C6A-6A6C4A6C6A2-7A4C6A4C7A3-26A5-9AB4AB9A8-5A10-5A5-
