model
size = 30 15 12, scale = 0.05, origin = -y
material deform = 1, fade = true, lighting = smooth, roughness = 0.3, metalness = 0.6
  colors = A:#0A0 B:#FFC C:#63C
voxels
6-B2ACA10-AC2AB9-2ABCA10-ACB2A8-CB2A2C2A8C2A2C2ABC5-4A3BA2BAC2BCA2BA3B4A3-B2AB3AC2AC6AC2AC3AB2AB2-3CB2A2BC2AB4AB2AC2B2AB3C-ACBABCBA2BABC4ACBA2BABCBABC3(AB)4A2BA2B2A2BA2B4A2(BA)2BAC4AB2ABCBA2CABCB2AB4AC2(AB)A2CAC2ABCA2B2A2BACB2ACA2CAB2(A2C)A3C2ABCB2CBCB2A3C2(A2C)-AB5AC2A3C2B3C2AC5ABA2-3A2CB2C2(AC)4B2(CA)2CB2C3A3-BC3AB2AC3A2C3AC2AB3ACB5-AC4AB2C6A2CB4ACA153-C28-CA28-AC28-CB28-BC28-C241-A26-A2-B26-B-AB26-2(BA)26-A2BC26-C2BA26-2(AB)26-BA-A26-A2-C26-C153-B24-B3-AB24-BA2-AB24-BA-B2A24-2(2AB)24-B2AC2A24-2(2AC)24-C2ABAB24-BAB-AC24-CA2-AB24-BA3-C24-C95-A22-A5-AC22-CA3-2AC22-C2A2-3A22-3A-3AB22-B3AC2AB22-B2AC3AC22-C3AC2AB22-B2AC3AB22-B3A-3A22-3A2-2AB22-B2A3-AC22-CA5-C22-C66-AC20-CA5-3A20-3A3-3AB20-B3A2-3AC20-C3A-4AB20-B9A20-5AC4A20-4AC4AB20-B8AB20-B4A-3AC20-C3A2-3AB20-B3A3-2AC20-C2A5-AB20-BA38-C2ABA10-AB2AC8-2AC3A2BCA4BAC2B3AC2A5-4A18-4A3-5A18-5A2-4AC18-C4A-6A18-11AC18-C10AB18-B10AC18-C11A18-6A-4AC18-C4A2-4AB18-B4A3-4A18-4A5-3A2CAC10ACA2C3A8-4CB10-B4C2(10-5A)8-24A5-4A18-4A3-5A18-5A2-5A18-5A-6A4(18-12A)18-6A-5A18-5A2-5A18-5A3-4A18-4A5-24A8-3(5A10-)5A8-24A5-4A18-4A3-5A18-5A2-5A18-5A-B5A18-5A2B5A18-5AB6A18-6AB5A18-5A2B5A18-5AB-5A18-5A2-5A18-5A3-4A18-4A5-24A8-3(5A10-)5A8-24A5-4A2BA2B3A2C3A2BA2B4A3-5A18-5A2-5A18-5A-6A18-12A18-6AC5A18-5AC6A18-12A18-6A-5A18-5A2-5A18-5A3-4A18-4A5-24A8-3(5A10-)5A8-24A5-26A3-5A18-5A2-5A18-5A-C5A18-5AC6A2(18-12A)18-6AC5A18-5AC-5A18-5A2-5A18-5A3-4A18-4A5-24A8-3(5A10-)5A8-24A5-26A3-28A2-7A4B6A4B7A-B6A6B4A6B6A2(B6A8B2A8B6AB5A8B2A8B5A)B-6A6B4A6B6A2-7A4B6A4B7A3-26A5-24A8-5A10-5A5-
