model
size = 30 15 12, scale = 0.05, origin = -y
material deform = 1, fade = true, lighting = smooth, roughness = 0.3, metalness = 0.6
  colors = A:#C0C B:#001 C:#390
voxels
6-2(AB)A10-2(AB)A9-A3BA10-A3BA8-A2BA2(4B2A)4BA2BA5-2B2A2B3ABAB2ABAB3A2B2A2B3-A2BABA5B2A2B2A5BABA2BA2-B2A2(BA)3B3A2B3A3B2(AB)2AB-A2B2(AB)2A2(2B3A)2B2A2(BA)2B4A2BAB5(A2B)ABA2B3A10B2(AB)2A2(BA)10B2ABA3B3ABA6BAB3A3BAB8ABAB2AB6AB2ABAB6A-6ABA2B2A4B2A2BAB6A2-BA2B2A2BAB8ABA2B2A2BAB3-4A2B2(2A4B)2A2B4A5-2(BA)3(B4A)2(BA)B153-B28-BA28-AB28-2B28-BA28-A241-A26-A2-B26-B-BA26-A3B26-2BAB26-2(BA)26-A3B26-2B-B26-B2-A26-A153-A24-A3-2A24-2A2-2A24-2A-2A2(B24-B5A24-5A)B24-B2A-AB24-BA2-AB24-BA3-A24-A95-B22-B5-AB22-BA3-2AB22-B2A2-3A22-3A-3AB22-B3AB2AB22-B2A2B3A22-3A2B2AB22-B2AB4A22-4A-2AB22-B2A2-3A22-3A3-AB22-BA5-B22-B66-2A20-2A5-2AB20-B2A3-4A20-4A2-3AB20-B3A-B3AB20-B3A2B4A20-4A2(2B3AB20-B3A)2B4A20-4AB-4A20-4A2-3AB20-B3A3-2AB20-B2A5-2A20-2A38-AB3A10-3ABA8-3ABA4B6A4BAB3A5-4A18-4A3-5A18-5A2-5A18-5A-6A18-6AB4AB18-B4A2(2B5A18-5A)B6A18-6A-5A18-5A2-4AB18-B4A3-3AB18-B3A5-2ABAB2A2BAB2ABA2B2ABAB2A8-2(5B10-)2BABA10-ABA2B8-7A3B4A3B7A5-4A18-4A3-5A18-5A2-5A18-5A-6A4(18-12A)18-6A-5A18-5A2-5A18-5A3-4A18-4A5-7A3B4A3B7A8-2BABA10-ABA2B10-3B2A10-2A3B8-9A6B9A5-4A18-4A3-5A18-5A2-5A18-5A-B4(5A18-5A2B)5A18-5AB-5A18-5A2-5A18-5A3-4A18-4A5-9A6B9A8-3B2A10-2A3B10-B4A10-4AB8-8A2(2BA)2B8A5-4A4B2ABA2BAB2A4B4A3-5A18-5A2-5A18-5A-6A4(18-12A)18-6A-5A18-5A2-5A18-5A3-4A18-4A5-8A2(2BA)2B8A8-B4A10-4AB10-3ABA10-AB3A8-7A2(2B2A)2B7A5-26A3-5A18-5A2-5A18-5A-B4(5A18-5A2B)5A18-5AB-5A18-5A2-5A18-5A3-4A18-4A5-7A2(2B2A)2B7A8-3ABA10-AB3A10-B2A2B10-2B2AB8-7A2B6A2B7A5-26A3-28A2-7A4C6A4C7A-B6A6C4A6C6A2B5A8C2A8C5AB6A8C2A8C6AB5A8C2A8C5A2B5A8C2A8C5AB-6A6C4A6C6A2-7A4C6A4C7A3-26A5-7A2B6A2B7A8-B2A2B10-2B2AB5-
