model
size = 30 15 12, scale = 0.05, origin = -y
material deform = 1, fade = true, lighting = smooth, roughness = 0.3, metalness = 0.6
  colors = A:#6F0 B:#960 C:#100
voxels
6-2AB2C10-2CB2A9-2ABAC10-CAB2A8-4A2C2BAB4CBA2B2C4A5-3ACABCBABC4ACBABCBAC3A3-BAB2(C2A)2B6A2B2(2AC)BAB2-2AB2A3BC10AC3B2AB2A-A2CAC2AC2(AB)AC2BC2(AB)AC2ACA2CA2B3ACAB3A2B4A2B3ABAC3A3B3ACA2(BC)3AC2AC3A2(CB)AC3AB3ACACBABCAC2B2A2BCACBABCAC5AC2A2C2ACBA2B2A2BABC2A2C2AC2A-ACA2CAC14ACA2CACA2-A2B2AC4AB6AB4AC2A2BA3-2ABC6ACA2BAC6ACB2A5-2ACA3B10A3BAC2A153-C28-CA28-2A28-AB28-2B28-B241-A26-A2-C26-C-BA26-A2BA26-2(AB)26-2(BA)26-A2BC26-CB-A26-A2-C26-C153-A24-A3-2A24-2A2-2A24-2A-3A24-5AC24-C5A24-6A24-5AC24-C2A-2A24-2A2-AC24-CA3-C24-C95-A22-A5-AC22-CA3-2AC22-C2A2-3A22-3A-C2AC22-C2ACB3A22-3ABC3A22-3ACB3A22-3ABC2AC22-C2AC-3A22-3A2-3A22-3A3-2A22-2A5-B22-B66-AC20-CA5-3A20-3A3-3AC20-C3A2-4A20-4A-4AB20-B8AC20-C4AC3AB20-B3AC4AC20-C9A20-5A-4A20-4A2-4A20-4A3-3A20-3A5-AC20-CA38-2ABAB10-BAB2A8-7ABC2B2A2BCB7A5-4A18-4A3-4AB18-B4A2-4AB18-B4A-5AC18-2(C5A)18-5ACB5A18-5ABC5A18-5AC5AB18-B5A-5A18-5A2-4AB18-B4A3-3AC18-C3A5-4ABAB3AB2AB3ABAB4A8-AC2BA10-A2BCA2(10-5A)8-24A5-4A18-4A3-5A18-5A2-5A18-5A-C5A18-5A2C5A18-5ACB5A18-5ABC5A18-5A2C5A18-5AC-5A18-5A2-5A18-5A3-4A18-4A5-24A8-3(5A10-)5A8-24A5-4A18-4A3-5A18-5A2-5A18-5A-B5A18-5AB6A2(18-12A)18-6AB5A18-5AB-5A18-5A2-5A18-5A3-4A18-4A5-24A8-3(5A10-)5A8-24A5-4A2B3CB2C2A2CB3C2B4A3-5A18-5A2-5A18-5A-C4(5A18-5A2C)5A18-5AC-5A18-5A2-5A18-5A3-4A18-4A5-24A8-3(5A10-)5A8-24A5-26A3-5A18-5A2-5A18-5A-6A4(18-12A)18-6A-5A18-5A2-5A18-5A3-4A18-4A5-24A8-3(5A10-)5A8-24A5-26A3-28A2-7A4B6A4B7A-7A6B4A6B13A3(8B2A8B12A)8B2A8B6A-6A6B4A6B6A2-7A4B6A4B7A3-26A5-24A8-5A10-5A5-
