model
size = 30 15 12, scale = 0.05, origin = -y
material deform = 1, fade = true, lighting = smooth, roughness = 0.3, metalness = 0.6
  colors = A:#063 B:#070 C:#606
voxels
6-A2CAB10-BA2CA9-C2BCA10-AC2BC8-C2BACAB2(CA)2B2(AC)BACA2BC5-A2BAB2CB2ABA2CAB2AB2CBA2BA3-B2CBC3AC2(BA)2B2(AB)C3ACB2CB2-CA2BC5AB6AB5AC2BAC-CB3CBAB2C3BC2AC3B2CBA2(B3C)6A2BAB6ABA2B6A2C2(AB)2ABACA2CAC2ACA2CACAB2ABAB4ACACB4ACAB2ABAC4ABCAC3AC2A5(BA)C2AC5(AB)2AC-2(AC)B4A2CBC2ACB2C4AB2(CA)2-ABAC3A2(BC)2A2C2A2(CB)3ACABA3-2B2CA2(CB)CAC2BCA2(CB)CA2C2B5-4ACB2ABCA2CACB2ABC4A153-A4(28-2A)28-A241-A26-A2-A26-A-2A4(26-4A)26-2A-A26-A2-A26-A153-A24-A3-2A24-2A2-2A24-2A-3A4(24-6A)24-3A-2A24-2A2-2A24-2A3-A24-A95-A22-A5-2A22-2A3-3A22-3A2-3A22-3A-4A4(22-8A)22-4A-3A22-3A2-3A22-3A3-2A22-2A5-A22-A66-2A20-2A5-3A20-3A3-4A20-4A2-4A20-4A-5A4(20-10A)20-5A-4A20-4A2-4A20-4A3-3A20-3A5-2A20-2A38-5A10-3(5A8-24A5-4A18-4A3-5A18-5A2-5A18-5A-6A4(18-12A)18-6A-5A18-5A2-5A18-5A3-4A18-4A5-24A8-3(5A10-))2(5A8-24A5-26A3-5A18-5A2-5A18-5A-6A4(18-12A)18-6A-5A18-5A2-5A18-5A3-4A18-4A5-24A8-3(5A10-))5A8-24A5-26A3-28A2-7A4B6A4B7A-7A6B4A6B13A3(8B2A8B12A)8B2A8B6A-6A6B4A6B6A2-7A4B6A4B7A3-26A5-24A8-5A10-5A5-
