model
size = 30 15 12, scale = 0.05, origin = -y
material deform = 1, fade = true, lighting = smooth, roughness = 0.3, metalness = 0.6
  colors = A:#C93 B:#CC0 C:#636
voxels
6-BA2BA10-A2BAB9-3BAB10-BA3B8-2B4A3B6A3B4A2B5-BA3BAB2AB6AB2ABA3BAB3-4B2(2AB)ABA2B2(AB)2AB2A4B2-2AB2A5BABA2BABA5B2AB2A-3A3BA4BA2B2A2BA4BA3B7ABA2(B2A2(BA))B2ABA2(B4A)3B2A2BA4BA2B2A3B4A3B2A2B2AB4A4B4AB3(2A2B)2A3BABA2B2A2BABA3B2A2B2A-2A3BA5B6A5BA3B2A2-2A4B3AB8AB3A4B2A3-BA2B3A4B4A4B3A2BAB5-BA4B3A2B2A2B3A4BAB153-A3(28-2A)28-AB28-B241-B26-B2-A26-A-2A26-4A26-3AB26-B3A26-4A26-2A-A26-A2-B26-B153-A24-A3-2A24-2A2-AB24-BA-2AB24-B5A2(24-6A)24-5AB24-B2A-2A24-2A2-2A24-2A3-B24-B95-A22-A5-AB22-BA3-2AB22-B2A2-2AB22-B2A-3AB22-B7A3(22-8A)22-4A-3A22-3A2-3A22-3A3-AB22-BA5-B22-B66-AB20-BA5-3A20-3A3-4A20-4A2-4A20-4A-4AB20-B9A20-10A20-9AB20-B8AB20-B4A-4A20-4A2-3AB20-B3A3-2AB20-B2A5-AB20-BA38-2(AB)A10-2(AB)A8-2AB7A4B7AB2A5-4A18-4A3-5A18-5A2-5A18-5A-6A2(18-12A)18-11AB18-B10AB18-B5A-5A18-5A2-4AB18-B4A3-3AB18-B3A5-2ABA4BA6BA4BAB2A8-2BABA10-ABA2B2(10-5A)2(8-24A5-4A18-4A3-5A18-5A2-5A18-5A-6A4(18-12A)18-6A-5A18-5A2-5A18-5A3-4A18-4A5-24A8-3(5A10-)5A)8-24A5-7AB3A4B3AB7A2(3-5A18-5A2-5A18-5A-6A4(18-12A)18-6A-5A18-5A2-5A18-5A3-4A18-4A5-24A8-3(5A10-)5A8-24A5-26A)3-28A2-7A4C6A4C7A-7A6C4A6C13A3(8C2A8C12A)8C2A8C6A-6A6C4A6C6A2-7A4C6A4C7A3-26A5-24A8-5A10-5A5-
