model
size = 30 15 12, scale = 0.05, origin = -y
material deform = 1, fade = true, lighting = smooth, roughness = 0.3, metalness = 0.6
  colors = A:#99C B:#0F3 C:#500
voxels
6-ABCAB10-BACBA9-2ABCB10-BCB2A8-B2CAB2ABACA2BACAB2ABA2CB5-2AC4AC2ACA2BAC2AC4AC2A3-2B2(CAB)CA3C2B3C2(ACB)AC2B2-3BAB2ACA2C6A2CAC2ABA3B-2(BA)BC3ABA3C2B3CAB3AC2(BA)B2A2BACA3C2(2A2B)2A3CACA2B3A2C2(AB)3AC3A2C3AC3A2(BA)2CAB2(A2C)2(AB)A6C2(AB)2(A2C)A2BA2(C3B)2ACA2CAC2A2(3BC)AB-2(AC)3AC2(BA)C2BC2(AB)C3A2(CA)2-ACB2A2C2ACABC2BCBAC2A2C2ABCA3-3BAB3ABCAC2ACACB3ABA3B5-2B2C2ABA2B4A2BAB2A2C2B153-A4(28-2A)28-A241-A26-A2-A26-A-2A4(26-4A)26-2A-A26-A2-A26-A153-A24-A3-2A24-2A2-2A24-2A-3A4(24-6A)24-3A-2A24-2A2-2A24-2A3-A24-A95-A22-A5-2A22-2A3-3A22-3A2-3A22-3A-4A4(22-8A)22-4A-3A22-3A2-3A22-3A3-2A22-2A5-A22-A66-2A20-2A5-3A20-3A3-4A20-4A2-4A20-4A-5A4(20-10A)20-5A-4A20-4A2-4A20-4A3-3A20-3A5-2A20-2A38-5A10-5A8-24A5-4A18-4A3-5A18-5A2-5A18-5A-6A4(18-12A)18-6A-5A18-5A2-5A18-5A3-4A18-4A5-24A8-2(5A10-)4CB10-B4C8-7A3(C2B)C7A5-4A18-4A3-5A18-5A2-5A18-5A-6A4(18-12A)18-6A-5A18-5A2-5A18-5A3-4A18-4A5-7A3(C2B)C7A8-4CB10-B4C10-C2B2C10-2C2BC8-7A2(BC)2B2(CB)7A5-4A18-4A3-5A18-5A2-5A18-5A-6A4(18-12A)18-6A-5A18-5A2-5A18-5A3-4A18-4A5-7A2(BC)2B2(CB)7A8-C2B2C10-2C2BC10-2ABAB10-BAB2A8-11A2C11A5-26A3-5A18-5A2-5A18-5A-6A4(18-12A)18-6A-5A18-5A2-5A18-5A3-4A18-4A5-11A2C11A8-2ABAB10-BAB2A10-2(BA)C10-C2(AB)8-7ACA2B2A2BAC7A5-26A3-5A18-5A2-5A18-5A-6A4(18-12A)18-6A-5A18-5A2-5A18-5A3-4A18-4A5-7ACA2B2A2BAC7A8-2(BA)C10-C2(AB)10-AC2AB10-B2ACA8-7ACA2C2A2CAC7A5-26A3-28A2-7A4B6A4B7A-7A6B4A6B13A3(8B2A8B12A)8B2A8B6A-6A6B4A6B6A2-7A4B6A4B7A3-26A5-7ACA2C2A2CAC7A8-AC2AB10-B2ACA5-
