model
size = 30 15 12, scale = 0.05, origin = -y
material deform = 1, fade = true, lighting = smooth, roughness = 0.3, metalness = 0.6
  colors = A:#903 B:#FCF C:#9F6
voxels
6-ABA2B10-2BABA9-2BABA10-ABA2B8-2A2BABA10BABA2B2A5-4A6BA4BA6B4A3-A2BA3B2ABA2B2A2BAB2A3BA2BA2-2(2BA)4BA6BA4B2(A2B)-4ABA7BA2BA7BAB5A3B2AB4ABAB2ABAB4AB2A3B3AB4ABA2(2B3A)2BAB4AB3A3B2(2A2B)AB2ABA2(2B2A)3BA2B3(AB)2AB3A2B3AB2A3(BA)2B-2A3B2(2AB4AB)2A3B2A2-4A3BA2B2(2AB)2A2BA3B4A3-2BAB2A3BA2B2A2BA3B2ABA2B5-2BAB2ABA3B2A3BAB2ABA2B153-B28-BA28-AB28-BA28-2A28-A241-A26-A2-B26-B-AB26-B3A3(26-4A)26-2A-A26-A2-A26-A153-A24-A3-AB24-BA2-2A24-2A-3A24-5AB24-B5A24-5AB24-B4AB24-B2A-2A24-2A2-2A24-2A3-A24-A95-A22-A5-2A22-2A3-3A22-3A2-3A22-3A-4A2(22-8A)22-7AB22-B7A22-4A-2AB22-B2A2-2AB22-B2A3-AB22-BA5-A22-A66-2A20-2A5-2AB20-B2A3-3AB20-B3A2-4A20-4A-5A2(20-10A)20-9AB20-B9A20-5A-4A20-4A2-4A20-4A3-3A20-3A5-2A20-2A38-2B2AB10-B2A2B8-2(2AB)A2(2B2A)2BA2(B2A)5-4A18-4A3-4AB18-B4A2-4AB18-B4A-6A4(18-12A)18-6A-4AB18-B4A2-5A18-5A3-4A18-4A5-8ABAB2ABAB8A8-2(2(BA)B10-)4AB10-B4A8-9AB4AB9A5-4A18-4A3-5A18-5A2-5A18-5A-6A4(18-12A)18-6A-5A18-5A2-5A18-5A3-4A18-4A5-9AB4AB9A8-4AB10-B4A2(10-2(AB)A)8-8AB6AB8A5-4A18-4A3-5A18-5A2-5A18-5A-6A4(18-12A)18-6A-5A18-5A2-5A18-5A3-4A18-4A5-8AB6AB8A8-2(2(AB)A10-)4AB10-B4A8-9AB4AB9A5-7AB2(2A2B)2AB7A3-5A18-5A2-5A18-5A-6A4(18-12A)18-6A-5A18-5A2-5A18-5A3-4A18-4A5-9AB4AB9A8-4AB10-B4A2(10-5A)8-9AB4AB9A5-26A3-5A18-5A2-5A18-5A-6A4(18-12A)18-6A-5A18-5A2-5A18-5A3-4A18-4A5-9AB4AB9A8-2(5A10-)AB3A10-3ABA8-7A2BA4BA2B7A5-26A3-28A2-7A4C6A4C7A-7A6C4A6C13A3(8C2A8C12A)8C2A8C6A-6A6C4A6C6A2-7A4C6A4C7A3-26A5-7A2BA4BA2B7A8-AB3A10-3ABA5-
