model
size = 30 15 12, scale = 0.05, origin = -y
material deform = 1, fade = true, lighting = smooth, roughness = 0.3, metalness = 0.6
  colors = A:#0F0 B:#020 C:#FF0
voxels
6-A2BAB10-BA2BA9-5B10-5B8-A3B2(2AB)A2BA2(B2A)3BA5-4BA2BA3B4A3BA2BA4B3-2A2BAB3A2(2B2A)2B3ABA2B2A2-2B3ABA4BAB2ABA4BAB3A2B-3BA7B3A2B3A7BA3B2(A2B)2ABA3B4A3BAB2A2BA2B2A2B3ABAB2AB6AB2ABAB3A2B3ABA2B2(AB)4A2B4A2(BA)2BAB3AB2A2B3A5B2A5B3A2B2ABA-B3A2B2A2(2B3A)2B2A2B3AB2-3A2B2A4BAB2ABA4B2A2B3A3-2A5B12A5B2A5-2A2B3AB8AB3A2B2A153-B3(28-2B)28-BA28-A241-B26-B2-B26-B-2A2(26-3AB26-B3A)26-2A-A26-A2-B26-B153-A24-A3-2A24-2A2-2A24-2A-2A3(B24-B4A)B24-B5A24-3A-AB24-BA2-AB24-BA3-A24-A95-A22-A5-2A22-2A3-2AB22-B2A2-3A22-3A-3AB22-B6AB22-B7A22-8A22-7AB22-B3A-3A22-3A2-2AB22-B2A3-AB22-BA5-B22-B66-AB20-BA5-2AB20-B2A3-4A20-4A2-4A20-4A-4AB20-B9A20-9A2(B20-B8A)B20-B4A-4A20-4A2-3AB20-B3A3-2AB20-B2A5-2A20-2A38-3BAB10-BA3B8-2A2(2BAB3ABA)2B2A5-3AB18-B3A3-5A18-5A2-5A18-5A-6A2(18-12A)18-11AB18-B11A18-6A-5A18-5A2-4AB18-B4A3-4A18-4A5-6AB2AB4AB2AB6A8-A2B2A10-2A2BA10-2B2AB10-B2A2B8-7A4B2A4B7A5-4A18-4A3-5A18-5A2-5A18-5A-6A4(18-12A)18-6A-5A18-5A2-5A18-5A3-4A18-4A5-7A4B2A4B7A8-2B2AB2(10-B2A2B)10-2B2AB8-8A8B8A5-4A18-4A3-5A18-5A2-5A18-5A-6A4(18-12A)18-6A-5A18-5A2-5A18-5A3-4A18-4A5-8A8B8A8-B2A2B10-2B2AB10-4BA10-A4B8-7ABA6BAB7A5-2(4ABA3BAB)4A3-5A18-5A2-5A18-5A-6A4(18-12A)18-6A-5A18-5A2-5A18-5A3-4A18-4A5-7ABA6BAB7A8-4BA10-A4B10-BA3B10-3BAB8-7A3BA2BA3B7A5-26A3-5A18-5A2-5A18-5A-6A4(18-12A)18-6A-5A18-5A2-5A18-5A3-4A18-4A5-7A3BA2BA3B7A8-BA3B10-3BAB2(10-5B)8-8A3B2A3B8A5-26A3-28A2-7A4C6A4C7A-7A6C4A6C13A3(8C2A8C12A)8C2A8C6A-6A6C4A6C6A2-7A4C6A4C7A3-26A5-8A3B2A3B8A8-5B10-5B5-
