model
size = 24 31 24, scale = 0.05, origin = -y
material deform = 1, fade = true, lighting = smooth, roughness = 0.3, metalness = 0.6
  colors = A:#AAA B:#00D C:#C0F D:#690 E:#63F F:#C90 G:#E00 H:#555 I:#F36 J:#F33 K:#FFC L:#609 M:#F99 N:#F6C O:#933
voxels
35-2B718-2H739-2B6A18-B3A21-2A689-4B8A13-BIB7A15-N2B5A18-B3A663-5B9A11-4B8A13-3B7A15-3B5A17-3B3A19-4B614-5EB9AB9-2CBCB9A10-BCJC2B3A3DAD11-CIC2B5ADA13-6B2(AD)15-C5BDB17-5BD19-4B565-7B9A2B7-2(CB)C2B7A2B8-7B3A2(DA)DB9-7B5A2B11-8BD3B13-10B14-BJB3D2(BD)15-4B2(DB)17-2(BD)ED19-D3B516-9B7A4B5-BCB3C2B7A3B7-4BC3B2ADA3DB8-CB3C4B3A2BDB9-9BDB3D11-3C9B12-2BA2(BD)B4D13-3A4BI2B15-2AD5B17-A5B18-2(BD)2B20-2B469-10B10A4-2BC2BKC4B3A2B3AB5-11BDBIBDAB7-C4BI8BJB8-10BD5B9-2B3A9B10-B4ADB2D3CBC11-6A2BDBCE13-3ADA2DCBC14-5A2BC2B15-2A4DCB17-A2BI2A19-2B2A21-2B420-4BA4BG5B7A3-2B3CBC7B6A4-B3ACAC5B3DAD3A5-B3CIC7BDBD2A7-CA2BC5B3DBDB8-3CAC2A2(3BD)B9-5ADA2BCDCBC10-7A7B11-4AD2ABC3B13-5AB3AB14-7ACAC15-8A17-2B4A18-2B4A19-2A2B21-AB372-2B5A7B8A3-7A7B6A4-7A7B6A5-6A8B4A6-7A9BAB7-8ABK6B8-B5A3DBCB3CB9-7ADBD3BC10-5A3DBCB3C11-4AD3AD2AB12-4A3DA4C13-10A15-8A16-3B5A17-6A19-3AB20-3AB21-2A311-G2-G9-B7A6B8A2-B7A6B8A3-8A6B6A4-7A7B6A5-8A7B3A6-9A7BJB7-9ABC3BCB8-9A7B9-9ACA3B10-13AB11-12A13-10A14-10A15-3CAC3A16-BKCAC3A17-2(AC)2A18-6A19-3CB21-2A191-3(F23-)F-F33-2B7A6B9A-9A5B8A2-9A5B8A3-8A6B6A5-7A7B4A6-9A3BK5B7-8ABJ3CBCB8-9A3BCICB9-9A3CBC10-9AC3AC11-8A3CA12-12A13-10A14-2(BC)AC4A15-BI6A16-C7A17-6A18-AC3AB19-B2AB21-2(2A22-)A23-FL22-2G22-3F22-FG23-F23-G24-G57-B9A5B9A-9A5B8A2-9A6B7A3-9A5B6A5-9A3BIBI3A6-10AB3CBC2B7-8A4B2(CB)8-B7A2B3(CB)9-9ACA3B10-9ACA3C11-12A12-12A13-BAB7A14-JCB3C4A15-3BAC3A16-CK3C3A17-BA2B2A18-4CKB19-3AB21-AB47-M22-F24-G23-F22-GF21-F-F24-F83-B7A6B8A2-9A6B7A3-10A4B6A4-11A4B5A5-11A5BAB6-11A2(CB)C2B7-10A6B8-B8ABC5B9-7A2BA4B10-9ACAC2B11-2A3DAD5A13-3ADAD4A14-2(BD)AD4A15-C2BAC3A16-DB3D3A17-3B3A18-5BA19-3B22-2B212-G27-G59-B7A5B9A3-7ABA4B7A4-11A3B6A5-11ABK2B3A6-11A3BI3B7-10ACB3CB8-BAB7A4BCB9-2B7ACB3C10-B7A2BJ3B11-B4A2BA4C12-2B2(DB)D4AB13-4B6A15-D2B5A16-3CAC3A17-2(BC)2A19-CBCA20-2BCB21-BC260-F28-F34-2B5A5B9AB3-10AB8AB4-18A2B5-11AB3A3B7-11A5B8-10AC3BCB9-B9A4B10-2B7AC4B11-B7A4B13-2B3A5B14-BDB3DBA2B15-4BD3A17-B3D2A18-4B2A19-3DB21-2B332-G40-3BA6B9AB4-2B3AB12A2B5-17AB7-15AB8-B10ABA3B9-B8A3CBC10-B9A2(BC)11-8A3CB13-7AC2B14-B5AB3C15-2(D3B)17-6B19-4B21-2B421-5BEBE2B9AB5-2B2(EB)E11A7-BEB13A8-BEB3E10A9-B12AB11-9A3B12-9A3B13-7ABJB15-6A2B17-3A3B18-2DBD2B20-BD470-9B9A7-BE4BAB8A8-4B12A9-EBE11A11-B11A13-8A2B14-7A3B15-6A2B17-4A2B19-A3B518-5BE2B8A9-EJ3E2B7A10-4B3AB6A11-4E8A13-7AB2A15-6A2B17-5AB19-3AB567-7B7A11-7B5A13-6B4A15-2BA3B2A17-3A3B19-3AB616-2(BE)3B5H13-EBE3B4H15-BE4B2H18-4B666-6B2A18-4B21-BO683-
