model
size = 29 16 29, scale = 0.05, origin = -y
material deform = 1, fade = true, lighting = smooth, roughness = 0.3, metalness = 0.6
  colors = A:#06C B:#F36 C:#070 D:#EEE E:#CF0 F:#E00 G:#0E0 H:#F0C I:#007
voxels
298-2(6B2E6B15-)6B2E6B103-2(5B2E4BH17-)7(5B2E5B17-)5B2E5B16-2(6B2E6B15-)H5B2E6B103-5B2E5B17-5B2E4BH2(17-5B2E5B)17-H4B2(2-5B17-5B)2-4BH3(17-5B2-5B)16-2(14B15-)H13B21-2E27-2E24-E26-4(5B2E5B17-)5(5B2-5B17-)5B2-5B16-2(14B15-)14B21-4E22-2E-4E21-E27-4(5B2E5B17-)5(5B2-5B17-)5B2-5B16-2(14B15-)14B19-5E23-2E-3E22-E27-4(5B2E5B17-)5(5B2-5B17-)5B2-5B16-2(14B15-)14B19-5E23-E2-3E50-5B2E4BH3(17-5B2E5B)6(17-5B2-5B)16-2(14B15-)14B19-5E26-3E50-12E3(17-E4B7E)6(17-E4B2-5E)16-2(6EB7E15-)6EB7E21-2E80-12E3(17-E4B7E)6(17-E4B2-5E)16-2(4E3B7E15-)4E3B7E18-5E23-E3-E52-4(5B2E5B17-)4(5B2-5B17-)5B2-4BH17-5B2-5B16-2(14B15-)14B18-6E22-2E-4E50-4(5B2E5B17-)4(5B2-5B17-)5B2-4BH17-5B2-5B16-2(14B15-)14B18-E-4E22-2E-4E21-E28-3(5B2E5B17-)H4B2E5(5B17-5B2-)4BH17-5B2-5B16-2(14B15-)14B19-5E24-5E21-E28-4(5B2E5B17-)5(5B2-5B17-)5B2-5B16-2(14B15-)14B20-3E26-3E51-2(H4B2EH3BH17-)2(5B2EH4B17-)3(5B2E5B17-)5B2E3BHB17-HBH2B2E3BHB17-4HB2E3B2H16-2(6B2E6B15-)6B2E6B392-6B2E5BH2(15-6B2E6B)398-7A2D5AI2(14-7A2D6A)102-I4AI2D4AI16-AI4A4(2D5A16-6A)2D5A16-AI4A2(2D5A16-6A)2DAI3A-7C2F4C2-6A2D4AI-7C2F4C-2(7A2D6A14-)7A2D6A88-2(6C2F3C3-6A2D5A2-)CG4C2F3C3-6A2D5A2-C2G3C2H4(3C3-6A2D5A2-6C2F)3C3-6A2D5A2-2C2G2C2F3C3-6A2D5A-4CG2C2F4C2-6A2D4AI-7C2F4C-2(7A2D6A14-)7A2D6A88-3(6C2F3C3-6A2D5A2-)2CG3C2F3C3-6A2D5A2-3CG2C4(2F3C3-6A2D5A2-6C)2F3C3-6A2D5A-4C2GC2F4C2-6A2D5A-4CG2C2F4C-2(7A2D6A14-)7A2D6A88-4(6C2F3C3-6A2D5A2-)3CG2C2F3C3-6A2D5A2-3C2GC2F3C3-6A2D5A2-4CGC2F3C3-6A2D5A2-6C2F3C3-6A2D5A2-5CG2F3C3-6A2D5A-5C2G2F4C2-6A2D5A-7C2F4C-2(7A2D6A3-4F2-F4-)7A2D6A17-D28-D41-2(11F3-6A2D4AI2-11F3-6A2D5A2-)4(F9-F3-6A2D5A2-)F9-F3-6A2D5A-2F5C2F2C2F2-6A2D5A-2F5C2F2C2F-7A2D6A2-9F3-7A2D6A2-5F2-2F3-7A2D6A17-4D2-3D20-4D2-3D33-4(11F3-13D2-)4(F9-F3-D11-D2-)F9-F3-D11-D-2F4CG4C2F2-D11-D-2F9C2F-2D5A2D4A2D2-9F3-2D5A2D4A2D2-5F-3F3-2D5A2D4A2D16-11D18-5D2-4D32-6C2F3C4(3-13D2-11C)3-D11-D2-11C3-D11-D2-6CG4C2(3-D11-D2-6C2G3C)3-D11-D-7CF5C2-D11-D-7CF5C-2D11A2D4-3F-3F3-2D11A2D9-2F3-2D11A2D16-11D18-5D-5D32-2CG3C2F3C3-6A2D5A6(2-11C3-13A)2-7CG3C3-13A2-8CG2C3-13A-7CF5C2-13A-7CF5C-7AD7A4-3F-2F4-7AD7A3-2F4-F4-7AD7A18-3D-5D25-4D32-6C2F3C3-6A2D5A2-2C2G7C3-13A2-3CG7C4(3-13A2-11C)3-13A2-G10C3-13A2-8CG2C3-13A-7C2F2G2C2-13A-7C2FCG2C-7AD7A8-F5-7AD7A3-3F8-7AD7A18-3D-2D-D20-2D6-D33-6C2F3C3-6A2D5A2-11C3-13A2-3C2G6C3-13A2-3CG7C3(3-13A2-11C)3-13A2-G10C3-13A2-CG9C3-13A-7C2F4C2-12AI-7C2F4C-2(7A2D6A14-)7A2D6A22-3D21-3D3-2D20-D13-6C2F3C3-6A2D5A2-5CG2F3C3-13A2-4C2G5(2F3C3-13A2-6C)2F3C3-13A2-CG4C2F3C3-13A-2C2G3C2F4C2-12AI-3CG3C2F4C-2(7A2D6A14-)7A2D6A51-3D21-2D25-2(6A2D4AI16-)6A2D5A16-6A2D2AI2A16-AI4A4(2D5A16-6A)2D4AI-7C2F4C2-6A2D4AI-7C2F4C-2(7A2D6A14-)7A2D6A82-2D307-2(7A2D6A14-)A2I4A2D6A87-
