model
size = 29 28 27, scale = 0.05, origin = -y
material deform = 1, fade = true, lighting = smooth, roughness = 0.3, metalness = 0.6
  colors = A:#EEE B:#60C C:#3FF D:#C99 E:#888 F:#3F6 G:#0D0 H:#F96 I:#F9F J:#F99 K:#F33 L:#F36 M:#FCF N:#F6F O:#F0C P:#FC6 Q:#FC3 R:#FF6 S:#F0F T:#FFF U:#CFC V:#F9C W:#F06 X:#CC3 Y:#F3F Z:#F03 Aa:#F90 Ab:#CFF Ac:#CCF Ad:#F60 Ae:#F69 Af:#F66 Ag:#F6C Ah:#F09 Ai:#CF0 Aj:#CCC Ak:#F3C Al:#FF9 Am:#CC0 An:#CF6
voxels
157-3(6A23-)5A689-10A18-2E9A18-2EA2-2A-3A18-3A2-2A-3A19-A2E7A20-2E6A540-U57-K57-13A16-A2EA-9A15-AE-A-6A-2A15-2A-CD6A-2A15-2ACE-4A-A2E17-AD2E6A2E568-K11-Ae44-An10-M17-14A14-6A-8AE13-A-4A-9A13-E-4CD9A13-2E4CD5A2E2A14-A4CD5A2EA20-D3B526-H13-T42-JU13-Am15-O11-17A2E10-2A2-11A2-2E10-2A2-3C10A-A10-2A-E5CD7A-A10-2AE-5CD6A-2A11-2AC-4CD5A-3A16-3CD4B22-2CD3B24-2C2B453-J56-I43-Z2-H-X8-E18A9-2E2-13A2-2A8-2A2-3C12A-A8-2A-A7C8A-A8-3A-7C3AC2DA-2A9-3A7C3A2CD3A14-6C3B3C18-C2F2C3BDC20-2F2C3BC22-2B2G2B24-B2GB421-Ad22-X21-V12-M20-L8-2E19A8-2E2-14A2-2A7-A3-C17A7-A-2A7C11A7-2A-A7C2AD3CDA-A8-4A7C2A4CD3A12-7C2B4CD16-2C2F2C2B4C18-C2F2C2B3C19-4B2GB3C20-3B2GBDC22-6B24-4B334-I22-W33-H22-J36-22A7-A2-16A-2A10-19A8-4A4CD12A7-E-3A5C2AD6C3A7-5AD4C2AD5CD-2A10-2BD4C2B6CD14-B5C2B6C16-3C2D2B5C17-7BD2C2F18-6B2DCF20-8B22-6B23-6B25-2B393-23A2(6-A2-20A)6-E-5A3C11A2E6-E-5AD2C3A7CA2E7-A-4AD2C3A7C3A10-3BD2C3B7C13-3B3C3B7C14-2BC2D3B6C15-8B3C2FC16-7BD2C2F18-2G8B19-2G8B20-6B2G22-5BG24-4B26-2B335-23A2(6-A-21A)6-21A2E6-A-11A6CDA2E6-13A7C3A9-10B7CB12-9B7C13-9B7C14-8B6C15-8B6C16-B2G9B18-2G8B19-7B2GB20-6B2G22-6B23-6B24-BC2D26-2C160-Af79-H29-R6-23A5-2(2A-23A3-)26A4-A-12A4CD4A6-14A4CD4A9-11B5C2B11-11BD4C2G12-10BD4CG13-10B5CB14-9B3C2D15-14B16-12B17-12B18-10B20-8B21-8B22-BD3CD24-4C25-4C26-2C131-Ag59-P18-L2-I-N3-23A5-2A-23A3-A2-21A-A3-E-22A-A4-E14A3C7A4-A-13A3C5A8-13BD2C4B10-12BD2CB2G11-12BD2CB2G12-2G9B3C2B13-2G9BC2D2B14-14B15-14B16-12B18-10B19-10B20-8B21-BD6C22-D5C23-6C24-4C26-2C96-Q27-R6-Ah19-I33-Ak3-24A5-26A3-A2-23A2(3-2E24A)4-23A8-20B10-18B11-4BC2D11B12-2GB2CD8B2G13-2GB3C8B2G14-2BD2C9B15-2B3C9B16-B2CD8B17-B2CD8B18-10B19-10B20-B7C21-B2F5C22-2F4C23-6C24-4C26-2C27-2C96-O34-24A5-26A3-A2-23A2(3-26A)4-23A8-20B10-18B11-3BD3CD10B12-2B4CD7B2G13-2B4CD7B2G14-B4CD8B15-B4CD8B16-4CD7B17-D3CD7B18-10B19-10B20-B6CD21-B2F2C2FC22-2FC3F23-3C2FC24-4C26-2C27-2C124-N7-E22A5-2E24A3-A2-21A-A3-A-22A-A3-16AC2D7A4-A-13A2CD5A8-13B3C4B10-12BD2C3B11-2BD6C3B3C3B12-BD5CD3B2CD2B13-B6CD3B2CD2B14-6CD7B15-6CD7B16-5CD6B18-5C5B19-10B20-8B21-2B4CDB22-B3C2F23-B2C3F24-DC2F26-2C131-K29-Z28-E22A5-2E-23A3-A2-21A-A3-A-22A-A4-A-12AD3CD3A-2A4-A-12A4CD4A9-11B4CD2B11-11B4CD2B12-B7C2B4CDB13-B2F5C2B4CDB14-2F5C2BD3CD15-7C7B16-6C6B17-6C6B18-5C5B20-8B21-8B22-2B3CB24-B3C25-BD2C26-DC130-P88-23A2(6-A-21A)6-23A6-A-11AD6C3A6-13AD5CD3A9-10B6CDB12-9B6CD13-B6CDB5C2F14-2F5CBD4CF15-2F5CB2D4C16-6C6B18-C2F2C5B19-C2F2C5B20-4C4B22-6B23-6B24-4B26-2B160-W116-23A2(6-A2-20A)4-2(A-)21A6-A-11A7C3A7-A-10A7C3A10-9B7C13-9B7C14-B4CD2B5CF15-B4CD2B5CF16-5C2BD4C18-4C6B19-C2FC6B20-2FC5B22-2D4B24-4B26-2B245-S29-V21-N7-Al19-J9-23A6-A2-20A5-2A2-20A6-A-E20A7-E-10A6CDA-A7-2A-9A7C-2A10-9B7C14-8B6C16-B3C3B5C17-B3C3B5C18-D2C3B4C20-2C6B22-C5B23-C5B25-2B325-Aa68-22A7-A2-16A-2A10-16A2-A9-18A-A7-E2-10A4CDA-2A7-13A4CDA-2A11-9B5C16-8BD3C18-7BD2C19-7B3C20-6B2C22-6B24-4B354-M42-L27-I26-19A9-2A2-13A-3A8-2A2-13A3-A8-2A-16A-A8-3A-10A3CA-2A9-13A3C3A14-9BD2C18-8BDC20-7BD22-6B24-4B407-T15-Y11-Ac74-19A10-AE2-11A2-2A10-A2E-11A3-A10-2A-14A-A10-2AE-12A-2E11-A2E-10A-A2E16-8B22-6B24-4B463-P27-K31-Ab21-J23-17A12-2E3-8A2-3A11-2E3-8A3-2A11-2A-12A-2A11-AE2-10A-3E12-2EA-8A-A2E19-4B579-S29-H19-14A14-2A5-2A4-3A13-A13-2A13-A3-8A2-2A13-3A3-4A3-A2E14-4A2-2A2-E2AE631-Q23-10A18-2E9A18-2EA5-3A18-3A2-2A-3A19-7A2EA20-6A2E661-A27-3(6A23-)5A575-Aj27-O29-Ai29-Y711-
