model
size = 18 12 19, scale = 0.05, origin = -y
material deform = 1, fade = true, lighting = smooth, roughness = 0.3, metalness = 0.6
  colors = A:#06F B:#036
voxels
-16B2-16B181-36B180-2B14-4B14-2B2-5(14A4-)14A5-12A57-3(2B14-4B14-2B2-5(A12-A4-)14A4-14A56-)2B14-4B14-2B2-5(A12-A4-)14A4-14A10-2A44-2B14-4B14-2B2-5(A12-A4-)14A4-14A9-4A43-2B14-4B14-2B2-5(A12-A4-)14A4-14A9-4A14-4A25-2B14-4B14-2B2-5(A12-A4-)14A4-14A8-6A13-4A15-2A8-2B14-4B14-2B2-5(A12-A4-)14A4-14A9-4A14-4A25-2B14-4B14-2B2-5(A12-A4-)14A4-14A9-4A43-2B14-4B14-2B2-5(A12-A4-)14A4-14A10-2A44-3(2B14-4B14-2B2-5(A12-A4-)14A4-14A56-)2B14-4B14-2B2-5(14A4-)14A5-12A57-36B181-16B2-16B181-
