model
size = 5 31 17, scale = 0.05, origin = -y
material deform = 1, fade = true, lighting = smooth, roughness = 0.3, metalness = 0.6
  colors = A:#960 B:#C60 C:#FC9 D:#FC0 E:#963
voxels
47-3(B4-)7(A4-)2(B4-)B84-B4-B3-2AB2-BAB2-3A37-2(3A2-)B2A3-B4-B69-B3-3A2-BAB2-3B57-2AB2-BAB2-3A3-B59-B3-B2A2-2AB77-2AB2-B2A3-B49-B3-3A2-BAB87-2AB2-B2A3-B39-B3-B2A2-BAB97-2AB2-3A3-B29-B3-3A2-BAB107-BAB2-3A3-B19-B3-3A2-B2A2-2AB107-3A2-B2A2-3A3-B14-B3-3A2-BAB117-BAB2-3A3-B9-B3-3A2-2AB2-B2A117-3A2-2AB2-3A3-B4-B3-2AB2-B2A127-B2A2-3A3-B4-B3-3A2-3A127-2AB2-B2A3-B3-3A2-B2A2-3A127-3A2-BAB2-3A-D3AD-3A2-3A127-3A2-3A-D3A3DA2D2-2(A4-)11(C4-)3(E4-)11(C4-)A4-A2-2DA2D-DAD3-A139-A3-DAD3-A149-A2-
