model
size = 18 17 7, scale = 0.05, origin = -y
material deform = 1, fade = true, lighting = smooth, roughness = 0.3, metalness = 0.6
  colors = A:#630 B:#111
voxels
232-A309-A13-A2-A16-A17-A235-A13-A38-A36-2(B12-B4-)B12-B5-B10-B7-B8-B9-B6-B10-A6BA10-2A4-2A9-3(A8-)A7-A8-A-A5-A8-A3-A18-A38-A36-2(B12-B4-)B12-B5-B10-B7-B8-B9-B6-B10-A6BA10-2A4-2A9-3(A8-)A7-A10-A5-A12-A5-A30-A18-A267-A323-A56-
