model
size = 28 31 23, scale = 0.05, origin = -y
material deform = 1, fade = true, lighting = smooth, roughness = 0.3, metalness = 0.6
  colors = A:#FAF1F1 B:#F2C511 C:#BBB4B4 D:#B6971F E:#EDFA06 F:#000
voxels
599-A57-C809-3AC25-2C24-A-2A25-A27-A729-C23-C-4A23-C3AC22-2A-2AC24-4A21-5A638-5A2-2A18-3A3-A2-A18-A3-AC2A20-A2(2-2A)19-A-9A18-A2-7A18-A-8A17-10A20-8A19-9A22-3A106-9C19-9B328-A58-A2-2A23-A23-9A18-10A18-AC2-6A18-10A18-3(11A17-)2(10A18-)AC8A22-3A105-11C17-C10B19-6(7B21-)7BA20-7B2A19-7BAC19-BE5BAC18-A4B3E2AC17-A4BEBEAC18-A4B3EC19-A7BA19-AB5ABA18-10A18-11A17-12A3(15-13A)15-C12A15-13A16-12A16-11A18-C8A20-C6A74-13C15-13B17-4(D7B2D18-)D7BDE4(18-D7B2D)17-AD7BDC18-D4BEBEDC17-AD7BDC18-D4BEBE2D18-D2B3A2B2D18-D7A2D17-11A17-12A2(15-13A)14-2(15A13-)C14A14-13A15-13A16-12A16-10A19-C8A22-3A47-15C13-14BC15-3(11B17-)10BE5(17-11B)17-2E9B17-2E4B3E2B16-A2E2B2AEBE2B17-2B7A2B2(17-10AB)A14-15A13-15A2(12-16A)2(11-17A)3(12-16A)13-15A15-12A16-11A17-10A43-2C4F11C11-17B13-2(D12B15-)D10B2E15-D10BEB15-D10B2E4(15-D12B)14-AEBE10B15-E12B15-2(EB)5A4B15-DB9A2B15-D10A2B14-AD11ABA13-15A2(12-16A)11-3(18A10-)17A11-17A12-16AC11-16A14-13A16-12A16-A2E7A19-AC21-3CFCF13C9-19B11-14BD13-E13BD13-12BEBE13-14BD13-12BEBE13-E13B3(D12-A14B)D12-AB3E10BD12-A2(BE)2B2A6BD12-AB3E7A3BD12-A2B10A2BD13-2B10A2BD12-A2B12AD12-16A12-17A10-18A10-19A2(8-AE18A)9-2(18A10-)17ABC10-16A14-13A15-13A16-2(2AE)4A20-A2-A18-4CF14C9-19B10-2(D16B11-)D12B3EB11-D12B2(EB)11-D12B3EB2(11-D16B)10-A2(D16B11-)C16B11-C6B3A7B10-AD4B7A5B10-AD2B10A4B10-AD2B11A3B10-AD2B12A2B2(11-16AB)2(A9-17AB)2(A8-AE16AB)9-AE16ABA9-17AB10-17ABC10-17A12-15A14-13A16-4AE6A21-2A18-20C8-19BC8-A17B10-A17BC10-2(17BC4-C5-)3(17BC10-)17BC9-2(A17BC4-2C3-)A6B5A6BC4-2C3-A4B9A4BC5-C4-3B10A4BC5-C3-A3B11A3BC5-C4-3B12A2B3(C5-C3-17AB)CA4-C2-18ABE5-C-AE17AB2C4-C-A2E16AB6C3-AE16AB2-4C3-CE16ABA9-17ABC9-17A13-15A14-14A15-12A20-A19-3CFC2F14C7-19B2C7-A17BC9-A17B6C5-18BC3-2C4-E16BC4-C4(5-17BC3-2C)5-17BC4-2C4-17BC4-2C3-A6B5A6BC4-CBC2-A4B9A4BC5-BC2-A3B10A4BC5-BC2-A3B11A3BC5-BC2-A3B12A2BC5-BC2-17ABC5-BC-18ABC5-BC2-17A2(BC5-BC19A)2BC4-C2-18A3B5C2-18AB6C3-18AB10-17ABC9-18A12-16A13-14A15-12A40-20C8-19BC9-17BC9-A17B6C4-A18BC3-2C4-17BC4-C4(5-17BC3-2C)5-2(17BC4-2C4-)7B2A8BC4-CBC2-A5B7A5BC5-BC2-A3B10A4BC5-BC-2A3B10A4BC5-BC2-A3B12A2BC5-BC-18A3(BC5-BC2-17A)BC5-BC-18A2BC4-C2-18A3B5C3-17AB6C4-17AB10-17ABC10-16A14-14A14-15A14-8AC3A17-A3-A5-A12-4C3F13C8-19BC8-AE16B10-A17BC10-2(17BC4-C5-)4(17BC10-)E16B2(C4-2C4-17B)C4-2C4-6B5A6BC5-C4-4B9A4BC5-C4-3B10A4BC5-C2-2A3B11A3BC5-C3-AB15ABC5-C4-16A3(BC5-C3-17A)B2C4-C3-17AB6C4-17AB-5C4-17AB10-17ABC10-17A13-15A14-11AE2A14-12A16-A23-3CFCF13C9-19B9-AD16B10-A7(D16B11-)D12B3EB11-D12B2(EB)11-D12B3EB11-D6B2A8B11-D4B7A5B2(10-AD2B10A4B)10-AD15AB11-D15AB10-AC15A3(B10-17A)2(B11-16A)B10-17ABC11-16A14-12A16-11A17-10A18-A7-A15-4C3F12C9-18BC11-3(14BD13-)B3E10BD13-2(BE)10BD13-B3E10B2(D13-14B)2(D13-12BEBE13-14B)D13-5B5A4BD13-3B9A2BD13-2B10A2BD13-B13AD2(13-15A)3(12-C15A)12-15AE12-16A11-AB15ABC11-16A14-9AC2A16-11A18-9A43-17C11-17B13-D12B15-D8B3EB15-D8B2(EB)15-EBE6B3EB15-D12B15-EBE10B2(15-D12B)15-D10B2E15-D10BEB15-D10B2E4(15-D12B)2(15-D10A2B)15-D11AB15-D12A15-E12A13-CAD12A15-E12A15-D12A13-C2B11A2BC12-12A2-A17-5ACA-A20-2A3C74-15C13-15B15-11B17-8BEBE17-11B17-2E6BEBE17-BE9B17-2E9B3(17-11B)17-2B3E6B17-2BEBE6B17-2B3E6B3(17-11B)17-B9A3(B17-10A)BA2(15-13A)16-12A16-10AB15-CB10A2BC14-11A-2A19-3A104-13C15-13B17-D7B2D18-D6B3E18-D6BEDE18-D6B3E5(18-D7B2D)2(18-DEBE4B2D18-D7B2D)2(18-D7B2D)18-DB5AE2D18-D7A2D18-9ADA2(16-11A)DA15-12A17-C9ADA16-10A17-CB9ABCA15-9A-2A24-A103-11C17-C9BC19-5B-B21-7B21-3BE3B2(21-7B)21-BE5B21-7B21-5BEB21-7B21-3E4B21-EBE4B21-3E4B21-3BE3B2(21-7B)21-4B3E21-2B2AEBE21-B2AC2AE2A19-2C6A18-11A17-C9A19-8A-A17-A-7A19-C2B5A2BC18-7A-2A130-9C19-9B21-2A-A23-2A2-A23-5A24-3A394-A23-2C2-A22-5A23-5A24-3A25-2A23-7C2BA19-8A694-C27-AC26-2A27-2A57-2A152-
