model
size = 24 12 29, scale = 0.05, origin = -y
material deform = 1, fade = true, lighting = smooth, roughness = 0.3, metalness = 0.6
  colors = A:#252525 B:#E83015 C:#E03C8A D:#FBE251 E:#F05E1C F:#FFB11B G:#FFC408 H:#FFF I:#111
voxels
6-2BGDC2HCDG2B12-ABEGD2CDGEBA12-2AB6-B2A12-3AB4-B3A14-2AB2GB2A17-2A2B2A157-3ABG6-GB3A8-3ABG6-G2B2A8-4AB6-B4A8-5AB4-B5A10-4AB2GB4A12-5A2B5A15-2A2C2A132-2A2B10-2B2A6-2A2B10-3BA2(6-3A12-3A)8-A12-A10-A12-A11-5A2C5A15-2A2C2A107-2AB14-B2A4-2AB14-2BA2(4-3A14-3A)6-A14-A8-2A12-2A9-2A10-2A12-4A2C4A16-2A2C2A83-A2B14-2BA4-ADB14-2BA2(4-2AC14-C2A)5-AC14-CA6-ADA12-ADA7-3A10-3A9-6A2C6A12-4A2C4A80-BAB16-BAB2-2AB16-2BA2-2A18-2A3-A18-A4-A18-A5-2AC12-C2A6-2ADA10-AD2A7-4A8-4A10-5A2C5A15-2A2C2A58-EB18-BE2-2B18-2B2-A20-I2-A20-A3-A18-A4-A18-A5-3AC10-C3A6-3ADA8-AD3A8-6A2C6A12-4A2C4A55-F2B18-2BFEAB18-BAE-BA18-AB2-A19-AI3-A18-A4-A18-A5-A16-A6-4AC8-C4A8-6A2C3AD2A12-4A2C4A55-DB20-BDFB20-BFEA20-AE-BA18-AB2-2A18-AI3-A18-A4-2A16-2A5-3A12-3A8-3ACA4-AC3A12-4A2C4A17-A2CA34-CB20-BCDB20-BDFA20-AFEA20-AE-BA18-AB2-2A18-AI3-2A16-2A4-4A12-4A6-5AC4-C5A10-3ADA2CAD3A15-2A2C2A33-CB20-B2CB20-BCDA20-ADFA20-AF-EA18-AE2-BA18-AB3-2A16-2A4-4A12-4A6-4A8-4A10-4A4C4A14-8A19-2B11-HB20-BHCB20-B3C20-2CDC20-CD-FC18-CF2-EC18-CE3-BC16-CB4-4C12-4C6-4C8-4C10-5C2H5C14-2CAD2A2C18-B2DB10-CB20-B2CB20-BCDA20-ADFA20-AF-EA18-AE2-BA18-AB3-2A16-2A4-4A12-4A6-4A8-4A10-4A4C4A14-8A19-2B11-C2B18-2BCDAB18-BADFA20-AF-EA18-AE2-BA18-AB3-A18-A4-2A16-2A5-3A12-3A7-4A8-4A10-3ACA2CAC3A15-2A2C2A34-DB18-BD2-FB18-BF2-EA18-IE2-BA18-AB3-A18-A4-A18-A5-A16-A6-3A12-3A8-3ACA4-AC3A12-4A2C4A17-A2CA35-F2B16-2BF2-E2B16-2BE2-BA18-AB2-2A18-2A3-A17-2A4-A17-2A5-A16-A6-3A12-3A8-2AC3A2C3AC2A12-4A2C4A57-EB16-BE4-2B16-2B2(4-A18-A)5-A16-A6-A16-A7-2AC10-C2A8-2ACA8-AC2A10-5A2C5A14-3A2C3A58-BEGD12-DGEB4-4B12-4B2(4-2A-C12-C3A)5-2AC12-C2A6-2AC12-C2A7-3A10-3A9-3A8-3A11-5A2C5A14-3A2C3A58-2BEGD10-DGE2B4-5B10-5B5-3A12-3A6-3A12-3A7-2(2A12-2A8-)3A10-3A9-6A2C6A11-12A16-A2CA60-3BEG2D2C2H2C2DGE3B4-BC3AG2DC2HC2DG3ACB6-3ABG2D2C2DGB3A8-4ABG4DGB4A9-4ABG2DGB4A10-5AB2GB5A10-6A2B6A11-12A13-4A2C4A81-4BEG2D4C2DGE4B4-BD2CD5AD4AD2CDB8-4(12A12-)12A13-10A15-3A2C3A82-5BEG2D2C2DGE5B4-B3C2ED2CH2CD2E4CB29-2F-2F2-4D3-2B8-2(2F-)2(2D2-)2B8-5F-2(2D2-)2B8-2(2F-)2(2D2-)2B8-2F-2F2-4D2-4B102-6BEG4DGE6B4-B2(CD)EFD3CDFE2(CD)CB245-6BEG2DGE6B6-B3C2EFDCDF2E4CB246-7BE2GE7B6-BCD2C2EFDF2E2(CD)CB247-7B2E7B8-B4C2EF2E5CB249-14B10-BCD2C3E2CDCDB251-12B12-B2CDCECD3CB253-10B14-10B247-
