model
size = 22 32 7, scale = 0.05, origin = -y
material deform = 1, fade = true, lighting = smooth, roughness = 0.3, metalness = 0.6
  colors = A:#EEE B:#111 C:#555 D:#BBB E:#888 F:#DDD G:#777
voxels
155-2(A21-)A18-A-2A3(18-4A)18-2ABA18-AB2A12(18-4A)18-2A-2(A18-A2-)A18-A156-7(A18-A2-)A18-A-BA18-AB-15(A18-A2-)A18-A135-4(A16-A4-)3(C16-C4-)B16-B3-2B16-2B-2BE16-E2B2-E16-E9(4-A16-A)3-2B16-2B3-5(A16-A4-)A16-A9-3A2B3A13-4A2B4A11-5A2B5A9-6A2B6A7-3(7A2B7A6-)A14CA6-3C10A3C6-16C6-C6B2C6BC6-3B2A6B2A3B5-3B3A6B3A3B3-3B2A10C2A3B2-B-3A3C4A3C3A-B4-5AD4AD3(5A6-5A2D2A2D)5A2(6-5B2G2A2G5B)2(6-5A2G2A2G5A)6-4A3B2A3B4A6-2A4B4A4B2A5-5B8A5B5-5(16A6-)16A10-3A2B3A13-4A2B4A11-5A2B5A9-6A2B6A7-3(7A2B7A6-)A14CA6-3C10D3C6-16C6-C6B2C6BC6-3B2E6B2E3B5-3B3E6B3E3B4-2B4E6C4E2B5-A4E6A4EA6-A4D6A4DA6-A6D2A6D2(A6-A4F2D2A2D4F)A2(6-5B6A5B)6-5C6A5C6-16A6-4A3B2A3B4A6-2A4B4A4B2A6-4B8A4B6(6-16A)10-3A2B3A13-4A2B4A11-5A2B5A9-6A2B6A7-7A2B7A2(6-6A4B6A)6-5A6C5A6-3C10D3C6-16C6-C6B2C6BC6-16B6-2B3A6B3A2B6-BD2A8C2ADB6-A2DAC6ACA2DA6-2A2DC6AC2D2A6-3A2D6A2D3A6-2(4A2D)4A6-5A2D2A2D5A2(6-4B-AD2ADA-4B)6-5CAD2ADA5C6-6AD2AD6A6-4A3B2A3B4A6-2A4B4A4B2A6-4B8A4B6(6-16A)10-3F2B3F13-4F2B4F11-E4F2B4FE9-AE4F2B4FEA7-2AE4F2B4FE2A6-3AE2F4B2FE3A6-4AEF4BFE4A6-5A6C5A6-3A10D3A6-2A12C2A6-A6B2C6BA6-2B3-6B3-2B6-2B3A6B3A2B6-B3A8C3AB6-A3EC6AC3EA6-2A2ECE4AEC2E2A6-3A4E2A4E3A6-4A3E2A3E4A6-5A2E2A2E5A11-AE2AEA16-AE2AEA11-5CAE2AEA5C6-6AE2AE6A6-4A3B2A3B4A6-2A4B4A4B2A6-4B8A4B5(6-16A)25-
