model
size = 30 15 30, scale = 0.05, origin = -y
material deform = 1, fade = true, lighting = smooth, roughness = 0.3, metalness = 0.6
  colors = A:#6A4028
voxels
40-3A6-2A28-2A370-2A26-A421-3A3-2A-4A3-2A2-2A3-2A4-A418-3A2-18A2-2A4-A4-2A-4A3-2A2-2A3-A10-2A385-20A12-14A-2A13-4A-3A2-4A17-2A7-3A344-23A9-21A10-17A-2A11-2A-4A2-4A26-3A314-24A8-22A10-19A14-13A18-12A21-3A27-2A255-A2-11A-11A2(8-22A)12-15A17-13A18-7A-2A20-7A256-2(22A8-)21A11-19A12-17A14-A-13A17-12A19-7A24-5A27-A169-23A7-21A10-20A2(11-19A)12-16A16-13A16-2A-7A23-7A24-5A165-A-24A6-23A7-21A2(11-19A)11-18A14-15A15-12A18-11A20-9A25-5A25-2A109-24A6-23A7-21A2(11-19A)12-17A14-14A16-12A18-11A20-9A25-3A-A25-2A29-A79-2(23A7-)22A8-21A10-19A11-18A13-16A15-13A18-12A18-11A20-7A-A20-5A-2A24-5A28-2A47-A-2(23A7-)22A8-2(20A10-)18A13-17A15-13A18-11A19-2(10A20-)5A-4A20-7A26-A-2A46-2A-23A7-22A8-21A9-2(19A11-)17A13-16A16-14A18-12A18-10A2(20-3A-6A)20-3A-3A26-4A28-A19-24A7-22A7-23A7-22A8-20A11-18A12-17A15-14A16-13A19-2(10A20-)9A23-4A29-A49-25A4-25A6-22A8-20A10-20A11-18A12-18A13-15A16-13A19-4A-4A21-9A21-8A24-4A78-27A2-27A3-24A7-23A7-22A10-18A12-17A15-14A16-7A2-3A20-5A2-A24-3A26-5A108-27A3-26A4-24A6-23A7-23A9-18A12-17A15-14A16-7A3-2A20-5A27-2A28-2A111-25A6-2(22A8-)2(21A9-)18A12-17A15-7A3-2A20-4A202-4(22A8-)21A9-19A12-17A15-5A232-3(22A8-)22A9-20A10-18A13-8A-4A-2A16-2A234-3(22A8-)11A2-8A10-10A3-7A15-4A27-2A257-A3-22A8-2(21A9-)21A11-A2-6A4-5A17-3A292-19A10-19A11-19A14-2A-4A2-A-3A19-2A323-17A14-15A15-4A-10A16-A9-4A27-2A311-A-A3-7A3-4A2-A8-A4-2A-3A4-4A16-A3-2A4-4A26-4A27-2A312-2A7-2A4-5A2-A7-A8-2A4-5A26-3A27-2A344-2A10-6A24-6A25-4A367-A6-A2-2A6-5A25-5A26-2A369-
