model
size = 32, scale = 0.05, origin = -y
material deform = 1, fade = true, lighting = smooth, roughness = 0.3, metalness = 0.6
  colors = A:#F0C B:#630 C:#222 D:#909 E:#006 F:#603 G:#3F6 H:#555 I:#600 J:#FFC17A K:#200 L:#9D550E M:#FFF N:#906 O:#633 P:#888 Q:#FF9F0F R:#3C0 S:#700 T:#363 U:#D97613 V:#111 W:#E00
voxels
-31G1740-4(7B25-)7B440-3E3-3E23-4E-4E24-7E25-7L57-H2(-F)-H23-DFH2(FD)FHFD20-DFDH2(DF)DHDFD19-FDFH2(FD)FHFDF18-IDF2(DH2(DF))17-2(DF)H2(FD)FHFDFI18-DFDH2(DF)DHDFD22-HFQJQFH24-2(9B23-)9B22-P9BP21-P9BP22-9B23-9B214-E9-E21-3E5-3E20-4E5-4E21-2E5-2E23-3E3-3E22-4E3-4E22-4E-4E24-7E25-E2LC2LE25-L2(FD)FL24-DH2(DF)DHD22-DFH2(FD)FHFD20-DFDH2(DF)DHDFD19-FDFH2(FD)FHFDF18-IDF2(DH2(DF))17-NFD2(FH2(FD))17-IDFDHD3MDHDFDNI16-7D-8D20-HFQUQFH2(-I)20-O7BO22-2(2O7B2O21-)2J7B2J21-PJ7BJP2(21-11B)22-9M23-B7KB24-B5KB22-2(2C9-2C19-)L11-L2(19-3E7-3E)19-4E5-4E20-3(4E3-4E21-)4E3-4E22-4E-4E24-7E25-3LC3L25-H2(FD)FH23-FDH2(DF)DHDF20-FDFH2(FD)FHFDF19-DFDH2(DF)DHDFDN18-FDFH2(FD)FHFDFIN16-IDFDH2(DF)DHDFDNI15-INFDFH2(FD)FHFDFINI15-IDFDHD3MDHDFDNI17-I-IHFQUQFHI-ID20-O7BO22-2O7B2O22-J7BJ23-J7BJ22-PJ7BJP21-BJ7BJB22-9B23-4M4SM23-B7KB24-7K22-2C9-2C19-2L9-2L19-CLE7-ELC19-3E7-3E19-4E5-4E20-3(4E3-4E21-)4E3-4E22-4E-4E24-7E25-E2LC2LE25-L2(FD)FL24-DH2(DF)DHD22-DFH2(FD)FHFD20-DFDH2(DF)DHDFD19-FDFH2(FD)FHFDFIN16-IDFDH2(DF)DHDFDNI16-NFDFH2(FD)FHFDFIN16-IDFDHD3MDHDFDNI16-7D-8D18-I-HFQJQFH-D2I21-BJ3BJB24-O7BO2(23-J7BJ)22-PJ7BJP22-2(J7BJ23-)4M4SM23-B7KB24-7K22-2(2C9-2C19-)2L9-2L52-E9-E20-3E7-3E20-3E5-3E53-3E5-3E21-3E5-3E22-4E-4E24-6E26-3LC3L3-2J20-H2(FD)FH3-IN18-FDH2(DF)DHD2-NI17-FDFH2(FD)FHFDFIN17-DFDH2(DF)DHDFDNI17-FDFH2(FD)FHFDFIN16-IDFDH2(DF)DHDFDNI15-INFDFH2(FD)FHFDFINI15-IDFDHD3MDHDFDNI17-FDFHM3-MHFDFI21-O-JOJ-O24-O2J3M2JO23-9J23-9G22-P2(GRTR)GP22-2(GRTR)G23-2JV3JV2J23-4MW4M23-B7KB24-B5KB22-2C9-2C19-2C9-2C343-2LC2L4-2J30-2J20-H2(F-)FH3-IN18-FDH2(DF)DHDF-NI18-DFH2(FD)FHFD-IN18-FDH2(DF)DHDFDNI16-NIDFH2(FD)FHFDFIN16-INFDH2(D-)DHDFDNI17-ID-H5-HFDF19-DF100-J249-2C9-2C594-NI30-IN194-G5-G789-IN30-NI62-G14-G16-G14-G17-G12-G19-G8-G52-G14-G752-NI29-GIN2(14-G)16-G113-G8-G689-G20-G10-G20-G11-G18-G12-G18-G14-IN30-NI126-G11-G655-G22-G8-G22-G140-NI30-IN126-G11-G82-G16-G458-G24-G6-G24-G235-IN30-NI91-G16-G112-G16-G328-G28-G2-G28-G393-2J91-G16-G393-G30-G489-J58-G18-G142-G18-G262-32G489-J24-G23-G171-G18-G294-G2(2AC)2(A3C)AC2AC11A2G2A2C3(AC)3ACA2CAC4A4C3AG450-G23-G549-G2A2C3(AC)A3CA2CAC4A4C3A2G2A2C3(AC)3ACA2CAC4A5C2AG353-G26-G232-G20-G389-G2ACA2C2(A3C)ACA2C4ACA2C2ACG321-G26-G232-G20-G421-G24AC3ACA2G10A5C7A2C3AC2AG224-G29-G769-G10A5C6AC2A3C3A2G10A5C5A2C2AC5AG452-G22-G548-G4A3C3A5C4AC3AC6AG96-G30-G292-G22-G580-G7AC10AC3A2C6A2G2AC5A3C6AC3AC2A2C4AG1024-G4AC6AC7A2C5A2C2A2G5A2C5A4C2AC3A3C3A2CG324-G22-G676-G7A2C4AC3AC4A3C5A2G9A2CAC3AC5A3C5AG260-G22-G740-G5A4C2AC2A2C9A2C3AG1024-G4A4CAC3AC4A2C4ACAC3A2GACA4CAC3AC5A2C4A2(C2A)G1024-G2AC4AC3AC12A2CAC2A2GA4CAC3ACA3C9A2CAC2AG1024-G4A2C2A2C5A3C9AC2AG1024-G2(3AC)7AC2AC7AC3A2G2AC3AC7AC2(4A2C)3AG1024-GAC3AC6A2C16A2G4AC6AC18AG32-
