model
size = 24 12 29, scale = 0.05, origin = -y
material deform = 1, fade = true, lighting = smooth, roughness = 0.3, metalness = 0.6
  colors = A:#252525 B:#46C68E C:#5BFFB8 D:#B481BB E:#6F3381
voxels
6-2A4(CB)2A12-2A8C2A12-3A6-3A12-4A4-4A14-8A17-6A157-2(3A2B6-2B3A8-)4AB6-B4A8-5AB4-B5A10-4A4B4A12-5A2B5A15-6A132-2(2A2B10-2B2A6-)3A12-3A6-3A12-3A8-A12-A10-A12-A11-5A2B5A15-6A107-2(2AB14-B2A4-)3A14-3A4-3A14-3A6-A14-A8-2A12-2A9-2A10-2A12-4A2B4A16-6A83-2(A2B14-2BA4-)2AB14-B2A4-2AB14-B2A5-AB14-BA6-ABA12-ABA7-3A10-3A9-6A2B6A12-10A80-2(2AB16-B2A2-)2A18-2A3-A18-A4-A18-A5-2AB12-B2A6-2ABA10-AB2A7-4A8-4A10-5A2B5A15-6A58-2(AB18-BA2-)A20-A2-A20-A3-A18-A4-A18-A5-3AB10-B3A6-3ABA8-AB3A8-6A2B6A12-10A55-2AB18-B4AB18-B2A-A20-A2-A20-A3-A18-A4-A18-A5-A16-A6-4AB8-B4A8-6A2B3AB2A12-10A55-AB20-B2AB20-B3A20-2A-A20-A2-2A18-2A3-A18-A4-2A16-2A5-3A12-3A8-3ABA4-AB3A12-4A2B4A17-4A34-AB20-B2AB20-B3A20-4A20-2A-2A18-2A2-2A18-2A3-2A16-2A4-4A12-4A6-5AB4-B5A10-3ABA2BAB3A15-6A33-AB20-B2AB20-B3A20-4A20-2A-2A18-2A2-2A18-2A3-2A16-2A4-4A12-4A6-4A8-4A10-4A4B4A14-8A19-2C11-A3(B20-B2A)B20-BA-AB18-BA2-AB18-BA3-AB16-BA4-2A2B12-2B2A6-2A2B8-2B2A10-2A8B2A14-3AC4A18-4C10-AB20-B2AB20-B3A20-4A20-2A-2A18-2A2-2A18-2A3-2A16-2A4-4A12-4A6-4A8-4A10-4A4B4A14-8A19-2C11-2A2(B18-B4A)20-2A-A20-A2-2A18-2A3-A18-A4-2A16-2A5-3A12-3A7-4A8-4A10-3ABA2BAB3A15-6A34-2(AB18-BA2-)A20-A2-A20-A3-A18-A4-A18-A5-A16-A6-3A12-3A8-3ABA4-AB3A12-4A2B4A17-4A35-2(2AB16-B2A2-)2A18-2A2-2A18-2A3-2A16-2A4-2A16-2A5-A16-A6-3A12-3A8-2AB3A2B3AB2A12-10A57-2(AB16-BA4-)A18-A4-A18-A5-A16-A6-A16-A7-2AB10-B2A8-2ABA8-AB2A10-5A2B5A14-8A58-A3B12-3BA4-2A2B12-2B2A2(4-3AB12-B3A)5-2AB12-B2A6-2AB12-B2A7-3A10-3A9-3A8-3A11-5A2B5A14-8A58-CED2B10-2BDEC4-C2A2B10-2B2AC5-3A12-3A6-3A12-3A7-2(2A12-2A8-)3A10-3A9-6A2B6A11-12A16-4A60-C2(ED)10B2(DE)C4-CB3A10B3ABC6-7A2B7A8-7A2B7A9-2(6A2B6A10-)6A2B6A11-12A13-10A81-C3(ED)E4D3(ED)EC4-2(CB)C5AB4A2(CB)C8-4(12A12-)12A13-10A15-8A82-C2(ED)E2D4E2D2(ED)EC4-3(CB)2C4B2C3(BC)36-4C19-2(2C2-2C18-)2C2-2C19-4C108-C3(DE)6D3(ED)C4-2C2(BC)B6C2(BC)B2C245-C2(DE)D6E2(DE)DC6-2C2(BC)6B2(CB)2C246-C2DEDE6DEDE2DC6-3CBCB6CBCB3C247-C2DED6EDE2DC8-3CBC6BCB3C249-C2DE6DE2DC10-3CB6CB3C251-2CD6ED2C12-3C6B3C253-10C14-10C247-
