model
size = 24 25 23, scale = 0.05, origin = -y
material deform = 1, fade = true, lighting = smooth, roughness = 0.3, metalness = 0.6
  colors = A:#111 B:#EEE C:#888 D:#222 E:#555 F:#444
voxels
226-3B20-5B18-2(7B17-)7B18-5B20-3B403-7B16-9B14-6(11B13-)11B14-9B16-7B306-5B17-9B15-A9B13-A11B11-13B9-2(16B8-)3B-A11B2(8-16B)10-13B11-13B12-11B14-9B17-5B234-7B15-2C9B13-A11B11-2A12B9-6B-5A3B8-2B-A2B-7A3B7-B2-2A-9A2B11-11A2B12-10A2B11-11A2B7-2(B-)A-9A2B7-2B-A2B-7A3B8-6B-5A3B9-15B10-13B12-11B15-7B185-7B15-11B13-A11B11-A4B-4A4B8-CA4B-7A3B7-B-2AB-9A2B6-B2-A-12A2B8-A2-11A3(2B12-10A)2B11-11A2B5-C2-A-12A2B5-2B-3A-9A2B7-B-2A2B-7A3B8-15B10-13B12-11B15-7B138-5B16-11B12-C12B11-A4B-5A3B9-A2B-11AB6-2B-A-12A2B5-2B-15AB8-A2-12AB12-12AB11-12AB12-11A2(B11-12A)B11-11AB11-12AB5-B2-A-12A2B6-B-2AB-9A2B8-6B-5A3B10-13B12-11B16-5B112-10B13-BA11B11-A4B-4A4B9-A3B-9A2B6-C2(A-)12A2B5-CB-15AB3-3B2-A-14A2(B11-12A)4(B12-11A)2(B11-12A)B10-F11AB5-2B-14A2B6-B-A2B-9A2B8-6B-4A4B10-13B13-9B88-7B14-12B10-3C13B8-2A4B-7A3B7-A-AB-11A2B6-2(A-)13AB3-4B-16AB2-2B3-A2-2(13AB11-)5(12AB11-)12AB10-12AB11-12A2(B4-)12A2B5-2B-2A-11A2B6-B-A3B-7A3B8-15B11-11B15-7B64-9B12-14B11-A4B-5A3B8-2A3B-9A2B7-2(A-)12A2B4-C2B-16AB2-4B-16AB2-3B2-A-15A2(B10-13A)6(B11-12A)B10-12AB3-B6-12A2B4-2B-14A2B6-B-A2B-9A2B8-6B-5A3B10-13B13-9B42-3B17-11B11-2BA4B-3A3B9-C4B-9A2B6-4AB-11A2B6-2(A-)13AB4-3B-16AB2-4B-17AB-2BD-18AB2-B7-2(13AB10-)14A2(B10-13A)B10-12AB11-12AB10-13AB-C8-13AB2-2B4-14AB4-2B-15AB5-2B-AB-11A2B6-5B-9A2B9-13B12-11B17-3B20-6B15-11B10-3C4B-4A4B8-A4B-9A2B8-2A-12A2B4-E2A-A-13A2B3-C2B-16AB2-4B-17AB-3B-18AB3-D5-15A3B7-3(14AB9-)14A2(B10-13A)2B8-13AB-2B6-14AB2-3B2-15AB3-3B-A-13A2B4-2B-A-12A2B6-5B-9A2B8-15B11-11B16-5B18-7B13-13B10-B2A4B-5A3B8-E4B-9A2B8-2A-12A2B5-2A-A-13A2B3-3B-16AB2-4B-17AB-3B-18AB-3B-19A3B-2A-17A3B-A3-16AB-B6-15AB-B7-14A3B7-14ABCB7-14A3B6-14AB-3B4-15AB2-4B-15AB3-3B-A-13A2B4-2B-A-12A2B6-B-A2B-9A2B8-15B11-11B15-7B18-6B15-11B10-3C4B-5A3B8-3A2B-9A2B8-2A-12A2B4-E2A-A-13A2B3-C2B-16AB2-4B-17AB-3B-18AB3-D2-A2-15A3B3-A3-3(14AB9-)14A2(B10-13A)2B8-13AB-2B6-14AB2-3B-16AB3-3B-A-13A2B4-2B-A-12A2B6-B-A2B-9A2B8-15B11-11B16-5B20-3B17-11B11-2BA4B-3A3B9-C4B-9A2B8-2AB-11A2B6-2(A-)13AB4-3B-16AB2-4B-17AB-2BD-18AB2-B7-2(13AB10-)14A2(B10-13A)B10-12AB11-12AB10-13AB-C8-13AB2-2B4-14AB4-2B-15AB5-2B-AB-11A2B6-5B-9A2B9-13B12-11B17-3B42-9B12-14B10-2A4B-5A3B8-3A2B-9A2B7-2(A-)12A2B4-C2B-16AB2-4B-16AB2-3B2-A-15A2(B10-13A)6(B11-12A)B10-12AB3-B6-12A2B4-2B-14A2B6-B-A2B-9A2B8-6B-5A3B10-13B13-9B64-7B13-13B10-3C13B8-A5B-7A3B7-A-AB-11A2B6-2(A-)13AB3-4B-16AB2-2B3-A2-2(13AB11-)5(12AB11-)12AB10-12AB11-12A2(B4-)12A2B5-2B-2A-11A2B6-B-A3B-7A3B8-15B11-11B15-7B87-10B13-BA11B10-2A4B-4A4B9-2A2B-9A2B6-C2(A-)12A2B5-CB-15AB4-2B2-A-14AB11-12A5(B12-11A)2(B11-12A)B10-F11AB5-2B2-13A2B6-B-A2B-9A2B8-6B-4A4B9-14B13-9B113-5B16-11B11-2C12B11-A4B-5A3B9-2AB-11AB6-2B-A-12A2B5-2B-15AB11-12AB12-12AB11-12AB12-11A2(B11-12A)B11-11AB11-12AB4-2B4-12A2B6-B-2AB-9A2B8-6B-5A3B9-14B12-11B16-5B138-7B15-11B13-A11B11-A4B-4A4B8-C-A3B-7A3B7-B-2AB-9A2B6-B2-A-12A2B11-11A3(2B12-10A)2B11-11A2B4-CB4-12A2B4-3B2-2A-9A2B6-2B-2A2B-7A3B8-15B9-14B12-11B15-7B185-7B15-2C9B13-A11B11-2A12B9-6B-5A3B8-2B-A2B-7A3B7-B2-2A-9A2B11-11A2B12-10A2B11-11A2B7-C-B-A-9A2B7-2B-A2B-7A3B8-6B-5A3B9-15B9-14B12-11B15-7B234-5B17-9B15-A9B13-A11B11-13B9-2(16B8-)3B-A11B2(8-16B)10-13B11-13B12-11B14-9B17-5B306-7B16-9B14-6(11B13-)11B14-9B16-7B403-3B20-5B18-2(7B17-)7B18-5B20-3B227-
