model
size = 23 25 25, scale = 0.05, origin = -y
material deform = 1, fade = true, lighting = smooth, roughness = 0.3, metalness = 0.6
  colors = A:#800 B:#EEE C:#500 D:#888 E:#222 F:#555
voxels
217-3B20-3B19-2(5B18-)5B19-3B20-3B387-5B17-7B15-6(9B14-)9B15-7B17-5B295-3B18-7B15-9B13-3B5A3B12-3B5A3B11-4(3B7A3B10-)3B7A3B11-3B5A3B12-3B5A3B13-9B15-7B18-3B226-5B16-9B13-4B3A4B11-4B5A4B10-3B7A3B9-3B9A3B4(8-2B11A2B)2(8-3B9A3B)9-3B7A3B10-4B5A4B11-11B13-9B16-5B179-5B16-9B13-11B11-3B7A3B9-3B9A3B8-2B11A2B7-3B11A3B5(6-2B13A2B)6-3B11A3B7-2B11A2B8-3B9A3B9-4B5A4B11-11B13-9B16-5B134-3B17-9B13-11B11-4B5A4B9-3B9A3B7-3B11A3B2(6-2B13A2B)5-4(3B13A3B4-)3B13A3B5-2(2B13A2B6-)3B11A3B7-4B7A4B9-4B5A4B11-11B13-9B17-3B110-7B14-11B11-4B5A4B9-3B9A3B7-2B13A2B6-2B13A2B5-3B13A3B7(4-2B15A2B)4-3B13A3B5-2B13A2B6-3B11A3B7-3B9A3B9-4B5A4B11-11B14-7B86-5B16-9B12-4B5A4B9-4B7A4B7-3B11A3B6-2B13A2B5-3B13A3B4-2B15A2B3-3B15A3B5(2-2B17A2B)2-3B15A3B3-2B15A2B4-3B13A3B5-2B13A2B6-3B11A3B7-4B7A4B9-4B5A4B12-9B16-5B63-7B14-11B11-4B5A4B9-3B9A3B7-3B11A3B5-3B13A3B4-2B15A2B3-3B15A3B7(2-2B17A2B)2-3B15A3B3-2B15A2B4-3B13A3B5-3B11A3B7-3B9A3B9-4B5A4B11-11B14-7B41-3B17-9B13-5B2A4B10-4B7A4B7-4B9A4B6-2B13A2B5-3B13A3B3-3B15A3B3(2-2B17A2B)-3B2(17A6B)17A3B-3(2B17A2B2-)3B15A3B3-3B13A3B5-2B13A2B6-4B9A4B7-4B7A4B10-11B13-9B18-B21-3B17-9B12-4B5A4B9-4B7A4B7-3B11A3B5-3B13A3B4-2B15A2B3-3B15A3B2(2-2B17A2B)-3B4(17A6B)17A3B-2(2B17A2B2-)3B15A3B3-3B13A3B4-3B13A3B5-3B11A3B7-4B7A4B9-13B12-9B17-3B19-2(5B16-9B12-4B5A4B9-4B7A4B7-3B11A3B5-3B13A3B4-2B15A2B3-3B15A3B2-2B17A2B-3B6(17A6B)17A3B-2B17A2B2-3B15A3B3-3B13A3B4-3B13A3B5-3B11A3B7-4B7A4B9-13B12-9B16-5B18-)5B16-9B12-5B3A5B9-4B7A4B7-3B11A3B5-3B13A3B4-2B15A2B3-3B15A3B2-2B17A2B-3B6(17A6B)17A3B-2B17A2B2-3B15A3B3-3B13A3B4-3B13A3B5-3B11A3B7-4B7A4B9-13B12-9B16-5B19-3B17-9B12-13B9-5B5A5B7-4B9A4B5-4B11A4B4-3B13A3B3-2(3B15A3B2-)2B17A2B-3B4(17A6B)17A3B-2B17A2B2(2-3B15A3B)3-3B13A3B4-4B11A4B5-4B9A4B7-5B5A5B9-13B12-9B17-3B21-B18-9B13-11B10-5B5A5B7-5B7A5B6-3B11A3B5-3B13A3B3-4B13A4B2(2-3B15A3B)2-2B4A-7A-4A2B-3B3A3-5A3-3A6B2A5-3A5-2A6B2(3A4-)3A3B-2B3A5-A5-3A2B2-3B3A4-A4-3A3B2-3B4A-5A-4A3B2-4B13A4B3-3B13A3B5-3B11A3B6-5B7A5B7-5B5A5B10-11B13-9B18-B42-7B14-11B11-13B9-5B5A5B7-D3B9A3BD5-3B13A3B4-3B13A3B3-4B13A4B2-3B2A4-3A4-2A3B2-3B2(A6-)A3B2(2-2B2(A7-)A2B)2-2BA15-A2B2(2-3BA13-A3B)2-4B2(A5-)A4B3-3B2A3-3A3-2A3B4-4B11A4B5-4B9A4B7-5B5A5B9-13B11-11B14-7B63-5B16-9B12-13B9-6B3A6B7-D4B7A4BD6-3B11A3B5-C2B13A2BC4-3B2A-7A-2A3B3-3B2(A6-)A3B2(2-2B2(A7-)A2B)2-BC17-CB2(2-2BA15-A2B)2-3BA13-A3B3-2BA13-A2B4-3B2(A5-)A3B5-3B2A-5A-2A3B6-5B7A5B7-6B3A6B9-13B12-9B16-5B86-BCDBDCB14-CD7BDC11-D11BD9-C13BC7-C4B7A4BA6-C2B11A2BA5-CB2A3-5A3-2ABC2(4-B2(A7-)AB)3(4-B17-B)4-2B15-2B4-BC15-CB4-2BA13-A2B5-BA13-AB6-2B2A3-3A3-2A2B7-2(3B3A)3B9-13B11-11B14-7B110-DCD17-DC2BDABAD13-CBD6ADA11-CB10AC9-CB13A7-CB15A6-B15AB6-B2(2A5-)AB5-B-2(A7-)4(B4-B17-)B5-2(BA14-B6-)B2A12-AB7-B2A4-BA4-A2B8-B11A2B10-B9A2B12-4B2A4B16-3B134-5C16-2C5B2C13-C9BC11-C11BC9-D13BD8-2B3-5A3-2B7-B7-A7-B6-B7-A7-B75-B15-B6-B15-B7-B13-B8-B13-B9-2B3-3B3-2B11-11B13-9B16-5B179-5C16-3C3B3C13-DC7BCD11-BD9BDB10-2B-BE3BEB-2B9-B5-CBC5-B15-A22-A84-B13-B32-2(B5-)B11-2B-5B-2B13-9B16-5B226-FCF18-3(DB)D15-9B13-11B15-2(B-)B19-3B21-B114-B21-3B18-7B18-3B295-5B17-7B15-3B-B-3B17-3B21-B68-B22-B21-3B19-5B411-4(B22-)B241-
