model
size = 12 31 19, scale = 0.05, origin = -y
material deform = 1, fade = true, lighting = smooth, roughness = 0.3, metalness = 0.6
  colors = A:#111 B:#555 C:#777 D:#222 E:#BBB F:#444
voxels
35-A371-A245-2A37-A86-A10-2A233-2A50-A84-A10-A211-A11-3A7-A-2A38-A95-A10-2A199-2A9-3AD7-A-2A26-A35-A23-A34-9(A11-)A92-B11-2(2B10-)2CD9-A26-A35-A24-A11-A8-2A-A5(8-A-2A)8-A6(-A9-D)22-B11-B10-C2BD8-2(C2B2D7-)CBAD8-CBAD9-C2A9-3A8-6A9-2A23-2A47-A7-ADB-A5(6-2A2(BA))3(6-2AB3A)2(6-2A2(BA))6-2AB2A8-2BA8-4B9-3B7-C4B7-C2(AB)D5-2C2(AB)D5-EC2(AB)D5-2E2(AB)A3-A-2C2(AB)A5-A2C3BA5-2C4BA7-5A8-4A23-2A56-AB-A5(8-AB2A)8-AB3A7-AB3A5-2AB4A5-2ABAB2A5-2A2(BA)6-2AB2A7-2(BA)8-2BA2B6-BC2(BA)6-E2(AB)A4(5-E3(BA))3-2A2B2(AB)A4-8A5-2(7A6-)6A6-2C2-2A22-2A10-2A45-A-A9-A11-3(A-A9-)A-2A8-A-2A7-A2B2(2A5-2ABAB)A6-2AB3A6-2(BA)8-2BABA6-2(3(BA)5-F)3(BA)5-E3(BA)5-F2(3(BA)5-E)3(BA)4-A6BA4-2A5BA5-D7A6-C5A6-2C-3A2(10-2A)44-AB-A5(8-AB2A)8-AB3A7-AB3A5-2AB4A5-2ABAB2A5-2A2(BA)6-2AB2A7-2(BA)8-2BA2B6-BC2(BA)6-E2(AB)A4(5-E3(BA))3-2A2B2(AB)A4-8A5-2(7A6-)6A6-2C2-2A22-2A10-2A23-A7-ADB-A5(6-2A2(BA))3(6-2AB3A)2(6-2A2(BA))6-2AB2A8-2BA8-4B9-3B7-2C3B7-C2(AB)D5-2C2(AB)D5-EC2(AB)D5-2E2(AB)A3-A-2C2(AB)A5-A2C3BA5-2C4BA7-5A8-4A23-2A35-A11-A8-2A-A5(8-A-2A)8-A6(-A9-D)22-B11-B10-C2BD8-2(C2B2D7-)CBAD8-CBAD9-C2A9-3A8-5A10-2A23-2A35-A34-9(A11-)A92-B11-2B10-CB10-C2D9-A26-A35-A72-A10-2A198-3A9-3AD7-A-2A26-A35-A60-A10-A212-A9-4A7-A-2A38-A73-A10-2A233-2A50-A73-A245-2A37-A86-A336-
