model
size = 26 29 22, scale = 0.05, origin = -y
material deform = 1, fade = true, lighting = smooth, roughness = 0.3, metalness = 0.6
  colors = A:#606 B:#111 C:#222 D:#63F E:#EEE F:#66F G:#001
voxels
582-6B20-6B694-11B16-8B692-13B11-16B461-A24-DA24-2A172-16B9-19B7-2CB13-2B434-2A23-3A2(22-4A)23-2A24-2A118-21B5-2C5B6-8B325-6A19-D7A18-8A17-D9A3(16-10A)2(16-6A-3A)5(16-10A)18-7A10-22B5-C4B4-4C3-5B303-A18-10A15-12A14-2AD9A14-AD10A8(14-12A)13-C2(12A14-)12A9-C21B5-CB5-BC4B5-3B13-2BC2B283-4A16-2A-9A7(14-12A)2(13-E12A)2(13-F12A)14-12A13-C12A8-2B4-12A5-B2-BC7B6A9B8-4B5A3B15-10BC15-3(10B16-)C9B174-6A17-3(12A14-)B11A4(14-12A)13-G2(12A13-E)12A13-F12A14-12A13-C12A7-4B3-12A4-12B8A9B7-2B8A3B13-12BC14-2(11B15-)C10B15-11B15-C9B16-C2B5-2B50-3A23-3A20-2A-3A16-10A2(14-12A)14-B11A5(14-12A)2(13-E12A)2(13-F12A)14-12A14-C11A7-4B3-12A4-11B10A8B6-2B10A2B3(13-13B)14-4(11B15-)10B23-4A22-4A18-8A16-10A2(14-12A)14-B11A2(14-12A)13-G8(12A14-)12A7-4B3-12A4-11B11A2BC4B6-2B11AB12-14B2(13-13B)2(13-C12B)14-2(11B15-)10B24-3A23-3A18-8A16-10A2(14-12A)14-B11A3(14-12A)13-G7(12A14-)12A7-4B3-12A4-11B11A2BC4B6-2B11AB2(12-14B)4(13-13B)14-11B49-3A23-3A20-2A-2AD16-10A3(14-12A)14-B11A4(14-12A)2(13-E12A)2(13-F12A)14-12A13-C12A7-4B3-12A4-11B11A7B6-2B11AB12-14B5(13-13B)14-11B15-10B96-6A17-7(12A14-)12A13-G2(12A13-E)12A13-F12A14-12A13-C12A7-4B3-12A4-11B11A7B6-2B10A2B12-3B2(A6BA3B13-2B)2(-6B-3B13-2B)-6B-3B14-B-6B-2B15-11B15-10B97-5A-A15-7(12A14-)2(12A13-E)2(12A13-F)12A14-12A13-C12A7-4B3-12A4-11B10A8B6-2B10A2B13-11B2C13-11BCB14-10B2(C15-C9B)C15-11B15-10B16-4B3-3B99-4A17-A-9A11(14-12A)13-C12A14-12A8-2B4-12A5-B2-10B5A9B8-5B3A3BC15-2(9BC16-)C8BC17-C7B18-8B202-3AD2A19-4AD3A18-D7A17-2D8A4(16-10A)16-6AB2AD4(16-10A)16-8A2D18-AD5A9-17BC5BC9-C7B2C17-3C3B2C19-6B20-6B21-5B22-3B336-2A24-2A23-A2-A22-A2-A23-A-A24-2A116-16BC4BC5-2CB5-4CB4-3BC509-2A24-DA25-A144-21B5-2B3C10-5BC710-14B10-4BC13BC7-4C10-4B689-8B13-18B8-3B5C10B714-10B14-14B15-3BC4B165-
