model
size = 19 28 19, scale = 0.05, origin = -y
material deform = 1, fade = true, lighting = smooth, roughness = 0.3, metalness = 0.6
  colors = A:#FC0 B:#222 C:#000
voxels
4-8A10-2A4-5A7-2A5-6A5-2A6-2(2ABAB3A3-A7-)2ABAB3A2-2A7-14(2ABAB3A2-A8-)2ABAB3A2-2A2(7-2ABAB3A3-A)7-2ABAB3A3-2A6-2AB3A6-2A5-5A8-2A2-3A13-4A15-8A10-2A4-5A7-2A5-6A5-2A6-2A4B2A3-A6-B2A4B4A-A6-B2A5B5A6-B2(2A5B4A8-)2A5(5B4A7-3A)7(5BA2-A7-3A)5BA2-2A6-3A5BA3-A6-3A4B2A3-A6-3A3B3A3-2A5-3A2B2A6-2A5-5A8-2A2-3A13-4A20-2(3A16-5A14-6A13-A5B2A10-BA5B4A2(8-BA6B3A)2(9-A6B3A)2(8-2A6B3A)8-2A6B2AB8-2A6B3A8-9(2A6BA10-)2A5B2A10-2A4B3A10-2A3B2A13-5A52-)2(3A16-5A14-6A13-8A10-2(B10A8-)B2(10A9-)10A2(8-11A)8-10AB8-11A8-11(9A10-)7A13-5A52-)3A16-5A14-6A13-8A10-2(B10A8-)B2(10A9-)10A2(8-11A)8-10AB8-11A8-3(9A10-)2(8AC10-)9A2(10-8AC)3(10-9A)10-7A13-5A52-3A16-5A14-6A13-8A10-2(B10A8-)B2(10A9-)10A2(8-11A)8-10AB8-11A8-2(9A10-)8AC10-9A2(10-8AC)2(10-9A)10-8AC2(10-9A)10-7A13-5A52-3A16-5A14-6A13-8A10-2(B10A8-)B2(10A9-)10A2(8-11A)8-10AB8-11A8-9A2(10-8AC)2(2(10-9A)10-8AC)10-8AC10-9A10-7A13-5A52-3A16-5A14-6A13-8A10-2(B10A8-)B2(10A9-)10A2(8-11A)8-10AB8-11A8-2(9A10-)3(8AC2(10-9A)10-)7A13-5A52-3A16-5A14-6A13-8A10-2(B10A8-)B2(10A9-)10A2(8-11A)8-10AB8-11A8-9A9(10-8AC)10-9A10-7A13-5A52-3A16-5A14-6A13-8A10-2(B10A8-)B2(10A9-)10A2(8-11A)8-10AB8-11A8-2(9A10-)8AC5(10-9A)10-8AC2(10-9A)10-4(7A13-5A52-3A16-5A14-6A13-8A10-2(B10A8-)B2(10A9-)10A2(8-11A)8-10AB8-11A8-11(9A10-))7A13-5A47-8A10-2A4-5A7-2A5-6A5-2A6-8A3-A6-B10A-A6-B12A6-B2(11A8-)11A4(7-12A)7(7-9A2-A)7-9A2-2A2(6-9A3-A)6-9A3-2A5-7A6-2A5-5A8-2A2-3A13-4A15-8A10-2A4-5A7-2A5-6A5-2A6-2(8A3-A7-)8A2-2A7-2(8A2-A8-)12(2AB5A2-A8-)2AB5A2-2A2(7-2AB5A3-A)7-2AB5A3-2A6-3AB2A6-2A5-5A8-2A2-3A13-4A116-6B13-6B402-
