model
size = 32 32 4, scale = 0.05, origin = -y
material deform = 1, fade = true, lighting = smooth, roughness = 0.3, metalness = 0.6
  colors = A:#39F B:#FFF C:#69F D:#CCF E:#9CC F:#6CF G:#EEE H:#CFF
voxels
11-C10AC19-C10AC18-16A14-20A11-22A9-9AFE2DEF9A7-7ACD8BDC7A5-7AD12BE7A4-6AH14BD6A3-6AH16BD6A2-5AD18BE5A-C4AC4BC10AG4B5AC5AD3BD11AF4BD10A4BE3AEHDFHDC2AG3BG9AF4BE3C2BDEHFG2DFG3BC8AE6B3EH4AF7BF8AE6BC2AG4AC7BF8AE6BD2AG4AC7BF8AF7B2AG4AF7BC8AC7BEDB4AD7B10A9BD3AC7BG10AD8BF2ACG7BE5AC5A8BGDE8BG5AC-5AE8BEC8BF5A2-6AD16BE6A3-6AD14BD6A4-7AE11BGF7A5-8AEG6BGE8A7-9AC3FC10A9-22A11-20A14-16A18-C10AC18-16A14-20A11-22A9-9AFE2DEF9A7-7ACD8BDC7A5-7AD12BE7A4-6AH14BD6A3-6AH16BD6A2-5AD18BE5A-C4AC4BC10AG4B5AC5AD3BD11AF4BD10A4BE3AEHDFHDC2AG3BG9AF4BE3C2BDEHFG2DFG3BC8AE6B3EH4AF7BF8AE6BC2AG4AC7BF8AE6BD2AG4AC7BF8AF7B2AG4AF7BC8AC7BEDB4AD7B10A9BD3AC7BG10AD8BF2ACG7BE5AC5A8BGDE8BG5AC-5AE8BEC8BF5A2-6AD16BE6A3-6AD14BD6A4-7AE11BGF7A5-8AEG6BGE8A7-9AC3FC10A9-22A11-20A14-16A18-C10AC20-C10AC18-16A14-20A11-22A9-9AFE2DEF9A7-7ACD8BDC7A5-7AD12BE7A4-6AH14BD6A3-6AH16BD6A2-5AD18BE5A-C4AC4BC10AG4B5AC5AD3BD11AF4BD10A4BE3AEHDFHDC2AG3BG9AF4BE3C2BDEHFG2DFG3BC8AE6B3EH4AF7BF8AE6BC2AG4AC7BF8AE6BD2AG4AC7BF8AF7B2AG4AF7BC8AC7BEDB4AD7B10A9BD3AC7BG10AD8BF2ACG7BE5AC5A8BGDE8BG5AC-5AE8BEC8BF5A2-6AD16BE6A3-6AD14BD6A4-7AE11BGF7A5-8AEG6BGE8A7-9AC3FC10A9-22A11-20A14-16A18-C10AC20-C10AC18-16A14-20A11-22A9-9AFE2DEF9A7-7ACD8BDC7A5-7AD12BE7A4-6AH14BD6A3-6AH16BD6A2-5AD18BE5A-C4AC4BC10AG4B5AC5AD3BD11AF4BD10A4BE3AEHDFHDC2AG3BG9AF4BE3C2BDEHFG2DFG3BC8AE6B3EH4AF7BF8AE6BC2AG4AC7BF8AE6BD2AG4AC7BF8AF7B2AG4AF7BC8AC7BEDB4AD7B10A9BD3AC7BG10AD8BF2ACG7BE5AC5A8BGDE8BG5AC-5AE8BEC8BF5A2-6AD16BE6A3-6AD14BD6A4-7AE11BGF7A5-8AEG6BGE8A7-9AC3FC10A9-22A11-20A14-16A18-C10AC10-
