model
size = 16 14 21, scale = 0.05, origin = -y
material deform = 1, fade = true, lighting = smooth, roughness = 0.3, metalness = 0.6
  colors = A:#BBB B:#630 C:#993 D:#555 E:#D00 F:#111 G:#930
voxels
135-2(2A14-)2(2D14-)2D126-4(2A14-)2D14-2D55-32B39-5(2A14-)2A71-17B11-C2-B23-5(2A14-)2A73-12B2-17B-2C2-4A3-C-B5-6A10-6A11-4A12-4A13-2A14-2A89-B10-B2-17B-2C-6A4-B4-8A8-8A9-6A11-4A12-4A13-2A89-B10-B2-17B4-6A4-B4-8A8-8A9-6A10-6A11-4A12-4A88-B10-B2-17B4-6A-C2-B4-F6AF2(8-8A)9-6A10-6A11-4A88-B10-B2-7B2A8B2C2-6A2-C-B4-8A8-F6AF2(8-8A)9-6A11-4A88-B10-B2-7B2A8B-C2-6A2-C-B4-3(8A8-)8A9-6A11-4A88-B10-B2-7B2A8B4-6A2-C-B4-3(8A8-)8A9-6A11-4A88-B10-B2-7B2A8B2-C-6A2-C-B4-3(8A8-)8A9-6A11-4A13-2A73-B10-B2-17B4-6A2-C-B4-3(8A8-)8A9-6A11-4A13-2A73-B10-B2-17B-C2-6A4-B4-3(8A8-)8A9-6A11-4A13-2A73-B10-B2-17B-C2-6A2C2-B4-2(8A8-)8A9-6A10-6A11-4A12-4A13-2A57-12B2-17B5-4AC-2C-B5-3(6A10-)6A11-4(4A12-)4A13-2A14-2A23-17B2(2-C)8-B38-8(4A12-)4A22-32B3-C83-2E13-4(4A12-)4A125-2(2E14-)2E13-2(4A12-)F2AF12-4A173-2G222-2G55-
