model
size = 30 17 21, scale = 0.05, origin = -y
material deform = 1, fade = true, lighting = smooth, roughness = 0.3, metalness = 0.6
  colors = A:#800 B:#F8C200
voxels
3-18(2B28-2B124-2(21A9-)15A16-4(3A28-)2A28-2A27-2A2(24-6A)18-)2B28-2B124-2(21A9-)15A16-2(4(3A28-)2A28-2A27-2A2(24-6A)15-62B28-2(2B5-2B21-)2(2B5-2B21A)9B21A9B-)3A8-9A11-3A9-7A12-3A10-5A13-3A11-3A14-2A13-A14-2A27-2A2(24-6A)15-
