model
size = 32, scale = 0.05, origin = -y
material deform = 1, fade = true, lighting = smooth, roughness = 0.3, metalness = 0.6
  colors = A:#070 B:#040 C:#0E0 D:#6F0 E:#0F0 F:#0F6 G:#3F0 H:#0D0 I:#6C0 J:#3F3 K:#0F3 L:#EEE
voxels
39-8AC7A16-8AC8A15-6A2(CA)C6A15-6AC3AC6A15-4ACAC3ACAC4A15-4AC7AC4A15-2A2(C5A)C2A15-CA3(C3A)CAC15-17A119-2D28-CD3CK22-2IF2HDI2CKIF2I18-CF2CD2HCK3CFC18-F2ECD2EHKH3GF18-3CD6G2H2C18-4G3DK4D2H23-CK2C764-4A27-6A25-3(8A24-)8A25-6A27-4A568-7(12A20-)4A4-4A20-3A6-3A19-3(3A8-3A18-)3A8-3A19-3A6-3A20-4A4-4A21-10A23-8A26-4A374-3(16A16-)9(2A12-2A16-)A14-A15-3(2A14-)2A15-A14-A2(16-2A12-2A)17-2A10-2A18-3A8-3A19-4A4-4A22-8A27-2A310-18A10(14-A16-A)13-2(2A16-2A12-)2(A18-A12-)2A16-2A12-2A16-2A13-A16-A2(14-2A)15-A14-A16-2A12-2A17-3A8-3A20-4A2-4A24-6A276-19A12-20A12-A18-A12-6(A18-2A11-)A18-2A10-2A18-2A6(10-A20-A)10-2A18-2A11-A18-A12-2A16-2A13-A16-A15-A14-A17-2A10-2A19-3A6-3A22-8A242-2(6A13-2A11-)6A8B5A-A11-A19-A9-6(2A21-A8-)7(A22-A8-)A22-A9-A20-A10-A20-A11-A18-A13-A16-A2(14-2A)16-A12-A19-2A8-2A22-8A208-2(5A17-2A8-)5A16-A-A8-5A14B3A-A8-A-A18BA-6(A8-A22-)A7-5(A24-A6-)A24-A7-2(A22-A8-)A22-A9-A20-A11-A18-A12-A18-A13-2A14-2A16-A12-A19-3A6-3A23-6A177-2A20-3A4(7-2A20-A-A)5(7-A23-A)3(6-A24-A)5-A26-A4-A26-A5-3(A24-A6-)A24-A7-A22-A8-A22-A9-A20-A10-A20-A11-A18-A13-2A14-2A16-2A10-2A20-4A2-4A26-2A147-2A20-3A5-4A20-A-A5-4A2(20-A2-A4-2A-A)20-A2-5(A4-2A25-)8(A4-A26-)A5-2(A24-A6-)A24-A7-A22-A9-A20-A11-A18-A13-A16-A15-A14-A17-3A8-3A21-8A142-4A20-3A5-A-2A20-A-A5-A-2A20-A2-A4-A2-A20-A2-A4-A2-B20-B2-7(A4-A26-)A3-3(A28-A2-)A28-A3-3(A26-A4-)A26-A5-A24-A6-A24-A7-A22-A9-A20-A11-A18-A13-A16-A15-2A12-2A18-4A4-4A24-4A112-3A21-3A5-A-A21-A-A5-A-A21-A2-2A3-A2(2-B20-B2(3-A))4(27-A3-A)27-8(A2-A28-)A3-2(A26-A4-)A26-A5-A24-A7-A22-A8-A22-A9-A20-A11-2A16-2A2(14-A)17-3A8-3A21-8A110-3A21-3A5-A-A21-A-A5-A-A21-A2-2A3-A2(2-B20-B2(3-A))4(27-A3-A)27-9(A2-A28-)A3-A26-A4-A26-A5-A24-A6-A24-A7-A22-A9-A20-A11-A18-A13-2A14-2A16-2A10-2A20-10A109-3A21-3A5-A-A21-A-A5-A-A21-B2-2A3-A2(2-B20-B2(3-A))4(27-A3-A)27-2(A2-A28-)A-A3(30-2A)30-A-3(A28-A2-)A28-A3-A26-A4-A26-A5-A24-A7-A22-A8-A22-A9-2A18-2A12-A16-A15-2A12-2A18-4A4-4A24-4A80-3A21-3A5-A-A21-A-A5-A-A21-B2-2A3-A2(2-B20-B2(3-A))4(27-A3-A)27-A2-A28-A-A3(30-2A)30-EA30-2A30-A-2(A28-A2-)A28-A3-A26-A4-A26-A5-A24-A6-A24-A7-A22-A9-A20-A11-2A16-2A14-2A12-2A18-3A6-3A23-6A79-3A21-3A5-A-A21-A-A5-A-A21-B2-2A3-A2(2-B20-B2(3-A))4(27-A3-A)27-A-2A29-3(2A30-)3(EA30-)2A30-A-2(A28-A2-)A28-A3-A26-A5-A24-A6-A24-A7-A22-A9-A20-A11-2A16-2A2(14-A)17-3A8-3A21-8A78-3A21-3A5-A-A21-A-A5-A-A21-B2-2A3-A2(2-B20-B2(3-A))4(27-A3-A)27-A-2A29-2(2A30-)5(EA30-)E2(-A29-C)-A28-A2(C2-A26-A-)C3-A24-A2-C4-A22-A3-C5-A20-A4-C6-A18-A5-C7-2A14-2A6-C9-2(3A8-)C12-8A11-C66-3A21-3A5-A-A21-A-A5-A-A21-B2-2A3-A2(2-B20-B2(3-A))4(27-A3-A)27-A-2A29-3(2A30-)EA2(30-EB)30-2B30-B-2(A28-A2-)A28-A3-A26-A4-A26-A5-A24-A7-A22-A9-A20-A11-A18-A13-2A14-2A16-3A8-3A21-8A78-3A21-3A5-A-A21-A-A5-A-A21-B2-2A3-A2(2-B20-B2(3-A))4(27-A3-A)27-A-2A29-3(2A30-)AB30-EB2(30-2B)30-B-2(A28-A2-)A28-A3-A26-A5-A24-A6-A24-A7-A22-A9-A20-A11-2A16-2A2(14-A)17-3A8-3A21-8A78-3A21-3A5-A-A21-A-A5-A-A21-B2-2A3-A2(2-B20-B2(3-A))4(27-A3-A)27-A2-A28-A-A2(30-2A)30-AB30-AC30-BC30-C-B28-B2(2-A28-A)3-A26-A4-A26-A5-A24-A6-A24-A7-A22-A9-A20-A11-2A16-2A14-2A12-2A18-3A6-3A23-6A79-3A21-3A5-A-A21-A-A5-A-A21-B2-2A2(2-A3-B20-B3-A)7(2-A28-A)-A2(30-AB)30-CD30-D-C28-C2-B28-B2(2-A28-A)3-A26-A4-A26-A5-A24-A7-A22-A8-A22-A9-2A18-2A12-A16-A15-2A12-2A18-4A4-4A24-4A81-2A21-3A5-A-A21-A-A5-A-A21-A2-2A2(2-A3-B20-B3-A)8(2-A28-A)2-B28-A2-C28-B2(2-C28-C)2-B28-B2-A28-A3-A26-A4-A26-A5-A24-A6-A24-A7-A22-A9-A20-A11-A18-A13-2A14-2A16-2A10-2A20-10A110-2A21-3A5-A-A21-A2-A3-A2-A21-A2(2-2(A3-)B20-B)2-5(A3-A27-)A3-3(A28-A2-)B28-A2-C28-B2(2-C28-C)2-B28-B3-2(A26-A4-)A26-A5-A24-A7-A22-A8-A22-A9-A20-A11-2A16-2A2(14-A)17-3A8-3A21-8A111-2A21-3A5-A-A21-A-A4-A2-A21-A2-2(A3-)A20-A2-2(A3-)B20-B2-7(A3-A27-)A3-B28-A2-B28-B2-F28-C2-D28-D3-C26-C4-B26-B2(4-A26-A)5-A24-A6-A24-A7-A22-A9-A20-A11-A18-A13-A16-A15-2A12-2A18-4A4-4A24-4A113-2A21-2A6-A-A21-A-A5-A-A21-A-A4-A3-A20-A2-2(A3-)A20-A2-7(A3-A27-)A3-B27-B4-B26-B4-C2(26-C4-J)26-D4-B26-B5-B2(24-A6-A)24-A7-A22-A9-A20-A11-A18-A13-A16-A15-A14-A17-3A8-3A21-8A143-2A21-2A6-A-A21-A-A5-A-A20-A2-A4-A3-2AB16-BA2-2(A4-)2B16-2B2-2(A4-A26-)A4-C26-C4-A27-C2(3-A27-A)3-A26-A5-B25-B5-C26-B4-E26-E5-2(C24-C6-)B24-B6-B24-B7-A22-A8-A22-A9-A20-A10-A20-A11-A18-A13-2A14-2A16-2A10-2A20-4A2-4A26-2A147-A21-2A6-3A20-A2-A5-A-A20-A2-A5-A2-4A14B2A3-2(A5-A25-)A5-C25-C2(5-A25-A)5-2(A26-A4-)B25-A6-B24-B6-C24-G6-E24-E6-J24-C6-G24-D7-B22-C8-B22-B8-A22-A9-A20-A11-A18-A12-A18-A13-2A14-2A16-A12-A19-3A6-3A23-6A134-A31-A10-A20-3A7-2A20-A-A6-A-A20-A2-A5-A2-5A12B3A3-A5-A25-A5-C25-C5(5-A25-A)5-B25-A6-B23-B8-C22-G8-J22-E8-J22-C8-G22-D8-B22-F9-B20-B10-A20-A11-A18-A13-A16-A2(14-2A)16-A12-A19-2A8-2A22-8A164-2A30-A11-6A2-15A8-2(A-5A2-13A2-A7-)A5-A2-B14-A7-A6-2B15-A7-C23-C5(7-A23-A)7-B23-B8-B21-B2(10-J20-G)10-C20-C10-G20-F10-CF18-CJ11-B18-B12-2A16-2A13-A16-A15-A14-A17-2A10-2A19-3A6-3A22-8A196-A31-A12-19A-2A3(9-A5-2A14-A)9-A21-A9-C21-C4(9-A21-A)9-A21-B9-B19-I-B10-CIJ16-IF12-J18-C12-E18-G12-CF16-FC12-G17-HF13-C16-C2(14-2B)15-A14-A16-2A12-2A17-3A8-3A20-4A2-4A24-6A212-18A13-19A12-5(2A17-2A11-)CE17-EC11-2A17-2A11-9A4-8A11-6AB8-B5A11-4A2B10-2B3A11-5B12-4B11-B2I2C12-2C-B2(14-C)15-J16-C14-C2(F15-)C14-C15-G15-C16-C14-C17-2B10-2B18-3A8-3A19-4A4-4A22-8A27-2A246-17A12(15-A)2(15-E)15-7A4-6A22-4B26-3BDF3B23-BF2CDCFJCB21-2DF2D2-D2F2D20-CFH6-CFC18-IL12-LI16-C14-C15-E-L13-2F15-F14-J16-G14-H17-CF2DC4-2CH2C20-10B23-8A26-4A302-
