model
size = 32, scale = 0.05, origin = -y
material deform = 1, fade = true, lighting = smooth, roughness = 0.3, metalness = 0.6
  colors = A:#222 B:#F60 C:#500 D:#B00 E:#A00 F:#600 G:#E00 H:#400 I:#111
voxels
39-8BC8B15-8AC8A15-6A2(CA)C6A15-6AC3AC6A15-4A2(CA)I2(AC)4A15-4AC2AIAI2AC4A15-2AC3AIACAI3AC2A15-CAC2AIC3ACI2ACAC15-5I7A5I119-2D28-CD3CH22-2EG2HDE2CHEG2E18-CG2CD2HCH3CGC18-G2FCD2F3H3EG18-3CD6E2H2C18-4E3DH4D2H23-CH2C764-4A27-6A25-3(8A24-)8A25-6A27-4A568-7(12A20-)4A4-4A20-3A6-3A19-3(3A8-3A18-)3A8-3A19-3A6-3A20-4A4-4A21-10A23-8A26-4A310-16B4(16-16A)9(16-2A12-2A)16-A14-A15-3(2A14-)2A15-A14-A2(16-2A12-2A)17-2A10-2A18-3A8-3A19-4A4-4A22-8A27-2A246-18B2(14-18A)10(14-A16-A)13-2(2A16-2A12-)2(A18-A12-)2A16-2A12-2A16-2A13-A16-A2(14-2A)15-A14-A16-2A12-2A17-3A8-3A20-4A2-4A24-6A212-19B2(13-19A)12-20A12-A18-A12-6(A18-2A11-)A18-2A10-2A18-2A6(10-A20-A)10-2A18-2A11-A18-A12-2A16-2A13-A16-A15-A14-A17-2A10-2A19-3A6-3A22-8A178-6B13-2B3(11-6A13-2A)11-6A8B5A-A11-A19-A9-6(2A21-A8-)7(A22-A8-)A22-A9-A20-A10-A20-A11-A18-A13-A16-A2(14-2A)16-A12-A19-2A8-2A22-8A144-5B17-2B3(8-5A17-2A)8-5A16-A-A8-5A14B3A-A8-A-A18BA-6(A8-A22-)A7-5(A24-A6-)A24-A7-2(A22-A8-)A22-A9-A20-A11-A18-A12-A18-A13-2A14-2A16-A12-A19-3A6-3A23-6A113-2B20-3B2(7-2A20-3A)4(7-2A20-A-A)5(7-A23-A)3(6-A24-A)5-A26-A4-A26-A5-2(A24-A6-)2A23-A6-2A23-A7-A22-A8-A22-A9-A20-A10-A20-A11-A18-A13-2A14-2A16-2A10-2A20-4A2-4A26-2A83-2B20-3B2(7-2A20-3A)5-4A20-A-A5-4A2(20-A2-A4-2A-A)20-A2-5(A4-2A25-)8(A4-A26-)A5-2(A24-A6-)A24-A7-A22-A9-A20-A11-A18-A13-A16-A15-A14-A17-3A8-3A21-8A78-4B20-3B2(5-4A20-3A)5-A-2A20-A-A5-A-2A20-A2-A4-A2-A20-A2-A4-A2-B20-B2-7(A4-A26-)A3-3(A28-A2-)A28-A3-3(A26-A4-)A26-A5-A24-A6-A24-A7-A22-A9-A20-A11-A18-A13-A16-A15-2A12-2A18-4A4-4A24-4A48-3B21-3B2(5-3A21-3A)5-A-A21-A-A5-A-A21-A2-2A3-A2(2-B20-B2(3-A))4(27-A3-A)27-8(A2-A28-)A3-2(A26-A4-)A26-A5-A24-A7-A22-A8-A22-A9-A20-A11-2A16-2A2(14-A)17-3A8-3A21-8A46-3B21-3B2(5-3A21-3A)5-A-A21-A-A5-A-A21-A2-2A3-A2(2-B20-B2(3-A))4(27-A3-A)27-9(A2-A28-)A3-A26-A4-A26-A5-A24-A6-A24-A7-A22-A9-A20-A11-A18-A13-2A14-2A16-2A10-2A20-10A45-3B21-3B2(5-3A21-3A)5-A-A21-A-A5-A-A21-B2-2A3-A2(2-B20-B2(3-A))4(27-A3-A)27-2(A2-A28-)A-A3(30-2A)30-A-3(A28-A2-)A28-A3-A26-A4-A26-A5-A24-A7-A22-A8-A22-A9-2A18-2A12-A16-A15-2A12-2A18-4A4-4A24-4A16-3B21-3B2(5-3A21-3A)5-A-A21-A-A5-A-A21-B2-2A3-A2(2-B20-B2(3-A))4(27-A3-A)27-A2-A28-A-A3(30-2A)30-FA30-2A30-A-2(A28-A2-)A28-A3-A26-A4-A26-A5-A24-A6-A24-A7-A22-A9-A20-A11-2A16-2A14-2A12-2A18-3A6-3A23-6A15-3B21-3B2(5-3A21-3A)5-A-A21-A-A5-A-A21-B2-2A3-A2(2-B20-B2(3-A))4(27-A3-A)27-A-2A29-3(2A30-)3(FA30-)2A30-A-2(A28-A2-)A28-A3-A26-A5-A24-A6-A24-A7-A22-A9-A20-A11-2A16-2A2(14-A)17-3A8-3A21-8A14-3B21-3B2(5-3A21-3A)5-A-A21-A-A5-A-A21-B2-2A3-A2(2-B20-B2(3-A))4(27-A3-A)27-A-2A29-2(2A30-)5(FA30-)F2(-A29-C)-A28-A2(C2-A26-A-)C3-A24-A2-C4-A22-A3-C5-A20-A4-C6-A18-A5-C7-2A14-2A6-C9-2(3A8-)C12-8A11-C2-3B21-3B2(5-3A21-3A)5-A-A21-A-A5-A-A21-B2-2A3-A2(2-B20-B2(3-A))4(27-A3-A)27-A-2A29-3(2A30-)FA2(30-FB)30-2B30-B-2(A28-A2-)A28-A3-A26-A4-A26-A5-A24-A7-A22-A9-A20-A11-A18-A13-2A14-2A16-3A8-3A21-8A14-3B21-3B2(5-3A21-3A)5-A-A21-A-A5-A-A21-B2-2A3-A2(2-B20-B2(3-A))4(27-A3-A)27-A-2A29-3(2A30-)AB30-FB2(30-2B)30-B-2(A28-A2-)A28-A3-A26-A5-A24-A6-A24-A7-A22-A9-A20-A11-2A16-2A2(14-A)17-3A8-3A21-8A14-3B21-3B2(5-3A21-3A)5-A-A21-A-A5-A-A21-B2-2A3-A2(2-B20-B2(3-A))4(27-A3-A)27-A2-A28-A-A2(30-2A)30-AB30-AC30-BC30-C-B28-B2(2-A28-A)3-A26-A4-A26-A5-A24-A6-A24-A7-A22-A9-A20-A11-2A16-2A14-2A12-2A18-3A6-3A23-6A15-3B21-3B2(5-3A21-3A)5-A-A21-A-A5-A-A21-B2-2A2(2-A3-B20-B3-A)7(2-A28-A)-A2(30-AB)30-CD30-D-C28-C2-B28-B2(2-A28-A)3-A26-A4-A26-A5-A24-A7-A22-A8-A22-A9-2A18-2A12-A16-A15-2A12-2A18-4A4-4A24-4A16-3B21-3B2(5-3A21-3A)5-A-A21-A-A5-A-A21-A2-2A2(2-A3-B20-B3-A)8(2-A28-A)2-B28-A2-C28-B2(2-C28-C)2-B28-B2-A28-A3-A26-A4-A26-A5-A24-A6-A24-A7-A22-A9-A20-A11-A18-A13-2A14-2A16-2A10-2A20-10A45-3B21-3B2(5-3A21-3A)5-A-A21-A2-A3-A2-A21-A2(2-2(A3-)B20-B)2-5(A3-A27-)A3-3(A28-A2-)B28-A2-C28-B2(2-C28-C)2-B28-B3-2(A26-A4-)A26-A5-A24-A7-A22-A8-A22-A9-A20-A11-2A16-2A2(14-A)17-3A8-3A21-8A46-3B21-3B2(5-3A21-3A)5-A-A21-A-A4-A2-A21-A2-2(A3-)A20-A2-2(A3-)B20-B2-7(A3-A27-)A3-B28-A2-B28-B2-G28-C2-D28-D3-C26-C4-B26-B2(4-A26-A)5-A24-A6-A24-A7-A22-A9-A20-A11-A18-A13-A16-A15-2A12-2A18-4A4-4A24-4A48-3B21-2B2(6-3A21-2A)6-A-A21-A-A5-A-A21-A-A4-A3-A20-A2-2(A3-)A20-A2-7(A3-A27-)A3-B27-B4-B26-B4-C2(26-C4-D)26-D4-B26-B5-B2(24-A6-A)24-A7-A22-A9-A20-A11-A18-A13-A16-A15-A14-A17-3A8-3A21-8A78-3B21-2B2(6-3A21-2A)6-A-A21-A-A5-A-A20-A2-A4-A3-2AB16-BA2-2(A4-)2B16-2B2-2(A4-A26-)A4-C26-C4-A27-C2(3-A27-A)3-A26-A5-B25-B5-C26-B4-F26-F5-2(C24-C6-)B24-B6-B24-B7-A22-A8-A22-A9-A20-A10-A20-A11-A18-A13-2A14-2A16-2A10-2A20-4A2-4A26-2A81-3B21-2B2(6-3A21-2A)6-3A20-A2-A5-A-A20-A2-A5-A2-4A14B2A3-2(A5-A25-)A5-C25-C2(5-A25-A)5-2(A26-A4-)B25-A6-B24-B6-C24-E6-F24-F6-D24-C6-E24-D7-B22-C8-B22-B8-A22-A9-A20-A11-A18-A12-A18-A13-2A14-2A16-A12-A19-3A6-3A23-6A112-2B20-3B2(7-2A20-3A)7-2A20-A-A6-A-A20-A2-A5-A2-5A12B3A3-A5-A25-A5-C25-C5(5-A25-A)5-B25-A6-B23-B8-C22-E8-D22-F8-D22-C8-E22-D8-B22-G9-B20-B10-A20-A11-A18-A13-A16-A2(14-2A)16-A12-A19-2A8-2A22-8A143-7B2-15B2(8-7A2-15A)8-2(A-5A2-13A2-A7-)A5-A2-B14-A7-A6-2B15-A7-C23-C5(7-A23-A)7-B23-B8-B21-B2(10-D20-E)10-C20-C10-E20-G10-CG18-CD11-B18-B12-2A16-2A13-A16-A15-A14-A17-2A10-2A19-3A6-3A22-8A176-23B9-23A9-20A-2A3(9-A5-2A14-A)9-A21-A9-C21-C4(9-A21-A)9-A21-B9-B19-E-B10-CED16-EG12-D18-C12-F18-E12-CG16-GC12-E17-HG13-C16-C2(14-2B)15-A14-A16-2A12-2A17-3A8-3A20-4A2-4A24-6A210-21B11-21A5(11-2A17-2A)11-CF17-FC11-2A17-2A11-9A4-8A11-6AB8-B5A11-4A2B10-2B3A11-5B12-4B11-B2E2C12-2C-B2(14-C)15-D16-C14-C2(G15-)C14-C15-E15-C16-C14-C17-2B10-2B18-3A8-3A19-4A4-4A22-8A27-2A246-17B12(15-A)2(15-F)15-7A4-6A22-4B26-3BDG3B23-BG2CDCGDCB21-2DG2D2-D2G2D20-CGH6-CGC18-2E12-2E16-C14-C15-F-E13-2G15-G14-D16-E14-H17-CG2DC4-2CH2C20-10B23-8A26-4A302-
