model
size = 31 29 22, scale = 0.05, origin = -y
material deform = 1, fade = true, lighting = smooth, roughness = 0.3, metalness = 0.6
  colors = A:#111 B:#909 C:#777 D:#AAA E:#C6C F:#F0C
voxels
416-5F863-5F57-2(5A26-)5A768-2F5-2F4(22-2A5-2A)23-7A25-5A705-F9-F20-A9-A19-2A9-2A19-2(A9-A20-)2A7-2A21-2A5-2A23-7A27-A644-F11-F5(18-A11-A)19-A9-A21-A7-A23-7A634-3C3-F13-F4(10-3A3-A13-A)10-2(3A4-2(A11-))3A5-A9-A12-3A6-2A5-2A13-3A8-5A15-3A28-3D554-5C2-A13-F3-3C5(3-5A2-A13-A3-3A)2(3-5A3-A11-A4-3A)3-5A4-2A7-2A5-3A3-5A6-7A7-3A3-5A20-3A3-5D20-3D529-8C15-F-5C4(-8A15-A-5A)2(-7A-A13-A2-5A)-7A2-A11-A3-5A-7A3-A9-A4-5A-7A4-2(2A5-)5A-7A6-5A7-5A-7D18-5D528-8C15-8C8A3(15-16A)15-15A2(-A13-A-14A)2-A11-A2-14A3-A9-A3-14A4-2A5-2A4-14A6-5A6-7A7D17-7D527-8C7-A7-8C8A3(15-16A)15-15A2(-A13-A-14A)2-A11-A2-14A2-2A9-2A2-14A4-2A5-2A4-14A6-5A6-7A7D8-A8-7D5-B20-B9-B20-B470-5C-C15-8C4(-5A-A15-8A)2(-5A2-A13-A-7A)-5A3-A11-A2-7A-5A4-A9-A3-7A-5A2(5-2A)4-7A-5A7-5A6-7A-5D18-7D36-B20-B9-2B18-2B10-B18-B410-3C2-C15-C-5C4(3-3A2-A15-A-5A)2(3-3A3-A13-A2-5A)3-3A4-A11-A3-5A3-3A5-A9-A4-5A3-3A6-2(2A5-)5A3-3A8-5A7-5A3-3D20-5D100-B18-B416-F13-F3-3C5(10-A13-A3-3A)2(2(11-A)4-3A)12-2A7-2A5-3A14-7A7-2(3A28-)3D101-B18-B11-B18-B385-F13-F4(16-A13-A)17-A11-A18-A11-A19-A9-A21-2A5-2A24-5A205-B18-B385-FA11-AF17-4(A11-A18-)A11-A19-A9-A21-A7-A23-7A204-B18-B11-B18-B385-F2A9-2AF18-A9-A19-2A9-2A19-2(A9-A20-)A9-A21-A7-A23-7A27-A176-B18-B11-B18-B50-B2-B362-F4A5-4AF18-3A5-2A21-2A7-A21-3A5-2A21-3A5-3A20-10A21-10A22-3(10E21-)10E17-B3-10E3-B12-2B16-2B2(11-B18-B)81-B2-B362-F13AF17-5(13A18-)13A52-2(2A-)2A23-A2-2A-A19-B4-A2-2A-A5-B13-B16-B175-B2-B363-F11AF81-E-E2-3E2-E19-4(E-)E2-E19-E3-3(E-)3E78-2(B16-B13-)B16-B204-3B2-3B22-2B6-2B20-2B8-2B18-2B10-2B7(17-B12-B)16-2B12-2B14-2BF11AF-2B8(13-B16-B)636-F9AF889-2F5A2F507-
