model
size = 17 12 22, scale = 0.05, origin = -y
material deform = 1, fade = true, lighting = smooth, roughness = 0.3, metalness = 0.6
  colors = A:#020 B:#DDD
voxels
23-5A182-5A29-2(5A12-)5A129-4(2A5-2A8-)2A5-2A9-7A11-5A94-A9-A6-A9-A5-2A9-2A5-2(A9-A6-)2(2A7-)2A5-2A9-7A13-A61-5(A11-A4-)A11-A5-A9-2(A7-)A9-7A57-4(A13-A2-)A13-A3-A11-A4-A11-A5-A9-A7-2A5-2A10-5A41-5(A13-A2-)A13-A3-A11-A4-A11-A5-2A7-2A8-7A39-2(A4(15-2A)15-A-A13-A2-A13-A3-A11-A5-A9-A7-2A5-2A10-5A23-)2(A7-)4(2A15-)A-A13-A2-A13-A3-A11-A4-2A9-2A6-2A5-2A10-5A14-A8-A4(15-2A)15-A-A13-A2-A13-A3-A11-A5-A9-A7-2A5-2A10-5A23-A4(15-2A)15-A-A13-A2-A13-A3-A11-A5-A9-A7-2A5-2A10-5A24-5(A13-A2-)A13-A3-A11-A4-A11-A5-2A7-2A8-7A40-4(A13-A2-)A13-A3-A11-A4-A11-A5-A9-A7-2A5-2A10-5A41-2A11-2A3-4(A11-A4-)A11-A5-A9-2(A7-)A9-7A57-3A9-3A4-A9-A5-2A9-2A5-2(A9-A6-)A9-2(A7-)A9-7A13-A60-2(5A5-)2A5-2A8-A7-A8-2A5-2A7-B2A5-2AB7-B7AB9-B5AB14-B76-15A7-2(A-)A11-B2(-A)-B9-B2(-2A)-B10-5A31-B95-13A9-B-B13-2(B-)B14-B146-13A192-11A194-9A191-
