model
size = 10 25 3, scale = 0.05, origin = -y
material deform = 1, fade = true, lighting = smooth, roughness = 0.3, metalness = 0.6
  colors = A:#333 B:#222 C:#FFF D:#444 E:#DDD F:#555 G:#777 H:#EEE I:#666 J:#06C K:#039 L:#6F9 M:#888 N:#111
voxels
DF8BG2F2D5B10-2F5ID2B2(F8AB)D9A3(F8AB)GAJ5LABGA6GABGAG3AG2ABGA3GAG2ABG3AGA2GABGA3GAG2ABG8A2(BG8D)JGD-6DBG2(D6-DBI)5D2IDBF5DIBDB-8D-DF2MD5BG2F2D5B10-2F5ID2B3C3H6CH3EH5C4(H3E2H4C)4E2H4C5EH3(4C6E)4CEH4E4C2E2H2E4C2(EH)2E4C6HCLGBK4BA2BGA6KAB2F6JFB9FBFB7FB9FN10B240-
