model
size = 23 12 29, scale = 0.05, origin = -y
material deform = 1, fade = true, lighting = smooth, roughness = 0.3, metalness = 0.6
  colors = A:#FBE251 B:#444 C:#E83015 D:#888 E:#FFFFFB F:#777 G:#111 H:#FCFAF2
voxels
6-2(2A7C2A12-)3A5-3A12-4A3-4A14-7A17-5A151-2(3A2B5-2B3A8-)4AB5-B4A8-5AB3-B5A10-4A3B4A12-5AB5A15-5A127-2(2A2B9-2B2A6-)3A11-3A6-3A11-3A8-A11-A10-2(A11-)5AB5A15-5A103-2(2AB13-B2A4-)3A13-3A4-3A13-3A6-A13-A8-2A11-2(2A9-)2A12-4AB4A16-5A80-2(A2B13-2BA4-)2AB13-B2A4-2AB13-B2A5-AB13-BA6-ABA11-ABA7-2(3A9-)6AB6A12-9A77-2(2AB15-B2A2-)2A17-2A3-A17-A4-A17-A5-2AB11-B2A6-2ABA9-AB2A2(7-4A)10-5AB5A15-5A56-2(AB17-BA2-)A19-A2-A19-A3-A17-A4-A17-A5-3AB9-B3A6-3ABA7-AB3A8-6AB6A12-9A53-2AB17-B4AB17-B2A-A19-A2-A19-A3-A17-A4-A17-A5-A15-A6-4AB7-B4A8-6AB3AB2A12-9A53-AB19-B2AB19-B3A19-2A-A19-A2-2A17-2A3-A17-A4-2A15-2A5-3A11-3A8-3ABA3-AB3A12-4AB4A17-3A33-AB19-B2AB19-B3A19-4A19-2A-2A17-2A2-2A17-2A3-2A15-2A4-4A11-4A6-5AB3-B5A10-3A2(BA)B3A15-5A32-AB19-B2AB19-B3A19-4A19-2A-2A17-2A2-2A17-2A3-2A15-2A4-4A11-4A6-4A7-4A10-4A3B4A14-7A18-3C10-A3(B19-B2A)B19-BA-AB17-BA2-AB17-BA3-AB15-BA4-2A2B11-2B2A6-2A2B7-2B2A10-2A7B2A14-3AC3A18-3C10-AB19-B2AB19-B3A19-4A19-2A-2A17-2A2-2A17-2A3-2A15-2A4-4A11-4A6-4A7-4A10-4A3B4A14-7A18-3C10-2A2(B17-B4A)19-2A-A19-A2-2A17-2A3-A17-A4-2A15-2A5-3A11-3A2(7-4A)10-3A2(BA)B3A15-5A33-AB17-BA2-AB17-B2(H2-A19-)A3-A17-A4-A17-A5-A15-A6-3A11-3A8-3AB5-B3A12-4AB4A17-3A34-2AB15-B2A2-2AB15-B2(AH2-2A17-)2A3-2A15-2A4-2A15-2A5-A15-A6-3A11-3A8-2A2(B3A)B2A12-9A55-2(AB15-BA4-)A17-A4-A17-A5-A15-A6-A15-A7-2AB9-B2A8-2AB9-B2A10-5AB5A14-7A56-A3B11-3BA4-2A2B11-2B2A2(4-3AB11-B3A)6-AB11-BA8-AB11-BA2(9-2A)10-2A9-2A12-4AB4A17-3A58-CFD2B9-2BDFC4-C2A2B9-2B2AC5-2A12-3A6-2A12-3A8-2(A11-A10-)2A9-2A11-5AB5A14-7A79-C2(FD)9B2(DF)C4-2C3A9B3A2C6-3A4-B4-3A8-3A4-B4-3A9-2A4-B4-2A10-2A4-B4-2A11-A4-B4-A13-9A16-5A80-C3(FD)F3D3(FD)FC4-5C9A5C9-2A2EA2E2A14-A2(EGB)EA14-A2(E2G)EA14-A7EA14-2A2EA2E2A15-7A102-C2(FD)F2D3F2D2(FD)FC4-19C10-3E-3E15-2(2E2-E2-2E14-)9E15-3E-3E17-2E-2E103-C3(DF)5D3(FD)C4-19C235-C2(DF)D5F2(DF)DC6-17C236-C2DFDF5DFDF2DC6-17C237-C2DFD5FDF2DC8-15C239-C2DF5DF2DC10-13C241-2CD5FD2C12-11C243-9C14-9C237-
