model
size = 23 30 29, scale = 0.05, origin = -y
material deform = 1, fade = true, lighting = smooth, roughness = 0.3, metalness = 0.6
  colors = A:#111 B:#E83015 C:#444 D:#C62020 E:#888 F:#777 G:#EEE
voxels
329-9A13-5(11A12-)11A13-9A15-7A17-5A404-A13-A8-2A11-2A8-3A9-3A8-15A8-2A2(3BD)3B2A8-2A5(DB)D2A8-2AB2(D3B)DB2A2(8-3A9C3A)8-7AC7A9-6AC6A11-5AC5A12-5AC5A15-5A357-2(2A13-2A6-)AD13-2A6-AB13-BA6-AD13-DA6-ABD11-DBA6-ADB11-BDA6-A2B11-2BA2(6-2A2C9-2C2A)6-3A11-3A7-2A11-2A9-A11-A10-2(A11-)5AC5A15-5A310-A17-A4-2A15-2A4-AD15-2A4-AB15-BA4-AD15-D3(A4-AB15-B)A4-AD15-DA2(4-2AC13-C2A)4-3A13-3A5-2A13-2A7-A13-A8-2A11-2(2A9-)2A12-4AC4A16-5A264-3(A17-A4-)AB16-3(A4-AD15-DA4-AB15-B)2(A4-A2C13-2C)A2(4-2AC13-C2A)5-AC13-CA6-ACA11-ACA7-2(3A9-)6AC6A12-9A262-A17-2A2-AD17-BA2-AB17-BA2-AD17-D3(A2-AB17-B)A2-AD17-D2(A2-AB17-B)A2(2-2AC15-C2A)2-2A17-2A3-A17-A4-A17-A5-2AC11-C2A6-2ACA9-AC2A2(7-4A)10-5AC5A15-5A240-A19-4(A2-AB17-BA2-AD17-D)A2-AB17-B2(A2-AC17-C)2(A2-A19-)A3-A17-A4-A17-A5-3AC9-C3A6-3ACA7-AC3A8-6AC6A12-9A237-2A19-3A2(D19-D3(2AB19-B)2A)D19-D3AC17-C4AC17-C2A-A19-A2-A19-A3-A17-A4-A17-A5-A15-A6-4AC7-C4A8-6AC3AC2A12-9A214-2A19-3A5(D19-D2AB19-B2A)C19-C2AC19-C3A19-2A-A19-A2-2A17-2A3-A17-A4-2A15-2A5-3A11-3A8-3ACA3-AC3A12-4AC4A17-3A171-A21-3A19-3A3(B19-B2A)D19-D3(2AB19-B)2AD19-D2(2AB19-B)2(2AC19-C)3A19-4A19-2A-2A17-2A2-2A17-2A3-2A15-2A4-4A11-4A6-5AC3-C5A10-3A2(CA)C3A15-5A32-B7(21-2B)A19-ABA5(D19-D2AB19-B2A)C19-C2AC19-C3A19-4A19-2A-2A17-2A2-2A17-2A3-2A15-2A4-4A11-4A6-4A7-4A10-4A3C4A14-7A18-3B10-B7(21-2B)A19-2(AB)19-B2(2AD19-D3(2AB19-B))2AD19-D4(2AC19-C)A-AC17-CA2-AC17-CA3-AC15-CA4-2A2C11-2C2A6-2A2C7-2C2A10-2A7C2A14-3AB3A18-3B148-A21-3A19-3A4(D19-D2AB19-B2A)D19-B2AB19-B2(2AC19-C)3A19-4A19-2A-2A17-2A2-2A17-2A3-2A15-2A4-4A11-4A6-4A7-4A10-4A3C4A14-7A18-3B171-2A19-3A3(B19-B2A)D19-D3(2AB19-B)2AD19-D2(2AB19-B)3A2(C17-C4A)19-2A-A19-A2-2A17-2A3-A17-A4-2A15-2A5-3A11-3A2(7-4A)10-3A2(CA)C3A15-5A193-2A21-AD19-3A2(B19-B2AD19-D2A)B19-B2AD19-B2AB19-B2AD19-D2AB19-B3AC17-C2A-AC17-C2(A2-A19-)A3-A17-A4-A17-A5-A15-A6-3A11-3A8-3AC5-C3A12-4AC4A17-3A218-2A17-2A2(2-AD17-D3(A2-AB17-B)A)2-AD17-DA2(2-2AC15-C2A)2(2-2A17-2A)3-2A15-2A4-2A15-2A5-A15-A6-3A11-3A8-2A2(C3A)C2A12-9A262-9(A17-A4-)2(AC15-CA4-)2(A17-A4-)2A15-2A5-A15-A7-2AC9-C2A8-2AC9-C2A10-5AC5A14-7A355-5(A17-A4-)A3C11-3CA4-2A2C11-2C2A2(4-3AC11-C3A)5-2AC11-C2A7-AC11-CA2(9-2A)10-2A9-2A12-4AC4A17-3A472-BFE2C9-2CEFB4-B2A2C9-2C2AB5-3A11-3A6-3A11-3A7-2A11-2A9-A11-A10-2A9-2A11-5AC5A13-9A492-B2(FE)9C2(EF)B4-BD3A9C3ADB6-3A4-C4-3A8-3A4-C4-3A9-2(2A4-C4-2A10-)2A4-C4-2A11-11A14-7A493-B3(FE)F3E3(FE)FB4-2(BD)B9A2(BD)B8-3(11A12-)11A13-9A14-9A515-B2(FE)F2E3F2E2(FE)FB4-3(BD)7B3(DB)12-2(G-G19-5G19-)G-G541-B3(EF)5E3(FE)B4-2B2(DB)D5B2(DB)D2B649-B2(EF)E5F2(EF)EB6-2B2(DB)5D2(BD)2B650-B2EFEF5EFEF2EB6-3BDBD5BDBD3B651-B2EFE5FEF2EB8-3BDB5DBD3B653-B2EF5EF2EB10-3BD5BD3B655-2BE5FE2B12-3B5D3B657-9B14-9B237-
