model
size = 28 28 9, scale = 0.05, origin = -y
material deform = 1, fade = true, lighting = smooth, roughness = 0.3, metalness = 0.6
  colors = A:#222 B:#777 C:#444 D:#30C E:#111 F:#E00 G:#EEE H:#39C
voxels
161-4(2A26-)2A572-A26-2A12-A12-3A2(12-4A8-4A)13-2(3A8-3A14-)4A7-3A14-4A6-4A15-A8-4A15-A488-C26-2CA11-AC10-3C2A11-2A3C7-2C3A2(11-2A3C6-2C4A)11-2A3C6-2C3A12-2A4C5-2C3A12-2A4C4-3C3A12-2A5C3-3C3A13-A4C4-4C2A13-A2C6-5C14-3C457-4EB9-4B8-2B3E13-E3B6-2B2E15-E3B4-3BE16-2(2E2B4-2BE17-)2E3B3-2BE17-2E3B-H3BE17-2E3B2H3BE17-2E3BH4BE17-2E4B-4BE16-3B4-6B13-5B4-7B13-3B89-2G23-G288-G13-G11-4ED9-2DFD8-2D3E13-EF2D6-DF2E15-E2FD4-D2FE17-2(EFD4-DFE18-)E2FD3-DFE18-E2FD-HD2FE18-E2FD2HD2FE18-E3FHD3FE17-2EF3D-D3FE16-DFD2-D-DFD2FD13-2D2FD2(-2D)-4D13-3D2-3(2D-D24-)2(2DG)21-GDG-2D22-2D2-3D21-2D3-2D20-3D3-3D18-3D5-3D16-3D7-6D8-6D9-8D2G8D12-6D2G7D15-4D2G5D20-D2HD19-G13-G11-4EA9-4A8-2A3E13-E3A6-2A2E15-E3A4-3AE17-2(E2A4-2AE18-)E3A3-2AE18-E3A-H3AE18-E3A2H3AE18-E3AH4AE17-2E4A-4AE16-3A2-A-6A13-5A2(-2A)-4A13-3A2-3(2A-A24-)2(2AG)21-GAG-2A22-2A2-3A21-2A3-2A20-3A3-3A18-3A5-3A16-3A7-6A8-6A9-18A12-15A15-11A20-4A45-4EB9-4B8-2B3E13-E3B6-2B2E15-E3B4-3BE17-3(E2B4-2BE18-)E3B-H3BE18-E3B2H3BE18-E3B-4BE17-2E3B2-4BE16-3B4-6B13-5B7-4B13-4B88-2G23-G315-2C25-3CA11-A2C9-3C2A11-A4C7-2C3A2(11-A4C6-2C4A)11-2(A4C6-2C3A12-)A5C4-3C3A12-A5C3-4C3A13-5C4-4C2A13-4C8-2C14-3C486-2A25-3A13-2A10-3A2(13-3A8-4A)13-2(3A8-3A14-)3A7-4A14-4A6-4A14-4A8-2A15-2A452-
