model
size = 7 29 14, scale = 0.05, origin = -y
material deform = 1, fade = true, lighting = smooth, roughness = 0.3, metalness = 0.6
  colors = A:#E00 B:#DDD C:#100 D:#500 E:#400 F:#002 G:#020
voxels
98-2(A6-)2A5-FD5-FC2(5-2C)5-CA5-2A5-EA5-FA5-DE117-2(A6-)2A5-FD5-FC2(5-2C)5-CA5-2A5-EA5-FA5-DE76-CA5-DA5-FC5-BC5-DA5-2A2(5-AE)5-D2(A5-F)A2(5-2C)5-F2(A5-C)F5-DF2(5-BA)5-2A55-EF5-BE5-2D5-DA5-FA5-2A5-B2(E5-A)3(E5-D)E5-CB5-CA5-BA5-CA5-2C2(5-BC)5-BF5-CA5-FA4-2DA41-2(D6-)DE2(5-DA)2(5-2A)5-BA5-B2(E5-D)E5-CA5-CB3(5-CA)5-BA5-2B5-B2(A5-C)2(A5-)BA4-2BD3-2CFE5-2C28-8(A6-)2(B6-)A6-E6-B6-A3(6-B)6-D6-F6-A6-C5-CA4-DBA3-3BA3-FBGA5-A22-6(A6-)2(E6-)2(A6-)2(B6-)A3(6-B)6-E6-B6-A6-E6-A5-FA4-CBA3-C2BD3-3BA3-FGC5-F2(E7-4(A6-)CA5-AC5-C2(E5-D)E2(5-2A)5-BD5-BA2(5-2B)5-BA5-BD2(5-2D)5-DB2(5-DA)5-BE4-DBA3-F2CA2-2CDBA2-4C3-BDBA5-)E21-6(A6-)2(E6-)2(2(A6-)2(B6-))E6-B6-A6-E6-A5-FA4-CBA3-C2BD3-3BA3-FGC5-FE27-8(A6-)2(B6-)A6-E6-B6-A3(6-B)6-D6-F6-A6-C5-CA4-DBA3-3BA3-FBGA5-A27-2(D6-)DE2(5-DA)2(5-2A)5-BA5-B2(E5-D)E5-CA5-CB3(5-CA)5-BA5-2B5-B2(A5-C)2(A5-)BA4-2BD3-2CFE5-2C33-EF5-BE5-2D5-DA5-FA5-2A5-B2(E5-A)3(E5-D)E5-CB5-CA5-BA5-CA5-2C2(5-BC)5-BF5-CA5-FA4-2DA60-CA5-DA5-FC5-BC5-DA5-2A2(5-AE)5-D2(A5-F)A2(5-2C)5-F2(A5-C)F5-DF2(5-BA)5-2A25-
