model
size = 32 32 31, scale = 0.05, origin = -y
material deform = 1, fade = true, lighting = smooth, roughness = 0.3, metalness = 0.6
  colors = A:#996 B:#0C0 C:#777 D:#A00 E:#AAA F:#444 G:#9C0 H:#9C6 I:#700 J:#080 K:#EEE L:#111
voxels
394-2F7-2F21-2F7-2F917-5(2C7-2C21-)2C7-2C821-2C7-2C213-2C7-2C21-2C7-2C693-2C7-2C21-2C7-2C309-2C7-2C21-2C7-2C597-2C7-2C21-2C7-2C373-2C7-2C21-2C7-2C565-2C7-2C437-2C7-2C533-2C7-2C21-2C7-2C437-2C7-2C533-2C7-2C469-2C7-2C501-2C7-2C21-2C7-2C469-3(2C7-2C501-)2C7-2C469-2C7-2C21-2C7-2C501-2(2C7-2C469-2C7-2C533-)2C7-2C437-2C7-2C434-4(2A4-5A4-2A15-)2(2A4F5A4F2A15-)11(17A15-)2A4F5A4F2A16-A4F5A4FA151-3B28-5B2(26-6B)27-4B29-2B118-15(19A13-)19A14-18A14-17A15-17A86-3B27-6B25-8B24-3(9B23-)8B25-7B26-5B84-16(19A13-)19A14-18A14-17A21-5A58-6B25-8B23-4(10B22-)10B23-9B24-7B26-5B51-15(21A11-)21A12-20A13-18A14-17A20-2A3-A27-5B25-8B23-10B22-11B21-11B2(20-12B)21-11B21-10B23-9B24-7B27-2B21-12(21A11-)21A6-C2(30A2C)29A2C5-21A12-19A14-17A20-2A3-2A25-6B25-9B22-10B22-11B4(20-12B)21-11B21-10B23-8B26-4B20-11(21A11-)21A6-C30AC96AC30AC6-19A14-17A20-2A2B2A26-6B24-10B20-17B11-23B9-19B3DB8-3B2D14B5DB7-B4D15B4DB6-2B4D15B4DB5-2B4D14B-2B4D2B3-2B2D3B2-10B3-4B2DB2-5B6-9B6-5B-2B10-6B11-2B6-11(10A-10A11-)10A-10A6-C14A-15AC15A-16AB14A-10A7B14A-15AB15A-16AC14A-15AC6-9A-9A19-2A2B2A26-7B23-10B20-17B11-23B9-19B3-B8-3B2-14B13-B4-15B11-2B4-15B10-2B4-14B-2B4-2B3-2B2-3B2-10B3-4B2-B2-5B6-9B6-5B-2B10-6B11-2B6-11(21A11-)21A6-C30AC96AC30AC6-19A14-17A22-2A28-6B24-2(10B22-)6(11B21-)10B23-9B25-5B19-12(21A11-)21A6-C2(30A2C)30AC5-21A12-19A14-17A21-4A27-6B25-9B22-10B22-6(11B21-)9BD23-8B27-3B20-15(21A11-)21A12-20A13-18A14-17A21-3A30-2B28-7B24-9B2(22-10B)22-11B21-2(10B22-)9BI23-D6BD25-6B52-16(19A13-)19A14-18A14-C16A54-2B29-5B26-7B24-9B22-10B22-9B23-6B2I25-I4B4I23-I4BILI25-D5B28-3B53-15(19A13-)19A14-18A14-17A15-C14AC56-B30-3B27-7B25-2B3K2B25-7B26-3B29-2IB28-3IB28-ILIB29-2D-2D85-16(17A15-)17A16-16A16-C13AC87-3B28-5J27-J3-J26-J-3J156-D90-16(15A17-)15A18-14A18-C11AC436-18(12A20-)2C7A2C437-17(11A21-)11A23-7C441-4(A5-A25-)13(EHGEGHE25-)EHGEGHE461-
