model
size = 32 14 6, scale = 0.05, origin = -y
material deform = 1, fade = true, lighting = smooth, roughness = 0.3, metalness = 0.6
  colors = A:#222 B:#3CF C:#F03 D:#888 E:#444 F:#111 G:#0CF H:#6CF I:#6FF J:#AAA K:#0E0 L:#080 M:#C90 N:#960 O:#FFF P:#0CC Q:#963 R:#FF0 S:#9CF T:#00D U:#700 V:#F00 W:#CFF X:#050 Y:#FF9 Z:#00C
voxels
130-A25-2A3-A-A23-4A3-A24-4A29-2A4-2A29-4A24-A3-4A23-A-A3-2A25-A386-B30-C2B28-2C-3B24-3C321-B30-C2B28-2CBIB26-CJCA2I2B22-2C2JA-3A24-3A3-3B10A2-10A3C3-4B2A6-2A2-2A6-2A4C-5B22A5C5B8A2FA2F9A5C5B7A3F2(AF)8A5C5B6A4FAF2AF7A5C5B6A2F2(AF)2AF7A5C5B6A4FAF2AF7A5C5B6A4FA2FAF7A5C5B6A4FAF2AF7A5CBI3B7A3F2(AF)8A5CB2I2B8A2FA2F9A3CJC-B2IB22AC2JC3-2B-22A-2C4-3B10A2E10A3C3-B4D20E4DC-B5DE2TQN2TQ2N2KNQ3N2QE5DCB5DE2G2L2GLNQ2KQ6LE5DCB5DEGPBV3B2P2K3B3PGE5DCB5DE3GZ3GH4K3H2MHE5DCB5DES2HYH2M3BX4B2MBE5DCB5DE3HVH2M2HOU3H4GE5DCB5DE5G2H2G2UH2BR3BE5DCB5DE2G2H3BR3B4H3GE5DCB5DEBSH2BH5GBR5GE5DCB5DES3OWOP2GR4GS2OWE4DJCA3DBD20EDC3JA-3A-2A3F9A2(-A)2(-3A)3-3B22A3C3-4BA20-A4C-5BA20-A5C2BI2BA20-AC2A2C2(BI)BA20-AD3AC2BI2BA20-AD3AC5BA20-AC2A2C2B2DB2(A20-A5CB4D)A20-A5C2B2DBA20-A5C5BA20-A5C-4BA20-A4C3-2B-22A-2C2-
