model
size = 30 28 16, scale = 0.05, origin = -y
material deform = 1, fade = true, lighting = smooth, roughness = 0.3, metalness = 0.6
  colors = A:#EEE B:#111 C:#E00 D:#800 E:#F60
voxels
253-3B747-3A26-2(5A25-)5A26-3A656-5A24-7A22-4(9A21-)9A22-7A24-5A416-5B26-3B115-5A24-7A22-9A20-4(11A19-)11A20-9A22-7A24-5A25-5C206-3B28-6B26-B27-2B27-4B25-7B24-5B25-2B-2B54-5A24-7A22-9A20-11A18-4(13A17-)13A18-11A20-9A22-7A23-7C55-3A26-2(6A24-)6A25-4A26-2BA-B26-6B24-2B28-3B25-5B25-7B23-7B24-2B-2B53-7A22-9A20-11A18-6(13A17-)13A18-11A20-9A21-2C5A2C24-3A-C24-6A23-2(8A22-)8A23-6A24-5BA23-9B21-7B25-5B24-6B23-9B21-9B23-5B25-3A24-9A20-11A18-2(13A17-)14A3(15-15A)16-14A16-13A17-13A18-11A19-2C7A2C21-2C5AC23-7A22-8A22-2(9A21-)8A23-2BA2B2A23-9B20-7B-B23-5B24-7B22-9B21-9B23-5B24-5A23-9A20-11A18-13A17-13A16-4(15A15-)15A16-13A17-13A18-11AC18-2C7A2C19-3C6AC22-8A21-2(10A20-)10A21-8A22-2ABA2B2A21-12B19-9B22-2(7B23-)7B22-9B23-5B24-5A23-9A20-11A18-13A17-13A16-4(15A15-)15A16-13A17-13AB17-10A2CB17-2C7A2C2-B16-3C6AC4-B17-8A5-B15-10A5-B5-3B6-10A12-B7-10A11-B9-8A11-B10-2ABAB3A20-13B19-9B22-2(7B23-)7B22-9B21-9B22-5A23-9A20-11A18-13A17-13A16-4(15A15-)15A16-13A17-B12AB16-B10A2CB15-B-2C7ACD2-B13-B3-2C6AD4-B11-B5-8A5-B9-B6-8A6-B6-2B6-9A7-2B4-B7-9A8-B3-2B8-8A8-2B2(-B)8-8A8-B-B2-B6-12B6-B13-9B23-5B24-7B23-7B22-9B21-9B23-3A24-9A20-11A18-2(13A17-)13A16-2(15A15-)15A16-2(13A17-)B12A17-B10A2C16-B-3C6ACD16-B4-C-4A-D16-B6-6A16-B6-8A22-8A7-3B12-8A8-B14-6A10-B13-6A11-B9-12B20-9B23-2(5B25-)5B24-7B23-7B52-7A22-9A20-11A18-6(13A17-)13A18-11A20-8ACDC19-D2C4AC2D21-2C4-C24-B3AB24-B3(6A24-)B4A26-3A24-11B20-7B25-4B3(27-3B)26-5B54-5A24-7A22-9A20-11A18-4(13A17-)13A18-C10A20-C8A22-7AD22-D5CD23-DC4-C25-3B31-B25-3A28-A31-B54-9B22-6B26-2B206-5A24-7A22-9A20-11A19-11A20-2(10A19-C)10A19-2C8A21-2C6A24-5C24-2D3CD117-E29-E87-4B27-4B28-B236-5A24-7A22-9A21-2(9A20-C)9A20-2C8A21-2C6A23-2C4A25-D3CD147-E29-E88-2B298-3B57-3A26-5A22-D2-5A22-C2-5A23-D2-3A25-D29-CD3B178-E315-
