model
size = 32 14 6, scale = 0.05, origin = -y
material deform = 1, fade = true, lighting = smooth, roughness = 0.3, metalness = 0.6
  colors = A:#888 B:#555 C:#444 D:#3CF E:#0CF F:#6CF G:#222 H:#C03 I:#AAA J:#6FF K:#0E0 L:#080 M:#C90 N:#960 O:#FFF P:#0CC Q:#963 R:#F03 S:#FF0 T:#9CF U:#00D V:#700 W:#111 X:#0C0 Y:#CFF Z:#050 Aa:#FF9 Ab:#00C
voxels
130-D25-2H3-D-D23-4H3-D24-4H29-2H4-2D29-4D24-H3-4D23-H-H3-2D25-H386-A30-3A28-2A-3A24-3A321-A30-3A28-I2AJA26-AIAG2J2A22-2A2IG-3G24-3G3-3A10B2-10B3A3-4A2B6-2B2-2B6-2B4A-5A22B10A8B2CB2C9B10A7B3C2(BC)8B10A6B4CBC2BC7B10A6B2C2(BC)2BC7B10A6B4CBC2BC7B10A6B4CB2CBC7B10A6B4CBC2BC7B6AJ3A7B3C2(BC)8B3AR2A2J2A8B2CB2C9B2ARIA-I2JA22BA3I3-2A-22B-2A4-3A10B2C10B3A3-5A20C5A-6AC2UQN2UQ2N2KNQ3N2QC12AC2E2L2ELNQ2KQ6LC12ACEPDX3D2P2K3D3PEC12AC3EAb3EF4K3F2MFC12ACT2FAaF2M3DZ4D2MDC12AC3FXF2M2FOV3F4EC12AC5E2F2E2VF2DS3DC12AC2E2F3DS3D4F3EC12ACDTF2DF5EDS5EC12ACT3OYOP2ES4ET2OYC4AIAG5A20C2A3IG-3G-2B3W9B2(-B)-3B-3G3-3A22B3A3-4AB20-B4A-5AB20-B7AJ2AB20-BA2G3A2(JA)B20-BA3G3AJ2AB20-BA3G6AB20-BA2G7AB20-B10AB20-B2AR7AB20-B2(AR)6AB20-B2AR7AB20-B5A-4AB20-B4A3-2A-22B-2A2-
