model
size = 11 32 6, scale = 0.05, origin = -y
material deform = 1, fade = true, lighting = smooth, roughness = 0.3, metalness = 0.6
  colors = A:#09C400
voxels
7-4A2(7-3A8-3A)8-3A7-2(3A8-)3A7-3A8-3A2(6-5A)2(5-2(5A6-)5A)2(6-5A7-5A)2(6-5A)3(7-5A6-5A)3(7-4A)2(6-2(4A7-)4A)7-3A8-3A251-6A5-2(6A4-2(6A5-))6A4-7A4-6A2(5-5A6-5A)6-5A5-3(5A6-)2(5A7-5A6-)4(5A6-5A7-)4A7-4A6-2A2-2A5-2A2-2A4-3A-2A5-2A2-2A5-6A4-2(6A5-)6A2(4-7A)2(3-7A4-7A)4-7A4-4(6A5-)7A4-7A5-2(7A4-)3(7A5-7A4-)7A2(5-6A)2(5-2A2-2A)4-3A-2A5-2A2-2A5-6A4-2(6A5-)6A2(4-7A)2(3-7A4-7A)4-7A4-4(6A5-)7A4-7A5-2(7A4-)7A5-7A4-7A5-4A-2A4-3A2-2A5-3A-3A4-3A2(2-2A5-2A)2-2A2(6-5A)2(5-2(5A6-)5A)5-5A6-5A2(4-7A)3-3(7A4-)4(6A5-)7A4-7A5-2(7A4-)3(7A5-7A4-)7A2(5-6A)
