model
size = 3 32 24, scale = 0.05, origin = -y
material deform = 1, fade = true, lighting = smooth, roughness = 0.3, metalness = 0.6
  colors = A:#EABB00
voxels
3-60A33-60A39-63A36-66A33-66A30-48A6-18A24-48A6-21A21-48A6-24A18-48A6-27A15-3(84A12-)2(87A9-)3(84A12-)48A6-27A15-48A6-24A18-48A6-21A21-48A6-18A24-2(66A27-)63A30-
