model
size = 9 30 21, scale = 0.05, origin = -y
material deform = 1, fade = true, lighting = smooth, roughness = 0.3, metalness = 0.6
  colors = A:#222 B:#000 C:#444
voxels
3-3(4B5-)2(CA7-)2A7-2C8-C62-A8-C8-A7-CA2(7-2C)7-AC7-2C7-AC7-A61-B4AB3-B2(CA)B3-B3CB4-B2CAB3-BC2ACA3-BA2C2A4-2(CA)C4-2CA2C4-2(CA)5-AC2A5-3C2A5-3A6-2CA5-2(AC)5-AC2A5-3AC5-2(CA)C5-2C2A5-C3A4-2A3C4-2CACA4-3C2A4-2A3C4-2C2A5-3AC5-4C5-3A6-2CA7-AC7-2A5-BA3CAB2-B4ACB2-BC2(3-B)A2-AB3-BA2-CB3-BC2-AC3-BC2-2C3-BC2-2AB2-BC2-2A3-BC2-ACB3-2A-CAB3-2C-2CB2-BAC-AC3-B2A-CA3-BA2-2A3-BA2-2C3-B2A-2C3-BAC2-AB2-BCA2-CB2-BAC2-AB2-BA3-AB2-BC3-CB2-3(BA2-CA3-)2(BC-2CA3-)B2C2AC3-B3ACA3-B5A3-B2C2ACB2-B2ACACB2-B4-B3-BA2(3-B)C3-CB2-BC3-AB2-BA3-CB2-B4-AB2-B4-CB2-BA3-CB2-BA4-2(B2-BC3-C)B2-B4-C2(B2-B4-A)2(B2-B4-C)2(B2-B5-)B2-BA4-B2-BA3-AB2-B4-CB2-B4-AB-AC4-CB-2A4-AB-2C4-CB-CA4-AB-AC4-AB-2A3-2AB2-BA2C2AB2-BAC3AB2-B4-AB2-B4-CB2-B4-AB2-BA2(3-CB2-BC)3-C15(B2-B5-)B-AC5-B-2A5-2(B-C6-)3(B-A6-)B2-BA4CB2-B2C2ACB2-B5-B2-BA3-CB2-BA3-AB2-BC3-CB-B2C3-2CBC2A3-2A2CA2(5-C3A)5-C2(-CA5-B)-AC5-A-CA5-C2-B5-A2-B5-2A-B5-C3A5-2C2A3(5-B-AC)5-B-CA5-B-A6-B-C4(6-B-A)6-2A-B3CACB2-B4CAB2-B2C2ACB2-BA3-AB2-BC3-CB2-BA3-AB-BAC3-2A2B2A3-ACB2C5-C2AC5-2(AC)5-A2(-2C5-B)-CA5-C-2C5-C2(2-B5-A)2-B5-C-CA5-3CA5-4A5-2CAC5-2ACA5-A2C6-C2A6-ACA6-CAC2(6-C2A)6-ACA6-2A19-BAC2ACB2-BC3-CB2-BA2(3-AB2-BC)3-CB2-BC2-2CB2-BC2-2AB2-BA4-B2-BA3-CB2-BC3-CB2-BA3-AB2-BA3(4-B2-BC)4-3(B2-B5-)B2-BA4-B2-BC4-B-2A5-B-CA5-B-2C5-2(B-C6-)C2A6-3A6-2CA6-2A10-B2CA2CB2-B3A2CB2-BC4-B2-BA2(3-AB2-BC)3-CB2-B2A-CAB2-B2C2ACB3-2(2C2-CB2-B)CA2-C4-AC2-AB3-2A2-AB3-CA2-CB3-2A2-2(AB2-BA3-)CB2-BA4-2(B2-BA3-C)B2-BC3-CB2-BA3-AB2-BA4-2(B-CA5-)B-2A5-B-CA5-B-AC5-B-A6-2A10-B2A3C2(B2-B5-)B2-BC3-AB2-BA3-CB2-B2A-CAB3-ACA2C4-3CAC4-2CACA4-5A4-CA2CA4-AC3A2(4-5C)4-2AC2A4-2(AC)A4-5CB3-ACA2CB3-AC3AB3-C3AC4-2C-CA4-CA-CAB2-B2C2-CB2-BC3-AB2-BA3-CB2-BC3-CB2-BA4-2(B-2A5-)B2-BCA2CAB2-B2(CA)C2(B2-B5-)B2-BA3-AB3-BC-CB4-B3AB4-2BA2B5-C2A7-2(A8-)C26-2A7-CA7-2C3(7-AC)6-A2C6-C2A6-3CA4-3CAC4-A2CAC4-2AC2A4-2C2ACB2-B5AB2-2AC2-CB2-3A2-AB2-BA4CAB-2(B5-B2-)BA3-CB2-BA2-2AB3-BACAB5-3B7-B134-A8-C7-CAC2(6-C2A)5-2ACAC4-2(CA)C4-5A3-BA2CACAB-2(B5-B2-)BC3-AB3-B3AB4-4B220-B2A2CAB2-B5-B2-BC3-AB2-BAC-2CB3-5B228-BC4AB2-B4-CB2-BA3-AB3-BC2AB5-3B229-BCA2CAB2-BA3-AB2-BC3-B4-5B237-BA3CAB2-BC3-C2(B3-)B4-5B237-B2(AC)B3-BCA2CB4-B2-AB4-5B238-2(BACAB4-)BA-B5-4B240-3B5-BC2AB4-B2CB6-3B248-5B5-3B246-
