model
size = 10 32 10, scale = 0.05, origin = -y
material deform = 1, fade = true, lighting = smooth, roughness = 0.3, metalness = 0.6
  colors = A:#002F00 B:#EEE C:#004300 D:#001 E:#D00 F:#777 G:#0E0 H:#C60 I:#093 J:#9C0 K:#F30 L:#00D
voxels
22-5A5-A2C2A14(5-2B2AB)5-5A6-4C6-3A126-5A5-A9-14(B3AB5-)C3AC6-2AC7-3A126-4AC5-5AC3-AC3A2C3-2B4AB3-BF4AF4(3-2B4AB)3-7B2(3-6BG)3-E6B3-E5BG2(3-E6B)3-7B3-C5AC3-5ACA4-3ACA6-3A7-2AC106-6A3-7AC-ACA4-AC-2BA4-AB-2FA4-AF-2BA4-AB-2DA4-A2(B-)A4-AB-2BA4-AB-3B2(4-2B-D2B)4-2B-3B3(4-BG-E2B)4-2B-3B4-AB-2CA4-AC2(2-3A)2-7A4-6A5-3AC6-3A8-2A68-2A15-8A-9AC2A6-C-BA6-ABFA6-AFDA6-A2DA6-ADBA6-A2DA6-BD2B2(6-4B)6-2BDB6-4B6-2BEB6-BGEB6-4B6-ABCA6-AC-2A4-AC-4A2-3A2-C5AC4-6A5-4A6-4A7-2(2A8-)AC3(8-2A)7-4A7-2A5-3AHAI2A-12A6-ACBA6-ABFA6-AFB3(A6-A2B)A2(6-2BDB)6-BD2B3(6-4B)6-2BEB6-3BA6-ABCA6-AC2A6-5A4-3A-3A2(2-3A3-2A)2-2A4-2A-2A6-C-2A6-A-2A4(6-4A)5-6A5-4A4-2AKHAILA-11A7-CAB7-ABF7-AFB3(7-A2B)7-3B7-B2D7-BDB2(7-3B)7-2BG7-3B7-BEB7-ABC7-AC2A6-5A4-3A-2A3-3A2-C2A2-3A3-2A2-2A4-2A3(2-A6-A)3(-2A6-A)-2A5-6A5-4A4-3AHJI2A-12A6-CABA6-ABFA6-ABD2(A6-A2D)A6-ABDB6-BD2B2(6-4B)6-2BGB6-BDGB6-2BGB6-BE2B6-BEBA6-ABCA6-AC2A5-6A3-4A-3A-4A3-C6A3-5A6-4A7-4(2A8-)CA8-2A7-4A7-2A5-8A-13A4-ACABA5-2ABF2A4-2AFB2A4-2A2B2A4-2ADB2A4-6B4-5B5-3B2(GB5-2BD)2B5-3BGB5-2(2BE3B4-)2BEB2A4-2AB3A4-2AC-2A4-2A2-8A2-7A4-6A5-4A7-2A68-2A16-6A3-8A2-ACA-4C4(2-B2A-2A2B)5(2-3B-4B)4(2-3B-2B2E)2-B2A-2A2B2-3A-4A2-C7A3-4A2C4-5A7-2A104-
