model
size = 31 26 26, scale = 0.05, origin = -y
material deform = 1, fade = true, lighting = smooth, roughness = 0.3, metalness = 0.6
  colors = A:#E00 B:#C93 C:#C90 D:#C60 E:#400
voxels
291-B3-C25-CB3-B26-C3-B150-B3-B25-2A3-A26-C3-C383-D685-A87-A30-D687-A147-A408-A26-D222-A494-A30-D30-A24-D30-A742-A371-D441-A22-A193-D22-A7-2A21-A122-A402-A190-D30-A25-A9-D51-A91-A402-A159-D61-A37-D30-D49-A30-D30-A530-2(D30-)A101-D47-A61-A530-A61-A165-A14-A561-A6-A23-A211-A508-2(A30-)A213-A50-A11-A18-A7-A297-A77-A26-A33-A248-A30-A26-B4-B2(24-A5-A)30-2A277-2A29-A30-A24-A5-B24-A4-A26-B3-A217-A24-B5-C5-A18-B5-B24-B6-B22-B7-B22-A7-A30-2A215-2A29-A30-B15-2A5-A7-B4-A11-A5-B6-B5-A11-A6-B5-C5-A18-B5-A24-B192-A22-B7-C22-B7-B22-B7-AB20-BA8-B20-B9-B20-A9-2A18-A10-2A153-2A29-2A5-2A11-A10-B20-A9-B4-2A14-B8-AB4-A15-BA7-B5-A16-B7-C22-B7-A22-B162-A22-A7-2A20-CA8-2(C20-B9-)B20-B9-AB18-BA10-B18-B11-B18-A11-2A16-2A12-A92-A29-2A16-2A11-B18-A11-B18-B10-AB18-BA9-B2(20-B9-C)20-B8-2A20-CA7-A22-A132-A20-A9-A20-C9-AC18-CA10-C18-B11-B18-B11-AB16-BA12-2(B16-B13-)AB14-BA13-2A14-2A75-2A14-2A13-AB14-BA2(13-B16-B)12-AB16-BA11-B18-B11-C18-B10-AC18-CA9-A20-C9-A20-A165-A18-2(A11-AC16-C)A12-2(B16-B13-)AB14-BA2(14-B)15-AB12-BA15-2A12-BA16-A30-A29-2A12-BA15-AB12-BA15-2(B14-)AB14-BA2(13-B16-B)12-2(AC16-CA11-)A18-A198-A16-A13-A16-C13-AC14-CA2(14-B)15-B14-B15-AB12-BA15-AB4-3B5-BA16-AB3-2BC4-BA17-AB10-BA18-A10-A18-2A10-A18-AB10-BA17-AB3-C2B4-BA16-AB4-C2B5-BA15-AB12-BA2(15-B14-B)14-AC14-CA13-A16-C13-A16-A231-A14-A15-AC12-CA15-AB12-CA16-B12-B17-B4-C2B5-B17-AB2-5B3-BA17-2A2-4BC3-2A18-A2-2CBCB3-A22-B3CB3-A19-A2-C4B23-A2-2(CB)C3-A18-2A2-4BC3-2A17-AB2-C4B3-BA17-B4-2CB5-B17-B12-B16-AB12-CA15-AC12-CA15-A14-A264-2(A12-A17-)AC10-2A18-B10-B19-A-B3CBCB2-B2(19-2AE5BE-2A)19-2A-5B2-2A20-A-5B2-A21-A-5B2-A20-2A-2(5B2-2A19-2AE)5B2-2A19-A-B4C2B2-B19-B10-B18-AC10-2A2(17-A12-A)297-2(A10-A19-)2A8-2A20-AC4BC-2A21-2A5B3A21-2A6B2A21-AE5BE2(A22-A-5B-)A22-AE2(5BE2A21-2A)5BE2A21-A2C3BC-2A20-2A8-2A2(19-A10-A)424-2C3BC-A22-3A4B3A22-2A4B2(2A23-A5B)A24-2(A5B2A23-)2A4B2A22-3A4B3A22-C4BC-A520-C3-2B24-2A3-3A24-A3-2A4(25-B3-BA)25-A3-2A24-2A3-3A24-C3-2B261-
