model
size = 23 28 32, scale = 0.05, origin = -y
material deform = 1, fade = true, lighting = smooth, roughness = 0.3, metalness = 0.6
  colors = A:#EEE B:#DDD C:#222 D:#001 E:#444 F:#777
voxels
583-DB45-F155-A22-AB20-D22-D506-B2(21-BD)20-2DA21-D2A20-D2B2(20-D2A)B20-D435-A21-2AB20-BAB20-3A20-3B21-D2A20-DBA20-D2A20-DBAB2(20-D2B)20-D366-A21-BA22-2A20-BAB20-3A21-DA21-D2A20-D2B20-DBA20-DB2A20-D2B20-DAB20-D2A363-AB21-2A22-BA20-3B20-3A20-2AB22-2A19-C-BA21-BA20-DB2A3(20-DAB)20-D320-A21-AB2-4C15-AB-3CEC2E13-B2ACE2CE4C10-2(AB)20-2AB18-2B2AB19-EB2AB19-C-2B19-CB2A20-DABA20-D2A20-D2B20-D2A20-D-BA317-B21-2B21-2A8-C10-A2B2A7-ECE9-2A2BC6-3C9-4A8-2(EC)6-EC3A20-CABA19-C2AB19-B3A19-BA2BA20-DBA2(20-D2A)20-2DAB21-2B317-B20-D2B21-DBA20-DAB7-3CEC6-F2BAB12-3C3-F-2BA12-E2C6-C2B13-2C4-3AB2(19-2ABA)B19-CABA20-D2B20-DBA20-D2BA20-DAB20-DBA20-D2A271-D21-DA21-D2B20-D2B10-3C5-F2-DA12-3C6-DB12-2C-C6-AB12-3C5-3A13-CE4-4A19-CAB2A19-2B2A19-B2(2AB20-DAB20-D)BA20-DAB21-D2A247-D21-DB19-2D3A20-D2B19-FBAB13-2C4-F-DA14-2E5-DAB13-2C6-2B13-CE5-EAB15-E3-4BA14-C4-BA2B19-C2BA20-D2B20-DB2(2A20-D)AB20-D2A21-DBA21-2D247-D21-DAB19-D2AB20-D2B18-F2-DA21-DBA20-DAB14-C6-2A15-C4-B3A14-E4-CB2A14-C4-B3A19-2ABA20-DB2A45-B2(21-DA)B20-3D271-A20-DBA20-D2B18-F-DAB20-DA2B20-DBA20-DAB15-E5-EBA14-C4-A2BA15-C3-BA2B15-C3-A2BA15-C3-2ABAB91-DA21-2D317-D20-3D20-4D20-DAB20-DBA15-C4-DABA14-E6-AB15-C3-3BA15-C3-B3A15-C3-B-3A14-C4-B95-D386-D2(A20-DB)2A15-C4-DAB15-E5-AB15-C3-3BA15-E3-B2-2A14-C4-2(BA)13-2C4-A17-C441-DA20-D-B20-DBAB20-D2A15-C22-C5-BA15-C3-BA-2A14-C4-B-A14-2C4-B2A13-E2C20-3C441-DB20-D2BA20-DAB67-2B14-CE4-ABA14-2C4-A2B13-3C4-BAB13-C-C20-C420-DB20-D3A20-D2A20-D69-2(AB13-2C6-)BA-3C7-C2E7-B-B2EC7-3C10-3CE5-E3C20-2E398-DBA20-D2A20-DBA20-D47-A13-CE6-AB13-2C6-AB-2CE7-3C8-2AE2C7-2CE10-2CEC5-CE2C11-3CE3-E3C14-7C517-A21-2A11-3C8-BA10-ECE8-BA-2CE5-3C14-CE3-2C17-2CE2C18-4CE518-B22-2A21-2B9-2CE9-2A3-CE3-EC17-5C18-2CE2C542-B21-BA2(21-2B)4-5C18-2CE2C565-A21-AB21-BA22-2A596-B21-2A22-AB21-AB22-A573-A22-2(2A21-)2(AB22-)D550-B21-2A21-2BA20-2BA21-FB22-D550-B21-2A21-2FA22-F22-D549-AB22-D21-2FA22-F596-DA20-D2B22-F596-DA20-DFA22-F22-D596-FA22-F596-DB21-DB22-F36-
