model
size = 29 23 31, scale = 0.05, origin = -y
material deform = 1, fade = true, lighting = smooth, roughness = 0.3, metalness = 0.6
  colors = A:#FF3 B:#F90 C:#F09 D:#FFC E:#F99 F:#FCC G:#FCF H:#FC0 I:#F96 J:#F60 K:#FF9 L:#CC0 M:#FFF N:#CC6 O:#CCC P:#CFF Q:#CF3 R:#CC3 S:#F0C T:#F30 U:#CF9 V:#F00 W:#F93 X:#FC9 Y:#F66 Z:#CF6 Aa:#FF6 Ab:#CF0 Ac:#F33 Ad:#F63 Ae:#F9F Af:#FF0 Ag:#F6F Ah:#FC3 Ai:#FC6 Aj:#F9C Ak:#F03 Al:#F6C Am:#F0F An:#CFC Ao:#CC9 Ap:#F69 Aq:#F39 Ar:#F06 As:#F36 At:#F3F Au:#CCF Av:#F3C
voxels
89-5B14-4B152-24A410-PY27-FJ19-NAdZHA3-AmUKAoE14-AbB2S8-EIAuRF10-AjWFD13-GWAdAuAsAnQSVSJAiAeAqAd69-22A6-24A4-26A31-28A58B58A204-AlXM22-PAp3-AqAf19-AqWAeFI3-GKAjQI14-PQYX8-GPEApL10-ApXHA13-IGVDAeQSAiAcGAfBAkRK41-19A9-22A6-24A4-26A-58B145A146-DAk24-TR-AiHD22-GAd3-AkO19-EVAkAS3-KAiAfAiX14-JApHI8-HAfAaAdQ10-HAUA13-TNJXKSCBWYVE3A14-16B11-A-17A9-2A-19A6-3A-20A4-4A-21A-6B-28B-22B6A4(-28A)-22A-27A118-LK24-AoO-EAfAb22-JL3-KF19-AfAcIRV3-AbRAhApV14-ZAfHAi8-AcTAgJAq10-AuWAjK13-XYBAdPCAfEBAtXQ3A13-17B11-19A9-22A6-24A4-26A-58B145A29B-27B89-AgE24-ArG-AeID22-FAb3-VAr19-AlZArAmAg3-AjAaWGAl14-AaAiAnAq8-AbDAdVB10-IVDAr13-LAcNVAnAfMQW2KAt3A13-17B11-19A9-22A6-24A4-26A-58B145A29B-27B3-26B60-OAq24-AaC-PJL22-PC3-UH19-TAhAdHAv3-ODATN14-AvGKB8-GAiAmAqAj10-MAmXE13-YAlAbJAnMFAtMAhAr4A13-17B11-19A9-22A6-24A4-26A-58B145A29B-27B3-26B60-AvR24-DAf-N2L22-OG3-2G19-ULPAcD3-2BAaVJ14-CBAaV8-WLOAAh10-ZAiAlAv13-AjAlIBQFLAAkYAqU3A13-17B11-19A9-22A6-24A4-26A-58B145A29B-27B3-26B4-24B32-PO24-AjM-UKAh22-HG3-NU19-THYDE3-SAaIHY14-GAvQAk8-BJRAcAs10-DWTI13-AiAdYNSLQUOANAh3A13-17B11-19A9-22A6-24A4-26A-58B145A29B-27B3-26B4-24B6-22B4-AdG24-XF-Au2E22-KAq3-ZR19-AhAi-DG3-VAeAmAjAc14-AAjAc9-AgAePAuS10-AoAsGQ13-AoAqUAbCQOAhZApAsAo3A13-17B11-19A9-22A6-24A4-26A-58B145A29B-27B3-26B4-24B6-22B4-AsC24-AmS-AkCAk22-ArAj3-AiK19-JQ-ArQ3-ArDCUAp14-2DXN8-AaAcIEAc10-DAnAtR13-HAuFIAfOAdAoAeZAvAh3A13-17B11-19A9-22A6-24A4-26A-58B145A29B-27B3-26B4-24B6-22B4-OAf24-AkI-NJY22-BV3-AjJ19-FAnHCL3-AeXYBA14-FWRU8-JDZAaP10-TEAmX13-AnHAnYMAdIAhNTArAb3A13-17B11-19A9-22A6-24A4-26A-58B145A29B-27B3-26B4-24B6-22B4-AbM24-AnI-FRD22-AE3-AfR19-CAeAaGAu3-QAgTAcE14-AaMAvAl8-QAsZAgN10-AhAgAnY13-DAcLUFIAmAbAjJVS3A13-17B11-19A9-22A6-24A4-26A-58B145A29B-27B3-26B4-24B6-22B4-XF24-VR-AeAdAk22-SAa3-TAb19-OAsHAnW3-KWXKAb14-LAqWAd8-ANWAdS10-AsBGAf13-TBEFLAmHSHAsMG3A13-17B11-19A9-22A6-24A4-26A-58B117A15CA11CA29B-27B3-26B4-24B32-NS24-YE-DAdR22-AbW3-ZX19-TNVFA3-AjAaBKS14-FSAiC8-AcDAAmW10-MAmRA13-AgAbAkAnQHAgGQAgAeY3A13-17B11-19A9-22A6-24A4-26A-58BA9CA17C2A15C2A10C75A-12A29B-27B3-26B60-MU24-PAp-AsAp23-AgH3-AAj19-FVAoJAk3-AjAlNAaAr14-Aj2AAj8-AmNQPAt10-J2QA13-FCAvHAaAcAlMArYAbGOAkP13-17B11-19A9-22A6-24A4-26A-58BA7C2A-6A2C3A6C2A7C8A-2(2C3A6C2A7C9A)2C3A6C2A7C8A-AC3A6CA29B2-26B4-23B62-EAf24-QAn-LK23-AvP3-AbM19-IBSKAe3-FYArAgE14-HAbAU8-AaJZGP10-ApAnAkAm13-EFLIAiJOAtAcAkCAhAoAqK13-17B11-19A9-22A6-24A4-26A8(2-27A)3-25A90-GD24-UG-LP23-AoN3-HAg19-BAoMAbAc3-AkAvApTS14-EZAI8-TAuZGP10-AaAlHD13-LOPArAdAtAoAuJAqNZAmTV13-B9-7B11-19A9-22A6-24A4-26A7(2-27A)3-26A4-24A90-OAe24-AlAn-ME23-IAd3-SAp19-WLJET3-BS2AAl14-AjOAW8-AvAjTUI10-AVNA13-AaUAiAcAlKAmPAtTAqMZHAm13-17B11-19A9-22A6-24A5-24A7(4-25A)5-23A120-CA24-HE-AiZ23-YJ3-AkU19-CHKRO3-ApONAfAb14-AnAgDV8-CEOAhE10-ApKFAv13-UAuHJAtFZ2KHQAbAAoAh50-B19-19A9-21A7-3(23A6-)18A-4A3(6-23A)7-21A16-5A129-AdM24-SM-TAe23-QA3-LAc19-KUAbNG3-VPAeAhAs14-AsLIAa8-CAlMAgT10-FAoAdV13-AlAiGAtHUAVFAoApAdWAhT48-5B23-B5-B21-B-5B-B19-BA7B-B17-B-9B-B15-B-11B-B13-B-13B-B12-B-13B-B13-B-11B-B15-B-9B-B17-B-7B-B19-B-5B-B21-B5-B23-5B71-NS24-AuU-AcAq23-GAo3-YU19-MApEAAj3-JNHZAs14-AjAAqT8-JAq2AfK10-AeAuAeZ13-XAeAtKATWAmUAhMA2AsP107-A-A23-7A24-2(A4-A23-)5A24-A4-A23-A4-A21-7A25-A-A26-A-A130-NAc24-VAm-AmAi23-AoAg3-AoAu19-AlAsRPD3-AbIAkCAt14-NLAuM8-ApQCHAh10-AgMSH13-3JFAvAoAsAhTAsAnOMAfA501-PAi24-XAl-FAr23-AeZ3-AdAh19-NINEAm3-ZAcCIAu14-FOAbAn8-AaAnAoZX10-AvWRW13-AmAAeUWDMTAoAfIEBAbAf501-FAf24-AuAi-AtH23-FAa3-JT19-IAsARW3-OAtXAgY14-HDMAt8-AAlJAkAq10-YAVAr13-AhYOTXQBPDAbArNJGL501-AkO24-AtAp-AhW23-IAt3-AbF19-ArAdPUAa3-AgAmUYE14-XDGT8-ApVRAhM10-AcBAaO13-AcAsQAoAvIJAQGEAePAcAn501-IAg24-AjAm-BM23-XQ3-AeAr19-AkCEAaP3-LAdPXZ14-AfAiUAi8-FKAkAdO10-LHXAr13-ZWAiDEDPAfIAcAgSGYZ501-AAg24-TAr-GAv23-DAi3-XM19-AeD2RAf3-AAqRKP14-FAoAeO8-AeAoFRAc10-EAeAtAh13-AgAuUQAdOGLDYAdPSCAu501-ApO24-XR-SAi23-DA3-EAk19-SAlUMZ3-LAbRAtY14-FQXAn8-AgAuJXV10-AnEAmAs13-AqAjM2IRSAnOCILApLY501-MB24-AtAr-AqAc23-AlAa3-PAs19-JVAaAvN3-OHCLG14-SEAAg8-AvMAAnAs10-JAjBL13-FAfKDKAlApZRLIAcRNC501-AvL24-AbK-XV23-ArAg3-AgAh19-ZGRArAv3-DAlAqFQ14-AfAaAqD8-YWAkHAt10-AeWQW13-AkAaAjONAiRAuAlNKApAlAhA500-
