model
size = 21 11 22, scale = 0.05, origin = -y
material deform = 1, fade = true, lighting = smooth, roughness = 0.3, metalness = 0.6
  colors = A:#222 B:#4AADE8 C:#6DA570 D:#D39367 E:#BF575F F:#CABE68
voxels
27-9A12-9A14-A3EA160-11A10-11A11-9A14-5A159-13A8-13A9-11A11-9A13-7A15-5A116-2(3A4-A4-3A6-)3A4-A4-3A7-13A9-11A11-9A13-7A93-2(2A13-2A4-)2A6-A6-2A5-3(A6-)15A7-13A9-11A11-9A70-2(2A15-2A2-)2A7-A7-2A3-2(A7-)A4-13A2-2A5-15A7-13A9-11A12-7A50-2(A17-A2-)2(A8-)A2-2(A8-)A3-13A2-2A4-17A5-15A7-13A9-11A13-5A29-2A2(17-4A)8-A8-2A-2(A8-)A2-14A2-3A3-17A4-17A5-15A7-13A10-9A15-3A9-A19-2A19-3A8-A8-4A8-A8-2A-14A2-3A3-2(17A4-)17A6-13A9-11A13-5A8-2A7-3A6-5A7-3A6-6A7-A7-5A8-A8-2A-14A2-3A2-19A3-17A4-17A5-15A8-11A12-7A7-A2(7-5A5-A-2A)-A6-3A6-A-2(2A7-5A7-16A2-4A-19A2-19A3-17A5-15A7-13A10-9A6-A2(6-7A6-2A)7-5A7-)2A7-5A7-16A2-4A-19A2-19A3-17A5-15A7-13A10-9A6-A2(7-5A5-A-2A)-A6-3A6-A-2A7-5A7-16A2-4A-19A2-19A3-17A5-15A7-13A10-9A6-2A7-3A6-5A7-3A6-6A7-A7-5A8-A8-2A-14A2-3A2-19A3-17A4-17A5-15A8-11A12-7A7-A19-2A19-3A8-A8-4A8-A8-2A-14A2-3A3-2(17A4-)17A6-13A9-11A13-5A8-2A2(17-4A)8-A8-2A-2(A8-)A2-14A2-3A3-17A4-17A5-15A7-13A10-9A15-3A10-2(A17-A2-)2(A8-)A2-2(A8-)A3-13A2-2A4-17A5-15A7-13A9-11A13-A3BA30-2(2A7-A7-2A2-)2A7-A7-2A3-2(A7-)A4-13A2-2A5-15A7-13A9-11A12-AC3BCA51-2(2A6-A6-2A4-)2A6-A6-2A5-3(A6-)15A7-13A9-11A11-2A2CA2C2A72-2(3A4-A4-3A6-)3A4-A4-3A7-13A9-11A11-9A13-A2F4A95-13A8-13A9-11A11-2AD3ED2A13-2(A2D)A15-2F3A113-
