model
size = 24 32 10, scale = 0.05, origin = -y
material deform = 1, fade = true, lighting = smooth, roughness = 0.3, metalness = 0.6
  colors = A:#36C B:#C90
voxels
28-4A8-4A9-3A8-3A11-3A6-3A12-4A4-4A12-5A2-5A38-2(8A16-)2(2AB)2A16-3AB4A16-4AB3A16-2(2AB)2A2(16-8A)16-2(2AB)2A16-4AB3A16-3AB4A16-2(2AB)2A16-8A15-10A14-3AB2AB3A14-4AB5A14-5AB4A14-3AB2AB3A2(14-10A)2(14-4A2-4A)14-3A4-3A14-2A6-2A15-A6-A14-12A13-10A15-3(8A16-)8B14-17(12A12-)12A11-14A10-14A9-16A10-2(12A12-)12A58-16A9-2A3-4A3-2A11-12A12-3A2-2A2-3A12-3A6-3A12-2B3A2-3A2B11-4A6-4A2(10-3A8-3A)14(10-2A)10-3A8-3A2(2(10-2A)2(10-3A8-3A))2(10-3A8-3A)8-5A2-4A2-5A6-5A8-5A5-6A8-6A7-3(2A2-)2A10-14A12-10A16-6A12-2A2(2-4A)2-2A7-2(2A-)4A2(-2A)9-5A-2A-5A10-5A4-5A10-3A8-3A10-B2A8-2AB9-2(3A10-3A8-2A12-2A8-)3(2A12-2A8-)3A10-3A8-2A12-2A8-A-A10-A-A2(8-3A10-3A)8-A-A10-A-A8-3A10-3A8-A-2A8-2A-A2(8-4A)2(8-B14-B)7-BA14-AB5-B2(2A6-)2AB4-B2A2-A8-A2-2AB3-B3A14-3AB-B4A14-4AB5-5A4-5A12-2A6-2A15-A6-A10-2A16-2A5-2A14-2A7-3(2A12-2A8-)BA12-AB3(7-3A12-2A)8-2A12-2A8(8-A14-A)8-2A12-2A2(8-A14-A)8-A-A10-A-A8-B14-B125-4A14-4A-B8A6-8AB7-2A6-2A15-A6-A9-2A18-2A3-2A16-2A5-3(2A14-2A6-)B16-B2(6-A16-A)6-2A14-2A5(6-3A12-3A)4(6-A16-A)6-A-A12-A-2(A6-A16-)A2(6-B16-B)147-B8A6-8AB7-2A6-2A15-A6-A9-2A18-2A3-A18-A4-2A16-2A5-2(A16-A6-)B16-B3(6-A16-A)5(6-2A14-2A)2(6-3A12-3A)5(6-A16-A)2(6-B16-B)147-B8A6-8AB7-2A6-2A15-A6-A9-2A18-2A3-A18-A4-3A14-3A5-2(2A14-2A6-)B3A10-3AB7(6-2A14-2A)6-A16-A6-2A14-2A2(6-3A12-3A)6-2A14-2A6-3A12-3A7-3(A14-A8-)B14-B125-4A14-4A-B8A6-8AB7-2A6-2A15-A6-A10-2A2-2A8-2A2-2A5-2A14-2A7-2A12-2A2(8-4A)8-A-A10-A-A8-2B2A8-2A2B3(8-3A10-3A)6(8-2A12-2A)2(8-3A10-3A)8-2(A-A10-)2(A10-)3A10-3A8-A-A10-A-A8-3A10-3A2(8-B14-B)8-A14-A7-2A14-2A6-2A14-2A4-B3A14-3AB-B4A14-4AB5-4A6-4A12-2A6-2A15-A6-A11-2A-4A4-4A-2A7-3A10-3A8-3A10-3A9-2(2A10-)3A8-3A11-12B11-4A6-4A2(10-3A8-3A)7(10-4A6-4A)10-3A8-3A2(10-4A6-4A)4(10-2A)2(10-3A8-3A)9-B3A8-3AB8-B3A8-3AB7-B4A8-4AB5-B5A8-5AB4-5A10-5A7-2(2A10-)5A4-5A12-2A6-2A31-
