model
size = 9 32 9, scale = 0.05, origin = -y
material deform = 1, fade = true, lighting = smooth, roughness = 0.3, metalness = 0.6
  colors = A:#BBB B:#C99
voxels
225-B352-3A284-5A96-5(B8-)4(A8-)A104-7A77-A7-3B5(6-BAB)5(6-3A)103-7A5-7(A8-)A7-3A6-BAB5-5(B3AB4-)4(5A4-)5A101-B7A77-A7-3B5(6-BAB)5(6-3A)104-5A96-5(B8-)4(A8-)A106-3A240-B42-
