model
size = 28 29 29, scale = 0.05, origin = -y
material deform = 1, fade = true, lighting = smooth, roughness = 0.3, metalness = 0.6
  colors = A:#FCC B:#EEE C:#BBB D:#DDD E:#AAA F:#777 G:#FFC H:#F69 I:#F3C
voxels
441-C781-DC28-C24-D2C25-2(D26-)2D646-C25-5C22-2CD-D18-C3-D2CDB19-2C2-D-BCDC2D16-C-CDCBC3-C17-2C-D2C2-DC22-D3C20-C-DCD4C21-C-D2C505-C25-C-2C22-2C-CBC20-2EC-D2B3C16-2EC-2BD3B17-2C2-C5B2D2C15-2C-C7BD16-2C6BD2B17-C9B-D16-2C2D4BD2C17-C-5B2C19-C-3D3C22-C480-2B24-D4B20-CEBD5B18-E2C8B15-E2CBC8B15-2C-10BC13-2EC11BC13-2E11BD15-E12B16-11BC16-10BC17-CD6B2C18-CDC2D3C25-C27-C278-D86-E26-3B23-ED5B19-2E8B17-B2C8B16-C11B15-C13B15-13BC14-13B13-E2A12B13-E2A11B15-EA11B15-E2A9BC15-EB5A4BC17-3B2A3B3C17-CDB2DB2C-C20-CD2C248-D28-4D25-2D29-2E25-E3B23-E6B19-ED7BC14-C2A-9B15-CA11B15-CA2(12B14-2A)2(13B13-2A)2(12B13-E2A)12B13-E3A10B13-2E6A6BC15-E4A6B2C15-EAB2A4B3C17-C-4B2C186-2(D28-)2D28-D4-2D22-4D-D28-3E22-6B15-2A3-D8B12-5A-10BC-C8-6AC10B11-5A13B2C7-6A13BC8-6A5B3A5B9-6A4B4A5B9-6A4B3A3(6B10-12A)5B12-9A7B13-C6A5BABC13-C5A7BC14-EC4A6BC16-EC7B2C20-E2B26-E78-A26-D27-2(D28-)3A26-3A3-2B21-4A2BD15-5A3-AB2-6B9-7A3-D9B7-9A12BC6-9AC11B7-9A12B-C5-9A13B2(6-16A6B)7-15A6B6-16A6BC5-G15A5BC6-CF14A5B8-15A5B9-11A7BC10-9A7BC12-C6A6BAB12-E2C12BC13-EC11BC15-EC9B18-2E-3B4C23-C47-D-2A23-2D-4A23-D-4A2(23-5A)22-9A4B13-10A3B3-B10-11A8BC7-12A9B-C5-2(12A10B6-)12A10B2(C5-17A5B)6-17A5B2(6-17A4BC)6-G17A3BC5-2F16A5B5-CF16A4BC7-12A8BC8-10A8BC10-8A9B11-ECA13BC12-C13B13-2EC11BC16-C9BC18-C2-C5-C42-D-2A24-D-4A23-6A22-6A20-G7A19-12A5B10-13A3B2-2B8-13A8B5-2B13A9BC3-2B15A7B5-18A5BC4-18A4B6-18A6B4-19A4BC5-G2(17A4BC5-C)17A4BC4-19A3B2(C4-2F17A4B)C5-CF15A5BC7-15A5B9-9A9B2C8-E3A14BC11-E14BC10-2EC13BC15-8B4C16-CB4C5-C13-D27-D-2A25-5A23-6A22-6A18-19A9-13A5B10-13A4B-3B7-13A8B-C4-B13A8BC3-2B18A5B4-B2(19A5B4-)2(19A4BC4-)19A4BC5-F17A4BC5-C17A4BC4-19A4B2(C3-2F17A5B)6-16A6BC6-15A5B9-13A6BC9-3A14BC9-E2A14BC10-ECA13BC12-2C10BCB15-2C-6C18-D28-3A25-5A23-6A19-9A17-G18AC8-18AC9-19A3B6-19A4B5-19A4B2-2B20A4BC-2B21A4B2-22A3BC2-22A4B2(3-21A3BC)4-20A3BC5-C18A3BC4-19A5B4-19A4BC3-2F17A5BC5-16A5BC6-16A6B8-13A6BC8-8A11B10-2A15B11-EA14B13-C11BC15-3CB6C16-D28-D3A25-4A24-6A18-G9A17-19AC8-19A8-H19A2BC5-H19A3BC4-H19A3BC2-2B20A4BC-2B21A2(3BC24A)3BC-23A3BC2-22A3BC3-21A3(3BC4-20A)3B2(C4-18A5B)6-17A4BC7-14A6B9-9A10B9-3A15B10-E2A14B14-12B16-3C4B3C15-D28-D3A25-4A24-6A18-10A17-11A16-H19AB7-2(H19A4B4-)H19A4BC-2B21A3BC-B22A2(3BC24A)3BC-23A2(3BC2-22A)4B3-21A4B4-20A3BC2(4-20A4B)4-19A4B6-17A4BC7-15A5BC8-A6B5A7B9-A17BC10-16BC12-C9BC2B2C14-5C2B3-2C13-D27-2D3A25-4A24-6A18-G9A17-13A5B10-13A5BAC7-2(H13A5BA4B4-)H19A3B2C-2B20A5B-2B21A4B24A3BC24A4B-23A3BC2-22A3BC3-21A2(3BC4-20A)4B4-19A5B2(4-19A4BC)5-16A6B7-A5B8A6B9-7BA11BC9-17BC11-14B2C12-C9BC2B19-5C17-D26-3D3A25-4A24-6A20-G7A17-G12A5B2(10-11A7B)A2BC6-11A7BA3BC5-11A4B4A2BC3-3B19A3BCB-3B19A4B2(C2-22A3B)C3-21A3BC4-20A3BC5-19A3BC5-C18A3BC4-20A3BC3-2F18A4BC3-2F17A5BC5-17A5BC6-15A6BC7-5B8A6BC9-17BC10-17B11-C14B14-C-C10B20-B3C44-D2-3A23-D-5A23-6A22-6A20-10A5B11-10A8B10-10A11B7-10A11B6-B10A11BC3-2B18A5B3-2B19A3BC5-2(19A4BC4-)20A3BC4-20A3BC5-F18A3BC5-C18A3BC4-20A3BC3-2F18A3BC4-2F17A4BC5-CF15A5BC7-2A4B9A5BC8-5B8A5BC10-17BC11-C14BC14-12BC16-6C2BC25-2C45-3A23-D2-4A22-2D-4A22-6A23-7A5B13-8A6B13-9A6B-3B8-10A11B5-2B10A11B5-3B16A2(4BC5-18A)5B5-18A4BC5-18A5BC5-G2(17A4BC5-C)17A5B4-19A5B3-2F18A4B5-CF16A5B6-CF14A5BC8-A5B7A6B10-9B3A5B11-2C14BC12-C14BC14-11B2C18-C3B2(-C)97-3(D28-)DA5-4B17-D4A6B17-5A4B16-8A3B-6B9-9A11B7-12A8BC7-14A7B2(C6-17A4B)C2(6-17A5B)2(6-17A4BC)6-G16A5B5-CF16A5B6-CF14A5B8-14A6B9-3(A5B)C11-10BA5BC11-2C13BC14-12B17-C7BC20-6C130-D2(27-2D)5-3B19-2D4A3BD19-D-3A-2D27-5B13-2A5-9B9-8A-A9B9-2(10A9BC8-)15A5B8-3(15A5BC7-)15A6B7-G14A5BC8-C11A7BC8-11A7BC10-3A4BA9BC11-16B13-C13BC14-C11BC15-C7BAB2C17-3C3-3C186-D28-D27-8D21-D-4D29-EB-E22-6B15-2A3-7B2C14-3A2-8BC13-6A9B12-7A9BC10-8A9BC10-12A5BC10-13A4B2(C10-12A5B)C11-10A6BC12-8A7BC12-A13BC13-C12BC15-C11B17-8BC19-C-3B3C23-2C248-3D25-D35-E24-E2BC-D20-E5BC20-E8B16-2A2-2(8B16-4A)9B15-5A8B15-5A9B14-5A2(8BC13-6A)7BC14-7A6BC13-C13B15-C11B17-10B18-2C6B21-2C-3C390-2EBD23-E2B2DB22-7B21-8B17-3A8B17-4A7B17-4A2(8B15-5A)7B16-5A7B15-CB4A6BC15-C11B17-9B2C17-C6B2C20-3C2-C421-D52-2D2B23-ED4B21-EBD5B19-E-7B18-EIBA7B16-E-2BA2(7B17-B3A)6B17-CB3A5B18-C8B20-C5B23-3C505-D2(26-2D)2B2D21-2D4B20-E2D5B22-D6B18-2BD7B17-2C9B18-C7BC19-C-C2B2C23-3C25-C506-D26-D27-D2-D-D22-D25-2D27-D5B18-2D2-5B20-D3-2C26-C-2C23-C670-2DBD2B22-D5B24-2C754-D-D344-
