model
size = 24 19 9, scale = 0.05, origin = -y
material deform = 1, fade = true, lighting = smooth, roughness = 0.3, metalness = 0.6
  colors = A:#777 B:#9CF C:#CF0
voxels
59-3A21-4A19-5A19-6A17-7A16-9A15-9A14-11A13-12A11-13A10-15A8-17A6-18A7-17A8-14A11-12A13-11A16-5A19-5A18-2(7A17-)8A2(14-10A)14-11A12-2(13A11-)13A9-16A8-17A6-19A2(4-20A)6-17A7-16A11-11A14-2(8A16-)9A15-9A14-10A13-12A12-13A11-13A2(10-14A)9-2(16A8-)17A6-20A2(2-22A)4-19A5-19A9-11A13-10A14-9A15-10A14-11A12-13A11-13A10-15A9-15A4(8-16A)8-17A6-21A-47A-22A3-20A9-2(11A13-)10A13-12A12-13A2(10-5A4B5A)9-6(6A4B6A8-)6A4B7A6-7A4B10A-9A4B20A4B10A-22A3-21A8-2(11A13-)11A12-12A12-13A11-4A4B5A10-5A4B5A9-4(6A4B6A8-)C5A2(4B6A8-6A)4B7A6-7A2(4B10A-9A)4B10A-22A3-21A8-11A13-4(10A14-)3A7BA12-4A2(7B2A10-5A)3(7B3A9-5A)8B2A8-C5A8BA9-6A6B4A7-7A6B6A3-9A6B8A-9A6B7A3-21A3-19A10-11A14-3(9A15-)9A2(14-3A6BA)14-3A2(6B2A12-4A)6B3A11-4A6B3A11-C3A6B3AC9-C4A7B3A8-C5A8B3A7-6A8B3A5-8A8B4A4-8A7B6A3-20A5-17A11-11A14-6(8A16-)9A14-3(11A13-)A2CAC2A2C2AC11-CAC3A3(CA)C10-2(AC)2(2AC)2(AC)10-C2A2C2ACA2C2A2C8-16A7-18A6-18A7-16A11-11A6-
