model
size = 29 24 31, scale = 0.05, origin = -y
material deform = 1, fade = true, lighting = smooth, roughness = 0.3, metalness = 0.6
  colors = A:#3CF B:#FF3 C:#CFB53B D:#111 E:#F09
voxels
62-C26-5C14-4C152-24A468-3C18-5C3-6C13-2C2D8-5C10-4C13-15C69-22A6-A21B2A4-26A31-144A233-3C21-3C3-A2C16-4CD2A3-2A4C11-2CDA2D8-2DA12C3DA13-4D7A4D41-19A9-A19B2A6-A21B2A4-A23B2A-61A3(23B6A)23B32A175-2C23-3C-2AC21-2CA3-A2C16-4CD2A3-2A4C11-2CDA2D8-2DA12C3DA13-4D7A4D14-16A11-A-17A9-AB-17B2A6-A2B-18B2A4-A3B-19B2A-6A-28A-25A3(3B-19B6A)3B-19B5A4B-20B2A-27A147-2C23-3C-A2C21-2CA3-A2C16-4CD2A3-2A4C11-2CDA2D8-2DA12C3DA13-4D7A4D13-17A11-19A9-A19B2A6-A21B2A4-A23B2A-61A3(23B6A)23B5A25B31A-27A118-2(2C23-3C-A2C21-2CA3-A2C16-4CD2A3-2A4C11-2CDA2D8-2DA12C3DA13-4D7A4D13-17A11-19A9-A19B2A6-A21B2A4-A23B2A-61A3(23B6A)23B5A25B31A-27A3-26A89-)2C23-3C-A2C21-2CA3-A2C16-4CD2A3-2A4C11-2CDA2D8-2DA12C3DA13-4D7A4D13-17A11-19A9-A19B2A6-A21B2A4-A23B2A-61A3(23B6A)23B5A25B31A-27A3-26A4-24C61-2(2C23-3C-A2C21-2CA3-A2C16-4CD2A3-2A4C11-2CDA2D8-2DA12C3DA13-4D7A4D13-17A11-19A9-A19B2A6-A21B2A4-A23B2A-61A3(23B6A)23B5A25B31A-27A3-26A4-C22AC6-22D33-)2(2C23-3C-A2C21-2CA3-A2C16-4CD2A3-2A4C11-2CDA2D8-2DA12C3DA13-4D7A4D13-17A11-19A9-A19B2A6-A21B2A4-A23B2A-61A3(23B6A)23B5A25B31A-27A3-26A4-C22AC6-22D16-2C15-)2C23-3C-A2C21-2CA3-A2C16-4CD2A3-2A4C11-2CDA2D8-2DA12C3DA13-4D7A4D13-17A11-19A9-A19B2A6-A21B2A4-A23B2A-61A3(23B6A)23B5A25B31A-27A3-26A4-C22AC6-22D33-2C23-3C-A2C21-2CA3-A2C16-4CD2A3-2A4C11-2CDA2D8-2DA12C3DA13-4D7A4D13-17A11-19A9-A19B2A6-A21B2A4-A23B2A-61A3(23B6A)23B5A14EB10E31A-27A3-26A4-24C61-2C23-3C-A2C21-2CA3-A2C16-4CD2A3-2A4C11-2CDA2D8-2DA12C3DA13-4D7A4D13-17A11-19A9-A19B2A6-A21B2A4-A23B2A-61A7EB15E6A13E2B8E2(6A23B)5A14B-10B31A-27A3-26A89-2C23-3C-A2C21-2CA3-A2C16-4CD2A3-2A4C11-2CDA2D8-2DA12C3DA13-4D7A4D13-17A11-19A9-A19B2A6-A21B2A4-A23B2A-61A5E2B-6B2E3B4E6A5E8B-2(2E3B4E6A5E9B)2E3B4E19A-41A2-26A4-23A91-2C23-3C-A2C21-2CA3-A2C16-4CD2A3-2A4C11-2CDA2D8-2DA12C3DA13-4D7A4D13-17A11-19A9-A19B2A6-A21B2A4-A6(23B2A2-2A)23B2A2-A25BA2-A25DA3-3A19D3A119-2C23-3C-A2C21-2CA3-A2C16-4CD2A3-2A4C11-2CDA2D8-2DA12C3DA13-4D7A4D13-A9-7A11-19A9-A19B2A6-A21B2A4-A2(23B2A2-2A)23B2A2-27A3(2-2A23B2A)2-27A3-A23D2A4-A21D2A119-2C23-3C-A2C21-2CA3-A2C16-4CD2A3-2A4C11-2CDA2D8-2DA12C3DA13-4D7A4D13-17A11-19A9-A19B2A6-A21B2A5-A22B6(A4-A23B)A4-A23DA5-23D149-2C23-3C-A2C21-2CA3-A2C16-4CD2A3-2A4C11-2CDA2D8-2DA12C3DA13-4D7A4D70-19D9-21D7-6(23D6-)23D7-21D179-2C23-3C-A2C21-2CA3-A2C16-4CD2A3-2A4C11-2CDA2D8-2DA12C3DA13-4D7A4D195-C23-D3-C-C5-D16-D2-C3-C21-D-2(C2-)C20-DC2-3C2-C19-2C-5C-2C184-8(2C23-3C-A2C21-2CA3-A2C16-4CD2A3-2A4C11-2CDA2D8-2DA12C3DA13-4D7A4D530-)2C23-3C-A2C21-2CA3-A2C16-4CD2A3-2A4C11-2CDA2D8-2DA13C2DA13-4D7A4D530-C25-2C-2C23-2C3-2C19-5C3-4C15-4C8-3C13-3C12-16C529-
