model
size = 11 31 30, scale = 0.05, origin = -y
material deform = 1, fade = true, lighting = smooth, roughness = 0.3, metalness = 0.6
  colors = A:#00E B:#FF0 C:#E00 D:#F09 E:#EEE
voxels
213-3(4A7-)4A101-E351-E10-E339-E11-E10-E9-E10-E307-E43-E9-E275-E20-E54-E9-E10-E127-2C8-4C7-4C8-2C81-E31-E75-E9-E94-4C6-3(6C5-)6C6-4C80-E30-E86-E10-E9-E52-2C7-6C5-6C4-8C3-8C4-6C5-6C7-2C70-E41-E107-E10-E20-C8-4C6-6C4-3(8C3-)8C4-6C6-4C80-E40-E118-C10-C8-4C6-6C4-3(8C3-)8C4-6C6-4C90-E41-E128-2C7-6C5-6C4-8C3-8C4-6C5-6C7-2C91-E51-E74-2D8-4D7-4D8-2D19-4C6-3(6C5-)6C6-4C112-2(E51-)4D6-6D5-DB4D5-D2B3D5-2DB3D6-4D19-2C8-4C7-4C8-2C135-E50-E31-2D7-2D2E2D5-6D4-8D3-D2B5D4-DB4D5-2DB3D7-2D179-E61-D9-2D8-D2ED6-D4ED4-2(8D3-)DB6D3-D2B5D4-D2B3D6-4D30-2B8-4B7-4B8-2B124-E60-D9-D2ED6-D4ED4-2(8D3-)DB6D3-D2B5D4-D2B3D6-4D18-4B6-3(6B5-)6B6-4B111-E72-2D7-6D5-6D4-8D3-DB6D4-DB4D5-2DB3D7-EB9-2B7-6B5-6B4-8B3-8B4-6B5-6B7-2B112-E71-4D6-3(6D5-)2DB3D6-4D18-4B6-6B4-3(8B3-)8B4-6B6-4B122-E72-2D8-4D7-4D8-2D30-4B6-6B4-3(8B3-)8B4-6B6-4B122-E147-6B5-6B4-8B3-8B4-6B5-6B7-2B134-E137-4B6-3(6B5-)6B6-4B155-E62-3(4A7-)4A39-2B8-4B7-4B8-2B166-E42-2A7-6A5-6A4-8A3-8A4-6A5-6A7-2A230-E29-6A4-5(8A3-)8A4-6A228-E19-4A6-6A4-8A2-3(10A-)10A2-8A4-6A6-4A229-A8-4A5-8A3-8A2-3(10A-)10A2-8A3-8A5-4A229-2A7-4A5-8A3-8A2-3(10A-)10A2-8A3-8A5-4A238-4A6-6A4-8A2-3(10A-)10A2-8A4-6A6-4A248-6A4-5(8A3-)8A4-6A260-2A7-6A5-6A4-8A3-8A4-6A5-6A7-2A81-
