model
size = 15 32 15, scale = 0.05, origin = -y
material deform = 1, fade = true, lighting = smooth, roughness = 0.3, metalness = 0.6
  colors = A:#111 B:#FFF C:#06F D:#DDD E:#EEE
voxels
5-5B370-5B98-9B8-5D23(10-5B)8-9B8-5D82-11B5-9D23(6-2B5A2B)5-11B5-9D8-5B66-13B3-11D23(4-B9AB)3-13B3-11D6-B5AB9-5B51-13B3-11D23(4-B9AB)3-13B3-11D5-B7AB7-7B49-15B-13D23(2-B11AB)-15B-13D3-B9AB5-3B3A3B9-3D36-2(15B-13D23(2-B11AB)-15B-13D3-B9AB5-2B5A2B8-5D11-3B12-3B6-)15B-13D23(2-B11AB)-15B-13D3-B9AB5-2B5A2B8-5D11-3B12-BEB6-15B-13D23(2-B11CB)-15B-13D3-B9AB5-3B3A3B9-3D37-13B3-11D23(4-B9AB)3-13B3-11D5-B7AB7-7B50-13B3-11D23(4-B9CB)3-13B3-11D6-B5AB9-5B52-11B5-9D13(6-2B5C2B)6-B3A3CAB6-BA5CAB6-2B3C4A6-B3A3CAB6-BA5CAB6-2(BA)3CAB4(6-2B5C2B)5-11B5-9D8-5B68-9B8-5D13(10-5B)10-2A2(3B10-BA)B2A10-2ABAB10-BA2BA10-2A3B4(10-5B)8-9B8-5D85-5B370-5B95-
