model
size = 30 27 9, scale = 0.05, origin = -y
material deform = 1, fade = true, lighting = smooth, roughness = 0.3, metalness = 0.6
  colors = A:#FFF B:#000 C:#050000 D:#9BADB7 E:#FBF236 F:#F3ECEC
voxels
630A180-41AC4A3C22AC4A2C130AC363AC2AC18A2C6A2C22ABC2A2-2D22-2D152-30AB9AC4A2C12A17(2B28A)2BC2AC24A3B2D22B2D2B2-2D22-2D152-39AC5AC527AC28A2C2AB2A2C8AB2(C2A)2C2A2-2D2-5D8-5D2-2D9-DBD10-DBD2(14-3B10-3B)14-16B15-14B8-56AC514AC34AB2A2C8ABCA2B6A6-DBCBD8-DBC2D13-DED10-DED14-3B10-3B14-BCB10-BCB14-BCF10BF2B15-14B8-56AC514AC34AB2A2C8A2CA2B6A6-5D8-5D13-DBD10-DBD2(14-3B10-3B)14-16B15-14B8-45ACAC8AC514AC3AC54A180-45ACAC38AC484AC3AC54A180-630A180-
