model
size = 22 32 17, scale = 0.05, origin = -y
material deform = 1, fade = true, lighting = smooth, roughness = 0.3, metalness = 0.6
  colors = A:#847E87 B:#FFF C:#000 D:#D9A066 E:#FBF236 F:#99E550 G:#FC0000 H:#696A6A I:#EDD400 J:#FC0404
voxels
157-10(D21-)2(D483-D9(21-C)21-)D98-A384-D9(21-C)21-D76-A145-5(CG)12-5(GC)229-D21-C5(21-E)2(21-I)21-C21-D30-5A3(17-A3HA)17-5A76-12A2(10-A9B2A)10-12A206-D21-C21-I21-6(E14A7-)C14A7-D6(14A8-)14A30-14A3(8-A11B2A)8-2A11BA8-14A30-13(3A8-)3A7-D3A8-3A7-C3A8-3A7-I3A8-3A7-E3B8A2B2(A7-C13B)A7-E3(13BA7-C)13BA7-D13B5(A8-A12B)A8-14A30-A6BA5B4(A8-A12B)A8-14A14-2C14-2(3A8-)11(ABA8-)ABA7-D2BA8-ABA7-C2BA8-ABA7-I2BA8-ABA7-E3B8A2BA7-I13BA7-C13BA7-E3(13BA7-C)13BA7-D13B5(A8-A12B)A8-14A30-5(A12BA8-)14A14-2C14-2(3A8-)2(ABA8-)9(3A8-)3A7-D3A8-3A7-C3A8-3A7-I3A8-3A7-EA2B8A2BA5-2A2(CA12BA4-3A)E3(A12BA4-2A-C)A12BA4-2A-DA12BA4-2A2-A12BA4-4A13B9A14B4A4-2(A12BA8-)14A30-5(A12BA8-)14A30-3(3A8-)3A117-D21-C21-I21-E14A5-2A2(E14A4-3A)3(E14A4-2A-)C14A4-2A-D3A3F8A4-2A2-2(AC)AF8A4-5A3C2F10AB6A2(CA)F12A4-2AC11A8-12AJA8-14A30-14A8-A5C2A5C2(A8-A5F2A5F)A8-A5C2A5CA8-14A30-3(3A8-)3A117-D21-C7(21-E)21-C3(21-D60-2A20-2A399-D9(21-C))21-D60-2A20-2A399-10(D21-)D60-2(2A20-2A680-)3(2A20-)2A198-
