model
size = 27 28 23, scale = 0.05, origin = -y
material deform = 1, fade = true, lighting = smooth, roughness = 0.3, metalness = 0.6
  colors = A:#5F9997 B:#22A C:#00008B D:#009 E:#0A0A0A
voxels
376-E25-3E25-E646-6(A2B24-)A2B537-2(A2B24-)AB5(25-2B)25-AB25-A2B24-A2B456-A2B2(24-3A)24-B2A23-4(3B24-)2B2A24-B2A24-3A24-AB25-A2B402-A2B24-3A24-AC24-3(B3A23-)2(BAB24-)3(B3A23-)B2(3A24-)AB25-A2B348-2(A2B24-)2(3A23-B)AC24-B3A23-4A23-2AB24-3(4A23-)2(B3A23-)B2(3A24-)AB25-A2B144-8B17-2B8-3B12-2B13-2B9-B17-B7-B19-2B4-B21-3B-B22-2AB-B22-AB-2B21-B3A2B21-B-2A2B21-B3A2(2B21-4A)2B22-DB-2B21-4A2B22-D2(C-2B21-2A)C-2(2B21-B3A)-B21-B3A-B22-AB3-B21-A2B3-B19-BA2B4-B17-B9-2B13-2B12-2B8-3B16-8B19-8A17-2A8-3A12-2A13-2A9-A17-A7-A19-2A4-A21-2AB-A22-A2B-A22-2(AB-2A21-B)-4A2(21-5AB)21-2AB-D22-2AB-AB21-4AD22-5AB2(21-6A)21-2AC-2A2(21-B3A-A)22-AB3-A21-A2B3-A19-4B4-A17-A9-2A13-2A12-2A8-3A16-8A19-8B17-BA8-A2B12-BA13-BA9-A17-B7-B19-AB4-A21-2AB-B22-2AB-A21-BAB-AB21-BA2(B-2B21-2A)B-BA4(21-2AB-2B)21-4A2B21-4ABA21-4A2B21-5AB21-4A-A21-BAB2-B21-BAB3-A21-A2B3-B19-BA2B4-A17-B9-BA13-BA12-BA8-BAB16-BA4BAB19-8B17-BA8-A2B12-BA13-BA9-A17-B7-B19-AB4-A21-2AB-B22-A2B-A21-BAB-AB21-2(BA)2(2B21-2ABA)2B22-D2(BA)21-2ABA2B22-DBA2B21-2AB-2B22-DB-BA21-4A2B22-D2A2B21-5AB21-2AB2-A21-BAB2-B21-BCB3-A21-A2B3-B19-BA2B4-A17-B9-BA13-BA12-BA8-BAB16-BA4BAB19-8A17-2A8-3A12-2A13-2A9-A17-A7-A19-2A4-A21-2AB-A22-A2B-A21-BAB-2A21-BAB3A2(21-2AC-2A)21-2AB-AB21-2AB-2A21-2(2AB)21-2AB-2A21-2AB-AB3(21-2AB-2A)21-2AB2-A21-B2C2-A21-BAB3-A21-A2B3-A19-4B4-A17-A9-2A13-2A12-2A8-3A16-8A19-8B17-2B8-3B12-2B13-2B9-B17-B7-B19-2B4-B21-3B-B22-3B-B21-2(B-)2B21-B-BA2(2B21-2AC-)2(2B21-2AB-)2B21-2A2(BA)21-2AB-2B21-A2B3(-2B21-2AB)-2B21-2AC2-B21-2BC2-B21-3B3-B21-A-B3-B19-BA2B4-B17-B9-2B13-2B12-2B8-3B16-8B19-8B17-2B8-3B12-2B13-2B9-B17-B7-B19-2B4-B21-3B-B22-BAB-B21-3B-2B21-3BA2(2B21-ABC-)2(2B21-A2B-)2B21-A2BABA21-ACB5(-2B21-A2B)2-B21-B2C2-B21-BCB3-B21-A2B3-B19-BA2B4-B17-B9-2B13-2B12-2B8-3B16-8B19-8A17-2A8-3A12-2A13-2A9-A17-A7-A19-2A4-A21-2AB-A22-A2B-A21-BAB-2A21-BA2(B3A21-2A)B3A22-DB2AB21-2AB3A22-DB-AB21-2AB-2A22-DB-AB21-6A22-D4A21-6A21-2AB2-A21-BAB2-A21-BCB3-A21-A2B3-A19-4B4-A17-A9-2A13-2A12-2A8-3A16-8A19-8B17-BA8-A2B12-BA13-BA9-A17-B7-B19-AB4-A21-2AB-B22-2AB-A21-BAB-AB21-BA3(B-2B21-2A)B-BA3(21-2AB-2B)21-4ABA2(21-4A2B)21-5AB21-4A-A21-BAB2-B21-BAB3-A21-A2B3-B19-BA2B4-A17-B9-BA13-BA12-BA8-BAB16-BA4BAB19-8B17-BA8-A2B12-BA13-BA9-A17-B7-B19-AB4-A21-2AB-B22-A2B-A22-AB-AB21-BAB-2B21-B3A2B21-4ABA21-4A2(2B21-2AB-)3(2B21-4A)BA21-4A2B21-2AC-AB21-B3A-A21-B3A-B22-AB3-A21-A2B3-B19-BA2B4-A17-B9-BA13-BA12-BA8-BAB16-BA4BAB19-8A17-2A8-3A12-2A13-2A9-A17-A7-A19-2A4-A21-BAB-A22-2AB-A22-AB-2A2(21-B5A)21-B4AB21-5AB21-4AD23-DB-AB21-4AD23-DC-AB2(21-2AC-2A)21-B5A2(21-B3A-A)22-AB3-A21-A2B3-A19-4B4-A17-A9-2A13-2A12-2A8-3A16-8A19-8B17-2B8-3B12-2B13-2B9-B17-B7-B19-2B4-B21-2B2-B22-A2B-B22-A4B22-2(3A2B21-B)AC-2B21-B3A2B21-4A2B21-2AB-3(2B21-4A)3(2B21-B3A)-B22-3A-B22-A2B2-B21-A2B3-B19-BAB5-B17-B9-2B13-2B12-2B8-3B16-8B223-A2B24-2AB24-4(3A23-B)2(AB24-B)3(3A23-B)2(3A24-)A2B24-A2B402-A2B24-2AB24-3A24-B2A23-4(3B24-)2B2A24-B2A24-3A2(24-A2B)456-A2B24-2(AB25-)5(2B25-)2(AB25-)A2B511-7(2B24-A)2B25-2B592-2E25-2E52-2E25-2E297-
