model
size = 22 26 3, scale = 0.05, origin = -y
material deform = 1, fade = true, lighting = smooth, roughness = 0.3, metalness = 0.6
  colors = A:#EEE B:#F596AA C:#DB4D6D
voxels
5-3A6-3A10-3A6-3A9-4A6-4A7-5A6-5A5-6A6-6A4-6A6-6A3-2(7A6-7A2-)7A6-7A-8A10(6-16A)6-8A-7A6-7A2-6A8-6A3-4A10-4A4-4A10-4A5-2A12-2A6-A14-A8-3A6-3A10-3A6-3A9-4A6-4A7-3(5A6-)5A5-3A2CA6-A2C3A2(4-2A3CA6-A3C2A)3-3A3CA6-A3C3A2-2AB3CA6-A3CB2(2A2-2A2B2CA6-A2C2B)2A-2A4BCA6-AC4B3(4A5BA6-A5B)4A4B2A6-2A4B2A-A4B2A6-2A4BA2-2A2B3A6-3A2B2A2-2A2B2A8-2A2B2A2-6A8-6A3-4A10-4A4-3A12-3A5-2(2A12-2A6-)A14-A10-A6-A13-2A6-2A12-2A6-2A11-3A6-3A8-2(5A6-)2A2-A6-A2-2A2(6-A3-A)5-2(2A3-A6-A3-2A4-)A4-A6-A4-A3-2(2A4-A6-A4-2A2-)4(A5-A6-A5-A2-)A4-2A6-2A4-A2-A4-A8-A4-A2(2-2A)8-2A2-2A3-A2-A10-A2-A4-4A10-4A5-2A12-2A7-A12-A8-A12-A48-
