model
size = 10, scale = 0.05, origin = -y
material deform = 1, fade = true, lighting = smooth, roughness = 0.3, metalness = 0.6
  colors = A:#339 B:#336 C:#DDD D:#100 E:#6FC F:#555 G:#C90
voxels
24-2C4-2(EC)2E2(CE)11-ECE2CECE5-2C4-C2-4C2-5C2G4C3-4C13-10B10A2(BA)2B2(AB)10AB3A2B3AB4A2B14A-3A2B3A3-2C2-2C3-8B-B8AB64A2B4A-2(3C2-)B6-B-BA6BAB10AB8AB44A2B4A-2(3C2-)B6-B-BAB4-BAB3A4B63A-8C2-B6-B-BAB4-BAB3A4B3AB8AB42AB4AB2A-C-4C-C2-B6-B-BAB4-BAB3A4B63A-8C2-B6-B-BA6BAB70A2-6C3-8B-B8AB11ADFD2FDFD12A2D4A2D2A2D4A2D11A-8A3-6C3-B6-B-4B2A4B11A8-A-8A-A2-4A2-2A2-4A2-11A-8A5-2C4-
