model
size = 17 28 15, scale = 0.05, origin = -y
material deform = 1, fade = true, lighting = smooth, roughness = 0.3, metalness = 0.6
  colors = A:#369 B:#AAA C:#39C D:#444 E:#F90 F:#DDD G:#111
voxels
37-6(11A6-)11A363-22(11A6-)3(11C6-)11C40-4(11A6-)11A3-3D2(11A6D)11A3D3-14(11A6-)3(3(11C6-)11C40-4(11A6-)11A3-3D2(10AC6D)10AC3D-9(2D10AC2D2-)2D10AC2D4-4(11A6-))4(11C6-)5E-5E23-4(11A6-)11A3-3D2(10AC6D)10AC3D-9(2D10AC2D2-)2D10AC2D4-7(11A6-)11C6-5E-5E8-E5-E8-4(11B6-)11B4-12(2D11B2D2-)2D11B2D4-11B6-11F6-11A5-3(G11AG4-)G11AG5-11C6-5E-5E8-E5-E8-2(19(11B6-)11F6-11A5-3(G11AG4-)G11AG5-11C6-5E-5E23-)19(11B6-)11F6-11A5-3(G11AG4-)F11AF5-11C6-5E-5E23-19(11B6-)11F3(6-11A)2(6-4A3C4A)6-11C400-2(5E12-5E454-)5E12-5E57-
