model
size = 17 28 14, scale = 0.05, origin = -y
material deform = 1, fade = true, lighting = smooth, roughness = 0.3, metalness = 0.6
  colors = A:#369 B:#DDD C:#39C D:#F90 E:#CF0 F:#111
voxels
414-5D12-5D77-25(11A6-)11A40-4(11A6-)11A3-3C2(11A6C)11A3C3-17(11A6-)3(11A40-4(11A6-)11A3-3C2(10A7C)10A4C-9(2C10A3C2-)2C10A3C4-7(11A6-))11A6-5D-5D23-4(11A6-)11A3-3C2(10A7C)10A4C-9(2C10A3C2-)2C10A3C4-8(11A6-)5D-5D8-D5-D8-11B4(6-4B6AB)4-12(2C4B6AB2C2-)2C4B6AB2C4-4B6AB6-11E6-11A5-3(F11AF4-)F11AF5-11A6-5D-5D8-D5-D8-2(11B18(6-4B6AB)6-11E6-11A5-3(F11AF4-)F11AF5-11A6-5D-5D23-)11B18(6-4B6AB)6-11E6-11A5-3(F11AF4-)B11AB5-11A6-5D-5D23-19(11B6-)11E6(6-11A)400-5D12-5D454-5D12-5D57-
