model
size = 9 31 17, scale = 0.05, origin = -y
material deform = 1, fade = true, lighting = smooth, roughness = 0.3, metalness = 0.6
  colors = A:#4E2B0F B:#000 C:#341800 D:#EEE
voxels
210-3B5-5B3-2(7B2-)7B3-5B5-3B212-5A3-7A-45A-7A3-5A202-5A3-7A-45A-7A3-5A213-C7-3C5-5C3-7C3-5C5-3C7-C223-3A5-5A3-2(7A2-)7A3-5A5-3A222-3A5-5A3-2(7A2-)7A3-5A5-3A15-3B7-C188-A7-3A5-5A3-2(7A2-)7A3-5A5-3A14-2(BD)B5-3A7-A2(8-2C6-2C2(8-A))8-AC7-8(A8-)A7-BAB2(6-3A)5-5A3-2(7A2-)7A3-5A5-3A14-2(BD)B4-C3AC5-2(2(2AC6-)2(C2A6-))2(2AC6-)11(3A6-)3A5-5A3-2(7A2-)7A3-5A5-3A14-B3DB5-3A7-AC2(7-A8-A7-2C8-2C)7-9(A8-)A7-BAB2(6-3A)5-5A3-2(7A2-)7A3-5A5-3A15-3B7-C188-A7-2(3A5-5A3-2(7A2-)7A3-5A5-3A222-)3A5-5A3-2(7A2-)7A3-5A5-3A223-C7-3C5-5C3-7C3-5C5-3C7-C213-5A3-7A-45A-7A3-5A202-5A3-7A-45A-7A3-5A212-3B5-5B3-2(7B2-)7B3-5B5-3B12-
