model
size = 32 16 32, scale = 0.05, origin = -y
material deform = 1, fade = true, lighting = smooth, roughness = 0.3, metalness = 0.6
  colors = A:#DCD800 B:#EAE600 C:#FF0 D:#2D2D2D
voxels
44-8C469-14C18-4A6B4A19-3A6B3A20-3A6B3A21-2A6B2A23-A6BA25-6B26-6B276-5C8-5C15-4A8D4A2(16-16A)17-14A18-14A19-12A22-A6BA25-6B26-6B211-3C14-3C12-3A3D8-3D3A12-6A8-6A13-5A8-5A14-5A8-5A15-16A16-16A17-14A20-10A24-6B26-6B178-3C16-3C10-3A2D12-2D3A2(10-5A12-5A)11-2(4A12-)6A8-6A13-18A15-16A17-14A19-12A22-A6BA25-6B145-2C20-2C8-2A2D16-2D2A2(8-4A16-4A)9-3A16-3A10-5A12-5A11-6A8-6A13-18A14-18A16-14A19-12A22-A6BA25-6B112-2C22-2C6-2A2D18-2D2A6-4A18-4A7-2(3A18-3A8-)4A16-4A9-5A12-5A11-6A8-6A12-20A13-18A16-14A19-12A23-6B26-6B79-3C22-3C5-2AD20-D2A3(6-3A20-3A)7-3A18-3A8-5A14-5A9-5A12-5A10-8A6-8A11-20A13-18A16-14A20-10A24-6B26-6B47-2C24-2C4-2AD22-D2A2(4-3A22-3A)5-2A22-2A6-3A20-3A6-5A16-5A7-5A14-5A9-6A10-6A11-7A6-7A13-18A15-16A17-14A21-A6BA25-6B46-2C26-2C2-2A2D22-2D2A3-3(3A22-3A4-)4A20-4A5-4A18-4A6-5A16-5A7-5A14-5A9-6A10-6A11-7A6-7A13-18A15-16A18-12A23-6B26-6B14-2C26-2C2-2AD24-D2A2(2-3A24-3A)3-2A24-2A4-3A22-3A4-4A20-4A5-4A18-4A7-5A14-5A8-6A12-6A9-6A10-6A11-20A14-16A17-14A21-A6BA25-6B14-2C26-2C2-2AD24-D2A3(2-3A24-3A)3-3A22-3A4-4A20-4A5-4A18-4A6-5A16-5A7-5A14-5A9-5A12-5A11-7A6-7A13-18A16-14A20-10A24-6B13-2C28-2C-AD26-DA3(2-2A26-2A)2-3A24-3A3-3A22-3A4-4A20-4A5-5A16-5A7-5A14-5A8-6A12-6A9-7A8-7A12-18A15-16A18-12A23-6B13-2C28-2C-AD26-DA3(2-2A26-2A)2-3A24-3A3-3A22-3A4-4A20-4A5-4A18-4A6-5A16-5A7-5A14-5A9-6A10-6A11-20A14-16A18-12A23-6B13-2C28-2C-AD26-DA3(2-2A26-2A)2-3A24-3A2-4A22-4A3-4A20-4A5-4A18-4A6-5A16-5A7-5A14-5A9-6A10-6A11-20A14-16A17-2(14A22-6B13-2C28-2C-AD26-DA3(2-2A26-2A)2-3A24-3A2-4A22-4A3-4A20-4A4-5A18-5A5-5A16-5A7-5A14-5A9-6A10-6A11-20A13-18A16-)14A22-6B13-2C28-2C-AD26-DA3(2-2A26-2A)2-3A24-3A2-4A22-4A3-4A20-4A5-4A18-4A6-5A16-5A7-5A14-5A9-6A10-6A11-20A14-16A17-14A22-6B13-2C28-2C-AD26-DA3(2-2A26-2A)2-3A24-3A3-3A22-3A4-4A20-4A5-5A16-5A6-6A14-6A7-6A12-6A9-7A8-7A11-20A14-16A18-12A23-6B13-3C26-3C-2AD24-D2A3(2-3A24-3A)3-3A22-3A4-4A20-4A4-5A18-5A5-5A16-5A7-5A14-5A8-6A12-6A9-8A6-8A12-18A15-16A18-12A23-6B13-3C26-3C-2AD24-D2A2(2-3A24-3A)3-2A24-2A4-3A22-3A4-4A20-4A5-4A18-4A7-5A14-5A8-6A12-6A9-6A10-6A11-20A14-16A17-14A20-10A24-6B13-3C26-3C-2A2D22-2D2A3-3(3A22-3A4-)4A20-4A5-4A18-4A6-5A16-5A7-5A14-5A9-6A10-6A11-7A6-7A13-18A15-16A18-12A22-A6BA25-6B13-4C24-4C2-2AD22-D2A3(4-3A22-3A)5-3A20-3A6-5A16-5A7-5A14-5A9-6A10-6A11-7A6-7A13-18A15-16A16-16A18-3A6B3A23-6B26-6B14-4C22-4C3-3AD20-D3A4-4A20-4A5-2(3A20-3A6-)4A18-4A7-5A14-5A9-5A12-5A10-8A6-8A11-20A13-18A15-16A18-12A22-A6BA25-6B46-4C22-4C4-2A2D18-2D2A6-4A18-4A7-3A18-3A8-3A18-3A9-3A16-3A10-5A12-5A11-6A8-6A13-18A15-16A18-12A21-10A24-2(6B26-)6B47-4C20-4C6-2A2D16-2D2A2(8-4A16-4A)9-3A16-3A11-2(4A12-)6A8-6A13-18A15-16A18-12A20-12A23-6A2(26-6B)80-5C16-5C7-4A2D12-2D4A9-5A12-5A10-5A12-5A11-4A12-4A13-5A8-5A14-18A15-16A18-12A20-12A22-8A25-6B26-6B113-5C14-5C9-4A3D8-3D4A11-6A8-6A12-6A8-6A13-5A8-5A15-16A16-16A18-12A20-12A22-8A25-6B26-6B146-7C8-7C12-5A8D5A14-18A15-2(16A16-)16A18-12A21-10A24-6A2(26-6B)179-20C14-16A16-16A17-14A19-12A20-12A22-8A25-6B26-6B244-18C19-8B25-5(6B26-)6B278-14C22-6B461-
