model
size = 31 17 32, scale = 0.05, origin = -y
material deform = 1, fade = true, lighting = smooth, roughness = 0.3, metalness = 0.6
  colors = A:#00F B:#030 C:#E00 D:#93C E:#009 F:#0D0 G:#F96 H:#001 I:#003 J:#444
voxels
194-3(3B9-3B16-)3B9-3B386-3(3B2-9B2-3B12-)3B2-9B2-3B414-2BA4B7A4BA3(2B10-2B-4B7-4B-)2B413-B2AE13AE2A3(B10-B19-)B412-2B3A2E9A2E3A3(2B8-2B19-)2B315-3(H27-H2-)H2-B4AEI9EIE4AB2(2-H)2-B21-B2-H5-B21-B8-B21-B284-H27-H2(2-G27-G)33-G2-B5AEI7EIE5AB2(2-G)2-B21-B2-G2-H2-B21-B2-H5-B21-B253-H27-H2-2(G27-G33-)G2-B5A2E2I3E2I2E5AB2-G5-B21-B5-G2-B21-B2-G2-H2-B21-B2-H250-H27-H2(2-G27-G)33-G27-G5-B5A2E7I2E5AB5-G2-B21-B2(2-G)2-B21-B2-G2-H2-B21-B2-H250-H27-H64-G27-G-31C-G2-B5A3E5I3E5AB2-G5-B21-B8-B21-B5-H2-B21-B2-H250-H27-H2-G11-6A10-G2-G11-6A-4D5-G9-4F-6A-4D8-G5-C4FC6AC4DC4-G5-B5A3E5I3E5AB5-G2-B21-B2(2-G)2-B21-B2-G2-H2-B21-B2-H250-H27-H2-G11-6A10-G14-6A-4D8-G6-4F-6A-4D5-G8-C4FC6AC4DC7-G2-B5A3E5I3E5AB2-G5-B21-B5-G2-B21-B2-G2-H2-B21-B2-H281-H11-6A10-H2-G11-6A-4D5-G2-G6-4F-6A-4D5-G8-C4FC6AC4DC7-G2-B5A3E5I3E5AB2(2-G)2-B21-B2-G2-H2-B21-B2-H5-B21-B296-6A13-H11-6A-4D5-H2-H6-4F-6A-4D5-H2-H5-C4FC6AC4DC4-2(H2-)B5A3E5I3E5AB2(2-H)2-B21-B2-H5-B21-B8-B21-B383-18C4(10-B5A3E5I3E5A3(B8-B21-)B327-6A-4D15-4F-6A-4D14-C4FC6AC4DC)10-B5A3E5I3E5A3(B8-B21-)B383-18C2(10-B5A3E5I3E5A3(B8-B21-)B296-6A25-6A-4D15-4F-6A-4D14-C4FC6AC4DC)10-B5A2E7I2E5A3(B8-B21-)B296-6A25-6A-4D15-4F-6A-4D14-C4FC6AC4DC10-B5A2E2I3E2I2E5A3(B8-B21-)B315-2(H27-H2-)H5-18C4-2(H2-)B5AEI7EIE5AB2(2-H)2-B21-B2-H5-B21-B8-B21-B284-H11-6A10-H2-G11-6A-4D5-G2-G6-4F-6A-4D5-G8-C4FC6AC4DC7-G2-B4AEI9EIE4AB2(2-G)2-B21-B2-G2-H2-B21-B2-H5-B21-B253-H27-H2-G11-6A10-G14-6A-4D8-G6-4F-6A-4D5-G8-C4FC6AC4DC7-G2-B4A2E9A2E4AB2-G5-B21-B5-G2-B21-B2-G2-H2-B21-B2-H250-H27-H2-G11-6A10-G2-G11-6A-4D5-G9-4F-6A-4D14-C4FC6AC4DC10-B3AE13AE3AB5-G2-B21-B2(2-G)2-B21-B2-G2-H2-B21-B2-H250-H27-H64-G27-G-30C2-G2-B2AE15AE2AB2-G5-B21-B8-B21-B5-H2-B21-B2-H182-J29-3J29-J5-H27-H2(2-G27-G)33-G27-G5-2BE17AE2B5-G2-2B19-2B2(2-G)2-2B19-2B2-G2-H2-2B19-2B2-H27-4(J30-)J29-2(3J28-)3J4-H27-H2-2(G27-G33-)G3-2B17A2B3-G6-2B17-2B6-G3-2B17-2B3-G2-H3-2B17-2B3-H182-J29-3J29-J36-H27-H2(2-G27-G)33-G4-2B3A4BA4B3A2B4-G2-G4-2B3-4B-4B3-2B4-G2-H4-2B3-4B-4B3-2B4-H7-2B3-4B-4B3-2B317-3(H27-H2-)H5-2BA2B2-3B2-2BA2B5-H2-H5-2B-2B2-3B2-2B-2B5-H8-2B-2B2-3B2-2B-2B14-2B-2B2-3B2-2B-2B255-
