model
size = 21 22 32, scale = 0.05, origin = -y
material deform = 1, fade = true, lighting = smooth, roughness = 0.3, metalness = 0.6
  colors = A:#FC0
voxels
8-8A33-8A11-12A7-2(5A5-)4A9-4A4-3A11-4A2-3A13-3A2-2A2(15-6A)16-4(4A17-)5A15-3A-2A15-3A-3A13-3A3-3A11-4A3-4A9-4A2(5-5A)8-12A97-5(3A18-)3A19-A292-3(3A18-)4(A-A18-)2(3A18-)3A249-3A18-5A16-A-3A16-5A16-4(3A18-)2(A-A18-)3A18-3A228-5A16-A-3A2(16-5A)17-2A40-A19-2(3A18-)4A17-A-2A17-3A208-2A18-2(5A16-)5A19-2A101-2A18-4A17-A-2A17-3A208-2A18-5A16-5A17-4A18-3A2(18-2A)19-2A19-A20-2A18-4A17-A-2A17-4A18-2A186-3A18-5A16-5A17-4A18-2(3A17-)3A18-3A19-2A18-3A18-4A16-2A2-A17-4A17-3A186-3A18-A-3A16-5A17-A-2A18-2(3A17-)3A18-4A18-2A18-3A17-2A-2A16-2A2-A16-2A-2A17-3A186-3A18-A-3A16-5A19-2A18-2A14-2A2-4A13-2A-5A13-2(2A-)2A17-A-2A16-3A17-2A-2A16-A3-A16-2A-2A17-3A186-3A18-A-3A16-5A14-2A3-2A14-2A2-2A14-3A-4A13-2A-5A2(12-3A2(-2A))12-2A2-3A17-2A-2A16-A3-A16-2A-2A17-3A186-3A18-A-3A16-5A2(14-2A2-3A)14-2A-4A16-5A2(12-3A2(-2A))12-2A2-4A16-2A-2A16-A3-A16-2A-2A17-4A185-4A17-A-3A14-7A2(14-2A2-3A)19-2(2A16-2A-)2A12-2A2-2A-2A12-2A2-4A16-2A2-A16-A3-A16-2A2-A17-4A185-4A17-A-3A14-7A2(14-2A2-3A)18-3A16-5A16-2A-2A12-2A-3A-2A12-2A-5A16-2A2-A16-A3-A16-2A2-A16-5A185-3A18-A-3A14-7A14-2A2-2(3A18-)3A16-5A16-2A-2A12-2A-2A2-2A12-2A-5A3(16-A3-A)16-5A185-3A18-A-3A14-7A14-2A2-2(3A18-)3A16-5A16-2A-2A12-2A-2A2-2A12-2A-5A16-3(A3-2A15-)5A185-3A18-A-2A15-7A14-2A2-2(2A19-)2A17-5A16-2A-2A12-7A14-8A16-A3-2A15-A4-A15-A3-2A15-5A18-2A165-3A18-A-2A15-6A15-2A-2(3A18-)3A17-4A17-3A14-7A14-5A-2A16-A3-2A14-2A4-A14-2A3-2A15-5A17-3A165-3A18-A-2A15-6A15-2A-3(3A18-)3A19-3A12-9A12-5A-4A13-2A3-3A13-2A4-2A13-2A3-3A14-2A-4A11-9A12-7A144-3A18-A-A16-6A4(15-2A2-2A)15-2A2-3A12-9A12-5A-3A14-2A4-2A13-A5-2A13-2A3-3A14-2A-3A12-9A12-6A145-3A18-A-A18-4A4(15-2A2-2A)15-2A17-8A13-9A4(14-7A)15-5A164-3A18-A-A18-3A4(20-A)15-A19-8A13-5A2-2A14-2A4-A14-A5-A14-2A4-A14-3A2-2A15-5A164-3A18-A-A18-3A98-2A19-8A13-4A3-2A3(14-A5-A)14-2A3-2A15-5A164-3(3A18-)2A58-2A18-3A2-A15-9A12-4A3-2A14-3(A5-2A13-)2A3-2A15-6A184-3A17-4A17-3A17-4A16-4A17-3A17-7A14-9A12-4A3-2A14-A2(5-2A12-2A)5-2A13-2A3-2A14-7A16-3A165-2A2(18-3A)17-4A16-4A17-3A18-7A14-8A14-2A4-2A12-2A5-2A12-2A6-A12-2A5-2A12-3A4-2A13-7A15-5A226-A20-A40-7A14-3A2-3A12-2A5-2A12-2A6-A12-A7-A12-2A6-A12-2A5-2A13-3A-4A14-6A267-5A15-8A12-3A3-3A11-3A5-3A3(10-2A7-2A)10-3A5-3A11-3A3-3A13-8A14-5A227-3A16-8A12-4A-5A10-3A5-3A10-2A7-2(3A8-)2A8-2A9-2A8-3A8-2A9-2A7-3A9-3A5-3A11-4A-5A12-8A15-3A186-3A15-9A11-11A10-3A5-4A8-3A7-3A8-5(2A9-3A7-)3A7-3A9-3A5-4A9-11A12-8A15-3A143-5A14-9A11-12A8-4A5-5A6-4A7-4A6-3A9-4A5(4-3A11-3A)5-3A9-4A5-2(4A7-)4A5-4A9-12A10-9A14-5A98-9A10-13A7-15A5-5A7-5A4-4A9-4A3-4A11-4A2-4A12-2(3A2-3A13-)4A-3A14-3A-3A13-4A-3A13-3A2-4A12-3A2-4A11-4A3-4A9-4A4-6A6-5A5-15A7-13A10-9A27-
