model
size = 32 32 14, scale = 0.05, origin = -y
material deform = 1, fade = true, lighting = smooth, roughness = 0.3, metalness = 0.6
  colors = A:#010 B:#111 C:#100 D:#330 E:#444 F:#555 G:#222 H:#400
voxels
206-4A27-2AD3A2(26-3AD2A)26-2AD3A28-2A952-2A10-2A18-2A10-2A632-2B30-2B280-3A8-3A2(18-4A6-4A)19-3A6-3A537-2(AB30-)2B248-3A8-3A17-5A6-5A16-6A4-6A16-2A-3A4-3A-2A17-2A-2A4-2A-2A18-5A4-5A19-3A6-3A202-2B28-4B4-3A14-3A4-2B4-6A12-6A7-7A12-7A6-7A12-7A9-3B14-3B12-3B6-EB6-3B12-2B7-EB7-2B12-B8-EB8-B21-EB30-EB155-2A4-2A22-12A19-14A17-2(7A2-7A16-)2A-4A2-4A-2A16-A3-3A2-3A3-A2(16-2A3-2A2-2A3-2A)17-2A-3A2-3A-2A17-7A2-7A15-7A4-7A13-6A8-6A11-7A8-7A9-8A8-8A6-2B9A2-2A2-10AB4-3B22A3B2-4B-22A-6B2-24A2-2B4-3A-16A-3A7-2A4-14A4-2A6-9A3-2A3-9A9-4B5-EB5-4B12-3B6-EB6-3B12-2B7-EB7-2B12-B8-EB8-B177-10A20-14A17-16A16-3A3-4A3-3A16-2A4-4A4-2A15-2(2A5-4A5-2A14-)2A5-4A5-2A15-A5-4A5-A16-2A3-2A2-2A3-2A15-3A3-6A3-3A14-3A3-6A3-3A13-3A2-10A2-3A11-3A3-10A3-3A9-3A4-10A4-3A8-2A5-10A5-2A6-2BA6-10A6-2AB4-3BA6-8A6-A3B4-2B-A7-2A2-2A7-A-2B7-A20-A10-2A18-2A9-4A3-10A3-4A8-9A2-2A2-9A11-3B5-EB5-3B22-EB30-EB190-2A25-12A19-3A8-3A17-2A12-2A15-6(2A14-)A16-A14-2(2A6-)3(2A14-2A5-4A5-)2A13-2(2A7-)2A12-2A16-2A11-2A18-2A9-2A20-2A8-2A20-2A7-B2A20-A2B6-2B2A18-2A2B8-2(3A16-3A10-)5A12-5A11-20A13-5A3-2A3-5A22-EB252-6A23-12A19-2A10-2A17-2A12-2A15-2(2A14-)4(A16-A14-)A7-2A7-A13-2(2(2A7-)2A12-)2A16-2A12-A18-A11-2A18-2A10-A20-A9-3A18-3D8-4A16-4D9-4A14-4D11-4A12-4D13-7A4-7D14-7A11D16-5A9D310-6A23-4A4-4A19-2A10-2A17-2A12-2A15-2(2A14-)2(A16-A14-)A16-A13-3(2A16-2A12-)2(A18-A12-)A18-A11-2A18-2A10-3A16-3A10-4E14-4A11-4E12-4A13-4E10-4A15-6EA2-7A17-5E9A22-E5A346-6A23-12A19-3A8-3A17-3A10-3A15-3A12-3A2(14-2A)2(14-A16-A)13-3(2A16-2A12-)4(AC16-2A12-)A2C14-3A13-3C12-3A15-2C2-2C4-2A2-2A17-6C8A19-5CAF5A24-CA2F409-10A21-3A6-3A19-3A8-3A17-2A12-2A15-3A12-3A4(14-2A)2(14-A16-A)2(14-2A)2(14-2C14-2G)14-3C12-3G14-4C10-4G14-5C8-5G15-7C2-A6G17-6C3A5G18-6CF2A5G469-8A23-10A20-4A6-4A18-3A8-3A17-3A10-3A16-2A12-2A15-3(3A12-3A14-)3A12-3A15-2A12-2A16-3A10-3A16-4A8-4A17-5A4-5A19-12A20-6AF5A20-2A2-AF2A2-2A534-8A23-10A21-4A4-4A19-4B6-4A18-3B8-3A17-A2B10-3F16-A2B10-3F17-2(3B8-3F18-)4B6-4F18-5B4-A4F19-4B5A3F21-3B3AF3A24-3AF2A55-H10-H567-6A25-8A23-10A21-5A2-5A2(20-4A4-4A)20-12A21-10A22-10A23-8A25-4A2F589-
