model
size = 16 25 3, scale = 0.05, origin = -y
material deform = 1, fade = true, lighting = smooth, roughness = 0.3, metalness = 0.6
  colors = A:#111 B:#E00 C:#B00
voxels
6-13(A2BA12-)A2BA6-7A2B8A14B2A14B8A2B7A6-6(A2BA12-)4A12-A2-A13-2C216-C5-2B5-C2-C5-2B5-C-A5-A96-2C29-4A390-
