model
size = 20 32 3, scale = 0.05, origin = -y
material deform = 1, fade = true, lighting = smooth, roughness = 0.3, metalness = 0.6
  colors = A:#FFF B:#F5F5F5 C:#BBB D:#C6C6C6 E:#F8F6F2 F:#DCDCDC G:#FF0 H:#111 I:#BBBB53
voxels
58-G18-G17-2G14-AFD2AG12-C2AFBDBA11-3AEBA2B11-2C2ECEBDA10-2DFBEF2BAD9-A2E2DBCDAEC8-C3ECBEBC2A8-B2AC2BEABEDB8-B2A2(EBC)ADB7-ABC2EBEDFCFD8-CEBEC2BDEA2B8-ADBE3BEDBA8-BDCEBEAECD2A8-2CEBCEFEBAD9-AB2ECFE2BAD9-FECF2EACAB10-BCAEDEAC2A10-BCBDED2AC11-2B2(D2A)C12-B3ACDA13-C3ACD14-AFD2A15-FADF17-DA18-F75-H18-GH17-2G17-GAG13-AB2(AG)11-2B5AIG9-2B6ADA9-AB8AD8-2B9AC7-2B10AC6-2C11A6-CB12A6-A2(B5A)B6-B11AB6-7A4B2AC6-10A4B6-12AB7-11A2B6-BC10AC7-C12A7-BC9AF8-AC8A2F8-C8AFB10-8ADA10-AD6AD11-DC4A2BA11-B6AB12-AC4AC14-C3AC15-C2AF17-2F18-F74-G18-G17-2G14-CF2AFG12-FAFC2AFA11-C4DBFA11-BACE2ACBC10-BAF4BCBA9-CA3D3BAEB8-3DC3BFBFE8-BA6BFAFB8-3(2BC)AFC7-2BA3BFB2DBA8-CEC2A3B2DCB8-FBDCABFBADC8-A2DAC2BCABDA8-2CAC3B2EBD9-ACFCBA3BCD9-A2B2A4BC10-2(BC)2AED2B10-CADF2BCDA11-2DA3BC2A12-ACBDAEA13-2CBDAB14-ACBDA15-2BDA17-AD18-A56-
