model
size = 3 31 25, scale = 0.05, origin = -y
material deform = 1, fade = true, lighting = smooth, roughness = 0.3, metalness = 0.6
  colors = A:#F80 B:#EEE C:#555 D:#888
voxels
28-6(A2-)A68-A-27A-A56-A2-A-6A-6(A2-)A-9A-A47-A-6A-2(A2-)7(B2-)A2-A-6A-A41-A-6A-A11(2-B)2-A-6A-A35-A-6A-A13(2-B)2-A-6A-A31-6A-A15(2-B)2-A-6A28-A-3A-A4(2-B)4(2-C)9(2-B)2-A-3A-A25-6A-A3(2-B)6(2-C)2-B4(2-C)3(2-B)2-A-6A22-A-3A-A2(3(2-B)2(2-C))6(2-C)3(2-B)2(2-A-3A-A20-A-3A-A5(2-C)4(2-B)2(2-C)3(2-B)5(2-C))2-A-3A-A8-D2-D8-A-3A-A3(2-B)2(2-C)4(2-B)2(2(2-C)3(2-B))2-D-DA4D-D2-D-6D-2(D2-)A-3A-A5(2-C)4(2-B)2(2-C)3(2-B)5(2-C)2-A-3A-A8-D2-D8-A-3A-A5(2-C)4(2-B)2(2-C)3(2-B)5(2-C)2-A-3A-A20-A-3A-A3(2-B)13(2-C)3(2-B)2-A-3A-A22-6A-A3(2-B)11(2-C)3(2-B)2-A-6A25-A-3A-A17(2-B)2-A-3A-A28-6A-A15(2-B)2-A-6A31-A-6A-A13(2-B)2-A-6A-A35-A-6A-A11(2-B)2-A-6A-A41-A-6A-2(A2-)7(B2-)A2-A-6A-A47-A-9A-6(A2-)A-9A-A56-A-27A-A68-6(A2-)A46-
