model
size = 24 18 19, scale = 0.05, origin = -y
material deform = 1, fade = true, lighting = smooth, roughness = 0.3, metalness = 0.6
  colors = A:#200 B:#111 C:#EEE
voxels
6-7A423-11A16-5A378-A20-13A13-9A65-5A19-5A258-A23-A19-15A10-13A15-2(5A18-)9A15-9A232-A23-A42-17A9-13A13-9A14-9A15-11A13-11A16-5A18-5A187-A23-A42-17A8-14A2(12-11A)13-13A12-11A15-7A16-7A19-5A18-5A92-2(5A18-)5A20-A41-18A8-14A2(12-11A)13-13A11-13A13-9A14-9A17-7A16-7A20-3A43-3A21-2(7A16-)7A18-3A28-B11-18A7-15A11-12A11-13A11-15A10-17AB7-11A5-C6-11A15-9A14-12A5-CB8-5A-4A2-2AB9-3A19-5A19-2(9A14-)9A16-5A3-B15-4A4-B11-18A7-15A11-12A11-13A11-15A4-AB4-6A-12AC5-11A12-11A15-9A7-C6-9A3B5-2AB6-11A2-4A7-16A6-17AB7-17A6-9A14-9AC14-7A2-B14-6A15-18A7-15A11-12A11-13A11-15A4-AB4-19A6-5A-5A12-5A-5A15-4A-4A14-4A-4A3B5-BAB6-3A-7A2-4A7-2A-13A6-3A-12A-B7-4A-11AB6-4A-4A14-4A-4A15-7A17-7A14-18A7-15A11-12A11-13A11-15A4-AB4-19AC5-11A12-11A15-9A7-C6-9A3B5-2AB6-11A2-4A7-16A6-17AB7-17A6-9A14-9AC14-7A2-B14-6A15-17A8-15A11-12A11-13A11-15A11-11A-3A2B7-11A5-C6-11A15-9A14-12A5-CB8-5A-4A2-2AB9-3A19-5A19-2(9A14-)9A16-5A3-B15-4A4-B11-17A9-14A2(12-11A)13-13A12-11A2(14-9A)17-7A16-7A20-3A43-3A21-2(7A16-)7A18-3A28-B12-17A8-14A2(12-11A)13-13A13-9A2(16-7A)19-5A18-5A92-2(5A18-)5A20-A42-17A9-13A13-9A14-9A15-11A16-5A19-5A18-5A187-A23-A43-14A11-13A15-2(5A18-)9A256-A23-A44-13A13-9A65-5A282-A23-A21-11A16-5A378-A23-7A419-
