model
size = 31 32 27, scale = 0.05, origin = -y
material deform = 1, fade = true, lighting = smooth, roughness = 0.3, metalness = 0.6
  colors = A:#111 B:#555 C:#EFBB24
voxels
232-2A28-4A26-6A26-4A24-A3-2A3-A20-3A6-3A18-5A4-5A18-3A-4A-3A20-A2-4A2-A24-4A678-4A26-6A22-A-8A-A18-14A16-16A16-14A16-2(16A15-)16A16-14A18-12A22-6A82-2(A14-)2(3A12-)5A10-5A2(12-3A)2(14-A)394-2A27-A4-A21-4A6-4A16-5A6-5A14-6A6-6A13-7A4-7A2(13-18A)12-20A10-22A10-20A12-A-14A-A16-12A18-14A15-6A2-2A2-6A12-6A2-4A2-6A10-7A-6A-7A9-7A2-4A2-7A9-7A3-2A3-7A2(10-5A)2(12-3A)388-A10-A17-3A10-3A14-4A10-4A13-4A10-4A12-6A8-6A11-7A6-7A10-22A8-2(24A7-)24A8-22A10-20A13-16A13-20A10-22A9-22A8-24A8-7A-6A-7A9-7A2-4A2-7A2(10-5A)13-A14-A357-2A10-2A15-3A12-3A13-2(3A12-)4A12-4A11-2(5A10-)6A10-6A8-8A2-4A2-8A7-24A6-26A6-24A7-24A8-22A11-18A11-22A9-22A11-3(18A13-)5A-6A-5A11-7A3-2A3-7A11-3A12-3A318-A30-A5-2A12-2A9-A4-2(3A12-)4A12-4A11-4A12-4A10-5A12-5A8-7A10-7A7-7A10-7A6-2(26A5-)26A6-24A7-24A9-20A10-22A8-24A10-3(18A13-)18A11-8A-4A-8A2(10-5A)317-A30-A6-A12-A15-2A14-2A13-2A14-2A12-3A14-3A9-6A12-6A7-6A12-6A6-2(8A10-8A5-)2(8A3-4A3-8A5-)9A2-4A2-2(9A6-)9A8-9A4-9A2(9-22A)11-3(18A13-)18A11-22A11-3A12-3A286-A30-3A25-A2-2A26-A2-A6-A14-A8-A5-2A14-2A11-4A14-4A8-5A14-5A6-4(7A12-7A5-)7A12-7A6-7A10-7A7-7A10-2(7A8-)7A10-8A4-8A10-22A11-3(18A13-)18A12-20A13-3A3-4A3-3A21-4A262-A30-3A24-2A2-2A26-A2-A30-A4-3A14-3A9-5A14-5A7-5A14-5A6-4(7A12-7A5-)7A12-7A6-6A12-6A7-7A10-7A8-6A10-6A4-A4-8A6-8A4-2A4-20A4-A5-2(22A9-)22A10-20A12-18A15-2A-8A-2A20-8A24-6A199-A30-2A26-A2-4A22-3A2-2A26-A2-A30-A3-4A14-4A8-5A14-5A6-6A14-6A2(5-7A12-7A)2(5-6A14-6A)6-5A14-5A2(4-A2-6A12-6A)4-A2-7A10-7A3-2A3-7A8-7A3-4A2-9A4-9A2-2A7-18A12-20A12-18A14-16A16-14A17-14A19-10A22-8A25-4A27-4A107-A30-A29-3A26-7A22-8A24-6A-3A18-3A-4A-6A14-6A-A-8A14-7A2(2-9A12-8A)3-7A14-7A4-6A14-6A5-6A14-6A4-A-5A14-5A4-8A14-7A2(2-9A12-8A)-11A10-23A6-43A6-20A12-18A14-16A15-16A16-14A19-10A21-10A23-6A25-6A44-2(A30-)A29-3A26-6A24-9A20-11A20-13A16-17A12-19A2(12-9A-9A)12-9A-8A2(14-7A3-7A)14-6A4-7A14-6A3-8A14-7A2(2-9A12-8A)-11A10-23A-4A-13A4-22A11-18A14-16A15-16A16-14A17-14A18-12A20-10A22-8A23-8A26-2A15-2(A30-)2A26-A-4A24-8A22-11A18-14A16-16A14-18A12-19A2(12-9A-9A)12-9A-8A14-8A2-2(7A14-7A3-)7A14-6A3-8A14-7A2(2-9A12-8A)-11A10-23A-4A-13A4-22A11-18A14-16A15-16A16-14A18-12A19-12A20-10A22-8A23-8A25-4A14-2(2A26-A2-)3A24-2A-4A24-8A22-11A18-14A16-16A14-18A12-20A10-10A-10A10-10A2(-9A12-9A)-8A14-8A2-7A14-7A3-7A14-6A4-8A12-7A3-9A12-8A2-10A10-9A2-11A8-10A-32A4-22A11-18A14-16A15-16A16-14A18-12A19-12A20-10A22-8A23-8A25-4A14-2(3A24-2A2-)3A24-2A-5A22-10A20-12A18-13A18-15A14-18A12-20A10-2(10A-10AB8-B)10A-9A2B8-2B9A2-8A2B8-2B2(8A3-8A12-)7A4-8A12-7A3-2(10A10-9A2-)12A6-11A2-29A6-22A11-18A14-16A15-16A16-14A18-12A19-12A20-10A23-6A25-6A27-2A15-2(3A24-2A2-)4A22-3A-6A20-12A2(18-13A)18-14A16-16A2B10-2B18A3B6-3B9A-10A2B6-2B2(10A-10A3B4-3B)9A3-8A3B6-3B8A3-8A3B6-3B7A5-7AB10-B6A5-9A10-8A4-9A10-8A3-11A8-10A2-13A4-12A2-29A6-22A11-18A14-16A15-16A16-14A18-12A20-10A21-10A24-4A27-4A46-3A22-2A3-4A22-3A2(2-5A20-4A)-7A3(18-13A)18-14A5B6-5B7A-8A5B4-5B7A2-9A4B4-4B8A2-10A2(3B4-3B9A3-9A)3B4-3B8A5-8A3B4-3B7A6-8A2B6-2B7A6-9A8-8A5-11A6-10A4-12A4-11A4-27A3-29A6-22A11-18A14-16A15-16A16-14A18-12A20-10A22-8A106-3A22-2A3-4A22-3A2(2-5A20-4A)3(2-6A18-5A)2-6A-4B8-4B-5A2-7A5B6-5B6A2-7A6B4-6B6A2-8A6B2-6B7A2-9A5B2-5B8A3-9A4B2-4B8A4-11A2B2-2B10A5-10AB4-B9A7-8AB6-B7A7-9A8-8A6-9A8-8A5-11A6-10A2(4-27A)7-22A11-18A14-16A15-16A16-14A18-12A21-8A24-6A107-3A22-2A4-3A22-2A3-2(5A20-4A2-)3(6A18-5A2-)7A4B8-4B6A2-7A6B4-6B6A2-8A5B4-5B7A2-8A6B2-6B7A3-8A5B2-5B7A4-9A4B2-4B8A5-9A3B2-3B8A6-10AB4-B9A7-8A2B4-2B7A8-8A8-7A7-9A8-8A6-10A6-9A6-25A5-27A4-27A8-20A12-18A14-16A15-16A21-4A27-4A140-2A22-A5-3A22-2A2(4-4A20-3A)3-6A18-5A2(2-7A16-6A)2-7A4B8-4B6A2-7A6B4-6B6A3-7A5B4-5B2(6A4-7A6B2-6B)6A5-7A5B2-5B6A6-8A4B2-4B7A7-2(8A2B4-2B7A8-)2(8A8-7A8-)9A6-8A7-2(25A6-)25A8-22A10-20A12-18A14-A6-2A6-A196-2A22-A6-2A22-A5-2(4A20-3A4-)5A18-4A2(4-6A16-5A)4-6A4B8-4B5A4-6A5B6-5B5A4-6A6B4-6B5A4-6A7B2-7B5A5-6A6B2-6B5A6-6A6B2-6B5A7-6A5B2-5B5A8-7A3B4-3B6A9-7AB6-B6A2(10-8A6-7A)9-4(23A8-)23A9-22A10-5A4-2A4-5A226-A29-2A22-A2(6-3A20-2A)5-5A18-4A3(4-6A16-5A)4-6A5B6-5B5A5-2(5A6B4-6B4A6-)6A5B4-5B5A7-5A5B4-5B4A8-6A4B4-4B5A9-6A3B4-3B5A11-6AB2-2B2-B5A12-6A8B5A12-7A6B6A11-9A4B8A5(10-21A)10-4A2-2A6-2A2-3A11-A18-A195-2(A30-)2A20-A7-3A20-2A6-4A18-3A3(6-5A16-4A)6-5A-2B10-2B-4A6-5A5B6-5B4A7-4A5B6-5B2(3A8-4A3C3B4-3B3C)3A9-3A3C2B6-2B3C2A11-5A2B6-2B4A13-4A4-2B4-3A15-3A10B2A15-5A8B4A14-6A6B5A13-8A4B7A3(12-19A)12-8A-2A-7A12-3A2-2A6-2A2-2A12-A276-2(2A20-A8-)3A18-2A5(8-4A16-3A)8-4A4B8-4B3A9-3A3CB8-B3C2A10-3A3CB8-B3C2A11-2A3CB3-2B3-B3CA13-3A5-2B5-2A15-3A-8B-2A17-2A-8B-A18-2A10BA17-4A8B3A16-5A6B4A15-3(17A14-)6A2-2A2-5A14-2A14-A291-2(A30-)2A18-A5(10-3A16-2A)10-4A14-3A11-3A14-2A12-4A12-3A13-3A12-2A15-2A4-4B4-A17-A3-6B24-2B4A2B23-2B4A2B21-A-2B4A2B21-2A-6B-A19-5A4B4A2(18-13A)18-2(2A4-)A387-A30-4(3A14-2A12-)3A14-2A13-2A14-A14-2A14-A15-A99-2A28-4A26-6A26-4A28-2A26-2A4-A2(24-7A)27-2A424-3(2A14-A14-)2A14-A15-A30-A673-
