model
size = 11 32 32, scale = 0.05, origin = -y
material deform = 1, fade = true, lighting = smooth, roughness = 0.3, metalness = 0.6
  colors = A:#1E1E1E B:#000 C:#232323 D:#EEE E:#E00
voxels
256-5A5-A5CA3-4(A7CA2-)A7CA3-A5CA5-5A280-A5-A345-2(A5-)A3-A335-A5-A4-2A3-2A5-A3-A2(335-2A3-2A5-2A-2A)6-A3-A3(324-A5-A4-2A3-2A5-2A-2A)6-A3-A302-2(A5-A4-)2A3-2A5-2A-2A6-2A-2A302-A5-A2(3-3A)2-4A-4A3-7A5-5A280-A5-A4-2(2A3-)3A3-3A2-4A-4A2(2-9A)3-7A5-5A258-A5-A3-2(4A-4A2-)9A-22A-9A2-9A3-7A6-3A248-3A-3A3-9A2-9A-44A-9A2-9A4-2AC2A238-A-A6-7A3-9A-66A-9A3-3AC3A6-3A218-A8-5A4-9A2-9A-2(11AC9AC)22A-9A3-3(AC)A5-A3DA7-3B9-8(B10-)C9(10-A)9-3A6-7A3-9A-22AC9AC11AC9AC22A-9A3-3(AC)A4-AD4BA5-5B7-8(3B8-)3C9(8-3A)7-5A2(5-7A3-9A-22AC9AC11AC9AC22A-9A3-3(AC)A4-ADBEDBA5-9(5B6-)5C10(6-5A))5-7A3-9A-22AC9AC11AC9AC22A-9A3-3(AC)A4-ADB2DBA5-5B7-8(3B8-)3C9(8-3A)7-5A5-7A3-9A-22AC9AC11AC9AC22A-9A3-3(AC)A5-A3BA7-3B9-8(B10-)C9(10-A)9-3A6-7A3-9A-22AC9AC11AC9AC22A-9A3-3AC3A6-3A218-A8-5A4-9A2-9A-55A-9A2-9A4-2AC2A238-3A6-7A3-9A2-9A-44A-9A3-7A5-2AC2A248-5A5-7A3-9A2-9A-22A-9A2-9A3-7A6-3A260-5A5-7A3-3(9A2-)9A3-7A5-5A281-5A5-7A3-9A2-9A3-7A5-5A303-3(5A6-)5A303-5A5-3(7A4-)7A5-5A271-3A7-5A5-7A3-3(9A2-)9A3-7A5-5A248-5A5-7A3-9A2(-27A)-9A3-7A5-5A237-5A5-2A3C2A3-2A5C2A-2A7C3A2(9C2A)9C3A7C2A-2A5C2A3-2A3C2A5-5A3-
