model
size = 15 18 31, scale = 0.05, origin = -y
material deform = 1, fade = true, lighting = smooth, roughness = 0.3, metalness = 0.6
  colors = A:#FF3 B:#F90 C:#FC0 D:#900 E:#A00 F:#C60 G:#700 H:#500 I:#400 J:#800 K:#600 L:#B00 M:#C90 N:#FC3 O:#FF0 P:#CC0
voxels
71-KA13-DC12-EF13-EK239-DA13-MC12-BK13-EF239-BA13-PC12-EA13-EK224-CA13-CA12-BC13-2D13-D43-G166-CA13-2A13-C13-2F13-2G13-D28-E14-G151-MA13-2A12-2A13-2C13-2E12-2D28-C13-EC13-2G136-DA13-CA12-2A13-2C13-M13-2G13-2L13-F13-2C13-GC136-J2(C13-)2A13-2A12-2C13-2D13-2G12-2D2(13-2C)13-G93-GB12-GK13-KC13-F13-2N13-A13-2C13-2M13-J13-2L13-2F13-C14-E13-2G63-2B13-GB12-GK13-JK12-2E13-2C13-A13-2A13-2C12-2F13-2G13-D2(14-C)13-EG63-BA13-BA12-JB13-GK12-2K13-2F12-2N13-2A13-C13-2B13-2D13-E14-F13-2C13-E50-B13-BA12-BA13-HB13-L13-2K13-2E12-2C13-2A13-A13-2C13-2F13-J14-D13-E14-E35-BA12-2A13-2A12-FA13-L2(B13-)2D13-2H12-2F13-2C13-A13-2C13-2B13-E14-L13-E35-2(2A13-2A12-)2(BA13-)C13-2B13-K13-2D13-2C13-A13-2A13-2C13-F14-J13-D35-2A13-2A12-2A13-3(A13-C)13-2B13-D13-2H13-2D13-C13-2A13-2C13-B14-J13-D35-AC12-2(2A13-)A2(13-2A)13-A13-2C13-B13-2G13-2K13-M2(13-2C)13-B13-2L13-E35-B2(2(13-2A)13-A)13-2A13-A13-2F13-2I13-J13-2M13-2O13-C13-2D13-D35-B13-2B13-AB13-A2(13-2A)12-2(2A13-)A13-2C13-2J12-2I13-2E13-C13-2C13-2D13-J49-2B13-B14-B13-AB2(13-2A12-2A)13-2C13-F2(13-2H)12-2E13-2F13-2L12-2J49-K2(14-B)13-CB13-AB12-AB13-2A12-2A13-2A12-2B13-2D12-2I13-2H13-2K12-2D13-2D64-K14-K13-JK12-2F13-CB12-AB13-AB12-AB13-2C12-3D12-2K13-2I12-2G13-2D13-L65-B13-2E13-JE12-2K13-2E12-2F12-2CB12-CB13-2C12-FB13-2G12-2I13-2J13-2D12-GF65-B13-B2(E12-2D)12-2J13-2H12-2G13-2E12-2D13-2J12-2H13-2I12-3E12-2D13-G80-2(2B12-)3M2(12-2D)13-2G12-2H13-2I12-2I13-2H12-2H13-2E13-2D93-2B13-2(2B12-)3B12-2M12-3D12-2L12-2G13-2H12-2I13-2J13-2D108-2D12-3F2(12-2B)2(12-3B12-2B)13-2D12-2I13-2E123-H13-2H12-3J12-2E12-2D13-2F12-2F13-2D12-2H13-2K138-D13-2E12-2G13-2H12-2(2I13-I13-)2I166-2D13-2D12-2E12-3D12-2D12-2H13-2I196-F13-2B12-2B13-2B12-2H193-B13-3B12-3B11-2B3F9-3C2J10-3E-I9-4D-H9-3E11-2F88-
