model
size = 16 31 21, scale = 0.05, origin = -y
material deform = 1, fade = true, lighting = smooth, roughness = 0.3, metalness = 0.6
  colors = A:#111 B:#C30 C:#930 D:#F30 E:#999 F:#4C2603 G:#630 H:#F60 I:#AAA J:#633 K:#996 L:#777 M:#400 N:#300 O:#592C01 P:#963 Q:#FCC R:#FFC S:#BBB T:#888 U:#444 V:#966 W:#C96 X:#C63 Y:#C99 Z:#800 Aa:#333 Ab:#555 Ac:#FC9 Ad:#222 Ae:#C60 Af:#CCB615 Ag:#CCAE1D Ah:#500 Ai:#700 Aj:#A00 Ak:#3F1F05 Al:#600
voxels
4-7A10-6A10-5A11-2(6A10-)6A2(11-5A)12-4A90-2(A15-)A40-8(A15-)A12-3A13-2A37-11A3(6-2A)5-2A7-5(2A6-)2(2A7-2A5-)2A7-3A4-3A2(6-10A)7-9A6-10A6-2A13-2A14-2A9-A4-2A9-A3-3A9-A3-4(2A11-A2-)2A11-A3-A11-A3-2A10-A4-2A8-A5-2A8-A6-3A5-A8-7A11-3A23-12A4-A10-A4-A9-A5-3(A10-A4-)3(2A9-A4-)2(2A10-A3-)3A9-A4-A10-A3-2A10-A2-2A11-A2-2(2A12-A-)5(A13-A-)A13-2(A2-A12-)A3-A11-A14-A5-2A7-A8-A5-2A9-5A21-13A3-2(A5-)A3-2(T5-)A3-2(K12-A2-)U11-A3-Ah3(11-A3-G)2(12-A2-G)13-A-2Ai11-A2-Z13-A-C13-5(AC14-)2(AJ14-)AF14-A-F13-A2-F12-A3-F11-A3-O10-A5-A8-A7-2A6-A9-6A20-6A-7A2-O4-O-O5-2AAb5-Ab-Ab5-2AJ5-3J5-A-Ad5-3Ad4(5-A-G5-3G)5-A-C6-3C4-A-C6-3C5-2(AC6-2C2A4-)4(AC14-)AB14-AC14-AP3(14-AV)14-A2V13-2(A2-K12-)A3-K10-A5-A9-A6-A7-A8-4A2-A10-5A4-6A4-5A-L4-L3-L5-AF4-F3-F5-AU4-U3-U5-AN4-N3-N4-A-C4-C3-C4-A-2(B4-B3-B5-A)Ae4-Ae3-Ae5-AAe4-2Ae2(3-A4-AH4-2H)2(4-A3-AB4-2B)4-A3-3(AB4-B9-)AB14-AD3-D10-AC3-C10-AJ3-J10-3(AF14-)A-F13-A2-F12-A2-F11-A4-J10-A5-6A3-A12-A-A14-2A3-5A5-5A-K3-K5-A4-AAa3-Aa5-A4-AM3-M5-A3-A-F3-F5-A3-A-Z3-Z5(5-A4-AB3-B)6-A3-AD3-D6-A3-AH3-H6-A3-AB3-B7-A2-3(AB3-B10-)AD3-D10-AD2-D11-AC2-C11-AG3-G10-AJ3-J10-AF14-AJ14-A-J13-A2-J12-A2-J6-2(A4-)J10-A5-7A2-A13-A-A14-A3-5A6-4A-I3-I5-A4-AAb3-Ab5-A4-AV3-V5-A3-A-G3-G5-A3-A-Z3-Z4(6-A3-AB3-B)6-A3-AB2-B7-A3-AH2-H7-A3-AD2-D7-A3-AB2-B8-A2-AB2-B4(11-AD2-D)9-A-AC2-C9-A-AJ2-J9-A-AF3-F8-A-2(AF14-)A-F13-A2-F12-A2-F6-2(A4-)F10-A5-T6A2-A13-A-A14-A3-4A7-5AE2-E7-A3-AO2-O7-A3-AL2-L7-A2-A-C2-C7-A2-A-Aj2-Aj2(7-A3-AB2-B)3(8-A2-AD2-D)8-A2-AH2-H8-A2-AB2-B3(8-A2-AD2-D)11-AD-D12-2(AD-D10-A-)AC2-C9-A-AF2-F9-A-2(AP3-P10-)AP14-A-P13-A2-P12-A2-P7-A3-A4-F3-3A4-A5-E2A3-A2-A13-A-A14-A3-4A7-5AI2-I7-A3-AL2-L7-A3-AK2-K2(7-A2-A-C2-C)2(7-A3-AB2-B)2(8-A2-AB2-B)8-A2-AD2-D9-A-AH2-H4(9-A-AD2-D)9-A-AD-D2(10-A-AB-B)10-A-AC2-C9-A-AP2-P9-A-2(AK3-K10-)AK14-A-K13-A2-K3-A8-A2-V7-A3-A4-V3-A2-A3-A5-E2A3-A2-A13-A-A14-A3-4A7-5AI2-I7-A3-AL2-L6-A4-AT2-T6-A3-A-G2-G6-A3-A-Z2-Z6-A4-AB2-B7-A3-3(AB2-B8-A2-)AB-B2(10-A-AH-H)2(10-A-AB-B)4(10-A-AD-D)10-A-AX2-X9-A-AK2-K9-A-2(AW3-W10-)AW14-A-W13-A2-W12-A2-W4-A2-A3-A4-K3-A2-A3-A5-E2A3-A2-A13-A-A14-A3-4A7-5AT2-T7-A3-AL2-L6-A4-AU2-U6-A4-AJ2-J6-A3-A-Ai2-Ai2(6-A4-AC2-C)7-A3-2(AB2-B8-A2-)2(AB-B10-A-)AH-H10-A-AB-B2(10-A-AD-D)2(10-A-AH-H)10-A-AB-B10-A-AX2-X9-A-AAf2-Af9-A-AAc3-Ac10-AQ3-Q10-AQ14-A-Q13-A2-Q12-A2-Q5-A-A3-A4-W3-3A4-A5-I2A3-A2-A13-A-A14-A3-5A6-5AL3-L6-A3-2(AU3-U5-A4-)AAa3-Aa5-A3-A-C3-C2(5-A4-AB3-B)6-A3-2(AB3-B7-A2-)AB2-B8-A2-AH2-H3(8-A2-AB2-B)9-A-AB2-B2(9-A-AD2-D)9-A-AB2-B9-A-AX2-X9-A-AAc2-Ac9-A-AQ3-Q8-A-AQ14-AR14-A-R13-A2-R12-A2-R5-3A3-A4-Y10-A5-Ag6A2-A13-A-A14-A3-5A6-6A3-A2(5-A4-AF3-F)5-A4-AAd3-Ad5-A3-A-Ak3-Ak5-A3-A-2(2(C4-)A4-A)2(2(C4-)2A3-A)C3-C5-2A3-AB3-B6-A3-AC2-C7-A3-3(AC3-C7-A2-)AC3-C10-AC3-C8-A-AB2-B9-A-AX2-X9-A-AAc3-Ac8-A-AR3-R8-A-AQ14-AR14-A-R13-A2-R12-A2-R6-2(A4-)Y10-A5-7A2-A13-A-A14-A3-6A4-7A3(4-A)O4-O3-O5-2A4-A3-A5-AAa4-Aa3-Aa4-A-G4-G3-G4-A-2(N5-N2-N5-A)2(M5-M2-M5-A)N4-2N2-N5-A2(N4-)A4-AM3-2M2(9-AM4-M)9-AM11-A2-AAh14-AAl14-AAh3-Ah10-AF3-F10-AY3-Y8-A-AY12-A-2(AAf14-)A-Af13-A2-Af12-A2-I6-2(A4-)Y10-A5-6A3-A12-A-A14-2A3-5A-A2-8A3-2(A-)2A5-2A3-2(A-)A5-A-A3-2(A-)A6-2A3-A-3A6-2A4-4A5-A-A6-2A5-A-E6-2E6-AT6-2T6-AO6-2O6-AI6-2I6-AS5-4S5-AI5-I8-AS2(14-AI)2(14-AS14-AI)14-AAb14-AY14-AE14-AL14-A-E13-A2-I12-A2-S6-2(A4-)A10-A5-A8-A7-5A2-A10-5A4-7A-9A2(4-2A-A5-A-A)4-A-A6-A-A4-A9-2A13-A-A14-AI14-AO12(14-2A)2(14-AI)14-A-A13-A2-A12-A2-A11-2A3-A5-A10-A16-A7-A8-A5-A10-5A5-14A2-A5-A6-A2-2(A5-)2A4(2-A12-A)2-E12-A2-Ab2(12-A2-A)12-A-2A12-A-3A11-A-2A2(13-3A)13-5(2A14-)AAg14-A-I13-A-A13-A2-A12-A3-A11-A3-A10-A5-A8-A7-2A6-A9-6A21-13A3-A10-2A3-A9-A5-3(A10-2A3-)2A9-2A3-2E9-2A3-2L10-A3-I2(E10-A3-A)2E9-A4-3(E10-A3-A)12-A-2A12-4(3A13-)A-I13-A-Ag13-2(A2-A12-)A3-A11-A4-A9-A5-2A7-A8-A5-2A9-5A22-11A3(6-2A)5-2A7-5(2A6-)2(2A7-2A5-)2A7-I2A4-4A5-L10A5-E10A6-10A5-E2A5-3A5-EA7-2A5-E2(9-A4-EA)2(9-A3-2EA)2(10-A2-2EA)10-A2-S2A10-A2-Ag2(2A10-A3-)2A10-A4-2A8-A5-2A8-A6-4A13-3A2-2A11-3A25-7A10-6A10-5A11-2(6A10-)6A2(11-5A)12-4A81-A8-A7-3(2A14-)2A7(15-A)14-2A13-3A10-5A11-4A35-
