model
size = 24 27 29, scale = 0.05, origin = -y
material deform = 1, fade = true, lighting = smooth, roughness = 0.3, metalness = 0.6
  colors = A:#F00 B:#000 C:#DE2400 D:#BE4800 E:#DA0107 F:#920316 G:#9E6D00 H:#B6020F I:#6E041E J:#7D9100 K:#BBB L:#4A0525 M:#020835 N:#EEE O:#3DDA00 P:#5DB600 Q:#119613 R:#1DFF00 S:#26062D T:#052C2B
voxels
422-3F21-3(F23-)2(I23-)I503-3F21-3(F23-)2(I23-)I93-2K5(22-2A)21-3E6(21-3H)4(21-3F)18-6F-5F2(12-12F)13-11F2(13-11I)13-5IB5I13-9B15-9B17-7B15-6K4(18-6A)17-9A2(15-9E)6(15-9H)15-9F15-2(7F17-)3(7F5-F11-)7F3-3F11-2(7I3-2I12-)3I4B3-2I2(12-7B2-3B)12-12B13-6K4(18-6A)17-9A3(15-9E)6(15-9H)15-2(7F17-)3(7F5-F11-)7F3-3F11-2(7I3-2I12-)3I4B3-2I2(12-7B2-3B)12-12B12-10K5(14-10A)5(14-10E)4(14-10H)2(14-10F)12-12F2-3F7-3(12F2-F9-)2(12I2-I9-)5I9BI3(9-15B)9-14K5(10-14A)6(10-14E)2(10-14H)2(9-15H)-2H5(6-15F-2F)2(6-15I-2I)6-6I10B2I3(6-18B)7-14K5(10-14A)7(10-14E)10-14H2(9-15H)-2H6-15H-2H4(6-15F-2F)2(6-15I-2I)6-6L10B2L3(6-18B)7-14K4(10-14A)9-15A8(9-15E)9-16H6-2(17H-2H4-)17F-2F3(4-20F)2(4-20I)4-8L10B2L3(4-20B)7-14K7(10-14A)3(9-15E)9-3(16E8-)18E4-20E2(4-20H)3(3-21F)2(4-20I)3-N9L9B2L2(4-20B)3-N20B7-14K7(10-14A)3(9-15A)9-3(16E8-)18E2(4-20E)4-20H3-21H2(3-21F)4-20I4-20L3-N9S9B2S2(4-20B)3-N20B7-15K13(9-15A)9-17E2(6-18E)3-E2-18E2(3-21H)3-21F3-21I3-21L-3N9M9B2M3(-3N20B)12-4K20-4A18-6A2(17-7A)15-9A15-2(6A18-)11A2(12-12A)10-2A-11A-2A2(7-2A-3A2-9A)6-A2-15A6-3A-17A3-3E-17E3-E3-17E3-E2-18E2(3-H2-18H)3-I2-18I3-M2-18M3-B9M9B2M2(-2N21B)3-21B12-4K20-4A18-6A2(17-7A)15-9A15-2(6A18-)11A2(12-12A)10-2A-11A-2A2(7-2A-3A2-9A)6-A2-15A6-2(3A-17A3-)A3-17A3-A2-18A2(3-E2-18E)3-A2-18A3-M2-18M3-B9T9B2T2(-2N21B)3-21B151-2(2A22-)5A16-2(6A18-)14A9-3(13A11-)2(18A6-)21A2(3-A3-17A)2(3-A2-18A)3-Q2-18Q3-B2-7Q9B2Q2(-2N21B)3-21B85-2A22-2A16-3A3-2A2(16-8A)16-5A-2A15-4A20-4A18-6A2-3A13-12A12-12A11-13A11-2(18A6-)2(21A3-)21C3-D2-18D3-G2-18G3-O2-18O3-B2-7R9B2R2(-2N21B)3-21B85-2A22-2A16-3A3-2A2(16-8A)16-5A-2A15-4A20-4A18-6A2-3A13-12A12-12A11-13A11-2(18A6-)3(21C3-)D2-18D3-G2-18G3-O2-18O3-B2-7R9B2R2(-2N21B)3-21B10-5K19-5A18-6A16-3(9A15-)6(11A13-)14A10-14A7-18A5-19A5-19C5-C2-18C3-C3-17C3-D3-17D3-D2-18D3-G2-18G3-P2-18P-2NB2-7O9B2O3(-2N21B)9-9K15-9A13-4(12A12-)5(14A10-)2(15A9-)15C9-17C2(6-18C)3-C2-18C3-2(D2-19D2-)22D2-22G2-22J2-N9P9B2P2(4-20B)3-N20B8-10K14-10A13-4(12A12-)5(14A10-)3(15C9-)17C6-18C6-2(18D3-D2-)19D2-D2-19D2(2-22G)2-22J2-N9P9B2P2(4-20B)3-N20B7-12K12-12A3(11-13A)11-3(15A9-)3(15C9-)3(16C8-)15C-2C2(6-15D-2D)6-18D3-2(22D2-)22G3-21G3-21J3-9J9B2J3(4-20B)7-12K12-12A3(11-13A)11-15A6(9-15C)9-2(16C8-)3(15D-2D6-)18D6-19D5-19G2(3-21G)3-21J3-9J9B2J3(4-20B)7-12K12-12A3(11-13A)11-15A6(9-15C)9-16C8-16D8-3(15D-2D6-)18D6-19D5-19G2(3-21G)3-21J3-9J9B2J3(4-20B)7-12K12-12A4(11-13A)11-7(15C9-)15D9-16D8-4(15D-2D6-)15G-2G6-18G4-20G4-20J4-9J9B2J3(6-18B)7-12K5(12-12A)6(12-12C)12-2(14D10-)14D12-10D2-D11-10D2-D8-13D2-D2(8-13G2-G)2(9-15G)9-15J9-6J5B4J3(9-15B)10-11K13-11A4(12-12A)5(12-12C)12-12D12-2(14D10-)14D12-10D2-D11-10D2-D8-13D2-D2(8-13G2-G)2(9-15G)9-15J9-6J5B4J3(9-15B)11-6K-2K4(15-6A-2A)15-9A4(15-9C)7(15-9D)13-11D3-D3(9-11G3-G)11-9G3-G11-9J3-J11-4J2B3J3-J11-2(9B-2B12-)9B-2B15-3K5(21-3A)3(21-3C)9(21-3D)3(21-3G)-2G18-3G-2G18-3J-2J18-3J21-2(3B-2B18-)3B21-3K5(21-3A)2(21-3C)9(21-3D)4(21-3G)-2G18-3G-2G18-3J-2J18-3J21-2(3B-2B18-)3B10-
