model
size = 7 29 14, scale = 0.05, origin = -y
material deform = 1, fade = true, lighting = smooth, roughness = 0.3, metalness = 0.6
  colors = A:#FBE251 B:#D19826 C:#FFC408 D:#FFB11B E:#DDD23B F:#FAD689 G:#EEE H:#FCFAF2
voxels
98-2(A6-)2A5-FD5-FB2(5-2B)5-BA5-2A5-EA5-FA5-DE117-2(A6-)2A5-FD5-FB2(5-2B)5-BA5-2A5-EA5-FA5-DE76-BA5-DA5-FB5-CB5-DA5-2A2(5-AE)5-D2(A5-F)A2(5-2B)5-F2(A5-B)F5-DF2(5-CA)5-2A55-EF5-CE5-2D5-DA5-FA5-2A5-C2(E5-A)3(E5-D)E2(5-BA)5-CA5-BA5-2B2(5-CB)5-CF5-BA5-FA4-2DA41-2(D6-)DE2(5-DA)2(5-2A)5-CA5-C2(E5-D)E5(5-BA)3(5-CA)2(5-BA)5-A5-CA4-CGD3-2BFE5-2B28-8(A6-)2(C6-)A6-E2(6-A)3(6-C)6-D6-F6-A6-B5-BA4-DGA3-C2GA3-FCHA5-A22-C6-B4(6-A)2(6-E)2(2(6-A)2(6-C))6-E2(6-A)6-E6-A5-FA4-BGA3-B2GD3-3GA3-FHB5-F2(E7-4(B6-)BA5-AB5-B2(E5-D)E2(5-2A)5-CD5-CA2(5-2C)5-CA5-CD2(5-2D)5-DE2(5-DA)5-CE4-DCA3-F2BA2-2BDCA2-4B3-CDCA5-)E21-C6-B4(6-A)2(6-E)2(2(6-A)2(6-C))6-E2(6-A)6-E6-A5-FA4-BGA3-B2GD3-3GA3-FHB5-FE27-8(A6-)2(C6-)A6-E2(6-A)3(6-C)6-D6-F6-A6-B5-BA4-DGA3-C2GA3-FCHA5-A27-2(D6-)DE2(5-DA)2(5-2A)5-CA5-C2(E5-D)E5(5-BA)3(5-CA)2(5-BA)5-A5-CA4-CGD3-2BFE5-2B33-EF5-CE5-2D5-DA5-FA5-2A5-C2(E5-A)3(E5-D)E2(5-BA)5-CA5-BA5-2B2(5-CB)5-CF5-BA5-FA4-2DA60-BA5-DA5-FB5-CB5-DA5-2A2(5-AE)5-D2(A5-F)A2(5-2B)5-F2(A5-B)F5-DF2(5-CA)5-2A25-
