model
size = 28 12 31, scale = 0.05, origin = -y
material deform = 1, fade = true, lighting = smooth, roughness = 0.3, metalness = 0.6
  colors = A:#555 B:#001 C:#111 D:#444 E:#FF0 F:#FFF G:#777 H:#E00 I:#080 J:#FC3 K:#C00 L:#F30 M:#F60 N:#070
voxels
34-C22-4A-C-7A9-2(4A-)C-7A9-4A-4A3-7A3(9-4A-14A)9-4A-27A85-2(27A-)2(4A3C20A-)4A3C8A2(GA)CAC5A-27A-15A2(GA)CAC5A2(-27A)85-8(27A-)5A18C4A85-8(27A-)5ACK11CJ4C4A85-2(27A-)C26A5(-27A)-5ACL9CJCE4C4A85-3(27A-)C26A4(-27A)-5ACM7C2(EC)E4C4A2-2(2C26-)2C25-4(27A-)C26A3(-27A)-5ACN2C12E2C4A85-5(27A-)C26A2(-27A)-5A18C4A85-5(27A-)C26A3(-27A)4-3(2F2-)2F67-4(27A-)C26A4(-27A)85-3(27A-)C26A5(-27A)4-2F79-2(27A-)C26A6(-27A)11-8B66-3(27A-)C26A5(-27A)9-12B64-4(27A-)C26A4(-27A)8-14B63-5(27A-)C26A3(-27A)7-16B62-2(4(27A-)27A2C26A3(-27A)6-18B61-)5(27A-)C26A3(-27A)5-20B60-4(27A-)C26A4(-27A)5-20B60-3(27A-)C26A5(-27A)5-20B60-2(27A-)C26A6(-27A)5-9B2G9B60-3(27A-)C26A5(-27A)5-9B2G9B60-4(27A-)C26A4(-27A)2(5-20B60-5(27A-)C26A3(-27A))6-18B61-4(27A-)C26A4(-27A)-4D-18B4D57-3(27A-)C26A5(-27A)-DI2D2-16B-D2HD57-2(27A-)C26A6(-27A)-D2ID3-14B2-D2HD57-9(27A-)DI2D4-12B3-D2HD57-9(27A-)4D6-8B5-4D57-5(27A-)5A17C5A3(-27A)84-
