model
size = 27 17 24, scale = 0.05, origin = -y
material deform = 1, fade = true, lighting = smooth, roughness = 0.3, metalness = 0.6
  colors = A:#222 B:#111 C:#004 D:#002 E:#555 F:#BBB G:#E00 H:#888 I:#DDD J:#0B0 K:#CF0 L:#008 M:#070
voxels
179-5(A26-)A170-6(A26-)A15-4B7-A6-K8-3BI7-A5-J-I2-G4-BI2B7-A6-L3-G15-4(A26-)A80-A25-A26-3(A5-17A4-)A5-11A4B2A3(4-A5-17A)4-A5-11A4B2A4-A5-11A4-2A4-2(A26-)A27-A80-A25-A5-10(17A3-A6-)17A3-2(A27-)A80-A4-17A4-A5-17A3-A6-18A-3(A7-18AB)2(A7-H17ABA7-18AB)A7-H17A-A7-17A3-A6-17A4-A27-A80-A4-17A4-A5-17A3-A6-18ABA7-7(18AD8-)18ABA7-17A3-A6-17A4-A27-A80-A4-17A4-A5-17A3-A6-18ABA7-3(18AD8-)H2(17AD8-18AD8-G)17ABA7-17A3-A6-17A4-A27-A80-A4-17A4-A5-17A3-A6-18ABA7-2(18AD8-)4(18AD4-A3-)18AD8-18ABA7-17A3-A6-17A4-A27-A80-A4-17A4-A5-17A3-A6-18ABA7-B17AD7-AB17AD4-A-2A2(B17AD4-C3A)B17AD4-C2A-B17AD4-CA2-18AD4-A3-17A2BA7-17AB2-A6-B15A2B3-A5-3B12-2B5-A6-15B13-13B33-A4-17A4-A5-17A3-A6-18ABA6-AB17AD4-A-2AB17AD4-4A3(B17AD4-C3A)B17AD4-C2A-18AD4-2A2-17A2BA3-F3-17AB2-A6-B15A2B3-A5-3B12-2B5-A6-15B13-13B33-A4-17A4-A5-17A3-A6-18ABA6-AB17AD4-A-2AB17AD4-4A3(B17AD4-C3A)B17AD4-C2A-18AD4-2A2-18AB2(A3-)17A3-A6-17A4-A27-A80-A4-17A4-A5-17A3-A6-18ABA6-AB17AD4-A-2AB17AD4-4A3(B17AD4-C3A)B17AD4-C2A-18AD4-2A-F18AB2(A3-)17A3-A6-11AB5A4-A16-B10-A80-A4-17A4-A5-17A3-A6-18ABA6-AB17AD4-A-2AB17AD4-M4(3AB17AD4-C)2A-18AD4-2A-F18ABA3-F3-17A3-A6-17A4-A16-E10-A80-A4-17A4-A5-17A3-A6-18A-A7-B17ABA6-A2B16ABA3-A-2A2(2B16ABA3-C3A)2B16ABA3-C2A-B17ABA3-CA2-18AB2(A3-)18AEA7-17A-E-A6-17A-E2-A17-3E2-E4-A19-2E59-A25-A5-4(17A3-A6-)2(17A3-A2-A3-6AFAF8A3-A2-A3-)2(17A3-A6-)17A3-2(A27-)A80-A25-A26-A5-17A4-A5-5A6-6A6(4-A5-4A8-5A)4-A5-5A6-6A4-2(A26-)A27-A80-7(A26-)2(A17-A8-)5(A26-)A206-5(A26-)A296-5(A26-6(CA25-)A269-)A26-6(CA25-)A144-
