model
size = 27 30 27, scale = 0.05, origin = -y
material deform = 1, fade = true, lighting = smooth, roughness = 0.3, metalness = 0.6
  colors = A:#040 B:#050 C:#030 D:#696 E:#930 F:#700 G:#FF3 H:#3C6 I:#500
voxels
469-7B776-7A17-13B746-7C18-11A14-15B16-7A720-9CGC14-15A10-19B12-11A716-15C11-17A8-21B9-15A16-7B690-G16C9-19A7-21B8-17A13-11B19-5A663-19C7-21A5-23B6-19A11-13B16-G8A20-AG3A636-19C7-21A4-G24B5-19A10-14BG13-13A16-9A20-5B608-21C5-23A3-25B4-21A8-17B12-13A15-11A17-9B20-5A180-2(D11-D14-)2D9-HD15-2D7-DH17-HD5-2D19-2D3-2D21-5D230-21C5-23A3-25B4-21A8-17B11-15A13-13A15-11B18-7A21-5B153-2(D11-D14-)2D9-2D14-3D7-3D15-3D5-3D17-3D3-2DH19-7D228-22CG3-25A-27B2-22AG6-19B10-15A13-13A15-11B17-8AG19-7B22-3A126-2D11-2D12-2D11-2D13-2D9-2D14-3D7-3D14-4D5-3DH15-H3D3-4D17-9D21-E2F24-FEF24-E2I24-FEI24-2FI24-I2F24-3I24-F2I14-23C3-25A-27B2-23A6-19B9-17A11-15A13-13B15-11A17-G8B20-5A23-3B99-2(2D11-2D12-)H2D9-2DH13-3D7-3D14-4D5-4D15-4D3-4D17-9D20-F4E22-4EF22-I3EF22-F3EI22-4EI22-I4E22-F3EI22-I4E13-G22C3-25A-27B2-23A6-19B9-17A11-G14A13-13B15-11A17-9B19-7A21-5B23-3A25-B46-HD11-2D12-2D11-2D12-3D9-3D13-3D7-3D14-H3D5-4D15-4D3-3DH17-9D20-F3EF22-F2E2F22-F4E2(22-4EF)2(22-I3EF)22-4EI13-23C3-25A-27B2-G22A6-19B9-17A11-14AG13-13B15-11A17-8BG19-7A21-5B23-3A24-3B25-B19-2(2D11-2D12-)3D9-3D13-3D7-2DH14-4D5-4D15-4D3-4D17-9D20-3EFE22-2FE2F22-3EFI22-F2E2F22-I4E22-FE2FI22-IE2FI22-FE3F13-23C3-25A-27B2-23A6-18BG9-17A11-15A13-13B15-G10A17-9B19-7A21-G4B23-3A25-B46-2D11-2D12-2D11-2D13-2D9-2D14-3D7-3D14-4D5-4D15-4D3-4D17-9D21-E2F24-3F24-FEF24-EIF24-2FE24-FIF24-IFI24-2IF14-23C3-25A-27B2-23A6-19B9-17A11-15A13-13B15-11A17-9B20-5A23-3B100-2(D11-D14-)HD9-2D14-3D7-3D15-3D5-3D17-3D3-3D19-H6D228-23C3-G24A-27B2-23A6-G18B10-15A13-13A15-11B17-8AG19-7B22-2AG127-2D9-HD14-2D9-2D14-3D7-2DH15-3D5-3D17-3D3-3D19-6DH21-5D230-21C5-23A3-25B4-21A8-17B11-15A13-13A15-11B18-7A21-5B154-D9-D16-2D7-2D16-3D5-2HD17-3D3-HDH19-H6D21-2DH2D257-21C5-23A3-25B4-21A8-17B12-13A15-11A17-9B20-2AG2A182-2D5-DH18-2D5-2D18-H2D3-2DH19-4DH2D21-DH3D285-19C7-21A4-25B5-19A10-15B13-13A16-9A20-5B211-H4D22-2H3D23-H2D340-19C7-21A5-23B6-19A11-G12B16-7AGA20-5A637-17C9-19A7-20BG8-17A13-11B19-5A665-G13CG11-17A8-21B9-15A16-3BG3B693-11C14-15A10-19B12-11A720-7C18-11A14-15B16-7A749-4AG2A17-11BGB800-G6B334-
