model
size = 28 29 30, scale = 0.05, origin = -y
material deform = 1, fade = true, lighting = smooth, roughness = 0.3, metalness = 0.6
  colors = A:#F03 B:#F99 C:#BBB D:#FF3 E:#FFF F:#F66 G:#F90 H:#FCF
voxels
655-6B20-10B723-2(G27-)G755-3(D27-)G27-G699-D24-3BC2B20-5BC4B23-D2(27-G)640-6A21-8A18-3B3-D2-3B15-3B4-D3-3B21-2(D27-)G585-4A22-8A18-12A15-14A13-2B6-D5-2B12-2B6-D5-2B20-3(D27-)G501-4A22-8A19-10A17-12A15-14A13-16A11-2B7-D6-2B9-3B7-D6-3B18-3(D27-)G445-4A22-8A19-10A17-12A15-14A13-16A11-18A10-18A9-B9-D8-B7-2B9-D8-2B17-4(D27-)G361-4A22-8A19-10A17-12A15-14A14-14A13-16A11-18A9-20A8-20A7-B10-D9-B6-B10-D9-B17-4(D27-)G305-4A23-6A20-10A18-10A17-12A15-14A13-16A12-16A11-18A9-20A8-20A7-22A5-2B10-D9-2B4-2B10-D9-2B16-4(D27-)G249-4A23-6A21-8A19-10A17-12A15-14A14-14A13-16A11-18A10-18A9-20A8-20A7-22A5-24A4-B11-D10-B3-2B11-D10-2B15-4(D27-)G25-2(4B24-)4E24-4F3(24-4A)23-6A21-8A19-10A18-10A17-12A15-14A14-14A13-16A11-18A10-18A9-20A8-20A7-22A5-24A4-24A3-B12-D11-B2-B12-D11-B15-3(D27-)G51-2(8B20-)2E4A2E20-2F4A2F4(20-8A)19-10A17-12A16-12A15-14A13-16A12-16A11-18A10-18A9-20A8-20A7-22A6-22A5-24A4-24A3-B3-5C4-D11-B-2B12-D11-2B14-3(D27-)G50-2(10B18-)E8AE18-F8AF4(18-10A)17-12A16-12A15-14A14-14A13-16A11-18A10-18A9-20A8-20A7-22A6-22A5-24A4-24A3-26A2-B3-H5C3-D11-B-B13-D12-B14-2(D27-)G78-2(10B18-)E8AE18-F8AF3(18-10A)17-12A16-12A15-14A14-14A13-16A12-16A11-18A10-18A9-20A8-20A7-22A6-22A5-24A3-26A2-26A-B4-H5C3-D12-2B13-D12-B14-D2(27-G)77-2(12B16-)E10AE16-F10AF4(16-12A)15-14A14-14A13-16A12-16A11-18A10-18A9-20A8-20A7-22A6-22A5-24A4-24A3-26A2-26A-B4-H5C3-D12-2B13-D12-B14-G27-G105-2(12B16-)E10AE16-F10AF4(16-12A)15-14A14-14A13-16A12-16A11-18A10-18A9-20A8-20A7-22A6-22A5-24A4-24A3-26A2-26A-B4-H5C3-G12-2B13-G12-B148-2(12B16-)E10AE16-F10AF4(16-12A)15-14A14-14A13-16A12-16A11-18A10-18A9-20A8-20A7-22A6-22A5-24A4-24A3-26A2-26A-B5-5C6-5C5-2B26-B148-2(12B16-)E10AE16-F10AF4(16-12A)15-14A14-14A13-16A12-16A11-18A10-18A9-20A8-20A7-22A6-22A5-24A4-24A3-26A2-26A-B16-H5C4-2B26-B149-2(10B18-)E8AE18-F8AF3(18-10A)17-12A16-12A15-14A14-14A13-16A12-16A11-18A10-18A9-20A8-20A7-22A6-22A5-24A3-26A2-26A-B16-H5C4-2B26-B149-2(10B18-)E8AE18-F8AF4(18-10A)17-12A16-12A15-14A14-14A13-16A11-18A10-18A9-20A8-20A7-22A6-22A5-24A4-24A3-26A2-B15-H5C3-B-B26-B150-2(8B20-)2E4A2E20-2F4A2F4(20-8A)19-10A17-12A16-12A15-14A13-16A12-16A11-18A10-18A9-20A8-20A7-22A6-22A5-24A4-24A3-B15-H5C3-B-2B24-2B152-2(4B24-)4E24-4F3(24-4A)23-6A21-8A19-10A18-10A17-12A15-14A14-14A13-16A11-18A10-18A9-20A8-20A7-22A5-24A4-24A3-B16-5C3-B2-B24-B377-4A23-6A21-8A19-10A17-12A15-14A14-14A13-16A11-18A10-18A9-20A8-20A7-22A5-24A4-B22-B3-2B22-2B433-4A23-6A20-10A18-10A17-12A15-14A13-16A12-16A11-18A9-20A8-20A7-22A5-2B20-2B4-2B20-2B490-4A22-8A19-10A17-12A15-14A14-14A13-16A11-18A9-20A8-20A7-B20-B6-B20-B547-4A22-8A19-10A17-12A15-14A13-16A11-18A10-18A9-B18-B7-2B18-2B603-4A22-8A19-10A17-12A15-14A13-16A11-2B14-2B9-3B14-3B660-4A22-8A18-12A15-14A13-3(2B12-)2B717-6A21-8A18-3B6-3B15-3B8-3B147-
