model
size = 17 31 17, scale = 0.05, origin = -y
material deform = 1, fade = true, lighting = smooth, roughness = 0.3, metalness = 0.6
  colors = A:#DDD586 B:#C5D1D4
voxels
312-5(5A12-)5B12-5B403-5A10-5(9A8-)2B5-2B8-2B5-2B10-5B12-5B367-9A6-5(13A4-)2B9-2B4-2B9-2B6-2B5-2B8-2B5-2B10-5B12-5B46-5B267-5A9-11A5-5(13A4-)B11-B4-B11-B5-B9-B6-B9-B7-2B5-2B8-2B5-2B10-5B12-5B11-7B249-5A11-7A7-13A3-5(15A2-)B13-B2-B13-B3-B11-B4-B11-B5-2B7-2B6-2B7-2B8-B5-B10-B5-B9-9B247-7A9-9A6-13A3-5(15A2-)B13-B2-B13-B3-B11-B4-B11-B5-B9-B6-B9-2(B7-)B8-2(B7-)11B10-3B218-3A11-9A7-11A4-15A-85AB15-2B15-B-B13-B2-B13-B3-B11-B4-B11-B5-2(B9-B6-)11B9-5B13-3B15-9(B16-)B15-3B13-5A10-9A7-11A4-15A-85AB15-2B15-B-B13-B2-B13-B3-B11-B4-B11-B5-2(B9-B6-)11B9-5B13-11(3B14-)3B13-5A10-9A7-11A4-15A-85AB15-2B15-B-B13-B2-B13-B3-B11-B4-B11-B5-2(B9-B6-)11B9-5B13-3B15-9(B16-)B15-3B13-5A10-9A7-11A4-15A-85AB15-2B15-B-B13-B2-B13-B3-B11-B4-B11-B5-2(B9-B6-)11B10-3B218-3A11-9A7-11A4-15A-85AB15-2B15-B-B13-B2-B13-B3-B11-B4-B11-B5-B9-B6-B9-B7-9B247-7A9-9A6-13A3-5(15A2-)B13-B2-B13-B3-B11-B4-B11-B5-B9-B6-B9-2(B7-)B8-B7-B9-7B249-5A11-7A7-13A3-5(15A2-)B13-B2-B13-B3-B11-B4-B11-B5-2B7-2B6-2B7-2B8-B5-B10-B5-B11-5B267-5A9-11A5-5(13A4-)B11-B4-B11-B5-B9-B6-B9-B7-2B5-2B8-2B5-2B10-5B12-5B299-9A6-5(13A4-)2B9-2B4-2B9-2B6-2B5-2B8-2B5-2B10-5B12-5B335-5A10-5(9A8-)2B5-2B8-2B5-2B10-5B12-5B386-5(5A12-)5B12-5B108-
