model
size = 28 30 28, scale = 0.05, origin = -y
material deform = 1, fade = true, lighting = smooth, roughness = 0.3, metalness = 0.6
  colors = A:#EEE B:#CC6 C:#993 D:#555 E:#3CF F:#F06 G:#FC9 H:#FF3 I:#F63 J:#CFF K:#CCC L:#F9F M:#CC9 N:#FF6 O:#F9C P:#F3F Q:#FF0 R:#F30 S:#FCF T:#F90 U:#FFC V:#FC0 W:#F99 X:#CCF Y:#FC3 Z:#F0F Aa:#CF3 Ab:#F66 Ac:#CFC Ad:#F39 Ae:#CC0 Af:#FF9 Ag:#F36 Ah:#F6C Ai:#F03 Aj:#FFF Ak:#F09 Al:#F96 Am:#F69 An:#F60 Ao:#F00 Ap:#F3C Aq:#F33 Ar:#CF6 As:#CC3 At:#CF9 Au:#F93 Av:#FCC Aw:#CF0 Ax:#FC6 Ay:#F0C Az:#F6F
voxels
2(28-29D25(26A2D)26A29D)56-D26AD728AD26AD56-D26AD417A8(C2-25A)C2-84AD26AD56-D26AD4A13(20B8A)3(20BAC2-4A)20BA7(C2-25A)C2-56AD26AD56-D3A20-3AD7(3AB20-BAC-)3A5(B20-B6A)4(B20-BC2-3A)B20-BC2-4ARKQYAsSRQZYBYAoLKAnAxAgJFA7(C2-25A)C2-28AD26AD56-D3A20-3AD3A6(B20-B6A)B20-BAC-3A5(B20-B6A)4(B20-BC2-3A)B20-BC2-4AMQHRZRAbGRAqAhKFUAbAyYAaApTA7(C2-25A)C2-28AD26AD56-D3A20-3AD3A6(B20-B6A)B20-BAC-3A5(B20-B6A)4(B20-BC2-3A)B20-BC2-4ANGAxMRTArJAc2AjNVAaAiTAqOLOA7(C2-25A)C2-28AD26AD56-D3A20-3AD3A6(B20-B6A)B20-BAC-3A5(B20-B6A)4(B20-BC2-3A)B20-BC2-4AAiJYNAcArGAoAtLAgBLKJArAj2FAnAC2-2(25ACE-)5(25AC2-)28AD26AD56-D3A20-3AD3A6(B20-B6A)B20-BAC-3A5(B20-B6A)4(B20-BC2-3A)B20-BC2-4AAeAoAqAiAtAxAsAcAl2UAdAkAbApHLTMAyA4(CE-25A)3(C2-25A)C2-28AD26AD56-D3A20-3AD7(3AB20-BAC-)3A5(B20-B6A)4(B20-BC2-3A)B20-BCE-4AAfAcAjAeAlAcAzNAuAaMAsSAiLGUOAeTA5(CE-25A)2(C2-25A)C2-28AD26AD56-D3A20-3AD7(3AB20-BAC-)3A5(B20-B6A)4(B20-BC2-3A)B20-BCE-4AFNLAfAuAmGIAvKHAqZJFHAaAnWArA5(CE-25A)2(C2-25A)C2-28AD26AD56-D3A20-3AD3A6(B20-B6A)B20-BAC-3A5(B20-B6A)4(B20-BC2-3A)B20-BC2-4APIUFAvXAcGAmAbWAlPApMXKAyPHA4(CE-25A)3(C2-25A)C2-28AD26AD13-D27-D14-D3A20-3AD3A6(B20-B6A)B20-BAC-3A5(B20-B6A)4(B20-BC2-3A)B20-BC2-4AFGAaPAmS2VQAiXVAdLAeAdAbTIGAC2-2(25ACE-)5(25AC2-)28AD26AD41-D14-D3A20-3AD3A6(B20-B6A)B20-BAC-3A5(B20-B6A)4(B20-BC2-3A)B20-BC2-4AKVKFQAwOAuAfJAnAxAaFWBAiArIHA7(C2-25A)C2-28AD26AD41-D14-D3A20-3AD3A6(B20-B6A)B20-BAC-3A5(B20-B6A)4(B20-BC2-3A)B20-BC2-4AAmAuAbKAfAwZAlJApAlAbNMPSJH2XA7(C2-25A)C2-28AD26AD41-D14-D3A20-3AD3A6(B20-B6A)B20-BAC-3A5(B20-B6A)4(B20-BC2-3A)B20-BC2-4AAkAlAiAmJPAnAfVLAjLYAeIKApGAhAdAC2-2(25ACE-)5(25AC2-)28AD26AD41-D14-D3A20-3AD3A6(B20-B6A)B20-BAC-3A5(B20-B6A)4(B20-BC2-3A)B20-BC2-4ABAfJAkVAtAfAdAmFAyRKWIQL2HBA4(CE-25A)3(C2-25A)C2-28AD26AD13-D27-D14-D3A20-3AD7(3AB20-BAC-)3A5(B20-B6A)4(B20-BC2-3A)B20-BCE-4AAhAdApBAmWAoYAgM2UNPXGFXZSA5(CE-25A)2(C2-25A)C2-28AD26AD56-D3A20-3AD7(3AB20-BAC-)3A5(B20-B6A)4(B20-BC2-3A)B20-BCE-4AAjYLAhAgAfFAwAaAeIAtBIAhJMAdOKA5(CE-25A)2(C2-25A)C2-28AD26AD56-D3A20-3AD3A6(B20-B6A)B20-BAC-3A5(B20-B6A)4(B20-BC2-3A)B20-BC2-4AAgAwFAjAaBVAkOWAkAuAdIHAoAeBAzQA4(CE-25A)3(C2-25A)C2-28AD26AD56-D3A20-3AD3A6(B20-B6A)B20-BAC-3A5(B20-B6A)4(B20-BC2-3A)B20-BC2-4AUAkMAgONLSFPAvAgAsXZAcWSRGAC2-2(25ACE-)5(25AC2-)28AD26AD56-D3A20-3AD3A6(B20-B6A)B20-BAC-3A5(B20-B6A)4(B20-BC2-3A)B20-BC2-4AMSAeUFAtAkNTIAwHAqAhONPKAbJA7(C2-25A)C2-28AD26AD56-D3A20-3AD3A6(B20-B6A)B20-BAC-3A5(B20-B6A)4(B20-BC2-3A)B20-BC2-4AHNWMTAzSAvOIAsTAlHAz2IQArAoA7(C2-25A)C2-28AD26AD56-D3A20-3AD7(3AB20-BAC-)3A5(B20-B6A)4(B20-BC2-3A)B20-BC2-4AWAvPHOAqZQAnXJAhVZRGI2GAcA7(C2-25A)C2-28AD26AD56-D26AD4A13(20B8A)3(20BAC2-4A)20BA7(C2-25A)C2-56AD26AD56-D26AD417A8(C2-25A)C2-84AD26AD56-D26AD728AD26AD56-
