model
size = 27 28 23, scale = 0.05, origin = -y
material deform = 1, fade = true, lighting = smooth, roughness = 0.3, metalness = 0.6
  colors = A:#C6C B:#C36 C:#008 D:#009 E:#35008B
voxels
376-B25-3B25-B646-6(B2A24-)B2A537-2(B2A24-)7(BA25-)B2A24-B2A456-B2A24-2(2B25-)2B4(24-3A)24-2AB2(25-2B)25-BA25-B2A402-B2A24-2B25-4(2B24-A)2(BA24-A)3(2B24-A)2(2B25-)BA25-B2A348-2(B2A24-)2(2B24-A)BC24-A2B24-3B24-2BA3(24-3B)3(24-A2B)25-2B25-BA25-B2A144-8A17-2A8-3A12-2A13-2A9-A17-A7-A19-2A4-A21-3A-A22-2BA-A22-BA-2A21-A2B-2A21-A-C-2A21-A2B2(-2A21-3B)-2A22-DA-2A21-3B-2A22-DB-2A21-3B-2A21-2B2(C-2A21-AB)C2-A21-A2B2-A22-BA3-A21-B2A3-A19-AB2A4-A17-A9-2A13-2A12-2A8-3A16-8A19-8B17-2B8-3B12-2B13-2B9-B17-B7-B19-2B4-B21-2BA-B22-B2A-B22-2(BA-2B21-A)-B-2B2(21-3B-BA)21-2BA-B22-2BA-BA21-3B-B22-3B-BA21-3B-2B21-2BC-2B21-3B-2B2(21-A2B2-B)22-BA3-B21-B2A3-B19-4A4-B17-B9-2B13-2B12-2B8-3B16-8B19-8A17-AB8-B2A12-AB13-AB9-B17-A7-A19-BA4-B21-2BA-A22-2BA-B21-ABA-BA21-AB2(A-2A21-2B)A-AB21-2BA-2A2(21-2BA-BA)21-2BA2(-2A21-3B)-AB21-3B-2A21-3B-BA21-3B2-B21-ABA2-A21-ABA3-B21-B2A3-A19-AB2A4-B17-A9-AB13-AB12-AB8-ABA16-AB4ABA19-8A17-AB8-B2A12-AB13-AB9-B17-A7-A19-BA4-B21-2BA-A22-B2A-B21-ABA-BA21-AB2(A-2A21-2B)A-2A22-DA-AB21-2BA-BA22-DA-BA21-2BA-2A22-DA-AB21-3B-2A22-DB-2A21-3B-BA21-2BA2-B21-ABA2-A21-AEA3-B21-B2A3-A19-AB2A4-B17-A9-AB13-AB12-AB8-ABA16-AB4ABA19-8B17-2B8-3B12-2B13-2B9-B17-B7-B19-2B4-B21-2BA-B22-B2A-B2(21-ABA-2B)2(21-3B-2B)21-3B3(-BA21-2BA-2B21-2BA)2(-2B21-2BA)2-B21-AEB2-B21-ABA3-B21-B2A3-B19-4A4-B17-B9-2B13-2B12-2B8-3B16-8B19-8A17-2A8-3A12-2A13-2A9-A17-A7-A19-2A4-A21-3A-A22-B2A-A2(21-2(A-)2A)21-3B-2A21-2BC-2A21-3B2(-2A21-2BA)-AB21-2BA-2A21-B2A3(-2A21-2BA)-2A21-3B2-A21-2AB2-A21-3A3-A21-B-A3-A19-AB2A4-A17-A9-2A13-2A12-2A8-3A16-8A19-8A17-2A8-3A12-2A13-2A9-A17-A7-A19-2A4-A21-3A-A22-2BA-A2(21-3A-2A)3(21-BAB-2A)21-B2A-2A21-B2A-AB21-BEA5(-2A21-B2A)2-A21-AEB2-A21-AEA3-A21-B2A3-A19-AB2A4-A17-A9-2A13-2A12-2A8-3A16-8A19-8B17-2B8-3B12-2B13-2B9-B17-B7-B19-2B4-B21-2BA-B22-B2A-B2(21-ABA-2B)2(21-2BA-2B)2(22-DA-BA21-2BA-2B)22-DA-BA21-3B-2B22-DB-2B21-3B-2B21-2BA2-B21-ABA2-B21-AEA3-B21-B2A3-B19-4A4-B17-B9-2B13-2B12-2B8-3B16-8B19-8A17-AB8-B2A12-AB13-AB9-B17-A7-A19-BA4-B21-2BA-A22-2BA-B21-ABA-BA21-AB3(A-2A21-2B)A-AB2(21-2BA-BA)21-2BA-2A21-3B-AB2(21-3B-2A)21-3B-BA21-3B2-B21-ABA2-A21-ABA3-B21-B2A3-A19-AB2A4-B17-A9-AB13-AB12-AB8-ABA16-AB4ABA19-8A17-AB8-B2A12-AB13-AB9-B17-A7-A19-BA4-B21-2BA-A22-B2A-B22-BA-BA21-ABA-2A21-A2B-2A21-3B-AB21-3B-2A2(21-2BA-BA)2(21-3B-2A)21-3B-AB21-3B-2A21-3B-BA21-A2B2-B21-A2B2-A22-BA3-B21-B2A3-A19-AB2A4-B17-A9-AB13-AB12-AB8-ABA16-AB4ABA19-8B17-2B8-3B12-2B13-2B9-B17-B7-B19-2B4-B21-2(2BA-B22-)BA3(-2B21-A2B)-BA21-2BC-BA21-3B-B23-DA-BA21-3B-B23-DB-BA21-3B-2B21-2B2(C-2B21-AB)C2-B21-A2B2-B22-BA3-B21-B2A3-B19-4A4-B17-B9-2B13-2B12-2B8-3B16-8B19-8A17-2A8-3A12-2A13-2A9-A17-A7-A19-2A4-A21-2A2-A22-B2A-A22-B4A22-2(2B-2A21-A)BC-2A21-A2B-2A21-3B-2A21-2BA3(-2A21-3B)-2A21-A2B-2A21-ABC-2A21-A2(2B2-A22-)B2A2-A21-B2A3-A19-ABA5-A17-A9-2A13-2A12-2A8-3A16-8A223-B2A24-2BA24-4(2B24-A)2(BA24-A)3(2B24-A)2(2B25-)B2A24-B2A402-B2A24-2BA24-2B25-2B4(24-3A)24-2AB2(25-2B)25-B2A24-B2A456-B2A24-9(BA25-)B2A511-7(2A24-B)2A25-2A592-2B25-2B52-2B25-2B297-
