model
size = 10 26 32, scale = 0.05, origin = -y
material deform = 1, fade = true, lighting = smooth, roughness = 0.3, metalness = 0.6
  colors = A:#FF3
voxels
5-2A227-2A8-3A7-2A37-3A7-4A2(5-5A)5-2(6A4-)5A5-5A6-4A166-3A6-2(5A5-)A7(3-2A)3-3A2-2A3-7A4-6A4-5A7-A129-2A7-3A7-4A5-2A-2A5-A2(3-2A)4-2(A3-A5-)2A2-A6-A2-A5-2A2-2A4-2A2-3A-3A4-6A4-5A7-A118-2(3A7-)4A5-A2-3A3-2A4-A3-A5-A3-A6-A-2A6-2(A-A7-)A-2A6-A2-A5-2A2-3A2-2A4-6A4-5A116-3A7-A-2A5-2A2-2(A5-A3-)2A3-2A4-2A-2A6-4(A-A7-)A-2A6-A2-A5-2A2-3A2-2A4-6A5-4A106-3A7-4A5-A-3A5-A3-2A4-A3-2A3-A5-A2-2A5-2A-A7-A-A7-3A2(7-A-A)7-A-2A6-A2-A5-2A2-7A4-6A5-3A106-2(5A5-)4A-A3-2A4-A3-A5-2A2-A5-2A-2A5-2A-A8-2A7-3A7-A-A8-2A7-A-2A6-A2-2A3-3A2-7A4-5A115-5A5-6A3-7A3-2A4-2A2-2A4-2A-2A5-5A5-4A8-2A7-A-A2(8-2A)7-A-2A6-A2(2-3A)3-6A5-4A115-6A3-7A3-3A2-2A3-2A4-2A-2A6-4A6-3A8-2A7-3A7-A-A8-2A7-4A6-A2-A5-2A2-7A4-5A107-A8-3A7-5A4-2A2-2A3-2A4-A2-3A4-2A-2A5-4A5(8-2A)7-A2-A6-A2(2-3A)3-6A5-4A97-A8-2A7-2A2-A5-2A2-2A4-A3(3-2A)2-3A4-4A7-3A3(8-2A)7-A-A7-A2-A6-A2-A5-2A2-7A4-5A6-3A106-A9-A3-A5-A3-A4-3(2A3-)3A-3A3-7A4-4A2(8-2A)7-2A-3(A6-A2-)2A4-A4-6A5-4A115-2(A3-A5-)2(A4-)2A2-2A3-8A-4A-8A4-4A8-2A8-3A3(6-A2-A)5-2A3-2A2-2A4-6A5-4A125-A3-A2(6-4A)3-9A-4A2-7A4-4A8-2A7-4A2(6-A2-A)5-2A2-2A4-A4-6A5-4A7-2A120-A6-2A-2(A7-)5A3-9A-4A2-3A-3A4-2A-A7-3A7-A2-A6-A2-A5-2A2-A5-A4-A3-2A4-5A6-4A147-2A7-4A4-8A2-3A-4A-3A4-2A-A7-2(A2-A6-)A2-A5-3(A4-)6A5-4A157-A8-4A4-6A4-8A2-2A4-2A2(2-A6-A)2-A5-2A3-2(A4-)2A2-2A5-4A7-2A167-4A5-5A4-8A2-2A4-2A2-A6-A2-A5-2A3-4(A4-)5A6-4A176-4A5-5A4-7A3-2A3-3A2-A5-2A3-4(A4-)6A5-4A186-4A5-6A4-6A3-A-A2-2A4(4-A)4-6A5-4A7-2A187-4A5-2(6A4-)2A2-2A2(4-A)4-2A2-2A4-5A6-4A196-4A5-6A4-2A2-2A4(4-A)4-6A5-4A206-4A5-6A4-2A2-2A2(4-A)4-6A5-4A207-2A6-6A4-2A2-2A2(4-A)4-6A5-4A7-2A208-2A6-6A4-A3-2A4-2A2-2A5-4A6-4A207-2A7-4A5-3A-2A4-2A2-2A5-4A6-4A217-2A7-4A6-A2-A2(6-4A)217-2A7-3(4A6-)4A226-3A7-4A6-A2-A6-4A7-2A218-2A7-4A6-A-2A6-4A7-2A228-3A6-4A7-3A7-2A4-
