model
size = 28 28 19, scale = 0.05, origin = -y
material deform = 1, fade = true, lighting = smooth, roughness = 0.3, metalness = 0.6
  colors = A:#030 B:#000100 C:#004044 D:#001A0D E:#009 F:#35008B
voxels
333-6(3A25-)3A557-2(3A25-)3A24-BAD3(25-BAC)25-BAD26-2(3A25-)3A473-3A25-3A24-B2A25-BAD5(25-BAC)25-BAD25-B2A26-3A25-3A417-3A25-AD25-B2A25-BAD7(25-BAC)25-BAD25-B2A26-AD26-3A178-8A18-2A8-3A2(13-2A)10-A17-A8-A19-A6-A21-A4-A22-3A-A23-5A22-B2A-2A22-B-A-2A22-BAD2(-2A22-BAC)-2A23-EB-2A22-BAB-2A23-EB2(-2A22-BAC)-2A22-BAD-2A22-B2A2-A22-B2A3-A22-3A3-A21-3A4-A19-A8-A17-A10-2(2A13-)2A8-3A17-8A20-8B18-2B8-3B2(13-2B)10-B17-B8-B19-B6-B21-B4-B22-3A-B23-AD-2B22-BAD-BA22-B-D-2B22-B2A2(-2B22-BAC-BA22-BAC)2(-2B22-BAC)-BA22-BAC2(-2B22-BAD)2-B22-BAD3-B22-AD4-B21-3A4-B19-B8-B17-B10-2(2B13-)2B8-3B17-8B20-8A18-2A8-3A2(13-2A)10-A17-A8-A19-A6-A21-3A2-A22-3A-A22-BAC-2A22-BAC-AB22-BAC2(-2A22-BAD)2(-AB22-BAC-2A22-BAC)-2A22-BAC-AB22-BAD-2A22-B2A-2A22-BAC2-A22-BAC3-A21-BAC4-A21-3A4-A19-4A5-A17-A10-2(2A13-)2A8-3A17-8A20-4(BA)18-BA8-ABA13-AB13-2B10-B17-A8-B19-B6-B21-3A2-A22-AC2-B22-BAC-BA22-BAC-2A22-BAC-BA22-BAC-B24-ED-2A22-BAD-B24-EC-2A22-BAC-B24-EC-BA22-BAD-2A23-EA2(-2A22-BAC)2-A22-BAC3-A21-BFC4-A21-AC5-A19-4A5-A17-B10-2B13-2A13-BA8-BAB17-4(BA)20-4(AB)18-AB8-BAB13-BA13-2A10-A17-B8-A19-A6-A21-3A2-B22-AC2-A22-BAC-2A22-BAC-BA22-BAB2(-2A22-BAC)-BA22-BAD-2A22-B2A-BA2(22-B2A-2A)22-B2A-BA22-BAC-2A22-BAC-2B22-BAB2-B22-BFC3-B21-BAC4-B21-AC5-A19-4A5-B17-A10-2A2(13-AB)8-ABA17-4(AB)20-4(BA)18-BA8-ABA13-AB13-2B10-B17-A8-B19-B6-B21-3A2-A22-AC2-B22-B-C-2B22-2(B-)3(2B22-BAC-)2B22-BAD-2B22-B2A-2B22-BD2-2(2B22-B2A-)2(2B22-BAC-)2A22-BAC2-A22-BAB3-A21-BAC4-A21-AC5-B19-4A5-A17-B10-AB13-BA13-2A8-BAB17-4(BA)20-4(AB)18-AB8-BAB13-BA13-2A10-A17-B8-A19-A6-A21-3A2-B22-AC2-A22-BAC-2A22-BAC-BA22-BAB2(-2A22-BAC)-BA22-BAD-2A22-B2A-BA22-BFA2(-2A22-B2A)-BA22-BAC-2A22-BAC-2B22-BAB2-B22-BFC3-B21-BFC4-B21-AC5-A19-4A5-B17-A10-2A2(13-AB)8-ABA17-4(AB)20-4(BA)18-BA8-ABA13-AB13-2B10-B17-A8-B19-B6-B21-3A2-A22-AC2-B22-BAC-BA22-BAC-2A22-BAC-BA22-BAC-B24-ED-2A22-BAD-B24-EC-2A22-BAC-B24-EC-BA22-BAD-2A23-EA2(-2A22-BAC)2-A22-BAC3-A21-BFC4-A21-AC5-A19-4A5-A17-B10-2B13-2A13-BA8-BAB17-4(BA)20-8A18-2A8-3A2(13-2A)10-A17-A8-A19-A6-A21-3A2-A22-3A-A22-BAC-2A22-BAC-AB22-BAC2(-2A22-BAD)2(-AB22-BAC-2A22-BAC)-2A22-BAC-AB22-BAD-2A22-B2A-2A22-BAC2-A22-BAC3-A21-BAC4-A21-3A4-A19-4A5-A17-A10-2(2A13-)2A8-3A17-8A20-8B18-2B8-3B2(13-2B)10-B17-B8-B19-B6-B21-B4-B22-3A-B23-AD-2B22-BAD-BA22-BAD-2B22-B2A2(-2B22-BAC-BA22-BAC)2(-2B22-BAC)-BA22-BAC2(-2B22-BAD)2-B22-BAD3-B22-AD4-B21-3A4-B19-B8-B17-B10-2(2B13-)2B8-3B17-8B20-8A18-2A8-3A2(13-2A)10-A17-A8-A19-A6-A21-A4-A22-3A-A23-5A2(22-B2A-2A)22-BAD2(-2A22-BAC)-2A23-EB-2A22-BAB-2A23-EB2(-2A22-BAC)-2A22-BAD-2A22-B2A2-A22-B2A3-A22-3A3-A21-3A4-A19-A8-A17-A10-2(2A13-)2A8-3A17-8A231-3A25-AD25-B2A25-BAD7(25-BAC)25-BAD25-B2A26-AD26-3A417-3A25-3A24-B2A25-BAD5(25-BAC)25-BAD25-B2A26-3A25-3A473-2(3A25-)3A24-BAD3(25-BAC)25-B2A26-2(3A25-)3A557-6(3A25-)3A280-
