model
size = 13 32 28, scale = 0.05, origin = -y
material deform = 1, fade = true, lighting = smooth, roughness = 0.3, metalness = 0.6
  colors = A:#111 B:#03F C:#222 D:#001 E:#00A F:#00D G:#00E H:#002 I:#005 J:#03C K:#006 L:#00C M:#008 N:#00B O:#007 P:#039 Q:#009 R:#036 S:#00F
voxels
181-A2(12-C)25-3(A12-C12-)C3(12-A)38-A2(12-C)168-A2(12-C)25-3(A12-C12-)C3(12-A)38-A2(12-C)12-A167-2(C12-)A12-J12-P3(12-A)12-M12-P3(12-A)12-C2(12-A)2(12-C12-A)115-2(A12-)C25-A12-E4(12-B)12-C12-E2(12-B)12-N12-K2(12-B)12-C3(12-A)12-C12-A89-A3(12-C)2(12-A)12-C12-Q4(12-B)12-A12-L2(12-B)12-J12-K2(12-B)12-H3(12-A)12-C12-A63-3(A12-)2(C12-)A12-H12-E12-C12-M4(12-B)12-R12-L2(12-B)12-J12-K12-B12-F12-D3(12-A)12-C37-2(A12-)2(C2(12-A)12-)K12-M2(12-I)12-H4(12-B)2(12-J)2(12-B)12-J12-E12-P12-O12-C3(12-A)50-A3(12-C)12-A12-I12-H12-G12-A12-F12-A12-E12-H4(12-B)12-J12-Q2(12-B)12-J2(12-A)12-L12-E12-C12-A50-2(A12-C12-)2(A12-)2(F12-)A12-H12-L12-Q12-E12-D5(12-B)12-I2(12-B)12-I12-M12-N12-F12-K2(12-A)50-D2(12-C)6(12-A)12-M12-A12-F2(12-A)12-F4(12-B)12-A12-F12-A12-Q12-N12-L12-E2(12-A)76-2(A12-C12-)C12-O2(12-E)12-A12-S2(12-G)12-P12-A4(12-B)2(12-A)2(12-N)12-F12-H128-3(A12-)K12-O12-I12-A12-H3(12-G)12-B12-A12-G3(12-B)12-A12-E12-N12-F12-H167-D12-O2(12-F)12-G12-L12-A2(12-G)12-B12-O12-M3(12-B)12-A12-E12-M12-D219-D3(12-I)12-A12-D12-L12-G12-A12-E12-B12-K2(272-11(D12-)D)272-D3(12-I)12-A12-D12-L12-G12-A12-E12-B12-K234-D12-O2(12-F)12-G12-L12-A2(12-G)12-B12-O12-M3(12-B)12-A12-E12-M12-D156-3(A12-)K12-O12-I12-A12-H3(12-G)12-B12-A12-G3(12-B)12-A12-E12-N12-F12-H130-2(A12-C12-)C12-O2(12-E)12-A12-S2(12-G)12-P12-A4(12-B)2(12-A)2(12-N)12-F12-H104-D2(12-C)6(12-A)12-M12-A12-F2(12-A)12-F4(12-B)12-A12-F12-A12-Q12-N12-L12-E2(12-A)65-2(A12-C12-)2(A12-)2(F12-)A12-H12-L12-Q12-E12-D5(12-B)12-I2(12-B)12-I12-M12-N12-F12-K2(12-A)65-A3(12-C)12-A12-I12-H12-G12-A12-F12-A12-E12-H4(12-B)12-J12-Q2(12-B)12-J2(12-A)12-L12-E12-C12-A65-2(A12-)2(C2(12-A)12-)K12-M2(12-I)12-H4(12-B)2(12-J)2(12-B)12-J12-E12-P12-O12-C3(12-A)91-3(A12-)2(C12-)A12-H12-E12-C12-M4(12-B)12-R12-L2(12-B)12-J12-K12-B12-F12-D3(12-A)12-C104-A3(12-C)2(12-A)12-C12-Q4(12-B)12-A12-L2(12-B)12-J12-K2(12-B)12-H3(12-A)12-C12-A117-2(A12-)C25-A12-E4(12-B)12-C12-E2(12-B)12-N12-K2(12-B)12-C3(12-A)12-C12-A169-2(C12-)A12-J12-P3(12-A)12-M12-P3(12-A)12-C2(12-A)2(12-C12-A)-
