model
size = 18 22 25, scale = 0.05, origin = -y
material deform = 1, fade = true, lighting = smooth, roughness = 0.3, metalness = 0.6
  colors = A:#15B90D B:#19DC06 C:#010 D:#C0C E:#119613 F:#393 G:#012400 H:#CF3 I:#050 J:#034800 K:#1DFF00 L:#000 M:#6C3 N:#060808 O:#CC9 P:#6F3 Q:#996 R:#303 S:#909 T:#F5B200 U:#101616 V:#070 W:#060 X:#040 Y:#3DDA00 Z:#4A0525
voxels
173-Z394-3D393-3D15-3D263-3A109-3D15-3D263-2A17-B71-F17-A2-SDS16-D265-M17-B17-X35-E17-A17-3A-D12-4A-D12-4F15-3F15-A53-2C15-JGJ2(15-3G)16-U107-M2(17-B)16-O4A12-2QAB3A11-7A10-2B4A2B10-2B4A3B9-3B3A2B11-2BA4B11-6E14-2C2(15-CAC)15-J2(AG15-G)2C16-2C88-M17-B15-2BA3B11-2O6A9-2L8A8-2L8AB7-11A7-B9AB7-B8A2B7-2B7AB9-B6A2B10-7A12-C2AC14-CAC15-JAC15-3G62-B16-B44-F15-2BA3B11-B6A2B8-B8AB7-V10AB6-W10AB6-3(B11AB5-)B10AB7-B9AB7-2B7AB10-7A13-CAC14-3N97-B17-B25-4E11-3B4A2B9-K8AK7-K10AK6-B11A4(B4-B12A)2(B5-B11A)B6-B9AB8-B7AB10-2IA4I13-R116-B16-B5-HB7F8-H2-7AB6-2H10AB6-H11AB4-P12AB4-P4(13AB3-B)12AB4-B12AB5-B10AB7-B8A2B8-8A153-H2B6A4-B3-H-9AB5-H-11AB5-T11AB4-P13AB3-R13A3(B2-B14A)B3-B13AB3-B14A4-12AB5-2B9AB8-9A152-H2B6A8-H-8A5B2-H-11AB5-T11AB4-Q13A2(B2-Y14A)2(B2-B14A)B3-B13AB3-15A3-13AB5-11AB7-10E152-H3B5A8-H-8A2B5-H-10A2B5-T11AB4-P13AB3-R13A3(B2-B14A)B3-B13AB3-B12ABA4-13A5-2B9AB8-9B152-HB7F8-H2-7AB6-2H10AB6-H11AB4-P12AB4-P4(13AB3-B)12AB4-B12AB5-B10AB7-B8A2B8-8A156-4E11-3B4A2B9-K8AK7-K10AK6-B11A4(B4-B12A)2(B5-B11A)B6-B9AB8-B7AB10-2IA4I13-R143-F15-2BA3B11-B6A2B8-B8AB7-V10AB6-W10AB6-3(B11AB5-)B10AB7-B9AB7-2B7AB10-7A13-CAC14-3N142-M17-B15-2BA3B11-2O6A9-2L8A8-2L8AB7-11A7-B9AB7-B8A2B7-2B7AB9-B6A2B10-7A12-C2AC14-CAC15-JAC15-3G124-M2(17-B)16-O4A12-2QAB3A11-7A10-2B4A2B10-2B4A3B9-3B3A2B11-2BA4B11-6E14-2C2(15-CAC)15-J2(AG15-G)2C16-2C70-M17-B17-X35-E17-A17-3A-D12-4A-D12-4F15-3F15-A53-2C15-JGJ2(15-3G)16-U88-2A17-B71-F17-A2-SDS16-D264-3A109-2(3D15-3D375-)3D394-Z222-
