model
size = 32 27 30, scale = 0.05, origin = -y
material deform = 1, fade = true, lighting = smooth, roughness = 0.3, metalness = 0.6
  colors = A:#E00 B:#60C C:#500 D:#111 E:#AAA F:#002 G:#393 H:#222 I:#FF0
voxels
107-4G27-4G28-4G29-3G286-15A17-15A18-4A5-4A395-4G27-4G28-4G29-3G733-4G2(26-6G)2-2D22-6G-3D23-5G2-4D23-2G4-2D661-5G27-5G26-6G2D24-6G6D22-4G5D-D22-3G2-5D22-3G5-3D30-D627-2G30-2G29-2G3-2GD-2D21-2(2G3-)3D23-2G2-6D22-2G4-5D21-G6-4D29-D-D625-3G29-3G28-2G30-2G10-3D29-3D21-G7-4D20-G7-5D28-4D186-17A14-9A-8A15-6A5-6A356-3G29-3G106-2D30-4D28-4D29-3D30-3D152-20A11-3A4-14A11-9A3-9A12-6A3-C2-7A498-2(2D30-)3D29-3D150-23A8-2A9-4C9A8-3A-6A5C9A9-9A5C8A12-6A5-C-6A14-3A2-A5-6A29-A437-3D29-3D30-2D149-11A3C11A7-2A10-3C10A7-2A-6A7C9A7-9A7C8A11-6AC2-4C7A12-7A3-2C6A20-A3-CA2-3A405-D25-3(2F4-2D24-)2F5-D24-2F30-2F31-F2-11B14-11A3C11A6-2A3-6A5C10A7-A2-6A7C9A7-2A-6A7C8A10-7A7C7A12-7A5C7A14-7A3C7A307-9B22-11B21-11B17-2F3-9B18-2F3-2F4D2F18-EFE3-F2-3D-F18-EFE3-2F2D3-F18-EFE3-F-2D3-F17-2EFE3-8F18-EFE30-2F-13B12-12A3C11A6-2A2-7A5C10A6-2A2-6A7C9A7-2A-6A7C9A9-7A7C7A12-7A5C8A12-8A3C8A15-7A-7A18-4A-4A216-11B20-13B18-2(14B16-2F)-13B15-EFE-13B14-2EFE2-12B13-2(H2EFE2-4B3D4B14-)H2EFE2-12B14-2EFE-13B15-EF17B10-26A6-A3-7A5C10A6-2A2-7A5C10A7-2A-7A5C10A9-8A5C8A12-7A5C8A12-19A14-17A17-13A19-12A24-5A152-12B18-14B18-15B15-2F15B14-EFE14B14-3(2EFE-13B13-H)2EFE-13B13-3EFE-13B13-H2EFE14B14-2EF17B10-26A6-A3-2F20A6-2A2-8A3C11A7-2A-8A3C11A9-9A3C9A12-20A12-19A14-17A16-14A19-13A20-10A24-6A119-2B8D3B18-15B16-16B15-F16B13-2EFE14B14-2EFE14B13-H2EFE-13B13-3E2(FE-13B13-H2E)2(FE14B13-H2E)18B10-26A6-A2-C2F20A6-2A4-20A7-2A-22A9-A-19A12-20A12-19A14-17A16-14A19-13A20-11A22-8A25-2A34-I27-A3-A24-2BD6ID3B18-15B16-16B15-F16B14-EFE15B13-2(2EFE14B13-H)2EFE-13B13-3E2(FE14B13-H2E)FE15B13-2E18B11-3C22A7-3C2F20A6-2A4-20A7-24A10-17A2(3C13-16A)3C14-17A16-15A18-13A20-2C10A20-2C8A24-2A32-A2-I28-I2-A23-2BD6AD3B18-15B16-16B15-F16B15-2F15B14-EFE14B14-3(2EFE14B13-H)2EFE14B14-2EFE15B14-E18B10-5C21A6-2C2-CF20A7-4C21A8-17A5CA10-16A5C11-16A2(4C13-15A)3C16-15A18-4C9A19-4C9A20-3C8A23-C5A58-A3-I24-2BD6ID3B18-15B2(16-16B)15-2F15B15-2F14B15-E3(FE14B14-2E)FE14B15-EFE15B15-F17B10-6C20A6-2C4-20A7-4C15A3C3A8-2C15A5C11-15A6C11-15A5C13-14A4C14-15A3C16-A3C10AC17-5C9A18-6C8A20-4C7A24-C4A61-I25-2BD6AD3B18-15B2(16-16B)17-15B15-5(2F14B16-)2F15B15-F17B10-6C20A6-3C3-20A7-4C15A3C3A8-2C15A5C11-15A6C11-15A5C13-14A4C14-15A3C15-2A3C10AC16-A5C9A18-6C8A19-5C7A24-C4A31-A26-A3-AI23-2BD6ID3B18-15B2(16-16B)15-2F15B15-2F14B15-E3(FE14B14-2E)FE14B15-EFE15B15-F17B10-6C20A6-3C3-20A7-4C15A3C3A8-2C15A5C11-15A6C11-15A5C13-14A4C14-15A3C15-2A3C10AC16-A5C9A17-7C8A18-6C7A24-C4A27-A31-I27-2BD6AD3B18-15B16-16B15-F16B15-2F15B14-EFE14B14-3(2EFE14B13-H)2EFE14B14-2EFE15B14-E18B10-5C21A6-2C2-CF20A7-4C21A8-17A5CA10-16A5C11-16A2(4C13-15A)3C15-16A16-A5C9A18-5C9A19-4C8A25-3A88-2B8D3B18-15B16-16B15-F16B14-EFE15B13-2(2EFE14B13-H)2EFE-13B13-EHEFE-13B13-H2EFE14B13-H2EFE15B13-2E18B11-3C22A7-3C2F20A6-26A7-25A9-17A3CA11-17A3C13-16A3C14-17A16-15A17-14A18-A3C10A20-2C9A116-13B18-14B18-15B15-2F15B13-2EFE14B14-2EFE14B13-H2EFE-13B13-3E3(FE-13B13-H2E)FE14B13-H2E18B11-4AE20A2(6-26A)7-25A8-22A12-20A12-19A14-17A16-15A18-13A20-12A21-9A118-11B19-14B18-14B16-2F14B15-EFE10B2D2B14-2EFE-5BD3B2D2B13-H2EFE-6B2DB2D2B13-H2EFE2-BF4B3DF2B13-H2EFE-2BF7BF2B13-3EFE-13B13-H2EFE-13B14-2E18B10-2(26A6-)26A7-25A7-23A12-20A12-19A14-17A16-14A19-13A20-11A23-7A151-11B21-2(12B16-2F2-)B6F2DF17-EFE2-BF3-4DF16-2EFE3-F5-2D2(F15-H2EFE3-F7-)F15-H2EFE3-9F16-2EFE29-EF16B11-2(26A6-)26A7-25A8-22A12-20A12-19A14-17A17-13A20-10A247-9B23-6B2DB18-2F9-2D19-2F2(9-2D18-EFE)29-EFE28-2EFE29-EFE30-2F15B11-26A6-A-24A6-26A7-25A9-21A12-20A12-19A14-17A18-11A141-3G29-3G106-2D30-4D28-4D19-2F8-3D19-2F9-2D19-3(2F30-)2F31-F-13B12-26A6-26A2(7-25A)9-21A12-20A12-8A3C7A16-15A172-3G29-3G28-2G30-2G10-3D29-3D21-G7-4D20-G7-5D28-4D185-7B16-2(25A7-)25A8-23A10-7A6C8A12-6A6C7A14-6AC3-6A205-2G30-2G29-2G3-2GD-2D21-2(2G3-)3D23-2G2-6D22-2G4-5D21-G6-4D29-D-D210-2(23A9-)23A10-2A4-A6C8A12-5A7-C5A269-5G27-5G26-6G2D24-6G6D22-4G5D-D22-3G2-5D22-3G5-3D30-D212-2(21A11-)21A12-6A7C7A333-4G2(26-6G)2-2D22-6G-3D23-5G2-4D23-2G4-2D246-19A13-20A13-6A5C8A13-5AC5-C5A292-
