model
size = 23 23 30, scale = 0.05, origin = -y
material deform = 1, fade = true, lighting = smooth, roughness = 0.3, metalness = 0.6
  colors = A:#111 B:#000 C:#555 D:#222
voxels
241-C22-C20-2C530-2(3A20-)5(2A21-)2A89-A22-A10(20-3A)17-2(6A2-4A11-)12A3(13-10A)2(13-4A2B4A)13-9B2(15-8B)17-A22-A10(20-3A)17-2(6A2-4A11-)12A3(13-10A)2(13-4A2B4A)13-9B2(15-8B)12-11(9A14-)8A15-3(8A4-2A9-)2(8A3-3A9-)8A2(3-A11-3A5B)3-A11-8B-3B2(11-12B)11-11(11A12-)11A11-2(12A-3A7-)4(12A-2A8-)2(4A9B2A8-)2(15B8-)15B9-11(11A12-)11A11-2(12A-3A7-)4(12A-2A8-)2(4A9B2A8-)3(15B8-)8(13A10-)13A3(8-15A)6(2-A5-15A)2-2(A5-6A11B)A3(5-18B)2(5-9(15A8-)17A6-17A5-3(16A2-A4-)4(19A4-)2(7A11BA4-)2(19B4-)19B)7-2(13A10-)13A3(8-15A)8-3(17A6-)18A5-18A3(4-19A)3(2-21A)4-19A2(4-9A9BA)3(4-19B)2(7-9(15A8-)16A7-16A5-2(18A2-2A-)18A4(2-21A)2(4-9A9BA)4-19B2(4-D18B))7-2(9A14-)6A17-10A13-10A11-12A10-2(A2-10A2-A7-)A2-3A-9A2(5-2A-15A)5-3A2-2(16A2-2A3-)16A4(2-2A-18A)2(2-2D9A9BA)3(2-2D19B)2(53-A22-4A19-4A16-6A17-13A10-13A8-3(14A9-)18A5-2(21A2-)2A3-16A3(2-2A-18A)2(2-2D-8A9BA)2-21B2(2-2D19B))7-2(3A3-A16-)7A2(16-4A2-A)14-5A17-2(6A-3A13-)12A2(9-14A)9-18A5-3(21A2-)3(2A-18A2-)2(2D-8A9BA2-)21B2(2-2D19B)2(7-2(9A14-)6(10A13-)13A7-18A5-18A3-20A3-2(2A-18A2-)2A3-16A3(2-2A-18A)2(2-2D-8A9BA)3(2-2D19B))7-2(12A11-)4(13A10-)3(15A8-)16A7-16A5-3(18A2-2A-)89A2-9A9BA4-9A9BA2-21B2(4-D18B)2(5-6(15A8-)3(17A6-)3(15A2-A5-)18A5-18A2-69A2-21A2-2(9A9BA4-)2(19B4-)19B)5-8(15A8-)17A6-3(15A2-A5-)2(18A5-)20A3(2-21A)2(2-9A9BA2C)2-2(19B4-)19B2(5-2(14A9-)7(15A8-)2(17A6-)3(15A2-A5-)15A2-A2(4-C18A)2-2C19A4C9A9BA2-2C9A9BA3(5-18B))7-8(12A11-)2(13A10-)13A11-11AC2(2A6-14A-)2A5-C14A-2A3(C7-15A)2(8-6A4B5A)3(8-15B)9-11(9A14-)9A3C10-10A3-2AC7-10A3-2AC5-2C10A3-2AC7-10A3-2A8-10A3-2A9-9A2(3-2A9-5AB3A)3-2A9-3(9B2-B11-)11(9A14-)9A3C10-10A3-2AC7-10A3-2AC5-2C10A3-2AC7-10A3-2A8-10A3-2A9-9A2(3-2A9-5AB3A)3-2A9-2(9B2-B11-)9B2-B14-9(3A20-)3A3C17-3A3C14-3C3A16-C3-3A6-2C8-C3-3A6-2C12-3A20-3(3A2-A17-)2(3A20-)3B2-B17-3B20-3B229-C22-C20-2C265-
