model
size = 32, scale = 0.05, origin = -y
material deform = 1, fade = true, lighting = smooth, roughness = 0.3, metalness = 0.6
  colors = A:#555 B:#000008 C:#888 D:#444
voxels
47-4(2B30-)2B217-12A20-12A148-12A20-12A726-4(8A56-)8A25-6A27-4A509-2A60-6A57-8A56-8A21-7(14A18-)14A19-12A20-12A21-10C23-8C26-4C284-4B27-6B26-6B23-6(12B20-)12B21-10A18-6(18A14-)18A15-2(16A16-)16A17-14C18-14C19-12C22-8C27-2A311-6(4B8-4B16-)4B8-4B18-2A8-2A16-8(20A12-)20A13-18A14-18C15-16C16-16C17-14C20-10A24-6A275-13(4B12-)4B14-2A12-2A13-9(22A10-)22A11-20C12-20C13-18C15-4C10A2C17-14A19-12A22-8A241-6(3B16-3B10-)3B16-3B11-2A16-2A10-9(24A8-)24A9-22C10-22C11-20C13-5C10A3C14-18A16-14A19-12A22-8A208-6(3B18-3B8-)3B18-3B9-2A18-2A2(8-9A)8(6-9A8-9A)7-2(8A8-)3(8C8-)8C9-7C8-7C11-6C8-2A4C12-6A8-6A13-18A16-14A19-12A23-6A176-6(3B20-3B6-)3B20-3B7-2A20-2A6-6(8A12-8A4-)8A12-8A5-3(7A12-7A6-)7C12-7C7-6C12-6C8-6C12-6C9-5C12-5C10-5A12-5A11-20A13-18A16-14A20-10A26-2A146-6(2B22-2B6-)2B22-2B7-A22-A6-9(7A14-7A4-)7A14-7A3(5-6C14-7C)6-5C14-6C8-4A14-4A11-20A13-18A15-16A17-14A21-8A142-6(3B22-3B4-)3B22-3B5-2A22-2A4-7(7A16-7A2-)7A16-7A3-2(6A16-6A4-)6C16-6C4-6C2(16-6C5-5C)16-6C6-4A16-4A9-22A11-20A13-18A15-16A18-12A24-4A112-6(2B24-2B4-)2B24-2B5-A24-A4-9(6A18-6A2-)6A18-6A3-5C18-4CB2(4-5C18-5C)5-C3A18-5C6-3A18-3A8-24A9-22A11-20A14-16A17-14A21-8A110-6(2B24-2B4-)2B24-2B5-A24-A4-9(5A20-5A2-)5A20-5A3-B3C20-3CB4-4C20-3CB4-B3C20-3CB5-C2A20-3CB5-3A20-3A7-24A9-22A11-20A13-18A16-14A20-10A108-7(2B26-2B2-)AB26-2A-6A7(20-12A)20-6A-5A20-5A2-5A20-5A3-B3C20-3CB4-B3C20-4C4-B3C20-3CB4-BC2A20-4C5-3A20-3A7-24A8-24A9-22A12-18A15-16A18-12A107-7(2B26-2B2-)2A26-2A-5A2(22-10A)22-5AC2(4A22-4A2C)4A22-4AC5A2(22-10A)22-5A-4A22-4A3-B2C2(22-3C4-3C)22-3C4-2CA22-3C5-2A22-2A6-26A7-24A9-22A11-20A14-16A18-12A107-7(2B26-2B2-)2A26-2A-5A22-10A22-5AC4A22-4A2C4A22-4ACD4A22-4ADC4A22-4A2C4A22-4AC5A2(22-10A)22-5A2-3(3C22-2CB4-)2CA22-2CB5-2A22-2A6-26A7-24A9-22A11-20A14-16A17-14A106-7(2B26-2B2-)2A26-2A-5A22-5AC4A22-4A2C2(4A22-4ACD4A22-4ADC)4A22-4A2C4A22-4AC5A22-10A22-5A2-B2C22-2CB2(4-B2C22-3C)4-BCA22-2CB4-3A22-3A5-26A7-24A9-22A11-20A13-18A16-14A75-B26-B3-7(2B26-2B2-)2A26-2A-5A22-5A3(C4A22-4ACD4A22-4AD)C4A22-4AC5A22-10A22-5A2-B2C2(22-2CB4-3C)22-2CB4-BCA22-2CB4-3A22-3A5-26A7-24A9-22A11-20A13-18A16-14A75-B26-B3-7(2B26-2B2-)2A26-2A-5A22-5AC4A22-4A2C2(4A22-4ACD4A22-4ADC)4A22-4A2C4A22-4AC5A22-10A22-5A2-3(B2C22-3C4-)BCA22-3C5-2A22-2A6-26A7-24A9-22A11-20A14-16A17-14A75-B26-B3-6(2B26-2B2-)2B26-2B33-5A22-10A22-5AC4A22-4A2C4A22-4ACD4A22-4ADC4A22-4A2C4A22-4AC5A22-10A22-5A-4A22-4A3-3C22-2CB2(4-3C22-3C)4-2CA22-3C5-2A22-2A6-26A7-24A9-22A11-20A14-16A18-12A45-B24-B5-2B24-2B3-6(3B24-3B2-)3B24-3B33-5A2(22-10A)22-5AC2(4A22-4A2C)4A22-4AC5A22-10A22-5A-4A22-4A2-4A22-4A3-B2C22-2CB4-3C22-2CB4-B2C22-2CB4-2CA22-2CB5-2A22-2A7-24A8-24A9-22A12-18A15-16A18-12A45-B24-B6-B24-B4-5(3B24-3B2-)3B24-3B65-5A3(22-10A)22-5A-4A22-4A-5A2(22-10A)22-5A-4A22-4A2-4A22-4A3-B2C22-2CB4-B2C22-3C4-B2C22-2CB4-2BC22-3C5-2A22-2A7-24A9-22A11-20A13-18A16-14A20-10A46-2B22-2B6-2B22-2B4-4(4B22-4B2-)4B22-4B97-6A3(20-12A)20-6A-5A20-5A-6A2(20-12A)20-6A-5A20-5A2-5A20-5A3-B3C2(20-4C4-4C)20-4C5-3C20-4C6-2A20-2A8-24A9-22A11-20A14-16A17-14A21-8A48-B22-B8-B22-B6-4(3B22-3B4-)2B24-2B98-6A3(20-12A)20-6A-5A20-5A-6A2(20-12A)20-6A2-2(4A20-4A4-)4C20-4C4-4C2(20-4C5-3C)20-4C6-2A20-2A9-22A11-20A13-18A15-16A18-12A24-4A19-B20-B9-2B20-2B8-2B20-2B7-2(3B20-3B6-)3B20-3B163-7A3(18-14A)18-7A-6A18-6A-7A2(18-14A)18-7A2-5A18-5A4-5A18-5A3(5-4C18-5C)6-3C18-4C8-2A18-2A11-20A13-18A15-16A17-14A21-8A49-2B18-2B10-2B18-2B9-3(3B18-3B8-)2B20-2B165-3(7A16-7A2-)7A16-7A3-6A16-6A3-2(7A16-7A2-)7A16-7A4-2(5A16-5A6-)5C16-5C7-4C16-4C8-4C16-4C9-3C16-3C10-3A16-3A11-20A13-18A16-14A20-10A26-2A53-2B16-2B11-2(3B16-3B10-)2B18-2B10-2B18-2B199-2(7A14-7A4-)AB5A14-5ABA2(4-2B5A14-5A2B)4-AB5A14-5ABA2(4-7A14-7A)5-6A14-6A7-5A14-5A2(8-4CA14-A4C)9-3CA14-A3C11-3C14-3C12-3A14-3A13-18A16-14A19-12A23-6A83-4(4B12-)2B16-2B265-7A12-7A6-7A12-7A7-3(5BA12-A5B8-)5BA12-A5B7-7A12-7A6-7A12-7A7-6A12-6A8-6A12-6A9-3C2A12-2A3C10-3C2A12-2A3C11-2C2A12-2A2C13-3C12-3C14-3A12-3A16-14A19-12A22-8A116-4B8-4B16-4B8-4B300-3(8A8-)8A9-3(4B3A8-3A4B10-)4B3A8-3A4B9-3(8A8-)8A9-7A8-7A10-7A8-7A11-2C4A8-4A2C12-2C4A8-4A2C13-C4A8-4AC15-2C2A8-4C17-3A8-3A19-12A22-8A150-12B20-12B23-6B27-4B29-2B212-22A10-22A11-3(3B14A3B12-)3B14A3B11-22A10-22A11-20A13-18A15-2(16C16-)16C17-14C20-10A24-6A185-8B24-8B25-6B27-4B29-2B213-20A12-20A13-3(2B14A2B14-)2B14A2B13-20A12-20A14-16A16-16A17-14C18-14C19-12C22-8C27-2A221-3(4B28-)4B29-2B215-16A16-16A17-3(14B18-)14B17-16A16-16A18-12A20-12A21-10C23-8C26-4C270-
