model
size = 30 30 25, scale = 0.05, origin = -y
material deform = 1, fade = true, lighting = smooth, roughness = 0.3, metalness = 0.6
  colors = A:#000 B:#111 C:#6C5B1F D:#846A24 E:#EEE F:#0D1300
voxels
584-2A692-A28-D2A27-D2A28-2A27-BA24-2B28-AB26-6B27-ABA29-B29-2B27-B-B508-DA28-2CAB26-2DA27-2DBA26-2DAB23-3A2DA25-4A2B23-A2B4-A23-BA3-BA21-2BAB2ABAB21-4ABA-2B21-AB-3A-2A22-2ABAB-B24-A4B25-BA2-A29-A416-BDA27-ADC2A25-D2CBA25-2DCB24-A-2CDB25-2ACD2B21-2AD2CDC3A21-2A3B3ABA21-2B2A3BAB20-2(AB)2(2AB)A19-2BAB4A2BA17-B-A3B3AB2A20-2(3BA)B23-4A-BA18-AB4-4BA-B17-2A7-2B-B416-A23-2CABD-2B21-2C4D-A20-D3C4DC2A20-DC6DB3A19-DCD3CD2A3B19-DC3DC2ABA2B13-4A4C2DC3ABA2B16-2A10B2A16-BA2(B2A)5BA15-BA4B4A4BA15-2B2A4B3A4B15-A-B3AB2(A2B)AB14-2A-4BAB6A15-AB-B2A4BA4B15-BAB-3B3A3BA15-2A2B2-ABA2B3AB17-B3-3B-A2-B259-A33-B27-AB-AB22-4B3A-B21-C3(BA)BDB19-DCACD3CBCBA17-3D5C2DC2B16-3D2(CD)C2D2CB2AB14-6D4CDCBAB2A9-A3-5DCD4CD6A8-2A4-5DC4D3BA2B8-A-2ADC3D3CD2CDB2A3B-A11-3D8A2B4AB12-3D5B2ABA2BAB2A2B11-2D2AB3AB2(A2B)2AB12-D3B3ABA3B3A2BA12-2DA7BAB4ABA2B9-2(4A2B)2AB3A-A10-A3B4ABAB2AB3AB14-2B3A4BA2B3AB12-B-2AB3ABA3B2A2BA12-AB-B2-BA2B3A2B18-A6-2B-B173-2C21-3A2-3CD22-ABD-BC2DAB19-2BAB3ADCAB18-2CA3B2(2CB)18-2DC2D3C2DADB16-DCD3CD4C2DBA15-2C2D2(CD)C2DCD2B15-CDC2D4(CD)B2AB13-D3C2(DC)2DCDC2B2(AB)8-A2-3D2C2(D3C)3BA2B11-D5C2DC2D2CA2(B2A)10-C2DCD7CD4B3A9-4C2DCD2C2D2C4BA2B3A4-A2-3CDC2BA3B6A2BAB2A7-FD3C2(AB)2A3B2(AB)2A2BA7-4DC2(B2A)BA2B4(AB)8-2D2C4BABA3BAB2A2B2AB7-4D2BAB2AB5ABA3BAB7-2ADC2ABA3B3A5B2AB9-A2(2B2A)2BAB3A2BAB10-3A2(BA)B2A2B2(AB)A2B10-A2B3A2BAB2A4B2A13-A3BA2B3AB2A2BA14-2A-A-5B2A2BA16-A-A7-A21-A7-B84-3C2D17-BA6-2DCD19-AB4-2C2DC18-DCBA2DBC3D2CB15-2D5C4D3C2A14-D5C4D3CDBA14-2D3C2(DC)2DC2DBA14-2D2C2(2DC)4D3A13-4DC6D3C2ABA12-2D3C2D3(CD)CA2B2A12-D2CDCD7C3A3B8-A-4CDC2D2C2DCDA2B2A2B10-3(D2C)2DCD2B2ABA2B9-E3C2D2C2DC2D4(AB)A8-E4D2C2(DC)2D3B3A2BA5-AD3C3D2B2A7BAB3AB7-F2DCDC4A3BA2B2(AB)2AB2A5-3(CD)BA2BABA2B3A2BAB2AB6-D4C3BABA5BABA2BAB7-2(DC)D4ABA4B6ABA8-3DC2BAB2AB3A5B3A8-2A3(BA)2B2A4B2A2BA10-BA2BAB2ABA3BA4BA10-BA4B7A3BA2B12-2A3BA2B2(A3B)A13-A-B2A2B2A2(BA)B2A16-AB3-2B2AB-B19-A3-A5-B19-A54-B7-CD2CD16-AD-A4-C2DCDC16-BD2A2-5CD2C16-D5CDC2DCD2CA15-DCD3C2D2(CD)2C2ABAB11-2(2DC)3D5CA3B12-4DCD2C2(DC)2D2BAB12-2D5CD4C2D2A2BA11-D5CD2CDC3DA3BA11-D4C4DCD3C2(A2B)10-6D6CDC5A2B7-A-D2CD3CDC3DCDBA2BABA10-CD2C2D2CD4C2A2B3AB9-BD2C2D2C2(DC)DB5A2B9-E2D3C4DC2D2AB2(A2B)5-A2DCD3C2AB2A3B3(AB)A2BA5-F3CDCD2B2(3A2BAB)AB5-F2(2CD)2A2B2(AB)A3B2ABA2B6-CD2CDCA7B2(AB)A4BA6-2C3DCB3A3B2A2BABA2B2A7-CBD2C3AB2A2B2(AB)2ABA2B7-2AB6AB2A3B4A2B2A7-2BABA2B2A7B4ABA8-3B5A5B5A3B11-2(3B2A)8B13-3A2B2(AB)A3BABA17-3A2BA2B2A17-4A2-4AB26-B2-B15-2B28-2B5-C4D2C16-BD2A2-3CD2CD-C15-2D2C-CD3C5DA13-D2C2D2(CD)2C3DCB16-E7C5D2BABA10-FD5CDC4D2C5A11-DCD2C5D4C4A2B10-3DC3D2CD4C5B11-D6CD2CD3C2B4A10-DC2(D2C)6DA2B2AB10-2D3C3DC2DCDC2ABAB2A7-A-2(D2C)5D2CD4BABA10-D4C2D4CDC2A5BA9-E2D2CD3C2DCDBA3B3AB8-E2D2(CD)C2D3CB2(A2B)ABA4-AC2D2CDC2B2AB6A2(2BA)7-4DCDA3B3A4BA3BA2B5-F2(2DC)5A2B2A4BA3B7-DCD3C4A3B4A5B8-2C2D2C7ABA4B2ABA7-C2BCDC5BABA3B4AB9-3AB4ABAB4A6B5-A2B2AB3A2(B2A)3B2ABA3B6-A-2A2BAB2A4B2AB3A2B2AB8-2BA2B3AB4AB2A3BA10-ABA4B2A2B2A2(BA)B13-2(B2A)3BA5B17-A-A2-B3ABA21-A2-B2-A-A15-B29-2BA3-D8C14-2D2CA-4CD3C-2C13-3DCD3C6DCDCA13-ED2C2D4C3DC2A13-2E3CD2C7DB4A10-DC2D3CDCD2C2DCB2A2BA9-F2(C2D)2C2DCD2CA4B8-3D7CD2C2D2C2(AB)2A9-DC2D4C2D2CD2C2(BA)2B10-2D3C2(DC)2DCDC3B2AB10-D2C2D4C2DC2D2A3B2A7-A-D4C2(DC)D2C2DBAB4AB9-C2D3CD2(C2D)A3BA2BA9-E4C3DC4DA2B3AB2A7-6C2D3CDCD2(B3A)B5-A4CDCD2BA3B2(A2B)AB2AB7-D4CD3BA2(3B2A)2B8-6CABA2BAB5A2BAB7-F2C2D2C2BABA2BA4B2ABA8-D4CDBAB2AB3A2B2ABAB8-DBA3CA3B3A2BA3BA2B8-2AB2A2B3A3BA2B3AB2A8-4AB2A2(2BA)BAB3AB2A9-BA2B2AB3A2BA2B3A2B11-2BA5B4A5B2A11-BAB8A4BABA13-BA2B2A2B2(AB)2A18-2A-AB2(A2B)A19-A2-B3-A17-B27-2AC2B-4D2C2D2C14-2(D2C)2DCD2C2D-2D13-3D5CDC3D4CA13-EDCD3C2DC3DCBA13-E2(DC)D3C2DC3D2BABA10-D2C2D3C2D2CDCDBAB2A9-FAC2D3C2D2(CD)2CAB3A8-2D4(CD)2(2CD)C2(B2A)7-2(2DC)2D2CD2C2D2CBAB2AB8-3D4C2(DC)5D2BA3B9-D4C2(DC)2(2DC)4ABAB8-D2C4DCD6C2(B2A)BA6-A2C2D3CDC3D3CBAB2ABAB6-A2CD3C5DC2DCA4BA3B5-A2(2DC)4DC2DCD6B2A8-C4DCABA5B2A2BAB3A7-DC2D2C4ABA2B2AB4A2B7-C3DCD2A4B2A2B2A3B2A7-2D2C2D2BA3BAB2A4BABA7-D5CBA7BAB2A3BA7-C2B2DC2(2AB)3A6B2A7-D2BA3BA2BA3B5A4B8-2AB2A6B2A3B3A3B6-3A5(BA)B3A6B9-2(BA2BA)BA3BA2B2A11-A-A2B4A2(B2ABA)13-BA3BABA2B3(AB)14-4A2BAB2A2B-B17-2(A3-)A16-B28-ACB2A2(CD)6CD14-2D2CDCD2C2(D3C)13-2D3CDC2(D3C)3DA12-E5C3DC2D3CDA12-E3D2C2(2DC)D2C4AB10-D5CDC2D5C2AB2A9-F2D3C2DC2D4CD3A2B6-2(3DC)D2CD3C2DCDBAB3A5-2D3C2(D2C)2D2(CD)2CA2B2AB6-D8C4D3CDC4BAB7-2D2C2(DC)3D4CDCB3AB2A6-5D2C3D3(CD)C2B6AB5-5D2C2DC3D2CD4B2AB2A5-A2C2DCDC3D2C2DCB3AB2A3B6-2(C3D)2(2CD)BAB3A4B6-4C2D2BAB9AB2A8-D2C3D3ABA2(B2A)4BA8-5DCAB2A2B2ABA2B3AB8-2DCD2C5BA2BA3B2ABA8-D3C2D2(2AB)A3BABA2BA8-C2A2CD2B2(AB)2ABA6B8-D2B4A2(B2A)2B3AB3A8-B6A2B3A2BA4B2AB7-3A5B3AB2A2(BA)4B9-B8AB2A2B3A3B10-2B-B2A2(BA)B2A2B4A15-2A2B3A8B17-A3BAB3ABA2B17-A-A3-A17-3B26-ACDC2D-3CDCD3C14-D14CDC13-2(D3C)D2C3(DC)A13-E2C3D4C3D3CA12-E3D2CDC3D2(CD)3ABA10-2DC2D2CDCD3CDC2A3B9-FA3CDCD6CDC3BAB6-3D2CD2(C2D)3C4D3A3B5-2(D2C)D6C3D3CBA4B6-D2C4D3C4D2(CD)BA2B2A7-3D4C2(DC)2(D2C)B2(A2B)6-D2(C3D)CD2C2D2C6BAB6-D2CD11CD3BA4B6-A3(CD)C2D2C3DCB2AB4A8-2CD4CDCD2CDCA2B5A8-C2D3C2BA2B2A3BA2B2(AB)7-2(D2C)B3A3BA4BA2B2A7-3CDCD2B7A5B3A7-DC2DCD3A3BA4BABA2B8-6DAB2A3BA2B4A2BA7-CABC2D2A2B3A2B2A2B3AB7-D2ABA2B3A3B2A2B2AB2A8-D2ABA2BABA2B3ABAB3AB8-2BA3BA5BABA2B4A8-2BA2B4A2(2BA)B3ABA11-2A3B2(2AB)A2B2ABA12-ABA-A4B2A2BA3B14-A3-2A5B2AB-AB18-2A3-A18-AB26-2A3D2-D2C2D2CDC14-3DCD2CDC2D2C5D12-D3CDC2D4CD2CDCD13-E3C3DC2D2CDCD2CA11-ED2C3D2C2(DC)2DABA2B10-DC2D2CD2C3D3C2B4A8-2F2C2DC2(D3C)DA3BA8-2D3C6DC3D2C3A2BA7-2D2CDCD4C2D2CDCBA2B2A8-2DCDC3DC5D2CA2B3A9-DC2D2C2DCD5C2(2AB)A8-2D7CD2C3DA4BA2B6-AC4(D2C)DC2(BA)2BAB6-A6CD2C2(DC)2DB2A2BABA6-A2D2C3D2C2(2DC)2B2A4B8-C3DC4D2C3D3BABA2B8-D3CDCBA2B2A3BA2B3AB8-C2D3CB2A5BAB2(A3B)6-D3CDCB2A2B3A2B2ABA2BAB6-D2C3D2BA2B3ABA3B2A2B7-D2B2CD3A4BA3(B2A)7-DBA3BAB2(2ABA2B)ABA7-2(AB)A7BA2B3A2BA2B7-4B2A2BAB4ABAB3A2B8-B3A2BA6B2(2AB)A8-5B-3A2B3(AB)4A9-A2-AB2-5B2(AB)A3B13-B5-A5B2AB-A19-AB21-B29-2BAB2-3CD2C3D14-D3CBD2C2D2C3DC2D12-9D2CD3CDCA13-E2C2D3CD5CDCA-A10-2E2C3D6C2D3CDCA9-DB4CDC6DCB2A2BA9-F3D2(CD)C6D4AB9-2(DC)3D2(2CD)CDC3BA2B9-4DC4D2(2CD)2B2(AB)10-DCD3CD2CDC2DCBA2B2A10-D2(C2D)CD3C2D4ABAB7-A-CDC3D2C2DC3DA3B2(AB)9-DC2D2CD6C2BA2B3A9-E2D2C3DCD2CD5A2BAB7-3D7C4D3B2A4B5-A2D4C3D4C2D4A2(B2A)6-2D5C2A2B2AB4A3BA2B6-D3CD2CA3B2A3B3ABA2B6-FDC4DCB3ABA9B8-DC2DCDCABA4B5AB2A8-D2B2CDC2A2B2(AB)2A3B2A8-DB3A3B7ABAB4A7-A2(2B2A)2BA4B2(A2B)A7-B2A7B2A3B2(AB)3A9-AB-B11A5B11-AB-BA4B7ABA12-2B2-B2A2(4BA)19-3A2B3AB22-AB3-B46-A6-CDC20-2(AB)2A4C3D3C14-DAB2C3DC4D2C2DA11-2D4(CD)2(2CD)C-C2A11-E5C5D2CD4CA9-F2(DC)D4C2D2CDBAB2A11-D4C2D3(CD)C3B2A11-D2C3D2CD5C2A3B11-3(D2C)D4C2(B2A)10-D3CD5C3DC2(BA)2B10-2(DCD2C)2(DC)BA2B2AB7-A-2CDC2DCD2C2(DC)5BAB10-CD8C2DC2B5AB9-E2D2C2DC2D2CD2ABA2B2AB8-ED5CD2CDCD3BAB2ABA5-A3D3C2(2D2C)DAB2A3BA8-DC2D3C2A3B2ABAB3ABA7-FDCD2C2D3BABA2B2A2(BA)B8-D2(C2D)3A5B2A2B2AB8-3D3CD2A4B3AB5A8-D2A4CA2B8A3BA9-B3A4BA2BA5B3ABA7-A3B2A2(BA)3B2ABAB4A9-B2A3BAB2(A2B)3AB2A12-A2(B2A)BAB3ABA2B11-A-BAB4ABA2B2(AB)A15-AB2A2BAB2A3B-B19-BA3BAB24-B2-2B76-2(B2-)A-3C3D2C-A13-2AB2A6CD3CDA12-4CD2CDC3DCD3C2A11-2D2(CD)2CD3CD2CD3A11-2D3C2(DC)D3C2DBAB12-3D2(2CD)CDC3DA2B12-2(2D3C)2(DC)DA2BA11-DC2D6CD3CDB3A11-3D4C2D2CD3C4BA10-DC2D2(CD)C4D2C2B2ABA7-A-CD3C3D3(CD)CB4AB10-D2(C3D)2CD2C3ABA2B9-BCDC2D4(CD)4AB2ABA7-E3DCDC2D2(CD)CBAB2A3B5-A3D5C5DC2DBAB2A3B7-DC4DC2B4A2B4(AB)6-F4CD2C2BA2B4A5B2A7-D3CDCD5(BA)4BABA6-2D4CDAB4A2B2(3AB)A7-2A4C4B4A2B2(AB)A2B7-B2ABA2BAB2A5B2ABAB2A8-9B2AB4ABA3B8-2BAB4AB2A4B2A2(BA)11-4B2A4B3A5B9-AB-3A4B2AB3A2B2A17-B2A3BAB2A-2B19-5B27-B84-A28-3A2C6-CA13-3CAD2C4D4-CA12-D3C4D2C5DA14-DC2DC3DCD2C3DA14-D4CD2C4D2CDB14-DC3D2CD4CD2CAB13-D2C3D3CD2CDCDBAB12-2(DC)7DC3DB2AB12-2(DC)D2C3D2C2DABA2B8-A-2D4C2DCD5C7B9-2C2DC2(D2C)DCD3BAB2A9-E5D2(CD)4CB2A3BA9-EDC6D5C3B3A2B5-A3D2CD4C2D4CB2A4B8-F6C10A2B4A7-2D2C2DC2(BA)3BAB2A2B2AB8-2(2DC)2A3BA2B4A4B8-D2C3D2(AB)2ABA2B2AB3A9-A4C5A2BA4B2A2B9-BAB3A2BA3BAB5AB10-2AB2A4B2A2BABA3BA10-2A2(2BA)3B3A2B3A12-5AB2A5B3AB11-A2-ABA3B3AB4AB18-BA3B2AB26-B144-A-A26-AB3ADA21-DAB5A2DB18-D2C5DC2DA18-DC2DC3D2C2AB17-3CD2CDC2D2CBA15-2(CD)2C2(3DC)A15-3CDCD5CD2CA2B13-D4CD2CDC2DCDBAB2A8-A2-6C5D3CBA3B11-3DCDC2D3C2DCAB2A2B10-2DC2D5C2(DC)ABA3B9-3D8C2D2CBAB2A3B5-A2-F4CD2C2D2CDC2B2A3BA8-FDC2DCB2ABA2(3B2A)9-3C3DA3B2AB4ABA2B10-C3DCA3B4A2B2A2BA10-2BD2C2(AB)A7B2AB10-BA2CD2(2B3A)2BA2B10-2(A2B)2A3BA2B3A2B12-2A2B3A2B4A2B2AB13-3B3(AB)6AB2A12-2A4B4A4B3A15-B2ABA-3A2B2A19-A6-A260-A2BA25-D5BA23-2C2BADC2B20-2DCD6CA18-2D2CD2(C2D)2B16-2CD4CDCD3C2AB14-4C3DCD2CDC4B9-A4-D9C2D2(2BA)7-2A4-DCD6CDCB3ABA7-A-2A2(DC)4DC3DC2B2AB14-D2C2D2CD3C2B2A2B13-D2C2AB3A2B6A14-DCB2AB3AB2ABA2B13-ABCB2A4BAB2A2BAB11-A2BC2B4A3(BA)3B11-2BAD2(A2B)AB2A2B2A12-2ABAB3ABA2BA3B2A14-2B5A2BABA2B14-AB4A2(BA)B2A4B15-ABA-AB-7B17-2A2-A4-A-A379-ACA2C24-2CABDC-B20-2D3CB3CDB19-D2C2(DC)3DBAB18-2C2DCD2C2DABA19-2CD5CB4A12-4A2CDCD2CDCBAB2A15-CD4CD3CAB2AB15-2C3(2AB)4A15-5A4BA2BABA15-A3BAB6A2BA14-2A2BABA2BAB2ABAB14-4A2BA4BAB2A13-2A2B2ABA3B3ABAB12-4A3BABA-A2B2A2B13-4AB2-AB-2A3B2A19-AB3-B2A27-2A385-CD28-2DCA26-D2CD2A23-CD3C2A22-4CDCA23-D3CD2CA20-2A4D2CDA21-2BACD2CBAB18-2B-A-5A2B-A16-ABA-B8AB16-ABA-2A4B3AB15-2A2BA2-6B3A14-ABA-B3-4A2BAB13-3ABAB3-4A-2AB14-A2B2A3-2B-A-BA23-AB-B475-DC27-2C2DA25-BD2CA25-A3DCA22-A-A3DCA22-AB4DA24-4A2B25-3B23-B2(3-A)21-BA-3B-BA3-A16-2A2B2-3B2-3A14-3B2AB3-B20-2ABA2B3-B5-A15-3A-A26-2A545-2D28-DCDA26-D2CA22-A3-3CA26-AC26-B29-B25-B30-BA2-A25-A30-A29-A196-
