model
size = 28 31 29, scale = 0.05, origin = -y
material deform = 1, fade = true, lighting = smooth, roughness = 0.3, metalness = 0.6
  colors = A:#394039 B:#503535 C:#252525 D:#707469 E:#4B4B4B F:#859593 G:#363D34 H:#2D4327 I:#333D31 J:#7C9EB3 K:#2E352D
voxels
374-8A3(20-8B)774-2A8-2A2(16-2B8A2B)16-2B7A3B18-8A20-5AG2A21-6A689-2(2A12-)2(2B2A8-2A2B12-)2B2A8-2A2B14-2A8-2A16-2A8-2A18-2(8A20-)8A21-2AG3A604-A16-A3(10-B2A12-2AB)11-AH3(12-2A)14-2(2A8-2A16-)11AG16-9AH2A19-6A575-A18-A3(8-BA16-AB)9-A16-H10-A16-G11-2A12-AG12-GA12-2A12-4A8-4A13-3A8-3A16-10A18-10A19-2AG5A517-A20-A3(6-BA18-AB)7-A18-A8-A18-A9-2(2A14-2A10-)3A12-3A10-3A12-3A11-5A6-5A13-4A6-4A15-G11A18-5AG2A21-6A461-A22-A4-BA20-AB4-2B20-2B2(4-BA20-AB)5-A20-A7-2(2A16-2A8-)3A14-3A9-2A14-2A10-4A10-3AH11-3A10-3A13-4A6-4A15-2(3AH)4A17-8AHA459-A27-2(B21-AB4-)BA20-AB4-BA20-AB5-A20-A7-2(A18-A8-)2A16-2A9-A16-A2(10-2A14-2A)11-G2A10-3A13-4A6-4A15-12A19-G5A400-A4-I22-I4-A21-A5-A21-A4-3(BA22-AB2-)BA22-AB4-A20-A6-A20-G6-2A18-2A7-A18-A9-2(2A14-2A10-)3A12-3A11-3A10-2AG13-4A6-4A16-10A20-AH4A320-A23-I3(3-A23-A)2(4-A22-A)2(B2-BA22-A)B2-BH22-HB4-2(A20-A6-)2A18-2A7-A18-A8-2A16-2A9-A16-A10-2A14-2A10-3A12-3A11-4A8-4A14-3A6-3A18-7AG291-I24-A2-3(A23-A3-)A23-2(A4-A22-)A3-2(BA22-AB2-)BA22-AB3-A22-A4-A22-A5-A20-A6-A20-A7-2A16-2A8-2A16-2A9-2A14-2A10-2AH12-3A11-3A10-H2A14-2A8-AH17-10A260-I-A24-I3(2-A24-A)2-A23-2A2-A23-2(A4-A22-)A3-2A22-2A3(2-BA22-AB)3-A22-A5-2(A20-A6-)GA18-2A7-A18-A8-2A16-2A9-2A14-2A10-2(3A12-)2A10-2A15-4A4-4A20-4A179-I-I25-A-5(A24-A2-)2A22-2A2-A23-2(A4-A22-)2A2-2A22-2A3(2-BA22-AB)3-A22-A4-2A20-2A5-A20-A2(6-2A18-2A)7-2A16-2A8-3A14-3A9-2(3A12-)2A10-2A15-3A6-G2A19-6A38-2D26-DA6(26-2A)25-3(A2-A24-)A2-2A22-2A2-A23-2A3-A2(22-2A2-2A)22-2A4(2-BA22-AB)3-2A20-2A5-A20-A2(6-2A18-2A)6-3A16-3A7-3A14-3A9-2(3A12-)2A10-2A15-3A6-3A19-2AG3A11-D27-D26-DA5(26-2A)26-A-4(A24-A2-)2A22-2A2-2A23-A4(2-2A22-2A)2(2-BA22-AB)2-BG22-AB3-2A20-AH5-A20-A6-HA18-2A6-2A18-2A6-3A16-3A7-3A14-3A9-2(3A12-)2A10-2A15-3A6-3A19-6A151-I27-A25-I5(2-A24-A)2-2A22-2A3-A23-A3-A22-A3-3(2A22-2A2-)3(BA22-AB2-)B2A20-2AB4-A20-A6-2A18-2A6-2A18-AG7-2A16-2A8-2AH14-3A9-2(3A12-)2A10-2A15-3A6-3A19-6A207-I28-I3(24-A2-A)24-A2-2A2(23-A3-A)22-A4-A22-A3-2A22-AG2(2-2A22-2A)2-BA22-AB2-B2A20-A2B2-B-A20-A2B4-A20-AB5-2A18-2A7-A18-A8-2A16-2A9-2A14-2A10-2(3A12-)2A10-2A15-4A4-4A20-4A265-A24-I4(3-A23-A)3-A22-A4-A22-A3-3(2A22-2A2-)BG3(A20-AB3-B-)A20-AB6-2A16-2A-B6-HA16-2A9-2A14-2A10-3A12-3A11-3A10-3A14-2A8-AH17-AG6A2G319-I4(23-A3-A)4(22-A4-A)22-A3-B-A20-A4-B-A20-AB3-B-2A18-2AB3-B2-A18-A-B3-B2-2A16-2AE8-A16-A10-2A14-2A10-3A12-3A11-4A8-4A14-3A6-3A18-8A348-A27-I22-I2(5-A21-A)4(4-A22-A)5-A20-A4-B-A20-AB3-B-2A18-AE4-B2-A18-AE5-BE-2(2A14-2A-E8-)G2A12-2AG-E9-3A10-3A13-4A6-4A16-10A20-G3AHA406-I21-A5-A21-I5-A20-2A5-2(A20-A6-)A20-A7-A18-A5-B2-A18-A6-BE2A16-2AE5-BE-A16-A2(-E5-BE-2A14-2A)-E6-E-C3A10-3AC11-C3AE6-4AC13-C12AC18-6A462-A27-I20-I3(6-2A18-2A)7-2A16-2A8-2A16-2A6-BE3A14-3AE5-BEC2A14-2ACE6-E2C3A10-3A2C7-E-C3A10-3AC10-2C4A6-4A2C10-3C2AE9A3C13-3C6A3C544-3(2A16-2A8-)CK2A12-2AKC8-C3A12-3A2(C7-EC5A8-5A)C8-CD15AG-C8-CDF4AEA2-AE4AFDC9-DF-3AE4AE3A-FD11-5D2CGA2C5D17-C2AGAC548-2(A16-A10-)3A12-3A2(10-C3AE7-E4AC)10-C4AE11AC10-DF2(4AE)4AFD9-CDF-AHAE4AEAHA-JDC11-FJ2FD4AD3FJ14-4FD4CD4F18-D4-D576-A16-A10-A16-A11-4A8-4A11-C3E9A4EC10-3DAE7AE2A3D10-DF-2AE9A-FD12-4FDC2ACD4F14-2FJFDC2ACD4F18-6D22-6D604-A16-A11-AK12-2A14-12A14-4C8A4C12-4DC6AC4D13-3FD2C2A2CD3F18-D4-D22-D4-D661-2A12-2A14-A10-A17-10A801-A10-A17-10A830-10A401-
