model
size = 30 31 8, scale = 0.05, origin = -y
material deform = 1, fade = true, lighting = smooth, roughness = 0.3, metalness = 0.6
  colors = A:#2A4A5B B:#E3E3E3 C:#959595 D:#BBB E:#5E5E5E F:#46647C
voxels
13-6A25-2A26-6A22-10A18-6A2-6A14-6A6-2(6A10-)6A7-5A7-A6-5A6-3A9-2(3A6-)3A9-5A4-3A5-4A10-5A3-4A4-3A9-6A5-3A4-3A6-7A7-3A4-3A3-8A9-3A3-4A-8A9-6A2-10A10-8A2-7A11-6A-3A2-5A10-7A3-3A-4A10-7A5-7A9-7A8-6A7-7A10-6A6-6A12-6A7-9A8-7A8-6A8-10A8-3A7-14A14-8A2-8A10-2(8A6-)8A10-8A2-8A14-14A18-10A441-8A2(22-8F)22-8A830-3A6-3A2(18-3F6-3F)18-3A6-3A827-2A10-2A2(16-2F10-2F)16-2A10-2A412-2A26-6A22-10A18-6A2-6A14-6A6-2(6A10-)6A7-5A14-5A2(6-3A18-3A)5-4A18-4A3(4-3A20-3A)3-4A20-4A3(2-3A3-2E12-2E3-3A)-4A3-2E12-2E3-7A3(24-6A)24-7A22-10A18-14A14-8A2-8A10-2(8A6-)8A10-8A2-8A14-14A18-10A22-6A26-2A26-6A22-10A18-6A2E6A14-6A2E2C2E6A10-6A3E2C2D3E6A7-5A2E2CE2C2DE2C2E5A6-3A2E3CDEC3DE3CD2E3A6-3A2E2C2DEC3DE2C2D2E3A5-4A2E3(C3DE)C4A4-3A2(EC)2(3DEC)3DE3C2(2A4-3A2(EC)3(3DEC)DC)2A3-4A2(EC)3(3DEC)DC2(3A2-3AECDEC3DEC2DBEC3DECDE)3A2-3AECD3(EC2DB)ECDE3A-4AECD3(EC2DB)ECDE7A2(ECD3(BEC2D)BE2DBE6A)ECD3(BEC2D)BE3DE6A2(EC2D)BEC3DEC2(2DBE)7A2EBEC3DEC2DBEC3DEC2E10A2E2(C2DBE)C2DB2E14A2EDBEC2DBECD2E8A2-8A3EC2DB3E8A6-8A2EDB2E8A10-8A2E8A14-14A18-10A22-6A26-2A26-6A22-10A18-14A14-18A10-22A7-2(24A6-)24A5-3(26A4-)26A3-3(28A2-)28A-240A2-26A6-22A10-18A14-14A18-10A22-6A26-2A26-6A22-10A18-6ADE6A14-6A2DBC2E6A10-6A2D3B3C2E6A7-5A2D5B5C2E5A6-3A2D7B7C2E3A6-3AD10B6CE3A5-4AD8BC2B6C4A4-3AD13B7C2A4-3AD9B11C2A4-3AD10B10C2A3-4AD9B11C3A2-3A11B10CB3A2-3A11B4C4B2CE3A2-3A11BC7B2CE3A-4A17B4CE7AD15B7CE6AD13B9CE6AD11B11CE6AD15B7CE7A2D12B6C2E10A2D9B5C2E14A2D5B5C2E8A2-8A2D3B3C2E8A6-8A2DBC2E8A10-8ADE8A14-14A18-10A22-6A12-
