model
size = 16 31 31, scale = 0.05, origin = -y
material deform = 1, fade = true, lighting = smooth, roughness = 0.3, metalness = 0.6
  colors = A:#00E B:#00B C:#EEE
voxels
295-5A2(10-6A)11-4A430-4A2(9-7A)9-B6A3(9-7A)9-6A380-6A6(7-9A)7-2AB6A7-8A9-7A345-7A8-9A7-5(10A6-)2(9A7-)8A9-7A328-4A-3A8-9A6-10AB3(5-11A)6-10A6-5A2B3A6-10A6-8AB7-5AB2A10-5A40-7A10-6A10-5A11-2(6A10-)6A2(11-5A)12-3AB75-7A8-3(9A7-)9A6-2AB8A4-5AB6A4-12A5-5A-5A3-3AB3A-5A3-13A3(5-11A)6-9A8-7A37-11A6-10A6-6AB2A7-2(10A6-)AB8A7-9A7-2AB6A7-10A6-5AB4A6-10A5-11A3-13A3-9AB3A2(2-14A)B3(-15A)B20AB19A2-2AB3A2-6A3-5A3-6A-6A2-12ABA4-9ABA5-4AB6A6-9A8-2AB4A11-3A23-4AB7A4-12A3-2AB6AB2A3-12ABA2-14A3-4AB8A3-13A2(4-12A)4-13A2(2-14A)-15A2-10A2B2A2-14A2-7AB2AB4A-15A-11AB3A-7A2BAB4A2(-15A)-7A2-6A-7A3-5A2-6A3-5A2-7A-6A2-14A4-6AB4A5-10A8-3AB4A9-5A21-13A3-13A2-14A2-10AB4A-15A-14A2(2-7AB6A)2-14A2-2(15A-)7AB8AC9AB4A-5(C15A)C5AB9AC15ACAB21A3-2AB10A4-4A-7A3-5A2-7A-6A2-14A2-7AB5A5-10A7-9A9-4ABA20-6A-7A2-AB4A-15A-23A2(-15A)-13ABA-8AB6A2(-15A)-27AB4AC8A2B46A-6AC7A2-14A3-9AB2A4-12A4-5ACBAB2A6-10AB5-11A5-12A3-3ABA2-6A3-5A2-7A-6A2-5AB7A5-11A6-9A8-7A10-5A4-6A4-5A-6A3-11ABA2(3-13A)3-3ABAB-6A3-6A-6A3-11ABA3-AB3AB4AB2A3-14A2(3-13A)4-10ABA4-2AB2AC6A4-5AC5A6-4AC5A6-10A2(6-4AC5A)6-4AC4A7-9A8-4AB4A7-8AB6-11A5-4A-7A3-5A2-7A-6A2-13A4-12A5-10A12-3A14-2A3-4AB5-5A-5A2(5-11A)5-5A-5A5-5A-B4A5(5-11A)3(6-10A)2(7-9A)7-AB7A7-9A7-8A9-7A9-8A8-6ABA8-9A6-2AB8A5-4A-7A3-2AB2A2-B6A-6A2-13A4-12A5-10A13-3A14-A3-5A6-4A-5A5-3AB7A5-11A5-AB3A-5A5-5A-5A6-10A6-6AB3A2(6-10A)6-3(9A7-)5AC3A3(8-8A)8-A2BAC3A8-4AC3A9-3AC3A9-7A9-8A8-9A6-10A6-4A-6A4-5A2-6AB2-3ABA2-AB11A4-12A5-10A13-3A14-A3-4A3(7-9A)7-4A-4A7-2ABA-4A2(7-9A)8-AB6A3(8-8A)8-4AC3A8-8A8-B7A8-AB6A8-4AC2A9-7A10-2AB3A10-2AB4A9-3AC3A9-8A7-9A7-10A6-4A-4ABA4-5A2-6A3-5A2-7A-3ABA4-12A5-B2A3-4A13-3A14-A3-4A3(7-9A)2(7-4A-4A)7-9A7-B3(8A8-)8A2(9-7A)9-3ACABA9-3AC2AB9-3AC3A9-B5A10-AB4A10-6A10-3AC3A9-7A9-8A7-2AB6A7-10A6-4A-5A5-5A2-6A3-5A2-6A2-5A4-5A2-5A5-3A3-4A13-3A14-A3-AB2A2(7-9A)6-B9A6-5A-4A6-5A-AB2A6-10A7-8AB2(8-8A)8-7A8(10-6A)10-2(7A9-)8A7-9A7-3AB6A6-4A-3ABA5-5A2-6A3-5A2-6A2-5A4-5A2-5A5-3A3-4A13-3A14-A3-2ABA7-2AB6A7-9A2(6-10A)6-5A-4A6-B9A6-3AB6A7-9A8-6ABA8-7A10-6A10-5AB6(10-3AC2A)10-3AC3A9-7A9-8A7-9A7-10A6-4A-6A4-5A2-6A3-5A2-7A-5A4-12A5-3A3-4A13-3A14-A3-5A2(6-10A)2(5-11A)5-5A-5A5-3AB7A5-11A6-10A7-3AB4AB7-7AB8-8A8-4AC3A2(8-8A)9-7A9-6AB2(9-5ABA)9-7A9-3AC3A9-8A8-5AB3A6-AB8A6-4A-6A4-B4A2-6A3-5A2-13A4-12A5-7AB2A13-3A14-A3-5A6-5ABAB2A5-AB9A5-11A5-3AB7A5-2AB2A-5A5-5A-6A4-7AB4A4-12A4-4AB7A4-11A5-8AB2A6-9A7-5AC4A7-4AC3AB3(7-4AC4A)8-2(3AC3A9-)5AB2A8-8A8-9A6-11A5-4A-7A3-5A2-7A-B5A2-2AB10A4-12A5-7AB2A13-3A14-A3-6A2(4-12A)3-11ABA3-2AB9AB3-6A-6A3-6A-7A2-5AB8A3(2-14A)2-13A4-12A5-B10A5-9ABA5-11A2(6-10A)6-7ABA2(7-9A)8-9A7-9A6-11A5-4A-7A3-5A2-7A-6A2-13A4-B11A5-10A12-3A14-2A3-5A-A2-12A2(-A)B11A-A-6AB-5A-A-13A-8AB16A-15A-60AB19AC15AC13ABAC4AB10AC2AB5A-6AC7A2-3AB2AC7A3-5AC6A4-5AC5ABA4-2ABAC5A2B4-2(14A2-)AB10A3-5A-B6A3-5A2-7A-6A2-7AB5A4-2AB9A5-10A7-8A10-5A5-2AB3A-15A-AB5A2(-7A)-15A-16A-10AB3A2-2(15A-)13ABA-20AB14AB11AC25AB26AB3A-14A2-14A3-BAB9A4-4AB6ABA3-3ABAC2AB4A3-15A-2AB12A-5A-7A3-5A2-2AB3A3-5A2-7A-6A3-11A6-10A7-9A8-7A10-5A6-13A2-5AB8A4(2-14A)3-8AB4A2(3-13A)3-12AB2(2-14A)-14AB-C2AB12AC15ACB14AC10AB4AC5AB9AC7AB7AC39A3-5A-7A4-4A-7A3-5A2-7A-6A3-B12A3-12A5-7AB2A7-9A9-6A22-12A3-AB11A3-11A5-13A3-2AB4AB5A2(3-13A)4-AB10A4-2AB9A2(4-12A)3-B12A4-12A3-12AB3-13A3-14A-15A-3AB27A-6AB8A-AB13A-7A2-6A-7A3-5A2-6A3-5A2-7A-6A3-9AB3A4-7AB3A5-7AB2A8-8A9-4AB23-4AB5A6-10A6-9A7-10A6-6A2B2A6-10A2(7-9A)7-2(11A5-)3AB7A6-10A5-11A5-2AB8A5-11A4-7AB4A4-12A3-13A4-6AB6A2-11AB2A2-14A2(2-6A)2-3AB2A3-5A3-6A-5AB3-6AB6A4-B2AB7A5-11A6-5AB3A8-7A11-3A25-7A10-6A10-5A11-6A10-3AB2A10-6A2(11-5A)12-4A75-7A8-3(10A6-)2(3AB)2A5-11A2(4-12A)4-2AB3A-5A4-6A-3ABA4-12A5-B10A5-11A5-B10A6-4AB4A8-B6A312-4A-3A8-9A6-2(11A5-)5AB5A5-11A3(6-10A)6-9A7-8A10-5A314-7A8-9A7-5(10A6-)2(9A7-)8A9-7A331-6A7-9A7-6AB2A7-9A7-A2(B3A)7-9A7-8AB7-2AB3AB2A7-AB6A9-5ABA348-3AB6(9-7A)9-6A395-5A10-4ABA10-6A11-4A149-
