model
size = 16 31 31, scale = 0.05, origin = -y
material deform = 1, fade = true, lighting = smooth, roughness = 0.3, metalness = 0.6
  colors = A:#EEE B:#797979 C:#5C5C5C D:#3F3F3F E:#B3B3B3 F:#222 G:#D0D0D0 H:#969696 I:#001 J:#A00 K:#700 L:#B00 M:#800
voxels
295-5A2(10-6A)11-4A430-4A6(9-7A)9-6A380-6A7(7-9A)7-8A9-7A345-7A8-9A7-5(10A6-)2(9A7-)8A9-7A328-4A-3A8-9A6-3(11A5-)11A3(6-10A)6-9A7-8A10-5A40-7F10-6F10-5D11-6D2(10-6C)2(11-5B)12-4B75-7E8-9E2(7-9G)7-9A6-11A2(4-12A)5-5A-5A3-7A-5A3-13A3(5-11A)6-9A8-7A37-11F6-10F6-9D7-10D2(6-10C)2(7-9B)7-2(10B6-)10B5-11H3-13H2(3-13E)3-2(14G2-)14A2-3(15A-)7A2(2-6A)3-5A2-7A-6A2-14A4-11A5-11A6-9A8-7A11-3A23-12F4-12F3-12D3-14D2-14C3-13C3-13B2(4-12B)4-13B2-14B2-14H-15H2(-15E)-32G72A2-6A-7A3-5A2-6A3-5A2-7A-6A2-14A4-11A5-10A8-8A9-5A21-13F3-13F2-14D2-15D-15C-14C3(2-14B)2-2(15B-)31H-32E32G72A3-13A4-4A-7A3-5A2-7A-6A2-14A2-13A5-10A7-9A9-6A20-6F-7F2-6F-8F7D-23D2(-15C)4(-15B)-16B32H32E9G-14G2-6GM7A3-2(5AJ6A4-)5AJ5A6-2(4AL6A5-)12A3-5A2-6A3-5A2-7A-6A2-13A5-11A6-9A8-I6A10-4IA4-6F4-5F-6F3-7F6D3-13D3-7D2(6C3-6C-)6B2(3-13B)3-14B3-13B3-6B7H4-12H4-5H7E4-11E6-4E6G6-10G6-4GM5A6-10A6-9A7-9A8-9A7-9A6-11A5-4A-7A3-5A2-7A-6A2-13A4-12A5-2I8A12-3A14-IA3-5F5-5F-5F5-6F5D5-11D5-5D-5C5-5C-5C5-6C5B4(5-11B)6-5B5H6-10H6-5H2(K4E7-4E)2(K4G7-4G)M4A7-4A2(J3A9-3A)J2(4A8-3AL)5A6-11A5-4A-7A3-5A2-7A-6A2-13A4-12A5-I9A13-3A14-I3-5F6-4F-5F5-6F5D5-11D5-5D-5C5-5C-5C6-5C5B3(6-10B)6-9B7-5B4H7-9H7-5H4E8-8E8-4E4G8-8G8-4G4A8-8A2(9-7A)9-8A8-9A6-10A6-4A-6A4-5A2-7A2-5A2-13A4-12A5-I9A13-3A14-I3-4F7-9F7-5F4D7-9D7-4D-4C7-4C-4C7-5C4B7-9B3(8-8B)8-4B4H8-8H8-4H4E8-4EK3E8-4EK3G8-4GK2G9-4GM2(2A10-3AJ)3A9-3AJ3A9-3AL4A7-9A7-10A6-4A-6A4-5A2-6A3-5A2-7A-5A4-12A5-I2A3-4A13-3A14-I3-4F7-9F7-5F4D7-9D7-4D-4C7-4C-4C7-5C4B7-9B3(8-8B)9-3B4H9-7H9-3HK3E9-7E9-3E4G9-6G10-3G3A10-6A10-2(7A9-)8A7-4AL4A7-10A6-4A-5A5-5A2-6A3-5A2-6A2-5A4-5A2-5A5-I2A3-4A13-3A14-I3-4F7-9F7-5F4D6-10D6-5D-4C6-5C-4C6-6C4B7-9B2(8-8B)8-7B10-3B3H10-6H10-3HK2E10-6E10-3E3G10-6G10-3G3A10-6A10-2(7A9-)8A7-4AL4A7-10A6-4A-5A5-5A2-6A3-5A2-6A2-5A4-5A2-5A5-I2A3-4A13-3A14-I3-4F7-9F7-5F4D6-10D6-6D4C6-5C-4C6-6C4B6-10B7-9B8-8B8-7B10-3B3H10-6H10-3H3E10-3EK2E10-3E2(K2G10-3G)M2(2A10-3AJ)3A9-3AJ3A9-3AL4A7-9A7-10A6-4A-6A4-5A2-6A3-5A2-7A-5A4-12A5-I2A3-4A13-3A14-I3-5F6-10F6-5F5D5-11D5-6D5C5-5C-5C5-6C5B5-11B6-10B7-9B7-8B8-4B4H8-8H8-4H4E8-8E9-3E4G9-7G9-3G4A3(9-7A)9-8A8-9A6-10A6-4A-6A4-5A2-6A3-5A2-13A4-12A5-I9A13-3A14-I3-5F6-10F5-6F5D5-11D5-6D2(5C5-5C-)6B3(4-12B)4-11B5-6B5H6-9H7-5H5E7-9E7-4E5G7-9G7-4GM4A8-2(3AJ3A9-)3AJ2(4A8-3AL)5A6-11A5-4A-7A3-5A2-7A-6A2-13A4-12A5-I9A13-3A14-I3-6F4-12F4-6F6D3-13D3-7D2(6C3-6C-)7B4(2-14B)2-7B6H4-12H5-5H6E5-11E5-5E6G6-10G6-4GM5A6-2(9A7-)9A8-9A7-9A6-11A5-4A-7A3-5A2-7A-6A2-13A4-12A5-I9A12-3A14-IA3-5F-F2-12F-F-8F5D-D-7D-5D-D-8D5C-25C-15B-64B32H2(K15E)K8G-6GK7G2-6GM7A3-5AJ6A4-5A2(J7A4-4A)L9A2-4AL9A2-12A3-5A-7A3-5A2-7A-6A2-13A4-12A5-10A7-2I6A10-4IA5-6F-15F-7F2(-7D)-15D-16C-14C2-3(15B-)31B32H32E9G-14G2-6G8A3-12A4-2(13A3-)2(15A-)5A-7A3-5A2-6A3-5A2-7A-6A3-11A6-10A7-9A8-7A10-5A6-13F2-14F2(2-14D)2(2-14C)4(3-13B)2-14B2-14H-15H-32E32G72A3-5A-7A4-4A-7A3-5A2-7A-6A3-13A3-12A5-10A7-9A9-6A22-12F3-13F3-11D5-13D2(3-13C)3-13B4(4-12B)3-13H4-12H2(3-13E)3-14G-15G4(-15A)-7A2-6A-7A3-5A2-6A3-5A2-7A-6A3-13A4-11A5-10A8-8A9-5A23-2(10F6-)9D7-10D2(6-10C)2(7-9B)7-2(11B5-)11B6-10H5-11H2(5-11E)2(4-12G)3-13A4-13A2(2-14A)3(2-6A)3-5A3-6A-6A3-13A4-11A5-11A6-9A8-7A11-3A25-7F10-6F10-5D11-6D2(10-6C)2(11-5B)12-4B75-7E8-10E2(6-10G)6-10A5-11A2(4-12A)2(4-6A-5A)4-12A3(5-11A)6-9A8-7A312-4A-3A8-9A6-3(11A5-)11A3(6-10A)6-9A7-8A10-5A314-7A8-9A7-5(10A6-)2(9A7-)8A9-7A331-6A7(7-9A)7-8A9-7A348-4A6(9-7A)9-6A395-5A2(10-6A)11-4A149-
