model
size = 29 24 31, scale = 0.05, origin = -y
material deform = 1, fade = true, lighting = smooth, roughness = 0.3, metalness = 0.6
  colors = A:#FF3 B:#1AAB9B C:#EEE D:#FC3 E:#F9C F:#F09 G:#FF6 H:#FF9 I:#FCC J:#F9F K:#CF9 L:#F96 M:#FC6 N:#FF0 O:#F6C P:#F99 Q:#F06 R:#FFF S:#F0F T:#CCC U:#CC0 V:#F60 W:#CC9 X:#F69 Y:#F63 Z:#CC3 Aa:#F6F Ab:#FC0 Ac:#F90 Ad:#F3C Ae:#F33 Af:#FCF Ag:#CFC Ah:#FC9 Ai:#CC6 Aj:#F66 Ak:#FFC Al:#F00 Am:#CF6 An:#F36 Ao:#F0C Ap:#F93 Aq:#CF0 Ar:#CF3 As:#CFF At:#F3F Au:#F30 Av:#CCF Aw:#F03 Ax:#F39
voxels
89-TApSAlH14-AfAuArU152-IHAwAhAeVZAjKLKArAkEFZQAdTAvOWAqJ439-AbF27-AlAr19-DNApAgI3-AnAvGEU14-JZEAd8-AiArAfArAd10-YNAqF13-AwLAiAtAwZAkIAoAbAlDSAbI69-IPFAkAwLFZDAjAg2AcAdWAhSFMAtYO6-EVOAtHAxKOAdEGENZTLUAiJNSLAsV4-UOEAdAvAkJGAuAhArAkAfDAfAeKR2FHAaAcTAhL31-XDJAsAiRAaAgSAtAmJMAvGIQAHSAdIEAtAqHXJHAoAcPIAoAxRKLGAwFPGYAtYEAqAaHQJFAaWAUWAxKAoApANJAeAwAiXOUApSAvAmAfIVAiWAs2AdDEAlDAjAiAcAqAfPUMAgFWAdAbALAnEAuQEAoAsIAcAhOAfAaYOAaJAcAjIOAaITAhAmArAbAsGAwMAxRAhXVAeAtAdLAi233-ZAlAh22-IF3-EAx19-PAqWAaAf3-Au2AfGAr14-GKAbAa8-AcApCVT10-AfZAiX13-AdCAvAnUEV2HAlAeD2CAq41-RLAGPLIAqAaAvOAtYTNAlQNK9-AwYKAmAiAmAgZTVLAgFAmAeAbEWHGQAr6-TXAoXAw13AAsAqYArAnZ4-2ApWAgAX13A2ISAiAtNI-FNDAqLIEAtAb2GAUAh2HKXMAjEHXAlPAArFKMArAcAaKDAfL14B2LAmAfAiOXQAKAdXEAuK14APAgAlUNAdAQAfAiAhAArAvX14AAbAxLAfAhHEArUAeAEAsG15AAlJAgAcAmAiAfAiHTMKFAiAgMSAjAsVJMXAtAxVKFAmAeEAfNIAxOAoJAeNAeGFKUAaVIEOQAuXJTGAdAwAnJU2DAjH175-BAm24-AlB-S2Ax22-PAa3-2Aj19-DLO2Ai3-LVJIAm14-GAiAcAg8-UAtCTX10-AaNYN13-AgCAiJEAePZAqJRV2CZ14-RAmHTDAhAgAiGFAxRAqVAfF11-T-AjSAkAvKHKFAiOJNIEAGAv9-MR-DXZLGWAeGFAdOHQJISWAmA6-ArUAn-V13AAtAaEAxIK4-AeAsRY-Z13AAvVAiAjAtTAf-AmWAvJNAu-Af14BAuMAgAkTDAkSEAoF2H-A14BMNKZMAeQXAiAmOAqP-I14ANAbAeAaPAnGAuSAxAdIAm-At14AAbVMRUNAkArAaAjHQAl-Av14AVTWJAbDTLFAjZRAv-GYUFWAqAiVAeApKZPAfKLAtAjAAeAWAgOVAaAnW-AkAmAfGDINTAnDGNAbPXKAtZAfAsAfE-AdKRYEHTEAcSOQAhAeNAcYArAlAvAXGAhUTP147-BY24-AwB-AuSAt22-SX3-LX19-TMZAqW3-AwAoPXAm14-YAoMP8-AmAoCAdQ10-PDSAm13-GCAvAuApAuAtIAlAsTAt2CX13-AaS13BAoL11-UAkAa13BAxAcAi9-ApAlQV13AAjAkSFT6-AtAqAaGE13AVAtAaAdAeAq4-DGAa2AkJ13AKFOAcMAaD-APVAiAdQTAs14BAxAcAvOAeAtAuAdAbZFAhGMI14BJKAoAgAnAvArAwAlAfGAAkPAp14AOAiAmKN2AnDUASAmTUAq14AAgAeAxAeDRAtAeApIAaAwMAbT14AKAvAjMKAxXAhSFHPYAtFAbRAvURAkZLZPAkDAjAmGNE2OAoGHAaGAkAvAuAvMAlYWRAjAsNKJAbRAeAlAxAgDMAuHAgAiWVSZWMAnQUAoENDAbArXAnAlYAnAbAjRKUAtJIF-E2AaENRQApAgAiHVAw2AAbUAoNFVAjGRAtPD118-BAd24-ZB-AhAwAf22-AgAh3-DP19-AbJApDQ3-AeAvFDF14-XAaAkAn8-ArECAlAs10-EALO13-WCAjDHAcFAAsArUAh2CV13-AgAq13BAhR11-AdKI13BAhAjU9-AdAhAeZ13AHDAlGH6-JAhAMN13AWVAaAiJA4-AgOAAmWAr13ADZAkFPAfP-AURAgAmAwAqA14BAnApUNApAaTEAlAjKAwXIAf14BYAqApAhDVAvAfAaDAeXWZU14AAuTDAmAcELAuAkVMWLNAf14AHAvAcSKJAlAvQZWLKArAc14APLKXAiAsEAmAaAv2AwIQAvAiDYAxFRAkGJDQJAuUWAIAgHAuAoAwOWAqAgApWLSKAuAjAdJRAgAnAeGPHAlAsAfAtKJAvAXAuEApXAqAsAlAaGMVAcUYRAbAnAkAoPAaIUAvAePGAf-AtAiAhLTIEOYNAhAeAlAo2AjNTAcAmAkSAfAnMAoAp3-SAxPAvSMAuSAbAhAsAaAgDAlDMFAlQAjAcRWAcA89-BAx24-ArB-VAjAe22-TAi3-VAs19-AoQKSAg3-AhTRXAb14-WGAcW8-YLCTS10-OAoAsAg13-AeCKAaAxAvPArNAwDAj2CA13-UM13BAdT11-EApQ13BAwAvAf9-AlAiDY13ADLAkGJ6-AmLSAcAm13AAeAlAsApAsAk4-AwAlAgAaKE13AAnEAbAIZAp-MVHLAxOAiO14BNAoRAaAhAnAlQKAkAgJAuAeH14BDAcJRAhRUYTZAxOAtAvJ14AKFUJHAxApAmRAaJAgAtAoP14AGArAlUWNDEAnROKGAmAo14AYAwAaAlDPAcKIYAqAbWAAsYLIAqAfSQWAbJWAsDSTOAkGFWDXQAuAaVLEIAuAwApTPAjGAsFPEAbVXApAuZAkOLVAWMAdTKAfSHAgAq2AvZAkIMAoAiAwZAuAqAtAaTAdKZ-AsNAhAeXAuAjPXTLWAhTSQAcSHAfArAaAtRMHX3-AbAMAAvZAmLAvAlEGMAjQFAaAkAAnAdGJPAiA89-BN24-TB-AxDAd22-AcM3-KL19-AtNPAgZ3-GAcKVE14-AqGAvAr8-XAhCIAt10-AmAbIS13-RCAeJEAkRIAlGAfAl2CE13-QAj13BMX11-AsYD13BUWI9-AjTAmV13ARLZAtAi6-HVApEZ13ANKN2FAx4-TAqKAqOAf13AHXArAdGJAt-YKRITAaHA14BSAhAkAEAgDAuTAnQRAdJI14BXHAsAdAiRVMRYWAnAhPAt14AAuWAbAwSAjZNAnAuAsYAAoAv14AArDAwDAaDAfAbYHIAuAmAcAn14AAnOHAeOVAAmGIAqAmYMXAmTWLAjHWTMAsAAhAlPUAgApFSQZAxAiApIAlSQAuEML2AlAqEApQAbAdAmLAoApKAhMAaGJAjFAqZ2LQArOPKEAbIAiAqY2AwSAgAcDAeAxQVAkAn-GTNAgAwArAnHUXMFQSAaAmHDXAxFAcMAfQET3-AvArAxAgAiAtJAbAUMWAaAdEAkAeAuJArKWAkArJM4-AJXNXPAkERQAsOAhOZAnArOAwAiAqAsAiAs61-BP24-AeB-AaZG22-AiAn3-JAp19-AcGFAnJ3-AnAPVAb14-FAkAeS8-AvTCAkO10-AvAuArT13-JCRNRTAdAoApAgAuJ2CA13-DF13BAfAe11-UAeO13BUMO9-AkAfAnAd13AAfQAuJAl6-AsRAcNH13AAcYAtOAbO4-AnTYAdDAi13AAdAmAtAgFAuAq-SAfAtApAoLKAo14BAdSKXAmAAqXAkXAqAgAcGA14BAwAjAeWAwAmTAuAsAoAaIAkYAf14ADZMLXAwAvArAbAxAdDAtSP14AAeAhWKWXLAnAwAjAhEFLAv14AAnGAqXLWAlUAcWAdVAdAjAeAfAlYJAuVAUVAhRAxAuPAsGJAvAaGAvAlKLAwEHDAnAuAaSFHKAdApTAmAxAjAvZTAkAsLOSAoAaAiKDJAiVNAvAkLOPTAwDAeSNVGJApTIAlAuAaAm-AeXAeAsAoZDGQAwAdAmRDAcMXPKApAnAqMApEAtV3-AAnIAAfKApGAgHAlAnAeKQAuZTAAbAaPAqMAtE4-NApAfAGAAkXAiLYAnAiYArJRAdAjAdUTUG6-22B33-BAf24-ApB-AjAkAs22-PD3-AsI19-EDAcAjR3-AbSDGQ14-XRArK8-AeSCAdM10-QWAuAn13-AmCTAqAhUAaAdAoZMAs2CV13-OAw13BKQ11-ZHX13BTArAv9-Am2JW13ARAiAoAcAx6-QAwAnPL13AAnNAmAeNA4-ZWXAbAoK13AYAhAxAsPAmO-AhMNAsWAjAcX14BAxLQFOAuWGNArILAlFA14BAjAgQM2HEAgAbASKAbArE14AVAxArQJPAiRVAfAjXFAwAf14AAhJAiQPAmSAjTUZAMAqAu14AAhONArAoAlAaSQYAhAqArSLNRAdAbDAuRAsZAxAfEMAnGFQAsIAkDXQSAIAsLKHNHAkVArAxTNAjAcArW2YMYI2QOAuArLAmQJAwXAqHAiRZAnNApArVAdAsAqAuSQAmSWGY-Ai2AwWFAgAIAqAoYAfAtPAqAKLJIHLQEAjAsAk3-AgXAsOXEQIAAoAXZAaAfTAcFZPAwArOZIT4-WIAdLAfWQAfAgIAoJAdURAkONAmAgAiHAhS6-BAjOEAdLAjAmAkAcAdAmZLAuAhAw2NXPB33-BAj24-AhB-AaAlH22-AuAh3-AbJ19-RAlLKAx3-FPAaAvF14-QAhJE8-OGCTAj10-OPQA13-SCUILOWAuArAaKAr2CAw13-OAa13BAgO11-AAdV13BXAgAu9-DAfHE13ALKAvFJ6-XVUAiJ13APAeGArPW4-AvWZAfAoAs13AAbMApAwAoEAb-NVWLAfAcAI14BWGJKQUL2AhEKAAdAfAp14BAqAkO2GAbAlAmAhAiXILPAq14AITAgY2AkESHSAAtAcAvT14AZMKSTRMXWAaEAvAkWAv14ANPAeLMYUPAoAdAoRAhAwGAlNArAaAlJAfGAkEPAlXOAtAvGXGETAoAmHAgAjAhHAgUPAsAdLUAcYRArUAbAoAdXLSAu2AiRAcAxAiIDHAkRApZJAhAgAlAdSYAsAbFAxHAoAlAaArFSAn-AjAoDVWZAjDJFAAxAa2LAoJAkMAjAiAxEVAnGAa3-AEZDAaDAcAnOAmJAkAcAwAgFRQVAoAjMEAtSO4-ArAfORVKAbAdAwOQAkAgIOYQKAVUJXAa6-BAlTAwQJAZAfAnXSHVWAjWAcGSAkB16-2B15-BS24-EB-NXS22-DAi3-AuAa19-AlHAnAwW3-ArOApAhF14-AgAdUW8-AqAxCXI10-YAbAxAh13-AsCDAhAfAcAnQAcYDAw2CAj13-AqJ13BAlAn11-VApF13BAbAtR9-V2AhO13AFXYWU6-UEAhAxAd13AM2AoAsApAs4-LRJHAfH13AQAxAgIDJP-ArAaPNAsWAkAi14BAkSAgEHRAqAiVAbHIDAsAo14BAtAaAxJWNINEAlAqApOAb15AFOJAsDHZAhJUIAqYAwAf14AAdAuOIOAqNAmAsApQTAuHP14AAcAtAgApYIArPAuArAcFAsHWEAeAhMAuMPAtQAlUDArIApAsAhAeAcAhAbZMAsAkAdIPAsAfMAhUAvNUXG2AbAcAwZDIGAnKHAlJNJAtAcApAmIAuQHRG2AbAoAkFAkKAqNAcSAgNAiWU-Ab2FAeAqAlSAvYWNApVAkAxTMRAiApArKAjRDAeD3-OAdAsTLAjGAmDHATRAjMQYAeAhAAiZAjKAvO4-AcTAvAgZApEOAqAdAeYVPQAoAvAxAfAeAhDGAo6-BNApWAoAdOHAqUYQLAfAiArMAfKWAkB16-2B15-BT24-AmB-AcAeF22-XAw3-MAd19-ArZAqAhT3-QAcAjAoD14-AsRAAh8-DAgCQAq10-AfRJY13-UCAfAkPVJAeMFVG2CF13-OAl13BArAb11-UYAa13BAwFQ9-ZRAuAk13AAqMQIE6-Aq2NMQ13AApQArAtOAb4-JAaArHNG13AAhQAiAvHVAm-JEUAdAAqAbAk14BAeAoTIMAbTAnMAlAhAfIVT14BAsAgRSPAkAeAbUAaAUQTM14ATIAnAjURMAjRAkAmAfWAeP14AApDYZAbYQAlNQAwAcAsMU14AAqEAuAhAkAoYAnZAhAlAfWAcTAtIAsYMZUApWDAeMJSZXAaLQSAaYAfAhEPDAeApFSIAmWAaAbDEAcMPOAaJAuAkKQAaVAuAHMAvOAsAqAdAjApEAqRAkAcAiKWUAgOAnArQXArVE-IWUWYTAaAcZAqOIJRKSAiAqAbKAuAbAnGAAiE3-DREAuApAdAeAhTHZUYAiAaAeIAkAeAtAjAtAkENJ4-NAiMAqAhAsGAvJNAlAoAeOAvZRMAtAlXTAfAh6-BGQMAuQOLAnAhAl2JAnAsQAtAaTPAvB33-BAs24-OB-FTAd22-QH3-ApAc19-ArAlFAoAm3-AqAeAAeAt14-AnZAsAa8-IMCAsAt10-AuHNAf13-OCAuAgAjPAuKAcNAtAg2CX13-AnAd13BAuM11-FRH13BArPAo9-YAdAxAi13AAnUAmAjY6-AhAmAcNAo13AAtAbAxVAmE4-AjAEAeP14AXAkAjKEArH-YRVAmOAsZAf14BOAlAtAqAvWAqAoJKAwHTJP14BYAaGAaLAsApAgUTXJApAnAv14AAuAkAiAdAlIAhIAlRWPAqAbW14AMQFAhESAxDAaAnLAoAaAjE14AN2GAMAjAfOYAsAnAjUKUAvAiWAbXHAeZAMAnAoAiUJAeAgGAoZAkAdAoINAlRAeApGFDAlAoAkMJAdPAtAxNAf2AnIAgAmAhAsHAgApDAbNMDApGOUAxZWAnAwUXAjAhAcAbNDRAxGAb-IAqKFHWAcASYApAjAaAqAbDAbAoVAmAdAjDE2AjAg3-TGM2AqKAdAaAuDVRIAjAeAkAxKSLAlKArDVR4-YQ2IAiAwVMAcKJZAlAnRAjTXAcAbGAsVAh6-22B33-BK24-QB-AhXAd22-ArG3-AH19-INYAcAv3-EAiFEAa14-AxAlZP8-AdArCSAg10-AdYAfU13-AhCMZAqAtD2PAdAhZ2CU13-AoAm13BAbL11-AfAcS13BAkKAt9-VUFX13ARXFHY6-LZAfArAu13AYAAdWAuAn4-VAgAfAcAwAr13AAoEAcDMRT-AbAdKAxAAdAqAn11BAoAnGJRLVApAnAk2AwTJILApAt11BAgNSPNPZAYTHDROAtAcAhX2FA8FIDAaAoHAbAfAdAuMAkAeAnAgAvAkAxAo8F2AFDKVAcAqAlAAwHPZAnYKAnAtAfAx11AEGEFIUIDPUAeAwMOUAjAqAo11AArYJArQApAtAeAmAbAnAgUAuApDIAgJMAeQ2JAxU-IJAuAdAZMAJYAlAkNXRAtDVZIAsUMArFUAjAfAlZOArLIJPAfPAmIAd-LNAtAcZNDIRWAiOAlVAcENAgAnAcAtAn2UAoEAt3-AbAjDNAfArApNAqNAdAaKAdMArKAtAkAv2AbAfAcOAv89-BI24-HB-AxD23-AvW3-EAa19-VAsZLD3-ArAkAcQAn14-AhAuAwAb8-AdWCAtAk10-AgLAmAt13-AbAwVOAoAdTAeQRAiAlAAwAu13-PAjHZAdAcLMAvWAxFEAmAqHU11-AhAmAlAkAfHFAcPAoAsNGMAwApPApAt9-YGAlAb13AAmDGDI6-IAuAgLF13AAlAcAiAeZL4-FAtHRAgM13ALKFAnNAwAr-AeDArAvPAjAxQ11BAmXAsApGAbWQXArAnAeAwAnAmDJQ11BAwWAbAYAkLWAoAsNAnAqRAlVOAr2A-6A2FXLAwAdSRKAsAxJDNApAxLZAgAi8A-2FWKHAwLYXIAjFKDAhNAgAfKN9A2FLXAkDAwAoASVOGKAxPAxAAeAh9A2FKAZAe2AgEAjKAdYGAfZJIMAmNDYXDJAiAh-EG2AeJADAxJVTHSYAkJOAtWSHAcSWOAsNGAbOSAvMPAfVJMAfQAt2-AsAnAgAvAqXAqK2LYIAhAgVHAaAoQAoPZOQAcY4-DYAeAtNIAiAwKAuApAmRTJVAmYAcAvAfAgY91-BQ24-MB-AtAr23-UP3-AiAw19-AwNLApU3-NHAmAoAg14-GSTN8-AxA2CAv10-Aw2YAa13-AmWAtAjAnJAkAqOHDEHAoI13-AiSEFVAtUAsAaHWAcMAkAgApAi11-AnFXAiAdKXAlAbAdJDKUZIAqNAv9-VAtGAu13ATAhGRV6-UAhXSAr13AAvAmApNKA4-SAfAhAoAaAn13ALSAHTAfAa2-TAjAcHAxVAt11AHEAiQLG2AcAk2-RZAdWAjEX11AAqArFWAlAkAeKQ2-AnAhLDVJAo11AIAsGAsETAsAiG2-YGAcOKAsAx11AQJSI2MTAeAk2-AuAgAkYTIAj11AWFAaSUPApAvT2-HRAtAuRApV11AAsOVAjRUAqAoM2-PAjFMAnAqKGRAwLANAiRMAgYRQJYZAcGEP2-AmDAdNY2TApJDPAfHSAxQIAoAjArOAuAhAeAnNAb3-VAcAbAuAvRAUAeAbUAqAaNQDAgDAiAgHGAsRAh119-BAq24-AvB-AfT23-VL3-AvI19-GSXZAl3-LAtAcGAp14-MAwEAt8-FAkD2As10-AbAgPD13-SJUAiGAwAlAxAuAxRNVXZ13-L9-AjAxAhTLNAd11-TKVOAcAvAAeFVAnVNAmAePArHT9-ZApXE14AAiMAgAw6-TAhAqAJ13AAfAoPIHL4-AlAvGAaEAs13AUAUDAkPAa2-AhELAgAdAfI11AHAdArAcAbEZAbT2-HMAlRAhAuAp11AJAcAnKSQXApAe2-WUEAjAAvAq11BPAeAtAiAa2WAM2-DRMDAmGT11AAoAsXAeVAsLAdQ2-ONUVAwApAv11AAcTAoAvEIKAwY2-YHRZXAL11AFApAxAoJSXDAm2-AuAqNAfWAdAlKAcSAcAxGAuJAi2AmKXGAvAgQYAbE3-IHALAwEGKAjAkJApHAnAoESXWSWKWArAeAp4-AqIKDMYAiZAtOAPAbAOXALAaEAeAsAwM119-BE24-IB-AeM23-TD3-UAj19-2AtApAvE3-RAlAjAgN14-HAbAtU8-VAxHLAu10-GHAkV13-YArUAvAeApH2AaAmHAl2AiZ13-AaAmAnApLAvAqJAkOEWLFAoAaAe11-AbAdEAtDAlAoAaPQAuODAgGAiHMAm9-AnAkAhO11AAkSAiLSAdS6-GAbRAH12ALPAlXLAaQ5-YAjYAmJ12APAmEAuAcOP4-ISAlAoAwP11ADRWGArAkAuAm4-SLAbAgXAo11AAcNDAp2AbAxAl4-AjAwFIWAc11AKHOAAwAjJL4-ZAgMDLF11AAiAqYAdHAlOAg4-AhXQEKAr11AAeIAuAwAkAbAgAq4-GLQArXAw11AAvQMDZFKAa4-AgPArAsAAqPQAaUAcKAqFAxGXAlLYOAaAlAmV5-AbAiJEApZGOApAeGApAdAfAk2LPAoAgAdES149-BAl24-HB-AdAb23-EAk3-FAi19-OWAdAiZ3-MSDFAc14-AoAxHE8-2OKAmD10-IAcAgAj13-WEDEAbRSAjAsSAfAApFI50-2B18-AqAwYAfAeI7CWAtVAcAbAi9-NIAgAuAcAnS7CLJTYFNZ7-AjDZXMAdNAj9CArAuMAhAaQ6-VKNLN11CAuGApAeAiAmD6-KGArPAb11CAtYAqAsFEAe6-TYAAbV11CAtS2TGOAn6-RSAfAlT11CGLAvApSHN6-AnL2UAe11CAiAwLAqAaJD6-YAwAfApM11CFAgAlAaVPK7-AgAcDQ11CGXEAdEAo16-5B158-BA24-KB-GAf23-AlT3-UO19-AjLFER3-Af2YAkJ14-AdYVP8-SZFAmAo10-UAjAhAu13-AlAgVAuAaSGAAgKAiXAfZA48-5B23-7B21-9B19-11B17-13B15-3(15B14-)15B15-13B17-11B19-9B21-7B23-5B100-BZ24-AkB-AsAa23-IR3-RAi19-AcQAbZY3-JAeAqMF14-NAiAeW8-IWOApK10-ArQPAe13-AhGPWHGAmXAgAnAjAmAiWZ162-2(C2-C-C2-C20-)C-C3-C-C20-2C5-2C20-C7-C243-BY24-AwB-HAu23-AeAq3-HAm19-MSArMAp3-PEOAfAs14-AjUQL8-HUIAE10-AxQDAl13-AfMAtDJAmApAmArAmAeAuAjGV530-BP24-PB-SAo23-ApAm3-AcZ19-HApVAhAl3-FNAhOZ14-PRJA8-HYJAoAs10-AcAbUY13-AIOVAxApAoAuAoAsOVAeFAb530-BU24-AgB-FAb23-EK3-AkJ19-AlHAArAe3-ROHAjA14-AbAlAbP8-AqVIAgV10-ETFL13-KZAoPRAoAfVFAaOAnO2M530-BX24-AvB-AdW23-AjAo3-2L19-AiAvGVAm3-KPAsPAn14-HWNG8-AbUAtDM10-DSWAq13-AcQMAtSAfEAnNRYAaOXD530-BAo24-UB-AdA23-AtAp3-AfV19-AwAfAnAvD3-PKTAlR14-AoAtAqAk8-AeAaAxHK10-AnAlAcG13-AqAeAcOGEHAaRFAxPYAaF530-BA24-RB-AlAd23-AuJ3-AwS19-AdAnLMU3-DLAfUAw14-SKHAb8-AAfHKAg10-AoQAjT13-AiXPAoAmHAuPIGAvAAxQZ530-BE24-AkB-AbAi23-EAs3-SAu19-AnDApJAb3-AaMIAnAf14-IVNK8-ZAtAcFAv10-AeAiQT13-OLArMApAuFAUAvAbAkAvNW530-BAe24-FB-AAs23-NM3-TAc19-NAhAtAbQ3-ApAdAgArR14-AqAaArG8-IAJAjS10-2AhIAk13-ZAjNAnRAcAvVDRAxXAxAhQ530-2B24-2B-AhQ23-DU3-QG19-AtApAmEAb3-ArYRAkP14-ONAtAq8-NQUAoAn10-ZAg2H13-AmRDAhYAqGOAmRISAfRJ529-
