model
size = 11 4 5, scale = 0.05, origin = -y
material deform = 1, fade = true, lighting = smooth, roughness = 0.3, metalness = 0.6
  colors = A:#444
voxels
22-3(A9-A33-)A9-A12-2(4A-)2(A4-)2A2(4-A)2(-4A)-
