model
size = 32 26 32, scale = 0.05, origin = -y
material deform = 1, fade = true, lighting = smooth, roughness = 0.3, metalness = 0.6
  colors = A:#F90 B:#300 C:#0C0 D:#100 E:#FC6 F:#001 G:#030 H:#010
voxels
-255A4B9(2(5D5B)5D7B)2(5D5B)5D3B3CH37CH10CH8CH3CHCH3CH6CH3CH5CH4CH6CH16CH2CH39C320A2B9(2(5D6B)5D5B)2(5D6B)5D3B21CG12C2G2CG4CG3CG31C2(G3C)GCG3CG11CG21CG5CG3CG22C352A2B9(2(5D6B)5D5B)2(5D6B)5D3B21CG10C-HCG2CG4CG3CG31C2(G3C)GCG3CG11CG21CG5CG3CG22C352A2B9(2(5D6B)5D5B)2(5D6B)5D3B159CG72A2E30A2E246A5(2B2(5D6B)5D3F)5(2B2(5D6B)8D)32C2(H63C)72A2E12A2E16A2E12A2E232A5(7D2(6B5D)3F)7D4(6B5D6B15D)6B5D6B8D160C68A2E8A2E6A2E12A2E8A2E6A2E232A5(5D22B5F)5D4(22B10D)22B5D95CG64C68A2E8A2E20A2E8A2E240A5(5D22B5F)5D4(22B10D)22B5D64CH95C352A5(5D22B5F)5D4(22B10D)22B5D63CG96C74A2E30A2E244A10(5D27B)160C74A2E30A2E244A320B64CH60C-CG32C81A2E2A2E26A2E2A2E233A320B160C81A2E2A2E26A2E2A2E233A320B32CH63CH62CG67A2E30A2E251A320B63CG96C67A2E30A2E251A10(27B5D)160C352A5D9(22B10D)22B5D127CG32C77A2E12A2E16A2E12A2E227A5D9(22B10D)22B5D96CH63C77A2E3A2E7A2E16A2E3A2E7A2E227A5D9(22B10D)22B5D95CG64C73A2E7A2E21A2E7A2E236A5D9(22B10D)22B5D32CH127C73A2E30A2E245A10(5D27B)160C352A320B63CG31CG64C87A2E30A2E231A309B5C6B96CH62CG66A2E19A2E9A2E19A2E231A309B5C6B160C66A2E9A2E19A2E9A2E241A309B5C6B32CH94CG32C74A2EA2E3A2E22A2EA2E3A2E236A309B5-6B128CH31C74A2E6A2E22A2E6A2E236A9(27B5D)21B5-B5D96CH63C71A2E30A2E247A5D9(22B10D)22B5D160C71A2E30A2E247A5D9(22B10D)22B5D63CGH95C81A2E6A2E22A2E6A2E229A9D9(5B5D5B17D)5B5D5B8D63CG96C81A2E6A2E22A2E6A2E229A9D9(5B5D5B17D)5B5D5B8D160C73A2E30A2E245A10(9D2(5B5D)3B)32CH-93CG32C73A2E30A2E245A4B9(2(5D5B)5D7B)2(5D5B)5D3B82CH12CG64C128A
