model
size = 15 27 14, scale = 0.05, origin = -y
material deform = 1, fade = true, lighting = smooth, roughness = 0.3, metalness = 0.6
  colors = A:#630 B:#930 C:#111 D:#F99 E:#EEE F:#F9C
voxels
81-3B11-5B10-A4B10-5B9-5BAB5(8-7B)9-A4B486-3(C11-C392-C11-C2-)6(C11-C392-)C11-C38-A13-3A11-5A9-2(7A8-)7A7-9A6-9A5-7(11A4-)11A5-9A9-3D11-5D10-5D8-2C5D2C5-4C3D4C3-6CD6C-2C2E5C2E4C2(-2C2E2C)2(3-2CEC)2(5-2C)10-A13-3A11-5A9-2(7A8-)7A7-9A6-9A5-7(11A4-)11A5-9A10-D13-FDF2(12-3D)132-3B11-BA3B10-4BA10-5B9-7B8-A6B7-2(9B6-)8BA2(6-9B)6-A8B6-9B6-4B2A3B8-5B155-
