model
size = 23 32 23, scale = 0.05, origin = -y
material deform = 1, fade = true, lighting = smooth, roughness = 0.3, metalness = 0.6
  colors = A:#C90 B:#FF0 C:#FF3 D:#E00 E:#960 F:#D00 G:#CC0 H:#963 I:#CF0
voxels
492-5A17-F6A684-5A16-AF7A13-2AFD7A17-B618-5A17-F5A16-AF7A12-12A11-13A12-2GD3B549-3A18-6A17-F6A14-2AF8A11-12A11-13A9-15A7-17A8-2G2BD6B12-2G2B-D3B19-D2C18-B2-B-C17-B3-B434-3A18-7A15-9A13-11A11-13A10-13A9-15A7-17A5-18A8-13B10-G-BC7B14-3C4BC14-2B2GD2CB16-BE2BDCBCD19-B-D363-3A18-6A17-7A14-11A12-11A11-12A10-15A8-15A7-17A5-18A5-19A6-15B8-G-9BCBD11-CE7BCDC10-2G4E5B13-B4ED-2CB14-4E2-BD15-4E2-D16-EH2E19-EHE230-3A19-5A17-6A16-9A13-11A12-11A11-13A10-13A9-15A7-17A2(5-18A)5-19A3-21A4-15B8-2GB-10BC7-2G2CG9BC10-G-G2E7BD10-G-BE-2E5B14-4ED4B14-4E-DBD15-H-2E19-H-2H206-3A18-6A17-7A16-7A14-11A12-11A11-12A11-13A9-15A8-15A6-2(18A5-)19A3-21A2-21A3-2G16B6-GBC11BC9-2C-9B3C8-C2GE8B2C9-3I2E-BD4BC13-4E-5B13-4E-D3B14-4E3-D16-H2E160-3A19-5A17-6A17-7A15-9A14-9A12-2(12A11-)13A9-15A8-15A7-17A2(5-18A)5-19A3-21A-23A2-G18B4-2GC14B7-3G12B2C7-B2F10BC9-B2-2E8BF12-3E7BF12-2EDBD4B14-3ED-2B-B14-H2ED2-B89-A21-3A19-5A17-6A17-7A16-7A15-9A13-11A12-11A11-12A11-13A10-13A9-15A7-17A6-17A5-19A4-19A3-21A-46A-G19B4-2G15BD6-2GC13BD6-BC2F10BCD7-2B2-F3B-4BCD13-FD5B-BFD12-F-2D4BF18-4B20-FB65-A21-3A19-5A18-5A17-7A16-7A15-9A13-11A12-11A11-12A11-13A10-13A9-15A7-17A6-17A5-18A5-19A4-19A3-21A-46A-G20B3-G17B5-CG15BC6-2BC12BC8-15B9-11BFB10-2(DF)6BF16-FBF2BD18-D-2FD19-A22-A21-3A19-5A18-5A17-6A17-7A16-7A15-9A13-11A12-11A11-12A11-13A10-13A9-15A7-17A6-17A5-18A5-19A4-19A3-21A-46A-21B2-G18B6-C15B8-14B2C7-13BCB8-DBF12B9-D-2F8B15-6B17-5D66-A21-3A19-5A18-5A17-7A16-7A15-9A13-11A12-11A11-12A11-13A10-13A9-15A7-17A6-17A5-18A5-19A4-19A3-21A-46A-G20B3-C18B4-C16B7-D14BCB7-D13BC8-14B9-B-9B3F10-3B3(FB)15-2B-3F-F89-A21-3A19-5A17-6A17-7A16-7A15-9A13-11A12-11A11-12A11-13A10-13A9-15A7-17A6-17A5-19A4-19A3-21A-46A-G19B4-D16BC6-D14B8-BC13BCB6-16B8-15B9-5BF3BFD2B11-2B-D-3F15-B5-F136-A20-5A17-6A17-7A15-9A14-9A13-11A11-12A11-13A10-13A9-15A7-17A6-17A5-18A5-F18A4-F18A3-21A-AD21A2-D18B5-16B7-C14B2C7-BC13B8-2B-12B9-4BD7BD11-3B-2BFBF-D14-D-2D19-D208-3A18-6A17-7A16-7A14-11AB11-11AB10-12A11-13AB8-15AB7-15AB5-18A2B3-18AB4-19A3-F20A2-F20A3-G17B7-C13B9-3C10B3C8-C11B-C8-2B2-9BD10-B2-6BFBD11-B-2(BD)BF2-B16-D253-3A19-5AB16-6A16-9AB2(12-11A)11-13A10-13A9-15AB6-17A2B3-18AB4-18A2B3-19A3-21AB3-G17B7-C11BC11-D9B3C10-DC8B2D10-3B-6BD13-BD-6B14-2BDBD4B14-2B5-2B14-B279-3A18-7A16-7A15-9A12-2(12A11-)13A9-15AB6-17AB4-18A5-19AB3-19AB4-G14B-2B6-CBC10B11-D-9BCD12-2C7B2CD10-2D7B-2C11-2(B-D)2B18-B-D3B20-B322-2B21-B19-3A18-7A15-9A13-11A11-13A10-13A9-15A7-17A5-18A7-2G10BD2-B8-D-C7BD15-8BCD12-DC5B5C12-3C2-CBC17-B-3B432-3A-2B15-6AB16-7A14-11A11-12A11-13A9-15A7-17A8-CG9BD13-C7B2C13-C5BDBC15-CB3CDC18-2BCDC20-D278-B68-B113-B18-3A17-9AB12-11A11-12A11-13A9-15A11-7BD2B15-2C2-D18-C-2C19-4C347-B45-B22-B45-B44-2B45-B23-B15-5ADB14-9AB12-8AD2A19-B-2B682-5A-DB14-6AD215-
