model
size = 15 32 15, scale = 0.05, origin = -y
material deform = 1, fade = true, lighting = smooth, roughness = 0.3, metalness = 0.6
  colors = A:#A00 B:#3FF
voxels
5-5B295-8(5A10-)3(5B10-)5B8-9B278-5A8-8(2A5-2A6-)3(2B5-2B6-)2(2B5-)11B262-5A8-9A5-8(A9-A4-)3(B9-B4-)B9-B3-13B246-5A9-A5BA6-11A3-8(A11-A2-)4(B11-B2-)13B232-3A10-2A3B2A7-A7BA5-11A3-8(A11-A2-)3(B11-B2-)B11-B-15B5-5B206-3B11-A3BA8-2A5B2A5-A9BA3-13A-A7(13-2A)13-AB3(13-2B)13-16B5-5B11-3B177-3B11-5B9-A5BA7-A7BA5-A9BA3-13A-A7(13-2A)13-AB3(13-2B)13-16B5-5B11-3B13-10(B14-)B13-3B11-5B9-A5BA7-A7BA5-A9BA3-13A-A7(13-2A)13-AB3(13-2B)13-16B5-5B11-3B177-3B11-5B9-A5BA7-A7BA5-A9BA3-13A-A7(13-2A)13-AB3(13-2B)13-16B5-5B206-3B11-A3BA8-2A5B2A5-A9BA3-13A-A7(13-2A)13-AB3(13-2B)13-B-13B232-3A10-7A7-AB3A3BA5-11A3-8(A11-A2-)4(B11-B2-)13B246-5A9-A5BA6-11A3-8(A11-A2-)3(B11-B2-)B11-B3-11B262-5A8-9A5-8(A9-A4-)3(B9-B4-)B9-B5-9B278-5A8-8(2A5-2A6-)3(2B5-2B6-)2B5-2B8-5B295-8(5A10-)3(5B10-)5B5-
