model
size = 13 24 32, scale = 0.05, origin = -y
material deform = 1, fade = true, lighting = smooth, roughness = 0.3, metalness = 0.6
  colors = A:#FFF B:#D8B37B C:#292929 D:#202020 E:#FCC F:#B28065 G:#181818 H:#FC0 I:#100
voxels
56-5C8-5B8-5A9-3A217-C-C9-3(5C8-)5B9-4(3A10-)3A4(11-2A)12-A35-5G5(8-5D)21-2(C-)C8-3(C4FC7-)B4EB7-2(A3BA8-)A3B6(A9-A2B)A9-2ABA9-4A8-6A7-6G7-D4I3(D7-D4B)D7-6D19-3(C-)C6-3(C6FC5-)B6EB6-A4BA4(7-6A)7-5A8-3(6A7-)6A6-7A6-AB5A6-6GIG5-DI4DG3(D5-DB4DB)D5-8D17-4(C-)2C3(3-C8FC)3-B8EB3-2A6BA4-3A4-B2A3(3-3A4-3A)3-5(3A4-2A4-)ABA4-2A5-2(2A4-)3G4-3G4(3-DID4-DID)3-3D4-3D17-4(C-)3(C3-C8F)C3-B8EB3-A8BA2(3-2A6-2A)3-2A6-AG3-2A6-2A3-5(2A6-A4-)2A6-A5-A6-A4-2G6-2G5(3-2D6-2D)16-4(C-)2C3(3-C8FC)3-B8EB3-A8BA2(3-2A6-AG)2(3-2A6-2A)3-5(2A6-A4-)2A6-A5-A6-A4-2G6-2G5(3-2D6-2D)17-4(C-)3(C3-C8F)C3-B8EB3-A8BA2(3-2A6-2A)3-2A6-AG3-2A6-2A3-5(2A6-A4-)2A6-A5-A6-A4-2G6-2G5(3-2D6-2D)16-4(C-)2C3(3-C8FC)3-B8EB3-A8BA4(3-2A6-2A)3-2A6-A4-2A5(6-A5-A)6-A4-2G6-2G5(3-2D6-2D)16-2C4(-C)3(3-C8FC)3-B8EB3-A8BA2(3-2A6-2A)2(4-A6-2A)4-6(A6-A5-)A6-A4-2G6-2G5(3-2D6-2D)17-2C2(-C)-2C4-9C2(4-C7FC)4-B7EB4-A7BA3(4-A6-2A)4-8(A6-A5-)G6-G5(5-D6-D)44-9C4-C7FC4-B7EB4-A7BA3(4-A6-2A)4-8(A6-A5-)5(G6-G5-)G6-G44-9C4-B7EB2(4-A7BA)3(4-A6-2A)4-9(A6-A5-)2(A6-A2(-D)-)A6-A-D2-DA6-AD4-H6AH6-6A32-9C4-B7EB2(4-A7BA)2(4-A6-2A)4-9(A6-A5-)3(8A5-)7AH5-H6AD57-10C3-B8EB3-A8BA3-A7BA2(4-A6-2A)4-6(A6-A5-)3(8A5-)A6-H5-H13-2(D5-)D64-10C3-C8FC3-B8EB3-A8BA3-A7BA4-A6-2A4-4(A6-A5-)3(8A5-)A6-A5-H6-H32-2D2-2D84-10C3-B8EB2(3-A8BA)3-A7BA4-A6-2A4-2(A6-A5-)2(8A5-)A6-A5-H6-H45-D4-D21-4D85-10C3-B8EB2(3-A8BA)3-A7BA4-2(A6-A5-)8A5-A6-A5-H6-H32-6D34-5D97-2C4(-C)3-4(CF)2C3-B8EB2(3-A8BA)3-A7B2A3-A6-A2(5-8A)5-H6-H19-6D162-4(C-)2C3-B8EB4(3-A8BA)3-7AB2A3-A7BA4-H6AH19-6D175-2C3(-C)-2C2-B9EB2(2-A9BA)2-3(A8BA3-)9A18-6D188-5(C-)C2-B9EB3(2-A9BA)2-2(A8BA3-)9A211-5(C-)2C-B10EB3(-A10BA)2-A9BA2-A7B2A4-7A212-2C5(-C)-B10EB3(-A10BA)-A9B2A2-A7BA5-7A211-2C4(-C)-2CB11EBA11B2A11BA-A10BA-A9B2A2-A7BA5-7A211-6(C-)CB11EBA2(11B2A)11BA-A9B2A2-A7BA5-7A211-2C4(-C)-2CB11EBA2(11B2A)11BA-A9B2A2-A7BA5-7A211-6(C-)2C11FCB11EBA11B2A11BA-A9BA3-A7BA5-7A212-6(C-)C11FCB11EBA11BA-A9BA2-A9BA3-A7BA5-7A213-4(C-)C3-5(CF)C2-B9EB3(2-A9BA)3-A7BA5-7A225-10C3-C9FC2-B9EB2-A9BA3-A7BA4-2A5B2A6-5A240-9C4-2B5E2B2(4-2A5B2A)5-7A224-
