model
size = 31 17 31, scale = 0.05, origin = -y
material deform = 1, fade = true, lighting = smooth, roughness = 0.3, metalness = 0.6
  colors = A:#FABA3B B:#78552B C:#7BA23F D:#FFB11B E:#E83015 F:#EEE G:#FFD857
voxels
105-7C428-5A25-7A24-7A21-13C52-7B55-7E86-7C208-11A19-13A18-13A16-17C19-7B21-13B21-7B22-11E22-5F16-27D11-G12C21-2AG4A24-7A144-15A15-17A14-17A13-19C15-13B16-17B16-13B18-13E19-2F5-2F14-27D9-17C16-13A18-12AG21-A4G2A112-17A13-19A12-19A11-21C13-15B14-19B14-15B16-15E17-F9-F13-27D8-19C14-15A16-G14A18-11A22-7A80-19A11-21A10-21A9-23C10-19B11-21B11-19B13-17E15-F11-F12-27D7-G20C11-19A12-19A14-2G13A18-AG4A2G2AG77-21A9-23A8-23A7-25C8-21B9-23B9-21B12-17E15-F11-F12-27D6-23C9-21A10-21A12-17A15-G11AG2A20-2AG4A47-23A7-25A6-25A5-27C7-21B8-25B8-21B11-19E2(13-F)11-27D5-25C8-21A10-21A11-18AG13-AG15A17-G6AG3A44-2(25A6-)25A5-27C6-23B7-25B7-23B10-19E2(13-F)11-27D5-25C7-23A8-G21AG9-G20A11-16AG2A15-13A43-25A5-27A4-27A3-29C4-25B5-27B5-25B9-19E2(13-F)11-27D4-27C5-25A6-25A8-21A11-19A14-15A41-2(27A4-)27A3-29C4-25B5-27B5-25B9-9E-9E2(13-F)11-27D4-27C5-G24A6-G24A7-23A9-20AG12-3AGAG11A40-2(27A4-)27A3-29C4-25B5-27B5-25B9-19E13-F11-5F9-27D4-27C5-25A6-25A7-23A9-21A12-13AG2AG20-5A15-27A3-29A2-29A-31C2-27B3-29B3-27B8-19E14-F8-2F-F3-2F7-27D3-29C3-G26A4-G26A5-G24A7-G22A10-16AGAG18-7A13-2(29A2-)29A-31C2-27B3-29B3-27B8-19E14-F7-2F2-F4-2F6-27D3-29C3-27A4-27A5-25A7-23A10-3AG15A17-3AG5A12-2(29A2-)29A-31C2-27B3-29B3-27B9-17E16-F6-F2-2(F6-)27D3-29C3-27A4-27A5-24AG7-23A10-17A2G17-9A12-29A2(2-14AC14A)-15CB15C2-27B3-29B3-13B-13B9-17E17-2F3-F-2F8-F5-27D3-29C3-27A4-G25AG5-25A7-23A10-16AG2A17-6AG2A12-2(29A2-)29A-31C2-27B3-29B3-27B10-15E14-5F-5F10-F5-27D3-29C3-27A4-26AG5-25A7-G21AG10-19A17-AG7A12-2(29A2-)29A-31C2-27B3-29B3-27B6-18E13-2F5-2F2-F11-F5-27D3-29C3-G26A4-G26A5-25A7-23A10-G15AG2A17-9A13-27A3-29A2-29A-31C2-27B3-29B3-27B5-20E11-2F7-2F-F11-F5-27D3-29C3-27A4-27A5-G24A7-22AG10-19A18-7A14-2(27A4-)27A3-29C4-25B5-27B5-25B5-9E-12E10-F9-F-F11-F5-27D4-27C5-G24A6-25A7-23A9-G20A12-AGA2G8A2G2A20-2AG2A15-2(27A4-)27A3-29C4-25B5-27B5-25B2(5-9E)8-F11-F-F9-F6-27D4-27C5-25A6-24AG7-23A9-21A12-17A41-25A5-27A4-27A3-29C4-25B5-27B5-25B5-4E-4E4-11E7-F11-F-2F7-2F6-27D4-27C5-G24A6-AG21A2G8-21A11-19A14-14AG42-2(25A6-)25A5-27C6-23B7-25B7-23B6-9E4-11E7-F11-F2-2F5-2F7-27D5-25C7-G22A8-23A9-G20A11-16AG2A15-4AG8A44-23A7-25A6-25A5-27C7-21B8-25B8-21B7-9E4-5E-5E7-F11-F4-5F9-27D5-25C8-21A10-21A11-19A13-AG14AG17-G5AGAG2A46-21A9-23A8-23A7-25C8-21B9-23B9-21B8-7E5-11E7-F11-F18-27D6-23C9-21A10-G19AG12-17A15-13A2G20-3AG3A49-19A11-21A10-21A9-23C10-19B11-21B11-19B10-5E6-11E8-F9-F19-27D7-21C11-19A12-19A14-14AG18-11A79-17A13-19A12-19A11-21C13-15B14-19B14-15B24-9E9-2F7-2F19-27D8-19C14-G14A16-G14A18-2G8AG22-G4AGA82-15A15-17A14-17A13-19C15-13B16-17B16-13B26-7E11-2F5-2F20-27D9-17C16-13A18-G11AG21-5AGA115-11A19-13A18-13A16-17C19-7B21-13B21-7B30-5E14-5F22-27D11-13C21-5AGA24-AG5A149-5A25-7A24-7A21-13C52-7B148-7C303-7C415-
