model
size = 31 16 31, scale = 0.05, origin = -y
material deform = 1, fade = true, lighting = smooth, roughness = 0.3, metalness = 0.6
  colors = A:#43341B B:#EEE C:#2A1F0F D:#BBE1C8 E:#FFB11B
voxels
74-7B486-13B481-5B7D5B453-7B18-3B3D7B3D3B450-11B15-3B2D11B2D3B447-15B12-2B2D4B7-4B2D2B419-7B19-5B7-5B10-2B2D3B11-3B2D2B416-11B16-4B11-4B8-3BD3B10-6BD3B21-5B27-B-B358-13B14-4B13-4B7-2BD3B11-7BD2B21-6B25-B-2B357-15B13-3B15-3B6-2B2D2B2C10-7B2D2B8-2C10-6B13-2C10-4B15-2C12-2B15-6(2C29-)2C122-17B11-3B17-3B5-2BD2B-C3A8-8BD2B8-C3A7-7B13-CA2E8-5B14-C3A9-2B16-C3A10-B16-C3A27-CA2E2(27-C3A)2(27-4C)27-2C91-17B11-3B17-3B5-2BD2B2C5A3-11BD2B7-2C5A4-8B12-2C3A2E5-3B-3B12-2C5A7-3B14-2C5A8-B15-2C5A24-2C3A2E2(24-2C5A)2(24-7C)25-4C88-19B9-3B19-3B3-2BD2BC13A6B-2BD2B5-C13A6B11-C7A5EA3B-2B11-C13A2-2B13-2(C13A17-)C7A6E2(17-C13A)2(17-14C)18-C3B6C83-19B9-3B19-3B3-2BD2BC17A2B-2BD2B5-C17A2B11-C16A3B11-C15AB14-2(C15A15-)C13A2E2(15-C15A)2(15-16C)16-6B7C19-3B58-19B9-3B19-3B3-2BDB2C18AB-2BD2B4-2C18AB10-2C17AB11-3(2C17A12-)2C15A2E2(12-2C17A)2(12-19C)13-7B9C16-5B28-B28-19B9-3B19-3B3-2BDB2C21ABD2B4-2C21A8-2C17A4E3(8-2C21A)8-2C17A4E2(8-2C21A)2(8-23C)9-7B13C12-5B27-3B27-19B9-3B19-3B3-2BD2BC17A3-2BD2B4-2C17A12-2C15A2E3(12-2C17A)12-2C15A2E2(12-2C17A)2(12-19C)13-7B9C16-5B28-B28-19B9-3B19-3B3-2BD2BC15A5-2BD2B5-C15A15-C13A2E3(15-C15A)15-C13A2E2(15-C15A)2(15-16C)16-5B8C19-3B58-19B9-3B19-3B3-2BD2B3C11A7-2BD2B5-3C11A17-3C5A6E3(17-3C11A)17-3C5A6E2(17-3C11A)2(17-14C)18-C3B6C84-17B11-3B17-3B5-2BD2B2C5A12-2BD2B7-2C5A24-2C3A2E3(24-2C5A)24-2C3A2E2(24-2C5A)2(24-7C)25-4C89-17B11-3B17-3B5-2BD2B-C3A14-2BD2B8-C3A27-CA2E3(27-C3A)27-CA2E2(27-C3A)2(27-4C)27-2C92-15B13-3B15-3B6-2B2D2B2C15-2B2D2B8-9(2C29-)2C124-13B14-4B13-4B7-2BD3B15-3BD2B415-11B16-4B11-4B8-3BD3B13-3BD3B417-7B19-5B7-5B10-2B2D3B11-3B2D2B445-15B12-2B2D4B7-4B2D2B448-11B15-3B2D11B2D3B451-7B18-3B3D7B3D3B478-5B7D5B481-13B486-7B415-
