model
size = 8 9 9, scale = 0.05, origin = -y
material deform = 1, fade = true, lighting = smooth, roughness = 0.3, metalness = 0.6
  colors = A:#111 B:#E00
voxels
-2(6A2-)6A-20A3-17A2(-6A2(2-A4-A)2-6A-A4(6-2A)6-A)-6A2(2-A4-A)2-6A-A6-2A6-5A3-2(2A6-)A-6A2(2-A4-A)2-6A-A4(6-2A)6-A-3(6A2-)6A-40A-6A18-6A-2A4-3A6-2(2A-B2-B-)2(3A4-2A-6A18-6A-2A4-3A2(6-2A)6-)3A4-2A-6A-
