model
size = 32 15 15, scale = 0.05, origin = -y
material deform = 1, fade = true, lighting = smooth, roughness = 0.3, metalness = 0.6
  colors = A:#E00 B:#111 C:#FFF
voxels
128-B31-B2A29-3(B3A28-)B2A29-B223-B31-B3A28-B5A26-B7A26-7A9-5B11-7A9-5B10-8A23-B7A24-B5A26-B3A28-B127-B31-B3A28-B2A-4A26-9A26-8A26-11AB3-B16-11AB3-B15-9A22-8A21-9A21-B2A-4A24-B4A27-B95-B3A28-B2A-5A26-4A-4A27-9A26-8A26-5A-2A2-2A21-5A-A2-2A20-8A22-9A19-10A19-4A-4A20-B2A-4A24-B3A60-BA30-B5A2(28-9A)27-3A2-4A26-9A26-5A-2A25-8A23-8A21-4A-4A20-3A2-4A19-9A18-9A21-B6A25-BA30-B2A29-B8A28-9A27-10A27-4A-4A27-4A-5A26-9A25-7A23-9A19-4A-5A18-4A-4A18-10A18-9A18-B7A24-B2A29-B3A29-8A30-3(8A29-)9A27-3A2-B29-ACB26-3A2-B22-9A18-2(8A19-)8A18-8A23-B3A28-B4A2(29-8A)30-8A29-8A30-7A30-2AB61-2AB24-7A2(19-8A)19-7A19-8A22-B3A28-B3A29-9A3(29-8A)29-9A27-3A2-B29-ACB26-3A2-B22-9A18-2(8A19-)8A18-8A23-B3A28-B2A29-B7A29-9A28-9A27-9A28-3A-5A26-9A25-7A23-9A20-3A-5A18-9A19-2(9A18-)B8A23-B2A29-BA30-B6A27-9A28-9A27-3A2-4A26-10A25-9A25-7A23-9A20-10A19-3A2-4A19-9A18-9A21-B6A25-BA62-B3A28-B2A2(-5A26-4A)-4A26-9A25-9A24-8A23-8A22-9A20-4A-4A19-4A2-3A20-B2A-5A23-B3A92-B31-B4A27-B2A-4A26-10A25-9A25-8A25-7A24-8A22-9A21-9A20-B2A-5A23-B4A27-B127-B31-B3A28-B6A25-B8A24-9A2(24-8A)22-B8A23-B6A25-B3A28-B223-BA30-B2A29-4(B3A28-)BA158-
