model
size = 18 23 31, scale = 0.05, origin = -y
material deform = 1, fade = true, lighting = smooth, roughness = 0.3, metalness = 0.6
  colors = A:#222 B:#111 C:#555 D:#0E0 E:#444 F:#0A0 G:#D00 H:#00E
voxels
203-B15-2ABECA10-BD-A3EB15-E-DB16-DF2(A17-)B285-2A11-2AB-EA11-B2A3C2A9-ABF-2C-C2-A6-B-A5-GFA7-B8-FA2(16-2E)17-A263-B-A-2A11-3BCAB3A8-DBAD3CB2-A6-2AD-D2-C4A6-2A6-FD2A5-BAE6-FC7-B8-CE7-B8-CA16-EA15-A2E228-A2-2A12-2(BA)B3A9-3ACACBA-A7-2BAC-2CB3A6-BAB5-G3A6-2C6-FCBA2(6-2C)2B5-3E6-2C-B5-AE7-DA7-B-D6-CEA7-D2-E5-E9-B3-EABA12-2B183-A-2A10-2(AB)3A10-2(ACB)3A7-ABACD2CB2-A6-BAD3-C-G-3A5-BC6-DFBA6-BD7-C2BA5-2C6-2CEB2(6-2C)A6-A2C6-DCA7-BD6-AEA7-2BFE-CA-A10-B4EA14-E2AE16-A149-2A10-2A-6A7-2(2AB)2A-2A6-DBCD2C2B2-2A5-A2D-2C-C5A4-BCA5-GFD4A3-BC7-F2B2A4-BC7-CEBA5-EC7-CEA6-2C6-DCA7-AC6-ACA7-A-F2-D2-A10-AF2CD2AB11-AECAEA15-AE166-2A9-B2A-B3A9-3BCAB5A6-B2A4CB4A5-BAB-D2-CGD4A3-ACA6-FD4A3-B2C6-FCB2A4-AC7-CE2B5-E2(C7-C2A6-A)CH5-ACA8-AF-2C2-BA9-2A4C-B11-AE-AE16-A148-BA11-A2-A-4A8-2AB8A6-BA2CACBA-2A6-BDAC-2CBD4A3-3AD5-2D4A3-ACD6-FCB3A3-A2C6-2C2BA4-A2C5-A2C2A4-2AC5-2AD3A5-ACD6-CEA8-D-C5-A9-A2CDC2A11-ACEACA13-B3A147-B17-4A12-B-3A-A7-B4AB2A-2A5-AB5ABD4A4-BAB3-A-2G4A3-ABC6-G-B4A2-ABC7-C2B2A3-A2C6-2CEBA4-A2C5-A2C3A4-B2C3-3A2C2A5-ABH2-3AB3A7-ABFC-CABA9-ABCE2CA11-2ABE3A13-2B-A147-B-2A14-5A11-AB5A9-3A2B-3A5-BDB5A2-3A4-ACA3-2AD-D3A4-BC8-2BA4-ABC7-2ABA4-2AC5-6A4-A2C4-2ADC2AB4-ABC3-4ACA6-A2BF-ACAB2A9-BF2CDA-A9-2ABECAEA11-A2B2AE14-BA148-4A15-4A12-B5A9-2(B3A)9-AB3A2B3A4-2A-BD3A2(D-)A5-3A-DA4-ABA4-3A6-3A2B4-2AC5-6A4-ABC4-5A6-ABCH2-2AB3A6-A2-F-CDA2B7-3A2B4CAB9-2ABE3A11-3AB2A13-2AB116-2(A15-AD)B16-2A14-5A10-4A-2A9-D3ABF-2A7-AB3AFBD2-A6-5ADAFA-B2A4-5A2-6A5-BA5-5A5-ABAH3-ABAC7-2ABD-3A2BA6-2A-2B2C3A8-A-2ABCEAC10-4AB3A10-7A12-3A-A113-B2A15-2B2A15-2A16-A32-A3-A10-A2B3-2A7-B-2(AF)2-A2BA5-4A2FBD3ABA5-4ADFB4A6-B2A2-6A6-2ABD2-2A2BA7-2A-BF4ABA6-4AB3AC2A8-4AB4A9-4A2B2A10-7A12-3A98-A16-2ADA16-BA15-A54-A16-2BA7-A-D4-2ABA6-3AB2-2A-2A6-3AF2B5A6-ABA2-D2AB2A7-A2BD-6A6-3ABF6A9-2AB3A-A9-3A2BA11-7A11-5A14-2A99-A-A14-B-BA16-A71-2A15-3A15-A2B7-AB3-2A2-A6-B2A3-3A8-ABAFBD2ABA8-A2-DB3A2BA6-2A-2B6A7-4AB3A-A8-2(5ABA11-)4A15-2A83-A15-ABA16-DB16-A54-A15-ABA15-A2BA15-2A13-A2-A7-A4-ABA8-2AB2-3AB2A7-2A2B7A6-A-2AB5A9-4AB2A10-5AB11-6A13-4A16-A81-3A15-3BA15-2A16-A36-A16-DA15-AD2A15-3A15-A14-A16-2BA12-2A-ABA8-2AB2A2-2A8-4ABA12-4A2B11-6A12-3ABA14-2AB81-A16-B3A14-A-2A15-AB53-A16-B2A14-2ABA15-AB31-2A2(15-3A)11-DA3-A8-4AB2A11-6A10-AB5A12-5A14-A83-A16-B-DA16-A71-2A2(15-3A)16-A14-A15-ADA15-A2BA10-DA3-AB10-AB2A2-A8-5ABA10-B2A2-AB10-A2BA15-ABA137-A54-A15-ADA15-A2BA15-AB13-A2-A13-BA15-A2BA11-A3-3A10-B2A2-A11-4A11-A3-2A11-D2(BA15-A)176-A16-BA15-ADBA15-3A15-A14-A16-D2A15-3A11-2A2-2A11-3A15-A2B11-DA3-A11-ABA15-A194-A16-D2A14-4A15-AB31-2A15-ABA15-A2B11-BA3-A11-AB2A11-A2-3A10-ABA3-A11-2A193-A17-2A15-ABA15-2A17-A14-A15-ADA15-4A10-DA3-2A10-AD2A2-A8-A2-4A10-DA3-AB10-ABA16-A175-A16-3A14-2ABA15-2A32-A16-DA15-A2BA11-A3-ABA10-B2A2-A11-2ABA11-A3-AB11-2BA15-AB16-A175-2A15-ABA15-AB50-A16-DBA15-3A11-2A2-2A11-3A15-3A11-DA3-A11-3A15-A210-2A16-A51-2A15-3A15-A2B11-DA3-A7-A3-AB2A10-2A2-2AB10-ABA3-A11-AB261-A18-A15-ABA15-2A12-BA3-2A10-ADA3-A7-2A2-4A9-ABA3-2A10-2A279-2A2(15-ABA)11-2A3-A11-AB2A11-A2-3A10-AFA3-A11-AB280-2(A15-AB)12-BA15-ABA3-A11-2A17-2A10-A18-A296-AF16-2A12-F16-AFA16-A413-A243-
