model
size = 18 23 31, scale = 0.05, origin = -y
material deform = 1, fade = true, lighting = smooth, roughness = 0.3, metalness = 0.6
  colors = A:#222 B:#111 C:#555 D:#0E0 E:#444 F:#0A0 G:#D00 H:#00E
voxels
210-B14-ACEB2A12-B3EA-DB9-BD-E13-AFD15-A17-B288-2A17-AE-B2A11-2A3C2AB8-A2-C-2C-FBA8-AFG5-A-B7-AF8-B7-2(2E16-)A270-2A-A-B10-3ABAC3B8-A2-B3CDABD7-4AC2-D-D2A6-2ADF6-2A8-CF6-EAB7-E2(C8-B7-A)E16-2EA232-2A2-A11-3A2(BA)B9-A-ABCAC3A8-3AB2C-CA2B7-3AG5-BAB6-ABCF6-2C6-2B2(2C6-)B-2C6-3E7-AD7-EA6-AEC6-D-B7-E5-E2-D9-ABAE3-B14-2B171-2A-A15-3A2(BA)10-3A2(BCA)9-A2-B2CDCABA6-3A-G-C3-DAB6-ABFD6-CB5-A2BC7-DB6-BE2(2C6-2C7-A)CD6-2CA6-AEA6-DB9-A-AC-EF2B11-A4EB12-E2AE15-A136-2A15-6A-2A9-2A-2(2AB)2A7-2A2-2B2CDCBD6-5AC-2C-2DA4-4ADFG5-ACB4-2A2BF7-CB5-ABEC7-CB6-AEC7-CE7-ACD6-2C7-ACA6-CA9-A2-D2-F-A9-B2AD2CFA11-AEACEA13-EA154-2A17-3AB-2AB8-5ABAC3B7-4AB4C2AB5-4ADGC2-D-BAB4-4ADF6-ACA4-2ABCF6-2CB5-2BEC7-CA6-2AC7-CE6-2AC7-CA7-ACA5-HCA8-AB2-2C-FA10-B-4C2A12-EA-EA14-A137-AB14-4A-A2-A8-8AB2A8-2A-ABCA2CAB6-4ADB2C-CADB5-4A2D5-D3A3-3ABCF6-DCA4-A2B2C6-2CA5-2A2(2CA5-)3AD2A5-C2A5-AEC6-DCA7-A5-C-D11-2ACD2CA12-ACAECA13-3AB136-B14-4A13-A-3A-B11-2A-2AB4AB7-4ADB5ABA5-4A2G-A3-BAB3-4AB-G6-CBA3-2A2BC7-CBA4-ABE2C6-2CA4-3A2(2CA5-)2A2C3A3-2CB6-3AB3A2-HBA8-ABAC-CFBA11-A2CECBA11-3AEB2A12-A-2B133-2A-B2(13-5A)BA11-3A-2B3A9-3A2-5ABDB5-3AD-D2A3-ACA5-A2B8-CB5-AB2A7-CBA4-6A5-C2A4-B2ACD2A4-2CA6-AC4A3-CBA7-2ABACA-F2BA8-A-AD2CFB11-AEACEB2A11-E2A2BA14-AB134-4A13-4A14-5AB13-2(3AB)9-3A2B3ABA9-A2(-D)3ADB-2A5-ABA4-AD-3A5-2B3A6-3A4-6A5-C2A6-5A4-CBA6-3AB2A2-HCBA8-2BADC-F2-A8-BA4C2B3A9-3AEB2A12-2AB3A14-B2A96-A17-ADA15-BDA15-2A15-5A14-2A-4A11-2A-FB3AD9-A2-DBF3ABA6-2AB-AFAD5A6-6A2-5A6-5A5-AB8-CABA3-HABA7-A2B3A-DB2A9-3A2C2B-2A9-CAECB2A-A9-3AB4A11-7A12-A-3A95-2AB14-2A2B15-2A17-A34-A3-A13-2A3-2BA9-A2BA2-2(FA)-B6-AB3ADB2F4A7-4ABFD4A8-6A2-2AB8-A2B2A2-DB2A7-AB4AFB-2A8-2AC3AB4A8-4AB4A10-2A2B4A11-7A14-3A78-A15-AD2A14-AB18-A52-A16-A2B15-AB2A4-D-A8-2A-2A2-B3A8-5A2BF3A8-2AB2AD2-ABA7-6A-D2BA8-6AFB3A8-A-3AB2A13-A2B3A12-7A13-5A15-2A76-A-A15-AB-B15-A70-2A16-3A15-2BA16-A2-2A3-BA11-3A3-2AB9-AB2ADBFABA7-A2B3ABD2-A8-6A2B-2A8-A-3AB4A2(11-AB5A)14-4A15-2A58-A17-ABA15-BD17-A52-A17-ABA14-A2BA15-2A17-A2-A17-ABA4-A9-2AB3A2-B2A7-7A2B2A9-5AB2A-A10-2AB4A13-B5A13-6A13-4A15-A59-3A14-A3B15-2A17-A34-A17-AD15-2ADA14-3A17-A20-A16-A2B15-ABA-2A13-2A2-2AB2A13-AB4A12-2B4A13-6A13-AB3A14-B2A59-A15-3AB14-2A-A15-BA52-A16-2AB15-AB2A15-BA37-2A16-3A15-3A16-A3-AD15-2AB4A12-6A13-5ABA12-5A16-A59-A15-AD-B15-A70-2A16-3A15-3A16-A20-A17-ADA14-A2BA15-BA3-AD12-A2-2ABA14-AB5A12-BA2-2AB15-A2BA14-ABA111-A52-A17-ADA14-A2BA15-BA17-A2-A17-AB15-A2BA14-3A3-A13-A2-2AB15-4A15-2A3-A16-ABD15-ABA17-A146-A17-AB15-ABDA14-3A17-A20-A16-2AD15-3A16-2A2-2A16-3A15-2BA16-A3-AD16-ABA17-A164-A16-2AD15-4A15-BA37-2A16-ABA15-2BA16-A3-AB15-2ABA15-3A2-A13-A3-ABA16-2A164-A16-2A16-ABA16-2A16-A20-A17-ADA14-4A15-2A3-AD12-A2-2ADA14-4A2-A12-BA3-AD16-ABA16-A147-A16-3A15-AB2A15-2A37-A17-AD15-A2BA14-ABA3-A13-A2-2AB15-AB2A15-BA3-A16-A2B16-BA17-A146-2A16-ABA16-BA55-A16-ABD15-3A16-2A2-2A16-3A15-3A16-A3-AD16-3A17-A183-2A17-A54-2A16-3A15-2BA16-A3-AD15-2ABA3-A11-B2A2-2A12-A3-ABA16-BA240-A16-A17-ABA16-2A15-2A3-AB12-A3-ADA14-4A2-2A11-2A3-ABA16-2A257-2A16-ABA15-ABA16-A3-2A15-2ABA15-3A2-A13-A3-AFA16-BA257-A17-ABA16-BA20-AB12-A3-ABA16-2A15-2A23-A16-A277-FA16-2A21-F16-AFA16-A413-A242-
