model
size = 13 32 6, scale = 0.05, origin = -y
material deform = 1, fade = true, lighting = smooth, roughness = 0.3, metalness = 0.6
  colors = A:#2D2B1D B:#EEE C:#1B813E D:#FBE251 E:#F05E1C F:#BDC0BA G:#4F4F48 H:#222 I:#E83015 J:#707C74
voxels
6-3D5-2(11A2-)A9BA2-AB7CBA2-ABCB2IBICBA2-ABC5BCBA2-ABCB3JBCBA2-ABCB3GBCBA2-ABC2BG2B2(CBA2-ABC5B)CBA2-A9EA2-AEGE2GEG2EA2-A2(EG)2E2GEA2-A9EA2-ABCB3DBCBA2-ABC2DA2DCBA2-ABC2(DA)DCBA2-ABCA3DACBA2-ABC2(DA)DCBA2-ABC2DA2DCBA2-ABC2BD2BCBA2-AB2C3B2CBA2-2A2(B2C)B2A3-2AB3CB2A5-2C3B2C60-3C6-2(11A2-)A9BA2-AB7CBA2-ABC5B2(CBA2-ABCB3HB)2(CBA2-ABC5B)CBA2-ABCBF3BCBA2-ABC2B2FBCBA2-ABCB2F2B2(CBA2-ABC2B2FBCBA2-ABCB3FB)CBA2-ABCB2F2BCBA2-ABCB3FBCBA2-ABC2(BF)BCBA2-ABCB3FBCBA2-ABC5BCBA2-A2BC3BC2BA2-2A2B3C2B2A2-3A5B3A3-9A5-7C60-3C10-3D6-11A-299A-11A3-2C5A2C6-5C10-2(C12-)C10-2(C3AC8-5D5-11A-299A-11A3-2C5A2C6-5C9-3C2(10-CAC)9-)C3AC8-5D5-11A-299A-11A3-2C5A2C6-5C10-2(C12-)C10-C3AC8-5D4-
