model
size = 11 28 11, scale = 0.05, origin = -y
material deform = 1, fade = true, lighting = smooth, roughness = 0.3, metalness = 0.6
  colors = A:#EEE B:#CAAD5F C:#E83015 D:#FBE251 E:#AAA F:#BBB G:#C4C4C4 H:#FFFFFB I:#313131
voxels
26-3A7-5A4(6-5C)17(6-5A)6-5D7-3D29-5E5-2(2A3B2A4-)7C4-A6C2(4-7C)4-4AB2A7(4-7A)3(4-D6A)2(4-7A)2(4-4AB2A)2(4-2A3B2A)4-2D3-2D5-5D7-3E8-3F6-2E3A2E3-2(2A5B2A2-)9C2-2A7C2(2-9C)2-5A2BA2(H2-8A)H2(2-9A)2-8AH2-9A2-D7AG2-C8A2-C7AG2-C8A2-D7AG2-9A2(2-5A2B2A)2(2-2A5B2A)2-2D5-2D3-7D5-E3-E6-F3-F4-2EA3EA2E2-A7BA-2A7B2A4C4B3C3AC2(4B7C)2A2B3CD5A2(2B2AI6A)2B2AH6A2(2B9A)2BA2HD5A2B3AC5A2BA2GC5A2B9A2BA2GC5A2B3AC5A2BA2GD5A2(2B9A)2B2(6A5B)3A2D7-2D-9D3-E5-E4-F5-F3-EA5EAE-2A7B4A7B2A4C4B3C3AC4B7C4B3CD3C4B3CG2A5B2AHD2A2(5B2AH3A)2(5B6A)5BA2H2(C2A5B3A)C2A5B6A5BA2G2(C2A5B3A)C5A2(2B9A)2B2(6A5B)3A2D7-5D2-F5D-E3-6F2-F5-F3-EA5EAE-2A7B4A7B2A4C4B3C3AC4B3CD2(3C4B3CG)2A5B2AIG2A5B2AID2A5B2AH3A2(5B6A)5B3AC2A5B6A5B2AGC2A5B6A5BA2GC2A5B3AC2A5BA2GC2A4(5B6A)5B3A2D7-5D2-F5D-E3-F-2(F2-)F5-F3-EA5EAE-2A7B4A7B2A4C4B3C3AC4B7C4B3CD3C4B3CG2A5B2AHD2A2(5B2AH3A)2(5B6A)5BA2HC2A5B3AC2A5B2AGC2A5B6A2(5B3AC2A)5BA2GC2A3(3B8A)5B6A5B3A2D7-5D2-F5D-E3-6F2(3-F)4-2EA3EA2E2-A7BA-2A7B2A4C4B3C3AC2(4B7C)2B2A3CD2A2(3B4AI3A)3B4AH3A2(3B8A)3B3A2HD2A3B5AC2A3B3A2GC2A3B8A3B3A2GC2A3B5AC2A3B3A2GD2A3(3B8A)5B6A5B3A2D7-2D-9D3-E5-E6-3F6-2E3A2E3-2(2A5B2A2-)9C2-2A7C2(2-9C)2-2A3B3A2(H2-8A)H2(2-9A)2-8AH2-9A2-D7AG2-C8A2-C7AG2-C8A2-D7AG2-9A2(2-2A3B4A)2(2-2A5B2A)2-2D5-2D3-7D5-E3-E17-5E5-2(2A3B2A4-)7C4-A6C2(4-7C)4-2A2B3A7(4-7A)3(4-D6A)2(4-7A)2(4-2A2B3A)2(4-2A3B2A)4-2D3-2D5-5D7-3E30-3A7-5A4(6-5C)17(6-5A)6-5D7-3D15-
