model
size = 20 31 10, scale = 0.05, origin = -y
material deform = 1, fade = true, lighting = smooth, roughness = 0.3, metalness = 0.6
  colors = A:#B00 B:#EEE C:#700 D:#CC0 E:#222 F:#BBB G:#E00
voxels
310-2A18-2A292-13C7-2C4(FB)F2C7-2C9G2C7-2C4(BF)B2C7-13C111-5A14-7A12-8A12-3(9A11-)9A12-6A16-4A71-B10-B2(6-5B)3-7B4-7B-8B4-7B-9B2-9B-7B4-7B2-7B4-7B3-2(5B6-)B10-B9-11C8-2C4(FB)F2C7-2C-7G-2C7-2C4(BF)B2C8-11C92-5A13-8A12-9A10-4(11A9-)11A10-9A12-7A14-5A50-3B8-3B2(4-7B)-8B3-8B-9B2(2-18B)2-9B-7B3-8B2-2(7B4-)2(3B8-)11C8-C-4(FB)F-C7-C3-5G3-C7-C-4(BF)B-C8-11C74-2A15-6A13-8A11-10A10-11A9-11A2(8-12A)9-11A10-9A12-7A14-5A49-5B6-5B3-7B4-7B-9B4(2-18B)2-9B-7B4-7B3-5B6-5B8-9C10-C9-C8-2C9-2C8-C9-C10-9C75-2A15-6A13-9A10-10A10-11A9-11A2(8-12A)9-11A10-9A11-8A14-5A49-5B6-5B3-7B4-7B-9B4(2-18B)2-9B-7B4-7B3-5B6-5B189-6A13-8A11-10A10-4(11A9-)11A10-9A12-7A14-5A49-5B6-5B3-7B4-7B-9B4(2-18B)2-9B-7B4-7B3-5B6-5B190-5A14-7A12-9A10-10A10-3(11A9-)11A10-8A13-6A16-4A69-5D6-5D3-3DE3D4-3DE3D2-2D3E2D4-2D3E2D2-D5ED4-D5ED2-2D3E2D4-2D3E2D2-3DE3D4-3DE3D3-5D6-5D211-3A15-6A13-8A12-9A3(10-10A)11-9A12-7A14-5A131-E10-E7-3E8-3E7-E10-E273-4A14-6A14-7A12-8A12-9A11-8A12-8A14-5A17-A478-3A16-5A3(14-6A)15-5A287-
