model
size = 31 22 31, scale = 0.05, origin = -y
material deform = 1, fade = true, lighting = smooth, roughness = 0.3, metalness = 0.6
  colors = A:#444 B:#1B813E C:#111 D:#FCFAF2 E:#DDD F:#ADFF2F G:#777
voxels
260-7A24-2B3F2B24-7A582-7A21-13A18-13B18-13A21-7A548-13A16-17A14-17B14-17A16-13A486-7C24-7C19-17A13-19A12-19B12-19A13-17A19-7C24-7C425-11C20-11C16-19A11-21A10-F19BF10-21A11-19A16-11C20-11C421-6C3E6C16-15C13-21A9-23A8-F21BF8-23A9-21A13-15C16-6C3E6C361-3BE3B24-7B19-17C14-17C11-23A7-25A6-25B6-25A7-23A11-17C14-17C19-7B304-5B23-11B20-11B16-19C12-19C9-25A5-27A4-27B4-27A5-25A9-19C12-19C16-11B271-2BE2B24-9B20-13B18-13B14-21C10-21C8-25A5-27A4-27B4-27A5-25A8-21C10-21C14-13B239-5B24-9B20-13B17-15B16-15B13-21C10-21C7-27A3-29A2-29B2-29A3-27A7-21C10-21C13-15B21-C4D26-C4D179-3BEBE3B21-11B19-13B16-17B14-17B11-23C8-23C6-27A3-29A2-29B2-29A3-27A6-23C8-23C11-17B18-9D22-4D3F2D24-C4D26-C4D116-5BE5B19-13B17-15B15-17B14-17B11-9CB13C8-23C6-27A3-29A2-29B2-29A3-27A6-23C8-23C11-17B17-11D20-5D3-3D22-7D24-3D2(FD)25-5C26-C4D54-11B19-13B17-15B14-19B12-19B9-25C6-25C4-29A-31A31B31A-29A4-25C6-25C9-19B16-11D20-5D2(27-2DCD)2(28-DCD)30-F25-4BE3BE4B17-15B15-17B13-19B12-19B9-25C6-25C4-29A-31A31B31A-29A4-25C6-25C9-19B15-6D5C2D18-4DC7-D19-3DC27-3D2(C28-2D)C30-C26-2(BE3BE)B17-15B15-17B13-19B12-19B9-2CE19CE2C6-25C4-29A-31AF29BF31A-29A4-25C6-2CE19CE2C9-19B15-6D5C2D18-4DC7-D19-3DC27-3D2(C28-2D)C29-DC26-2B2(E3B)E2B17-E13BE15-17B13-E17BE12-19B9-2CE19CE2C6-25C4-14AC14A-31AF14BG14BF31A-29A4-25C6-2CE19CE2C9-19B15-C3DCD5C2D18-C3DC7-D19-C2DC27-C2D2(C28-CD)C29-2C26-2(BE3BE)B17-15B15-17B13-19B12-19B9-2CE19CE2C6-25C4-29A-31AF29BF31A-29A4-25C6-2CE19CE2C9-19B15-4DCD5C2D18-4DC7-D19-3DC27-3D2(C28-2D)C29-DC26-4BE3BE4B17-15B15-17B13-19B12-19B9-25C6-25C4-29A-31A31B31A-29A4-25C6-25C9-19B15-4DCD5C2D18-4DC7-D19-3DC27-3D2(C28-2D)C30-C27-11B19-13B17-15B14-19B12-19B9-25C6-25C4-29A-31A31B31A-29A4-25C6-25C9-19B16-3DC7D20-3D2(CD27-2D)2(CD28-D)CD30-F26-5BE5B19-13B17-15B15-17B14-17B11-23C8-23C6-27A3-29A2-29B2-29A3-27A6-23C8-23C11-17B17-3DC7D20-3DCD3-3D22-DC5D24-DC2(DF)D25-C4D26-5C55-3BEBE3B21-11B19-13B16-17B14-17B11-23C8-23C6-27A3-29A2-29B2-29A3-27A6-23C8-23C11-17B18-9D22-2DCD3F2D24-C4D26-C4D119-5B24-9B20-13B17-15B16-15B13-21C10-21C7-27A3-29A2-29B2-29A3-27A7-21C10-21C13-15B21-5D26-C4D212-2BE2B24-9B20-13B18-13B14-21C10-21C8-25A5-27A4-27B4-27A5-25A8-21C10-21C14-13B301-5B23-11B20-11B16-19C12-19C9-25A5-27A4-27B4-27A5-25A9-19C12-19C16-11B332-3BE3B24-7B19-17C14-17C11-23A7-25A6-25B6-25A7-23A11-17C14-17C19-7B392-6C3E6C16-15C13-21A9-23A8-F21BF8-23A9-21A13-15C16-6C3E6C421-11C20-11C16-19A11-21A10-F19BF10-21A11-19A16-11C20-11C425-7C24-7C19-17A13-19A12-19B12-19A13-17A19-7C24-7C486-13A16-17A14-17B14-17A16-13A548-7A21-13A18-13B18-13A21-7A582-7A24-2B3F2B24-7A353-
