model
size = 8 25 5, scale = 0.05, origin = -y
material deform = 1, fade = true, lighting = smooth, roughness = 0.3, metalness = 0.6
  colors = A:#3CF B:#003 C:#399 D:#0F6 E:#050 F:#6F0 G:#6C0 H:#093 I:#3F3 J:#0F0 K:#080 L:#0F9 M:#060
voxels
5C3-5C71-4B4-4B104-5C3-5C5-3(A7-)A2-A2(4-A2-B)4-2(A2-2B3-)A-B-EB2-A-BGEB2-A2-MD3-11(A7-)A5-5C3-2(CA)C4-A-A5-A-3A3-2(A-)A3-2(A-)2A4(2-2(A-)2B)2-A-AB-KB2(-A)BDFB2(-A)-DG2-11(A-A5-)A-A4-5C3-5C5-3(A7-)A2-A2(4-A2-B)4-2(A2-2B3-)A-BDJB2-A-BHLB2-A2-FI3-11(A7-)A5-5C3-5C71-4B4-4B104-
