model
size = 29 8 32, scale = 0.05, origin = -y
material deform = 1, fade = true, lighting = smooth, roughness = 0.3, metalness = 0.6
  colors = A:#3CF B:#EEE C:#963 D:#555 E:#777 F:#888 G:#444
voxels
15-2C200-2C24-6(7A22-)2A3-2A22-2A3-2A19-6(13A16-)5A3-5A16-5A3-5A14-2(17A12-)5(5A7-5A12-)5A7-5A11-2(19A10-)5(4A11-4A10-)4A11-4A9-2(21A8-)5(3A15-3A8-)3A15-3A7-2(23A6-)5(3A17-3A6-)3A17-3A5-2(25A4-)6(3A19-3A4-)2(25A4-)5(2A21-2A4-)2A21-2A3-2(27A2-)6(3A21-3A2-)27A2-10AD16A6(2-2A23-2A)2(2-27A)6(2-2A23-2A)-60A5(25-4A)25-62A5(25-4A)25-42AED18A3(25-4A)25-2A58-40AE19A3(25-4A)25-2A58-40A2EA2E15A3(25-4A)25-2A58-46AE2AD10A5(25-4A)25-41AD6AE13A5(25-4A)25-2A-27A2-13A3DEAD8A6(2-2A23-2A)2-27A2-12A2DA2E10A6(2-2A23-2A)2-27A2-10A2DF2E12A6(2-3A21-3A)3-25A4-12A2F11A6(4-2A21-2A)2(4-25A)4(4-3A19-3A)4-3A9-DE8-3A4-3A9-GF8-3A5-23A6-13AD9A4(6-3A17-3A)2(6-3A8-2B7-3A)7-2(21A8-)4(3A15-3A8-)3A7-2B6-3A8-3A7-2B6-3A9-2(19A10-)4(4A11-4A10-)4A5-2B4-4A10-4A5-2B4-4A11-2(17A12-)4(5A7-5A12-)5A3-2B2-5A12-5A3-2B2-5A14-6(13A16-)5A-2B5A16-5A-2B5A19-6(7A22-)2A-CB2A22-2A-2C2A199-2C27-2C201-2C27-2C13-
