model
size = 21 26 23, scale = 0.05, origin = -y
material deform = 1, fade = true, lighting = smooth, roughness = 0.3, metalness = 0.6
  colors = A:#800 B:#E00 C:#96C D:#700 E:#060808 F:#0D1111 G:#000 H:#400 I:#FFFA00 J:#C66 K:#000124 L:#0D0 M:#F08E00
voxels
133-MC190-2AK17-3AGL16-2B2AG16-2BA2B17-4B18-E20-2E19-2F20-F163-M19-2C169-4B16-5AB14-B6A2(14-7A)14-B5AB15-5AB17-A205-2C19-2C147-A19-A2B2A2B14-6AI14-3(7AB13-)7A14-B5AB15-5H203-2C19-2C126-2B19-AB18-B6A14-6AI13-B7AG12-2(B8AB11-)8AB13-7A15-5B95-D5-D101-2C126-2B19-BA19-2A18-B6A14-6AI13-B7AG12-2(B8AB11-)8AB13-7A15-5B95-D5-D14-D5-D80-2C104-2B19-2BA19-2B19-3B18-5AB14-6AI13-2(B7AB12-)B2(7AB13-)B6A15-5A95-J5-J14-D5-D80-2C83-2B19-BA19-3B62-5B15-5AB14-B6A2(14-7A)14-B5AB15-5AB17-A97-J5-J14-D5-D37-5B13-9B11-5B2C4B10-5B2-3B14-2B2-2B19-A19-BA19-2B105-A-K17-3AGL16-2B2AG16-2BA2B17-4B18-E20-2E19-2F20-F75-D5-D12-A3(B2A)B9-4(2AB)A8-2B9-2B8-2A9-BA8-2AB7-ABA8-12BA10-2(B2A)B19-2B172-2AK17-3AGL16-2B2AG16-2BA2B17-4B18-E20-2E19-2F20-F30-7B10-3(2AB)2A-A7-B2A9-BA7-2B11-BA6-BA11-2A6-BA11-A8-3B7-3B9-A3(B2A)B169-4B16-5AB14-B6A2(14-7A)14-B5AB15-5AB17-A70-11B2(9-2B)7-2B11-B2(A6-B13-)A6-2B11-BA6-3B9-2BA7-13B11-9B2(19-2B)19-5B19-2B20-B18-5B16-2B2A2B14-6AI14-3(7AB13-)7A14-B5AB15-5H68-11B9-2A9-BA7-BA11-2A3(6-B13-A)6-2B11-BA8-A3(B2A)BA11-2(2AB)A3(BA19-)4BA19-BA20-A18-4A2B14-B6A14-6AI13-B7AG12-2(B8AB11-)8AB13-7A15-5B68-11B9-2AB7-ABA7-BA11-2A6-2B11-BA6-B13-A6-BA11-2A6-3B9-2BA9-2(B2A)B3A3(20-B)20-4B19-2B20-B18-4A2B14-B6A14-6AI13-B7AG12-2(B8AB11-)8AB13-7A15-5B72-6B10-13B8-2(3B7-)3B9-2BA6-2B11-BA6-3B9-2BA7-13B11-7BA19-2B99-2AK17-3AGL3-5A8-2B2AG3-5AB7-2BA2B2-6AI8-4B-B7AB8-E3-B7AB8-2E2-B7AB8-2F3-7AB9-F3-B6A15-5A70-D5-D13-3(B2A)11-A3(B2A)B9-13B2(8-4(2AB)A)9-11B18-2B19-BA19-2B57-4B16-5AB14-B6A14-7A3-5B6-7A2-5AB6-B5AB-B6A7-5AB-7A9-A4-7A14-B5AB15-5AB17-A51-J5-J14-D5-D56-7A14-3A2C2A83-2B18-2BA18-3B14-5B16-2B2A2B14-6AI14-2(7AB13-)7AB2-A-K8-7A2-3AGL7-B5AB2-2B2AG8-5H3-2BA2B17-4B18-E20-2E19-2F20-F8-J5-J14-D5-D80-2C104-4B17-3BA14-4A2B14-B6A14-6AI13-B7AG12-2(B8AB11-)8AB13-7A15-5B120-D5-D14-D5-D80-2C104-B20-B17-4A2B14-B6A14-6AI13-B7AG12-2(B8AB11-)8AB13-7A15-5B120-D5-D101-2C143-5A16-5AB14-6AI13-2(B7AB12-)B2(7AB13-)B6A15-5A228-2C19-2C144-5B15-5AB14-B6A2(14-7A)14-B5AB15-5AB17-A230-2C19-2C165-A-K17-3AGL16-2B2AG16-2BA2B17-4B18-E20-2E19-2F20-F188-M19-2C544-MC411-
