model
size = 16 31 31, scale = 0.05, origin = -y
material deform = 1, fade = true, lighting = smooth, roughness = 0.3, metalness = 0.6
  colors = A:#222 B:#333 C:#444 D:#555 E:#666 F:#777 G:#888 H:#999 I:#AAA J:#BBB K:#CCC L:#663 M:#996 N:#DDD O:#FFF P:#966 Q:#EEE R:#99C
voxels
292-5B11-6B10-6B11-4B426-4B12-5(7B9-)7B10-6C376-6B10-4(9B7-)2(9C7-)9C8-8E8-7D345-7B8-9B3(6-10B)2(6-10C)7-9C7-9D8-8D8-7D329-3B-4B7-9B6-2(11B5-)11C5-11D5-2(10D6-)10E7-9D8-8E9-5C44-7A9-6A11-5A3(10-6A)10-5A11-5B11-4A74-7B7-4(10B6-)11D5-12B4-12C4-5C-6C4-5D-6D4-12D4-2(11E5-)11E6-9F8-7C41-10A6-10A7-9A2(6-10A)6-10C6-9A7-9A3(5-11A)5-10A6-3(11B5-)12C4-12B4-13B2-13D3-2(14C2-)2(6D2-)5D3-6D2-6E-6E3-13E4-11F5-11E6-9E8-7C11-3B25-12A4-13A5-11A4(3-13A)3-4(12A4-)13A3-12A4-13B3-13B2-14B2-15B-15D-15E2(-15D)-6D2-7D-5E3-7E-5E3-6E2-6F-7F2-13F4-11E6-10D6-8B10-5C24-13A3-5(14A2-)4(13A3-)14B2-14A2-15A16B16D32B16E16C16D16F5E3-12E4-7E-5E3-7E-6F-7F2-13F4-12E5-10D6-9C8-6C23-8A-6A2-4(7A-)15A16C-14A4(-15A)-32A32B16D6B-9B6C2-13C3-8C5D4-12D3-8D5E3-8E5F2(-15F)3-7F-5F3-6F2-6F-7F4-11F5-10D6-9B8-7C10-5C7-7A2-A-13A-A-5A-7A-A-5A8C-C-5C10A-5A-15A-47A16C16A64B6C-15C2-13C3-8C5D4-7D4E4-8E4F4-12F2-10F4G2-10G5F3-13F3-7F-6F-7F3-13F3-12C5-10C7-8B9-5B7-6A4-12A4-6A7B3-6B7A2(3-6A-6A)3-6A7B2-7B7A2(2-14A)2-7A7B2-13B4-6B5C5-6C5B5-11B5-6B4C6-6C4D6-10D6-6D4E7-5E4G7-8G8-8G7-10G6-6G4F5-12F3-7F-6G-7G3-13E3-12C5-10C7-3C13-2B11-5A6-3(11A5-)2(5A-5A5-)11A3(4-12A)4-6A6B5-5B5D6-5D5B7-8B7-5B4C7-9C7-5C4D7-5D3E8-5E3F9-4F3G9-4G3I8-5I3H8-9H6-6H4G5-12G3-7G-6G-7G3-13E3-12C5-10D6-3C14-B12-5A6-10A6-2(11A5-)5A-5A2(5-11A)5-10A6-9A7-5A4B7-9B2(8-8B)8-4B4D8-4D3C9-4C3D9-4D3E9-4E3F9-4F3G9-4G3H9-4H3I9-7I8-5I4H6-10H6-11H4-6H-5G3-6G3-13L3-12C5-10C6-3C14-B12-5A7-9A7-2(10A6-)4A-5A2(6-10A)6-9A7-4A4B8-4B4D8-4D2(3B10-3B3C10-3C)3D10-6D10-3D3F10-3F3G10-3G3H10-3H3I9-4I3J9-8J7-9J7-5J4I6-6I5H4-6H-5F3-6F3-5D-7D3-12D5-4D3-3D6-3C14-A12-5B7-4B5A7-10A2(6-4A-5A)6-10A6-9A7-8A8-4A4B8-8B8-7B10-3B3C10-6C10-3C3D10-6D10-3D3E10-3E3F10-3F3H10-3H3R10-3R3K9-7K9-8K7-5K4J7-5J4I6-6I5M5-5M-5L3-6L3-5L2-6L3-5D2-5D5-4C3-3C6-3B14-A12-5A2(7-9A)2(7-4A-4A)2(7-9A)7-4A4B8-4B4E8-4E4B8-4B3C2(9-7C)9-4C3D9-4D3E9-4E3F9-4F3G10-3G3I10-3I3K10-3K3N9-7N9-8N7-5N4J7-5J4H6-6H5M5-5M-5C3-6C3-5C2-6C3-5D2-5D5-4C3-3C6-3A14-A12-5A2(7-9A)7-4A-4C7-4C-4A7-9A7-4A5B7-3(8B8-)4B4C8-8C8-4C4D8-8D8-4D4E8-4E4G8-4G4H9-3H3J10-3J3Q10-3Q3O9-4O3Q9-4Q4N7-5N4J7-5J4H6-6H5P4-6P-5C3-6C3-5C-7C3-12C5-4B3-3B6-3A14-A13-4A6-11A5-5A6D5-5D-5A5-5A-5A5-10A6-5A5B3(6-10B)6-5B5C7-4C5D7-9D7-4D4E8-4E4G8-4G4H8-4H4I8-4I4N8-4N3O2(9-7O)9-4O3K8-5K4I6-6I4M6-6M5L4-6L-5C2-7C3-13C3-12C5-10B6-3A14-A13-5A2(5-11A)2(5-5A-5A)5-11A5-5A6B2(5-11B)5-5B6C5-10C6-5C5D6-5D5E6-5E4F7-5F4G7-5G4I7-5I4K7-5K4N7-5N3Q9-4Q3O9-4O3N8-5N3J8-5J4M6-6M4P5-7P5C3-7C-6D-7D3-13C3-12C5-10A6-3A14-B13-5A4-3(13A3-)6A-6A3-6A-6B2(3-13B)3-6B7C3-12C3-13C3-7C5D4-7D5E4-7E5F4-7F4I6-10I6-6I4K6-6K4N6-6N4Q6-6Q4N7-5N3K8-5K3H7-6H4M6-6M4L5-7L5C3-7C-6C-7C3-13C3-12B5-10A7-3C13-2A12-7A2(-6A-8A)-7A2(-15A)4(-15B)-15C16D32E16G16H6I-9I6J2-8J5K3-13K4-12K4-7K4I6-6I4M5-7M4P5-7P5C3-13C3-6C2-6C-7C3-13C3-11B6-9A8-7A10-5A9-2(13A3-)14A2(-15A)4(2-14B)-15C-15D16E-15F16G16H16I48J16I16M5E3-8E4L4-8L5C3-7C-6C-7C2-14C3-13B4-10A6-9A8-6A25-12A4-12A5-12A3-2(14A2-)2(13B3-)12B4-12B3-13C3-14D2-14E2-15E2(-15G)16H48I16H16G6L2-8L5B3-8B5C3-6C2-6C-7C2-14C3-11B6-10D6-8A10-5A26-11A5-10A7-9A3(6-10B)6-9B7-9B2(6-10C)6-10D6-11E5-2(13F3-)14F-15H2(-15G)16H16G16F6E2-7E-5D3-6D2-6E-6E3-14C3-11B5-11B6-9A8-7A11-3A29-7B9-6A11-5A3(10-6B)10-2(5B11-)4C74-7E8-2(9G7-)9F7-9F6-11G5-12F4-12E4-5C-5C5-5C-7C3-13C3-2(11B5-)11A6-9A8-7A313-3E-4E7-9E6-11L5-11D2(5-11C)5-10C2(6-10B)7-9A8-8E9-5A314-7D8-9E6-10D3(6-10C)6-10B7-9C7-9A8-8A8-7A328-6E10-2(9C7-)4(9B7-)9B8-8A8-7A345-4D12-7C5(9-7B)10-6A394-5C11-6C10-6C11-4C151-
