model
size = 10 7 8, scale = 0.05, origin = -y
material deform = 1, fade = true, lighting = smooth, roughness = 0.3, metalness = 0.6
  colors = A:#9CF B:#FFF C:#1E1414 D:#FFEFEF
voxels
14-2B8-2B6-6A4-6A25-A2-A2(6-4A)46-A2-A5-A-2A-3(A4-)6A43-2(A6-A2-)A6-A3-6A2(4-A-2A-A)3-2(A6-A2-)A6-A3-A4-A3-2(2A4-)D2AD14-A6-A2-A6-A3-A4-A3-A6-A2-2A4-2(2A-)4A-3A8-A-A6-A3-A4-A3-A6-A2(2-2A4-2A)4-B2AB24-A-C2-C-A2-2(A-)2A-A2-A6-A3-6A2(4-A-2A-A)2-
