model
size = 20 32 26, scale = 0.05, origin = -y
material deform = 1, fade = true, lighting = smooth, roughness = 0.3, metalness = 0.6
  colors = A:#630 B:#555 C:#888 D:#996 E:#800 F:#777 G:#AAA H:#444 I:#6F3 J:#111
voxels
64-3(I2(19-D)19-)I418-2(7A13-)2(7D13-)2(7A2(13-7D)13-)7A15-4A14(16-A2-A)16-A-EA16-A-J2(A16-A2-)A53-2(9A11-)2(9D11-)2(9A2(11-9D)11-)2(9A11-)16(4ABC3A11-)4ABC3A14-A2-A16-A2-A13-10A12(9-11A)2(9-5ABC4A)3-A5-5ABC4A3-2A4-5ABC4A4-A4-5ABC4A4-2A3-5ABC4A5-A3-5ABC4A5-2A2(2-5ABC4A6-A)2-5ABC4A6-2A5(-5ABC4A7-A)-5ABC4A6-2A-5ABC5A5-A3-4ABC3A-2A3-2A6-A2-A4-5A4-10A9-11A2(9-D10A)9-11A9-D10A9-D9ADB8-10AD2(B8-D10A)D8-11A2D2(7-D10A-D)7-5ABC4A-2D5-EF4ABC4A2-DA4-2J4ABC4A3-2A4-5ABC4A4-A4-5ABC4A4-2A3-5ABC4A5-A3-5ABC4A5-2A2(2-5ABC4A6-A)2-5ABC4A6-2A5(-5ABC4A7-A)-5ABC4A6-2A-5ABC5A5-A3-4ABC3A-2A3-2A6-A2-A4-5A4-10A9-11A2(9-D10A)9-11A9-D10A9-D9ADB8-10A2D8-D10AB8-D10AD8-11A2D2(7-D10A-D)7-5ABC4A-2D6-F4ABC4A2-DA5-G4ABC4A3-2A4-5ABC4A4-A4-5ABC4A4-2A3-5ABC4A5-A3-5ABC4A5-2A2(2-5ABC4A6-A)2-5ABC4A6-2A5(-5ABC4A7-A)-5ABC4A6-2A-5ABC5A5-A3-4ABC3A-2A3-2A6-A2-A4-5A4-10A9-11A9-D10A8-2D10A2(8-H11A2(8-2D10A))8-H11A2(9-D10A)9-5ABC4A9-F4ABC4A3-A5-G4ABC4A3-2A4-5ABC4A4-A4-5ABC4A4-2A3-5ABC4A5-A3-5ABC4A5-2A2(2-5ABC4A6-A)2-5ABC4A6-2A5(-5ABC4A7-A)-5ABC4A6-2A-5ABC5A5-A3-4ABC3A-2A3-2A6-A2-A4-5A4-3(10A4(9-11A2(9-D10A))9-5ABC4A9-F4ABC4A9-G4A14(BC4A9-5A)BC4A10-4ABC3A14-A2-A13-)4(10A4(9-11A2(9-D10A))9-5ABC4A9-F4ABC4A9-G4A8(BC4A9-5A)4(BC4A8-E5A)2(BC4A9-5A)BC4A10-4ABC3A14-A2-A13-)2(10A4(9-11A2(9-D10A))9-5ABC4A9-F4ABC4A9-G4A8(BC4A9-5A)2(BC4A8-H5A)2(BC4A8-E5A)2(BC4A9-5A)BC4A10-4ABC3A14-A2-A13-)10A4(9-11A2(9-D10A))9-5ABC4A9-F4ABC4A9-G4A8(BC4A9-5A)BC4A8-E5ABC4A8-H2(5ABC4A8-E)2(5ABC4A9-)5ABC4A10-4ABC3A14-A2-A13-10A4(9-11A2(9-D10A))9-5ABC4A9-F4ABC4A9-G4A14(BC4A9-5A)BC4A10-4ABC3A14-A2-A13-10A9-10AE3(2(9-D10A)9-11A)2(9-D10A)9-5ABC4A9-F4ABC4A9-G4A14(BC4A9-5A)BC4A10-4ABC3A14-A2-A13-10A9-11A9-D9AE9-D10A3(9-11A2(9-D10A))9-5ABC4A9-F4ABC4A9-G4A14(BC4A9-5A)BC4A10-4ABC3A14-A2-A13-10A9-10AE3(2(9-D10A)9-11A)2(9-D10A)9-5ABC4A9-F4ABC4A3-A5-G4ABC4A3-2A4-5ABC4A4-A4-5ABC4A4-2A3-5ABC4A5-A3-5ABC4A5-2A2(2-5ABC4A6-A)2-5ABC4A6-2A2(-5ABC4A7-A)-5ABC4A7-D-5ABC4A7-A-5ABC4A7-D-5ABC4A6-2A-5ABC5A5-A3-4ABC3A-2A3-2A6-A2-A4-5A4-10A9-11A9-D9AE9-D10A9-11A9-D10A9-D9ADB8-10A2D8-D10AB8-D10AD8-11A2D2(7-D10A-D)7-5ABC4A-2D6-F4ABC4A2-DA5-G4ABC4A3-2A4-5ABC4A4-A4-5ABC4A4-2A3-5ABC4A5-A3-5ABC4A5-2A2(2-5ABC4A6-A)2-5ABC4A6-2A2(-5ABC4A7-A)-5ABC4A7-D-5ABC4A7-A-5ABC4A7-D-5ABC4A6-2A-5ABC5A5-A3-4ABC3A-2A3-2A6-A2-A4-5A4-10A9-10AE2(9-D10A)9-11A9-D10A9-D9ADB8-10AD2(B8-D10A)D8-11A2D2(7-D10A-D)7-5ABC4A-2D6-F4ABC4A2-DA5-G4ABC4A3-2A4-5ABC4A4-A4-5ABC4A4-2A3-5ABC4A5-A3-5ABC4A5-2A2(2-5ABC4A6-A)2-5ABC4A6-2A2(-5ABC4A7-A)-5ABC4A7-D-5ABC4A7-A-5ABC4A7-D-5ABC4A6-2A-5ABC5A5-A3-4ABC3A-2A3-2A6-A2-A4-5A4-10A12(9-11A)2(9-5ABC4A)3-A5-5ABC4A3-2A4-5ABC4A4-A4-5ABC4A4-2A3-5ABC4A5-A3-5ABC4A5-2A2(2-5ABC4A6-A)2-5ABC4A6-2A2(-5ABC4A7-A)-5ABC4A7-D-5ABC4A7-A-5ABC4A7-D-5ABC4A6-2A-5ABC5A5-A3-4ABC3A-2A3-2A6-A2-A4-5A24-2(9A11-)2(9D11-)2(9A2(11-9D)11-)2(9A11-)16(4ABC3A11-)4ABC3A14-A2-A16-A2-A34-2(7A13-)2(7D13-)2(7A2(13-7D)13-)7A15-4A18(16-A2-A)31-
