model
size = 29 20 29, scale = 0.05, origin = -y
material deform = 1, fade = true, lighting = smooth, roughness = 0.3, metalness = 0.6
  colors = A:#CC0 B:#CF0 C:#03C
voxels
8-2(13A16-)13A507-2(17A12-)17A505-2(17A12-)17A504-2(20A9-)20A13-6(10A19-)10B7(19-10A)2(19-10B)42-2(6A10-7A6-)6A10-7A9-6(3A10-4A12-)3B10-4B7(12-3A10-4A)2(12-3B10-4B)15-10A13-2(6A10-7A6-)6A10-7A9-6(3A10-4A12-)3B10-4B7(12-3A10-4A)2(12-3B10-4B)15-10A12-2(4A17-5A3-)4A17-5A6-6(A17-2A9-)B17-2B7(9-A17-2A)2(9-B17-2B)10-17A8-2(4A17-5A3-)4A17-5A6-2(6(A17-2A9-)B17-2B7(9-A17-2A)2(9-B17-2B)10-17A6-6A2(17-12A)17-6A5-)6(A17-2A9-)B17-2B7(9-A17-2A)2(9-B17-2B)10-17A6-10(5A2(20-9A)20-4A3-6(2A20-A6-)2B20-B7(6-2A20-A)2(6-2B20-B)8-20A4-)6A2(17-12A)17-6A5-2(6(A17-2A9-)B17-2B7(9-A17-2A)2(9-B17-2B)10-17A8-2(4A17-5A3-)4A17-5A6-)6(A17-2A9-)B17-2B7(9-A17-2A)2(9-B17-2B)10-17A9-2(6A10-7A6-)6A10-7A9-6(3A10-4A12-)3B10-4B7(12-3A10-4A)2(12-3B10-4B)15-10A15-2(20A9-)20A13-6(10A19-)10B7(19-10A)2(19-10B)44-2(20A9-)20A13-6(10A19-)10B7(19-10A)2(19-10B)45-2(17A12-)17A507-2(13A16-)13A21-3A27-A457-13A16-6AC6A16-5A3C5A20-A3CA25-ACA27-A420-
