model
size = 16 24 18, scale = 0.05, origin = -y
material deform = 1, fade = true, lighting = smooth, roughness = 0.3, metalness = 0.6
  colors = A:#FCFAF2 B:#E2943B C:#FFB11B D:#FFC408 E:#BDC0BA F:#F9BF45 G:#222 H:#F7D94C I:#D0104C J:#CB1B45 K:#111
voxels
21-2A2-2A10-2A2-2A9-2(8A8-)E6AE6-2(5A2-5A4-)2A2-4A2-2(2A4-A4-)A4-2A2(4-A)4-2A4-A3(4-12A)5-10A7-8A11-2A221-4A11-3(6A10-)6A11-4A267-6A9-8A7-5(10A6-)10A7-8A9-6A204-2A11-8A7-10A5-2(12A4-)12A3-14A2-14A3-2(12A4-)12A5-10A7-8A11-2A171-8A7-E8AE5-12A3-2(14A2-)14A-32A-2(14A2-)14A3-12A5-10A7-8A11-2B3(14-2C)30-2D14-2D58-10A6-E8AE4-14A-128A-14A3-12A5-10A7-8B2(8-8C)8-C2-2C2-C8-C6-C11-2D14-2D58-10A6-E8AE3-160A-14A3-12A5-10B6-FH6AH3(F6-FC6-C)F6-J8-J70-10A6-E8AE3-176A-14A3-12B4-CH8AHC3(4-2C8-2C)85-10A6-E8AE3-176A-14A3-12B4-C10AC4-C3-4A3-C117-10A6-E8AE3-176A-14A3-12B4-C10AC4-C2-6A2-C117-10A6-E8AE3-192A-14B2-2C10A2(2C2-)6A2(2-2C)10-2C18-2D10-2D2-2D10-2D52-10A6-E8AE3-192A-14B2-2C10A2(2C2-)6A2(2-2C)10-2C18-2D10-2D2-2D10-2D4-3(A8-A6-)10A6-E8AE3-176A-14A3-12B4-C10AC4-F2-6A2-F69-3(A8-A6-)10A6-E8AE3-176A-14A3-12B4-C10AC4-F3-4A3-F101-2(10A6-)E8AE3-176A-14A3-12B4-CH8AHC3(4-2C8-2C)69-2(10A6-)E8AE3-160A-14A3-12A5-10B6-FH6AH3(F6-FC6-C)F6-J8-J22-2(A8-A6-)2(10A6-)E8AE4-3(14A2-)3AIJ4AJI3A-2(4A2I)20A-3(14A2-)14A3-12A5-10A7-8B8-8C8-C2F2C2FC8-C2-2C2-C8-C6-C11-2D14-2D10-2(A8-A6-)A3-2A3-A6-10A6-E8AE4-2(6A2K6A2-)3A2G4A2G3A2(2-2(2AG2-G)2A)2-2(2A4G)2A3(2-14A)3-12A5-10A7-8A11-2B3(14-2C)30-2D14-2D7-
