model
size = 16 20 18, scale = 0.05, origin = -y
material deform = 1, fade = true, lighting = smooth, roughness = 0.3, metalness = 0.6
  colors = A:#FCFAF2 B:#222
voxels
21-2A2-2A10-2A2-2A9-2(8A8-)8A6-2(5A2-5A4-)2A2-4A2-2(2A4-A4-)A4-2A2(4-A)4-2A4-A3(4-12A)5-10A7-8A11-2A157-4A11-3(6A10-)6A11-4A203-6A9-8A7-5(10A6-)10A7-8A9-6A140-2A11-8A7-10A5-2(12A4-)12A3-14A2-14A3-2(12A4-)12A5-10A7-8A11-2A107-8A7-10A5-12A3-2(14A2-)14A-32A-2(14A2-)14A3-12A5-10A7-8A11-2A90-10A6-10A4-14A-128A-14A3-12A5-10A7-8A87-10A6-10A3-160A-14A3-12A5-10A8-6A72-10A6-10A3-176A-14A3-12A6-8A71-10A6-10A3-176A-14A3-12A5-10A9-4A57-10A6-10A3-176A-14A3-12A5-2(10A8-6A56-10A6-10A3-192A-14A4-)2(10A8-6A2(8-A)2(6-A8-A)2(6-10A)3-176A-14A3-12A5-)10A9-4A25-3(10A6-)10A3-176A-14A3-12A6-8A39-A-6A-A3(6-10A)3-160A-14A3-12A5-10A8-6A24-2(A8-A6-)2(10A6-)10A4-3(14A2-)14A-32A-3(14A2-)14A3-12A5-10A7-8A39-2(A8-A6-)A3-2A3-A2(6-10A)4-6A2B6A2-14A2-3A2B4A2B3A2(2-2(2AB2-B)2A)2-2(2A4B)2A3(2-14A)3-12A5-10A7-8A11-2A39-
