model
size = 25 30 31, scale = 0.05, origin = -y
material deform = 1, fade = true, lighting = smooth, roughness = 0.3, metalness = 0.6
  colors = A:#BBB B:#001
voxels
25-28(23A2-)23A3-2B17-2B3-7(23A2-)7(5A4-14A2-)14(23A2-)23A3-2B17-2B3-7(23A2-)21(2(5A4-)5A2-)2(5A4-)5A27-6A3-14A6(2-23A)18(2-2(5A4-)5A)2-2(5A-2B-)3(5A2-2(5A4-))5A27-7A-3A4-8A6(2-23A)18(2-2(5A4-)5A)2-5A2-B-5A-B2(2-5A)2(4-5A)2(2-2(5A4-)5A)27-7A-2A-12A6(2-23A)18(2-2(5A4-)5A)2-5A2-B-5A-B2(2-5A)2(4-5A)2(2-2(5A4-)5A)27-7A-2A3-10A2-10A3-10A5(2-23A)18(2-2(5A4-)5A)2-2(5A-2B-)3(5A2-2(5A4-))5A27-7A-2A-5A2-2A-2A6(2-23A)18(2-2(5A4-)5A)2-5A-B2-5A2-B-3(5A2-2(5A4-))5A27-7A-3A4-A-3A-2A2-3(23AB-)3(23A2-)18(2(5A4-)5A2-)5A-B2-5A2-B-3(5A2-2(5A4-))5A27-7A-9A3-3A2-23AB-23AB24AB-3(23A2-)18(2(5A4-)5A2-)2(5A-2B-)3(5A2-2(5A4-))5A27-7A-3A4-8A2-23AB-23AB24AB-3(23A2-)2(2(5A4-)5A2-)2(5A4-)4AB15(2-2(5A4-)5A)2-5A2-B-5A-B2(2-5A)2(4-5A)2(2-2(5A4-)5A)27-7A-2A-5A2-A-3A2-3(23AB-)3(23A2-)5(2(5A4-)5A2-)2(5A4-)4AB12(2-2(5A4-)5A)2-5A2-B-5A-B2(2-5A)2(4-5A)2(2-2(5A4-)5A)27-7A-2A-7A-A-2A2-3(23AB-)3(23A2-)2(5A4-)5A2-2(2(5A4-)5AB-)15(2(5A4-)5A2-)2(5A-2B-)3(5A2-2(5A4-))5A27-7A-3A4-A5-2A2-23AB-23AB24AB-3(23A2-)2(5A4-)4A2B-2(5A4-)5A2-2(2(5A4-)5AB-)14(2(5A4-)5A2-)5A-B2-5A2-B-3(5A2-2(5A4-))5A27-7A-15A2-23AB-23AB24AB-2(23A2-)23AB-3(2(5A4-)5A2-)2(2(5A4-)5AB-)2(5A4-)5A2-2(5A4-)4AB11(2-2(5A4-)5A)2-5A-B2-5A2-B-3(5A2-2(5A4-))5A27-7A-2A5(-A)-2A2-3(23AB-)3(23A2-)2(5A4-)5AB-2(5A4-)5A2-2(2(5A4-)5AB-)14(2(5A4-)5A2-)2(5A-2B-)3(5A2-2(5A4-))5A27-7A-2A5-A5-2A2-3(23AB-)3(23A2-)2(5A4-)5A2-2(2(5A4-)5AB-)15(2(5A4-)5A2-)5A2-B-5A-B2(2-5A)2(4-5A)2(2-2(5A4-)5A)27-7A-15A2-23AB-23AB24AB-3(23A2-)5(2(5A4-)5A2-)2(5A4-)4AB12(2-2(5A4-)5A)2-5A2-B-5A-B2(2-5A)2(4-5A)2(2-2(5A4-)5A)27-7A-2A2(-A)-2A-A-3A2-23AB-23AB24AB-3(23A2-)2(2(5A4-)5A2-)2(5A4-)4AB15(2-2(5A4-)5A)2-2(5A-2B-)3(5A2-2(5A4-))5A27-7A-2A5-3(A-)2A2-20A-2A3(B-23A)2(2-23A)18(2-2(5A4-)5A)2-5A-B2-5A2-B-3(5A2-2(5A4-))5A27-7A-8A5-2A2-20A-2A5(2-23A)18(2-2(5A4-)5A)2-5A-B2-5A2-B-3(5A2-2(5A4-))5A27-7A-2A-12A6(2-23A)18(2-2(5A4-)5A)2-2(5A-2B-)3(5A2-2(5A4-))5A27-7A-2A-12A6(2-23A)18(2-2(5A4-)5A)2-5A2-B-5A-B2(2-5A)2(4-5A)2(2-2(5A4-)5A)27-7A-2A5-8A6(2-23A)18(2-2(5A4-)5A)2-5A2-B-5A-B2(2-5A)2(4-5A)2(2-2(5A4-)5A)27-6A3-14A6(2-23A)2-2(5A4-)17(5A2-5A5-3A5-)5A2-5A-3B4A4B-5A2-5A4-4A5-2(5A2-2(5A4-))5A3-2B17-2B3-7(23A2-)21(2(5A4-)5A2-)2(5A4-)5A3-2B17-2B3-28(23A2-)23A27-5(23A2-)19(11A-11A2-)11AB2(11A2-11A-)11A2(2-23A)638-B747-5B745-5B111-
