model
size = 32 17 15, scale = 0.05, origin = -y
material deform = 1, fade = true, lighting = smooth, roughness = 0.3, metalness = 0.6
  colors = A:#BBB B:#EEE C:#111 D:#444
voxels
82-A2(542-2A)541-3A29-2A308-D201-3A28-3A47-8B31-B25-2(B-)2B25-5B27-4A97-D31-D201-3A28-3A15-3B30-2B32-5B28-2B-B2A22-8B2A22-10A27-C63-D228-10B22-B9A12-11B5A17-10B5A17-3C5-14A9-B2-C4-15A9-B22A9-3AC19A14-13A19-D-11A19-D183-2B29-2B12-14B3-3B11-B13A2B-3B3-10B15A3B4-9B16A2B6-3C14A3-4AB8-C13A5-4A2B5-B2A3-3A12-4A3B4-15A5-3A3-3B2-15A3-4A6-3B5-15A10-2B14-4A13-2B13-4A29-3A30-2A31-A90-10B22-B9A12-11B12A10-10B12A10-3C5-2B12A9-B-C20A9-B2A3-17A9-23A8-22A14-15A26-4A28-4A29-3A30-2A31-A95-3A28-3A15-8B24-8B25-3C29-CBC-2B-13A11-B5AB2-12A11-3AC3AB12A17-13A19-D-11A19-D233-3A28-3A15-3B30-7B30-2B24-2(B9A22-)10A27-C63-D233-3A29-2A47-8B31-B25-2(B-)2B25-5B27-4A97-D31-D202-2A339-D202-2A543-A461-
