model
size = 31 31 16, scale = 0.05, origin = -y
material deform = 1, fade = true, lighting = smooth, roughness = 0.3, metalness = 0.6
  colors = A:#444 B:#400 C:#800 D:#020 E:#D00
voxels
41-11A20-12A17-14A2(16-15A)17-2(13A18-)9AB3A18-8ABC2BA18-7ABCBECB18-A6B2C3B2A17-ABCE2(B3C)BA16-A2(BC)E3BCBECB2A15-AB2CBCE4CBEB2A14-3AB2C3B5CB2A14-3AB9CB3A14-4AB2CEB3CB4A14-5A7B3ADA14-17A14-2A3DA3D2AD3ADA14-2A3(DA)D2AD4AD15-AD3ADA2(D2A)DAD15-3(A3D)2AD18-12A209-9A18-12A19-11A21-A5-5A30-2A20-7A23-10A-A3(19-12A)18-13A17-14A18-13A17-15A16-15A15-2(17A14-)17A13-6(19A12-)19A13-17A171-2(15A16-)14A16-16A15-16A3(16-15A)16-16A5(13-18A)13-19A3(11-20A)10-21A8-4(25A6-)25A7-23A8-23A9-16A-4A14-12A110-17A14-17A15-15A15-4(17A14-)17A13-5(19A12-)19A11-2(21A10-)21A7-A2-21A2-A7(4-27A)5-25A7-23A9-21A12-17A18-8A49-19A12-19A13-17A13-7(19A12-)2(8A3-8A12-)8A3-8A11-9A3-9A3(10-9A4-8A)6-12A6-2(11A2-10A8-)11A2-9A10-10A2-9A3-4A3-10A2(2-29A)3-2(27A4-)27A5-25A8-21A13-15A18-10A17-7(19A12-)7A3-9A5(12-7A5-7A)11-6A8-7A10-5A9-7A2(10-5A10-6A)6-9A10-10A-10A10-21A11-19A12-10A-8A12-9A2-7A13-A-7A2-9A10-10A2-29A3-27A4-27A5-25A7-23A11-17A16-2A8-3A14-7A7-7A10-8A5-8A11-7A2-10A11-2(8A2-11A10-)7A3-11A10-7A4-10A2(10-7A6-8A)11-6A6-7A12-5A7-7A12-4A9-6A12-4A10-5A11-3(5A10-6A10-)5A10-6A6-8A13-8A-9A2(13-18A)13-17A15-8A-5A19-5A2-6A17-6A2-8A13-8A3-10A6-11A4-27A5-25A7-23A10-5A8-6A15-A10-2A14-5A2(10-6A)9-6A7(10-6A8-7A)11-2(4A9-6A12-)4A10-5A12-4A10-5A11-2(5A10-6A10-)4A13-4A10-4A13-4A6-3A-4A13-4A-3A-9A2(13-18A)13-14A15-2A4-5A-4A15-2A4-4A2-5A19-5A2-6A17-6A3-7A13-7A4-11A4-12A5-11A2-12A7-9A4-10A10-4A10-5A15-A10-2A14-5A11-2(5A10-)7(6A10-5A10-)6A11-3(4A10-5A12-)4A10-5A11-3(5A10-6A10-)4A13-4A7-7A13-7A2-9A2(13-18A)13-15A14-2A3-6A-5A14-2A3-5A2-6A17-6A2-8A13-8A3-11A5-11A4-12A2-13A5-11A2-12A7-9A4-10A10-4A10-5A15-A10-2A14-3(4A13-4A10-)5A11-2(5A10-)4(6A10-5A10-)6A11-3(4A10-5A12-)4A10-5A11-3(5A10-6A10-)5A10-6A8-7A10-8A3-9A13-18A2(11-20A)11-11A-8A11-10A2-9A10-10A2-11A6-12A3-27A4-27A5-25A7-9A4-10A11-3A10-4A16-A10-2A14-6(5A10-6A10-)5A9-7A10-5A9-7A11-4A9-2(6A12-5A8-)6A2(12-5A9-5A)11-6A9-3(6A10-5A10-)6A8-7A10-8A4-9A10-10A-10A10-20A11-11A-2(9A10-10A2-)11A6-12A2-13A2-14A3-27A4-27A5-25A8-21A14-A10-2A45-5(6A8-A-5A10-)6A8-7A11-4(5A7-7A12-)3(5A8-6A12-)5A8-6A11-2(6A8-7A10-)6A8-7A9-7A8-8A6-9A9-2(9A4-8A10-)9A4-9A8-10A4-11A4-12A3(4-27A)5-25A7-23A12-15A28-A46-8A4-9A11-9(7A4-8A12-)6A6-7A12-6A6-6A13-6A7-6A5(12-6A6-7A)11-6A8-7A9-7A2(8-8A)6-9A2(8-23A)9-3(21A10-)21A12-17A17-11A78-5(19A12-)19A13-4(17A14-)8A5(2-7A13-9A)2-3(8A12-7A4-)8A11-21A10-21A11-20A2(10-21A)11-19A13-17A15-15A18-11A109-17A15-6(17A14-)4(16A15-)17A13-17A14-4(18A13-)19A12-18A13-2(19A12-)19A11-20A11-19A13-18A14-15A17-13A142-14A17-15A4(15-16A)15-15A3(17-14A)16-16A15-16A4(14-17A)14-5(18A13-)18A14-17A15-15A18-11A196-
