model
size = 24 7 19, scale = 0.05, origin = -y
material deform = 1, fade = true, lighting = smooth, roughness = 0.3, metalness = 0.6
  colors = A:#111 B:#400 C:#700
voxels
A2BCBC4BA2-A2BCBC4B2A2(BC)5BA2-A2(BC)5B2A9BA2-A9B30A5-4A5-8A8-2A8-5A20-2A72-15(A22-A144-)A22-A120-A23-A22-A143-A23-A72-
