model
size = 30 32 30, scale = 0.05, origin = -y
material deform = 1, fade = true, lighting = smooth, roughness = 0.3, metalness = 0.6
  colors = A:#DDD B:#222 C:#444 D:#EEE
voxels
12-8A1881-8A742-6(8A22-)8A19-14A499-7(8A22-)8A19-6(14A16-)14A14-18A18-7(7A23-)7A8(22-8A)20-7(12A18-)12A16-6(16A14-)16A12-10AB9A15-7(11A19-)11A8(18-12A)16-7(16A14-)16A12-6(20A10-)20A9-10ABCB9A12-7(15A15-)15A8(14-16A)13-7(18A12-)18A10-6(22A8-)22A7-11ABCB10A10-17A7(13-4A9-4A)8(12-5A9-4A)11-7(6A9-5A10-)6A9-5A9-6(7A9-6A8-)7A9-6A6-11AB3-B10A8-19A7(11-5A9-5A)8(10-6A9-5A)9-7(7A9-6A8-)7A9-6A7-6(8A9-7A6-)8A9-7A5-10ABC3-CB9A8-19A7(11-5A9-5A)8(10-6A9-5A)9-7(7A9-6A8-)7A9-6A6-2(6(9A9-8A4-)9A9-8A3-10AB2C3-2CB9A6-21A14(9-6A)8(8-7A9-6A)7-7(8A9-7A6-)8A9-7A5-)6(9A9-8A4-)9A9-8A3-9AB3C3-3CB8A5-23A7(7-7A9-7A)8(6-8A9-7A)5-7(9A9-8A4-)9A9-8A3-6(10A9-9A2-)10A9-9A-9AB4C3-4CB8A4-23A7(7-7A9-7A)8(6-8A9-7A)5-7(9A9-8A4-)9A9-8A3-6(10A9-9A2-)10A9-9A-8AB4CB3-B4CB7A4-23A7(7-7A9-7A)8(6-8A9-7A)5-7(9A9-8A4-)9A9-8A3-6(10A9-9A2-)10A9-9A-8AB2C3B3-3B2CB7A4-23A7(7-7A9-7A)8(6-8A9-7A)5-7(9A9-8A4-)9A9-8A3-6(10A9-9A2-)10A9-9A-7ABC5B3-5BCB6A4-23A7(7-7A9-7A)8(6-8A9-7A)5-7(9A9-8A4-)9A9-8A3-6(10A9-9A2-)10A9-9A-8A2D4B3-4B2D7A4-23A7(7-7A9-7A)8(6-8A9-7A)5-7(9A9-8A4-)9A9-8A3-6(10A9-9A2-)10A9-9A-8ABC2D2B3-2B2DCB7A4-23A7(7-7A9-7A)8(6-8A9-7A)5-7(9A9-8A4-)9A9-8A3-6(10A9-9A2-)10A9-9A-9AB2CDB3-BD2CB8A5-21A14(9-6A)7-7(8A9-7A6-)8A9-7A5-7(9A9-8A4-)9A9-8A3-6(10A9-9A2-)10A9-9A-10AB2CD3-D2CB9A5-21A14(9-6A)8(8-7A9-6A)7-7(8A9-7A6-)8A9-7A5-6(9A9-8A4-)9A9-8A3-9AB3C3-3CB8A7-19A7(11-5A9-5A)9-7(7A9-6A8-)7A9-6A7-7(8A9-7A6-)8A9-7A5-6(9A9-8A4-)9A9-8A3-10AB2C3-2CB9A7-19A7(11-5A9-5A)8(10-6A9-5A)9-7(7A9-6A8-)7A9-6A6-6(9A9-8A4-)9A9-8A3-11ABC3-CB10A8-17A7(13-4A9-4A)11-7(6A9-5A10-)6A9-5A9-7(7A9-6A8-)7A9-6A7-6(8A9-7A6-)8A9-7A5-10ABC3-CB9A10-15A7(15-3A9-3A)13-7(5A9-4A12-)5A9-4A11-7(6A9-5A10-)6A9-5A9-6(7A9-6A8-)7A9-6A6-11AB3-B10A12-7(11A19-)11A16-6(16A14-)AD12ABA14-DB12ADA13-7(18A12-)18A10-6(22A8-)22A7-11ABCB10A15-4(7A23-)3AB3A2(23-2ABCB2A)23-AB3CBA20-2(12A18-)10A2(BA18-AB8A)CB18-BD8ADB18-DB8ABD18-2B8A2B16-2B12A2B14-AB12ACB14-AB12ABA5(14-16A)12-6(20A10-)20A9-10ABCB9A255-2AB3CBA22-AB5CB22-AB2CD2CB22-B2CDBD2C22-C2D3BDC22-D6BD2(22-8B)20-2B8A2B18-CB8ABC2(18-BC8ACB)2(18-AB8ABA)2(18-12A)16-6(16A14-)16A12-10AB9A496-2(8B22-)C7B22-2C5BC22-4CB3C22-B7C22-AB5CB22-AB4CBA19-6(14A16-)14A14-18A737-AB4CBA22-2AB3CBA2(22-3ABCB2A)22-4AB3A2(22-8A)19-14A8-
