model
size = 30 32 30, scale = 0.05, origin = -y
material deform = 1, fade = true, lighting = smooth, roughness = 0.3, metalness = 0.6
  colors = A:#DDD B:#66F C:#FF3 D:#C63 E:#6FF F:#777 G:#EEE H:#BBB
voxels
12-8A1881-8A742-6(8A22-)8A19-14A499-7(8A22-)8A19-6(14A16-)14A14-18A18-7(7A23-)7A8(22-8A)20-7(12A18-)12A16-6(16A14-)16A12-20A15-7(11A19-)11A8(18-12A)16-7(16A14-)16A12-6(20A10-)20A9-22A12-7(15A15-)15A8(14-16A)13-7(18A12-)18A10-6(22A8-)22A7-3A4D10A4B3A10-17A7(13-4A9-4A)8(12-5A9-4A)11-7(6A9-5A10-)6A9-5A9-6(7A9-6A8-)7A9-6A6-3A6D3A3-2A6B3A8-11AH7A7(11-5A9-5A)8(10-6A9-5A)9-7(7A9-6A8-)7A9-6A7-6(8A9-7A6-)8A9-7A5-2A8D2A3-A8B2A8-9A2H8A7(11-5A9-5A)8(10-6A9-5A)9-7(7A9-6A8-)7A9-6A6-6(9A9-8A4-)9A9-8A3-3A8D2A3-A8B3A6-9AH11A14(9-6A)8(8-7A9-6A)7-7(8A9-7A6-)8A9-7A5-6(9A9-8A4-)9A9-8A3-3A8D2A3-A8B3A6-8AH12A14(9-6A)8(8-7A9-6A)7-7(8A9-7A6-)8A9-7A5-6(9A9-8A4-)9A9-8A3-3A8D2A3-F8B3A5-23A7(7-7A9-7A)8(6-8A9-7A)5-7(9A9-8A4-)9A9-8A3-6(10A9-9A2-)10A9-9A-5A6D3A3-2F6B5A4-23A7(7-7A9-7A)8(6-8A9-7A)5-4(9A9-8A4-)3(9A9-G7A4-)9A9-G7A3-6(10A9-9A2-)10A9-9A-6A4D3AF3-3F4B6A4-23A7(7-7A9-7A)8(6-8A9-7A)5-4(9A9-8A4-)3(9A9-G7A4-)9A9-G7A3-6(10A9-9A2-)10A9-9A-12A2F3-6F7A4-23A7(7-7A9-7A)8(6-8A9-7A)5-4(9A9-8A4-)3(9A9-G7A4-)9A9-G7A3-6(10A9-9A2-)10A9-9A-10A4F3-5F8A4-23A7(7-7A9-7A)8(6-8A9-7A)5-4(9A9-8A4-)3(9A9-G7A4-)9A9-G7A3-6(10A9-9A2-)10A9-9A-9A5F3-4F9A4-23A7(7-7A9-7A)8(6-8A9-7A)5-4(9A9-8A4-)3(9A9-G7A4-)9A9-G7A3-6(10A9-9A2-)10A9-9A-8A6F3-2F11A4-23A7(7-7A9-7A)8(6-8A9-7A)5-4(9A9-8A4-)3(9A9-G7A4-)9A9-G7A3-6(10A9-9A2-)10A9-9A-6A4E4F3-F2A4C6A5-12AH8A14(9-6A)7-7(8A9-7A6-)8A9-7A5-4(9A9-8A4-)3(9A9-G7A4-)9A9-G7A3-6(10A9-9A2-)10A9-9A-5A6E3F3-2A6C5A5-11AH9A14(9-6A)8(8-7A9-6A)7-4(8A9-7A6-)3(8A9-G6A6-)8A9-G6A5-6(9A9-8A4-)9A9-8A3-3A8E2F3-A8C3A7-9AH9A7(11-5A9-5A)9-7(7A9-5CA8-)7A9-6A7-4(8A9-7A6-)3(8A9-G6A6-)8A9-G6A5-6(9A9-8A4-)9A9-8A3-3A8E2F3-A8C3A7-8AH10A7(11-5A9-5A)7(10-6A9-4CA)10-6A9-5A9-4(7A9-6A8-)3(7A9-G5A8-)7A9-G5A6-6(9A9-8A4-)9A9-8A3-3A8EFA3-A8C3A8-6AH10A7(13-4A9-4A)11-A5E9-4CA5(10-A5E9-5C)10-A5E9-4CA10-6A9-5A9-4(7A9-6A8-)7A9-G5A3(8-7A9-5BA)7-8A9-5B2A3(6-8A9-6BA)3(6-8A9-7A)5-2A8E2A3-A8C2A10-15A7(15-3A9-3A)13-6(5E9-4C12-)A4E9-4C12-5A9-4A11-4(6A9-5A10-)6A9-G4A10-A4DA9-4BA2(10-A4DA9-5B)9-3(A5DA9-6B8-)7A9-5BA3(8-7A9-6A)6-3A6E3A3-2A6C3A12-7(11A19-)11A16-7(6E4A6C14-)GF12AGA13-4(18A12-)14AG3A12-A3D2(7A7B12-4D)7A7B10-2A4D3A4G9B8-A5D4A3G9B8-A5D5AGA9B8-11AGA8BA3(8-22A)7-3A4E10A4C3A15-7(7A23-)7A20-7(4E4A4C18-)2F10A16-3(16A14-)14AFA14-13AGFA3(14-6D4A6B)12-8D4G8B10-8DA3G8B10-8D2AGA8B10-A7D2AGA8B3(10-20A)9-22A255-E6AC4(22-2E4A2C)22-2EF3A2C22-E4F2AC22-6F2A20-2F10A18-AF10A18-10AFA2(18-10A2F)3(18-4D4A4B)16-6D4G6B14-6DA3G2(6B14-6D2AGA)6B3(14-16A)12-20A496-6F2A22-7FA22-A7F2(22-2A6F)22-D2A4FB22-2D2A2F2B22-2D3AF2B19-5D4G5B16-5DA3G2(5B16-5D2AGA)5B3(16-14A)14-18A737-2D3AF2(2B22-2D4A)2B22-D6AB3(22-8A)19-14A8-
