model
size = 6 10 31, scale = 0.05, origin = -y
material deform = 1, fade = true, lighting = smooth, roughness = 0.3, metalness = 0.6
  colors = A:#111 B:#EEE C:#222 D:#E00
voxels
2A2C3A4C9A2D3A3(D2A)D3A2D9A4C3A2C4A2C14AB3(4A2B)4AB14A2C4A2C8AB4AB24AB4AB8A2C4A2C8AB4A4(B5A)2B4AB8A2C4A2C52A2C4A2C8AB4A2B2(5AB)4A2B5AB4AB8A2C4A2C8AB4A2(B5A)2B4AB5A2B4AB8A2C4A2C52A2C4A2C8AB4A2B5AB3(4A2B)4AB8A2C4A2C19AB6AB16AB8A2C4A2C13AB5A2B4A3(B5A)B8A2C4A2C8A5(B5A)B13A2C4A2C13A5(B5A)B8A2C4A2C8AB4AB12A2(B5A)B4AB8A2C4A2C8AB2(4A2B)4A2(B5A)2B4AB8A2C4A2C52A2C4A2C8AB3(4A2B)2(5AB)4AB8A2C4A2C8AB4AB17AB5A2B4AB8A2C4A2C8A5(B5A)B13A2C4A2C13A5(B5A)B8A2C4A2C8A2(B5A)B4A2B2(5AB)13A2C4A2C14AB16AB6AB13A2C4A2C8AB4AB5A4(2B4A)B8A2C4A2C52A2C4A2C8AB4A2B2(5AB)4A2B5AB4AB8A2C4A2C8AB4A2(B5A)2B4AB5A2B4AB8A2C4A2C52A2C4A2C8AB4A2B4(5AB)4AB8A2C4A2C8AB4AB24AB4AB8A2C4A2C14AB3(4A2B)4AB14A2C4A2C3A4C8A2(D2A)DA2D2A2DA2(D2A)D8A4C3A2C2A
