model
size = 32 28 14, scale = 0.05, origin = -y
material deform = 1, fade = true, lighting = smooth, roughness = 0.3, metalness = 0.6
  colors = A:#00F B:#EEE C:#F0C
voxels
44-8A24-8A22-6A26-6A2(24-8A)24-10A22-10A2(24-8A)26-4A28-4A98-2(4A2-4A22-)8A24-8A380-6A26-6A24-4A28-4A2(22-10A)22-8A24-8A26-4A28-4A610-6A26-6A24-4A28-4A2(22-10A)22-8A24-8A26-4A28-4A728-12A20-12A18-2(12A20-)10A2-4A16-10A2-4A18-6A2-4A20-6A2-4A22-8A24-8A2(26-6A)26-4A28-4A91-2(3A29-)3(5A27-)5A216-12A20-12A18-2(12A20-)10A2-4A16-10A2-4A18-6A2-4A20-6A2-4A22-8A24-8A2(26-6A)26-4A28-4A91-2(3A29-)3(5A27-)5A86-4A28-4A22-12A20-12A24-2(12A20-)3(14A18-)14A4(20-12A)22-12A20-12A2(22-10A)26-8A24-8A22-2(4A2B6A20-)12A20-12A142-4A28-4A22-12A20-12A24-2(12A20-)3(14A18-)14A4(20-12A)22-12A20-12A2(22-10A)26-8A24-8A22-2(4A2B6A20-)12A20-12A134-6A2-6A18-6A2-6A16-2(8A2C8A14-)2(4A2-14A12-)4A4-14A10-4A3(4-14A12-2A)6-12A12-2A6-12A12-4A4-14A10-4A4-14A2(12-2A6-12A)2(12-2A8-10A)10-4A12-6A2B8-4A12-7AB8-2B12-12A6-2B12-12A4-4B12-14A2-4B12-14A27-5A2C25-5A2C66-6A2-6A18-6A2-6A16-2(8A2C8A14-)2(4A2-14A12-)4A4-14A10-4A3(4-14A12-2A)6-12A12-2A6-12A12-4A4-14A10-4A4-14A2(12-2A6-12A)2(12-2A8-10A)10-4A12-6A2B8-4A12-7AB8-AB13-11A6-AB12-12A4-3AB12-14A2-4B12-14A27-5A2C25-5A2C74-6A26-6A20-14A18-14A22-2(12A20-)3(14A18-)14A4(20-12A)22-12A20-12A2(22-10A)26-8A24-8A22-2(4A2B6A20-)12A20-12A142-6A26-6A20-14A18-14A22-2(12A20-)3(14A18-)14A4(20-12A)22-12A20-12A2(22-10A)26-8A24-8A22-2(4A2B6A20-)12A20-12A204-5(10A22-)10A24-2(10A22-)12A20-12A2(22-10A)2(24-8A)2(28-4A)87-2(4A28-)6A26-6A2(28-4A)149-5(10A22-)10A24-2(10A22-)12A20-12A2(22-10A)2(24-8A)2(28-4A)87-2(4A28-)6A26-6A2(28-4A)25-8A24-8A22-6A26-6A2(24-8A)24-10A22-10A2(24-8A)26-4A28-4A98-2(4A2-4A22-)8A24-8A326-
