model
size = 28 14 15, scale = 0.05, origin = -y
material deform = 1, fade = true, lighting = smooth, roughness = 0.3, metalness = 0.6
  colors = A:#330 B:#111 C:#555 D:#444 E:#222 F:#960 G:#660 H:#888 I:#777 J:#3CF K:#EEE L:#300 M:#F9C N:#C90 O:#630 P:#BBB Q:#06F R:#A00 S:#E00
voxels
6-3B11-3B10-2BD2B9-2BD2B7-A-BDPDB9-BDPDB7-A-2BD2B-A5-A-2BD2B-A6-A-3B-A7-A-3B-A8-5A3-D5-5A10-3A272-3A21-2A2-4A5B2AG5AG2BA2B3A2-5A3B3AG5AGA3B4A2-11AG5AG7A21-D27-D232-D3A21-2AD-K3A5B9A2BA2B2AE2-S4A3B10A5B3A2-24AN3-11AG5AGAD3-DN21-D232-D3A21-2AD-2A3BK3B9A2BA2B2AC2-AB4-DF10A5B3A2-A5-DF16AK3-A5-D2FO3L2BD2I2A3-DN9-D11-B15-D11-2(B27-)B148-H3A21-2ADH2A5E2B9A2BA2B2AE2-AB5-F10A5B3A2-A6-F11A3B3A3-A6-2FO3L2BDCI7A21-J15-D11-2(J27-)B47-C27-C72-D3A21-2AD-2A7B9A2BA2B2AC2-KB5-F2A2CD5A5B3A2-A6-F2ACD7A3B2AE3-A6-2FOL3ABDRI7A14-2CD4-J15-D4-C6-J20-C6-J27-B47-H27-C72-D3A21-2AD-2A5E2B9A2BA2B2AE2-QB5-MA2CH6A5B3A2-A6-MA2CH7A3B2AE3-A6-2F2CHL2BDCI3A3GA12-3C3-B2-J15-D2-3C6-J18-3C6-K19-3C5-B19-CBC25-2C99-D3A21-2AD-2AB2(M2B)9A2BA2B2AH2-QB5-F3CHI5A5B3A2-A6-F3CHI6A3B2AE3-A6-M3CHI2BDCI7A11-3CHI2-BE-J15-D2-2CH3-B2-K18-3C6-J18-4C5-B18-2CE2CM22-3C99-D3A21-2AD-2A2E2ME2B9A2BA2B2AE2-QB5-F3CHI5A5B3A2-A6-F3CHI6A3B2AE3-A6-F3CHI2BDCI3A3GA11-3CH3-BE-K15-D2-3C3-B2-J18-3C6-J18-4C5-B19-CEC25-2C99-D3A21-2AD-2A7B9A2BA2B2AH2-KB5-FA3C6A5B3A2-A6-FA3C7A3B2AE3-A6-2F3CL2BDCI7A13-2C3-B2-J15-D3-2C6-J20-C6-K27-B47-H27-C72-H3A21-2ADH2A5E2B9A2BA2B2AE2-AB5-F2A2CD5A5B3A2-A6-F2ACD7A3B3A3-A6-2FOL3ABDRI7A14-2CD4-J15-D4-C6-K27-J27-B47-C27-C72-D3A21-2AD-2A3BK3B9A2BA2B2AH2-AB4-DF10A5B3A2-A5-DF11AB4AN3-A5-D2FO3L2BD2I2A3-DN9-D11-B15-D11-2(B27-)B148-D3A21-2AD-K3A5B9A2BA2B2AE2-S4A3B10A5B3A2-24AK3-11AG5AGAD3-DN21-D233-3A21-2A2-4A5B2AG5AG2BA2B3A2-5A3B3AG5AGA3B4A2-11AG5AG7A21-D27-D182-3B11-3B10-2BD2B9-2BD2B7-A-BDPDB9-BDPDB7-A-2BD2B-A5-A-2BD2B-A6-A-3B-A7-A-3B-A8-5A3-D5-5A10-3A215-
