model
size = 18 32 15, scale = 0.05, origin = -y
material deform = 1, fade = true, lighting = smooth, roughness = 0.3, metalness = 0.6
  colors = A:#FCC B:#F0F C:#F33 D:#6F0 E:#F96 F:#0FF G:#66F H:#FF6 I:#3FF J:#FF3
voxels
9-FGB14-HDFG13-CEHDFG12-BCEHDF12-GBCEHD12-FGBCE13-DFGBC13-HDFGB13-EHDFG13-CEHDF13-BCEHD12-FGBCEH12-DFG-CE12-HDF-BC12-EHD-GB12-CEH-FG12-BC286-EHDFGBCE10-CE2A-GBC9-GB2A2-FGBC8-FG5-FGB8-DF4-HDFG7-EHD4-EHDF7-CEH4-CEHD7-BCE5-CEH7-GBC5-BCE8-GB5-GBC8-FG5-FGB8-DA4-ADFG8-HA-AB2AHDF8-EA-AG2AEHD8-CA-AF2ACEH8-B3AD2AB10-G2AEHDFG10-FGBC-HD11-DFGB14-HDF15-EHD15-CEH15-BCE177-CEHDFGBCEH7-GBA6-CE7-F2A6-BAE6-DA8-BC5-EHA8-GB5-C2A8-FG5-BA9-DF4-FGA9-HD4-DF2A8-EH5-DFA8-CE6-DA8-BC6-HA2-4A2-GB6-EA8-FG7-E8-DF7-C6-AEAD7-B2-2A2-ACE8-G2-4AG10-F2-AE2AF10-D-2ACEHD10-H-AG-CEH10-E-D15-C-H15-BAE15-GBC15-FG16-DF16-H106-BCEHDFGBCEHD6-GA8-EH5-DA9-CE5-HA10-C4-C2A10-B3-GBA11-GB2-FGA11-FG2-D2A11-DF2-HDA11-HD4-DA10-EH5-D10-CEH4-H10-BCE4-EA2-4A3-GBC4-CA9-FG6-C8-HD7-B6-ACEH7-G2-2A2-G10-F-3A2-F10-D-AB2A-D10-H-AGB2AH10-E-D-GBCE9-BA-H2-GBC9-GA-E2-FGB9-F2AC14-D2AB14-H2AG14-EAD15-CEH15-BCE15-GB51-GBCEHDFGBCEHD5-FA10-H4-H2A10-E4-EA11-CE2-B2A11-BC-F2A12-GB-DA14-G-HA14-F-E3A12-DF-EH4A9-HD-CEH3A9-EH3-E2A11-E4-EA2-5A3-BC4-C2A8-FGB5-C9-D7-BA5-2AEH7-G4A-2ABC8-FGBCA-AF10-DFG-C2-D10-HDF-B2-H10-EHD-GA-E9-BCEH-FA-C9-G2AE2-FAB9-F2AC2-DFG9-D2AB3-DF9-H2AG14-E-AF14-C-H15-BAE15-GAC15-FGB32-GBCEHDFGBCEHD5-F11-H4-HA11-E3-CA12-CE2-BA13-C-FA14-B-D15-G-H15-F-EA2-3A9-DF-E2-2AB10-D-C4AG10-H-BC4A10-E2-BCE8A4-C5-EH2A5-DFGB5-CEHA5-HD7-BCE5A-EH8-BCE5AC12-EHDAGB12-C2AD14-B2AH14-G2AE14-FA-C10-BC2-DA-B9-FGB3-DAG9-DFG3-HAF9-HDF3-EHD9-EHD4-EH9-CEH4-CE9-BCE15-GBC15-FGB32-GBCEHDFGBCEHD5-FA10-H4-HA11-E3-C2A11-CE2-BA12-BC-FA14-B-DA14-G-HA2-A-2A8-F-EA2-2ACA8-DF-E2-AG-C8-HD-C2-AF-B8-DH-BA-2AF6A-B-CE2-B3AD5A-AF2-C2-GACE-D7AFGB3-GBC2-DF3A-HDF9-HDF2A-E12-HDF2AC15-FAB13-EH-FG13-CE16-BCE15-GAC14-D2AB14-HA-G15-H-F15-EAD15-C2AD14-B2AH15-BC63-BCEHDFGBCEHD5-F3A7-EH5-DA9-CE4-EA11-C3-B2A11-BC2-G2A11-GB2-FGA11-FG2-DF4A8-DF2-HDFGBCEH3A2-AHD2-E2AF2-CE4A-2AH2-CA-AF2-CEH5AE2-BA-AD-GB4A2(DA)E2-B-3AF5ADA-BC2-GA-AH-FGBCEH3AB3-GBCE3-GB3ADF12-G2AE14-FA-C15-FAB15-DFG49-GB16-FGB15-DAG15-HAF15-EAD15-C2AD14-B2AH14-G2AE15-GBC15-FG16-DF11-EHDFGBCEH7-GBCEHDFABCE6-DF3AEH2A-BAE5-H2A2-AEA3-BC4-CEA3-ACA3-GB4-BCA2-2AB2A-DFG5-BA-2AFGB3ADF5-GBCEHDFGBCEHD11-DFGBCEH4-HDF4-JDIGBCE4-EHD6-DIGBC4-CEADF2-CEHD3AC3-B4AFGBCEH-F2AC2-G2A-AD-G4-D2AB3-GBCEH4-CE2AF13-BAEHD12-F2AC14-DA-B15-DFG86-F16-HDF15-EHD15-CEHD14-B2AH14-G2AE14-F2AC15-FAB15-DFG33-GBC9-GBCE-DFGBC7-DFGBC-HDFGB7-HDFGB-EHDFG7-EHDFG-CEHDF7-CEJD3-CEH8-BCE69-HDF6-IGB5-C3AF5-D2AB4-B2A-D5-H2AG5-BCAH6-HAF7-CE3-GBC-H13-F2AC14-D2AB15-DFG158-CE16-BCE15-GBC15-FGB15-DFG159-GBC15-FA2(B15-D2A)B6-EHDF4-H2AG6-CEAD5-H2AG6-CAH6-HDF7-CE3-GBC-H13-F-AC14-D2AB15-DF393-GBC15-FAB15-D2AB15-DAG15-H2AG8-HD2-BCEHDF8-EH2-GBC15-F2AC14-DA-B15-DAG16-DF393-2(GB16-F)G16-DFG12-BCEHDF12-G2AE14-FA-C15-F2AC14-DA-B15-DFG481-BCE15-GBCE14-FGAC15-F2AC14-D2AB15-DFG519-B17-GB16-FG275-
