model
size = 14 23 10, scale = 0.05, origin = -y
material deform = 1, fade = true, lighting = smooth, roughness = 0.3, metalness = 0.6
  colors = A:#FFC408 B:#BEC23F C:#EEE D:#FFFFFB
voxels
18-5AC9-AC2A11-2A272-A12-C-C10-A2-A10-C2-A10-A3-C8-A5-7AC9-CA230-A12-3A10-2A-A10-A2-A10-A3-A8-A5-8A8-4A229-A12-3A10-4A10-2A-A10-A3-A8-A5-8A7-6A9-C3A11-2(2A12-)AC12-2A11-D2AD9-A4-A7-D3-A2-D5-A2-D4A-A3-A2-A3-D3-A2-D3-4A3-D2(2-A)3(3-A)2-AD3A-A5-D3-A2-D7-A4-A9-D2AD5-C12-3A10-4A10-AC-A10-A3-A8-A5-8A7-6A9-4A11-3(2A12-)2A11-4B9-6B7-8B5-10B3-2(12B2-)12B3-10B5-8B7-6B9-4B5-A12-3A10-2A-A10-A2-A10-A3-A8-A5-8A8-4A10-4A11-3(2A12-)2A11-C2AC9-A4-A7-C2-A3-C5-A-4AC2-2(A3-)C3-2(A2-)C3-5A2-C2-2(A3-)A2-A3-A-3ACA2-A5-C2-A3-C7-A4-A9-C2AC5-A11-2A-A10-C2-A10-A2-C10-A3-A8-A5-8A9-AC231-2(A10-A2-)A10-A3-A8-C5-5AC2A7-6A244-2(A8-A4-)A8-A5-8A7-AC4A259-2(A6-)2A4-2A6-AC6A7-6A270-
