model
size = 16 29 30, scale = 0.05, origin = -y
material deform = 1, fade = true, lighting = smooth, roughness = 0.3, metalness = 0.6
  colors = A:#CF6 B:#222 C:#444 D:#111 E:#777 F:#555 G:#888 H:#AAA I:#CFC J:#CF3 K:#CF9 L:#00D M:#00E N:#693 O:#DDD P:#D00 Q:#E00
voxels
7-4D23-3D13-D-D13-3D353-4D2(12-D2MD)11-3(6A10-)6A409-3(8A8-)8A10-4C4(12-C2GC)12-4C12-2(4D44-)4D202-3(8A8-)8A9-6(C4-C10-)D4ED11-4E12-4B11-D4GD11-4E12-4B11-6D11-4F12-4F169-3(10A6-)10A7-C6-C4(8-G6-G)8-C6-C8-DE4-ED9-E4-E10-B4-B9-DG4-GD9-E4-E10-B4-B9-2DF2-F2D9-6F10-6F167-3(12A4-)12A5-CG6-G5(C6-C8-)C6-DE6-ED7-E6-E8-B6-B7-DGD4-DGD7-E6-E8-BDF2-FDB7-2DFC2-CF2D7-2F4C2F8-2F4C2F10-4C3(12-4B)104-3(12A4-)12A5-6(D8-D6-)DE6-ED7-E6-E8-B6-B7-DG6-GD6-ED6-DE6-B8-B5-2D-C4-C-2D5-F2C4-2CF6-F2C4-2CF7-2C-2B-2C3(8-8B)101-3(3A8-3A2-)3A8-3A3-6(C10-C4-)DE8-ED5-E8-E6-B8-B5-DG8-GD5-E8-E6-B8-B5-2D8-2D5-FC6-CF6-FC6-CF7-C2-2B2-C7-2(10B6-)10B8-2B2P2B10-2B2P2B70-3(3A8-3A2-)3A8-3A3-C10-C4(4-G10-G)4-C10-C4-DE8-ED5-E8-E6-B8-B5-DG8-GD5-E8-E6-B8-B5-2D8-2D5-FC6-CF6-FC6-CF7-C6-C7-5(2B6-)2B7-B6-B8-8B10-B2PB54-4A3(8-8A)8-4A2-6(C10-C4-)DE8-ED5-E8-E6-B8-B5-DG8-GD5-E8-E6-B8-B5-2D8-2D5-FC6-CF6-FC6-CF7-C6-C7-5(2B6-)2B7-B6-B8-3B2-3B9-6B11-4B38-2A-A3(8-8A)8-4A2-6(D10-D4-)DE8-ED5-E8-E6-B8-B5-DG8-GD5-E8-E6-B8-B5-2D8-2D5-FC6-CF6-FC6-CF7-C6-C7-6(2B6-)2(3B4-3B6-)2J2B2-2B2J5-3J6B3J4-2J3-2B3-2J18-3A3(10-6A)10-3A-6(C12-C2-)DE10-ED3-E10-E4-B10-B3-DG10-GD3-E10-E4-B10-B3-2D10-2D3-FC8-CF4-FC8-CF5-C8-C5-2(3B6-3B4-)3B6-3B5-2(2B6-)3B4-3B6-J2B4-2BJ5-3J6B3J4-2J2-4B2-2J18-3A3(10-6A)10-3A-C12-C4(2-G12-G)2-C12-C2-DE10-ED3-E10-E4-B10-B3-DG10-GD3-E10-E4-B10-B3-2D10-2D3-FC8-CF4-FC8-CF5-C8-C5-2(2B8-2B4-)2B8-2B5-B8-B6-3B4-3B7-2B4-2B9-2B2-2B11-4B13-2B7-3A2(10-6A)C8-C6AB8-B3A-2(CB10-BC2-)4(C12-C2-)DE10-ED3-E10-E4-B10-B3-DG10-GD3-E10-E4-B10-B3-2D10-2D3-FC8-CF4-FC8-CF5-C8-C5-2(2B8-2B4-)2B8-2B5-B8-B2(6-2B)7-2B4-2B9-2B2-2B11-4B13-2B7-3A3(10-6A)10-3A-6(D12-D2-)DE10-ED3-E10-E4-B10-B3-DG10-GD3-E10-E4-B10-B3-2D10-2D3-FC8-CF4-FC8-CF5-C8-C5-2(2B8-2B4-)2B8-2B5-B8-B2(6-2B)7-3B2-3B9-6B11-4B13-2C7-3A3(10-6A)10-3A-6(C12-C2-)DE10-ED3-E10-E4-B10-B3-DG10-GD3-E10-E4-B10-B3-2D10-2D3-FC8-CF4-FC8-CF5-C8-C5-2(2B8-2B4-)2B8-2B5-B8-B2(6-2B)7-8B10-4B13-2C14-2C7-3A3(10-6A)10-3A-C12-C4(2-G12-G)2-C12-C2-DE10-ED3-E10-E4-B10-B3-DG10-GD3-E10-E4-B10-B3-2D10-2D3-F2C6-2CF4-F2C6-2CF5-2C6-2C5-2(3B6-3B4-)2(3B6-)B6-B8-8B9-6B12-2(2C14-)2C7-64A-4(C12-C2-)C-G8-G-C2-C12-C2-D3E6-3ED3-3E6-3E4-3B6-3B3-D3G6-3GD3-3E6-3E4-3B6-3B3-4D6-4D4-2F6C2F6-2F6C2F8-6C7-2(12B4-)12B7-2(6B10-)6C11-4C13-2C14-2C7-50A2IK6AK2I2A2-3C6-3C4(4-CGC6-CGC)4-3C6-3C4-3D6E3D7-6E10-6B7-3D6G3D7-6E10-6B7-12D7-6F10-6F26-2(6B10-)6B60-2H14-2H25-2(12A4-)3I9A4-3I6AK9-A4NA10-6N10-6C2(10-C4GC)10-6C10-2(6D42-)6D156-2H14-2H26-10A5-I10A5-3I4A3KA5-3I4A3K363-2H14-2H27-8A6-3I7A6-3I4A3K6-3I4-3K363-2H14-2H48-3K7-G5-3K13-3K363-2H14-2H48-3F7-G5-FOF13-3F346-H2D2(H12-H2L)H12-4H41-G6-O363-4F2(12-F2LF)12-4F41-G6-O363-H2D2(H12-H2L)H12-4H41-2(G6-O380-2E14-2E58-)G6-O363-4D2(12-D2MD)12-4D24-3D13-3D5-Q7-3D353-E2D2(E12-E2M)E12-4E6-
