model
size = 28 28 14, scale = 0.05, origin = -y
material deform = 1, fade = true, lighting = smooth, roughness = 0.3, metalness = 0.6
  colors = A:#00F B:#F0C C:#EEE
voxels
40-8A20-8A18-6A22-6A2(20-8A)20-10A18-10A2(20-8A)22-4A24-4A86-2(4A2-4A18-)8A20-8A332-6A22-6A20-4A24-4A2(18-10A)18-8A20-8A22-4A24-4A534-6A22-6A20-4A24-4A2(18-10A)18-8A20-8A22-4A24-4A636-12A16-12A14-2(12A16-)10A2-4A12-10A2-4A14-6A2-4A16-6A2-4A18-8A20-8A2(22-6A)22-4A24-4A88-4A24-4A2(22-6A)22-4A24-4A182-12A16-12A14-2(12A16-)10A2-4A12-10A2-4A14-6A2-4A16-6A2-4A18-8A20-8A2(22-6A)22-4A24-4A88-4A24-4A2(22-6A)22-4A24-4A68-4A24-4A18-12A16-12A20-2(12A16-)3(14A14-)14A4(16-12A)18-12A16-12A2(18-10A)22-8A20-8A2(18-4A2C4A)2(18-10A)124-4A24-4A18-12A16-12A20-2(12A16-)3(14A14-)14A4(16-12A)18-12A16-12A2(18-10A)22-8A20-8A2(18-4A2C4A)2(18-10A)116-6A2-6A14-6A2-6A12-2(8A2B8A10-)2(4A2-14A8-)4A4-14A6-4A3(4-14A8-2A)6-12A8-2A6-12A8-4A4-14A6-4A4-14A2(8-2A6-12A)2(8-2A8-10A)6-2(4A12-8A4-)2A12-10A4-2A12-10A2(2-4A10-12A)14-2B4A22-2B4A68-6A2-6A14-6A2-6A12-2(8A2B8A10-)2(4A2-14A8-)4A4-14A6-4A3(4-14A8-2A)6-12A8-2A6-12A8-4A4-14A6-4A4-14A2(8-2A6-12A)2(8-2A8-10A)6-2(4A12-8A4-)2A12-10A4-2A12-10A2(2-4A10-12A)14-2B4A22-2B4A76-6A22-6A16-14A14-14A18-2(12A16-)3(14A14-)14A4(16-12A)18-12A16-12A2(18-10A)22-8A20-8A2(18-4A2C4A)2(18-10A)124-6A22-6A16-14A14-14A18-2(12A16-)3(14A14-)14A4(16-12A)18-12A16-12A2(18-10A)22-8A20-8A2(18-4A2C4A)2(18-10A)178-5(10A18-)10A20-2(10A18-)12A16-12A2(18-10A)2(20-8A)2(24-4A)88-2A26-2A4(24-4A)120-5(10A18-)10A20-2(10A18-)12A16-12A2(18-10A)2(20-8A)2(24-4A)88-2A26-2A4(24-4A)12-8A20-8A18-6A22-6A2(20-8A)20-10A18-10A2(20-8A)22-4A24-4A86-2(4A2-4A18-)8A20-8A282-
