model
size = 29 27 27, scale = 0.05, origin = -y
material deform = 1, fade = true, lighting = smooth, roughness = 0.3, metalness = 0.6
  colors = A:#111 B:#FC6 C:#222 D:#F4C874 E:#888 F:#AAA G:#EEE H:#DAAF57 I:#202424 J:#B69248 K:#000 L:#404848 M:#BBB N:#777 O:#819191 P:#600 Q:#E00 R:#92763A S:#DDD T:#D3BDA0 U:#996 V:#26200E W:#A2B6B6
voxels
414-2A-A25-2ACAF26-2A721-CA26-C4A25-2ACAC25-3A25-CA-A29-A575-3A24-2(2AC)23-5AC22-3A2(CA)F21-5AC2A3E19-2(AC)4AECE18-C2A2CAC2AE20-7A2C23-4A28-A458-2C25-CAC2A4-A19-5ACF-2A19-A2C2ACE21-7A2E19-C7ACFE18-C2AC8A18-C5A2CA-C18-4AC3AC-AE18-7A2(CA)19-7ACA23-4AC400-C26-3ACA23-8A-A18-8A-AD18-AC5AC2AD17-3AC5ACACD16-2CA3C4A2FG16-2AC5AC2A18-10ACG17-3A4(CA)-C16-2AC5ACAC-2A15-2(2AC)4A2C2A16-C3ACA4C2A18-5AC4AC22-3AC2A339-CAC25-CAC3A5-A16-C7A2-4A15-5A2CA-A2B-A14-5C5ACAD-AG13-2A2CAC3AC2DB2-G12-9A5BE14-8ACAC2ACE14-CAC9AE16-4A2(C2A)3C2-G13-5ACA3C3A3G13-3C3ACA2C3A-AEG13-2ACAC5AC3AE14-AC7AC4A16-4A2C6A19-4A2C3AC22-3AC2A281-C3-A22-6A5-A16-2AC4A2C-AC3A14-C2AC3ACA-ABCBA14-AC3AC2A2C-2BABG12-6AC4A2BD2A13-4AC5AC2DBDAC12-2AC3A2BD2B3DBC5M7-2ACA2(C3A)2BDBMA11-6AC4AC2AEAEC11-C3ACA2C2AC3AECBE11-2(4AC)6ADE12-C3AC6AC3ABFG11-A2C3ACAC3AC2AF2G12-8A2C2ACAE14-4AC2A3(CA)E17-3A2C6A20-AC2AC3AC22-4A169-3A26-A2C51-CAC2(2A2-)C5-H10-4A2C2AC2(-A)-D2H11-2A2C3A2C2A2BABDB2H10-A2(C4A)BA3BD2B10-C5AC3A5BD2BDK9-2ACAC2A3CB2D6BK8-A2C2(AC)3ACD2BD4BDK8-2A2C2A4BD6B2(DB)DM6-3AC2A6BDB3DBDK9-4A2C9A2CDBK9-AC6A2(CA)2C3A2D10-3AC5AC4A2C3BK9-8ACAC5AD2BC9-8A2(CA)3CAB2FE10-6ACAC4ACACEG12-2AC4A2C2A3CE15-3ACAC4ACA2C16-3A-2CAC4A19-ACA3-3A107-B-D4BDH20-7BH21-C3AD24-6A7-DBDK8-A5-2(AC)3-H2BDBDKI8-6AC3ACA2BD3BDKI7-6AC3AC2A2(BD)2B2KI7-C9A2(BD)B4DK2I6-ACA3C3ACA2B4DBDBKI7-11AB3D6BI7-A2C8A10BI3-N3-11AB2D3BD3BI3-L3-4ACD2B2D4BD3B3DB-2ML2-4(CA)D2B2D6BDB3I5-6AC2ACA2C5A2BD3I5-4A2C6AC3ACADBK2I7-AC11AC2ABD2BK-I7-CAC2A2CA3C4A2BD2BK7-4A2C7ACAC4BDN8-2C7A2C3AC2ACBG9-2(AC)4A2C2AC3A2EG11-4AC2ACA2C4AE14-3(AC)2AC2A2C17-2(5AC)20-2C2AC2A52-D5-D20-D2B5DBDJ18-BD3BDBD3J17-A2C2AD2B2J2D2B3-B12-6A3BHB2(D2B)K7-CAC-3AC2ADHDB3D2BDBI6-6A2(CA)CB3(D2B)I6-A2C2(2AC)3AB2D4B2DBL6-4AC2AC3AD5B2DB2DLO5-CA2C2A3C2A3BD4BD2BLO5-A2C8AD2B2(D3B)W5-5AC6ADBD7BDO-2O2-2ACA2C3AC2AD10BI2L3-5A4B2D4B7DBDQ4-C4ACACDB2DBD5B3DAD2IL2-2(AC)7ACAC3ACB2DBABI4-AC2A2C9AC2A4BD2K3-4A2C8AC2ACA2B2DIK4-5A2C6A2C3A2BD3BI6-3C4A3CAC4A2(DB)DK8-14A2CACDBN8-AC8ACAC5ADG10-4C2A2(CA)C3A2CAG11-2(2AC)ACA2CAC2AFG13-6AC6A17-CA-C-4A2-A21-C3ACA21-4D3B3D18-4BDB2D4BJ17-D5BD3BD2B2-BDR10-5A6B2(DB)D-2DH8-5AC2ABD2B2DB3D2BH5-2AC4AC3A3(2BD)B2DH4-6A3(CA)BD3BD5BK5-2A2CAC4ACA3DBD3BD2BI4-2AC2A3C4ABDB3D2B2DBI5-2(C2A)3C2AC6BDB2DBLO4-12A4BDBD4BDO4-5AC2AC3AB2(2D3B)D2OL2-6AC4AC6B2DB2D2BL2-5AD2BDBD3BD2B2D3BDBDQ3-3A2C4AD3BD4B2D3(BD)BL2-4A2C3ACAC2AC3AD3BABDL3-2C2ACA2C5A2CACADBD2BDI5-4A2C4AC6ABD2B2DK3-A2(C5AC2A)3BDBI4-C6AC7AC2A2DB2D2B6-2(2A2C)6AC4A2BD7-ACA2C3AC4A2(CA)C2ABN8-18ABG10-3AC2ACAC2AC4ABG11-2C3AC6ACA2-G13-AC-3(2AC)20-2CA4-2A19-7BD2BDJ16-D2BD4B2D3B2J3-DH11-10BD2B3D2B10-C4ABD4B2D2BD2BP6-A3-6AC4BDB3D2BP6-3A-7AD2B4DBD2BDH4-C2AC3A2C2AC6BDB2DBDH5-6AC4A2BDBD2BD3BK4-AC2AC7ABD3B2(2DB)DK4-A2C3AC5A2DBDB6DBK4-5AC6AB2D3BD2B3DO3-3AC5A2(CA)2(BD)3BD2BDBO-L-4ACD2BC3AC2(2BD)B2D2(BD)L2-2CA2C4B3D4B4DB2D2BQ3-6AC2A2(BD)2BD3BDB2D3BDL-2C3AC3ADBD5BDB3DBA2BL2-A2C4AC7AC3AD4BDBI2-C3ACA2(C4A)C2A2BDB2DL4-AC4AC5AC3ACA2(DB)2DI3-3ACAC4ACA3C2ACADB2D2B5-5AC11A2(B2D)B6-6AC3A2C7AC2BD7-2A2(CA)2CAC8ADBG8-C2AC6ACAC3ACA-G10-A-4AC6AC2AC13-C-AC3ACA2C2A-A16-A3-2ACA2-A18-2(2BD)3BDBDJ15-DBD3B3D6B2-3DH9-D2BDBD3BD6B2DBH9-2AC2ABD4BDBD3BDBH7-C-AC4A5BD2B2DBP6-3AC-2C4ABD3B3D2BDBP5-A2C5ACAC5B3D5BD3-C6AC2ACABDB2D4BD2B5-6AC4ACB2D2B2D4BDB4-2AC9A3BDB2(D2B)DK3-2C4A4C3A2(2BD)BD2BDBO3-2A2CA2C6A3BD7B2DOI2-C3A2BD3B2DB3D2(2BD)3BL3-3ACBD3BD2BD3B2DB2D3BQ4-2(CA)2CAD2BD3BDB2DBD5BL2-5AC2AC4(3BD)BL2-2AC6A3C2AC4A3(BD)BI2-ACA2C3AC6AC3A2(2BD)K4-3AC7AC6A4BDBI4-AC7A2C6AC5BI5-2AC3ACAC5AC3A3B2DB7-5AC3A2CAC4ACA2B7-3A2C2AC3ACAC6ABF8-3AC11AC2AF-C9-C2AC8AC3A14-A-C5ACAC2ACA16-A3-AC2AC20-D5BDB2D3B15-2(D2B)DBD3BD2B2-4D9-4BD4B2D2BDB5D10-6BD2BD5B2D2B7-A2-2C3A2BD2B2(2DB)P6-C2AC2-2AC2A4BD6BDP5-2AC8A12BDB3-4A2(C2A)CA5BDB2(D2B)4-2(C2A)C5A2D6BD3BD4-2(A2C)6A2(2BDBD)BD2B2-4A2CAC5A2D2BDB3DB2(D2B)-C2(A2C)AC3A2B3(DB)3D5B-2ACADB2D5B3DBD4BD2BK3-4AD7B2D2BDBD2B2D2BK3-5ACA4BD9BD3BI3-4ACACD2B2D8BD4BK3-A2(C6A)C2A7BK2-6AC6A2C2ACA2DBD2BI3-4AC2AC7AC2AC4BDBK5-C5A3C8A3B2DI5-3AC5A2C3ACA2C3BDBD6-AC2A2CAC3A2C4ABD2BD8-2(AC)5A2C2A4CA2B-U7-5A2C2AC3A2C2AC2-E9-5A2CA2C4AC2A-A11-2C8A2C2AC2A14-AC3-AC2AC3A16-3BD2B2DBD3B15-2DB2D10B2-2DBD9-2B2D7B2DBDB4D7-A2-2B3(DB)D4B3DB2D9-3C3ABD3B2DBD2BP7-3A2-5A3D5BD2BDP5-3A5CACA2(BD)2BD7B3-C3A2C6A2BD4B2(D2B)4-7AC4A4BDBD4B2D4-2C3ACAC4A2(2BD)BD6B2-2AC6A2(CA)4BD3BD2BDBD2B5A2(C2A)CAB3DBD2B2DB4DB3A2C3DBD4B2(D5B)L2-AC3ADBD5BD4BD2B2D2BDL2-3C2AC2A2(D2B)D3BD8B2-3AC4AB2D2(2BD)2(3BD)2B2-C3ACA2CAC3AC5A3B2DB2D3-2A2(CA)C2ACA2C5A2BD3BD4-C2AC6AC7A2(DB)2DK5-2(2AC)3A2C5AC2B2DBDI4-5AC4A3C3ACABD2B2D6-A3CAC2AC5ACAC2BD2B-F6-3AC7AC3AC4BFA7-4AC3AC7A2FEG10-2A2C2AC2A3C2AF4-E10-A-6A2C4A17-C-CAC7A17-2D5BDB2DB16-DBD3BDB4D3B2-2(DH)9-B4D3B2(DB)2D5BD7-A2-B4D3B4D6BH8-4A3C3BD5B2DP7-3A2-2C3A2B2D5BDBDP5-C2AC7ABD6B2(D2B)4-4AC3AC2ADBD5BD2B2D4-CAC5AC2ACBDB2DBD5BD4-4AC2ACAC2A3B2D4BDB2D4-A2C9A8B2DBD2BN2-5AC2A3CABD2B3D4BD2BE-C4ABDB2DBD3BD5BD3BDBM-3A2C3ABD2B2D4B3D3BQ4-5A2CA3(BD)B2D5BDB2DJL-7ACD7B2D2BD2BA2DJ2-AC4AC2ACAC2A2DB3D6BA3-2C2A3C7AC2AC2(DB)D2B4-7AC3A3C4A2(D2B)D4-4AC4A2C4A3C2B2D2B6-2ACAC10A2C5BD6-CA2C4AC6A2C3D2B2E6-7AC3AC4A3D2F8-A2C5ACAC4ACDFG11-14AF4-E10-A-AC2A2C3A2C4A-F12-A2-7AC2A-A14-3B3D5B18-2D7BDB3D2-2DH11-B2(2D2B)D3B2DB-H11-3BDBD3BD2B2D3BP8-2AC5AB2D2BD4BDBP6-3AC2AC3A2D2B2D2(BD)B2DH3-A-3A3C4A2BD4B2DBD2BH4-C8A2C3BD2BDBD2B-R5-5A2C4A2B2D2BDB2D2BH4-4AC3ACA2C3DB5DB2DJ4-3AC8AD2BDBD7B-N2-C4A3C3ACD6B2D2BD2BJ2-C3ACD2BDBD2B2D3B2(3DB)2-CA2(C2A)4B3D6B2DBQ4-2C2(2AC)2(D2B)3DB2D7BT2-2A3C2ADB2D2B2D3BD3BA2BV3-7A4B2D6B2D2B2DB3-7AC3AC5AC2B3D2B5-C3ACA4C5A2CD5B5-2AC10A2C3ABD4B6-2C7ACA3C2ACBD3B-E5-2ACA3C8ACA2(BD)EG7-A2C2AC6A2C2ABDE-AFG7-CA2(C3A)2(CA)CFE13-14A-CE14-3AC11A14-C3-3AC4AC17-B2DBD4B19-D2B2D4BDHJ18-9B3D2-BD-D11-D5BD6B2DB2DH8-2ACAC2A2B2(DB)2ABDB2DH6-2A2-4AC4B5D4BH5-ACA5C-A2(BD)3BD2BDBJ4-5AC4A2C7B2D2BDJ5-5AC5A2DB3D2(BD)BJ5-2C2ACA3CACA9BDBJ5-C-7AC2AD2B2D5BDB2-N2-ACA2CAC5ABDB2D7B-BJ2-C4ABD3BD2B2D3BD5B-D3-5A2CBD2(B2D)2B3(DB)Q5-7A2BD5BD3BD2BAD2BT2-C6A2B3D4BD5BC2BA3-2ACA2CA5B2DBD2B2D3BDB4-2(3AC)AC2(A3C)2B2D2B6-C16AD2B3D6-2ACA3C2A2(CA)2C2AD4BAG6-2AC4AC6A2CBD2BEC6-2(AC)2A2C4AC2ACABDFEFAE6-3AC4ACAC5ABF2-F9-C5ACAC6A5-F9-13ACA2-C-E10-3AC2AC5A2-2C13-A-A3-4A2C48-D4BD2BH20-BD3B2DJ22-4B2D2BJ5-J11-3ACAC2A-2BA2D3B2-J8-A3-A2C-CB2D2A2BD-DBJ6-2(AC)5A2-3DR2BD3BDR4-A-2A3C5A4BDB3D2BR6-C9A-2D2(3BD)BJ6-5A3C3A2DB4D2B2DJ5-4AC6AC4B3(DB)2JB-N2-CAC3A3BD2BDB3D2BD5B5-4ACD2BD9BD4B5-2AC3A2D3BDBD3B2D3B2Q5-2AC3AD4BD2BDBD4BD3BT3-A2CACA6B2(D3B)DBDVJ4-3ACAC2B8D3BD4B5-AC2AC8AC2ACA3BDG7-2(AC)3A2C5AC2AD4BAG5-3A2C2A3(CA)2CAC3BDE-UG5-4AC10ACBDB2-2FG6-2C3A2CAC4ACABDA2-FEG6-2C2ACA2C5A2CAN3-F9-5AC4A2C3A3-E11-ACA2CAC6A3-A13-11A4-A13-A-3A-2A-A49-3BDH25-3B2DH25-B2DB-J19-A-2C5-A21-ACA2-3A4-B11-3AC2A-C3A-A-R3H-BH7-3C4A2C-A2-4BHBDBJ6-2AC6A2(CA)DABDHA2BDJ7-3ACAC6A2B3DBDBJ6-A-4AC4A2CAD5B2D8-3(2AC)4A2BD5B4-N3-6A7BDBD2BDBD4-M3-A2CACA2(D3B)D6BSM3S3-5ACB2D7BD2BDJ7-7ABD4BDBD3B3D8-4ACA3(DB)2(D2B)DBD8-2A2C3A3(CA)C3ABDB-C8-3(AC)10AFDB2F8-C2AC3ACA2C5ABEDE9-A2C6A3C4ADB-CF-EG6-3A3C2AC7AE-NAF9-C3A2C3A3C3A3-2F10-C6A2C4A3-F13-AC5A2C2A4-A14-2ACA2CA26-C140-2A4-A29-A24-A22-2AC3A5-2A15-2AC3ACA4-2BA11-C-C5AC4A-2CDBD13-2A2C2AC2A2CBDAC2B9-6AC2A2(2CA)3BAD10-7AC5AC2(DB)A10-3A2CAD2B3ACADBF4M8-2C4ABD2BA3CBD2BJ10-4AC2ADBD4A2B3D10-AC5AD2(B2D)BD2FC11-4A2C3BD3B2(EB)CF10-A2C3AC3A4CAF-FAG9-C2ACAC2AC4A2(CA)GE11-9AC3A-3ACEF9-2A2C3AC3A3-A2GN2GF10-5ACA3-2A6-G11-10A4-E16-2A-2A27-C255-3A6-2N16-5AC6-C15-C4ACAC4-DAC14-10A-2B2CB14-AC6AC3AFA14-C6A2(C2A)EA14-AC4A2C4ABEA13-C2AC9ABE2C12-9A3CAFE2F12-7A2C4A-A14-2A2(CA)C4ACF-C-F12-2ACAC4AC2AE-A15-7AC2AC2-F-G13-CA3C6A2-E2-2G12-4A2C2AF21-4C2AF2-E22-2A2CA3C23-AF287-C26-2AC24-C3AC23-C7A-2D18-2AC7ACB16-3(2AC)AC2A16-AC2AC6AC2A14-8AC5AE15-CA2CAC7AG-A13-2(AC)3ACA2CAC2-G13-C3AC5ACA-AG14-2C2AC3A2CAC17-6A2(CA)C19-CA3C4A2-A18-6AC-3C19-C-ACA2-ACA23-2A-A342-A27-2A26-4A3-2A19-3AC2AC-C19-C9A19-A2CAC4A2CA16-C5ACAC2A-2A15-C2AC8AC2-G13-A2C2A2(C3A)17-5AC2A2C2A17-5CA2(C2A)17-C10AC19-2(3AC)-A21-CAC2-3A23-A28-A373-A27-CA-A25-3A-2A21-A2C2A2-A23-4ACA-A18-8A2C2-2A17-5AC2A-AC18-CA-C6AC18-C2A2C2(2AC)18-2A-2ACA-C2A20-4AC2A-C21-A2C-C2-A26-C486-C26-4AC28-2A25-A-2A4-C19-C-2A4-2A18-C3-CAC-A-C19-A3-2A2-2A21-3A25-C3A-A2-A22-2A2-A544-A27-A29-2A367-
