model
size = 29 27 27, scale = 0.05, origin = -y
material deform = 1, fade = true, lighting = smooth, roughness = 0.3, metalness = 0.6
  colors = A:#111 B:#FC6 C:#222 D:#F4C874 E:#888 F:#DAAF57 G:#AAA H:#B69248 I:#EEE J:#777 K:#BBB L:#92763A M:#4A3D1D N:#D3BDA0 O:#DDD P:#633 Q:#26200E R:#996
voxels
414-2A-A25-2ACAG26-2A721-CA26-C4A25-2ACAC25-3A25-CA-A29-A575-3A24-2(2AC)23-5AC22-3A2(CA)G21-5AC2A3E19-2(AC)4AECE18-C2A2CAC2AE20-7A2C23-4A28-A458-2C25-CAC2A4-A19-5ACG-2A19-A2C2ACE21-7A2E19-C7ACGE18-C2AC8A18-C5A2CA-C18-4AC3AC-AE18-7A2(CA)19-7ACA23-4AC400-C26-3ACA23-8A-A18-8A-AD18-AC5AC2AD17-3AC5ACACD16-2CA3C4A2GI16-2AC5AC2A18-10ACI17-3A4(CA)-C16-2AC5ACAC-2A15-2(2AC)4A2C2A16-C3ACA4C2A18-5AC4AC22-3AC2A339-CAC25-CAC3A5-A16-C7A2-4A15-5A2CA-A2B-A14-5C5ACAD-AI13-2A2CAC3AC2DB2-I12-9A5BE14-8ACAC2ACE14-CAC9AE16-4A2(C2A)3C2-I13-5ACA3C3A3I13-3C3ACA2C3A-AEI13-2ACAC5AC3AE14-AC7AC4A16-4A2C6A19-4A2C3AC22-3AC2A281-C3-A22-6A5-A16-2AC4A2C-AC3A14-C2AC3ACA-ABCBA14-AC3AC2A2C-2BABI12-6AC4A2BD2A13-4AC5AC2DBDAC12-2AC3A2BD2B3DBC5K7-2ACA2(C3A)2BDBKA11-6AC4AC2AEAEC11-C3ACA2C2AC3AECBE11-2(4AC)6ADE12-C3AC6AC3ABGI11-A2C3ACAC3AC2AG2I12-8A2C2ACAE14-4AC2A3(CA)E17-3A2C6A20-AC2AC3AC22-4A169-3A26-A2C51-CAC2(2A2-)C16-4A2C2AC2(-A)-D2F11-2A2C3A2C2A2BABDB2F10-A2(C4A)BA3BD2B10-C5AC3A5BD2BDB9-2ACAC2A3CB2D7BF7-A2C2(AC)3ACD2BD4BDB8-2A2C2A4BD6B2(DB)DK6-3AC2A6BDB3DBDB9-4A2C9A2CD2B9-AC6A2(CA)2C3A2DB9-3AC5AC4A2C3BC9-8ACAC5AD2BC9-8A2(CA)3CAB2GE10-6ACAC4ACACEI12-2AC4A2C2A3CE15-3ACAC4ACA2C16-3A-2CAC4A19-ACA3-3A107-B-D4BDF20-7BF21-C3AD24-6A7-2(DB)8-A5-2(AC)3-F2B2(DB)F8-6AC3ACA2BD3BDBH7-6AC3AC2A2(BD)4BH7-C9A2(BD)B4DFBF6-ACA3C3ACA2B4DBDBFDF6-11AB3D6BH7-A2C8A11B3-E3-11AB2D3BD3B2(K3-)4ACD2B2D4BD3B3DB-2KO2-4(CA)D2B2D6BD3BH5-6AC2ACA2C5A2(2BD)5-4A2C6AC3ACADBD2B7-AC11AC2ABD2BD-A7-CAC2A2CA3C4A2BD2BA7-4A2C7ACAC4BDJ8-2C7A2C3AC2ACBI9-2(AC)4A2C2AC3A2EI11-4AC2ACA2C4AE14-3(AC)2AC2A2C17-2(5AC)20-2C2AC2A52-D5-D20-D2B5DBDH18-BD3BDBD3H17-A2C2AD2B2H2D3B2-2B11-6A3BFB2(D2B)L7-CAC-3AC2ADFDB3D2BDBH6-6A2(CA)CB2(D2B)D3BL5-A2C2(2AC)3AB2D4B2DBL6-4AC2AC3AD5B2DB2DH6-CA2C2A3C2A3BD4BD2BF6-A2C8AD2BD3BD4B2-J2-5AC6ADBD7BDB-B3-2ACA2C3AC2AD11BDM3-5A4B2D4B7DBD3B2-C4ACACDB2DBD5B3DA2DN3-2(AC)7ACAC3ACB2DBABH4-AC2A2C9AC2A4B3D3-4A2C8AC2ACA2B2D2B4-5A2C6A2C3A2BD3BA6-3C4A3CAC4A2(DB)DA8-14A2CACDBJ8-AC8ACAC5ADI10-4C2A2(CA)C3A2CAI11-2(2AC)ACA2CAC2AGI13-6AC6A17-CA-C-4A2-A21-C3ACA21-4D3B3D18-4BDB2D4BH17-D5BD3BD2B2-BDF10-5A6B2(DB)4DF8-5AC2ABD2B2DB3D2BF5-2AC4AC3A3(2BD)B2DF4-6A3(CA)BD3BD5BL5-2A2CAC4ACA3DBD3BD2BH4-2AC2A3C4ABDB3D2B2DBF5-2(C2A)3C2AC6BDB2DBD5-12A4BDBD4B2D-J2-5AC2AC3AB2(2D3B)2(DB)2-6AC4AC6B2DB2D3BF-5AD2BDBD3BD2B2D3BDB2DBM-3A2C4AD3BD4B2D3(BD)BN2-4A2C3ACAC2AC3AD3BABDQ3-2C2ACA2C5A2CACADBD2B2D5-4A2C4AC6ABD2B2DB3-A2(C5AC2A)3BD2B4-C6AC7AC2A2DB2D2B6-2(2A2C)6AC4A2BD7-ACA2C3AC4A2(CA)C2ABJ8-18ABI10-3AC2ACAC2AC4ABI11-2C3AC6ACA2-I13-AC-3(2AC)20-2CA4-2A19-7BD2BDH17-2BD4B2D3B2H3-DF11-10BD2B3D2B10-C4ABD4B2D2BD2BF6-A3-6AC4BDB3D2BPL5-3A-7AD2B4DBD2BDF4-C2AC3A2C2AC6BDB2DBDF5-6AC4A2BDBD2BD3BL4-AC2AC7ABD3B2(2DB)DF4-A2C3AC5A2DBDB6DBH4-5AC6AB2D3BD2B3DB-J-3AC5A2(CA)2(BD)3BD2BD4B-4ACD2BC3AC2(2BD)B2DBDB2DF-2CA2C4B3D4B4DB2D4BM-6AC2A2(BD)2BD3BDB2D3BDN-2C3AC3ADBD5BDB3DBA2BQ2-A2C4AC7AC3AD4BDBH2-C3ACA2(C4A)C2A2BDB2DB4-AC4AC5AC3ACA2(DB)2DB3-3ACAC4ACA3C2ACADB2D2B5-5AC11A2(B2D)B6-6AC3A2C7AC2BD7-2A2(CA)2CAC8ADBI8-C2AC6ACAC3ACA-I10-A-4AC6AC2AC13-C-AC3ACA2C2A-A16-A3-2ACA2-A18-2(2BD)3BDBDH16-BD3B3D6B2-3DF9-D2BDBD3BD6B2DBF9-2AC2ABD4BDBD3BDBF7-C-AC4A5BD2(2B2D)4-3AC-2C4ABD3B3D2BDBPL4-A2C5ACAC5B3D5BF3-C6AC2ACABDB2D4BD3BF3-6AC4ACB2D2B2D4BD2B3-2AC9A3BDB2(D2B)DH3-2C4A4C3A2(2BD)BD2BDB2DJ-2A2CA2C6A3BD7B3DG2-C3A2BD3B2DB3D2(2BD)3BDE2-3ACBD3BD2BD3B2DB2D3BDBO2-2(CA)2CAD2BD3BDB2DBD5BH2-5AC2AC4(3BD)BH2-2AC6A3C2AC4A3(BD)BA2-ACA2C3AC6AC3A2BD2B2D4-3AC7AC6A4BD2B4-AC7A2C6AC5BD5-2AC3ACAC5AC3A3B2DB7-5AC3A2CAC4ACA2B7-3A2C2AC3ACAC6ABG8-3AC11AC2AG-C9-C2AC8AC3A14-A-C5ACAC2ACA16-A3-AC2AC20-D5BDB2D3B16-2(2BD)BD3BD2B2-3DF9-4BD4B2D2BDB4DF10-6BD2BD5B2DBD7-A2-2C3A2BD2B2DB2D2B2D4-C2AC2-2AC2A4BD6BDPL4-2AC8A12BDB3-4A2(C2A)CA5BDB2(D2B)F3-2(C2A)C5A2D6BD3BDB3-2(A2C)6A2(2BDBD)BD2B2-4A2CAC5A2D2BDB3DB2(D2B)-C2(A2C)AC3A2B3(DB)3D5B-2ACADB2D5B3DBD4BD3B3-4AD7B2D2BDBD2B2D2BJ3-5ACA4BD9BD4B3-4ACACD2B2D8BD5B3-A2(C6A)C2A8B2-6AC6A2C2ACA2DBD3B3-4AC2AC7AC2AC4BDBD5-C5A3C8A3B2D2B4-3AC5A2C3ACA2C3BDBD6-AC2A2CAC3A2C4ABD2BD8-2(AC)5A2C2A4CA2B-R7-5A2C2AC3A2C2AC2-E9-5A2CA2C4AC2A-A11-2C8A2C2AC2A14-AC3-AC2AC3A16-3BD2B2DBD3B16-DB2D10B2-2DBF9-2B2D7B2DBDB3DF7-A2-2B3(DB)D4B3DB2D9-3C3ABD3B2DBD2BDBD5-3A2-5A3D5BD2BDPL4-3A5CACA2(BD)2BD7B3-C3A2C6A2BD4B2(D2B)F3-7AC4A4BDBD4B2DB3-2C3ACAC4A2(2BD)BD6B2-2AC6A2(CA)4BD3BD2BDBD2B5A2(C2A)CAB3DBD2B2DB4DB3A2C3DBD4B2(D5B)D2-AC3ADBD5BD4BD2B2D2BDJ2-3C2AC2A2(D2B)D3BD8B2-3AC4AB2D2(2BD)2(3BD)2B2-C3ACA2CAC3AC5A3B2DB2D3-2A2(CA)C2ACA2C5A2BD3BD4-C2AC6AC7A2(DB)3D5-2(2AC)3A2C5AC2B2DBDB4-5AC4A3C3ACABD2B2D6-A3CAC2AC5ACAC2BD2B-G6-3AC7AC3AC4BGA7-4AC3AC7A2GEI10-2A2C2AC2A3C2AG4-E10-A-6A2C4A17-C-CAC7A17-2D5BDB2DB17-BD3BDB4D3B2-2(DF)9-B4D3B2(DB)2D5BF7-A2-B4D3B4D6BF8-4A3C3BD5B3DBF5-3A2-2C3A2B2D5BDBDPL4-C2AC7ABD6BD2BDBF4-4AC3AC2ADBD5BD2B2DF3-CAC5AC2ACBDB2DBD5BDB3-4AC2ACAC2A3B2D4BDB2D4-A2C9A8B2DBD2BJ2-5AC2A3CABD2B3D4BD2BE-C4ABDB2DBD3BD5BD3BDBK-3A2C3ABD2B2D4B3D6BK-5A2CA3(BD)B2D5BDB2DH2-7ACD7B2D2BD2BA2DH2-AC4AC2ACAC2A2DB3D6BA3-2C2A3C7AC2AC2(DB)D2B4-7AC3A3C4A2(D2B)D4-4AC4A2C4A3C2B2D2B6-2ACAC10A2C5BD6-CA2C4AC6A2C3D2B2E6-7AC3AC4A3D2G8-A2C5ACAC4ACDGI11-14AG4-E10-A-AC2A2C3A2C4A-G12-A2-7AC2A-A14-3B3D5B18-2D7BDB3D2-2DF11-B2(2D2B)D3B2DB-F11-3BDBD3BD2B2D3BF8-2AC5AB2D2BD4BDBPL5-3AC2AC3A2D2B2D2(BD)B2DF3-A-3A3C4A2BD4B2DBD2BF4-C8A2C3BD2BDBD2B-L5-5A2C4A2B2D2BDB2D2BF4-4AC3ACA2C3DB5DB2DH4-3AC8AD2BDBD7B-J2-C4A3C3ACD6B2D2BD2BH2-C3ACD2BDBD2B2D3B2(3DB)F-CA2(C2A)4B3D6B2D4BM-2C2(2AC)2(D2B)3DB2D7BN2-2A3C2ADB2D2B2D3BD3BA2BQ3-7A4B2D6B2D2B2DB3-7AC3AC5AC2B3D2B5-C3ACA4C5A2CD5B5-2AC10A2C3ABD4B6-2C7ACA3C2ACBD3B-E5-2ACA3C8ACA2(BD)EI7-A2C2AC6A2C2ABDE-AGI7-CA2(C3A)2(CA)CGE13-14A-CE14-3AC11A14-C3-3AC4AC17-B2DBD4B20-2B2D4BDFH18-9B3D2-B3D11-D5BD6B2DB2DF8-2ACAC2A2B2(DB)2AB4DF6-2A2-4AC4B5D4BF5-ACA5C-A2(BD)3BD2BDBH4-5AC4A2C7B2D2BDH5-5AC5A2DB3D2(BD)BH5-2C2ACA3CACA9BDBH5-C-7AC2AD2B2D5BDB2-J2-ACA2CAC5ABDB2D7B-BH2-C4ABD3BD2B2D3BD5B-DF2-5A2CBD2(B2D)2B2(DB)D2BDBM2-7A2BD5BD3BD2BAD2BN2-C6A2B3D4BD5BC2BA3-2ACA2CA5B2DBD2B2D3BDB4-2(3AC)AC2(A3C)2B2D2B6-C16AD2B3D6-2ACA3C2A2(CA)2C2AD4BAI6-2AC4AC6A2CBD2BEC6-2(AC)2A2C4AC2ACABDGEGAE6-3AC4ACAC5ABG2-G9-C5ACAC6A5-G9-13ACA2-C-E10-3AC2AC5A2-2C13-A-A3-4A2C48-D4BD2BF20-BD3B2DH25-B2D2BH5-H11-3ACAC2A-2B3D3B2DH8-A3-A2C-CB2DAD2B3DBH6-2(AC)5A2-DADL2BD3BDL4-A-2A3C5A4BDB3D2BL6-C9A-2D2(3BD)BH6-5A3C3A2DB4D2B2DH5-4AC6AC4B3(DB)2HB-J2-CAC3A3BD2BDB3D2BD5B5-4ACD2BD9BD4B-M3-2AC3A2D3BDBD3B2D5B-B3-2AC3AD4BD2BDBD4BD3BN3-A2CACA6B2(D3B)DBDQH4-3ACAC2B8D3BD4B5-AC2AC8AC2ACA3B2D7-2(AC)3A2C5AC2AD4BA6-3A2C2A3(CA)2CAC3BDE-R6-4AC10ACBDB2-2GI6-2C3A2CAC4ACABDA2-GEI6-2C2ACA2C5A2CAJ3-G9-5AC4A2C3A3-E11-ACA2CAC6A3-A13-11A4-A13-A-3A-2A-A50-2BDF25-3B2DF30-H19-A-2C5-D21-ACA2-3A16-3AC2A-C3A-A-L3FDBF7-3C4A2C-A2-4B2(DB)H6-2AC6A2(CA)DABDFA2BDH7-3ACAC6A2B3DBDBH6-A-4AC4A2CAD5B2D8-3(2AC)4A2BD5B4-J3-6A7BDBD2BDBD4-K3-A2CACA2(D3B)D6BOK3O3-5ACB2D7BD2BDH7-7ABD4BDBD3B3D8-4ACA3(DB)2(D2B)DBD8-2A2C3A3(CA)C3ABDB-C8-3(AC)10AGDB2G8-C2AC3ACA2C5ABEDE9-A2C6A3C4ADB-CG-EI6-3A3C2AC7AE-JAG9-C3A2C3A3C3A3-2G10-C6A2C4A3-G13-AC5A2C2A4-A14-2ACA2CA26-C140-2A34-A24-A22-2AC3A5-2A15-2AC3ACA4-2BA11-C-C5AC4A-2CDBD13-2A2C2AC2A2CBDAC2B9-6AC2A2(2CA)3BAD10-7AC5AC2(DB)D10-3A2CAD2B3ACADBG4K8-2C4ABD2BA3CBD2BH10-4AC2ADBD4A2B3D10-AC5AD2(B2D)BD2GC11-4A2C3BD3B2(EB)CG10-A2C3AC3A4CAG-GAI9-C2ACAC2AC4A2(CA)IE11-9AC3A-3ACEG9-2A2C3AC3A3-A2IJ2IG10-5ACA3-2A6-I11-10A4-E16-2A-2A27-C255-3A6-2J16-5AC6-C15-C4ACAC4-DAC14-10A-2B2C15-AC6AC3AGA14-C6A2(C2A)EA14-AC4A2C4ABEA13-C2AC9ABE2C12-9A3CAGE2G12-7A2C4A-A14-2A2(CA)C4ACG-C-G12-2ACAC4AC2AE-A15-7AC2AC2-G-I13-CA3C6A2-E2-2I12-4A2C2AG21-4C2AG2-E22-2A2CA3C23-2A287-C26-2AC24-C3AC23-C7A-2D18-2AC7ACB16-3(2AC)AC2A16-AC2AC6AC2A14-8AC5AE15-CA2CAC7AI-A13-2(AC)3ACA2CAC2-I13-C3AC5ACA-AI14-2C2AC3A2CAC17-6A2(CA)C19-CA3C4A2-A18-6AC-3C19-C-ACA2-ACA23-2A-A342-A27-2A26-4A3-2A19-3AC2AC-C19-C9A19-A2CAC4A2CA16-C5ACAC2A-2A15-C2AC8AC2-I13-A2C2A2(C3A)17-5AC2A2C2A17-5CA2(C2A)17-C10AC19-2(3AC)-A21-CAC2-3A23-A28-A373-A27-CA-A25-3A-2A21-A2C2A2-A23-4ACA-A18-8A2C2-2A17-5AC2A-AC18-CA-C6AC18-C2A2C2(2AC)18-2A-2ACA-C2A20-4AC2A-C21-A2C-C2-A26-C486-C26-4AC28-2A25-A-2A4-C19-C-2A4-2A18-C3-CAC-A-C19-A3-2A2-2A21-3A25-C3A-A2-A22-2A2-A544-A27-A29-2A367-
