model
size = 15 20 8, scale = 0.05, origin = -y
material deform = 1, fade = true, lighting = smooth, roughness = 0.3, metalness = 0.6
  colors = A:#FF4364 B:#FFC86B C:#F3E1C9 D:#FCDFAC E:#1A222F F:#FFF
voxels
167-10A5-10A2(3-6B2A2E2A)5(5-10A)155-10A5-10A2(3-6B2A2E2A)5(5-10A)170-10A5-6A2(-3A3-2B4AFA)-3A5-10A5-A5-4A3(5-10A)52-7(5C2A8-)5C2A6-10A5-10A2(3-2B4AF5A)5-10A5-A5-4A3(5-10A)22-2(2B3-2B8-)A4C2A8-A4C2A6-4A5D2A4-11A2-30A4-7A8-7A6-10A5-2(10A3-2B)2(10A5-)A4-5A2(5-10A)5-12A13-2A5-2(2B3-2B8-)A4C2A8-A4C2A6-4A5D2A4-11A2-30A4-7A8-7A6-10A5-2(10A3-2B)5(10A5-)12A13-2A35-7(7A8-)7A6-10A5-2(10A3-2B)5(10A5-)10A69-3A98-10A5-2(10A3-2B)5(10A5-)10A18-
