model
size = 15 32 28, scale = 0.05, origin = -y
material deform = 1, fade = true, lighting = smooth, roughness = 0.3, metalness = 0.6
  colors = A:#960 B:#A00 C:#444 D:#222 E:#333
voxels
426-3B12-3B132-3B477-2(3B12-)3B447-3(3B12-)3B462-4(3B12-)3B87-3(3B12-)3B297-15(3B12-)3B267-2(15(3B12-)3B282-)7(3C12-)7(3B12-)3B268-5(D14-)D13-3(3C12-)6(3B12-)3B191-5A10-2A-2A11-A-A13-2A27-3(3C12-)3C13-2(D14-)D13-2(3C12-)5(3B12-)3B189-2(A7-)4(8A7-)7A8-2A3C2A8-2A3C-A9-A3C2A10-3CA12-2(D14-)D13-2(3C12-)5(3B12-)3B173-A9-A2(4-3A5-3A)2(5-3A4-3A)5-3A3-4A5-4A-5A5-9A6-9A7-2A3C3A8-A3C2A10-ADA13-D14-D13-2(3C12-)4(3B12-)3B184-A4(3-2A8-2A)3-2A7-3A3-2(2A7-2A4-)3A6-2(2A5-)3A5-3A3C3A7-2A3C2A10-ADA13-D14-D13-3C6(12-3B)157-A14-4(2A10-A2-)2(2A9-2A2-)2A9-2A3-A9-2A3-2A8-A5-2A6-2A5-3A3C3A8-A3C2A11-D14-D13-2(3C12-)4(3B12-)3B170-3A6(11-2A-A)11-A2-2A10-A3-A9-2A3-2A8-A5-2A6-A7-2A3C2A10-ADA13-D14-D13-3C5(12-3B)156-A14-A13-2A13-4(3A12-)A-A12-A-A11-A2-2A10-A3-A9-A5-A7-2A6-2A3C-2A9-AD2A12-D14-D13-3C5(12-3B)66-A13-2A13-3A2(12-A-A)12-3A12-5(2A13-)2(3A12-)A-A12-A-A11-A2-2A10-A3-A9-A5-A7-2A6-2A3C-2A8-2AD2A12-D14-D13-3C5(12-3B)52-A2(12-3A)12-A2(-A11-2A)-A11-A2-A11-4A4(12-3A)2(12-A-A)11-2A-A11-A2-A11-A3-A10-A3-A9-A5-2A6-A7-2A3-2A10-3C13-D14-D13-3C5(12-3B)37-A11-A2-3(A11-2A-)A11-A2-2A10-3(A2-A11-)6(2A-A11-)A2-2A2(10-A3-A)9-2A4-A8-A2(5-2A)8-6A10-3C13-D14-D13-3C5(12-3B)23-A4(9-2A2-2A)3(9-2A3-A)9-2A2(2-2A10-A)32-A11-2(A2-2A10-)A2-2A2(9-2A3-A)9-2A3-2A7-2A5-2(2A6-)3A-4A8-A3CA12-2(D14-)D13-3C5(12-3B)9-A8-A4-4(2A8-2A3-)4(2A8-A4-)2A8-2A14-A32-2A3(9-2A3-A)9-A4-2A8-A4-2A7-2(2A5-)3A5-4A2-3A7-7A10-3C13-D14-D13-2(3C12-)4(3B12-)3B9-2A5-2A6-5(2A5-3A5-)3(2A6-2A5-)A7-2A4-A44-2(2A7-2A4-)3A6-2A4-2(3A5-)2A2(5-3A)3-3A7-8A7-7A10-AE2A26-3C13-D13-3C6(12-3B)10-5(2A4-2A7-)A5-2A2(7-2(A-)4A)6-2A2(-A)-2A6-A2-A-A2(12-3A)10-A-3A-A7-6A-3A2(5-3A-6A)5-5A-3A7-8A7-7A9-6A10-3A42-3C13-D13-3C5(12-3B)26-2(A3-2A9-)3(A4-A9-)A-A2-2(A10-3A-)A11-2A-A11-2A13-2A12-4A9-7A9-6A9-5A10-5A11-4A11-3A13-A88-2C13-5(3B12-)3B387-6(3B12-)3B402-4(3B12-)3B432-2(3B12-)3B51-
