model
size = 31 25 29, scale = 0.05, origin = -y
material deform = 1, fade = true, lighting = smooth, roughness = 0.3, metalness = 0.6
  colors = A:#F90
voxels
290-A188-A372-A30-A28-A-2A-A24-2A-2A25-6A-A4(23-8A)23-7A25-6A-A24-4A28-3(5A26-)4A334-2(A-)A2-A22-2A-3A-4A19-2(3A-)5A18-2(12A19-)2A2-9A18-2A2-10A15-A-14A17-11A20-11A21-10A21-12A18-A-11A22-9A22-8A25-A-4A25-A241-A29-2(3A8-2A18-)3A8-2A17-3A28-2(2A29-)2A13-A15-2A7-2A4-A15-3A6-2A2-4A15-3A8-3A17-4A6-4A18-14A17-16A15-15A20-10A21-9A22-7A26-A209-2A26-A-3A26-A2-2A26-4A27-3A28-3A16-A11-2A17-A12-A16-2A12-2A15-2A11-3A14-2(3A12-)4A13-3A10-5A13-4A8-6A13-6A4-7A16-15A16-14A17-14A20-8A25-6A204-A30-A29-5A7(25-6A)12-A12-6A12-2A12-5A11-4A11-5A10-5A11-5A9-5A13-5A6-7A13-16A18-13A18-10A22-9A23-A176-2(A30-)A29-2A-2A26-5A27-4A27-4(6A25-)6A2(26-5A)13-A14-3A12-6A10-4A10-7A11-5A6-8A14-14A17-11A20-11A23-A4-A142-2A28-3A27-4A27-3A27-4A26-5A27-3A28-2A-A26-3A-A25-5A27-4A2(28-3A)20-A8-4A16-3A10-2A16-4A10-3A12-6A10-4A10-6A11-7A4-8A15-14A18-13A18-7A172-2(3A28-3A27-)6(3A28-)4A27-4A29-3A18-2A8-4A16-3A9-4A14-7A7-4A12-7A9-5A8-6A13-16A16-15A17-11A23-A115-2(A30-)A29-2(2A28-)6(3A28-)5A26-5A27-4A19-A8-3A18-4A7-3A16-7A6-3A14-6A9-4A7-8A13-3A-A5-6A16-15A16-14A19-12A136-A30-A2(28-3A)4(27-4A)2(28-3A)29-4A27-4A26-5A28-2A20-4A5-3A18-5A6-3A17-2(4A8-)10A10-4A7-7A14-16A16-14A19-12A105-A2(29-2A)2(28-3A)6(27-4A)29-A30-2A23-A5-2A22-2A6-2A20-4A5-3A18-5A6-3A17-5A6-4A9-4A-5A9-5A-A5-7A14-16A16-15A18-12A23-2A80-A30-A29-2A2(28-3A)4(27-4A)27-3A28-3A29-2A30-A30-2A22-2A5-3A20-3A6-2A20-4A5-3A18-5A6-4A14-5A9-4A4-3A5-4A12-18A15-15A17-12A21-8A138-2A10(28-3A)29-2A26-A2-2A22-5A2-3A20-6A3-3A18-6A4-4A16-6A7-4A5-A-A3-5A12-18A14-16A17-12A20-9A77-A29-2A27-A-2A27-4A9(28-3A)2(29-2A)22-5A2-3A20-6A3-3A18-5A5-4A16-5A6-A-5A3-3A4-5A12-19A13-16A17-13A19-9A77-A2(29-2A)9(28-3A)28-2A30-2A29-2A22-4A3-3A20-5A4-3A18-3A7-4A16-3A8-8A9-5A12-19A12-17A17-12A20-9A139-A29-2A2(28-3A)28-3(2A29-)3(3A28-)4A28-3A28-2A22-3A4-3A20-4A5-3A18-4A7-3A16-3A9-5A4-4A2-6A12-19A13-16A17-12A19-9A24-A83-A30-2A29-2A8(28-3A)29-3A28-3A21-A2(6-3A20-2A)8-2A18-2A9-4A15-3A9-5A6-A2-7A12-18A15-15A17-12A22-6A47-2(2A29-)2(2A28-2A29-)3A27-4A3(28-3A)2(29-2A)29-3A28-3A20-3A5-3A20-3A6-3A18-3A8-3A16-3A9-4A14-3A10-6A3-4A-7A10-A-18A15-15A18-11A24-2A49-A30-2A29-2A4(28-3A)28-4(2A29-)3A27-3A29-2A29-3A20-A7-3A20-4A5-3A18-4A7-3A16-3A10-2(4A12-)5A8-6A13-17A16-12A20-9A140-A9(28-3A)28-2A29-3A20-A2-A4-3A20-4A4-4A18-6A5-3A16-4A9-3A14-4A10-5A11-3A13-6A6-6A14-16A17-12A22-7A28-A81-A2(29-2A)2(28-2A29-2A)29-2A3(30-A)30-2A21-A7-2A20-3A6-3A18-4A7-3A16-5A8-3A14-6A8-2(4A12-)5A8-4A14-17A15-15A18-10A24-7A109-2A30-A2(29-2A)28-2A2(28-3A)28-2A30-A30-2A29-2A30-A30-2A18-2A2(9-3A16-3A)10-4A12-2(5A10-)4A13-7A4-6A14-15A18-13A19-3A-5A204-A3(29-2A)27-A-A30-2(A18-A11-)A30-2A29-2A30-2A16-2A11-3A14-3A11-4A12-3A12-5A10-4A12-7A6-5A14-17A14-15A19-12A20-2A179-A30-2A3(28-3A)28-2A18-A2(11-A17-2A)10-2A17-2(2A10-3A16-)2A11-3A14-4A10-4A12-2(5A10-)4A12-7A6-7A12-17A14-17A16-14A18-6A26-2A212-A28-2(4A27-)3A29-2A29-A16-A13-A16-A12-3A14-3A11-3A14-2(3A12-)5A11-4A10-6A11-5A8-6A13-6A4-7A15-16A15-15A16-15A15-6A27-3A29-2A214-2A2(28-3A)27-3A28-2(2A12-A16-)2A12-2A15-2A12-4A13-3A4-A5-5A13-4A3-A4-6A14-4A6-4A-2A15-2(13A18-)13A2(19-12A)17-A-2A4-A25-A215-A2(29-2A)6-2(A22-4A-2A-)A3-A17-11A2-A17-14A17-8A-5A18-3A-9A16-A-13A18-2(12A19-)12A20-11A20-A-9A22-7A-A30-A360-A-A2-2A26-2A-2A2(26-5A)24-A-6A23-A2-6A22-A2-6A25-7A26-2A2-A30-A322-
