model
size = 23 32 9, scale = 0.05, origin = -y
material deform = 1, fade = true, lighting = smooth, roughness = 0.3, metalness = 0.6
  colors = A:#D1B83B B:#EAD272 C:#CC6
voxels
-21C-C29(21A2C)21AC-21C-C2(21AC690AC21A2C)4(21AC409A2B21A2B5(6A17B)141AC21A2C)21AC409A2B21A2B5(6A17B)141AC21AC-21C-C3(21A2C)7A3(CA)C7A2(2C6A4(CA)C6A)2C7A3(CA)C7A2(2C21A)2C4A2(C3A)CAC3AC2A2C4A2(C3A)C5AC2A2C2A2(3CA)3C3A3C2A2C2A5(CA)C3ACAC2A2C2A2(3CA)3C3A3C2A2(2C21A)2C3A3(3CA)2C4A2C3A4(CA)C2(3ACAC3A2C2(3AC)2(AC))3ACAC3A2C3A2(3CA)C3A2C4A2(2C21A)2C3A4(CA)3CA3C3A2C3A4(CA)C3ACAC3A2C3ACA2C2A2(CAC3A)2C3A4(CA)C3ACAC3A2C3A4(CA)C3A3C3A2(2C21A)C-21C-
