model
size = 32 32 26, scale = 0.05, origin = -y
material deform = 1, fade = true, lighting = smooth, roughness = 0.3, metalness = 0.6
  colors = A:#9CF B:#96F C:#6F6 D:#96C E:#63C F:#660 G:#9F6 H:#66C I:#CF6 J:#339 K:#336 L:#222 M:#99C N:#93F O:#669 P:#639 Q:#693 R:#696 S:#9C9 T:#007 U:#99F V:#383838 W:#330 X:#333 Y:#663 Z:#010 Aa:#6C9 Ab:#555 Ac:#363 Ad:#020 Ae:#30C Af:#6C6 Ag:#690 Ah:#888 Ai:#63F Aj:#309 Ak:#996 Al:#777 Am:#360 An:#030 Ao:#005 Ap:#666 Aq:#90F Ar:#60F As:#070 At:#001 Au:#9C3 Av:#6F9 Aw:#444 Ax:#306 Ay:#366 Az:#30F Ba:#00E Bb:#00A Bc:#999 Bd:#009 Be:#393 Bf:#100 Bg:#003 Bh:#004 Bi:#390 Bj:#9C6 Bk:#6F3 Bl:#AAA Bm:#699 Bn:#66F Bo:#33C Bp:#6C0 Bq:#00D Br:#050 Bs:#33F Bt:#00C Bu:#008 Bv:#6C3 Bw:#002 Bx:#93C By:#9CC Bz:#9F9 Ca:#BBB Cb:#969 Cc:#69C Cd:#60C Ce:#006 Cf:#936
voxels
621-A5-A24-2(A5-A25-)A5-A24-2(A7-A23-)A8-A23-A7-A23-A6-A1111-10A22-10A918-10A22-10A20-2A10-2A18-2A10-2A852-10A22-10A20-2A10-2A18-2A10-2A17-A14-A16-A14-A819-10A20-2A10-2A18-2A10-2A17-A14-A16-A14-A15-A16-A14-A16-A786-10A20-2A10-2A17-A14-A16-A14-A15-A16-A14-A16-A13-A18-A12-A18-A723-6A24-10A21-A10-A19-A12-A17-A14-A16-A14-A15-A16-A13-2A16-2A12-A18-A12-A18-2A660-2A28-6A24-10A20-2A10-2A17-2A12-2A16-A14-A15-A16-A14-A16-A13-A18-A11-2A18-2A2(10-A20-A)13-23(16A16-)3A10-3A16-2A12-2A16-A14-A15-A16-A13-2A16-2A10-2(3A18-3A8-)2A20-2A8-2A20-2A10-19(20A12-)20A6-4A2-20A2-9A-20A-69A-30A3-28A5-5A-14A-5A7-4A-14A-4A8-3A2-14A2-3A7-4A3-12A3-4A6-2A22-2A7-A22-A9-18(5A12-5A10-)5A12-5A5-10A12-20A12-11A2(3-6A12-6A3-2A)3-6A12-6A3-4A-6A12-2(6A-)6A12-6A-3A-2A-6A12-6A-2A3-8A12-8A5-4A-2A12-2A-4A6-4A2-2A10-2A2-4A6-2A5-12A5-2A6-2A22-2A7-23(4A16-4A8-)4A16-4A4-A3-4A16-4A3-3A2-4A16-4A2-5A-4A16-4A-3A-7A16-7A3-6A16-6A4-5A-A14-A-5A4-3A4-2A10-2A4-3A5-2A22-2A25(6-4A18-4A)3-A2-4A18-4A2-3A-4A18-4A-9A18-7A-6A18-6A3-6A16-6A4-3A3-A14-A3-3A5-2A22-2A5-25(5A18-5A4-)5A18-5A2-A-5A18-5A-8A18-14A18-7A-7A16-7A3-3A3-A14-A3-3A5-2A22-2A5-26(4A20-4A4-)5A18-5A2-7A18-14A18-7A-7A16-7A3-3A3-A14-A3-3A5-2A22-2A5-27(4A20-4A4-)4A20-4A2-A-5A18-5A-9A16-8A2-3A3-A14-A3-3A5-2A22-2A5-28(4A20-4A4-)5A18-5A2-8A16-8A3-2A3-A14-A3-2A6-2A22-2A5-28(4A20-4A4-)5A18-5A2-8A16-8A3-2A3-A14-A3-2A7-A22-A6-27(4A20-4A4-)4A20-4A2-A-5A18-5A-A-7A16-7A5-2A2-A14-A2-2A9-A20-A7-26(4A20-4A4-)4A20-4A2-A-4A20-4A-8A18-7A2-6A16-6A7-A2-A14-A2-A11-A18-A8-25(4A20-4A4-)4A20-4A2-A2-4A18-4A2-3A-4A18-4A-5A-3A18-3A-3A3-6A14-6A9-2(A2-A12-)A18-A8-24(5A18-5A4-)5A18-5A2-A2-4A18-4A2-3A-4A18-4A-5A-3A18-3A-3A2-7A14-7A8-3A14-3A13-A-3A8-3A-A14-A16-A10-5(4A18-3AI6-)4A18-3AG6-4A18-3AC3(6-Ak3A18-4A)6-F3A18-4A6-Y3A18-4A6-R3A8(18-4A6-4A)18-4A5-5A18-5A4-5A18-5A5-4A18-4A3-A2-4A18-4A2-3A-4A18-4A-9A18-7A-6A18-6A7-3A14-3A13-6A6-6A15-A14-A16-A14-A12-2(I23A8-)Q23A8-Ac22AAu8-Ax22ABp8-P22ABk8-Cf22AC2(8-D18A-3AG)8-K18A-3AG8-W18A-3AC8-F18A-3AC8-Q18A-3AG8-Al18A-3AAk8-D18A-3AJ8-B18A-3ABb8-19A-3ABd8-19A-3ABf8-19A-4A4-A3-19A-4A3-3(2A2-20A-5A2-)2A2-26A2-4A-24A-6A-24A-3A2-28A8-20A14-6A4-6A17-2A10-2A18-A12-A46-BjAcAb16AIAI10-AmZL16ABeBjI10-YAmX16AAsAgAu10-OPCe16ABiFAg10-OAbV16AR2Ag10-O2K16AHRBp10-P2E16ABBnAf10-2ED15ABBl2C10-BxET15AUS2C10-PDAe15AAa3C10-2XAd15A4C10-2FW15A4C10-3F15A2C2G10-AbKT15ACAaBcI10-BHE15ACBcBsH10-3B15AGDAzBa10-3B15ASAiAzBq10-D2B15ADAqArBt10-AD16ANAArBd6-22AN2ABf4A-23AB2(31AE)8A-30A3-28A5-26A10-18A16-14A19-2A8-2A20-A10-A82-OApT2AjKBrAdZLAmAnAdWAcAu16-AoKJBhXL2AnWQAgAsAfBvBiAs16-BwVBgAtLBhXAcYApAmQ3CBe16-AnZAtVAwVAxPHEAcS4C16-Ad2ZXKV2L3KCcAaSAaO16-LZVAyRAyJAoLQTHM2BN16-AbAcApAeBoNAiBoAoRAyAlM3B16-AhEBa2AiAjEJRYAl5B16-BBnBbHETAePRQON2BMU16-PEAoODAeEJRAfEN2BSAv16-AtVWBgJEJAb2BmAqNBUAaC16-AdWFWLXAbAhHB2NUMQAf16-Aw4F2YCbM2BDAvAfQC16-TAxAw2FYOBUBBlAv2CBkC16-2P2JTJ3BMG5C16-4BH4BBy6C16-9BM6C16-9BUBz4CG15-11BS3CGCaAq13-AhD10BHAaGSMBArAe10-3AAhD11BMU2BCdBu2A6-6AAh15BAj5A4-7AD14B6A5-7AD11BDH5A8-7AD7BDO5A12-8AHBDHAl5A17-12A21-2A6-2A139-
