model
size = 5 10 14, scale = 0.05, origin = -y
material deform = 1, fade = true, lighting = smooth, roughness = 0.3, metalness = 0.6
  colors = A:#9CF
voxels
5-4(2A3-)A4-A19-4(2A3-)A4-A26-2(A4-)A3-2A2-3A2-2(2A3-)A17-2(A4-)A3-2(2A2-)2(3A2-)2A3-A12-3(A4-)A3-2A2-3A-2(3A2-)2A12-3(A4-)2(A3-)2A2-3A-3A2-2A3-A8-4(A4-)2(A3-)2(2A2-)3A2-A8-2(5(A4-)2(A3-)2(2A2-)2A7-)4(A4-)2(A3-)2(2A2-)3A2-A8-3(A4-)2(A3-)2A2-3A-3A2-2A3-A7-3(A4-)A3-2A2-3A-2(3A2-)2A11-2(A4-)A3-2(2A2-)2(3A2-)2A3-A11-2(A4-)A3-2A2-3A2-2(2A3-)A14-
