model
size = 5 10 14, scale = 0.05, origin = -y
material deform = 1, fade = true, lighting = smooth, roughness = 0.3, metalness = 0.6
  colors = A:#9CF
voxels
8-3(2A3-)2A2(4-A)18-3(2A3-)2A2(4-A)22-3(A4-)2A3-3A2(3-2A)4-A11-3(A4-)2A4-2A3-3A2-3A3-2A4-A6-4(A4-)2A2(3-3A)2-3A3-2A5-3(A4-)A5-A4-2A2(3-3A)3-2(2A4-)3(A4-)A5-A2(4-2A)3-3A4-2A2(5(4-A)5-A2(4-2A)4-3A)4(4-A)5-A2(4-2A)3-3A4-2A3(4-A)5-A4-2A2(3-3A)3-2A4-A-4(A4-)2A2(3-3A)2-3A3-2A6-3(A4-)2A4-2A3-3A2-3A3-2A4-A7-3(A4-)2A3-3A2(3-2A)4-A10-
