model
size = 24 31 28, scale = 0.05, origin = -y
material deform = 1, fade = true, lighting = smooth, roughness = 0.3, metalness = 0.6
  colors = A:#C6C6C6 B:#FFDB2D C:#FFF D:#ECECEC E:#B4B4B4 F:#D9D9D9 G:#ECC711 H:#C6AE35 I:#FFD400 J:#A1A1A1 K:#FFE25C L:#D9BA23 M:#FFE573 N:#FFEDA1 O:#FFE98A P:#FFD716 Q:#A19558 R:#FFDE44 S:#B4A146
voxels
587-3(2C22-)2C646-3(2C22-)2C622-2C22-2C21-4(D2CD20-)4D21-2D286-HG22-GH238-2D21-2(D2CD20-)D2CD21-3(2C22-)NC22-CN22-ND236-MO2NOM2(18-6B)18-6I188-2F21-D2CD19-D4CD19-D2CD21-2C142-NC22-CN210-KM6AMK2(14-2B6A2B)14-2G6A2G16-2F2A2F19-4A69-HG22-GH22-2A21-D2CD19-D4CD19-D2CD21-2C400-BK2A6-2AKB8-HG2B2A6-2A2BGH6-GH2B2A6-2A2BHG8-LG2A6-2AGL12-2A6-2A14-F2A4-2AF15-3A2E3A17-J4EJ18-6B18-2B2C2B19-A2CA19-F4CF18-2F2C2F20-2F22-2D399-K2A10-2AK7-GB2A10-2ABG6-HB2A10-2ABH7-LHA10-AHL2(10-E)12-F10-F12-2A8-2A13-2E6-2E15-J6AJ2(16-2BC2AC2B)17-AC2ACA19-F2CF21-2F422-KA14-AK2(6-BA14-AB)6-LH14-HL8-E12-E10-A12-A10-F12-F11-A10-A13-J8-J14-B3A2-3AB14-HQC4ACQG14-GBNC2ACNBH17-4A445-MA14-AM2(6-BA14-AB)6-LA14-AL7-E14-E8-A14-A8-D14-D9-F12-F11-E10-E13-J8-J14-B3A2-3AB14-4B2A4B16-BI2CIB20-HG421-MA16-AM2(4-BA16-AB)4-LA16-AL5-E16-E6-A16-A7-F14-F8-D14-D9-F12-F11-E10-E13-JA6-AJ15-B2A2-2AB16-3B2A3B18-RGHR420-OA16-AO2(4-BA16-AB)4-GA16-AG5-J16-J6-E16-E6-A16-A7-A14-A8-A14-A9-F12-F11-2E8-2E14-J6-J17-JE2-EJ20-2E276-S23-H119-BA18-AO2(2-BA18-AB)2-GA18-AG3-J18-J5-J16-J2(6-E16-E)7-E14-E9-A12-A11-A10-A13-F8-F15-FA4-AF18-4A251-L2(23-I)23-H2(23-Q)23-H23-BA18-AO2(2-BA18-AB)2-IA18-AI2-HA18-AH3-H18-H4-HA16-AH5-G16-G6-GA14-AG7-IA12-AI9-IA10-AI11-IA8-AI13-IA6-AI15-PBA2-ABP18-K2OK203-L23-I23-K23-N23-M23-K23-I2(23-B)A18-AN-GBA18-ABGHBA18-ABH-IA18-AI2(2-MA18-AM)3-KA16-AK4-KA16-AK5-KA14-AK6-RA14-AR7-BA12-AB9-PA10-AP11-PA8-AP13-I2A4-2AI15-G2L2B2LG19-HG180-L23-I23-K2(23-M)23-K23-I2(23-B)A18-AN-HBA18-ABHGBA18-ABG-IA18-AI2(2-MA18-AM)3-KA16-AK4-KA16-AK5-KA14-AK6-RA14-AR7-BA12-AB9-PA10-AP11-PA8-AP13-I2A4-2AI15-G2L2B2LG19-GH204-L2(23-I)23-H2(23-Q)23-H23-BA18-AO2(2-BA18-AB)2-IA18-AI2-HA18-AH3-H18-H4-HA16-AH5-G16-G6-GA14-AG7-IA12-AI9-IA10-AI11-IA8-AI13-IA6-AI15-PBA2-ABP18-K2OK251-S23-H119-BA18-AO2(2-BA18-AB)2-GA18-AG3-J18-J5-J16-J2(6-E16-E)7-E14-E9-A12-A11-A10-A13-F8-F15-FA4-AF18-4A420-OA16-AO2(4-BA16-AB)4-GA16-AG5-J16-J6-E16-E6-A16-A7-A14-A8-A14-A9-F12-F11-2E8-2E14-J6-J17-JE2-EJ20-2E421-MA16-AM2(4-BA16-AB)4-LA16-AL5-E16-E6-A16-A7-F14-F8-D14-D9-F12-F11-E10-E13-JA6-AJ15-B2A2-2AB16-3B2A3B18-RHGR421-MA14-AM2(6-BA14-AB)6-LA14-AL7-E14-E8-A14-A8-D14-D9-F12-F11-E10-E13-J8-J14-B3A2-3AB14-4B2A4B16-BI2CIB20-GH422-KA14-AK2(6-BA14-AB)6-LH14-HL8-E12-E10-A12-A10-F12-F11-A10-A13-J8-J14-B3A2-3AB14-HQC4ACQG14-GBNC2ACNBH17-4A446-K2A10-2AK7-GB2A10-2ABG6-HB2A10-2ABH7-LHA10-AHL2(10-E)12-F10-F12-2A8-2A13-2E6-2E15-J6AJ2(16-2BC2AC2B)17-AC2ACA19-F2CF21-2F424-BK2A6-2AKB8-HG2B2A6-2A2BGH6-GH2B2A6-2A2BHG8-LG2A6-2AGL12-2A6-2A14-F2A4-2AF15-3A2E3A17-J4EJ18-6B18-2B2C2B19-A2CA19-F4CF18-2F2C2F20-2F22-2D402-KM6AMK2(14-2B6A2B)14-2G6A2G16-2F2A2F19-4A69-HG22-GH22-2A21-D2CD19-D4CD19-D2CD21-2C404-MO2NOM2(18-6B)18-6I188-2F21-D2CD19-D4CD19-D2CD21-2C142-CN22-NC238-HG22-GH238-2D21-2(D2CD20-)D2CD21-3(2C22-)CN22-NC22-DN550-2C22-2C21-4(D2CD20-)4D21-2D59-
