model
size = 20 27 14, scale = 0.05, origin = -y
material deform = 1, fade = true, lighting = smooth, roughness = 0.3, metalness = 0.6
  colors = A:#D65D7E B:#B2E097 C:#FFF D:#F17A98 E:#1A222F
voxels
340-11B9-11B10-10B10-12B8-12B290-8B12-8B512-8B10-12B10-11(8B12-)8B272-8B10-11(12B8-)12B10-8B95-2(2B4-2B12-)2A4-2A12-2A4-2A9-5(13A7-)13A5-4(B11A8-)B9A-B8-B8A-A4(B8-B10A)B8-2B8A2B8-12B10-8B95-2(2B4-2B12-)2A4-2A12-2A4-2A9-5(13A7-)13A5-4(12A8-)11AB8-9A-AB8-11A3(B8-B10A)B8-2B8A2B8-12B10-8B172-5(13A7-)13A5-5(12A8-)2(9A-2A3(8-12A)8-11AB8-10A2B8-2A10B10-8B172-3(13A7-)13A-2B4-13A-3B3-13A-3B3(-12A-6B)-12A3-4B-12A3-3B2-)9A-2A7-B9A-2A7-2B2(10-A8-B)11A8-2B10A10-8B2A10-8B172-5(13A7-)13A5-5(12A8-)9A-2A7-B9A-2A7-2B2(10-A8-B)11A8-2B10A10-8B2A10-2(8B92-2(2B9-2B7-)2(2A9-2A7-)5(13A7-)13A5-5(12A8-)A9-2A7-BA9B-A7-2B2(10-A8-B)9A2B8-2B8A2B10-8B12-)8B290-2(12A8-)2(10A-A8-)12A8-A9-2A7-BA9B-A7-2B2(10-A8-B)9A2B8-2B8A2B10-3BC4B12-3BC4B15-C19-C254-2(A2D6A2DA8-)2(A2EA4CA2EA8-)12A8-12A7-B12A7-2B2(11A8-B)9A2B8-12B13-5(C19-)C13-
