model
size = 30 11 27, scale = 0.05, origin = -y
material deform = 1, fade = true, lighting = smooth, roughness = 0.3, metalness = 0.6
  colors = A:#000
voxels
150-2(A28-A330-)23(A28-A300-)A28-A93-7A10-7A5-A7-A8-A7-A3-11A6-11A-2A9-A6-A9-15A4-14A11-A4-A11-15A2-15A12-4A12-31A-A10-6A10-A3-26A2-
