model
size = 14 25 14, scale = 0.05, origin = -y
material deform = 1, fade = true, lighting = smooth, roughness = 0.3, metalness = 0.6
  colors = A:#EDCC48 B:#9CF C:#97C770 D:#827357
voxels
61-4A9-2(6A8-)A4-A2(8-6A)2(8-2A2-2A)10-2A12-2A10-6A8-6A177-4A9-9(6A8-)6A9-4A178-4A9-6A7-9(8A6-)8A7-6A9-4A150-4A8-8A5-11(10A4-)10A5-8A8-4A122-4A8-8A5-10A4-10A3-9(12A2-)12A3-10A4-10A6-6A9-4A120-A6-A5-2A6-2A3-3A6-3A-4A9(6-8A)6-4A-3A6-3A3-10A5-2A4B2A7-A4BA9-4A92-A6-A5-2A6-2A3-3A6-3A-4A11(6-8A)6-4A-12A3-2A5B3A5-A5B2A7-2A2B2A10-2A79-A6-A5-2A6-2A3-3A6-3A-4A11(6-8A)6-4A-12A3-2A5B3A5-A5B2A7-A4BA9-A2BA11-2A12-D10-2C-D9-3C2D9-2C13-A6-A5-2A6-2A3-3A6-3A-4A11(6-8A)6-4A-12A3-2A5B3A5-A5B2A7-A4BA9-4A11-2A65-A6-A5-2A6-2A3-3A6-3A-4A11(6-8A)6-4A-12A3-4A3B3A5-3A3B2A7-2A2B2A10-2A93-A6-A5-2A6-2A3-3A6-3A-4A9(6-8A)6-4A-3A6-3A3-10A5-3A3B2A7-2A3BA9-4A94-4A8-8A5-10A4-10A3-2(12A2-)4A4-4A2-12A6(2-5A)2-3A2-2A2(2-3A)2-2A2-3A2-12A3-10A4-4A3B3A6-2A3BA9-4A122-4A8-8A5-3(10A4-)2(3A4-)2(10A4-)2(4A2-4A4-)2(2(2A2-)2A4-)10A4-10A5-3A3B2A8-4A150-4A8-3(8A6-)2A4-2A2(6-8A)2(6-3A2-3A)2(6-A2-2A2-A)2(6-8A)8-4A131-
