model
size = 32 32 27, scale = 0.05, origin = -y
material deform = 1, fade = true, lighting = smooth, roughness = 0.3, metalness = 0.6
  colors = A:#F63 B:#200 C:#400 D:#630 E:#F66 F:#E00 G:#F60 H:#C30 I:#EEE J:#AAA K:#700 L:#BBB M:#F30 N:#DDD O:#777 P:#010 Q:#F33
voxels
264-B158-B31-B32-B201-B24-C67-C485-C18-B30-2B10-C19-2B31-B34-B27-B31-2B30-4B3(30-2B)6-B24-2B5-2B28-2B-B26-2B3-2C23-2B30-2C2-C29-C-BC326-C60-C28-C3-3C18-B6-4C18-3B6-2C3-C18-3B6-2C2-C17-3B7-C-B18-3B11-C18-3B6-C3-C17-5B3A2-2C19-C-2(BC)4AB21-C3BC5AD21-C4B2A26-4B3A4-B21-3B5A2-B21-3B3A4-2B20-C3B5A-2B20-C4B-2A2BCB21-12B22-7B2CB21-2BC6B-B21-CB-C4B2-B25-C-BC32-C229-C31-2C31-C27-5C19-4A2DC-5C15-2B2-4A2DBDB2C16-2BA2-4A3D2B2C14-4B2A-3A3D2BDC16-B8A3DBDB16-2B8A2D2BDA16-2B8ADB2D3A15-2B8AB2D4A2(15-2B9AB5A)15-2B6A-2ADC4A15-2B15A14-C2B14A16-CB14A17-2B8AC4A18-B13AB17-CB11A-B18-CB8A3B19-C3B5AC2B21-C6BC3B22-C6B30-BCB24-C6-C4-B149-2A11-C18-2A8-2C19-3A3-C2-C-CBC18-5AD2(-C)2B3C16-7ADBCB-3C14-2B-8ABD2(BC)-C13-2B11AD2BC-C10-B-B13ADB13-C2BAB13AD14-CB15AC13-CB17AC4(13-B18A)12-CB8AC9A2(12-CB18A)14-B16A15-B16A14-C2B15A15-C2B14A16-3B12AB17-2B11A2B18-2B9A3B19-2(3BC)4B20-2C2-2CB-CB3-B18-3C3-B2-C3-CB18-C128-6ADB3-2C-2C15-2A3G3AD-B2(-2C)15-7AD2-3C3BC14-8ADBC2D2BC15-11A5BC12-2B13AD3BCB10-B-B13AD3B-C10-2B15ADB-B11-B17ABC12-B17AD12-2B19A10-C2B2(19A11-CB)19A12-B19A10-2CB19A11-CB18A11-2CB18A12-CB19A11-CB18A12-CB18A2(13-CB17A)13-2CB16AB13-C2B14A2B16-B12A2B17-C15BC16-4C2-B3C2-3C17-C-C9-2C114-3G6ADB3-4C14-2G7AD2B-2BC2B2C12-9A2DBCD5BC11-11A4D2B11-2B-13AD4BC9-3B15AD4BC8-3B15AD4BC7-3B17A3BC10-B18ADCB9-2B18AD9-C3B19A8-2C2B21A8-2CB21A9-CB21A7-3C2(B21A8-2C)B22A9-2(B22A8-C)B22A9-CB21A10-B20A10-CB20A11-CB19A11-CB18AB11-2C2B15A3B11-C2-4B7A6B16-C-13B19-C-BC-2C2-3C22-C6-2C82-3G8AD-C-3C-2C11-G10AD2BC3B4C10-11A5D5BC6-3B13A2D4BC8-3B15A3B-BC8-2B17A5B7-3B17AD3B8-3B18A3DB7-2B20AD2B7-2B20AD8-3B21A2(9-B22A)8-CB23A7-CB24A6-CB24A7-B24AE4-2CB23AE5-2C2B22A6-2C2B22A7-2CB22A6-3CB22A7-2C2B20AB9-CB21A10-2B19A12-CB16A2B13-C2B12A4B15-C2B6A5B19-C-6B-3B22-C-2B2C87-11AD-2C3B3C10-G12A2D6B2C9-13A2(2D2B)C7-2B15A2D3BC9-2B16AD2-B10-2B17A2BD2B6-3B19AD2BDB6-2B20A2D7-2(2B21AB8-)2B21AD8-B22A9-B23A8-B24A7-2(B24AE6-)B22A-AE5-CB22A-E5-C2B24A5-2CB22AE7-CB21AI9-B22AE7-C2B22ABC5-2CB23A6-2CB23A7-C-2B19AB12-2B14A3B13-C-B10AB-2B-4B12-C4B3A4B-B4-BC13-2C2-4BC25-C4-C55-12A2D-B2DB3C10-12A5D2B4C6-B15A6DBC2B6-B16A3D2BC-B-C-B2-2B17AB2D3BC3-C4B17A3D2ABC4-C-B23AD4-C2B23A7-2B23A8-B22AB6-2B22AB2(8-B23A)8-B24A6-2(B25AE5-)B25AE6-B23AE7-B22A-A7-B22A7-C2B21AP7-C2B22AE6-C2B24AB4-C2B24A6-2CB23A7-C2B21AB10-2B16A5B11-2B11A3BC3B14-2B6AB-3BC-3B14-C9B2-2C-2C16-2(CB)-3BC24-C27-7A2F4A4D2BDB2C9-13A5DBD2B2C2-B3-2B14A7D3B2C3B-B17A4D5B-5B18A4DBC3-4B19AD4AB2C2-3B24AC4-2B22AH6-C2B22A7-CB23AH6-CB22AB8-B22AB6-CB25A5-CB26A5-B25A6-B26A5-B24A-E5-2(B25A6-)B23A8-2B21AI8-2B22AE7-2B24AB4-C2B24A5-C3B23A6-C3B21A8-2C-2B18A2B11-2B12AB-3B14-C2B8A4B2CB15-2C10B-BC-C17-7B-B2-BC20-2CB-2B-C2-C17-6A4F4A3D-2BC-C8-B14AD-DB2D3BC2-2B-2B16A6D2C3-C2B-B21A2DB4-3B23AB4-B-2B24AB3-3B25A5-B24AH6-B22AO8-B23AJ7-B24AH5-B24AB6-B25A6-B27A3-CB26A4-CB25A5-C2(B25A6-)B25A5-CB23AE7-B22AL8-2B24A6-2B24AB6-B24A7-2B23A8-2B22A8-2CB19A11-2C2B14A3B12-2C2B10A3BCB17-C2B5A5BC19-C9B-B26-B4-B17-5A2F2INF4A2D2B2C-C6-2B16A6D2BC4-2B17A8D2C2-3B23ADBC3-2B25AB3-B-B23A-AB2-C2B25AD3-C2B24AH5-2B22AL7-CB23AJ6-B25AH5-B24AD2(6-B25A)CHA3-B28A3-B27A4-B27A3-CB26A4-2(CB25A5-)CB24A7-2(2B24A6-)2B24A7-2B23A7-3B22A8-3B19A11-C2B16AB14-2B13A2B16-2BCB7A4B-C17-2C7B2(-B)21-C5-B3-B17-5AFI2KNF4A2D2BDB-2C6-B16A6D2B2C4-B17A8DB3-B-B23A2DB3-2B25ADB3-B26AB3-B-25AD4-2B24AQ4-C2B22AL7-CB23AJ5-CB25AH5-B24AD6-B25A6-B28A3-2(B28A2-C)B28A3-2(B27A4-)3(B26A5-)2B24A2(8-B23A)8-2B22A9-2B19A13-B16AB15-B13A3B15-2BCB7A3B-CBC15-4C7B-B2-C18-C5-3B20-5AFI2KNF4A2D2B2-C8-B16A3D2-B2C7-C16A7DBC2-2B-B23A2DC2-3B24A2DBC-2(2B26AB3-)2B24AM5-2B22AO7-2B23AJ5-CB25AM4-CB24AB2(5-CB25A)CHA2-CB28A3-2(B27A4-)B26A5-2(B25A6-)B24A7-B25A2(6-2B24A)5-C3B23A6-C3B22A7-C3B19A10-2C2B16ABC12-C-B13A3BC15-3B7A4B20-9B-B22-C-6B-B18-5A2F2I2F4A2D3B3C7-B-14A4D4BC6-C17A5D4B2-2B-B19ADA2DBD2(2B-)20AD2A2DB3-3B25ADB2-2B26ABC2-B-24AM5-2B23A7-2B24A6-2B24AH5-B24AB6-B25A6-B27A4-B26A5-4(B25A6-)B23AE7-2B21AL8-B25A6-2B24AB6-B24A6-C2B23A6-2C2B22A8-C2B19AC9-5B15ABC13-3B12A3B15-5B6A6BC16-3BC5B2-3BC21-2B-3B20-6A4F4AD3B-BC9-B-13A3DB-2BC9-C16A2DBD2B-3C5-C17A4D5B-B2-B18A2DB2D3BC2(-B)25AD3-2B23A2(3-B)-23A7-2(2B23AH6-)2B22AB7-B23AD7-B25A6-B26A5-5(B25A6-)B23A8-B22AI7-CB23AE7-2C24AB5-2C24A7-CB23A8-2B22A8-4B18A2B8-B-3B14A3B15-B10A3B18-5B4A6B17-C2B-5B4-2B18-8B5-B16-13A2D2B3-C11-13A4DB-2B2-C5-2B15A2D8B2(2-B)17A2D8B-B3-18A2D2-2D2BC-B-C20A2DB2D2B2-2BC21A2D-B4-B-23AB6-B-22ADB6-2B22AB7-2B22AB2(8-B23A)8-B24A2(6-B25A)2(E5-B25A)6-B25A6-B23A7-2CB21AP7-2CB22AE7-CB24AC5-2B24A8-B23A9-B21A9-4B18A12-B-B12A3BC16-2B8A4B17-CBC8B-2B-B17-2C6BC4-2B19-C3B2-C23-12AD6B12-13A3D-3B6-B3-B-14A2D3B10-B16A4D5B3-2B-B17A3D2BD3BC-B-2C18AD-5B2C3-C20A2D3BC3-2B22ADB2C4-2B22AB7-2B22AB6-C2B23A6-C3B22A2(7-2B23A)7-2(CB24AE5-)2B24AE5-CB23AE6-CB24A5-2CB23A8-C21AI9-B22AE8-2B23AB5-3B23A7-3B22A8-3B20A11-3B15AB14-3B11A3BC14-3C2B6A4B-2B16-CB-6B2-C2-B18-C-3B-3C4-B21-CB26-AG9AD7B13-10A3D2B-2B13-13AD2B-3B10-B-13A2D7BC3-B2-2B15A2D5BC6-CB17ADB-4B7-C18ADB-2BC3-2C2B20AD2-C5-2(C-B20AD8-)CB22A8-B-22A8-2B22A8-B-25A2(6-B24AE)5-CB24AE5-2B23AE6-2(3B22A7-)B-B21AG7-4B21A7-B-2B22AB8-B22A8-3B21A9-3B18A12-B-2B13A2B13-CBC-2B6A6B15-C3-7BC2-3B18-B-4B5-C-B21-2C58-3G7A2D4B16-9A3D-3B16-11AD7B11-C13AD8B8-B15AD6B7-CB17AD4BC9-C16A2D2BC6-C3B18A2D10-CB18AD11-B21A8-3B21A9-2B21A8-B-C21A8-B-B21A8-3B21A9-2B23AE6-2B23AE5-3B22AE6-B-B22A2(7-4B21A)7-B2-B20A8-B2-B21AB8-3B21A11-B19A10-B-CB15AB15-3B8A6B17-C3B2A3B-2C3B21-3BC3-2CB21-C3BC3-C-C24-C57-A2G6AD3B19-9ADB-2B17-10A2D-5B13-C11AD7B11-C13AD6BC7-C2B15AD4B10-CB15A2D2BC8-C2B17A2DB10-CB18AD10-3C19A9-4B19A9-C2B21A8-2CB21A8-C2B3(21A7-CB-B)21A7-C4B19A9-C-B-19A9-2(B-)19A9-3B-18A10-2B-2B16A14-2B16AB12-4B14A2B14-C3B11A3B15-C2B10A4B17-4B5A2B3C19-C-9B2C22-7B24-C4B2C25-2C61-7AD-3B20-6ADCD2BC20-5AD3C3B2-B16-5AD2C3D5B15-9A4D4B11-2CB11A3D4B13-B13AD3BC10-C-B15A4B10-CB16ADB12-CB16A2D9-2C3B16AD2A9-C-2B19A12-B2(19A11-2B)19A10-3B18A11-3B18A10-C-2B18A12-2B18A10-C-2B18A10-C4B16A13-4B14AB12-CBC2B14AB13-2CB-2B11A2B15-C3B10A4B17-3B6A2B-2CB18-11B2C19-C2-2B-4BC24-B2-2B27-C2-2B30-B65-3B30-3C30-2C28-C3B22-2A4D-B-4BC15-C-5A3DB-4B14-2C-8A3D4BC12-2B-11A2D3BC11-3B-12ADB14-3B13ADB11-C2-C2B13ADC14-CB15ADC13-2B16A14-2(2B16A13-C)2B7AC8A12-C3B16A13-C3B14A14-4B14A15-4B13A14-B-3B13A14-B-4B11AB17-4B8A4B18-C3B5A5B16-B-C11B2-B18-C-9B21-C2-B2-4B28-2B30-B129-C32-C31-2C28-2C2B26-4CB27-D-C2B2-2B16-C7-2DB-3B16-C5-3A4D3B2C12-CB5-4A5D2BC12-C3B3-5A5DBC14-CB3-7ADC3D16-3B9A4DC15-3B10AC2DC14-3B10A2C2D16-2B11ACDC16-3B5A-4ACDA16-3B10A2DA15-2B-B13A15-B-3B11A17-2B-B11AB17-C2B10A2B17-CB-2B6A5B17-2C4B2A3B-3B20-B-6B2-2B22-6B27-C2-3B29-2C30-C226-C29-3C30-C30-2C28-2C2-B29-2B-B16-2B9-2C-3B15-2B9-CB-B17-B13-2B16-2B5-2A5-B18-2B3-4A4-B19-B3-5A3-B19-B2-2A-3A24-B-2A28-B-2A27-CB-5A2-B-B18-2C-B3A4-B-B18-C2-2B5A5B20-3B-2A2BCB22-B-5BC2B-B22-B-3BCB27-B2-C28-C2-2C30-C448-CB18-2B30-B13-B31-B18-B31-B204-B31-B61-C334-
