model
size = 28 18 29, scale = 0.05, origin = -y
material deform = 1, fade = true, lighting = smooth, roughness = 0.3, metalness = 0.6
  colors = A:#222 B:#444 C:#111 D:#EEE E:#555 F:#DDD
voxels
39-6A22-6A468-3A4-3A18-3A4-3A464-3A8-3A13-4A8-4A11-3A12-3A10-2A14-2A486-A16-A10-A16-A486-A16-A9-2A16-2A7-2A18-2A2(6-A20-A)6-2A18-2A7-A18-A370-2A20-2A4-2A20-2A62-2A16-2A369-2A22-2A2-2A22-2A62-A16-A10-2A14-2A313-A26-3A24-4A24-2A90-2A12-2A13-2A10-2A15-2A8-2A17-2A6-2A233-A2(26-2A)26-A178-A6-A20-2A4-2A21-2A2-2A179-A2(26-2A)26-A236-A2-A9(180-A2(26-2A)26-A236-4A)180-A26-AC26-2C26-C236-4A16-AB16-BA144-A26-AC26-2C26-C208-4A24-4A15-4A14-4A7-AB16-BA116-A26-AC26-2C26-C-B2AB18-B2AB3-4B16-4B126-4A24-4A42-6A12-6A5-3AB14-B3A6-A20-A87-A26-AC26-2C26-C-3B20-3B3-B2AB16-B2AB98-4A24-4A70-9A6-9A3-6AB12-B6A2(-A)22-A-2A-A22-A-AB-A22-A-BA-A22-A-2A-A22-A-AC-A22-A-2C-A22-A-C-A2B20-2BA3-B2A2B14-2B2AB70-4A24-4A98-10A4-10A3-9AB6-B9A-2A24-4A24-2ABA24-AB2A24-4A24-2ACA24-A2CA24-AC-B24-B3-B3A3B10-3B3AB42-4A24-4A126-10A4-10A3-10AB4-B10A-2A24-4A24-2ABA4-2D12-2D4-AB2A2(3-4D10-4D3-4A)4-2D12-2D4-4A24-2A-A24-A3-B5A12B5AB14-4A24-4A154-10A4-10A3-A10C4-10CA-2A24-4A24-2ABA4-2D12-2D4-AB2A2(3-4D10-4D3-4A)4-2D12-2D4-4A24-2A-A10-4A10-A3-B8AB4AB8AB200-24A3-A24CA-2A24-4A4-2E12-2E4-2ABA3-E2DE10-E2DE3-2(A2BA2-ED2FDE8-ED2FDE2-)A2BA3-E2DE10-E2DE3-A2BA4-2E5-2A5-2E4-AB-A10-4A10-A3-B22AB200-A22BA3-2B22A2B-2B24A2BC26ACB26ABC26A2C26ACB26A3B24A2B-2B22A2B3-3B2A14B2A3B198-
