model
size = 10, scale = 0.05, origin = -y
material deform = 1, fade = true, lighting = smooth, roughness = 0.3, metalness = 0.6
  colors = A:#91989F B:#707C74 C:#0D5661 D:#33A6B8 E:#211E55
voxels
-4CD2-3AB9ABA7BAB8A3-4AEBA4-4ABA2D3-3ABA2C2D2-2ABA3CD3-ABA4CD2-AB2A2(B2-D5CA)B3-D4CABA2-2D3CAB2A3-3DAB3A5-AB4A4-ABAE4AB2ABA4BAB2AB6AB2AB2-D5CBA2-D5C2A3-D4CB2A2-2D3CB3A3-3DB4A5-B5A4-2(8ABAB)A4BAB2AB2-D5CBA2-2D4C3A2-D4CE2A3-2D2C4A3-3D5A5-7A3-8ABA2B7ABAB4AEAB2AB3-D4CB2A2-D4C3A2-2D3C3A3-4D4A6-5A5-AB6A3-B6ABA2-AB5AB3-5AB2ABA2-2D3CB2A3-2D2C3A3-4D4A4-2D5A5-AB4A7-5ABA4-6A4-B4AB4-4A2(B2A)3-3DB3A3-3D4A6-5A5-AB4A7-5ABA4-6A5-5A2D3-B3AB2D3-3AB2AB3A5-B4A5-5A5-AB4A7-5ABA4-6AD4-5A3D3-3AEC2D3-B2AB2C2D2-2(2AB)AE2A4-B6A3-8A3-B6ABA4-6A5-5A3D3-4A2C2D2(2-4A3CD)3-4ABA6BAB8ABAB6ABA2-AB5AB4-B4AB2D3-B3ABC2D3-B2AB3CD2-B2AB3C2D2-BAB4CD2-3B
