model
size = 9 19 15, scale = 0.05, origin = -y
material deform = 1, fade = true, lighting = smooth, roughness = 0.3, metalness = 0.6
  colors = A:#E1B400 B:#BBB C:#AAA D:#F93 E:#FC3 F:#DDD G:#EEE H:#F99 I:#222 J:#F90 K:#FC9 L:#FF9 M:#F96 N:#888 O:#FFC P:#F60
voxels
12-EDA160-A7-A-E160-A7-A-A156-5AE4AE2A-A2EA153-E4BDHD2AB3C3-A153-E4B3D2AFC2B3-A4-C8-B8-F130-A2D3BDHEA2-2CB2-A3-2CB6-3C6-B2C2(6-BCB)6-BCF7-BF7-2G34-J8-E40-A2D3B2D2A2-3C2-A3-2(3C6-)2CB6-3C5-B2CB5-3CB5-FBCB6-GIF7-IG7-I8-P7-EA7-2KE8-L7-O17-G4-A2DBNB2D2A2-B2C2-E3-2(B2C6-)2(2BC6-)3B6-3B7-BF7-FG34-J8-E8-L31-A5DHD2E7-A153-ADHDM3D2A7-A153-8A2E5AE2A4-2(A8-)E143-A26-A143-E26-A152-2(A8-)E130-
