model
size = 32 31 32, scale = 0.05, origin = -y
material deform = 1, fade = true, lighting = smooth, roughness = 0.3, metalness = 0.6
  colors = A:#FFF700 B:#000 C:#DAD300 D:#6D6900 E:#918D00 F:#B6B000
voxels
398-4A27-6A25-3(8A24-)8A25-6A27-4A732-4A27-6A25-3(8A24-)8A25-6A27-4A668-4A26-8A23-10A21-4A4-4A20-3A6-3A19-3(3A8-3A18-)3A8-3A19-3A6-3A20-4A4-4A21-10A23-8A26-4A509-2A27-8A22-4A4-4A19-3A8-3A18-2A10-2A17-2(2A12-2A16-)A14-A15-3(2A14-)2A15-A14-A2(16-2A12-2A)17-2A10-2A18-3A8-3A19-4A4-4A22-8A27-2A412-6A24-4A2-4A20-3A8-3A17-2A12-2A16-A14-A15-2(2A14-)A16-A13-2(2A16-2A12-)2(A18-A12-)2A16-2A12-2A16-2A13-A16-A2(14-2A)15-A14-A16-2A12-2A17-3A8-3A20-4A2-4A24-6A345-8A22-3A6-3A19-2A10-2A17-A14-A15-A16-A13-2A16-2A12-A18-A11-2A18-2A6(10-A20-A)10-2A18-2A11-A18-A12-2A16-2A13-A16-A15-A14-A17-2A10-2A19-3A6-3A22-8A280-8A22-2A8-2A19-A12-A16-2(2A14-)A16-A13-A18-A11-A20-A10-A20-A9-7(A22-A8-)A22-A9-A20-A10-A20-A11-A18-A13-A16-A2(14-2A)16-A12-A19-2A8-2A22-8A217-6A23-3A6-3A19-A12-A16-2A14-2A13-A18-A12-A18-A11-A20-A9-2(A22-A8-)A22-A7-5(A24-A6-)A24-A7-2(A22-A8-)A22-A9-A20-A11-A18-A12-A18-A13-2A14-2A16-A12-A19-3A6-3A23-6A156-2A26-4A2-4A20-2A10-2A16-2A14-2A13-A18-A11-A20-A10-A20-A9-A22-A8-A22-A7-3(A24-A6-)A24-A5-A26-A4-A26-A5-3(A24-A6-)A24-A7-A22-A8-A22-A9-A20-A10-A20-A11-A18-A13-2A14-2A16-2A10-2A20-4A2-4A26-2A123-8A21-3A8-3A17-A14-A15-A16-A13-A18-A11-A20-A9-A22-A7-2(A24-A6-)A24-A5-7(A26-A4-)A26-A5-2(A24-A6-)A24-A7-A22-A9-A20-A11-A18-A13-A16-A15-A14-A17-3A8-3A21-8A90-4A24-4A4-4A18-2A12-2A15-A16-A13-A18-A11-A20-A9-A22-A7-A24-A6-A24-A5-3(A26-A4-)A26-A3-3(A28-A2-)A28-A3-3(A26-A4-)A26-A5-A24-A6-A24-A7-A22-A9-A20-A11-A18-A13-A16-A15-2A12-2A18-4A4-4A24-4A58-2A4-2A21-3A8-3A17-2(A14-)2A16-2A11-A20-A9-A22-A8-A22-A7-A24-A5-2(A26-A4-)A26-A3-7(A28-A2-)A28-A3-2(A26-A4-)A26-A5-A24-A7-A22-A8-A22-A9-A20-A11-2A16-2A2(14-A)17-3A8-3A21-8A55-2A6-2A20-2A10-2A16-2A14-2A13-A18-A11-A20-A9-A22-A7-A24-A6-A24-A5-A26-A4-A26-A3-9(A28-A2-)A28-A3-A26-A4-A26-A5-A24-A6-A24-A7-A22-A9-A20-A11-A18-A13-2A14-2A16-2A10-2A20-10A53-2A8-2A18-2A12-2A15-A16-A12-2A18-2A9-A22-A8-A22-A7-A24-A5-A26-A4-A26-A3-3(A28-A2-)A28-A-A3(30-2A)30-A-3(A28-A2-)A28-A3-A26-A4-A26-A5-A24-A7-A22-A8-A22-A9-2A18-2A12-A16-A15-2A12-2A18-4A4-2(4A24-)A10-A18-2A12-2A14-2A16-2A11-A20-A9-A22-A7-A24-A6-A24-A5-A26-A4-A26-A3-2(A28-A2-)A28-A-A5(30-2A)30-A-2(A28-A2-)A28-A3-A26-A4-A26-A5-A24-A6-A24-A7-A22-A9-A20-A11-2A16-2A14-2A12-2A18-3A6-3A23-6A22-A12-A17-2(A14-)2A16-2A11-A20-A9-A22-A7-A24-A6-A24-A5-A26-A3-2(A28-A2-)A28-A-A7(30-2A)30-A-2(A28-A2-)A28-A3-A26-A5-A24-A6-A24-A7-A22-A9-A20-A11-2A16-2A14-A2-2B-B-2B-3B-A17-3A8-3A21-8A21-A12-A16-2A14-2A13-2A16-2A11-A20-A9-A22-A7-A24-A5-2A24-2A4-A26-A3-2(A28-A2-)A28-A-A7(30-2A)30-A-2(A28-A2-)A28-A3-A26-A4-2A24-2A5-A24-A7-A22-A9-A20-A11-2A16-2A13-2A3(-B)2-3(B-)2A16-3A8-3A21-8A21-A12-A16-2A14-2A13-2A16-2A11-A20-A9-A22-A7-A24-A5-2A24-2A4-A26-A3-2(A28-A2-)A28-A-A7(30-2A)30-A-2(A28-A2-)A28-A3-A26-A4-2A24-2A5-A24-A7-A22-A9-A20-A11-2A16-2A13-2A3(-B)2-B-3B-2A16-3A8-3A21-8A21-A12-A17-2(A14-)2A16-2A11-A20-A9-A22-A7-A24-A6-A24-A5-A26-A3-2(A28-A2-)A28-A-A7(30-2A)30-A-2(A28-A2-)A28-A3-A26-A5-A24-A6-A24-A7-A22-A9-A20-A11-2A16-2A14-A2-2(2B-B-)B-A17-3A8-3A21-8A22-A10-A18-2A12-2A14-2A16-2A11-A20-A9-A22-A7-A24-A6-A24-A5-A26-A4-A26-A3-2(A28-A2-)A28-A-A5(30-2A)30-A-2(A28-A2-)A28-A3-A26-A4-A26-A5-A24-A6-A24-A7-A22-A9-A20-A11-2A16-2A14-2A12-2A18-3A6-3A23-6A23-2A8-2A18-2A12-2A15-A16-A12-2A18-2A9-A22-A8-A22-A7-A24-A5-A26-A4-A26-A3-3(A28-A2-)A28-A-A3(30-2A)30-A-3(A28-A2-)A28-A3-A26-A4-A26-A5-A24-A7-A22-A8-A22-A9-2A18-2A12-A16-A15-2A12-2A18-4A4-4A24-4A25-2A6-2A20-2A10-2A16-2A14-2A13-A18-A11-A20-A9-A22-A7-A24-A6-A24-A5-A26-A4-A26-A3-9(A28-A2-)A28-A3-A26-A4-A26-A5-A24-A6-A24-A7-A22-A9-A20-A11-A18-A13-2A14-2A16-2A10-2A20-10A55-2A4-2A21-3A8-3A17-2(A14-)2A16-2A11-A20-A9-A22-A8-A22-A7-A24-A5-2(A26-A4-)A26-A3-7(A28-A2-)A28-A3-2(A26-A4-)A26-A5-A24-A7-A22-A8-A22-A9-A20-A11-2A16-2A2(14-A)17-3A8-3A21-8A58-4A24-4A4-4A18-2A12-2A15-A16-A13-A18-A11-A20-A9-A22-A7-A24-A6-A24-A5-3(A26-A4-)A26-A3-3(A28-A2-)A28-A3-3(A26-A4-)A26-A5-A24-A6-A24-A7-A22-A9-A20-A11-A18-A13-A16-A15-2A12-2A18-4A4-4A24-4A90-8A21-3A8-3A17-A14-A15-A16-A13-A18-A11-A20-A9-A22-A7-2(A24-A6-)A24-A5-2(A26-A4-)B26-B5(4-A26-A)5-2(A24-A6-)A24-A7-A22-A9-A20-A11-A18-A13-A16-A15-A14-A17-3A8-3A21-8A123-2A26-CE2A2-2AEC20-2A10-2A16-2A14-2A13-A18-A11-A20-A10-A20-A9-A22-A8-A22-A7-3(A24-A6-)B24-B5-D26-D4-C26-C5-3(A24-A6-)A24-A7-A22-A8-A22-A9-A20-A10-A20-A11-A18-A13-2A14-2A16-2A10-2A20-4A2-4A26-2A156-6D23-3D6-3D19-D12-D16-AD14-DA13-A18-A12-F18-F11-C20-C9-A22-A8-C22-C8-A22-A7-A24-A6-E24-E6-B24-B6-D24-D6-C24-C6-A24-A7-2(A22-A8-)A22-A9-A20-A11-A18-A12-A18-A13-2A14-2A16-A12-A19-CFA6-AFC23-6A217-8B22-2B8-2B19-B12-B16-DB14-BD14-B16-B13-B18-B11-D20-D10-B20-B9-D22-D4(8-B22-B)8-D22-D2(8-A22-A)9-A20-A10-A20-A11-A18-A13-A16-A2(14-2A)16-C12-C19-EB8-BE22-FC4ACF280-8B22-BEC6-CEB19-EC10-CE17-E14-E15-E16-E13-BC16-CB12-E18-E11-BC18-CB10-E20-E10-C20-C10-A20-A10-E20-E10-B20-B10-A20-A10-2A18-2A11-A18-A12-2A16-2A13-A16-A15-A14-A17-CB10-BC19-3B6-3B22-BE4AEB345-C4AC24-4A2-4A20-3A8-3A17-CA12-AC16-A14-A15-2(2A14-)A16-A13-2(2A16-2A12-)2(A18-A12-)2A16-2A12-2A16-2A13-A16-A2(14-2A)15-A14-A16-AC12-CA17-C2B8-2BC20-3BC2-C3B24-BC2ACB412-2A27-8A22-4A4-4A19-3A8-3A18-2A10-2A17-2(2A12-2A16-)A14-A15-3(2A14-)2A15-A14-A2(16-2A12-2A)17-AC10-CA18-AEB8-BEA19-4B4-4B22-2BC2AC2B27-2A509-4A26-8A23-10A21-4A4-4A20-3A6-3A19-3(3A8-3A18-)3A8-3A19-3A6-3A20-4A4-4A21-2FC4AC2F23-BE4AEB26-C2AC302-
