model
size = 22 30 9, scale = 0.05, origin = -y
material deform = 1, fade = true, lighting = smooth, roughness = 0.3, metalness = 0.6
  colors = A:#EEE B:#B00 C:#33C D:#222 E:#3F6 F:#33F G:#BBB H:#A00
voxels
6-2(9B13-9B11-13B2(9-2B)9-13B8-3B9-3B7-15B8-13B10-11B12-9B15-B4-B14-C3-2C3-C12-2(2C2-)2C2(12-10C)13-8C14-8C15-6C17-2(3C19-)3C14-A4-3C5-A6-5A2-3C3-5A3-7A2-2C2-7A-8A2-2C2-7A-9A4-9A-7A6-7A2-7A6-7A3-5A8-5A6-A12-A10-)9B13-9B11-13B9-2B4(GA)G2B9-13B8-3B4(AG)A3B7-15B8-13B10-11B12-9B15-B4-B14-C3-2C3-C12-2(2C2-)2C2(12-10C)13-8C14-8C15-6C17-2(3CF18-)3CF13-A4-3CF4-A6-5A2-3CF2-5A3-7A2-2C2-7A-8A2-2C2-7A-9A4-9A-7A6-7A2-7A6-7A3-5A8-5A6-A12-A11-7B15-7B13-11B10-2BGAG3-GAG2B9-2B-7B-2B9-2B4(AG)A2B9-12B10-12B11-11B13-3B-3B36-C3-2C3-C12-2(2C2-)2C2(12-10C)13-8C14-8C15-6C17-2(3CF18-)3CF12-3A3-3CF3-3A4-7A-3CF-7A-8A2-2C-8A-9A-2C-2(18A4-)9A-7A5-8A2-7A6-7A4-3A10-3A11-5B16-7B13-11B10-B-4(GA)G-B9-B3-5B3-B9-B-4(AG)A-B9-12B11-11B12-BH7B57-C3-2C3-C12-2(2C2-)2C2(12-10C)13-8C14-8C15-6C17-2(3CF18-)3CF11-5A2-3CF2-5A3-7A-3CF-7A-9A2(-2C-18A)2(4-18A)4-9A-7A6-7A3-5A8-5A10-5B16-B3H3B13-11B11-B9-B10-2B9-2B10-B9-B11-11B12-3H6B15-2B-2B63-2C17-C2-2C2-C13-10C12-10C13-8C14-8C15-6C17-2(3CF18-)3CF11-5A2-3CF2-5A3-7A2-C3-7A-9A4(4-18A)4-9A-7A6-7A3-5A8-5A276-2C17-8C14-F6CF15-2(F5C16-)6C17-2(3CF18-)2C2F11-5A4-C3-5A3-7A6-7A-9A4(4-18A)4-9A-7A6-7A3-5A8-5A298-2(2C20-)FC3(20-2C)20-C57-5E8-5E3-2E3D2E6-2E3D2E3(2-E5DE6-E5DE)2-2E3D2E6-2E3D2E3-5E8-5E343-2(C21-)C168-D12-D7-3D10-3D7-D12-D70-
