model
size = 19 32 14, scale = 0.05, origin = -y
material deform = 1, fade = true, lighting = smooth, roughness = 0.3, metalness = 0.6
  colors = A:#070 B:#0B0
voxels
279-B109-B170-B115-2(3A16-)BA36-A-A16-4A16-2A34-A17-4A16-2A53-2A16-4A16-2A53-3A16-3A17-A17-2A2(16-4A)16-3A17-A96-A-A16-5A14-5A13-7A12-7A13-5A14-5A13-7A12-7A11-7A12-B5A13-7A11-8A12-6A11-7A13-5A13-6A12-8A11-7A12-6A12-7A11-9A11-7A12-7A11-8A2(11-9A)11-7A13-5A15-A40-5A13-7A11-7(9A10-)9A9-10A8-11A8-10A10-9A9-10A8-11A7-11A8-10A10-8A10-10A8-11A8-10A9-9A9-10A10-9A9-11A2(8-11A9-10A)11-5A37-6A-A11-7A11-9A9-11A8-11A7-2B10A2(8-11A)9-10A2(8-11A)7-11A8-10A8-2(12A7-)11A7-11A8-10A9-11A8-10A8-11A7-2(11A8-)11A7-12A8-11A8-12A6-13A7-12A8-10A10-7A15-A20-8A10-10A8-12A7-11A8-12A6-13A7-11A8-11A7-13A7-2(12A6-)2(13A6-)12A6-2(13A5-)B14A5-13A6-12A6-13A5-13A7-12A7-11A7-2(13A6-)14A5-13A6-13A7-12A7-11A10-8A13-3A17-11A9-10A8-12A7-11A7-13A6-13A7-11A8-11A7-2(13A6-)12A6-2(14A5-13A5-)15A4-2(14A5-13A5-)14A6-12A6-14A5-13A6-13A5-15A4-14A6-14A5-13A7-11A9-10A11-5A16-11A9-10A8-12A7-11A7-13A6-13A7-11A8-11A7-2(13A6-)12A6-14A5-13A5-14A5-13AB4-15A4-2(14A5-13A5-)14A6-12A6-14A4-B13A6-13A5-15A4-14A6-14A5-13A7-12A8-10A11-6A15-11A9-10A8-12A7-11A7-13A6-13A7-11A8-11A7-2(13A6-)12A6-2(14A5-13A5-)15A4-2(14A5-13A5-)14A6-12A6-14A5-13A6-13A5-15A4-14A6-14A5-13A7-12A8-10A11-6A17-8A10-10A8-12A7-11A8-12A6-13A7-11A8-11A7-13A7-2(12A6-)2(13A6-)12A6-13A5-13A6-14A5-13A6-12A6-13A5-13A7-12A7-11A7-2(13A6-)14A5-13A6-13A7-12A7-11A9-10A12-5A17-8A10-10A2(8-11A)8-12A6-13A7-11A8-11A7-13A7-12A6-12A7-11A2(7-12A)6-13A5-13A7-12A6-13A6-12A6-13A7-11A7-12A7-11A2B6-12A6-13A6-12A7-13A6-13A7-12A7-11A10-8A14-3A19-5A13-7A11-9A9-11A8-11A2(9-10A2(8-11A))7-11A8-10A8-2(B11A7-)11A7-11A8-10A9-11A8-10A8-11A7-2(11A8-)11A7-12A8-11A8-12A6-13A7-12A8-10A11-6A16-A20-2A-2A13-7A12-7A11-2(9A10-)9A2(11-8A)2(10-9A)9-10A9-9A9-10A10-9A9-10A8-10A9-9A9-10A10-8A10-10A2(9-9A)3(10-9A)9-10A9-11A9-10A10-9A11-7A13-4A77-3A15-5A13-B6(5A14-)5A13-5A14-4A14-6A14-2(5A13-)4A15-4A14-6A13-6A12-6A13-2(5A14-)5A13-6A14-6A13-6A12-7A13-6A14-5A46-
