model
size = 19 32 32, scale = 0.05, origin = -y
material deform = 1, fade = true, lighting = smooth, roughness = 0.3, metalness = 0.6
  colors = A:#630 B:#633 C:#111 D:#444
voxels
27-4C15-4D15-4A1023-BA2(B14-B3A)B12-2AB3AB2A10-2A2B2A2(BA)7-4AB7AB6-13B10-5C14-5D14-5B3(14-5A)5(14-B3AB)4(14-B2ABA)14-2BABA14-3ABA14-5A14-2AB2A14-3A2(BA14-B2A)B3(A14-2(AB))A14-AB2-A-B2(10-2A5-2A)B7-2A9-BA6-2A10-B5-B13-A4-2B10-3B7-9C10-2D5-2D10-2B5-2B8(10-2A5-2A)10-2A5-3A9-2A5-3A16-4(3A9-2A5-)ABA9-2A5-3A9-2A5-ABA8-3A5-A2B3(8-3A5-ABA)8-3A5-AB-A7-3A5-AB-A6-BA9-BA6-BA9-A7-B11-A6-B11-A4-AB13-2A2-2B13-2B5-11C8-D9-D8-B9-B5(8-A9-A)15(8-B9-A)8-A10-A2(7-A9-2A)6-B11-A5-A12-A5-A13-A3-2A13-A3-A15-A2-B15-B5-11C8-D9-D8-B9-B3(8-A9-A)5(8-A9-B)8-5(A10-B7-)3(A10-A7-)A10-2A2(6-A10-AB)6-A10-2B6-B9-B8-B9-B7-B2(11-B6-A)12-B4-A13-B4-A14-B-2A2(16-2B)3-13C6-D11-D6-B11-B2(6-A11-A)6-3(B11-2A4-A)B11-2A4-2(BA11-A5-)B9(A11-A6-)A11-B5-AB2(11-A5-BA)11-2A4-BA11-2A5-B12-A4-B13-2A3-B14-2A-B15-A2-B16-2(AB17-)B3-13C6-D11-D6-B11-B5(6-A11-A)6-5(A12-2A4-)8(A12-A5-)2(A12-B5-)A12-A5-A12-A3-2A13-A3-A14-A2-2A15-A2-A15-B-A17-2A17-AB17-B3-13C6-D11-D6-B11-B8(6-A11-A)5-A12-A5-2(B13-A4-)A13-B4-2(A14-B3-)A3(13-B3-2A)13-B3(4-A13-A)5-A12-B4-B13-A4-A14-A2-A14-A3-A15-B-A16-B-A17-AB17-B3-12C7-D10-D7-B11-B5(6-A11-A)6-A11-2(B5-A12-)B5-6(A13-A4-)A13-AB3-2(A12-A5-)A12-A4-2(A14-B3-)2A13-B5-A11-B5-A13-B4-A14-2(B2-A15-)A-A16-B-A17-2B17-B3-12C7-D10-D7-B11-B6-A11-A6-A3(11-B5-2A)11-B5-A8(B11-A6-)2(A11-A6-)2(A12-A5-)A12-A4-B13-2(A4-2A12-)A2-3A13-A2-4A11-A3-2A2(14-A3-A)15-4A15-A-A17-AB17-B4-11C8-D9-D8-B9-B7(8-A9-A)8-2(A10-2A6-)A10-3A5-A10-2A2(6-A11-A)5-2(A11-A6-)A11-B6-A2(12-A5-B)12-A6-B10-2A6-B11-A5-B11-A7-B11-2A3-BA12-BA2-B14-A3-B14-A4-A16-2A16-2B17-B4-10C9-D8-D2(9-B)7(8-A9-A)7-A10-A7-2A9-A7-BA2(9-A-A5-2A)10-2A2(5-BA11-A)5-B11-A6-A11-3(A7-A10-)A6-A10-B7-A11-B5-2A11-B7-A10-B5-2A11-B5-A13-B4-B14-AB2-B14-B2-B15-A2-B15-B4-11C8-D9-D8-A9-B3(9-A8-A)2(10-A7-A)9-A7-2A9-2A6-3A8-3A3(7-A9-2A)7-B9-2A2(8-A)9-B8-2(A9-B7-B)A9-B6-2BA9-2(B6-BA10-)2(A7-B10-)A6-AB9-2A4-2(BA)10-2A3-2AB10-A7-A11-2A5-A12-B5-A12-A3-2A14-A2-B14-2B4-11C8-D9-D8-2(A9-)2(A8-A9-)A8-A10-2(A6-A11-)A5-A13-A4-A14-A2-A-2A12-A2(-2A)12-2ABA2-A10-2(A-)A4-A9-2(A-)A4-A3(10-A2-A3-2A)10-A2-B3-2A10-A2-A3-2A9-2A2-A4-B9-2A2(3-A)9-BA-B-A2-B-A8-2A3-A2-B2A8-2A3-A2-B-A8-B2(A3-)2A7-BA7-A-A6-B3A8-A6-BA9-B-A4-ABA9-B2A4-A13-A4-B12-2B5-12C7-D10-D7-A10-2(A8-)2(A9-A8-)A10-2(A6-A11-)A5-B13-B3-A15-2(A-)A15-A2-A18-5A11-A-2A-3A10-2(2A-)2A10-3A-3A12-3A-2AB12-3A-A-B12-B2A-B-A12-3A-B-A13-2A-B-AB12-A2B-2AB12-A-2(B-A)11-A2B-2A-B11-ABA-2A13-AB2(A-)B-A9-A-B2(-A)-BA10-A2-A-2AB9-2A5-2A-A8-A6-2A8-BA9-AB6-B11-B5-13C6-D11-D6-A11-A7-A9-A8-A9-B8-2(A9-)B7-A10-A7-A11-A5-B13-B3-A15-A-A17-A22-A16-A-B16-A-A16-B-A14-B-A16-A3(2-A15-B)2-2(A16-A-)2(A16-B-)AB15-B2-A12-B2(A-)2A13-ABA-A14-2(AB)A13-2AB-BA-A9-2A6-3A8-2B7-2B6-13C6-D11-D6-A11-A7-A9-A8-A9-B8-2(A9-)B7-A10-A7-A11-A5-B13-B3-A15-A-A17-A116-A132-B19-A17-B18-B35-A15-2AB4A12-7B8-13C6-D11-D6-A11-A7-A9-A8-A9-B8-2(A9-)B7-A10-A7-A11-A5-B13-B3-A15-A-A17-A392-13C6-D11-D6-A11-A7-2(A9-A8-)2(A9-)B7-A10-A7-A11-B5-B13-B3-A15-A-A17-A392-14C5-D12-D5-A11-2A6-2(A9-A8-)2(A9-)B7-A10-A7-A11-B5-B13-A3-A15-A-A17-A392-14C5-D12-D5-A12-A6-2(A10-A7-)A10-2(B8-)A9-A8-A10-A6-A12-A4-A14-B2-A16-2A391-14C5-D12-D5-A12-A6-2(A10-A7-)A10-2(B8-)A9-A8-A10-A6-B12-A4-A14-BA-A17-A392-13C6-D11-D6-A11-A7-2(A9-A8-)A2(9-B)7-A10-A2(7-A11-A5-B13-A3-A15-B-A17-A392-13C6-D11-D6-A11-A7-2(A9-A8-)A9-B9-A7-A10-B)7-A11-A5-B13-A3-A15-B2A411-11C8-D9-D8-A9-2(A8-)A9-A8-A9-B8-B10-A6-A11-A6-B12-2A3-B14-AB-A17-A412-11C8-D9-D8-2(A9-)A2(7-A10-B)7-B11-A5-A12-2A4-B14-A2-A15-2BA431-10C9-D8-D9-A8-A10-2(A6-A11-)A6-B12-A4-A13-2A3-A15-A-A17-B432-8C11-D6-D11-A6-A11-2(A5-A12-)A5-A13-AB2-A15-BA-A17-A451-8C11-D6-D11-A6-A12-A4-2(A13-AB2-B)16-BA18-A471-6C13-D4-D13-A4-A14-4A16-2A17-BA502-
