model
size = 30 10 30, scale = 0.05, origin = -y
material deform = 1, fade = true, lighting = smooth, roughness = 0.3, metalness = 0.6
  colors = A:#111 B:#FF6
voxels
40-10A260-10A288-14A284-18A258-6A17-20A198-4A24-8A20-12A13-22A137-4A24-8A21-3A4-3A19-2A8-2A17-14A11-24A76-4A24-8A21-3A4-3A19-2A8-2A17-2A10-2A15-2A12-2A13-18A8-26A15-4B24-8A21-3A4-3A19-2A8-2A17-2A10-2A16-A12-A15-A14-A13-A16-A11-20A7-11A4-11A12-3B4-3B20-A8-A19-A10-A17-A12-A15-3(A14-)A13-A16-A11-A18-A10-20A6-2(9A10-)B10-B17-2A10-2A16-A12-A15-A14-A13-A16-A12-A16-A11-A18-A10-A18-A9-22A5-8A12-8A9-B12-B16-A12-A15-A14-A13-A16-A12-A16-A11-A18-A10-A18-A9-A20-A7-24A3-8A14-8A7-2(B14-)A14-A13-A16-A12-A16-A11-A18-A10-A18-A9-A20-A8-A20-A7-24A3-8A14-8A7-B14-B13-A16-A12-A16-A11-A18-A10-A18-A9-A20-A8-A20-A7-A22-A6-24A3-8A14-8A7-B14-B13-A16-A12-A16-A11-A18-A10-A18-A9-A20-A8-A20-A7-4(A22-A5-26A2-7A16-7A6-B16-B12-A16-A11-A18-A10-A18-A9-A20-A8-A20-A7-A22-A6-)2(A22-A5-26A2-8A14-8A7-B14-B13-A16-A12-A16-A11-A18-A10-A18-A9-A20-A8-A20-A7-)A22-A6-24A3-8A14-8A7-2(B14-)A14-A13-A16-A12-A16-A11-A18-A10-A18-A9-A20-A8-A20-A7-24A4-8A12-8A9-B12-B16-A12-A15-A14-A13-A16-A12-A16-A11-A18-A10-A18-A9-A20-A7-24A4-2(9A10-)B10-B17-2A10-2A16-A12-A15-A14-A13-A16-A12-A16-A11-A18-A10-A18-A9-22A6-11A4-11A12-3B4-3B20-A8-A19-A10-A17-A12-A15-3(A14-)A13-A16-A11-A18-A10-20A7-26A15-4B24-8A21-3A4-3A19-2A8-2A17-2A10-2A16-A12-A15-A14-A13-A16-A11-20A8-24A76-4A24-8A21-3A4-3A19-2A8-2A17-2A10-2A15-2A12-2A13-18A10-22A137-4A24-8A21-3A4-3A19-2A8-2A17-14A13-20A198-4A24-8A20-12A15-18A258-6A20-14A278-
