model
size = 28 30 31, scale = 0.05, origin = -y
material deform = 1, fade = true, lighting = smooth, roughness = 0.3, metalness = 0.6
  colors = A:#777
voxels
14-A867-A838-A-A26-A810-3A25-A-A25-3A26-A782-3A25-A-A25-3A26-A726-3A24-2(A3-A23-)A3-A24-3A26-A27-A670-3A24-A3-A22-2(A5-A21-)2A3-2A22-5A24-3A26-A27-A613-5A22-A5-A20-3(A7-A19-)2A5-2A19-3A3-3A20-7A22-5A24-3A26-A557-5A22-A5-A20-A7-A18-4(A9-A17-)2A7-2A18-2A5-2A20-7A22-5A24-3A26-A501-5A21-2A5-2A18-A9-A17-A9-A16-4(A11-A15-)2A9-2A16-2A7-2A17-3A5-3A18-9A21-5A24-3A26-A444-6A20-2A6-2A17-A10-A15-2A11-A14-A12-A14-A26-3(2A13-A12-)3A11-2A13-2A11-A14-3A9-2A14-5A5-4A15-12A17-10A20-6A414-6A20-10A17-3A6-3A15-2A10-2A14-A12-A13-5(A14-A12-)A14-A13-A12-A14-A12-A15-A10-A17-2A6-2A20-6A23-3A444-6A20-2A6-2A17-A10-A15-A12-A14-A12-A13-4(A14-A12-)A14-A27-A13-A12-A14-2A10-2A15-3A6-3A17-10A20-6A414-6A20-2A6-2A17-A10-A15-A12-A14-A12-A13-5(A14-A12-)A14-A13-A12-A14-A12-A15-A10-A17-2A6-2A20-6A24-2A416-6A20-2A6-2A17-A10-A15-A12-A14-A12-A13-5(A14-A12-)A14-A13-A12-A14-A12-A15-A10-A17-2A6-2A20-6A414-6A20-2A6-2A17-A10-A15-A12-A14-A12-A13-5(A14-A12-)A14-A13-A12-A14-A12-A15-A10-A17-2A6-2A20-6A442-6A20-3A4-3A17-A10-A15-A12-A14-A12-A13-5(A14-A12-)A14-A13-A12-A14-A12-A15-A10-A17-2A6-2A20-6A24-2A417-4A21-3A4-3A17-A10-A15-A12-A13-2(A14-A12-)A14-A11-3(A16-A10-)2A14-2A11-A14-A2(12-2A)12-3A10-3A13-4A6-4A15-12A17-10A21-4A358-8A19-A8-A16-2A10-2A14-A12-A13-A14-A11-7(A16-A10-)A16-A11-A14-A13-A12-A14-2A10-2A16-A8-A19-8A330-4A21-3A4-3A17-A10-A15-A12-A13-A14-A11-2(A16-A10-)A16-A9-3(A18-A8-)A18-A9-2(A16-A10-)A16-A11-A14-A13-A12-A15-A10-A17-3A4-3A21-4A302-2A4-2A18-2A8-2A15-A12-A13-A14-A11-A16-A10-A16-A9-7(A18-A8-)A18-A9-A16-A10-A16-A11-A14-A13-A12-A15-2A8-2A18-8A299-2A6-2A16-2A10-2A13-A14-A11-A16-A10-A16-A9-2(A18-A8-)A18-A7-3(A20-A6-)A20-A7-2(A18-A8-)A18-A9-A16-A10-A16-A11-A14-A13-2A10-2A16-3A4-3A21-4A272-2A8-2A15-A12-A13-A14-A11-A16-A9-A18-A8-A18-A7-7(A20-A6-)A20-A7-A18-A8-A18-A9-A16-A11-A14-A13-A12-A15-2A8-2A18-8A269-2A10-2A13-A14-A11-A16-A9-A18-A8-A18-A7-2(A20-A6-)A20-A5-3(A22-A4-)A22-A5-2(A20-A6-)A20-A7-A18-A8-A18-A9-A16-A11-A14-A13-2A10-2A16-3A4-3A21-4A242-2A12-2A11-A16-A9-A18-A8-A18-A7-A20-A6-A20-A5-7(A22-A4-)A22-A5-A20-A6-A20-A7-A18-A8-A18-A9-A16-A11-2A12-2A14-2A8-2A18-8A239-2A14-2A9-A18-A8-A18-A7-A20-A5-2(A22-A4-)A22-A3-5(A24-A2-)A24-A3-2(A22-A4-)A22-A5-A20-A7-A18-A8-A18-A9-2A14-2A2(12-A)15-3A6-3A19-6A185-A14-A11-A16-A9-A18-A7-A20-A5-2(A22-A4-)A22-A3-7(A24-A2-)A24-A3-2(A22-A4-)A22-A5-A20-A7-A18-A9-A16-A11-A14-A13-3A8-3A17-8A183-A16-A9-A18-A7-A20-A5-A22-A4-A22-A3-2(A24-A2-)A24-A-A5(26-2A)26-A-2(A24-A2-)A24-A3-A22-A4-A22-A5-A20-A7-A18-A9-A16-A11-2A12-2A14-3A6-3A19-6A155-2A16-2A7-A20-A6-A20-A5-A22-A3-A24-A2-A24-A-A9(26-2A)26-A-A24-A2-A24-A3-A22-A5-A20-A6-A20-A7-2A16-2A10-A14-A13-2A10-2A16-10A126-A16-A9-A18-A7-A20-A5-A22-A3-A24-A2-A24-A-A11(26-2A)26-A-A24-A2-A24-A3-A22-A5-A20-A7-A18-A9-A16-A11-2A12-2A14-3A6-3A19-6A99-A18-A7-A20-A5-A22-A3-A24-A2-A24-A-A13(26-2A)26-A-A24-A2-A24-A3-A22-A5-A20-A7-A18-A9-2A14-2A12-2A10-2A16-10A9-
