model
size = 21 21 32, scale = 0.05, origin = -y
material deform = 1, fade = true, lighting = smooth, roughness = 0.3, metalness = 0.6
  colors = A:#AAA B:#BBB C:#111
voxels
115-A21-A450-6(B20-)B174-2(7B133-B6(19-2B)19-B133-7B14-)7A13-A7-2A9-2A10-2A6-A13-A5-A15-2A3-A16-A2-A17-A-A6(19-2A)19-A-A17-A2-A17-A3-A16-A3-2A14-A6-A12-A2(7-3A)11-7A15-5A14-2A5-3A9-2A10-2A6-A13-A5-A15-A4-A16-2(A2-A17-)A-A4(19-2A)19-A-2(A17-A2-)A17-A3-A15-A4-2A14-A6-A11-2A8-3A5-3A13-5A37-5A13-3A5-3A9-A11-A7-A13-A5-A15-A4-A16-A3-A16-5(A2-A17-)2(A3-A16-)A3-A15-2A4-A13-A7-A11-2A8-A9-A11-10A57-A16-4A-5A2(9-2A)7-A13-A6-A13-A5-A15-A4-A15-2A2(3-A16-A)2-A17-2(A3-A16-)A3-A15-2A3-A15-A4-AC14-A5-A13-A7-2A10-2A9-2A5-3A12-7A78-5A14-2A5-2A10-2A9-2A8-A11-A7-A13-A6-A13-A5-4(A15-A4-)A15-A5-A13-A6-C13-A7-C12-C7-2C10-C10-2A5-3A13-5A121-5A14-2A5-3A10-2(A9-)A11-2A7-A12-5(A6-A13-)A7-A12-A7-C12-C30-C8-C11-9A118-7A12-3A5-3A9-2A10-A8-A11-2A2(6-A13-A)5-2(A15-A4-)A15-A5-A13-A6-A13-A7-A12-A7-C11-2C30-C2A3-3AC14-3A122-5A14-2A5-3A10-2(A9-)A11-2A7-A12-5(A6-A13-)2(A7-A12-)A7-2CA8-2C10-C8-C11-C8A141-3A15-3A3-4A10-2(A9-)A11-A8-A12-A7-A12-3(A6-A13-)2(A7-A12-)A7-3A8-2A11-A6-A-C10-C7-AC12-7A161-7A13-A7-A11-2(A9-)2(A11-A8-)3(A12-A7-)A11-A8-A11-A9-2A8-A12-A6-A13-2A3-2A16-3A164-5A15-2A4-A13-A7-2A10-2(A9-)2A10-4(A8-A11-)2(A9-)A11-A8-A12-A5-2A14-5A206-4A14-3A4-2A12-A8-A11-A8-4(A10-A9-)A11-A8-A11-A7-A13-7A226-A18-2A-4A13-A7-A12-A8-3(A10-A9-)A11-A8-A11-A7-A13-A5-A15-5A247-3A17-7A13-2A6-A12-3(A8-A11-)A7-A13-A5-A15-A3-A17-3A290-6A13-2A6-2(A12-A7-)A12-2A5-2A14-A3-A17-4A18-A291-6A13-2A6-2(A12-A7-)A13-A5-A15-A3-A17-3A314-2A15-4A2-2(A14-A5-)A15-A3-A17-3A19-A315-A17-3A-2(A16-A3-)A17-4A18-A355-4A17-A2-A17-4A19-A356-A2(19-2A)19-A377-2(2A19-)2A397-2A19-2A20-A376-A20-2A19-2A397-2(2A19-)A398-2A19-2A397-2A19-2A20-A2(397-2A19-2A)324-
