model
size = 24 31 28, scale = 0.05, origin = -y
material deform = 1, fade = true, lighting = smooth, roughness = 0.3, metalness = 0.6
  colors = A:#FC9 B:#FC6 C:#222 D:#B00 E:#0CF F:#EEE G:#111
voxels
371-B23-B647-3A20-5A3(18-6A)19-5A570-6A17-8A15-2(10A14-)3(11A13-)10A15-8A17-6A20-3A428-5A17-8A15-11A12-13A2(10-14A)9-4(16A8-)16A9-14A2(11-13A)12-11A16-5A354-6A16-10A14-11A12-13A9-16A2(8-16A7-17A)2(7-17A)3(8-16A)9-14A11-13A12-10A16-6A328-10A14-11A11-14A10-14A9-16A2(7-17A)2(7-2(18A6-)17A)7-18A7-16A9-14A12-11A13-10A16-6A3(18-C-C2-C)211-5A16-11A11-14A9-16A8-16A2(7-17A)7-8(18A6-)17A8-16A9-14A12-11A13-10A17-5A-2(C19-C3-)C19-C164-6A16-11A11-14A9-16A8-17A6-2(17A7-)10(18A6-)18A7-16A9-14A11-13A11-C11A12-2(C-)C3-C15-2(C-)C3-C17-C-C3-C68-3(3B21-)3A17-10A13-13A9-16A8-16A7-2(18A6-)17A7-11(18A6-)17A8-16A9-14A11-13A16-3A2-2(C19-C3-)C19-C44-3(6B18-)6A16-11A12-13A9-16A7-17A7-13(18A6-)18A7-17A7-16A8-16A10-13A11-C-C6A3-2(C11-2(C-)2(C3-))C15-C3-C41-3(8B16-)8A15-11A11-14A8-17A7-16(18A6-)18A7-16A9-14A13-8A2(C19-C3-)C19-C42-3(10B14-)10A13-13A9-16A7-18(18A6-)18A7-16A10-C10A-C11-2(C-)5A3-C11-2(C-)2(C3-)C13-C-C3-C23-C16-3(11B13-)11A12-13A9-16A7-7(18A6-)18A4-B-18A-B-2B2(-18A-4B)-18A-2B-B-18A-B3-B18AB5-3(18A6-)18A7-16A8-16A9-C-11A11-C3-6A-C12-C6-C3-C19-C3-C38-3(11B13-)11A11-14A9-16A7-7(18A6-)18A4-B-18A-B2-2B18A2B3-B18AB4-B18AB5-18A4-2B18A2B2-B-18A-B4-3(18A6-)18A7-16A11-11A13-C-6A2(16-C2-C3-C)23-C16-3(11B13-)11A12-13A9-16A2(7-17A)7-6(18A6-)18A4-2B18A2B3-B18AB4-B18AB3-2B18A2B2-2B18A2B4-4(18A6-)17A8-16A11-11AC14-6A2(-C)14-C2-C3-C-C14-C2-C3-C19-C18-3(10B14-)10A13-13A10-15A8-16A7-17A7-6(18A6-)18A5-B18AB4-B18AB3-2B18A2B3-B18AB4-B18AB5-3(18A6-)18A7-17A7-16A9-C-10A12-C-C2-5A14-C-C2-C3-C16-C2-C3-C23-C16-3(10B14-)10A13-13A2(10-14A)9-16A7-8(18A6-)18A5-B18AB4-B18AB5-5(18A6-)17A9-14A12-10AC15-C-3A3-C15-C2-C4-C18-C23-C19-3(8B16-)8A15-11A11-14A10-14A9-16A2(7-17A)7-13(18A6-)17A8-15A10-14A12-C8A2(15-2(C3-)C)19-C3-C41-3(6B18-)6A16-11A12-13A10-14A9-16A8-16A7-13(18A6-)18A7-17A7-16A10-13A11-C2-6A15-C2-C3-C16-C2-C3-C23-C139-6A16-11A11-14A9-16A8-16A7-17A7-11(18A6-)18A7-16A9-14A11-13A12-11A14-C2-C4-C15-C2-C4-C18-C4-C162-2A19-7A14-14A10-15A2(8-16A)7-17A7-9(18A6-)18A7-16A8-16A9-14A12-11A13-C8A15-C2-2(C-)C16-C2-2(C-)C21-C-C165-2B20-4A17-11A11-3AD10A9-3AD8AD3A3(8-16A)7-6(18A6-)18A7-17A7-16A8-16A9-14A12-11A13-10A17-5A236-2B21-4B19-6B18-D5A17-D6AD15-D8ADA12-13A2(10-14A)9-4(16A8-)16A9-14A2(11-13A)12-12A12-11A13-10A16-6A331-5D17-2D5AD15-D8ADA12-AD8AD2A10-3A3D2A3D3A2(10-14A)9-3(16A8-)16A9-14A2(11-13A)12-11A16-5A401-8D16-D4FCFD16-8D65-B-2B-B18-6B19-4B20-4B17-3E4B3E14-EGE4BEGE14-4E2B4E13-11BC13-4C3-4C543-B-2B-B18-B-2B-B19-2(4B20-)4B21-2B22-2B18-10C568-6B18-B-2B-B19-4B21-3(2B22-)2B598-2B21-4B21-2(2B22-)B324-
