model
size = 12 19 12, scale = 0.05, origin = -y
material deform = 1, fade = true, lighting = smooth, roughness = 0.3, metalness = 0.6
  colors = A:#1C1D20
voxels
4-6A65-12(6A6-)6A66-13(6A6-)6A18-3(6A6-)6A4-13(2A6-2A2-)2A6-2A4-6A5-3(A6-A4-)A6-A3-13(A8-A2-)A8-A3-2A4-2A4(3-3(A8-A2-)A8-A-A13(10-2A)10-A2-A6-A)3-3(A8-A2-)A8-A-A13(10-2A)10-A2-2A4-2A3-3(A8-A2-)A8-A-A13(10-2A)10-A3-6A5-3(A6-A4-)A6-A3-13(A8-A2-)A8-A16-3(6A6-)6A4-13(2A6-2A2-)2A6-2A-
