model
size = 30 12 3, scale = 0.05, origin = -y
material deform = 1, fade = true, lighting = smooth, roughness = 0.3, metalness = 0.6
  colors = A:#000
voxels
13-4A25-6A25-4A16-2A8-4A8-2A5-4A8-2A8-4A3-2A2-2(2A7-)2A2-2A-2A4-3A12-3A4-4A2-A2-4A8-4A2-A2-2A-4A4-5A2-5A4-4A3-2A6-4A2-4A6-2A13-3A2-3A23-A4-A25-4A25-6A25-4A16-2A8-4A8-2A5-4A8-2A8-4A3-2A2-2(2A7-)2A2-2A-2A4-3A12-3A4-4A2-A2-4A8-4A2-A2-2A-4A4-5A2-5A4-4A3-2A6-4A2-4A6-2A13-3A2-3A23-A4-A105-2A20-2A5-4A18-4A3-2A2-2A16-2A2-2A-2A4-3A12-3A4-4A2-A2-4A8-4A2-A2-2A-4A4-5A2-5A4-4A3-2A6-4A2-4A6-2A13-3A2-3A23-A4-A12-
