model
size = 32 23 30, scale = 0.05, origin = -y
material deform = 1, fade = true, lighting = smooth, roughness = 0.3, metalness = 0.6
  colors = A:#3CC B:#BBB C:#888 D:#AAA
voxels
367-2A29-4(4A28-)4D687-4(A28-A2-)A28-A-A30-A513-A28-A2-A28-A129-A30-2A30-A418-A26-A4-A26-A258-A30-A354-A26-A322-A30-A322-A26-A322-A30-2A30-A290-A26-A354-A30-A322-A26-A322-2(A30-A323-A24-A355-A30-A323-A24-A323-)A30-A292-A22-A7-2(A24-A6-)A24-A5-A26-A4-A26-A195-A28-A294-A20-A9-A22-A7-2(A24-A6-)A24-A5-2(A26-A4-)A26-A3-A28-A3-A26-A99-A28-A293-2(A22-A8-)A22-A7-A24-A6-A24-A5-A25-A5-2(A26-A4-)A26-A3-3(A28-A2-)A28-A294-A20-A9-2(A22-A8-)A22-A7-2(A24-A6-)A24-A5-4(A26-A4-)A26-A3-A27-A3-A28-A294-A20-A9-2(A22-A8-)A22-A7-2(A24-A6-)A24-A5-6(A26-A4-)A26-A264-A18-2A10-A20-A10-A21-2(A8-A22-)A8-A23-3(A6-A24-)A5-A25-A5-4(A26-A4-)A26-A264-A18-A11-A20-A10-A20-A9-2(A22-A8-)A23-4(A6-A24-)5(A5-A25-)A265-A18-A12-A19-2(A10-A20-)A10-A21-2(A8-A22-)A7-3(A24-A6-)A24-A5-A25-4(A6-A24-)A202-A16-A14-A17-2(A12-A18-)2A3(10-A20-A)9-2(A22-A8-)A22-A7-2A22-A7-A23-4(2A6-2A22-)2A7-A22-A203-2(A16-A14-)A17-3(A12-A18-)2A3(10-A20-A)9-2A20-A9-5(2A20-2A8-)2A20-2A9-A20-A205-A14-A15-3(A16-A14-)A16-2A3(12-A18-A)11-2A18-A11-6(2A18-2A10-)2A18-2A30-A175-A12-A17-2A12-2A2(16-A14-A)15-2(2A14-)2(A16-A14-)A2(16-A13-2A)6(16-2A12-2A)16-2A13-A16-A14-A16-A177-2A8-2A19-2A10-2A18-2A11-A18-A12-A17-2(2A12-2A16-)A14-A16-A14-A15-15(2A14-)2A15-A14-A16-2A12-2A179-4A2-4A21-2A7-3A20-2A8-2A20-A10-A19-2(2A10-2A18-)2(A12-A18-)A12-A17-4(2A12-2A16-)2A12-2A17-2(A12-A18-)A11-2A18-2A10-2A182-6A25-8A23-3A4-2A23-2A6-2A21-3(2A8-2A20-)6(A10-A20-)D10-D20-CA9-C20-BA9-B20-AB8-2A20-2A8-2A217-2A28-6A26-6A25-2A4-2A24-2A4-2A23-3(2A6-2A22-)5(A8-A22-)D8-D22-CA7-C23-A7-B23-2A5-2A24-A4-A252-2A29-4A27-6A26-6A25-3A2-3A2(24-2A4-2A)4(24-A6-A)24-D6-D24-CA5-C24-BA4-AB25-2B2-2B28-2A382-2A29-4A27-6A26-2A2-2A4(26-A4-A)26-DA2-AD26-6C28-2B175-
