model
size = 24 16 22, scale = 0.05, origin = -y
material deform = 1, fade = true, lighting = smooth, roughness = 0.3, metalness = 0.6
  colors = A:#3F3 B:#3C3 C:#393 D:#360 E:#30C F:#036
voxels
52-2(A14-A8-)D14-A2(8-D14-D)8-A14-D8-A14-A174-3(A18-A4-)2(A18-D4-)2(D18-A4-)D2(18-A364-A)18-A11-6A17-2(2(2AD)2A16-)2(2AD)2A17-6A251-A5-8A5-A9-4(10A14-)10A15-8A56-A4(22-2A)2(22-2D)22-DA-6A8C6A-A7-5(10A14-)10A16-6A201-A6-AC6-CA6-A7-2A6B2A5(14-10A)15-8A200-A6-AC6-CA6-A7-2AB-2B-B2A5(14-10A)15-8A200-8AC6-C8A7-3(2AB-2B-B2A5(14-10A)15-8A207-AC6-CA14-)2AB-2B-B2A5(14-10A)15-8A201-7AC6-C7A2(8-2AB-2B-B2A5(14-10A)15-8A201-A5-AC6-CA5-A)8-2A6B2A5(14-10A)16-6A202-A5-AC6-CA5-A8-2A6B2A5(14-10A)16-6A18-6A178-A2-4A8C4A2-A8-5(10A14-)10A16-6A18-6A10-4(A20-A2-)D20-A2(2-D20-D)2-D2-A4-6A4-A2-A10-4(6A18-)6A16-F-6A-F17-F2-F20-F2-F182-A4-6A4-A13-5(6A18-)6A229-A5-4A5-A13-5(6A18-)6A229-A4-6A4-A13-3(6A18-)6A42-F4-F211-E2-E14-A5-E2-E5-A14-E2-E20-E2-E154-
