model
size = 26 28 18, scale = 0.05, origin = -y
material deform = 1, fade = true, lighting = smooth, roughness = 0.3, metalness = 0.6
  colors = A:#555 B:#888 C:#111 D:#777 E:#444
voxels
33-12C14-C4D2C4DC13-EC3DE2CE3DCE11-2ECD2E4C2EDC2E11-2CE2(2CB)2CE2C12-CBC3B2C3BCB2(C12-C4BE2CE4B)C2(12-5BE2CE5B)12-4B2E2C2E4B12-B3E6C3EB12-E4C4-4CE2(12-C)12-14C12-C5A2C5AC11-CA4BA2CA4BAC9-CA5BA2CA5BAC7-CA7B2C7BAC4-2CA8B2C8BA2C-2CA9B2C9BA2C2-A9B2C9BA5-9B2C9B2(8-4B)91-10C15-C4B2C4BC13-AC3BA2CA3BCA11-2ACB2A4C2ABC2A11-2CA2(2CB)2CA2C12-CBC3B2C3BCB2(C12-C4BA2CA4B)C2(12-5BA2CA5B)12-4B2A2C2A4B12-B3A6C3AB12-A4C4-4CA2(12-C)12-14C11-DC5A2C5ACD9-DCA4BA2CA4BACD8-CA5BA2CA5BAC7-CA7B2C7BAC5-CA8B2C8BAC2-2CA9B2C9BA3C2(A10B2C10BA2C)2A9B2C9B2AC3-A8B2C8BA88-C4B2C4BC13-D5A2C5AD11-D6A2C6AD9-C7A2C7AC9-C6A2C6AC10-D6A2C6AD10-7A2C7A4(10-C6A2C6AC)10-7A2C7A10-C6A2C6AC11-C5A2C5AC10-2(2C6A)2C8-D7A2C7AD7-D8A2C8AD6-D8A2C8AD5-D8AB2CB8AD3-B9AB2CB9AB-B2(10AB2CB10A2B)10AB2CB10AB2C9AB2CB9A2C2-CA8B2C8BAC5-A5B8-5BA61-CB10-BC11-2DA10-A2D9-2D2A10-2A2D7-C4A10-4AC6-AD3A10-3ADA2(6-CD3A10-3ADC)6-2D3A10-3A2D2(6-AD3A10-3ADA)6-C4A10-4AC7-C3A10-3AC9-B2A10-2AB11-CA10-AC9-C2B2A10-2A2BC6-D4A10-4AD5-C5A10-5AC4-D5A10-5AD3-B6A10-6AB2-B5A12-5AB-2B4A6-2C6-4A3(4B10A2C10A)2B2-C9A2C9AC5-AB7A2C7ABA2(8-4A)36-CB12-BC9-3D12-3D7-C3A12-3AC6-4A12-4A5-6(C4A12-4AC4-)CB3A12-3ABC6-B2A12-2AB9-BA12-AB11-A12-A8-C3BA12-A3BC4-C4A12-4AC3-2(B5A12-5AB2-)B4A14-4AB2-B3A16-3AB-2B2A18-2A4BA9-2C9-A2(4B10A2C10A)2B2-10A2C10A5-C8A2C8AC2(8-4A)34-2CB14-B2C6-C2A14-2AC6-3A14-3A6-B2A14-2AB5-6(B3A14-3AB4-)2B2A14-2A2B6-BA14-AB9-B14-B33-C3B14-3BC4-C2AC14-C2AC3-5C14-5C2-4C16-4C2-3C18-3C2-2C20-2C-2C22-3C24-2(2C11-)2(2C11A)C2B10A2C10A2B2-10A2C10A5-AC7A2C7ACA8-3CA8-A3C8-3B14-3B3(6-B2A14-2AB)6-3A14-3A5-4(B3A14-3AB4-)B3A14-3AB5-3A14-3A7-BA14-AB9-B14-B33-4B14-4B4-4C14-4C184-C11A2C11A7C6A2C6A6C2-4C6A2C6A4C5-3C3A8C3A3C8-3CA8-A3C8-A2B14-2BA6-3A14-3A2(6-B2A14-2AB)6-3A14-3A5-4(B3A14-3AB4-)B3A14-3AB5-3(3A14-3A7-BA14-AB9-B14-B33-4B14-4B5-2C16-2C185-C9A6-9AC2B8A6-8A2B2-8A6-8A5-6AC6-C6A2(8-A2CA)9-CB14-BC7-3A14-3A2(6-B2A14-2AB)6-3A14-3A6-C2A14-2AC5-2(B3A14-3AB4-)B3A14-3AB5-C2A14-2AC6-)3A14-3A7-BA14-AB9-B14-B33-4B14-4B5-2C16-2C185-C9A6-9AC2B8A6-8A2B2-8A6-8A5-6AC6-C6A2(8-A2CA)8-A2B14-2BA6-3A14-3A2(6-B2A14-2AB)6-3A14-3A5-4(B3A14-3AB4-)B3A14-3AB5-3A14-3A7-BA14-AB9-B14-B33-4B14-4B5-2C16-2C185-C9A6-9AC2B8A6-8A2B2-8A6-8A5-6AC6-C6A2(8-A2CA)8-3B14-3B3(6-B2A14-2AB)6-3A14-3A5-4(B3A14-3AB4-)B3A14-3AB5-3A14-3A7-BA14-AB9-B14-B33-4B14-4B4-4C14-4C184-C11A2C11A7C6A2C6A6C2-4C6A2C6A4C5-3C3A8C3A3C8-3CA8-A3C8-C2B14-2BC6-3A14-3A2(6-B2A14-2AB)5-6(B3A14-3AB4-)2B2A14-2A2B6-BA14-AB9-B14-B33-C3B14-3BC4-C2AC14-C2AC3-5C14-5C2-4C16-4C2-3C18-3C2-2C20-2C-2C22-3C24-2(2C11-)2(2C11A)C2B10A2C10A2B2-10A2C10A5-9A2C9A8-3CA8-A3C9-C2B12-2BC7-C3A12-3AC6-4A12-4A6-B3A12-3AB5-6(C4A12-4AC4-)CB3A12-3ABC6-B2A12-2AB9-BA12-AB11-C12-C9-C2BA12-A2BC5-B4A12-4AB3-B5A12-5AB2-B4A14-4AB2-B3A16-3AB2-B2A18-2AB-B2A20-2A2BA10-2C10-A2(2B11A2C11A)B2-C9A2C9AC5-2C4A3B2C3B4A2C8-C2BA8-A2BC36-C2B10-2BC9-D3A10-3AD7-C4A10-4AC6-5A10-5A6-E4A10-4AE2(6-C4A10-4AC)6-D4A10-4AD2(6-E4A10-4AE)6-C4A10-4AC7-B3A10-3AB9-B2A10-2AB11-CA10-AC10-CB2A10-2ABC7-5A10-5A5-B5A10-5AB3-B5A12-5AB2-B4A14-4AB2-B3A16-3AB-B3A8-2C8-3A2B11A2C11AB12A2C13AC10A2C10ACA2-C3A2B4A2C4A2B3AC5-C2A2BA3B2C3BA2B2AC2(8-A2BA)37-C12BC11-D14AD9-D16AD7-C18AC7-6(D16AD8-)E16AE8-C16AC9-B14AB11-C12AC11-C6A2C6AC9-8A2C8A6-B6A8-6AB4-6A10-6A3-B3ABA12-AB3AB2-B3AB6-2C6-B3AB-B4AB6A2C6AB4AB5AB6A2C6AB5A2C3AB6A2C6AB3A2C2-3AB3A3B2C3B3AB3A5-2A7B2C7B2A2(8-4B)64-C10BC13-D12AD11-D14AD9-C16AC9-C14AC10-D14AD10-E14AE4(10-C14AC)10-E6A2B6AE10-C4ABD2-DB4AC11-C3D6-3DC12-C5A2C5AC11-7A2C7A9-8A2C8A7-5A10-5A5-3AB2A4-2C4-2AB3A3-B3AB6A2C6AB3AB-3A3B6A2C6A3B3AC2A3B6A2C6A3B2AC2-A3B6A2C6A3BA5-3B3A3B2C3B3A3B2(8-4B)83-
