model
size = 19 25 13, scale = 0.05, origin = -y
material deform = 1, fade = true, lighting = smooth, roughness = 0.3, metalness = 0.6
  colors = A:#2F2F2F B:#444
voxels
7-5A185-2(2AB2A14-)A3BA14-2AB2A222-7A14-3A131-A16-5A13-2(A2-)2(A12-A5-)A12-7A220-9A12-5A15-3A93-A17-3A14-2A3-2A11-3(A7-A10-)2A5-2A12-5A185-5A11-11A10-7A13-5A16-A56-A17-3A15-5A12-2A5-2A2(9-A)2(8-A9-A)8-2A7-2A10-2A3-2A14-8(3A16-)3A14-2A3-2A9-13A8-5A3-A11-7A14-3A17-A18-A17-3A15-5A13-A4-2A10-2(2A7-)3(A11-A6-)2A9-2A8-2A5-2A12-7(A3-A14-)A3-A13-2A3-A12-2A5-2A8-13A7-11A9-9A12-5A15-3A16-3A15-5A13-2A3-2A11-2A4-3A9-A8-2A7-3(A11-A6-)2A9-2A8-A7-A11-8(A5-A12-)A5-A11-A7-A8-13A7-6A3-2A9-6A-2A11-7A13-5A14-5A13-7A11-3A3-3A9-3A4-4A8-A9-A7-2A9-2A2(6-A11-A)4-4A9-4A3-A2-A7-A2-A4-A3-A5-A3-A2-2A4-A5-A4-A-3(A5-)2(2A2(5-A)5-)3A4-A5-A4-2A-2A2-2A5-2A2-2A3-3A-A5-A-3A8-A5-A11-A7-A8-13A7-11A9-9A12-5A15-3A16-3A15-5A13-2A3-2A11-2A4-3A2(9-A)7-3(A11-A6-)2A9-2A8-A7-A11-8(A5-A12-)A5-A11-A7-A8-13A8-9A11-7A14-3A17-A18-A17-3A15-A2-2A13-A4-2A10-2(2A7-)3(A11-A6-)2A9-2A8-2A5-2A12-8(A3-A14-)A3-A12-2A5-2A9-11A9-4A-3A13-5A16-A56-A17-3A15-5A12-2A4-3A2(9-A)2(8-A9-A)8-2A7-2A10-2A3-2A14-8(3A16-)3A14-2A3-2A11-9A11-6A15-3A93-A17-3A14-2A3-2A11-3(A7-A10-)2A5-2A12-5A185-5A13-7A14-3A131-A16-5A13-2(A2-)2(A12-A5-)A12-7A222-5A185-2(2AB2A14-)A3BA14-2AB2A216-
