model
size = 32 15 21, scale = 0.05, origin = -y
material deform = 1, fade = true, lighting = smooth, roughness = 0.3, metalness = 0.6
  colors = A:#FC0 B:#F90 C:#C90 D:#222 E:#C60 F:#960 G:#004 H:#660 I:#633 J:#0CC K:#06F L:#03F M:#963
voxels
51-2DMB2A26-C5A26-6A27-4A29-2A302-5D26-17D2-4A16-4DI2F2C7A20-12A21-11A22-10A22-9A24-7A28-2B206-D2E27-13D10-3A7-11DI2F7-4A14-2CB4A7-4A17-5A5-4A18-14A19-13A19-12A21-10B24-4E3C195-A5-7D18-3A4-12D13-3A7-3DHF3CBA11-4A13-5A10-3A15-5A8-4A16-6A5-5A17-14A18-14B19-7E5C22-CEC2E4B162-2A30-2A3-9D18-2A4-6DHF3C14-3A10-6A2(13-3A)12-4A14-4A9-4A15-5A7-5A16-16B17-C7E6C19-3CEC2E5B21-6E4B131-2A30-2A2-4D24-2A2-7DHFC17-3A6-C6A16-3A11-3A14-3(3A13-)4A11-4A14-5B8-4B16-2C5E2-7C17-E3CEC2E6B19-7E5B22-4C4B101-A2(30-2A)-8D21-2A3-F3C5A17-3A9-4A16-3A11-3A14-4A12-2(3A13-)4B11-4B14-B2C2E8-4C16-2E3CE4-5B18-8E5B21-5C5B25-2CB72-2(A31-)A-6D23-2AG-2F3C4A19-2AG7-4A17-3A11-2A16-3A11-3A14-4A12-3B12-4B14-B2CE10-4C14-3E3C6-4BC16-7E-E6B19-6C6B22-4C3B70-2(A31-)AK3D27-AKD2F3C3A20-2AG6-5A18-2A10-3A16-3A11-2A16-3A12-2B14-3B13-2B2C11-4C14-3EC9-3BC16-5E5-5B18-7C6B21-5C4B69-2(A31-)AL2D28-AKD2F3C2A22-AG5-6A18-2A10-2A18-AJ11-2A16-3A11-3B14-4B12-2BC13-3C14-3EC10-2BC16-4E7-5B17-7C6B20-6C4B29-2B38-2(A31-)AL30-AGD2F3C2A22-AG5-5A19-2AG9-2A18-AJ11-2A16-3A11-3B15-3B12-2BC13-3C14-3E11-2B2C14-5E8-4B17-5C2-6B20-6C4B29-2B38-2(A31-)AG2D28-AGD2F3C2A22-AG5-6A18-2A10-2A18-2A11-2A16-2AJ11-3B14-4B12-2BC13-3C14-3EC10-2BC16-4E7-5B17-7C6B20-6C4B29-2B38-2(A31-)A-3D27-AGD2F3C3A20-2A6-6A18-2A10-2A17-2AJ11-2A16-3A12-2B14-3B13-2B2C11-4C14-3EC9-3BC16-5E6-4B18-7C6B21-5C4B69-2(A31-)AG5D24-2AG-2F3C4A19-2AG6-5A17-3A10-3A16-3A11-3A14-4A12-2(3B13-)2B2CE10-4C14-3E2C7-4BC16-7E2-6B19-6C6B22-4C3B70-A2(30-2A)-8D21-2AG2-F3C5A18-2A9-4A16-3A11-3A14-4A12-2(3A13-)4B11-4B14-B2C2E8-4C16-2E3CE4-5B18-8E5B20-6C5B25-2CB71-2A30-2A2-3D25-2A2-7DHFC17-3A5-2C6A16-3A10-4A14-3(3A13-)4A11-4A14-5B8-4B16-2C4E4-6C17-E3CEC2E6B19-7E5B22-4C4B99-2A30-2A3-9D18-2A3-7DHF3C15-2A10-6A2(13-3A)12-4A14-3A11-4A14-5A7-5A16-7B2-7B17-C7E6C19-3CEC2E5B21-6E4B130-2A4-6D19-3A4-12D13-3A7-3DHF3CBA12-3A13-4A11-3A15-5A8-4A16-5A6-5A16-15A18-14B19-7E5C22-CEC2E4B26-2EB140-12D11-3A6-12DIF8-4A14-2CB4A7-4A16-6A5-5A17-7A-6A18-14A19-12A21-11B23-4E3C172-5D26-16D3-5A14-5DI2F2C8A19-12A2(21-11A)22-9A24-8A26-4B250-2(8A24-)7A26-6A27-4A296-
