model
size = 21 16 32, scale = 0.05, origin = -y
material deform = 1, fade = true, lighting = smooth, roughness = 0.3, metalness = 0.6
  colors = A:#200 B:#BBB C:#600 D:#EEE
voxels
135-3A17-6A2(14-7A)15-4A273-4C14-3C3-4C10-4(C9-2C9-)3C6-2C13-6C163-4(4B14-3B3C3B11-BC2B3-5B2(8-2B9-2B)8-2B9-3B7-2(2B9-)3B5-4B10-B8D162-)2(4B14-3B3C3B11-BC2B3-5B2(8-2B9-2B)8-2B9-3B7-2(2B9-)D2B5-4B10-B8D162-)4C14-9C11-12C2(8-13C)8-14C7-13C9-12C10-9C162-4C14-9C11-12C2(8-13C)8-14C7-13C9-12C10-9C183-4A14-10A10-4(12A9-)11A12-7A202-9A11-12A3(8-13A)9-11A11-9A199-13A7-14A6-15A3(7-14A)10-9A197-2(15A6-)2(16A5-)15A7-14A9-11A195-16A5-17A4-17A2(5-16A)6-14A9-11A174-2A18-17A4-18A3-18A4-17A5-16A6-15A8-12A13-5A133-2(3A18-)17A4-2(18A3-)18A2(5-16A)8-12A13-5A133-3A18-3A17-18A4-2(18A3-)18A2(5-16A)8-12A13-5A112-2A18-2(4A17-)18A3-19A2-19A3-18A4-17A5-16A8-12A13-6A110-3A18-2(4A17-)18A3-19A2-19A3-18A4-17A5-16A8-12A13-5A111-2(3A18-)4A17-18A3-19A2-19A3-18A2(5-16A)8-12A13-5A79-2A9-2A18-2(4A17-)5A16-19A3-19A2-19A3-18A2(5-16A)8-12A13-5A34-7A14-8A6-A6-8A5-3A5-8A4-5A5-6A5-5A17-4A17-19A3-19A2-19A3-18A2(5-16A)8-12A13-3A16-5A14-9A12-10A5-A5-10A4-4A3-10A3-5A3-9A4-5A16-5A17-19A3-19A2-19A4-17A5-16A6-14A9-11A31-9A11-11A9-13A4-A3-13A3-4A2(-13A2-5A)16-5A17-20A2-19A3(5-16A)6-14A9-11A31-9A10-12A9-13A7-15A2-19A-20A-5A-12A3-20A3-19A4(5-16A)6-14A9-10A32-9A10-12A9-14A6-15A2-19A2(-20A)2-20A2-19A3(5-16A)5-15A7-14A9-9A33-9A11-11A9-14A2(6-15A)3-A2-15A3-2A-16A2-A2-4(16A5-)16A6-14A7-13A12-6A55-9A10-13A7-5(15A6-)2(16A5-)15A6-15A7-13A10-10A75-7A11-12A8-14A7-7(15A6-)15A8-11A11-9A96-7A12-12A9-12A8-5(14A7-)14A8-12A12-6A141-3A17-6A13-10A11-3(11A10-)10A12-8A111-
