model
size = 15 24 32, scale = 0.05, origin = -y
material deform = 1, fade = true, lighting = smooth, roughness = 0.3, metalness = 0.6
  colors = A:#EEE B:#66C C:#919191 D:#BBB E:#FCC F:#B28065 G:#202020 H:#2D2D2D I:#F90 J:#100 K:#F0C L:#633
voxels
63-2B5C2B7-7B281-C-C11-2(5C10-)5C9-6B10-5(4A11-)4A101-5H5(10-5D)11-3D10-6C3(9-C4FC)8-2B4EB3(9-2A3BA)3(9-2A2B2A)10-4(4A11-)4A10-6A9-6H9-D4J3(D9-D4B)D9-D4GD9-6D9-C4-2C7-CF6C2(7-C6FC)6-2B6EB7-2A4B2A5(7-8A)8-4(6A9-)7A8-5ABA7-HJ6H7-DH4DJ3(D7-DB4DB)D7-DG4DGD7-2D4-2D6-2C-3C2-2C5-CF6CFC5-C2FL5FC5-C8FC4-2B8E2B4-2A6B2A5-2AB4(4-3A5-3A)4-3A6-5(2A4-2A7-)2A4-2A6-3H4-3H4(5-DJD4-DJD)5-DGD4-DGD5-2D6-2D7-C3-C-C6-2CL5CFC5-CFL6FC5-C8FC4-2B8E2B4-A8BA4(5-2A6-2A)5-2A6(6-A7-A)6-A2(6-2H)5(5-2D6-2D)5-D8-D5-2(C-)3C-2C5-8CFC5-C3FLFL2FC5-C8FC4-2B8E2B4-A8BA4(5-2A6-2A)5-2A6-A7-A3(6-A7-K)2(6-A7-A)6-A2(6-2H)5(5-2D6-2D)5-D8-D7-C5-C6-8CFC5-C2FL5FC5-C8FC4-2B8E2B4-A8BA3(5-2A6-2A)5-2A6-A6-2A6-A7-K3(6-A7-A)6-A7-K6-A7-2(A6-)2H6-2H5(5-2D6-2D)5-D8-D5-2C2(-3C)5-8CF2(C5-C8F)C4-2B8E2B4-A8BA2(5-2A6-2A)5-2A6-A6-2A3(6-A7-A6-A7-K)6-A7-2(A6-)2H6-2H5(5-2D6-2D)5-D22-C6-8CF2(C5-C8F)C4-2B8E2B4-A8BA5-2A6-2A5-2(2A6-A6-)2A3(6-A7-A6-A7-K)6-A7-2(A6-)2(2H6-)D4(6-2D5-2D)6-2D20-2C2(-C)-2C3-I2-9C3-I2-C7FC6-C7FC5-2B7E2B5-A7B3(A6-2A6-)3(A7-A6-)2(A7-K6-)3(A7-A6-)A2(7-H6-H)7-2(D6-)2(2D6-D6-)2D6-D48-G2-9C3-G2-C7FC5-2B7E2B5-A7B3(A6-2A6-)9(A7-A6-)A5(7-H6-H)51-9C3-G-2B7EBI2-G-BA7BAI5-A7B3(AG5-2A6-)A2(G2(6-A))8(7-A6-A)14-2(A7-A6-)A7-I6-I51-9C5-2B7E2B2-2(G2-A7BA3-)G2-2A6-A6-2A2(6-A7-A)6-A3(G2(6-A))2G2(5-A6-A-G)5-A6-A2G12-A7-A6-A7-A14-A6-A7-I6-A14-I65-10C4-2B8E2B4-A8BA6-A7B2(A3-G2-2A6-)2(A3-G3-A6-)A3-2G2-A6-A4-G2-A6-A4-2G-A6-A5-G-A6-A5-3G7A2(7-8A)G6-I6-A14-I95-10C5-C8FC4-2B8E2B4-A8BA6-A7BA6-2A4(6-A7-A)6-A7-8A7-G7A7-8A7-A2G4-G7-I6-I8-6A9-6A111-10C4-2B8E2B4-A8BA5-A8BA6-A7BA6-2A2(6-A7-A)6-A7-8A7-G7A7-AG4-2G7-I6-I9-3G-G39-G4-G10-5A9-5A97-10C4-2B8E2B4-A8BA5-A8BA6-A7B2(A7-A6-)A7-8A7-G4-G-G7-I2-2G2-I8-G32-3G39-5G26-5A9-4A68-10C5-2C4(FC)4-2B8E2B4-2(A8BA5-)2A7BA7-A6-A7-8A7-G6AG7-I6-I24-3G117-4A67-C8-C4-2B8C2B4-4(A8BA5-)2AB7A6-A7BA7-I6AI23-6G200-11C4-B4(EC)E2B3-A9BA4-A9B3(A5-A8B)A6-9A23-G4-G215-C9-C3-2B9C2B3-2(A9BA4-)A9B2(A5-A8B)A6-9A24-4G216-12C2-2B5(EC)2B2-3(A10BA3-)A9BA5-2A7BA7-7A245-C10-C2-2B10C2B2-3(A10BA3-)2A9BA5-A7BA7-7A245-13C-2B5(EC)E2B-2(A11BA2-)A10BA3-2A9BA5-A7BA7-7A245-C11-C-2B11C2B-3(A11BA2-)2A9BA5-A7BA7-7A245-13C-2B5(EC)E2B-3(A11BA2-)2A9BA5-A7BA7-7A245-C11-C2-13C-2B11E2B-A11BA2-A11BA3-A9BA5-2A5B2A8-5A247-11C3-5(CF)3C-2B11E2B-A11BA3-A9BA4-A9BA5-3A4B2A8-5A248-C7-C5-11C3-2B9E2B3-2(A9BA4-)2A8BA6-2A3B3A9-3A250-7C7-9C5-C9FC3-2B9E2B3-A9BA5-A7BA7-7A279-5C8-9C5-3B5E3B5-2A5B2A7-7A9-5A260-
