model
size = 17 32 11, scale = 0.05, origin = -y
material deform = 1, fade = true, lighting = smooth, roughness = 0.3, metalness = 0.6
  colors = A:#B6B6B6 B:#000 C:#919191 D:#484848 E:#242424 F:#005671 G:#008BB6 H:#F00
voxels
41-2(5B12-)5B504-2(B5-B10-)B5-B420-2B15-2B63-2(B7-B8-)B7-B365-3(2(2B-)2B9-)6B2A11-4B14-2A45-2(B9-B6-)B9-B196-5B12-7B8-10B2(5-12B)4-13B4-4(2B-)2B3-B2-2(2B-)2B2-B3-B2-2(2B-)2B9-2(2B-)2B2-2A4-2(10B7-)10B8-2A4B2A11-4B14-2A45-2(B9-B6-)B9-B195-B5-B9-2B7AB6-2B8AB4-4B9AB3-4B9AB2-5B9AB2-BAB-BA3(B2A)4B2-BA2(B2A)2BA4B-3(B2A)B-5B-3(B2A)B-2C4-3(B2A)B7-3(B2A)B8-3(2AB)11-2C15-2A28-4(A9-A6-)BA7-AB2(7-A)7(8-A7-A)9-3(A5-A10-)A5-A9-10A6-11A4-C13A3-13AC2-3AB11A2-2A2B14AB-3(B2A)B-AC2AB-3(B2A)B-4AB-3(B2A)B8-2(2A-)2A9-2(2C-)2C9-2(2A-)2A59-3(A9-A6-)A9-2(A7-)7(A8-A7-)A9-4(A5-A10-)A5-A11-7A8-2A7CA5-C11A5-AC10A4-C2AC10A2-CAC4(-2A)2-AC2-2(2A-)2A2-C2-A3-2(2A-)2A9-2(2C-)2C110-3(A9-A6-)A9-2(A7-)3(A8-A7-)A9-6(A5-A10-)2A3-2A11-5A12-5A63-E7BE7-D9B6-11B6-B4(FG)2B6-E9BE124-A9-A6-A9-2(A7-)A8-A7-A9-4(7A10-)7A11-4(5A12-)5A13-3A104-B16-B178-2(2A5-2A8-)3A3-3A9-7A11-5B11-9(7B10-)7B11-5B15-B3(16-2B)16-B197-5A12-5A13-3A14-3A47-H2-AD15-AD12-H2-DA15-AD12-A2-DA15-AD13-A-DA12-ACA15-A297-
