model
size = 3 28 3, scale = 0.05, origin = -y
material deform = 1, fade = true, lighting = smooth, roughness = 0.3, metalness = 0.6
  colors = A:#111 B:#EEE C:#93F
voxels
75-4BC4B-24(A2-)A-3B3(CB)75-4BC4B
