model
size = 12 20 32, scale = 0.05, origin = -y
material deform = 1, fade = true, lighting = smooth, roughness = 0.3, metalness = 0.6
  colors = A:#800 B:#9CF C:#EEE
voxels
16-A2-A8-4A3(8-C2AC)176-A2-A8-4A3(8-C2AC)187-2A2-2A2(6-6A)5-8A6-C2AC187-2A2-2A2(6-6A)4-10A5-5A7-C2AC175-A4-A6-A4-A3-4A2(5-7A)5-3A-10A4-C4AC161-2A5-2A-4A3(5-7A)5-15A3-6A6-C4AC157-A-2A3(8-4A)8-14A3-2(6A6-)C4AC135-2A4(8-4A)8-38A-10A3-C6AC122-2A4(8-4A)8-50A2-8A4-C6AC110-2A4(8-4A)8-74A-C8AC97-2A4(8-4A)8-86A-C8AC85-2A4(8-4A)8-86A-10A2(2-C8AC)3-C6AC50-2A3(8-4A)8-2ABA8-AB60A12B12A-2(10A2-)10A3-8A4-C6AC38-2A2(8-4A)8-2ABA8-A2BA8-AB60A24B-2(10A2-)10A3-8A4-8A5-C4AC39-2A3(8-4A)8-2A2B8A2B12A36B24A-2(10A2-)10A3-8A4-8A5-C4AC39-2A3(8-4A)8-2A2B8A26B12A12B24A-2(10A2-)10A3-8A4-8A5-6A6-C4AC27-2(2A3(8-4A)8-2A2B8A50B24A-2(10A2-)10A3-8A4-8A5-6A6-6A7-C2AC16-)2A3(8-4A)8-2A2B8A26B12A12B24A-2(10A2-)10A3-8A4-8A5-6A6-C4AC27-2A3(8-4A)8-2A2B8A2B12A36B24A-2(10A2-)10A3-8A4-8A5-C4AC27-2A2(8-4A)8-2ABA8-A2BA8-AB60A24B-2(10A2-)10A3-8A4-8A5-C4AC27-2A3(8-4A)8-2ABA8-AB60A12B12A-2(10A2-)10A3-8A4-C6AC38-2A4(8-4A)8-86A-10A2(2-C8AC)3-C6AC50-2A4(8-4A)8-86A-C8AC85-2A4(8-4A)8-74A-C8AC97-2A4(8-4A)8-50A2-8A4-C6AC110-2A4(8-4A)8-38A-10A3-C6AC123-A8-A-2A3(8-4A)8-14A3-2(6A6-)C4AC136-A8-A-2A3(8-4A)8-14A3-6A6-C4AC149-2A5-2A3-2A5-2A-3A2(6-6A)6-3A-10A4-C4AC162-2A2-2A2(6-6A)4-10A4-6A7-C2AC175-2A2-2A2(6-6A)5-8A6-C2AC184-
