model
size = 26 32 31, scale = 0.05, origin = -y
material deform = 1, fade = true, lighting = smooth, roughness = 0.3, metalness = 0.6
  colors = A:#111 B:#EEE C:#AAA D:#DDD E:#555 F:#888
voxels
131-2A24-2A25-2A23-4A2(23-ABA)24-B648-A24-2A23-4A22-5A21-2A-3A21-C2-2A21-C5A21-C4A21-CAB2A22-AB2A23-BA594-A23-A2-A22-A3-A21-A4-A20-B4-2A2(20-B4-A)21-A3-2A20-CA2-2A21-C4A21-CAB2A22-CABA23-AB513-3A23-4A22-5A22-2(A-)A21-A4-A20-A4-A21-A3-A21-2(B4-A20-)B5-A20-A4-A20-2A2-2A21-C4A21-C2ABA22-CABA23-A2B486-2A24-4A22-5A22-3A-A21-A3-A21-A4-A20-A4-A21-A3-A21-B4-A20-B4-A21-B3-2A20-A3-2A20-3A-2A21-C4A22-CAB2A21-CAB2A22-AB2A24-B434-A2-A2(22-4A)23-4A22-2A2-A21-A4-A20-A4-A21-A3-A21-A2(4-A20-B)4-A21-B3-2A20-A4-A20-2A3-A21-C5A20-C5A21-CAB2A22-4A23-2A411-A22-4A22-5A22-4A22-2(2A2-A21-)A3-A21-A4-A21-A3-A21-A2(4-A20-B)4-3A18-B2(A4-3A18-)2A3-3A18-3A2-2A20-6A21-4A23-2A232-3B23-A2-A2(21-2A2-B)21-2A2-C21-2A3-D20-4A-A20-4A-B18-6A-A17-3A-A2B2-B16-3A-A2C2-C16-A-2A-AB2-C16-2A2(-A)3-C16-A3-2A2(-C)16-A4-3A2(2C16-A5-2A)2B16-A7-AB16-B7-2A17-B6-2A17-A6-2A17-2A4-2A19-A3-3A19-6A127-4A19-8A18-2A6B18-2A6C18-5A4B17-9A2(17-3A2BA3B)17-2A-2CA3C17-2A-2DCADC17-2A-6A18-A-6A18-4A2(BA)18-4A2B2A18-5AC2A16-6ABCACB15-6A2CA2B15-6A-CA2B15-2A2-A3-A2B2(15-A7-ABA)14-A8-2A15-A9-A2(15-A8-2A)16-A6-2A17-A6-2A18-2A2-3A21-4A47-7A19-7A18-8A17-4A2(-2A)16-2A6-AB16-2A7-C16-3(2A7-2A15-)2A4(7-2A16-A)8-A16-A8-A16-2A7-C17-A7-A2(17-A7-B)2(16-A8-A)15-2A8-2(A15-A9-)2A13-A10-2A13-A9-2(2A15-A8-)2A15-A7-2A17-2A4-2A20-5A44-2(10A16-)2A2-3A-2A16-A8-2A2(14-A10-A)6(15-A9-A)2(16-A8-A)16-A8-2A15-A8-AD15-A9-A2(15-A9-B)15-A9-A2(15-A9-C)4(14-A10-A)14-A9-2A14-A9-A16-A7-2A17-A5-2A19-A3-3A20-4A18-2A7-2A15-3A4-4A14-2A-7A-2(A14-A10-)D14-A10-F14-A10-D14-A10-2(E15-A9-)2A3(14-A10-A)15-A9-A15-A9-2A14-A9-AC14-A9-2A14-A9-AD2(14-A9-AB)14-A9-AE2(13-A11-C)2(13-A11-A)2(13-A10-2A)13-A10-A15-A8-2A16-A7-A18-A5-A20-5A16-2A8-2A14-A-A7-2A14-2A-A5-3A2(14-A10-A)F13-A10-AB13-A10-A2E12-A11-EF12-A11-FD3(13-A10-2A)13-A10-ACD12-A10-ADB12-A11-2A13-A10-AD13-A10-2A13-A10-AE12-A11-2B12-A11-AE2(12-A11-AB)12-A12-B12-A12-C2(12-A11-2A)12-A11-A14-A10-A15-A8-2A16-A6-2A18-A5-A19-A3-2A16-A9-2A14-2A7-3A13-3A7-4A12-A10-3A12-A11-AB12-A11-A2E11-A12-AF11-A12-AD11-A12-AF2(12-A11-2A)3(12-A)12-C12-A12-D3(12-A)12-C3(12-A)12-B2(12-A)E11-A12-AB11-A12-AE2(11-A12-AC)2(11-A12-2A)11-A12-B13-A11-B13-A10-AB14-A9-A16-A7-2A17-A5-2A23-2A15-A10-2A13-2A8-3A13-A-A7-A-2(A12-)2A11-A13-E2(11-A13-F11-A13-D)5(12-A)13-B11-A13-D11-A13-B11-A13-A11-A13-D11-A13-A11-A13-B11-A13-D11-A13-B4(11-A13-A)11-A13-2(B12-A12-)A13-A10-B15-A9-A15-2A7-A17-A6-2A23-2A14-2A10-A13-3A8-2A13-3A7-A2-4(A12-)E12-A12-D12-A12-F12-A13-D11-A13-F11-A13-B11-A13-A11-A13-D11-A13-C11-A13-D11-A13-A11-A13-C11-A13-A11-A13-D2(11-A13-B)11-A13-C11-A13-AC2(10-A13-2A)11-A12-AB11-A12-2(2A11-)B13-2A10-B14-A9-A16-A8-A17-A6-A24-A15-2A9-A14-2A8-2A14-A-A6-A2-2(A12-2A11-)E12-2A11-F12-A12-D12-A13-F11-A13-D11-A13-B11-A13-A11-A13-B11-A13-D11-A13-B3(12-A)12-D3(12-A)2(12-B12-A)2(13-B11-A)13-C2(11-A13-A)11-A13-B11-2A12-B12-2A11-B13-A10-A15-A9-A15-2A7-A17-A6-A23-2A16-A9-A15-2A7-2A14-A-2A5-A2-2(A13-A11-)E13-A11-D13-A11-F13-A11-D12-A12-F13-A12-B3(12-A)12-D12-A12-C12-A12-D3(12-A)12-C3(12-A)12-B3(12-A12-C)12-A13-2(A11-2A12-)3(A12-)2A12-B12-A11-A14-A10-A14-2A8-A16-2A7-A17-4A2-2A20-4A17-A8-A15-3A6-2A15-A-2A4-A-A15-A10-A13-A11-E2(13-A11-F13-A11-D)6(13-A11-A)13-2A10-A13-2A10-2A2(12-2A11-A)3(13-A11-A)13-2(A12-)2(2A11-)2A3(12-A)13-A11-A13-2A9-A15-2A8-A16-3A5-A18-7A21-2A19-A6-2A16-3A4-A-A15-2A-2A2(2-A)15-2A8-A15-A7(10-A13-2A)4(10-A14-A)10-4(A14-2A9-)3A12-2A10-3A11-2A10-3A12-A11-2A2(12-A)12-2A11-A13-A11-A13-2A10-A14-2A8-A16-2A7-A17-3A3-2A20-4A43-2A5-A18-8A18-A-4A-2A16-2A7-6(A15-2A8-)A15-3(2A9-A14-)2A9-A15-A9-A15-2A8-A2(15-2A7-2A)-A13-2A8-4A12-2A8-5A11-2A9-4A2(11-2A)12-A11-2A12-A11-D13-2A10-D14-A10-A14-2A9-A15-2A7-A17-3A5-A19-6A22-2A44-7A19-7A2(18-3A4-A)18-2A6-6(A16-2A7-)3(A16-3A6-)A17-3A4-2A2-2A13-2A-4A-A-4A12-2A5-7A12-2A4-8A12-2(2A-)5A-2A12-2A-2A3-A4-A12-2A-A-3A5-2(D12-3A10-)D13-2A9-A14-2A9-A15-2A7-A16-3A6-A17-3A5-A19-3A2-A21-4A70-2(5A21-)2A2-A21-2A2(3-A18-4A)3-2(A18-3A4-)2(2A17-4A3-)2A17-2(3A-)A18-3A3-2A18-8A4-A13-8A-2(5A13-6A2-)A-3A13-5A3-A2-2A13-4A3-A4-A13-4A3-A3-2(D14-7A4-)A14-7A4-A14-6A4-A15-3A-A4-AC15-4A5-C17-3A5-C18-3A3-2A19-3A-2A21-5A96-2(3A23-)2(4A22-)2(5A21-)5A20-6A3(21-5A)5-A16-3A5-3A21-6A20-3A-2(2A20-A3-)A21-A3-D20-A4-D20-2(A3-A21-)A2-A21-2A-AC20-2A2-AC18-2(3A-3A19-)3A-DA21-5A22-3A366-3A22-5A20-3A-2A20-A4-A20-2A3-A20-2A2-A21-A3-D21-A3-A21-A2(2-C21-2A)-C22-3AC22-ADA23-AD23-2AD23-AD24-A369-A23-4A21-5A20-2A3(3-A21-A)3-D21-A2-D22-A2-A21-3A2C21-3(ADA23-)AD470-A23-4A21-3A-4(A21-A3-)D21-2(A2-A22-)3AC22-ADA25-A519-2A24-3A21-3A-2(A21-A3-)A21-2A2(2-D22-A)-A2(23-DAC)23-DA570-4A22-A-2A2(22-A2-A)21-2A2-D22-DAD2(23-DAC)24-A622-A2-A22-3A23-2(4A22-)DAC24-AC726-2(2A24-)2A599-
