model
size = 23 24 32, scale = 0.05, origin = -y
material deform = 1, fade = true, lighting = smooth, roughness = 0.3, metalness = 0.6
  colors = A:#66BAB7 B:#FCFAF2 C:#FB9966 D:#B5495B E:#8A6BBE F:#00AA90 G:#A5A051 H:#0B1013
voxels
27-19(A2BAB2A6B2A8-)A2BAB2A6B2A222-13(A22-)A250-13(5A18-)5A246-13(9A14-)9A243-13(11A12-)11A242-13(11A12-)11A241-13(13A10-)13A240-13(13A10-)13A83-5H152-13(13A10-)13A15-2(3F20-)3F19-H3FH151-13(7A-7A8-)7A-7A14-2(F-F20-)F-F19-HF-FH151-13(15A8-)15A14-2(3F20-)3F19-H3FH151-13(15A8-)15A82-5H151-13(15A8-)15A100-19(6D3A6D8-)6D3A6D2(100-19(2A4C3A4C2A8-)2A4C3A4C2A)100-10(2A4C3A4C2A8-)2A4C3A4C2A4-G4(3-2A4C3A4C2A3-2G)3-2A4C3A4C2A3-G4-3(2A4C3A4C2A8-)2A4C3A4C2A100-10(2A4C3A4C2A8-)2A4C3A4C2A4-G3-2A4C3A4C2A3-G4E2(2A4C3A4C2A8E)2A4C3A4C2A4EG3-2A4C3A4C2A3-G4-3(2A4C3A4C2A8-)2A4C3A4C2A100-10(2A4C3A4C2A8-)2A4C3A4C2A4-G3-2A4C3A4C2A3-G4E2A4C3A4C2A4E23-4E2A4C3A4C2A4EG3-2A4C3A4C2A3-G4-3(2A4C3A4C2A8-)2A4C3A4C2A100-10(2A4C3A4C2A8-)2A4C3A4C2A4-G3-2A4C3A4C2A3-G4E2(2A4C3A4C2A8E)2A4C3A4C2A4EG3-2A4C3A4C2A3-G4-3(2A4C3A4C2A8-)2A4C3A4C2A100-10(2A4-3A4-2A8-)2A4-3A4-2A4-G4(3-2A4-3A4-2A3-2G)3-2A4-3A4-2A3-G4-3(2A4-3A4-2A8-)2A4-3A4-2A3(100-19(15A8-)15A)8(100-19(A2BAB2A6B2A8-)A2BAB2A6B2A)96-
