model
size = 20 12 10, scale = 0.05, origin = -y
material deform = 1, fade = true, lighting = smooth, roughness = 0.3, metalness = 0.6
  colors = A:#500 B:#100 C:#B00 D:#200 E:#FF9 F:#111 G:#AAA H:#400 I:#555
voxels
164-2E-E4-E-2E7-5E-2A-5E7-2E3-2A3-2E105-D16-D3(2-B16-B)-2B2(16-4B)16-2B2C16-2C23-D12-D5-DB12-BD4-2B12-2B3-D2B12-2BD3(2-A2B12-2BA)-2A2(2B12-2B4A)2C12-2C2A2C16-2C23-3D8-3D5-DA2B8-2BAD4-2A2B8-2B2A3-D2A2B8-2B2AD3(2-3A2B8-2B3A)-4A2B8-2B8A2C8-2C6A2C12-2C2A2C16-2C2(6-D)9-3DB6-B3D5-D3AB6-B3AD4-4AB6-B4A3-D4AB6-B4AD3(2-5AB6-B5A)-6AB6-B10A3C6-3C6A2C12-2C2A2C16-2C6-8D9-3DA6BA3D5-D4A6B4AD4-5A6B5A3-D5A6B5AD3(2-6A6B6A)-7A6B11A3C-4B-3C6A2C5-2B5-2C2A2C16-2C6-8D9-3D8A3D5-D14AD4-4A8F4A3-D3A10F3AD2-4A10F4A2-4A2F6A2F4A2(2-18A)2-3A3C-4A-3C3A2-3C5-2A5-3C27-8D10-2D8A2D7-4AGA2GAG4A6-2AGI-I2-I-IG2A5-2AG10-G2A4-2AG2-I-2I-I2-G2A4-H2AI-2G2A2G-I2AH4-H3AG6AG3AH4-H14AH4-5C-4A-5C11-2A56-6A12-10A9-2A8-2A7-2A10-2A6-AH10-HA6-HA2-6A2-AH6-H5A2H5AH6-H12AH6-4C-4A-4C12-2A153-2E-E4-E-2E7-6E2-6E5-6E4A6E5-4E-4A-4E7-2E3-2A3-2E24-
