model
size = 3 29 18, scale = 0.05, origin = -y
material deform = 1, fade = true, lighting = smooth, roughness = 0.3, metalness = 0.6
  colors = A:#EEE B:#6FC C:#E00 D:#FF0 E:#06F F:#9CF G:#3F6 H:#306 I:#636 J:#9F0 K:#F0C L:#F6C M:#F30 N:#C96 O:#C3C
voxels
55-3(B2-)C2-D2-E68-5(B2-)B65-2(B2-)2(J2-)3(C2-)N2(2-B)56-B3(2-J)2-C3(2-D)2-C2(2-N)2-B50-B3(2-J)2-C2-D3(2-E)2-D2-C2(2-N)2-B44-B3(2-J)2-C2-D2-E3(2-G)2-E2-D2-C2(2-N)2-B41-B2(2-J)2-C2-D2-E2-G3(2-H)2-G2-E2-D2-C2-N2-B38-B2(2-J)2-C2-D2-E2-G2-H3(2-M)2-H2-G2-E2-D2-C2(2-B)11(2-A)2-B2-J2-C2-D2-E2-G2-H2-M2-C3(2-M)2-H2-G2-E2-D2-C2-B-A11(F2A)FA-C2-D2-E2-G2-H2-M2-C2-D2-C2-M2-H2-G2-E2-D2-C2-L2-B-A11(F2A)FA-2(C2-D2-E2-G2-H2-)G2-E2-D2-C2-I2-L2-B11(2-A)2-B2-K2-C2-D2-E2-G2-H2-C2-D2-E2-G2-E2-D2-C2(2-I)2-L2-B35-B2-K2-O2-C2-D2-E2-G2-H2-C2-D2-E2-D2-C3(2-I)2-L2-B38-B2-K2-O2-C2-D2-E2-G2-H2-C2-D2-C3(2-I)2-L2-B41-B2(2-K)2-O2-C2-D2-E2-G2-H2-C4(2-I)2-L2-B44-B2(2-K)2-O2-C2-D2-E2-G2-H3(2-I)2-L2-B50-B2(2-K)2-O2-C2-D2-E2-G2-H2(2-L)2-B56-2(B2-)2(K2-)C2-D2-E2-G2-H2-B13-
