model
size = 32 32 15, scale = 0.05, origin = -y
material deform = 1, fade = true, lighting = smooth, roughness = 0.3, metalness = 0.6
  colors = A:#EEE B:#963 C:#888 D:#AAA E:#D00 F:#800
voxels
64A32-32AC2A9(2CA)2C64A2(32-96A)C2A9(2CA)2C320AD5(A2D)A3D4(A2D)192-32A32-32A64-3(32A32-)32A224-288A128-32A32-32A64-3(32A32-)32A160-384A96-10(2DA)2D32-32A64-3(32A32-)32A160-416A64-32A32-32A64-96A32-32A10(2CA)2C32A160-129A127BA31B128A64-32A32-32A416-129A63B96-32BA31B128A2(32-32A)416-128A32B160-32B128A32-96A416-2(128A32B160-32B128A544-)129A63B96-32BA31B128A576-129A127BA31B128A608-8(2CA)2C2A2C386A640-320A10(2DA)2D704-7AFAE28A5F2A2(3FA)3F232A800-10AE3AE2A3(EA)E14A5E3AE2A3(EA)E14AE7AE2A3(EA)E14A5E2A2E2A3EA3E15AEAE22A160-
