model
size = 16 27 32, scale = 0.05, origin = -y
material deform = 1, fade = true, lighting = smooth, roughness = 0.3, metalness = 0.6
  colors = A:#888 B:#0D0 C:#555 D:#B00 E:#00BC00 F:#08FF00 G:#444
voxels
37-4(6A10-)6A517-17A14-2(2A3(2-2B)2-)2A14-17A336-17A14C4(2A2C2B2C)2A14C17A336-35A3(2B6A)2B35A3(336-35A2B14A2B43A)7-2A14-EB14-BE14-BF14-2F14-EB14-BF231-35A2B14A2B43A6-4A12-E2BE12-F3B12-F2BE12-E2BF12-F3B12-E3B13-2B215-35A2B14A2B43A5-6A10-6B10-E4BE10-6B10-F4BF10-6B10-F4BE11-4B13-2B199-96A5-2A-3A10-EB-2BE10-2B-3B10-6B10-F5B10-E4BE10-6B11-4B13-2B199-96A6-4A12-E2BE12-3BF12-F3B12-3BE12-4B12-E2BE13-2B215-96A7-2A14-2B14-EB14-2F14-BE14-BF14-2B231-5(96A336-)66A12D4A12-2A336-66A12D4A12-2A325-6A5-66A12D4A12-2A309-6A10-6A5-66A12D18A293-2(6A10-)6A5-96A277-3(6A10-)6A6-14A-64A-14A262-5(6A10-)6A7-12A3-14A2-14A3-12A247-6(6A10-)2(2A2C2A10-)2A2C2A12-2G252-8(6A10-)2A2C2A10-2A2C2A11-4G251-9(6A10-)6A12-2G252-9(6A10-)6A266-9(6A10-)6A282-8(6A10-)6A298-7(6A10-)6A314-6(6A10-)6A325-
