model
size = 32, scale = 0.05, origin = -y
material deform = 1, fade = true, lighting = smooth, roughness = 0.3, metalness = 0.6
  colors = A:#111 B:#00E C:#0E0 D:#001
voxels
-1143A3B28AB3-B18A3B5AB5-B16AB3-B4AB2-D2-B15AB5-B3AB5-B15AB2-D2-B4AB3-B8A5B3AB5-B5A3B8A2B3-2B3AB3-B16A2B5-2B3A3B17A2(B7-B23A)B7-B6A5B12A2B5-2B5A2B3-2B12A2B3-2B5A2B5-2B12A5B6AB7-B23AB7-B2A3B18AB7-BAB3-B17A2B5-2BAB-D-B7A5B6A2B3-2B2AB3-B6A2B3-2B6A5B4A3B6A2B5-2B23AB7-B7A3B13AB7-B6AB3-B12AB7-B6AB-D-B12A2B5-2B6AB3-B13A2B3-2B8A3B15A5B119A2(30-2A)23-3B4-2A22-2(B3-)2A13-3B2(5-B)2-2A12-B3CB4-B2-D2-B2-2A11-B5CB3-B5-B2-2A11-B2C-2CB4-2(B3-)2A3-5B3-B5CB5-3B4-2A2-7B3-B3CB13-2A-2(3B3-)3B14-2A-2B5-2B20-2A-2B2-D2-2B20-2A-2B5-2B6-5B9-2A-3B3-3B5-7B8-2A2-7B5-3B3-3B7-2A3-5B6-2B5-2B7-2A14-2B2-D2-2B2-3B2-2A14-2B5-2B-B3CB-2A14-3B3-3B-BC-CB-2A4-5B6-7B2-B3CB-2A3-7B6-5B4-3B2-2A2-3B3-3B19-2A2-2B5-2B7-3B9-2A2-2B2-D2-2B6-B3CB8-2A2-2B5-2B6-BC-CB8-2A2-3B3-3B6-B3CB2-3B3-2A3-7B8-3B2-B3CB2-2A4-5B14-BCACB2-2A23-B3CB2-66A2(30-2A)23-3B4-2A22-B3CB3-2A13-3B5-B5CB2-2A12-5B4-B2C-2CB2-2A11-7B3-B5CB2-2A11-3B-3B4-B3CB3-2A3-5B3-7B5-3B4-2A2-7B3-5B13-2A-3B3C3B3-3B14-2A-2B5C2B20-2A-2B2CB2C2B20-2A-2B5C2B6-5B9-2A-3B3C3B5-7B8-2A2-7B5-3B3-3B7-2A3-5B6-2B5-2B7-2A14-2B2-D2-2B2-3B2-2A14-2B5-2B-5B-2A14-3B3-3B2(-2B)-2A4-5B6-7B2-5B-2A3-7B6-5B4-3B2-2A2-3B3C3B19-2A2-2B5C2B7-3B9-2A2-2B2C-2C2B6-5B8-2A2-2B5C2B6-2B-2B8-2A2-3B3C3B6-5B2-3B3-2A3-7B8-3B2-2BD2B2-2A4-5B14-2BADB2-2A23-5B2-66A2(30-2A)23-3B4-2A22-5B3-2A13-3B5-7B2-2A12-5B4-3B-3B2-2A11-7B3-7B2-2A11-7B4-5B3-2A3-5B3-7B5-3B4-2A2-7B3-5B13-2A-9B3-3B14-2A-9B20-2A2(-4B)20-2A-9B6-5B9-2A-9B5-7B8-2A2-7B5-3B3C3B7-2A3-5B6-2B5C2B7-2A14-2B2C-2C2B2-3B2-2A14-2B5C2B-5B-2A14-3B3C3B2(-2B)-2A4-5B6-7B2-5B-2A3-7B6-5B4-3B2-2A2-9B19-2A2-9B7-3B9-2A2-4B-4B6-5B8-2A2-9B6-2B-2B8-2A2-9B6-5B2-3B3-2A3-7B8-3B2-2BD2B2-2A4-5B14-2BADB2-2A23-5B2-66A2(30-2A)23-3B4-2A22-5B3-2A13-3B5-7B2-2A12-5B4-3B-3B2-2A11-7B3-7B2-2A11-7B4-5B3-2A3-5B3-7B5-3B4-2A2-7B3-5B13-2A-9B3-3B14-2A-9B20-2A2(-4B)20-2A-9B6-5B9-2A-9B5-7B8-2A2-7B5-9B7-2A3-5B6-9B7-2A14-4B-4B2-3B2-2A14-9B-5B-2A14-9B2(-2B)-2A4-5B6-7B2-5B-2A3-7B6-5B4-3B2-2A2-9B19-2A2-9B7-3B9-2A2-4B-4B6-5B8-2A2-9B6-2B-2B8-2A2-9B6-5B2-3B3-2A3-7B8-3B2-B3-B2-2A4-5B14-2(B-)B2-2A23-B3-B2-66A2(30-2A)23-3B4-2A22-5B3-2A13-3B5-7B2-2A12-5B4-3B-3B2-2A11-7B3-7B2-2A11-3B-3B4-5B3-2A3-5B3-7B5-3B4-2A2-7B3-5B13-2A-9B3-3B14-2A-9B20-2A2(-4B)20-2A-9B6-5B9-2A-9B5-7B8-2A2-7B5-9B7-2A3-5B6-9B7-2A14-4B-4B2-3B2-2A14-9B-5B-2A14-9B2(-2B)-2A4-5B6-7B2-5B-2A3-7B6-5B4-3B2-2A2-9B19-2A2-9B7-3B9-2A2-4B-4B6-5B8-2A2-9B6-2B-2B8-2A2-9B6-5B2-3B3-2A3-7B8-3B2-5B2-2A4-5B14-2B-2B2-2A23-5B2-66A2(30-2A)23-3B4-2A22-5B3-2A13-3B5-7B2-2A12-5B4-3B-3B2-2A11-7B3-7B2-2A11-7B4-5B3-2A3-5B3-7B5-3B4-2A2-7B3-5B13-2A-9B3-3B14-2A-9B20-2A2(-4B)20-2A-9B6-5B9-2A-9B5-7B8-2A2-7B5-9B7-2A3-5B6-9B7-2A14-4B-4B2-3B2-2A14-9B-5B-2A14-9B2(-2B)-2A4-5B6-7B2-5B-2A3-7B6-5B4-3B2-2A2-9B19-2A2-9B7-3B9-2A2-4B-4B6-5B8-2A2-9B6-2B-2B8-2A2-9B6-5B2-3B3-2A3-7B8-3B2-5B2-2A4-5B14-2B-2B2-2A23-5B2-66A2(30-2A)23-3B4-2A22-5B3-2A13-3B5-7B2-2A12-5B4-3B-3B2-2A11-7B3-7B2-2A11-7B4-5B3-2A3-5B3-7B5-3B4-2A2-7B3-5B13-2A-9B3-3B14-2A-9B20-2A2(-4B)20-2A-9B6-5B9-2A-9B5-7B8-2A2-7B5-9B7-2A3-5B6-9B7-2A14-4B-4B2-3B2-2A14-9B-5B-2A14-9B2(-2B)-2A4-5B6-7B2-5B-2A3-7B6-5B4-3B2-2A2-9B19-2A2-9B7-3B9-2A2-4B-4B6-5B8-2A2-9B6-2B-2B8-2A2-9B6-5B2-3B3-2A3-7B8-3B2-5B2-2A4-5B14-2B-2B2-2A23-5B2-66A2(30-2A)23-3B4-2A22-5B3-2A13-3B5-7B2-2A12-5B4-3B-3B2-2A11-7B3-7B2-2A11-3B-3B4-5B3-2A3-5B3-7B5-3B4-2A2-7B3-5B13-2A-9B3-3B14-2A-9B20-2A2(-4B)20-2A-9B6-5B9-2A-9B5-7B8-2A2-7B5-9B7-2A3-5B6-9B7-2A14-4B-4B2-3B2-2A14-9B-5B-2A14-9B2(-2B)-2A4-5B6-7B2-5B-2A3-7B6-5B4-3B2-2A2-9B19-2A2-9B7-3B9-2A2-4B-4B6-5B8-2A2-9B6-2B-2B8-2A2-9B6-5B2-3B3-2A3-7B8-3B2-5B2-2A4-5B14-2B-2B2-2A23-5B2-66A2(30-2A)23-3B4-2A22-5B3-2A13-3B5-7B2-2A12-5B4-3B-3B2-2A11-7B3-7B2-2A11-3B-3B4-5B3-2A3-5B3-7B5-3B4-2A2-7B3-5B13-2A-9B3-3B14-2A-9B20-2A2(-4B)20-2A-9B6-5B9-2A-9B5-7B8-2A2-7B5-9B7-2A3-5B6-9B7-2A14-4B-4B2-3B2-2A14-9B-5B-2A14-9B2(-2B)-2A4-5B6-7B2-5B-2A3-7B6-5B4-3B2-2A2-9B19-2A2-9B7-3B9-2A2-4B-4B6-5B8-2A2-9B6-2B-2B8-2A2-9B6-5B2-3B3-2A3-7B8-3B2-5B2-2A4-5B14-2B-2B2-2A23-5B2-66A2(30-2A)23-3B4-2A22-5B3-2A13-3B5-7B2-2A12-5B4-3B-3B2-2A11-7B3-7B2-2A11-3B-3B4-5B3-2A3-5B3-7B5-3B4-2A2-7B3-5B13-2A-9B3-3B14-2A-9B20-2A2(-4B)20-2A-9B6-5B9-2A-9B5-7B8-2A2-7B5-9B7-2A3-5B6-9B7-2A14-4B-4B2-3B2-2A14-9B-5B-2A14-9B2(-2B)-2A4-5B6-7B2-5B-2A3-7B6-5B4-3B2-2A2-9B19-2A2-9B7-3B9-2A2-4B-4B6-5B8-2A2-9B6-2B-2B8-2A2-9B6-5B8-2A3-7B8-3B9-2A4-5B21-2A20(30-66A29(30-2A))30-33A
