model
size = 28 26 28, scale = 0.05, origin = -y
material deform = 1, fade = true, lighting = smooth, roughness = 0.3, metalness = 0.6
  colors = A:#111 B:#222 C:#444 D:#555 E:#777 F:#888 G:#AAA H:#FCFAF2 I:#BBB J:#DDD K:#EEE L:#FFFFFB M:#BDC0BA
voxels
30-A22-A676-A22-A703-3A20-3A3-B22-B4-C22-C647-3A3-2(2A4-)2A3-3A2-3B3-B12-B3-3B2-3C3-C12-C3-3C3-D22-D4-E22-E591-3A3-3A2-4A2-3A3-3A2-3B3-2B4-AB4-2B3-3B2-3C3-2C4-AB4-2C3-3C2-3D3-D12-D3-3D2-3E20-3E3-F22-F563-4A2-2(4A-)4A2-4A3-2B4-2B2-BA2B2-2(2B4-)2C4-2C2-BABC2-2C4-2C5-2(D4-)AB2(4-D)6-E9-AB9-E6-F20-F6-G20-G537-4A3-10A3-4A4-3B4-4BA5B4-3B2(4-3C)BAB4C4-3C4-2D5-2D-BABC-2D5-2D4-2E5-ED-BABC-2(2E5-)F6-D2-AB2-E6-F6-G6-D2-AB2-E6-G535-28A-6B-5BA6B-6B2-6C-4CBAB5C-6C3-4D3-2DCBABC3D3-4D4-4E3-EDCBABCD2E3-4E4-2F-F3-EDCBABCDEF3-F-2F4-2G-G3-EDCBABCDEF3-G-2G5-I8-BABC8-I15-BABC488-5A18-5A-12BA13B2-11CBAB12C2-6D-3DCBABC4D-6D2-6E-FEDCBABCD3E-6E4-3F3-EDCBABCDEF3-3F6-3G3-EDCBABCDEF3-3G7-2I4-DCBABCDE4-2I14-DCBABCDE21-CB2-CD22-CB2-CH434-2A18-2A7-2B16-2B8-8CBAB9C9-D-4DCBABC5D-D10-E-EFEDCBABCD4E-E10-F2-FEDCBABCDE2F2-F10-G2-FEDCBABCDEFG2-G10-I3-EDCBABCDEF3-I14-EDCBABCDEJ19-DCBABCDK20-HCBABC2H23-AB26-AM26-2A352-2A18-2A7-2B16-2B8-3C14-3C8-3D14-3D8-3E14-3E9-F-2FEDCBABCDE3F-F10-G-GFEDCBABCDEF2G-G10-I2-FEDCBABCDEFG2-I13-JEDCBABCDE2J17-KDCBABCD2K18-2HCBABC3H20-LBAB2L22-2MA3M22-6A24-AB26-AB294-4A18-4A3-4B16-4B4-5C14-5C4-5D14-5D4-5E14-5E5-5F12-5F6-5G12-5G7-3I-FEDCBABCDEFG-3I10-J-JEDCBABCDE2J-J14-2KDCBABCD3K16-3HCBABC4H18-2LBAB3L20-3MA4M20-8A22-BABC24-BABC25-2(AB26-)AG25-2F25-2E156-4A18-4A3-4B16-4B4-5C14-5C5-4D14-4D6-4E14-4E7-2F-F12-F-2F8-2G-G12-G-2G11-IFEDCBABCDEFGI14-2JEDCBABCDE3J16-KDCBABCD2K18-2HCBABC3H18-3LBAB4L18-10C18-10A20-CBABCD22-CBABCD23-BABC24-BABI24-GA2G23-4F23-4E25-2D130-2A18-2A7-2B16-2B8-3C14-3C9-2D14-2D10-2E14-2E11-2(2F12-)2G12-2G14-FEDCBABCDEFG16-JEDCBABCDE2J16-2KDCBABCD3K16-3HCBABC4H17-2(10B18-)10A20-EBABCE22-CBABCD22-CBABCJ22-IBAB2I22-2GA3G21-6F21-6E23-4D25-2C103-A18-A9-B16-B10-2C14-2C11-D14-D12-E14-E13-F12-F14-G12-G14-IFEDCBABCDEFGI14-2JEDCBABCDE3J16-KDCBABCD2K4(18-10A)19-2EBABCDE20-DCBABCDK21-CBABCJ22-IBAB2I22-2GA3G21-6F21-6E22-5D23-5C23-3B25-2A26-A22-A18-A9-B16-B10-2C14-2C11-D14-D12-E14-E13-F12-F14-G12-G14-IFEDCBABCDEFGI14-2JEDCBABCDE3J16-KDCBABCD2K18-2HCBABC3H2(18-10B)18-10A19-2EBABCDE20-DCBABCDK21-CBABCJ22-IBAB2I22-2GA3G21-6F21-6E22-5D24-4C24-2B75-2A18-2A7-2B16-2B8-3C14-3C9-2D14-2D10-2E14-2E11-2(2F12-)2G12-2G14-FEDCBABCDEFG16-JEDCBABCDE2J16-2KDCBABCD3K16-3HCBABC4H17-3LBAB4L18-10C18-10A20-EBABCE22-CBABCD22-CBABCJ22-IBAB2I22-2GA3G21-6F21-6E23-4D25-2C100-4A18-4A3-4B16-4B4-5C14-5C5-4D14-4D6-4E14-4E7-2F-F12-F-2F8-2G-G12-G-2G11-IFEDCBABCDEFGI14-2JEDCBABCDE3J16-KDCBABCD2K18-2HCBABC3H18-3LBAB4L18-4MA5M18-10A20-EBABCD22-CBABCD23-BABC24-BABI24-GA2G23-4F23-4E25-2D128-4A18-4A3-4B16-4B4-5C14-5C4-5D14-5D4-5E14-5E5-5F12-5F6-5G12-5G7-3I-FEDCBABCDEFG-3I10-J-JEDCBABCDE2J-J14-2KDCBABCD3K16-3HCBABC4H18-2LBAB3L20-3MA4M20-8A22-BABC24-BABC25-2(AB26-)AG25-2F25-2E158-2A18-2A7-2B16-2B8-3C14-3C8-3D14-3D8-3E14-3E9-F-2FEDCBABCDE3F-F10-G-GFEDCBABCDEF2G-G10-I2-FEDCBABCDEFG2-I13-JEDCBABCDE2J17-KDCBABCD2K18-2HCBABC3H20-LBAB2L22-2MA3M22-6A24-AB26-AB296-2A18-2A7-2B16-2B8-8CBAB9C9-D-4DCBABC5D-D10-E-EFEDCBABCD4E-E10-F2-FEDCBABCDE2F2-F10-G2-FEDCBABCDEFG2-G10-I3-EDCBABCDEF3-I14-EDCBABCDEJ19-DCBABCDK20-HCBABC2H23-AB26-AM26-2A349-5A18-5A-12BA13B2-11CBAB12C2-6D-3DCBABC4D-6D2-6E-FEDCBABCD3E-6E4-3F3-EDCBABCDEF3-3F6-3G3-EDCBABCDEF3-3G7-2I4-DCBABCDE4-2I14-DCBABCDE21-CB2-CD22-CB2-CH431-28A-6B-5BA6B-6B2-6C-4CBAB5C-6C3-4D3-2DCBABC3D3-4D4-4E3-EDCBABCD2E3-4E4-2F-F3-EDCBABCDEF3-F-2F4-2G-G3-EDCBABCDEF3-G-2G5-I8-BABC8-I15-BABC490-4A3-10A3-4A4-3B4-4BA5B4-3B2(4-3C)BAB4C4-3C4-2D5-2D-BABC-2D5-2D4-2E5-ED-BABC-2(2E5-)F6-D2-AB2-E6-F6-G6-D2-AB2-E6-G536-4A2-2(4A-)4A2-4A3-2B4-2B2-BA2B2-2(2B4-)2C4-2C2-BABC2-2C4-2C5-2(D4-)AB2(4-D)6-E9-AB9-E6-F20-F6-G20-G536-3A3-3A2-4A2-3A3-3A2-3B3-2B4-AB4-2B3-3B2-3C3-2C4-AB4-2C3-3C2-3D3-D12-D3-3D2-3E20-3E3-F22-F563-3A3-2(2A4-)2A3-3A2-3B3-B12-B3-3B2-3C3-C12-C3-3C3-D22-D4-E22-E591-3A20-3A3-B22-B4-C22-C646-
