model
size = 32 19 13, scale = 0.05, origin = -y
material deform = 1, fade = true, lighting = smooth, roughness = 0.3, metalness = 0.6
  colors = A:#444 B:#111 C:#3FF D:#F0C E:#0F6 F:#EEE G:#FF3 H:#90F I:#222 J:#6FF K:#9FF L:#0F3 M:#E00
voxels
3-D-D29-2(D-)23A3-A2(-D)-24A-2A3(-D25-5A)-D5(25-7A)25-3A-10ABA5BAB11A3-9ABAB3DBAB10A13-BAB3DBAB24-AB3DBA25-A5BA25-2ABAB2A27-B-B18-D-D28-2(BD)B15A4(HA)3-3(AB)24A-A2B30A2(2B2A23-5A)2B2A4(23-9A)23-36A-30A3-12A3D13A13-B2A3D2AB24-2A3D2A2(25-7A)27-B-B18-D-D28-2(BD)B15A2(H3A)3-2B28A-2B30A7(2B3A23-4A)2B30A-B29A3-9B3A3D13A13-B2A3D2AB24-2A3D2A2(25-7A)27-B-B18-D-D28-2(BD)B14A2(HA)3H2A3-AB28A-37A6(23-9A)23-36A-30A3-12A3D13A2G11-B2A3D2AB24-2A3D2A2(25-7A)27-B-B18-D-D28-2(BD)B23A3-2B28A-3B29A7(3B2A23-4A)3B29A-2B28A3-9B3A3D13A2G11-B2A3D2AB9-3B12-2A3D2A10-3G12-7A25-7A27-B-B18-D-D28-2(BD)B23A3-AB28A-37A6(23-9A)23-36A-30A3-12A3D13A2G11-B2A3D2AB3-M-L-K-3B12-2A3D2A10-3G12-7A25-7A27-B-B18-D-D28-2(BD)B23A3-2B28A-3B29A7(3B2A23-4A)3B29A-2B28A3-9B3A3D13A2G11-B2A3D2AB3-M-L-K-3B12-2A3D2A10-3G12-7A25-7A27-B-B18-D-D28-2(BD)B23A3-AB28A-37A6(10-2A11-9A)10-2A11-36A-30A3-12A3D13A2G11-B2A3D2AB24-2A3D2A2(25-7A)27-B-B18-D-D28-2(BD)B23A3-AB28A-4A8(25C7A)25C3A-30A3-12A3D13A13-B2A3D2AB24-2A3D2A2(25-7A)27-B-B18-D-D28-2(BD)B23A3-3(2B3AB24A2-)6B24A7(2-30A)3-12A3D13A13-B2A3D2AB24-2A3D2A2(25-7A)27-B-B18-D-D29-2(D-)23A4-4G-A18E4A4-4G-AEF2EF4EF3E3FEF4A4-4J-A3(EF)4EF2EF4E4A9-A4EF4E2F3EF3E4A4-6A3(EF)2EFEF4EF2E4A4-6AEF2EF4EF3E2F3E4A4-6A18E4A4-28A4-9A9B2(10A4-9AB7AB)10A13-B2A3D2AB23-B2A3D2AB24-2A3D2A2(25-7A)27-B-B120-F2-F4-F3-3F-F8-4J3-2(F-)F4-F2-F22-F4-2F3-F2-3B13-2(F-)F2-F-F4-FB3GB12-F2-F4-F3-2FB5GB25-B2GA2GB4-3D18-B5GB3-D3BD18-B3GB4-D3BD6-7A6-3B5-D3BD6-A5BA15-3D7-3(AB3DBA25-)A5BA25-2ABAB2A27-B-B264-2(3I29-)3I7-F30-F-F30-F9-5B3(27-B3-B)27-5B78-
