model
size = 17 27 10, scale = 0.05, origin = -y
material deform = 1, fade = true, lighting = smooth, roughness = 0.3, metalness = 0.6
  colors = A:#272727 B:#343434 C:#414141 D:#EEA9A9 E:#E83015
voxels
22-9A8-8A9-4A14-4A12-6A11-2(7A10-)6A12-4A14-2A209-B75-9A8-8A9-4A14-4A12-6A11-2(7A10-)6A12-4A14-2A209-B91-10A7-9A8-6A12-6A10-8A9-2(9A8-)8A10-6A12-4A14-2A176-C16-B12-2(A16-)A43-6A2-4A5-6A2-3A6-6A2-2A7-7A-2A4(7-10A)4(8-9A)9-9A9-2(8A10-)6A11-3A2(14-4A)13-5A12-6AC10-6AB10-5A12-AB2(16-A)26-6A2-4A5-6A2-3A6-6A2-2A7-7A-2A7(7-10A)2(8-10A8-9A)9-8A9-2(6A11-)2(7A11-7A10-)3AE13-5A12-3A15-2A15-A5-2(10A7-)2A-7A7-2A-8A6-5(2A-9A5-)2A2-9A4-2A2-10A3-2A2-11A2-2A3-11A-2A4-10A-3A4-8AB-4A4-8A2-3ABA2-7A4-2ABA2-6A11-7A10-6AD2A9-5AD11-8A10-6AB11-4A53-2(10A7-)2A-7A7-2A-8A6-5(2A-9A5-)2A2-9A4-2A2-10A3-2A2-11A2-2A3-11A-2A4-10A-3A4-8AB-4A4-8A2-3ABA2-7A4-2ABA2-6A11-7A10-6AD2A9-5AD11-8A10-6AB11-4A57-6A2-4A5-6A2-3A6-6A2-2A7-7A-2A7(7-10A)2(8-10A8-9A)9-8A9-2(6A11-)2(7A11-7A10-)3AE13-5A12-3A15-2A15-A9-6A2-4A5-6A2-3A6-6A2-2A7-7A-2A4(7-10A)4(8-9A)9-9A9-2(8A10-)6A11-3A2(14-4A)13-5A12-6AC10-6AB10-5A12-AB2(16-A)26-10A7-9A8-6A12-6A10-8A9-2(9A8-)8A10-6A12-4A14-2A176-C16-B12-2(A16-)A39-
