model
size = 19 24 10, scale = 0.05, origin = -y
material deform = 1, fade = true, lighting = smooth, roughness = 0.3, metalness = 0.6
  colors = A:#5B4230 B:#8F5A3C C:#E87A90 D:#F9BF45 E:#111
voxels
25-9A10-8A11-4A16-4A14-6A13-2(7A12-)6A14-4A16-2A262-9A10-8A11-4A16-4A14-6A13-2(7A12-)6A14-4A16-2A280-10A9-9A10-6A13-7A12-3(8A11-)8A13-5A14-4A173-A4(17-2A)29-6A2-4A7-6A2-3A8-6A2-2A9-7A-2A4(9-10A)4(10-9A)2(11-9A)11-8A12-6A34-A17-2A17-2(6A13-)5A15-3A17-2A8-7A2-4A6-7A2-3A7-7A2-2A8-8A-2A2(8-11A)5(9-10A)10-10A9-11A9-9AB10-8AB10-9A11-6A13-7A12-7AC12-5A2C12-8A12-6A13-3AD16-2(4A4-10A8-11A8-2A2-7A12-8A11-9A10-9A3(11-8A)11-9A2(10-10A)9-10A2(B9-9A)B10-8AB10-7A12-8A12-6AC2A10-5AC14-9A10-8AE11-5A15-)4A7-7A2-4A6-7A2-3A7-7A2-2A8-8A-2A2(8-11A)5(9-10A)10-10A9-11A9-9AB10-8AB10-9A11-6A13-7A12-8A12-5ACA12-8A12-6A13-3AD16-4A8-6A2-4A7-6A2-3A8-6A2-2A9-7A-2A4(9-10A)4(10-9A)2(11-9A)11-8A12-6A34-A17-2A17-2(6A13-)5A15-3A17-2A9-10A9-9A10-6A13-7A12-3(8A11-)8A13-5A14-4A173-A4(17-2A)24-
