model
size = 31 13 12, scale = 0.05, origin = -y
material deform = 1, fade = true, lighting = smooth, roughness = 0.3, metalness = 0.6
  colors = A:#FFF B:#000 C:#BDBDBD D:#DEDEDE E:#838383 F:#CDCDCD G:#414141 H:#F6F6F6 I:#E6E6E6 J:#A4A4A4 K:#9C9C9C
voxels
33-2(9A8-9A5-)9A8-3C11-9C270-2(9A8-9A5-)9A8-3C11-9C300-3A2(D2A)D8A2(D2A)D3A3-A9-8A9-A3-A9-8A3-7C3-A8-A8C6AF2AI3-7A2B9-5AF3A5-6A12-4AFA7-5A13-3AF9-EAE16-A11-2B151-3A9(D2A)-A28-A-A28-C2-A15-2C9-A3-A8-2(AC2B)A9-A3-A6-3(C2BA)6-2A4-A5-2A2(C2BA)C2B3-3A6-B3-3B2A2(C2BA)C2B-A10-B-3BA3-2(C2BA)CBA11-2BGKA5-2(C2BA)14-GA8-C2A77-10(2AD)2(2A29-)CA28-A-A28-A2-A25-2A3-G10-A11-3A5-B21-E8-B19-2E10-B16-2E12-B11-3A2E15-GA10-AE45-A9(D2A)D3A29-2A29-CA29-IA28-F-A27-AF2-B22-E3A4-B21-A8-H20-A10-B17-2A11-H15-BA14-B12-BA17-A9-KA15-10(2AD)2(2A29-)CA29-2A28-A-A27-FA2-B22-FI2F4-H21-A8-B20-J10-B17-JA11-B15-AB14-B12-AB17-A9-AB15-3A8(D2A)D4A29-2A29-CA29-2A28-A-A27-FA2-B22-FI2F4-H21-A8-B20-J10-B17-JA11-B15-AB14-B12-AB17-A9-AB15-A9(D2A)D3A29-2A29-CA29-IA28-F-A27-AF2-B22-E3A4-B21-A8-H20-A10-B17-2A11-H15-BA14-B12-BA17-A9-KA15-3A8(D2A)D4A29-2A29-CA28-A-A28-A2-A25-2A3-G10-A11-3A5-B21-E8-B19-2E10-B16-2E12-B11-3A2E15-GA10-AE45-9(2AD)3A-A28-A-A28-C2-A15-2C9-A3-A8-2(AC2B)A9-A3-A6-3(C2BA)6-2A4-A5-2A2(C2BA)C2B3-3A6-B3-3B2A2(C2BA)C2B-A10-B-3BA3-2(C2BA)CBA11-2BGKA5-2(C2BA)14-GA8-C2A78-3AD2AD11A2(D2A)D3A3-A9-8A9-A3-A9-8A3-7C3-A8-A8C6AF2AI3-7A2B9-5AF3A5-6A12-4AFA7-5A13-3AF9-EAE16-A11-2B151-
