model
size = 28 11 24, scale = 0.05, origin = -y
material deform = 1, fade = true, lighting = smooth, roughness = 0.3, metalness = 0.6
  colors = A:#111 B:#96F C:#96C D:#C6F E:#36F F:#66F G:#F9F H:#008 I:#00C J:#60F K:#93F L:#30C M:#444 N:#555 O:#00A P:#009 Q:#66C R:#63F S:#309 T:#03F U:#00B V:#C9F W:#99F X:#90C Y:#93C
voxels
4-7A8-7A5-Q5C9-Q5C6-BC4B2C8-C4B2C2(4-2CHORJ3ECB)2-CBH2IJ2FECB4-CBH2IJ2FECB2-CDS2IJ2FE2B4-CDS2IJ2FE2B-ABDGPTUKFV2BN2-NBDGPTUKFV2B2ABDGHLOK2D2B-2N-BDGHLOK2D2BAMCBDGHPLKD2BA2-ACBDGHPLKD2BMA2CW2GLXYDCBA2-A2CW2GLXYDCBA-2AC2B2DBC2A4-2AC2B2DBC2A113-A26-2A2(26-A308-A)19(26-A280-A)26-A280-M26-M84-
