model
size = 22 31 22, scale = 0.05, origin = -y
material deform = 1, fade = true, lighting = smooth, roughness = 0.3, metalness = 0.6
  colors = A:#111 B:#03F C:#96C D:#96F E:#333 F:#C6F G:#F9F H:#36F I:#30C J:#00A K:#008 L:#66F M:#60F N:#C9F O:#93F P:#00C Q:#66C R:#F6F S:#93C T:#99F U:#009 V:#33C W:#C6C X:#90C Y:#00B Z:#639 Aa:#00D Ab:#309 Ac:#63F Ad:#555
voxels
23-20B2-20A2-5AQ8CQ4AB2-4A3C2DO3D3C4A2-3AQC2DJIMVLH2DCQ2AB2-2A2CSK2JAc2MV4H2C2A2-2A2CRKJ2PIM2L3HDC2A2-BACDGKJ2PI2M2L2HDC2A2-2ACFGAbJ2PB2M3L2HDAB2-2ADF2GKIAaBIMDL2N2D2A2-2ADF2GZU2BYJO2L2ND2A2-BAD2F2GKIBIJOFD2ND2A2-2AD2F2GK2I2JO3FNDAB2-2ACD2F2GKJUJIO3FD2A2-2ACDTF2G4KIO2FDC2A2-BA2CHTF3G2IXS2FDC2A2-3AC3D5GRFGFC2AB2-4A2C3D2FWFD2C4A2-5A3C4D3C5A2(2-20A)2-8A4B8A2-7AB4-B7A2-3(BA)B6-3(BA)B3-2(BA)B8-2(BA)B4-2(BA)B8-2(BA)B343-A20-3A406-20B2-7EAd4AAd6EA2-5EQ8CQ4EA2-4E3C3DO2D3C3EA2-3EQC2DHLVMIJ2DCQ2EA2-2E2C4HV2MAc2JKS2CEB2-EACD3H2LMI2PJKR2C2A2-BACD2H2L2MI2PJKGDC2A2-2AD2H3L2MB2PJAbGFC2A2-2A2D2NLDMIBAaIK2GFDAB2-2AD2N2LOJY2BUZ2GFD2A2-BAD2NDFOJIBIK2G2FD2A2-2ADN3FO2J2IK2G2FD2A2-2AD3FOIJUJK2G2FDCAB2-EACD2FOI4K2GFTDC2A2-BACD2FSX2I3GFTH2C2A2-2EACFGFR5G3DCAEA2-3EA2CDFW2F3D2CA2EB2-4EA3C4D3CA3EA2-5E10A4EA2-3AB12AB3A2-4AB10AB4A2-5AB8AB5A2-B5ABA4BAB5AB3-2(B5AB4-)2(BA)2B6-2B2(AB)112-B20-BA2(20-2A)4(20-AB20-2A20-BA20-2A)2(20-2A)20-AB20-B68-2(BA)B8-2(BA)B90-B20-BA20-2A20-AB20-2A20-2B4(20-2A20-BA20-2A20-AB)20-A21-B90-2(BA)B8-B-BAB68-B20-BA20-AB2(20-2A20-2B)3(20-2A20-BA20-2A20-AB)20-2A20-2B20-A21-B134-2(BA)B8-2(BA)B46-B20-2B2(20-2A20-BA20-AB)3(20-2A20-BA20-2A20-AB)20-A21-B178-2(BA)B8-2(BA)B24-B2(20-BA)3(20-2A20-AB20-2A20-BA)20-2A20-AB20-2A20-2B20-A21-B200-2(BA)B8-2(BA)B24-B20-BA2(20-2A)20-AB3(20-BA)2(20-2A20-AB20-2A20-BA)20-2A20-AB20-A21-B244-2(BA)B8-2(BA)B2-B20-BA2(20-2A)20-2B20-AB2(20-BA20-2A)20-AB20-2A20-BA20-2A20-AB20-2A20-2B20-A21-B266-2(BA)B8-2(BA)B2-B20-BA20-2A20-BA20-AB20-2A20-2B2(20-2A)20-BA20-2A20-AB20-2A20-BA20-2A20-AB20-A21-B288-2(BA)B8-2(BA)B2-B2(20-BA)20-2A20-AB20-2A20-BA20-AB2(20-2A)20-BA20-2A20-AB20-2A20-2B20-A21-B310-2(BA)B8-2(BA)B2-B14(20-2B)20-B21-B310-2(BA)B8-2(BA)B2-B2(20-BA)20-2A20-AB20-2A20-BA20-AB2(20-2A)20-BA20-2A20-AB20-2A20-2B20-A21-B310-2(BA)B8-2(BA)B2-B20-BA20-2A20-BA20-AB20-2A20-2B2(20-2A)20-BA20-2A20-AB20-2A20-BA20-2A20-AB20-A21-B288-2(BA)B8-2(BA)B2-B20-BA2(20-2A)20-2B20-AB2(20-BA20-2A)20-AB20-2A20-BA20-2A20-AB20-2A20-2B20-A21-B266-2(BA)B8-2(BA)B2-B20-BA2(20-2A)20-AB3(20-BA)2(20-2A20-AB20-2A20-BA)20-2A20-AB20-A21-B244-2(BA)B8-2(BA)B2-B2(20-BA)3(20-2A20-AB20-2A20-BA)20-2A20-AB20-2A20-2B20-A21-B200-2(BA)B8-2(BA)B24-B20-2B2(20-2A20-BA20-AB)3(20-2A20-BA20-2A20-AB)20-A21-B178-2(BA)B8-2(BA)B24-B20-BA20-AB2(20-2A20-2B)3(20-2A20-BA20-2A20-AB)20-2A20-2B20-A21-B134-2(BA)B8-2(BA)B46-B20-BA20-2A20-AB20-2A20-2B4(20-2A20-BA20-2A20-AB)20-A21-B90-2(BA)B8-2(BA)B68-B20-BA2(20-2A)4(20-AB20-2A20-BA20-2A)2(20-2A)20-AB20-B68-2(BA)B8-2(BA)B90-
