model
size = 5 32 3, scale = 0.05, origin = -y
material deform = 1, fade = true, lighting = smooth, roughness = 0.3, metalness = 0.6
  colors = A:#444 B:#555 C:#222
voxels
2-A158-3A3-12(A4-)4(C4-)4(A4-)4(B4-)B3-3B-5B-3B2-3B3-2(B4-)A157-
