model
size = 7, scale = 0.05, origin = -y
material deform = 1, fade = true, lighting = smooth, roughness = 0.3, metalness = 0.6
  colors = A:#D9AB42 B:#111
voxels
8A2(B15A)B9A2(BA)2(B7A)B19AB83AB17AB53A2(BA)2(B7A)B19AB15AB3AB23AB3AB8A
