model
size = 23 26 14, scale = 0.05, origin = -y
material deform = 1, fade = true, lighting = smooth, roughness = 0.3, metalness = 0.6
  colors = A:#FF797A B:#91989F C:#86C166 D:#FFFFFB E:#222 F:#FFF G:#DDD H:#F4A7B9 I:#64363C J:#A35E47 K:#C73E3A L:#9E7A7A M:#CC543A N:#F596AA O:#884C3A P:#CB4042 Q:#C46243 R:#CB1B45 S:#904840 T:#8E354A U:#9A5034 V:#D7C4BB W:#787D7B X:#F19483 Y:#F8C3CD Z:#EEA9A9 Aa:#9F353A Ab:#D0104C Ac:#DB4D6D Ad:#FEDFE1 Ae:#724832 Af:#B54434 Ag:#A96360 Ah:#E16B8C Ai:#AB3B3A Aj:#B19693 Ak:#854836 Al:#BF6766 Am:#734338 An:#EB7A77 Ao:#F75C2F Ap:#954A45 Aq:#B5495B Ar:#E87A90 As:#DC9FB4 At:#D05A6E Au:#86473F Av:#B55D4C Aw:#B9887D Ax:#6A4028 Ay:#E83015 Az:#554236 Ba:#D75455 Bb:#994639
voxels
57-2A20-4A18-6A16-8A14-10A9-D3-10A3-D6-16A9-12A12-5(10A13-)10A12-2(12A11-)2A2E4A2E2A11-AE2GE2AE2GEA11-2A2E4A2E2A11-12A13-8A16-6A65-2A21-2A20-4A19-4A18-6A16-8A13-3A6-3A10-14A11-12(A8-A13-)10A14-8A110-2A20-3A20-4A19-4A18-6A16-8A10-6A6-6A5-5A8B5A6-3AB8-B3A9-11(AB8-BA11-)2A8B2A11-12A12-2A6-2A14-8A64-2A20-4A18-6A17-6A34-5A8-7A-22A2-6A8B6A4-4AB8-B4A6-3AB8-B2A9-2AB8-BA10-9(2AB8-B2A9-)3A8B3A10-2A8B2A11-2AB6-B2A12-2A6B2A15-6A145-9A8-14AB8-B6A-6AB8-B5A4-2A2-B8-B2-2A6-3AB8-B3A8-2(2AB8-B2A9-)7(2AB8-B2AD7-D)2AB8-B2AD8-2AB8-B2A9-2AB8-B2A10-ABAj6-YBA12-3AAcFAjXAfLA14-8A17-4A100-3A20-5A17-6A3CB8-5C2A-3A3CB8-B5A4-AC2-B8-B2-2A6-A2CB8-B3A7-A2CB8-B2A9-2A9(B8-B3A7-3A)B8-B3A8-2AB8-B2A10-ABAcOKFAkAaVAwBA12-10A14-8A16-6A76-2A21-3A20-5A17-6A3CB8-5C2A-3A3CB8-B5A4-DC2-B8-B2-AD6-A2CB8-B3A7-A2CB8-B2A9-2A3(B8-B3A7-3A)B8-B3A7-2A-B8-B-2A5(7-3AB8-B3A)8-2AB8-B2A10-ABTQAuAoKLJIBA12-10A14-8A16-6A53-2(2A21-)3A20-5A17-6A3CB8-5C2A-3A3CB8-B5A4-AC2-B8-B2-2A6-A2CB8-B3A7-A2CB8-B2A9-2AB8-B3A7-4(3AB8-B3A8-DAB8-BAD8-)3AB8-B3A8-2AB8-B2A10-ABPHAmTZAfAdAaBA12-10A14-8A16-6A53-2(2A21-)3A20-5A17-6A3CB8-5C2A-3A3CB8-B5A4-AC2-B8-B2-2A6-A2CB8-B3A7-A2CB8-B2A9-2A9(B8-B3A7-3A)B8-B3A8-2AB8-B2A10-ABVTAbPApAsAgJBA12-10A14-8A16-6A76-2A21-3A20-5A17-6A3CB8-5C2A-3A3CB8-B5A4-DC2-B8-B2-AD6-A2CB8-B3A7-A2C2(B8-B2A9-2A)B7-2(B4A7-4AB6-)B4A7-2A-AB6-BA-2A8-2(3AB6-B3A9-)A-A3(B6-B3A9-3A)B6-B3A10-2ANAqLVAlAnAW2A12-10A14-8A16-6A99-3A20-5A17-6A3CB8-5C2A-3A3CB8-B5A4-DC2-B8-B2-AD6-A2CB8-B3A7-A2C2(B8-B2A9-2A)B7-3(B3A9-3AB6-)2(B3A12-B6-B12-3AB6-)2(B3A9-3AB6-)B3A10-2AWOAkBbKHAcW2A12-10A14-8A16-6A122-9A8-14AB8-B6A-6AB8-B5A4-2A2-B8-B2-2A6-3AB8-B3A8-2(2AB8-B2A9-)2AB7-3(B3A9-3AB6-)B3A8-2(4AB6-B4A7-)4AB6-B4A8-2(3AB6-B3A9-)3AB6-B3A10-2AWFZAaXAfUW2A12-10A14-8A17-4A126-7A6-8A-7AAnHIYAjQKBa7A2-D5AAtAkKLYFAhAe5AD4-D4AAgYMILHAbF4AD6-4AUITKIAhAvS3A9-3AIQRMKJAAp3A9-3ANAxPAyRXZAr3A9-3APXMFJAiAsQ3A9-3AMTSAnAeZPF3A9-3ASAzFAtMAmXH3A9-3AFAlVAgAaOAiAh3A9-3AVAgHUAAeZJ3A9-3AHLAbILRAmN3A9-3AAbAdUYArJOAf3A9-3AUOAdNQAlAeAo3A9-3AAdNSPFAiRO3A10-2ASRAcMHAqJN2A11-2A8B2A12-2A6B2A15-6A65-2A20-A2BA18-A4BA17-6B16-A6BA9-2A3D10A3D2A4-18A6-16A9-8(12A11-)2A2E4A2E2A11-AE2GE2AE2GEA11-2A2E4A2E2A2(11-12A)12-10A14-8A53-
