model
size = 22 32 21, scale = 0.05, origin = -y
material deform = 1, fade = true, lighting = smooth, roughness = 0.3, metalness = 0.6
  colors = A:#E2943B B:#74673E C:#222 D:#7D532C E:#AB3B3A F:#78552B G:#6A4028 H:#C7802D I:#855B32 J:#444
voxels
229-4A15-10A12-10A11-12A10-12A8-16A6-16A8-12A11-10A14-6A17-4A18-4F456-8A12-2A8B2A10-12B9-A12BA7-2(16A6-)16A7-14A9-12A10-12A12-8A14-3H2A3H16-4F19-2E20-2E388-A12-A6-G2A12-2AG5-2(2A12-2A6-)2A12B2A6-4A8B4A5-5A8B5A6-3A8B3A9-12A10-12A11-10A12-H8AH15-F2AF19-2(2E20-)2E386-G2A12-2AG5-2(2A12-2A6-)2A2B8-2B2A6-2A2B8-2B2A5-3A2B8-2B3A6-3A8B3A2(8-14A)10-10A12-H8AH15-I2AI18-F2EF19-2E20-2E385-GA16-AG3-2A14-2A5-2(2A12-2A6-)2A2B8-2B2A5-3A2B8-2B3A4-3A12B3A6-A12BA8-A12BA9-12A10-H10AH13-6A17-F2EF19-2(2E20-)2E363-GA16-AG3-2(A16-A4-)A16-A5-B14-B5-2(3AB10-B3A4-)3A12B3A5-2A12B2A8-12A10-H10AH12-8A15-2A2E2A17-F2EF19-2(2E20-)2E341-GA16-AG2-GA16-AG3-A16-A4-A16-A5-B14-B5-2(2A2B10-2B2A4-)2A14B2A5-A14BA7-14A8-2H10A2H10-10A13-3A2E3A16-F2EF19-3(2E20-)2E341-GA16-AG3-2(A16-A4-)AB14-BA2(4-2A2B10-2B2A)4-2A14B2A5-A14BA7-14A8-H12AH10-10A12-4A2E4A14-2A2E2A17-F2EF19-3(2E20-)2E319-GA16-AG3-2(A16-A4-)AB14-BA4-A16-A4-2A2B10-2B2A4-2A14B2A5-A14BA7-14A8-H12AH9-12A11-4A2E4A14-2A2E2A17-I2EI18-F2EF19-2(2E20-)2E319-GA16-AG2-GA16-AG3-A16-A4-AB14-B2(A4-A16-)A4-2A14B2A5-A14BA7-14A8-14A9-12A11-4A2E4A13-3A2E3A16-I2EI18-F2EF19-2(2E20-)2E319-GA16-AG2-GA16-AG3-A16-A4-AB14-B2(A4-A16-)A4-A3-10B3-A5-A14BA6-D14AD7-14A9-12A11-4A2E4A13-3A2E3A16-I2EI18-F2EF19-3(2E20-)2E319-GA16-AG3-A16-A4-AB14-B2(A4-A16-)A4-A3-10B3-A4-2A14B2A5-D14AD7-14A9-12A11-4A2E4A14-2A2E2A17-I2EI18-F2EF19-3(2E20-)2E319-DA16-AD3-A16-A4-AB14-B2(A4-A16-)A4-A3-10B3-A4-2A14B2A5-D14AD7-14A10-10A13-3A2E3A15-2A2E2A17-F2EF18-F2EF19-3(2E20-)2E253-3(DB16-BD2-)DB16-BD3-A16-A4-AB14-B2(A4-A16-)A4-A3-10B3-A4-2A14B2A5-D14AD7-14A11-8A15-2A2E2A17-3(F2EF18-)F2EF19-3(2E20-)2E164-DA18-A2DA18-AD-D18-D3(2-A18-A)2-D18-D3-A16-A4-DB14-B2(D4-D16-)D4-A3-10B3-A4-2A14B2A5-D14AD7-14A8-A3-6A3-A13-A2FA4(18-4F)19-3(2E20-)2E164-DA18-AD2A18-2A-4(A18-A2-)D18-D3-A16-A4-D16-D48-D3-10B3-D4-2A14B2A5-D14AD7-14A8-2A3-4A3-2A8-2A10-2A124-2(2E20-)2E164-DA18-AD2A18-2A-4(A18-A2-)D18-D3-A16-A4-D16-D48-D3-10B3-D4-2A14B2A5-16A6-D14AD7-2(2A4-)2A9-A10-A147-2E20-2E19-4C18-4C98-D18-D-DA18-AD2A18-2A-4(A18-A2-)D18-D3-A16-A4-D16-D52-10A8-D16AD5-16A6-D14AD7-D3A2-2A2-3AD10-2A6-2A190-6C16-6C15-8C13-10C12-3C4-3C13-C6-C8-D5-C6-C5-D-DA5-2C4-2C5-AD2A5-3C2-3C5-2A-A6-6C6-3(A2-A18-)A2-D18-D3-A16-A4-D16-D52-10A9-3D10A3D6-16A7-14A9-D10AD13-6A192-6C14-10C11-2(12C10-)5C2-5C7-DA2-2C6-2C2-AD3-D3A-3C4-3C-3AD-D4A5C2-5C4AD6A10C6A-6A8C6A2-7A-C2-C-2(7A2-7A6-)7A2-D6A6-6AD3-4A2D6-2D4A4-4D10-4D52-2D6A2D3(12-10A)12-3D4A3D15-D2AD18-D2AD170-8C12-12C9-3CJ5C2J3C8-10CJ3C7-D2CJ3C2-3CJ2CD6-D-J2C6-3C-D6-AD4C4-4CDA6-AD5C2-5CDA6-2AD10CD2A6-3AD8CD3A5-5AD-C2DC-D5A4-AF3AD2-2D2-D3AFA4-2AF2AD-4D-D2AF2A4-5AD2-2D2-D5A5-3A2(2D2-)2D3A13-2D20-2D19-D2AD17-D4AD18-6(2D20-)2D142-
