model
size = 20 12 19, scale = 0.05, origin = -y
material deform = 1, fade = true, lighting = smooth, roughness = 0.3, metalness = 0.6
  colors = A:#EEE B:#963
voxels
4-11(5A15-)5A13-11(9A11-)9A10-23(11A9-)11A8-12(13A7-)12(5A3B5A7-)12(5AB-B5A7-)12(5A3B5A7-)11(13A7-)13A8-12(11A9-)11(10A10-)10A12(11-9A)13-11(8A12-)9A19-11(2A18-)2A20-4(11(2A18-)2A19-)11(2A18-)2A
