model
size = 22 12 19, scale = 0.05, origin = -y
material deform = 1, fade = true, lighting = smooth, roughness = 0.3, metalness = 0.6
  colors = A:#EEE B:#963 C:#960 D:#FF0 E:#0C0
voxels
6-2(5A17-)C4A17-2C2(3A17-AC)3A3(17-5A)17-2AC2A17-2A2CA17-3A2C15-2(9A13-)AC3(7A13-2C)7A13-C8A4(13-9A)13-5A2C2A12-2(11A11-)2(C10A11-)2(11A11-)C10A4(11-11A)11-6AC4A11(11-11A)11-7A3CA10-12(13A9-)12(5A3B5A9-)6(5AB-B5A9-)5AB-B5A7-E2(C5AB-B5A8-)C3(5AB-B5A9-)6(5A3B5A9-)2(5A3B5A8-C)5A3B5A7-2C3(5A3B5A9-)6(13A9-)13A8-C13A7-DC13A8-C2(13A9-)13A10-8(11A11-)10AC3(11-11A)11-2(10A12-)9AC4(12-10A)12-9AC4(12-10A)2(13-8AC2(13-9A))6(13-9A)15-7(8A14-)6A3C13-7AC14-5A3C14-8A14-9A21-3(2A20-)AC2(20-2A)18-2C2A18-3CA18-4C20-CA2(20-2A)22-3(2A20-)CA2(20-2A)17-C-2CA16-3C-CA16-DC2-CA3(20-2A)21-3(2A20-)CA8(20-2A)21-3(2A20-)2(CA20-)6(2A20-)2A21-4(2A20-)CA7(20-2A)21-11(2A20-)2A
