model
size = 32, scale = 0.05, origin = -y
material deform = 1, fade = true, lighting = smooth, roughness = 0.3, metalness = 0.6
  colors = A:#BBB B:#004 C:#FC3 D:#001 E:#D00 F:#FC0 G:#0A0 H:#0E0 I:#070 J:#050
voxels
15-4B27-2(4B28-)28(4A28-)4B28-4D1018-8D1014-12D1010-16D54-4F189-G31-2(GH30-)GH29-2(2G2H28-)G2-H29-JI29-5(2J2I28-)GJIH3(28-2G2H)29-GH30-GH31-H150-7D4B7D21-4B28-4A26-2F4A2F26-8(4A28-)4A27-G4AH25-2G4A2H24-G-4A-H25-J4AI25-3(2J4A2I24-)2G4A2H24-2G4A2H25-G4AH26-G4AH27-6(4A28-)4B28-4B20-6D2B4-2B6D18-2B4-2B2(24-2A4-2A)22-2F2A4-2A2F22-9(2A4-2A24-)2A4-2A23-G2A4-2AH21-G-2A4-2A-H21-J2A4-2AI21-2J2A4-2A2I20-2G2A4-2A2H21-G2A4-2AH23-9(2A4-2A24-)2B4-2B24-2B4A2B17-5D2B8-2B5D15-2B8-2B3(20-2A8-2A)18-2F2A8-2A2F18-9(2A8-2A20-)2A8-2A19-G2A8-2AH19-2A8-2A19-J2A8-2AI19-11(2A8-2A20-)2B8-2B20-2B3A2E3A2B15-3D2B12-2B3D13-2B12-2B4(16-2A12-2A)15-F2A12-2AF15-23(2A12-2A16-)2B12-2B16-2B12A2B12-3DB16-B3D11-B16-B5(14-A16-A)13-FA16-AF13-22(A16-A14-)B16-B14-B7A2E7AB11-2DB18-B2D10-B18-B6(12-A18-A)11-FA18-AF11-21(A18-A12-)B18-B12-B8A2E8AB10-DB20-BD9-B20-B7(10-A20-A)9-FA20-AF9-20(A20-A10-)B20-B10-B20AB8-2DB20-B2D8-B20-B8(10-A20-A)8-C-A20-A-C8-19(A20-A10-)B20-B10-B3AE5A2E5AE3AB8-DB22-BD7-B22-B9(8-A22-A)7-2(CA22-AC6-)CA22-AC7-16(A22-A8-)B22-B8-B5AE4A2E4AE5AB7-DB22-BD7-B22-B12(8-A22-A)6-C-A22-A-C4-F-A22-A-C4-C-A22-A-C6-13(A22-A8-)B22-B8-B22AB7-2(B24-B6-)14(A24-A6-)A24-A5-2(FA24-AC4-)FA24-AC5-10(A24-A6-)B24-B6-B8AE2A2E2AE8A2(B6-B24-)B18(6-A24-A)4-2(C-A24-A-C2-)C-A24-A-C4-7(A24-A6-)B24-B6-B9AEA2EAE9AB5-22(B26-B4-)B26-B3-2(CB26-BC2-)CB26-BC3-5(B26-B4-)B26AB4-B25-2B25(4-B26-B)2-2CB26-B4C2(B26-B2C2F)B26-B2C2-B26-B4-BAE7(A2E)AEAB4-B25-2B3-26(CB26-BC2-)CB26-BC-2(2FB26-B2C)2-B26-B4-BAE7(A2E)AEA28(B4-B26-)B2-2CB26-B4CB26-B2C2-B26-B4-B26AB5-2(B24-B6-)28(A24-A6-)B24-B6-B9AEA2EAE9A2(B6-B24-)B28(6-A24-A)6-B24-B6-B8AE2A2E2AE8AB7-2(B22-B8-)28(A22-A8-)B22-B8-B22A2(B8-B22-)B28(8-A22-A)8-B22-B8-B5AE4A2E4AE5AB9-2(B20-B10-)28(A20-A10-)B20-B10-B3AE5A2E5AE3A2(B10-B20-)B28(10-A20-A)10-B20-B10-B20AB11-2(B18-B12-)28(A18-A12-)B18-B12-B8A2E8AB13-2(B16-B14-)28(A16-A14-)B16-B14-B7A2E7AB15-2(2B12-2B16-)28(2A12-2A16-)2B12-2B16-2B12A2B18-2(2B8-2B20-)28(2A8-2A20-)2B8-2B20-2B3A2E3A2B22-2(2B4-2B24-)28(2A4-2A24-)2B4-2B24-2B4A2B12-
