model
size = 32 32 18, scale = 0.05, origin = -y
material deform = 1, fade = true, lighting = smooth, roughness = 0.3, metalness = 0.6
  colors = A:#EEE B:#004 C:#D00
voxels
367-2B55-B6-2B6-B15-BA6BCA6BAB15-B6-2B6-B47-B7-2B7-B13-BA7BCA7BAB13-B7-2B7-B45-B8-2B8-B11-BA8BCA8BAB11-B8-2B8-B521-16(26A6-)26A5-28A327-22A10-22A9-24A8-24A7-26A6-26A5-15(28A4-)28A3-30A168-18A14-18A13-20A12-20A11-22A10-22A9-A22-A8-A22-A7-A24-A6-A24-A5-2A24-2A15(4-A26-A)3-A28-A-32A12-3(8A24-)8A19-A16-A14-A16-A13-A18-A12-A18-A11-A20-A10-A20-A9-A22-A8-A22-A7-A24-A6-A24-A5-2A24-2A15(4-A26-A)3-A28-A-13A6-13A11-3(2A6-2A22-)2A6-2A18-A16-A14-A16-A13-A18-A12-A18-A11-A20-A10-A20-A9-A22-A8-A22-A7-A24-A6-A24-A5-2A24-2A15(4-A26-A)3-A28-A-A30-A10C2A8-2A10C10-2(2A8-2A20-)2A8-2A17-A16-A14-A16-A13-A18-A12-A18-A11-A20-A10-A20-A9-A22-A8-A22-A7-A24-A6-A24-A5-2A24-2A15(4-A26-A)3-A28-A-A30-12A10-11A3(2(10-A)2(20-A10-A)17-A16-A14-A16-A13-A18-A12-A18-A11-A20-A10-A20-A9-A22-A8-A22-A7-A24-A6-A24-A5-2A24-2A15(4-A26-A)3-A28-A-A30-A10BA10-A10B)2(10-A)2(20-A10-A)17-A16-A14-A16-A13-A18-A12-A18-A11-A20-A10-A20-A9-A22-A8-A22-A7-A24-A6-A24-A5-2A24-2A15(4-A26-A)3-A28-A-A30-12A10-11A2(10-A)2(20-A10-A)17-A16-A14-A16-A13-A18-A12-A18-A11-A20-A10-A20-A9-A22-A8-A22-A7-A24-A6-A24-A5-2A24-2A15(4-A26-A)3-A28-A-A30-A10CA10-A10C2(10-A)2(20-A10-A)17-18A14-18A13-A18-A12-A18-A11-A20-A10-A20-A9-A22-A8-A22-A7-A24-A6-A24-A5-2A24-2A15(4-A26-A)3-A28-A-32A2(10-A)3(20-A10-A)20-B4-2B4-B19-BA4BCA4BAB15-4AB10AB4A12-20A11-A20-A10-A20-A9-A22-A8-A22-A7-A24-A6-A24-A5-2A24-2A15(4-A26-A)3-A28-A-32A207-2B52-22A10-22A9-A22-A8-A22-A7-A24-A6-A24-A5-2A24-2A15(4-A26-A)3-30A298-B5-2B5-B17-BA5BCA5BAB12-5AB12AB5A8-24A7-16(26A6-)26A5-28A401-2B50-16(26A6-)26A491-B6-2B6-B15-BA6BCA6BAB11-4AB14AB4A13(8-24A)260-
