model
size = 30 32 25, scale = 0.05, origin = -y
material deform = 1, fade = true, lighting = smooth, roughness = 0.3, metalness = 0.6
  colors = A:#CFF B:#C6C C:#C60 D:#6F0 E:#F6C F:#603
voxels
419-C28-2C28-C496-C29-C368-2C28-6C26-3C260-C29-2C28-2C173-2(4C26-)4C2(27-3C)27-2C3(29-C)-3C25-C2-3C28-2C28-3C29-2(3C28-)3C112-C29-7(2C28-)C174-4C25-5C2(26-4C)3(27-3C)27-5C25-6C24-6C25-3CF2C24-3C2-2C23-3C28-3C27-4C27-3C28-2(3C27-)4C26-E3C26-E4C25-7C26-4C26-2C29-C59-C29-C141-2C26-2(4C27-3C27-)3(3C27-)CEC27-3C28-2C28-3C27-3C28-3C27-4C27-3C28-2(3C27-)2(3C28-)CEC27-6C25-5C25-2C29-2C28-2(C29-)C141-2C2(27-3C)28-2C549-2C28-C52-2D2-2C23-4D2-C23-3D711-A29-2A43-2C28-2C79-4D2-CE22-D2CD2-2C22-4D740-2A28-2A14-2C108-4D26-2DCD3-2C21-4D741-A29-A14-2C109-2D27-A3D3-2C20-2A2D87-3D27-4D26-2D593-2A28-A182-2A28-2A60-4D26-D2CD26-3D562-2A28-2A210-2A28-2A61-4D26-2DCD26-4D502-B28-2B2(28-2A)170-B39-2A28-2A58-3DC-D23-4DC3D22-4D-2D501-3B27-3B29-A170-B29-B9-4(2A28-)3D26-2DCD26-D2CD473-B29-3B2A26-2BA180-A18-2B9-2A17-2B9-AE3(28-2A)28-3D26-3D27-3D44-4B26-4B27-3B27-2B28-2B212-B19-2D8-3B16-4D8-4B3-A10-4D10-3B2-2A9-3D12-3B-2A9-3D137-2(2A28-)2(2A17-2B9-)2A28-2A168-B24-6B24-3B-2B3(25-5B)4(26-4B)27-3B27-4B26-5B18-3D4-6B5-2A9-2DCD4-2B2-4B3-2A9-D2CD2(4-2B)3-2A9-DC2D4-2B9-A10-3D5-2B28-B29-2(B11-2A16-)B11-2A28-2A17-2B9-2A17-2B8-3A17-2B8-2(2A28-)2(A29-)A28-2A28-A21-B7-A16-6B7-A16-2B2(3-B25-B)3-B25-2B2(2-B26-B)2-2(B26-2B-)2(B27-B-)2B26-B-2B8-A10-3D4-3B8-2A6-2A-4D3-3B9-2A6-3AD2CD3-3B10-F8-ADC2D3-3B20-3D4-3B28-2B3(10-2A15-3B)10-2A14-5B9-2A13-3B-2B8-3A13-2B2-2B8-AE-A16-2B8-AE-2A16-2B7-2A-2A16-B8-A29-A3(28-2A)27-4A14-6B6-4A14-2B3-B6-4A2(15-2B2-B7-3A)15-2B-2B7-2A3(17-4B8-A)-3A14-2BF8-A2-3A13-3B12-2A13-3B12-3A12-3B9-A4-3A10-3B8-2A5-3A-4D4-2B10-A6-3A4D3-3B10-A9-4D3-3B10-2A8-2D6-2B10-2A16-BF10-3A14-2(3B10-4A13-)3B12-3(2A15-2B11-)2A16-B11-2A-3D24-A2-2(3D27-)2D110-4A14-6B5-5A15-2B-BE6-4A15-5B6-4A2(16-4B7-3A)16-3B8-3A17-2B8-5A15-2B8-6A24-6A25-3AF2A24-3A2-2A23-3A28-3A27-2(4A26-)2(5A25-)6A24-2AE3A26-E4A25-7A26-4A26-2A29-A28-3D27-DC28-DCD27-3D110-2A16-4B6-4A16-4B7-3A17-3B7-4A27-3A27-4(5A25-)4A3(27-3A)27-2AEA2(26-5A26-4A)27-2(3A28-)AEA27-6A25-5A25-2A29-2A27-3D2(27-DCD)27-2D111-2A2(27-3A)28-2A58-3A2D25-3A3D25-2A2D26-4A26-3A27-3A4(28-2A)217-2A28-A56-2A27-3D27-D29-3D28-2D261-5D25-3DCD25-5D26-2A339-2(2D27-A)3D83-AE28-2A350-5D25-D2CD26-4D367-4D26-2DCD26-4D114-2A350-2(2D28-)2D368-4D26-D2CD26-4D114-2A781-2D27-4D26-D304-
