model
size = 26 29 26, scale = 0.05, origin = -y
material deform = 1, fade = true, lighting = smooth, roughness = 0.3, metalness = 0.6
  colors = A:#FFF B:#777 C:#505050 D:#888 E:#AAA
voxels
10-8A355-14(8A18-)8A356-15(8A18-)8A278-2(8A18-)8A16-15(2A8-2A14-)2A8-2A198-2(8A18-)8A16-2(2A8-2A14-)2A8-2(2A12-)15(2A10-2A12-)2A118-CB2ECDAC18-ACD2ABEC18-8B16-2(2A8-2A14-)2A8-2(2A12-)2(2A10-2A12-)2A9-15(A16-A8-)A16-A65-2DACEDAC18-CDCBAECA16-CA8-AD14-2D8-DA14-2B8-2B2(12-2A)2(10-2A12-2A)9-2(A16-A8-)A16-A7-15(A18-A6-)A18-A38-2(AC)EADC16-CE8-ED14-DA8-CE13-A12-C12-D12-C2(12-B)10-2A14-2A2(8-A16-A)7-2(A18-A6-)A18-A5-15(A20-A4-)A20-A11-ADCECA2D16-DE8-DA13-A12-C12-D12-A11-D14-D10-D14-E10-B14-B9-2(A16-A8-)A16-A7-2(A18-A6-)A18-A5-15(A20-A4-)A20-A10-C8-A14-DA10-2D11-D14-C10-C14-E9-C16-A8-C16-D8-B16-B7-2(A18-A6-)A18-A5-2(A20-A4-)A20-A3-15(A22-A2-)A22-A8-B10-C13-A12-E11-D14-D10-D14-A9-D16-C8-B16-E8-B16-B7-2(A18-A6-)A18-A5-2(A20-A4-)A20-A3-15(A22-A2-)A22-A7-A12-D11-D14-A9-A16-C8-B16-D7-E18-D6-C18-D6-B18-B5-2(A20-A4-)A20-A3-2(A22-A2-)A22-A-A15(24-2A)24-A6-C12-C11-B14-E9-B16-C8-C16-D7-2(A18-A6-)B18-B5-2(A20-A4-)A20-A3-2(A22-A2-)A22-A-A15(24-2A)24-A6-A12-A11-B14-A9-C16-E8-C16-E7-D18-D6-A18-C6-B18-B5-2(A20-A4-)A20-A3-2(A22-A2-)A22-A-A15(24-2A)24-A6-B12-B11-A14-C9-E16-D8-A16-E7-E18-A6-B18-C6-B18-B5-2(A20-A4-)A20-A3-2(A22-A2-)A22-A-A15(24-2A)24-A6-E12-C11-E14-E9-C16-A8-D16-A7-E2(18-D6-B)18-B5-2(A20-A4-)A20-A3-2(A22-A2-)A22-A-A15(24-2A)24-A6-A12-C11-D14-A9-A16-C8-A16-D7-D18-C6-C18-B6-B18-B5-2(A20-A4-)A20-A3-2(A22-A2-)A22-A-A15(24-2A)24-A6-E12-A11-C14-B9-D16-A8-C16-D7-A18-D2(6-B18-B)5-2(A20-A4-)A20-A3-2(A22-A2-)A22-A-A15(24-2A)24-A6-C12-C11-C14-D9-C16-E8-A16-D7-C18-A6-D18-B6-B18-B5-2(A20-A4-)A20-A3-2(A22-A2-)A22-A-A15(24-2A)24-A7-C10-D13-A12-E11-D14-A10-A14-C9-C16-C8-A16-A8-B16-B7-2(A18-A6-)A18-A5-2(A20-A4-)A20-A3-15(A22-A2-)A22-A9-A8-C14-EA10-2A11-D14-D10-E14-C9-D16-D8-E16-D8-B16-B7-2(A18-A6-)A18-A5-2(A20-A4-)A20-A3-15(A22-A2-)A22-A10-CDBACABC16-DA8-2A13-E2(12-C)12-A11-A14-A10-B14-D10-B14-B9-2(A16-A8-)A16-A7-2(A18-A6-)A18-A5-15(A20-A4-)A20-A37-3CABDAB16-2A8-CB14-DE8-BD13-A12-D12-E12-D2(12-B)10-2A14-2A2(8-A16-A)7-2(A18-A6-)A18-A5-15(A20-A4-)A20-A63-ADEBCADC18-D2ECDCAB16-BA8-DA14-AE8-AC14-2B8-2B2(12-2A)2(10-2A12-2A)9-2(A16-A8-)A16-A7-15(A18-A6-)A18-A116-CDEAB2EC18-2(CA)BECD18-8B16-2(2A8-2A14-)2A8-2(2A12-)2(2A10-2A12-)2A9-15(A16-A8-)A16-A195-2(8A18-)8A16-2(2A8-2A14-)2A8-2(2A12-)15(2A10-2A12-)2A274-2(8A18-)8A16-15(2A8-2A14-)2A8-2A7-
