model
size = 23 26 14, scale = 0.05, origin = -y
material deform = 1, fade = true, lighting = smooth, roughness = 0.3, metalness = 0.6
  colors = A:#EEE B:#86BCDE C:#222 D:#FFF E:#F4A7B9 F:#9F353A G:#0089A7 H:#C46243 I:#9E7A7A J:#F596AA K:#C73E3A L:#A35E47 M:#64363C N:#FFFFFB O:#CB4042 P:#D0104C Q:#E16B8C R:#B54434 S:#B19693 T:#884C3A U:#F8C3CD V:#EEA9A9 W:#8E354A X:#E87A90 Y:#724832 Z:#D7C4BB Aa:#F75C2F Ab:#DB4D6D Ac:#86473F Ad:#CB1B45 Ae:#904840 Af:#9A5034 Ag:#FEDFE1 Ah:#BF6766 Ai:#A96360 Aj:#787D7B Ak:#DDD Al:#B55D4C Am:#B5495B An:#734338 Ao:#AB3B3A Ap:#554236 Aq:#FF797A Ar:#6A4028 As:#994639 At:#EB7A77 Au:#854836 Av:#B9887D Aw:#E83015 Ax:#DC9FB4 Ay:#D05A6E Az:#D75455
voxels
57-2A20-4A18-6A16-8A14-10A9-B3-10A3-B6-16A9-12A12-5(10A13-)10A12-2(12A11-)2A2C4A2C2A11-AC2GC2AC2GCA11-2A2C4A2C2A11-12A13-8A16-6A65-2A21-2A20-4A19-4A18-6A16-8A13-3A6-3A10-14A11-12(A8-A13-)10A14-8A110-2A20-3A20-4A19-4A18-6A16-8A10-6A6-6A5-5A2HEKMESAc5A6-3AB8-B3A9-11(AB8-BA11-)2AAaURDFAxXL2A11-2AFAlAaBPRPJ2A12-2A6-2A14-8A64-2A20-4A18-6A17-6A34-5A8-7A-22A2-6AHJSAzAwTME6A4-B3AB8-B3AB6-B2AB8-BAB9-2AB8-BA10-9(2AB8-B2A9-)3AApSAmZKAsUG3A10-2AAtAsQAgQVJAc2A11-2AB6-B2A12-2A6B2A15-6A145-9A8-14AB8-B6A-6AB8-B5A4-BA2-B8-B2-AB6-3AB8-B3A8-2AB8-B2A9-2AB2(8-B2A)7(B8-B2AB7-B2A)B8-B2(2AB8-)B2A9-2AB8-B2A10-ABS6-UBA12-3AAbDSGRIA14-8A17-4A100-3A20-4A18-5A5B8-5B2A-3A4B8-B5A4-2B2-B8-B2-AB6-A3B8-B3A7-A3B8-B2A9-9(2AB8-B2AB7-B)2AB8-B2(2AB8-)B2A10-ABAbTKDAuFZAvBA12-10A14-8A16-6A76-2A21-3A20-4A18-5A5B8-5B2A-3A4B8-B5A4-2B2-B8-B2-AB6-A3B8-B3A7-A3B8-B2A9-2A3(B8-B3A7-3A)B8-B3A7-2A-B8-B-2A5(7-3AB8-B3A)8-2AB8-B2A10-ABWHAcAaKILMBA12-10A14-8A16-6A53-2(2A21-)3A20-4A18-5A5B8-5B2A-3A4B8-B5A4-2B2-B8-B2-AB6-A3B8-B3A7-A3B8-B2A9-2AB8-B3A7-4(3AB8-B3A8-NAB8-BAN8-)3AB8-B3A8-2AB8-B2A10-ABOEAnWVRAgFBA12-10A14-8A16-6A53-2(2A21-)3A20-4A18-5A5B8-5B2A-3A4B8-B5A4-2B2-B8-B2-AB6-A3B8-B3A7-A3B8-B2A9-2A9(B8-B3A7-3A)B8-B3A8-2AB8-B2A10-ABZWPOBAxAiLBA12-10A14-8A16-6A76-2A21-3A20-4A18-5A5B8-5B2A-3A4B8-B5A4-2B2-B8-B2-AB6-A3B8-B3A7-A3B2(8-B2A9-2AB)7-Y4A7-4AF6-B4A7-4AAq6-F4A7-2A-AI6-AqA-2A8-3AX6-I3A9-3AH6-X3A9-A-AD6-H3A9-3AE6-D3A9-3AQ6-E3A9-3AL6-Q3A10-2AJAmIZAhAtAAj2A12-10A14-8A16-6A99-3A20-4A18-5A5B8-5B2A-3A4B8-B5A4-2B2-B8-B2-AB6-A3B8-B3A7-A3B2(8-B2A9-2AB)7-Ap3A9-3AAh6-F3A9-3AAo6-Av3A9-3AAm6-Aw3A12-U6-S12-3AAl6-F3A12-Av6-P12-3AS6-Ab3A9-3AAa6-Aq3A9-3AF6-H3A10-2AAjTAuAsKEAbAj2A12-10A14-8A16-6A122-9AB6-B14AB8-B6A-6AB8-B5A4-BA2-B8-B2-AB6-3AB8-B3A8-2(2AB8-B2A9-)2AB7-Ar3A9-3AAi6-Ap3A9-3AY6-Ah3A9-3AAn6-Ac3A8-B3AX6-K3AB7-B3AR6-O3AB7-B3AB6-O3AB8-3AAl6-W3A9-3AI6-Ar3A9-3AAc6-G3A10-2AAjDVFGRAfAj2A12-10A14-8A17-4A126-7B6-8B-7A8B7A2-B5AAyAuKIUDQY5AB4-B4AAiUBMIEPD4AB6-4AAfMWKMQAlAe3A9-3AMHAdBKLAB3A9-3AJArOAwAdGVX3A9-3AOGBDLAoAxH3A9-3ABWAeAtYVOD3A9-3AAeApDAyBAnGE3A9-3ADAhZAiFTAoQ3A9-3AZAiEAfAYVL3A9-3AEIPMIAdAnJ3A9-3APAgAfUXLTR3A9-3AAfTAgJHAhYAa3A9-3AAgJAeODAoAdT3A10-2AAeAdAbBEAmLJ2A11-2A8B2A12-2A6B2A15-6A65-2A20-A2BA18-A4BA17-6B16-A6BA9-2A3B10A3B2A4-18A6-16A9-8(12A11-)2A2C4A2C2A11-AC2AkC2AC2AkCA11-2A2C4A2C2A2(11-12A)12-10A14-8A53-
