model
size = 23 26 14, scale = 0.05, origin = -y
material deform = 1, fade = true, lighting = smooth, roughness = 0.3, metalness = 0.6
  colors = A:#A67C00 B:#FFBF00 C:#BF9B30 D:#222 E:#FFF F:#F4A7B9 G:#9F353A H:#F19483 I:#C46243 J:#9E7A7A K:#F596AA L:#C73E3A M:#A35E47 N:#64363C O:#FFFFFB P:#CB4042 Q:#D0104C R:#E16B8C S:#B54434 T:#B19693 U:#884C3A V:#F8C3CD W:#EEA9A9 X:#8E354A Y:#E87A90 Z:#724832 Aa:#D7C4BB Ab:#F75C2F Ac:#DB4D6D Ad:#86473F Ae:#CB1B45 Af:#904840 Ag:#9A5034 Ah:#FEDFE1 Ai:#BF6766 Aj:#A96360 Ak:#787D7B Al:#DDD Am:#B55D4C An:#B5495B Ao:#734338 Ap:#AB3B3A Aq:#554236 Ar:#FF797A As:#6A4028 At:#994639 Au:#EB7A77 Av:#854836 Aw:#B9887D Ax:#E83015 Ay:#DC9FB4 Az:#D05A6E Ba:#D75455
voxels
57-2A20-4A18-6A16-8A14-10A9-C3-10A3-C6-16A9-12A12-5(10A13-)10A12-2(12A11-)2A2D4A2D2A11-AD2HD2AD2HDA11-2A2D4A2D2A11-12A13-8A16-6A65-2A21-2A20-4A19-4A18-6A16-8A13-3A6-3A10-14A11-12(A8-A13-)10A14-8A110-2A20-3A20-4A19-4A18-6A16-8A10-6A6-6A5-5A2IFLNFTAd5A6-3AB8-B3A9-11(AB8-BA11-)2AAbVSEGAyYM2A11-2AGAmAbCQSQK2A12-2A6-2A14-8A64-2A20-4A18-6A17-6A34-5A8-7A-22A2-6AIKTBaAxUNF6A4-B3AB8-B3AB6-B2AB8-BAB9-2AB8-BA10-9(2AB8-B2A9-)3AAqTAnAaLAtVH3A10-2AAuAtRAhRWKAd2A11-2AB6-B2A12-2A6B2A15-6A145-9A8-14AB8-B6A-6AB8-B5A4-BA2-B8-B2-AB6-3AB8-B3A8-2AB8-B2A9-2AB2(8-B2A)7(B8-B2AB7-B2A)B8-B2(2AB8-)B2A9-2AB8-B2A10-ABT6-VBA12-3AAcETHSJA14-8A17-4A100-3A20-4A18-5A5B8-5B2A-3A3CB8-B5A4-BC2-B8-B2-AB6-A2CB8-B3A7-A2CB8-B2A9-9(2AB8-B2AB7-B)2AB8-B2(2AB8-)B2A10-ABAcULEAvGAaAwBA12-10A14-8A16-6A76-2A21-3A20-4A18-5A5B8-5B2A-3A3CB8-B5A4-2C2-B8-B2-AC6-A2CB8-B3A7-A2CB8-B2A9-2A3(B8-B3A7-3A)B8-B3A7-2A-B8-B-2A5(7-3AB8-B3A)8-2AB8-B2A10-ABXIAdAbLJMNBA12-10A14-8A16-6A53-2(2A21-)3A20-4A18-5A5B8-5B2A-3A3CB8-B5A4-2C2-B8-B2-AC6-A2CB8-B3A7-A2CB8-B2A9-2AB8-B3A7-4(3AB8-B3A8-OAB8-BAO8-)3AB8-B3A8-2AB8-B2A10-ABPFAoXWSAhGBA12-10A14-8A16-6A53-2(2A21-)3A20-4A18-5A5B8-5B2A-3A3CB8-B5A4-2C2-B8-B2-AC6-A2CB8-B3A7-A2CB8-B2A9-2A9(B8-B3A7-3A)B8-B3A8-2AB8-B2A10-ABAaXQPCAyAjMBA12-10A14-8A16-6A76-2A21-3A20-4A18-5A5B8-5B2A-3A3CB8-B5A4-2C2-B8-B2-AC6-A2CB8-B3A7-A2C2(B8-B2A9-2A)B7-Z4A7-4AG6-B4A7-4AAr6-G4A7-2A-AJ6-ArA-2A8-3AY6-J3A9-3AI6-Y3A9-A-AE6-I3A9-3AF6-E3A9-3AR6-F3A9-3AM6-R3A10-2AKAnJAaAiAuAAk2A12-10A14-8A16-6A99-3A20-4A18-5A5B8-5B2A-3A3CB8-B5A4-2C2-B8-B2-AC6-A2CB8-B3A7-A2C2(B8-B2A9-2A)B7-Aq3A9-3AAi6-G3A9-3AAp6-Aw3A9-3AAn6-Ax3A12-V6-T12-3AAm6-G3A12-Aw6-Q12-3AT6-Ac3A9-3AAb6-Ar3A9-3AG6-I3A10-2AAkUAvAtLFAcAk2A12-10A14-8A16-6A122-9AC6-C14AB8-B6A-6AB8-B5A4-CA2-B8-B2-AC6-3AB8-B3A8-2(2AB8-B2A9-)2AB7-As3A9-3AAj6-Aq3A9-3AZ6-Ai3A9-3AAo6-Ad3A8-C3AY6-L3AC7-C3AS6-P3AC7-C3AC6-P3AC8-3AAm6-X3A9-3AJ6-As3A9-3AAd6-H3A10-2AAkEWGHSAgAk2A12-10A14-8A17-4A126-7C6-8C-7A8C7A2-C5AAzAvLJVERZ5AC4-C4AAjVBNJFQE4AC6-4AAgNXLNRAmAf3A9-3ANIAeBLMAC3A9-3AKAsPAxAeHWY3A9-3APHBEMApAyI3A9-3ABXAfAuZWPE3A9-3AAfAqEAzBAoHF3A9-3AEAiAaAjGUApR3A9-3AAaAjFAgAZWM3A9-3AFJQNJAeAoK3A9-3AQAhAgVYMUS3A9-3AAgUAhKIAiZAb3A9-3AAhKAfPEApAeU3A10-2AAfAeAcBFAnMK2A11-2A8B2A12-2A6B2A15-6A65-2A20-A2CA18-A4CA17-6C16-A6CA9-2A3C10A3C2A4-18A6-16A9-8(12A11-)2A2D4A2D2A11-AD2AlD2AD2AlDA11-2A2D4A2D2A2(11-12A)12-10A14-8A53-
