model
size = 32 15 21, scale = 0.05, origin = -y
material deform = 1, fade = true, lighting = smooth, roughness = 0.3, metalness = 0.6
  colors = A:#C30 B:#F60 C:#F30 D:#930 E:#F93 F:#F90 G:#FC3 H:#C60 I:#700 J:#800 K:#500 L:#600 M:#EEE N:#F63 O:#400 P:#FC6 Q:#C93 R:#300 S:#630 T:#FF6
voxels
51-3B3A26-CBAJAB26-CB4A27-C3A29-2C302-5B26-I7B2(EF)5B2-4A16-BEFE4BCBAJAB2A20-4BCB6A21-2CB2C4ACA22-B8CA22-DA2C2BA2B24-C4BAC28-BC206-2BH27-RD2BH5BFEF10-3A7-D2BH5BFE3B7-2ACA14-2BFN3B7-2ABA17-B3CB5-AC2A18-B2CB8C2A19-CADA2C2BA2B2A19-3AC4BA2CB21-6BC2AC24-2F4BC195-B5-OSBE3A18-ABA4-OSBE3A4BF13-C2A7-E3A4BFN11-AB2A13-2BFBC10-3A15-BFB2C8-C3A16-F2CADA5-2B3A17-J3AC4BA2CBA18-D7BC2ACBA19-DAB2F4BCBA22-7BAC162-2B30-BA3-OD2BN3AH18-2A4-D2BN3AH3B14-B2A10-AH3BE13-2AB13-2BE12-3AC14-BE2C9-B3A15-BEJ2A7-2CB2A16-ED7BC2ACB2A17-ADAB2F4BCB2A19-A8BA2C21-2GE5B2C131-BA30-2A2-KD2B24-2A2-KD4B2AHB17-3A6-2B2AHBF16-ABA11-BFB14-2AC13-FBG13-3A13-FBGJ11-B3A14-BGD2B8-CB2A16-GADAB2F2-2BCB2AD17-EA8BA2CD19-3G2B3FB3C22-G2B3FBC101-A2(30-2A)-RLA5B21-2A3-A5B3A17-ABC9-3AH16-A2C11-AHB14-4A12-HBG13-3A13-HBGD11-B2AC14-BGADA8-B2AD16-GEA3B4-BA2CD18-3GBFG2FEN3B21-GBFG2FEN2B25-G2F72-A31-C31-A-OK2ABH23-AC2-K2ABH2ADI19-BC8-AD2I17-A2C11-ID16-3A11-IDB14-4A12-DBQ12-B2AC14-BGAD10-2ADA14-BGEA2B6-A2CDL16-3GFEPG-3E4B19-GFEPG4E3B22-EPG4E70-A31-C31-B-ODA27-CMOD3AH2DK20-BC7-2D3K18-2CM9-2KD16-3A11-KD16-3A12-DH14-2AC13-DHGA11-2ADA14-HGEA9-2CDL16-2G2EP5-EF3B18-G2EPTGF3EF2B21-EPTGF3EF69-2(C31-)BMKD28-C-KD3AH2D22-CM5-H2DK2I18-2C10-2I18-2AM10-ID16-2AC11-IDF14-2ACA12-DFG13-ADA14-FGEA10-CDL16-3EF7-E2BCB17-2EF3GE2G2E2B20-EF3GE2G2E29-GE38-C31-M31-BM30-C-K2(DA)HDI22-CM5-HDILD19-2C10-DB18-2AM10-BF16-2AM11-BFE15-ACA12-FEG13-ADA14-EGE11-CDLJ14-2EB2F8-BH2B17-B2FGE2-E3GBH20-2FGEFBE3G29-2G38-2(C31-)BMKD28-CMKD4ADJ22-CM5-ADJD2B18-2CM9-2B18-2AM10-BE16-3A11-BEF14-2ACA12-EFG13-ADA14-FGEA10-CDL16-BHBF7-N3AC17-HB2FHA2B2EN2A20-B2FHA2B2EN29-2E38-2(C31-)B-L2A27-C-L5A3B20-BC6-A4BA18-2C10-BA17-3A11-AB16-3A12-2B14-2AC13-2BGA11-2ADA14-BGEA9-2CDL16-F2BFH6-B3A18-2BFHD3AEGB2A21-FHD3AEGB69-A31-C31-B-LAD2A24-2A2-AD2A3BFB19-BC7-2BFBA17-ACA10-B2A16-3A11-3A14-4A12-2AQ13-2AC13-2AGAD10-2ADA14-AGEAB7-A2CDL16-A3BAJA2-BECA2D19-2BAJAH2BECAD22-AJAH2BE70-C2(30-2A)-KID2A2BH21-2A3-D2A2BH2BA18-BC9-2B2A16-A2C11-3A14-4A12-2(3A13-)2AQD11-B2AC14-AGADA8-B2AD16-GEA3B4-BA2CD18-B4ADH3BCAD20-4ADH3BCA25-DHB71-BC30-AC2-DIA25-2A2-DI3ABH2BA17-2AC5-2ABH2B2A16-ABC10-B2AC14-2AC13-ACB13-3A13-ACAJ11-B3A14-CQD2B8-CB2A16-GADABF4-BCB2AD17-EA8BA2CD19-ACBA2DA3DLD22-BA2DA3D99-2B30-BA3-I3DAHA2B18-2A3-I3DAHA4BA15-2A10-4BAF13-2AB13-BAB12-3AC14-ABC11-4A14-2AJ2A7-2CB2A16-QD5B2-C2ACB2A17-ADAB2F4BCB2A19-A8BA2C21-2B4AJIOR130-2B4-DIJD2A19-ABA4-DIJD2AC2B2AE13-C2A7-D2AC2B2AEN12-B2A13-2AFB11-3A15-A2B2C8-C3A16-B2CAD6-2B3A16-AJ3AC4BA2CBA18-D7BC2ACBA19-DAB2F4BCBA22-7BAC26-ADJ140-ILDHAH2A2D2E11-2AB6-ILDHAH2A2D2E2B8-2ACA14-2DEN3B7-2ABA16-FB3CB5-AC3A17-B2CB3C-4C2A18-2CADA2C2BA2B2A19-3AC4BA2CB21-6BC2ACB23-2F4BC172-3D2A26-4D2A2ID2EF4B3-5A14-2ID2E4BCBAJAB2AC19-4BCB6A21-2CB2C4ACA21-CB8CA22-DA2C2BA2B24-C4BA2C26-2BCA250-4B4A24-BCBAJABA24-BCB4A26-2C4A27-4C296-
