model
size = 25 29 32, scale = 0.05, origin = -y
material deform = 1, fade = true, lighting = smooth, roughness = 0.3, metalness = 0.6
  colors = A:#001 B:#F00 C:#BE4800 D:#EEE E:#920316 F:#19DC06 G:#119613 H:#DE2400 I:#9E6D00 J:#B6020F K:#DA0107 L:#15B90D M:#3DDA00 N:#6E041E O:#052C2B P:#020835 Q:#C96 R:#4A0525 S:#7D9100 T:#1DFF00 U:#0D731A V:#095021 W:#5DB600 X:#26062D Y:#6D0000 Z:#020
voxels
240-2Y22-6(4Y21-)3Y523-2Y22-3Y22-5(4Y21-)3Y522-3Y21-2Y22-2(2Y4-Y18-)2Y4IY18-2Y4I19-2(2Y4SY18-)2Y3S2Y19-5Y21-3Y446-5Y19-2Y3-2Y17-2Y5-2Y16-Y7-Y16-Y-5I-Y16-Y7IY16-Y6I2Y3(16-Y7SY)16-2Y5S2Y17-2Y3W2Y19-5Y320-6C19-7C17-8C16-10C14-11C14-12C13-12C12-13I11-15I9-16I10-15I3(8-17S)8-17W2(9-16W)10-14M10-M-12M15-8M243-8C14-12C12-14C11-15C9-3C5-9C7-9C2-7C7-17CA8-16IA7-13IA2I-A6-15IAI-A5-16IAI3(-A5-16SAS)2(-A5-16WAW)-A6-14WA2W-A6-18M9-10M-5M10-9M-3M12-10M217-11C13-13C10-12CA3C9-2C7-3C3AC8-2C-7C-2C3ACA7-C-5C9ACA8-6C8A2CQ7-7I8AI-Q6-8I8AI-Q5-9I7A3-Q4-10I3(7A3-Q4-10S)7A3-Q4-10W7A3-Q4-9W8A3-Q4-9M9AM-A5-8M9AM-A7-17M9-10M-4M11-11T15-7T193-12H12-11CA4C8-2C7-7CA7-2C-7C-5C-A7-C-5C6A4CQ8-6C6A4CQ6-7CA-AC-5C-Q6-7IA-7A2-QD4-8IA10-QD3-9IA10-QD2-10I2(A10-QD2-10S)A10-Q3-10S2(A10-Q3-10W)A10-Q3-10MA10-Q4-9MA8-M-A6-8M7A-M-A6-18T9-10T-3T12-9T17-7F167-15H9-2H6-4HA4H7-2C-6C2-6CA7-C-15CQ8-16CQ6-8C6-4CQD4-8CA-7AC-QD4-8CA10-QD3-9IA10-QD2-10IA3-D6-QD-11IA2-4D4-QD-11SA-A4D4-QD-11SA2-4D4-QD-11WA-A4D4-QD-11WA10-Q2-11M2(A10-Q3-10M)A10-Q5-9T7A-T-A5-19T7-16T11-10F16-9F17-6F142-16H8-2H5-11H7-C-14C-A8-15C-Q6-18CQD4-9C6-4CQD3-9CA-7AC-QD3-9CA2-2D6-QD2-10IA2-4D4-QD-11I3A5D3-QD-11I-2A4D4-2(QD-11S3A5D3-)QD-11W3A6D2-QD-11W3A-4D3-QD-11M4A7-Q2-11MA-2A7-Q2-11MA8-M-Q4-9TA8-T-A4-9T8A3T6-17F9-13FA13-10F16-9F19-2F118-18H7-H6-9H-A8-15H-Q7-16C-Q6-18CQD4-9C7-3CQD3-9CA-7AC-QD2-10CA2-4D4-QD-11IA2-6D2-QD-11I3A6D2-QD-11I-2A2(6D2-QD-11S3A)6D2-QD-11W3A6D2-QD-11M3A-5D2-QD-11M4A4D3-Q2-11MA-2A5-M-Z2-11TA8-T-Q3-10TA8-T-A4-9F8A3F6-15FA2F8-13FQ12-11FA14-10F17-7F115-4H4-10H11-12H-A7-16H-Q6-17H-Q5-18C-QD3-10C7-3CQD2-10CA-7AC-QD-11CA2-4D4-QZ-11CA2-5D3-QZ-11I3A6D2-QD-11I-2A2(6D2-QD12S3A)6D2-QD12W3A6D2-QD12M3A-5D2-QD-11M4A-2D4-Q2-11TA-2A7-Z2-11TA8-T-Q2-11FA8-F-A3-10F8A3F5-17FA2F6-15FQ10-13FQ12-11FA15-9F18-4L92-2H9-7H9-14H-A6-17H-Q5-18H-Q4-19H-QD2-11C7-3CQD-11CA-7AC-QD-11CA3-D6-QD-11CA2-4D4-2(QD12I3A5D3-)QD12S-2A6D2-QD12W3A6D2-QD12M3A5D3-QD12M3A-D6-QD12TA2-A7-Q-12TA10-Q-12FA10-Q2-11FA8-F-A2-11F8A4F3-21F5-17FA8-15FA10-12L2A13-10L16-9L44-6B19-6B14-2B9-7B9-14B-A5-18H-Q4-19H-Q3-20H-QD-12H7-3HQD-11HA-7AH-QD-11CA10-QD-11CA2-D7-QD12CA2-3D5-QD12IA2-4D4-QD12SA-A4D4-QD12WA-AD-D5-QD12MA-A3D5-QD12MA10-QD12T2(A10-Q-12F)A10-Q2-11FA8-F-A2-11F8A4F2-22F4-20L6-18L8-16L11-12L15-9L17-6L20-7B18-7B14-B10-7B8-15B-A5-18B-Q4-19B-Q3-20B-Q2-12H7-3HQD-11HA-7AH-QD-11H2(A10-QD12C)A10-QD12IA10-QD12WA10-QD12M2(A10-QD12T)3(A10-Q-12F)A10-Q2-11LA8-L-A2-11L8A4L2-22L4-20L6-18L8-16L11-12L14-10L17-7L19-7B18-7B14-B10-7B8-15B-A5-18B-Q4-19B-Q3-20B-Z2-12B8-2BQ2-11HA-7AH-Q2-11HA8-H-QD12HA10-QD12CA10-QD12IA10-QD12MA10-QD2(12TA10-Q-)3(12FA10-Q-)12LA10-Q2-11LA8-L-A2-11L8A4L2-22L4-20L6-18L8-16G10-14G13-10G17-7G19-7B18-7B14-B10-7B8-15B-A5-18B-Q4-10BA8B-Z3-20B-Q2-12B7A3BQ2-11BA10-Q2-11BA8-B-Q-12HA8-A-Q-12CA10-Q-12IA10-Q-12M2(A10-Q-12T)3(A10-Q-12L)A10-Q-12GA10-Q2-12G2A6-G-A2-13G6A4G2-22G4-20G6-18G8-16G10-14G13-10G17-7G19-7B18-7B14-B10-7B8-15B-A5-18B-Q4-19B-Z3-20B-Q2-12B7A3BQ2-11BA10-Q2-11BA8-B-Q-12BA8-A-2(Q-12BA10-)7(Q-12GA10-)Q2-11G3A6-G-A2-12G7A4G2-22G4-20G6-18G8-16G10-14G13-10G17-7G19-7B18-7B14-B10-7B8-15B-A5-18B-Q4-19B-Q3-20B-Z2-12B8-2BQ2-11BA-7AB-Q2-11BA8-B-2(QD12KA10-)QD12BA10-QD12PA10-QD12O4(A10-Q-12V)A10-Q-12UA10-Q2-11UA8-U-A2-11U8A4U2-22U4-20U6-18U8-16U10-14U13-10U17-7U19-7B18-7B14-B10-7B8-15B-A5-18B-Q4-19B-Q3-20B-Q2-12K7-3KQD-11KA-7AK-QD-11K2(A10-QD12J)A10-QD12N2(A10-QD12P)2(A10-QD12O)2(A10-Q-12O)A10-Q-12VA10-Q2-11VA8-V-A2-11V8A4V2-22U4-20U6-18U8-16U11-12U14-10U17-7U20-6B19-6B14-2B9-7B9-14B-A5-18B-Q4-19K-Q3-20K-QD-12K7-3KQD-11KA-7AK-QD-11JA10-QD-11JA2-D7-QD12EA2-3D5-QD12NA2-4D4-QD12RA-A4D4-QD12PA-AD-D5-QD12PA-A3D5-QD12PA10-QD2(12OA10-Q-)12OA10-Q2-11OA8-O-A2-11V8A4V2-22V4-20V6-18V8-16V11-12U15-9U17-6U66-2K9-7K9-15KA6-17K-Q5-18K-Q4-19K-QD2-11K7-3KQD-11JA-7AJ-QD-11JA3-D6-QD-11EA2-4D4-QD12E3A5D3-QD12N3A5D3-QD12R-2A6D2-QD12X3A6D2-QD12P3A5D3-QD12P3A-D6-QD12PA2-A7-2(Q-12OA10-)Q2-11OA8-O-A2-11O8A4O3-21O5-17VA8-15VA10-12V2A13-10V16-9V89-4K4-10K11-12K-A7-16K-Q6-17K-Q5-18K-QD3-10J7-3JQD2-10JA-7AJ-QD-11EA2-4D4-QZ-11EA2-5D3-QZ-11E3A6D2-QD-11N-2A6D2-QD12N3A6D2-QD12R2(3A6D2-QD12X)3A-5D2-QD-11P4A-2D4-Q2-11PA-2A7-Z2-11PA8-P-Q2-11OA8-O-A3-10O8A3O5-17OA2O6-15OQ10-13OQ12-11VA15-9V18-4V92-18K7-K6-9K-A8-15K-Q7-16J-Q6-18JQD4-9J7-3JQD3-9EA-7AE-QD2-10EA2-4D4-QD-11EA2-6D2-QD-11E3A6D2-QD-11N-2A6D2-QD-11N3A6D2-QD-11R2(3A6D2-QD-11X)3A-5D2-QD-11X4A4D3-Q2-11PA-2A5-P-Z2-11PA8-P-Q3-10PA8-P-A4-9O8A3O6-15OA2O8-13OQ12-11OA14-10O17-7O116-17K7-2K5-11K7-J-14J-A8-15J-Q6-18JQD4-9J6-4JQD3-9EA-7AE-QD3-9EA2-2D6-QD2-10EA2-4D4-QD-11E3A5D3-QD-11N-2A4D4-QD-11N2(3A5D3-QD-11R)3A6D2-QD-11R3A-4D3-QD-11X4A7-Q2-11XA-2A7-Q2-11PA8-P-Q4-9PA8-P-A4-9P8A3P6-17P9-13OA13-10O16-9O19-2O120-16K8-2J6-4JA4J7-2J-6J2-6JA7-J-15JQ8-16JQ6-8E6-4EQD4-8EA-7AE-QD4-8EA10-QD3-9EA10-QD2-10EA3-D6-QD-11NA2-4D4-QD-11NA-A4D4-QD-11NA2-4D4-QD-11RA-A4D4-QD-11RA10-Q2-11R2(A10-Q3-10X)A10-Q5-9P7A-P-A5-19P7-16P11-10P16-9P17-6O144-13J11-11JA4J8-2J7-7JA7-2J-7J-5J-A7-E-5E6A4EQ8-6E6A4EQ6-7EA-AE-5E-Q6-7EA-7A2-QD4-8EA10-QD3-9E3(A10-QD2-10N)3(A10-Q3-10R)A10-Q3-10XA10-Q4-9XA8-X-A6-8X7A-X-A6-18P9-10P-3P12-9P17-7P169-12J12-13J10-12JA2J10-2J7-3J3AJ8-2E-7E-2E3AEA7-E-5E9AEA8-6E8A2EQ7-7E8AE-Q6-8E8AE-Q5-9E3(7A3-Q4-10N)2(7A3-Q4-10R)7A3-Q4-9R8A3-Q4-9R9AR-A5-8X9AX-A7-17X9-10X-4X11-11P15-7P196-9J13-12J12-14J11-14E10-3E5-8E8-9E2-7E7-17EA8-16EA7-13EA2E-A6-15EAE4(-A5-16NAN)2(-A5-16RAR)-A6-14RA2R-A6-18R9-10X-5X10-9X-3X12-10X220-6J19-7J17-8E16-10E14-11E14-12E13-12E12-13E11-15E9-16E10-15N3(8-17N)8-17R2(9-16R)10-14R10-X-12X15-8X344-5Y19-2Y3-2Y17-2Y5-2Y16-Y7-Y16-Y-5E-Y16-Y7EY16-Y6N2Y3(16-Y7NY)16-2Y5R2Y17-2Y3R2Y19-5Y446-3Y21-2Y22-2(2Y4-Y18-)2Y4EY18-2Y4N19-2(2Y4NY18-)2Y3N2Y19-5Y21-3Y283-
