model
size = 20 31 32, scale = 0.05, origin = -y
material deform = 1, fade = true, lighting = smooth, roughness = 0.3, metalness = 0.6
  colors = A:#888 B:#C06 C:#F0C D:#C09 E:#C0F F:#C6F
voxels
609-2C598-2C36-6D54-6B54-6E435-5F16-3C34-D6-D52-B6-B52-E6-E433-2F3C2F15-3C32-2D8-2D48-2B8-2B48-2E8-2E410-9B12-2F3-2F15-3C32-D3-5A2-D11-5A15-5A12-B3-3A4-B48-E10-E251-A18-3A16-5A15-6A14-7A13-2(8A12-)10C11-C7-B12-2F3-2F15-3C31-D2-2A5-2A-D8-2A5-2A11-2A5-2A9-B2-2A3-3A2-B9-8A13-7A9-E3-6A3-E11-4A16-3A17-3A18-2A19-A117-2A16-5A14-2A-4A13-A3-4A11-A5-4A10-A6-3A10-A7-3A9-A8-2A9-C8-3B9-B8-C10-B8-B11-B5-2F13-5C30-D2-A9-A-D6-A9-2A8-A9-A7-B-2A8-A2-B6-2A8-A10-2A7-A7-E2-2A6-A3-E7-3A4-2A2(12-2A3-3A)12-3A2-2A13-4A-2A5(13-7A)12-3A2-3A11-2A5-2A11-A7-2A10-A8-A9-3(A10-A8-)C11-C7-C11-B8-B9-C10-B8-B11-B5-2F12-6C30-D-A10-A-D5-A11-A7-A11-A6-BA11-A-B5-A11-A7-2A10-A6-E-A9-A2-E6-2(A9-)2(2A8-A9-)4(2A7-2A9-)3(2A7-A10-)A8-2A8-A9-2A8-2(A10-2A7-)A2(11-A7-C)11-A7-B11-C7-B11-B8-B9-C2(9-B)10-B6-2F12-6C29-D-A12-A-D3-A13-A5-A13-A4-B13-A2-B3-A12-A6-A12-A5-E-A11-A2-E4-4(A11-A7-)2(A10-A8-)A11-A3(7-A10-2A)2(7-A11-A)7-A2(12-A6-C)2(12-A6-B)12-C6-B12-B6-B11-B7-B10-C2(9-B)10-B6-2F12-6C29-D-A12-A-D3-A13-A5-A13-A4-B14-A-B3-A13-A5-A13-A4-EA13-A-E3-A13-A5-5(A12-A6-)2(A13-A5-)A13-A6-A12-2(A5-A13-)2(A5-C13-)2(A5-B13-)2(C5-B13-)B5-B12-B7-B10-C3(9-B)7-2F11-4C-2C29-DA14-AD2-2(A15-A3-)B15-AB2-2(A15-A3-)E15-AE2-A15-A5(3-A14-2A)2(3-A15-A)4-2(A13-A5-)A14-A4-C2(14-A4-B)14-C3(4-B14-B)4-2(B13-B5-)B12-B7-B10-B8-B9-F10-B7-B12-C14-D-A14-A-D-A15-A3-A15-A2-B16-A-B-A15-A3-A15-A2-E16-A-E-11(A15-A3-)C2(15-C3-B)2(15-B3-B)15-2(B4-B14-)B4-B13-B5-B12-B7-B10-B8-B9-F10-B7-B11-C15-D-A14-A-D-A15-A3-A15-A2-B16-A-B-A15-A3-A15-A2-E16-A-E-9(A15-A3-)2(C15-C3-)3(B15-B3-)2(B16-A2-)2(B15-B3-)B14-B5-B12-B6-B11-B8-B10-B8-B9-B10-C15-D-A14-A-D-A15-A3-A15-A2-B16-A-B-A15-A3-A15-A2-E16-A-E-7(A15-A3-)2(C15-C3-)3(B15-B3-)B16-A2-B15-A3-3(B16-A2-)B15-2A2-B14-B5-B12-B6-B11-B8-B10-B8-B9-B10-C15-DA15-A-D-A15-A3-A15-A2-B16-A-B-A15-A3-A15-A2-E16-A-E-5(A15-A3-)2(C15-C3-)3(B15-B3-)7(B16-A2-)B15-B3-B14-B5-B12-B6-B11-B8-B10-B8-B9-B10-C15-DA15-A-D-A15-A3-A15-A2-B16-A-B-A15-A3-A15-A2-E16-A-E-3(A15-A3-)A15-C3-C15-C5(3-B15-B)3-4(B16-A2-)B15-A3-2(B16-A2-)B15-B3-B14-B5-B12-B6-B11-B8-B10-B8-B9-B10-C15-DA15-A-D-A15-A3-A15-A2-B16-A-B-A15-A3-A15-A2-E16-A-E-5(A15-A3-)2(C15-C3-)3(B15-B3-)7(B16-A2-)B15-B3-B14-B5-B12-B6-B11-B8-B10-B8-B9-B10-C15-D-A14-A-D-A15-A3-A15-A2-B16-A-B-A15-A3-A15-A2-E16-A-E-7(A15-A3-)2(C15-C3-)3(B15-B3-)B16-A2-B15-A3-3(B16-A2-)B15-2A2-B14-B5-B12-B6-B11-B8-B10-B8-B9-B10-C15-D-A14-A-D-A15-A3-A15-A2-B16-A-B-A15-A3-A15-A2-E16-A-E-9(A15-A3-)C2(15-C3-B)3(15-B3-B)2(16-A2-B)2(15-B3-B)14-B5-B12-B6-B11-B8-B10-B8-B9-B10-C15-D-A14-A-D-A15-A3-A15-A2-B16-A-B-A15-A3-A15-A2-E16-A-E-7(A15-A3-)A15-A4-A13-A5-C13-A5-B14-A2(4-B14-C)4(4-B14-B)4-2(B13-B5-)B12-B7-B10-B8-B9-F10-B7-B12-C14-D2-A12-A2-D-2A13-A4-A14-A3-B15-A2-B-A14-A4-A14-A3-E15-A2-E-A14-A4-A14-8(A5-A13-)2(A5-C13-)A5-B14-A4-B14-C3(4-B14-B)4-B13-B5-B12-2B6-B10-C8-B10-B9-B8-F11-C5-CB28-D-A12-A-D3-A13-A5-A13-A4-B14-A-B3-A13-A5-A13-A4-EA13-A-E3-A13-A5-5(A12-A6-)2(A13-A5-)A13-A6-A12-2(A5-A13-)A5-C2(13-A5-B)3(13-C5-B)13-B5-B12-B7-B10-C3(9-B)7-2F11-4C-2C29-D-A12-A-D3-A13-A5-A13-A4-BA12-A2-B3-A12-A6-A12-A5-E-A11-A2-E4-4(A11-A7-)2(A10-A8-)A11-A3(7-A10-2A)2(7-A11-A)7-2(C12-A6-)B12-A2(6-B12-C)6-B12-B6-B11-B7-B10-C2(9-B)10-B6-2F12-6C29-D2-A10-A2-D4-A11-A7-A11-A5-B-A11-A2-B4-A11-A7-2A10-A5-E2-A9-A3-E5-2(A9-)2(2A8-A9-)4(2A7-2A9-)3(2A7-A10-)A8-2A8-A9-2A8-2(A10-2A7-)2(C11-A7-)B11-DC6-B11-C7-B11-B8-B9-C2(9-B)10-B6-2F12-6C30-D2-A9-A-D6-A9-2A8-A9-A7-B-2A8-A2-B6-2A8-A10-2A7-A7-E2-2A6-A3-E7-3A4-2A2(12-2A3-3A)12-3A2-2A13-4A-2A5(13-7A)12-3A2-3A11-2A5-2A11-A7-2A10-A8-A9-2(A10-A8-)C10-A8-B11-C7-B11-B8-B9-C10-B8-B11-B5-2F12-6C30-D3-2A5-2A2-D7-2A5-2A11-2A5-2A8-B3-2A3-3A3-B8-8A13-7A8-E4-6A4-E10-4A16-3A17-3A18-2A19-A117-2A16-5A14-2A-4A13-A3-4A11-A5-4A10-A6-3A10-C7-3A9-C8-3C8-B10-B9-B8-C10-B8-B11-B5-2F13-5C31-D4-5A3-D10-5A15-5A11-B4-3A5-B46-E12-E250-A18-3A16-5A15-6A14-7A13-C7A12-C10B9-B8-C11-B7-B12-2F3-2F15-3C32-D10-D48-B10-B48-E10-E390-9C11-B7-B12-2F3-2F15-3C32-2D8-2D48-2B8-2B48-2E8-2E410-9B12-2F3-2F15-3C34-D6-D52-B6-B52-E6-E433-2F3C2F15-3C35-6D54-6B54-6E435-5F16-3C28-
