model
size = 23 31 25, scale = 0.05, origin = -y
material deform = 1, fade = true, lighting = smooth, roughness = 0.3, metalness = 0.6
  colors = A:#EEE B:#CCC C:#AAA D:#BBB E:#DDD F:#888 G:#666 H:#999 I:#777 J:#FFF K:#555
voxels
702-4A701-8A3-3A698-2A13-A697-A15-A695-2A16-A671-A18-A668-3A18-A668-A21-2A20-A668-2(A21-A690-)A20-A691-A20-A668-A20-A691-A19-2A692-A17-2A670-2A39-A672-A15-2A695-2A13-2A697-A12-2A675-2A33-2A677-2A9-A679-2A30-A681-A6-2A705-A4-2A178-K2C19-ADGCH17-FDI2G2CA13-A2BCK2GIHDC11-C2AJEAH2C4BF8-BJAE-AE2DEA-2BEH7-CF3-FA2BED3-GI13-DEBF20-AD9(21-AC)21-BH15-DE4B3DC2DC9-3(2BE)2(2BD)9-DED6BD2BD15-FEDF18-2AEC2A171-
