model
size = 28 31 25, scale = 0.05, origin = -y
material deform = 1, fade = true, lighting = smooth, roughness = 0.3, metalness = 0.6
  colors = A:#EEE B:#DDD C:#CCC D:#BBB E:#AAA F:#777 G:#FFF H:#666 I:#888
voxels
854-4A856-8A3-3A853-2A13-A852-A15-A850-2A16-A821-A18-A818-3A18-A818-A21-A5-A20-A818-2(A21-A845-)A20-A846-A20-A818-A20-A846-A19-2A847-A17-2A820-2A44-A822-A15-2A850-2A13-2A852-A12-2A825-2A38-2A827-2A9-A829-2A35-A192-2B26-2C26-2D23-I6DI13-EB3-2D3-2A3-2D3-BE7-DC-B5-2A5-B-CD9-2B4-A4GA4-2B9-HB-D-10A-D-BH8-A3-2AB6AB2A3-A7-FC2-2AC2-4A2-C2A2-CF6-B2-ABC2(2A2-)2ACBA2-B6-B3-AB4-2E4-BA3-B3-D-CA2F2CH2E6C2EH2C2FAC-DEFCA2F2C3EC4BC3E2C2FACFE3-B7-BD2ADB7-B6-DE5-BH-2A-HB5-ED7-A4-AI2-2A2-IA4-A8-CD2-AE3-2G3-EA2-DC9-BHDI4-2G4-IDHB10-IAD5-2A5-DAI9-CA3C3-B2-B3-3CAC9-D3-2B6A2B3-D17-B2CB20-A6-2A220-2B26-2C26-2D23-I6DI13-EB3-2D3-2A3-2D3-BE7-DC-B5-2A5-B-CD9-2B4-A4GA4-2B9-HB-D-10A-D-BH8-A3-2AB6AB2A3-A7-FC3-AC2-4A2-CA3-CF6-B2-ABC2(2A2-)2ACBA2-B6-B3-AB4-2E4-BA3-B3-D-CA2F2CH2E6C2EH2C2FAC-DE3A2F2C3EC4BC3E2C2F3AE3-B7-BD2ADB7-B6-DE5-BH-2A-HB5-ED7-A4-AI2-2A2-IA4-A8-CD2-AE3-2G3-EA2-DC9-BHDI4-2G4-IDHB10-IAD5-2A5-DAI9-CA3C3-B2-B3-3CAC9-D3-2B6A2B3-D17-B2CB21-A4-2A221-2A79-I6DI13-EB3-2D8-2D3-BE10-B5-2A5-B12-2B4-A4GA4-2B9-HB-D-10A-D-BH8-A3-2AB6AB2A3-A7-FC3-AC2-4A2-CA3-CF6-B2-ABC2(2A2-)2ACBA2-B6-B3-AB4-2E4-BA3-B3-D2-A9-2C9-A2-DE2-A9-2B9-A2-E3-B9-2A9-B6-DE8-2A8-ED7-A8-2A8-A8-CD7-2G7-DC9-BH6-2G6-HB10-IA6-2A6-AI9-CA3C3-B2-B3-3CAC9-D3-2B6A2B3-D18-2A22-6A209-
