model
size = 14 17 6, scale = 0.05, origin = -y
material deform = 1, fade = true, lighting = smooth, roughness = 0.3, metalness = 0.6
  colors = A:#555 B:#EEE C:#222 D:#BBB E:#444 F:#111 G:#777 H:#007 I:#CFF J:#00E K:#F0C
voxels
29-BA2-D2CD2-AB-ABA2-D2CD2-AB2ABA2-D2CD2-ABA-BA2-D2CD2-AB7-2C161-BA2-4C2-AB-ABA-C4-C-AB2ABA-C4-C-A2(BA-)C4-C-AB5-2C2-2C8-2D2-2D7-2D4-2D5-2(D8-D4-)D8-D5-8D74-BA8-AB-ABA-AD2CDA-A2(B2A2(BA)4-ABE)B2AJABFA2-2ABE2(BA-)4AFC-AB5-DG2DGD7-BD4-DB5-I2(8-B4-B)8-B5-8B73-ABA8-AB2ABA-AD2CDA-AEA2BAB6AB2E3BABC5AK2E2(BA)B2H4AB2E2ABA-6A-ABA4-D3F2D7-BF4CFB4-AI2(8CB3-AB)8CB3-G-8B4-3(G13-)AE12-3A10-ABA8-AB2ABA-AD2CDA-ABA2BABAC2EFAB2E3BAB4E2CB2E2(BA)-A4EA-AE2ABA2-4A2-ABA5-4D8-3D2C3D4-A3D4C3D2(3-AD8CD)5-8D74-BA8-AB-ABA-AD2C3(DA-AB2ABA-AD2E)DA-ABA-BA2-D2AD2-AB7-2C146-
