model
size = 14 12 6, scale = 0.05, origin = -y
material deform = 1, fade = true, lighting = smooth, roughness = 0.3, metalness = 0.6
  colors = A:#111 B:#00E C:#222 D:#EEE E:#444 F:#007
voxels
29-BA2-4A2-AB-ABA-2A2B2A-AB2ABA-A4BA-ABA-BA2-A2BA2-AB7-2A91-BA2-4C2-AB-ABA-C4-C-AB2ABA-C4-C-A2(BA-)C4-C-AB5-2C2-2C8-2C2-2C7-2C4-2C5-2(C8-C4-)C8-C5-8C4-BA8-AB-ABA2-4A2-A2(B2ABEBA4-ABE)B2ABEB2A2-AFBE2(BA-)C4AC-AB5-CA2CAC7-BA4-AB5-2(B8-B4-)B8-B5-8B3-ABA8-AB2ABA2-4A2-AEA2BEB6AB2E3BEBC5AB2EBABEB2F3AFB2E2ABA-C4AC-ABA4-C4AC7-BA4DAB5-2(2B6D2B4-)2B6D2B5-8B3-ABA8-AB2ABA2-4A2-AEA2BEBAC2E2AB2E3BEB4E2CB2E2(BA)-A4EA-AE2ABA2-4A2-ABA5-C2AC8-2C4D2C5-2(C8DC4-)C8DC5-8C4-BA8-AB-ABA2-4A2-AB2ABA-A3E2A2(-AB2ABA-A3ECA)-ABA-BA2-4A2-AB7-2C76-
