model
size = 31 9 31, scale = 0.05, origin = -y
material deform = 1, fade = true, lighting = smooth, roughness = 0.3, metalness = 0.6
  colors = A:#555 B:#746039
voxels
12-8(7A24-)7A21-8(13A18-)13A16-8(17A14-)17A13-8(19A12-)19A11-8(21A10-)21A9-8(23A8-)23A7-8(25A6-)25A5-10A5-2B10A8(4-11A5B11A)4-8A9-2B8A8(4-9A2B5-2B9A)3-7A13-8(9A2-9AB9-B)9A2-7A13-8(B8A2-8AB11-)B8A2-6A15-8(B7A2-7AB13-)B7A-7A15-8(B16AB13-)B14A4(17-8(B14AB15-)B13A)17-8(B14AB15-)B14A15-8(B16AB13-)B8A-6A15-8(B7A2-7AB13-)B7A2-7A13-8(B8A2-8AB11-)B8A2-7A13-8(9A2-9AB9-B)9A3-8A9-2B8A8(4-9A2B5-2B9A)4-10A5-2B10A8(4-11A5B11A)5-8(25A6-)25A7-8(23A8-)23A9-8(21A10-)21A11-8(19A12-)19A13-8(17A14-)17A16-8(13A18-)13A21-8(7A24-)7A12-
