model
size = 21, scale = 0.05, origin = -y
material deform = 1, fade = true, lighting = smooth, roughness = 0.3, metalness = 0.6
  colors = A:#C25100 B:#008945 C:#7100C2 D:#FC6900 E:#41C200 F:#6100A6 G:#000 H:#101010
voxels
156-BDC17-2BD2C15-2(3BD3C14-)3BD3C15-2BD2C17-BDC269-2BD2C15-3BD3C13-3B2A-3C11-3B3A-H3C3(10-2B4A3-2C)10-3B3A2-3C11-3B2A-3C13-3BD3C15-2BD2C204-3BD3C13-2B4DA2C11-2B5-2A2C9-2B6-3A2C5(8-B10-EC)8-2B8-3C9-2B7-2C11-2B5-2C13-3BD3C161-3BD3C12-2B7A2C8-D2B6D3A2CD6-DB7-4ACD6-D8-5A6(D6-D12-A)D6-DB11-CD6-D2B9-2CD8-2B7E2C12-3BD3C119-3BD3C11-D2B7A2CD8-D11AD7-C8D5AB6-C8-5AB5-FA8-6A6(B4-FA12-2A)B5-F12-AB6-F12-AB7-D11ED8-D2B7A2CD11-3BD3C78-2BD2C13-D2B5A2CD9-C11AB7-C13AB6-C8D5AB5-FA8-6AB4-FA8-6AB3-4(F2A12-3AB2-)F2A12-3AB3-FA12-2AB4-FA12-2AB5-F12-AB6-F12EAB7-FG10AB9-D2B5A2CD13-2BD2C57-3BD3C12-CD7ADB9-C11AB7-C13AB5-FA8D6AB4-FA8-6AB3-F2A8-7A6(B2-F2A12-3A)B3-FA12-2AB4-FA12-2AB5-F12EAB7-F11AB9-FDG5AGDB12-7D37-BDC15-D2B3A2CD10-2C9A2B7-C13AB5-F15AB4-FA8D6AB3-2(F2A8-7AB2-)F2A12-3AB-3(F3A12-4AB)-2(F2A12-3AB2-)F2A12-3AB3-FA12-2AB4-FA12E2AB5-F13AB7-2F9A2B10-3F3A3B15-FDB17-2BD2C13-CDB5ACDB9-C11AB7-C13AB5-F15AB3-F2A8D2(7AB2-F2A8-)7AB-5(F3A12-4AB)-2(F2A12-3AB2-)F2A12-3AB3-FA12E2AB5-F13AB7-F11AB9-3F5A3B13-2FD2B15-3BD3C12-CD7ADB9-C11AB7-C13AB5-F15AB3-F2A8D7AB2-F2A8-7AB-F3A8-8A6(BF3A12-4A)B-F2A12-3AB2-F2A12-3AB3-FA12E2AB5-F13AB7-F11AB9-2F7A2B12-3FD3B14-7D12-2D7A2D9-D11AD7-D13AD5-D15AD3-D2A8D7AD2-D2A8-7AD-D3A8-8A6(2D3A12-4A)D-D2A12-3AD2-D2A12-3AD3-DA12E2AD5-D13AD7-D11AD9-2D7A2D12-7D14-3CD3B12-BD7ADC9-B11AC7-B13AC5-B15AC3-B2A8D7AC2-B2A8-7AC-B3A8-8A6(CB3A12-4A)C-B2A12-3AC2-B2A12-3AC3-BA12E2AC5-B13AC7-B11AC9-2B7A2F12-3BD3F15-2CD2B13-BDC5ABDC9-B11AC7-B13AC5-B15AC3-B2A8D2(7AC2-B2A8-)7AC-5(B3A12-4AC)-2(B2A12-3AC2-)B2A12-3AC3-BA12E2AC5-B13AC7-B11AC9-3B5A3F13-2BD2F17-CDB15-D2C3A2BD10-2B9A2C7-B13AC5-B15AC4-BA8D6AC3-2(B2A8-7AC2-)B2A12-3AC-3(B3A12-4AC)-2(B2A12-3AC2-)B2A12-3AC3-BA12-2AC4-BA12E2AC5-B13AC7-2B9A2C10-3B3A3F15-BDF37-3CD3B12-BD7ADC9-B11AC7-B13AC5-BA8D6AC4-BA8-6AC3-B2A8-7A6(C2-B2A12-3A)C3-BA12-2AC4-BA12-2AC5-B12EAC7-B11AC9-BDG5AGDC12-7D57-2CD2B13-D2C5A2BD9-B11AC7-B13AC6-B8D5AC5-BA8-6AC4-BA8-6AC3-4(B2A12-3AC2-)B2A12-3AC3-BA12-2AC4-BA12-2AC5-B12-AC6-B12EAC7-BG10AC9-D2C5A2BD13-2CD2B78-3CD3B11-D2C7A2BD8-D11AD7-B8D5AC6-B8-5AC5-BA8-6A6(C4-BA12-2A)C5-B12-AC6-B12-AC7-D11ED8-D2C7A2BD11-3CD3B119-3CD3B12-2C7A2B8-D2C6D3A2BD6-DC7-4ABD6-D8-5A6(D6-D12-A)D6-DC11-BD6-D2C9-2BD8-2C7E2B12-3CD3B161-3CD3B13-2C4DA2B11-2C5-2A2B9-2C6-3A2B5(8-C11-B)8-2C9-2B9-2C7-2B11-2C5-2B13-3CD3B204-2CD2B15-3CD3B13-3C3-3B11-3C5-3B3(10-2C7-2B)10-3C3-H-3B11-3C2-H3B13-3CD3B15-2CD2B269-CDB17-2CD2B15-2(3CD3B14-)3CD3B15-2CD2B17-CDB156-
