model
size = 21, scale = 0.05, origin = -y
material deform = 1, fade = true, lighting = smooth, roughness = 0.3, metalness = 0.6
  colors = A:#C25100 B:#DFDFDF C:#000
voxels
156-BCA17-2BC2A15-2(3BC3A14-)3BC3A15-2BC2A17-BCA269-2BC2A15-3BC3A13-3B3-3A11-3B3(5-3A10-2BA)5-3A10-3B5-3A11-3B3-3A13-3BC3A15-2BC2A204-3BC3A13-2B7A11-2B9A9-2B7-5(4A8-B8-)4A8-2B7-4A9-2B9A11-2B7A13-3BC3A161-3BC3A12-2B9A8-C2B11AC6-CB12A7(C6-CA12-)C6-CB12AC6-C2B11AC8-2B9A12-3BC3A119-3BC3A11-C2B9AC8-C11AC7-14AB6-14AB5-6(3A12-AB4-)3A12-AB5-14AB6-14AB7-C11AC8-C2B9AC11-3BC3A78-2BC2A13-C2B7AC9-12AB7-14AB6-14AB5-16AB4-3A12-AB3-4(4A12-2AB2-)4A12-2AB3-3A12-AB4-16AB5-14AB6-14AB7-AC10AB9-C2B7AC13-2BC2A57-3BC3A12-AC7ACB9-12AB7-14AB5-16AB4-16AB3-6(4A12-2AB2-)4A12-2AB3-16AB4-16AB5-14AB7-12AB9-A2C5A2CB12-7C37-BCA15-C2B5AC10-11A2B7-14AB5-16AB4-16AB3-18A2(B2-4A12-2A)B-3(5A12-3AB)-2(4A12-2AB2-)18AB3-16AB4-16AB5-14AB7-11A2B10-6A3B15-ACB17-2BC2A13-ACB6ACB9-12AB7-14AB5-16AB3-2(18AB2-)4A12-2AB-5(5A12-3AB)-4A12-2A2(B2-18A)B3-16AB5-14AB7-12AB9-8A3B13-2AC2B15-3BC3A12-AC7ACB9-12AB7-14AB5-16AB3-18AB2-18AB-7(5A12-3AB)-18AB2-18AB3-16AB5-14AB7-12AB9-9A2B12-3AC3B14-7C12-2C7A2C9-C11AC7-C13AC5-C15AC3-C17AC2-C17AC-C6(4A12-3A2C)4A12-3AC-C17AC2-C17AC3-C15AC5-C13AC7-C11AC9-2C7A2C12-7C14-3AC3B12-BC7ACA9-B12A7-B14A5-B16A3-B18A2-B18A-7(B4A12-4A)-B18A2-B18A3-B16A5-B14A7-B12A9-2B9A12-3BC3A15-2AC2B13-BC6ABCA9-B12A7-B14A5-B16A3-2(B18A2-)B3A12-3A-5(B4A12-4A)-B3A12-3A2(2-B18A)3-B16A5-B14A7-B12A9-3B8A13-2BC2A17-ACB15-C5A2BC10-2B11A7-B14A5-B16A4-B16A3-B18A2(2-B3A12-3A)-3(B4A12-4A)-2(B3A12-3A2-)B18A3-B16A4-B16A5-B14A7-2B11A10-3B6A15-BCA37-3AC3B12-BC7ACA9-B12A7-B14A5-B16A4-B16A3-6(B3A12-3A2-)B3A12-3A3-B16A4-B16A5-B14A7-B12A9-B2C5A2CA12-7C57-2AC2B13-C7A2BC9-B12A7-B14A6-B14A5-B16A4-B5A9-2A3-4(B5A10-3A2-)B6A9-3A3-B5A9-2A4-B16A5-B14A6-B14A7-BC11A9-C7A2BC13-2AC2B78-3AC3B11-C9A2BC8-C11AC7-B14A6-B14A5-B5A9-4(2A4-B4A10-)2(2A4-B5A9-)2A5-B14A6-B14A7-C11AC8-C9A2BC11-3AC3B119-3AC3B12-9A2B8-C11A2BC6-C12AB3(C6-C4A5-4A)C6-C4A9-3(C6-C4A5-4A)C6-C12ABC6-C11A2BC8-9A2B12-3AC3B161-3AC3B13-7A2B11-9A2B9-4A5-2A2B5(8-4A5-3AB)8-4A5-2A2B9-9A2B11-7A2B13-3AC3B204-2AC2B15-3AC3B13-3A3-3B11-3A5-3B3(10-3A5-A2B)10-3A5-3B11-3A3-3B13-3AC3B15-2AC2B269-ACB17-2AC2B15-2(3AC3B14-)3AC3B15-2AC2B17-ACB156-
