model
size = 4 27 25, scale = 0.05, origin = -y
material deform = 1, fade = true, lighting = smooth, roughness = 0.3, metalness = 0.6
  colors = A:#F8C3CD B:#EEE C:#FFC408 D:#111 E:#BBB F:#F4A7B9 G:#4A225D
voxels
44-2AD8AFC3ACA3CACD2(CA)72-2B2AC3A28-D3A3DA56-BE5BA44-AB3AB2A44-4B60-3BA36-3BA68-4B28-AB2A72-4DBE2B24-AB2A76-3BA20-3DA84-2B2A16-D3A84-C3A12-2(CA)92-2ADA8-CACD92-4A8-CA2C92-3AF8-C3A92-C3A8-3AF92-CA2C8-4A92-CACD8-2ADA92-2(CA)12-C3A84-D3A16-2B2A84-3DA20-3BA76-AB2A24-4B76-AB2A28-4B68-3BA15-2A-10A5B2G5B60-4B32-BE10BAB3AB2A44-3BABE2B56-3DAD3A28-C3A2B2A72-3(CA)CDCA3C6AF6ADA36-
