model
size = 26 10 22, scale = 0.05, origin = -y
material deform = 1, fade = true, lighting = smooth, roughness = 0.3, metalness = 0.6
  colors = A:#CF0 B:#F60 C:#EEE D:#111
voxels
35-4A23-2A205-4A23-2A228-10A2B15-8A19-6A22-2A175-12A2B13-10A16-10A18-6A21-4A147-14A3B9-14A13-12A15-10A17-8A20-4A120-16A3B7-16A11-14A13-12A15-10A17-8A20-4A93-6A6-6A3B6-16A10-16A11-14A13-12A15-10A18-6A22-2A67-6A8-6A3B4-6A6-6A8-18A9-16A11-14A13-12A15-10A18-6A65-6A8-6A4B2-7A6-7A7-18A9-16A10-16A11-14AC13-12AC14-8A21-2A41-5A10-5A5B-5A10-5A6-5A10-5A7-4A10-4A9-3A10-3A11-2A10-2ACD11-13AC13-10A19-4A39-6A10-5A5B-5A10-5A6-5A10-5A7-4A10-4A8-4A10-4A9-3A10-2AC11-14AC13-10A18-6A38-2(6A10-5A5B6A2(10-5A6-5A)10-5A7-4A10-4A9-3A10-3A11-14A13-12A16-8A21-2A14-)6A10-5A5B-5A10-5A6-5A10-5A7-4A10-4A8-4A10-4A9-3A10-2AC11-14AC13-10A18-6A39-5A10-5A5B-5A10-5A6-5A10-5A7-4A10-4A9-3A10-3A11-2A10-2ACD11-13AC13-10A19-4A40-6A8-6A4B2-6A7-7A7-6A2-10A9-16A10-16A11-14AC13-12AC14-8A21-2A41-6A8-6A3B4-5A7-6A8-6A2-10A9-16A11-14A13-12A15-10A18-6A66-6A6-6A3B6-5A2-9A10-16A11-14A13-12A15-10A18-6A22-2A69-16A3B7-16A11-14A13-12A15-10A17-8A20-4A95-14A3B9-14A13-12A15-10A17-8A20-4A122-12A2B13-10A16-10A18-6A21-4A149-10A2B15-8A19-6A22-2A170-
