model
size = 18 22 18, scale = 0.05, origin = -y
material deform = 1, fade = true, lighting = smooth, roughness = 0.3, metalness = 0.6
  colors = A:#006 B:#FF0 C:#BBB D:#EEE
voxels
7-6C31-18(2A16-)2A14-6C32-18(2A16-)2A14-6C12-6C30-18(6A12-)6A11-C6AC10-8C12-4A12-17(8A10-)A6BA10-A6BA9-CA6BAC8-2C6-2C10-2A2-3A9-17(10A8-)A8BA8-A8BA7-CA3BD2BDBAC6-2(2C8-)2A5-2A7-17(12A6-)A10BA6-A10BA5-CA10BAC4-2C10-2C6-2A7-2A5-17(14A4-)A12BA4-A12BA3-CA12BAC2-2C12-2C4-2A9-2A3-17(16A2-)A14BA2-A14BA-CA2BDBD2BD6BA3C14-2C2-2A11-A3-17(16A2-)A14BA2-A14BA-CA3BD5BD4BA3C14-2C2-A12-A2-308A14B4A7B-6B2ACA6BDBD3BDBA3C14-2C2-A12-A2-308A14B4A14B2ACA14BA3C14-2C2-A11-2A3-17(16A2-)A14BA2-A14BA-CA2BDB2DBD6BA3C14-2C2-2A9-2A4-17(16A2-)A14BA2-A2B-9B-BA-CA14BA3C14-2C3-2A7-2A6-17(14A4-)A12BA4-A2B-7B2-A3-CA3(2BD)3BAC2-2C12-2C2(5-2A)8-17(12A6-)A10BA6-A2B-5B2-A5-CA3BD6BAC4-2C10-2C7-2A3-2A10-17(10A8-)A8BA8-AB7-A7-CA8BAC6-2C8-2C9-5A12-17(8A10-)A6BA10-A6BA9-CA2BD3BAC8-2C6-2C28-18(6A12-)6A11-C6AC10-8C5-
