model
size = 15 8 32, scale = 0.05, origin = -y
material deform = 1, fade = true, lighting = smooth, roughness = 0.3, metalness = 0.6
  colors = A:#FFAB70 B:#8F8F8F C:#EFEFEF D:#C6FFFA E:#BFBFBF F:#9F9F9F G:#C6FFE2 H:#C6FFCA
voxels
3-5BD3-H94-5BF3-F9-DED11-D3-D128-ED5-DC125-D9-C109-D9-D109-C9-D108-D11-C107-D11-D107-D11-E122-E11-D107-D11-E107-F11-D107-D11-D122-C11-C107-E11-E108-G9-G109-E9-C110-E7-G127-G5-C114-E3-G115-2E-CE116-FCG113-F3BDEB2A2BDF2-D3B2D3-2B2D91-FC3ACDB2ABACF-DC3ACD3-BACD91-F3ACA2B2ABCABDC3ACAB3-BCAB90-B2ABC2A2BACB2ADB2A-C2AB3-B2AD90-BACB2AD2BCABACDBHC-3AB3-BACD90-BCA6B2AB2C2BCA8-B2CB90-B2ABA2C2BACBCA2B2A-A2CB3-BCAB90-B2AB2CAB2DCB2AFB2A-2CAB3-B2AD90-BA2C3A3B3AB-BA2C3AB3-2AB92-DC4AB2-BAB3-DC4AB3-AB2-
