model
size = 15 8 32, scale = 0.05, origin = -y
material deform = 1, fade = true, lighting = smooth, roughness = 0.3, metalness = 0.6
  colors = A:#FCD200 B:#EFEFEF C:#DFBA00 D:#FFE770 E:#A68A00 F:#FFDE36 G:#FFD91A H:#FFE253
voxels
3-5CF3-F94-6C3-C9-A2F11-G3-D128-BA5-AB125-D9-F109-A9-B109-F9-A108-F11-H107-B11-A107-A11-H122-A11-H107-A11-B107-B11-B107-G11-G122-D11-B107-A11-A108-D9-D109-G9-A110-A7-D127-F5-A114-B3-B115-GB-BG116-GBF113-2C2B4CD2(BC)2-B2C3B3-EC2B91-CB3AB2CD2(AB)C-FB2ADBF3-EABF90-CB3ABA2C2A2BACFB2AD2BC3-EBAC90-C2AEB2A2CA2B2A2CAB-B2AC3-E2AB90-CABE2AB2CD2(AB)2CAB-2ABC3-EABF90-CBA5EC2A3B2C2B8-E2BD90-C2AEA2B2CAD2BA2CBA-ADBC3-E2BC90-C2AE2BA2C2DB2A2C2A-2BDC3-EBAC90-CA2B3A3C3AC-CA3B2AC3-BAC92-CB4AC2-CAC3-FDB3AC3-AC2-
