model
size = 8 7 17, scale = 0.05, origin = -y
material deform = 1, fade = true, lighting = smooth, roughness = 0.3, metalness = 0.6
  colors = A:#F0C B:#330 C:#AAA
voxels
42-4A4-4A12-3A4-4A20-A3-2A2-A4-A2-5A3-5A2-6A16-A-A5-3A5-A2-5A2-7A-7A9-A5-3A6-A8-3(7A-)2A5-2A6-A7-A8-2(7A-)8ACA4-ACA6-A17-6A-7A-10A4-4A4-A-2A4-2A-A8-5A2-6A3(-7A)2-6A3-4A12-4A2-7A2-6A-7A3-4A12-3A4-5A2-7A2-4AB2A-6A4-2A12-5A2-7A-7A2-B6A2-5A17-3(7A-)2A3(BA)4(-A)16-2(7A-)9AB7A-5A17-2(7A-)8AB2ABAB2(2A-)A-2A17-6A-7A-9A2(B2A)B2-2A2(-A)17-2(6A2-)A2(B2A)-2B5A-2A-3A27-4A3-6A2-3(AB)4-A-A18-
