model
size = 6 10 16, scale = 0.05, origin = -y
material deform = 1, fade = true, lighting = smooth, roughness = 0.3, metalness = 0.6
  colors = A:#222 B:#EEE C:#DDD D:#BBB E:#555 F:#777
voxels
7-4B2-4C3-2B40-3B9(3-3A)2-2(BC)B-5A-A3-A2(-5A)-2(4A2-)5(A2-)A-2(BD)2B2A2-3A4-3A2(2-2A-A)2-2A-B2-AB-B3-B-A3-A6-2B2(DB)2A3-4(2A4-)AB4-2B4-BA4-A6-2(BD)2BA7(4-2A)4-A6-2B2(DB)2A2-3A4-3A2-4A2-2AE3-AEA3-2AE4-EA4-A6-2(BD)2BF6A4-13A-4A2-2B2C2(2-4A)3-2A2-2B2(DB)AB5A4-7A-B3C31-2(BD)2B7A4-7A36-2B2(DB)F6AB3CA-B2CB37-2(BD)2B12A42-2B2(DB)7AB3CA42-2(BD)2B12A42-2B2(DB)6C6B42-2(BD)2B-4C2-4B43-
