model
size = 13 3 21, scale = 0.05, origin = -y
material deform = 1, fade = true, lighting = smooth, roughness = 0.3, metalness = 0.6
  colors = A:#553A2A B:#1C150B C:#5B544A D:#664731
voxels
34-2AD2-3B30-D2A3-B-C31-2AD2-7(B-C31-2B3-)B-C5-2A10-4A10-2(2B3-B-C4-4A8-6A9-)2B3-B-C5-2A10-4A10-2B3-B-C4-4A9-4A10-2B3-3A4-4A8-2A2-2A16-A3-6A6-A-A2-A-A15-A3-6A6-A-4A-A8-2B5-D3-6A6-8A20-4A8-6A22-2A10-4A15-
