model
size = 18 25 31, scale = 0.05, origin = -y
material deform = 1, fade = true, lighting = smooth, roughness = 0.3, metalness = 0.6
  colors = A:#111 B:#FFF C:#3C3 D:#930 E:#222 F:#888 G:#AAA
voxels
62-2A16-2A412-2A52-2A376-2A88-2A340-2A52-2E16-2E52-2A322-2A52-2E14-CF2EF2(C12-C4-)C12-C-2A-C12-C4-C12-6C302-2A88-2A52-2C16-2C304-2A52-2A88-2C322-2A16-2A106-2C16-2C448-2C16-2C140-6D302-2C16-2C122-6D320-2C6(16-2A)14-6D338-2C16-2C86-6D230-2(2A16-)2A88-2C16-2C69-4D195-2(2A16-)3(2B16-)2A16-2A70-2C3(16-2A)15-4D177-2A2(16-2B)70-2(2B16-)2A70-2C52-2D160-2A16-2B142-2B16-2A70-2C178-2A16-2B178-2B16-2A70-2C142-2A16-2B214-2B16-2A52-2C124-2A16-2B250-2B16-2A34-2C124-2A16-2B250-2B16-2A52-2C26-D16-D44-2A16-2B142-2E142-2B16-2A34-2C26-D2B12-2BD44-2A16-2B124-2E14-2F2G2F12-C-2E-6(C12-C4-)C12-C-2B-C12-C-2A-C12-C4-C12-6C14-2C8-D-2B4-2C4-2B-D3-2B3-2C3-2B9-6B14-2A16-2B142-2E142-2B16-2A84-2B6-2B9-2B4-2B31-2A16-2B250-2B16-2A160-2A16-2B250-2B16-2A178-2A16-2B214-2B16-2A214-2A16-2B178-2B16-2A250-2A16-2B142-2B16-2A286-2A2(16-2B)70-2(2B16-)2A322-2(2A16-)3(2B16-)2A16-2A376-2(2A16-)2A260-
