model
size = 32 27 18, scale = 0.05, origin = -y
material deform = 1, fade = true, lighting = smooth, roughness = 0.3, metalness = 0.6
  colors = A:#222 B:#91989F C:#77428D D:#EEE E:#AAA F:#FBE251 G:#86C166 H:#CA7A2C I:#00AA90 J:#1E88A8 K:#3A3226 L:#E83015 M:#D0104C N:#0B346E
voxels
548-3A28-2A3CA2(26-AC3AC)2(26-ACD2AC)26-AC2DAC27-A3CA28-3A572-3A28-2A3CA2(26-AC3AC)2(26-ACD2AC)26-AC2DAC27-A3CA28-3A478-A30-2A14-A14-3A14-2A12-5A13-4A8-B8A10-A4C8-9A10-C4A2(C7-9A10-CD3A)C7-B8A10-CD3AC7-B8A10-ACDAC9-8A11-A2C11-6AB12-B13-A4BA88-B3AB13-B2AB11-B2A14-B2AB12-2A15-2BA13-2A16-A13-BA16-2A12-BA17-2A11-2A17-AB11-AB17-BAB10-BAB16-BA11-ABA15-2AB10-4A14-3A11-B3A13-B2A12-B3A12-B2A13-B3A12-4A11-2B3A12-5AB8-7A11-6A7-9A10-6A7-9AB6AB8A6-18AB8A5-B12A2B3AB8A5-12AB2AB3AB7A5-11A2(B3A)B7A6-9AB5AB3AB5AB7-15AB3A5BA8-AB6A87-5A13-4AB11-2A15-3A12-2A15-3A13-2A16-A13-2A16-2A12-2A17-2A11-2(2A17-3A10-)3A16-2AB10-3A15-3A10-4A14-3A11-4A13-3A12-4A12-3A13-4A12-4A11-5A12-6A8-7A2-8A-7A6-10A6B10AB2(4-28A4-B27A)4-B26AB4-B27A5-26AB6-AB22A72-5A13-B2AB12-2A14-B2AB12-2A15-2B2(A13-2A16-)2A12-2(2A17-2A11-)2A17-3A10-3A16-2A11-3A15-3A10-4A14-2AB11-4A13-2AB12-4A12-2AB13-4A12-3AB11-5A12-6A8-7A2-8A-7A6-27A2(4-B26AB4-27AB)2(4-28A)5-26AB5-AB24A8-5A3-3(B3A)BA41-B3AB28-B2A30-2A31-B31-A2(31-B)31-A31-BA30-ABA28-4A2(28-B3A)28-4A12-3AB11-5A12-6A8-7A2-8A-7A6-26AB4-28A4-B27A4(4-28A)5-27A5-B25A7-7A-3(B3A)B2AB9-5A475-B4A13-5A8-7A2-8A-7A6-26AB4-B26AB2(4-28A)2(4-27AB)4-28A5-27A5-B25AB6-7A3(B3A)B4A9-A3EA506-7A2-8A-7A6-6(27A4-B)2(27A5-)B26A6-7A3(B3A)B4AB8-2(AE)A407-M31-L30-LH30-2H3-6A2-8A-7A3-HF-27A-H2F28A-2FG28A-F2G28A-2GI28A-G2I28A-2IJ28A-2J2-27A2J3-27AN5-B6A3(B3A)B4AB8-2(AE)A407-M31-L30-LH30-2H3-6A2-8A-7A3-HF-27A-H2FAK26A-2FGAK26A-F2GAK26A-2GIAK26A-G2IAK26A-2IJAK26A-2J2-27A2J3-27AN5-B6A3(B3A)B4AB8-2(AE)A506-7A2-8A-7A6-6(27A4-B)2(27A5-)B26A6-7A3(B3A)B4AB8-2(AE)A475-B4A13-5A8-7A2-8A-7A6-26AB4-B26AB2(4-28A)2(4-27AB)4-28A5-27A5-B25AB6-7A3(B3A)B4A9-A3EA26-B3AB28-B2A30-2A31-B31-A2(31-B)31-A31-BA30-ABA28-4A2(28-B3A)28-4A12-3AB11-5A12-6A8-7A2-8A-7A6-26AB4-28A4-B27A4(4-28A)5-27A5-B25A7-7A-3(B3A)B2AB9-5A26-5A13-B2AB12-2A14-B2AB12-2A15-2B2(A13-2A16-)2A12-2(2A17-2A11-)2A17-3A10-3A16-2A11-3A15-3A10-4A14-2AB11-4A13-2AB12-4A12-2AB13-4A12-3AB11-5A12-6A8-7A2-8A-7A6-27A2(4-B26AB4-27AB)2(4-28A)5-26AB5-AB24A8-5A3-3(B3A)BA41-5A13-4AB11-2A15-3A12-2A15-3A13-2A16-A13-2A16-2A12-2A17-2A11-2(2A17-3A10-)3A16-2AB10-3A15-3A10-4A14-3A11-4A13-3A12-4A12-3A13-4A12-4A11-5A12-6A8-7A2-8A-7A6-10A6B10AB2(4-28A4-B27A)4-B26AB4-B27A5-26AB6-AB22A72-B3AB13-B2AB11-B2A14-B2AB12-2A15-2BA13-2A16-A13-BA16-2A12-BA17-2A11-2A17-AB11-AB17-BAB10-BAB16-BA11-ABA15-2AB10-4A14-3A11-B3A13-B2A12-B3A12-B2A13-B3A12-4A11-2B3A12-5AB8-7A11-6A7-9A10-6A7-9AB6AB8A6-18AB8A5-B12A2B3AB8A5-12AB2AB3AB7A5-11A2(B3A)B7A6-9AB5AB3AB5AB7-15AB3A5BA8-AB6A475-A30-2A14-A14-3A14-2A12-5A13-4A8-B8A10-A4C8-9A10-C4A2(C7-9A10-CD3A)C7-B8A10-CD3AC7-B8A10-ACDAC9-8A11-A2C11-6AB12-B13-A4BA86-
