model
size = 11 15 5, scale = 0.05, origin = -y
material deform = 1, fade = true, lighting = smooth, roughness = 0.3, metalness = 0.6
  colors = A:#352C27
voxels
23-A21-3(A6-A14-)A5-2A9-A4-3(A-)A37-A9-2A10-A9-2(2A6-A3-A6-2A-)3A5-A3-A5-2A2-2A5-3A2-2A4-A4-8A5-2A43-A2-A6-6A4-8A2-9A3-9A2(2-8A)4-8A2(3-7A)5-6A-A4-2A2(-A)6-A-A13-A2-2A4-3A3-A4-A5-2A-3A6-5A-A6-2A7-2(A2-)A8-A6-A-A11-A-A5-A12-A-A7-A14-A49-2(A2-)A8-A-A6-A104-
