model
size = 18 8 9, scale = 0.05, origin = -y
material deform = 1, fade = true, lighting = smooth, roughness = 0.3, metalness = 0.6
  colors = A:#001 B:#036 C:#960 D:#222 E:#0F6 F:#444 G:#555 H:#111 I:#EEE
voxels
3-15C5(3-15A)38-16C2-16A2(2-2A14B)2(2-AF14B)3-G14D19-17C-2A-14A2(-2A14-D)-A15-B-A-10B4-B2-G10B4-D3-12E3-18C3A-17A14-D3A14-D2A15-BAF2B13-B-G11B4-D2(3-E)-E4-E3-18C3A-17A14-D3A14-D2A15-BAF2B13-B-G2B4(HI)H4-D3-3E-E-3E2-E3-18C3A-17A14-D3A14-D2A15-BAF2B13-B-G11B4-D5-2(E-)2(E4-)17C-2A-14A2(-A15-D)-A15-B-A-10B4-B2-G10B4-D3-3E-E-6E5-16C2-16A2(2-A-14B)2(2-AF14B)3-G14D21-15C5(3-15A)36-
