model
size = 32 8 19, scale = 0.05, origin = -y
material deform = 1, fade = true, lighting = smooth, roughness = 0.3, metalness = 0.6
  colors = A:#FF6 B:#FF9 C:#9F6 D:#963
voxels
64-2(4D28-)4D189-3A28-2A-D29-CDC189-C2A29-A-A29-3C189-DCA29-3AC28-D2C190-2C29-3AC28-4C189-CAC29-2AC29-B2C189-2CB29-A-2A28-B2AB29-CB126-CAB28-3A2B27-A-3A27-B4A27-B2ACB28-2A93-AB2AB26-3A-2AB20-3B2-2A3-2A17-6AD-2A3-2A17-6AB2-6A18-2A3B3-4AB91-AB3A2B15-4B5-2A3-3AB12-8AB2-A5-3A11-8A2(-2A)4-3A11-6A3-AD-BA3-4A12-10A2-5A2B15-A4BA38-B3A26-7A2B10-3B5A4-2A5-3ABA5-7A2-2A2B2-A7-6A-7A7-AD-A7-6A-7A7-2A-BA5-5A5-7A4-2AD2-B5A2BA9-10A6-4A15-3B2A8-B6A10-6A7-3A2-4A10B7AB4-2A7-12A6-ABA2(2-2A9-7A10-2A)2-3A6-11A8-AB3-B2A2-5AB11A3-3A6-5A3B7-4B5A8-B22A7-4A4-12A4-A2B5-2A24-2A2(4-A26-A)4-BA24-2A5-BA6-9A7-2AB6-8A7B9A9-B20AB8-4A18-4A5-3A22-3A2(4-2A24-2A)4-3A22-3A5-B2A20-2AB7-24A10-B18AB10-AB2A16-2ABA7-3A20-3A2(6-2A22-2A)6-3A20-3A7-B2A18-2AB9-22A12-B15A2B12-AB3A11-6A9-4A16-4A8-3A18-3A8-3A19-2A8-3A17-4A9-B3A13-3A2B11-20A15-2B10AB17-2B13A2BA13-4A11-5A11-4A14-4A10-3A15-2(4A11-)6A11-2B6A3-6A2B15-15A50-A12B18-16A15-6A5-7A14-5A7-6A14-AB11ABA2B17-3B9AB23-5A90-7A23-11A21-11A22-9B76-
