model
size = 31 29 19, scale = 0.05, origin = -y
material deform = 1, fade = true, lighting = smooth, roughness = 0.3, metalness = 0.6
  colors = A:#FF9 B:#F66 C:#F33 D:#9CF E:#FCC F:#EEE G:#001 H:#F69 I:#FFF J:#9F9 K:#F0C L:#F30 M:#3FF N:#3C6
voxels
43-7B23-12B18-4B4-7B16-3B8-5B15-3B10-4B28-2(3B29-)3B28-2(3B29-)3(2B29-)2B28-3B28-2B28-2(3B27-)2(4B26-)4B27-2B206-6B23-2B6A4B18-B12A2B16-B3A5B6AB15-B2AB5-2B5AB14-4B7-2B3(3AB27-B)2(2AB28-B2AB27-B)2(2AB27-B)2AB26-B2AB27-2(B2AB26-)3(B3AB25-)B3AB26-BA2B27-2B176-7B22-2B7A4B17-B13AB16-B3A4B7AB15-B2AB4-3B5AB14-4B7-2B4AB26-3(B3AB27-)B2AB27-B3A3(B27-B2A)B27-BA2(JB26-B2A)B26-2(B3AB25-)2(B4AB24-)B4AB25-B2A2B26-3B175-7B22-2B7A4B17-B13AB16-B3A4B7AB15-B2AB4-3B5AB14-4B7-2B4(3AB27-B)2AB28-BAB28-3(B2AB27-)BAJB27-BAB27-B2AB26-3(B3AB25-)B3AB26-B2AB26-BA2B27-2B176-7B22-2B7A2B19-B3A4B2A4B17-B2AB4-7B16-B2AB7-5B15-4B9-4B28-3(3B29-)2B29-3B5(29-2B)28-5(3B27-)3B28-2B199-14B17-5B8AB17-4B9AB17-4B4A4BAB2(17-4B4A6B)2(17-14B)17-13BH2(17-14B)18-12B19-12B20-10B116-6B24-3(8B23-)8B24-2B2C2B201-26B5-6B14A6B7-3(4B14A4B9-)4B14A4B10-3B14A3B13-B14AB15-B13A2C15-B14AB15-B14AC15-2B12A2B15-2B12ABC16-2B10A2B3(17-14B)18-3B6A3B4(19-2B8A2B)19-3B2A2C2A3B20-2BCB2CBC2B22-BCB2CBCB138-26B5-2B22A2B7-4(B20AB9-)2B18A2B11-B16AB13-C14A3C14-B14AB15-4C11AC15-B14AB15-3C10A3C15-B14AB16-8(B12AB17-)B5A2C5AB18-B4A2CAC2AB19-2BACA2CACA2B21-BCB2CBCB107-26B5-2B22A2B7-4(B20AB9-)2B18A2B11-B16AB13-4C11A3C14-B14AB15-4C11AC15-B14AB15-3C10A3C15-B14AB16-8(B12AB17-)B5A2C5AB18-B4A2CAC2AB19-2BACA2CACA2B21-BCB2CBCB107-26B5-4B18A4B7-3(2B18A2B9-)2B18A2B10-B18AB12-B16AB13-4C11A3C14-B14AB15-4C11AC15-B14AB15-3C10A3C15-B14AB16-8(B12AB17-)B5A2C5AB18-B4A2C4AB19-2BACA2C3A2B21-BCB2CBCB111-18B7(13-B16AB)13-4C11A3C14-B14AB15-4C11AC15-B14AB15-3C10A3C15-B13ADB16-8(B12AB17-)B5A2C5AB18-B4A2C4AB19-2B3A2C3A2B21-BCA2CACB25-B2CB28-2CB29-B21-18B7(13-B16AB)13-4C11A3C14-B14AB15-4C11AC15-B14AB15-3C10A3C15-B13ADB16-6(B12AB17-)B4A4F4A2(B17-B5A2F5A)B17-B5A2C5AB16-2B4AF2CF4A2B15-5BCF2CFC5B15-4B2-B2CB2-4B15-4B3-2C3-4B15-2B12-2B14-18B7(13-B16AB)13-4C11A3C14-B14AB15-4C11AC15-BN13AB15-3C7D3A3C16-7(B4D8AB17-)B4D4F4A2(B17-B4DA2F5A)B17-B5A2C5AB16-BC4AF2CF4ACB15-B2CABCB2CBCBA2CB16-2CB3-C4-B2C16-B-2B8-2B-B15-2B12-2B14-18B5(13-B16AB)14-B13AJB15-B12A2JB15-3C10AJ2C15-B12A2JB15-4C10AJC15-BN13AB16-2C7D3A2C3(17-B4D8AB)15-2B5D9A2B14-B5D9AB15-B5D8AJB16-B4D8AB17-B4D4F4A2(B17-B4DA2F5A)B18-B4A2C4AB19-B3AF2CF3AB20-2BCB2CBC2B21-B8-B80-16B5(15-B14AB)15-B12A2JB16-3B8A3B17-2C2B6A2B2C17-4B6A4B17-3C2B4A2B3C17-14B18-C10BC19-5B2C5B18-14B17-BA3B4G3BAB15-6BGB2GBG6B14-BEC10BCEB15-B2CA3B2G3BA2CB16-BA3B4G3BAB17-B4F4B4FB17-BF3KF2BF3KFB17-BF2GKF2BFK2GFB18-BMG2F2C2FGMB19-2B2FB2CB2F2B21-BCB2CBCB112-4B8E4B5(15-B3A8E3AB)16-3B8E3B20-8E24-6E25-6E26-4E113-2G14-2G15-2G10-2G47-2(2G12-)3G2(3-G3-2G)15-G3-4G3-G16-3G-3I4-3I-3G16-I2LBI2-IB2LI19-I2GLI2-IL2GI19-5H2-5H20-3H4-3H142-4B8-4B15-B2AF8-F2AB2(15-4B8-4B)16-2(3B8-3B17-)3B8-3B698-5B6-5B15-5B6-5B852-5B6-5B15-2(B-)B6-2(B-)B847-
