model
size = 26 29 14, scale = 0.05, origin = -y
material deform = 1, fade = true, lighting = smooth, roughness = 0.3, metalness = 0.6
  colors = A:#6C3 B:#CF3 C:#FCC D:#001 E:#6C0 F:#FFF G:#FF9 H:#F6C I:#693 J:#9CF K:#FCF L:#A00 M:#EEE N:#E00 O:#B00 P:#0F6 Q:#F0C R:#3FF S:#FC9
voxels
31-5A6-5A10-2(A-)A6-2(A-)A687-10(14A12-)14A13-12A14-12A15-10A96-6A19-3(8A18-)8A19-6A166-52A2-3(22A4-)22A5-20A8-5(16A10-)16A11-3(14A12-)14A13-5(12A14-)12A15-10A17-8A113-52A2-4(22A4-)22A6-18A8-18A9-4(16A10-)16A11-8(14A12-)13A14-12A14-11A17-7A18-4E66-52A2-4(22A4-)22A6-18A8-18A9-4(16A10-)16A11-8(14A12-)8A4C15-7A4C15-6A4CH17-3AH3CHC16-4EK-K63-52A2-3(22A4-)22A5-20A7-18A8-18A9-4(16A10-)16A11-7(14A12-)10ACH14-10A2C15-6A6C14-6A5C17-3A2CH2C17-4EK2-K66-8(18A8-)18A9-4(16A10-)16A11-7(14A12-)10ACH14-10A2C15-6A5CH14-4A-7C16-2A3(HC)H16-3E3-K67-8(18A8-)18A9-4(16A10-)16A11-7(14A12-)2(10A2C14-)7A6C12-2A4G-6C13-6AHC2HCS14-3A3E-K3-K14-2A24-A24-8(18A8-)18A9-3(16A10-)16A11-10(14A12-)7A3-3CA11-A2I3G5-3C12-A2IE2A2CHC-C15-2I3EK-K17-A50-5(18A8-)18A9-5(16A10-)16A11-3(14A12-)14A10-18A9-16A10-16A11-3(14A12-)14A13-12A14-A9GA16-5A21-A3E71-6(16A10-)16A11-4(14A12-)4A6J4A13-3AO4J4A14-AB5AN3AB13-E3BNB2ONA3BA12-EG2BN2(DM)O4B10-3A3B3(DM)5BA9-ACI10BI2B10-B2I9BD2IB11-BG10BDB12-ABM11B12-AMQ11B12-AMD11B13-AR10B14-2A9B17-4B96-5(4A8B4A10-)4A8B4A11-3A8B3A15-2(8B18-)8B19-O5B20-6B21-3BN41-2D26-2D49-2D21-3D3-D3-2D19-D3-4D15-3D-3F4-3F15-F3LF2-F3LF14-F2DLF2-FL2DF14-FPD2F2-2FDPF15-3F4-3F117-3(4A8-4A10-)4A8-4A11-2(3A8-3A12-)3A8-3A583-5A6-5A10-5A6-5A707-
