model
size = 14 29 8, scale = 0.05, origin = -y
material deform = 1, fade = true, lighting = smooth, roughness = 0.3, metalness = 0.6
  colors = A:#111 B:#BBB C:#EEE
voxels
104-2A12-2A376-2A12-2A375-4(4A10-)4A277-2A11-4A9-2A2-2A8-A4-A10-2A11-4A9-3(6A8-)6A9-4A10-4A249-2A11-4A9-2A2-2A7-2A4-2A5-2(2A2-)2A7-4A9-6A7-8A7-6A8-6A9-4A10-4A11-2A11-C3B9-B4-B7-B6-C2(6-B)5-C8-B4-B8-B3-C10-B2-C10-B-B12-2B12-BC12-B-B10-B3-B8-C5-B6-B7-B4-B9-C3B11-2A11-4A9-2A2-2A8-A4-A10-2A11-4A9-6A7-8A7-6A8-6A9-4A10-4A11-2A292-2A11-4A9-3(6A8-)6A9-4A10-4A318-4(4A10-)4A271-
