model
size = 14 27 3, scale = 0.05, origin = -y
material deform = 1, fade = true, lighting = smooth, roughness = 0.3, metalness = 0.6
  colors = A:#BEC23F B:#FFC408 C:#FFFFFB D:#EEE
voxels
5-C2BC9-B4-B7-C3-B2-C5-B2-C4B-B3-B2-B3-C3-B2-C3-4B3-C2(2-B)3(3-B)2-BC3B-B5-C3-B2-C7-B4-B9-C2BC234-4A9-6A7-8A5-10A3-2(12A2-)12A3-10A5-8A7-6A9-4A10-3AB9-B4-A7-C3(6-A)5-B8-A4-A8-A3-B10-B2-C10-A-A12-CA12-2A12-B-B10-A3-C8-B5-A6-A7-A4-B9-AB2A10-D2BD9-B4-B7-D2-B3-D5-B-4BD2-2(B3-)D3-2(B2-)D3-5B2-D2-2(B3-)B2-B3-B-3BDB2-B5-D2-B3-D7-B4-B9-D2BD229-
