model
size = 22 28 22, scale = 0.05, origin = -y
material deform = 1, fade = true, lighting = smooth, roughness = 0.3, metalness = 0.6
  colors = A:#C90 B:#999 C:#996 D:#9C9 E:#CC9 F:#C66 G:#F60 H:#C63 I:#993 J:#990 K:#696 L:#C33 M:#963 N:#AAA O:#C93 P:#966 Q:#663 R:#C96 S:#399 T:#099 U:#396 V:#888 W:#693 X:#933 Y:#699 Z:#444 Aa:#C30 Ab:#936 Ac:#690 Ad:#E00 Ae:#666 Af:#C00 Ag:#F63 Ah:#777 Ai:#C99 Aj:#C36 Ak:#D00 Al:#CC6 Am:#F90 An:#F33 Ao:#C60 Ap:#969 Aq:#369 Ar:#F00 As:#960 At:#366 Au:#363 Av:#C69 Aw:#CC3 Ax:#930 Ay:#F30 Az:#669 Ba:#333 Bb:#360 Bc:#9CF Bd:#CC0 Be:#555 Bf:#C03 Bg:#639 Bh:#909 Bi:#633
voxels
30-3AJ2A16-2QAZMA16-2QAZQA16-2MA2MJ16-6I2(16-6C)16-2I3CK16-A5C16-3O2IC16-CW4I16-W2BbWMAh16-K2WCOI16-K2IC2K16-S2KAeFN16-K2AuAeFR16-AhBbQ2PF16-P2QPAbF16-F2C20-RF173-AJ4A16-2(A2Q)16-JZQA2Z16-JQJA2M16-IO2AAoM16-2AGAyLAe16-AAo2AaXAe16-AcWUSTS16-XLBeAbXH16-AdArAdAk2Ar16-LXAtBeLAj16-I2SApAhAe16-STSAeLAk16-PAeXAkAaH16-AeAfArAa2Ac16-AtAkAdAs2Ac16-HAyAoJ2Ac16-3FI2Ac16-3B20-VF192-3A6-2AJ10-3A6-2AZ10-3A6-2QBa10-A2J6-AMQ10-2IO6-2IW10-O2A6-3T10-3J6-K2I10-AJAc6-KAJ10-2JM6-2AJ10-AsAaAy6-L2M10-GAmAo6-2FAj10-2AmA6-2LAj10-H2F6-L2F10-BVF6-IMAh10-BVAh6-IPS10-FCT6-K2Aq10-A2K6-UTAh10-CVR6-WUT11-DBR6-2U11-BDB20-BDBF19-3Ap21-Bh125-A12-A8-A12-J2(8-A12-A)8-K12-O8-M12-I8-J12-H8-A12-H8-J12-A8-As12-A8-Ad12-O8-Am12-O8-O12-H2(8-B12-M)8-F12-O8-Am2F10-O8-C2FC9-I8-2BFC9-I8-2DBC9-A9-2BAz20-SAz21-BVBgAq19-EBAq102-3(A14-A6-)J14-A6-K14-A6-M14-Ag6-J14-H6-J14-An6-A14-A6-J14-A6-Ak14-A6-G14-A6-O14-H2(6-B14-Ag)6-F14-A6-OF13-Bd6-CF13-A6-B2F12-A6-D2B12-Ag7-2B12-H7-AhS21-TYAz20-2E22-ENY79-J16-A4-Z16-Aw4-Ba16-E4-Q16-Al4-K16-A4-M16-An4-Ac16-A4-J16-Ag4-A16-H4-A16-A4-Ax16-A4-Ao16-A4-O16-L4-B16-A4-B16-H4-F16-H4-2F15-A4-B2(F15-A4-D)B15-An5-B15-O5-C15-E6-2T21-T22-B2ENY19-CKU56-A18-A2-J18-Al2(2-M18-E)2-K18-O2-X18-An2-Ac18-A2-W18-Ag2-A18-H2-A18-A2-M18-A2-Ae18-A2-O18-L2-D18-A2-B18-H2-F18-H2-2F17-A2-BF17-A2-DBcF16-A3-DB16-Ag3-2B16-O4-C16-E4-2T21-T22-T2B21-YCKW21-W34-A18-A2-Am18-Al2(2-A18-E)2-K18-O2-X18-An2-Ac18-A2-K18-Ag2-A18-H2-I18-A2-J18-A2-U18-A2-C18-L2-B18-A2-B18-H2-Ap18-H2-Av18-A2-B2(Av17-A2-D)B17-Ag3-B17-O3-C17-E4-N21-B22-3B21-BY22-WQW34-A18-A2-A18-Aw2-A18-E2-A18-Al2-K18-A2-L18-An2-As18-A2-U18-Ag2-O18-H2-K18-A2-J18-A2-U18-A2-K18-L2-N18-A2(2-B18-H)2-B18-2(A2-2D17-)A2-BD17-Ag2-VD17-O3-P17-E3-2N16-E4-Ai22-2N21-NB22-3SW33-J20-HBi20-AQ20-AwM20-AW20-ABf20-LAx20-AU20-HM20-HK20-AJ20-AU20-AS20-LN20-AD2(20-HB)20-Bd2(D20-A)-V19-An-P19-O-C19-N2-Ai18-N2-E18-N3-2E21-2E22-4AiW20-TU11-A2(20-HQ)20-AM20-AW20-HAk20-HAx20-AU20-HX20-HAh20-AI20-AU20-HS20-H2(B20-A)D20-H2(B20-A)B20-HVB19-H-F19-O-H19-2(E2-H18-)E3-RG16-E4-2N22-3N21-2AuU11-A20-2A2(20-HJ)20-HK20-HBf20-AX20-AS20-AL20-HK20-HI20-HU20-HS3(20-AB)20-OD2(20-HB)20-HVB19-A-H19-O-G19-E-GH18-E2-G18-E3-2G16-E4-RG21-3R22-2RU11-A2(20-AQ)20-AM20-JK20-IL20-IX20-KAq20-VL20-EK20-EI20-ET20-ES3(20-ED)20-EB20-ED20-EB20-EVB19-E-H2(19-E-G)H18-E2-G18-E3-2G16-E4-HG21-3G22-2HAf11-A20-AQ20-MZ20-2M20-MC20-IAj20-IX20-AlAt20-EL20-EK20-EI20-ET20-ES2(20-EB)2(20-ED)2(20-EB)20-AiVB19-R-H19-F-G19-R2(2-Aa18-E)3-2G16-E4-2G22-3G21-GLAf11-A20-J2(A20-Z)A20-MC20-IP20-IX20-AlAe20-EAk20-EAh20-EI20-ET20-ES20-EB20-ED20-EB20-ND20-CD20-FB20-F-C19-Aj-H19-Ad-G19-L2(2-Aa18-E)3-2G21-2G22-2AoRLAf20-LAf12-J18-A2-Z18-A2-Q18-A2-M18-A2-K18-I2-Ah18-I2-X18-Al2-Ae18-E2-Ak18-E2-Ah18-E2-I18-Al2-T18-E2-Y2(18-E2-D)18-Ai2-D18-R2-D18-P2-2D17-Ab2-2B17-P2-PC17-Aj2-2G17-Ad3-G17-L3-2G16-E4-G22-2G21-2G22-NRLAf34-A2(18-A2-Q)18-A2-M18-A2-K18-I2-Ap18-I2-L18-C2-L18-Y2-L18-C2-Y18-C2-C18-C2-U18-N2-Y18-C2-D18-C2-B18-P2-B18-Ab2-B18-F2-2D17-F2-BD17-P2-PG17-L3-G17-Ad3-G17-L4-G21-G22-3G21-GN22-RLAf34-2(A18-A2-)J18-A2-J18-As2-K18-I2-Ap18-C2-Aj18-K2-Ar18-S2-X18-C2-Y18-C2-B18-I2-Y18-R2-Y18-E2-B18-N2-B18-F2-D18-P2-2D17-Ab2-2D17-P2-BBcD16-F3-PD16-Aj3-2G16-Ad4-G16-X4-2G21-G22-G2R21-NRLAa21-Af35-A16-A4-A16-Z4-J16-Ba4-J16-Q4-K16-I4-Aq16-C4-F16-K4-Ad16-S4-X16-K4-Y16-C4-D16-I4-D16-N4-B16-E4-D16-N4-B16-F4-D16-F4-BD15-F4-2D15-P4-BD15-Ab4-PD15-L5-H15-Ad5-G15-X6-2G21-G22-R3NAa19-RLAa58-A14-A3(6-A14-M)6-K14-I6-T14-C6-I14-K6-G14-S6-L14-K6-Y14-C6-B14-I6-D3(14-C6-B)14-P6-D14-Ab2(6-2D13-F)6-V2D12-F6-P2D12-L7-HG12-Ad7-2G21-GHC20-RN22-RLAa81-4(A12-A8-)O12-I8-K12-C8-I12-K8-Am12-S8-L12-K8-V12-C8-B12-O2(8-B12-C)8-D12-C2(8-D12-F)8-B2D10-P8-B2D10-Ab8-VF2D9-F8-3FP9-Aj9-HFC20-HC21-NRLAf19-RLAa104-J2A6-3A10-ZMA6-3A10-ZQJ6-3A10-2MJ6-J2A10-OHI6-3I10-AOC6-3C10-AIC6-3C10-A2C6-KYS10-OCO6-3C10-V2C6-3C10-DEC6-I2O10-BEN6-U2C10-BNAi6-At2C10-B2N6-At2C10-BDB6-V2P10-2DB6-FAbF10-2BV6-FAbF10-F2P6-Ab2F11-AbFD6-FP11-AbFP20-FAbLAd19-PLAf21-Af121-
