model
size = 32, scale = 0.05, origin = -y
material deform = 1, fade = true, lighting = smooth, roughness = 0.3, metalness = 0.6
  colors = A:#111
voxels
529-A24-A35-A830-A66-A163-A697-A32-A35-A25-A67-A26-A6-A26-A101-A25-A611-A56-A31-A3-A35-A34-A22-A27-A7-A25-A35-A3-A36-A16-A10-A23-A34-A572-A34-A32-A-A22-A28-A8-A23-A3-A39-A2-A22-A27-A7-A26-A27-A6-A3-A2-A32-A18-A8-A25-A-A22-A8-A28-A59-A8-A34-A378-A31-A29-A7-A18-A39-A-A22-A47-A13-2(A3-)A27-2A6-A25-A7-2A19-A3-4A7-A12-A5-A-3A23-A5-3A2(2-A)45-2(A6-)A26-A-A8-2A12-A38-A26-A40-A33-A57-A315-A8-A58-A-A5-A50-2A6-A33-A22-A8-A6-A11-A-A7-A24-A3-A-3A2-A25-5A3-A16-A3-A-7A6-A18-7A21-2A2-8A2-A13-A8-5A25-A2-3A-A19-2A5-A-A5-3A49-A3-A26-2A9-A2-A25-A2-A23-A30-A31-A3-A282-A31-2(A3-)A27-A31-A-A36-2A2-A16-A6-A56-A3-6A6-A11-A5-9A17-2A-A2-9A22-12A16-2A2-11A3-A17-11A20-12A-A14-A4-11A18-A3-9A23-9A-A4-A18-5A-A21-2(A4-)A28-A4-A53-A5-A60-A314-A32-A6-A25-3(A-)A25-A-A2-2A2(2-A)14-A2-3A-4A6-A19-8A2-2A18-13A12-A7-11A4-A12-A-14A19-13A17-18A15-15A3-2A12-15A11-2A-A3-13A17-15A20-12A4-A8-A6-11A16-A3-A-8A17-A6-A2-3A4-A21-A31-A5-A6-A28-A2-A21-A28-A226-A128-A10-A18-5A2-A22-10A17-A3-11A20-13A13-A4-18A10-2(A-)15A14-19A15-17A15-19A13-17A12-20A16-15A3-A13-15A13-A4-13A16-16A21-9A-2A3-2A17-5A4-3A13-A7-A2-A22-A5-A2-A3-A54-A189-A39-A27-A2-A28-A-2A5-A15-A6-A-A29-3A8-A17-9A5-A16-11A3-2A-A7-A2-2A-13A5-A11-16A16-17A15-17A14-18A10-A3-19A10-22A13-19A8-A5-17A15-20A9-20A16-17A16-13A2-3A14-12A20-A-9A18-2(A2-)A-3A2-2A4-A15-A2-A7-A23-A4-A31-A-A182-A32-A8-A19-A3-A7-A20-A2-A6-A19-A-A2-A6-A3-A12-2(A2-)A-8A22-11A20-13A2-A10-A4-15A16-17A2-2A11-17A14-19A13-19A3-2A8-22A10-19A13-19A9-23A13-19A14-17A15-17A2(16-15A)16-2A2-11A14-A8-7A6-A89-A21-A138-A24-A31-A4-A30-2A30-A27-5A4-A14-A-A2-11A-A14-18A17-17A14-17A11-23A12-19A8-2A3-19A9-24A11-21A6-A4-21A11-22A10-21A-2A9-19A2(4-A)3-19A8-A4-19A11-A2-17A4-A6-A4-17A9-A6-13A2-A11-A5-11A3-A14-2(A2-)5A20-A3-A4-A25-A5-A2-A28-A27-A2-A7-A90-A30-A3-A21-A2-A-A3-2A21-A2-A-A3-A18-A3-2A2(-A)3-A23-9A22-11A5-A13-15A16-17A15-17A14-19A12-21A11-21A4-A6-2(21A11-)21A6-2A3-2(21A11-)21A8-24A12-21A9-20A3-A9-19A13-A-16A14-A-A2-11A18-A3-10A23-A5-A-3A3-2A16-A5-A3-A20-2A9-A26-A88-A62-A12-A48-A6-3A22-3A-9A21-13A3-A9-A4-15A-2A13-18A13-19A3-2A8-22A9-21A11-25A7-21A10-23A9-26A4-25A3-A6-21A11-23A9-21A12-19A13-19A4-A9-18A15-15A-A16-13A2-A18-9A5-A20-3A23-A7-A22-A8-A31-A121-A32-2A31-2A7-2A22-5A3-A20-12A19-13A14-2A-17A13-19A5-A3-A4-19A12-2(21A11-)21A10-4(23A9-)23A7-24A2-2A3-A3-21A6-A4-22A11-19A2-2A10-17A10-A4-17A17-13A19-12A19-2A3-5A2-A19-A3-2A6-2A21-2A8-2A19-A12-A27-A57-A4-A26-A3-A2-2A24-2(A2-)A25-4A7-A18-7A6-A16-11A3-A15-16A2-2A11-17A2-A11-21A6-A4-20A8-A2-21A8-27A7-23A5-A3-23A3-2A-29A5-25A7-25A8-23A9-23A10-21A9-23A9-2(A2-19A10-)A2-18A4-A9-A-15A15-A3-11A-A14-A6-7A4-A12-A9-3A-A27-A3-2A26-A4-A91-2(A24-A6-)A4-A20-A4-3A2-2A15-A4-A2-8A17-3A-12A18-16A16-17A14-19A13-19A12-21A11-21A3-2A5-23A9-23A8-25A7-25A4-A2-27A-A-26A2-A6-25A8-21A11-23A10-19A13-22A10-18A3-A9-2A-15A19-11A23-7A5-A21-3A93-A92-A9-A21-A5-A25-A2-4A25-8A23-13A17-15A12-A3-20A9-21A4-A8-19A2-2A6-25A9-21A10-23A7-28A5-2(25A7-)25A8-23A9-23A-A5-24A3-A7-21A12-19A10-22A14-18A12-A2-15A-2A14-A-11A5-A13-2(A-)7A-A3-A14-A2-2(A-)3A3-A18-A4-2(A3-)A22-A5-A25-A5-A63-A24-A2-2A2-A28-A2-A3-A24-A5-A19-A4-5A2-A19-A-11A-A17-14A4-A7-A4-17A15-17A9-A4-19A9-2A-2(21A11-)21A6-3A-23A2-2A5-23A9-26A6-23A9-23A10-21A7-2A2-21A6-A4-21A12-21A7-A4-17A2-2A11-17A13-A3-13A20-11A24-5A24-A73-A88-A3-A27-A56-A32-2A5-3A5-A20-9A2-A18-13A5-A12-15A16-17A14-19A12-20A12-21A11-24A8-21A10-23A5-A3-23A6-28A8-21A11-24A8-21A12-19A13-19A14-2(17A16-)13A2-A12-A5-9A-A2-A19-A-3A-A2-A22-A-2(A3-)A21-A-A3-A4-A22-A31-A96-A4-A21-A4-A3-A22-2A4-A-A24-A4-A-A3-A-A18-9A4-A12-A4-11A3-A12-20A14-17A3-2A10-20A8-22A12-21A3-A4-24A2-A8-21A11-24A3-A4-21A11-21A2-3A6-21A11-21A2-A5-24A2(3-A)4-21A12-17A2-2A9-19A4-A8-A2-15A17-A-11A19-A2-9A5-A13-2A7-2(A31-)A-A25-A3-A2-A24-A33-A90-A79-A19-5A18-A5-11A20-13A18-15A16-17A10-A3-19A13-19A9-A3-20A7-A3-21A11-21A2-2A7-21A8-24A8-A2-21A12-2(19A13-)19A14-18A15-15A-A4-A6-A4-13A20-12A20-A2-5A3-A20-A10-A17-A2-A68-A155-A2-A28-2A-2A3-A24-A2-A3-A20-A3-A2-2(A-)A20-A3-9A19-A-11A16-17A-4A13-16A12-20A15-17A14-22A9-20A13-19A12-20A13-22A5-A4-19A13-19A14-17A12-20A14-A-15A15-A2-13A19-12A3-A19-7A2(26-A4-A)23-A2-A4-2A-A19-A2-2A188-A3-A5-A30-A29-A22-A3-A4-A28-3A2(3-A)11-A6-9A2(3-A)9-A2-A-11A2(2-A)14-13A13-2A3-19A11-18A15-17A3-A8-2A-17A14-19A11-21A13-19A2-A11-17A4-2A8-18A15-20A8-A2-A-15A4-2A12-13A15-2A3-12A18-2A-9A20-A5-3A7-A14-A8-A21-A9-A31-A2-A31-A24-A5-A211-A32-A3-A8-A25-A5-A24-6A20-2A2-10A21-11A20-13A5-A10-A-16A10-A5-15A12-A3-17A3-A11-18A11-A2-2(17A15-)17A13-2A-15A17-16A10-A3-A2-13A20-15A18-9A-A15-A3-A2-6A2(-A)24-A6-2A23-A7-A23-A31-A-A31-A253-A3-A24-A2-A3-A-2A24-A3-A31-A20-A3-A2-3A3-A23-7A22-12A2-A13-2A3-11A2-A17-13A17-A-13A5-A12-15A-2A14-15A13-A2-18A10-A5-13A15-A3-13A18-A-11A2-A14-A3-11A19-3A-7A5-A21-3A4-A3-A15-A2-A3-A2-A24-A6-A23-A2-A28-A10-A23-A65-A193-A28-A26-A62-A8-A2-A16-A2-3A3-A4-2A51-A3-5A5-A19-9A17-A5-9A19-A2-13A19-11A21-12A16-2A-12A4-A16-11A16-A4-11A18-2A2-9A3-2A12-A6-6A22-A-A7-A20-2(A6-)A18-2A6-2A60-A4-A59-A377-A8-A2-A21-A3-A39-A16-2A7-A26-A2-A3-A26-3A7-A14-A5-5A-A2-2A18-A-7A25-8A-A16-2(A2-)7A7-A18-5A18-A5-A3-3A2(-A)18-A6-A-A4-A22-A3-A7-A25-2A22-A3-A7-A22-A3-A22-A37-A418-2A25-A30-A2-A6-A18-A40-A-2A23-A2-A40-A13-A9-A2-A22-A2-4A21-A7-3A2-A-2A18-A2-A-3A30-A26-A7-A20-A6-A7-A21-A35-A2-A22-A70-A27-A446-A-A66-A35-A21-A2-2A22-A14-A20-A5-A2-2A2(24-A)9-A2-2A20-A-2A9-A17-A6-A26-A7-A27-A24-A4-A31-A35-A2-A605-A25-A34-A59-2(A2-)A63-A3-A22-A35-A25-A9-A25-A61-A340-
