model
size = 21 31 19, scale = 0.05, origin = -y
material deform = 1, fade = true, lighting = smooth, roughness = 0.3, metalness = 0.6
  colors = A:#FF6 B:#E00 C:#0D0 D:#555
voxels
239-5A15-4(7A14-)7A12-7DAD2A10-DBD3BDAD2A10-2(DB)7D10-2(DB)D3BDBD10-2(DB)D5BD10-3DB3D3BD2(10-11B)11-10B202-3CAC16-5C16-A4C16-5C16-4CB16-5C16-CA3C13-3C5-3C2(10-2C7-2C)10-CA2(7-2C10-2C)7-2C10-5(A10-C9-)2A9-C9-11AC8-C11AC8-2C10A2C8-12C96-4AB3(16-5A)14-6(2A5-2B12-)2A5-2B10-CA9-2A8-C11-A8-C11-B3(8-C11-A)7-4(2C12-B6-)AC2(12-B6-2C)12AB6-C13AB6-C14A6-2C12AC4-18C71-2A5-AB12-2A5-2B2(12-2A5-AB)10-6(CA9-2A8-)CA9-2A7-5(A13-B6-)A13-B4-6(2A15-A3-)2A15-B4(3-2A15-A)B2-18AB48-3(A9-A10-)2(A9-)C11-A8-C11-B2(8-C11-A)8-A2(11-A8-C)11-A5-2BA13-A5(B3-2B15-)B3-6(2A16-B2-)A17-4(B20-)B2-15AB2AB47-3(A11-C8-)A11-C7-6(A13-B6-)A13-B4-5(BA15-A3-)BA15-A2-5(3A16-B-)2A17-B128-7A5-8B25-3(A11-A8-)A11-A7-2(A13-B6-)A13-A4(6-A13-B)4-BA15-A3(C2-B17-)B2(2-B17-C)-5(A19-B)148-AB4A7-7B24-3(C13-B6-)C13-B5-3(A15-A4-)A15-B3(4-A15-A)3-B17-A5(2-B17-C)-B3(19-BA)19-B190-5B9-3AB2A3-3(C13-B6-)C13-B5-6(A15-A4-)A15-A3-5(B17-C2-)B17-C-3(A19-B)211-4B11-5A3-3(C13-B6-)C13-B5-A15-B5(4-A15-A)4-B15-A3-5(B17-C2-)B17-C-2(A19-B)232-4B11-5A3-3(C13-B6-)C13-B5-6(A15-A4-)A15-A3-5(B17-C2-)B17-C-3(A19-B)211-4B11-5A3-3(C13-B6-)C13-B5-A15-C4-B3(15-C4-A)15-A2(4-A15-C)3-5(B17-C2-)B17-C-4(A19-B)190-5B9-3AB2A4-3(A11-A8-)A11-A7-3(B13-A6-)A3(13-A6-B)13-A4-BA15-A5(C2-B17-)C-4(A19-B)20-B148-6B7-7B25-B11-A8-B11-B2(8-B11-A)7-6(B13-A6-)B13-A5-2(A15-C4-)B3(15-C4-A)15-C3-4(C17-C2-)C17-7(C20-)C2-20B26-3(A9-B10-)A9-B9-2(C11-A8-)C11-B4(8-C11-A)6-2A13-AC4-A15-B4(4-A15-C)3-4(C17-C2-)C17-C20-4(C14-6A)C14-5AB3-C16AB50-2(BA5-2A12-)BA5-AB12-BA5-2A10-4(CA9-2B8-)CA9-AB2(8-CA9-2B)7-5(B13-B6-)B13-B4-CA15-5(B3-C16-)4(B3-CA10-A4-)B3-CA10-A3-AB3-C16AB52-3(5A16-)AB3A14-2(2C5-2A12-)2C5-BA12-CB3(5-2A12-2C)5-2A10-2A9-2A5(8-A11-A)6-2A13-5(C5-A14-)3(C5-12A3-)C5-12A2-AC6-14A160-3B17-5(5B16-)5B13-3C5-3C10-2C7-2C10-CA3(7-2C10-2C)7-2C8-2C11-5(C7-C12-)2(C7-C12A)C7-2C10A2C8-3CB8C328-AB3A15-4(7A14-)7A12-5A2B3A10-2ADA7DB9-2ADAD3B2(DB)9-7D2(BD)B9-DBD3B3(DB)9-D5B3(DB)9-D3B2(3DB)9-12B10-10B111-
