model
size = 32 10 32, scale = 0.05, origin = -y
material deform = 1, fade = true, lighting = smooth, roughness = 0.3, metalness = 0.6
  colors = A:#001 B:#CF3 C:#FF3
voxels
38-18AB269-20A298-13AB4AB5A295-9AB16A293-5AB22A292-2AB13AB12A290-30A289-12AC18A289-22AB9A288-4AB22AB4A8-17A263-32A8-17A16-15A232-32A8-17A16-15A18-11ABA201-32A8-17A16-15A18-13A20-4AB6A170-AC30A8-17A16-15A18-13A20-11A22-9A139-32A8-17A16-15A18-B12A20-11A22-9A24-7A108-29AB2A8-17A16-15A18-12AB20-11A22-9A24-6AB26-5A77-16AB15A8-17A16-15A18-13A20-11A22-9A24-7A26-B4A28-2AB30-A15-32A8-17A16-15A18-13A20-11A22-9A24-7A26-5A77-10AB21A8-17A16-15A18-13A20-11A22-9A24-7A108-4AB27A8-17A16-15A18-13A20-11A22-3AB5A139-32A8-17A16-15A18-13A20-B10A170-25AC6A8-17A16-15A18-10AB2A201-AB26AB3A8-17A16-15A232-31AB8-5AB11A263-2(32A288-)7AB24A289-2AB27A290-10AC9AB8A292-28A294-25AC295-10AB12A292-
