model
size = 32 14 32, scale = 0.05, origin = -y
material deform = 1, fade = true, lighting = smooth, roughness = 0.3, metalness = 0.6
  colors = A:#DC0211
voxels
15-A28-9(8A24-)7A25-6A26-5A28-3A28-9(8A24-)8A25-7A26-5A28-3A30-A24-9(4A6-4A18-)3A7-A-2A18-2A11-A18-A93-12(3A12-3A14-)3A13-2A2(15-A)13-10(2A16-2A12-)2A16-2A13-A16-2A30-A44-8(2A18-2A10-)2A18-2A11-A18-2A30-A106-9(2A20-2A8-)2A21-A8-A126-11(2A22-2A6-)2A23-A6-A62-12(2A24-2A4-)2A24-2A5-A25-12(A4-A26-)A31-A35-8(2A26-2A2-)2A26-2A3-A26-2(2A30-)A67-9(A28-A2-)A28-A130-9(A28-A2-)A31-A126-2A10(28-4A)29-3A30-A63-A12(30-2A)2(31-A)12(30-2A)30-A32-A11(30-2A)30-2(A31-)11(2A30-)2(A31-)A32-A9(30-2A)30-2(A31-)A64-A8(30-2A)30-2(A31-)A96-2A9(28-4A)29-A-A127-11(A28-A2-)A95-12(A28-A2-)A63-13(2A26-2A2-)A27-12(A4-A26-)A31-A36-10(2A24-2A4-)A25-2A31-A69-8(2A23-A6-)2A23-A7-A23-A135-9(2A20-2A8-)2A30-2A31-A95-10(2A18-2A10-)2A18-A11-2A30-2A31-A31-12(2A16-2A12-)A64-9(3A12-3A14-)2A13-3A14-A14-2(3A29-)3A30-A17-8(4A6-4A18-)4A6-4A19-3A7-3A20-2A8-2A31-A73-
