model
size = 18 32 18, scale = 0.05, origin = -y
material deform = 1, fade = true, lighting = smooth, roughness = 0.3, metalness = 0.6
  colors = A:#600
voxels
18-2A14-4A3(14-A2-A)14-A2-2A7(13-A3-A)13-2A2-2A11-3A2-15A3-2(2A16-)6(A17-)2A16-5(A17-)A33-2A14-4A3(14-A2-A)14-A2-2A6(13-A3-A)13-A3-2A12-2A2-3A10-3A2-15A3-2(2A16-)6(A17-)2A16-5(A17-)A51-2A13-5A13-3(6A12-)3A-2A12-6(3A-3A11-)3A-3A10-4A-5A8-4A-17A-15A3-6(3A15-)3A16-2A6(15-3A)16-A49-2A16-12(A17-)A3-4A10-2A2-4A4(-A)-2A3-6(A17-)2A15-2A17-2A16-3(A17-)A16-3A15-3A16-A266-A2-3A11-2A3-A12-A111-A16-3A16-A106-3A15-3A268-3A11-2A3-14A129-2A123-2A16-3A268-3A11-2A3-A12-A129-2A123-2A16-3A268-3A11-2A3-14A111-2(2A16-)2A105-2A16-3A268-3A11-2A3-A12-A93-2A70-2A87-2A16-3A268-3A11-2A2-2A2(-3A)-4A3-3(2(2A16-)2A34-)2A16-2A2(15-3A)268-3A11-2A2-4A2(-3A)-2A3-3(2A34-2(2A16-))2A33-3A15-3A268-3A11-2A3-A12-A75-2A106-2A69-2A16-3A268-3A11-2A3-14A93-4(2A16-)2A87-2A16-3A268-3A11-2A3-A12-A129-2A123-2A16-3A268-3A11-2A3-14A129-2A123-2A16-3A265-A2-3A11-2A3-A12-A111-A16-3A16-A106-3A15-3A30-2A16-12(A17-)A3-4A10-2A2-4A4(-A)-2A3-6(A17-)2A15-2A17-2A16-3(A17-)A16-3A15-3A16-A15-2A13-5A13-3(6A12-)3A-2A12-6(3A-3A11-)3A-3A10-4A-4A9-4A-17A-15A3-6(3A15-)3A16-2A6(15-3A)16-A33-
