model
size = 32, scale = 0.05, origin = -y
material deform = 1, fade = true, lighting = smooth, roughness = 0.3, metalness = 0.6
  colors = A:#111 B:#FFF C:#BBB D:#DDD E:#222 F:#800 G:#B00 H:#888 I:#444 J:#EEE K:#D00 L:#500 M:#555 N:#A00
voxels
32-66B8(28-4B)28-2C2B3(28-2B2C)15(28-4B)28-2B32-270BC3BC26B7C25B7C23B2C7B2C21B2C3DJ3D2C19B2C2DCHCDCHC2D2C17B2CDCHK3H2(KHCD2C17B2CDCH2(KN))KHCD2C17B2C2DCHNKNHC2D2C17B2CJ2DC3HC2DJ2C19B2C2D3C2D2C21B2CJ5DJ2C23B7C25B7C28BC1297B28-36B30(28-4B)28-36B28-5(4B-26A-)2BCB8(-26A-4B)2(-26A-2BCB)-26A-B2CB-26A-BC2B2(-26A-B2CB)-26A-BC2B2(-26A-B3C)-26A-6(4C28-)2C2B28-36B28-14(4B-26A-)2(2BCB-26A-)B2CB-26A-BC2B2(-26A-B2CB)-26A-BC2B2(-26A-B3C)-26A-6(4C28-)2C2B3-22D3-36B28-5(4B-26A-)2BCB8(-26A-4B)2(-26A-2BCB)-26A-B2CB-26A-BC2B2(-26A-B2CB)-26A-BC2B2(-26A-B3C)-26A-6(4C28-)2C2B3-22D3-36B28-14(4B-26A-)2(2BCB-26A-)B2CB2(-26A-BC2B)5(-26A-4B)6(28-4B)3-2D18B2D3-36B28-5(4B-26A-)2BCB4(-26A-4B)2(-26A-BC2B)2(-26A-4B)2(-26A-2BCB)-26A-B2CB2(-26A-BC2B)5(-26A-4B)6(28-4B)3-2D18B2D3-36B28-10(4B-26A-)2(BC2B-26A-)2(4B-26A-)2(2BCB-26A-)B2CB2(-26A-BC2B)5(-26A-4B)4(28-4B)2(14-G13-4B)3-2D18B2D3-36B28-5(4B-26A-)2BCB8(-26A-4B)2(-26A-2BCB)-26A-B2CB2(-26A-BC2B)5(-26A-4B)13-2B13-4B13-BH13-4B13-CB13-4B14-J13-4B14-G13-4B28-4B3-2D18B2D3-36B28-5(4B-26A-)2BCB7(-26A-4B)-26A-BC2B3(-26A-B2CB)2(-26A-BC2B)5(-26A-4B)12-B2-B12-4B12-H2-B12-4B12-B2-C12-4B12-J15-4B11-2G15-4B11-G16-4B3-2D18B2D3-36B28-5(4B-26A-)2BCB7(-26A-4B)-26A-BC2B3(-26A-B2CB)2(-26A-BC2B)5(-26A-4B)11-B4-B11-4B11-B4-H11-4B11-C4-B11-4B16-J11-4B16-2G10-4B17-G10-4B3-2D18B2D3-36B28-5(4B-26A-)2BCB7(-26A-4B)-26A-BC2B3(-26A-B2CB)2(-26A-BC2B)5(-26A-4B)2(10-B6-B10-4B)10-H6-C10-4B10-J17-4B9-2G17-4B9-G18-4B3-2D18B2D3-36B28-5(4B-26A-)2BCB6(-26A-4B)2(-26A-BC2B)2(-26A-B2CB)-26A-2BCB7(-26A-4B)10-B6-B10-4B10-B6-H10-4B10-B6-B10-4B17-J10-4B17-2G9-4B18-G9-4B3-2D18B2D3-36B28-5(4B-26A-)B2CB2(-26A-BC2B-26A-4B)3(-26A-BC2B)3(-26A-B2CB)-26A-2BCB7(-26A-4B)11-B4-B11-4B11-H4-B11-4B11-B4-C11-4B11-J16-4B11-G16-4B28-4B3-2D18B2D3-36B28-5(4B-26A-)B2CB2(-26A-BC2B-26A-4B)2(-26A-BC2B)4(-26A-B2CB)-26A-2BCB7(-26A-4B)12-B2-B12-4B12-B2-H12-4B12-B2-B12-4B15-J12-4B11-G3-G12-4B11-G16-4B3-2D18B2D3-36B28-5(4B-26A-)2BCB2(-26A-4B)-26A-BC2B-26A-4B-26A-BC2B5(-26A-B2CB)8(-26A-4B)13-2B13-4B13-HB13-4B13-BC13-4B13-J14-4B13-G-G12-4B15-G12-4B3-2D18B2D3-36B28-5(4B-26A-)2BCB2(-26A-4B)-26A-BC2B-26A-4B3(-26A-B2CB)2(-26A-2BCB)9(-26A-4B)4(28-4B)2(13-G14-4B)3-2D18B2D3-36B28-5(4B-26A-)2BCB2(-26A-4B)-26A-BC2B-26A-2BC3(B-26A-B2C)B-26A-2BCB7(-26A-4B)2(-26A-2BCB)-26A-6(4B28-)4B3-2D18B2D3-36B28-5(4B-26A-)2BCB2(-26A-4B)-26A-BC2B-26A-2BC3(B-26A-B2C)B8(-26A-4B)2(-26A-2BCB)-26A-6(4B28-)4B3-2D18B2D3-36B28-5(4B-26A-)2BCB2(-26A-4B)-26A-BC2B-26A-2BC2(B-26A-B2C)B-26A-BC2B11(-26A-4B)6(28-4B)2(3-2D18B2D3-36B28-5(4B-26A-)2BCB2(-26A-4B)-26A-BC2B-26A-2BC2(B-26A-B2C)B-26A-BC2B8(-26A-4B)2(-26A-2BCB)-26A-6(4B28-)4B)3-2D18B2D3-36B28-5(4B-26A-)3(2BCB-26A-)BC2B-26A-2BC2(B-26A-B2C)B-26A-BC2B11(-26A-4B)6(28-4B)3-2D18B2D3-36B28-7(4B-26A-)2BCB-26A-BC2B-26A-2BC2(B-26A-B2C)B2(-26A-BC2B11(-26A-4B)6(28-4B)3-22D3-36B28-7(4B-26A-)2BCB-26A-BC2B-26A-2B2C2(-26A-B3C))-26A-BC2B11(-26A-4B)6(28-4B)28-36B28-7(4B-26A-)2BCB-26A-B2CB-26A-2B2C2(-26A-B3C)-26A-BC2B11(-26A-4B)6(28-4B)28-36B28-3(4B-26A-)4B-11A4F11A-4B-9A2F4L2F9A-4B-9AFL4FLF9A-4B-8AFL2F2A2FLF8A-4B-8A2F6A2F8A-2C2B-26A-2B2C2(-26A-B3C)-26A-BC2B-26A-4B-4A2(CA)C8A2(CA)C4A-4B-2A2E2(AE)A8E2(AE)A2E2A-4B-2A2I2(MI)M8I2(MI)M2I2A-4B-2A2E2(AE)A8E2(AE)A2E2A-4B-4A2(CA)C8A2(CA)C4A-4B-3A2(C2A)C6A2(C2A)C3A4(-4B-26A)-7(4B28-)36B7(28-4B)28-2BCB28-3CB28-2B2C2(28-B3C)28-BC2B16(28-4B)28-68B8(28-4B)28-2C2B3(28-2B2C)16(28-4B)28-2B32-
