model
size = 11 14 22, scale = 0.05, origin = -y
material deform = 1, fade = true, lighting = smooth, roughness = 0.3, metalness = 0.6
  colors = A:#331919 B:#EEE
voxels
4-5A38-5A5-7A3-9A-55A-9A3-7A51-5(3A8-)3A42-B53-3B30-3(3A8-)3A9-A2(10-B)31-2(3B8-)3B41-2(A-A8-3A140-3A8-)A-A8-3A107-3A7-5A6-2A-2A6-5A7-3A96-3A7-5A6-2A-2A6-5A7-3A85-4(3A7-5A5-7A4-3A-3A4-7A5-5A7-3A74-)3A7-5A5-7A4-3A-3A4-7A5-5A7-3A96-3A7-5A5-7A4-3A-3A4-7A5-5A7-3A84-5A5-7A3-2(9A2-)4A-4A2(2-9A)3-7A5-5A72-5A5-7A3-2(9A2-)4A-4A2(2-9A)3-7A5-5A84-3A7-5A5-7A4-3A-3A4-7A5-5A7-3A96-3A7-5A5-7A4-3A-3A4-7A5-5A7-3A84-3A7-5A5-7A4-3A-3A4-7A5-5A7-3A74-5A5-7A3-2(9A2-)4A-4A2(2-9A)3-7A5-5A72-3A7-5A5-7A4-3A-3A4-7A5-5A7-3A74-5A5-7A3-2(9A2-)4A-4A2(2-9A)3-7A5-5A13-
