model
size = 11 14 24, scale = 0.05, origin = -y
material deform = 1, fade = true, lighting = smooth, roughness = 0.3, metalness = 0.6
  colors = A:#331919
voxels
4-5A38-5A5-7A3-9A-55A-9A3-7A96-A153-A10-A141-3A8-3A140-2(3A8-)3A129-2(A-A8-3A140-3A8-)A-A8-3A107-3A7-5A6-2A-2A6-5A7-3A96-3A7-5A6-2A-2A6-5A7-3A85-4(3A7-5A5-7A4-3A-3A4-7A5-5A7-3A74-)3A7-5A5-7A4-3A-3A4-7A5-5A7-3A96-3A7-5A5-7A4-3A-3A4-7A5-5A7-3A84-5A5-7A3-2(9A2-)4A-4A2(2-9A)3-7A5-5A72-5A5-7A3-2(9A2-)4A-4A2(2-9A)3-7A5-5A84-3A7-5A5-7A4-3A-3A4-7A5-5A7-3A96-3A7-5A5-7A4-3A-3A4-7A5-5A7-3A84-3A7-5A5-7A4-3A-3A4-7A5-5A7-3A74-5A5-7A3-2(9A2-)4A-4A2(2-9A)3-7A5-5A72-3A7-5A5-7A4-3A-3A4-7A5-5A7-3A74-5A5-7A3-2(9A2-)4A-4A2(2-9A)3-7A5-5A13-
