model
size = 32 28 10, scale = 0.05, origin = -y
material deform = 1, fade = true, lighting = smooth, roughness = 0.3, metalness = 0.6
  colors = A:#F0F B:#66F C:#F06 D:#3FF E:#F93 F:#FF0 G:#6F6
voxels
303-2B29-4B27-6B25-3B2-3B23-3B4-3B21-3B6-3B19-3B8-3B17-3B10-3B15-3B12-3B3(14-2B)2(6-2B)14-3B3-6B3-3B15-7B2-7B17-5B4-5B376-2A29-4C27-6C25-3C2-3C23-3C4-3C21-3C6-3C19-3C8-3C17-3C10-3C15-3C12-3C13-3C14-3C3(12-2C16-2C)12-3C6-2A6-A2C12-4C3-6C3-A2C14-7C4-6C16-5C6-4C280-2A29-4A27-6A25-8A23-10A21-12A19-14A17-16A15-8A2-8A13-8A4-8A11-8A6-8A9-2(8A8-)7A10-7A8-6A12-7A6-6A6-2A5-7A6-7A4-4A4-7A6-2(8A-)7A2(8-24A)8-11A2-10A10-9A4-8A13-6A7-4A151-2B28-6B25-8B23-10B21-5B2-5B19-5B4-5B17-5B6-5B15-5B9-4B13-5B11-4B11-5B13-4B10-4B6-2B7-4B8-4B6-4B7-2(4B6-)2B2-2B7-4B4-4B6-2B4-2B6-4B4-3B6-2(2B2-)2B6-4B2-4B5-2B2-4B2-2B5-4B2-4B4-2B2-6B2-B6-3B2-3B5-5B4-4B5-4B2-4B5-2B8-B6-4B2-4B22-4B2-4B9-4B8-4B4-4B7-6B6-5B4-6B4-9B2-6B6-12B2-12B7-9B6-8B11-5B10-4B54-2D28-6D25-8D24-2D4-3D22-2D6-3D20-2D8-3D17-3D10-3D15-3D12-3D13-3D14-3D11-3D16-3D10-2D18-3D8-2D20-3D6-3D21-3D4-3D10-2D11-2D3-3D10-4D11-2D2-2D10-6D10-2B2-2D9-3D2-3D10-4D9-3D4-3D9-2(4D28-)4D27-6D26-2D2-2D12-2D11-3D2-3D10-4D10-3D3-3D7-3D2-3D6-4D4-5D3-4D4-4D2-5D7-9D6-9D11-3D36-4G27-6G25-2G4-2G23-2G6-2G21-3G7-2G19-3G9-3G16-3G11-3G14-2G14-3G12-2G16-3G10-2G18-3G8-2G20-3G6-3G21-3G4-3G23-2G3-3G25-2G2-2G26-5G2(28-4G)29-2(2G30-)2G29-2(4G28-)5G11-4G11-2G2-2G10-6G9-3G2-4G7-3G2-3G7-3G4-6G-4G6-10G7-8G8-7G19-4F27-6F25-3F2-3F23-3F4-3F21-3F6-3F19-3F8-3F17-3F10-3F15-3F13-3F12-3F15-3F10-3F17-3F8-3F19-3F6-3F21-3F4-3F23-2F4-2F24-3F2-2F26-2F-3F27-6(4F28-)4F13-F13-6F11-4F10-3F2-3F9-6F8-4F3-4F5-3F4-3F5-4F5-10F6-10F8-7F9-6F51-4E27-6E25-3E-4E23-3E4-3E21-3E6-3E19-3E8-4E16-3E10-4E14-3E12-4E12-3E14-4E10-3E16-4E8-3E18-4E6-3E20-3E5-3E22-3E4-3E23-3E2-3E24-3E2-3E25-3(2E2-2E26-)2E2-2E25-3E2-3E24-3E2-3E10-4E9-4E2-4E8-6E7-4E4-5E4-4E2-4E3-5E6-11E4-10E9-7E8-7E115-3C28-6C25-8C23-10C21-5C2-5C19-5C4-5C17-5C6-5C15-5C9-4C13-5C11-4C11-5C13-4C9-5C15-4C8-4C7-2C8-4C6-4C7-4C8-3C6-3C7-7C6-4C4-4C6-3C2-3C6-4C4-3C7-2C4-2C7-3C4-3C21-4C4-4C20-4C4-4C9-2C9-4C4-5C2(7-4C)6-5C5-7C3-6C6-12C2-11C8-10C4-9C11-6C8-5C214-2A29-4A27-6A25-8A23-11A20-13A18-15A16-17A14-19A12-9A2-10A10-9A4-9A10-8A6-8A9-8A3-2A3-8A8-8A2-4A2-8A8-24A8-23A2(10-22A)11-9A2-9A13-7A5-5A136-
