model
size = 16 28 29, scale = 0.05, origin = -y
material deform = 1, fade = true, lighting = smooth, roughness = 0.3, metalness = 0.6
  colors = A:#630 B:#111 C:#0F0 D:#FF0
voxels
68-3(2A14-)2A366-2A13-3A4(12-4A)13-3A14-2A318-2A13-3A12-4A4(11-5A)12-4A13-3A14-2A301-3A12-4A6(11-5A)12-4A13-3A286-2A12-4A2(11-5A)4(10-6A)2(11-5A)12-4A14-2A270-2(2A12-4A2(11-5A)4(10-6A)2(11-5A)12-4A14-2A2(15-B)6(15-2B)15-B120-)2A12-4A2(11-5A)4(10-6A)2(11-5A)12-4A14-2A149-2B15-B118-3A12-4A6(11-5A)12-4A13-3A182-2B118-2A13-3A12-4A4(11-5A)12-4A13-3A14-2A183-B15-B118-2A13-3A4(12-4A)13-3A14-2A215-B15-B134-3(2A14-)2A263-B15-B135-C15-C295-B15-B119-C15-C311-2(B15-)D87-C15-C327-B14-DBD86-C15-C343-DBD85-C15-C328-B14-DBD68-3(2A14-)2A296-2(B15-)D37-2A13-3A4(12-4A)13-3A14-2A248-B15-B53-2A13-3A12-4A4(11-5A)12-4A13-3A14-2A216-B15-B68-3A12-4A6(11-5A)12-4A13-3A183-B15-2B15-B69-2A12-4A2(11-5A)4(10-6A)2(11-5A)12-4A14-2A149-2B15-2B102-2(2A12-4A2(11-5A)4(10-6A)2(11-5A)12-4A14-2A2(15-B)6(15-2B)15-B120-)2A12-4A2(11-5A)4(10-6A)2(11-5A)12-4A14-2A285-3A12-4A6(11-5A)12-4A13-3A302-2A13-3A12-4A4(11-5A)12-4A13-3A14-2A318-2A13-3A4(12-4A)13-3A14-2A366-3(2A14-)2A330-
