model
size = 15 29 29, scale = 0.05, origin = -y
material deform = 1, fade = true, lighting = smooth, roughness = 0.3, metalness = 0.6
  colors = A:#E00 B:#0A0 C:#930
voxels
64-3(4A11-)4A356-4A10-6A8-3(8A7-)8A8-6A10-4A311-4A10-6A8-8A6-3(10A5-)10A6-8A8-6A10-4A295-6A8-8A6-5(10A5-)10A6-8A8-6A280-4A9-8A6-10A5-10A4-3(12A3-)12A4-10A5-10A6-8A9-4A266-2(4A9-8A6-10A5-10A4-3(12A3-)12A4-10A5-10A6-8A9-4A12-2(B14-)6(2B14-)B127-)4A9-8A6-10A5-10A4-3(12A3-)12A4-10A5-10A6-8A9-4A138-2B14-B125-6A8-8A6-5(10A5-)10A6-8A8-6A168-2B125-4A10-6A8-8A6-3(10A5-)10A6-8A8-6A10-4A170-B14-B125-4A10-6A8-3(8A7-)8A8-6A10-4A200-B14-B140-3(4A11-)4A245-4(B14-B434-)CB13-2C404-B13-CB13-2C64-3(4A11-)4A276-B14-B64-4A10-6A8-3(8A7-)8A8-6A10-4A231-B14-B64-4A10-6A8-8A6-3(10A5-)10A6-8A8-6A10-4A201-B14-B78-6A8-8A6-5(10A5-)10A6-8A8-6A169-B14-2B14-B79-4A9-8A6-10A5-10A4-3(12A3-)12A4-10A5-10A6-8A9-4A138-2B14-2B110-2(4A9-8A6-10A5-10A4-3(12A3-)12A4-10A5-10A6-8A9-4A12-2(B14-)6(2B14-)B127-)4A9-8A6-10A5-10A4-3(12A3-)12A4-10A5-10A6-8A9-4A280-6A8-8A6-5(10A5-)10A6-8A8-6A295-4A10-6A8-8A6-3(10A5-)10A6-8A8-6A10-4A311-4A10-6A8-3(8A7-)8A8-6A10-4A356-3(4A11-)4A322-
