model
size = 32 29 32, scale = 0.05, origin = -y
material deform = 1, fade = true, lighting = smooth, roughness = 0.3, metalness = 0.6
  colors = A:#9CF B:#3CF C:#00E D:#E00 E:#F60 F:#30C G:#111 H:#555 I:#EEE J:#0CF K:#0A0 L:#444
voxels
145-3G8(29-2BJ)29-B2J492-2464A33-30A-162AFAKAD18ADAKAF4AFAKAD18ADAKAF642A66-3(5H18-5H4-)5H18-5H130-608A67-2(3I20-3I6-)3I20-3I163-608A132-G23-G163-3(608A320-)608A9-7E304-608A9-8E303-608A8-9E303-169A2-437A8-10E302-106A2-28A2-30A4-A-28A-405A8-7E2IEF301-105A4-2A-24A6-A-24A6-27A2-2A-27A2-373A8-3EFE2I2FE2F300-79A-24A9-23A8-24A7-25A6-27A3-2A-26A-342A8-3EFEI3FE3F299-79A-24A10-22A9-23A2(7-25A)4-AB-25A2-A-340A9-2E2FI7F299-80A2-22A11-21A9-23A8-24A8-A-22A7-25A4-A2-A-335A10-2E10F298-81A-22A11-21A2(9-23A)10-22A8-A-22A4-B4-23A3-309A11-2E9F298-104A4(11-21A)8-A2-21A9-23A3-A-A2-24A2-278A15-6F299-104A2(11-21A)12-20A3(11-21A)9-23A3-A2-26A-247A17-4F299-608A320-104A5C6D-20A6C-4D-20A-7C5-4(19A-9C3-)19A3-6C4-19A5-3C5-2(19A13-)171A320-104A7-4D-20A7-5D20A3-C2-2C5-8(19A13-)171A320-104A7-4D-20A7-4D2-19A7-C5-8(19A13-)18A3G11-139A423-3G8-2D3-C15-L2B5-6D-C16-L2B11-C17-G2B29-3(GB30-)GB19-C10-GB17-2C11-LB13-C-C3-2C9-L3B14-3C11-4G13-4C-C555-3G7-2D20-3B7-3D19-8(3B29-)J2B30-2G554-D20-2G7-3D20-2B6-3D21-6(2B30-)2(B31-)2B30-2G552-5D18-2G7-2D21-2B30-3B29-5(2B30-)2(B31-)2B30-3G519-4D28-4D19-2G30-2(3B29-)7(2B30-)J2B30-4G572-4G8(29-3B)29-2B30-J4B29-3G460-
