model
size = 32, scale = 0.05, origin = -y
material deform = 1, fade = true, lighting = smooth, roughness = 0.3, metalness = 0.6
  colors = A:#EEE B:#111 C:#E00 D:#00E
voxels
-31A512-480A2(512-512A)512-479AB156A3-29A2(4-28A)3-288A2(D31A)D415AB156A3(4-28A)4-287A2(D31A)D415A2(B156A3(4-28A)4-289A2(B31A)6(B29ABA)4(B29AB-)B93A)B156A3-29A2(4-28A)3-290A2(B31A)5(B29ABA)3(B29AB-)2(B29ABA)B61AB188A3(4-28A)4-289A2(B31A)4(B29ABA)2(B29AB-)4(B29ABA)B61AB188A3(4-28A)4-289AB31AB30AC2(B29AB-3(B29ABA))2(B29ABA)B61AB188A3-29A2(4-28A)4-224AC63A2(CB30A)C5(B29AB-)5(B29ABA)B61AB188A3(4-28A)4-224A2(C31A)CB30ACB31A5(B29AB-)5(B29ABA)B250A2(4-28A)3-29A3-257AC32A2(B31A)5(B30A-)5(B31A)B250A3(4-28A)4-289A2(B31A)B30A-9(B31A)B250A3(4-28A)3-290A3(B30A-)9(B31A)B250A3-29A2(4-28A)4-191AB97A3(B30A-)9(B31A)B250A3(4-28A)4-158A2B31AB97AB30A-11(B31A)B250A3(4-28A)4-191AB96A-B30A-11(B31A)B250A2(3-29A)4-28A4-924A2(4-28A)3-29A3-925A3(4-28A)4-383A9(B31A)B252A3(4-28A)4-383A9(B31A)B63AB188A3-29A2(4-28A)3(4-383A9(B31A)B63AB188A3(4-28A))3-384A9(B31A)B95AB156A2(3-29A)4-28A4-383A9(B31A)B95AB156A3(4-28A)4-767AB157A2-30A2(3-29A)2-768AB32A512-479AB32A512-512A
