model
size = 32, scale = 0.05, origin = -y
material deform = 1, fade = true, lighting = smooth, roughness = 0.3, metalness = 0.6
  colors = A:#0FF B:#111 C:#EEE D:#0C0 E:#06C F:#603 G:#609 H:#E00 I:#C33 J:#FF3 K:#0B0 L:#00E M:#D00 N:#3FF
voxels
33-18(30B2-)10(2B27-B2-)2B27-B2(-M30L)34-3J29-3J4F25-3J4F3A22-3J4F5A4G16-3(3J4F4AN4G5D3E8-)3J4F4AN20(4G5D5E4H2-3J4F5A)4G5D5E4H-2(H30IK)65-3J29-JIJ29-J2I4F3A22-J2I4F5A4G16-3(J2I4F5A4G5D3E8-)20(J2I4F5A4G5D5E4H2-)J2I4F5A4G5D5E4H-2(H3I4F5A4G5D5E4HK)-29(30B2-)30B-M29ACKM30AK26(-2(30B2-)27(B28AB2-)B28AB-2(M30AK))-2(30B2-)22(B28AB2-)B4A2H22A5(B2-B28A)B-2(M30AK)-2(30B2-)17(B28AB2-)10(BA27CB2-)BA28B-2(M30AK)-30B-
