model
size = 27, scale = 0.05, origin = -y
material deform = 1, fade = true, lighting = smooth, roughness = 0.3, metalness = 0.6
  colors = A:#FF3
voxels
28A8(-2A)-31A2(3-6A)3-4A2(-A3-A-2A)-A3-A-4A2(3-6A)3-31A8(-2A)-37A9-10A2(-2A)-A9-A2(-2A)-10A9-12A3-3A9-3A3-4A-A3-A-A9-A-A3-A-4A3-3A9-3A3-12A9-10A2(-2A)-A9-A2(-2A)-10A9-37A8(-2A)-31A2(3-6A)3-4A2(-A3-A-2A)-A3-A-4A2(3-6A)3-31A8(-2A)-29A8(-2A)-A27-A9(-2A)2(-A3-A-2A)-A3-A-A27-A3(-A3-A-2A)8(-2A)-A27-A11(-2A)-A9-A2(-2A)-A27-A2(-2A)-A9-A3(-2A)-A3-A-A9-A-A3-A-A27-A-A3-A-A9-A-A3-A3(-2A)-A9-A2(-2A)-A27-A2(-2A)-A9-A11(-2A)-A27-A9(-2A)2(-A3-A-2A)-A3-A-A27-A3(-A3-A-2A)8(-2A)-A27-A8(-2A)-29A8(-2A)-31A2(3-6A)3-4A2(-A3-A-2A)-A3-A-4A2(3-6A)3-31A8(-2A)-37A9-10A2(-2A)-A9-A2(-2A)-10A9-12A3-3A9-3A3-4A-A3-A-A9-A-A3-A-4A3-3A9-3A3-12A9-10A2(-2A)-A9-A2(-2A)-10A9-37A8(-2A)-31A2(3-6A)3-4A2(-A3-A-2A)-A3-A-4A2(3-6A)3-31A8(-2A)-31A2(3-6A)3-4A2(-A3-A-2A)-A3-A-4A2(3-6A)3-3A81-3A2(3-6A)3-4A2(-A3-A-2A)-A3-A-4A3(3-6A)3-3A9-3A3-4A-A3-A-A9-A-A3-A-4A3-3A9-3A3-3A81-3A3-3A9-3A3-4A-A3-A-A9-A-A3-A-4A3-3A9-3A3(3-6A)3-4A2(-A3-A-2A)-A3-A-4A2(3-6A)3-3A81-3A2(3-6A)3-4A2(-A3-A-2A)-A3-A-4A2(3-6A)3-4A2(-A3-A-2A)-A3-A-A27-A2(-A3-A-2A)-A3-A-A81-A2(-A3-A-2A)-A3-A-A27-A3(-A3-A-2A)-A3-A-A9-A-A3-A-A27-A-A3-A-A9-A-A3-A-A81-A-A3-A-A9-A-A3-A-A27-A-A3-A-A9-A3(-A3-A-2A)-A3-A-A27-A2(-A3-A-2A)-A3-A-A81-A2(-A3-A-2A)-A3-A-A27-A2(-A3-A-2A)-A3-A-4A2(3-6A)3-4A2(-A3-A-2A)-A3-A-4A2(3-6A)3-3A81-3A2(3-6A)3-4A2(-A3-A-2A)-A3-A-4A3(3-6A)3-3A9-3A3-4A-A3-A-A9-A-A3-A-4A3-3A9-3A3-3A81-3A3-3A9-3A3-4A-A3-A-A9-A-A3-A-4A3-3A9-3A3(3-6A)3-4A2(-A3-A-2A)-A3-A-4A2(3-6A)3-3A81-3A2(3-6A)3-4A2(-A3-A-2A)-A3-A-4A2(3-6A)3-31A8(-2A)-31A2(3-6A)3-4A2(-A3-A-2A)-A3-A-4A2(3-6A)3-31A8(-2A)-37A9-10A2(-2A)-A9-A2(-2A)-10A9-12A3-3A9-3A3-4A-A3-A-A9-A-A3-A-4A3-3A9-3A3-12A9-10A2(-2A)-A9-A2(-2A)-10A9-37A8(-2A)-31A2(3-6A)3-4A2(-A3-A-2A)-A3-A-4A2(3-6A)3-31A8(-2A)-29A8(-2A)-A27-A9(-2A)2(-A3-A-2A)-A3-A-A27-A3(-A3-A-2A)8(-2A)-A27-A11(-2A)-A9-A2(-2A)-A27-A2(-2A)-A9-A3(-2A)-A3-A-A9-A-A3-A-A27-A-A3-A-A9-A-A3-A3(-2A)-A9-A2(-2A)-A27-A2(-2A)-A9-A11(-2A)-A27-A9(-2A)2(-A3-A-2A)-A3-A-A27-A3(-A3-A-2A)8(-2A)-A27-A8(-2A)-29A8(-2A)-31A2(3-6A)3-4A2(-A3-A-2A)-A3-A-4A2(3-6A)3-31A8(-2A)-37A9-10A2(-2A)-A9-A2(-2A)-10A9-12A3-3A9-3A3-4A-A3-A-A9-A-A3-A-4A3-3A9-3A3-12A9-10A2(-2A)-A9-A2(-2A)-10A9-37A8(-2A)-31A2(3-6A)3-4A2(-A3-A-2A)-A3-A-4A2(3-6A)3-31A8(-2A)-37A9-10A2(-2A)-A9-A2(-2A)-10A9-12A3-3A9-3A3-4A-A3-A-A9-A-A3-A-4A3-3A9-3A3-12A9-10A2(-2A)-A9-A2(-2A)-10A9-9A243-9A9-10A2(-2A)-A9-A2(-2A)-10A9-12A3-3A9-3A3-4A-A3-A-A9-A-A3-A-4A3-3A9-3A3-12A9-10A2(-2A)-A9-A2(-2A)-10A9-10A2(-2A)-A9-A2(-2A)-A27-A2(-2A)-A9-A3(-2A)-A3-A-A9-A-A3-A-A27-A-A3-A-A9-A-A3-A3(-2A)-A9-A2(-2A)-A27-A2(-2A)-A9-A2(-2A)-A243-A2(-2A)-A9-A2(-2A)-A27-A2(-2A)-A9-A3(-2A)-A3-A-A9-A-A3-A-A27-A-A3-A-A9-A-A3-A3(-2A)-A9-A2(-2A)-A27-A2(-2A)-A9-A2(-2A)-10A9-10A2(-2A)-A9-A2(-2A)-10A9-12A3-3A9-3A3-4A-A3-A-A9-A-A3-A-4A3-3A9-3A3-12A9-10A2(-2A)-A9-A2(-2A)-10A9-9A243-9A9-10A2(-2A)-A9-A2(-2A)-10A9-12A3-3A9-3A3-4A-A3-A-A9-A-A3-A-4A3-3A9-3A3-12A9-10A2(-2A)-A9-A2(-2A)-10A9-12A3-3A9-3A3-4A-A3-A-A9-A-A3-A-4A3-3A9-3A3-3A81-3A3-3A9-3A3-4A-A3-A-A9-A-A3-A-4A3-3A9-3A3-3A243-3A3-3A9-3A3-4A-A3-A-A9-A-A3-A-4A3-3A9-3A3-3A81-3A3-3A9-3A3-4A-A3-A-A9-A-A3-A-4A3-3A9-3A3-4A-A3-A-A9-A-A3-A-A27-A-A3-A-A9-A-A3-A-A81-A-A3-A-A9-A-A3-A-A27-A-A3-A-A9-A-A3-A-A243-A-A3-A-A9-A-A3-A-A27-A-A3-A-A9-A-A3-A-A81-A-A3-A-A9-A-A3-A-A27-A-A3-A-A9-A-A3-A-4A3-3A9-3A3-4A-A3-A-A9-A-A3-A-4A3-3A9-3A3-3A81-3A3-3A9-3A3-4A-A3-A-A9-A-A3-A-4A3-3A9-3A3-3A243-3A3-3A9-3A3-4A-A3-A-A9-A-A3-A-4A3-3A9-3A3-3A81-3A3-3A9-3A3-4A-A3-A-A9-A-A3-A-4A3-3A9-3A3-12A9-10A2(-2A)-A9-A2(-2A)-10A9-12A3-3A9-3A3-4A-A3-A-A9-A-A3-A-4A3-3A9-3A3-12A9-10A2(-2A)-A9-A2(-2A)-10A9-9A243-9A9-10A2(-2A)-A9-A2(-2A)-10A9-12A3-3A9-3A3-4A-A3-A-A9-A-A3-A-4A3-3A9-3A3-12A9-10A2(-2A)-A9-A2(-2A)-10A9-10A2(-2A)-A9-A2(-2A)-A27-A2(-2A)-A9-A3(-2A)-A3-A-A9-A-A3-A-A27-A-A3-A-A9-A-A3-A3(-2A)-A9-A2(-2A)-A27-A2(-2A)-A9-A2(-2A)-A243-A2(-2A)-A9-A2(-2A)-A27-A2(-2A)-A9-A3(-2A)-A3-A-A9-A-A3-A-A27-A-A3-A-A9-A-A3-A3(-2A)-A9-A2(-2A)-A27-A2(-2A)-A9-A2(-2A)-10A9-10A2(-2A)-A9-A2(-2A)-10A9-12A3-3A9-3A3-4A-A3-A-A9-A-A3-A-4A3-3A9-3A3-12A9-10A2(-2A)-A9-A2(-2A)-10A9-9A243-9A9-10A2(-2A)-A9-A2(-2A)-10A9-12A3-3A9-3A3-4A-A3-A-A9-A-A3-A-4A3-3A9-3A3-12A9-10A2(-2A)-A9-A2(-2A)-10A9-37A8(-2A)-31A2(3-6A)3-4A2(-A3-A-2A)-A3-A-4A2(3-6A)3-31A8(-2A)-37A9-10A2(-2A)-A9-A2(-2A)-10A9-12A3-3A9-3A3-4A-A3-A-A9-A-A3-A-4A3-3A9-3A3-12A9-10A2(-2A)-A9-A2(-2A)-10A9-37A8(-2A)-31A2(3-6A)3-4A2(-A3-A-2A)-A3-A-4A2(3-6A)3-31A8(-2A)-29A8(-2A)-A27-A9(-2A)2(-A3-A-2A)-A3-A-A27-A3(-A3-A-2A)8(-2A)-A27-A11(-2A)-A9-A2(-2A)-A27-A2(-2A)-A9-A3(-2A)-A3-A-A9-A-A3-A-A27-A-A3-A-A9-A-A3-A3(-2A)-A9-A2(-2A)-A27-A2(-2A)-A9-A11(-2A)-A27-A9(-2A)2(-A3-A-2A)-A3-A-A27-A3(-A3-A-2A)8(-2A)-A27-A8(-2A)-29A8(-2A)-31A2(3-6A)3-4A2(-A3-A-2A)-A3-A-4A2(3-6A)3-31A8(-2A)-37A9-10A2(-2A)-A9-A2(-2A)-10A9-12A3-3A9-3A3-4A-A3-A-A9-A-A3-A-4A3-3A9-3A3-12A9-10A2(-2A)-A9-A2(-2A)-10A9-37A8(-2A)-31A2(3-6A)3-4A2(-A3-A-2A)-A3-A-4A2(3-6A)3-31A8(-2A)-31A2(3-6A)3-4A2(-A3-A-2A)-A3-A-4A2(3-6A)3-3A81-3A2(3-6A)3-4A2(-A3-A-2A)-A3-A-4A3(3-6A)3-3A9-3A3-4A-A3-A-A9-A-A3-A-4A3-3A9-3A3-3A81-3A3-3A9-3A3-4A-A3-A-A9-A-A3-A-4A3-3A9-3A3(3-6A)3-4A2(-A3-A-2A)-A3-A-4A2(3-6A)3-3A81-3A2(3-6A)3-4A2(-A3-A-2A)-A3-A-4A2(3-6A)3-4A2(-A3-A-2A)-A3-A-A27-A2(-A3-A-2A)-A3-A-A81-A2(-A3-A-2A)-A3-A-A27-A3(-A3-A-2A)-A3-A-A9-A-A3-A-A27-A-A3-A-A9-A-A3-A-A81-A-A3-A-A9-A-A3-A-A27-A-A3-A-A9-A3(-A3-A-2A)-A3-A-A27-A2(-A3-A-2A)-A3-A-A81-A2(-A3-A-2A)-A3-A-A27-A2(-A3-A-2A)-A3-A-4A2(3-6A)3-4A2(-A3-A-2A)-A3-A-4A2(3-6A)3-3A81-3A2(3-6A)3-4A2(-A3-A-2A)-A3-A-4A3(3-6A)3-3A9-3A3-4A-A3-A-A9-A-A3-A-4A3-3A9-3A3-3A81-3A3-3A9-3A3-4A-A3-A-A9-A-A3-A-4A3-3A9-3A3(3-6A)3-4A2(-A3-A-2A)-A3-A-4A2(3-6A)3-3A81-3A2(3-6A)3-4A2(-A3-A-2A)-A3-A-4A2(3-6A)3-31A8(-2A)-31A2(3-6A)3-4A2(-A3-A-2A)-A3-A-4A2(3-6A)3-31A8(-2A)-37A9-10A2(-2A)-A9-A2(-2A)-10A9-12A3-3A9-3A3-4A-A3-A-A9-A-A3-A-4A3-3A9-3A3-12A9-10A2(-2A)-A9-A2(-2A)-10A9-37A8(-2A)-31A2(3-6A)3-4A2(-A3-A-2A)-A3-A-4A2(3-6A)3-31A8(-2A)-29A8(-2A)-A27-A9(-2A)2(-A3-A-2A)-A3-A-A27-A3(-A3-A-2A)8(-2A)-A27-A11(-2A)-A9-A2(-2A)-A27-A2(-2A)-A9-A3(-2A)-A3-A-A9-A-A3-A-A27-A-A3-A-A9-A-A3-A3(-2A)-A9-A2(-2A)-A27-A2(-2A)-A9-A11(-2A)-A27-A9(-2A)2(-A3-A-2A)-A3-A-A27-A3(-A3-A-2A)8(-2A)-A27-A8(-2A)-29A8(-2A)-31A2(3-6A)3-4A2(-A3-A-2A)-A3-A-4A2(3-6A)3-31A8(-2A)-37A9-10A2(-2A)-A9-A2(-2A)-10A9-12A3-3A9-3A3-4A-A3-A-A9-A-A3-A-4A3-3A9-3A3-12A9-10A2(-2A)-A9-A2(-2A)-10A9-37A8(-2A)-31A2(3-6A)3-4A2(-A3-A-2A)-A3-A-4A2(3-6A)3-31A8(-2A)-28A
