model
size = 30 16 31, scale = 0.05, origin = -y
material deform = 1, fade = true, lighting = smooth, roughness = 0.3, metalness = 0.6
  colors = A:#C6F B:#200 C:#FC3 D:#BBB E:#F93 F:#DDD G:#555
voxels
38-11A18-13A16-3A9B3A14-3A7B2D2B2A13-3A10BDB3A12-3A11BDB4(2A12-2A14B)2A12-2A2BF11B2A8-6A2BGDF9B4ACE2C2-6A14B4A2(4C6-20A)CE2C11-8A20-13A16-15A15-4A6-5A14-3A10-4A12-3A11-4A2(12-3A13-2A)2(12-2A14-2A)11-3A14-2A10-4A14-2A8-6A12-6A2CAC2-6A12-6A2CAC6-20A4C6-20ACE2C388-2A27-CAC27-3C28-2A388-2A2(28-2C)28-13(2A388-3(2A28-))2(2A389-3(A29-)A389-2(3(2A28-)2A388-)3(2A28-))4(2A388-3(2A28-))2A2(389-3(A29-)A)
