model
size = 11 32 11, scale = 0.05, origin = -y
material deform = 1, fade = true, lighting = smooth, roughness = 0.3, metalness = 0.6
  colors = A:#FF0505 B:#FDFDFD C:#FFE11D
voxels
52-6(A10-)11(B10-)5(A10-)A87-5(A10-)3(2A9-)5(2B9-)2A5(9-2B)3(9-2A)9-3(A10-)A37-5C56-A10-5(2A9-)4(2B9-)BA9-2A9-BA4(9-2B)5(9-2A)9-3(A10-)A14-2C3-2C13-9(A10-)A3(9-2B)9-BA4(9-2A)3(9-2B)2(9-2A)2(9-3(A10-)A)2-2C5-2C56-5(A10-)A2(9-2B)9-BA6(9-2A)2(9-2B)3(9-2A)9-2(A10-)A9-2A9-2(A10-)A2-C7-C23-8(A10-)A9-2B9-BA8(9-2A)9-2B4(9-2A)9-A10-A2(9-2A)9-A10-A2-C7-C56-5(A10-)A2(9-2B)9-2A9-2B3(9-2A)9-2B9-2A2(9-2B)3(9-2A)9-2(A10-)A9-2A9-2(A10-)A2-C7-C12-9(A10-)A3(9-2B)5(9-2A)3(9-2B)2(9-2A)2(9-3(A10-)A)2-2C5-2C54-A10-5(2A9-)2(2B9-)2A9-2B3(9-2A)9-2B9-2A2(9-2B)5(9-2A)9-3(A10-)A14-2C3-2C33-5(A10-)3(2A9-)5(2B9-)2A5(9-2B)3(9-2A)9-3(A10-)A37-5C56-6(A10-)11(B10-)5(A10-)A57-
