model
size = 11 32 11, scale = 0.05, origin = -y
material deform = 1, fade = true, lighting = smooth, roughness = 0.3, metalness = 0.6
  colors = A:#E90101 B:#FBFBFB C:#FFE11D
voxels
52-9(A10-)2(B10-)11(A10-)A87-5(A10-)6(2A9-)2(2B9-)9(2A9-)3(A10-)A37-5C56-A10-8(2A9-)2(2B9-)11(2A9-)3(A10-)A14-2C3-2C13-9(A10-)A3(9-2A)2(9-2B)8(9-2A)2(9-3(A10-)A)2-2C5-2C56-5(A10-)A3(9-2A)2(9-2B)9(9-2A)9-2(A10-)A9-2A9-2(A10-)A2-C7-C23-8(B10-)B15(9-2B)9-B10-B2(9-2B)9-B10-B2-C7-C56-5(B10-)B14(9-2B)9-2(B10-)B9-2B9-2(B10-)B2-C7-C12-9(A10-)A3(9-2A)2(9-2B)8(9-2A)2(9-3(A10-)A)2-2C5-2C54-A10-8(2A9-)2(2B9-)11(2A9-)3(A10-)A14-2C3-2C33-5(A10-)6(2A9-)2(2B9-)9(2A9-)3(A10-)A37-5C56-9(A10-)2(B10-)11(A10-)A57-
