model
size = 11 32 11, scale = 0.05, origin = -y
material deform = 1, fade = true, lighting = smooth, roughness = 0.3, metalness = 0.6
  colors = A:#FDFDFD B:#FF220B C:#0E8A0E D:#FFE11D
voxels
52-7(C10-)9(A10-)6(B10-)B87-5(C10-)4(2C9-)9(2A9-)4(2B9-)3(B10-)B37-5D56-C10-6(2C9-)9(2A9-)6(2B9-)3(B10-)B14-2D3-2D13-9(C10-)C9-2C9(9-2A)3(9-2B)2(9-3(B10-)B)2-2D5-2D56-5(C10-)C9-2C9(9-2A)4(9-2B)9-2(B10-)B9-2B9-2(B10-)B2-D7-D23-8(C10-)C9-2C9(9-2A)5(9-2B)9-B10-B2(9-2B)9-B10-B2-D7-D56-5(C10-)C9-2C9(9-2A)4(9-2B)9-2(B10-)B9-2B9-2(B10-)B2-D7-D12-9(C10-)C9-2C9(9-2A)3(9-2B)2(9-3(B10-)B)2-2D5-2D54-C10-6(2C9-)9(2A9-)6(2B9-)3(B10-)B14-2D3-2D33-5(C10-)4(2C9-)9(2A9-)4(2B9-)3(B10-)B37-5D56-7(C10-)9(A10-)6(B10-)B57-
