model
size = 11 32 11, scale = 0.05, origin = -y
material deform = 1, fade = true, lighting = smooth, roughness = 0.3, metalness = 0.6
  colors = A:#FBFBFB B:#F7F7F7 C:#FF0505 D:#FFE11D
voxels
52-17(A10-)5(B10-)B87-5(A10-)6(2A9-)AC3(9-2C)9-AC3(9-2A)3(9-2B)9-3(B10-)B37-5D56-A10-7(2A9-)7(2C9-)2(2A9-)5(2B9-)3(B10-)B14-2D3-2D13-9(A10-)A9-2A9(9-2C)9-2A2(9-2B)2(9-3(B10-)B)2-2D5-2D56-5(A10-)A9-2A9(9-2C)9-2A3(9-2B)9-2(B10-)B9-2B9-2(B10-)B2-D7-D23-8(A10-)A9-2A9(9-2C)5(9-2B)9-B10-B2(9-2B)9-B10-B2-D7-D56-5(A10-)A9-2A9(9-2C)4(9-2B)9-2(B10-)B9-2B9-2(B10-)B2-D7-D12-9(A10-)A9-2A9(9-2C)3(9-2B)2(9-3(B10-)B)2-2D5-2D54-A10-7(2A9-)7(2C9-)2A6(9-2B)9-3(B10-)B14-2D3-2D33-5(A10-)6(2A9-)AC3(9-2C)9-AC2(9-2A)4(9-2B)9-3(B10-)B37-5D56-16(A10-)6(B10-)B57-
