model
size = 11 32 11, scale = 0.05, origin = -y
material deform = 1, fade = true, lighting = smooth, roughness = 0.3, metalness = 0.6
  colors = A:#E90101 B:#1E00D8 C:#F8F8F8 D:#FFE11D
voxels
52-8(A10-)C2(10-B)10-C11(10-A)87-5(A10-)5(2A9-)2C2(9-2B)9-2C8(9-2A)9-3(A10-)A37-5D56-A10-7(2A9-)2C2(9-2B)9-2C10(9-2A)9-3(A10-)A14-2D3-2D13-9(A10-)A2(9-2A)9-2C2(9-2B)9-2C7(9-2A)2(9-3(A10-)A)2-2D5-2D56-5(C10-)C3(9-2C)2(9-2B)9(9-2C)9-2(C10-)C9-2C9-2(C10-)C2-D7-D23-8(B10-)B15(9-2B)9-B10-B2(9-2B)9-B10-B2-D7-D56-5(B10-)B14(9-2B)9-2(B10-)B9-2B9-2(B10-)B2-D7-D12-9(C10-)C3(9-2C)2(9-2B)8(9-2C)2(9-3(C10-)C)2-2D5-2D54-A10-7(2A9-)CA2(9-2B)9-2C10(9-2A)9-3(A10-)A14-2D3-2D33-5(A10-)5(2A9-)CA2(9-2B)9-2C8(9-2A)9-3(A10-)A37-5D56-8(A10-)C2(10-B)10-C11(10-A)57-
