model
size = 11 32 11, scale = 0.05, origin = -y
material deform = 1, fade = true, lighting = smooth, roughness = 0.3, metalness = 0.6
  colors = A:#FAFAFA B:#F60000 C:#0000B4 D:#FFE11D
voxels
52-A3(10-B)2(10-A)4(10-C)10-A10-B10-A4(10-C)2(10-A)3(10-B)10-A87-3(C10-)2(A10-)3(2B9-)2(2A9-)2(2C9-)2A9-2B9-2A2(9-2C)2(9-2A)3(9-2B)9-2(A10-)C10-C37-5D56-C10-2(2C9-)2(2A9-)3(2B9-)3(2A9-)2B3(9-2A)3(9-2B)2(9-2A)2(9-2C)9-3(C10-)C14-2D3-2D13-9(C10-)A9-2A3(9-2B)2(9-2A9-2B)2(9-2B)2(9-2A)9-2C2(9-3(C10-)C)2-2D5-2D56-5(A10-)A4(9-2A)9-AB9-2B9-AB7(9-2A)9-2(A10-)A9-2A9-2(A10-)A2-D7-D23-8(B10-)B15(9-2B)9-B10-B2(9-2B)9-B10-B2-D7-D56-5(A10-)A4(9-2A)9-AB9-2B9-AB7(9-2A)9-2(A10-)A9-2A9-2(A10-)A2-D7-D12-9(C10-)A9-2A3(9-2B)2(9-2A9-2B)2(9-2B)2(9-2A)9-2C2(9-3(C10-)C)2-2D5-2D54-C10-2(2C9-)2(2A9-)3(2B9-)3(2A9-)2B3(9-2A)3(9-2B)2(9-2A)2(9-2C)9-3(C10-)C14-2D3-2D33-3(C10-)2(A10-)3(2B9-)2(2A9-)2(2C9-)2A9-2B9-2A2(9-2C)2(9-2A)3(9-2B)9-2(A10-)C10-C37-5D56-A3(10-B)2(10-A)4(10-C)10-A10-B10-A4(10-C)2(10-A)3(10-B)10-A57-
