model
size = 32 27 18, scale = 0.05, origin = -y
material deform = 1, fade = true, lighting = smooth, roughness = 0.3, metalness = 0.6
  colors = A:#563F2E B:#222 C:#3A3226 D:#43341B
voxels
548-3A28-5(6A26-)6A27-5A28-3A572-3A28-5(6A26-)6A27-5A28-3A478-A30-2A14-A14-3A14-2A12-5A13-4A8-9A10-5A8-4(9A10-6A7-)9A10-5A9-8A11-3A11-7A12-2A12-6A88-5B13-4B11-3B14-4B12-2B15-3B13-2A16-A13-2A16-2A12-2(2A17-2A11-)2A17-3A10-3A16-2A11-3A15-3A10-4A14-3A11-4A13-3A12-4A12-3A13-4A12-4A11-5A12-6A8-7A11-6A7-9A10-6A7-25A6-3(27A5-)27A6-26A7-25A8-8A87-5B13-5B11-2B15-3B12-2B15-3B13-2A16-A13-2A16-2A12-2A17-2A11-2(2A17-3A10-)3A16-3A10-3A15-3A10-4A14-3A11-4A13-3A12-4A12-3A13-4A12-4A11-5A12-6A8-7A2-8A-7A6-26A5-5(28A4-)28A5-27A6-24A72-5B13-4B12-2B14-4B12-2B15-3B13-2A16-A13-2A16-2A12-2(2A17-2A11-)2A17-3A10-3A16-2A11-3A15-3A10-4A14-3A11-4A13-3A12-4A12-3A13-4A12-4A11-5A12-6A8-7A2-8A-7A6-27A6(4-28A)5-27A5-26A8-5A3-14A41-5B28-3B30-2B5(31-A)31-2A30-3A4(28-4A)12-4A11-5A12-6A8-7A2-8A-7A6-27A6(4-28A)5-27A5-26A7-7A-16A9-5A475-5A13-5A8-7A2-8A-7A6-27A6(4-28A)2(5-27A)6-24A9-5A506-7A2-8A-7A6-27A6(4-28A)2(5-27A)6-25A8-5A407-B31-C30-BC30-2C3-6A2-8A-7A3-2C-27A-B2C4(28A-3C)28A-2CD28A-CD2-27A2C3-27AC5-25A8-5A407-B31-C30-BC30-2C3-6A2-8A-7A3-2C-C26A-B2C4(AC26A-3C)AC26A-2CDAC26A-CD2-27A2C3-27AC5-25A8-5A506-7A2-8A-7A6-27A6(4-28A)2(5-27A)6-25A8-5A475-5A13-5A8-7A2-8A-7A6-27A6(4-28A)2(5-27A)6-24A9-5A26-5B28-3B30-2B5(31-A)31-2A30-3A4(28-4A)12-4A11-5A12-6A8-7A2-8A-7A6-27A6(4-28A)5-27A5-26A7-7A-16A9-5A26-5B13-4B12-2B14-4B12-2B15-3B13-2A16-A13-2A16-2A12-2(2A17-2A11-)2A17-3A10-3A16-2A11-3A15-3A10-4A14-3A11-4A13-3A12-4A12-3A13-4A12-4A11-5A12-6A8-7A2-8A-7A6-27A6(4-28A)5-27A5-26A8-5A3-14A41-5B13-5B11-2B15-3B12-2B15-3B13-2A16-A13-2A16-2A12-2A17-2A11-2(2A17-3A10-)3A16-3A10-3A15-3A10-4A14-3A11-4A13-3A12-4A12-3A13-4A12-4A11-5A12-6A8-7A2-8A-7A6-26A5-5(28A4-)28A5-27A6-24A72-5B13-4B11-3B14-4B12-2B15-3B13-2A16-A13-2A16-2A12-2(2A17-2A11-)2A17-3A10-3A16-2A11-3A15-3A10-4A14-3A11-4A13-3A12-4A12-3A13-4A12-4A11-5A12-6A8-7A11-6A7-9A10-6A7-25A6-3(27A5-)27A6-26A7-25A8-8A475-A30-2A14-A14-3A14-2A12-5A13-4A8-9A10-5A8-4(9A10-6A7-)9A10-5A9-8A11-3A11-7A12-2A12-6A86-
