model
size = 14 17 32, scale = 0.05, origin = -y
material deform = 1, fade = true, lighting = smooth, roughness = 0.3, metalness = 0.6
  colors = A:#FFF B:#383838 C:#010101 D:#242424 E:#A8A8A8 F:#2F2F2F G:#303030 H:#282828 I:#888 J:#1D1D1D K:#151515 L:#111 M:#0D0D0D N:#0A0A0A O:#020202 P:#080808 Q:#CFCFCF R:#252525
voxels
18-2(E5A8-)6C9-3FE174-2(4E5A5-)9C6-7F8-2(5B9-)5G9-5H2(9-5D)9-5J9-5K9-5L9-5M9-5N9-5P9-5O7-2(4E5A5-)9C6-7F8-2(5B9-)5G9-5H2(9-5D)9-5J9-5K9-5L9-5M9-5N9-5P9-5O6-2(5E6A3-)11C4-9F6-2(7B7-)7G7-7H2(7-7D)7-7J7-7K7-7L7-7M7-7N7-7P7-7O5-2(5E7A2-)12C3-10F5-2(8B6-)8G6-8H2(6-8D)6-8J6-8K6-8L6-8M6-8N6-8P6-8O4-2(2(5E7A2-)12C3-10F2(5-9B)5-9G5-9H2(5-9D)5-9J5-9K5-9L5-9M5-9N5-9P5-9O3-)2(5E7A2-)12C3-10F2(5-9B)5-9G5-9H2(5-9D)5-9J5-9K5-9L5-9M5-9N5-9P5-9O4-2(4E7A3-)11C4-9F2(6-8B)6-8G6-8H6-8D6-8I6-8J6-8K6-8L6-8M6-8N6-8P6-8O4-2(4E8A2-)12C3-10F5-2(8B6-)8G7-7H7-7I7-7D7-7J7-7K7-7L7-7M7-7N7-7P7-7O5-2(3E8A3-)11C4-9F6-2(7B7-)7G7-7I2(7-7D)7-7J7-7K8-5L9-5M9-5N9-P3IP9-5O6-2(3E8A3-)11C4-9F6-2(7B7-)7I7-7H2(7-7D)7-7J8-5K9-5L9-M3IM49-2(2E8A4-)10C5-8Q6-7B7-7I7-7G8-5H9-5I9-5D9-5J9-K3IK77-2(2E8A4-)10C5-8Q7-6I8-6B8-6G8-5I9-5D9-D3ID105-2(2E8A4-)10C5-8Q7-2(6B8-)6I8-5H9-5D119-2(2E8A4-)10C5-8Q7-6B8-6I8-6G8-5H9-D3ID119-2(2E8A4-)10C5-8Q7-6I8-6B8-6G8-5I9-5D119-2(2E8A4-)10C5-8Q7-2(6B8-)6I8-5H9-D3ID119-2(2E8A4-)10C5-8Q7-6B8-6I8-6G8-5H9-5D11-2D106-2(2E8A4-)10C5-8Q7-7I7-7B7-7G7-6H8-6D9-4D105-2(2E9A3-)11C4-9F6-2(7B7-)7G7-6H8-6D9-4D105-2(2E9A3-)11C4-10F4-2(9B5-)9G6-7H7-7D8-4D104-2(3E9A2-)12C3-11F4-2(9B5-)9G5-8H6-8D8-3D105-2(3E9A2-)12C3-10F2(5-9B)5-9G5-8H6-8D8-3D104-2(4E8A2-)12C3-11F2(4-10B)4-10G5-8H6-8D7-3D105-2(4E8A2-)12C3-10FE4-2(9B5-)9G6-7H7-6D9-3D104-2(5E8A-)13C2-11F4-9BE5-9B5-9G6-7H7-6R116-2(5E7A2-)12C3-10FE4-9B6-7BE6-8G7-6H8-5R117-2(5E7A2-)12C3-10F5-8BE6-7B8-5GE9-3HE132-2(4E7A3-)11C4-9F6-7B8-6B8-2G3E147-2(3E6A5-)9C6-8F7-6B9-3BE162-2(2E6A6-)8C7-6F9-B3E173-
