model
size = 21 17 21, scale = 0.05, origin = -y
material deform = 1, fade = true, lighting = smooth, roughness = 0.3, metalness = 0.6
  colors = A:#C25100 B:#EFEFEF C:#000
voxels
72-BCB17-2BC2B15-2(3BC3B14-)3BC3B15-2BC2B17-BCB185-2BC2B15-3BC3B13-3B3C3B11-3B5C3(3B10-2B6C)3B10-3B5C3B11-3B3C3B13-3BC3B15-2BC2B120-3BC3B13-2B5A2B11-2B2A3C2A2B9-2B3C3-3C2B8-B3C5-3(3CB8-B2C6-)3CB8-B3C5-3CB8-2B3C3-3C2B9-2B7C2B11-2B5C2B13-3BC3B96-11B8-C2B9C2BC6-CB11CBC6-3C9-3C5(6-2C11-2C)6-3C9-3C6-CB2C7-2CBC6-C2B9C2BC8-2B7A2B12-3BC3B74-C2B7-2BC7-B2C9-2CB6-BC11-CB5-6(BAC12-CB4-)BAC12-CB5-BC11-CB6-BA12CB7-C11AC8-C2B7A2BC11-3BC3B52-2B11-2B6-BC11-CB5-BAC11-CAB4-BAC12-CB3-4(B2AC12-CAB2-)B2AC12-CAB3-BAC12-CB4-BAC12-CB5-BA12CB6-B13AB7-BC10AB9-C2B5A2BC13-2BC2B32-2B11-2B5-BAC11-CAB4-BAC11-CAB3-6(B2AC12-CAB2-)B2AC12-CAB3-BAC12-CB4-B2A12CAB5-B13AB7-B11AB9-B2C5A2CB12-7C30-3B11-3B4-BAC11-CAB3-B2AC11-C2A2(B2-B2AC12-CA)B-B2(3AC12-C2A2B)3AC12-C2AB-2(B2AC12-CAB2-)B2AC12-CAB3-B2A12CAB4-B15AB5-B13AB7-2B9A2B10-3B3A3B15-BCB2(11-3B)3-2(B2AC11-C2AB2-)B2AC12-CAB-B4(3AC12-C2A2B)3AC12-C2AB-2(B2AC12-CAB2-)B3A12C2AB3-B15AB5-B13AB7-B11AB9-3B5A3B13-2BC2B10-3B11-3B3-B2AC11-C2AB2-B2AC11-C2AB-B6(3AC12-C2A2B)3AC12-C2AB-B2AC12-CAB2-B3A12C2AB3-B15AB5-B13AB7-B11AB9-2B7A2B12-3BC3B9-C2B11-2BC3-C2AC11-C2AC2-C2AC11-C2AC-C6(3AC12-C2A2C)3AC12-C2AC-C2AC12-CAC2-C3A12C2AC3-C15AC5-C13AC7-C11AC9-2C7A2C12-7C9-3B11-3B3-B2AC11-C2AB2-B2AC11-C2AB-B6(3AC12-C2A2B)3AC12-C2AB-B2AC12-CAB2-B3A12C2AB3-B15AB5-B13AB7-B11AB9-2B7A2B12-3BC3B9-3B11-3B3-2(B2AC11-C2AB2-)B2AC12-CAB-B4(3AC12-C2A2B)3AC12-C2AB-2(B2AC12-CAB2-)B3A12C2AB3-B15AB5-B13AB7-B11AB9-3B5A3B13-2BC2B10-3B11-3B4-BAC11-CAB3-B2AC11-C2A2(B2-B2AC12-CA)B-B2(3AC12-C2A2B)3AC12-C2AB-2(B2AC12-CAB2-)B2AC12-CAB3-B2A12CAB4-B8AB6AB5-B13AB7-2B9A2B10-3B3A3B15-BCB12-2B11-2B5-BAC11-CAB4-BAC11-CAB3-6(B2AC12-CAB2-)B2AC12-CAB3-BAC12-CB4-B2A5C2-5CAB5-B6A2CB4AB7-B6AC4AB9-B2C5A2CB12-7C31-2B11-2B6-BC11-CB5-BAC11-CAB4-BAC12-CB3-4(B2AC12-CAB2-)B2AC12-CAB3-BAC12-CB4-BAC12-CB5-BA12CB6-B7AB5AB7-BC10AB9-C2B5A2BC13-2BC2B33-B11-B7-BC11-CB6-BC11-CB5-6(BAC12-CB4-)BAC12-CB5-BC12-B6-BA12CB7-C11AC8-C2B7A2BC11-3BC3B54-2B7-2B8-C2B9-2BC6-CB2(11-BC6-2C)5(12-C6-2C)12-C6-CB11-BC6-C2B7C-C2BC8-2B6AC2B12-3BC3B77-7B13-B7-B11-2(B9-)2B9-2B5(8-2B10-B)8-2(2B9-)2B7-2B11-2B5C2B13-3BC3B101-B20-B57-4(2B7-2B10-)3B5-3B11-3B3-3B13-3BC3B15-2BC2B204-3(3BC3B14-)3BC3B15-2BC2B17-BCB156-
