model
size = 21 17 21, scale = 0.05, origin = -y
material deform = 1, fade = true, lighting = smooth, roughness = 0.3, metalness = 0.6
  colors = A:#8CFF53 B:#C25100 C:#EFEFEF D:#000
voxels
72-3A17-5A15-2(7A14-)7A15-5A17-3A185-5A15-7A13-9A11-4(11A10-)11A11-9A13-7A15-5A120-7A13-2A5B2A11-2A2B3A2B2A9-5A3-5A8-4A5-4A3(8-3A7-3A)8-4A5-4A8-5A3-5A9-11A11-2A5D2A13-7A96-11A8-2(C13AC6-)CDA9-2A5(C6-CA11-A)C6-CDA9-2AC6-C3A7-3AC6-C2AD7AD2AC8-2A7B2A12-7A74-C2A7-2AC7-ADA9-ADA6-2A11-2A5-6(ABA11-3A4-)ABA11-3A5-2A11-2A6-AB11ADA7-C11BC8-C2A7B2AC11-7A52-2A11-2A6-2A11-2A5-ABA11-ABA4-ABA11-3A3-4(A2BA11-2ABA2-)A2BA11-2ABA3-ABA11-3A4-ABA11-3A5-AB13A6-A13BA7-AD10BA9-3C5B3C13-5C32-2A11-2A5-ABA11-ABA4-ABA11-ABA3-6(A2BA11-2ABA2-)A2BA11-2ABA3-ABA11-3A4-A2B12ABA5-A13BA7-A11BA9-2AD5BD2A12-7A30-3A11-3A4-ABA11-ABA3-A2BA11-A2B2(A2-A2BA11-2AB)A-A2(3BA11-2A2B2A)3BA11-2A2BA-2(A2BA11-2ABA2-)A2BA11-2ABA3-A2B12ABA4-A15BA5-A13BA7-2A9B2A10-3A3B3A15-2(3A11-)3A3-2(A2BA11-A2BA2-)A2BA11-2ABA-A4(3BA11-2A2B2A)3BA11-2A2BA-2(A2BA11-2ABA2-)A3B12A2BA3-A15BA5-A13BA7-A11BA9-3A5B3A13-5A10-3(3A11-3A3-A2BA11-A2BA2-A2BA11-A2BA-A6(3BA11-2A2B2A)3BA11-2A2BA-A2BA11-2ABA2-A3B12A2BA3-A15BA5-A13BA7-A11BA9-2A7B2A12-7A9-)3A11-3A3-2(A2BA11-A2BA2-)A2BA11-2ABA-A4(3BA11-2A2B2A)3BA11-2A2BA-2(A2BA11-2ABA2-)A3B12A2BA3-A15BA5-A13BA7-A11BA9-3A5B3A13-5A10-3A11-3A4-ABA11-ABA3-A2BA11-A2B2(A2-A2BA11-2AB)A-A2(3BA11-2A2B2A)3BA11-2A2BA-2(A2BA11-2ABA2-)A2BA11-2ABA3-A2B12ABA4-A8BC6BA5-A13BA7-2A9B2A10-3A3B3A15-3A12-2A11-2A5-ABA11-ABA4-ABA11-ABA3-6(A2BA11-2ABA2-)A2BA11-2ABA3-ABA11-3A4-A2B12ABA5-A6B2AC4BA7-A6BD4BA9-2AD5BD2A12-7A31-2A11-2A6-2A11-2A5-ABA11-ABA4-ABA11-3A3-4(A2BA11-2ABA2-)A2BA11-2ABA3-ABA11-3A4-ABA11-3A5-AB13A6-A7BC5BA7-AD10BA9-3C5B3C13-5C33-C11-C7-2A11-2A6-2A11-2A5-6(ABA11-3A4-)ABA11-3A5-2A11-2A6-AB13A7-C11BC8-C2A7B2AC11-7A54-2A7-2A8-C2A9-2A9(C6-CA11-A)C6-C13AC8-2A6B3A12-7A77-7A13-A7-A11-2(A9-)2A9-2A5(8-2A10-A)8-2(2A9-)2A7-2A11-9A13-7A101-A20-A57-4(2A7-2A10-)3A5-3A11-3A3-3A13-7A15-5A204-3(7A14-)7A15-5A17-3A156-
