model
size = 21 17 21, scale = 0.05, origin = -y
material deform = 1, fade = true, lighting = smooth, roughness = 0.3, metalness = 0.6
  colors = A:#FF1A40 B:#C25100 C:#DBFF70 D:#EFEFEF E:#000
voxels
72-3A17-5A15-2(7A14-)7A15-5A17-3A185-5A15-7A13-9A11-4(11A10-)11A11-9A13-7A15-5A120-7A13-2A5B2A11-2A7B2A9-5A3-5A8-4A5-4A3(8-3A7-3A)8-4A5-4A8-5A3-5A9-11A11-2A5E2A13-7A96-11A8-2(D13AD6-)DEA10-5(AD6-DA11-)AD6-DEA9-2AD6-D3A7-3AD6-D2AE7AE2AD8-2A7B2A12-7A74-D2A7-2AD7-CEA9-AEC6-CA11-AC5-6(CBA11-2AC4-)CBA11-2AC5-CA11-AC6-CB11AEC7-D11BD8-D2A7B2AD11-7A52-2C11-2C6-CA11-AC5-CBA11-ABC4-CBA11-2AC3-4(C2BA11-2ABC2-)C2BA11-2ABC3-CBA11-2AC4-CBA11-2AC5-CB12AC6-C13BC7-CE10BC9-3D5B3D13-5D32-2C11-2C5-CBA11-ABC4-CBA11-ABC3-6(C2BA11-2ABC2-)C2BA11-2ABC3-CBA11-2AC4-C2B12ABC5-C13BC7-C11BC9-2CE5BE2C12-7C30-3C11-3C4-CBA11-ABC3-C2BA11-A2B2(C2-C2BA11-2AB)C-C2(3BA11-2A2B2C)3BA11-2A2BC-2(C2BA11-2ABC2-)C2BA11-2ABC3-C2B12ABC4-C15BC5-C13BC7-2C9B2C10-3C3B3C15-2(3C11-)3C3-2(C2BA11-A2BC2-)C2BA11-2ABC-C4(3BA11-2A2B2C)3BA11-2A2BC-2(C2BA11-2ABC2-)C3B12A2BC3-C15BC5-C13BC7-C11BC9-3C5B3C13-5C10-3(3C11-3C3-C2BA11-A2BC2-C2BA11-A2BC-C6(3BA11-2A2B2C)3BA11-2A2BC-C2BA11-2ABC2-C3B12A2BC3-C15BC5-C13BC7-C11BC9-2C7B2C12-7C9-)3C11-3C3-2(C2BA11-A2BC2-)C2BA11-2ABC-C4(3BA11-2A2B2C)3BA11-2A2BC-2(C2BA11-2ABC2-)C3B12A2BC3-C15BC5-C13BC7-C11BC9-3C5B3C13-5C10-3C11-3C4-CBA11-ABC3-C2BA11-A2B2(C2-C2BA11-2AB)C-C2(3BA11-2A2B2C)3BA11-2A2BC-2(C2BA11-2ABC2-)C2BA11-2ABC3-C2B12ABC4-C8BD6BC5-C13BC7-2C9B2C10-3C3B3C15-3C12-2C11-2C5-CBA11-ABC4-CBA11-ABC3-6(C2BA11-2ABC2-)C2BA11-2ABC3-CBA11-2AC4-C2B12ABC5-C6B2AD4BC7-C6BE4BC9-2CE5BE2C12-7C31-2C11-2C6-CA11-AC5-CBA11-ABC4-CBA11-2AC3-4(C2BA11-2ABC2-)C2BA11-2ABC3-CBA11-2AC4-CBA11-2AC5-CB12AC6-C7BD5BC7-CE10BC9-3D5B3D13-5D33-D11-D7-CA11-AC6-CA11-AC5-6(CBA12-AC4-)CBA12-AC5-CA12-C6-CB12AC7-D11BD8-D2A7B2AD11-7A54-2A7-2A8-D2A9-2A9(D6-DA11-A)D6-D13AD8-2A6B3A12-7A77-7A13-A7-A11-2(A9-)2A9-2A5(8-2A10-A)8-2(2A9-)2A7-2A11-9A13-7A101-A20-A57-4(2A7-2A10-)3A5-3A11-3A3-3A13-7A15-5A204-3(7A14-)7A15-5A17-3A156-
