model
size = 32, scale = 0.05, origin = -y
material deform = 1, fade = true, lighting = smooth, roughness = 0.3, metalness = 0.6
  colors = A:#444 B:#FF0 C:#06C
voxels
584-3A29-3A28-2(5A27-)5A28-3A813-5A2(29-4A)25-3A29-3A27-A-3A27-2(3A30-)5A402-B328-5A26-3A3-A24-A6-2A22-A2-3A2-2A22-2(A-7A23-)9A23-6A27-3A30-7A26-5A370-B31-B43-B174-5A26-4A11-5A11-2A13-3A3-A10-A13-3A5-A9-A12-7A12-A11-3A-6A22-11A13-A7-11A13-2A6-11A21-10A23-3A30-3A3-3A24-7A401-B31-B11-B31-B47-C31-C30-5A26-7A24-9A6-7A9-4A5-2A4-4A3-2A8-3A6-2A3-7A11-3A7-A2-9A10-3A10-10A9-A12-11A13-A7-11A13-2A6-11A13-3A5-10A22-4A29-4A3-3A16-3A4-9A16-3A6-3A20-3A6-3A208-2(C31-)C95-C3-B31-B11-B15-C15-B15-C30-5A26-7A24-9A8-3A11-11A4-9A7-5A3-5A2-5A3-2A2(8-2(3A-)4A-11A)8-3A-3A3-2A-11A8-A9-14A13-2A3-A-12A13-5A2-12A13-4A3-5A3-3A13-5A3-5A19-7A-6A3-A14-8A-11A5-7A-A-5A4-5A8-4A6-5A4-5A8-4A7-3A6-3A372-B31-B11-B31-B13-7A11-B12-9A22-11A6-5A9-13A3-9A8-12A2-5A2-3A9-11A-12A6-13A-12A6-26A6-25A8-A3-19A9-A3-14A2-3A13-14A2-3A11-16A2-3A11-20A7-27A4-16A3-8A5-6A4-6A3-8A5-6A2(5-4A)9-4A391-B27-3A-B11-B12-9A10-B11-11A9-B10-13A5-5A9-13A3-9A8-12A2-10A7-26A2(5-27A)5-26A7-24A10-2(23A9-)23A7-24A6-27A4-16A3-9A4-8A2-6A3-9A4-8A3-4A5-7A6-4A418-5A25-9A10-B11-11A9-B10-13A5-5A9-13A3-9A8-13A-10A7-26A2(5-27A)5-26A7-24A10-23A9-23A10-22A6-25A6-27A4-17A2-9A4-9A-7A2-9A4-9A2-4A5-7A6-7A290-C95-C28-5A25-9A10-B11-11A9-B10-13A6-3A10-13A3-9A6-15A-6A3-A7-25A2(6-26A)6-2(24A9-)24A8-24A9-23A5-2A3-22A4-28A3-11A-7A-9A5-8A2-7A-9A5-8A5-3A3-3A-3A10-3A415-5A12-B12-9A10-B11-11A9-B10-13A19-13A4-7A7-15A2-5A3-A6-21A11-23A9-23A10-22A10-21A11-24A8-24A10-22A6-A4-18A8-24A7-25A12-5A-15A11-5A5-3A7-3A10-3A218-B4(31-2B)31-B17-B13-B-3A13-B12-9A22-11A20-13A19-13A5-5A9-13A4-4A3-C6-2(21A11-)21A12-21A10-24A8-23A9-23A10-21A9-A4-17A9-23A8-23A15-3A-13A15-3A2-7A-3A387-B31-B45-7A24-9A22-11A20-13A19-13A5-5A9-21A11-2(21A3-A7-)25A6-24A8-23A9-23A10-21A9-A3-18A9-23A8-23A14-18A14-5A-4A3-4A16-3A300-2B29-3B29-2B3-B25-2B30-2B19-5A6-B19-7A4-2B18-9A3-B18-11A20-13A19-23A9-24A8-25A7-25A6-24A8-23A9-23A10-21A9-22A9-23A8-16A-6A13-12A-6A-A11-6A-2(4A3-)A12-3A465-C13-5A5-B7-C12-7A4-B7-C11-9A3-B18-11A21-11A2-3A16-19A2-C10-21AC10-23A8-2(23A9-)22A10-2(22A9-)23A8-15A-6A-A10-13A-6A-2A9-12A3-4A3-3A8-5A511-5A26-7A4-B19-9A3-B18-10A3-B19-9A-7A15-18A2-C11-19A12-21A10-22A11-21A11-20A11-21A10-22A9-14A-5A2-5A6-13A-5A2-5A6-6A-5A3-3A4-3A8-3A523-B19-5A7-B18-7A25-8A5-5A12-11A3-7A11-11A2-9A10-23A6-2A3-21A6-26A6-25A7-25A11-21A11-20A11-13A-8A3-A6-5A-7A-12A6-5A2-5A3-3A4-3A8-3A491-B19-5A7-B18-7A24-9A22-11A3-7A10-13A-9A9-24A5-2A-24A5-3A-22A5-27A5-28A2(5-27A)7-2A-21A10-13A2-7A3-A6-5A2-6A2-11A6-5A4-3A6-3A-3A8-3A459-B31-B18-7A24-9A22-11A5-3A12-13A-9A9-24A6-27A5-26A6-25A5-27A5-2(28A4-)28A5-26A10-7A2-7A-5A10-6A3-7A-9A6-6A12-6A9-5A14-4A11-3A15-3A11-3A361-B31-B20-3A26-9A22-11A20-13A3-5A11-13A-9A2(7-26A)6-25A7-24A7-25A7-26A6-26A4-28A5-26A7-12A2-13A8-9A2-16A5-7A5-4A2-8A7-6A12-6A9-5A13-5A9-5A14-3A311-B31-B51-5A25-9A22-11A7-C12-13A3-5A11-13A-9A8-25A7-2(26A6-)2(25A7-)24A8-27A4-28A2-30A4-20A-6A8-17A-7A7-9A3-4A3-7A7-6A12-6A9-5A13-5A9-5A14-3A14-2(C31-)C191-2(C8-B22-)C31-C28-5A25-9A22-11A20-2(13A19-)14A18-14A2-5A11-23A8-25A7-26A6-27A5-28A3-29A-31A3-20A3-5A8-16A2-6A8-10A-4A3-7A8-6A11-6A9-5A13-5A9-5A14-3A247-B31-B115-5A25-9A22-11A20-13A21-11A21-12A20-12A2-5A11-23A8-25A7-26A6-27A5-28A3-29A2-30A3-4A-15A3-5A9-15A2-6A9-10A-3A3-7A8-6A11-6A9-5A13-5A9-5A14-3A396-3A26-9A2(22-11A)2(22-10A)22-11A2-6A12-21A8-25A7-26A6-27A5-28A3-29A2-30A8-14A6-3A10-13A4-6A9-2(12A5-4A11-)3A5-4A6-3A11-3A444-7A24-9A2(23-10A)22-10A4-4A14-10A3-6A12-11A2-8A8-14A-10A6-26A6-27A5-28A3-29A5-2A-24A8-14A4-3A14-11A4-3A14-12A23-9A24-8A27-4A436-5A26-7A2(24-9A)23-10A4-4A14-10A2-8A11-11A2-8A7-15A-10A6-26A6-27A5-26A2(10-22A)10-5A2-8A2(2-5A16-9A)3-3A17-9A23-9A24-7A469-2A27-7A26-6A26-7A7-4A14-7A5-8A11-7A6-8A8-10A5-10A7-25A8-25A7-24A2(10-22A)10-5A2-8A2-5A16-9A2-6A15-9A3-3A17-9A23-9A24-7A467-6A25-2(8A24-)8A7-4A13-8A6-6A9-11A5-8A8-11A4-10A7-11A-13A8-25A8-24A2(9-23A)9-6A-8A2-6A12-12A2-8A10-12A3-6A14-9A23-9A24-7A436-4A27-6A25-8A23-10A2(21-11A)5-6A10-11A4-2(8A9-10A5-)8A9-25A8-25A9-23A9-24A8-6A-6A2(4-7A9-12A)7-3A11-3A-7A25-7A26-3A439-4A26-3A3-2A24-3A28-6A3-2(A22-A-5A2-)A7-2A12-2A-5A2-A5-6A10-7A9-6A11-4A10-8A10-4A3-2A2-2A-8A12-22A10-23A9-14A-9A9-5A13-5A9-5A-3A2(9-5A)-3A10-3A11-3A2-3A29-3A471-A29-2A30-2A29-A2-3A28-2(5A27-)5A28-3A10-3A14-5A10-4A28-4A19-A8-4A16-4A2-4A5-6A11-4A2-4A5-7A2(9-5A13-5A)9-5A14-3A11-3A508-2(A30-)2A5-A23-A2-3A2-A25-4(5A27-)5A28-3A112-2(3A11-3A15-)3A11-3A116-
