model
size = 32, scale = 0.05, origin = -y
material deform = 1, fade = true, lighting = smooth, roughness = 0.3, metalness = 0.6
  colors = A:#200 B:#FCF C:#400 D:#FC0
voxels
488-B5(30-2B)798-B31-B5(30-2B)831-B30-3B2(31-B)30-2B29-3B30-2B29-2B735-B30-2B30-3B30-B32-B31-B29-3B2(30-2B)28-4B733-2B30-3(3B29-)3B3(30-2B)29-3B28-4B733-2(2B30-)3B29-3B28-4B29-3B-B27-6B25-7B2-A22-B-5B25-7B28-3BA22-A4-5A26-2A2-A667-B31-2B2(29-3B)26-A2-3B3-B21-A3-3B2-B23-2A3-6B21-2A2B-3BA2B2A19-3A5BA2B2A18-4AB-5B3A19-A-AB-2B2AB2A21-3A2B2ABA-A22-5A-A3C23-4A2CA26-2AC-A676-2A22-2B-2B22-A4-B2-2B2(-A)18-A4-4B3A-A19-2A2-3B5A19-5A-B6A19-4A3B6A18-6A2B4AC19-12AC21-11A4C19-7A25-A-4A647-A23-B4-3A21-6BA-2A2-2A13-2A3-B2-2B2A-5A15-A3-4B9A13-5A4B5A-4A13-7AB8A-A14-13AC4A14-12AC-3A-2A13-12A3-A-C15-12A-2AC17-8A5-A18-6A615-A24-B5-3A23-3B-A-3A20-5B4AB4A18-5B7A-A18-2B-11A15-2A-B11A18-A-B11A17-2A2-11A16-3A2-12A15-3A3-4AB6A16-2A3-4A-5A-A20-3A3-2A-A2C16-A3-3A103-A443-A27-3B-3A24-4B2(-A)24-2(4B-6A21-)2(4B-7A20-)4B-4A-2A20-4B-5A-A21-3B-7A23-B-6A24-B-5AC26-5A27-B4AC26-4A29-2A30-A-3A27-A2-3A29-3A406-2B2-2A26-B2-3A25-3B7A21-5B2A-3A2(21-4B-6A)21-2(5B7A20-)5B8A19-5B8A20-4B7A23-B-8A22-B-8A24-B5AC25-B6A25-2B6A26-5A28-5A27-6A29-2A353-A20-B-3A26-3B3A7-3A15-4B6A4-3A15-3B5A-A5-A15-4B5A-A21-4B7A4-2A15-4B7A5-A15-4B7A21-4B7A5-A15-4B9A3-2A14-4B9A3-2A15-3B8A23-B9A22-B2(9A23-)B-7A25-5ACA24-A2-2A2(CA)25-3A-3A24-4A-3A25-2A4-A24-4A105-A187-A21-2A6-4A18-B-3A6-2A18-4B2A6-2A17-4B4A-A4-A16-4B5A-A3-2A16-4B4A2-A3-2A2(16-4B7A4-A)-3A12-4B8A3-A-3A12-4B8A5-3A12-4B9A4-A14-4B9A4-A15-3B9A4-2(A17-B10A3-)A19-9A2-2A19-8A25-6ACA24-A2-4A25-3A-A27-2A2-A27-2A-2A27-2A2-A71-2A-A29-2(A31-)A29-A-A29-2A28-3A28-4A17-2B2A6-5A17-2B3A6-4A16-3B4A5-2A17-4B4A5-2A16-4B5A-A21-4B4A-3A2-2(A17-4B7A3-)A2-3A12-4B8A2-2A-2A13-4B9A-A2(2-2A13-3B12A)2-2A14-2B10A2(-2A)15-B12A2-2A16-B12A-2A17-9A-A-2A21-5A2-A24-8A23-A2-2A-A21-A6-4A20-2A3-2A-4A26-6A26-5A70-4A28-4A29-A2(30-2A)28-2A-A2(27-4A)17-2B3A5-5A17-2B4A5-4A16-3B4A5-2A-A15-4B4A-2A-3A-A14-5B7A2-2A2(-A)12-5B3A-2(3A2-)A12-4B7A3-2(A-)A13-4B9A-A2-2A13-4B9A-A2-3A12-4B12A-2A13-3B13A-2A13-4B11A2-A15-2B11A3-2A15-2B12A-A17-B12A-AC15-A-11A-A-C18-7A-2A-A19-A2-8A21-2(A2-)2(A-)A26-A2-2A30-2A133-2A2(29-3A)29-2A29-3A27-2ACA27-A2-2A27-2A-2A16-2B3A5-2A2-AC16-2B3A5-2A2-C16-3B4A5-A2-A15-4B4A-A2-3A16-4B8A2-A2-2A13-5B3A-2(2A2-)A-A12-4B8A2-2(A-)2A12-4B9A-A2-3A12-4B9A-2A-3A12-4B12A-2A13-4B12A-2AC12-4B12A-2A14-2B11A2(-A)15-B14A-AC16-12AD-A18-11A-ACA18-A-5A-2A-AC24-2A2-A-2A24-A2-A82-A3-2A26-2(A-)3A27-3A47-A2(29-3A)27-A-A28-3A-A26-3A-C27-A31-3A18-2B3A5-2A-A-C16-3B2A5-2A-A17-4B3A5-A2-A15-5B3A4-2A-A15-5B6A3-5A13-5B6A3-3A-A13-4B8A2-3A-2A2(12-4B9A-6A)12-4B9A-5AC12-3B15AC13-3B11A-3AC14-3B10A2-2AC14-3B10A-4A16-B10A-3A-A16-11AD2A-A17-5A-A-2AD3A15-A7-2A-2A18-2A3-A6-A19-2A8-A-2A18-2A7-4A18-4A8-A19-3A-A4-3A26-5A72-A29-3A28-4A27-3A-A26-2A2(-A)26-2A-A27-2A2-A17-3BA6-2A2-A17-2B3A5-2A2-A16-4B3A4-2A-2A15-4B4A5-A2-A14-5B5A5-4A13-4B6A3-6A13-4B8A3-2A-2A12-4B8A2-2A-3A12-3B10A2-A-2A13-4B9A2-4A13-5B9A-A-3A12-4B10A-5A13-3B10A3-2(3A14-B11A-A-)A18-12A-2A17-8A-A-D2A19-A2-2A-A2-A25-A31-A62-A26-A31-A111-3A30-2A27-4A28-4A26-5A26-2A-3A26-2A2-A17-3B8-A2-A16-3B4A4-2A2-A15-5B3A5-A2-2A13-4B-4A5-4A14-5B6A4-4A13-5B7A2-5A13-4B8A3-A-2A13-4B9A2-4A13-5B8A2-2(5A12-4B10A-)2A-2A13-3B10A3-A17-B10A-A2-CA15-B10A-2A2-A16-5A-4A-2ACA18-3A3-2A-A3-A18-5A-2A-A23-5A21-2A4-7A19-A-11A19-12A20-8A-2A22-7A107-A31-A30-2A60-2A28-A-3A27-A-2A17-2B8-2A2-A16-5B6-2A2-A15-4B4A4-2A-2A14-4B-5A4-5A13-4B7A3-3A-A13-4B8A2-5A13-4B8A3-4A13-5B8A2-5A12-4B9A2-2(A-)A12-4B9A2-3AC13-4B10A-A-2AC13-3B10A-4AC15-B10A-2A-AC15-B10A-3A18-5A4-A-2A2C18-3A4-2A23-2A3-A2-A24-4A23-A7-2A31-2A30-2A24-4A28-A266-3A28-4A16-B12-3A15-2B-B8-4A16-2B-2B3A5-3A15-3B-2B3A5-3A15-4B7A3-2(A-)A13-4B8A2-3A15-4B8A3-2A-A2(13-4B9A2-4A)13-4B9A3-A-A13-4B10A19-2B11A-A2-A15-12A-3A17-11A-3A18-8A-2A2-A18-A2-5A-2A24-5A-A24-4A31-2A31-3A29-2A21-3A28-4A349-2B-B10-A17-2B-2B2-A5-4A14-3B-2B2-A5-4A14-4B3-4A3-A2-A14-7B5A4-2A14-8B4A3-3A14-7B6A2-A-A14-7B6A4-A14-7B6A19-7B6A20-4B9A2(21-B10A)22-B8A26-7A25-7A26-2A-A122-2A30-2A391-A16-3B4-2A23-4B3-3A22-4B3-5A20-3BAB7A3-3A14-5B6A21-5B7A5-A14-4B9A19-5B8A20-4B8A22-AB8A22-10A22-9A23-8A25-10A22-4A-4A26-5A27-2A29-2A30-2A28-2A416-A-A23-4B7A2(21-3B8A)21-2B9A21-BAB9A20-3B8A20-2AB10A19-AB9AC20-3(13A19-)13A20-8ACA24-8A-A25-A-4A27-4A28-A30-A448-A28-A2-4A22-4B3-4A21-2B8A22-2B9A2(21-B10A)17-A2-11AC15-13AC2A16-17A14-17A15-2(17A16-)13A-2A17-A-3A-7A29-2A30-A-A532-B29-6B7-2A19-4B-7A20-5B5ACA20-5B-4A-2A16-A4-3B5A-2A16-14A2-C14-14A-2C14-14A2C-C14-14ACA2CA13-16A-A16-16A16-13A21-4A-7A25-2A-A29-3A29-A474-B31-B29-4B28-4B4-2AB3A15-2A3-2B3-7A14-4A2-5B4AC-C14-4A2-4B4A2C16-4AB-B9A16-16A16-15A16-5A-10A2-C14-15A2C17-15A18-14A19-A-2A-8A27-A29-A31-A443-2B30-3B29-3B28-4B3-A-2A21-4B4-2A-A17-A2-5B2-B4A17-A3-4B-3A-C18-2A-5B4A23-5B4A20-A2-5BA-2A18-A-A4-3BA-2A20-2A-A4B3A21-2(3AB)3A-C19-11AC19-A2-8AC23-9A537-2B30-2(3B29-)3B6-A21-4B28-4B3-A25-4B2-A21-A3-5B3A24-5B26-6B28-3B55-A3-A2-A-2A30-A29-A30-A543-B30-2B30-3B31-B2(30-2B)29-3B2(30-2B)28-4B92-A705-B30-3B3(30-2B)29-3B30-2B29-3B374-
