model
size = 31 32 20, scale = 0.05, origin = -y
material deform = 1, fade = true, lighting = smooth, roughness = 0.3, metalness = 0.6
  colors = A:#DFBA00 B:#9F9F9F
voxels
280-29A-6(A4-)6(2A5(4-A)4-)32A683-29A-6(A4-)6(2A5(4-A)4-)32A559-29A4(2-A3-4(A4-)A3-A)-A29-A217-A29-A467-27A2(4-A6-2(A5-)A6-A)157-A29-A217-A29-A467-A6-2(A5-)A6-A219-A8(29-2A)29-A467-A6-2(A5-)A6-A219-A29-A217-A29-A467-27A2(4-A25-A)3-4(A27-A2-)A27-A-2(A29-A217-A29-A467-A6-2(A5-)A6-A219-)A8(29-2A)29-A467-27A2(4-A25-A)3-4(A27-A2-)A27-A-A29-A217-A29-A467-A6-2(A5-)A6-A219-A29-A217-A29-A-B27-B437-A6-2(A5-)A6-A219-A29-A217-A29-A-B27-B2-A27-A406-27A2(4-A25-A)3-4(A27-A2-)A27-A-A29-A217-A29-A63-A27-A2-A27-A344-A6-2(A5-)A6-A219-A8(29-2A)29-A125-A27-A2-A27-A282-A6-2(A5-)A6-A219-A29-A217-A29-A187-A27-A2-A27-A220-27A2(4-A25-A)3-4(A27-A2-)A27-A-A29-A217-A29-A249-A27-A2-A27-A158-A6-2(A5-)A6-A219-A29-A217-A29-A311-A27-A2-A27-A96-A6-2(A5-)A6-A219-A8(29-2A)29-A373-A27-A2-A27-A3-10A7B10A4-27A2(4-A6-2(A5-)A6-A)157-A29-A217-A29-A559-29A4(2-A3-4(A4-)A3-A)-A29-A217-A29-A465-
