model
size = 18 32 21, scale = 0.05, origin = -y
material deform = 1, fade = true, lighting = smooth, roughness = 0.3, metalness = 0.6
  colors = A:#222 B:#90C C:#0C3 D:#EEE E:#C6C F:#F9F G:#CF6 H:#6CF I:#039 J:#3CC K:#66C L:#06C M:#3CF N:#93F O:#90F P:#CF9 Q:#050 R:#F93 S:#FF6 T:#FCF U:#111 V:#C00 W:#A00 X:#D00 Y:#800 Z:#F0C
voxels
27-A575-3(A17-)A35-2A16-W449-2(A17-)2A16-3A15-A17-2A16-2AW15-2A193-6D12-D4M3(D12-DM2ZM)D12-DMDZMD12-D4MD12-6D213-A17-2A16-2A174-8B10-O6DO10-ND4ADN9-2KDA2VAD2K8-2IDA2VAD2I8-2LDA2VAD2L8-2HDADVAD2H8-2JD4AD2J9-Q6DQ10-8C194-2(A17-)2A16-A18-W16-A18-A85-6E10-10B8-2O6-2O7-2(3N6-)2KA6-3K2(6-3I)6-2LA6-A2L2(6-3H)2(6-3J)6-3Q-3D2-A2Q7-10C10-6G214-A4(16-2A)17-A66-8E8-12B2(6-3O)5-4N6-4N4-3KA6-4K4-4I6-4I4-3LA6-A3L4-4H6-4H4-4J6-4J4-4Q-3D2-3AQ5-12C8-8G12-4P267-W2A15-3A16-2A31-6F10-10E6-14B4-4O6A4O4-4N9AN3-4K7A5K2-5I6A5I2-4L8A4L2-5H6A5H2-5J6A5J3-4Q9AQ4-14C6-10G10-2P2A2P14-2S247-6A13-5A14-4A14-4T12-8F8-12E4-16B2-5O6A5O2-5N9A2N2-4K11AK2-I10A5I2-4L8A4L2-5H6A5H2-J10A5J2-5Q10AQ2-16C4-2GA9G8-2P4A2P12-4S94-A17-A132-3A4-A11-2A4-A12-A2-Y-A12-T2VAYT10-10F6-14E3-16B2-D7(2-10A2(2-D))2-10A2-D2-16C3-2G7A5G6-3P5A2P10-S4AS13-4R40-A52-2AW16-A17-A53-W6-A8-2A7-A9-2A7-2(A6-A10-)AD2-DY-A10-TA2V3AT8-12F5-14E3-16B2-D2-10A2-D2-M5(2-10A2(2-M))2-10A2-M2-D2-10A2-D2-16C3-G8A5G5-4P6A2P8-S6AS11-6R14-2X23-A17-A5-A11-3A14-2A16-2A5-A11-AW3-WA11-A5-2A10-A6-2A9-A6-A8-4A5-2A6-4A2(6-2A)7-3A6-2A8-2A2D4-2A7-2T3AV2Y2AT7-12F5-5E5A4E3-16B2-D2-10A2-D2-M2-10A2-M2-U2(2-10A2(2-U))2-10A2-U2-D2-10A2-D2-M2-10A2-M2-D2-10A2-D2-16C3-G8A5G5-4P7AP7-2S6A2S10-6R13-4X28-A11-A4-3A10-A5-A10-A24-A29-A5-2A16-W2A9-W6-2A15-3A6-A9-2A6-2AW7-2A6-2A7-3AD5-2A8-T2A2VYV2AT7-12F5-5E5A4E3-16B2-D2-10A2-D2-M2-10A2-M2-U3(2-10A2(2-U))2-10A2-U2-M2-10A2-M2-D2-10A2-D2-16C3-G8A5G5-4P7AP7-2S6A2S10-6R13-4X7-4A15-A-A15-4A10-A5-2(2A15-)W2A2(17-A)73-2A5-A10-A6-A10-A2-D3-A10-T2VA2YAT8-12F5-5E5A4E3-16B2-D2-10A2-D2-M5(2-10A2(2-M))2-10A2-M2-D2-10A2-D2-16C3-G8A5G5-4P6A2P8-S6AS11-6R14-2X9-2A17-A53-A17-2A2(17-A)74-2(A4-2A11-)A3D-A12-T4AT10-10F6-5E5A4E3-16B2-D7(2-10A2(2-D))2-10A2-D2-16C3-2G7A5G6-2P6A2P10-S4AS13-4R200-A11-A5-2A10-4A-2A11-5A13-4A14-4T12-8F8-12E4-16B2-5O6A5O2-5N6A5N2-5K6A5K2-5I6A5I2-5L6A5L2-5H6A5H2-4J7A5J2-5Q10AQ2-16C4-2G6A4G8-2P4A2P12-4S194-A17-2A4-A11-2A3-3A15-2A64-6F10-10E6-14B4-4O6A4O4-4N6A4N3-5K6A5K2-5I6A5I2-5L6A5L2-5H6A5H2-4J7A5J3-4Q6A4Q4-14C6-2G5A3G10-2P2A2P14-2S177-2(2A16-)A18-W4-A99-8E8-12B6-3O6A3O5-4N6A4N4-4K6A4K4-4I6A4I4-4L6A4L4-4H6A4H4-3J7A4J4-4Q6A4Q5-12C8-2G4A2G12-4P123-A17-2A16-2A15-2A16-3A158-6E10-10B8-2O6-2O7-2(3N6-)2(3K6-)2(3I6-)2(3L6-)2(3H6-)2JA6-3J2(6-3Q)7-10C10-6G87-3A15-2A16-2A15-3A16-2A15-AW34-W176-8B10-O6DO10-ND4MDN9-2KDM2UMD2K8-2IDM2UMD2I8-2LDM2UMD2L8-2HDMUDMD2H8-2JD4MD2J9-Q6DQ10-8C105-A16-A35-A34-2A539-W512-
