model
size = 26 28 32, scale = 0.05, origin = -y
material deform = 1, fade = true, lighting = smooth, roughness = 0.3, metalness = 0.6
  colors = A:#609 B:#FFF C:#100 D:#303 E:#F33 F:#500 G:#200 H:#CCC I:#C99 J:#F00 K:#800 L:#AAA M:#C33 N:#400 O:#DDD P:#60C Q:#444 R:#B00 S:#300 T:#606 U:#000
voxels
351-3A24-A469-A23-3A19-3A5(-4A17-4A)-4A18-2A2-3A24-2A466-3A18-3A2(-4A17-4A)-A-2A17-2A2(-A)3(2-A17-A2-A-A)2-A17-4A-A-2A17-4A-4A17-3A2-4A23-3A413-3A17-4A-4A17-4A-2A-A17-2A2(-A)2-A17-A2-2(A-)2A17-2A-A3(-4A17-4A)2(-4A17-A-2A)-A2-A17-4A-2A-A17-3A2-4A23-3A361-2A18-3A-5A17-10A16-A2-8A15-A2-A-6A15-4A-4A17-4A-3A19-3A23-2A23-3A3-2A18-2(4A-4A17-)A-2A-4A17-4A-2A-A17-3A3-3A356-8A17-10A16-A-5A-3A15-A-11A13-4A2-7A13-4A4-5A24-A118-3A3-2A18-3A3-3A16-2A-A3-A-A17-3A3-4A23-2A308-3A18-9A16-11A15-2A-10A14-13A13-3A3-4A2-2A20-6A22-4A24-2A116-3A3-3A16-4A3-4A15-4A3-4A16-2A5-2A228-3A23-4A23-3A18-3A-5A16-11A15-10A-2A14-11A15-14A18-9A18-6A-2A17-9A18-8A19-5A-A18-8A18-7A18-4A15-3A3-5A15-4A2-5A15-4A-6A16-2A2-6A19-5A20-5A21-4A2(22-3A)2(23-3A23-4A)23-4A23-3A17-4A2-4A16-11A15-3A-6A-A14-12A15-11A20-10A17-2A2-6A8-2A7-6A-2(2A8-)2(8A8-2A8-)8A17-2A-5A18-2A-4A12-3A3-2A2-A-2A12-4A2-A-3A15-4A-2A-3A16-2A-2A2-3(2A20-2A-)2A21-2(4A22-)A-2A22-4A22-2A-A23-4A23-3A42-6A-6A11-15A10-2A3-2A2-6A11-2A2-3A-9A9-2A-14A9-8A3-2A-3A9-8A4-9A8-4A6-9A7-4A7-6A-A7-4A7-8A2(7-4A)-2A8-3A7-2(2A-)2A8-3A-A5-2A-5A9-5A3-2A-6A11-4A2-5A-2A12-4A-2A-3A16-2A-6A11-2A7-2A-2A12-3A5-2A-2A13-4A3-2A-2A14-4A3-4A15-4A2(3-4A16-3A)3-4A2(23-3A)93-4A2-2A17-12A-3A10-A3-12A9-2A2-9A-4A8-2A-4A-2A2-6A8-6A-2A4-6A7-5A2-A6-5A7-5A2-A7-5A7-2A-A2-A7-6A9-A-2A7-7A8-A-2A7-4A-2A8-4A6-5A2-A8-4A6-8A5-2A2-3A5-4A-4A5-3A-2A6-4A2-2A6-3A8-4A11-4A6-4A12-4A5-5A12-2A-3A3-4A14-A-3A3-3A15-2A-A4-2A17-A-A4-2A17-3A23-3A129-5A3-2A-A12-8A-4A11-11A-4A9-2A2-13A13-2(3A-)6A11-3A-2A5-A2-2A10-5A6-2A-2A2(7-8A7-4A)7-8A7-6A5-2(5A-2A10-4A4-)6A-A10-A2-A4-8A10-4A4-4A-3A11-3A4-2(2A-)2A12-A6-A-2A22-A2-4A19-7A20-5A21-4A23-3A23-A-A23-3A24-2A103-5A5-A12-4A-4A2-4A10-9A-6A9-17A9-11A2-2A-A9-2A-6A5-2A-A8-A2-A-3A6-4A8-A2-A-2A8-3A7-2A2-A-A19-2A2-4A18-2A2-4A12-A6-A2-5A10-3A5-A2-5A10-4A4-A2-3A-2A9-2A-A4-A2-A-4A9-4A4-2A-6A10-3A5-A-2A22-8A18-7A23-2A48-2(3A23-)3A24-2A85-2A16-2A2-A3-3A12-8A-5A11-A2-14A9-2A-14A9-3A3-4A-3A-A9-4A10-3A9-4A11-3A8-2(4A22-)2(A-2A22-)A2(-2A)19-A-2A-3A11-3A4-4A-4A9-4A4-4A-A-2A9-2A-A4-4A-4A10-3A5-3A-4A11-A6-3A-4A22-3A100-2A13-3A8-2A13-4A7-2A14-3A7-2A56-A-5A13-3A2-8A11-16A10-16A11-15A12-3A5-6A21-3A36-2A24-4(3A23-)3A16-2A5-3A2-3A11-3A5-2A2-4A10-A-A9-4A10-3A2(9-4A)10-3A9-3A22-2(3A23-)4A23-3A23-4A8-2A13-4A7-2A14-3A7-2A58-2A-2A13-3A5-2A-2A12-4A4-7A10-5A4-7A11-5A3-7A11-4A4-7A20-2A-A211-A25-A-A2(23-3A)21-2(4A22-)A-2A22-4A22-2A-A23-4A23-3A8-2A24-2A58-2A-2A21-2A-2A12-2(4A4-3A-3A11-)5A3-3A-3A11-4A4-3A-3A19-3A-3A20-2A-2A22-A-A185-2A23-2A-A22-4A21-3(4A22-)4A2(23-3A)121-2A-2A21-2A-2A13-2A4-4A-3A11-4A3-4A-3A11-A2-A3-4A-3A11-4A4-3A-3A19-3A-3A20-2A-2A21-2A-2A184-2A23-2A24-2(3A23-)2A24-2A199-3A-3A19-3A-3A12-2A4-4A-3A11-4A3-4A-3A11-A2-A3-4A-3A11-4A4-3A-3A12-3A4-3A-3A19-3A-3A20-2A-2A21-4A22-A-A22-2A-2A20-3A-3A19-7A18-9A16-11A15-11A16-9A18-8A253-2(3A-3A19-)2A3-2A11-4A3-4A-3A11-2A-A3-4A-2A12-2A-A5-2A-2A13-3A5-2A-2A20-2(3A-3A19-)7A19-6A17-11A14-9AB3A12-4AB4A2B4A10-4AJBH2BHBJNF3A9-3ACKLC2BCLK2C3A9-3ACGCB2ABCGCQ3A9-4ACO4AO2C4A10-10ABI4A11-14A13-12A270-2A24-2A7-A-A14-A7-2A-A14-2A5-3A-3A13-A4-2(4A-3A18-)8A16-11A13-15A10-2A3B6A4B2A8-2ABEM2B4A2BME2B2A6-2ABEFNJBH2BHBJNFEB3A5-2ABR2CKLC2BCLK2CR2B2A5-2ABFQCGCB2ABCGCQFBS2A5-2A5CO4AO6C2A6-2A2CIB6ABI2CIB2A7-18A9-16A12-12A251-2A3-2A12-2A5-3A2-2A12-2A5-3A-3A12-2A4-4A-3A13-A4-4A-3A18-4A-3A17-9A15-13A11-17A8-2A4B6A4B3A6-2A2BEM2B4A2BME2B3A4-3ABEFNJBH2BHBJNFEB4A3-2A2BR2CKLC2BCLK2CR2B3A3-2ASBFQCGCB2ABCGCQFBS3A3-AG6CO4AO6CG2A4-ABI2CIB6ABI2CIB3A5-20A7-18A9-16A13-10A200-2A3-2A2(19-2A2-3A)12-2A5-3A-3A12-2A4-4A-3A13-A4-4A-3A18-4A-3A17-9A15-13A11-17A8-2A4B6A4B3A6-2A2BEM2B4A2BME2B3A4-3ABEFNJBH2BHBJNFEB4A3-2A2BR2CKLC2BCLK2CR2B3A3-2ASBFQCGCB2ABCGCQFBS3A3-AG6CO4AO6CG2A4-ABI2CIB6ABI2CIB3A5-20A7-3(18A8-)3A12-3A117-3A3-2A18-3A3(3-2A19-2A)2-3A13-A5-2A2-3A13-A5-3A-3A13-A4-4A-3A18-4A-3A16-11A15-11A13-15A10-A4B6A4B2A8-ACBEM2B4A2BME2B2A6-2ABEFNJBH2BHBJNFEB3A5-ACBR2CKLC2BCLK2CR2B2A5-ACBFQCGCB2ABCGCQFBS2A5-G6CO4AO6CGA6-2P2CIB6ABI2CIP2A7-4D11A2DA8-A4D8A4DA8-A2D12A2DA8-5A7-6A8-3A12-3A117-T2A2-3A18-3A2-3A20-A3-A98-2A2-3A19-3A-3A18-4A-3A17-9A16-11A14-C11A13-C3B6A3B2C11-BEM2B4A2BME2BC9-UEFNJBH2BHBJNFEBC9-BR2CKLC2BCLK2CRBC9-BFQCGCB2ABCGCQFBS9-5CO4AO6C10-2CIB6ABI2CP14-9A2D11-A4-7AD4-A8-A2-3A5-2A2D2-A8-5A7-3A2DA8-3A12-3A118-2T3-2T19-TA3-2A151-A-A22-2A-2A19-8A16-11A14-C11AC13-C2B6A3BC13-EM2B4A2BMEB13-FNJBH2BHBJNFE13-2CKLC2BCLK2CR13-QCGCB2ABCGCQF14-2CO4AO3C15-IB6ABI2C15-10AD16-8A16-2A7-3A12-3A10-A2D355-2A22-5A19-9A15-C10AC14-U2B6A3B2C12-EM2B4A2BMEB13-FNJBH2BHBJNFE13-2CKLC2BCLK2CR14-CGCB2ABCGCQ15-2CO4AO3C15-PB6ABI2C15-10A17-8A437-2A22-5A18-C9AC15-CB6A3BC14-M2B4A2BME15-NJBH2BHBJNF15-CKPC2BCLK2C16-GCB2ABCGC17-C2P3AP2C17-2P5A2PC17-8A19-6A461-7A18-9AC14-2CP6A2BC16-2B4A2BM18-AH2BHBJ20-C2BCL21-P3AC593-5A-A16-2C7AC18-C4ABC19-CH2BHBC20-5A619-5A20-6A21-5A21-A2BHA21-4AP619-3(5A21-)5A347-
