model
size = 28 27 18, scale = 0.05, origin = -y
material deform = 1, fade = true, lighting = smooth, roughness = 0.3, metalness = 0.6
  colors = A:#CC0 B:#F66 C:#444 D:#111 E:#100 F:#FFF G:#EEE H:#063 I:#BBB J:#F30 K:#066 L:#DDD M:#010 N:#033 O:#999 P:#B00 Q:#099 R:#699 S:#020 T:#696 U:#F36 V:#AAA W:#CC6 X:#888 Y:#6CC Z:#399 Aa:#555 Ab:#666
voxels
387-3(A27-)A643-3(A27-)A475-A167-C25-3(3AC24-)3AC27-A418-2(A27-)2A25-2A81-3AC23-4A2C21-5A3F2(20-5A3G)20-5A3F21-4AFC2-A20-3AC390-A27-2A26-2AB24-2A26-2A23-5A21-7AAbC19-7A3F17-8A3L17-8A4H17-7A3MH17-7A3I3-A16-5A3F2-A18-4AFC24-2AC273-BP25-AB26-2A26-A34-A11-2AB10-4A11-2A8-6A20-8A19-10A18-10AVC15-B9AD2G15-10AD3K2(14-10AD3E)15-9AD3O3-2A10-9AD2T5-A11-9A2F19-6AC273-B2PA24-3BA23-6A21-8A20-9A11-2AB6-8AB10-3A4-11A16-2B10A16-B11A15-AB10AVC14-AB9AD2G14-11AD3N2(13-11AD3E)5-A7-11AD3E4-2A8-10AD2S5-2A8-11A2F16-9AC20-6A335-2A21-8AB12-B4-B9AB10-4A2-13A9-4A-A2B11A9-4A-AB12A9-6AB10AAaA10-2A-2AB9ADGC10-2A-12AD2Q9-2A2-12AD2EI6-4A2-12AD3E5-4A3-12AD2E6-5A3-11AD2R6-5A3-12AGC6-3A6-11AC17-10A20-6A303-4A22-9AB16-2B9ABA12-A-14A12-AJA2B12A10-4AB12A11-4AB12A10-15ADXA10-15ADGC10-15ADYC8-17ADZC8-17ADIC8-17ADGAC9-2A2-11AD2A14-14A15-12A18-8A22-4A275-6A20-10A17-2B9ABA14-15A12-JA2B10AW13-2AB13A11-3AB12A12-16A12-17A2(11-13AU3A)11-17A10-17A13-16A13-14A15-12A17-10A20-7A273-6A12-3A5-10A10-3AB3-2B9ABA9-4A-15A9-3AJA2B10AW11-4AB13A10-4AB12A11-17A11-18A2(9-15AU3A)9-19A8-19A9-3A-16A13-14A15-12A16-11A18-10A19-8A20-6A22-4B22-3B25-B143-4A13-A8-8A11-2A5-2B9ABA9-3A2-14A9-4A-A2B12A8-2(6AB12A9-)16ADXA9-16ADGC10-15ADYC8-17ADZC8-17ADIC7-18ADGAC6-5A2-11AD2A14-14A15-12A18-8A22-4B22-2A26-5A23-4B23-2B116-2A26-2A25-4A21-8AB17-10AB16-13A14-B2J11A9-4A-AB12A9-6AB10AAaA10-2A-2AB9ADGC10-2A-12AD2Q9-2A2-12AD2EI6-4A2-12AD3E5-4A3-12AD2E5-6A3-11AD2R5-6A3-12AGC6-3A6-11AC17-10A20-6A192-A26-B2PA23-A3B2A21-7A21-6A22-9A20-8AB17-11A16-2J10A16-B11A15-AB10AVC14-AB9AD2G14-11AD3N2(13-11AD3E)5-2A6-11AD3E4-2A8-10AD2S4-3A8-11A2F16-9AC20-6A336-B27-2B26-3A20-6A20-8A19-10A18-10AVC15-B9AD2G15-10AD3K2(14-10AD3E)15-9AD2OE15-9AD2T3-A13-9A2F2-A16-6AC362-B27-2A26-2A24-3A25-2A24-2A-2A21-7AAbC19-7A3F17-8A3L17-8A4H17-7A3MH17-7A3I20-5A3F21-4AFC2-A21-2AC390-A27-2A24-2A82-3AC23-4A2C21-5A3F2(20-5A3G)20-5A3F21-4AFC23-3AC446-B139-A25-3(3AC24-)3AC26-AC283-
