model
size = 9 31 31, scale = 0.05, origin = -y
material deform = 1, fade = true, lighting = smooth, roughness = 0.3, metalness = 0.6
  colors = A:#EEE B:#555 C:#3C0 D:#300 E:#303 F:#306 G:#309 H:#BBB
voxels
3-A7-3A7-A79-3AB5-3ABA3-4A2(BADC5A)BA2-2(5AB3-)5A4-5A5-3A97-2(3A6-)3A78-3ABA4-3ABADC-4A2(BA2-5ABADC5A)B3-5A4-5A5-3A98-A7-3A7-A68-2(5ABA2-)5ABADC3(5ABA2-)5ABADC3(5AB3-)5A184-3(5ABA2-)3(5ABADC)5ABA2-3(5AB3-)5A184-8(5ABA2-)2(5AB3-)5A115-A7-3A7-A37-B8-3(BA2-5A)4(BADC5A)2(BA2-5A)2(B3-5A)114-2(3A6-)3A36-BA7-7(BA2-5A)BADC5ABA2-2(5AB3-)5A6-2(2A7-)2A89-A7-3A7-A37-BA7-7(BA2-5A)BADC5AB3-4(5ABA2-)2(5AB3-)5A5-4A6-A119-BA7-3(BA2-5A)5(BADC5A)6(BA2-5A)2(B3-5A)5-4A117-BA7-15(BA2-5A)2(B3-5A)6-2A71-A7-3A7-A19-BA7-3(BA2-5A)5(BADC5A)BA2-5ABADC5(5ABA2-)2(5AB3-)5A6-2A70-2(3A6-)3A15-A2-BA4-A2-15(BA2-5A)B3-5A5-4A79-A7-3A7-A14-4(5ABA2-)2(5ABADC)2(5ABA2-)5ABADC7(5ABA2-)5AB3-5AB4-3A113-7(5ABA2-)5ABADC7(5ABA2-)5AB3-3(5ABA2-)2(5A4-)5A5-4A76-6(5ABA2-)5ABADC12(5ABA2-)3(5AB3-)5A76-4(5ABA2-)5(5ABADC)3(5ABA2-)2(5ABAG-)6(5ABA2-)2(5AB3-)5AB75-11(5ABA2-)5A2B2-5ABAG-5AB2A-8(5ABA2-)5AB75-4(5ABA2-)4(5ABADC)3(5ABA2-)2(5A2B2-)9(5ABA2-)5AB75-8(5ABA2-)5ABADC11(5ABA2-)2(5AB3-)5AB75-8(5ABA2-)5ABADC3(5ABA2-)2(5ABAF-)6(5ABA2-)2(5AB3-)5A76-4(5ABA2-)4(5ABADC)3(5ABA2-)5A2B2-5ABAF-5AB2A-3(5ABA2-)5AB3-5ABA4-2A-BA4-2A7-2A86-11(5ABA2-)2(5A2B2-)4(5ABA2-)5ABA7-B8-B102-5AB3-3(5ABA2-)5(5ABADC)5ABA2-5ABADC5(5ABA2-)5A3(BA7-)B102-5AB3-11(5ABA2-)2(5ABAE-)5ABA2-5A3(BA7-)BA128-2(5ABA2-)4(5ABADC)3(5ABA2-)5A2B2-5ABAE-5AB2A-5ABA2-5A2(BA7-)BA137-6(5ABA2-)5ABADC2(5ABA2-)2(5A2B2-)3(5ABA2-)4A149-2(5ABA2-)6(5ABADC)5ABH5(2-5ABA)2-4A160-3A12(BA2-5A)BA2-4A160-3ABA2-2(5ABADC3(5ABA2-))3(5ABA2-)5AB3-4A160-3ABA2-6(5ABADC)4(5ABA2-)5AB3-5A168-3AB3-4(5ABA2-)5ABADC4(5ABA2-)5AB3-5A4-4A68-
