model
size = 18 30 23, scale = 0.05, origin = -y
material deform = 1, fade = true, lighting = smooth, roughness = 0.3, metalness = 0.6
  colors = A:#400 B:#F5B200 C:#800 D:#001 E:#070 F:#EB6B00 G:#E64700 H:#F08E00 I:#D00 J:#DC0000 K:#E12300 L:#7D9100 M:#FAD600
voxels
63-F194-2B2-2B13-3BL15-2B15-BF2B286-F17-H138-LB6-2B9-2B4-2B83-2B2-2B11-2B4-2B194-J17-K17-G17-F17-H17-B101-GB8-BF151-2B6-FB175-J17-K17-G17-F17-H17-B17-M65-B10-G187-B8-G157-J17-K17-G17-F17-H17-B64-B12-L4-B12-B185-B10-L6-B10-B192-F17-H81-B14-B61-5A14-A-A14-3(5A13-)5A63-B12-B191-F99-B14-B43-2(5A13-C3AC13-)C3AC13-I3AI13-C3AC13-5A45-B12-B81-2D208-B14-B26-A-A14-5A2(13-I3AI13-5A13-C3AC)13-C3AC13-5A27-B12-B45-4(2D16-)2D72-F80-2B14-2B42-5A13-C3AC2(13-5A)13-C3AC13-5A4(13-C3AC)13-5A22-B2-2B41-2D3(16-2E)16-2D72-F17-H62-2B14-2B60-2(5A2(13-C3AC)13-)3(C3AC13-)5A22-2B-2B41-2D3(16-2E)16-2D18-J17-K17-G17-F17-H17-B44-2B14-2B78-2(5A2(13-C3AC)13-)2(C3AC13-)5A23-B-2B41-2D3(16-2E)16-2D18-J17-K17-G17-F17-H17-B17-M26-2B14-2B96-3(5A13-C3AC13-)5A13-5A22-2B-2B41-2D3(16-2E)16-2D18-J17-K17-G17-F17-H17-B44-2B14-2B96-5A13-C3AC13-5A13-I3AI13-5A13-C3AC13-I3AI13-5A22-B2-2B41-2D3(16-2E)16-2D72-F17-H62-2B14-2B96-2(5A13-)I3AI13-C3AC13-5A2(13-C3AC)13-5A22-B2-2B41-2D3(16-2E)16-2D72-F99-B14-B79-5A13-I3AI13-C3AC13-5A3(13-C3AC)13-5A9-B12-B45-4(2D16-)2D172-B14-B79-2(5A13-C3AC13-)2(C3AC13-)5A27-B12-B81-2D108-F99-B14-B79-2(5A13-)2(C3AC13-)5A13-5A45-B12-B191-F17-H82-L12-B4-B12-B98-5A13-5A64-L10-B6-B10-B138-J17-K17-G17-F17-H17-B83-G10-B187-G8-B157-J17-K17-G17-F17-H17-B17-M83-FB8-BG151-BF6-2B175-J17-K17-G17-F17-H17-B120-2B6-BL9-2B4-2B83-2B2-2B11-2B4-2B248-F17-H176-2B2-2B13-L3B15-GB15-2BFB286-F476-
