model
size = 32 17 20, scale = 0.05, origin = -y
material deform = 1, fade = true, lighting = smooth, roughness = 0.3, metalness = 0.6
  colors = A:#F30 B:#D00 C:#F93 D:#C30 E:#F63 F:#FC3 G:#E00 H:#F60 I:#930 J:#A00 K:#600 L:#C00 M:#C93 N:#C60 O:#400 P:#800 Q:#900 R:#111 S:#500 T:#DDD U:#FC6 V:#300 W:#200 X:#F00 Y:#C63 Z:#B00 Aa:#630 Ab:#F96 Ac:#700 Ad:#444 Ae:#963 Af:#993 Ag:#330
voxels
39-W507-CA12-F-DO12-A2F13-CAM90-CM19-FE8-2AE20-A8-BA339-FCA12-F-DO12-A2FH11-FCAMAa13-F12-DMC16-E12-2D18-UF8-ECML18-FE8-2AEB18-CA8-BAG20-N316-EFK13-F-DO12-AF13-FCAMAa12-GF12-DMC16-E12-2D17-CJG8-ECML17-FZG8-2AEB17-FVD8-BAGB18-CI8-LDP170-2(R31-)R86-FED29-CAM29-O49-JG8-ESDS17-FZG8-AKAB17-FVD8-BKAD17-MCI8-LPXD69-EAb28-AECUF27-EB2FE-R25-AIFCAAdBT25-DMC-AdBT26-D2-AdBT30-R168-J10-SDS17-FZG8-AKAD16-IFVD8-BKAB17-MCI8-LPXB17-2D10-QXD3-CGFUC26-2HCEAbUI25-EAECUFBRS23-2EB2FEDBT23-CAIFCAMBT23-CHDMCNYBT24-E3DP2BT25-AEC-AdBT30-R135-CJG29-FZGB7-AKAD16-IFVDHJG3-G2BKAD16-DMCICZAOPCB2LPXDS16-2DNCBWABCAG2QXDKQHCGFUCAfK9-NFAS2JD2AAcJGDPL2HCEAbUIJAb17-JGVDHBEAECUFBRSFAc18-DHG2EB2FEDBTOQ18-DHACAIFCAMBT22-ACHDMCNYBR22-A2E3DP2BT23-G2EB2FEBT30-R135-CJGD6-GE19-BFZGBQBENHABAKAB16-IFVDHJGEICG2BKADV15-DMCICZAOPCB2LPXDS16-2DNCBWABCAG2QXDKQHCG6H6-LJNFAS2JD2AAcJGDPL2HC8A11-DN2AYCEICBEA5ER3E18-ICG2EB4ABTOQ18-I2(CA)I3HMBT20-ICACHDMCNYBR22-A2E3DP2BR23-ACAIFCABT30-R135-CJGDPLHDFEGE18-4EGBQBENHABAKAD16-2AVAHJGEICG2BKADV15-HMCHCZAOPCB2LPXDSOAH13-EDNCBWABCAG2QXDKQHCG8C4-LJNFAS2JD2AAcJGDPL2HC8ER5-UFBKSBAcVDCYONCBEAE10B16-NCG2EB4IR5I16-N2(CA)I4DBT3D17-NCACH5DBTD20-CA2ED4MBT23-ACHDMCNR167-CJGDPLHDFEGE18-4BGBQBENHABAKAD15-2IF2IHJGEICG2BKAD2V14-4DCZAOPCB2LPXDSOAH12-3DNCBWABCAG2QXDKQHCG7ER4-LJNFAS2JD2AAcJGDPL2H11C4-FED2(OQ)GEVYINFBEAE10F16-NFG2EB10F16-NFACAI4MR5M16-NFACH5DR2D21-A2ED4LR2L22-ECM4A168-CJGDPLHDFEGE18-4FGBQBENHABAKADW14-FI3FHJGEICG2BKAD2VA13-3MICZAOPCB2LPXDSOAH13-2DNCBWABCAG2QXDKQHC8AbR4-LJNFAS2JD2AAcJGDPL2H11U4-CAMAaWCZACAAgMSFBEA11F16-DFG2E11C16-DFACA11C16-DFACH8D21-A2E8J22-EC5L168-CJGDPLHDFEGE18-4FGBQBENHABAKAB15-CI2CDHJGEICG2BKAD2V14-3CICZAOPCB2LPXDSOA14-2DNCBWABCAG2QXDKQHC8UR5-JNFAS2JD2AAcJGDPL2H11F5-NYONCBACHDASHBEA11E16-NHG2E11A16-NHACA5NR5N16-NHACH5PR2P21-A2E5LRL23-EC5D169-JGD6-GE18-4EGBQBENHABAKAB15-A-2ADHJGEICG2BKADV15-3NICZAOPCB2LPXDSOA14-PDNCBWABCAG2QXDKQHC9I5-JNFAS2JD2AAcJGDPL2H9BR10-F2A2ESAWCBEA11D15-DICG2E5MR5M15-DI2(CA)5YBT3Y17-ICACH6BTB20-CA2E6BT23-EC5AR169-G27-4DGB7-AKAD15-5MHJG3-G2BKADV15-Ae2YICZAOPCB2LPXDS16-BDNCBWABCAG2QXDKQHC7J8-NFAS2JD2AAcJGDPL2H9K16-V2PCBEA5OR3O17-OPCG2E5AaBT2Aa17-OP2(CA)5OBT20-PCACH5KBR22-A2E5JBR23-EC6BT30-R144-EGE18-4O3-B2-HAB3-D16-4Aa2-G2-CGB3-D16-4O-ZAO-CB3-XDS16-2K2-BWAB-A3-XDKQHCGFUCAfK20-GDPL2H7S19-ABCBEA5QR3Q17-ABCG2E5WBT2W17-AB2(CA)IFCAMBT22-ACHDMCNYBR22-A2E3DP2BT23-EC5KBT30-R20-OF30-KF86-LH-FEGE20-SP3-BENHABA19-V3B2-GEICG2B19-Ae-2B2-AOPCBL21-K2BK-WAB2-GQ5-HCGFUC10-2BJ6-A6-2HCEAbUI24-BEAECUFBR12-EF9-G2EB2FEDBT22-ACAIFCAMBT23-CHDMCNYBT23-2E3DP2BT24-CMLJLAdBT30-R11-2WV5-Ac-FW20-2V5-CIKFC20-SO4-ACD23-KQ4-AE25-LHDFEGE25-BENHABA20-3B2-GEI-G2B19-Ae3BO-AOP-B2L20-K-BKAf5-G22-ABJIU12-HCEAb14-BFU12-ECUF14-EF11-EB2FE-R25-AIFC-AdBT24-HDMC-AdBT25-3D-AdBT30-R43-2WVD4-Ac-FW20-2VA4-CIKFC20-SO4-ACD23-KQ4-AE24-PLHDFEGE26-ENHA2B21-A4-EICGB21-BABO2-OP2-L22-ABKAf29-2AI31-AF31-EF49-2(R31-)R75-2WVD4-Ac-F21-2VA5-IKF87-HD-EG27-ENHA28-EI26-Ae30-ABK30-2AI255-2W30-2V504-
