model
size = 32 17 20, scale = 0.05, origin = -y
material deform = 1, fade = true, lighting = smooth, roughness = 0.3, metalness = 0.6
  colors = A:#050 B:#0E0 C:#040 D:#360 E:#0A0 F:#0D0 G:#060 H:#0C0 I:#080 J:#0B0 K:#020 L:#070 M:#030 N:#0F0 O:#090 P:#111 Q:#DDD R:#330 S:#3F0 T:#6F0 U:#9C0 V:#390 W:#444
voxels
39-H507-BN12-M-HD12-HFB13-G2E90-2F19-LV8-AHF20-E8-EH339-2BN12-M-HD12-HF2B11-LG3E13-F12-GHG16-D12-LB18-GD8-G2FH18-LV8-AHFH18-JE8-EHJ20-H316-B2C13-G-CA12-HF13-AGACA12-HF12-GHG16-D12-LB17-DGD8-G2FH17-DLV8-AHFH17-DJE8-EHJI18-EH8-EHE170-2(P31-)P86-2(2MC29-)M49-2(AG8-IEIK17-D)AG8-IEIK17-EAG8-IEIK69-MK28-HJCMR27-FG2AC-P25-JLDNBWFQ25-GCF-WJQ26-M2-WLQ30-P168-A10-LAC17-D2A8-ALAC16-RD2A8-ALAC17-E2A8-ALAC17-JA10-LAC3-2KAKM26-C2KAKMD25-C2KCKMBTP23-C2KAKM2NQ23-C2KDK2BFQ23-C2KCKBFJQ24-2KMKHJLQ25-3K-WCQ30-P135-DAG29-DAGR7-C2GU16-RDAGRML3-AKC2GU16-GEAGRMLJ2EAKC2GUH16-JAGRMLJ2EAKC2GUHCT4KC2K9-GRMLJ2EAKC2GUHCT4KC3K17-C2GUHCTHJ2KCBPLNS18-UHCTFG2KC2NQNB18-UHC3T2K3TQ22-CT2C2K3CP22-CT2H2K3HQ23-T2U2K3UQ30-P135-D2AM6-AG19-AD2AMGI2E-GAGHFB16-RD2AMGI2EHGAGHFBF15-GE2AMGI2EHGAGHFBF16-J2AMGI2EHGAGHFBFNEGCKDT3D6-E2AMGI2EHGAGHFBFNEGCKDT5K11-EHGAGHFBFNEGCKDT5C18-BFNEGCKDT5G18-BFNEGCKD4E20-BFNEGCKD3NP22-NEGCKD3FP23-EGCKD3BQ30-P135-DKDCAGE2-CGL18-RADKDCAGELACGLF2B16-RDKDCAGELACGLF3B15-GEKDCAGELACGLF3BIGI13-JKDCAGELACGLF3BIG2ILNS5N4-EKDCAGELACGLF3BIG2ILNS6L5-DCAGELACGLF3B2(IG2ILNS7I16-2B)IG2ILN7G17-2BIG2ILN3IQI20-BIG2ILN3BQ23-G2ILN2BP167-DE4AE2-MAJ18-RADE4AEO2MAJ3F15-DRDE4AEO2MAJ4FB14-G2E4AEO2MAJ4FBJI12-IJE4AEO2MAJ4FBJIHFNS4NP4-2E4AEO2MAJ4FBJIHFNS7F4-4AEO2MAJ4FBJIHFNS7H16-2FBJIHFNS6I17-2FBJIHFN8J16-2FBJIHFN2BP2B21-BJIHFN2FP2F22-JIHFN2F168-DC4AL2-CAO18-RADC4ALO2CAOHJEI14-DRDC4ALO2CAOHJE2IL13-GEC4ALO2CAOHJE2ILB13-JC4ALO2CAOHJE2ILBJF6BP4-EC4ALO2CAOHJE2ILBJF2B7F4-4ALO2CAOHJE2ILBJF2B7J16-E2ILBJF9B16-E2ILBJFB8L16-E2ILBJFB5I21-ILBJFB5I22-LBJFB2E168-DCM2A2M2-ALE18-RADCM2A2M2CALEH2E15-DRDCM2A2M2CALEH2ECA14-GECM2A2M2CALEH2ECAO14-JCM2A2M2CALEH2ECAO2BSHA4HP5-CM2A2M2CALEH2ECAO2BSHA7S5-2A2M2CALEH2ECAO2BSHA7B16-ECAO2BSHA6B17-ECAO2BSH8O16-ECAO2BSH2AP2A21-AO2BSH2CPC23-O2BSH2E169-CKA6-2O18-RADCKAGCKCAI2OHEV15-D-DCKAGCKCAI2OHEVD15-GECKAGCKCAI2OHEVDAH14-JCKAGCKCAI2OHEVDAHB2NJD5J5-CKAGCKCAI2OHEVDAHB2NJD6N10-CAI2OHEVDAHB2NJD7N15-EVDAHB2NJD7B15-EVDAHB2NJ7H17-VDAHB2NJ3AQA20-DAHB2NJ3DQ23-HB2NJ2VP169-D27-RADCV2C6-JEJL15-DRDCE3C3-L2(EJ)LG15-GECH3CM2AL2(EJ)LG16-JCO3CM2AL2(EJ)LGAJ2BDKM3K8-O3CM2AL2(EJ)LGAJ2BDKM5D16-EJLGAJ2BDKMBP3B17-JLGAJ2BDKM2BQ2B17-JLGAJ2BDK3JQ20-LGAJ2BDK3AP22-AJ2BDK3GP23-J2BDK3LQ30-P144-LEJ18-RADC3-M2-CLE3-D16-RDC2(M2-)CLE3-D16-GECM-K2M-CL3-3D16-JC2-K2MC-L3-4D2FBNDM2D20-4D2FBNDM3N19-4D2FBNDMBPBNS17-4D2FBND3FQNB17-4D2FBND3FQ22-D2FBN4DP22-D2FBN4DQ23-2FBN4DQ30-P20-RA30-RA86-CK2-2OI20-DC3-CKBU2OI19-RDCK2-CKFG2OI19-G-CK2-CKHG2O21-JCKC-CKG2-OI5-2H2BDC10-CKC6-O6-2H2BDCD24-I2H2BDCBP12-CK9-I2H2BDC2NQ22-I2H2BD2BFQ23-2H2BDBFJQ23-2H2BDHJLQ24-H2BDEWCQ30-P11-GCK5-O-RO20-GC5-IODRO20-GC4-LIO23-GC4-LI25-CKD-GLI25-F2BUGLI20-DJE2-FBF-AIE19-G2E2H-2FH-L2E20-J-OEO5-I22-EOL2A12-HOAM14-CMC12-JCMR14-MA11-FG2AC-P25-JLDN-WFQ24-HGCF-WJQ25-AMO-WLQ30-P43-JHIC4-M-GM20-B2I4-AMALG20-LJ4-2CD23-IB4-MA24-IFBF-CMG25-F2BUCKA21-J4-BF-AI21-2E2H2-FH2-E22-JOEO29-OLA31-CM31-MA49-2(P31-)P75-JHIC4-M-G21-B2I5-MAL90-CM27-B2-C28-BF26-H30-JOE30-OLA255-JH30-BI504-
