model
size = 32 32 5, scale = 0.05, origin = -y
material deform = 1, fade = true, lighting = smooth, roughness = 0.3, metalness = 0.6
  colors = A:#91989F B:#DDD C:#EEE D:#787D7B E:#D7C4BB F:#BDC0BA G:#FFF H:#AAA I:#BBB J:#888 K:#0B1013 L:#6E75A4 M:#EB7A77 N:#A8D8B9 O:#777 P:#F4A7B9 Q:#B9887D R:#51A8DD S:#58B2DC T:#808F7C U:#EEA9A9 V:#77969A W:#8A6BBE X:#9E7A7A
voxels
1057A3C2B2EF2EH5EH2F5EC2A3J2A3CFE2BHE6BFBABJF5BA3J2A3C2BCBHE6BF3BOI3C2H4J2A3CBE2BHEB2C3BF2BEBF4CI4J2AB3CB2CHE2CBCB7CIB3C4B2A2CAB2CJHEACBIC2(B2C)IABCBH4E2ACI2CHCJHEJCHJBACABCHBAJ2C5B2A2BCB3CIBJ5CFCFBEF2E2F5B2AB4CBCH7BFB2CE4C2BJ3B2AB2CB3EH8EB2CE4CFBDJBD2AB2C9EF2IF3BE4CFB4D2A3B5EB3EFILFB2CE4CFB4D2A3B5EC2E2BCIB3CE4C2BE3B2A8HCHCBACHACI2C2H4C2B2C2AFJBFC3D2CMPMQB3CI2C2B2CF2C2B2AFJBEC2HNB2ABHARHFIH2CFCBC2HIBE2AFJB2C2HNBEBCBFSACBE3BCECF2(BC)2A3BCE3FBCHCAH2CE8BIE2BC2AB5GBTBABCBEUDF8BIECBE2AV5GFBFEF2C2IH9CIF2BF2AWG3KGABA2B3CE10CIF3C2AX5G5BFBCIBF8EIF3C2AL5G10CF8DIF3C2AF5C2H8CF8DIF3C2AC5G10CF8DIF3C2AC2GK2G10CF8DIF3C2ACG3KG3CBCF4CBD2FBECBDIF3C2AC2GK2G2(HE)H3CHI2BCBE2C3H4F2AC5G10CB2C6BI4B2A4CB12C2B6CI3CB33A60-3D8-B2-4B3-B-B2-5B-3D5-2B-B2-5B2-3BD6-4D5-B-2B2-B2-3B-B2-B6-4D15-B20-D3-D31-2(D2-)2(D9-)2B7-D5-F-2(F2-)2F7-B4-B26-B2-B12-B7-F-2(D2-)2B10-3F-3B5-F-4D2-3B9-2F2-B7-F-4D2-3B62-DB2-3D13-2B5-2B3-DB20-B9-DB10-F3-B-3B6-B3-3B2-3F9-B-3B-2B2-2B3-B5G11-B-3B-2B8-5GFB18-F2B4-G3KG-B-2B15-F6-5G2B-2B15-F6-5G11-8D-F5-F5C11-8D-F6-5G11-8D-F6-2GK2G11-8D-F6-G3KG5-F5-D6-D-F6-2GK2G9-F3-B6-4F3-5G13-6B11-B129-B2-3B10-2B12-B-2(B2-)B5-B7-4D2(7-B)12-4D36-D35-D2-D23-B62-B31-B16-B8-4D2-2B24-4D2-2B64-B2-D-D58-B25-B3-B18-3B49-B63-B-B71-2(8D24-)8D253-B21-B13-4D7-B20-4D211-B8-4D2-2B24-4D2-2B158-B208-2(8D24-)8D166-
