model
size = 30 29 9, scale = 0.05, origin = -y
material deform = 1, fade = true, lighting = smooth, roughness = 0.3, metalness = 0.6
  colors = A:#7C5229 B:#FF9 C:#111
voxels
130-A809-2C2(28-2A)28-A29-A27-3A28-A690-C29-A29-2A28-2A27-3A14-2C10-4A14-2A10-3A14-2A12-A2-2A10-3A13-4A9-2A17-A-A7-A20-3A5-A24-2A2-A27-2A29-A560-A28-A-A14-2C9-A-A16-2A9-3A15-2A12-2A13-2A9-B3-4A-2A6-4A15-6A4-3A18-6A2-3A20-9A24-5A26-4A27-4A23-2B3-2A24-2B29-2B28-2BA28-B3A26-2B2A27-2B28-3B28-B-B248-2B29-2B28-2B3-3A23-3B-5A22-2B-8A19-2B-13A3-A11-3B-11A2-A13-2B2-11A20-11A22-9A22-8A23-7A21-3B6A2(22-4B4A)23-3B4A4-2A17-3B4A3-3A18-B10A19-2B6ACA21-2B6A23-3BAB26-3B2(29-B)98-B29-2B28-3B4-A22-4B-5A21-3B-7A19-4B10A17-3B12A15-2(3B14A14-)2B-14A17-15A17-14A16-2B12A18-B11A19-B10A20-B8A20-3B7A3-2A15-3B7A2-4A15-2B7A-5A15-2B12A16-3B10A15-6B8A19-3B7A22-2BA3B26-B-B47-2C28-3C27-A20-2B6-A20-3B5-2A20-4B4-2A21-4B-5A21-3B-7A19-4B10A17-3B12A15-2(3B14A14-)2B-2(14A17-)B14A16-2B12A18-B11A19-B10A19-2B8A20-3B7A3-2A15-3B7A2-4A15-2B7A-5A15-2B12A16-3B10A15-6B8A19-3B7A22-2BA3B26-B-B47-2C28-3C3(27-2A)16-2C4-B5-2A16-3C3-2B4-2A17-C2A3-2B2-3A18-2A3-4B5A15-2A5-3B8A12-A7-2B13A6-2A8-2B-11A5-2A13-11A3-3A14-11A-3A15-3B11A17-3B10A18-3B8A20-3B7A21-4B4A22-4B4A23-3B4A4-2A17-3B4A3-3A18-B10A19-2B6ACA21-2B6A23-3BAB26-3B2(29-B)153-2C11-A16-3C9-2A16-2CA9-2A19-A7-3A18-A9-4A16-A10-5A13-A13-3A12-2A17-3A7-2A18-3A6-2A20-3A3-3A22-2A-4A24-2A-2A22-B29-2(3B28-)3B2(27-4B)27-3B28-3B29-B97-
