model
size = 22 30 19, scale = 0.05, origin = -y
material deform = 1, fade = true, lighting = smooth, roughness = 0.3, metalness = 0.6
  colors = A:#F70 B:#FFDADA C:#1C1C1C
voxels
28-3(10A12-)2(2(10B12-)5(10A12-))6(10A12-)10A13-8A100-12C3(10-12A)2(2(10-12B)5(10-12A))7(10-12A)11-10A13-8A76-2C12-2C3(6-2A12-2A)2(6-2B12-2B)5(6-2A12-2A)14(6-2B12-2B)7-BA10-AB9-12A11-10A52-C16-C3(4-A16-A)2(2(4-B16-B)5(4-A16-A))7(4-A16-A)5-B14-B7-BA10-AB9-12A12-8A15-6C9-C18-C3(2-A18-A)2(2(2-B18-B)5(2-A18-A))7(2-A18-A)3-A16-A5-B14-B7-BA10-AB10-2A6-2A13-C6-C8-C18-C3(2-A18-A)2(2(2-B18-B)5(2-A18-A))2(2-A18-A)4(2-C18-C)2-A18-A3-A16-A5-B14-B7-B12-B9-2A8-2A11-C8-C6-C20-CA2(20-2A)2(20-AB20-2B20-BA4(20-2A))20-2A20-AC20-C89-C18-C3-A16-A5-B14-B7-B12-B9-A10-A11-C8-C6-4(C20-CA2(20-2A)2(20-AB20-2B20-BA4(20-2A))20-AC20-C134-C16-C5-B14-B7-B12-B9-C10-C27-)C20-CA2(20-2A)2(20-AB20-2B20-BA4(20-2A))20-AC20-C134-C16-C5-B14-B7-BA10-AB10-C8-C28-C20-CA2(20-2A)2(20-AB20-2B20-BA4(20-2A))20-2A20-AC20-C89-C18-C3-2A14-2A5-2B12-2B8-A-C6-C-A11-C8-C29-C18-C3(2-A18-A)2(2(2-B18-B)5(2-A18-A))2(2-A18-A)4(2-C18-C)2-3A14-3A4-B14-B7-B2AC6-C2AB10-A8-A51-C18-C3(2-A18-A)2(2(2-B18-B)5(2-A18-A))6(2-A18-A)3-AB14-BA6-B2AC6-C2AB9-A10-A73-C16-C3(4-A16-A)2(2(4-B16-B)5(4-A16-A))6(4-A16-A)5-2B2AC6-C2A2B116-2C12-2C3(6-2A12-2A)2(6-2B12-2B)5(6-2A12-2A)12(6-2B12-2B)6-2B3AC4-C3A2B140-3C6-3C3(10-3A6-3A)2(2(10-3B6-3B)5(10-3A6-3A))2(10-3A6-3A)3(10-3AC4-C3A)167-19(C4-C16-)C4-C228-
