model
size = 31, scale = 0.05, origin = -y
material deform = 1, fade = true, lighting = smooth, roughness = 0.3, metalness = 0.6
  colors = A:#040202 B:#FCFCFC C:#FEFB00 D:#0303FF E:#03FF03 F:#FF8B03 G:#FF0303
voxels
32A3(8(2(9DA)9D2A)2(9DA)9D33A)4(3(9CA)4(F2(9CA)9CG)5(F2(9DA)9DG)31A9(F2(9DA)9DG)31A5(F2(9DA)9DG)4(F9BA19BG)3(A9B)2A)4(3(9CA)4(F2(9CA)9CG)5(5F21A5G)31A9(5F21A5G)31A5(5F21A5G)4(F9BA19BG)3(A9B)2A)3(9CA)4(F2(9CA)9CG)5(5F21A5G)31A9(5F21A5G)31A5(5F21A5G)4(F9BA19BG)3(A9B)963A2(3(9CA)4(F2(9CA)9CG)5(5F21A5G)31A9(5F21A5G)31A5(5F21A5G)4(F2(9BA)9BG)3(A9B)2A)3(9CA)4(F2(9CA)9CG)5(5F21A5G)31A9(5F21A5G)31A5(5F21A5G)4(F2(9BA)9BG)A9BA2B2A3(BA)3(9B2A3(9CA)4(F2(9CA)9CG)5(5F21A5G)31A9(5F21A5G)31A5(5F21A5G)4(F2(9BA)9BG)A9BABA3B2(AB)A)9B2A3(9CA)4(F2(9CA)9CG)5(5F21A5G)31A9(5F21A5G)31A5(5F21A5G)4(F2(9BA)9BG)A9BA2B2A2(2BA)9B2(2A3(9CA)4(F2(9CA)9CG)5(5F21A5G)31A9(5F21A5G)31A5(5F21A5G)4(F2(9BA)9BG)3(A9B))963A5(3(9CA)4(F2(9CA)9CG)5(5F21A5G)31A9(5F21A5G)31A5(5F21A5G)4(F2(9BA)9BG)3(A9B)2A)3(3(9CA)4(F2(9CA)9CG)5(5F5E2(A9E)G)31A9(5F5E2(A9E)G)31A5(5F5E2(A9E)G)4(F2(9BA)9BG)3(A9B)2A)3(9CA)4(F2(9CA)9CG)5(5F5E2(A9E)G)31A9(5F5E2(A9E)G)31A5(5F5E2(A9E)G)4(F2(9BA)9BG)3(A9B)3(33A8(2(9EA)9E2A)2(9EA)9E)32A
