model
size = 31, scale = 0.05, origin = -y
material deform = 1, fade = true, lighting = smooth, roughness = 0.3, metalness = 0.6
  colors = A:#040202 B:#03FF03 C:#0303FF D:#FF8B03 E:#FCFCFC F:#FEFB00 G:#FF0303
voxels
32A8(9G2(A9E)2A)9G2(A9E)33A8(9DA9GA9C2A)9DA9GA9C33A8(9CA9DA9E2A)9CA9DA9E33A4(9B2(A9C)A4(F9B2(A9C)G)5(F9G2(A9E)G)31A9(B9DA9GA9CG)31A5(5G5CA9DA9EB)4(5G5FA9D10EB)A9FA9EA9D2A)4(9B2(A9C)A4(F9B2(A9C)G)5(5F21A5G)31A9(5B21A5G)31A5(5G21A5B)4(5G5FA10E5D5B)A9FA9EA9D2A)9B2(A9C)A4(F9B2(A9C)G)5(5F21A5G)31A9(5B21A5G)31A5(5G21A5B)4(5G5FA10E5D5B)A9FA9EA9D963A2(9CA9FA9BA4(D9CA9FA9BG)5(5D21A5G)31A9(5C21A5B)31A5F5(21A10F)3(5GA9EA5C10F)5GA9EA5C5FA9GA9EA9C2A)9CA9FA9BA4(D9CA9FA9BG)5(5D21A5G)31A9(5C21A5B)31A5F5(21A10F)3(5GA9EA5C10F)5GA9EA5C5FA9GA2E2A3(EA)3(9C2A9CA9FA9BA4(D9CA9FA9BG)5(5D21A5G)31A9(5C21A5B)31A5F5(21A10F)3(5GA9EA5C10F)5GA9EA5C5FA9GAEA3E2(AE)A)9C2A9CA9FA9BA4(D9CA9FA9BG)5(5D21A5G)31A9(5C21A5B)31A5F5(21A10F)3(5GA9EA5C10F)5GA9EA5C5FA9GA2E2A2(2EA)2(9C2A9CA9FA9BA4(D9CA9FA9BG)5(5D21A5G)31A9(5C21A5B)31A5F5(21A10F)3(5GA9EA5C10F)5GA9EA5C5FA9GA9EA)9C963A5(9D2(A9B)A4(F9D2(A9B)D)5(5F21A5D)31A9(5E21A5G)31A5(5C21A5B)4(5C5EA9FA5G5B)A9EA9FA9G2A)3(9D2(A9B)A4(F9D2(A9B)D)5(5F5CA9FA5F5D)31A9(5E5BA9DA9EG)31A9(5C5DA9DA5E5B)A9EA9FA9G2A)9D2(A9B)A4(F9D2(A9B)D)5(5F5CA9FA5F5D)31A9(5E5BA9DA9EG)31A9(5C5DA9DA5E5B)A9EA9FA9G33A8(9C2(A9F)2A)9C2(A9F)33A8(9BA9DA9E2A)9BA9DA9E33A8(2(9DA)9E2A)2(9DA)9E32A
