model
size = 23 12 29, scale = 0.05, origin = -y
material deform = 1, fade = true, lighting = smooth, roughness = 0.3, metalness = 0.6
  colors = A:#111 B:#444 C:#EEE D:#FFFFFB
voxels
6-2(11A12-)3A5-3A12-4A3-4A14-7A17-5A151-3(5A5-5A8-)6A3-6A10-11A12-11A15-5A127-2(4A9-4A6-)3A11-3A6-3A11-3A8-A11-A10-2(A11-)11A15-5A103-3(3A13-3A4-)3A13-3A6-A13-A8-2A11-2(2A9-)2A12-9A16-5A80-3(3A13-3A4-)3A13-3A5-2A13-2A6-3A11-3A7-2(3A9-)13A12-9A77-2(3A15-3A2-)2A17-2A3-A17-A4-A17-A5-3A11-3A6-4A9-2(4A7-)4A10-11A15-5A56-2(2A17-2A2-)A19-A2-A19-A3-A17-A4-A17-A5-4A9-4A6-5A7-5A8-13A12-9A53-3A17-6A17-3A-A19-A2-A19-A3-A17-A4-A17-A5-A15-A6-5A7-5A8-13A12-9A53-2A2(19-4A)19-2A-A19-A2-2A17-2A3-A17-A4-2A15-2A5-3A11-3A8-5A3-5A12-9A17-3A33-2A3(19-4A)19-2A-2A17-2A2-2A17-2A3-2A15-2A4-4A11-4A6-6A3-6A10-11A15-5A32-2A3(19-4A)19-2A-2A17-2A2-2A17-2A3-2A15-2A4-4A11-4A6-4A7-4A10-11A14-7A18-3C10-2A3(19-4A)19-2A-2A17-2A2-2A17-2A3-2A15-2A4-4A11-4A6-4A7-4A10-11A14-7A18-CAC10-2A3(19-4A)19-2A-2A17-2A2-2A17-2A3-2A15-2A4-4A11-4A6-4A7-4A10-11A14-7A18-3C10-3A17-6A17-5A19-2A-A19-A2-2A17-2A3-A17-A4-2A15-2A5-3A11-3A2(7-4A)10-11A15-5A33-2(2A17-2A2-)A19-A2-A19-A3-A17-A4-A17-A5-A15-A6-3A11-3A8-4A5-4A12-9A17-3A34-2(3A15-3A2-)2A17-2A2-2A17-2A3-2A15-2A4-2A15-2A5-A15-A6-3A11-3A8-13A12-9A55-2(2A15-2A4-)A17-A4-A17-A5-A15-A6-A15-A7-3A9-3A8-3A9-3A10-11A14-7A56-3(4A11-4A4-)4A11-4A5-3A11-3A6-3A11-3A7-2(3A9-)2A9-2A11-11A14-7A56-AB3A9-3ABA4-5A9-5A5-3A11-3A6-3A11-3A7-2(2A11-2A8-)2(3A9-)13A11-11A16-3A58-2(AB)11A2(BA)4-19A6-3A4-A4-3A8-3A4-A4-3A9-2(2A4-A4-2A10-)2A4-A4-2A11-11A13-9A78-4(AB)3A4(BA)4-19A8-5AC5A12-4ACAC4A12-11A12-4A3C4A12-3A2CA2C3A13-A2C3A2CA15-7A79-3(AB)2A3B2A3(BA)4-19A13-D21-D-D43-3D19-2D-2D17-2D3-2D16-2D3-2D79-2A2(BA)B5A2(BA)B2A4-19A235-2A2(BA)5B2(AB)2A6-17A236-3ABAB5ABAB3A6-17A237-3ABA5BAB3A8-15A239-3AB5AB3A10-13A241-3A5B3A12-11A243-9A14-9A237-
