model
size = 26 32 17, scale = 0.05, origin = -y
material deform = 1, fade = true, lighting = smooth, roughness = 0.3, metalness = 0.6
  colors = A:#FF6 B:#06C C:#111 D:#777 E:#E00 F:#555 G:#BBB H:#3CC I:#F30 J:#444
voxels
-24D3(2-D22AD)2-D22-D2-D-C-2C2-C3-3C-7CD2-D-2C2-2(C3-)C-C5-CD2-D-4C2-C3-3C-C-3C-C2(D2-)C8-2C2-C-3C-C2(D2-)2C-8C2-C-3C-CD2-D2(-C)2-3C-C2-C-C5-CD2-D-C2-3C-5C2-7CD2-D4-C-3C-2C-C8-D2-D-4C2-C3-5C3-C-CD2-D3-C-C3-C7-2C-C-D2-D-4C2-C3-C-3C2(-2C)D2-D-C2-C6-2(C2-)2C3-D2-D-2C2-9C-2C2-3CD2-D10-4C8-D2-D-7C3(-C)-7CD2-D-C5-C3-2(C-)C5-CD2-D-C-3C2(-C)3-2(C-)3C-CD2-D-C-3C-C-2C-C2-C-3C-CD2-D-C-3C-C2-3C2-C-3C-CD2-D-C5-C2(-2C)-C5-CD2-D-7C-5C-7CD2-D22-4(D2-D22A)D2-24D2-D22AD3(30(2-B22AB)2(2-D22AD))30(2-B22AB)2-D7A8D7AD2-D22AD17(2-B22AB)-D2(B22AB2D)B22ABD-9(B22AB2-)4(B7A8D7AB2-D6AD8-D6AD2-D22AD16(2-B22AB)2(-DB22ABD-2(B22AB2-)B22AB)5(2-B22AB)2-)B7A8D7AB2-D6AD8-D6AD2-D22AD17(2-B22AB)-D2(B22AB2D)B22ABD-9(B22AB2-)B7A8D7AB2-D7A8D7AD2-D22AD30(2-B22AB)2(2-D22AD)8(2-B22AB)2(2-BA20CAB)3(2-B22CB)2-B13C3(2GC)B2-B2CG2C3G3(CG)2CG3CGCB2-B4(CG)2C2(G2C2GC)B2-B2(CG)C3G3(CG)2(2CG)2CB2-B13C2GCG2C2GCB2-B22CB2-BC2GC2(G3CG2C)3GCB2-BCG2CG3CG2C2G2(2CG)CGCB2-BC2G2C3(GC)2G2(C3G)CB2-B22C7(B2-B22A)B2(2-D22AD)3(2-D22ED)6(2-D22AD)2-24F13(2-F22-F)2-24F2-D22AD5(2-B22AB)2-D22AD2-D22ED81-5(22A4-)22A5-3I10-B69-E304-D22AD5(2-B22AB)2-D22AD133-2(22A4-)2(19AD2A4-)22A5-3I2-J6-3B16-J25-J24-3E24-E278-D22AD2-B22AB4(2-24B)2-D22AD159-11A3CA2CA3HA4-12A2(C2A)H-HA4-11A2C2A2CAH-HA4-18A3HA5-3I10-B69-E330-D22AD2-D-E3-2E2(-E)2(2-E)2(-E)-D2-D-3E-E2-3E2-E8-D2-D3(-E)2-7(E-)D2-D-3E-E3-E2-5(E-)D2-D22AD-
