model
size = 14 27 5, scale = 0.05, origin = -y
material deform = 1, fade = true, lighting = smooth, roughness = 0.3, metalness = 0.6
  colors = A:#EEE B:#222 C:#111 D:#BDC0BA E:#DDD23B F:#FFFFFB
voxels
62-2B11-4B9-2(6B8-)6B9-4B11-2B235-3AE9-AE2B-A7-A-4B-A5-E-B4-B-E3-A-B2-2B2-B-E2-AB2-4B2-BA2-E2-6B2-E3-A8BE5-A6BA7-E4BE9-E2BA234-4A9-6A7-8A5-10A3-12A2(2-5A2F5A)3-4A2F4A5-3A2F3A7-2A2F2A9-A2FA10-4D9-D4-D7-E3(6-D)5-D8-D4-D8-D3-D10-D2-D10-E-D2(12-2D)12-E-E10-D3-D8-D5-D6-E7-D4-D9-E3D10-4A9-E4-A7-A-4C-E5-A-C4-C-A3-E-C2-2C2-C-E2-AC2-4C2-C2(A2-)6C2-E3-E-6C-A5-A6CA7-A4CE9-A2CA291-2C11-4C9-2(6C8-)5C10-4C11-2C230-
