model
size = 27 8 32, scale = 0.05, origin = -y
material deform = 1, fade = true, lighting = smooth, roughness = 0.3, metalness = 0.6
  colors = A:#222 B:#777 C:#111 D:#700 E:#444 F:#555 G:#BBB H:#D00
voxels
81-81A108-81A82-2A21-2A2-2E21-2E-25AE23A4-2A2B24A4-2C4-7B14-2C49-2A21-2A2-2E21-2E-25AE23A4-2A2B24A4-2C2-11B12-CH4-7C15-C75-25A-23A4-28A6-15B14-11C89-25A-23A4-2AB25A5-17B11-15C87-25A-23A4-C27A4-19B9-17C86-25A-23A4-2AB25A3-21B7-19C85-25A-23A4-28A3-21B7-19C85-25A-23A4-C27A2-23B5-21C84-25A-23A4-28A2-23B5-8C5D8C84-25A-23A4-28A-25B3-8C7D8C83-25A-23A4-28A-25B3-7C5DG3D7C83-25A-23A4-28A-25B3-7C6DG2D7C83-25A-23A4-28A-25B3-7C4DC4D7C83-25A-23A4-28A-25B3-7C2DG6D7C83-25A-23A4-28A-25B3-7C3DG5D7C83-25A-23A4-28A-25B3-8C7D8C83-25A-23A4-28A2-23B5-8C5D8C84-25A-23A4-28A2-23B5-21C84-2(25A-23A4-28A3-20B8-19C85-)25A-23A4-28A4-19B9-17C86-25A-23A4-4AB18A2-3A5-17B8-A2-15C87-25A-23A4-28A6-15B14-11C89-25A-23A4-2AE25A8-11B18-7C91-25A-23A4-2AE20A3C2A10-7B5-3C32-4BF73-25A-23A4-2AE19A5CA21-5C23-3C7-B-3F12-3C56-25A-23A4-2AE19A2(2CA)21-5C23-3C11-11F7C54-25A-23A4-C21A5CA21-5C23-3C24-3C3-2A21-2A2-2E21-2E-25A-23A4-2AE2A8C10A3C2A8-B13-3C57-2A21-2A2-2E21-2E-81A81-
