model
size = 16 32 26, scale = 0.05, origin = -y
material deform = 1, fade = true, lighting = smooth, roughness = 0.3, metalness = 0.6
  colors = A:#C90 B:#EEE C:#DDD D:#111 E:#E00 F:#222 G:#BBB
voxels
310-7F3G6-2F5-3G6-F15-F410-3C15-2C28-2(F15-)F4-2F10-6F152-2(CE14-)3(C2E13-)C2E98-4(5A11-)5A7-3C-5A6-5C5A6-C2D2C2(5A7-2D2-)5A7-7D2A8-6D14-2F136-2(CE14-)C3E12-CEG2F11-CEG3F10-C2E-3F14-3F13-2DF14-3D13-3D12-2(5A11-)5(C3AB11-)4(4AB11-)5A11-5A150-2(CE14-)C3E12-CEG2F11-CEG3F10-C2E-F2D14-3D13-3D14-3D12-2(5A11-)C3AB5(11-5A)4(11-C4A)11-C3AB2(11-5A)134-2(CE14-)C3E12-2(C2E13-)C2E34-3(5A11-)C3AB11(11-5A)11-C3AB2(11-5A)235-5A2(11-C3AB)13(11-5A)11-C3AB2(11-5A)203-2(5A11-)C3AB15(11-5A)11-C3AB2(11-5A)171-2(5A11-)C3AB17(11-5A)11-C3AB2(11-5A)63-F91-5A11-C3AB3(11-5A)3(11-B4A)2(4(11-B3AB)11-B4A)3(11-5A)11-C3AB11-4AG13-3B13-2BC14-BC15-F91-5A11-C3AB3(11-5A)11-B4A12(11-B3AB)3(11-5A)11-C3AB11-4AG2(13-2BD)14-BC15-F75-2(5A11-)C3AB11-5A11-B4A3(11-B3AB)11-4AB2(11-5A)11-B4A2(11-B3AB)3(11-5A)4(11-B3AB)11-5A11-C3AB11-4AG13-3B13-2BC14-BC15-F75-5A11-C3AB4(11-5A)11-B4A11-B3AB11-4AB2(11-5A)11-B4A2(11-B3AB)2(11-5A)11-3ABA2(11-B3AB)3(11-5A)11-C3AB11-5A47-F15-F75-5A11-C3AB4(11-5A)11-B4A11-B3AB11-4AB2(11-5A)11-B4A2(2(11-B3AB)3(11-5A))11-C3AB11-5A139-5A11-C3AB3(11-5A)11-4A2(B11-B3A)B11-4AB2(11-5A)11-B4A2(11-B3AB)3(11-5A)2(11-B3AB)2(11-4AB)11-5A11-C3AB11-5A139-5A11-C3AB2(11-5A)3(11-B4A)11-B3A3(B11-4A)3(B11-B3A)3(B11-4A)2(B11-B3A)B2(11-B4A)11-5A11-C3AB11-4AG13-3B13-2BC14-BC15-F75-2(5A11-)C3AB3(11-5A)11-B4A12(11-B3AB)3(11-5A)11-C3AB11-4AG2(13-2BD)14-BC15-F91-5A11-C3AB4(11-5A)2(5(11-B4A)11-5A)2(11-5A)11-4AB11-C3AB11-3ABG13-3B13-2BC14-BC15-F91-2(5A11-)C3AB16(11-5A)11-4AB11-C3AB2(11-5A)47-F15-F107-2(5A11-)C3AB15(11-5A)11-C3AB2(11-5A)203-5A11-C4A11-4AB13(11-5A)11-C3AB2(11-5A)219-2(5A11-)C4A11-C3AB11(11-5A)2(11-C3AB)11-5A123-8C8-7E9-2E2-E91-3(5A11-)C3AB11-4AB8(11-5A)11-C3AB3(11-5A)123-C3D4EC7-C3D3E9-E3DE12-3(3D13-)2(2DF13-)3D13-3D12-A3DA11-5A11-C4A11-C3AB3(11-5A)11-4A3(B11-C3A)B2(11-5A)155-C3D4EC7-C3D3E9-E3DE12-2DF13-FDF13-3F13-2FD13-3D13-2DF13-2FD13-2DF12-3(5A11-)4(C3AB11-)3(5A11-)5A12-2D157-8C8-7E9-2E2-E171-4(5A11-)5A3-2G6-A2(8D2G6-)2D5-2G7-2D5-G8-2F152-
