model
size = 19 32 26, scale = 0.05, origin = -y
material deform = 1, fade = true, lighting = smooth, roughness = 0.3, metalness = 0.6
  colors = A:#C90 B:#444 C:#777 D:#DDD E:#E00 F:#555 G:#EEE H:#111 I:#BBB J:#400 K:#933
voxels
329-2E17-E21-7E3I9-2E5-3I9-E18-E488-3D18-2D34-2(E18-)E4-2E13-6E10-2(E18-)4E13-E18-2E96-2(DE17-)3(D2E16-)D2E116-4(5B14-)5B10-3D-5B9-5D5B9-D2J2D2(5B10-2J2-)5B10-5J2H2B11-3J3H17-2J163-2(DE17-)D3E15-DEI2G14-DEI2GI13-D2E-2GI17-3G16-2DG17-3D16-3D15-5B14-B3AB5(14-D3AC)4(14-B3AC)14-B3AB14-5B180-2(DE17-)D3E15-DEI2D14-DEI3D13-D2E-3D17-3D16-3H17-3H15-2(B3AB14-)D3AC5(14-B3AB)4(14-D3AB)14-D3AG14-B3AB14-5B161-2(DE17-)D3E15-2(D2E16-)D2E40-5B2(14-B3AB)14-D3AG11(14-B3AB)14-D3AC14-B3AB14-5B280-5B2(14-D3AC)13(14-B3AB)14-D3AG14-B3AB14-5B242-5B14-B3AB14-D3AC8(14-B3AB)13-2C3AC6(14-B3AB)14-D3AC14-B3AB14-5B204-5B14-B3AB14-D3AG7(14-B3AB)13-2C3AC14-F3AF2(14-B3AB)13-2C3AC5(14-B3AB)14-D3AG14-B3AB14-5B56-K18-K109-5B14-D3AC6(14-B3AB)2(13-2C3AC)14-F3AF13-2C3AC14-B3AB13-2C3AC14-F3AF13-2C3AC5(14-B3AB)14-D3AC14-2B2AI16-3G16-2GD17-GD18-K109-5B14-D3AC4(14-B3AB)2(13-2C3AC)2(14-F3AF)13-2C3AC2(14-B3AB)13-2C3AC2(14-F3AF)13-2C3AC4(14-B3AB)14-D3AC14-2B2AI2(16-2GH)17-GD18-K90-5B14-B3AB14-D3AC2(14-B3AB)13-2C3A2C12-2C3A2C13-3(F3AF14-)F3AF13-2C3AC14-B3AB13-2C3A2C13-3(F3AF14-)F3AF13-2C3AC3(14-B3AB)14-D3AC14-2B2AI16-3G16-2GD17-GK18-K90-5B14-D3AC3(14-B3AB)13-2C3A2C13-3(F3AF14-)F3AF13-2C3AC2(14-B3AB)13-2C3A3C12-2(F3AF14-)F2AG2(F14-F3A)F13-2C3A2C13-2(B3AB14-)D3AC14-5B56-K18-K90-5B14-D3AC2(14-B3AB)13-3(2C3A2C12-)2(2C3A3C11-)2C3A4C11-B3AB14-B3AB13-2C3A4C10-2(2C3A3C11-)5(2C3A2C12-)2C3A2C13-B3AB14-D3AC14-5B166-5B14-D3AC3(14-B3AB)13-2C3A2C13-3(F3AF14-)F3AF13-2C3AC2(14-B3AB)13-2C3A3C12-4(F3AF14-)F3AF13-2C3A2C13-2(B3AB14-)D3AC14-5B56-K18-K90-5B14-D3AC3(14-B3AB)13-2C3A2C12-2C3A2C13-3(F3AF14-)F3AF13-2C3AC14-B3AB13-2C3A2C13-3(F3AF14-)F3AF13-2C3AC3(14-B3AB)14-D3AC14-2B2AI16-3G16-2GD17-GD18-K90-5B14-B3AB14-D3AC3(14-B3AB)13-2C3AB2(13-2C3AC)2(14-F3AF)13-2C3AC2(14-B3AB)13-2C3AC2(14-F3AF)13-2C3AC4(14-B3AB)14-D3AC14-2B2AI2(16-2GH)17-GD18-K109-5B14-D3AC6(14-B3AB)2(13-2C3AC)14-F3AF13-2C3AC14-B3AB13-2C3AC14-F3AF13-2C3AC4(14-B3AB)14-B3AC14-D3AC14-2BAGI16-3G16-2GD17-GK18-K109-5B14-B3AB14-D3AG7(14-B3AB)13-2C3AC14-F3AF2(14-B3AB)13-2C3AC4(14-B3AB)14-B3AC14-D3AC14-B3AB14-5B56-K18-K128-5B14-B3AB14-D3AG8(14-B3AB)13-2C3AC6(14-B3AB)14-D3AC14-B3AB14-5B242-5B14-D3AB14-B3AC13(14-B3AB)14-D3AC14-B3AB14-5B261-5B14-B2(3AB14-D)3AG11(14-B3AB)2(14-D3AC)14-5B147-8D11-7E12-2E2-E109-5B2(14-B3AB)14-D2(3AC14-B)7(3AB14-B)3AB14-D3AC14-B3AB2(14-5B)147-D3H4ED10-D3H3E12-EH2GE15-3(3G16-)2GDI15-2G2D15-DHD16-DHD15-B3HB14-B2(3AB14-D)3AG3(14-B3AB)14-B3(3AC14-D)3AC14-B3AB14-5B185-D3H4ED10-D3H3E12-EH2GE15-2GD16-DGD16-3D16-2DGI15-3GI15-2GD2(16-3D)15-2(5B14-)B3AB4(14-D3AC)2(14-B3AB)2(14-B2A2B)15-2H187-8D11-7E12-2E2-E204-4(5B14-)5B3-2I9-B4H4J2I9-2H6J2I9-HJ5-2I10-HJ5-I11-2E179-
