model
size = 18 30 27, scale = 0.05, origin = -y
material deform = 1, fade = true, lighting = smooth, roughness = 0.3, metalness = 0.6
  colors = A:#FFF B:#EEE C:#111 D:#BBB
voxels
B22(A14-A2B)A14-AB126-B2(A14-A2B)5(A14-ABC)A14-ACB6(A14-A2B)A14-ABC2(A14-ACB)A14-A2BA14-ABCA14-ACB2(A14-A2B)A14-AB126-B5(A14-A2B)A14-A2CA14-ABCA14-ACB6(A14-A2B)3(A14-ABC)2(A14-A2C)3(A14-A2B)A14-AB126-B3(A14-A2B)A14-ACB2(A14-A2C)2(A14-ACB)6(A14-A2B)A14-ABC2(A14-A2B)A14-ACBA14-ABC3(A14-A2B)A14-AB126-B5(A14-A2B)2(A14-ABC)8(A14-A2B)5(A14-ACB)2(A14-A2B)A14-AB126-B2(A14-A2B)A14-ABCA14-A2C3(A14-ABC)15(A14-A2B)A14-AB126-B3(A14-A2B)A14-ACB4(A14-A2B)5(A14-ABC)2(A14-A2B)2(A14-A2C)A14-ABCA14-A2C3(A14-A2B)A14-AB126-B3(A14-A2B)A14-ACB3(A14-A2C)A14-ACB2(A14-A2B)2(A14-ABCA14-A2B)2(A14-ABC)2(A14-A2BA14-ACB)2(A14-A2B)A14-AB3(D17-)D16-2D16-3D14-2D-16D-B2(A14-A2B)3(A14-ABC)4(A14-A2B)2(A14-ACB)A14-A2BA14-A2C2(A14-A2B)2(A14-ABC)A14-A2CA14-A2BA14-ACB2(A14-A2B)A14-AB53-D17-D54-B3(A14-A2B)A14-ACB3(A14-ABC)A14-ACB3(A14-A2B)A14-ACBA14-A2BA14-ACBA14-ABCA14-A2C4(A14-ACB)2(A14-A2B)A14-AB35-D17-D72-B3(A14-A2B)3(A14-ACBA14-A2B)2(A14-ABC)A14-A2CA14-A2BA14-ACBA14-A2B4(A14-ABC)3(A14-A2B)A14-AB2(17-D)90-B2(A14-A2B)A14-ABCA14-ACB3(A14-A2C)A14-ACBA14-ABC3(A14-ACB)A14-A2CA14-ACB2(A14-A2B)3(A14-ACB)3(A14-A2B)A14-AB17-D108-B2(A14-A2B)4(A14-ABCA14-A2B)2(A14-A2B)A14-ABC2(A14-A2B)A14-A2C2(A14-ABC)A14-A2BA14-ACB2(A14-A2B)A14-AB126-B2(A14-A2B)A14-ABC2(A14-A2C)A14-ACBA14-ABCA14-ACBA14-A2BA14-ABC2(A14-A2C)A14-ACBA14-A2B2(A14-ABCA14-ACB2(A14-A2B))A14-AB126-B3(A14-A2B)4(A14-ACBA14-A2B)2(A14-A2B)A14-ACBA14-ABCA14-A2B2(A14-ACB)A14-A2C3(A14-A2B)A14-AB126-B2(A14-A2B)2(A14-ABCA14-A2C)A14-A2CA14-ACBA14-ABCA14-A2C3(A14-ABC)A14-ACBA14-A2B3(A14-ABC)4(A14-A2B)A14-AB126-B2(A14-A2B)3(A14-ABCA14-A2B)2(A14-A2B)A14-A2CA14-ACBA14-A2C3(A14-A2B)4(A14-ACB)2(A14-A2B)A14-AB17-D108-B2(A14-A2B)A14-ABC2(A14-A2B)A14-ACBA14-A2CA14-ACB2(A14-A2B)2(A14-ABCA14-A2B)A14-ABC2(A14-A2C)2(A14-ABC)3(A14-A2B)A14-AB2(17-D)90-B3(A14-A2B)3(A14-ACB)2(A14-A2B)2(A14-ABC)A14-A2BA14-ABCA14-A2BA14-ACB2(A14-A2B)A14-A2CA14-ACBA14-A2C3(A14-A2B)A14-AB35-D17-D72-B2(A14-A2B)3(A14-ABC)2(A14-A2C)A14-ACB3(A14-A2B)2(A14-ACBA14-A2B)A14-ACBA14-A2CA14-A2BA14-ABC3(A14-A2B)A14-AB53-D17-D54-B2(A14-A2B)A14-ABC6(A14-A2B)5(A14-ACB)2(A14-ABC)A14-ACBA14-A2C2(A14-ACB)2(A14-A2B)A14-AB3(D17-)D16-2D16-3D14-2D-16D-B2(A14-A2B)A14-ABC5(A14-ACB)14(A14-A2B)A14-AB126-B6(A14-A2B)2(A14-ACB)6(A14-A2B)5(A14-ABC)3(A14-A2B)A14-AB126-B2(A14-A2B)3(A14-ABC)2(A14-A2C)8(A14-A2B)A14-ACBA14-ABC2(A14-A2B)A14-ACB2(A14-A2B)A14-AB126-B4(A14-A2B)A14-ABCA14-A2BA14-A2CA14-ACB7(A14-A2B)A14-ACB2(A14-A2C)2(A14-ACB)2(A14-A2B)A14-AB126-B3(A14-A2B)3(A14-ACB)A14-A2CA14-ACB6(A14-A2B)A14-ABCA14-A2C2(A14-A2B)A14-ABCA14-ACB2(A14-A2B)A14-AB126-B22(A14-A2B)A14-AB126-
