model
size = 30, scale = 0.05, origin = -y
material deform = 1, fade = true, lighting = smooth, roughness = 0.3, metalness = 0.6
  colors = A:#FFF B:#B00 C:#111 D:#A00 E:#800 F:#D00 G:#EE4242 H:#EF868A
voxels
-1830A27(10-20A)10-80A10-26(19A11-)2(20A10-80A10-13(19A11-)10(19A6-2C3-)3(19A11-))2(20A10-80A10-11(19A11-)2(19A6-2C3-)8(19A6-2E3-)2(19A6-2D3-)2(19A6-2C3-)19A11-)2(20A10-80A10(10-20A)2(5-2C3-20A)2(5-2E3-20A)8(5-2D3-20A)2(5-2B3-20A)2(5-2C3-20A)10-)3(20A10-80A10-6(19A11-)3(19A6-2C3-)2(19A6-2E3-)2(19A6-2D3-)8(19A6-2B3-)2(19A6-2F3-)2(19A6-2C3-)19A11-)2(20A10-80A10-4(19A11-)2(19A6-2C3-)3(19A6-2E3-)2(19A6-2D3-)7(19A6-2B3-)3(19A6-2F3-)2(19A6-2C3-)3(19A11-))20A2(10-80A3(10-20A)2(5-2C3-20A)2(5-2E3-20A)3(5-2D3-20A)9(5-2B3-20A)3(5-2C3-20A)5(10-20A))10-80A10-2(19A11-)2(19A6-2C3-)2(19A6-2E3-)3(19A6-2D3-)9(19A6-2B3-)3(19A6-2C3-)5(19A11-)2(20A10-80A10-4(19A11-)2(19A6-2C3-)15(19A6-2B3-)2(19A6-2C3-)3(19A11-))2(20A10-80A10-6(19A11-)3(19A6-2C3-)12(19A6-2B3-)2(19A6-2F3-)2(19A6-2C3-)19A11-)2(20A10-80A10(10-20A)2(5-2C3-20A)7(5-2B3-20A)3(5-2F3-20A)2(5-2G3-20A)2(5-2C3-20A)10-)20A10-80A10-9(19A11-)2(19A6-2C3-)7(19A6-2B3-)3(19A6-2F3-)2(19A6-2G3-)2(2(19A6-2C3-)19A11-20A10-80A10-11(19A11-)2(19A6-2C3-)3(19A6-2B3-)2(19A6-2F3-)3(19A6-2G3-)2(19A6-2H3-))2(19A6-2C3-)19A11-2(20A10-80A10-13(19A11-)10(19A6-2C3-)3(19A11-))20A10-80A27(10-20A)10-49A
