model
size = 27 29 16, scale = 0.05, origin = -y
material deform = 1, fade = true, lighting = smooth, roughness = 0.3, metalness = 0.6
  colors = A:#F9F9F9 B:#90C3E3 C:#C2EBFF D:#A1CDE8
voxels
291-B668-B755-B25-3B25-B26-B674-B25-3B23-5B23-3B24-3B25-B26-B647-B25-3B25-B26-B728-B854-B755-B25-3B25-B26-B186-19C7-21A5-C18AC2AC4-9AC8AC-3A3-C8AC-8A2-4A3-8A2-7AC-4A5-6A2-8A4-C7-4A3-7A14-AC5-5A23-2AC233-B25-3B23-5B23-3B24-3B25-B26-B105-19B7-21C5-C21AC3-BC18AC2ACB2-C9AC8ACB3AC-BC2(8ACB)4AB-C8ACB7ACB4AC3-D6ACB8AC-BD2C5-D4AC-D7AC4-B7-DA2C3-D5AC14-2B5-D2A2C23-3B233-B25-3B25-B26-B158-21B5-B21CB3-BC21ACB2-BC18AC2ACB-BC9AC8ACB3AC2BC2(8ACB)4A2BC8ACB7ACB4ACB-BD6ACB8ACDBD2CB3-BD4ACBD7ACB2-D2B5-BDA2CB-BD5ACB12-D3B3-BD2A2CB21-D4B75-B183-B213-19B7-21C5-C21AC3-BC18AC2ACB2-C9AC8ACB3AC-BC8ACB8AC5AB-C8ACB7ACB4AC3-D6ACB8AC2-D2C5-D4AC-D7AC4-B7-DA2C3-D5AC14-2B5-D2A2C23-3B49-B25-3B25-B26-B370-19C7-21A5-C18AC2AC4-9AC8AC-3A3-C8AC-8A-5A3-8A2-7AC2-3A5-6A2-8A4-C7-4A3-7A14-AC5-5A23-2AC49-B25-3B23-5B23-3B24-3B25-B26-B90-B556-B25-3B25-B26-B117-B25-3B25-B26-B529-B144-B25-3B23-5B23-3B24-3B25-B26-B647-B25-3B25-B26-B464-
