model
size = 7 7 32, scale = 0.05, origin = -y
material deform = 1, fade = true, lighting = smooth, roughness = 0.3, metalness = 0.6
  colors = A:#EEE B:#222 C:#A00 D:#BBB E:#777
voxels
16-B-B3-2(B-)2(B3-B-)B-B3-B-B11-3D3-2(5D2-)5D3-3D11-4(3A3-5A-21A-5A3-3A4-)3A3-5A-14AC5AC-5A3-3A4-3A3-5A-7AC5A2C5AC-5A3-3A4-3A3-5A-7AC6AC5AC-5A3-3A4-3A3-5A-6AE2(C6A)-5A3-3A4-3A3-5A-E5AEC5A2C6A3(-5A3-3A4-3A3-5A-E5AEC5A2C5AC)-5A3-3A4-3A3-5A-E5AEC5AC6AC-5A3-3A4-3A3-5A-E12AC6AC-5A3-3A4-3A3-5A-13A2C5AC-5A3-3A4-3A3-5A-7AC5A2C5AC-5A3-3A4-3A3-5A-14AC5AC6(-5A3-3A4-3A3-5A-21A)-5A3-3A2(4-3B3-5B-21B-5B3-3B)4-B-B3-5B-7B-13B-3(5B3-B-B4-B-B3-2(5B-7B-))5B3-B-B10-4(5B2-)5B8-
