model
size = 19 8 11, scale = 0.05, origin = -y
material deform = 1, fade = true, lighting = smooth, roughness = 0.3, metalness = 0.6
  colors = A:#222 B:#2D2D2D C:#EEE D:#E84331
voxels
-17B-76A-17A39-3(19B95A38-)19B95A9-C28-19B95A8-CDC17-D9-19B95A9-C28-2(19B95A38-)19B95A39-17B-76A-17A39-
