model
size = 31 32 31, scale = 0.05, origin = -y
material deform = 1, fade = true, lighting = smooth, roughness = 0.3, metalness = 0.6
  colors = A:#86C166 B:#DDD
voxels
756-7A982-3A7B3A21-7A949-2A3B3-B3-3B2A16-13A945-2A2(B6-)B2A14-15A943-A2B15-2BA11-6A3-B3-6A18-7A915-AB19-BA9-5A5-B5-5A15-11A912-AB-B17-B-BA7-4A15-4A12-4A3-B3-4A20-7A882-2AB21-B2A6-3AB15-B3A11-3A5-B5-3A17-11A880-AB23-BA5-3A2-B13-B2-3A9-3A13-3A15-4A2-B2-4A22-5A851-AB25-BA3-4A19-4A8-2A-B11-B-2A14-3A4-B4-3A19-9A849-AB25-BA3-3A21-3A7-2A17-2A12-3A2(B4-)B3A17-11A23-5A820-AB25-BA3-3A21-3A7-2A17-2A12-2A2-2(B3-)B2-2A16-13A21-7A818-AB27-BA-3A23-3A5-2A19-2A10-3A3-2(B2-)B3-3A15-13A20-9A25-3A789-AB27-BA-3A23-3A5-2A19-2A10-2A5-B3-B5-2A14-6A-B-6A18-11A23-5A788-AB27-BA-3A23-3A5-2A19-2A10-2A15-2A14-5A-3B-5A18-11A22-7A151-20(B30-)B15-A3B11-B11-3BA-3A2B9-B9-2B3A5-2A2B7-B7-2B2A10-2A5B2-B2-5B2A14-5A5B5A18-11A22-7A27-B61-B30-B666-AB27-BA-3A23-3A5-2A19-2A10-2A15-2A14-5A-3B-5A18-11A22-7A58-B728-AB27-BA-3A23-3A5-2A19-2A10-2A5-B3-B5-2A14-6A-B-6A18-11A23-5A59-B728-AB27-BA-3A23-3A5-2A19-2A10-3A3-2(B2-)B3-3A15-13A20-9A25-3A60-B729-AB25-BA3-3A21-4A6-2A17-2A12-2A2-2(B3-)B2-2A16-13A21-7A120-B698-AB25-BA3-3A21-4A6-2A17-2A12-3A2(B4-)B3A17-11A23-5A820-AB25-BA3-4A19-5A7-2A-B11-B-2A14-3A4-B4-3A19-9A850-AB23-BA5-3A2-B13-B2-3A9-3A13-3A15-4A2-B2-4A22-5A852-2AB21-B2A6-3AB15-B3A11-3A5-B5-3A17-11A881-AB-B17-B-BA7-4A15-4A12-4A3-B3-4A20-7A884-AB19-BA9-5A5-B5-5A15-11A914-A2B15-2BA11-6A3-B3-6A18-7A917-2A2(B6-)B2A14-15A945-2A3B3-B3-3B2A16-13A948-3A7B3A21-7A954-7A229-
