model
size = 25 30 19, scale = 0.05, origin = -y
material deform = 1, fade = true, lighting = smooth, roughness = 0.3, metalness = 0.6
  colors = A:#E00 B:#FF0 C:#EEE D:#CF3 E:#000 F:#00C G:#251505 H:#BBB I:#CF0 J:#CC6 K:#939 L:#960 M:#AAAAB9 N:#1C0900 O:#AAA P:#00F Q:#888 R:#FCF
voxels
6-7C9(18-C5AC)5(18-7A)9(18-C5AC)18-7C141-11C2(14-2C7B2C)14-2CB3-B-4(B2C14-2CB5-)B2(2C14-2CA5-A)2C5(14-3A5-3A)14-2CA5-B2C14-2CA5-M2C14-2CE5-E4(2C14-2CM5-M)2C14-2CM5DM2C14-2C3G2N2G2C14-2C7-2C138-13C2(12-C11BC)12-CB4-3B2-BC12-CB4-2B3-3(BC12-CB9-)B2(C12-CA9-A)C4(12-2A9-2A)12-2A6-5A12-CA6-2B2AC12-CA7-D2AC12-CE7-3EC12-CF7-D3(2EC12-CF8-)2EC12-CM7DB2EC12-C3GNL2NL2GNC12-C11-C136-15C2(10-C13BC)10-C9B2-2BC10-C8B4-3(BC10-C7B5-)B2(C10-C7A5-A)C4(10-2A2-A3B5-2A)10-2A2-A4B6A10-CA2-A3B-B-3AC10-CA2-A3D2-D3AC10-CE2(2-4E)C10-CF2-4D2-D3(3EC10-CF2-4D2-I)3EC10-CM8DI3EC10-C5GL2G2NG2NC10-C6-J6-C134-17C2(8-C7B-7BC)8-C13B-BC8-C10B4-3(BC8-C8B6-)B2(C8-C8A6-A)4(C8-C5A3B6-A)C8-C5A4B-5AC8-C5A4B2-4AC8-C5A4D-D4AC8-C9E-5EC8-C4F7D3(4EC8-C4F6DI)4EC8-CM9DI4EC8-CG3NL4GLGNG2NC8-C6-J-J6-C42-O90-17C2(8-C15BC)5(8-C12B3-C)2(8-C12A3-C)2(8-C5A5B2A3-C)8-C5A4B3A3-C8-C5A4B3A2-AC8-C5A3B-A-2A-AC8-C5A4B2-4AC8-C5A4D-D4AC8-C9E-4E-C8-C4F7D3(4EC8-C4F6DI)4EC8-C10DI4EC8-C2G2L4G2LGN2GNC8-C5-2(J-)J5-C42-QH19-H4-H63-19C2(6-C17BC)5(6-C13B3-BC)2(6-C13A3-AC)2(6-C6A3D2B2A3-AC)2(6-C13A3-AC)6-C9A-5A-AC6-C6A3DB2-5AC6-C6A3DB-B5AC6-C10E-6EC6-C5F4C3D3(5EC6-C5F4C2DI)5EC6-CM10DI5EC6-CG2NLGL3GLGLNL2GNC6-C5-3(J-)J5-C16-Q24-H20-QOQ3-H62-19C5(6-C17BC)6-2(C-16B7A)2(C-2A2BA3D4B5A5-A)2(C-5A3D2B7A5-A)2(C-15A-A5-A)C-8A-A-4A-A5-AC-5A3DB3-3A-A5-AC-5A3D2(B-)3A-A5-AC-9E-E-3E-7AC-3FD4C3D4E-7A2(C-3FD4C2DI4E-C6-)C-3FD4C2DI5EC6-C-10DI5EC6-CGNGL3GL8GNC6-C4-4(J-)J4-C15-3O21-2O-2H19-2OH2-OH18-O5-O36-19C5(6-C6B8A4C)6-C-5BIAD4A4I7AC-5BI2D4A4I7A2(C-2A2BA3D4B5A5-A)2(C-5A3D2B7A5-A)2(C-15A-A5-A)C-8A-6A-A5-AC-5A3DB3-3B-A5-AC-5A3D2(B-)3B-A5-AC-5E4D-D-3D-7AC-3FD4C7D-7A2(C-3FD4C2DI4D-C6-)C-3FD4C2DI5DC6-C-10D2ID4C6-C2G2L2GL3GL5GNC6-C3-5(J-)J3-C15-3H68-H44-19C5(6-C6B8A4C)6-C-5BIAD4A4I7AC-5BI2D4A4I7A2(C-2A2BA3D4B5A5-A)2(C-5A3D2B7A5-A)3(C-15A-A5-A)2(C-5A3D7B-A5-A)C-5E3D4C3D-7AC-3FD4C7D-7A2(C-3FD4C2DI4D-C6-)C-3FD4C2DI5DC6-C-10D2ID4C6-CGL6G2L4GL2NC6-C2-6(J-)J2-C15-2HO21-2H-2H19-2H2-3H16-Q-H4-2H18-H17-19C5(6-C6B8A4C)6-C-5BI4DIA4IB6AC-17B6A2(C-2A2BA7B5A5-A)C-4A2-2A2B2(7A5-AC-4A6-)A-3A2(-A5-AC-15A)2(-A5-AC-5A3D7B)-A5-AC-5E3D3C3KD-7AC-3F8D3KD-M6A2(C-3F8D3KD-C6-)C-3F8D3K2DC6-C-11D2K4C6-C6GL9GNC6-C3-5(J-)J3-C40-3H21-OH-2H16-3ORO3-2H14-2O-2H5-H11-19C5(6-C6B8A4C)6-C-5BI4DIAI3C7AC-16B7A2(C-2A2BA7B5A5-A)C-4A2-2A2B2(7A5-AC-4A6-)A2-2A2(-A5-AC-15A)-A5-AC-4A4D7B-A5-AC-3A5D7B-A5-AC-5E3D3C2(3KD-7AC-3F8D)2(3KD-C6-C-3F8D)3K2DC6-C-11D2K4C6-C8GL3GLGLNGC6-C4-4(J-)J4-C40-3H42-O2H43-19C7(6-C16B2C)2(6-C3A10B4AC)6-C9A2B6A4(C6-C17A)C6-C5A4D8BC6-C4A5D8BC6-C6E2D8AE4(C6-C4F8D3KDM)C6-CM11D2K4C6-C5G2L5GLN2GNC6-C5-3(J-)J5-C40-3H21-OH-2H16-5O3-2H14-2O-2O5-H12-17C8-C12B3PC8-C12BP3C8-C12B3P3(C8-C15B)C8-C13B3C2(8-C2A10B4C)8-C8A2B5A4(C8-C15A)C8-C4A4D2B5AC8-C3A5D2B5AC8-C5E2D8A4(C8-2C2F12D)C8-C13D3C8-CLG2LGL3GL2G2LGC8-C5-2(J-)J5-C110-Q2-HO18-17C7(8-C11B2C-2C)2(8-C2A9B2C-2C)8-CA-6A2B3A4(-AC8-CA-11A)-AC8-C4A4D2B3A-AC8-CA-A5D2B3A-AC8-CE-11E-E3(C8-2C-F10D-M)C8-2C2F10D-MC8-CMB11D-2C8-C2G2(LG)L2GLNL3GC8-C6-J-J6-C85-H24-O3-H19-15C7(10-C10B4C)10-CA9B4C10-CA2B8-3C10-5A5B5A10-3AB11A10-15A2(10-8A-6A)10-C2A5B-B4AC10-C2A5D-B4AC10-C7E-5E4(C10-C2F5D-4DM)C10-CM6D-4D2C10-C4GLGL2G2N2GC10-C6-J6-C86-H28-H20-13C12-C2B8-2C6(12-C9B3C)2(12-C9A3C)12-4A5B4A4(12-13A)12-CA7B3AC12-CA5D2B3AC12-C11E4(C12-CF8D2A)C12-CM9DMC12-C6GLN3GC12-C11-C115-2H21-11C6(14-2CB3-3B2C)14-2CB2-4B2(2C14-2CA2-4A)2C14-3A2-6A14-3A-7A3(14-11A)2(14-2C7A2C)14-2C7E5(2C14-2CM5DM)2C14-2C7G2C14-2C7-2C91-2(H24-)7C9(18-C5AC)5(18-7A)9(18-C5AC)18-7C93-O43-
