model
size = 25 30 19, scale = 0.05, origin = -y
material deform = 1, fade = true, lighting = smooth, roughness = 0.3, metalness = 0.6
  colors = A:#E00 B:#EEE C:#00C D:#CF3 E:#FF0 F:#251505 G:#CF0 H:#AAAAB9 I:#BBB J:#CC6 K:#939 L:#960 M:#1C0900 N:#AAA O:#040 P:#888 Q:#FCF
voxels
6-24(7B18-)7B141-11B2(14-2B7A2B)14-2BA3-A-A2B14-2B4(A5-3A14-2C)8(E5-E2A14-2C)H5-H2A14-2CA5-3A4(14-2CH5-H2A)14-2BH5DH2B14-2B3F2M2F2B14-2B7-2B138-13B2(12-B11AB)12-BA4-3A2-AB12-BA4-2A3-4(2A12-2C9-)5(EA12-2C9-)E2(A12-2C6-4E)A12-2C7-2DHA12-2C7-4A12-2C7-2D3(HA12-2C8-D)HA12-BH7DED2B12-B3FML2ML2FMB12-B11-B136-15B2(10-2B11A2B)10-2B8A2-A2B10-2B7A4-3(2A10-4C4A5-)2A2(10-4C4E5-EA)4(10-2C2-4E5-EA)10-2C2-10EA10-2C2-4E-E-3EA10-2C2-4D2-3DHA10-2C2-4A2-5A10-2C2-4D2-3D3(HA10-2C2-4D2-G2D)HA10-BH8DGD3B10-B5FL2F2MF2MB10-B6-J6-B134-17B2(8-3B5A-5A3B)8-3B11A-2B8-3B8A4-3(2A8-5C4A6-)2A6(8-5C4E6-EA)8-5C5E-5EA8-5C5E2-4EA8-5C5D-4DHA8-5C5A-6A8-5C10D3(HA8-5C6DG3D)HA8-BH9DGD4B8-BF3ML4FLFMF2MB8-B6-J-J6-B42-N90-17B2(8-3B11A3B)8-3B10A3-B8-3B10A3(3-A8-5C8A)6(3-A8-5C8E)2-EA8-5C4E-E-2E-EA8-5C5E2-4EA8-5C5D-5DA8-5C5A-4A-A8-5C10D3(EA8-5C6DG3D)EA8-B10DGD4B8-B2F2L4F2LFM2FMB8-B5-2(J-)J5-B42-PI19-I4-I63-19B2(6-4B11A4B)6-4B10A3-2B6-4B10A3-BA6-6C8A3-BA6-6C2GAD4A3-2A6-6C2G2D4A3-2A6(6-6CA3D4E3-EA)6-6CA3D-5E-EA6-6CA3DE2-5EA6-6C4DE-6EA6-6C5A-7A6-6C4B7D3(HA6-6C4B2DG4D)HA6-BH10DG2D4B6-BF2MLFL3FLFLML2FMB6-B5-3(J-)J5-B16-P24-I20-PNP3-I62-19B3(6-4B11A4B)6-4B11A3BA6-5C10A3BA6-C-3C3GAD9A6-C-3C3G2D4A3G2A4(6-C-3C2A3D8EA)2(6-C-3C2A3D7E-A)6-C-3C2A3D-E-4E-A6-C-3C2A3DE3-3E-A6-C-3C5D2(E-)3E-A6-C-3C6A-A-3A-A6-C-3CD4B7D2(-A6-C-3CD4B2DG4D)-A6-C-3CD4B2DG5DA6-B-10D2GD4B6-BFMFL3FL8FMB6-B4-4(J-)J4-B15-3N21-2N-2I19-2NI2-NI18-N5-N36-19B3(6-4B11A4B)6-4B11A3BA6-5C10A3BA6-C-3C3GAD4A4GA6BC-3C3G2D4A4GA6B4(C-3C2A3D8EA5-B)2(C-3C2A3D7E-A5-B)C-3C2A3D-6E-A5-BC-3C2A3DE3-3E-A5-BC-3C5D2(E-)3E-A5-BC-3CA5D-D-3D-H6BC-3CD4B7D-H6B2(C-3CD4B2DG4D-A6-)C-3CD4B2DG5DA6-B-10D2GD4B6-B2F2L2FL3FL5FMB6-B3-5(J-)J3-B15-3I68-I44-19B3(6-4B11A4B)6-4B11A3BA6-5C10A3BA6-C-3C3GAD4A4GA6BC-3C3G2D4A4GA6B4(C-3C2A3D8EA5-B)4(C-3C2A3D7E-A5-B)C-3C5D7E-A5-BC-3CA4D4B3D-H6BC-3CD4B7D-H6B2(C-3CD4B2DG4D-A6-)C-3CD4B2DG5DA6-B-10D2GD4B6-BFL6F2L4FL2MB6-B2-6(J-)J2-B15-2IN21-2I-2I19-2I2-3I16-P-I4-2I18-I17-19B3(6-4B11A4B)6-4B11A3BA6-5C10A3BA6-2(C-3CGAG4DGA4GA6B)2(C-3C5A8EA5-B)C-3CA2-2A8EA5-BC-3CA6-6EA5-BC-3CA6-E-3E3(-A5-BC-3CA4D7E)-A5-BC-3C5D7E-A5-BC-3CA4D3B2(3KD-H6BC-3C8D)2(3KD-A6-C-3C8D)3K2DA6-B-11D2K4B6-B6FL9FMB6-B3-5(J-)J3-B40-3I21-NI-2I16-3NQN3-2I14-2N-2I5-I11-19B3(6-4B11A4B)6-4B11A3BA6-5C10A3BA6-C-3CGAG4DGAG10BC-3CGAG4DGA5G6B2(C-3C5A8EA5-B)C-3CA2-2A8EA5-BC-3CA6-6EA5-BC-3CA6-E2-2E3(-A5-BC-3CA4D7E)-A5-BC-3C5D7E-A5-BC-3CA4D3B2(3KD-H6BC-3C8D)2(3KD-A6-C-3C8D)3K2DA6-B-11D2K4B6-B8FL3FLFLMFB6-B4-4(J-)J4-B40-3I42-N2I43-19B3(6-4B2D9A4B)6-4B2D3(9A3BA6-5CD)13A5(6-5C5A8EA)3(6-5CA4D8EA)6-5C5D8EA6-5CA3D10A4(6-5C8D3KDHA)6-BH11D2K4B6-B5F2L5FLM2FMB6-B5-3(J-)J5-B40-3I21-NI-2I16-5N3-2I14-2N-2N5-I12-17B3(8-3B2D9A3B)8-3B2D3(12A8-4CD)12A3(8-4C5A7EA)2(8-4C3A2O7EA)3(8-4CA4D7EA)8-4C5D7EA8-4CA3D9A4(8-4C12DA)8-B13D3B8-BLF2LFL3FL2F2LFB8-B5-2(J-)J5-B110-P2-IN18-17B3(8-3B11A-2B)8-3B11A3(-2A8-4C10A)-2A2(8-4C5A5E-EA)8-2C-C5A5E-EA8-2C-CA4O5E-EA8-2C-CA2(DO)2(5E-EA8-2C-CA4D)5E-EA8-4CA4D5E-EA8-2C-C5D5E-EA8-2C-C10A-2A3(8-2C-C10D-HA)8-4C10D-HA8-BHE11D-2B8-B2F2(LF)L2FLML3FB8-B6-J-J6-B85-I24-N3-I19-15B3(10-2B11A2B)10-2B13A10-3C12A10-3C9B3A10-3C12A10-3C11EA10-3CE8-2E3(A10-3C11E)3(A10-3C5E-5E)A10-3C5D-5EA10-3C5A-6A4(10-3C5D-4DHA)10-BH6D-4D2B10-B4FLFL2F2M2FB10-B6-J6-B86-I28-I20-13B12-B2A8-A2(B12-B11A)B12-B12A12-2C11A12-2C9B2A12-2C11A8(12-2C8E3A)12-2C5D3E3A12-2C11A4(12-2C8D3A)12-BH9DHB12-B6FLM3FB12-B11-B115-2I21-11B3(14-2BA3-3A2B)14-2B3(A3-5A14-2C)A2-6A3(14-2CE2-4E2A)14-2CE-5E4(2A14-2C7E)2A14-2CH3D3E2A14-2C9A4(14-2CH5DH2A)14-2BH5DH2B14-2B7F2B14-2B7-2B91-2(I24-)24(7B18-)7B93-N43-
