model
size = 25 30 19, scale = 0.05, origin = -y
material deform = 1, fade = true, lighting = smooth, roughness = 0.3, metalness = 0.6
  colors = A:#FF0 B:#E00 C:#CF3 D:#000 E:#EEE F:#00C G:#251505 H:#BBB I:#CF0 J:#CC6 K:#AAAAB9 L:#939 M:#960 N:#1C0900 O:#AAA P:#040 Q:#888 R:#FCF
voxels
6-8(7A18-)9(7B18-)7(7D18-)7D141-3(11A14-)3A3-A-4(3A14-3A5-)3A2(14-3B5-3B)6(14-3B5-A2B)14-3B5-K2B14-3D5-3D4(14-2DK5-K2D)14-2DK5CK2D14-2D3G2N2G2D14-2D7-2D138-3(13A12-)2A4-3A2-2A12-2A4-2A3-3(2A12-2A9-)2A6(12-2B9-2B)2(12-2B6-2A3B)12-2B7-C3B12-2D7-4D12-DF7-C3(3D12-DF8-)3D12-DK7CA3D12-D3GNM2NM2GND12-D11-D136-3(15A10-)10A2-3A10-9A4-3(2A10-8A5-)2A2(10-8B5-2B)4(10-2B2-B3A5-2B)10-2B2-B6A4B10-2B2-B3A-A-4B10-2B2-B3C2-C4B10-2D2-4D2-5D10-DF2-4C2-C3(4D10-DF2-4C2-I)4D10-DK8CI4D10-D5GM2G2NG2ND10-D6-J6-D134-17A2(8-8A-8A)8-14A-2A8-11A4-3(2A8-9A6-)2A2(8-9B6-2B)4(8-6B3A6-2B)8-6B4A-A5B8-6B4A2-5B8-6B4C-C5B8-10D-6D8-D4F7C3(5D8-D4F6CI)5D8-DK9CI5D8-DG3NM4GMGNG2ND8-D6-J-J6-D42-O90-3(17A8-)5(13A3-A8-)2(13B3-B8-)3(6B6AB3-B8-)6B6AB2-2B8-6B3A-A2(-2B)8-6B4A2-5B8-6B4C-C5B8-10D-4D-D8-D4F7C3(5D8-D4F6CI)5D8-D10CI5D8-D2G2M4G2MGN2GND8-D5-2(J-)J5-D42-QH19-H4-H63-3(19A6-)5(14A3-2A6-)2(14B3-2B6-)4(7B3C3AB3-2B6-)7B3C-2A3B-2B6-7B3CA2-6B6-7B3CA-A6B6-11D-7D6-D5F4E3C3(6D6-D5F4E2CI)6D6-DK10CI6D6-DG2NMGM3GMGMNM2GND6-D5-3(J-)J5-D16-Q24-H20-QOQ3-H62-6(19A6-)2(A-17A6-)2(B-2B2AB3C4A5B6-)2(B-5B3C3A6B6-)2(B-5B3C3A4B-B6-)B-5B3C-A-4B-B6-B-5B3CA3-3B-B6-B-5B3C2(A-)3B-B6-D-9D-D-3D-D6-D-3FC4E3C3(4D-D6-D-3FC4E2CI)6D6-D-10CI6D6-DGNGM3GM8GND6-D4-4(J-)J4-D15-3O21-2O-2H19-2OH2-OH18-O5-O36-19A5(6-7A8B3EA)6-A-5AIBC4B4I8A-5AI2C4B4I7AB2(-2B2AB3C4A5B5-2B)2(-5B3C8AB5-2B)2(-5B3C7A-B5-2B)-5B3C-6A-B5-2B-5B3CA3-3A-B5-2B-5B3C2(A-)3A-B5-BD-5D4C-C-3C-K7D-3FC4E7C-K7D2(-3FC4E2CI4C-D6-D)-3FC4E2CI5CD6-D-10C2IC3ED6-D2G2M2GM3GM5GND6-D3-5(J-)J3-D15-3H68-H44-19A5(6-7A8B3EA)6-A-5AIBC4B4I8A-5AI2C4B4I7AB2(-2B2AB3C4A5B5-2B)2(-5B3C8AB5-2B)4(-5B3C7A-B5-2B)-5B3C7A-B5-BD-5D3C4E3C-K7D-3FC4E7C-K7D2(-3FC4E2CI4C-D6-D)-3FC4E2CI5CD6-D-10C2IC3ED6-DGM6G2M4GM2ND6-D2-6(J-)J2-D15-2HO21-2H-2H19-2H2-3H16-Q-H4-2H18-H17-19A5(6-7A8B3EA)6-A-5AI4CIB4I8A-23AB2(-2B2AB7A5B5-2B)-4B2-2B8AB5-2B-4B6-6AB5-2B-4B6-A-3A4(-B5-2B-5B3C7A)-B5-BD-5D3C3E2(3LC-K7D-3F8C)2(3LC-D6-D-3F8C)3L2CD6-D-11C2L3ED6-D6GM9GND6-D3-5(J-)J3-D40-3H21-OH-2H16-3ORO3-2H14-2O-2H5-H11-19A5(6-7A8B3EA)6-A-5AI4CIBI3E8A-23AB2(-2B2AB7A5B5-2B)-4B2-2B8AB5-2B-4B6-6AB5-2B-4B6-A2-2A3(-B5-2B-4B4C7A)-B5-2B-3B5C7A-B5-BD-5D3C3E3LC-8D-3F8C3LC-K7D2(-3F8C3LC-D6-D)-3F8C3L2CD6-D-11C2L3ED6-D8GM3GMGMNGD6-D4-4(J-)J4-D40-3H42-O2H43-8(19A6-)2(4B10A5B6-)3(10B8AB6-)3(6B4C8AB6-)5B5C8AB6-7D2C8B2D4(6-D4F8C3LCKD)6-DK11C2L3ED6-D5G2M5GMN2GND6-D5-3(J-)J5-D40-3H21-OH-2H16-5O3-2H14-2O-2O5-H12-8(17A8-)2(3B10A4B8-)9B2(2A6B8-7B2P)3(2A6B8-5B4C)2A6B8-4B5C2A6B8-6D2C8B4(D8-DE2F12C)D8-D13C2ED8-DMG2MGM3GM2G2MGD8-D5-2(J-)J5-D110-Q2-HO18-17A7(8-14A-2A)2(8-3B10AB-2B)8-2B-6B2A3B-2B8-2B-2B4P2A3B-2B8-2B-2B2(CP)2(2A3B-2B8-2B-2B4C)2A3B-2B8-5B4C2A3B-2B8-2B-B5C2A3B-2B8-2D-11D-2D3(8-DE-F10C-KD)8-DE2F10C-KD8-DKA11C-ED8-D2G2(MG)M2GMNM3GD8-D6-J-J6-D85-H24-O3-H19-8(15A10-)2B10A3B10-2B2A8-3B3(10-3B7A5B)3(10-3B5A-A5B)10-3B5C-A5B10-8D-6D4(10-D2F5C-4CKD)10-DK6C-4CED10-D4GMGM2G2N2GD10-D6-J6-D86-H28-H20-13A12-3A8-2A6(12-13A)2(12-10BA2B)6(12-2B7A4B)12-2B5C2A4B12-13D4(12-DF8C2BD)12-DK9CKD12-D6GMN3GD12-D11-D115-2H21-11A6(14-3A3-5A)14-3A2-6A3(14-3B2-6B)14-3B-7B5(14-11B)14-11D5(14-2DK5CK2D)14-2D7G2D14-2D7-2D91-2(H24-)8(7A18-)9(7B18-)7(7D18-)7D93-O43-
