model
size = 25 30 19, scale = 0.05, origin = -y
material deform = 1, fade = true, lighting = smooth, roughness = 0.3, metalness = 0.6
  colors = A:#E00 B:#FF0 C:#CF3 D:#251505 E:#CF0 F:#AAAAB9 G:#EEE H:#BBB I:#960 J:#939 K:#CC6 L:#AAA M:#040 N:#888 O:#FCF
voxels
6-8(7A18-)9(7B18-)7(7A18-)7A141-3(11A14-)3A3-A-4(3A14-3A5-)3A8(14-3B5-3B)14-2BF5-F2B14-3A5-3A4(14-2AF5-F2A)14-2AF5CF2A14-2A7D2A14-2A7-2A138-3(13A12-)2A4-3A2-2A12-2A4-2A3-3(2A12-2A9-)2A6(12-2B9-2B)2(12-2B6-5B)12-2B7-2CFB12-2A7-4A12-AF7-2C3(FA12-AF8-C)FA12-AF7CBCFA12-A4DI2DI3DA12-A11-A136-3(15A10-)10A2-3A10-9A4-3(2A10-8A5-)2A2(10-8B5-2B)4(10-2B2-4B5-2B)10-2B2-11B10-2B2-4B-B-4B10-BF2-4C2-3CFB10-2A2-4A2-5A10-AF2-4C2-3C3(FA10-AF2-4C2-E2C)FA10-AF8CE2CFA10-A5DI7DA10-A6-K6-A134-17A2(8-8A-8A)8-14A-2A8-11A4-3(2A8-9A6-)2A6(8-9B6-2B)8-10B-6B8-10B2-5B8-BF8C-4CFB8-10A-6A8-AF13C4(FA8-AF9CE3C)FA8-A2(4DI)DI3DA8-A6-K-K6-A42-L90-3(17A8-)5(13A3-A8-)5(13B3-B8-)13B2-2B8-9B-B2(-2B)8-10B2-5B8-B9C-5CB8-10A-4A-A8-A14C4(BA8-A10CE3C)BA8-A2D2I4D2I2DI2DA8-A5-2(K-)K5-A42-NH19-H4-H63-3(19A6-)3(14A3-2A6-)6A2EAC4A3-2A6-6A2E2C4A3-2A6(6-4B3A3C4B3-2B)6-4B3A3C-5B-2B6-4B3A3CB2-6B6-BF8CB-7B6-11A-7A6-AF4C4G7C3(FA6-AF4C4G2CE4C)FA6-AF10CE4CFA6-A2(3DIDI)2(DI)DA6-A5-3(K-)K5-A16-N24-H20-NLN3-H62-6(19A6-)A-6EAC4A3E2A6-A-6E2C4A3E2A4(6-B-2B3A3C9B)2(6-B-2B3A3C7B-B)6-B-2B3A3C-B-4B-B6-B-2B3A3CB3-3B-B6-B-8C2(B-)3B-B6-A-9A-A-3A-A6-A-4C4G7C2(-A6-A-4C4G2CE4C)-A6-A-4C4G2CE5CA6-A-10C2E4CA6-A2(3DI)9DA6-A4-4(K-)K4-A15-3L21-2L-2H19-2LH2-LH18-L5-L36-6(19A6-)A-6EAC4A4E8A-6E2C4A4E7AB4(-2B3A3C9B5-2B)2(-2B3A3C7B-B5-2B)-2B3A3C-6B-B5-2B-2B3A3CB3-3B-B5-2B-8C2(B-)3B-B5-BA-4A5C-C-3C-F7A-4C4G7C-F7A2(-4C4G2CE4C-A6-A)-4C4G2CE5CA6-A-10C2E4CA6-A2D2I2DI3DI6DA6-A3-5(K-)K3-A15-3H68-H44-6(19A6-)A-6EAC4A4E8A-6E2C4A4E7AB4(-2B3A3C9B5-2B)4(-2B3A3C7B-B5-2B)-8C7B-B5-BA-4A4C4G3C-F7A-4C4G7C-F7A2(-4C4G2CE4C-A6-A)-4C4G2CE5CA6-A-10C2E4CA6-ADI6D2I4DI2DA6-A2-6(K-)K2-A15-2HL21-2H-2H19-2H2-3H16-N-H4-2H18-H17-6(19A6-)A-4EAE4CEA4E8A-4EAE4CEA4E7AB2(-2B6A9B5-2B)-2B2A2-2A9B5-2B-2B2A6-7B5-2B-2B2A6-B-3B3(-B5-2B-2B2A4C7B)-B5-2B-8C7B-B5-BA-4A4C3G2(3JC-F7A-11C)2(3JC-A6-A-11C)3J2CA6-A-11C3J2CA6-A6DI10DA6-A3-5(K-)K3-A40-3H21-LH-2H16-3LOL3-2H14-2L-2H5-H11-6(19A6-)A-4EAE4CEA5E7A-4EAE4CEA5E6AB2(-2B6A9B5-2B)-2B2A2-2A9B5-2B-2B2A6-7B5-2B-2B2A6-B2-2B3(-B5-2B-2B2A4C7B)-B5-2B-8C7B-B5-BA-4A4C3G2(3JC-F7A-11C)2(3JC-A6-A-11C)3J2CA6-A-11C3J2CA6-A8DI3DID2IDA6-A4-4(K-)K4-A40-3H42-L2H43-19A7(6-A3E2C13A)5(6-4B6A9B)3(6-4B2A4C9B)6-BF8C9B6-6A3C10A5(6-AF11C3JCFA)6-A2(5D2I)DIDA6-A5-3(K-)K5-A40-3H21-LH-2H16-5L3-2H14-2L-2L5-H12-17A7(8-A2E2C12A)3(8-3B6A8B)2(8-3B4A2M8B)3(8-3B2A4C8B)8-B8C8B8-5A3C9A5(8-A15CA)8-AID2IDI3DI2D2IDA8-A5-2(K-)K5-A110-N2-HL18-17A7(8-AE12A-2A)2(8-3B6A5B-2B)8-2B-6A5B-2B8-2B-2A4M5B-2B8-2B-2A2(CM)2(5B-2B8-2B-2A4C)5B-2B8-3B2A4C5B-2B8-BF-6C5B-2B8-2A-11A-2A3(8-AF-11C-FA)2(8-AFB11C-FA)8-A2D2(ID)I2D3I3DA8-A6-K-K6-A85-H24-L3-H19-8(15A10-)15B10-4B8-3B3(10-15B)3(10-8B-6B)10-BF6C-6B10-8A-6A5(10-AF6C-4CFA)10-A4DIDI2D2I2DA10-A6-K6-A86-H28-H20-13A12-3A8-2A6(12-13A)8(12-13B)12-BF5C6B12-13A5(12-AF9CFA)12-A6DI4DA12-A11-A115-2H21-11A6(14-3A3-5A)14-3A2-6A3(14-3B2-6B)14-3B-7B4(14-11B)14-2BF3C5B14-11A5(14-2AF5CF2A)14-2A7D2A14-2A7-2A91-2(H24-)8(7A18-)9(7B18-)7(7A18-)7A93-L43-
