model
size = 12 30 12, scale = 0.05, origin = -y
material deform = 1, fade = true, lighting = smooth, roughness = 0.3, metalness = 0.6
  colors = A:#08082F B:#1D1D56 C:#100 D:#003 E:#F90 F:#FC0 G:#F60 H:#FC3 I:#700 J:#500 K:#400
voxels
40-4E9-2E21-G2-G9-2G10-2G9-G2-G2(32-J2-J8-J2-J)32-G2-G9-2G10-2G9-G2-G21-2E9-4E115-2(6C6-)6C126-3(6C6-)6C161-5(2C4-)2C124-7(2C4-)2C159-2(2C6-2C2-)2C6-2C122-3(2C6-2C2-)2C6-2C4(158-2(C8-C2-)C8-C122-3(C8-C2-)C8-C)110-KA6-AK3(2-2A6-2A)-F3(2A6-2A2F)2A6-2AF-8(2A6-2A2-)2A6-2A-F4(2A6-2A2F)2A6-2AF-2(2A6-2A2-)EA6-AE3-E6-E40-2A4-2A3-K2A4-2AK4(2-3A4-3A)-H3A4-3A2H3A4-3AH-10(3A4-3A2-)3A4-3A-H2(3A4-3A2H)3A4-3AH-2(3A4-3A2-)3A4-3A3-2(2A4-)EA4-AE5-E4-E19-4D6-IB4DBI25(4-2B4D2B)5-B4DB6-E4DE7-4E7-6I2(2(6-6B)6-BD2BDB)6-BD2BDB6-6B2(2(6-BD2BDB)2(6-6B))2(2(6-BD2BDB)6-6B)6-6B6-BD2BDB3(6-6B)7-4B16-
