model
size = 15 15 3, scale = 0.05, origin = -y
material deform = 1, fade = true, lighting = smooth, roughness = 0.3, metalness = 0.6
  colors = A:#111 B:#100 C:#555 D:#222 E:#800 F:#200 G:#FC9 H:#300 I:#777 J:#E00
voxels
7-2B13-2E3-DG8-F3-DGD8-5BD9-E3HB10-3FHB8-3A-FHB-EB7-2A2(FEB)8-A14-A88-2B13-2E3-2D8-F3-3D8-4A2D9-J3AD9-5AD9-CAC2AD-EB5-2CGCAJDFEB4-2CGI2A8-2IGCICA7-2CG2C8-CICG2C9-CIGCI10-CG2C11-GC2I18-2B13-2E3-DG8-F3-DGD8-5BD9-E3HB10-3FHB8-3A-FHB-EB7-2A2(FEB)8-A14-A81-
