model
size = 21 26 3, scale = 0.05, origin = -y
material deform = 1, fade = true, lighting = smooth, roughness = 0.3, metalness = 0.6
  colors = A:#1B813E B:#0F4C3A C:#096148
voxels
9-B21-3(B20-)B17-6A11-14A7-15A5-7A-8A5-2A3-6A-5A3-2A5-AC9A3-2A2-6A-2AC-4A-2A3-11A-3A-A4-A-9A2-3A5-5A-6A3-A5-12A9-3A2-3A-4A8-2(3A2-)3A7-4A2-3A3-2A7-2(3A3-)3A6-3A4-3A3-2A6-3(2A5-3A11-)A7-2A11-A7-2A122-A13-B2-B3(-A)2-A14-A4-C11-B6-C2-A13-A2-A-A9-B13-2B9-C5-C8-B4-A13-B8-A-C2-2A6-B6-A7-B14-A7-B19-B11-B4-C15-B10-B7-B21-B5-2B4-B15-B20-B33-B29-B122-B41-A388-
