model
size = 30 22 29, scale = 0.05, origin = -y
material deform = 1, fade = true, lighting = smooth, roughness = 0.3, metalness = 0.6
  colors = A:#4AA8DB B:#FDEF14 C:#FF432E D:#393 E:#BBB F:#EEE G:#E11B22 H:#888 I:#578A3D J:#777
voxels
11-7E23-7E620-13E17-3E7-3E615-17E2(13-2E)612-19E11-E17-E610-21E9-E19-E608-23E7-E20A-E8-11(20A10-)20A248-25E5-2E20A2-E7-2(20B10-20C10-20D10-20A10-)20B10-20C10-20D10-20A248-25E5-E22A-E6-2(22B8-22C8-22D8-22A8-)22B8-22C8-22D8-22A21-F224-27E3-E-22A2-E5-2(22B8-22C8-22D8-22A8-)22B8-22C8-22D8-22A17-F-5F26-2F194-27E3-E2-20A3-E6-2(20B10-20C10-20D10-20A10-)20B10-20C10-20D10-20A17-10F22-3F-2F24-3G2F25-3G27-3G105-27E3-E2-20A3-E6-2(20B10-20C10-20D10-20A10-)20B10-20C10-20D10-20A17-10F21-F2G4F23-G3-3F23-4G2F24-5G26-3G74-29E-E4-18A5-E6-2(18B12-18C12-18D12-18A12-)18B12-18C12-18D12-18A19-8F22-F2G3-2F22-2GF-2F24-5G25-5G26-3G28-I29-2I14-29E-E4-18A5-E6-2(18B12-18C12-18D12-18A12-)18B12-18C12-18D12-18A18-3F-2F-3F20-F-5F24-2GF-2F24-4GF25-5G26-3G74-29E-E5-16A6-E7-2(16B14-16C14-16D14-16A14-)16B14-16C14-16D14-16A20-9F22-5F-F23-2GF-F25-3G27-3G104-29E-E5-16A6-E7-2(16B14-16C14-16D14-16A14-)16B14-16C14-16D14-16A19-9F22-6F192-29E-E6-14AH6-E8-14B3H13-14C2-6HJ7-2(14D16-14A16-14B16-14C16-)14D16-14A21-4F-2F23-2F-F2-F191-29E-E6-14AH6-E8-14B3H13-14C2-6HJ7-2(14D16-14A16-14B16-14C16-)14D16-14A21-4F-F25-F196-29E-E7-12A8-E9-2(12B18-12C18-12D18-12A18-)12B18-12C18-12D18-12A251-27E3-E6-12A7-E10-2(12B18-12C18-12D18-12A18-)12B18-12C18-12D18-12A251-27E3-E7-10A8-E11-2(10B20-10C20-10D20-10A20-)10B20-10C20-10D20-10A252-27E3-E7-10A8-E11-2(10B20-10C20-10D20-10A20-)10B20-10C20-10D20-10A253-25E5-E7-8A8-E13-2(8B22-8C22-8D22-8A22-)8B22-8C22-8D22-8A254-25E5-E7-8A8-E13-2(8B22-8C22-8D22-8A22-)8B22-8C22-8D22-8A255-23E7-E7-6A8-E15-2(6B24-6C24-6D24-6A24-)6B24-6C24-6D24-6A257-21E9-E6-6A7-E16-2(6B24-6C24-6D24-6A24-)6B24-6C24-6D24-6A258-19E11-E6-4A7-E18-2(4B26-4C26-4D26-4A26-)4B26-4C26-4D26-4A260-17E13-2E4-4A5-2E19-2(4B26-4C26-4D26-4A26-)4B26-4C26-4D26-4A262-13E17-3E2-2A3-3E22-2(2B28-2C28-2D28-2A28-)2B28-2C28-2D28-2A266-7E23-7E612-
