model
size = 31 26 21, scale = 0.05, origin = -y
material deform = 1, fade = true, lighting = smooth, roughness = 0.3, metalness = 0.6
  colors = A:#111 B:#C63 C:#555 D:#444 E:#777 F:#90F G:#333 H:#222 I:#666 J:#663 K:#03F L:#888 M:#9F9 N:#999 O:#AAA
voxels
481-4A2D25-4A2H25-4A2G2(25-4A2D)614-4A2C25-4A2D25-4A2F25-4A2(F13-14B3A)2F12-14B3A2C13-13B3A2C392-A28-4A25-6A24-7A24-9A21-11A20-15A2I14-15A2G14-15AF15-15AM2(12-15B3AF)12-15B3A2F11-15B3A2E14-2(12A19-)10AD21-9A23-6A242-8A22-9A21-11A20-12A18-14A17-15A15-17A2I12-17A2F12-17AF13-17AM3(12-15B3AF)12-15B3A2C12-14AC2A2J13-13AC17-14A17-13A19-10A238-12A19-12A18-13A18-14A16-2(16A15-)17A2E12-17A2F12-17AF13-17AM3(11-15B4AF)11-15B4A2D12-14AH2A2C12-14AE16-15A16-14A18-13A127-3K28-4K26-5K25-D-4K12-13A3G2K12-17A13-18A13-15AGIA13-15AGA2(13-18A)2D11-18A2E11-18AF12-18AM2(10-16B4AF)10-16B3AC2F9-16B4A2E11-17A14-17A15-16A15-15A16-14A97-2A27-5A26-6A24-E6A24-C6A10-14AG5A10-15A3H2AH10-20A11-15AH2EA11-16AD2H12-16ADA13-18A2I10-19A2L10-19A2F10-19A2(F10-16B4A)2F9-16B3AC2J9-16B3AJ2C11-3(17A14-)16A16-15A125-5A26-6A-I22-I6A2I22-D6AD8-15A2G4AG9-15A7H9-22A8-16AH2E2HA9-16AG2H2G9-17AD2A11-19A12-18A13-19A2I10-19A2D2(9-16B4A2I)9-16B4A2D9-16B4A2(12-19A)13-2(17A14-)16A103-E27-4C22-3A6G20-2J3A5J21-2J3A4J7-15A8C8-15A8G7-23A8-16AH2E2HEA7-17AD2H2D9-17AD2HDA9-20AC10-20A11-19A12-19A2I9-16B4A2E9-16B4A2J9-16B4AL10-16B5A11-19AL11-19A12-18A14-17A14-16A43-A28-3A26-5A24-6A21-9A20-11A20-10A6-9A6L9A7-9A6E9A6-10A6L8A7-10A6L7A7-23A8-21AI9-17A5N9-17A4LH9-17A3D11-17A3D10-16B2A3G10-16B2A3O10-16B2A3N10-16B2A3E11-17A3I11-17A2I12-17A2E12-17AC14-16A43-A28-3A26-M4A24-6A21-9A20-11A20-10A6-9A6I9A7-9A6E9A6-10A6E8A7-10A6E7A7-22AJ8-21AI9-17A5C9-17A5H9-20A11-17A3E10-16B2A3I2(10-16B2A3D)10-16B2A3C11-17A3D11-17A2D12-17A2C12-17AD14-16A103-E27-4C22-3A6G20-2J3A5J21-2J3A4J7-15A8C8-15A8G7-23A8-16AH2E2HEA7-17AD2H2D9-17AD2HDA9-20AC10-20A11-19A12-19A2I9-16B4A2E9-16B4A2J9-16B4AL10-16B5A11-19AL11-19A12-18A14-17A14-16A125-5A26-6A-I22-I6A2I22-D6AD8-15A2G4AG9-15A7H9-22A8-16AH2E2HA9-16AG2H2G9-17AD2A11-19A12-18A13-19A2I10-19A2D2(9-17B3A2I)9-17B3A2D9-17B3A2(12-19A)13-2(17A14-)16A96-2A27-5A26-6A24-E6A24-C6A10-14AG5A10-15A3H2AH10-20A11-15AH2EA11-16AD2H12-16ADA13-18A2I10-19A2L10-19A2F10-19A2(F10-17B3A)2F9-17B2AC2J9-17B2AJ2C11-3(17A14-)16A16-15A126-3K28-4K26-5K25-D-4K12-13A3G2K12-17A13-18A13-15AGIA13-15AGA2(13-18A)2D11-18A2E11-18AF12-18AM2(10-17B3AF)10-17B2AC2F9-17B3A2E11-17A14-17A15-16A15-15A16-14A236-12A19-12A18-13A18-14A16-2(16A15-)17A2E12-17A2F12-17AF13-17AM3(11-16B3AF)11-16B3A2D12-14AH2A2C12-14AE16-15A16-14A18-13A238-8A22-9A21-11A20-12A18-14A17-15A15-17A2I12-17A2F12-17AF13-17AM3(12-15B3AF)12-15B3A2C12-14AC2A2J13-13AC17-14A17-13A19-10A244-A28-4A25-6A24-7A24-9A21-11A20-15A2I14-15A2G14-15AF15-15AM2(12-15B3AF)12-15B3A2F11-15B3A2E14-2(12A19-)10AD21-9A23-6A437-4A2C25-4A2D25-4A2F25-4A2(F13-14B3A)2F12-14B3A2C13-13B3A2C645-4A2D25-4A2H25-4A2G2(25-4A2D)707-4A2G25-4A2C29-2C226-
