model
size = 19 31 18, scale = 0.05, origin = -y
material deform = 1, fade = true, lighting = smooth, roughness = 0.3, metalness = 0.6
  colors = A:#FC0 B:#F90 C:#FFF D:#FFC E:#FC6 F:#C60 G:#FC3 H:#930 I:#200 J:#CC3 K:#FF9 L:#500 M:#400 N:#600 O:#300 P:#F93 Q:#CC6 R:#C93 S:#C30 T:#700 U:#630 V:#F96 W:#C63 X:#800 Y:#F60 Z:#C96 Aa:#960 Ab:#900 Ac:#963
voxels
121-3A15-5A14-2(6A13-)2B3A15-B2A12-I4-2A25-I18-I64-MN3-N495-M533-H18-X31-N3-N18-M414-3A15-5A2(13-6A)14-3A2B15-2AB2-F13-2A3-F20-I18-I7-E-FBE2-B3-I7-2EW2E-G13-E-V2-R21-T317-2A15-B3A2B12-2B2(3A3B10-3B)3A2(4B9-6A)4B10-5A3B2-L5-MH-2B6A-HM4-O6-2AB3-OI4-O9-N2-OI5-I-B6-M3-I7-F6-F11-E18-TGE2-THF-F9-2FGE-VL12-FUFG-ROH262-3A13-2B3A2B11-6A3B9-7A4B8-4B3A5B2(7-4B8A)7-4B3A5B7-7A4B9-6A4B6-X3-5A3B-X5-L4-6A2-L6-2M7-B2-2M5-I-B6-B3-I7-N6-N10-TIF3-F-I-M8-OIS3-S22-U241-A15-7A11-3B3A4B8-4B3A4B7-5B3A4EA6-5B8A6-5B3A5G6-8A5E6-8A5D6-5B2JA5E7-12A4-H2-4B7A4-OH4-8A2-HL-IMAbH4-3ABE4-H4-2I2(2-G)4-2I6-2H6-H-FH7-FLF3-EFL-N8-SMS3-FS11-FLH4-H2-IHU17-T17-FO17-F29-L152-6A11-3B3A3B9-11A7-13A6-5E2AJ6C5-5G2CD6C5-5A2DA5C6-5B2E2(A6C5-5B2C)A6C5-5B3A5G7-7A5P8-10A4-IMAb3-2B3A3B3-H-2ITHT2EWE2AG3-T-H3-NTNF-R2-R3-TNFH6-NFH2-HF-NE9-MSL2-LS12-IHO2-OH2E10-H-R4-2E-T7-ILFH3-EGO10-MSLV-EG2F10-LH-R-G2(FU)10-LF2E-F14-O2-U-O-U124-2B5A10-4B7A7-7AP5B6-5B3A5D5-6D2CA6C5-5A3C5A6-5B2CA6C5-5B2CJ6D5-5A2DA5Q6-5A2DA6D5-5B3A5CD5-5B2QE5D7-4B2EA4G9-9A12-B4A9-NT-2E-V2-R2-TEFH6-HGE2-EHF-H9-2F4VLS10-2FU4ROH-IHU8-NE4-E12-IH3-EGI11-IFV-EGFI11-UFR-G2FU11-NLAa2-AaL11-FU2M-F2M12-2(H3-)H88-3A13-9A9-4B7A7-5K3A5B5-6D2JK6D4-9C5A5-6C2JC5A5-6D2QC5A6-5A3C6D5-5E2JC5A6-5P2AD5E5-D5E2CA6C5-5K3D4B7-5B2EA5G8-3B3A4B10-5A2B14-2V15-EG3-2G-W10-4E15-FE2G2-EF11-H2E3-EH11-LFG2-GFL11-MSF2-FSM11-LHU2-UH14-4FL11-2HFW-EW12-2FHF-EF12-2R-3RAc12-H2-H-E18-E34-B3AB12-3B3A3B9-7A4G7-5J2AK5D6-5Q2AK6C4-6D3C5A5-6D2PJ5A5-6D2AE5J5-6C9D4-6C2ED5E5-6C2AC6D4-6C2D7C6-4E2DA6D5-5A2DJ5K7-4B3A4B9-B7A31-F4E14-S4G14-H4F2EB32-4EF14-4GS14-4FH15-2E13-2B-HBE3-B9-2F-2FE3-F9-2Z2-FZ14-E-H2E3-E14-E34-B3AB12-3B3A3B9-4G7A7-5D2KA5J5-6C2KA5Q6-5A3C6D5-5A2JP6D5-5J2EA6D4-9D6C5-5E2DE6C4-6D2CA6C4-8CD6C4-6D2AD4E7-5K2JD5A7-4B3A4B9-F7A11-HE3-2EH11-LFG2-GFL-E9-MSF2-FSM12-HUW-UHL10-NH3-2V4-T8-L8-FO12-2E3-F13-2G3-U11-H4EAaF13-HBE13-2Y-FYE13-F3-3E16-2E18-E17-W17-3A13-9A9-7A4B7-5B3A5K5-6D2KJ6D5-5A9C5-5A2CJ6C5-5A2CQ6D4-6D3C5A6-5A2CJ5E6-5E2DA5P5-6C2AC5ED6-4B3D5K6-5G2AE5B7-4B3A3B11-2B5A9-T2-E4-EN2-EF7-IGE3-HI11-IFGE-VFI11-U2FGERFU-EHU9-R2-V-2E11-FH3-EG12-SL4V2F11-HO4RUF12-LH2-HL11-2E3-EW127-5A2B10-7A4B7-5B2P6A6-5D3A5B5-6C2AC6D5-5A3C5A5-6C2AC5B5-6D2JC5B6-5Q2AD5A5-6D2AD5A5-D5C3A5B6-5D2EQ5B7-4G2AE4B9-9A10-2E4ABHI10-2E4-R-H10-OGE3-HF11-2FGE-VLS11-FUFGERWHE16-R14-FH2-HF13-SL2-LS13-HO2-O19-L145-6A12-3B3A3B9-11A7-13A5-6C2JA5E5-6C2DC5G6-5C2AD5A5-6C2AE2(5B5-6C2AC)5B6-5G3A5B6-5P7A8-10A3-LO5-3B3A2BI13-2A3-U10-T8-T9-G-G3-2G-G9-F2E19-G2-G20-H11-LF4-FL12-S4-S13-H172-A12-L2-7A9-N4B3A3B9-4B3A4B7-A4E3A5B6-8A5B6-5G3A5B6-5E8A6-5D8A6-5E2AJ5B6-12A8-7A4B9-8A3-HLO2-AbH3-B3A-2S3-H3-THT10-T-H4-TNT8-TNFH5-FN2G2-2(G-)N8-SMB7-M9-IB6-BI19-T9-I16-IM96-Ac113-3A12-M2-2B3A2B9-N-3B6A9-4B7A7-5B3A2(4B7-8A)4B7-5B3A4B8-4B7A8-4B6A7-X2-3B5A8-L3-6A10-M9-O-2M5-2I10-2I8-E6-E9-TMN3-G2-N8-MOIM6-B2-SO5-FIF9-U7-H19-F248-2A12-O2-2B3AB12-3B3A2B11-3B2(3A3B9-4B)6A9-4B6A10-3B5A9-M-6A2B8-O4-B2A6-I4-O13-2(I5-I12-)I26-N8-N9-MB2-E16-G-E-W216-
