model
size = 19 31 30, scale = 0.05, origin = -y
material deform = 1, fade = true, lighting = smooth, roughness = 0.3, metalness = 0.6
  colors = A:#BBB B:#A00 C:#111 D:#222 E:#444 F:#EEE G:#333 H:#633 I:#777 J:#555 K:#0F3 L:#888 M:#336 N:#966 O:#999 P:#963 Q:#666 R:#369 S:#969 T:#96F U:#100 V:#96C W:#36C X:#669 Y:#663 Z:#996 Aa:#C99 Ab:#66C Ac:#330 Ad:#FC0 Ae:#CC9 Af:#99C Ag:#39C Ah:#700 Ai:#933 Aj:#DDD Ak:#9CF
voxels
103-2B16-2(4B15-)4B16-2B16-4C15-4C16-2C17-2C16-4C15-4C16-2C359-2B16-2(4B15-)4B16-2B16-4C15-4C16-2C17-2C16-4C15-4C16-2C358-4B14-5(6B13-)6C13-6C14-5(4C15-)2C322-2B15-6B13-6B12-2(8B11-)8B12-6B4(13-6C)14-3(4C15-)2C17-2G302-4B14-6B12-4(8B11-)8B12-3(6C13-)6C14-4C15-4C2(16-2C)17-2M17-2E17-C2-Ah14-2H2-2Ah69-8E11-8E146-4B14-6B12-4(8B11-)8B12-6C13-6C14-4C15-4C91-2G-G13-4Q-3Q11-4D-3D11-3H2-3H49-8E2(11-7EAd)11-8E128-2B15-6B13-6B12-2(8B11-)8B12-6B14-4C15-4C16-2C17-2C72-2D2-2D12-2(3G2-3G11-)3D2-3D11-3H2-3H49-8E2(11-7EAd)11-8E146-4B14-4(6B13-)6B127-2C2-2C12-4(3D2-3D11-)G6AG12-2(6A13-)6A12-8E11-8E108-5B14-5B15-3B35-2B16-2(4B15-)4B16-2B111-D2-D13-3C2-3C11-3D2-3D3(11-3C2-3C)10-3(10A9-)10A10-8A11-8A13-4A91-2(6B13-)6B14-3B203-3D2-3D11-3C2-3C11-3G2-3G11-3H2-3H11-3E2-3E11-3D2-3D6-3D12A2BA4-3(12A7-)12A8-10A10-8AF2Aj9-6A-F2A17-2F48-2(7B12-)6B13-5B14-3G2(16-3D)16-3G17-D18-E74-O2-O13-3D2-3D11-3C2-3C11-3J2-3J11-3L2-3L7-13O2BN3-13C2BN2-2G14ABA3-3(14A5-)12A2F6-9A3F2D5-9A3F3H5-8A3F3H7-6A3F2H15-2F2J28-2(7B12-)6B13-5B14-3H3(16-3D)15-4DK14-4JK13-6HK13-5I14-5C14-3I-2I12-3C2-3C11-3C2-3C8-12IBS5-12CBS4-13I2BN3-13C2BN2-H17A2-2(16A3-)16A4-11A2F2G4-10A3F3N4-8A4F3Z4-8A4F3P6-7A3F3P8-4A-3F2H16-FA10-3(6B13-)4B15-3H3(16-3D)15-4DK14-4AiK13-6GK13-5J14-5L14-3I-2I10-11EV7-11CV6-12JBS5-12LBS4-13I2BN3-13C2BN2-H17A2-2(16A3-)13A2FA3-11A3F3Y2-11A3F3Aa3-9A4F4Ac3-8A4F4U4-7A4F3P6-7A3F3H14-2FE10-5B14-5B15-3B129-3K15-5D14-5D12-9DT9-9CT8-11CV7-11CV6-12DBS5-12CBS4-13E2BN3-13D2BN2-3(18A-)14A2F2A2-11A3F2H3-11A3F3Ae3-9A4F4H2-9A4F4U3-8A7F6-7A3F3Z8-4A2-2FE141-7K11-K7C2(K9-9C)K9-2(10GT8-)10RT8-11CV7-11CV6-12DBS5-12DBS4-13D2BN3-13C2BN2-4(18A-)13A2F2EA2-11A3F3N2-11A3F3P3-10A3F3P4-9A3F3Y5-8A3F2C8-6A145-7K11-K7DK10-K7DK9-2(10GT8-)10ET9-9XT8-11CV7-11CV6-12JBS5-12LBS4-13O2BN3-13C2BN2-4(18A-)14AF3A2-12A2F2D3-11A3F2H4-10A3F3G4-10A2F2C6-10AFL9-6A145-7K11-K7GK10-K7GK9-10GT8-10ET8-10CT9-9ET8-11CV7-11CV6-12IBS5-12CBS4-13I2BN3-13C2BN2-4(18A-)18A2-16A3-12A3FA4-11A3F6-11A2F7-10A11-6A145-7K11-K7EK9-9HK9-9EK9-10JT8-10ET8-10JT8-11CV7-11DV6-12JBS5-12LBS4-13I2BN3-13G2BN2-4(18A-)14A2F2A2-11A3F2D3-11A3F3H3-10A3F3H4-9A3F2H6-9A2F2J8-6A2(14-5B)15-3B129-3K15-5D14-5D12-9MT9-9WT8-11CV7-11CV6-12DBS5-12GBS4-13R2BN3-13D2BN2-3(18A-)18A2-12A2F2G3-11A3F3N3-9A4F3Z3-9A4F3P4-9A3F3P6-7A3F2H9-4A3-FA10-3(6B13-)4B15-3H2(16-3D)16-3M15-4XK14-4AaK13-6AfK13-5D14-5Ab14-3Ab-2Ab10-11DV7-11CV6-12EBS5-12GBS4-13M2BN3-13C2BN2-H17A2-2(16A3-)13A2FA3-11A3F3Y2-11A3F3Aa3-9A4F4Ac3-8A4F4U4-7A4F3P6-7A3F3H14-2FE10-2(7B12-)6B13-5B14-3H3(16-3D)15-4HK14-4HK13-6QK13-5D14-5W14-3Ag-2Ag12-3D2-3D11-3C2-3C8-12DBS5-12MBS4-13E2BN3-13C2BN2-H17A2-2(16A3-)13A2FA4-10A3F2H4-10A3F3Ae4-8A4F4H3-8A4F4U5-6A7F8-4A-3F3Z14-2FE10-2(7B12-)6B13-5B14-2(3H16-)3G16-3D17-G18-H74-Ak2-Ak13-3(3D2-3D11-)3G2-3G7-13Q2BN3-13D2BN2-2H14ABA3-3(14A5-)11A2F2E5-9A3F3N4-9A3F3P5-8A3F3P7-6A3F3Y13-3F2C28-2(6B13-)6B14-3B203-3D2-3D11-3C2-3C11-3D2-3D2(11-3G2-3G)11-3D2-3D6-3H12A2BA4-3(12A7-)11AF8-9A2F2D7-7A3F2H8-6A3F3G14-2F2C16-FL29-5B14-5B15-3B35-2B16-2(4B15-)4B16-2B111-D2-D13-3C2-3C4(11-3D2-3D)10-3(10A9-)10A10-8A11-8A13-4A3-2F17-2F124-4B14-4(6B13-)6B127-2C2-2C12-3D2-3D3(11-3C2-3C)11-G6AG12-2(6A13-)6A12-8E11-8E147-2B15-6B13-6B12-2(8B11-)8B12-6B14-4C15-4C16-2C17-2C72-2G2-2G12-3H2-3H11-3E2-3E2(11-3D2-3D)49-8E2(11-7EAd)11-8E127-4B14-6B12-4(8B11-)8B12-6C13-6C14-4C15-4C91-2L-L13-4O-3O11-4C-3C11-3G2-3G49-8E2(11-7EAd)11-8E127-4B14-6B12-4(8B11-)8B12-3(6C13-)6C14-4C15-4C16-2C16-2I17-2C17-2I17-C2-Ah14-2H2-HAh69-8E11-8E147-2B15-6B13-6B12-2(8B11-)8B12-6B4(13-6C)14-3(4C15-)2J17-2L321-4B14-5(6B13-)6C13-6C14-5(4C15-)2D276-
