model
size = 7 29 14, scale = 0.05, origin = -y
material deform = 1, fade = true, lighting = smooth, roughness = 0.3, metalness = 0.6
  colors = A:#030 B:#0E0 C:#630 D:#080 E:#070 F:#050 G:#0A0 H:#111 I:#020
voxels
98-2(A6-)2C5-GE5-GD2(5-2D)5-DA5-2C5-FA5-GA5-EF117-2(A6-)2C5-GE5-GD2(5-2D)5-DA5-2C5-FA5-GA5-EF76-DA5-EA5-2C5-BD5-EA5-2A2(5-AF)5-EA5-GC5-GA2(5-2D)5-G2(A5-D)C5-EG2(5-BA)5-2A55-2C5-BF5-2E5-EA5-GC5-2A5-B2(F5-A)3(F5-E)C2(5-DA)5-BA5-DA5-2D5-BC5-BD5-BG5-DA5-GA4-3C41-E6-C6-EF2(5-EA)5-AC5-2A5-BA5-B2(F5-E)F5-DA5-DC3(5-DA)2(5-BA)5-BC2(5-DA)5-A5-BA4-2BC3-2DGF5-2D28-A6-C3(6-A)6-C2(6-A)2(6-B)6-A6-F6-C6-A3(6-B)6-E6-C6-A6-D5-DA4-EBA3-3BC3-GBIA5-A22-G6-D6-C3(6-A)6-C6-F2(6-A)2(6-B)6-A6-C2(6-B)6-F2(6-A)6-C6-A5-GA4-DBA3-D2BE3-3BC3-GID5-GF7-2(B6-E6-)DH5-AC5-D2(C5-E)H2(5-AC)4(5-BC)5-BH5-B5(C5-E)H5-BC4-EBC3-G2DC2-2DEBC2-3D2H2-BEBA5-F7-2(E6-B6-)DH5-AC5-D2(C5-E)H2(5-AC)4(5-BC)5-BH5-B5(C5-E)H5-BC4-EBC3-G2DC2-2DEBC2-3D2H2-BEBA5-F21-G6-D6-C3(6-A)6-C6-F2(6-A)2(6-B)6-A6-C2(6-B)6-F2(6-A)6-C6-A5-GA4-DBA3-D2BE3-3BC3-GID5-GF27-A6-C3(6-A)6-C2(6-A)2(6-B)6-A6-F6-C6-A3(6-B)6-E6-C6-A6-D5-DA4-EBA3-3BC3-GBIA5-A27-E6-C6-EF2(5-EA)5-AC5-2A5-BA5-B2(F5-E)F5-DA5-DC3(5-DA)2(5-BA)5-BC2(5-DA)5-A5-BA4-2BC3-2DGF5-2D33-2C5-BF5-2E5-EA5-GC5-2A5-B2(F5-A)3(F5-E)C2(5-DA)5-BA5-DA5-2D5-BC5-BD5-BG5-DA5-GA4-3C60-DA5-EA5-2C5-BD5-EA5-2A2(5-AF)5-EA5-GC5-GA2(5-2D)5-G2(A5-D)C5-EG2(5-BA)5-2A25-
