model
size = 23 8 18, scale = 0.05, origin = -y
material deform = 1, fade = true, lighting = smooth, roughness = 0.3, metalness = 0.6
  colors = A:#000 B:#A93AF6 C:#7A1FF5 D:#510BDF E:#2609BB F:#BE4FF7 G:#0B0894 H:#CB73F9
voxels
2-2(9A3-9A-)2AHF2BCDE2A-2AHF2BCDE3AH2FB2CDEGA-AH2FB2CDEG2AHF2BC2DEGA-AHF2BC2DEG2AHFB2CD2EGA-AHFB2CD2EG2AHFBC2DE2GA-AHFBC2DE2G3AFBCD2EG5AFBCD2EG2A92-A2(21-2A3(21-A161-A))10(21-A161-A)21-A23-
