model
size = 29 14 27, scale = 0.05, origin = -y
material deform = 1, fade = true, lighting = smooth, roughness = 0.3, metalness = 0.6
  colors = A:#FF6905 B:#0A0000 C:#212489 D:#3825C5 E:#A08CEC F:#6F51DF G:#5F3EDC H:#D7AEF4 I:#DABCF8 J:#CB88EA K:#F6D644 L:#BB6CE0 M:#A553CB N:#7F63E5 O:#4C26D8 P:#22259E Q:#BB9FF3 R:#FAEB88 S:#2B24B2 T:#B465D9 U:#FDF4B9 V:#030303 W:#9144B4 X:#FE3C00 Y:#1352F1 Z:#1224B0
voxels
96-11B18-2(C2B)3C3(2B18-4(CB)C)2B18-3(CB)3CBC18-11B219-3B9-3B14-3C3(9-BCB14-CBC)9-BCB14-3C9-3C14-3B9-3B216-2B5(13-2B12-BC)13-CB12-2B13-2B214-2B2(15-2B10-CB)15-2B10-2B2(15-BC10-CB)15-BC10-2B15-2B212-2B17-2B8-BC17-2B8-2C17-2B8-CB17-2C8-2C17-CB8-BC17-2C8-2B17-2B210-2B19-2B6-CB19-2C6-2C19-2C6-BC19-2C6-2C19-2C6-CB19-2C6-2B19-2B208-2(2B2(21-2B4-BC)21-2B4-)2B21-2B206-2B3(23-2B2-CB)2(23-2C2-CB)23-2C2-2B23-2B204-2B25-2B2C25-2CBC25-4C25-2CBC25-2B2C25-4B25-2B203-B27-BC27-2B27-BC27-CB27-2C27-CB27-B203-B6(27-2B)27-B203-B27-BC2(27-2C)27-BC27-2C27-CB27-B203-B27-BC2(27-2B)27-CB27-2B27-CB27-B203-B27-BC5(27-CB)27-B203-B6(27-2B)27-B203-B27-BC27-CB3(27-BC)27-CB27-B203-B27-BC27-CB27-BC27-2B27-BC27-CB27-B203-B27-BC2(27-2C)27-CB27-2C27-CB27-B203-B6(27-2B)27-B121-8B3-8B7-7B3-2B-2B3-7B2-4B9-B-B9-5B2V10-3B10-V2B-C2(B11-)2(BC-BVB23-3B-CB23-)BC-BVB23-4BVB23-7B21-BV2B-7B13-7B4-5B13-5B8-8C3-8C7-3CBA6BC-C6BAB3C2-2CBYTLJ6-C-C6-JLTYB3C2AMTLJ6-BCB6-JLTM2A2C2AMTLJ6-3B6-JLTM2A2C2AMTLJ7-B7-3(JLTM2A2C2AMTLJ15-)JLTM2A2C2AWMTJ15-JTMW2A2C2AWMTL15-LTMW2A2CBAZMTL15-LTMZA2C-2CB3A4B7-4B3A3C4-4C4B7-4B4C8-8C3-8C7-3CB4A3BC-C3B4A4C2-2CB4AHIE3-C-C3-EIH4AB2CB6AHIE3-BCB3-EIH6A2B6AHIE3-3B3-EIH6A2B6AHIE4-B4-5(EIH6A2B6AHIE9-)EIH6ABCB5AJHE9-EHJ5A2C-2CB6A9B6A3C4-7C9B7C8-8C3-8C7-3CB6AXC-CB6AB3C2-BCB7AFGDC-CDGF7ABC2B9AFGDBCBDGF9ABM9AFG-3B-GF9A2M9AFG2-B2-4(GF9A2M9AFG5-)GF9AMB9AFG5-GF9A3B8AEF5-FE8AXB-2CB8A5B8A2CB4-23C8-8C3-8C7-3CB6ABC-CB6AB3C3-2B10AC-C10A2B2-J12ACAD10AJ2-J10AD3AD10AJ2-L10ADPA4(PD10AL2-L10ADPC)PD10AL2-L10A2DP2D10AL2-B10AGDPDG10AB2-BCB21AX2B4-23C8-8C3-8C7-B2CB6ABC-CB6AB2CB4-B10AC-C10AB4-H11AC11A2(H4-H23A)H5(4-J23AJ)4-JH21AHJ4-BH21A2B5-B21CB8-B7C3-7CB8-3B2K4ABC-CB4A2K3B6-IQRK6AC-C6AKRQI6-I2RK7AC7AK2RI6-I2RK15AK2RI6(6-HURK15AKRUH)7-IR2K13A2KRI8-IQR2K11A2KRQI8-3B15C3B10-7B3-7B12-2NFGOD2B-2BDOGF2N11-E2NFGODSB-BSDOGF2NE9-Q2ENFGODS3BSDOGFN2EQ8-2QENFGODSPBPSDOGFNE2Q5(8-IQENFGODSPCPSDOGFNEQI)8-IQENFG2ODSPSD2OGFNEQI9-QENFG2ODSPSD2OGFNEQ11-QENFGODSPSDOGFNEQ12-17B6-
