model
size = 29 14 27, scale = 0.05, origin = -y
material deform = 1, fade = true, lighting = smooth, roughness = 0.3, metalness = 0.6
  colors = A:#FF6905 B:#FE3C00 C:#0A0000 D:#F6D644 E:#FDF4B9 F:#FAEB88 G:#F28214 H:#F2AB14 I:#F29114 J:#B9E7FD K:#4AA7F6 L:#1352F1 M:#F3BC27 N:#1224B0 O:#FF5705 P:#F23914 Q:#FF3A05 R:#ED2707 S:#030303
voxels
96-11B18-2(C2B)3C3(2B18-4(CB)C)2B18-3(CB)3CBC18-11B219-3B9-3B14-3C3(9-BCB14-CBC)9-BCB14-3C9-3C14-3B9-3B216-2B5(13-2B12-BC)13-CB12-2B13-2B214-2B2(15-2B10-CB)15-2B10-2B2(15-BC10-CB)15-BC10-2B15-2B212-2B17-2B8-BC17-2B8-2C17-2B8-CB17-2C8-2C17-CB8-BC17-2C8-2B17-2B210-2B19-2B6-CB19-2C6-2C19-2C6-BC19-2C6-2C19-2C6-CB19-2C6-2B19-2B208-2(2B2(21-2B4-BC)21-2B4-)2B21-2B206-2B3(23-2B2-CB)23-BC2(2-CB23-2C)2-2B23-2B204-2B25-2B2C25-2CBC25-4C25-2CBC25-2B2C25-4B25-2B203-B27-BC27-2B27-BC27-CB27-2C27-CB27-B203-B6(27-2B)27-B203-B27-BC2(27-2C)27-BC27-2C27-CB27-B203-B27-BC2(27-2B)27-CB27-2B27-CB27-B203-B27-BC5(27-CB)27-B203-B6(27-2B)27-B203-B27-BC27-CB3(27-BC)27-CB27-B203-B27-BC27-CB27-BC27-2B27-BC27-CB27-B203-B27-BC2(27-2C)27-CB27-2C27-CB27-B203-B6(27-2B)27-B121-8C3-8C7-7C3-2C-2C3-7C2-4C9-C-C9-4C2BS10-3C10-S2B-2C11-C11-2(2C-2BC23-C2B-2C23-)2C-2BC23-C2BCSC23-7C21-CS2C-7C13-7C4-5C13-5C8-8B3-8B7-3BCA6CB-B6CAC3B2-2BCLKJE6-B-B6-EJKLC3B2ALKJE6-CBC6-EJKL2A2B2ALKJE6-3C6-EJKL2A2B2ALKJE7-C7-EJKL5(2A2B2ANLKJ15-JKLN)2A2BCANLKJ15-JKLNA2B-2BC3A4C7-4C4A2B4-4B4C7-4C4B8-8B3-8B7-3BC4A3CB-B3C4AC3B2-2BC4ADHI3-B-B3-IHD4AC2BC6ADHI3-CBC3-IHD6A2C6ADHI3-3C3-IHD6A2C6ADHI4-C4-IHD5(6A2C6AEDH9-HDE)6ACBC5AEDH9-HDE5ACB-2BC6A9C6A3B4-7B9C7B8-8B3-8B7-3BC6A2B-BC6AC3B2-CBC7AG2AB-B2AG7ACB2C9AG2ACBC2AG9ACN9AGA-3C-AG9A2N9AGA2-C2-AG4(9A2N9AIG5-GI)9ANC9AIG5-GI9A3C8AIG5-GI8ABC-2BC8A5C8A3B4-23B8-8B3-8B7-3BC6ACB-BC6AC3B3-2C10AB-C10A2C2-K12AB12AK2-K10AP3AP10AK2-L10APRARP10AL2-L10A2PR2P10A3(L2-L11APRP11A)L2-L12AP12AL2-C12AP12AC2-3C21AB2C4-23B8-8B3-8B7-C2BC6ACB-BC6AC2BC4-C10AB-B10AC4-J11AB11A2(J4-J23A)J5(4-K23AK)4-KJ21AJK4-CJ21A2C5-2C19B2C8-2C6B3-6B2C8-3C2D4ACB-BC4A2D3C6-E2FD6AB-B6AD2FE6-E2FD7AB7AD2FE6-E2FD15AD2FE6(6-JEFD15ADFEJ)7-EF2D13A2DFE8-E2F2D11A2D2FE8-3C15B3C10-7C3-7C12-2MHIGA2C-2CAGIH2M11-D2MHIGAOC-COAGIH2MD9-F2DMHIGAO3COAGIHM2DF8-2FDMHIGAOQCQOAGIHMD2F5(8-EFDMHIGAOQRQOAGIHMDFE)8-EFDMHI2GAOQOA2GIHMDFE9-FDMHI2GAOQOA2GIHMDF11-FDMHIGAOQOAGIHMDF12-17C6-
