model
size = 20 26 13, scale = 0.05, origin = -y
material deform = 1, fade = true, lighting = smooth, roughness = 0.3, metalness = 0.6
  colors = A:#555 B:#DFA59A
voxels
183-14B6-14A303-A2(BA14-AB2A)BA14-ABA2BA14-A4BA14-A2BA3(BA14-AB2A)2B14A2B2A18B2A2B14A15(2B2A2B14-)2B2ABA14-AB2(2A-A14-A-)AB-A14-A-2B-A14-A-BA3(-A14-A-2A)2-14AB-2A2-15B-2A-B14AB-2A2B14-2B2(2A-B14-B-)2A2B14-2B2A-B14-B-2A2B14-2BA160-A2B14-2B2ABA14-AB2(2A-A14-A-AB-A14-A-BA-A14-A-)2A-A14-A-2A2-14AB-2A2-15B-21A2(20-A2B14-2B2A2B14-2BA)160-A2B14-2B2ABA14-AB2(2A-A14-A-AB-A14-A-BA-A14-A-)2A-A14-A-2A2-14AB-2A2-15B-21A20-A2B14-2BA20-3B14-3B40-A2B14-2BA20-A2B14-2B2A2B14-2BA80-A2B14-2B2ABA14-AB2A-A14-A-AB-A14-A-BA2(-A14-A-2A)-A14-A-AB-A14-A-BA-A14-A-2A2B14AB-2A18B2A2B14A2B2A2B14-2B2A-B14-2B2A2B14-2BA20-A6(2B14-2B2A)2B14-2BA60-A2B14-2B2ABA14-2(AB)-A14-A-BA3(-A14-A-2A)-A14-A-AB-A14-A-BA-A14-A-2A2B14A2BA3-14B6-14A3-A16-B2-AB15-2B-A2(2B14-2B2A)-B14-2B2A2B14-2BA20-A2B14-2B2A-B14-B-A20-A5(2B14-2B2A)BA14-2(AB)-A14-A-BA4(-A14-A-2A)-A14-A-AB-A14-A-BA2B14AB-2A18B2A2B14A2B2A2B14-2B2A-B14-2B2A2B14-2BA20-A6(2B14-2B2A)2B14-2BA60-A2B14-2B2ABA14-2(AB)-A14-A-BA4(-A14-A-2A)-A14-A-AB-A14-A-BA2-14AB-2A2-15B-21A20-A2B14-2BA20-3B14-3B40-A2B14-2BA20-A2B14-2B2A2B14-2BA80-A2B14-2(2BA)14-A2BA6(-A14-A-2A)-A14-A-AB2-14AB-BA2-15B-21A2(20-A2B14-2B2A2B14-2BA)160-A2B14-2(2BA)14-A2BA6(BA14-AB2A)BA14-ABA3B14A3BA18B2A2B14A15(2B2A2B14-)2BA180-A18B2A2B14A9(2B2A2B14-)2BA300-B2A14-2ABAB17A2(BA)2(14-AB3AB)14AB5A14-5AB14-B4AB15AB2ABA14-AB2ABA14-2A2B18AB120-
