model
size = 25 30 19, scale = 0.05, origin = -y
material deform = 1, fade = true, lighting = smooth, roughness = 0.3, metalness = 0.6
  colors = A:#E00 B:#FF0 C:#CF3 D:#080 E:#EEE F:#251505 G:#CF0 H:#AAAAB9 I:#777 J:#BBB K:#960 L:#939 M:#CC6 N:#AAA O:#040 P:#888 Q:#009 R:#FCF
voxels
6-7(7D18-)2B5D18-3B2(4D18-D2B)2(4D18-3B)4(4D18-D2B)4D18-3B4D18-B6D6(18-7D)141-11D2(14-2D7A2D)14-2DA3-A-A2D14-BD2(A5-A2D14-2B)A5-A2D14-DBA5-A2D14-3B3(5-B2D14-2DB)5-B2D14-D2B5-B2D14-3B5-B2D14-BD2(B5-B2D14-2D)H5-H2D14-2DA5-A2(2D14-2BH5-H)2D14-BD2(H5-H2D14-2D)H5CH2D14-2D7F2D14-2D7-2D138-13D2(12-D11AD)12-BA4-3A2-AD12-BA4-2A3-AD12-DA9-AD12-2B9-AD12-DA9-AD12-DB2(9-BD12-2B)3(9-BD12-DB)9-B2(D12-2B6-4B)D12-DB7-2CHD12-DA7-3AD12-BH7-2CHD12-D2(H8-CHD12-B)H8-CHD12-DH7CBCHD12-D4FK2FK3FD12-D11-D136-15D10-D2(13AD10-B)9A2-2AD10-D8A4-AD10-D7A5-AD10-3B5A5-AD10-D7A5-A2(D10-D7B5-B)2(D10-2B2-4B5-B)2(D10-DB2-4B5-B)D10-DB2-10BD10-2B2-4B-B-3BD10-DH2-4C2-3CHD10-BA2(2-4A)D10-BH2-4C2-3C2(HD10-DH2-4C2-G2C)HD10-BH2-4C2-G2CHD10-BH8CG2CHD10-D5FK7FD10-D6-M6-D134-17D2(8-B7A-7AD)8-D13A-AD8-D10A4-AD8-D8A6-AD8-4B5A6-AD8-I8A6-A6(D8-I8B6-B)D8-I9B-5BD8-I9B2-4BD8-IH8C-4CHD8-I9A-5AD8-IH13C3(HD8-DH9CG3C)HD8-BH9CG3CHD8-B2(4FK)FK3FD8-D6-M-M6-D42-N90-17D2(8-B15AD)3(8-D12A3-D)8-I12A3-D8-13A4(3-D8-A12B)3-D8-13B3-D8-A12B2-BD8-A8B-B-2B-BD8-A9B2-4BD8-A9C-5CD8-B9A-4A-D8-I14C3(BD8-D10CG3C)BD8-B10CG3CBD8-B2F2K4F2K2FK2FD8-D5-2(M-)M5-D42-PJ19-J4-J63-19D2(6-2B16AD)2(6-D13A3-AD)6-I13A3-AD6-6A2GAC4A3-AD6-B5A2G2C4A3-AD6-A6(3B3A3C4B3-BD6-I)3B3A3C-5B-BD6-I3B3A3CB2-5BD6-2A8CB-6BD6-11A-6AD6-2I4C4E7C3(HD6-DH4C4E2CG4C)HD6-2B10CG4CHD6-B2(3FKFK)2(FK)FD6-D5-3(M-)M5-D16-P24-J20-PNP3-J62-19D2(6-2B16AD)2(6-D17AD)6-I17AD6-A-6GAC4A3GAD6-A-6G2C4A3GAD6-I2(-2B3A3C8BD6-E)-2B3A3C8BD6-Q-2B3A3C8B2(D6-E-2B3A3C7B-)D6-E-2B3A3C-B-4B-D6-I-2B3A3CB3-3B-D6-A-8C2(B-)3B-D6-A-9A-A-3A-D6-I-4C4E7C2(-D6-D-4C4E2CG4C)-D6-D-4C4E2CG5CD6-B-10C2G4CD6-B2(3FK)9FD6-D4-4(M-)M4-D15-3N21-2N-2J19-2NJ2-NJ18-N5-N36-19D2(6-2B16AD)2(6-D17AD)6-I17AD6-A-6GAC4A4GA6EI-6G2C4A4GA7E4(-2B3A3C8BD5-2E)2(-2B3A3C7B-D5-2E)-2B3A3C-6B-D5-EI-2B3A3CB3-3B-D5-EA-8C2(B-)3B-D5-EA-4A5C-C-3C-H6EI-4C4E7C-H6E2(D-4C4E2CG4C-D6-)D-4C4E2CG5CD6-B-10C2G4CD6-B2F2K2FK3FK6FD6-D3-5(M-)M3-D15-3J68-J44-19D2(6-2B16AD)2(6-B17AD)6-I17AD6-A-6GAC4A4GA6EI-6G2C4A4GA7E2(-2B3A3C8BD5-EQ-2B3A3C8BD5-2E)-2B3A3C7B-D5-EQ-2B3A3C7B-D5-2E-2B3A3C7B-D5-EI-2B3A3C7B-D5-EA-8C7B-D5-EB-4A4C4E3C-H6EI-4C4E7C-H6E2(B-4C4E2CG4C-D6-)B-4C4E2CG5CD6-B-10C2G4CD6-BFK6F2K4FK2FD6-D2-6(M-)M2-D15-2JN21-2J-2J19-2J2-3J16-P-J4-2J18-J17-19A2(6-2B17A)2(6-19A)6-I17AD6-A-4GAG4CGA4GA6EI-4GAG4CGA4GA7E2(-2B6A8BA5-2E)-2B2A2-2A8BA5-2E-2B2A6-6BA5-2E-2B2A6-B-3B2(-A5-2E-2B2A4C7B)-A5-EI-2B2A4C7B-A5-EA-8C7B-A5-EA-4A4C3E3LC-H6EI-11C3LC-H6E2(A-11C3LC-A6-)A2(-11C3L2CA6-B)6FK10FA6-A3-5(M-)M3-A40-3J21-NJ-2J16-3NRN3-2J14-2N-2J5-J11-19A2(6-2B17A)2(6-19A)6-I18A6-2(A-4GAG4CGA5G6E)I2(-2B6A8BA5-2E)-2B2A2-2A8BA5-EQ-2B2A6-6BA5-2E-2B2A6-B2-2B2(-A5-2E-2B2A4C7B)-A5-EI-2B2A4C7B-A5-EA-8C7B-A5-EA-4A4C3E3LC-H6EI-11C3LC-H6E2(A-11C3LC-A6-)A2(-11C3L2CA6-B)8FK3FKF2KFA6-A4-4(M-)M4-A40-3J42-N2J43-19A2(6-2B2G2C13A)2(6-A3G2C13A)6-I3G2C13A6-A3G2C13A6-B3G2C13A6-A5(3B6A8BA6-I)2(3B2A4C8BA6-I)3B2A4C8BA6-AH8C8BA6-6A3C10A6-2I3(11C3LCHA6-AH)2(11C3LCHA6-2B)4F2K5F2KFKFA6-A5-3(M-)M5-A40-3J21-NJ-2J16-5N3-2J14-2N-2N5-J12-17A2(8-B2G2C12A)3(8-A2G2C12A)8-I2(2G2C12A8-A)3(2B6A7BA8-A)2B4A2O7BA8-3B4A2O3(7BA8-A2B2A4C)7BA8-A8C7BA8-B4A3C9A8-I3(15CA8-A)2(15CA8-B)KF2KFK3FK2F2KFA8-A5-2(M-)M5-A110-P2-JN18-17A2(8-BG12A-2A)3(8-AG12A-2A)8-4B10A-2A8-IG12A-2A2(8-I2B6A5B-BA)8-IB-6A5B-BA8-IB-2A4O5B-BA8-IB-2A2(CO)2(5B-BA8-IB-2A4C)5B-BA8-I2B2A4C5B-BA8-IH-6C5B-BA8-IA-11A-2A8-I3(H-11C-HA8-A)2(HB11C-HA8-B)2F2(KF)K2F3K3FA8-A6-M-M6-A85-J24-N3-J19-15A3(10-B14A)2(10-15A)10-3B12A10-15A10-14BA10-A3B8-2BA10-14B2(A10-A13B)2(A10-8B-5B)A10-A7B-5BA10-AH6C-5BA10-2B6A-6A10-2B2(6C-4CHA10-AH)2(6C-4CHA10-BH)6C-4CHA10-A4FKFK2F2K2FA10-A6-M6-A86-J28-J20-13A12-3A8-2A3(12-B12A)12-13A12-2B11A12-13A2(12-12B2(A12-A11B)A)2(12-12BA)12-AH5C5BA12-13A12-BH9CHA12-A2(H9CHA12-B)2(H9CHA12-A)6FK4FA12-A11-A115-2J21-11A2(14-3A3-5A)14-B2A3(3-5A14-2BA)3-5A14-3A2-6A14-2AB2-4B2A14-BAB2-4B2A14-A2B2-4B2A14-2AB-5B2A14-BA7B2A14-A8B2A14-2A2(7B2A14-BA)H3C3B2A14-AB9A2(14-2BH5CH2A)14-BA3(H5CH2A14-2A)7F2A14-2A7-2A91-2(J24-)6(7A18-)B6A18-2B5A18-A3B2(3A18-2A2B)3A18-4B2(3A18-2A2B)3A18-BA2B2(3A18-A3B)3A18-2B5A18-B6A6(18-7A)93-N43-
