model
size = 25 30 19, scale = 0.05, origin = -y
material deform = 1, fade = true, lighting = smooth, roughness = 0.3, metalness = 0.6
  colors = A:#FF0 B:#06F C:#EEE D:#E00 E:#CF3 F:#000 G:#00C H:#251505 I:#BBB J:#CC6 K:#CF0 L:#939 M:#960 N:#1C0900 O:#AAAAB9 P:#AAA Q:#00F R:#888 S:#FCF
voxels
6-12(3B4A18-)4(7A18-)8(3B4A18-)3B4A141-11B2(14-2B5C2A2B)14-2BC3-C-8(A2B14-2BC5-)A2B4(14-3A5-3A)14-2BC5-A2B14-2BF5(5-A2B14-2BO)4E2A2B14-2B3H2N2H2B14-2B7-2B138-13B2(12-B11CB)12-BC4-3C2-CB12-BC4-2C3-7(CB12-BC9-)CB2(12-AC9-2A)2(12-AC6-C4A)12-BC7-3CB12-BF7-3FB12-BG7-E3(2FB12-BG8-)2FB12-BO7EA2FB12-B3HNM2NM2HNB12-B11-B136-15B2(10-BA12CB)10-BA8C2-2CB10-B8C4-5(CB10-B7C5-)2(CB10-BC2-4C5-)CB2(10-2A2-4C5-2A)10-2A2-9C2A10-2A2-4C-C-2C2A10-BC2-4C2-3CDB10-BF2(2-4F)B10-BG2-4E2-E3(3FB10-BG2-4E2-K)3FB10-BO8EK3FB10-B5HM2H2NH2NB10-B6-J6-B134-17B2(8-B7A-7AB)8-B13A-AB8-B10C4-4(AB8-B8C6-)3(DB8-B8C6-)DB2(8-3A6C6-2A)8-3A7C-3C3A8-3A7C2-2C3A8-B9C-3C2DB8-B9F-5FB8-B4G7E3(4FB8-B4G6EK)4FB8-BO9EK4FB8-BH3NM4HMHNH2NB8-B6-J-J6-B42-P90-17B2(8-B15AB)8-B12A8(3-B8-B12C)3-B8-3A10C3-A8-3A10C2-2A8-3A6C-C-2C-2A8-3A7C2-2C3A8-B9C-3C2DB8-B9F-4F-B8-B4G7E3(4FB8-B4G6EK)4FB8-B10EK4FB8-B2H2M4H2MHN2HNB8-B5-2(J-)J5-B42-RI19-I4-I63-19B2(6-B17AB)6-B13A5(3-AB6-B13C)3(3-DB6-B13C)3-DB2(6-4A10C3-2A)6-4A6C-4CA-2A6-4A7C2-2C4A6-B10C-3C3DB6-B10F-6FB6-B5G4C3E3(5FB6-B5G4C2EK)5FB6-BO10EK5FB6-BH2NMHM3HMHMNM2HNB6-B5-3(J-)J5-B16-R24-I20-RPR3-I62-19B3(6-B17AB)2(6-B14C3AB)6-B2(-13C3AD7B)3(-13C3DB5-2B)-13C3DB5-BA2(-2A11C2D-A5-2A)-2A6C-C-2C2D-A5-2A-2A7C3-C2D-A5-AB-9C2(-C)2D-B5-2B-9F-F-3F-D7B-3GE4C3E4F-8B2(-3GE4C2EK4F-B6-B)-3GE4C2EK5FB6-B-10EK5FB6-BHNHM3HM8HNB6-B4-4(J-)J4-B15-3P21-2P-2I19-2PI2-PI18-P5-P36-6(19B6-)B-24B-5AK2E4D4K8B2(-2D2AD3E4A4DB5-2B)-5D3E2A6DB5-2B-5D3E2A6DB5-BA2(-15D-A5-2A)-8D-6D-A5-2A-5D3EA3-3A-A5-AB-5D3E2(A-)3A-B5-2B-5F4E-E-3E-D7B-3GE4C7E-8B2(-3GE4C2EK4E-B6-B)-3GE4C2EK5EB6-B-10E2KE3CB6-B2H2M2HM3HM5HNB6-B3-5(J-)J3-B15-3I68-I44-6(C17BC6-)C-16B8C-5AK2E4D4K8C2(-2D2AD3E4A4DC5-2C)2(-5D3E2A6DC5-2C)3(-15D-C5-2C)2(-5D3E7A-C5-2C)-5F3E4C3E-D7C-3GE4C7E-D7C2(-3GE4C2EK4E-C6-C)-3GE4C2EK5EC6-C-10E2KE4C6-CHM6H2M4HM2NC6-C2-6(J-)J2-C15-2IP21-2I-2I19-2I2-3I16-R-I4-2I18-I17-19B5(6-B6A8D3CB)6-B-5AK4EKD4KA7B-17A7B2(-2D2AD7A4DB5-2B)-4D2-2D2A6DB5-2B-4D6-6DB5-BA-4D6-D-3D2(-A5-2A-15D)-A5-2A-5D3E7A-A5-AB-5D3E7A-B5-2B-5F3E3C3LE-D7B-3G8E3LE-8B2(-3G8E3LE-B6-B)-3G8E3L2EB6-B-11E2L3CB6-B6HM9HNB6-B3-5(J-)J3-B40-3I21-PI-2I16-3PSP3-2I14-2P-2I5-I11-19B5(6-B6A8D3CB)6-B-5AK4EKDK4C7B-16AC7B2(-2D2AD7A4DB5-2B)-4D2-2D2A6DB5-2B-4D6-6DB5-BA-2A2D6-D2-2D-A5-2A-15D-A5-2A-2A13D-A5-2A-2A2D4E7A-A5-AB-3D5E7A-B5-2B-5F3E3C2(3LE-8B-3G8E)2(3LE-B6-B-3G8E)3L2EB6-B-11E2L3CB6-B8HM3HMHMNHB6-B4-4(J-)J4-B40-3I42-P2I43-19B7(6-B16ACB)2(6-B3D10A4DB)6-B9D2A6DB6-B17DB6-4A8D7A6-5A8D6A6-4A9D6A6-4A2D4E9A6-B4D5E8AB6-B6F2E8DF4(B6-B4G8E3LEO)B6-BO11E2L3CB6-B5H2M5HMN2HNB6-B5-3(J-)J5-B40-3I21-PI-2I16-5P3-2I14-2P-2P5-I12-17B8-B12A3QB8-B12AQ2CB8-B12A3Q3(B8-B15A)B8-B13A2C2(B8-B2D10A3C)B8-B8D2A5DB8-B15DB8-3A8D6A8-4A8D5A8-3A9D5A8-3A2D4E8A8-B3D5E2A5DB8-B5F2E8D4(B8-BC2G12E)B8-B13E2CB8-BMH2MHM3HM2H2MHB8-B5-2(J-)J5-B110-R2-IP18-17B7(8-B11A2C-CB)2(8-B2D9A2C-CB)8-BD-6D2A3D-DB8-BD-11D-DB8-2A-8D3A-2A8-2A-A8D2A-2A8-2A-9D2A-2A8-3A2D4E5A-2A8-BD-D5E2A3D-DB8-BF-11F-F3(B8-BC-G10E-O)B8-BC2G10E-OB8-BOA11E-CB8-B2H2(MH)M2HMNM3HB8-B6-J-J6-B85-I24-P3-I19-15B4(10-B10A3CB)4(10-BC9A3CB)10-BC2A8-2CB10-BC3D5A3DCB10-BCDA9DCB10-2A8D5A10-3A5D-2D4A10-2A6D-2D4A10-2AD5A-6A10-BCD5E-A3DCB10-B7F-5F4(B10-B2G5E-4EO)B10-BO6E-4ECB10-B4HMHM2H2N2HB10-B6-J6-B86-I28-I20-13B12-B2A8-C6(B12-B9A2C)2(B12-B9D2C)B12-B3D5A2DCB12-B10DCB12-4A5D4A2(12-4A6D3A)12-AD11A12-BD5E2A3DB12-B11F4(B12-BG8E2D)B12-BO9EOB12-B6HMN3HB12-B11-B115-2I21-11B2(14-2BA3-3A2B)4(14-2BC3-3A2B)14-2BC2-4A3(2B14-2BC2-4D)2B14-2BC-5D2B14-3A5D3A2(14-3A6D2A)14-2AC5D3A14-2BC6D2B14-2BC6F2B14-2BC4(5EO2B14-2BO)5EO2B14-2B7H2B14-2B7-2B91-2(I24-)12(4A3B18-)4(7A18-)8(4A3B18-)4A3B93-P43-
