model
size = 25 30 19, scale = 0.05, origin = -y
material deform = 1, fade = true, lighting = smooth, roughness = 0.3, metalness = 0.6
  colors = A:#E00 B:#EEE C:#FF0 D:#CF3 E:#000 F:#06F G:#00C H:#251505 I:#BBB J:#CC6 K:#CF0 L:#939 M:#960 N:#1C0900 O:#AAAAB9 P:#AAA Q:#00F R:#888 S:#FCF
voxels
6-12(3A4B18-)4(7B18-)8(3A4B18-)3A4B141-11A2(14-2A5B2C2A)14-2AB3-B-8(C2A14-2AB5-)C2A4(14-2BC5-C2B)14-2AB5-C2A14-2AE5(5-C2A14-2AO)4D2C2A14-2A3H2N2H2A14-2A7-2A138-13A2(12-A11BA)12-AB4-3B2-BA12-AB4-2B3-7(BA12-AB9-)BA2(12-2B9-CB)2(12-2B6-B3CB)12-AB7-3BA12-AE7-3EA12-AG7-D3(2EA12-AG8-)2EA12-AO7DC2EA12-A3HNM2NM2HNA12-A11-A136-15A2(10-AC12BA)10-AC8B2-2BA10-A8B4-5(BA10-A7B5-)2(BA10-AB2-4B5-)BA2(10-BC2-4B5-CB)10-BC2-9BCB10-BC2-4B-B-2BCB10-AB2-4B2-3B2A10-AE2(2-4E)A10-AG2-4D2-D3(3EA10-AG2-4D2-K)3EA10-AO8DK3EA10-A5HM2H2NH2NA10-A6-J6-A134-17A2(8-A7C-7CA)8-A13C-CA8-A10B4-4(CA8-A8B6-)3(2A8-A8B6-)2A2(8-B2C6B6-CB)8-B2C7B-3B2CB8-B2C7B2-2B2CB8-A9B-3B3A8-A9E-5EA8-A4G7D3(4EA8-A4G6DK)4EA8-AO9DK4EA8-AH3NM4HMHNH2NA8-A6-J-J6-A42-P90-17A2(8-A15CA)8-A12C8(3-A8-A12B)3-A8-B2C10B3-B8-B2C10B2-CB8-B2C6B-B-2B-CB8-B2C7B2-2B2CB8-A9B-3B3A8-A9E-4E-A8-A4G7D3(4EA8-A4G6DK)4EA8-A10DK4EA8-A2H2M4H2MHN2HNA8-A5-2(J-)J5-A42-RI19-I4-I63-19A2(6-A17CA)6-A13C5(3-CA6-A13B)3(3-2A6-A13B)3-2A2(6-B3C10B3-CB)6-B3C6B-4BC-CB6-B3C7B2-2B3CB6-A10B-3B4A6-A10E-6EA6-A5G4B3D3(5EA6-A5G4B2DK)5EA6-AO10DK5EA6-AH2NMHM3HMHMNM2HNA6-A5-3(J-)J5-A16-R24-I20-RPR3-I62-19A3(6-A17CA)2(6-A14B3CA)6-A2(-13B3C8A)3(-13B4A5-2A)-13B4A5-AB2(-2C11B2A-B5-2B)-2C6B-B-2B2A-B5-2B-2C7B3-B2A-B5-BA-9B2(-B)2A-A5-2A-9E-E-3E-8A-3GD4B3D4E-F7A2(-3GD4B2DK4E-A6-A)-3GD4B2DK5EA6-A-10DK5EA6-AHNHM3HM8HNA6-A4-4(J-)J4-A15-3P21-2P-2I19-2PI2-PI18-P5-P36-19A5(6-A17FA)6-A-17F7A-5CK2D4A4KF7A2(-2A2CA3D4C5A5-2A)-5A3D2C7A5-2A-5A3D2C7A5-AB2(-15A-B5-2B)-8A-6A-B5-2B-5A3DC3-3C-B5-BA-5A3D2(C-)3C-A5-2A-5E4D-D-3D-8A-3GD4B7D-F7A2(-3GD4B2DK4D-A6-A)-3GD4B2DK5DA6-A-10D2KD3BA6-A2H2M2HM3HM5HNA6-A3-5(J-)J3-A15-3I68-I44-B17A5(B6-B17F)B6-B-16F8B-5CK2D4A4K8B2(-2A2CA3D4C4AB5-2B)2(-5A3D2C6AB5-2B)3(-15A-B5-2B)2(-5A3D7C-B5-2B)-5E3D4B3D-A7B-3GD4B7D-A7B2(-3GD4B2DK4D-B6-B)-3GD4B2DK5DB6-B-10D2KD4B6-BHM6H2M4HM2NB6-B2-6(J-)J2-B15-2IP21-2I-2I19-2I2-3I16-R-I4-2I18-I17-19A5(6-A6C8A3BA)6-A-5CK4DKA4KC7A-17C7A2(-2A2CA7C5A5-2A)-4A2-2A2C7A5-2A-4A6-7A5-AB-4A6-A-3A2(-B5-2B-15A)-B5-2B-5A3D7C-B5-BA-5A3D7C-A5-2A-5E3D3B3LD-8A-3G8D3LD-F7A2(-3G8D3LD-A6-A)-3G8D3L2DA6-A-11D2L3BA6-A6HM9HNA6-A3-5(J-)J3-A40-3I21-PI-2I16-3PSP3-2I14-2P-2I5-I11-19A5(6-A6C8A3BA)6-A-5CK4DKAK4B7A-16CB7A2(-2A2CA7C5A5-2A)-4A2-2A2C7A5-2A-4A6-7A5-AB-2C2A6-A2-2A-B5-2B-15A-B5-2B-2C13A-B5-2B-2C2A4D7C-B5-BA-3A5D7C-A5-2A-5E3D3B2(3LD-F7A-3G8D)2(3LD-A6-A-3G8D)3L2DA6-A-11D2L3BA6-A8HM3HMHMNHA6-A4-4(J-)J4-A40-3I42-P2I43-19A7(6-A16CBA)2(6-4A10C5A)6-10A2C7A6-19A6-B3C8A6CB6-B4C8A5CB6-B3C9A5CB6-B3C2A4D8CB6-5A5D8CA6-A6E2D8AE4(A6-A4G8D3LDO)A6-AO11D2L3BA6-A5H2M5HMN2HNA6-A5-3(J-)J5-A40-3I21-PI-2I16-5P3-2I14-2P-2P5-I12-17A8-A12C3QA8-A12CQ2BA8-A12C3Q3(A8-A15C)A8-A13C2B2(A8-3A10C3B)A8-9A2C6A8-17A8-B2C8A5CB8-B3C8A4CB8-B2C9A4CB8-B2C2A4D7CB8-4A5D2C6A8-A5E2D9A4(8-AB2G12DA)8-A13D2BA8-AMH2MHM3HM2H2MHA8-A5-2(J-)J5-A110-R2-IP18-17A7(8-A11C2B-BA)2(8-3A9C2B-BA)8-2A-6A2C3A-2A8-2A-11A-2A8-BC-8A3C-CB8-BC-C8A2C-CB8-BC-9A2C-CB8-B2C2A4D5C-CB8-2A-A5D2C3A-2A8-AE-11E-E3(A8-AB-G10D-O)A8-AB2G10D-OA8-AOC11D-BA8-A2H2(MH)M2HMNM3HA8-A6-J-J6-A85-I24-P3-I19-15A4(10-A10C3BA)4(10-AB9C3BA)10-AB2C8-2BA10-AB3A5C3ABA10-ABAC9ABA10-BC8A4CB10-B2C5A-2A3CB10-BC6A-2A3CB10-BCA5C-5CB10-ABA5D-C3ABA10-A7E-5E4(A10-A2G5D-4DO)A10-AO6D-4DBA10-A4HMHM2H2N2HA10-A6-J6-A86-I28-I20-13A12-A2C8-B6(A12-A9C2B)2(A12-10A2B)A12-4A5C2ABA12-11ABA12-B3C5A3C2(B12-B3C6A2C)B12-BA10CB12-2A5D2C4A12-A11EA4(12-AG8D3A)12-AO9DOA12-A6HMN3HA12-A11-A115-2I21-11A2(14-2AC3-3C2A)4(14-2AB3-3C2A)14-2AB2-4C2A3(14-2AB2-6A)14-2AB-7A14-2BC5AC2(2B14-2BC6A)2B14-3B5AC2B14-2AB8A14-2AB6E2A14-2AB4(5DO2A14-2AO)5DO2A14-2A7H2A14-2A7-2A91-2(I24-)12(4B3A18-)4(7B18-)8(4B3A18-)4B3A93-P43-
