model
size = 25 30 19, scale = 0.05, origin = -y
material deform = 1, fade = true, lighting = smooth, roughness = 0.3, metalness = 0.6
  colors = A:#E00 B:#EEE C:#FF0 D:#CF3 E:#30F F:#000 G:#06F H:#00C I:#251505 J:#BBB K:#CC6 L:#CF0 M:#939 N:#960 O:#1C0900 P:#AAAAB9 Q:#AAA R:#00F S:#888 T:#FCF
voxels
6-12(3AB2EB18-)4B2EB2(18-7E)18-4B9(2EB18-3AB)2EB141-11A2(14-2A5B2C2A)14-2AB3-B-8(C2A14-2AB5-)C2A14-2BC5-C2B2(14-3E5-3E)14-2BC5-C2B14-2AB5-C2A14-2AF5(5-C2A14-2AP)4D2C2A14-2A3I2O2I2A14-2A7-2A138-13A2(12-A11BA)12-AB4-3B2-BA12-AB4-2B3-7(BA12-AB9-)BA12-2B9-CB12-2E9-2E12-2E6-B2C2E12-2B6-B3CB12-AB7-3BA12-AF7-3FA12-AH7-D3(2FA12-AH8-)2FA12-AP7DC2FA12-A3ION2ON2IOA12-A11-A136-15A2(10-AC12BA)10-AC8B2-2BA10-A8B4-5(BA10-A7B5-)2(BA10-AB2-4B5-)BA10-BC2-4B5-CB10-2E2-2E2B5-2E10-2E2-2E6B3E10-BC2-4B-B-2BCB10-AB2-4B2-3B2A10-AF2(2-4F)A10-AH2-4D2-D3(3FA10-AH2-4D2-L)3FA10-AP8DL3FA10-A5IN2I2OI2OA10-A6-K6-A134-17A2(8-A7C-7CA)8-A13C-CA8-A10B4-4(CA8-A8B6-)3(2A8-A8B6-)2A8-B2C6B6-CB8-7E2B6-2E8-7E3B-2B4E8-B2C7B2-2B2CB8-A9B-3B3A8-A9F-5FA8-A4H7D3(4FA8-A4H6DL)4FA8-AP9DL4FA8-AI3ON4INIOI2OA8-A6-K-K6-A42-Q90-17A2(8-A15CA)8-A12C8(3-A8-A12B)3-A8-B2C10B3-B8-7E5BE2-2E8-7E2B2(-B)E-2E8-B2C7B2-2B2CB8-A9B-3B3A8-A9F-4F-A8-A4H7D3(4FA8-A4H6DL)4FA8-A10DL4FA8-A2I2N4I2NIO2IOA8-A5-2(K-)K5-A42-SJ19-J4-J63-19A2(6-A17CA)6-A13C5(3-CA6-A13B)3(3-2A6-A13B)3-2A6-B3C10B3-CB6-8E5BE3-2E6-8E2B-3B2E-2E6-B3C7B2-2B3CB6-A10B-3B4A6-A10F-6FA6-A5H4B3D3(5FA6-A5H4B2DL)5FA6-AP10DL5FA6-AI2ONIN3ININON2IOA6-A5-3(K-)K5-A16-S24-J20-SQS3-J62-19A3(6-A17CA)2(6-A14B3CA)6-A2(-13B3C8A)3(-13B4A5-2A)-13B4A5-AB-2C11B2A-B5-BE-2C9B4E-E5-2E-2C6B2(-B)3E-E5-EB-2C7B3-B2A-B5-BA-9B2(-B)2A-A5-2A-9F-F-3F-8A-3HD4B3D4F-G7A2(-3HD4B2DL4F-A6-A)-3HD4B2DL5FA6-A-10DL5FA6-AIOIN3IN8IOA6-A4-4(K-)K4-A15-3Q21-2Q-2J19-2QJ2-QJ18-Q5-Q36-19A5(6-A17GA)6-A-17G7A-5CL2D4A4LG7A2(-2A2CA3D4C5A5-2A)-5A3D2C7A5-2A-5A3D2C7A5-AB-15A-B5-BE-11A4E-E5-2E-8A-3A3E-E5-EB-5A3DC3-3C-B5-BA-5A3D2(C-)3C-A5-2A-5F4D-D-3D-8A-3HD4B7D-G7A2(-3HD4B2DL4D-A6-A)-3HD4B2DL5DA6-A-10D2LD3BA6-A2I2N2IN3IN5IOA6-A3-5(K-)K3-A15-3J68-J44-B17A5(B6-B17G)B6-B-16G8B-5CL2D4A4L8B2(-2A2CA3D4C4AB5-2B)2(-5A3D2C6AB5-2B)3(-15A-B5-2B)2(-5A3D7C-B5-2B)-5F3D4B3D-A7B-3HD4B7D-A7B2(-3HD4B2DL4D-B6-B)-3HD4B2DL5DB6-B-10D2LD4B6-BIN6I2N4IN2OB6-B2-6(K-)K2-B15-2JQ21-2J-2J19-2J2-3J16-S-J4-2J18-J17-19A5(6-A6C8A3BA)6-A-5CL4DLA4LC7A-17C7A2(-2A2CA7C5A5-2A)-4A2-2A2C7A5-2A-4A6-7A5-AB-4A6-A-3A-B5-BE-12A3E-E5-2E-11A4E-E5-EB-5A3D7C-B5-BA-5A3D7C-A5-2A-5F3D3B3MD-8A-3H8D3MD-G7A2(-3H8D3MD-A6-A)-3H8D3M2DA6-A-11D2M3BA6-A6IN9IOA6-A3-5(K-)K3-A40-3J21-QJ-2J16-3QTQ3-2J14-2Q-2J5-J11-19A5(6-A6C8A3BA)6-A-5CL4DLAL4B7A-16CB7A2(-2A2CA7C5A5-2A)-4A2-2A2C7A5-2A-4A6-7A5-AB-2C2A6-A2-2A-B5-BE-12A3E-E5-2E-2C9A4E-E5-EB-2C2A4D7C-B5-BA-3A5D7C-A5-2A-5F3D3B2(3MD-G7A-3H8D)2(3MD-A6-A-3H8D)3M2DA6-A-11D2M3BA6-A8IN3ININOIA6-A4-4(K-)K4-A40-3J42-Q2J43-19A7(6-A16CBA)2(6-4A10C5A)6-10A2C7A6-19A6-B3C8A6CB6-E4C8AC5E6-6E7A6E6-B3C2A4D8CB6-5A5D8CA6-A6F2D8AF4(A6-A4H8D3MDP)A6-AP11D2M3BA6-A5I2N5INO2IOA6-A5-3(K-)K5-A40-3J21-QJ-2J16-5Q3-2J14-2Q-2Q5-J12-17A8-A12C3RA8-A12CR2BA8-A12C3R3(A8-A15C)A8-A13C2B2(A8-3A10C3B)A8-9A2C6A8-17A8-B2C8A5CB8-5E7AC4E8-5E7A5E8-B2C2A4D7CB8-4A5D2C6A8-A5F2D9A4(8-AB2H12DA)8-A13D2BA8-ANI2NIN3IN2I2NIA8-A5-2(K-)K5-A110-S2-JQ18-17A7(8-A11C2B-BA)2(8-3A9C2B-BA)8-2A-6A2C3A-2A8-2A-11A-2A8-BC-8A3C-CB8-2E-2E7ACE-2E8-2E-2E7A2E-2E8-B2C2A4D5C-CB8-2A-A5D2C3A-2A8-AF-11F-F3(A8-AB-H10D-P)A8-AB2H10D-PA8-APC11D-BA8-A2I2(NI)N2INON3IA8-A6-K-K6-A85-J24-Q3-J19-15A4(10-A10C3BA)4(10-AB9C3BA)10-AB2C8-2BA10-AB3A5C3ABA10-ABAC9ABA10-BC8A4CB10-4E4A-2AC3E10-4E4A-2A4E10-BCA5C-5CB10-ABA5D-C3ABA10-A7F-5F4(A10-A2H5D-4DP)A10-AP6D-4DBA10-A4ININ2I2O2IA10-A6-K6-A86-J28-J20-13A12-A2C8-B6(A12-A9C2B)2(A12-10A2B)A12-4A5C2ABA12-11ABA12-B3C5A3CB12-3EC6AC2E12-3EC6A3E12-BA10CB12-2A5D2C4A12-A11FA4(12-AH8D3A)12-AP9DPA12-A6INO3IA12-A11-A115-2J21-11A2(14-2AC3-3C2A)4(14-2AB3-3C2A)14-2AB2-4C2A3(14-2AB2-6A)14-2AB-7A14-2BC5AC2B14-11E14-2EC6A2E14-3B5AC2B14-2AB8A14-2AB6F2A14-2AB4(5DP2A14-2AP)5DP2A14-2A7I2A14-2A7-2A91-2(J24-)12(B2EB3A18-)B2E4B2(18-7E)18-B2E4B9(18-B2EB3A)93-Q43-
