model
size = 19 30 25, scale = 0.05, origin = -y
material deform = 1, fade = true, lighting = smooth, roughness = 0.3, metalness = 0.6
  colors = A:#E00 B:#EEE C:#CF3 D:#00C E:#FF0 F:#000 G:#251505 H:#BBB I:#CF0 J:#CC6 K:#939 L:#960 M:#AAAAB9 N:#1C0900 O:#AAA P:#888 Q:#FCF
voxels
6-8(3AB3A12-)10(3DB3D12-)6(7B12-)7B105-6(11A8-)2(3A5-3A8-)10(3D5-3D8-)4(2BD5-D2B8-)2BM5-M2B8-2B7G2B8-2B7-2B102-8(13A6-)6DA8(6D6-4D3A)6D6-4D3F6D4(6-3B9DB)6-BM9CMB6-BGL3GLG2N2GB6-B11-B100-8(15A4-)7DA6DB4-B4D5(3A6DB4-BD-2D)3A6DB4-B4D2(3A6DB4-BD-2D)3F6D3(B4-BD-11D)B4-B13DB4-BME10CMB4-B7GL2(GN)GB4-B6-J6-B62-2H18-OPO-O11-8(17A2-)B15AB2-15A7(DA2-14A-)DA2-A13F-DA4(2-B13D-DB)2-BM13CMB2-B2G2L4G4LN2GB2-B6-J-J6-B64-3O16-O-O11-3(17A2-)4(15A-A2-)B14A-B2-D14A-D2-15A-5(A2-14A2-)A2-A2E11A2(2-A)6C7A2(2-A)13F2-A2-B4(10C3D2(2-B))15CB2-B3GL7GLN2GB2-B5-2(J-)J5-B64-OHOPH27-21A-51A2(-18A)-2AB15A-ABD15A-A3D14A-A2D2A-12A-AD7A2-7A-9A2-7A-2AB6A2-7A-AB16A-18A-4A2E4C8A-4A6C8A-4A14F-2AB4(M7C4B3C-M2B)M15CM2B3GLGL5GLGL3G2B5-3(J-)J5-B50-PH5-OH4-OHO11-2H2-HO-H10-20A2-17A-18A-14A2-2A-14A2-AB-14A2-BD2(-14A2-2D)-14A2-D2(A-)12A2(2-2A-5A2-7A)2-AB6A2-4A3E2-B13A3E2-14A3E2-ABA2E9C3E2-B2A14C2-3A3F6C5F2-AB4(8C4B3C2-2B)17C2B2GLG2L2(GL)5GNG2B4-4(J-)J4-B47-H-2O12-O-QH-O9-3H2O-2H9-20A2-8A2(E8A-9A)E4A2-AB-9AE4A2-BD-9AE4A2-2D-5A2C2AE4A2-2D-5A2E2CE4A2-2D-5A2E3C4A2-D2(A-)3A2E3C4A2-2A-7A3C4A2-8A2-3C4A2-AB6A2-4A3E2-B13A3E2-14A3E2-ABA2E9C3E2-B2A14C2-3A3F6C5F2-AB4(8C4B3C2-2B)17C2B3GL6GL3G2LG2B3-5(J-)J3-B28-H-O13-O-OH-OP12-O-O29-20A2-8AE2A-5A-9AE2A-4AB-9AE5A-BD-9AE5A-2D-9AE4A2-2D-5A4CE4A2-2D6A2E2CE4A2-3D5A2E3C4A2-2D2A-3A2E3C4A2-DB8A2(3C4A2-2B6A2-)4A2(3E2-2B12A)3E2-2BA2E9C3E2-2BA14C2-B2A3F2A4C5F2-AB4(8C4B3C2-2B)17C2B2GL3GLGL6G2N2B2-6(J-)J2-B9-2HO13-4H-O13-H-H2-H45-21A-8A2(E18A)E7AB10AE5A-BD10AE2A4-2D6A2C2AE2A4-2D6A2E2AE2A4-3D5A5E2A4-D3A-3A2(5E2A4-8A)2-3E2A4-AB6A2-4AE4-B3A-9AE4-4A-6A4-2E2-ABAE-11E3-B2AE-9E2C3-3AF-F2A3BC4F3-AB4(2C-11C3-2B)2C-14C2BGL6GL2G2L2G2N2B3-5(J-)J3-B9-2HOP12-3H3-HPO61-21A-8A2(E18A)E5A-12AE3A3-AB10AE2A4-BD6A2C2AE2A4-2D6A2E2AE2A4-3D5A5E2A4-D3A-3A2(5E2A4-8A)2-3E2A4-AB6A2-5A4-B14A4-15A-2A-ABA8E5-2E-B2A8E8-3A3F2A3B8-AB4(14C3-2B)17C2BGNG2L4GL2G2LNLG2B4-4(J-)J4-B9-OHO13-4H2(-H)11-H-2H3-H43-21A-8A2(E18A)E3A2-2(13AE2A3-)2AB6A2I2AE2A3-ABD6A2E2AE2A3-A3D5A5E2A3-A2D2A-3A5E2A3-AD14A3-16A3-2AB13A3-AB14A3-13A-A-11A4E6-2E7A7E4CM3A3F2A3BC6F2ABM15C3(M2BM7C7I-)M2BM7C7IEM2B2G2N7GL2GN2G2B5-3(J-)J5-B28-H-H13-H-2H-OH12-H-2H29-17A2-A-8A2(E6A2-10A)E3A2-3(A2-10AE2A3-)A2-B5A2E2AE2A3-B2-D5A5E2A3-D2-2A-3A5E2A2(3-A2-13A)3-A2-6A2-5A3-A2-13A3-A2-17A2(2-5A4E2-6A)2-A3F2A2KB2-5FA4(2-BA3C3K2C6FB)2-B4C3K2I6FB2-BGNLG2L4G3N2GB2-B5-2(J-)J5-B48-H-H13-H-2H-O13-H-H11-17A2(2-10AE6A)2-10AE2-4A2(2-10AE4-2A)2-6A4IE4-2A2-6A2E2IE4-2A2-B10A4-AB3(2-11A4-2A)2-6A-4A4-2A2-11A4-2A2-17A2(2-5A5E7A)2-A3F2A2K2C6FA4(2-BA3C3K2C6FB)2-BM3C3K2C6FB2-B3GLN5GL2G2NB2-B6-J-J6-B98-15A2(4-2A-2A4BE5A)3(4-2A-2A4BE3-2A)4-2A-2AB3IE3-2A4-2A-2A2E2IE3-2A4-2D6(-2D5A3-AB4-BD)-2D6A-2A2(B4-BD-2D4E5A)B4-BD-2D2K4(2C5FB4-BM-C3K)2C5FB4-2B-6B5FB4-B2G2(LG)L4G2NB4-B6-J6-B100-13A2(6-4A4BE4A)3(6-4A4BE2-2A)6-4AB3IE2-2A6-4A2E2IE2-2A5(6-4D5A2-2D)2(6-4D5A-3D)2(6-4D4EA4D)6-4D4CFD-2D4(6-BM6C4FB)6-8B4FB6-B3GNGN3G2NB6-B11-B102-11A5(8-3A4BE3A)8-3AB3IE3A8-3A2E2IE3A4(8-3D5A3D)6(8-3D5-3D)3(8-2BM5-F2B)8-2BM4C2F2B8-7B2F2B8-2BNG5N2B8-2B7-2B105-6(A5BA12-)2(2AE4A12-)9(D5BD12-)D5AD12-BAM3AB6(12-7B)222-5(5B14-5B185-5B14-5B337-)12(5B14-)5B216-
