model
size = 25 30 19, scale = 0.05, origin = -y
material deform = 1, fade = true, lighting = smooth, roughness = 0.3, metalness = 0.6
  colors = A:#E00 B:#FF0 C:#CF3 D:#EEE E:#000 F:#251505 G:#00C H:#BBB I:#CF0 J:#CC6 K:#939 L:#960 M:#1C0900 N:#AAA O:#AAAAB9 P:#00F Q:#888 R:#FCF
voxels
6-3(7A18-)7(A5DA18-)5(7D18-)7(A5DA18-)2(7A18-)7A141-11A2(14-2A7B2A)14-2AB3-B-4(B2A14-2AB5-)B2A2(14-3A5-3A)5(14-3D5-3D)14-3A5-B2A14-3A5-O2A14-2AE5-E4(2A14-2AO5-O)2A14-2AO5CO2A14-2A3F2M2F2A14-2A7-2A138-13A2(12-A11BA)12-AB4-3B2-BA12-AB4-2B3-3(BA12-AB9-)BA2(12-2A9-2A)4(12-2D9-2D)12-2D6-A4D12-2A6-2B3A12-2A7-C3A12-AE7-3EA12-AG7-C3(2EA12-AG8-)2EA12-AO7CB2EA12-A3FML2ML2FMA12-A11-A136-15A2(10-A13BA)10-A9B2-2BA10-A8B4-3(BA10-A7B5-)BA2(10-8A5-2A)4(10-DA2-A3B5-2D)10-DA2-A4BA5D10-2A2-A3B-B-4A10-2A2-A3C2-C4A10-AE2(2-4E)A10-AG2-4C2-C3(3EA10-AG2-4C2-I)3EA10-AO8CI3EA10-A5FL2F2MF2MA10-A6-J6-A134-17A2(8-A7B-7BA)8-A13B-BA8-A10B4-3(BA8-A8B6-)BA2(8-9A6-2A)4(8-6A3B6-2A)8-6A4B-6A8-6A4B2-5A8-6A4C-C5A8-A9E-5EA8-A4G7C3(4EA8-A4G6CI)4EA8-AO9CI4EA8-AF3ML4FLFMF2MA8-A6-J-J6-A42-N90-17A2(8-A15BA)5(8-A12B3-A)2(8-13A3-A)2(8-6A5B2A3-A)8-6A4B3A3-A8-6A4B3A2-2A8-6A3B-A2(-2A)8-6A4B2-5A8-6A4C-C5A8-A9E-4E-A8-A4G7C3(4EA8-A4G6CI)4EA8-A10CI4EA8-A2F2L4F2LFM2FMA8-A5-2(J-)J5-A42-QH19-H4-H63-19A2(6-A17BA)5(6-A13B3-BA)2(6-14A3-2A)2(6-7A3C2B2A3-2A)2(6-14A3-2A)6-10A-5A-2A6-7A3CB2-6A6-7A3CB-B6A6-A10E-6EA6-A5G4D3C3(5EA6-A5G4D2CI)5EA6-AO10CI5EA6-AF2MLFL3FLFLML2FMA6-A5-3(J-)J5-A16-Q24-H20-QNQ3-H62-19A5(6-A17BA)6-A2(-16B8A)2(-2A2BA3C4B5A5-2A)2(-5A3C2B7A5-2A)2(-15A-A5-2A)-8A-A-4A-A5-2A-5A3CB3-3A-A5-2A-5A3C2(B-)3A-A5-2A-9E-E-3E-8A-3GC4D3C4E-8A2(-3GC4D2CI4E-A6-A)-3GC4D2CI5EA6-A-10CI5EA6-AFMFL3FL8FMA6-A4-4(J-)J4-A15-3N21-2N-2H19-2NH2-NH18-N5-N36-19A5(6-A6B8A3DA)6-A-5BIAC4A4I8A-5BI2C4A4I8A2(-2A2BA3C4B5A5-2A)2(-5A3C2B7A5-2A)2(-15A-A5-2A)-8A-6A-A5-2A-5A3CB3-3B-A5-2A-5A3C2(B-)3B-A5-2A-5E4C-C-3C-8A-3GC4D7C-8A2(-3GC4D2CI4C-A6-A)-3GC4D2CI5CA6-A-10C2IC3DA6-A2F2L2FL3FL5FMA6-A3-5(J-)J3-A15-3H68-H44-19A5(6-A6B8A3DA)6-A-5BIAC4A4I8A-5BI2C4A4I8A2(-2A2BA3C4B5A5-2A)2(-5A3C2B7A5-2A)3(-15A-A5-2A)2(-5A3C7B-A5-2A)-5E3C4D3C-8A-3GC4D7C-8A2(-3GC4D2CI4C-A6-A)-3GC4D2CI5CA6-A-10C2IC3DA6-AFL6F2L4FL2MA6-A2-6(J-)J2-A15-2HN21-2H-2H19-2H2-3H16-Q-H4-2H18-H17-19A5(6-A6B8A3DA)6-A-5BI4CIA4IB7A-17B7A2(-2A2BA7B5A5-2A)-4A2-2A2B2(7A5-2A-4A6-)A-3A2(-A5-2A-15A)2(-A5-2A-5A3C7B)-A5-2A-5E3C3D3KC-8A-3G8C3KC-O7A2(-3G8C3KC-A6-A)-3G8C3K2CA6-A-11C2K3DA6-A6FL9FMA6-A3-5(J-)J3-A40-3H21-NH-2H16-3NRN3-2H14-2N-2H5-H11-19A5(6-A6B8A3DA)6-A-5BI4CIAI3D8A-16B8A2(-2A2BA7B5A5-2A)-4A2-2A2B2(7A5-2A-4A6-)A2-2A2(-A5-2A-15A)-A5-2A-4A4C7B-A5-2A-3A5C7B-A5-2A-5E3C3D2(3KC-8A-3G8C)2(3KC-A6-A-3G8C)3K2CA6-A-11C2K3DA6-A8FL3FLFLMFA6-A4-4(J-)J4-A40-3H42-N2H43-19A7(6-A16BDA)2(6-4A10B5A)6-10A2B7A4(6-19A)6-6A4C8BA6-5A5C8BA6-A6E2C8AE4(A6-A4G8C3KCO)A6-AO11C2K3DA6-A5F2L5FLM2FMA6-A5-3(J-)J5-A40-3H21-NH-2H16-5N3-2H14-2N-2N5-H12-17A8-A12B3PA8-A12BP2DA8-A12B3P3(A8-A15B)A8-A13B2D2(A8-3A10B3D)A8-9A2B6A4(8-17A)8-5A4C2B6A8-4A5C2B6A8-A5E2C9A4(8-AD2G12CA)8-A13C2DA8-ALF2LFL3FL2F2LFA8-A5-2(J-)J5-A110-Q2-HN18-17A7(8-A11B2D-DA)2(8-3A9B2D-DA)8-2A-6A2B3A4(-2A8-2A-11A)-2A8-5A4C2B3A-2A8-2A-A5C2B3A-2A8-AE-11E-E3(A8-AD-G10C-O)A8-AD2G10C-OA8-AOB11C-DA8-A2F2(LF)L2FLML3FA8-A6-J-J6-A85-H24-N3-H19-15A7(10-A10B3DA)10-2A9B3DA10-2A2B8-2DA10-5D5B5D2(10-6D3A6D)2(10-6D2A-6D)10-A5D2B-5DA10-3A5C-B5A10-A7E-5E4(A10-A2G5C-4CO)A10-AO6C-4CDA10-A4FLFL2F2M2FA10-A6-J6-A86-H28-H20-13A12-A2B8-D5(A12-A9B2D)A3(12-13A)12-4D5A3(4D12-5D4A)4D12-4D6A3D7(12-13A)12-AO9COA12-A6FLM3FA12-A11-A115-2H21-11A6(14-2AB3-3B2A)3(14-3A2-6A)14-3D2-3A3D14-3D-2(4A3D14-4D)4A3D14-3D6A2D8(14-11A)14-2A7F2A14-2A7-2A91-2(H24-)3(7A18-)7(A5DA18-)5(7D18-)7(A5DA18-)2(7A18-)7A93-N43-
