model
size = 25 30 19, scale = 0.05, origin = -y
material deform = 1, fade = true, lighting = smooth, roughness = 0.3, metalness = 0.6
  colors = A:#EEE B:#009 C:#FF0 D:#E00 E:#CF3 F:#000 G:#06F H:#30F I:#00C J:#251505 K:#BBB L:#CC6 M:#CF0 N:#939 O:#960 P:#1C0900 Q:#AAAAB9 R:#AAA S:#00F T:#888 U:#FCF
voxels
6-12(3BA2DA18-)4A2DA2(18-7D)18-4A9(2DA18-3BA)2DA141-11B2(14-2B5A2C2B)14-2BA3-A-8(C2B14-2BA5-)C2B14-2AC5-C2A2(14-2DH5-H2D)14-2AC5-C2A14-2BA5-C2B14-2BF5(5-C2B14-2BQ)4E2C2B14-2B3J2P2J2B14-2B7-2B138-13B2(12-B11AB)12-BA4-3A2-AB12-BA4-2A3-7(AB12-BA9-)AB12-2A9-CA12-DH9-HD12-DH6-A2CHD12-2A6-A3CA12-BA7-3AB12-BF7-3FB12-BI7-E3(2FB12-BI8-)2FB12-BQ7EC2FB12-B3JPO2PO2JPB12-B11-B136-15B2(10-BC12AB)10-BC8A2-2AB10-B8A4-5(AB10-B7A5-)2(AB10-BA2-4A5-)AB10-AC2-4A5-CA10-DH2-2H2A5-HD10-DH2-2H6A2HD10-AC2-4A-A-2ACA10-BA2-4A2-3ADB10-BF2(2-4F)B10-BI2-4E2-E3(3FB10-BI2-4E2-M)3FB10-BQ8EM3FB10-B5JO2J2PJ2PB10-B6-L6-B134-17B2(8-B7C-7CB)8-B13C-CB8-B10A4-4(CB8-B8A6-)3(DB8-B8A6-)DB8-A2C6A6-CA8-D6H2A6-HD8-D6H3A-2A3HD8-A2C7A2-2A2CA8-B9A-3A2DB8-B9F-5FB8-B4I7E3(4FB8-B4I6EM)4FB8-BQ9EM4FB8-BJ3PO4JOJPJ2PB8-B6-L-L6-B42-R90-17B2(8-B15CB)8-B12C8(3-B8-B12A)3-B8-A2C10A3-A8-D6H5AH2-HD8-D6H2A2(-A)H-HD8-A2C7A2-2A2CA8-B9A-3A2DB8-B9F-4F-B8-B4I7E3(4FB8-B4I6EM)4FB8-B10EM4FB8-B2J2O4J2OJP2JPB8-B5-2(L-)L5-B42-TK19-K4-K63-19B2(6-B17CB)6-B13C5(3-CB6-B13A)3(3-DB6-B13A)3-DB6-A3C10A3-CA6-D7H5AH3-HD6-D7H2A-3A2H-HD6-A3C7A2-2A3CA6-B10A-3A3DB6-B10F-6FB6-B5I4A3E3(5FB6-B5I4A2EM)5FB6-BQ10EM5FB6-BJ2POJO3JOJOPO2JPB6-B5-3(L-)L5-B16-T24-K20-TRT3-K62-19B3(6-B17CB)2(6-B14A3CB)6-B2(-13A3CD7B)3(-13A3DB5-2B)-13A3DB5-BA-2C11A2D-A5-AD-2C9A4H-D5-2D-2C6A2(-A)3H-D5-DA-2C7A3-A2D-A5-AB-9A2(-A)2D-B5-2B-9F-F-3F-D7B-3IE4A3E4F-G7B2(-3IE4A2EM4F-B6-B)-3IE4A2EM5FB6-B-10EM5FB6-BJPJO3JO8JPB6-B4-4(L-)L4-B15-3R21-2R-2K19-2RK2-RK18-R5-R36-19B5(6-B17GB)6-B-17G7B-5CM2E4D4MG7B2(-2D2CD3E4C4DB5-2B)-5D3E2C6DB5-2B-5D3E2C6DB5-BA-15D-A5-AD-11D4H-D5-2D-8D-3D3H-D5-DA-5D3EC3-3C-A5-AB-5D3E2(C-)3C-B5-2B-5F4E-E-3E-D7B-3IE4A7E-G7B2(-3IE4A2EM4E-B6-B)-3IE4A2EM5EB6-B-10E2ME3AB6-B2J2O2JO3JO5JPB6-B3-5(L-)L3-B15-3K68-K44-A17B5(A6-A17G)A6-A-16G8A-5CM2E4D4M8A2(-2D2CD3E4C4DA5-2A)2(-5D3E2C6DA5-2A)3(-15D-A5-2A)2(-5D3E7C-A5-2A)-5F3E4A3E-D7A-3IE4A7E-D7A2(-3IE4A2EM4E-A6-A)-3IE4A2EM5EA6-A-10E2ME4A6-AJO6J2O4JO2PA6-A2-6(L-)L2-A15-2KR21-2K-2K19-2K2-3K16-T-K4-2K18-K17-19B5(6-B6C8D3AB)6-B-5CM4EMD4MC7B-17C7B2(-2D2CD7C4DB5-2B)-4D2-2D2C6DB5-2B-4D6-6DB5-BA-4D6-D-3D-A5-AD-12D3H-D5-2D-11D4H-D5-DA-5D3E7C-A5-AB-5D3E7C-B5-2B-5F3E3A3NE-D7B-3I8E3NE-G7B2(-3I8E3NE-B6-B)-3I8E3N2EB6-B-11E2N3AB6-B6JO9JPB6-B3-5(L-)L3-B40-3K21-RK-2K16-3RUR3-2K14-2R-2K5-K11-19B5(6-B6C8D3AB)6-B-5CM4EMDM4A7B-16CA7B2(-2D2CD7C4DB5-2B)-4D2-2D2C6DB5-2B-4D6-6DB5-BA-2C2D6-D2-2D-A5-AD-12D3H-D5-2D-2C9D4H-D5-DA-2C2D4E7C-A5-AB-3D5E7C-B5-2B-5F3E3A2(3NE-G7B-3I8E)2(3NE-B6-B-3I8E)3N2EB6-B-11E2N3AB6-B8JO3JOJOPJB6-B4-4(L-)L4-B40-3K42-R2K43-19B7(6-B16CAB)2(6-B3D10C4DB)6-B9D2C6DB6-B17DB6-A3C8D6CA6-D4C8DC4HD6-D5H7D5HD6-A3C2D4E8CA6-B4D5E8CB6-B6F2E8DF4(B6-B4I8E3NEQ)B6-BQ11E2N3AB6-B5J2O5JOP2JPB6-B5-3(L-)L5-B40-3K21-RK-2K16-5R3-2K14-2R-2R5-K12-17B8-B12C3SB8-B12CS2AB8-B12C3S3(B8-B15C)B8-B13C2A2(B8-B2D10C3A)B8-B8D2C5DB8-B15DB8-A2C8D5CA8-D4H7DC3HD8-D4H7D4HD8-A2C2D4E7CA8-B3D5E2C5DB8-B5F2E8D4(B8-BA2I12E)B8-B13E2AB8-BOJ2OJO3JO2J2OJB8-B5-2(L-)L5-B110-T2-KR18-17B7(8-B11C2A-AB)2(8-B2D9C2A-AB)8-BD-6D2C3D-DB8-BD-11D-DB8-AC-8D3C-CA8-DH-2H7DCH-HD8-DH-2H7D2H-HD8-A2C2D4E5C-CA8-BD-D5E2C3D-DB8-BF-11F-F3(B8-BA-I10E-Q)B8-BA2I10E-QB8-BQC11E-AB8-B2J2(OJ)O2JOPO3JB8-B6-L-L6-B85-K24-R3-K19-15B4(10-B10C3AB)4(10-BA9C3AB)10-BA2C8-2AB10-BA3D5C3DAB10-BADC9DAB10-AC8D4CA10-D3H4D-2DC2HD10-D3H4D-2D3HD10-ACD5C-5CA10-BAD5E-C3DAB10-B7F-5F4(B10-B2I5E-4EQ)B10-BQ6E-4EAB10-B4JOJO2J2P2JB10-B6-L6-B86-K28-K20-13B12-B2C8-A6(B12-B9C2A)2(B12-B9D2A)B12-B3D5C2DAB12-B10DAB12-A3C5D3CA12-D2HC6DCHD12-D2HC6D2HD12-AD10CA12-BD5E2C3DB12-B11F4(B12-BI8E2D)B12-BQ9EQB12-B6JOP3JB12-B11-B115-2K21-11B2(14-2BC3-3C2B)4(14-2BA3-3C2B)14-2BA2-4C3(2B14-2BA2-4D)2B14-2BA-5D2B14-2AC5DC2A14-2D7H2D14-2DC8D14-3A5DC2A14-2BA6D2B14-2BA6F2B14-2BA4(5EQ2B14-2BQ)5EQ2B14-2B7J2B14-2B7-2B91-2(K24-)12(A2DA3B18-)A2D4A2(18-7D)18-A2D4A9(18-A2DA3B)93-R43-
