model
size = 25 30 19, scale = 0.05, origin = -y
material deform = 1, fade = true, lighting = smooth, roughness = 0.3, metalness = 0.6
  colors = A:#EEE B:#E00 C:#FF0 D:#CF3 E:#006 F:#0A0 G:#251505 H:#00C I:#CF0 J:#AAA K:#BBB L:#AAAAB9 M:#939 N:#CC3 O:#960 P:#1C0900 Q:#F30 R:#040 S:#06C T:#CC6 U:#888 V:#FCF
voxels
6-9(7E18-)9(7A18-)6(7B18-)7B141-11E2(14-2E7B2E)14-2EB3-B-4(B2E14-2EB5-)B2E14-3E5-3E7(14-2AC5-C2A)14-2AL5-L2A14-2AB5-B2A14-3B5-3B3(14-2BL5-L2B)14-2BL5DL2B14-2B3G2P2G2B14-2B7-2B138-13E2(12-E2A9BE)12-EA4-3B2-BE12-EA4-2B3-3(BE12-EA9-)BE12-2E9-2E5(12-2A9-CA)2(12-2A6-4CA)12-2A7-2DLA12-2A7-3BA12-2B7-D2(3B12-BA8-)DLB12-BA8-DLB12-B2A6DCDAB12-B3GPO2PO2GPB12-B11-B136-15E2(10-E3A9BAE)10-E3A6B2-BAE10-EF2A5B4-3(BE10-EH2A4B5-)BE10-8E5-2E10-AH2A5(4C5-CA10-AH2-)10CA10-AH2-4C-C-3CA10-AH2-4D2-3DLA10-AH2(2-4B)A10-2B2-4D2-D2(4B10-BH2-4D2-I)2DLB10-BH2-4D2-I2DLB10-BL2A6DID2AB10-B5GO2G2PG2PB10-B6-N6-B134-17E2(8-E4A3B-5B2AE)8-E4A9B-AE8-E2F2A6B4-3(QE8-E2H2A4B6-)QE8-E2H2A4C6-QE5(8-A2H2A4C6-QA)8-A2H2A5C-4CQA8-A2H2A5C2-3CQA8-A2H2A5D-4DQA8-A2H2A5B-4BQA8-5B7D2(5B8-B2H2A6DI)3DQB8-B2H2A6DI3DQB8-BLD2A6DID3AB8-BGP2GO4GOGPG2PB8-B6-N-N6-B42-J90-17E2(8-E4A9B2AE)8-E4A8B3-E8-E2F4(2A8B3-E8-E2H)2A8C3-E4(8-A2H2A8C3-A)8-A2H2A8C2-QA8-A2H2A4C-C-2C-QA8-A2H2A5C2-3CQA8-A2H2A5D-4DQA8-A2H2A5B-4B-A8-5B7D2(5B8-B2H2A6DI)3DQB8-B2H2A6DI3DQB8-B2D2A6DID3AB8-B8G2OGP2GPB8-B5-2(N-)N5-B42-UK19-K4-K63-19E2(6-E5A9B3AE)6-E5A2(8B3-AE6-E3F2A)F7B3-AE6-E3F2AFIBD4B3-BE6-E3F2AFI2D4B3-BE6-2E2F2AF3D4C3-2E5(6-A3F2AF3D4C3-CA)6-A3F2AF3D-5C-CA6-A3F2AF3DC2-3CQCA6-A3F2AF3DC-4CQCA6-A3F2AF4B-4BQBA6-6BF3A3D2(6B6-B3F2AF3A2DI)3DQLB6-B3F2AF3A2DI3DQLB6-BL2D2A6DI2D3AB6-BG2P2GO3GOGOPO2GPB6-B5-2(N-)T-N5-B16-U24-K20-UJU3-K62-19E3(6-E5A9B3AE)6-E2F3A9B3AE6-E3F2AF8B3AE6-E-2F2AFIBD8BE6-E-2F2AFI2D4B3IBE6-E-2F2AF3D7C2E3(6-A-2F2AF3D8CA)2(6-A-2F2AF3D7C-A)6-A-2F2AF3D-C-4C-A6-A-2F2AF3DC3-3C-A6-A-2F2AF3D2(C-)3C-A6-A-2F2AF4B-B-3B-A6-B-4BF3A3D2(4B-B6-B-2F2AF3A2DI)4D-B6-B-2F2AF3A2DI5DB6-B-2D2A6D2ID3AB6-BGP2GA2GO8GPB6-B4-2(N-)2(T-)N4-B15-3J21-2J-2K19-2JK2-JK18-J5-J36-19E3(6-E5A9B3AE)6-E2F3A9B3AE6-E3F2AF8B3AE6-E-2F2AFIBD4B4IB6AE-2F2AFI2D4B4IB6AE-2F2AF3D4C5E3(5-2A-2F2AF3D8CA)2(5-2A-2F2AF3D7C-A)5-2A-2F2AF3D-6C-A5-2A-2F2AF3DC3-3C-A5-2A-2F2AF3D2(C-)3C-A5-2A-2F2AF4D-D-3D-L6AB-4BF3A7D-L6A2(B-2F2AF3A2DI4D-B6-)B-2F2AF3A2DI5DB6-B-2D2A6D2ID3AB6-B2GOA2GO3GO5GPB6-B3-3(N-)T2(-N)3-B15-3K68-K44-19E3(6-E5A9B3AE)6-E2F3A9B3AE6-E3F2AF8B3AE6-E-2F2AFIBD4B4IB6AE-2F2AFI2D4B4IB6AE-2F2AF3D4C5E3(5-2A-2F2AF3D8CA)5(5-2A-2F2AF3D7C-A)5-2A-2F2AF3D4A3D-L6AB-4BF3A7D-L6A2(B-2F2AF3A2DI4D-B6-)B-2F2AF3A2DI5DB6-B-2D2A6D2ID3AB6-BGO2GA3G2O4GO2PB6-B2-3(N-)2(T-)N-N2-B15-2KJ21-2K-2K19-2K2-3K16-U-K4-2K18-K17-19E3(6-E5A9B3AE)6-E2F3A9B3AE6-E3F2AF8B3AE6-2(E-2F2AFI4DIB4IB6A)E-2F2AF3B4C5E5-2A-2F2AF3B8CA5-2A-2F2A2-2B8CA5-2A-2F2A6-6CA5-2A-2F2A6-C-3C4(-A5-2A-2F2AF3D7C)-A5-2A-2F2AF3D3A3MD-L6AB-4BF6D3MD-L6A2(B-2F2AF6D3MD-B6-)B-2F2AF6D3M2DB6-B-2D2A7D2M3AB6-B3GA2GO9GPB6-B3-5(N-)N3-B40-3K21-JK-2K16-3JVJ3-2K14-2J-2K5-K11-19E3(6-E5A9B3AE)6-E2F3A9B3AE6-E3F2AF8B3AE6-E-2F2AFI4DIBI10AE-2F2AFI4DIB5I6AE-2F2AF3B4C5E5-2A-2F2AF3B8CA5-2A-2F2A2-2B8CA5-2A-2F2A6-6CA5-2A-2F2A6-C2-2C4(-A5-2A-2F2AF3D7C)-A5-2A-2F2AF3D3A3MD-L6AB-4BF6D3MD-L6A2(B-2F2AF6D3MD-B6-)B-2F2AF6D3M2DB6-B-2D2A7D2M3AB6-B3GOA2(3GO)GOPGB6-B4-4(N-)N4-B40-3K42-J2K43-19E3(6-E5A9B3AE)6-E2F3A9B2(3AE6-E3F2AF8B)3AE6-E3F2AF11BE6-2E2F2AF3B4C5E4(6-A3F2AF3B8CA)4(6-A3F2AF3D8CA)6-A3F2AF2D9BA6-6BF6D3M3B3(6-B3F2AF6D3MDLB)6-BL2D2A7D2M3AB6-B4G3O5GOP2GPB6-B5-3(N-)N5-B40-3K21-JK-2K16-5J3-2K14-2J-2J5-K12-17E3(8-E4A9B2AE)8-EF3A4(11BE8-E2H2A)4B4C4E2(8-A2H2A4B7CA)2(8-A2H2A2B2R7CA)4(8-A2H2A4D7CA)8-A2H2A3D8BA8-B2H2A10D2B3(8-B2H2A11DB)8-B2D2A9D2AB8-BO4GO3GO2G2OGB8-B5-2(N-)N5-B110-U2-KJ18-17E3(8-E4A9B-AE)8-EF3A4(9B-BE8-E2H2A)4B4CE-2E8-A2H2(2A4B5C-CA8-AH-)2A4R5C-CA8-AH-2A2(DR)2(5C-CA8-AH-2A4D)5C-CA8-A2H2(2A4D5C-CA8-AH-)2A9B-BA8-2B-2A9D-2B2(8-BH-2A9D-LB)8-B2H2A9D-LB8-BLC2A9D-AB8-B2G3OGO2GOPO3GB8-B6-N-N6-B85-K24-J3-K19-15E3(10-E3A9BAE)10-EF2(2A10BE10-EH)10A2BE10-EH2A10BE10-EH2A8C3E10-AH2A8-2C3(A10-AH2A10C)3(A10-AH2A4C-5C)A10-AH2A4D-5CA10-AH2A4B-5BA10-2B3(2A4D-4DLB10-BH)2A4D-4DLB10-BL2A4D-4DAB10-B4GOGO2G2P2GB10-B6-N6-B86-K28-K20-13E12-E2A8-B4(E12-E2A9B)E12-E10ABE12-E2A9BE12-E2A7CB2E7(12-3A7C2BA)12-3A4D3C2BA12-3A9BA4(12-B2A7D3B)12-B2A8DLB12-B6GOP3GB12-B11-B115-2K21-11E6(14-2EB3-3B2E)14-2EB2-4B2E14-2JC2-4CJE2(14-JAC2-4CAJ)14-JAC-5C4(AJ14-JA7C)AJ14-JAL3D3CAJ14-11J14-2SL5DL2S14-SBL5DLBS3(14-2BL5DL2B)14-2B7G2B14-2B7-2B91-2(K24-)7(7E18-)7J18-3AB3A2(18-7A18-2ABAB2A18-7A18-2(B2A)B)18-7K18-2E2S3E18-E2BSBEB5(18-7B)93-J43-
