model
size = 25 30 19, scale = 0.05, origin = -y
material deform = 1, fade = true, lighting = smooth, roughness = 0.3, metalness = 0.6
  colors = A:#E00 B:#FF0 C:#CF3 D:#00C E:#009 F:#EEE G:#251505 H:#CF0 I:#AAAAB9 J:#BBB K:#CC6 L:#939 M:#960 N:#1C0900 O:#AAA P:#040 Q:#888 R:#FCF
voxels
6-24(7B18-)7B141-2E7B2A2(14-2E9A)14-2EA3-A-4(3A14-2EA5-)3A8(14-2EB5-B2A)14-2EI5-I2A14-2EA5-3A4(14-2EI5-I2A)14-2EI5CI2A14-2E3G2N2G2A14-2E7-2A138-3E7B3A2(12-E12A)12-EA4-3A2-2A12-EA4-2A3-4(2A12-ED9-)5(BA12-ED9-)B2(A12-ED6-4B)A12-ED7-2CIA12-ED7-4A12-ED7-2C3(IA12-ED8-C)IA12-EI7CBCFA12-E3GNM2NM2GNA12-E11-A136-4E7B4A2(10-EF11AFA)10-EF8A2-AFA10-EF7A4-3(2A10-E3D4A5-)2A2(10-E3D4B5-BA)4(10-ED2-4B5-BA)10-ED2-10BA10-ED2-4B-B-3BA10-ED2-4C2-3CIA10-ED2-4A2-5A10-ED2-4C2-3C3(IA10-ED2-4C2-H2C)IA10-EI8CHC2FA10-E5GM2G2NG2NA10-E6-K6-A134-5E7B5A2(8-E2F5A-5A2FA)8-E2F11A-FA8-E2F8A4-3(2A8-E4D4A6-)2A6(8-E4D4B6-BA)8-E4D5B-5BA8-E4D5B2-4BA8-E4D5C-4CIA8-E4D5A-6A8-E4D10C3(IA8-E4D6CH3C)IA8-EI9CHC3FA8-EG3NM4GMGNG2NA8-E6-K-K6-A42-O90-5E7B5A2(8-E2F11A2FA)2(8-E2F10A3-A)3(8-E4D8A3-A)5(8-E4D8B3-A)8-E4D8B2-BA8-E4D4B-B-2B-BA8-E4D5B2-4BA8-E4D5C-5CA8-E4D5A-4A-A8-E4D10C3(BA8-E4D6CH3C)BA8-E10CHC3FA8-E2G2M4G2MGN2GNA8-E5-2(K-)K5-A42-QJ19-J4-J63-6E7B6A2(6-E3F11A3FA)2(6-E3F10A3-FA)6-E5D8A3-FA6-E5D2HAC4A3-2A6-E5D2H2C4A3-2A6(6-E5DA3C4B3-BA)6-E5DA3C-5B-BA6-E5DA3CB2-5BA6-E5D4CB-6BA6-E5D5A-7A6-E5D4F7C3(IA6-E5D4F2CH4C)IA6-EI10CH2C3FA6-EG2NMGM3GMGMNM2GNA6-E5-3(K-)K5-A16-Q24-J20-QOQ3-J62-6E7B6A4(6-E3F11A3FA)6-E4D10A3FA6-E-3D3HAC9A6-E-3D3H2C4A3H2A4(6-E-3D2A3C8BA)2(6-E-3D2A3C7B-A)6-E-3D2A3C-B-4B-A6-E-3D2A3CB3-3B-A6-E-3D5C2(B-)3B-A6-E-3D6A-A-3A-A6-E-3DC4F7C2(-A6-E-3DC4F2CH4C)-A6-E-3DC4F2CH5CA6-E-10C2HC3FA6-EGNGM3GM8GNA6-E4-4(K-)K4-A15-3O21-2O-2J19-2OJ2-OJ18-O5-O36-6E7B6A4(6-E3F11A3FA)6-E4D10A3FA6-E-3D3HAC4A4HA5BAE-3D3H2C4A4HA5B4(AE-3D2A3C8BA5-)2(AE-3D2A3C7B-A5-)AE-3D2A3C-6B-A5-AE-3D2A3CB3-3B-A5-AE-3D5C2(B-)3B-A5-AE-3DA5C-C-3C-I5BAE-3DC4F7C-I5BA2(E-3DC4F2CH4C-A6-)E-3DC4F2CH5CA6-E-10C2HC3FA6-E2G2M2GM3GM5GNA6-E3-5(K-)K3-A15-3J68-J44-6E7B6A4(6-E3F11A3FA)6-E4D10A3FA6-E-3D3HAC4A4HA5BAE-3D3H2C4A4HA5D4(AE-3D2A3C8BA5-)4(AE-3D2A3C7B-A5-)AE-3D5C7B-A5-AE-3DA4C4F3C-I5DAE-3DC4F7C-I5BA2(E-3DC4F2CH4C-A6-)E-3DC4F2CH5CA6-E-10C2HC3FA6-EGM6G2M4GM2NA6-E2-6(K-)K2-A15-2JO21-2J-2J19-2J2-3J16-Q-J4-2J18-J17-6E7B6A4(6-E3F11A3FA)6-E4D10A3FA6-E-3DHAH4CHA4HA5BAE-3DHAH4CHA4HA5D2(AE-3D5A8BA5-)AE-3DA2-2A8BA5-AE-3DA6-6BA5-AE-3DA6-B-3B3(-A5-AE-3DA4C7B)-A5-AE-3D5C7B-A5-AE-3DA4C3F3LC-I5DAE-3D8C3LC-I5BA2(E-3D8C3LC-A6-)E-3D8C3L2CA6-E-11C2L3FA6-E6GM9GNA6-E3-5(K-)K3-A40-3J21-OJ-2J16-3ORO3-2J14-2O-2J5-J11-6E7B6A4(6-E3F11A3FA)6-E4D10A3FA6-E-3DHAH4CHAH4F5BAE-3DHAH4CHA5H5B2(AE-3D5A8BA5-)AE-3DA2-2A8BA5-AE-3DA6-6BA5-AE-3DA6-B2-2B3(-A5-AE-3DA4C7B)-A5-AE-3D5C7B-A5-AE-3DA4C3F2(3LC-I5BAE-3D8C)2(3LC-A6-E-3D8C)3L2CA6-E-11C2L3FA6-E8GM3GMGMNGA6-E4-4(K-)K4-A40-3J42-O2J43-6E7B6A4(6-E3F2C9A3FA)2(6-E4DC9A3FA)6-E4DC13A5(6-E4D5A8BA)3(6-E4DA4C8BA)6-E4D5C8BA6-E4DA3C10A4(6-E4D8C3LCIA)6-EI11C2L3FA6-E5G2M5GMN2GNA6-E5-3(K-)K5-A40-3J21-OJ-2J16-5O3-2J14-2O-2O5-J12-5E7B5A3(8-E2F2C9A2FA)8-E2F2C3(12A8-E3DC)12A3(8-E3D5A7BA)2(8-E3D3A2P7BA)3(8-E3DA4C7BA)8-E3D5C7BA8-E3DA3C9A4(8-E3D12CA)8-E13C2FA8-EMG2MGM3GM2G2MGA8-E5-2(K-)K5-A110-Q2-JO18-5E7B5A3(8-2EF11A-FA)8-2EF11A3(-2A8-2E2D10A)-2A2(8-2E2D5A5B-BA)8-2E-D5A5B-BA8-2E-DA4P5B-BA8-2E-DA2(CP)2(5B-BA8-2E-DA4C)5B-BA8-2E2DA4C5B-BA8-2E-D5C5B-BA8-2E-D10A-2A3(8-2E-D10C-IA)8-2E2D10C-IA8-2EB11C-FA8-2E3(GM)2GMNM3GA8-E6-K-K6-A85-J24-O3-J19-4E7B4A3(10-3E10AFA)2(10-3E12A)10-3E9F3A10-3E12A10-3E11BA10-3EB8-2B3(A10-3E11B)3(A10-3E5B-5B)A10-3E5C-5BA10-3E5A-6A4(10-3E5C-4CIA)10-3E5C-4CFA10-3E2GMGM2G2N2GA10-E6-K6-A86-J28-J20-3E7B3A12-E2A8-2A3(12-E12A)12-ED11A12-ED9F2A12-ED11A8(12-ED8B3A)12-ED5C3B3A12-ED11A4(12-ED8C3A)12-EI9CIA12-E6GMN3GA12-E11-A115-2J21-2E7B2A6(14-2EA3-5A)14-2EA2-6A3(14-2EB2-4B2A)14-2EB-5B4(2A14-2E7B)2A14-2EI3C3B2A14-2E9A5(14-2EI5CI2A)14-2E7G2A14-2E7-2A91-2(J24-)24(7B18-)7B93-O43-
