model
size = 6 7 6, scale = 0.05, origin = -y
material deform = 1, fade = true, lighting = smooth, roughness = 0.3, metalness = 0.6
  colors = A:#03F B:#03C C:#E70000 D:#800 E:#A00
voxels
2(6-2A4(BCB3A)BCBA)12-2ABCB20ABACBA2-E9-3BC3B3(4A2B)3A2B-2CD4-C3-7C2(4A2C)4A3C3AC2-D2C4-C2-3BC3B2(4A2B)4A4BA2B3-E8-
