model
size = 3 31 6, scale = 0.05, origin = -y
material deform = 1, fade = true, lighting = smooth, roughness = 0.3, metalness = 0.6
  colors = A:#BBB B:#FFFF97 C:#7E5200
voxels
4-A17-A71-A17-A73-3A15-3A13-19(A2-)B-3A-4(C2-)C-3A-5(A2-)15(B2-)2(A2-)B4-3A-4(C2-)C-3A-21(A2-)B7-3A15-3A-20(B2-)B10-
