model
size = 24 20 5, scale = 0.05, origin = -y
material deform = 1, fade = true, lighting = smooth, roughness = 0.3, metalness = 0.6
  colors = A:#FC0 B:#F96 C:#FF0
voxels
389-A12-A418-ABA9-ABA8-2(5A7-)BA-AB7-B3AB2(7-5A)8-ABA9-ABA369-A-A9-A-A8-2(AB)A7-2(AB)A8-A-A9-3A8-2(AB)A7-2(AB)A8-A-A9-A-A417-A12-A82-B12-B9-ACA10-ACA7-BC-CB8-BC-CB5-AC3-CA6-AC3-CA3-BC5-CB4-BC5-CB-BC7-CB2-BC7-CBAB7-BA2-AB7-BABC7-CB2-BC7-CBAB2-BCB2-BA2-AB2-BCB2-BABC2-CAC2-CB2-BC2-CAC2-CBAB2-BCB2-BA2-AB2-BCB2-BAB9AB2-B9AB5-A12-A9-3B10-3B7-B3CB8-B3CB5-BC3ACB6-BC3ACB4-B2(CA)CB6-B2(CA)CB4-BC3ACB6-BC3ACB5-B3CB8-B3CB7-3B10-3B4-
