model
size = 31 14 29, scale = 0.05, origin = -y
material deform = 1, fade = true, lighting = smooth, roughness = 0.3, metalness = 0.6
  colors = A:#FF6905 B:#FE3C00 C:#0A0000 D:#F6D644 E:#F28214 F:#F2AB14 G:#F29114 H:#FAEB88 I:#FDF4B9 J:#F3BC27 K:#FF5705 L:#B9E7FD M:#4AA7F6 N:#1352F1 O:#FF3A05 P:#1224B0 Q:#F23914 R:#ED2707 S:#030303
voxels
103-11B20-2(C2B)3C3(2B20-4(CB)C)2B20-3(CB)3CBC20-11B235-3B9-3B16-3C3(9-BCB16-CBC)9-BCB16-3C9-3C16-3B9-3B232-2B5(13-2B14-BC)13-CB14-2B13-2B230-2B2(15-2B12-CB)15-2B12-2B2(15-BC12-CB)15-BC12-2B15-2B228-2B17-2B10-BC17-2B10-2C17-2B10-CB17-2C10-2C17-CB10-BC17-2C10-2B17-2B226-2B19-2B8-CB19-2C8-2C19-2C8-BC19-2C8-2C19-2C8-CB19-2C8-2B19-2B224-2(2B2(21-2B6-BC)21-2B6-)2B21-2B222-2B3(23-2B4-CB)23-BC2(4-CB23-2C)4-2B23-2B220-2B25-2B2-2C25-2C2-BC25-2C2-2C25-2C2-BC25-2B2-2C25-2B2-2B25-2B219-B27-B2-C27-B2-B27-B2-C27-C2-B27-C2-C27-C2-B27-B219-6(B27-B2-)B27-B219-B27-B2(2-C27-C)2-C27-B2(2-C27-C)2-B27-B219-B27-B2-C2(27-B2-B)27-C2-B27-B2-B27-C2-B27-B219-B27-B2-C5(27-C2-B)27-B219-6(B27-B2-)B27-B219-B27-B2-C27-C2-B3(27-B2-C)27-C2-B27-B219-B27-B2-C27-C2-B27-B2-C27-B2-B27-B2-C27-C2-B27-B219-B27-B3(2-C27-C)2-B27-C2-C27-C2-B27-B219-6(B27-B2-)B27-B131-8C3-8C9-7C3-2C-2C3-7C4-4C9-C-C9-4C2-2BS10-3C10-S2B3-2C11-C11-2(2C3-2BC23-C2B3-2C23-)2C3-2BC23-C2B2-CSC23-3C2-4C21-CS2C3-7C13-7C6-5C13-5C10-8B3-8B9-3BCA6CB-B6CAC3B4-2BCNMLI6-B-B6-ILMNC2B2-B2ANMLI6-CBC6-ILMN2AB2-B2ANMLI6-3C6-ILMN2AB2-B2ANMLI7-C7-ILMN5(2AB2-B2APNML15-LMNP)2AB2-BCAPNML15-LMNPA2B3-2BC3A4C7-4C4A2B6-4B4C7-4C4B10-8B3-8B9-3BC4A3CB-B3C4AC3B4-2BC4ADFG3-B-B3-GFD4AC2B-2C6ADFG3-CBC3-GFD6A4C6ADFG3-3C3-GFD6A4C6ADFG4-C4-GFD5(6A4C6AIDF9-FDI)6A2C-BC5AIDF9-FDI5ACB3-2BC6A9C6A3B6-7B9C7B10-8B3-8B9-3BC6A2B-BC6AC3B4-2BC7AE2AB-B2AE7AC2B-2C9AE2ACBC2AE9A2C-P9AEA-3C-AE9AP2-P9AEA2-C2-AE4(9AP2-P9AGE5-EG)9AP-2C9AGE5-EG9A2C-BC8AGE5-EG8A2B3-2BC8A5C8A3B6-23B10-8B3-8B9-3BC6ACB-BC6AC3B4-3C10AB-C10A3C2-CM12AB12AMC3-M10AQ3AQ10AM4-N10AQRARQ10AN4-N10A2QR2Q10A3(N4-N11AQRQ11A)N3-CN12AQ12ANC2-2C12AQ12A2C3-2BC21A3B6-23B10-8B3-8B9-3BC6ACB-BC6AC3B5-2C10AB-B10A2C5-L11AB11A2(L6-L23A)L5(6-M23AM)5-CML21ALMC4-2CL21A3C6-23B10-8B3-8B9-2CBC2D4ACB-BC4A2DCB2C6-CI2HD6AB-B6AD2HIC7-I2HD7AB7AD2HI8-I2HD15AD2HI6(8-LIHD15ADHIL)9-IH2D13A2DHI8-C-I2H2D11A2D2HI2C7-2C19B2C10-2C6B3-6B2C10-3C2JFGEACB-BCAEGF2J3C10-D2JFGEAKB-BKAEGF2JD11-H2DJFGEAKCBCKAEGFJ2DH10-2HDJFGEAKOCOKAEGFJD2H5(10-IHDJFGEAKOROKAEGFJDHI)10-IHDJFG2EAKOKA2EGFJDHI11-HDJFG2EAKOKA2EGFJDH13-HDJFGEAKOKAEGFJDH12-3C15B3C11-4C4B3-4B4C12-C2-FGEACB-BCAEGF2-C14-JFGEAKB-BKAEGFJ15-DJFGEAKCBCKAEGFJD13-HDJFGEAKOC5(OKAEGFJDH12-HDJFGEAKOR)OKAEGFJDH13-DJFG2EAKOKA2EGFJD15-JFG2EAKOKA2EGFJ17-JFGEAKOKAEGFJ16-2C13B2C16-5C3-5C22-2C-2C27-C-C28-3C29-C272-13C9-
