model
size = 31 4 31, scale = 0.05, origin = -y
material deform = 1, fade = true, lighting = smooth, roughness = 0.3, metalness = 0.6
  colors = A:#FC3 B:#EEE C:#000 D:#E00 E:#050
voxels
12-3(7A24-)3A-3A21-13A2(18-6AC6A)18-6A-6A16-5A3BC3B3(5A14-5A7-)5A13-4A5BC5B3(4A12-4A11-)4A11-3A15B3(3A10-3A15-)3A9-3A17B3(3A8-3A17-)3A7-3AC17BC3(3A6-3A19-)3A5-3A2BC15BC2B3(3A4-3A21-)3A4-2A23B3(2A4-2A23-)2A3-3A24B2A3(2-3A23-3A)2(2-2A25B3(2A2-2A25-)2A)-2A27B3(4A27-)4A27B4A27-4A11-5A11-4A27-4A12B3C12B4A27-4A4-5D9A5E4-4A12-3C12-4A2C10B3C10B2C3A2(C13-)C2AC2-3D3-D3-ACA3-E3-3E2-CA14-3C14-2A12B3C12B4A27-4A4-5D9A5E4-4A12-3C12-4A27B4A27-4A11-5A11-4A27-4A27B3(4A27-)2A-2(2A25B3(2A2-2A25-)2A2-)3A23B3(3A2-3A23-)3A3-2A23B3(2A4-2A23-)2A4-3A2BC15BC2B3(3A4-3A21-)3A5-3AC17BC3(3A6-3A19-)3A7-3A17B3(3A8-3A17-)3A9-3A15B3(3A10-3A15-)3A11-4A5BC5B3(4A12-4A11-)4A13-5A3BC3B3(5A14-5A7-)5A16-13A2(18-6AC6A)18-6A-6A21-3(7A24-)3A-3A12-
