model
size = 18 7 31, scale = 0.05, origin = -y
material deform = 1, fade = true, lighting = smooth, roughness = 0.3, metalness = 0.6
  colors = A:#A4F814 B:#99F213
voxels
19-A14-A2-A14-A-BA14-AB-A14-A38-A14-A2-A14-A37-BA14-AB-B14-B20-2A12-2A55-A16-2AB14-BA20-A12-A74-2AB12-B2A-B14-B3-2A10-2A75-AB12-BA2-B14-B4-A10-A76-AB12-BA2-B14-B4-A10-A6-2B8-2B58-AB12-BA2-B14-B23-B8-B59-AB12-BA2-B14-B23-2B6-2B60-AB10-BA3-2B12-2B24-B6-B61-AB10-BA4-B12-B25-2B4-2B61-AB10-BA4-B12-B26-B4-B62-AB10-BA4-B12-B26-BA2-AB62-AB10-BA4-B12-B27-A2-A64-AB8-BA5-2B10-2B27-4A64-2(AB8-BA6-B10-B29-2A65-)AB8-BA6-B10-B29-2A66-AB6-BA7-2B8-2B11-2A16-2A66-AB6-BA2(8-B)12-2A84-AB6-BA2(8-B)12-2A85-B6-B9-B8-B12-2A85-AB4-BA9-BA6-AB12-2A85-AB4-BA10-A6-A13-2A16-2A67-BAB2-BAB10-BA4-AB13-2A16-2A15-A2-A30-B6-B10-B2-2B2-B11-2A2-2A14-2A15-4A14-A2-A13-A4-A11-B6-B11-B-2A-B12-6A14-2A15-4A13-6A11-2BA2-A2B11-B4-B12-B4-B13-4A32-4A13-A-2A-A2(12-B4-B)13-B2-B14-4A33-2A15-4A13-B4-B13-B2-B14-B2AB15-2A52-2A15-B2AB14-B2AB15-2B88-2A16-2A44-
