model
size = 17 30 24, scale = 0.05, origin = -y
material deform = 1, fade = true, lighting = smooth, roughness = 0.3, metalness = 0.6
  colors = A:#600 B:#0E0 C:#050 D:#080 E:#0A0 F:#070 G:#020 H:#FF0 I:#0B0 J:#0FC
voxels
190-A14-4A13-4A14-A271-2A15-2A490-4A13-4A14-2A134-A18-A13-A18-A304-2A15-2A134-A15-4A13-4A15-A303-2(4A13-)4A132-3A14-3A305-B-B12-4A13-4AB11-B4A17-B11-2(B-)B66-B-B29-3A-B11-B3A18-B11-2(B-)B80-2(B-)B29-B2-H15-HJH2-B12-H16-2(B-)B95-C15-C2(4A13-)4A98-C15-C17-2(4A13-)4A103-D17-I43-I17-D103-C-B12-4A13-4AB11-C4A17-E11-2(B-)C66-C-B29-4AB11-C4A13-4AC11-2(B-)C80-2(B-)D29-D8-2G13-D29-D2(-B)112-2(4A13-)4A132-2(4A13-)4A139-3G143-C-BCB11-C4A13-4AB12-4AC11-I4-B14-CB64-C-BCB11-C17-4AB12-4AC11-I4AB14-CB83-D2-E10-D6-D16-3G24-D6-D10-E2-D115-2(4A13-)4A132-2(4A13-)4A122-D2-D13-G18-D-B12-D12-E5-B-B92-C-B12-4A13-4AB11-C4A17-C11-2(B-)C66-C-B29-4AB11-C4A13-4AC11-2(B-)E80-2(B-)D3-E2-D22-D20-E32-D-B32-E64-C4-B3-B-B4-C4A13-4A-B3-B-B5-4A3-C14-E3-C-B21-2(B-)E3-E2-E25-C2-E27-2(B-)C13-4A12-B4A13-4A12-2(B-)E32-F30-2(B-)D33-E40-H5-D17-E2-D-B3-B-B59-E32-B4-C6-A2-13A-A2-13A3-B13A4-3(4A13-)4A3-C2-C5-C4(4A13-)4AB12-4A15-2AC28-F38-F17-D3-D-B21-B10-H16-J9-F6-H8-B4-E97-B-C3-C-B2-2A-16A-15A2-13A3-B4A13-4A12-C3(4A13-)4A12-C4A13-4A12-B4A13-4A12-F2(4A13-)4AF12-4A12-F4A13-3AE3-D8-B2(4A13-)3AD6-H26-C-D3-D-B4-E2-D2-E14-D13-E3-E14-E17-E13-A13-2A-16A-15A2-13A4-3(4A13-)4A5-C-B5-4(4A13-)2(4AB12-4A13-)2(4A13-)4AB12-4A-B3-B-B5-2(4A13-)4A16-F115-2A3(2-C)3-A2-13A-A2-2(13A4-)4A12-C2(4A13-)4A3-C8-E4A2-C10-4A13-4A12-C4A13-4A12-E4A46-F50-F20-E67-2D2-E2-D60-E51-2(C2-)C26-B-C3-C-B7-B4-C9-C4-B3-B-B7-C-B21-B-B5-F2-F32-F-B12-F3A13-4AB12-F3A15-F-B29-F2-F32-F-B12-F4-B3-B-B7-B4-D12-B-D3-D-B8-E17-D2-I2-D43-E219-B-B29-4AB11-B4A13-4AB11-F2(-B)169-E251-F15-F17-2(4A13-)4A440-F-B29-3A-B11-F3A18-F11-2(B-)F455-3A14-3A456-F-BFB11-F17-3A-B12-3A-F11-F4-B14-FB455-3A14-3A302-
