model
size = 16 24 14, scale = 0.05, origin = -y
material deform = 1, fade = true, lighting = smooth, roughness = 0.3, metalness = 0.6
  colors = A:#5DAC81 B:#20604F C:#0F4C3A D:#222 E:#111 F:#FFFFFB G:#91989F H:#DDD
voxels
71-2C14-2C13-A2CA11-2A2C2A9-4(3A2C3A8-)3A2C3A7-4A2C4A6-2A6E2A6-AE6GEA6-EG6FGE6-E2F4E2FE6-AEF4EFEA6-2A6E2A7-3A2B3A9-2A2B2A92-2B14-2B13-A2BA11-4(2A2B2A10-)2A2B2A9-3A2B3A7-7(4A2B4A6-)4A2B4A7-3A2B3A75-2C13-4C12-4C11-CA2CAC9-2(C2A2C2AC8-)2(3A2C3A8-)3A2C3A7-2(2C2A)2C5-BC3A2C3AC5(B4-B4A2C4A)B4-BA2HA2CA2HA2(B4-B4A2C4A)B4-2B3A2C3A2B5-10B7-8B27-2D13-D2AD11-D4AD10-DA2CAD9-D2A2C2AD6-2D3A2C3A2D4-3C2A2C2A3C2(4-5A2C5A)4-C4A2C4AC3-BC4A2C4AC9(B2-B5A2C5A)B3-5A2C5A4-5A2B5A5-4A2B4A7-3A2B3A85-D12-D2-C12-C2-A12-A2-C12-C-AC12-C3A8(12-4A)-10A-2A-B12AB2-B12AB3-5A2B5A5-4A2B4A7-3A2B3A69-D12-D2-C12-C-A12(14-2A)2-10A2-17A-B12AB3-5A2B5A5-4A2B4A7-3A2B3A53-D12-D2-C12-C-A13(14-2A)2(2-10A2-17A-B12AB3-5A2B5A5-4A2B4A7-3A2B3A37-D12-D2-C12-C-A14(14-2A))2-10A2-17A-B12AB3-5A2B5A5-4A2B4A7-3A2B3A53-D12-D2-C12-C-A13(14-2A)2-10A2-8A2B7A-B5A2B5AB3-5A2B5A5-4A2B4A7-3A2B3A69-D12-D2-C12-C-AD12-D11(2A14-)2A2-10A2-8A2B7A-B5A2B5AB3-5A2B5A5-4A2B4A7-3A2B3A85-D12-D2-C12-C2-A12-A2-C12-C-AC12-C3A8(12-4A)-10A-2A-B5A2B5AB2-B5A2B5AB3-5A2B5A5-4A2B4A7-3A2B3A11-2D13-D2AD11-D4AD10-D4AD9-D6AD6-2D8A2D4-2C8A2C2(4-12A)4-C10AC3-BC10AC8(B2-B12A)B2-B5A2B5AB3-5A2B5A4-5A2B5A5-4A2B4A7-3A2B3A27-2C13-4C12-C2AC11-C4AC9-C6AC7-CAB4ABAC3(6-2AB4AB2A)6-CAB4ABAC5-BC8AC5(B4-B10A)B4-BA2H4A2HAB4-B10AB4-2(2B3A)2B4-3B2A2B2A3B5-10B7-8B20-
