model
size = 32 11 15, scale = 0.05, origin = -y
material deform = 1, fade = true, lighting = smooth, roughness = 0.3, metalness = 0.6
  colors = A:#444 B:#EEE
voxels
6-6B8-6B11-B6AB6-B6AB9-B8AB4-B8AB7-B9AB4-B9AB5-B11AB2-B11AB4-B11A4B11AB4-B9A2B4-2B9AB3-2B7A2B8-2B7A2B2-9B12-9B2-4B22-4B-B30-B225-2(B28-B322-)B28-B2-9(B28-B322-)B28-B290-B28-B2-B28-B290-B28-B97-
