model
size = 27 25 28, scale = 0.05, origin = -y
material deform = 1, fade = true, lighting = smooth, roughness = 0.3, metalness = 0.6
  colors = A:#606 B:#FFA850 C:#609 D:#222 E:#E00 F:#639 G:#FC0 H:#FF0 I:#F96 J:#F63 K:#D00 L:#B00 M:#FF3 N:#CC0
voxels
237-H447-7D20-3BJ3B20-3BI2JB20-3BIJBI583-14D13-14B13-12BJB13-BIB2IJBI3BJBI404-H53-N121-15D2(12-15B)12-2BJ4BI5BJI376-2(H26-M26-)H92-19D2(8-7B7A5B)8-JI5B7A3BJB15-7E20-3KLE2K20-3EL3E20-G2(M2G)20-2A2C3A20-2C5A20-2CAF3A20-6AC20-ACF3AC20-AF5A20-2AF3AC55-2(H26-)N26-M26-H26-N26-H64-21D6-6B11A4B6-6B11A3BI6-J2BI2B11A2B2J12-EL9E16-L3K7E16-11E16-11G16-11A16-10AC16-C9AC16-C7A2CA16-F9AH16-10AN16-6AC3A2(H26-)N2(26-H26-E)26-H26-M26-H37-21D2(6-5B13A3B)6-J4B13A2BI11-3E8A2E14-3E8AEK14-3E8A2E14-M10A2G14-13A14-11A2C14-2C9A2C14-2C11A14-2F9AHA14-11AHA14-5ACAC2AFHA25-N26-H26-M26-H26-E2(26-H26-N)26-M9-9D5-9D4-5B4A5-6A3B4-I4B4A5-6A2BJ4-IJ2IB4A5-6A3B9-2E2A5-3A3E12-LE2A5-3AE2K12-2E2A5-3A3E12-2G2A5-3A3G12-4A5-6A2(12-4A5-3A3C)12-4A5-6A12-12AH2A12-4A5B3AHAC12-2A4C2AC3AHFA24-2(H26-)N2(26-E26-H)26-M26-H35-8D9-9D-5B3A9-5A4B-2I3B3A9-5AB2JI-2I3B3A9-5A3BJ6-2EA9-A4E2(10-2EA9-A3EK)10-2GA9-A4G10-3A9-5A10-F2A2(9-5A10-3A)9-4AC10-16AC10-C2A9B5A10-F6C2ACF3AF2A50-3(H26-)N26-H26-N26-H62-7D11-8D2(-4B3A11-5A3B)-2I2B3A11-5A3B5-LEA11-A4E2(8-2EA11-A2E2K)8-MGA11-A4G4(8-3A11-5A)8-C18A8-2CA11B5A8-10A3C2AC3A76-M3(26-H)26-M89-7D12-7D-4B2A13-4A3B-4B2A13-4A2BI-IJ2B2A13-4A3B5-3(EA13-A3E8-)GA13-A3G4(8-2A13-4A)8-19A8-2A13B4A8-9AF5AC3A103-N53-M115-7D13-7D2(4B3A13-2A4BI)4B3A13-2A5B4-2(2EA13-A4E6-)2EA13-A3EL6-2GA13-A4G6-3A13-4AC3(6-3C13-5C)3(6-21C)272-6D15-6DI3B2A15-A4B2IB2I2A15-A4BI4-BA15-3AB6-EA15-A3E6-KA15-A2EK6-EA15-A3E6-GA15-A3G4(6-2F15-4F)3(6-21F)272-6D15-6D2(IB)2A15-A5B4-2(BA15-3AB6-)EA15-A3E6-LA15-A3E6-EA15-A3E6-MA15-A3G4(6-2C15-4C)3(6-21C)272-6D15-6D4-3(BA15-3AB6-)EA15-A3E6-KA15-A2EL6-EA15-A3E6-GA15-A3G4(6-2C15-4C)3(6-21C)272-6D15-6D4B2A15-A5B4-2(BA15-3AB6-)LA15-A3E6-LA15-A2EK6-EA15-A3E6-MA15-A3G6-2A15-4A6-2A15-3AF2(6-2A15-4A)6-21A6-2A15B3AF6-FA3C6AFC2AC2FCAC272-6D15-6D4B2A15-A7BIB2A15-A5B4-BA15-3AB6-LA15-A3E6-EA15-A2EK6-EA15-A2EL6-GA15-A3G6-2A15-4A6-2A15-3AF6-2A15-4A6-2A15-3AC6-21A6-2A15B4A6-2A3C3A2F5A2F4A272-7D13-7D4B3A13-2A5BI3B3A13-2A9B3A13-2A5B4-2EA13-A4E6-2EA13-A3EK6-2EA13-A4E6-2GA13-2A3G6-3A2(13-5A6-2CA)13-5A6-FCA13-4AC6-F19AC6-3A13B5A6-AF4AC8A2C3AF273-6D13-7D-4B2A13-4A3B-J3B2A13-4A3B-JI2B2A13-4A3B5-3(EA13-A3E8-)GA13-2A2G8-2A2(13-4A8-CA)13-3AC8-CA13-3AC8-19A8-2A13B4A8-2(A2F)2(A2C)2A2CA2C274-7D11-8D-4B3A11-5A3B-J3B3A11-5A3B-2J2B3A11-5ABIB5-2EA11-A4E8-LEA11-A3EL8-2EA11-A4E8-G2A11-3A2G8-3A11-5A8-F2A11-5A2(8-C2A11-4AC)8-19A8-2FA11B5A8-3A3C3A4CA3CAC274-8D9-9D-5B2(3A9-5A4B-J4B)3A9-5A3BI6-E2A9-2A3E10-K2A9-2A3E10-E2A9-2A3E10-MGA9-A4G10-3A9-5A10-2CA9-4AC2(10-3A9-5A)10-16AC10-F2A9B5A10-2AC3AFACF7A276-9D5-9D3(4-5B4A5-6A3B)9-2E2A5-4A2K12-LE2A5-4AEK12-2E2A5-4AEL12-2G2A5-2A4G2(12-2F2A5-6A)12-4A5-4A2C12-4A5-6A12-15A12-2F2A5B5AC12-3A2C6AF2AC278-21D2(6-5B13A3B)6-2B2JB13A2BI11-3E5A2E2AK14-L2E5A2E2AL14-3E5A2E2AE14-3G5A5GH13-2(F12A14-)12AC14-C11AC14-13A14-F11AC14-2A2C8AC279-21D6-6B11A4B6-J5B11A4B6-I5B11A3BI12-L10E16-K8ELE16-11E-H14-GM9G-H14-11A-H14-C10A16-C8A2C16-9A2(2F16-2F7A)2C16-4A3C2(AC)281-20D7-7B7A6B7-7B7A3BJIJ7-BJ2B2JB7A3BIBI14-7E3-H16-LE2KL2K3-H16-L3EL2E3-H16-3(GM)G3-H16-AF5A3-H16-A5FC3-H16-F2A2CFC20-AF5C20-3CA2FA20-2(C2A)C20-3AFCAC284-16D11-16B11-I15B11-3I2J11B54-2(H26-)E3(26-H)390-14D13-2BJ11B13-B2J8BJ2B13-2BI6B2IBIB27-5(H26-)H420-7D20-7B20-3BJI2B20-BIB2IBI85-2(H26-)H437-
