model
size = 25 32 29, scale = 0.05, origin = -y
material deform = 1, fade = true, lighting = smooth, roughness = 0.3, metalness = 0.6
  colors = A:#AAA B:#777 C:#888 D:#656765 E:#444 F:#555 G:#222 H:#E16B8C I:#F05E1C J:#EEE K:#77428D L:#FBE251 M:#005CAF N:#E83015 O:#78552B P:#277736 Q:#91989F
voxels
358-4AC4A15-4ACAC4A14-5AC5A14-4A3J4A14-3B5J3B14-3B2(JN)J3B14-3A5J3A14-4ACAC4A16-3AC3A19-2(AC)A490-A13-A10-2A11-2A10-3A9-3A10-15A10-2A2(3BC)3B2A10-2A5(CB)C2A10-2AB2(C3B)CB2A2(10-2B11D2B)2(10-7AD7A)12-5AD5A14-5AD5A17-2AC2A439-2(2A13-2A8-)AC13-2A8-AB13-BA8-AC13-CA8-ABC11-CBA8-ACB11-BCA8-A2B11-2BA8-BID11-DIB8-BHD11-DHB8-AKA11-AKA8-3A11-3A10-A11-A12-A11-A13-5AD5A17-2(AC)A388-A17-A6-2A2(15-2A6-AB)15-BA6-AC15-C3(A6-AB15-B)A6-AC15-CA6-BID13-DIB6-BHD13-DHB6-AKA13-AKA6-3A13-3A8-A13-A10-2(2A11-)2A9-2A14-4AD4A18-2AC2A338-3(A17-A6-)AB16-3(A6-AC15-CA6-AB15-B)A6-BID13-DIB6-BHD13-DHB2(6-2AD13-D2A)7-AD13-DA8-AHA11-AH2(A9-AK)A11-6AD6A14-3ACAC3A335-2A17-2A2(4-AB17-BA)4-AC17-C3(A4-AB17-B)A4-AC17-C2(A4-AB17-B)A4-BID15-DIB4-BHD15-DHB4-BA17-AB5-A17-A6-A17-A7-2AD11-D2A8-2(A2KA9-)2AIA7-AI2A12-5AD5A17-2AC2A312-A19-4(A4-AB17-BA4-AC17-C)A4-AB17-B2(A4-AD17-D)A4-A19-A4-B19-B5-A17-A6-A17-A7-3AD9-D3A8-2A2IA7-A2I2A10-6AD6A14-3ACAC3A309-2A19-2A2-AC19-C2(A2-AB19-B)A2-FB19-BF2-FC19-C2(F2-FB19-B)F2-AB19-BA2-AC19-CA2-AID17-DIA2-AHD17-DHA3-A19-A4-B19-B5-A17-A6-A17-A7-A15-A8-4AD7-D4A10-2AL3AD3AL2A14-4AC4A284-2A19-2A2-AC19-CA2-AB19-BA2-AC19-CA2-FB19-BF2-FC19-CF2-EB19-BE2-EC19-CE2-FB19-BF2-FC19-CF2-AB19-B2(A2-AD19-D)A2-2A19-2A3-A19-A4-BA17-AB5-A17-A6-2A15-2A7-3A11-3A10-3ADA3-AD3A14-4AD4A19-CAC237-A21-A2-2A19-2A2(2-AB19-BA)2-FB19-BF2-FC19-CF-EKB19-BKEGPB19-BP2GMB19-BMGELC19-CLE-2(FB19-BF2-)2(AD19-DA2-)2A19-2A2-2A19-2A3-2A17-2A4-BA17-AB5-2A15-2A6-4A11-4A8-5AD3-D5A12-3APADAP3A17-2AC2A86-F21-F6(2-C21-C)2-BA19-AB2-AC19-CA2-AB19-BA2-FC19-CF2-EB19-BE-GKC19-CKGEPB19-BPEQMC19-CMQGLB19-BLG-EC19-CE2-FB19-BF2-AD19-DA2-ND19-DN2(2-2A19-2A)3-2A17-AME3-BA17-ABE4-2A15-2A-E4-4A11-4A-E6-4A7-4A3-E8-4A3D4A5-E10-7A7-E12-3B9-2(E24-)N77-4(C21-C2-)2A19-2A2-2B19-2B2-FC19-CA2-EB19-BF2-EB19-BE-GKB19-BKGQPC19-CPQEMB19-BMEGLB19-BLG-EB19-BE2-FC19-CF2(2-AD19-DA)2-ND19-DN2-AD19-DA3-AD17-DA4-BD17-DB5-AD15-DA6-2A2D11-2D2A8-2A2D7-2D2A12-2A7D2A16-3AM3A20-3B212-A21-A2-2A19-2A2-FC19-CA2-EB19-BA2-FC19-CF2-FB19-BF-EKC19-CKEGPB19-BP2GMC19-CMGELB19-BLE-FC19-CF2-FB19-BF2(2-AD19-DA)2(2-2A19-2A)3-2A17-2A4-BA17-AB5-2A15-2A6-4A11-4A8-4A7-4A12-4A3D4A16-7A20-3B237-FA19-2A2-EB19-BA2-FB19-BA2-AB19-BA2-FC19-CF2-FB19-BF2(2-EB19-BE)2-FC19-CF2-FB19-BF2-AB19-BA2-AID17-DIA2-AHD17-DHA2-2A19-2A3-A19-A4-BA17-AB5-A17-A6-2A15-2A7-3A11-3A9-4A7-4A12-3A2(DA)D3A17-5A236-F24-EA23-FC19-2A2-AB19-BA2-AC19-CA2-AB19-BA2-FC19-CF2-FB19-BE2-FC19-CF2-FB19-BF2-AC19-CA2-AB19-BA2-2A2(D17-DA4-A)19-A4-B19-B5-A17-A6-A17-A7-A15-A8-3A11-3A10-3AD5-D3A14-4AD4A19-3A214-F23-2E23-FA23-AB17-2A4-AC17-C3(A4-AB17-B)F4-AC17-CE4-AB17-BF2(4-AB17-BA)4-AC17-CA4-AID15-DIA4-AHD15-DHA4-2A17-2A4-2B17-2B5-2A15-2A6-2A15-2A7-A15-A8-3A11-3A10-2A2(D3A)D2A14-9A211-F24-E24-F74-4(A17-A6-)A17-AE5-4(A17-A6-)2(AD15-DA6-)A17-A6-B17-B7-A15-A8-A15-A9-2AD9-D2A10-2AD9-D2A12-5AD5A16-7A167-4(G-)G11-F3-11G10-E3-11G10-F4-4GB4G17-2G3B2G19-2(5B20-)5B21-2(3B22-)3B14-A7-3B7-AE5-A8-B8-3(A6-A17-)A6-BE2D11-2DEB6-BH2D11-2DHB6-B2AD11-D2AB7-2(2AD11-D2A8-)2AD11-D2A2(9-AKA)11-2A9-2A13-5AD5A16-7A162-F4-4(G-)G11-E3-11G10-F3-G9OG15-G7HG17-G5IG19-B3LB20-2BM2B20-2BI2B21-BMB16-G3-G-BOB2-3E12-G-G2-BKB-E3GE12-G3-BPB-EGFGE2-E8-G-G3-B2-E3GE10-G3-G6-3E59-BECED9-DECEB6-B3HD9-D3HB7-AKA11-AKA8-AOA11-AOA9-2(2A11-2A10-)AKA9-AKA11-6AD6A13-11A18-3A165-E24-F4-3(G-)G16-11G15-2G5H2G18-B3IB20-B3LB20-2BM2B20-2BI2B21-BMB22-BOB22-BKB22-3B8-E14-B90-B2(EC)9D2(CE)B6-BF3H9D3HFB8-3A4-D4-3A10-3A4-D4-3A11-2(2A4-D4-2A12-)2A4-D4-2A13-5AI5A15-9A187-F24-E28-4(G-)G17-7G20-BIB21-B3LB20-2BM2B21-BIB22-BMB22-3B23-B34-E105-B3(EC)E3C3(EC)EB6-2(BF)11H2(FB)10-4(11A14-)11A15-9A17-7A189-E24-F80-3B22-B2LB21-BMB22-3B23-B28-3F21-F-N-F20-FN-NF2EF17-F-N-F21-3F59-B2(EC)E2C3E2C2(EC)EB6-3(BF)BH3BH3(BF)B13-4(J3-J20-)4J241-F24-E80-3B22-BLB22-3B239-B3(CE)5C3(EC)B6-2BFBNBF5BFBNBF2B359-E4-2E18-F4-2E73-3B22-3B265-B2(CE)C5E2(CE)CB8-2BFBNB5FBNBF2B360-2(FE)F2G18-2(EF)3G366-B2CECE5CECE2CB8-3BFBF5BFBF3B759-B2CEC5ECE2CB10-3BFB5FBF3B761-B2CE5CE2CB12-3BF5BF3B763-B2C5E2CB14-3B5F3B765-9B16-9B308-
