model
size = 29 31 27, scale = 0.05, origin = -y
material deform = 1, fade = true, lighting = smooth, roughness = 0.3, metalness = 0.6
  colors = A:#FF0 B:#FF3
voxels
419-A2-A1794-A2-A895-A2-A489-A2-A837-A2-A83-A2-A373-A2-A12-A389-A2-A141-A2-A344-A2-A13-A26-A332-A2-A199-A2-A333-A24-A304-A2-A257-A2-A286-A2-A15-A22-A276-A2-A315-A2-A257-A2-A16-A20-A248-A2-A373-A2-A249-A18-A220-A2-A431-A2-A199-A2-A18-A16-A192-A2-A489-A2-A170-A2-A19-A14-A164-A2-A547-A2-A165-A12-A136-A2-A605-A2-A112-A2-A21-A10-A108-A2-A663-A2-A83-A2-A22-A8-A80-A2-A721-A2-A81-A6-A52-A2-A779-A2-A25-A2-A24-A4-A24-A2-A837-A2-A25-A2-A867-B28-A27-2AB27-A28-B637-A28-B27-A-A26-B-B25-A3-A24-B-A-B22-A2(B2-)2A18-2A3-3A3-2A18-AB2(2-A)B22-B-A-B24-A3-A25-B-B26-A-A27-A28-B347-B28-B27-BAB2(26-ABA)25-2(2(AB)A24-)2(BA)B23-3(AB)A20-2A2(BA)B4A16-4A3(BA)2B3A11-B3A2B6AB2A2B3AB6-2(2B2A)2B5A2(2B2A)2B6-B3A2B8A3B3AB11-3A2B3(AB)4A16-4A2(BA)B2A20-3(AB)A23-2(BA)B2(24-2(AB)A)25-2(ABA26-)BAB27-B28-B144-B28-A27-BAB26-3A17-B7-5A8-B8-A6-B3AB7-A10-B5-5A6-B12-A3-7A4-A14-B2-B5AB3-B18-7A20-AB7ABA16-AB11ABA11-2AB15ABAB6-B23AB2-A3B24AB2-AB22AB6-2AB15ABAB11-AB11ABA16-AB7ABA16-B3-7A17-A4-B5AB3-B12-B5-7A4-A10-A7-5A6-2(B8-)B3AB7-A16-5A8-B16-B2A26-2AB27-A28-B144-B28-B27-BAB26-3A26-ABA25-2(2(AB)A24-)2AB2A23-3AB3A20-B3ABAB3AB16-B5ABAB5AB11-B3A2B9A2B4A6-2B2(AB)2A2B5A2B2A2B2(AB)6-B3A2B5A2B2A2B4A11-6A2(BA)2B3A16-4ABAB4A20-2(AB)3A23-3BAB2(24-2(AB)A)25-ABA2(26-3A)27-B28-B347-A28-B27-A-A26-B-B25-A3-A24-B-A-B22-AB2-A2-BA18-AB3-A-A3-2A18-AB2-A2-BA22-B-A-B24-A3-A25-A-B26-B-A27-A28-A637-B28-A27-3A27-B28-A840-A420-
