model
size = 17 21 23, scale = 0.05, origin = -y
material deform = 1, fade = true, lighting = smooth, roughness = 0.3, metalness = 0.6
  colors = A:#EEE B:#633 C:#BBB D:#555 E:#963 F:#CF0 G:#930 H:#933 I:#777 J:#444
voxels
160-5(3A14-)3A235-2(3A14-)3A82-3A14-3A184-2(3A14-)3A133-3A14-3A150-2(3A14-)3A167-3A14-3A99-3(3A14-)3A201-3A14-3A64-3(5A12-)5A216-2(5A12-)5A29-20(5A12-)5A10-11(9A8-)2(3A3B3A8-)7(3A3-3A8-)3A3-3A6-11(13A4-)2(3A2-5B3A4-)3A2-G-2G-7(3A4-3A7-)2AE4-2A9C2A10(4-13A)4-2A9B2A4-2A9BAB4-2A4-2HGA-2(2A4-2A9-)2(AB4-2A9-)2(2A4-2A9-)AB4-2A9-2E3-2A2(CF)3C2(FC)2A8(2-15A)2(2-I14A)2-I2(A11B2A2-D)A2-G-3H-G2-2A2-DA5-E5-6(2A2-2A11-)BA2-AC2(4F2C)A8(2-15A)2(2-I14A)2-I13BA2-D4B3E2BE3BA2-D2-AH3-E2-AH-E2-D2-2G9-A2-A13-E2-A13-A2-A13-B2-A13-A2-A13-E2-A13-B-2A2(CF3CF)C138A2(I16A)IA13B2ADA7BE5B2ADA-GH2-2H-AEAG-2AD2(A2-)AE2-E-H-4A2-E10-2(4A13-)AB2A13-4A13-AB2A13-BE2A2(CF3CF)C104A2(D16A)D34A15B2A8BE6B2A2-H-EHA2-E2-G2-2A2(2-E)6-G2-3(AC15-)2(2A15-)BA15-3AC2(4F2C)10A5(B16A)3(B7A2D7A)B16AB9A15B2A6BEBE6B2A2GE-H4-H-2G2-2A12-G2-AC2(15-2C)15-CA2(15-2A)15-B2A2(CF3CF)C103A2(2D15A)2D34A15B2A2BE12B2A3-HG-GAEHG-2G-2A9-A2-E2-AC2(15-2C)15-CA2(15-2A)15-3A2(CF3CF)C103A2(DI15A)DI35A13B4ABE8BE2B5A3-2G-EHE3-4A8-A4-2ADA8-G4-2(ACDA13-)AC2A2(13-4A)13-2A-AC2(4F2C)A5(2-15A)2-14A2(C2-I13A)C2-I14A2-15A2-A13BA2-A2B2E2BE4BEBA2-A-E3-G-A3G2(2-A)7-E5-A3(2-D13-D)3(2-A13-A)2-A2CFCF3CFCF2CA5(2-15A)2-14A2(C2-I13A)C2-I14A2-15A2-2A12BA2-2A10BEBA2-3A3EHGA2-G2-A2-3A2(-E)7-A3(2-DA12-D)3(2-2A12-A)3-A11CA5(4-13A)3(4-12AC)2(4-13A)4-A10B2A4-A2(3BE)2B2(2A4-A6-G3-)2A3(4-A10-AD)3(4-A10-2A)4-2A9C2A8(4-13A)2(4-11A2D)4-3A7BA2D4-3A2BE4B3(A2J4-3A7-)5(3A4-3A7-)3A6-9(9A8-)2(7A2D8-)3A3BA2D8-3AB2E3(A2J8-3A3-)5(3A8-3A3-)3A10-20(5A12-)5A6-
