model
size = 31 3 32, scale = 0.05, origin = -y
material deform = 1, fade = true, lighting = smooth, roughness = 0.3, metalness = 0.6
  colors = A:#2C29D1 B:#FFF C:#4B4B4B D:#93C9FF E:#C6C6C6 F:#DDF2FF G:#000 H:#F0F7FF I:#3D3D3D J:#FFE228 K:#71B4DC L:#989898 M:#E8F3FF N:#8484B6 O:#4B311A
voxels
-30D124A31D32ABF27BA2D2H23D2H2D32ABF2BF4BF6BF7BF2BFBADH2FH21DH2FHD4A2E2(2A3E)2(AE)2A3E2A2J3AF4BF3BF4BFBF3B2F2BF4BADH2FM21HM2FHD3A4(E2A)3(EA)E2AEA2(J2A)2BF6B2(F2B)2(2F2B)2(F2B)ADH2FM2H2J2H3J3H2J3H3JHM2FHD3A2(E2A)E3A3E2AE3A3E4AJ2A3BF6BFBF3BFB2F6BF2BADH2FM3(HJ2HJ)HJ4HM2FHD3A2(E2A)E5AE2AE3A2(EA)2(J2A)BF4B2F8BFBF8BFBADH2FMHJ4H3J2H4JHJH2JHM2FHD4A2E3AE5A4(E2A)2J3ABF4BF9BF12BAD3HM4(HJ2HJ)HM3HD32ABFB2GBF2(2B2G)2F3B2G2F2G3BADH2DM2H2J2H3J2(2HJ)2H3JHM2DHD32ABF2(2B2G)3B2GF4B2GBF2G2BFA5D21H5D7A2(E2A)2E2A2(2E3A)3J2AF3B2G2B2G3B2G2(BF)B2GBF2G3BA31D7AEA2EAE2AE3AEAE2AEA2(J2A)F4B4G2BFB2G5B2G2B2G3BA31D7A2E2(AE)4(2AE)2A3J2A6B2G3BFB2G5B2G2B2GBFBA5(DC)2(5DC)4(DC)D7A2(E2AEA)E3AE2AEA2(J2A)2B2F2B2G2BF2B2G3BFB2G2B2GBFBAD9C4KLKL4K9CD7A2(E2A)2E3A2E2A2E3A3J2A2BF2B4G2BFB2G2BF2(2B2G)3BAD9C2(KL)3K2(LK)9CD32AB2FB2G2B2G3B2G5B2G2B2G2FBAD9C11L9CD32A4B2GFB2G3B5G2B2GFB2G3BAD9C11L9CD17A2(3E2A)2J3A3B2GB2FB2G2B5G2(2B2G)3BAD9C11I9CD18A2(E2A)EA2(J2A)F5BF11BF8BFBAD9C11I9CD18AE3A3EA4J2A3B2G2BG3B2GBG2(B3G)2(BG)2BAD9C11I9CD18AE3A2(EA)2(J2A)2BG3B2(GB)G3BGBG4BG2BGBG2BAD9C5IO5I9CD18A2(E2A)EA2(J2A)3BG2F3(GB)FBGB2G2FB2(G3B)AD9C5KN5K9CD32A2F2BGF2(GB)G2BFGBG2BFBG2FBG2BFAD9C11I9CD32AFB2G3BG3B2GBGB3GBF2(GB2F)AD9C11I9CD2(AE)2A3EA3E2(3AE)2AE2A3J3AF4BF17BF5BAD9C11I9CD3(AE)2A3(E3A)2(EA)E4AJ2AF2B2F2(10BF)2BAD9C11I9CD2AE3A3E2A2E2(3AE)A3EA2JAJ2A9B3F2BF2B2F5BF2BFBAD9C5IO5I9CD2AE3AEA3(E3A)3(EA)2(J2A)2B2F12B2F5B2F2B2FAD9C2KC2KN2KC2K9CD3(2AE)3(A3E)2(AE)A3J3A2BF3BF6BF8B3F3BFAD29ED32AB2(2F2B)FBF2BF5BF8BAD29AD32A10BF8B2F5BF2BAD29AD
