model
size = 24 31 17, scale = 0.05, origin = -y
material deform = 1, fade = true, lighting = smooth, roughness = 0.3, metalness = 0.6
  colors = A:#100 B:#E00 C:#C03 D:#111 E:#222 F:#BBB G:#933 H:#B00 I:#C33 J:#633 K:#963 L:#696 M:#D00 N:#C66 O:#500 P:#C96 Q:#363 R:#C00 S:#A00 T:#396 U:#993 V:#333 W:#F03 X:#C36 Y:#09F Z:#C63 Aa:#CC6 Ab:#330 Ac:#800 Ad:#936 Ae:#400 Af:#903 Ag:#09C Ah:#099 Ai:#066 Aj:#366 Ak:#069 Al:#900 Am:#555
voxels
9-BAd2(MG)18-IDEDNJR18-3DE19-6DAe16-2D4ADAD15-2AJ2NJ3A13-4AG2NG3A13-4AJ2XJ3A13-12A12-2KE2A2K2AAb2K12-2PZAK2PKAZ2P12-2PNAK2PKAN2P12-ZNJAE2NEAJNZ12-12A12-9AAb2U12-9A2(U2Aa11-10A)Ab2UA10-14A10-DTLVAE2TEAVLT12-3LAAj2LAjA2L253-BMG6-2RS12-IME7-IHI12-IED4-EIJG12-JED7-EGO10-3D9-EO10-D2A9-DE10-D11-DA10-A11-2A9-2A12-A10-A12-A2(10-K12-K)10-E12-E2(10-A12-A)9-2A12-K9-A13-K2(A8-A14-)A8-A13-DA8-AQ11-LQA9-Q2LTAQ2LQAT2LQ11-2QD2A2Q2AD2Q201-WBW12-HMS7-BX13-RS7-I2G11-JI8-IE13-J8-J14-E8-D14-D8-D8(14-A8-A)14-A7-A15-A7-5(A16-A6-)2A14-2A7-2A12-2A9-14A12-3AAi2AgAi3A17-Ah2YAh132-C18-H5-C17-H5-J16-H6-E2(16-G6-D)16-E6-D16-D6-A16-A6-A15-A7-A15-A8-A15-A7-A15-A6-A16-A6-A15-A7-A16-A6-A16-A5-5(A18-A4-)A18-A5-A16-A6-2A14-A8-2(3A10-)4A4-4A14-2AAk2YAk2A106-3(C18-H4-)C18-C4-G2(18-O4-C)18-E4-C17-A5-A17-6(A6-A16-)A5-2(A18-A4-)A18-A3-2A18-A2-3(B2A19-A-)B2A18-A2-B2A17-2A3-3A16-A6-3A12-2A9-3A8-2A14-A6BA82-M18-H4-C19-Ac3-C18-I4-C18-H4-G18-H4-C18-O4-C18-E4-Am18-A4-A17-A6-A16-A6-A17-A4-A18-A4-A17-A5-A18-A4-A2(18-A3-2A)18-A2-BA20-2(A-B21-)A24-B23-2(B22-A)2B20-2A-B2A17-3A3-4A12-3A9-3A4-A2-2A15-B4-2B57-C20-Al2-C20-Ac2-C20-C2-C19-C4-C18-H4-V18-O4-D18-E5(4-A18-A)3(3-2A18-A)3-A19-A2-B21-A23-A24-2(B23-)B71-B23-2B22-2B2A18-2A3-4A7-A4-3A9-2AB6-B2A55-C20-Al2-C20-Ac2-C20-C2-C19-C3-C19-C4-V18-O4-D18-E5(4-A18-A)3-2A19-2(A2-A20-)A-B21-A23-A24-B191-2B22-B-3A9-A6-3A5-2A11-3A10-2AB6-2B32-2(C20-C2-)C19-C3-C19-C2(4-C18-O)4-D18-E4(4-A18-A)3-A19-A3-2(A20-A2-)A20-A-B21-A24-B216-B22-2B12-A9-B-4A14-4A6-2A8-B-2A12-2(B8-)C19-H3-C20-C2-C19-3(C4-C18-)H4-D18-E4(4-A18-A)3-A19-A3-2(A20-A2-)A20-A-B22-B264-B12-A9-B-2A13-A3-3A4-3A10-A-2A10-2(2B8-)M18-H4-C18-C4-C18-H4-Af18-H4-G18-H4-V18-O4-D18-E4(4-A18-A)3-A19-A3-2(A20-A2-)A20-A-B22-B264-B12-A2-A6-B-2A14-A3-2A4-3A11-4A9-2(2B8-)2(C18-H4-)G18-H4-Af17-G5-G17-G6-A16-E5-D18-E5(4-A18-A)3-3(A20-A2-)A21-2B239-B22-2B22-B-3A12-A3-3A5-2A10-A-2A10-2B8-2B9-W16-S6-C16-S6-J16-H6-E16-G6-A15-E7-A15-D7-A16-DE5-A16-2(A5-A17-)A5-A18-A4-A18-A3-A19-2A2(2-A20-A)2-A21-B-A22-B191-B23-B22-B-A19-2A3-3A14-2A8-4A6B4A13-B6-B12-B14-M8-B14-R8-I14-I8-I13-OJ8-A12-EO9-2A10-ADE9-A14-AD6-2A15-4(A6-A16-)A5-A17-A-A3-A18-2A2-A19-2A2-A20-A2-A21-B-A22-2(B23-)B71-2(B23-)B22-B-2A18-2AB2-4A12-4A7-14A14-6B38-W11-SH10-XI9-IHI10-2GIE4D2EIJGH10-EJE5A2DAeEG11-12A13-4A2-4A13-A10-AD2A9-A11-4A3(6-2A15-A)3(6-A16-A)5-2A16-A5-A18-2A2-A19-2A2-A20-A2(B-A21-)2B2(23-B)A22-BA23-A21-B-3A15-4AB3-18A9-12A84-BMGBAd2(MG)2R14-MEIDEDNJR90-2A18-4A2-5A13-A9-A12-2(A10-4A9-)A2(10-4A8-2A)10-4A8-A11-A2-A8-A14-A7-2A15-2(A5-2A16-)2A4-A18-2A2-2(2A18-2AB-)2A18-2AB2-A18-2AB2-2A4-8A4-3AB2-21A5-15A276-8A16-9A5(14-10A)13-14A10-2A2F4A3F3A10-2A2(2F6A2F3A8-3A)2F5A2F4A7-3A3F6A2F4A6-5AF4A3F5A3(6-18A)7-4A8-4A172-
