model
size = 22 19 31, scale = 0.05, origin = -y
material deform = 1, fade = true, lighting = smooth, roughness = 0.3, metalness = 0.6
  colors = A:#EEE B:#303 C:#96C
voxels
3-12B2(10-12A)10-11A2(12-10A)13-9A19-2A253-BA10-AB8-2A10-2A8-2A9-2(3A8-)3A9-2A8-2A10-3A7-2A10-12A11-11A11-10A2(13-9A)15-6A164-BA12-AB2(6-2A12-2A)6-3A10-3A7-2(2A10-2A8-)3A2(9-2A)8-3A9-3A7-2A11-2A7-2A11-4A4-3A2(11-11A)11-10A2(13-9A)33-11B11-11B8-BA14-AB4-2A14-2A5-A14-2A5-2A12-3A5-2(2A12-2A6-)3A11-2A7-2A10-2(3A7-3A9-)5(2A9-)2A8-3A9-3A7-2A10-3A7-2A11-3A5-3A10-11C10-13B9-13B7-BA15-B2(4-2A15-A)4-2A2(14-2A5-A)14-2(2A5-2A13-)2A5-2A12-2(2A6-3A11-)2A7-2A11-2A7-2A10-3A7-3(3A9-2A8-)C11AC8-15B7-15B6-B16-B2(4-A16-A)4-2A4(15-A5-A)2(14-2A5-A)14-2A5-2A2(13-2A4-3A)2(12-3A5-2A)12-2A6-3A11-A7-C4A6-3AC7-3(5B6-)5B5-B16-B4-A16-2(A4-2A15-)5(A5-A15-)4(A4-2A15-)A2(4-2A14-2A)4-3A13-2A4-C4A8-3AC5-2(5B8-5B4-)BA15-B2(4-2A15-A)5(5-A15-A)2(4-2A15-A)6(4-A16-A)4-C3A10-3AC4-2(4B10-5B3-)BA15-B4-2A6(15-A5-A)15-A4-2A15-5(A4-A16-)A4-2(A17-A3-)C2A12-2AC4-3B12-4B3-3B12-4B4-BA13-AB5-2A13-2(2A5-A14-)2A4(5-A15-A)4-2A15-3(A4-A16-)2A4(3-A17-A)3-CA14-AC4-2B14-3B3-2B14-3B4-B2A11-AB6-3A11-2A6-2A12-2A6-2A13-2(2A5-A14-)2A2(5-A15-A)4-2A15-2(A4-A16-)2A3-A16-2A4(3-A17-A)3-CA15-AC3-2B15-3B2-2B15-3B4-B2A8-2AB8-3A9-2A8-2A10-3A6-2A12-2A6-2A13-A6-A14-2A5-A2(15-A4-2A)15-2(A4-A16-)2A3(3-A17-A)3-2(A17-2A2-)CA15-AC3-2B15-3B2-2B15-3B5-B9A2B10-12A9-4A6-4A8-3A8-4A6-3A10-3A6-2A13-2A5-A14-2A2(4-2A15-A)4-A16-A4-A16-2A2(3-A17-A)3-3(A17-2A2-)CA15-AC3-2B15-3B2-2B15-3B7-8B14-8A13-10A11-12A9-4A6-5A6-4A10-2A6-2A13-2A5-A15-A4-2A15-2(A4-A16-)2A2(3-A17-A)3-A17-3A-2(A17-2A2-)CA15-AC3-2B15-3B2-2B15-3B73-8A13-12A8-15A6-6A8-3A5-3A12-2A4-2A15-A4-2(A16-2A3-)2(A17-A3-)A17-2A2-A17-3A-A17-2A2-CA15-AC3-2B15-3B2-2B15-3B96-9A11-13A6-8A6-3A5-4A11-2A4-2A15-A4-2(A16-2A3-)2(A17-A3-)2(A17-2A2-)A17-3A-CA15-2A2C-2B15-7B15-3B51-8A13-10A10-14A7-6A7-3A6-4A11-2A5-A15-A4-2A15-2(A4-A16-)2A2(3-A17-A)3-A17-2A2-2(A17-3A-)CA15-2AC2-2B15-4B-2B15-3B6-10B12-10A11-12A9-4A6-4A8-3A8-4A6-2A12-3A5-A14-2A5-A15-A4-2A15-2(A4-A16-)2A3-A17-A3-A17-2A2-A17-3A-2(A17-2A2-)CA15-AC3-2B15-3B2-2B15-3B5-BA6-3AB10-2A3(8-3A)8-2A10-3A6-2A12-2A6-2A13-2A5-A2(15-A4-2A)15-2(A4-A16-)2A3-A17-2A2-2(A17-A3-)2(A17-2A2-)CA15-AC3-2B15-3B2-2B15-3B4-BA10-A2B7-2A10-3A6-3A11-2A6-2A12-2A6-2A13-2A5-A14-2A2(5-A15-A)4-2A15-2(A4-A16-)2A4(3-A17-A)3-A17-2A2-CA15-AC3-2B15-3B2-2B15-3B3-BA12-AB6-2A13-A6-2A13-2(2A5-A14-)2A3(5-A15-A)4-2A15-2(A4-A16-)2A3-A16-2A4(3-A17-A)3-CA15-AC3-2B15-3B2-2B15-3B3-B14-AB2(5-A14-2A)5(5-A15-A)4-2A15-3(A4-A16-)2A4(3-A17-A)3-C2A13-AC4-2(3B13-3B3-)BA15-B2(4-2A15-A)5(5-A15-A)4-2A15-5(A4-A16-)A4-A17-A3-A16-2A3-C3A11-2AC4-2(4B11-4B3-)B16-B4-A16-2(A4-2A15-)4(A5-A15-)2(A4-2A15-)4(A4-A16-)A4-2A15-A4-2A14-2A4-C4A9-3AC4-2(5B9-5B3-)B16-B2(4-A16-A)4-2A5(15-A5-A)2(15-A4-2A)3(14-2A4-2A)14-2A4-3A13-2A5-2A12-3A4-C5A7-3AC5-2(6B7-5B4-)B16-B4-A16-2(A4-2A15-)A5-A15-A2(5-A14-2A)3(5-2A13-2A)5-2A12-3A5-2(2A12-2A6-)3A11-2A6-3A11-2A7-2A10-3A6-C5A4-4AC7-7B3-6B6-7B3-6B5-BA14-AB2(4-2A14-2A)5-A14-2(2A5-2A13-)2A5-2A12-2A6-3A3(11-2A7-2A)10-3A7-2(3A9-2A8-)3A2(9-2A)8-3A9-3A7-3A8-C12AC8-15B7-15B6-BA13-AB5-3(2A12-2A6-)2A12-2A2(7-2A10-3A)7-3A4(9-2A)8-2(3A9-3A7-)2A11-3A6-2A2(11-11A)11-10A11-C10AC10-13B9-13B7-B2A10-2AB6-3A10-3A7-3(2A10-2A8-)3A8-3A9-2A8-2A10-3A7-2A11-7A-3A11-11A11-10A2(13-9A)14-8A56-10C2(12-10B)10-B2A8-A2B8-3A8-2A10-2A8-2A10-3A7-2A10-8A-3A10-12A11-10A12-10A13-9A18-3A210-11B11-11A2(12-10A)13-9A18-3A295-
