model
size = 28 32 30, scale = 0.05, origin = -y
material deform = 1, fade = true, lighting = smooth, roughness = 0.3, metalness = 0.6
  colors = A:#8A8EDC B:#2222AE C:#5988A0 D:#BBB E:#DDD F:#303 G:#E00 H:#336 I:#C0F J:#555 K:#966 L:#603 M:#999 N:#369 O:#444 P:#330 Q:#636 R:#066 S:#00B T:#333 U:#969 V:#699 W:#69C X:#00A Y:#888 Z:#633 Aa:#CCC Ab:#500 Ac:#800 Ad:#933 Ae:#AAA Af:#00F Ag:#D00 Ah:#C33 Ai:#63F Aj:#A00 Ak:#C66 Al:#9C6 Am:#EEE An:#99C
voxels
405-4C23-5C22-6C22-2(5C23-)5C24-3C26-2C670-4C23-5C22-6C22-2(5C23-)5C24-3C26-2C615-2C23-7C20-8C19-4C24-3C25-2C2(25-3C)26-2C26-3C25-4C25-5C24-3C529-7C20-4C2-2C19-2(2C25-)3(2C26-)2(C27-)2(2C26-)3(2C27-)4C25-3C361-8G20-8G18-3C6AbC19-9C18-3(2C25-)2C26-C27-C4(26-2C)2(27-C)4(27-2C)27-3C314-Aj17-2G8AaG17-2G8-G16-C27-2(2C25-)2C2(26-C)2(27-C)26-3(C27-)C28-2(C27-)C28-C3(27-2C)28-3C279-6E2-Aj15-G3E6-2EG15-G25-2C27-2(C26-)C27-2(C26-2(C27-))C27-C28-2(C27-)C28-C27-3(C28-)2C28-3C225-2E22-4E2-4EAj13-2G2C10-G13-2G25-C28-2(C26-)C7-2(A19-C6-)2A2-A16-C6-2A2-A16-C7-2A18-C7-4B16-C8-3B-B14-C8-5B14-C7-8B12-C4-7B-3B12-C4-B-4B-2B14-C4-3B2-5B14-C6-7B14-C6-2B-2B17-3(C28-)2C28-2C107-9D19-9D20-8D23-8E17-3E8-2E2Aj11-GE13-2G11-G26-C5-Am21-C5-O20-C6-A20-C6-2A18-C2-4B-3A17-C-5B5A15-C-12B14-C-13B13-C-13B2S2B9-C16B3S8-C18BS8-C19B8-C18B9-C17B2(11-C16B)12-C-12B14-C3-8B17-2(C28-)2(2C28-)C78-2(12D16-)11D18-10D4E13-G8D6-2EAj10-G16-G9-CG25-C27-C6-A20-C6-2A18-C-6B3A-2A14-C2B4AB7A12-C2B13A2(12-CB14A)12-CB16A9-C-20B6-C-2(19BS7-C)20B7-C19B8-C18B10-C16B11-C-15B12-C-12B14-C3-7B18-C3(28-2C)77-5D4Ae5D14-14D15-13D15-11D2-3E11-G9D7-E-E8-GE5D11-CG7-CG25-C4-6A-3A14-C2-12A12-C-B14A11-CB15A10-CB16A10-C17A9-2(CB16A10-)CB16A-A8-CB18A8-CB19A7-C21BS5-C20BS6-C-20B7-C19B8-C18BS9-C16B11-C-14B13-C2-9B17-2(C28-)2(2C28-)C49-3D7W5D13-4D6M5D13-4D4W7D14-11D3-2E11-G9D7-3E8-G6D3A9-GE6-CG13A6-G5-C2-14A11-C-15A11-CB16A9-C2B16A9-C17AAi8-CB18A8-C18A9-C17HJ9-2(C20A7-)C19AAf7-C20A7-C21BS5-C22B5-C21B7-C17BSB8-C-15BS11-C16B11-C2-12B14-C3-7B18-C3(28-2C)49-3D9V3D13-3D6V6D13-3D5M7DE12-4DK7D4-2E9-GH9D8-2E7-GA6D8A5-2E4-CG15A3-2I-G4-C-16A2-2I6-C-16A2-2I5-C-B16A9-C2B16AAi7-CB19A7-C18RAl8-C2B17O8-C19P7-C20A7-C21A6-C20AAf6-CB20A7-C22B5-C21BS5-C22B5-C21B7-C17BS9-C-15BS11-C16B12-C2-10B16-2(C28-)2C28-3C49-2D11K2D13-3D6K6D13-3D5K7DE12-3D2U7D4-4E7-K10D6A4-2E5-GH6D8HA5-E4-CG15T2A-2I2-G2-C2-16JA4I5-C17HA-2I5-C-B17A8-C19A7-CB18AAi7-C19A8-C19N7-C20J7-C21A6-C20AAf2(6-C21A)6-CB20A7-C22B5-C21BS5-C20BS7-C18B9-C-16B11-C15BS12-C-12B15-2(C28-)2C28-3C49-2D11M2D13-2D7K6D13-3D5Y7D5E8-3D2U6DA5-C2EAc6-U10D2U5A3-YAc5-2Z6D9Z2A2I2-E3-CG17F4I-G2-C2-17F4I5-C18Q4I4-CB19A2I5-C20A6-CB20A6-C21A5-2(C20A7-)C21A6-C20AAf6-C21A6-C23X4-C21A6-C23B5-C22B5-C20BS7-C18B9-C-16B11-C15B12-C2-12B14-C3(28-2C)28-C21-2D11K2D13-2D7Ah6D13-2D6Ak7D5EAc7-3D2M6D3A4-3AcE5-U10D4U4A3-Ac5-2L6D11L2I2-E3-C18F4I-G2-C2-17F4I-G3-C18L4I4-CB19A2I4-CB21A2(5-C22A)4-C22A5-4(C21A6-)C23B4-C22BS4-C23B5-C21B6-C19BSB6-C-17BS9-C-16B11-C15B12-C2-12B14-C28-2C28-C28-3C28-C21-2D11U2D13-2D7Ag6D13-2D6Y7D5EAc7-3D2M6DAMA4-3AcE5-Y10D4Y4A3-Ac5-2Ad6D11Ad2I2-E3-C18F4I-G2-C2-17F4I-G3-C18L4I4-CB19A2I4-CB21A2(5-C22A)4-C22A5-4(C21A6-)C21B6-C22B5-C21BS2(6-C21B)6-C-17BS9-C-16B11-C14B13-C2-11B15-C28-2C28-C28-3C28-C21-2D11M2D13-2D7K6D13-3D5Y7D5E8-3D2U6DA5-Y2EAc6-U10D2U5A3-CAc5-2Z6D9Z2A4-E3-CG17FA2I2-G2-C2-17F4I5-C18QA2I5-CB19A7-C20A6-CB20A6-C21A5-2(C20A7-)C21A6-C20AAf6-2(C20A7-)C21B6-C22B6-C20BS6-C20B8-C18B9-C-16B11-C-13B13-C2-11B15-C3(28-2C)28-C21-2D11K2D13-3D6K6D13-3D5K7DE12-3D2U6D5-5E6-K10D6A4-2E5-GH6D8HA5-E4-CG16TA-2I2-G2-C2-16JA-2I6-C17HA-2I5-CB18A8-C19A7-CB18AAi7-C19A8-C19N7-C20J7-C21A6-C19AAf2(7-C20A)7-C20B8-2(C20B7-)C20B8-C17B10-C-15B12-C-13B14-C2-9B17-2(C28-)2C28-3C49-3D9V3D13-3D6V6D13-3D5M7DE12-4DK6D5-2E9-GH9D8-3E6-GA6D8A5-CE4-CG16A5-G4-C-16A10-C-16A9-C-B16A9-CB17AAi7-CB19A7-C18RAl8-C19O8-C19P2(7-C20A)7-C19AAf7-CB2(19A8-C)19B8-C20B7-C19BS8-C17B10-C2-13B13-C4-9B15-C3-7B18-2(C28-)2C28-3C49-3D7WAn4D13-4D5M6D13-4D4W7D14-10D4-2E11-G9D7-3E8-G6D12-GE6-CG13A6-G5-C2-14A11-C-16A10-CB16A9-CB17A9-C17AAi8-CB18A8-C18A9-C17HJ9-C19A8-C18A9-C17AAf2(9-C18A)9-CB17A9-C-2(17B10-C)-15B12-C2-10B15-C5-B22-2(C28-)2(2C28-)2C49-4D5Ae5D14-5D3W6D15-13D15-10D3-3E11-G9D7-E-E8-GC5D11-CG7-CG25-C3-12A13-C-13A12-C-15A11-CB15A10-CB16A10-C2(17A9-CB)3(16A10-CB)14A12-C17B10-C18B9-C-17B10-C-16B10-C-15BS11-C2-13B12-C3-9B16-3(C28-)2(2C28-)C50-2(12D16-)12D17-9D-4E13-G8D6-2EG10-G16-G9-CG25-C6-A20-C5-3A19-C5-2A3-3A13-C-4B9A13-C2B13A11-C2B14A11-CB15A11-CB14A12-CB13A2(12-C-14B)13-C15B12-C16B11-C-16B10-C-3B11ABS11-C-14BS11-C3-11B14-C3-8B16-2(C28-)2(2C28-)2C79-2(9D19-)9D20-7D4E16-G3E8-2E2G12-G13-2G11-CG24-C28-C26-C5-2A20-C4-AB2A18-C2-5B3A17-C-5B5A15-C-12B14-C-13B13-2(C-12B14-)C-13B13-C-14B12-C2-13B12-C3-12B2(13-C3-11B)14-C4-6B17-3(C28-)2(2C28-)C170-2E20-G-4E2-4EG15-GE10-G13-2AbG24-C5-Am22-C4-O21-C5-A20-C7-2(A19-C6-)2A2-A16-C6-2A2-A16-C7-2A18-2(C27-)C5-B21-C4-4B19-C6-B20-2(C27-C28-)3(C28-)2C28-2C224-E2AaEAaE-2G15-G3E6-C2G15-G25-2C27-2(C26-)C27-2(C26-2(C27-))C27-C28-2(C27-)C28-C27-3(C28-)2C28-3C258-G17-2G8AaG17-2G8-G16-C27-2(2C25-)2C2(26-C)2(27-C)26-3(C27-)C28-2(C27-)C28-C3(27-2C)28-3C306-8G20-8G18-3C6AbC19-9C18-3(2C25-)2C26-C27-C4(26-2C)2(27-C)4(27-2C)27-3C446-7C20-4C2-2C19-2(2C25-)3(2C26-)2(C27-)2(2C26-)3(2C27-)4C25-3C504-2C23-7C20-8C19-4C24-3C25-2C2(25-3C)26-2C26-3C25-4C25-5C24-3C266-
