model
size = 30, scale = 0.05, origin = -y
material deform = 1, fade = true, lighting = smooth, roughness = 0.3, metalness = 0.6
  colors = A:#86C166
voxels
-41A14(6-24A)6-5838A5(14(6-6A6-12A)6-6A6-462A)14(6-6A6-12A)6-6A6-468A16(14(6-24A)6-474A)14(6-24A)6-462A
