model
size = 31 31 13, scale = 0.05, origin = -y
material deform = 1, fade = true, lighting = smooth, roughness = 0.3, metalness = 0.6
  colors = A:#888 B:#111 C:#9CF
voxels
135-B7-B23-B5-B25-B3-B27-B-2(B29-)B-B27-B3-B25-B5-B23-B7-B25-3B26-7B24-B5-B25-4B26-B4-2B24-B6-B22-B7-B22-B2(-2B)-B22-2(B2-)B-B23-B6-B24-B4-B26-4B209-3(11A20-)AB7ABA20-2B7A2B20-2AB5AB2A20-2(3AB)3A20-4ABAB4A20-5AB5A20-4ABAB4A20-2(3AB)3A20-2AB5AB2A20-2B7A2B19-2ABA5BAB2A18-3A7B3A18-3AB5AB3A17-5A5B5A16-4AB4A3B3A15-5AB2AB3A2B3A14-4AB7A2B3A13-5AB3(A2B)4A12-5AB3(A2B)4A11-7AB6A2B5A10-7A2B4A2B6A11-7A6B6A13-17A17-11A143-13(A11-A18-)A11-A17-2A11-2A2(16-A13-A)2(15-A)13-2A15-2A12-2A15-2A11-3A15-3A9-2(4A15-4A8-)4A15-4A9-4A13-4A11-5A9-5A13-17A16-13A21-7A82-14(A13-A16-)A13-2(A15-)A14-A15-A13-A17-A12-A17-A11-2(2A17-2A10-)2A17-2A8-4A17-4A5-5A17-5A6-4A15-4A9-2(5A11-)4A11-4A13-17A16-13A21-7A50-15(A15-A14-)A15-A13-A17-A12-A17-A11-2A17-2A10-2A17-2A69-2A23-2A4-3A21-3A3-5A19-5A4-6A13-6A7-6A11-6A9-5A11-5A12-2AC2A7-5A16-3A7-3A21-A5-A18-16(A17-A12-)A17-A11-2A17-2A192-3A23-3A-5A21-5A2-3A21-3A6-5A13-5A9-5A11-5A13-2A11-2A18-3A5-3A2(16-15(A17-A12-)A17-A11-2A17-2A223-3A23-3A-5A21-5A-4A21-AC2A4-3A19-3A7-6A11-6A10-4A11-4A16-A9-A)16-16(A17-A12-)A17-A11-2A17-2A192-3A23-3A-5A21-5A2-3A21-3A6-5A13-5A9-5A11-5A13-2A11-2A18-3A5-3A17-15(A15-A14-)A15-A13-A17-A12-A17-A11-2A17-2A10-2A17-2A69-2A23-2A4-3A21-3A3-4A21-4A6-A19-3A7-4A15-4A2(9-6A)12-6A5-6A16-4A5-4A21-7A19-16(A15-A14-)A15-A13-A17-A12-A17-A11-2(2A17-2A10-)2A17-2A8-3A19-3A5-A-3A17-5A7-3A15-4A9-4A13-4A11-19A13-17A16-13A21-7A51-15(A13-A16-)A13-2(A15-)A14-A15-A13-2A15-2A12-2A15-2A11-3A15-3A9-2(4A15-4A8-)5A13-5A10-4A11-5A11-6A7-6A13-17A16-13A20-9A82-14(13A18-)13A17-15A16-15A15-17A14-17A13-2(19A12-)19A11-21A10-21A11-19A13-17A17-11A134-
