model
size = 10 12 32, scale = 0.05, origin = -y
material deform = 1, fade = true, lighting = smooth, roughness = 0.3, metalness = 0.6
  colors = A:#FF0 B:#6F6 C:#3FF D:#F0F E:#F06 F:#66F G:#F93
voxels
87-A43-A9-2E8-3D8-2F97-2E8-3D8-3F8-2C96-3D8-3F8-3C8-2B85-3D8-3F8-3C8-3B8-2A75-2D8-4F7-3C8-3B8-2A9-2G54-E9-2D8-4F7-3C8-3B8-3A8-2G9-2E9-2D9-F11-A10-E9-3D8-3F7-4C7-3B8-3A8-2G9-2E9-2D9-FB10-A10-2E8-3D8-3F7-4C7-3B8-3A8-2G9-2E9-2D10-B10-2A9-2E8-3D2(8-3F8-3C7-3B8-3A8-3G8-2E10-D10-B10-2A9-2E9-2D)8-3F8-3C7-4B7-3A8-3G9-E10-D10-B10-A10-2E9-2D8-3F8-3C8-3B7-3A8-3G9-2E9-D10-B10-A10-2E9-2D9-2F8-3C8-3B7-3A8-3G2(9-2E9-D21-A10-E10-2D9-2F8-3C8-3B7-4A8-2G)9-2E9-D21-A10-E10-2D9-2F9-2C8-3B7-4A8-2G9-2E9-D21-A10-E10-D10-2F9-2C8-3B7-4A2(8-2G9-2E9-D32-E10-D10-2F9-2C8-3B8-3A)8-2G9-2E9-D43-2(D10-F10-2C8-3B8-3A8-2G9-2E53-)D10-F10-2C9-2(2B8-3A8-2G9-2E53-D10-F10-C10-)2B8-3A8-2G9-2E64-2(F10-C10-B10-2A8-2G9-E65-)F10-C10-B10-2A8-2G75-F10-2(C10-B10-A10-G86-)C10-B10-A10-G97-B10-A10-G31-
