model
size = 31 19 27, scale = 0.05, origin = -y
material deform = 1, fade = true, lighting = smooth, roughness = 0.3, metalness = 0.6
  colors = A:#FF0 B:#6F6 C:#3FF D:#F93 E:#66F F:#F0F G:#F06
voxels
257-5(13D18-)13D419-17A4(14-2(3A4-)3A)14-17A415-10B-10B4(10-2B2-6B-6B2-2B)10-10B-10B412-6C11-6C4(8-C2-3C11-3C2-C)8-6C11-6C410-5E15-5E4(6-E2-2E15-2E2-E)6-5E15-5E408-4F19-4F4(4-F-2F19-2F-F)4-4F19-4F406-4G21-4G2(2-G)3(21-3(G2-)G)21-2(G2-)4G21-4G404-4D23-6D3(-D23-D-4D)-D23-D-6D23-4D403-3A3(25-6A)25-4A-A25-6A25-3A403-3B25-4B3(-B25-B-2B)-B25-B-4B25-3B403-3C25-4C3(-C25-C-2C)-C25-C-4C25-3C403-3E25-4E3(-E25-E-2E)-E25-E-4E25-3E403-3F25-4F3(-F25-F-2F)-F25-F-4F25-3F403-3G25-4G3(-G25-G-2G)-G25-G-4G25-3G403-4D23-5D3(2-D23-D2-2D)2-D23-D2-5D23-4D403-5A21-7A3(-2A21-2A-4A)-2A21-2A-7A21-5A404-5B19-5B4(2-2B-2B19-2B-2B)2-5B19-5B406-5C17-5C4(4-2C-2C17-2C-2C)4-5C17-5C408-6E13-6E4(6-2E-3E13-3E-2E)6-6E13-6E410-9F5-9F4(8-3F-5F5-5F-3F)8-9F5-9F413-19G4(12-3G3-7G3-3G)12-19G269-D29-3D27-5D25-7D23-9D21-11D19-13D17-4(15D16-)7D-7D17-5D3-5D179-A29-3A27-5A25-7A23-9A21-11A19-4A5-4A17-4A7-4A15-17A3(14-4A-7A-4A)14-17A15-7A-7A17-5A3-5A117-B29-3B27-5B25-3B-3B23-3B3-3B21-3B6-2B19-3B8-2B17-3B4-B5-2B15-3B4-3B5-2B13-3B4-5B4-3B12-2B4-2B3-2B4-2B12-2B3-2B5-2B3-2B12-2B15-2B12-3B14-2B13-17B15-7B-7B17-5B3-5B55-C29-3C27-5C25-7C23-3C3-3C21-3C5-3C19-3C7-3C17-3C4-C4-3C15-3C4-C-C4-3C13-3C4-C3-C4-3C11-4C3-C5-C4-3C10-3C3-C2-3C2-C3-3C10-3C2(2-C)3-2(C2-)3C10-3C3-2C4-3C3-3C10-3C15-3C11-3C2-C2-3C5-3C13-3C2-7C-4C15-15C17-6C-6C86-E29-3E27-5E25-7E23-9E21-3E2(-E)-3E19-5E3-5E17-3E-E5-5E15-5E7-E-3E13-5E9-5E12-4E4-3E4-4E12-5E2-2E2-E2-5E13-10E-6E15-15E17-6E-6E19-4E3-4E180-F29-3F27-2F-2F25-2F3-2F23-2F5-2F21-2F7-2F19-2F9-2F17-2F11-2F16-F13-F16-2F4-3F4-2F17-2F2-2F-2F2-2F19-4F3-4F21-2F5-2F73-
