model
size = 20 32 24, scale = 0.05, origin = -y
material deform = 1, fade = true, lighting = smooth, roughness = 0.3, metalness = 0.6
  colors = A:#555 B:#C66 C:#FF0 D:#990 E:#00F F:#0D0 G:#EEE H:#C0F I:#CF0 J:#D00 K:#00B L:#111 M:#E00
voxels
451-2B18-2B17-4B189-2(4B18-)5B17-3B529-2D17-D2-D16-D-5B13-D2-D-4B12-2D4-6B16-4B569-2B47-2B18-2B549-2B18-2B46-4A15-2(6A14-)6A13-4(8A12-)8A13-6A387-2B47-2A16-6A13-3(8A12-)8A11-5(10A10-)10A12-6A327-2B18-2B44-3(8A12-)8A11-8(10A10-)10A12-6A14-6A15-4A268-2B64-8A11-13(10A10-)10A12-6A14-6A247-2(2B4-)2B51-15(10A10-)10A11-8A245-2B2(4-3B)50-9(10A10-)10A8-5(14A6-)14A9-8A13-2(6A14-)2(6A10-D3-)6A10-D135-B5-4B2-4B11-2B4-2B12-2B4-2B11-A2B4A2BA9(10-10A)8-5(14A6-)14A8-10A12-6A14-6A10-D3-2(6A14-)6A30-D25-2(2F18-)2F47-2B5-4B2-4B11-2B4-2B12-2B4-2B11-A2B4A2BA9(10-10A)8-B-10A-B8-10A11-4(8A12-)8A13-6A14-6A10-D3-6A14-6A10-4B6A4B5-3(5B6-5B4-)2(5B2-2E2-5B4-)5B2-2E2-5B5-3B8-3B-B5-5B2-5B10-2B4-2B32-9(8A12-)8A9-B3-6A3-B10-7(6A14-)6A10-D3-3(6A14-)6A10-D3-2(6A14-)6A15-4A17-2J18-2J7-B5-5B2-5B10-2B4-2B33-6A13-7(8A12-)8A13-6A10-B12-B130-2(6A14-)3(6A10-D3-)3(6A14-)6A15-4A17-2E18-2E13-5B2-5B51-6A13-7(8A12-)8A29-B12-B130-8(6A14-)6A15-4A17-2I18-2I13-5B2-5B70-6(8A12-)8A49-B12-B130-5(6A14-)6A12-2(2C6A2C10-)3C4A3C13-4A17-2F18-2F13-5B2-5B91-5(6B14-)6B50-B12-B130-5(6A14-)6A12-2(3C4A3C10-)3C4A3C13-4A17-2H18-2H13-M3BC2-C3BM247-B12-B130-4(6A14-)6A53-L6-L92-K6-K248-3B10-3B4-3B10-3B110-4A15-3(6A14-)6A409-3B10-3B4-3B10-3B5-2(B12-B6-)B12-B51-3(4A15-6A14-6A15-4A16-4A556-)4A15-6A14-6A15-4A17-2A538-2G18-2G17-2(B2AB16-)4B17-2B147-
