model
size = 29 14 29, scale = 0.05, origin = -y
material deform = 1, fade = true, lighting = smooth, roughness = 0.3, metalness = 0.6
  colors = A:#FF6905 B:#FFF C:#0A0000 D:#F6D644 E:#F28214 F:#F2AB14 G:#F29114 H:#FAEB88 I:#FDF4B9 J:#F3BC27 K:#FF5705 L:#B9E7FD M:#4AA7F6 N:#1352F1 O:#FF3A05 P:#1224B0 Q:#F23914 R:#ED2707 S:#FE3C00 T:#030303
voxels
96-11B18-2(C2B)3C3(2B18-4(CB)C)2B18-3(CB)3CBC18-11B219-3B9-3B14-3C3(9-BCB14-CBC)9-BCB14-3C9-3C14-3B9-3B216-2B5(13-2B12-BC)13-CB12-2B13-2B214-2B2(15-2B10-CB)15-2B10-2B2(15-BC10-CB)15-BC10-2B15-2B212-2B17-2B8-BC17-2B8-2C17-2B8-CB17-2C8-2C17-CB8-BC17-2C8-2B17-2B210-2B19-2B6-CB19-2C6-2C19-2C6-BC19-2C6-2C19-2C6-CB19-2C6-2B19-2B208-2(2B2(21-2B4-BC)21-2B4-)2B21-2B206-2B3(23-2B2-CB)23-BC2(2-CB23-2C)2-2B23-2B204-2B25-2B2C25-2CBC25-4C25-2CBC25-2B2C25-4B25-2B203-B27-BC27-2B27-BC27-CB27-2C27-CB27-B203-B6(27-2B)27-B203-B27-BC2(27-2C)27-BC27-2C27-CB27-B203-B27-BC2(27-2B)27-CB27-2B27-CB27-B203-B27-BC5(27-CB)27-B203-B6(27-2B)27-B203-B27-BC27-CB3(27-BC)27-CB27-B203-B27-BC27-CB27-BC27-2B27-BC27-CB27-B203-B27-BC2(27-2C)27-CB27-2C27-CB27-B203-B6(27-2B)27-B121-8C3-8C7-7C3-2C-2C3-7C2-4C9-C-C9-4C2BT10-3C10-T2B-2C11-C11-2(2C-2BC23-C2B-2C23-)2C-2BC23-C2BCTC23-7C21-CT2C-7C13-7C4-5C13-5C8-8B3-8B7-3BCA6CB-B6CAC3B2-2BCNMLI5-CB-BC5-ILMNC3B2ANMLI6-CBC6-ILMN2A2B2ANMLI6-3C6-ILMN2A2B2ANMLI7-C7-ILMN5(2A2B2APNML15-LMNP)2A2BCAPNML15-LMNPASB-2BC3A4C7-4C4A2B4-4B4C7-4C4B8-8B3-8B7-3BC4A3CB-B3C4AC3B2-2BC4ADFG2-CB-BC2-GFD4AC2BC6ADFG3-CBC3-GFD6A2C6ADFG3-3C3-GFD6A2C6ADFG4-C4-GFD5(6A2C6AIDF9-FDI)6ACBC5AIDF9-FDI5ACB-2BC6A9C6AS2B4-7B9C7B8-8B3-8B7-3BC6ASB-BC6AC3B2-2BC7AE2AB-B2AE7AC2BC9AE2ACBC2AE9ACP9AEA-3C-AE9A2P9AEA2-C2-AE4(9A2P9AGE5-EG)9APC9AGE5-EG9ACBC8AGE5-EG8ASB-2BC8A5C8AS2B4-23B8-8B3-8B7-3BC6ACB-BC6AC3B2-3C10AB-B10A4CM12AB12AMC-M10AQ3AQ10AM2-N10AQRARQ10AN2-N10A2QR2Q10A3(N2-N11AQRQ11A)N-CN12AQ12AN3C12AQ12A2C-2BC21AS2B4-23B8-8B3-8B7-3BC6ACB-BC6AC3B3-2C10AB-B10A2C3-L11AB11A2(L4-L23A)L5(4-M23AM)3-CML21ALMC2-2CL21A3C4-23B8-8B3-8B7-2CBC2D4ACB-BC4A2DCB2C4-CI2HD6AB-B6AD2HIC5-I2HD7AB7AD2HI6-I2HD15AD2HI6(6-LIHD15ADHIL)7-IH2D13A2DHI6-C-I2H2D11A2D2HI2C5-2C19B2C8-2C6B3-6B2C8-3C2JFGEACB-BCAEGF2J3C8-D2JFGEAKB-BKAEGF2JD9-H2DJFGEAKCBCKAEGFJ2DH8-2HDJFGEAKOCOKAEGFJD2H5(8-IHDJFGEAKOROKAEGFJDHI)8-IHDJFG2EAKOKA2EGFJDHI9-HDJFG2EAKOKA2EGFJDH11-HDJFGEAKOKAEGFJDH10-3C15B3C10-3C4B3-4B3C14-FGEACB-BCAEGF15-JFGEAKB-BKAEGFJ13-DJFGEAKCBCKAEGFJD11-HDJFGEAKOC5(OKAEGFJDH10-HDJFGEAKOR)OKAEGFJDH10-HDJFG2EAKOKA2EGFJDH11-DJFG2EAKOKA2EGFJD13-DJFGEAKOKAEGFJD13-2C13B2C14-5C3-5C20-2C-2C25-C-C26-3C27-C253-15C7-
