model
size = 31, scale = 0.05, origin = -y
material deform = 1, fade = true, lighting = smooth, roughness = 0.3, metalness = 0.6
  colors = A:#EEE B:#001 C:#111 D:#B00
voxels
385-2AC2A25-A2DC2DA24-2ADCD2A3(24-3AC3A)25-2AC2A677-2AC2A24-4AC4A21-5AC5A20-11A19-4(B11AB18-)B11AB19-11A20-5BC5B21-4AC4A24-2AC2A522-2DC2D24-4AC4A21-11A19-B11AB17-AB11ABA16-AB11ABA15-4(17A14-)17A15-AB11ABA16-2B11A2B17-B11AB19-11A21-4AC4A24-2AC2A428-3DC3D22-A2D5A2DA19-B11AB17-AB11ABA15-17A14-17A13-6(19A12-)19A13-B15AB14-17A15-AB11ABA17-B11AB19-11A22-3AC3A364-4AC4A20-B11AB17-AB11ABA15-17A13-19A12-19A11-8(21A10-)2B17A2B11-19A12-19A13-17A15-AB11ABA17-B11AB20-4AC4A301-4AC4A20-B11AB17-15A15-17A13-19A11-21A10-21A9-8(23A8-)B21AB9-21A10-21A11-19A13-17A15-15A17-B11AB20-4AC4A240-3AC3A21-B11AB17-15A15-17A13-19A11-21A9-2(23A8-)23A7-6(25A6-)25A7-B21AB2(8-23A)9-21A11-19A13-17A15-15A17-B11AB21-3AC3A180-2AC2A23-11A18-AB11ABA15-17A13-19A11-21A9-23A8-23A7-2(25A6-)25A5-4(27A4-)27A5-25A6-B23AB6-25A7-23A8-23A9-21A11-19A13-17A15-AB11ABA18-11A23-2AC2A148-4AC4A20-B11AB16-17A13-19A11-21A9-23A8-23A7-25A6-25A5-8(27A4-)B25AB5-25A6-25A7-23A8-23A9-21A11-19A13-17A16-B11AB20-4AC4A117-2AC2A23-11A18-AB11ABA14-19A11-21A9-23A8-23A7-25A6-25A5-2(27A4-)27A3-4(29A2-)29A3-27A4-B25AB4-27A5-25A6-25A7-23A8-23A9-21A11-19A14-AB11ABA18-11A23-2AC2A86-4AC4A20-B11AB16-17A13-19A11-21A9-23A7-25A6-25A5-27A4-27A3-8(29A2-)B27AB3-27A4-27A5-25A6-25A7-23A9-21A11-19A13-17A16-B11AB20-4AC4A83-5AC5A18-AB11ABA15-17A12-21A9-23A8-23A7-25A5-27A4-27A3-9(29A2-)B27AB2-29A3-27A4-27A5-25A7-23A8-23A9-21A12-17A15-AB11ABA18-5AC5A54-2AC2A23-11A18-AB11ABA14-19A11-21A9-23A7-25A6-25A5-27A4-27A3-2(29A2-)29A-155A-29A2-B27AB2-29A3-27A4-27A5-25A6-25A7-23A9-21A11-19A14-AB11ABA18-11A23-2AC2A25-2(3AC3A21-B11AB16-17A13-19A11-21A9-23A7-25A5-27A4-27A3-2(29A2-)29A-217A-B27AB2(2-29A)3-27A4-27A5-25A7-23A9-21A11-19A13-17A16-B11AB21-3AC3A24-)7C21-3C7A3C16-2C13A2C13-C17AC11-C19AC9-C21AC7-C23AC5-C25AC4-C25AC3-2(C27AC2-)C27AC-C6(29A2C)29AC-2(C27AC2-)C27AC3-C25AC4-C25AC5-C23AC7-C21AC9-C19AC11-C17AC13-2C13A2C16-3C7A3C21-7C2(24-3AC3A21-B11AB16-17A13-19A11-21A9-23A7-25A5-27A4-27A3-2(29A2-)29A-217A-B27AB2(2-29A)3-27A4-27A5-25A7-23A9-21A11-19A13-17A16-B11AB21-3AC3A)25-2AC2A23-11A18-AB11ABA14-19A11-21A9-23A7-25A6-25A5-27A4-27A3-2(29A2-)29A-155A-29A2-B27AB2-29A3-27A4-27A5-25A6-25A7-23A9-21A11-19A14-AB11ABA18-11A23-2AC2A54-5AC5A18-AB11ABA15-17A12-21A9-23A8-23A7-25A5-27A4-27A3-9(29A2-)B27AB2-29A3-27A4-27A5-25A7-23A8-23A9-21A12-17A15-AB11ABA18-5AC5A83-4AC4A20-B11AB16-17A13-19A11-21A9-23A7-25A6-25A5-27A4-27A3-8(29A2-)B27AB3-27A4-27A5-25A6-25A7-23A9-21A11-19A13-17A16-B11AB20-4AC4A86-2AC2A23-11A18-AB11ABA14-19A11-21A9-23A8-23A7-25A6-25A5-2(27A4-)27A3-4(29A2-)29A3-27A4-B25AB4-27A5-25A6-25A7-23A8-23A9-21A11-19A14-AB11ABA18-11A23-2AC2A117-4AC4A20-B11AB16-17A13-19A11-21A9-23A8-23A7-25A6-25A5-8(27A4-)B25AB5-25A6-25A7-23A8-23A9-21A11-19A13-17A16-B11AB20-4AC4A148-2AC2A23-11A18-AB11ABA15-17A13-19A11-21A9-23A8-23A7-2(25A6-)25A5-4(27A4-)27A5-25A6-B23AB6-25A7-23A8-23A9-21A11-19A13-17A15-AB11ABA18-11A23-2AC2A180-3AC3A21-B11AB17-15A15-17A13-19A11-21A9-2(23A8-)23A7-6(25A6-)25A7-B21AB2(8-23A)9-21A11-19A13-17A15-15A17-B11AB21-3AC3A240-4AC4A20-B11AB17-15A15-17A13-19A11-21A10-21A9-8(23A8-)B21AB9-21A10-21A11-19A13-17A15-15A17-B11AB20-4AC4A301-A7BA20-BAB7ABAB17-AB11ABA15-17A13-19A12-19A11-8(21A10-)B19AB11-19A12-19A13-17A15-AB11ABA17-B11AB20-4AC4A364-3DC3D22-B2D5A2DB19-2B9A2B17-AB11ABA15-17A14-17A13-6(19A12-)B17AB13-B15AB14-17A15-AB11ABA17-B11AB19-11A22-3AC3A428-2DC2D24-9B21-11A19-B11AB17-AB11ABA16-AB11ABA15-3(17A14-)AB13ABA14-B15AB15-2D11A2D16-2B11A2B17-B11AB19-11A21-4AC4A24-2AC2A522-2AC2A24-4AC4A21-5AC5A20-11A19-3(B11AB18-)AB9ABA18-DAB7ABAD19-DAB5ABAD20-5BC5B21-4AC4A24-2AC2A677-2BC2B25-B2DC2DB24-ABDCDBA24-2ABAB2A2(24-3AC3A)25-2AC2A385-
