model
size = 32 31 31, scale = 0.05, origin = -y
material deform = 1, fade = true, lighting = smooth, roughness = 0.3, metalness = 0.6
  colors = A:#BBB B:#555 C:#111 D:#777 E:#0E0 F:#222 G:#E00
voxels
366-4E27-2E2C2E25-2E4C2E2(24-E6CE)24-2E4C2E25-2E2C2E27-4E668-4B26-8B23-10B21-4B4A4B20-3B6A3B19-3(3B8A3B18-)3B8A3B19-4B4A4B20-4B4A4B21-10B23-8B26-4B509-2B27-3A2B3A22-12A19-14A18-14A17-2(16A16-)16A15-2B14A2B14-2B14A2B15-2(16A16-)16A17-14A18-14A19-12A22-3A2B3A27-2B412-2A2B2A24-10A20-14A17-16A16-16A15-18A14-18A13-2(20A12-)2(B18AB12-)20A12-20A13-18A14-18A15-16A16-16A17-14A20-10A24-2A2B2A345-3A2B3A22-12A19-14A17-16A15-18A13-20A12-20A11-3(22A10-)2(B20AB10-)2(22A10-)22A11-20A12-20A13-18A15-16A17-14A19-12A22-3A2B3A280-3A2B3A22-12A19-14A16-18A14-18A13-20A11-22A10-22A9-3(24A8-)2(B22AB8-)2(24A8-)24A9-22A10-22A11-20A13-18A14-18A16-14A19-12A22-3A2B3A217-2A2B2A23-12A19-14A16-18A13-20A12-20A11-22A9-2(24A8-)24A7-2(26A6-)2(B24AB6-)26A6-26A7-2(24A8-)24A9-22A11-20A12-20A13-18A16-14A19-12A23-2A2B2A156-2B26-10A20-14A16-18A13-20A11-9A4-9A10-9A4-9A9-10A4-10A8-24A7-3(26A6-)26A5-B26AB4-B26AB5-3(26A6-)26A7-24A8-24A9-22A10-22A11-20A13-18A16-14A20-10A26-2B123-3A2B3A21-14A17-16A15-18A13-7A6-7A11-8A6-8A9-9A6-9A7-4(10A6-)26A5-3(28A4-)2(B26AB4-)2(28A4-)28A5-2(26A6-)26A7-24A9-22A11-20A13-18A15-16A17-14A21-3A2B3A90-4B24-12A18-16A15-18A13-6A8-6A11-7A8-7A9-8A8-8A7-9A8-9A6-9A8-9A5-2(10A8-10A4-)28A4-28A3-3(D28AD2-)D28AD3-3(28A4-)28A5-26A6-26A7-24A9-22A11-20A13-18A15-16A18-12A24-4B58-3B2-3B21-4A6-4A17-5A6-5A14-5A10-5A11-6A10-6A9-7A10-7A8-7A10-7A7-8A10-8A5-2(9A10-9A4-)9A10-9A3-D9A10-9A7(D2-D28A)D3-2(28A4-)28A5-26A7-24A8-24A9-22A11-20A14-16A17-14A21-8B55-2B6-2B20-3A8-3A16-3A12-3A13-4A12-4A11-5A12-5A9-6A12-6A7-7A12-7A6-7A12-7A5-8A12-8A4-8A12-8A3-3(D8A12-8AD2-)6(D28AD2-)D28AD3-28A4-28A5-26A6-26A7-24A9-22A11-20A13-18A16-14A20-10B53-2B8-2B18-2A12-2A15-2A14-2A12-4A14-4A9-5A14-5A8-5A14-5A7-6A14-6A5-7A14-7A4-7A14-7A3-3(D7A14-7AD2-)D7A14-7AD-E2(D7A14-7AD2E)D28AD2ED28ADE-3(D28AD2-)D28AD3-B26AB4-B26AB5-26A7-24A8-24A9-22A12-18A15-16A18-12B24-4E24-2B8-2B18-2A12-2A2(14-3A)11-4A14-4A9-5A14-5A7-6A14-6A6-6A14-6A5-7A14-7A4-7A14-7A3-2(D7A14-7AD2-)D7A14-7AD-E8A14-8A2E8A14-8AEF8A14-8A2F9A12-9AFE30A2E30AE-2(D28AD2-)D28AD3-B26AB4-B26AB5-26A6-26A7-24A9-22A11-20A14-16A18-12B23-2E2C2E22-2B10-2B17-2A12-2A2(14-3A)11-4A14-4A9-5A14-5A7-6A14-6A6-6A14-6A5-7A14-7A3-2(D7A14-7AD2-)D7A14-7AD-E8A14-8A2E8A14-8AEF2(8A14-8A2F)9A12-9A2F10A10-10AFE10A10-10A2E10A10-10AE-2(D28AD2-)D28AD3-B26AB5-26A6-26A7-24A9-22A11-20A14-16A17-14B21-2E4C2E21-B12-B16-2BA12-A2B13-B2A14-2AB11-B3A14-3AB9-B4A14-4AB7-B5A14-5AB5-B6A14-6AB4-B6A14-6AB3-2(D7A14-7AD2-)D7A14-7AD-E8A14-8AEF3(8A14-8A2F)9A12-9A2(2F10A10-10A)FE10A10-10AE-D10A8-10A2(D2-D28A)D3-3(B26AB4-)B-24A-B4-B2-22A2-B4-B3-20A3-2(B4-)18A2(4-B)6-14B6-B4-G9-E6CE9-G11-B12-B16-2BA12-A2B13-B2A14-2AB11-B2A16-2AB9-B3A16-3AB7-B4A16-4AB5-B5A16-5AB4-B5A16-5AB3-2(D6A16-6AD2-)D6A16-6AD-E7A16-7AEF7A16-7A2(2F8A14-8A)2F9A12-9A2(2F10A10-10A)FE10A10-10AE-D10A8-10AD2-D11A6-11AD2-D28AD3-3(B26AB4-)B-24A-B4-B2-22A2-B4-B3-20A3-2(B4-)18A2(4-B)6-14B6-B4-G9-E6CE9-G42-2(A14-)3A14-3A11-3A16-3A9-4A16-4A7-5A16-5A6-5A16-5A5-6A16-6A3-2(D6A16-6AD2-)D6A16-6AD-E7A16-7A2E7A16-7AEF2(8A14-8A2F)9A12-9A2F10A10-10AFE10A10-10A2E10A10-10AE-D10A8-10AD2-D11A6-11AD2-D12A4-12AD3-B26AB5-26A6-26A7-24A9-22A11-20A14-16A17-14B21-2E4C2E52-2(A14-)3A14-3A11-3A16-3A9-3A18-3A7-4A18-4A6-4A18-4A5-5A18-5A4-5A18-5A3-2(D5A18-5AD2-)D5A18-5AD-ED6A16-6AD2E8A14-8AEF8A14-8A2F9A12-9AFE10A10-10A2E10A10-10AE-D9A10-9AD2-D10A8-10AD2-D11A6-11AD3-B11A4-11AB4-B12A2-12AB5-26A6-26A7-24A9-22A11-20A14-16A18-12B23-2E2C2E53-A14-A15-A16-A12-3A16-3A9-3A18-3A8-3A18-3A7-3A20-3A5-4A20-4A4-4A20-4A3-2(D4A20-4AD2-)D5A18-5AD2-D6A16-6AD-E2(8A14-8A2E)9A12-9A2E10A10-10AE-C9A10-9AC2-D9A10-9AD2-D10A8-10AD2-D11A6-11AD3-B11A4-11AB4-B12A2-12AB5-26A7-24A8-24A9-22A12-18A15-16A18-12B24-4E85-A16-A13-2A16-2A11-2A18-2A9-3A18-3A7-3A20-3A6-2A22-2A5-3A22-3A4-3A22-3A3-D4A20-4AD2-D5A18-5AD2-D6A16-6A2(D2-D7A14-7A)D2-D8A12-8AD2(2-C9A10-9AC)2-D9A10-9AD2-D10A8-10AD3-11A6-11A2(4-12A)5-12A2-12A6-26A7-24A9-22A11-20A13-18A16-14A20-10B145-2A16-2A11-2A18-2A9-3A18-3A8-2A20-2A7-2A22-2A5-2A24-2A4-3A22-3A4-4A20-4A3-D5A18-5AD2-D6A16-6A2(D2-D7A14-7A)D2-D8A12-8AD2(2-C9A10-9AC)2-D9A10-9AD3-10A8-10A4-11A6-11A2(4-12A)5-26A7-24A8-24A9-22A11-20A14-16A17-14A21-8B147-A16-A13-A18-A11-2A18-2A9-2A20-2A7-2A22-2A6-2A22-2A5-3A22-3A4-4A20-4A4-5A18-5A4-6A16-6A3-2(D7A14-7AD2-)D8A12-8AD2-C9A10-9AC3-C8A10-8AC4-9A10-9A4-10A8-10A4-11A6-11A5-26A6-26A7-24A9-22A11-20A13-18A15-16A18-12A24-4B212-A18-A11-A20-A9-2A20-2A7-2(3A20-3A6-)3A20-3A5-5A18-5A4-6A16-6A2(4-7A14-7A)4-8A12-8A2(4-C8A10-8AC)4-9A10-9A5-9A8-9A2(6-26A)7-24A9-22A11-20A13-18A15-16A17-14A21-3A2B3A242-A18-A11-2A18-2A10-2A18-2A9-3A18-3A8-3A18-3A7-2(4A18-4A6-)5A16-5A6-6A14-6A5-7A14-7A4-8A12-8A5-2(C7A10-7AC6-)8A10-8A6-26A7-24A8-24A9-22A10-22A11-20A13-18A16-14A20-10A26-2B277-A18-A12-A18-A11-2A18-2A9-2(3A18-3A8-)3A18-3A7-5A16-5A2(6-6A14-6A)6-7A12-7A2(6-C24AC)7-2(24A8-)24A9-22A11-20A12-20A13-18A16-14A19-12A23-2A2B2A371-A18-A11-2A18-2A10-2A18-2A9-3A18-3A8-4A16-4A2(8-5A14-5A)8-24A2(8-C22AC)8-24A9-22A10-22A11-20A13-18A14-18A16-14A19-12A22-3A2B3A434-A18-A12-A18-A11-2A18-2A10-C2A16-2A5(C10-C20A)C10-2C18A2C11-20A12-20A13-18A15-16A17-14A19-12A22-3A2B3A561-22C10-3C16A3C2(10-2C18A2C)3(10-3C16A3C)12-18A15-16A16-16A17-14A20-10A24-2A2B2A594-22C10-C2-C14A4C12-C16A3C10-C-C16A3C11-3C14A4C13-C14A4C10-4C14A4C14-14A18-14A19-12A22-3A2B3A27-2B628-2(22C10-)3C8(GC)G2C10-4C7(GC)G3C10-3C8(GC)G2C2(10-22C)16-4A2B4A23-3A2B3A26-A2BA302-
