model
size = 25 8 30, scale = 0.05, origin = -y
material deform = 1, fade = true, lighting = smooth, roughness = 0.3, metalness = 0.6
  colors = A:#0F0F0F B:#1F1F1F C:#1A1A1A D:#191919 E:#141414 F:#1E1E1E
voxels
50-2(A25-A24-)A25-3A18CB2(25-A)24-A25-A24-A25-3A18CB74-5(B24-)B49-2(B24-)5(A24-)2(B24-)A24-D4(24-A)2(24-B)2(24-A)24-F24-E2(24-A)2(24-B)2(24-A)24-E24-F24-D24-A2(24-B)24-E3(24-A)24-E24-F2(24-B)24-E2(24-D)3(24-A)2(24-B)2(24-A)24-F24-D2(24-A)2(24-B)4(24-A)2(24-D)2(2(24-B)6(24-A))24-B49-3(B24-)2(A24-)B24-B124-2(B24-)2(B174-B24-)B149-2(B24-)B74-3(B24-)2(A24-)B24-B49-B5(24-A)2(24-B)24-A24-D4(24-A)2(24-B)2(24-A)24-F24-E2(24-A)2(24-B)2(24-A)24-E24-F24-D24-A2(24-B)24-E3(24-A)24-E24-F2(24-B)24-E2(24-D)3(24-A)2(24-B)2(24-A)24-F24-D2(24-A)2(24-B)4(24-A)2(24-D)2(24-B)6(24-A)3(24-B)5(24-A)24-B49-5(B24-)B25-
