model
size = 26 32 26, scale = 0.05, origin = -y
material deform = 1, fade = true, lighting = smooth, roughness = 0.3, metalness = 0.6
  colors = A:#000 B:#FC0 C:#F50000 D:#007F1B E:#A35803 F:#B67831
voxels
36-5(6A20-)6A670-5(6A20-)6A693-5(12A14-)12A18-2(4C22-)4C615-5(4A6-4A12-)4A6-4A14-3(3C4-3C16-)10C17-8C20-2(4B22-)4B484-5(2A12-2A10-)3A10-3A11-2(2C10-2C12-)2C10-2C13-2C8-2C14-3C6-3C15-2(4B2-4B16-)4B2-4B18-6B456-5(2A14-2A8-)2A14-2A9-3(C14-C10-)2C12-2C11-2C10-2C13-2(2B8-2B14-)2B8-2B15-2B6-2B17-8B18-8B402-5(2A16-2A6-)2A16-2A7-3(C16-C8-)2C14-2C9-C14-C3(10-2B12-2B)11-2B10-2B13-3B6-3B15-11B16-8D375-5(2A18-2A4-)2A18-2A5-2(C18-C6-)C18-C7-C16-C8-C16-C9-3(B14-B10-)2B12-2B11-2B10-2B13-3B6-4B14-2D6-2D18-6D20-6D323-5(2A20-2A2-)3A18-3A4-4(C18-C6-)2C16-2C7-2(B16-B8-)B16-B9-B14-B10-2B12-2B11-3B8-4B12-2D8-2D15-4D2-4D16-4D2-4D19-4D298-5(2A20-2A2-)2A20-2A3-3(C20-C4-)2C18-2C5-C18-C3(6-2B16-2B)7-B16-B9-B14-B2(10-3B)11-2D10-2D13-3D6-3D14-3D6-3D16-8D124-DBCD22-ADAB22-CADA22-DBCD90-5(2A20-2A2-)2A20-2A3-4(C20-C4-)2C18-2C5-2(B18-B6-)B18-B7-B16-B8-2B14-2B8-3B12-3B9-2(2D12-)2D8-2D14-2D8-2D15-10D72-AD22-ACB2AB20-D4AC19-AB4ADA18-D6AB19-B4AC20-DADBAB22-BC38-2A2(22-4A)3(21-E4A)22-2A2-4(C20-C4-)C20-C5-3(B18-B6-)B18-B7-B16-B8-2B14-2B9-D14-D11-2D10-2D12-2D10-2D14-3D4-3D19-4D47-CBDADC19-B7A18-C6AB18-D6AC18-8A18-C6AD18-D7A19-BCADCD36-2A2(22-4A)21-E4A21-F4A21-E4A22-2A-2(C22-C2-)C22-C3-2(C20-C4-)2(2B18-2B4-)2B18-2B5-B18-B7-B16-B8-2B14-2B9-D14-D11-2D10-2D12-2D10-2D13-3D6-3D17-6D21-DCAB21-6A19-7AB17-D8AC16-10A16-C8AD16-D8AC17-7AD19-D5A21-ADCB11-2A2(22-4A)21-E4A21-F4A21-E4A22-2A-2(C22-C2-)C22-C3-2(C20-C4-)2(B20-B4-)B20-B5-B18-B7-B16-B8-2B14-2B9-D14-D11-3(D12-)D13-3D6-3D17-6D21-3CD20-BDA2C2AD18-C7A17-9AB16-B8AD16-9AC16-B8AB17-8A18-C5ABC20-DBAD11-2A2(22-4A)21-E4A21-F4A21-E4A22-2A-2(C22-C2-)C22-C3-2(C20-C4-)2(B20-B4-)B20-B5-B18-B7-B16-B8-2B14-2B9-D14-D11-3(D12-)D13-3D6-3D17-6D21-A2CA20-D2A2C2AB18-7AC17-D8AD16-9AC16-D9A16-C8AD17-D6AD18-AD5AB20-BCDB11-2A2(22-4A)21-E4A21-F4A21-E4A22-2A-2(C22-C2-)C22-C3-2(C20-C4-)2(2B18-2B4-)2B18-2B5-B18-B7-B16-B8-2B14-2B9-D14-D11-2D10-2D12-2D10-2D13-3D6-3D17-6D21-BDAC21-5AD19-B7A17-9AC16-C8AD16-9AB16-D9A17-B6AC19-C4AD21-ADAC11-2A2(22-4A)3(21-E4A)22-2A2-4(C20-C4-)C20-C5-3(B18-B6-)B18-B7-B16-B8-2B14-2B9-D14-D11-2D10-2D12-2D10-2D14-3D4-3D19-4D47-BD3AB19-C6AD18-B7A18-7AB18-B6AC18-D6AB18-7AD19-2(BDA)37-5(2A20-2A2-)2A20-2A3-4(C20-C4-)2C18-2C5-2(B18-B6-)B18-B7-B16-B8-2B14-2B8-3B12-3B9-2(2D12-)2D8-2D14-2D8-2D15-10D72-CD22-D2ABAC20-D4AD19-B6AB18-C5ADA19-D4AB20-CADCBC22-BA39-5(2A20-2A2-)2A20-2A3-3(C20-C4-)2C18-2C5-C18-C3(6-2B16-2B)7-B16-B9-B14-B2(10-3B)11-2D10-2D13-3D6-3D14-3D6-3D16-8D124-2(CB)22-BADA22-DACB22-BDAD90-5(2A20-2A2-)3A18-3A4-4(C18-C6-)2C16-2C7-2(B16-B8-)B16-B9-B14-B10-2B12-2B11-3B8-4B12-2D8-2D15-4D2-4D16-4D2-4D19-4D299-5(2A18-2A4-)2A18-2A5-2(C18-C6-)C18-C7-C16-C8-C16-C9-3(B14-B10-)2B12-2B11-2B10-2B13-3B6-4B14-2D6-2D18-6D20-6D325-2(2A16-2A6-)EA3(16-2A6-2A)16-2A7-3(C16-C8-)2C14-2C9-C14-C3(10-2B12-2B)11-2B10-2B13-3B6-3B15-11B16-8D377-2(2A14-2A8-)EA3(14-2A8-2A)14-2A9-3(C14-C10-)2C12-2C11-2C10-2C13-2(2B8-2B14-)2B8-2B15-2B6-2B17-8B18-8B404-2(2A12-2A10-)EA2(12-2A10-2A)12-2A2(10-3A)11-2(2C10-2C12-)2C10-2C13-2C8-2C14-3C6-3C15-2(4B2-4B16-)4B2-4B18-6B458-5(4A6-4A12-)4A6-4A14-3(3C4-3C16-)10C17-8C20-2(4B22-)4B486-5(12A14-)12A18-2(4C22-)4C609-
