model
size = 26 30 26, scale = 0.05, origin = -y
material deform = 1, fade = true, lighting = smooth, roughness = 0.3, metalness = 0.6
  colors = A:#565656 B:#1352F1 C:#7F7F7F D:#FE3C00 E:#A35803 F:#B67831
voxels
36-5(6A20-)6A618-5(6A20-)6A641-5(12A14-)12A18-2(4C22-)4C563-5(4A6-4A12-)4A6-4A14-3(3C4-3C16-)10C17-8C20-2(4B22-)4B432-5(2A12-2A10-)3A10-3A11-2(2C10-2C12-)2C10-2C13-2C8-2C14-3C6-3C15-2(4B2-4B16-)4B2-4B18-6B404-5(2A14-2A8-)2A14-2A9-3(C14-C10-)2C12-2C11-2C10-2C13-2(2B8-2B14-)2B8-2B15-2B6-2B17-8B18-8B350-5(2A16-2A6-)2A16-2A7-3(C16-C8-)2C14-2C9-C14-C3(10-2B12-2B)11-2B10-2B13-3B6-3B15-11B16-8D323-5(2A18-2A4-)2A18-2A5-2(C18-C6-)C18-C7-C16-C8-C16-C9-3(B14-B10-)2B12-2B11-2B10-2B13-3B6-4B14-2D6-2D18-6D20-6D271-5(2A20-2A2-)3A18-3A4-4(C18-C6-)2C16-2C7-2(B16-B8-)B16-B9-B14-B10-2B12-2B11-3B8-4B12-2D8-2D15-4D2-4D16-4D2-4D19-4D246-5(2A20-2A2-)2A20-2A3-3(C20-C4-)2C18-2C5-C18-C3(6-2B16-2B)7-B16-B9-B14-B2(10-3B)11-2D10-2D13-3D6-3D14-3D6-3D16-8D72-2ACA22-4A22-C3A22-2ACA90-5(2A20-2A2-)2A20-2A3-4(C20-C4-)2C18-2C5-2(B18-B6-)B18-B7-B16-B8-2B14-2B8-3B12-3B9-2(2D12-)2D8-2D14-2D8-2D15-10D20-2A22-AC4A20-5AC19-8A18-8A19-5AC20-6A22-AC38-2A2(22-4A)3(21-E4A)22-2A2-4(C20-C4-)C20-C5-3(B18-B6-)B18-B7-B16-B8-2B14-2B9-D14-D11-2D10-2D12-2D10-2D14-3D4-3D18-C4AC19-8A18-C7A18-7AC18-8A18-C7A18-8A19-6A36-2A2(22-4A)21-E4A21-F4A21-E4A22-2A-2(C22-C2-)C22-C3-2(C20-C4-)2(2B18-2B4-)2B18-2B5-B18-B7-B16-B8-2B14-2B9-D14-D11-2D10-2D12-2D10-2D13-3D6-3D17-6A19-8A17-9AC16-10A16-C9A16-9AC17-8A19-6A21-2ACA11-2A2(22-4A)21-E4A21-F4A21-E4A22-2A-2(C22-C2-)C22-C3-2(C20-C4-)2(B20-B4-)B20-B5-B18-B7-B16-B8-2B14-2B9-D14-D11-3(D12-)D13-3D6-3D16-3A2C3A18-C7A17-3(10A16-)10A17-8A18-C6AC20-4A11-2A2(22-4A)21-E4A21-F4A21-E4A22-2A-2(C22-C2-)C22-C3-2(C20-C4-)2(B20-B4-)B20-B5-B18-B7-B16-B8-2B14-2B9-D14-D11-3(D12-)D13-3D6-3D16-3A2C3A18-7AC17-10A16-9AC16-10A16-C9A17-8A18-8A20-AC2A11-2A2(22-4A)21-E4A21-F4A21-E4A22-2A-2(C22-C2-)C22-C3-2(C20-C4-)2(2B18-2B4-)2B18-2B5-B18-B7-B16-B8-2B14-2B9-D14-D11-2D10-2D12-2D10-2D13-3D6-3D17-6A19-8A17-10A16-C9A2(16-10A)17-7AC19-C5A21-3AC11-2A2(22-4A)3(21-E4A)22-2A2-4(C20-C4-)C20-C5-3(B18-B6-)B18-B7-B16-B8-2B14-2B9-D14-D11-2D10-2D12-2D10-2D14-3D4-3D18-6A19-C7A2(18-8A)18-7AC2(18-8A)19-6A37-5(2A20-2A2-)2A20-2A3-4(C20-C4-)2C18-2C5-2(B18-B6-)B18-B7-B16-B8-2B14-2B8-3B12-3B9-2(2D12-)2D8-2D14-2D8-2D15-10D20-CA22-5AC20-6A19-8A18-C5ACA19-6A20-2(C2A)22-2A39-5(2A20-2A2-)2A20-2A3-3(C20-C4-)2C18-2C5-C18-C3(6-2B16-2B)7-B16-B9-B14-B2(10-3B)11-2D10-2D13-3D6-3D14-3D6-3D16-8D72-2(CA)22-4A22-2ACA22-4A90-5(2A20-2A2-)3A18-3A4-4(C18-C6-)2C16-2C7-2(B16-B8-)B16-B9-B14-B10-2B12-2B11-3B8-4B12-2D8-2D15-4D2-4D16-4D2-4D19-4D247-5(2A18-2A4-)2A18-2A5-2(C18-C6-)C18-C7-C16-C8-C16-C9-3(B14-B10-)2B12-2B11-2B10-2B13-3B6-4B14-2D6-2D18-6D20-6D273-2(2A16-2A6-)EA3(16-2A6-2A)16-2A7-3(C16-C8-)2C14-2C9-C14-C3(10-2B12-2B)11-2B10-2B13-3B6-3B15-11B16-8D325-2(2A14-2A8-)EA3(14-2A8-2A)14-2A9-3(C14-C10-)2C12-2C11-2C10-2C13-2(2B8-2B14-)2B8-2B15-2B6-2B17-8B18-8B352-2(2A12-2A10-)EA2(12-2A10-2A)12-2A2(10-3A)11-2(2C10-2C12-)2C10-2C13-2C8-2C14-3C6-3C15-2(4B2-4B16-)4B2-4B18-6B406-5(4A6-4A12-)4A6-4A14-3(3C4-3C16-)10C17-8C20-2(4B22-)4B434-5(12A14-)12A18-2(4C22-)4C557-
