model
size = 30 28 10, scale = 0.05, origin = -y
material deform = 1, fade = true, lighting = smooth, roughness = 0.3, metalness = 0.6
  colors = A:#FFFFFB B:#111
voxels
5-6B10-6B3-30B30A30B42AB4AB24AB2A4B23A2(B2ABAB24A)B2ABAB109AB3AB2A3BAB3AB14A3(BA)B5ABAB15A3(BA)B6AB9AB6A3(BA)B5ABAB7ABAB5A2BA2B2A3BAB3AB5AB3AB24A2(B2A)B22AB2AB-B2AB20AB2AB3-B2AB18AB2AB5-B2AB16AB2AB7-BAB7A2B7ABAB8-BAB6AB2-B6ABAB8-BAB5AB4-B5ABAB8-BAB4AB6-B4ABAB8-BAB3AB8-B3ABAB4-30B30A30B42AB4AB23A4B3(2AB24ABAB)2AB109AB3ABA3B2AB3AB15ABAB5A3(BA)B16AB6A3(BA)B15ABAB5A3(BA)B7AB6AB3ABA3B2A2BA2B6ABAB26A2(BA)B24ABAB-BAB22ABAB3-BAB20ABAB5-BAB18ABAB7-BAB7A2B7ABAB8-BAB6AB2-B6ABAB8-BAB5AB4-B5ABAB8-BAB4AB6-B4ABAB8-BAB3AB8-B3ABAB8-6B10-6B8(4-B28-BA28-AB28-BA12(28-2A)28-AB28-BA28-AB28-B244-BAB2AB10-B2ABAB)4-
