model
size = 30 26 10, scale = 0.05, origin = -y
material deform = 1, fade = true, lighting = smooth, roughness = 0.3, metalness = 0.6
  colors = A:#FCFAF2 B:#111 C:#FFFFFB
voxels
4-24B2(4-11B)4-B10A4-10AB4-BA9B4-9BAB3-2BAB9A2-9ABA2B2-B2AB9A2-9AB2AB-2BA2B20A2BA2B3AB22AB3A4B22A4B30A-3(28A2-)14AC10AC2A2-3ACACBC2AB2C3BABC2AB3AC2A2-3ACA4(CB)2ACACBAB4AC2A3-2ACA3(CB)AB2A2C2AB5ACA4-2ACA3(CB)AB2ACACBAB4ACA4-2A2C2(A2B)2C3BABC2AB3ACA4-14AC9ACA4-15AC10A4-15A2C9A5-24A6-24B6-24C6-24B5-2(11B4-)B10A4-10AB4-BA9B4-9BAB3-2BAB9A2-9ABA2B2-B2AB9A2-9AB2AB-2BA2B20A2BA2B3AB22AB3A4B22A4B30A-4(28A2-)6AB3ABA3B2AB3AB6A2-7ABAB5A3(BA)B6A3-7AB6A3(BA)B5A4-6ABAB5A3(BA)B5A4-5AB3ABA3B2A2BA2B5A3(4-26A)5-24A6-24B6-24C2(6-24B)5-2(B24-B4-)B24-B3-B26-B2-B26-B-B28-BA28-AB28-B2A26-2A-5(A26-A2-)2A24-2A3-5(A24-A4-)A24-A5-A22-A6-B22-B6-C22-C2(6-B22-B)2(5-2(B24-B4-)B24-B3-B26-B2-B26-B-B2(28-2B)28-3B26-2B-5(B26-B2-)2B24-2B3-5(B24-B4-)B24-B5-4(B22-B6-)B22-B)2(5-2(B24-B4-)B24-B3-B26-B2-B26-B-B28-BA28-AB28-B2A26-2A-5(A26-A2-)2A24-2A3-5(A24-A4-)A24-A5-A22-A6-B22-B6-C22-C2(6-B22-B))2(5-2(B24-B4-)B24-B3-B26-B2-B26-B-B2(28-2B)28-3B26-2B-5(B26-B2-)2B24-2B3-5(B24-B4-)B24-B5-4(B22-B6-)B22-B)5-2(B24-B4-)B24-B3-B26-B2-B26-B-B28-BA28-AB28-B2A26-2A-5(A26-A2-)2A24-2A3-5(A24-A4-)A24-A5-A22-A6-B22-B6-C22-C2(6-B22-B)3-
