model
size = 26 28 26, scale = 0.05, origin = -y
material deform = 1, fade = true, lighting = smooth, roughness = 0.3, metalness = 0.6
  colors = A:#AAA B:#888 C:#555 D:#222 E:#BBB F:#777 G:#111 H:#E00 I:#FF0
voxels
243-8C18-8C19-6H21-4H618-8C18-8C19-6C21-4C434-5(B-2(2BA)2B-B14-)2(12B14-)12A2(14-2C8A2C)14-3C6A2C15-4C4A3C15-C-8C20-4C380-5(B-BA7-B2A-B10-)2(4B7-5B10-)4A7-5A10-2C2A7-3A2C10-2C2A7-3AC11-3CA7-2A2C11-3CA7-2AC14-2C7-3C15-3C4D3C18-6C22-2C328-5(2(AB)10-2A2B8-)2(4B10-4B8-)4A10-4A8-C3A10-3AC8-2C2A10-2A2C8-2C2A10-2AC9-3CA10-A2C10-2CA10-2C13-C10DC15-10C17-8C20-4C300-5(4B12-3BA6-)2(4B12-4B6-)4A12-4A2(6-C3A12-2A2C)6-2C2A12-2AC7-2C2A12-2AC8-2CA12-2C11-C12DC12-14C14-10C17-8C20-4C273-5(A3B14-4B4-)2(4B14-4B4-)4A14-4A4-C3A14-3AE5-3(C2A14-2AC6-)2CA14-2C9-C14DC10-C2A11CAC11-14C14-10C17-8C21-2C249-4(AB16-BA6-)AB16-BA5-2(3B16-3B4-)3A16-3A3(4-C2A16-2AE)5-CA16-AC6-CA16-2C7-C16DC8-5C8A5C9-4C8A4C11-3C8A3C14-2C6A2C18-6B245-5(3B18-2AB2-)2(3B18-3B2-)3A18-3A2(2-E2A18-2AE)3-2(CA18-AE4-)CA18-2C5-C18DC7-4C10A4C9-3C10A3C11-2C10A2C13-C10AC15-3B4A3B19-4B221-4(A19-BA4-)A19-BA3-2(2B19-3B2-)AB19-3A4(2-EA19-2AE)3-C19-2C4-C19D2C5-4C12A4C7-3C12A3C9-2C12A2C11-C12AC13-2B8A2B16-8B217-B4(A21-2A2B)A21-2A3B21-5B21-3B2A21-3AEA21-2A2EA21-2AE-2(E21-AE2-)E21-AE3-E20DC5-B16A3C6-B16A3C7-B15A2C9-2B12A2C12-B10AB15-3B4A3B19-4F349-AB21-2B3A21-3AE2(A21-2A2E)A21-2AE-E21-AE2-E21-AE3-E20DE4-E20AE5-B18AB7-B17A9-B14A2B10-2B10A2B14-2B6A2B18-6F296-A2(24-2A)B21-2BAFA21-3AEA21-2AFE2(A21-2A2E)A21-2AE-E21-AE2-E21DAE3-E20AE5-B19A6-B18AB7-2B14A2B10-B12AB13-2B8A2B16-8F191-A6(24-2A)B21-2B3A21-3AEA21-2AEFA21-2A2EA21-2AFEA21-2AE-E21-AE2-E21DAE3-E20AE4-E20AE5-19AB6-B18AB6-3B16AB6-B3G12A3GB6-B4GBA6FAB4GB6-B4G2B6-2B4GB2(6-2B3G2B)6-2B2G3B6-3B2G2B2(6-3BG3B)7-5B8-5B9-3B10-3B11-B12-B6-A4(24-2A)24-AF24-2AB21-2BF2A21-3AE3(A21-2A2E)A21-2AE-E21-AE2-E21DAE3-E20AE4-E20AE5-B18AB7-B16AB9-2B12A2B12-2F8A2F16-8F295-A2(24-2A)B21-2BAFA21-3AEA21-2AFE2(A21-2A2E)A21-2AE-E21-AE2-E21DAE3-E20AE5-B18AB6-B18AB7-2B14A2B10-B12AB13-2F8A2F16-8F347-AB21-2B3A21-3AE2(A21-2A2E)A21-2AE-E21-AE2-E21-AE3-C20DC4-C20AC5-C18AC7-C16AC9-C14AC11-2B10A2B14-2F6A2F18-6F348-3B19-4B3A19-4AE2A19-3A2E2A19-3AE-2(EA19-2AE2-)EA19-2AE3-C19DAC5-C18AC6-C18AC7-C16AC9-2C12A2C12-B10AB15-3F4A3F19-4F350-2B19-3B2-2A19-3A4(2-EA19-2AE)3-C18-A2C4-C18D3C5-E18AE7-E16AE9-E14AE11-I12AI13-2C8A2C16-8F374-2B18-4B2-2A18-4A2(2-E2A17-3AE)3-2(CA17-2AC4-)CA2D15-A2C5-E2C15DCE7-E2AI13AE9-EAI12AE11-2I11AI13-I10AI15-3C4A3C19-F2CF377-3B15-4B4-3A15-4A3(4-C2A15-3AC)5-CA15-2AC6-2CD14-A2C7-EC14DAE8-E2AI13AE9-EAI12AE11-2I10A2I14-HC6ACH18-6C402-4B13-5B4-4A13-5A4-C3A13-4AC5-2(C2A13-3AC6-)C2A13-3AC7-CA13-2AC9-E13DAE10-EAI12AE11-2I10A2I14-H8AH16-3H4C3H20-2C405-4B11-5B6-4A11-5A2(6-C3A11-A4C)7-C2A11-A3C8-C2A11-A3C9-CA11-A2C11-C11DAC12-CI10AIC14-H8AH16-HAH4AHAH19-4C431-5B7-6B8-5A7-6A2(8-3C2A7-3A3C)9-2C2A7-3A2C10-2C2A7-3A2C11-C2A7-3AC13-CA7D2AC15-2H6A2H17-2H4C3H19-4C458-16B10-16A10-2C12A2C11-2C11AC12-2C10A2C13-C10AC14-2C8A2C15-3C4A3C18-6C22-2C410-10B5-G10-B4(A-)B8-G7-B4(-A)B5-G9-12B8-G5-12A3-G10-2C8A2C10-G3-2C8A2C-G10-G-G2C6A2CG15-G2C4A2CG-G12-G2-8C4-G15-4C15-G18-G31-G20-G30-G256-
