model
size = 23 32 4, scale = 0.05, origin = -y
material deform = 1, fade = true, lighting = smooth, roughness = 0.3, metalness = 0.6
  colors = A:#FC0
voxels
57-A758-A735-A664-4A21-A22-3A19-2A4(22-A)21-A-A19-A3-3(A18-2(A-))A17-7A14-3A2(-A)-3A11-2A2-A3-A2-2A9-A4-A3-A4-A7-2A3-A5-A3-2A3-23A-3A4-A5-A4-3A3-2A3-A7-A3-2A4-A-A2-A7-A2-A-A4-A2-2A9-2A2-A4-A3-2A7-2A3-A4-A3-A-2A3-2A-A3-A4-2A-A4-3A4-A-2A5-2(A-A4-)A-A6-3A2-2A3-2A2-3A2(7-A2-A)8-3A9-3A7-2A-3A5-3A-2A6-A4-7A4-A3-
