model
size = 20 32 19, scale = 0.05, origin = -y
material deform = 1, fade = true, lighting = smooth, roughness = 0.3, metalness = 0.6
  colors = A:#D2D2D2 B:#D9CDC1 C:#000 D:#84492C E:#7D0028 F:#F5E5D8
voxels
108-2A7(19-A)2(19-B)9(19-A)3(19-B)2(19-A)70-16C3(9-11C)9-5C7A11-7(5A15-)4AB2(15-5B)3(15-5A)15-5B4(15-5A)15-2A3B2(15-5B)15-2B3A2(15-5A)18-2A18-5CB3C11-C-3CB17C3(2AC3-14C)2AC3-2CB-10C3A11-7(3AE2A14-)3AE2B2(14-6B)3(14-3AE2A)14-6B14-B2A3(E2A14-3A)E2A14-2A4B2(14-6B)14-2BAEAB2(14-3AE2A)15-2AE2A16-BD7CB10-BDC3D3CB4(14C2AC3-)2CB11C3A2(11-3A2EA-2A)9-5A2EA4(-2A9-8A)-2A9-6A2B2(-2B9-8B)3(-2A9-8A)-2A9-8B-2B9-3B5A3(-2A9-8A)-A10-B6AB-B3(10-4B3A3B)2(10-10A)10-9A12-B2C2DE7C9-2CD2C3D17C3(2AC3-14C)2AC3-2CB11C2AC12-2A3E3A12-2(2A3E4A8-A2-)3(9A8-A2-)9A6-3A2-3A6B6-3B2-9B6-3B2-6B3A3(6-3A2-9A)6-3B2-9B6-3B2-9A6-3(3A2-8A7-)3B2-4A3(4B7-3B2-B3A)4B2(7-3A2-8A)9-A2-10A6-C2B-6D5C8-C5DC3D16C3(2AC3-14C)2AC3-2CB11C2AC11-3A2E3A12-3A2(2E2A11-5A)3(3EA11-5A)3EA9-3AE3A3EA2(9-11B)9-3AE3A3EA9-2(3AE)3A9-3AE3A3EA9-11B9-5B6A9-3AE10A6-3AE3A3E2AEA6-3AE3A3E5A5-3BE3A2E3(5BA5-6BA2D)5BA2(5-3AD3A3D5A)6-2AD3A3D5A4-C2-C9D3CB7-B6D2C2DCB10-3(7C13-)7C11-9C11-5A2-2A11-5A13-7A13-3(9A11-)9A9-11A2(9-11B)9-11A9-9A11-11A9-11B9-5B2A13-2(3AE10A6-)3AE3A3E4A6-3BE3A3E3(5A5-6BA3D)3(5A5-3AD3A3D)5A4-2B2C10D3C6-C7D3CD2C245-6(A19-)B19-A18-6A14-3A3E8A6-3A7E4A6-3A7E3(5A5-6B4D)3(5A5-3A7D)5A4-4C10D3C6-B9DC2DC424-13A7-3A7E4A6-3A7E3(5A5-6B4D)3(5A5-3A7D)5A4-4C11DCB3-2C-C9D2CDB423-13A2(7-4A7E2A)7-4A5D2E2A7-2(4A5D2E5A4-)2(4A7D5A4-)C3A7D5A4-2AFE10D3C3-4C9DCD2C423-14A6-4A7E4A5-4A7E2(5A4-4A5D2E)2(5A4-4A4D3E)5A4-4A7D5A4-C3A7D5A4-2A2F11D2C3-4C9D2CDC372-4B15-A4B15-5A7-14A6-4A7E4A5-4A7E5(5A4-4A2E5D)5A4-C3A7D5A4-B3C10D3C3-3C-9DC2D8C2(-9C3-7C)-9C3-3CB13C9-3C8A6(14-A4-A)5(14-A4-B)2(14-A4-A)2(14-A4BA)2(6-14A)6-4A7E4A5-4A7E5(5A4-4A2E5D)5A4-4A7D5A4-4CE9D2C5-2C-C8DCD2-3(7C-6C2AC3-)3CB10C2AC9-8C2AC11-A-AE5A11-A5(-8A8-3A)3(-2A6B6-3B2A)-2A6B6-5A-2A5BA6-5A-8A6-A3BA-8A6-4B4A4BAB6-2B6A4BAB6-5A2E7A6-3A4E7A6-3A7E5A5-9BE3(5B5-9BD)5B2(5-3A2E5D5A)5-3A7D5A5-2(CE)8DCEB6-3C-6DCBC2-3(7C-6C2AC3-)3CB10C2AC9-8C2AC11-A3E4A12-A2(2E5A10-3A)2(2E7A8-3A)2E7A8-A3(4EA6B6-3B)4EA6B6-3A4EA5BA6-3A4E7A6-A3B3E7A6-4B3EA4BAB6-2BA4EA4BAB2(6-3A4E7A)6-3A7E4A6-9BE3(4B6-9BD)4B2(6-3A2E5D4A)6-3A7D5A5-BE2C8DBEC6-B-C2-5DC-C2-2(14C2AC3-)14C2AC4-2CB10C2AC9-8C2AC11-9A11-10A4(8-12A)8-6A3(6B7-2B5A)6B7-7A5BA7-13A7-3B10A7-3B4A6B7-B6A4BAB3(7-13A)7-3(8BA3B8-)8BA4B3(7-13A)6-8C4DBC10-2(B3C)-C5-11C2AC6-11C2AC10-7C2AC10-C2-4C2AC10-C6-2AC2(11-9A)4(9-11A)3(9-11B)9-B5A5B9-6A5B9-11A9-7B4A9-11B9-6A4BA3(9-11A)4(9-7BA3B)3(9-11A)9-2C2(B3C)BC27-11C9-11C2(13-7C)18-2C13-7A13-5(6A14-)3(6B14-)2(3A3B14-)6A14-4B2A14-6B14-3A3B2(14-6A)14-3A2BA4(14-6B)3(14-6A)13-B3CB2C217-2(A19-)5(B19-)A3(19-B)2(19-A)5(19-B)3(19-A)47-
