model
size = 32 3 32, scale = 0.05, origin = -y
material deform = 1, fade = true, lighting = smooth, roughness = 0.3, metalness = 0.6
  colors = A:#F06 B:#FF0 C:#0F3 D:#0FF
voxels
69-26D38-26D69-D26AD38-C3-C-3C-C2(-5C)7-D26AD6-5B2-4B7-5B9-6(C-)C6-3C8-D26AD6-3(B-)B5-5B3-B11-5C-C-3C2(-5C)7-D26AD6-B3-B2-4B7-5B39-D26AD40-4(20B8-D26AD8-20C12-)3(12B4-4B8-D26AD8-12C4-4C12-)12B4-4B8-D26AD8-12C4-4C4(24-8B8-D26AD20-8C)3(12-12B4-4B8-D26AD8-12C4-4C)12-12B4-4B7-D27AD8-12C4-4C12-20B7-D27A2(D8-20C12-20B6-D28A)D8-20C12-20B5-D29AD8-20C36-5D26AD38-C3-C2-4C7-5C7-D26AD6-5B-B-3B2(-5B)9-3(C-)C5-5C3-C9-D26AD6-6(B-)B6-3B10-5C2-4C7-5C7-D26AD6-B3-B-3B-B2(-5B)39-D26AD32-
