model
size = 20 28 29, scale = 0.05, origin = -y
material deform = 1, fade = true, lighting = smooth, roughness = 0.3, metalness = 0.6
  colors = A:#003 B:#960 C:#300 D:#FF0 E:#C30 F:#EEE G:#630
voxels
202-2(17C3-)17C22-3(18A2-)18A383-17C3(3-C15AC)4-15C3-6(18A2-)18A264-15C5-16C4-16C4(3-C15AC)4-C13AC3-9(18A2-)18A165-4B4C5B7-2B9C2B6-C12AB6-C13A2C4-C14A2(C3-C15A)C3-C-14AC3-C15AC4-C13AC3-10(18A2-)18A145-13B7-B11A2(B6-C12A)B6-C13A2C2(3-C15AC)3-C-14AC3-C15AC4-C13AC3-11(18A2-)18A105-13B2(7-2B10AB)7-B11A2(B6-C12A)B5-C14AC4-C15AB3-C15A2B2-C15A2B3-C14A2B-17AD12(2-18A)85-13B2(7-2B10AB)2(7-B11AB)6-C12AB5-C13AB5-C14A5BC15A4BC15AG-3B16A2B17A2B-11(18A2-)18A85-13B5(7-B11AB)5-2C13A5B2(C15A4B)C-14A2B2-B15A4BD15A2B-11(18A2-)18A28-7B12-9B9-13B6(7-B11AB)3-3B-B12A7B14A2B-2B14AB2-3B14AB3-2B15A5B15A2B-2DB15A4-B15A10(2-18A)28-7B12-9B9-13B6(7-B11AB)3-4B13A5B16A2B2-B14AB3-2B15A2B-B17A2B2D16AB-2DB13ACD4-B15A10(2-18A)28-7B12-9B9-13B3(7-B11AB)7-2(B12AB6-)B12AB2-4B13AB2-3B14AB4-B14AB2-3B14AB2-B17AD-B2D15AD2-2DB13ACD4-B15A10(2-18A)28-7B12-9B9-4B5A4B7-2B9A2B7-B11AB7-B12A6(B4-2B13A)G4-2B13AB3-2(2D15AD2-)2DB13ACD4-B13AC3-9(18A2-)18A28-7B12-9B9-4B5A4B7-2B9A3B6-B12A6(B4-2B13A)G2(4-2B13AB)3-2(2D15AD2-)2DB13ABD4-B13AC3-9(18A2-)18A10-3A15-7B12-9B9-4B5A4B5-4B9A3B6(4-2B13AB)4-3G12A2(B4-2B13A)B3-2(2D15AD2-)2DB13ABD4-B13AB3-9(18A2-)18A10-3A15-7B12-9B8-5B5A4B5-4B9A3B5(4-2B13AB)4-3G12A3(B4-2B13A)B4(3-2(2D15AD2-)2DB13ABD4-B13AB3-9(18A2-)18A28-7B12-9B8-5B5A4B5-4B9A3B9(4-2B13AB))3-2(2D15AD2-)2DB13ABD4-B13AB3-9(18A2-)18A28-7B12-2B5A2B8-4B7A3B5-4B10A2B8(4-2B13AB)3-2DB14A2(D2-2D15A)D2-2DB13ABD4-B13AB3-9(18A2-)18A28-7B12-9B8-14B5-5B7A4B4-6B5A5B3(4-16B)4-6B5A5B3(4-2B13AB)3-2D15AD2-D16AD2-2D15AD2-2D15BD4-15B3-4(18A2-)5A4FA4F4A2-5AF2AFAF2AF4A2-5A2FAFA4F4A2-8AFAF7A2-18A108-7B14-5B75-5B8-7D5A6D2-D5E2D3A2D4ED2-D6ED3AD5ED2-D2EF4E3D2EF3ED2-DEF5E3DEF4ED2-D7E3D6ED2-18D22-3(18A2-)18A309-2(B-)B15-B3AB16-BAB17-3B109-3(18A2-)18A309-5B15-B3AB16-BAB17-3B109-2(18A2-)18A330-3(3B17-)3B109-2(18A2-)18A502-3(18A2-18A522-)18A201-
