model
size = 18 31 15, scale = 0.05, origin = -y
material deform = 1, fade = true, lighting = smooth, roughness = 0.3, metalness = 0.6
  colors = A:#EEE B:#111 C:#444 D:#FC0 E:#C66
voxels
149-2B4-2A258-6C4A6C8-4A15-2E16-2E229-2B4-2A263-6A12-5AB6-6C4A2B6C8-AB14-B-2B-B209-3(2B4-2A10-)2B4-BA3(10-2B4-2B)10-2B4-BA10-2B4-2A10-5B3A10-6B2A11-5BA12-5BA13-4A31-6A2(12-5AB)11-3D2A3D10-D-D2BD-D10-3D2-3D190-4(2B4-2A10-)2B4-AB2(10-2B4-2B)10-2B4-BA10-2B4-2A10-B7A4(10-8A)11-2(6A12-)3(5AB12-)A5B208-2A6-2A135-3AB4A5(10-8A)11-2(6A12-)2(5AB12-)5AB11-2A4BAB2(10-2A4-2B)11-A4-B154-10A9-6(8A10-)3A2B3A5(10-8A)11-6A12-A4BA12-6A3(12-5AB)12-A5B12-A4-B190-10A8-10A9-8A9-2(10A8-)10A9-8A10-3A3B2A10-2A5BA2(10-8B)11-6B13-4B14-4B32-4A13-2(5AB12-)A5B226-5(10A8-)10A9-8A2(10-B6AB)11-6B389-3B5A9-3(10A8-)10A9-8A10-8B11-6B12-6B13-4B391-6B12-5AB11-2(7AB10-)A7B10-8B461-6B12-AB2A2B2(12-6B)500-2B16-2B538-2B16-2B397-2A16-2A15-3A15-2AB15-AB15-BAB14-3B15-2(2B16-)2B397-2A16-2A2(15-3A)15-AB15-3B14-3B15-2B16-2B404-
