model
size = 21 31 21, scale = 0.05, origin = -y
material deform = 1, fade = true, lighting = smooth, roughness = 0.3, metalness = 0.6
  colors = A:#001 B:#B00 C:#E00
voxels
363-2(4A3CA13-)4AC3A13-2ACAC3A13-3A2C3A13-8A13-3A3-2A13-8A371-4AC2A14-2ACAC2A14-3A2C2A14-A2(C2A)14-2A3C2A14-7A12-6(11A10-)4A3B4A10-2A7B2A223-4(5A16-)2(3A2C16-)3A2C13-2AB5-B2(2A10-CA7-2A10-2A7-)2A10-CA7-2A2(10-A)4(9-A10-A)9-AB9-A9-3A5-4A8-4A5-4A8-3A7B4A7-14A95-2(5B16-)5A16-5A14-4(2A5-2A12-)CA5-CA12-2A5-CA12-CA5-CA10-AB9-BA8-C11-C8-A11-A8-C11-C8-B11-A8-C11-A7-6(2A12-A6-)3(5A5-5A6-)2(5A5-)5A7B5A71-2(2B5-2B12-)2A5-2A12-2A5-2A10-4(2A9-2A8-)2C9-2A8-2A9-2A8-2C9-2A7-2(A13-A6-C13-C6-)A13-A6-C13-C4-10(2A15-A3-)2A15-AB2-18AB48-2(B9-B10-)A9-A10-2(A9-)4(A11-A8-)C11-C8-A11-A8-C11-C6-AB13-2A4-C15-C4-A15-B4-B15-C4-A15-A4-C15-C3-5(A17-A2-)6(B17-B2-)B5A7B5AB47-2(B11-B8-)A11-A8-A11-A7-4(A13-A6-)C13-C6-A13-A6-C13-C5-A15-B2(4-C15-C4-A15-A)4-C15-C3-4(A17-A2-)B17-B149-B5A7B5AB26-2(B11-B8-)A11-A8-A11-A7-4(A13-A6-)C13-C6-A13-A6-C13-C4-AB15-BA2-C17-C2-A17-A2-C17-C2-B17-A2-C17-C-A3(19-2A)19-AB19-B148-B3A2B7-2B3AB25-2(B13-B6-)A13-A6-A13-A5-4(A15-A4-)C15-C4-A15-A4-C15-C3-A17-B2(2-C17-C2-A17-A)2-C17-C-A2(19-2A)19-AB19-B190-B3AB9-B3AB4-2(B13-B6-)A13-A6-A13-A5-4(A15-A4-)C15-C4-A15-A4-C15-C3-A17-A2-C17-C2-B17-A2-C17-C2-A17-A2-C17-C-A19-2A19-AB19-B211-B2AB11-B2AB4-2(B13-B6-)A13-A6-A13-A5-4(A15-A4-)C15-C4-A15-A4-C15-C3-A17-A2-C17-C2-A17-B2-C17-C2-A17-A2-C17-C-A19-AB19-B232-B2AB11-B2AB4-2(B13-B6-)A13-A6-A13-A5-4(A15-A4-)C15-C4-A15-A4-C15-C3-B17-A2-B2(17-C2-A17-A2-C)17-C-A19-2A19-AB19-B211-B2AB11-B2AB4-2(B13-B6-)A13-A6-A13-A5-4(A15-A4-)C15-C4-A15-A4-C15-C3-A17-B2(2-C17-C2-A17-A)2-C17-C-A2(19-2A)19-AB19-B190-B3AB9-B3AB5-2(B11-B8-)A11-A8-A11-A7-4(A13-A6-)C13-C6-B13-A6-C13-C4-AB15-B2(A2-C17-C2-A17-)B2-C17-C-A3(19-2A)19-AB19-B148-B4AB7-B4AB26-2(B11-B8-)A11-A8-A11-A7-4(A13-A6-)C13-C6-A13-A6-C13-C5-2(A15-A4-C15-C4-)A15-A4-C15-C3-4(A17-A2-)B17-A7(20-B)2-B5A7B5A2B26-2(B9-B10-)A9-A10-2(A9-)4(A11-A8-)C11-C8-A11-A8-C11-C6-AB13-2A4-B15-C4-A15-B4-C15-C4-A15-A4-C15-C3-4(A17-A2-)B17-A19-A5(15-6A)3-B5A7B5A50-2(2B5-2B12-)2A5-2A12-2A5-2A10-4(2A9-2A8-)2C9-2C8-2A9-2A8-2C9-2C7-2(A13-A6-C13-C6-)A13-A6-C13-C4-2A15-4(A3-A16-)A3-B16-5(A3-BA10-A4-)A3-B17A52-2(5B16-)5A16-5A14-4(2A5-2A12-)CA5-2A12-2A5-2A12-2C5-AC10-AB9-2B8-B2(11-C8-A11-A8-C)11-C6-2A13-5(A5-A14-)3(A5-6A5-A3-)A5-6A5-A2-2A6-4A7B4A158-2(3C2A16-)3(2AC2A16-)2ACAC16-2A2CA13-2AB5-B2A10-2C7-AC10-2A7-AB10-BA7-2A10-2A7-2A10-CA7-2A8-2A11-5(A7-A12-)A2(7-5A5-4A)7-4A7B3A7-13A327-3(7A14-)AC5A14-2AC4A14-3AC3A11-3A7-4(2A9-2A8-)2A9-4A5-3A9-4A-3B-3A9-3A7B2A494-4A2C3A12-A2C2A2CAC12-A2(2C2A)12-AC3AC2AC12-2A3C4A12-9A12-3A3B3A12-9A132-
