model
size = 32, scale = 0.05, origin = -y
material deform = 1, fade = true, lighting = smooth, roughness = 0.3, metalness = 0.6
  colors = A:#070 B:#080 C:#EEE D:#0E0 E:#0C0 F:#050
voxels
44-D31-C26-C10-C-CDC34-D17-C14-C20-2C9-C7-C-C18-C24-2C-C151-C10-C-2C13-C3-C8-D16-D39-C23-D13-C8-C30-3C19-D47-D82-C45-C21-D3-C198-D8-D31-C9-C16-C10-C-CDC3-2C22-C6-D14-C2-C35-C-C15-C46-2C44-C22-C2-D3-2C2-C24-C49-C27-C3-C8-D16-D39-C23-D13-C13-D32-2C13-D6-C-D6-D31-D5-D6-C31-C37-C2(8-D)24-C2-C21-D3-CD42-D45-D56-D215-5C100-4C83-D272-D191-D46-CDC186-D3-D12-D2-2D154-C7-C2-C135-D170-C26-C4-C166-F112-F194-CD41-D155-3C7-C21-2C4-C2-2C41-D8-D53-D2(3-C)4-C20-D12-D22-C4-C54-C-C8-C26-2C2(15-C)21-C2-C-C70-C22-C12-D20-C4-C56-D269-D27-D189-F3-F8-D104-D5-6C6-C18-8C23-10C22-5C-4C22-C-8C22-9C12-C10-3(10C22-)C-8C23-7C27-3C-C13-C63-D37-2(F3-)F10-F461-D7-C2D21-D5-8D18-D-10D4C18-10D3C20-12D2(19-13D)20-12D19-13D16-F2-13D19-14D9-D9-12DC18-14D19-11DC8-D12-5D-4D24-6D297-D17-F2-F14-C9-C67-B2-B22-B3-BC4-2A3-B18-13B-B17-11B-2B13-2D3-5B7AC-BC6-D6-2B14AB-A11-FA2B10A8C2(-F)7-A2B10A6C15-C2(13AD15-A2B)13A2D14-AB-13A2D15-2B13A2D14-C2B13AD15-A-B14ABCA13-2B14A-CA12-A2B14AB-C7-F3-FA-B14A2BAF-C10-CBAC12AB14-A2-14ABCA12-D3B2(C2B)21-DF2-2B-3B29-B30-C5-B45-D73-C9-D19-D94-F7-B2-B7-F16-12B16-F-16A-F8-2(F-)BC17AB-F11-18A8-3D-2D18AB13-18A14-18AB12-B18AB5-C7-18A13-B18AB6-D2(F-)FB18ABC-F9-B18A6-C-D4-B18AB7-FDF-CB18AB2-F2(-C)5-B18A13-3(B18AB12-)B18AB13-18A14-C17A14-13A2-2A12-2(C-)4AB2-3ACB2A20-3B3-4B18-F10-B86-2C2-C124-2B-2B4-2B-2B17-2B5A2-4ABAB7-C7-18A13-B18A14-18AC9-4D18AB12-B18AB12-C3(18AB12-B)18AB6-2D4-B18AB12-B18AB5-D6-B18AC6-3D3-3(B18AB12-)B18AC12-B18AB12-C2(18AB12-B)18AC13-18AB14-16A16-2BAB3A2-2ABCB22-2B4-B93-C47-D11-B6-B24-B6-B2-B9-C7-F-B-2B4-2B-B-F16-16A7-C6-19A13-C18A14-C17AB6-7D19A3-D7-E20AE9-2E20A2E5-D-D2E19AC-ED9-20AE9-2E20AE5-2D2-2E20A2ED-D5-2E20A2E8-CE20AE8-C2E20A2ED-D5-2E20AE10-E20A2E5-D-D2E20AE-D7-2E20AE10-E20A2E10-19AC3-D9-18AB12-B18AB14-17A15-8AC7A18-B-2B4-B4-F17-B2-B31-B42-D19-3BD2BD3B11-D9-12B19-5BD2BD5B9-D8-4B2(2D3B)15-F-16A-C12-20A12-B18A13-B18AC11-E20A2E8-2E20AE9-5(2E20A2E8-)2E20AEC5(8-2E20A2E)9-E20A2E8-2E20A2E3-D-D3-E20AC11-B18AB12-C18A14-17AC13-F-15AB17-4BDB2-2D4B19-B2-BD2B27-B-3B11-D16-CD13-C11-D-12B10-C8-2(14B18-)2(2B4D)2B18-14A15-20A8-2(F-)B18A2(C-)C8-B18AB9-D2E20A2ED7-CE20A2E8-2E20A2E2-C5-2E20A2E7-C2E20A2EC6-C2E20A2EC5-2C2E20A2E2C-C4-2E20A2E7-C2E20A2EC5-2C2E20A2E2C6-2(2E20A2EC7-)2E20A2E8-2E20A2E2-C5-2E20A2E9-E20A2ED9-B18AB8-2(F-)B18AB2(-F)9-17A17-14AC16-CB2C3D2-5DB17-2C37-2B21-C13-C16-C3-14B6-D11-2(14B18-)3B8D3B18-14A8-C6-20A5-C6-B18AC12-B18AB10-2(2E20A2E8-)2E20A2E7-8(C2E20A2EC6-)C2E20A2EC2-D4-2E20A2EC7-2(2E20A2E8-)2E20AE5-D5-B18AB12-B18AC5-C7-18A16-14A18-C2-8D25-C4B28-4B30-C24-14B18-14B8-C9-5B4C5B18-2B10D2B17-16A7-D6-20A12-B18AC12-B18AB10-2E20AEC8-2E20A2E7-C2E20A2E6-2C2E20A2EC3-C2-C2E20A2E2(C2-)2(2C2E20A2EC5-)2C2E20A2EC2-C3-C2E20A2E2(C2-)2C2E20A2EC6-C2E20A2EC3-C2-C2E20A2EC2-C3-C2E20A2EC6-C2(2E20A2E8-)2E20A2E4-D5-B18AB12-B18AB13-17A16-16A19-10D24-B2CBCB28-2B42-D8-D4-14B2D16-14B8-C9-4B6C4B8-C4-D4-2B10D2B4-D10-F-16A-F10-C2-18A2-D10-B18AC10-D-B18AB-D5-D-D2E20AE2C-D5-2E20A2E7-C9(2E20A2EC5-2C)2E20A2EC6-C2(2E20A2EC7-)2E20A2E5-C-D2E20A2ED7-D-B18AB-D11-18A14-18A7-D5-FC16A-C10-D4-C-10D6-D16-B6CB24-8B11-C13-B-2B-B22-6B2C6B18-14B18-4B6C4B18-B12DB9-D7-16A14-C2(18AC12-B)18AB10-2E20A2E8-2E20A2E5-C-C2E20A2EC-C3-4(2C2E20A2EC5-)2C2E20A2E2C4-2C2E20A2E2C-C2-2C2E20A2EC5-2C3(2E20A2EC6-C)2E20A2EC7-2E20A2E8-2E20A2E10-B18AB12-B18AB13-18A15-16A17-B12DBC3-D15-2B6C2B24-6B27-BC2B4-C18-6BC7B18-14B18-4B6C4B18-B12DB9-D7-16A14-20A5-C6-B18AC12-B18AB10-2E20A2E8-2E20A2E7-C2E20A2EC-C3-4(2C2E20A2EC5-)2C2E20A2E2C-C3-C3(2E20A2EC5-2C)2E20A2EC6-C2E20A2EC4-C-C2E20A2EC-C5-2E20A2E8-2E20A2E10-B18A13-B18AB13-18A15-16A17-B12DBC3-D15-2B6C2B24-6B27-B2CB4-C13-D4-14B2D16-14B8-C9-4B6C4B8-C9-2B10D2B15-F-16A-F5-D4-D2-18A2-D10-B18AC10-D-B18AB-D5-D-D2E20A2ED-D5-2E20A2E8-2(2E20A2EC6-C)6(2E20A2EC5-2C)2(2E20A2EC6-C)2(2E20A2EC7-)2E20A2E5-D-D2E20A2ED-D5-D-B18AB-D10-B18A11-D2-18A14-C16A-F10-D4-C-10D6-D16-B6CB24-8B11-C13-B-2B-B23-13B18-14B8-C9-5B4C5B18-2B10D2B17-15AB7-D6-20A12-B18AB12-B18AC10-2E20A2E8-2(2E20A2E7-C)2E20A2EC6-2CE20A2EC2-C3-2CE20A2EC6-C2(2E20A2EC5-2C)2E20A2EC6-C2E20A2EC5-2C2E20A2EC6-C2E20A2EC2-C4-2E20A2EC7-2(2E20A2E8-)2E20A2E10-B2(18AB13-)18A15-16A19-10D24-B4CB28-2B42-D9-C3-14B6-D11-2(14B18-)3B8D3B18-14A16-19A13-18AC12-B18AB10-3(2E20A2E8-)2E20A2E7-6(C2E20A2EC6-)C2E20A2EC7-2E20A2EC2-D4-2E20A2EC8-E2(20A2E8-2E)20A2E10-B18AB12-B18A6-C8-17A16-14A18-C2-8D25-C4B28-4B17-C12-C4-C18-D-13B9-C8-2(14B18-)2B4D2B3DC2B18-14A15-20A12-B18AB2(-F)8-B18AB9-C2E20A2ED-C5-2E20A2E8-2E20AEC2-C5-2(2E20A2E8-)2E20A2EC5-2C2E20A2E2C6-2E20A2EC6-C2E20A2EC5-2C2E20A2E2C5-C2E20A2EC7-2E20A2E9-E20A2E8-2E20A2E2-C5-2E20A2E4-D2-D2E20A2ED-D7-B18AB8-F-F2-18AB-F-C-D7-18A16-14AC16-CB5D2-4D2B17-2C37-2B18-C16-C22-3BD2BD4B10-D9-13B18-5BD2BD5B18-3B3D2B3D3B15-F-B15A-C13-19A12-C18AB12-B18AB11-E20A2E9-E20AE9-5(2E20A2E8-)2E20AEC3(8-2E20A2E)9-E20AEC8-2E20A2E10-20AEC10-20A2E3-3D3-C20A6-2D5-18AB12-B18AB13-C17A13-F-13AB2A-C6-C8-3B3D2-DBD3B9-C9-B2-BD2BDB2-B22-B-4B-B8-D16-CD2-B10-C35-D11-B6-B21-B2-B6-B2-B17-F-B-2B4-2B-B-F16-2B13AB7-C7-18A14-18A13-B18AC7-D4-20A3-D8-20A2E9-E20A2E5-D-D2E20A2E2-D5-E-20AEC8-2E20A2E4-D2-D2E20A2ED-D6-E20A2E9-E20A2E5-D-D2E20A2ED7-2E20A2E9-E20AE9-2E20A2E10-20AE11-20A12-19A13-B18AB6-C6-18A15-17A15-2F5AB7AF16-F-B-2B4-2B-B-F17-B2-B6-B2-B21-B6-B35-D113-2B-2B4-2B-2B17-2BAB3A2-ABA2BCB2(7-C)14A3C13-B18A13-C18AB7-D4-C18AB5-D6-4(B18AB12-)B18AB6-D5-B18AC12-B18AB5-D6-B18AB6-3D3-B18AB12-B18A13-3(B18AB12-)C18AB12-B18A13-B18AB12-B18AB13-7AC10A15-B-2(AC)A2-5A-B17-2B-2B4-2B-2B22-C5-C60-C22-D102-B2-B7-F16-11B19-AB13AB-F10-F-B18A15-17A13-C18AC12-B18AB12-B18AC12-B18AB5-C7-18A13-B18AB6-DF2(-C)B18A5-F8-18AB12-B18AB7-FDF-FB18ABC-F3-C5-B18A13-B18A14-18AB12-B18AC12-B-17A13-B18A14-17A12-F2-C17AB-F4-D3-C-F-2A-3ABAB2AC2A2B-C16-11B23-C-B2-B-C-D3-C25-C53-C2-C47-D-D15-F2-F95-B26-BA4-2A3-B17-9B5CB-F15-3B-11BC16-14AB-A6-D5-A2BA-12A2B8-F-C-F2-B14A2BA2(F-)F9-B14A2BA12-A2B14ABC13-A-B14AB-A12-A2B14A2BA12-AB-14A2BA12-C2B14A2BC12-A-B14AB15-BC14A2BA14-B14AB14-A2B14AC-A11-F-2B14AB14-C-B14A2B14-CB-13A-CA14-B2-13B13-D5-2(B-)2(2B-)2B2-C-D16-2B2-D-2B3-B19-C2(2-B)129-D44-C235-D-C4D14-D2-3D4-D-4D-3D12-2(D-)2D3-2D-6D-DCD18-12D-D19-12DC18-14D15-F2-13D3-F15-C13D18-13D20-13D18-13DC19-12D20-13D19-10D-D8-D16-D-5D25-4D-D93-C24-D20-D103-C13-C10-D17-D44-C148-C3-F71-D31-D4-D37-C-3C27-8C25-8C10-D11-10C22-10C11-C10-3C-6C22-10C22-9C24-9C23-8C18-F6-6C13-C101-C2(3-F)2-F3-F226-4D152-C31-2C2(-C)76-D31-2D33-D12-D22-C4-C54-D-C13-F21-2C9-C5-C15-C6-2C13-C2-D-C8-C-DC53-C4-C22-D12-D20-C3-2C3-C60-D261-D16-D12-D42-D99-C15-2(C4-)2C20-CF4C2-C71-D32-3D90-2D78-C7-C23-C4-4C-2C25-C472-D118-C-3C26-C28-4C41-5C45-D118-2C5-D2-D119-3C146-C102-2D159-D71-
