model
size = 30 6 30, scale = 0.05, origin = -y
material deform = 1, fade = true, lighting = smooth, roughness = 0.3, metalness = 0.6
  colors = A:#E00 B:#DDD C:#B00 D:#EEE E:#700
voxels
41-C2(29-A)88-C29-A151-C27-3A28-A118-C29-3A27-A-A120-C26-4A27-A118-C3-2(C12-)2AB2A11-2A14-3A28-A87-C14-C13-2AB2A11-2A13-3A12-A15-A91-C7-C-C16-2ABA6-6A14-4A10-2A16-A92-C25-AB3A4-5AC16-4A4-3A19-A87-C7-C-C2-C16-3AB2A-5ABA16-6A-2A-3A17-5A3-A87-C23-3AB7ABA17-5A-7A18-4A2-4A109-4AB4A2BAC18-10A21-8A76-C2-C26-8AB3AB2A16-14A19-10A20-4A-2A25-2A18-C-C15-C11-12A4B3A13-17A17-11A21-7A25-2A15-C29-5A11B-B3A13-12AD4A17-13A20-2(3A-)A23-2A19-C2-C14-C11-11A3B5A13-17A16-12A22-A-5A23-2A24-C-C26-7AB2A2B3A16-14A19-AED3AD4A22-2AE65-C18-3AB4A2B2A19-10A20-2D2A2D4A79-C12-C16-2AB7A2B2A17-12A18-5A2-3A22-2A62-C22-2AB9ABA16-6A-7A17-5A28-A55-C3-C4-C-A2-A15-2AB2A4-4ABA15-5A5-4A17-3A116-2AB2A7-4A14-5A26-3A85-C4-C8-C-C13-2AB3A8-4A13-5A26-3A103-C12-AB2(2A12-)3A117-C-C2(27-3A)146-AB2A26-3A117-C-C27-ABA27-2A148-2A28-2A119-C2(28-2A)148-2A28-2A107-
