model
size = 16 17 30, scale = 0.05, origin = -y
material deform = 1, fade = true, lighting = smooth, roughness = 0.3, metalness = 0.6
  colors = A:#FF0 B:#001 C:#309 D:#EEE E:#222 F:#111 G:#333 H:#DDD
voxels
20-A15-5A302-5(A15-)A175-A15-A63-A15-A14-3A14-A143-2A94-A14-2A14-3A14-A111-A15-2A93-2A14-2A13-2ABA14-A15-A95-A15-2A14-4(A15-)A14-3A13-ACA11-2ACBCA11-2ACA14-A95-A15-2A93-2A14-ACA11-2ACBCA11-2ACA14-A57-H14-D-D14-D5-A15-2A93-2A14-ACA11-2ACBCA11-2ACA14-A73-D21-A15-2A93-2A14-ACA11-2ACBCA11-2ACA14-A73-D5-2(A15-)2A93-2A14-ACA11-2ACBCA11-2ACA14-A57-A14-AD7A8-A5-2A14-2A4(15-A)14-2A13-3A13-AFA11-2ACBCA11-2ACA14-A57-A5-2A7-7A2EA7-A5-2(3A13-)3(2A14-)2A13-A-EA12-AGEA12-AC2A10-2ACB2A11-2ACA14-A57-A4-3A7-2A2(7-A)5-3A14-A15-A61-2(3A13-)ACA11-2ACBCA11-2ACA14-A57-A6-A7-2A6-2A7-A6-2A93-A14-2A14-ACA11-2ACBCA11-2ACA14-A57-A6-A7-2A6-2A7-A101-A14-2A14-ACA11-2ACBCA11-2ACA14-A57-8A7-10A7-A101-A14-2A13-2ACA11-2ACBCA11-2ACA14-A57-A5-2A7-3A5-2A7-A85-A15-A13-4A12-A-C2A10-2ACBCA11-2ACA14-A57-A5-2A7-3A5-2A7-A69-A15-A13-4A12-A3BA10-A5BA9-A5BA10-A3BA12-A-A14-2A40-A5-2A7-3A5-2A7-A69-A15-2A12-5A10-2(A5BA9-)A3BABA9-A3BABA10-AB-BA12-3A40-A5-2A7-3A5-2A7-A69-2A13-3A11-2A-B-A10-A5BA9-A5BA8-A4B2ABA8-AB3A-A9-2(A2B)A10-2AB2A13-A25-A5-2A7-3A5-2A7-A69-2A12-A2-A12-5A10-2(A5B3A7-)A2B5A7-2ABA-ABA8-5ABA11-5A13-A25-A5-2A7-3A5-2A7-A53-3A13-4A10-A2-2A-A9-8A7-6A2-2A6-5ABA2-A4-3ABA2-2A-2A4-2A-2A2-4A6-A4-4A8-2A2-3A10-5A23-A5-2A7-3A5-2A7-A54-2A13-2A-A11-2A3-A9-6A-2(A7-)A2(5-2A)2-2A2-5A7-2A3-2A8-2A5-A2(7-2A)4-2A9-6A12-3A7-A5-2A7-3A5-2A7-A54-2A13-A2-A11-2A3-A9-3A-A2-A7-A8-A4-2A9-2A2-3A9-A4-A9-A5-A8-A7-A6-A9-A3-2A11-4A8-A5-2A7-3A5-2A7-A52-A-2A12-2A-2A10-2(2A-)A7-3A4-3A6-2A5-2A-A4-A11-A2-2A10-A4-A8-2A5-2A7-A6-2A5-2A8-2A4-A11-4A8-A5-2A7-3A5-2A7-A52-2A-A11-6A8-2A5-2A6-AEA7-A5-2A8-2A3-A12-A2-A11-A3-A11-A4-A9-2(A5-)4A7-A5-EA9-6A7-A5-2A7-3A5-2A7-A52-2A14-5A10-A4-A8-2A14-A8-2A4-A11-A2-A11-A4-A10-A4-A9-A6-A7-A8-A4-2A10-4A8-A5-2A7-3A5-2A7-A52-2A14-5A9-2A4-3A6-2A6-3A4-A9-2A3-2A10-3A-A12-A2-2A10-A4-A9-A6-A7-A8-A4-2A10-4A8-A5-2A8-3A4-2A59-3A12-7A8-2A5-3A6-2A7-A4-2A10-2A-2A11-5A12-A2-A11-A4-A-A7-A6-2A6-A8-A4-2A10-4A9-2A3-2A10-2A3-A60-3A12-A3-3A8-A6-3A5-2A8-3A2-2A11-A-2A12-4A12-A2-A11-A4-A9-A6-A7-A8-A4-2A10-4A7-
