model
size = 31 5 31, scale = 0.05, origin = -y
material deform = 1, fade = true, lighting = smooth, roughness = 0.3, metalness = 0.6
  colors = A:#630 B:#FF3 C:#200 D:#500 E:#FC3 F:#600 G:#960 H:#888 I:#555 J:#FF0 K:#AAA L:#777 M:#444 N:#700 O:#963
voxels
76-E2B150-BEBLEBE145-4B5DL2BE140-2BI11DIBE137-E17CB135-BEAN8AG3AG2ABE133-BEKB2AN5AF6ABLEB131-B2CB2E13C3B2CB130-B3DBLE6D2A3DBIB3DB129-BI2DAD3B3DA5DE2B2DADMB128-B6DELB7DBKB5DAB128-B7C2BE5C3B7CB127-BLAGAF4ABIB3AEME6AGAHB126-E10AE2B-3B2(4AG)B16-B108-JBAN9AE3-B10AGEB14-B-B29-B25-3F5A3F12-11F5-11F2-JK10CB5-B10CLB13-B3-B27-3B76-2B2AGAG6AB3-BAF9A2E14-B-B29-B78-B3AG6AE2J-BEB10AE16-B109-BMF4AN2ABHB3ABHB2AG5AKB127-E7C3B5CE2B7CB128-J6DBHB7DBIB3DA2DB128-EI4DJEB4D2A3D3B4DME129-B3DJIB4DO6DEHB3DB130-2BCB2E13CB2E2CE131-2BKE6AG8ABM2E133-EB4AG8A2(GA)EB135-B3AG10AG2AB137-2EH11CKEB140-3BH5DHE2B145-E2BKE2B150-BJB76-
