model
size = 22 17 23, scale = 0.05, origin = -y
material deform = 1, fade = true, lighting = smooth, roughness = 0.3, metalness = 0.6
  colors = A:#002 B:#F0C C:#DC00B3 D:#F93 E:#004 F:#009 G:#007 H:#EEE I:#FFB648 J:#F60 K:#00B L:#E00
voxels
9-5A367-9AE362-11A2E360-12A3E358-13A4E10-2(7D15-)13(7A15-)7E9-6A7CA5E7-2DC5-CJ12-2DA5BAJ12-3A5B2A3(12-3A6CA)9(12-10A)12-9EG7-5ACB7-C6E5-IA9CJ10-IAC8BJ10-FACB7CA10-FACB5-2CA10-FAB7-CA10-F2AB6-CA10-F3A5B2CA8(10-F11A)10-F7A3EG6-4ACB8-C6E4-2(IAC8-BAD8-)3(FAC8-C2A8-)F2AB6-2C2A8-F3A6B2C2A8(8-F13A)8-F8A4EG5-4AC10-2C4A4-2(DC10-BAD7-)AC10-B2A7-AC9-CB2A2(7-2AB8-C3A)7-3A7B2C3A8(7-15A)7-9A4EGF3-4A2C10-BC4A4-2(DB10-BAD7-)AB10-2(B2A7-AB9-C)3A7-A2B9-3A7-2A8B2C3A7-15A2(7-14AH)5(7-15A)7-13AGF3-4AB11-BC4A3-2(DAB10-BAD6-)2AB10-2(B2A6-2AB9-C)3A6-2A2B9-3A6-3A8B2C2AH6-15AL2(6-15AH)5(6-16A)6-15AF3-4AB11-BC4A3-2(DAB10-BAD6-)2AB10-2(B2A6-2AB9-C)3A6-2A2B9-2AH6-3A8B2C2A2(H6-15A)H6(6-16A)6-15AG3-4AB11-BC4A3-2(DAB10-BAD6-)2AB10-2(B2A6-2AB9-C)3A6-2A2B8-B3A6-3A8B2C2AH6-15AL2(6-15AH)6(6-16A)3-4AB11-2C4A3-DA2B9-CAD6-DA2B8-B2AD6-2A2B2(8-B3A6-3AB)8-B3A6-2A2B7-B4A6-3A9B4A6-16A2(6-15AH)6(6-16A)4-4AB10-C5A4-DAC9-CAD7-DAB8-B2AD7-2AB7-2B3A7-2AB7-B-3A7-2AB7-B4A7-2A-C5-C5A7-3A6B6A8(7-15A)7-14AE4-4AB9-BC5A4-DAC7-CBCD8-D2AB6-2BAD8-3AB6-B3A8-3AC6-B3A8-2AC-B4C-B3A8-3A7C4A8-3A5B6A8(8-14A)8-13AF6-4ABC7-C4AK6-DAC6-C2AI9-DA2B5C3AI2(9-2A2B5C3AF)9-A2CB5C3AF9-4A4-C3A10(F9-12A)F6-5A8C5AK7-D8CAI11-D9AI14(11-10AG)8-16AG9-2(2D4A3D13-)13(9A13-)8AE10-15A12-2(4D18-)13(4A18-)4A14-13A363-10A366-5A360-
