model
size = 24 29 25, scale = 0.05, origin = -y
material deform = 1, fade = true, lighting = smooth, roughness = 0.3, metalness = 0.6
  colors = A:#C0F B:#603 C:#EEE D:#001
voxels
180-4(2A22-)2A574-5(2A22-)2A186-7A17-7A289-2(B23-)B19-2A118-2A22-2A91-2(B-)B19-2(B-)B18-7A15-11A13-11A15-7A17-7A313-B115-2A22-2A89-B7-B15-B7AB14-11A11-15A9-15A11-11A13-11A15-7A17-7A135-B23-2(B24-)2(B23-)B8-B24-2(B23-)B22-B42-2A22-2A63-2(B11-)B11AB11-13A9-17A7-17A9-13A2-3C6-13A2-3C7-11A13-11A16-5A258-B79-B43-2A17-2A3-2A17-2(2A22-)2A20-13A10-15A7-19A5-19A2C2(5-15A-3C)6-13A2-3C6-13A13-9A17-5A235-B24-B23-2(B20-2A-)B5-2(B14-2A3-2A2-)B14-2A3-2A17-2A3-2A13-B2(3-2A)5-B7-B15AB7-17A6-19A2C3-19A2C4-17A3CD3-17A3CD4-15A-3C5-15A-3C6-13A13-9A273-B23-B5-2(2A22-)2A-B25-2A22-2A2-B19-2A22-2A13-17A6-19A4-21AC2-21AC3-19A2CD2-19A2CD3-17A3C4-17A3C6-13A12-11A16-5A125-2A100-B29-2A22-2A16-B33-B51-B22-2(B11-)2(B5-)B17AB5-19A4-21A3-21AC2(3-19A2C)4-17A3C4-17A8-15A10-13A14-7A82-B23-B17-2A5-B3-2A11-2A6-2(B23-)B22-B16-2A10-2A9-3A10-2A8-2A7-2B12-2A10-B7-B3-2A10-B11-2A22-2A56-19A4-21A2-23A-23A2(2-21AC)3-19A5-19A7-15A10-13A13-9A134-2(2A11-2A9-)3A6(10-2A)9-3A10-2A8-2A21-2A22-2A18-B3-2A10-B7-B3-2A18-B3-2A7-B10-B3-2A2(3-B)19AB3-21A2-23A-23A2-21A3-21A4-19A5-19A6-17A8-15A11-11A17-3A137-2A11-2A9-3A4(10-2A)139-B11-2(2A22-)2A8-19A4-21A2-23A-23A2-21A3-21A4-19A5-19A6-17A8-15A11-11A16-5A17-B23-B217-B24-2(B23-)B22-2B17-B3-B16-B2-B3-B12-B3-B9A-9AB3-21A2-23A-23A2-21A3-21A4-19A5-19A6-17A8-15A11-11A16-5A65-B169-B184-19A4-21A2-23A-23A2-21A3-21A4-19A5-19A6-17A8-15A11-11A16-5A89-B23-2(B24-)2(B23-)B150-B23-B8-B14-B4-B3-B19AB3-21A2-23A-23A2-21A3-21A4-19A5-19A6-17A8-15A11-11A17-3A183-2A21-4(2A22-)2A23-2A10-B12-3A2(22-2A)18-19A4-21A2-23A-23A2(2-21AC)3-19A5-19A7-15A10-13A13-9A76-B23-B79-2A22-2A21-2A8-2A3(3-B2(8-2A))2-B9-2A11-B11-2A23-3A22-2A18-B3-2A12-B5-B17AB5-19A4-21A3-21AC2(3-19A2C)4-17A3C4-17A8-15A10-13A14-7A110-2A13-B7-3A21-2A22-2A31-2A3-B18-8(2A22-)2A12-17A6-19A4-21AC2-21AC3-19A2CD2-19A2CD3-17A3C4-17A3C6-13A12-11A16-5A111-2A21-3A13-B7-2A14-B23-B16-2A4-B17-2A90-B3-2A18-B3-2A13-2B3-B3-2A15-B2-B3-2A12-2(B2-)B3-2A4-B7-B15AB7-17A6-19A2C3-19A2C4-17A3CD3-17A3CD4-15A-3C5-15A-3C6-13A13-9A165-3(2A22-)2A90-B65-B73-13A10-15A7-19A5-19A2C2(5-15A-3C)6-13A2-3C6-13A13-9A17-5A167-2(2A22-)2A13-B21-2B29-B23-B89-B49-2(B11-)B11AB11-13A9-17A7-17A9-13A2-3C6-13A2-3C7-11A13-11A16-5A230-B44-B7-B63-2B24-B23-B75-B7-B15-B7AB14-11A11-15A9-15A11-11A13-11A15-7A17-7A207-B23-B2-B19-B3-B23-B39-B23-B151-2(B-)B19-2(B-)B18-7A15-11A13-11A15-7A17-7A258-B358-7A17-7A236-2(B23-)B22-B589-
