model
size = 28 17 28, scale = 0.05, origin = -y
material deform = 1, fade = true, lighting = smooth, roughness = 0.3, metalness = 0.6
  colors = A:#FC3 B:#E00 C:#FC0 D:#00D E:#0D0 F:#EEE G:#BBB H:#9CF I:#CC0 J:#0E0
voxels
39-6A248-2D26-2D164-6A248-2D26-2D189-12A18-5AC2A21-C3A2C2(22-CA2-AC)22-C4AC22-C4-C22-C3A2C22-CA2D2A2(22-AD2ADA)22-2A2D2A22-6A23-A2-A24-4A25-2C26-AC19-5A6B5A13-3AG6BG3A15-3C7ACA16-C4A2F2A3C16-C-3A2F3A-A16-C-8A-A16-C-2A4-2A-A16-C-8A-A16-C11A2(16-A-8A-A)19-6A23-4A24-A2-A25-2A26-2A46-4A10B4A11-A2G10BAHA13-C3A3-A2-4A15-C2(2A2-)3A15-EA-A2-2A2-2(A-AE14-EA-A6-)A-AE15-A-A6-A-A15-4A6-4A14-2A-A6-A-2A14-2A10-2A2(14-A12-A)123-4A13B3A9-CGA13BGA11-C3A3-3B2-4A13-C2A4-A3-3A5(14-CA10-2A)13-3A10-3A12-2A12-AC2(12-2A)12-A14-A12-A14-C11-CA14-A2(C10-C16-)C8-3A5B7-4B3A7-CG6B5-5BHA9-CA3-9B2-2A16-7B22-5B25-A186-2A14-2A10-BA14-AB9-CA16-AC8-C17-AC8-A18-C6-3A4B11-3B3A5-CA5B9-4BHA7-2A2-3B7-3B-2A13-11B18-9B20-7B24-A73-3(A18-A8-)2(2A16-2A8-)A18-A62-2A4B13-3B2A4-2A4B13-3BAC5-CA-3B11-2B-2A7-A3-3B7-3B2-A7-EA3-13B2-AE6-EA4-11B3-AE6-EA6-7B5-AE7-A9-A8-A7-4(2A18-2A6-)A20-A116-3A3B15-2B3A3-2A3B15-2BAC4-C2A-2B13-2B2AC4-C2A2-2B11-2B-3A4-C2A2-4B7-4B-3A4-C2A3-13B2-3A4-C2A4-11B3-3A4-C2A6-7B5-3A4-3A9-A8-3A4-3A18-3A4-2A20-2A171-2A3B17-2B2A3-A4B15-3BC4-C2A-B15-B2AC4-3A-2B13-2B2AC2(9-3B)13-5B5-5B14-13B17-9B11-2A8-5B7-2A16-A210-2A3B17-2B2A2-AG3B17-2BHC3-2A-2B15-2BAC4-2A2-2B13-2B-2A4-2A2-3B11-3B-2A4-2A3-4B7-4B2-2(2A4-)13B3-AC4-2A5-11B4-AC4-2A7-7B6-2A4-2A10-A9-2A4-A22-A170-2A3B19-2B2A-C4B17-3BA2-CA2-B17-B-AC2-CA2-2B15-2B-AC2-CA3-2B13-2B2-AC2-CA3-4B9-4B2-AC2-CA4-2(6B3-)AC2-CA5-5B3-5B4-2A2-CA7-3B3-3B6-2A2-2A10-3B9-2A2-2A11-A10-2A2-2A22-2A2-A24-A113-2A3B19-2B2A-C3B19-2BA2-2A2-B17-B-2(2A2-)2B15-2B-2(2A2-)3B13-3B-2A2-2A3-3B11-3B2-2A8-5B5-5B7-2A2(5-4B)4-2A2-CA6-2(3B5-)2A2-DA9-5B8-AD2-DA11-A10-AD3(2-2A22-2A)2-A24-A57-2A3B19-2B2A-A3B19-2BA2-2A-2B17-2B2A3-FA-2B15-2BAF4-FA-3B13-3BAF3-2A3-3B11-3B2-2A8-2(4B7-)2A5-3B7-3B4-2A2-DA6-2B7-2B5-AD-D2A8-7B7-2A2D2A10-3B9-2AD-DA11-A10-AD2-2A22-2A30-2(CA22-AC2-)C24-A-2A3B19-2B2A-A3B19-2BA2-2A-2B17-2B2A3-F2A2B15-2BAF4-FA-3B13-3BAF3-2A2-A3B11-3BA-2A7-A4B7-4BA6-2A4-A3B7-3BA3-2A2-DA5-A2B7-2BA4-AD-D2A6-2A7B2A5-2A2D2A8-2ABJB2A7-2AD-DA10-A-A9-AD2-2A22-2A30-CA22-2A2-CA22-AC2-A24-C-2A3B19-2B2A-A3B19-2BC2-2A-2B17-2B2A2-CA2-2B15-2B-2(2A2-)3B13-3B-2A2-2A3-3B11-3B2-2A8-2(4B7-)2A5-3B7-3B4-2A2-2A6-2B7-2B5-2A2-DA8-7B7-AD2-DA10-3B9-AD2-2A11-A10-2(2A2-2A22-)2A2-A24-A57-2A3B19-2B2A-C3B19-2BC2-CA2-B17-B-AC2-CA2-2B15-2B-AC2-CA2-3B13-3B-AC2-CA3-3B11-3B2-AC2-CA4-5B5-5B3-AC2-CA2(5-4B)4-AC2-CA6-2(3B5-)AC2-2A9-5B8-2A2-2A11-A10-2A2-2A22-2A2-A24-A114-2A2B19-2BA2-CG3B17-3BA3-CA-B17-B2A4-CA-2B15-2B2A4-CA2-2B13-2B-2A4-CA2-4B9-4B-2A4-CA2(3-6B)2-2A4-CA5-4B3-5B3-2A4-CA6-3B3-3B5-2A4-2A9-3B8-2A4-A11-A10-A171-3A2B17-2B2A3-CA2B17-2BA4-3A2B15-2BAC4-3A-2B13-2B3A8-3B11-3B12-4B7-4B14-13B16-11B10-2A7-7B6-2A16-A210-3A2B17-2B2A3-AG3B15-3BC4-3A-B15-B2AC4-3A-2B13-2B2AC4-3A2-3B9-3B-2AC4-3A2-5B5-5B-2AC4-3A3-13B2-2AC4-3A5-9B2(4-3A)7-5B6-3A4-3A9-A8-3A4-2A20-2A172-3A2B15-2B2A4-AGA2B15-2BHA5-2A-2B13-2B2A7-A2-2B11-2B-A7-EA2-4B7-4B-AE6-EA3-13B2-AE6-EA4-11B3-AE7-A6-7B5-A7-2A9-A8-3(2A6-2A18-)2A6-A20-A117-3A3B13-2B3A5-AH3B13-2BHA7-2A-2B11-2B2A12-3B7-3B15-13B16-11B19-7B24-A64-2(A8-A18-)A2(8-2A16-2A)8-A18-A63-3A3B11-2B3A7-AH4B9-3BHC9-3A3B7-3B2A12-A12B15-A2-9B16-A3-7B17-A6-A20-4(A27-)A25-2A14-2A10-BA14-AB9-2A16-AC8-CA16-AC8-C18-A8-4A3B7-3B3A9-3A4B5-4BHC11-C2A10B-AC13-IA2-7B2-C14-2A3-5B3-C14-2A2(5-A)14-2A11-C2(14-2A11-A)14-2A11-5(2A12-)2A13-A12-A14-A11-CA14-AC10-C16-C10-A16-C10-4A11B3A11-CAG11BHC13-C3A2-3B-3AC15-3A2-2A2-3A15-EA-A2-2A2-2(A-AE14-EA-A6-)A-AE15-A-A6-A-A15-4A6-4A14-2A-A6-A-2A14-2A11-2(A14-A12-)A125-5A7B4A13-2CAH7B3C15-3C6A3C16-C4A2F2ACAC16-C-3A2F2AC-C16-C-7AC-C16-C-2A4-AC-C16-C-7AC-A16-C11A2(16-A-8A-A)19-6A23-4A24-A2-A25-2A26-2A49-12A18-4AC3A21-2CA3C22-2C2-AC22-CA2-AC22-2C3AC22-A4-C22-5AC22-2A2DA2(C22-AD2AD)A22-CA2DAC22-AC4A23-A2-A24-3CA25-2C26-CA13-
