model
size = 16 32 16, scale = 0.05, origin = -y
material deform = 1, fade = true, lighting = smooth, roughness = 0.3, metalness = 0.6
  colors = A:#FC0 B:#008 C:#E00 D:#909 E:#0E0 F:#00A G:#0A0
voxels
103-2A13-B2AB11-2B2A2B10-2B2A2B11-B2AB13-2A414-2A13-B2AB11-2B2A2B10-2B2A2B11-B2AB13-2A398-2A12-2B2A2B9-3B2A3B8-2B4A2B7-2B6A2B6-2B6A2B7-2B4A2B8-3B2A3B9-2B2A2B12-2A350-2A11-8B7-10B6-4B2A4B5-4B4A4B2(4-3B6A3B)4-4B4A4B5-4B2A4B6-10B7-8B11-2A318-2A11-8B7-B8AB5-2(B10AB4-)B10AB3-2B10A2B2-2B10A2B3-2(2B8A2B4-)3B6A3B5-4B2A4B7-8B11-2A300-2B2A2B8-10B5-B10AB4-B10AB3-B12AB3(2-2B10A2B)2-3B8A3B2-BAB8ABAB3-3B6A3B4-BA3B2A3BAB5-2BA4BA2B8-2B2A2B283-4A10-2(2BA)2B7-4B2A4B5-B10AB3-2(B12AB2-)2B10A2B-BAB10ABA2BAB10ABAB-3B8A3B2-BAB8ABAB2-BA2B6A2BAB3-BA3B2A3BAB5-2BA4B2AB7-3B2A3B11-2A268-6A9-8B6-4B4A4B4-B10AB3-B12AB2-B12AB-B3(AB10ABA2B)A2B8A2BAB-BAB8ABAB2-BA2B6A2BAB3-BA3B2A3BAB4-2B2A4B2A2B6-3B2A3B11-2A267-3A2C3A7-2A6B2A5-A2B6A2BA3-14A2-14A-18A3(B10AB4A)2B8A2B5AB8AB3A-2A2B6A2B2A2-3A3B2A3B3A3-4A4B4A5-10A8-6A11-2(4A2(12-A2-A)12-)A2-A8-12A3-2(A2-A-)3(A2-)2(A-A2-)A3-12A8-2(A2-A12-)4A13-2A27-2A4C2A7-2A6B2A5-A2B6A2BA3-14A2-14A-18A3(B10AB4A)2B8A2B5AB8AB3A-2A2B6A2B2A2-3A3B2A3B3A3-4A4B4A5-10A8-6A11-4A2(12-A2EA)12-4A2(12-A2FA)8-A3-A2F2(A3-)14A2(2-A2DAGA2CAGA2DA)2-14A2(3-A)2EA3-A8-A2EA2(12-4A)13-2A11-3A2C3A7-3A4B3A5-2A2B4A2B2A3-14A2-14A-18A3(B10AB4A)2B8A2B5AB8AB3A-2A2B6A2B2A2-3A3B2A3B3A3-4A4B4A5-2AB4AB2A8-6A11-2(4A2(12-A2-A)12-)A2-A8-12A3-2(A2-A-)3(A2-)2(A-A2-)A3-12A8-2(A2-A12-)4A13-2A28-6A9-2(2BA)2B7-4B2A4B5-B10AB3-2(B12AB2-)2B10A2B-BAB10ABA2BAB10ABAB-3B8A3B2-BAB8ABAB2-BA2B6A2BAB3-BA3B2A3BAB5-B2A4B2AB7-3B2A3B11-2A269-4A11-2B2A2B8-10B5-B10AB4-B10AB3-B12AB3(2-2B10A2B)2-3B8A3B2-BAB8ABAB3-3B6A3B4-BA3B2A3BAB5-2BA4BA2B8-2B2A2B300-2A11-8B7-B8AB5-2(B10AB4-)B10AB3-2B10A2B2-2B10A2B3-2(2B8A2B4-)3B6A3B5-4B2A4B7-8B11-2A318-2A11-3B2A3B7-2B6A2B6-B8AB5-2B8A2B2(4-B10AB)4-2B8A2B5-B8AB6-2B5A3B7-3B2A3B10-B2AB349-2A12-2B2A2B9-3B2A3B8-2B4A2B7-2B6A2B6-2B6A2B7-2B4A2B8-3B2A3B9-2B2A2B12-2A311-
