model
size = 27 14 26, scale = 0.05, origin = -y
material deform = 1, fade = true, lighting = smooth, roughness = 0.3, metalness = 0.6
  colors = A:#09F B:#FC0 C:#CFF D:#EEE E:#FF0 F:#9CF G:#69C H:#FFC
voxels
32-2(17B10-)17B11-2(B26-)B215-2(15B12-)15B308-3(17B10-)2(B15E11-)B241-19B2(8-17BAB)2(9-ED14AEB)10-B14E-B10-B14E12-11B175-21B6-BD16BDAB6-18BDAB8-EAD13ADE9-EAD13ADE10-2(ED13AB11-)BD8A6B12-B8E18-B129-23B2(4-2BA16B3AB)5-2(BEB2AD11AD2AE6-)B-2(E2AD11ADAE9-)B2AD11AD2B10-2ED11EB14-B11-B115-25B2-2(BD)A15B3ADB2-3BDA15B3ADB4-ED4AD9AD4AB5-ED4AD9AD3AEB5-2B4AD9AD2AE-B5-2B4AD9AD2AE7-2B4AD9AD2AB8-B2E2AD9AD2E9-B2-EAB9EB15-EB9EB88-29BABAD15BA7BABAD15BA5B2-E2AD4AD5AGAD4ADAE3-E2AD4AD5AGAD4AD2E4-2(EAD4AD5AGAD4AB6-)BAD4AD5AGAD3A2B7-ED4AD5AGAD2AE10-B2E2AD5AGADAE14-2ED7ED2E16-B7-B62-29B4A15BA7B4A15BA5B-E4AD2A10D3AD2AE2-E4AD2A10D3AD2AE3-E3AD2A10D3ADAE4-E3AD2A10D3ADAE5-B2AD2A10D3ADB7-EAD2A10D2AEB9-ED2A10DAE-B9-EB2E10D2E12-B2-10B62-28B6A2D2F6CF4D6B6A2D2F6CF4D5B-E5A2D2F6CF4D3AE2-E5A2D2F6CF4D3AE3-E4A2D2F6CF4D2AE4-E4A2D2F6CF4D2AE5-B3A2D2F6CF4D2AB6-E2A2D2F6CF4D2E8-EA2D2F6CF3DB10-2E2D2F6CF3DB12-2BEF6CF3B16-8E36-28B6AD2F8CFD2A6B6AD2F8CFD2A5B-E5AD2F8CFD5AE2-E5AD2F8CFD5AE3-E4AD2F8CFD4AE4-E4AD2F8CFD4AE5-B3AD2F8CFD4AB6-E2AD2F8CFD2A2E8-EAD2F8CFDAE10-2ED2F8CFD2E12-B2F8CFB15-3E6C2E19-6E10-28B6ADF10CD2A6B6ADF10CD2A5B-E5ADF10CD5AE2-E5ADF10CD5AE3-E4ADF10CD4AE4-E4ADF10CD4AE5-B3ADF10CD4AB6-E2ADF10CD2A2E8-EADF10CDAE10-2EDF10CD2E12-BF10CB15-E9CE17-9E9-28B6AD11CD2A6B6AD11CD2A5B-E5AD11CD5AE2-E5AD11CD5AE3-E4AD11CD4AE4-E4AD11CD4AE5-B3AD11CD4AB6-E2AD11CD2A2E8-EAD11CDAE10-2ED11CD2E12-B11CB15-E9CE17-9E9-28B6AD2CB5D3CD2A6B6AD3C5F3CD2A5B-E5AD3C5F3CD5AE2-E5AD3C5F3CD5AE3-E4AD3C5F3CD4AE4-E4AD3C5F3CD4AE5-B3AD3C5F3CD4AB6-E2AD3C5F3CD2A2E8-EAD3C5F3CDAE10-2ED3C5F3CD2E12-B3C5F3CB15-E2C5F2CE17-9E9-28B6AD2CB5D3CD2A6B6AD3C5F3CD2A5B-E5AD3C5F3CD5AE2-E5AD3C5F3CD5AE3-E4AD3C5F3CD4AE4-E4AD3C5F3CD4AE5-B3AD3C5F3CD4AB6-E2AD3C5F3CD2A2E8-EAD3C5F3CDAE10-2ED3C5F3CD2E12-B3C5F3CB15-E2C5F2CE17-4EH4E9-28B6AD3C5D3CD2A6B6AD3C5F3CD2A5B-E5AD3C5F3CD5AE2-E5AD3C5F3CD5AE3-E4AD3C5F3CD4AE4-E4AD3C5F3CD4AE5-B3AD3C5F3CD4AB6-E2AD3C5F3CD2A2E8-EAD3C5F3CDAE10-2ED3C5F3CD2E12-B3C5F3CB15-E2C5F2CE17-3E3H3E9-28B6AD4C4D3CD2A6B6AD4C4F3CD2A5B-E5AD4C4F3CD5AE2-E5AD4C4F3CD5AE3-E4AD4C4F3CD4AE4-E4AD4C4F3CD4AE5-B3AD4C4F3CD4AB6-E2AD4C4F3CD2A2E8-EAD4C4F3CDAE10-2ED4C4F3CD2E12-B4C4F3CB15-E3C4F2CE17-4E2H3E9-28B5AGD11CD2A6B5AGD11CD2A5B-E4AGD11CD5AE2-E4AGD11CD5AE3-E3AGD11CD4AE4-E3AGD11CD4AE5-B2AGD11CD4AB6-EAGD11CD2A2E8-EGD11CDAE10-2ED11CD2E12-B11CB15-E8C2E17-8E10-28B6ADF9CF2DA6B6ADF9CF2DA5B-E5ADF9CF2D4AE2-E5ADF9CF2D4AE3-E4ADF9CF2D3AE4-E4ADF9CF2D3AE5-B3ADF9CF2D3AB6-E2ADF9CF2DA2E8-EADF9CF2DE10-2EDF9CF2DE12-BF8CFE2B14-2E6C2E19-6E11-28B5A2D2F7C2FDAD6B5A2D2F7C2FDAD5B-E4A2D2F7C2FDAD3AE2-E4A2D2F7C2FDAD3AE3-E3A2D2F7C2FDAD2AE4-E3A2D2F7C2FDAD2AE5-B2A2D2F7C2FDAD2AB6-EA2D2F7C2FDAD2E8-E2D2F7C2FDAB10-E2D2F7C2FDEB11-3BE6CFE2B17-7E37-28B4AD2ADF6C2FD3A6B4AD2ADF6C2FD3A5B-E3AD2ADF6C2FD3AD2AE2-E3AD2ADF6C2FD3AD2AE3-E2(2AD)F6C2FD3ADAE4-E2(2AD)F6C2FD3ADAE5-BAD2ADF6C2FD3AD2B6-ED2ADF6C2FD2AEB9-B3EF6C2FDAE-B9-B3EF6C2FD2E15-10B62-28B3AD4A9D4A6B3AD4A9D4A5B-E2AD4A9D5ADE3-E2AD4A9D5ADE4-EAD4A9D5AB5-EAD4A9D5AB6-2B4E9D4AEB7-B4E9D2A2E9-B4-B7EBAE16-B7EB2E24-B64-25B2(2-BAD5AD8AD5ADB)3-2(BD5AD8AD4AEB4-)2B5AD8AD3AE-B5-B5ED8AD3AE7-B5-B8ADA2EB13-B8EBE16-B8-B26-B91-23B4-B5AD10AD3ADB4-B5AD10AD3A2B5-E4AD10AD2AE7-E4AD10AD2AE8-E3AD10ADAE9-4ED10ADAE9-B3-B10EDEB13-B10-B145-21B2(6-B3AD12ADA2B)7-E2AD12ADE9-E2AD12ADE10-EAD12EB11-2ED12EB11-16B172-19B2(8-BAD14A2B)9-ED14EB10-ED14EB11-2B13-B12-B26-B181-
