model
size = 27 14 26, scale = 0.05, origin = -y
material deform = 1, fade = true, lighting = smooth, roughness = 0.3, metalness = 0.6
  colors = A:#09F B:#FC0 C:#EEE D:#CFF E:#9CF F:#69C G:#BBB
voxels
32-2(17B10-)17B11-2(B26-)B215-2(15B12-)15B308-3(17B10-)2(B15C11-)B241-19B2(8-17BAB)2(9-2C14ACB)10-B14C-B10-B14C12-11B175-21B6-BC16BCAB6-18BCAB8-CAC13A2C9-CAC13A2C10-2(2C13AB11-)BC8A6B12-B8C18-B129-23B2(4-2BA16B3AB)5-2(BCB2AC11AC2AC6-)B-2(C2AC11ACAC9-)B2AC11AC2B10-14CB14-B11-B115-25B2-2(BC)A15B3ACB2-3BCA15B3ACB4-2C4AC9AC4AB5-2C4AC9AC3ACB5-2B4AC9AC2AC-B5-2B4AC9AC2AC7-2B4AC9AC2AB8-B2C2AC9A3C9-B2-CAB9CB15-CB9CB88-29BABAC15BA7BABAC15BA5B2-C2AC4AC5AFAC4ACAC3-C2AC4AC5AFAC4A3C4-2(CAC4AC5AFAC4AB6-)BAC4AC5AFAC3A2B7-2C4AC5AFAC2AC10-B2C2AC5AF2(AC)14-13C16-B7-B62-29B4A15BA7B4A15BA5B-C4AC2A10C3AC2AC2-C4AC2A10C3AC2AC3-C3AC2A10C3ACAC4-C3AC2A10C3ACAC5-B2AC2A10C3ACB7-CAC2A10C2ACB9-2C2A10CAC-B9-CB14C12-B2-10B62-28B6A2C2E6DE4C6B6A2C2E6DE4C5B-C5A2C2E6DE4C3AC2-C5A2C2E6DE4C3AC3-C4A2C2E6DE4C2AC4-C4A2C2E6DE4C2AC5-B3A2C2E6DE4C2AB6-C2A2C2E6DE6C8-CA2C2E6DE3CB10-4C2E6DE3CB12-2BCE6DE3B16-8C36-28B6AC2E8DEC2A6B6AC2E8DEC2A5B-C5AC2E8DEC5AC2-C5AC2E8DEC5AC3-C4AC2E8DEC4AC4-C4AC2E8DEC4AC5-B3AC2E8DEC4AB6-C2AC2E8DEC2A2C8-CAC2E8DECAC10-3C2E8DE3C12-B2E8DEB15-3C6D2C19-6C10-28B6ACE10DC2A6B6ACE10DC2A5B-C5ACE10DC5AC2-C5ACE10DC5AC3-C4ACE10DC4AC4-C4ACE10DC4AC5-B3ACE10DC4AB6-C2ACE10DC2A2C8-CACE10DCAC10-3CE10D3C12-BE10DB15-C9DC17-9C9-28B6AC11DC2A6B6AC11DC2A5B-C5AC11DC5AC2-C5AC11DC5AC3-C4AC11DC4AC4-C4AC11DC4AC5-B3AC11DC4AB6-C2AC11DC2A2C8-CAC11DCAC10-3C11D3C12-B11DB15-C9DC17-9C9-28B6AC2DB5C3DC2A6B6AC3D5E3DC2A5B-C5AC3D5E3DC5AC2-C5AC3D5E3DC5AC3-C4AC3D5E3DC4AC4-C4AC3D5E3DC4AC5-B3AC3D5E3DC4AB6-C2AC3D5E3DC2A2C8-CAC3D5E3DCAC10-3C3D5E3D3C12-B3D5E3DB15-C2D5E2DC17-9C9-28B6AC2DB5C3DC2A6B6AC3D5E3DC2A5B-C5AC3D5E3DC5AC2-C5AC3D5E3DC5AC3-C4AC3D5E3DC4AC4-C4AC3D5E3DC4AC5-B3AC3D5E3DC4AB6-C2AC3D5E3DC2A2C8-CAC3D5E3DCAC10-3C3D5E3D3C12-B3D5E3DB15-C2D5E2DC17-4CG4C9-28B6AC3D5C3DC2A6B6AC3D5E3DC2A5B-C5AC3D5E3DC5AC2-C5AC3D5E3DC5AC3-C4AC3D5E3DC4AC4-C4AC3D5E3DC4AC5-B3AC3D5E3DC4AB6-C2AC3D5E3DC2A2C8-CAC3D5E3DCAC10-3C3D5E3D3C12-B3D5E3DB15-C2D5E2DC17-3C3G3C9-28B6AC4D4C3DC2A6B6AC4D4E3DC2A5B-C5AC4D4E3DC5AC2-C5AC4D4E3DC5AC3-C4AC4D4E3DC4AC4-C4AC4D4E3DC4AC5-B3AC4D4E3DC4AB6-C2AC4D4E3DC2A2C8-CAC4D4E3DCAC10-3C4D4E3D3C12-B4D4E3DB15-C3D4E2DC17-4C2G3C9-28B5AFC11DC2A6B5AFC11DC2A5B-C4AFC11DC5AC2-C4AFC11DC5AC3-C3AFC11DC4AC4-C3AFC11DC4AC5-B2AFC11DC4AB6-CAFC11DC2A2C8-CFC11DCAC10-3C11D3C12-B11DB15-C8D2C17-8C10-28B6ACE9DE2CA6B6ACE9DE2CA5B-C5ACE9DE2C4AC2-C5ACE9DE2C4AC3-C4ACE9DE2C3AC4-C4ACE9DE2C3AC5-B3ACE9DE2C3AB6-C2ACE9DE2CA2C8-CACE9DE3C10-3CE9DE3C12-BE8DEC2B14-2C6D2C19-6C11-28B5A2C2E7D2ECAC6B5A2C2E7D2ECAC5B-C4A2C2E7D2ECAC3AC2-C4A2C2E7D2ECAC3AC3-C3A2C2E7D2ECAC2AC4-C3A2C2E7D2ECAC2AC5-B2A2C2E7D2ECAC2AB6-CA2C2E7D2ECA3C8-3C2E7D2ECAB10-3C2E7D2E2CB11-3BC6DEC2B17-7C37-28B4AC2ACE6D2EC3A6B4AC2ACE6D2EC3A5B-C3AC2ACE6D2EC3AC2AC2-C3AC2ACE6D2EC3AC2AC3-2(C2A)CE6D2EC3ACAC4-2(C2A)CE6D2EC3ACAC5-BAC2ACE6D2EC3AC2B6-2C2ACE6D2EC2ACB9-B3CE6D2ECAC-B9-B3CE6D2E3C15-10B62-28B3AC4A9C4A6B3AC4A9C4A5B-C2AC4A9C5A2C3-C2AC4A9C5A2C4-CAC4A9C5AB5-CAC4A9C5AB6-2B13C4ACB7-B13C2A2C9-B4-B7CBAC16-B7CB2C24-B64-25B2(2-BAC5AC8AC5ACB)3-2(BC5AC8AC4ACB4-)2B5AC8AC3AC-B5-B6C8AC3AC7-B5-B8ACA2CB13-B8CBC16-B8-B26-B91-23B4-B5AC10AC3ACB4-B5AC10AC3A2B5-C4AC10AC2AC7-C4AC10AC2AC8-C3AC10ACAC9-5C10ACAC9-B3-B12CB13-B10-B145-21B2(6-B3AC12ACA2B)7-C2AC12A2C9-C2AC12A2C10-CA13CB11-15CB11-16B172-19B2(8-BAC14A2B)9-16CB10-16CB11-2B13-B12-B26-B181-
