model
size = 31 3 9, scale = 0.05, origin = -y
material deform = 1, fade = true, lighting = smooth, roughness = 0.3, metalness = 0.6
  colors = A:#630 B:#633 C:#111
voxels
12-A-B2(-A)24-A2B2A2B24-3(A-)B21-4A2(-A)-4A18-B4A2B3AB2A18-4A-B2(-A)B2A16-5A7-3A2B14-B4A7-3BAB14-2B3A7-5A12-2A2B13-2B2A10-B3A13-4A10-4A13-4A8-2(AB)17-B3A6-3BA17-3AB6-3AB17-AB2A5-3A21-3A4-2AB21-A2B4-A2B21-BAB3-2A25-BA2-BA25-BA2-AB25-2A2-2A25-2A-B2A25-3A-2A25-2A-A29-A31CA29-A
