model
size = 26 32 13, scale = 0.05, origin = -y
material deform = 1, fade = true, lighting = smooth, roughness = 0.3, metalness = 0.6
  colors = A:#D8B1AA B:#DEB9B2 C:#E7C0B9 D:#CE9E9A E:#BB908A F:#C49792 G:#AD867E H:#CFABA4 I:#A67F76 J:#A37670 K:#8C625B L:#956F67 M:#9A7B73 N:#9A766D O:#8F6860 P:#EEC6C2 Q:#AF8D8B R:#815A55 S:#B88683 T:#9D605D U:#7A544F V:#A08680 W:#A16D67 X:#704944 Y:#876760 Z:#64413D Aa:#3E2C28 Ab:#8D6D66 Ac:#925854 Ad:#C0A099 Ae:#593E3B Af:#694540 Ag:#4A3531 Ah:#8E766F Ai:#B79992 Aj:#B37474 Ak:#C78C8C Al:#7E4B48 Am:#C07C81 An:#6E5852 Ao:#C4ACAD Ap:#884347 Aq:#A96467
voxels
403-H778-SFA22-AjEH2C21-JEHBC21-AjEA2B22-AkA700-WGF21-TWJS2DA19-2W3-2B19-TW3-BA20-JS-2BA20-JEA2B22-FAB671-WAlUJSJ20-2W3-SD19-W5-2A18-T5-A19-TW3-2A19-2WAj-BA21-JE2BA22-D2B465-S2GE22-2Ak2DH20-TAqAk2AmAj19-JSDHD2HF18-KLG2FDJ20-KIFD2E20-AlRSFS20-JAlRJESAj18-2T5-FH17-T7-H17-2Ac5-2A18-T5-A19-W4-2A19-2J3-A21-WDC2A22-DCA310-AbMIQ21-IGFEF21-IEFDA21-ESH2A20-2(GE)FA19-G2S2IEHA18-TAj2AkD3A17-NWApAc2-AkAmJAc16-KLI4-HIE16-KAcO4-QGE16-TAcK3-2EF17-TAcAl3-2FH17-2TAl4-EH17-T7-A17-T7-H17-Ac7-A17-2T5-A19-W5-B19-W4-2B19-2W2-2A21-WDC2A21-AjDCB21-LGD2A19-R2LS3DG18-2EFDAD2F18-2D6A18-DAB2C3B19-2BP2CB21-P2C101-RYRAbYMAbRAb17-YNISF3QI17-SEIE2-HFQ17-EFEG-2AHE16-I2GFGFD2AD16-J2G4-2AHF14-ROJ6-2HF14-KL7-SLG13-OKR8-EQ13-ILK8-QE13-ESJ7-3H13-DEJAc6-3A13-HST7-AB15-2T7-HA15-JAc7-2A15-ST7-B2(17-J6-BC)17-2J5-B19-W4-A20-2T3-A20-TJDC2A16-EGJOAcID2AFE14-ORURKOSDAD3E13-RKLGS4-FSN2K12-2FDFD3-3AHFQ12-2(FD)A2BC6B13-DHA2BP5CBC13-2HAB2PCB3CP15-A2BPBCB3C16-8BC18-3B2CB2C19-XAfX5-2UX15-UY7-AbY14-OJG7-IN14-JGE7-QM13-2JIG7-EGAb12-JNJ8-HEQ11-2LR10-2F11-KOK10-G2F10-KOK10-EFH9-2GJ11-E2D9-E2FE10-3A9-F2DF9-2BA10-2DHF9-3B10-2DHE9-ABC10-3DF9-B2C11-2DF8-3C12-DFEI7-3C13-DSI6-B2C15-SI6-2C17-JL4-AB15-LI2-K4-A14-KR2ZXUAc4-HF12-I3ENRU5-FSJQ10-RAbMI9-EFHAB8-X2R12-FHA8-GEF12-N2Y9-3F11-2BH9-F2D10-3C10-2D2H8-C3P11-DHAB6-2C2P12-DHA2B4-3C2P12-2H4BP5C2P15-AeZ8-3M12-AeZX9-YAh12-ZX10-YR12-RL10-M2Y10-LNJ11-VN10-LJ12-2G9-KON12-FE9-2K13-F2Q8-LO14-2E7-3G14-HD7-3E13-2AD7-E2F13-3B6-GEFD13-C2B6-2E2D13-3B6-EF2D12-2C2B6-E3D12-2C2B7-4D10-3CB8-4DF8-4CB8-2D2HFG7-3CP9-IEF2DJ6-2BCPC8-AeRMIEGKAc4-2AHABA7-KZURZAfOR5-SWEAoRO7-UMG11-G4IQ6-2U14-E4H5-2U16-CAF5-G2E15-2YAb6-2F15-AF7-2F14-2CB7-2FD13-2P8-2FD12-3P9-2F11-3P10-FDH10-3P13-2Ag10-2M11-AeAgAe11-2V10-AeZ12-NVM8-2ZX13-AbM8-RU14-VAb8-2L14-NM7-KO15-QG7-LK16-M7-IJ16-NQ5-IG17-QAi5-IG17-2H2(4-I2G17-2A)4-IGE17-2A4-IGF17-2A4-GEF16-2BA4-GED16-3B4-EF2D14-2CB6-EFD13-2PCB6-OJE12-CP2C6-ZAfK12-DB3A5-XUZ15-UQKI4-AfX17-KGF4-AfX18-2HAi3-2K19-VN4-G18-LFH4-GE17-AB5-2E16-3C5-2E16-2C6-2EF15-2C7-EF14-P2C7-2E14-2C11-2Aa12-2V10-AaAg13-VQ8-AaAg14-QM8-2Ae15-2V6-2X16-VQ6-RK16-VI5-2K17-QV5-KO18-V5-LJ18-Ad4-NI19-Ad4-2I19-AiQ3-NI19-AdQ2-2N20-HAd2-2N20-AH2(2-NJ20-2A)2-IG20-2A2-2GE18-B2A2-2GE18-2B3-2LO17-CBA3-RX18-AB4-X19-ODA3-Z20-DAd3-Z21-Q3-R21-Q3-M21-H3-IG19-BA3-MG19-2B3-MG18-CB4-IG18-2B5-GE16-C2B5-2G16-CB10-2Aa12-MVAb8-2Aa14-2M7-2Aa16-2M6-AeAg17-Ah5-AeZ18-Ah5-AfX18-2Ah3-UR19-2V3-RK19-2Q3-KO19-AdAi3-L21-Ai2-LN21-Q2-2L21-V2-L22-MN2L22-GVOL22-AiGOL22-AdAiLN22-D-LI21-AD-NIG20-HD-NMN19-BAH-2O20-2B2-2X21-A2-Z22-HD-Af22-EL-RK22-G-LN21-AdAi-NM21-H2-NM21-A2-2N20-2A3-N20-BA3-MI19-A4-MI18-AH8-2Aa14-YX7-2Aa16-UAe6-Aa18-U5-2Ag18-YAa4-Ag20-An3-ZAe20-R3-ZAf20-U3-U21-Ah2-UR21-VAh-KO21-2M-O23-AhOL23-VO24-MO24-N2(K24-M)O24-GO23-AdFL23-AdEL23-D-O22-AD-X22-AD-Af23-G-X23-O-U23-U-K23-L-O23-M-Ab22-DM-O2(22-Ad2-Y)Ab20-HQ3-M20-QY2-
