model
size = 12 28 24, scale = 0.05, origin = -y
material deform = 1, fade = true, lighting = smooth, roughness = 0.3, metalness = 0.6
  colors = A:#FFF B:#9300FF C:#FF00E9 D:#FFFEFE E:#000 F:#FFF300 G:#F00
voxels
71-8(A11-)A227-3(8(A11-)A239-)4(A11-)E4(11-A)239-3(A11-)3(E11-)2(A11-)A239-2(A11-)5(E11-)A11-A239-A2(11-E)2(11-A11-E)11-E11-A239-A2(11-E2(11-A))11-E11-A182-2(3D9-)3D10-D11-D7-4(A11-)E4(11-A)181-3(B3-B7-)5B7-5B5-A-5B5-3(A2-3B6-)E3(2-3B6-A)3-B7-A3-B176-5(D5-)D6-B3-B7-4(B3-B5-A-)B3-B5-E3(-B3-B5-A)2-3C6-A2-5(3C9-)3C10-3(C11-)C68-6(D5-)DB3-BD5-DB3-BD4-4(A-B3-B5-)E3(-B3-B5-A)-BC-CB5-A-BC-CB5-2(G2-C-C6-)7(F2-C-C6-)F3-C7-F3-C6-F4-2(F5-)F4-F6-5F4-5(D5-)D6-B3-B7-4(B3-B5-A-)B3-B5-E3(-B3-B5-A)2-3C6-A2-5(3C9-)3C10-3(C11-)C69-3(B3-B7-)5B7-5B5-A-5B5-3(A2-3B6-)E3(2-3B6-A)3-B7-A3-B178-2(3D9-)3D10-D11-D7-2(4(A11-)E4(11-A)239-)A2(11-E2(11-A))11-E11-A239-A2(11-E)2(11-A11-E)11-E11-A239-2(A11-)5(E11-)A11-A239-3(A11-)3(E11-)2(A11-)A239-4(A11-)E4(11-A)2(239-8(A11-)A)180-
