model
size = 14 30 9, scale = 0.05, origin = -y
material deform = 1, fade = true, lighting = smooth, roughness = 0.3, metalness = 0.6
  colors = A:#FFF B:#AC3232 C:#000 D:#847E87
voxels
-C10-C2-12B-B12CBC14(12B2C)12BCD12C3(2D12-)DC5(12-2C)12-3C10-2C-12C15-14BC12ACB14(12A2B)AC9A2B-B10CB3-10B156-14BC12ACB14(12A2B)11A2B-BC8ACB3-10B156-14BC12ACB14(12A2B)11A2B-B9ACB3-10B156-14BC12AC14AC195A-12A3-10A2(156-14BC12ACB14(12A2B)11A2B-B9A2B3-10B)143-C10-C-BA10BABC12ACB13(12A2B)11A4B10A2B2-10B171-12B-B12C2(BC)7(8BCB2CBC)3B2A3BCB2CBC8BC2(B2CB10C)B3(2C12B)C-C10BC3-10C156-
