model
size = 14 30 9, scale = 0.05, origin = -y
material deform = 1, fade = true, lighting = smooth, roughness = 0.3, metalness = 0.6
  colors = A:#FFF B:#000 C:#847E87 D:#595652 E:#AC3232
voxels
-B10-B2-12A-A12BAB14(12A2B)12ABD12B3(2D12-)DB5(12-2B)12-3B10-2B-12B15-14AB12AB198AB9AEA-A10BA3-10A156-14AB12AB210A-AB8ABA3-10A156-14AB12AB210A-10ABA3-10A156-14AB12ABC12ACB13(12A2C)12AC-C10AC3-10C2(156-14AB12AB208AEA-10AEA3-10A)143-B10-B-14AB12AB194AE15A2-10A171-12A-A12B2(AB)7(8ABA2BAB)3A2D3ABA2BAB8AB2(A2BA10B)A3(2B12A)B-B10AB3-10B156-
