model
size = 4 17 35, scale = 0.05, origin = -y
material deform = 1, fade = true, lighting = smooth, roughness = 0.3, metalness = 0.6
  colors = A:#000
voxels
17-2A2-26A34-4A7(2-2A)2-5A-2A21-5A5(2-2A)-3A4(2-2A)-A2-2A14-4A3(2-2A)2(-2A)2-2A2-A3-2A-3A-A2(2-2A)2-4A11-A2(-2A)2(2-2A)-2A-A22-3A-A2(2-2A)2-4A6-2A-A2(2-2A)2-A-2A29-3A-A2-2A2-4A6-4A2-2A2-A-3A32-3A-A2-2A2-5A5-4A2-2A2-A-3A33-A2-A-3A2-5A5-4A2-2A2-A-3A33-2A-A2-2A2-5A5-4A2-2A2-5A32-3A-A2-2A2-4A6-2A-A2(2-2A)2-A-3A25-2A-A2(2-2A)2-4A9-5A2(2-2A)2-A-3A17-2A-A3(2-2A)2-A-2A10-2A-A3(2-2A)2-5A-3A-2A-5A3(2-2A)2-4A18-2A-A9(2-2A)2-5A25-2A-5A5(2-2A)2-5A-2A38-2A2-2A-11A2-2A251-A2-2A2-4(3A-)2A38-3A-A-6(2A2-)5A-2A26-4A9(2-2A)2-A-2A18-4A3(2-2A)2-A2(-3A)-8A3(2-2A)2-A-2A10-2A-A3(2-2A)2-A-2A18-2A-A2(2-2A)2-5A9-4A2(2-2A)2-A-2A26-2A-A2(2-2A)2-A-2A6-4A2-2A2-A-3A32-5A2-2A2-A-2A5-5A2-2A2-A-2A34-2A-A2-2A2-5A4-5A2-2A2-A-2A34-2A-A2-2A2-5A5-4A2-2A2-A-3A32-5A2-2A2-5A5-4A2-2A2-A-3A29-2A-A2(2-2A)2-A-2A6-2A-A2(2-2A)2-A-3A21-2A-A2(2-2A)2-3A-A2-A10-4A2(2-2A)2-5A-3A-2(2A2-)4A3(2-2A)2-A-2A15-A2-A-10(2A2-)5A22-A2-4A7(2-2A)2-A-3A33-3A-19A-2A2-2A17-
