model
size = 15 32 13, scale = 0.05, origin = -y
material deform = 1, fade = true, lighting = smooth, roughness = 0.3, metalness = 0.6
  colors = A:#222 B:#444 C:#555
voxels
22-A27-5A7-A2-5A2-A8-3A28-A402-5A9-7A7-9A7-7A11-A416-7A7-2(9A6-)9A8-5A401-3A9-9A5-11A4-11A5-9A7-7A10-3A386-5A8-9A5-2(11A4-)11A6-7A9-A3BA12-2(B14-)B44-3(B14-)2(B29-4(B14-))B59-A8-A3-5A2-A4-10A5-11A2-15A2-11A3-A2-8A8-2(AB)A2-A24-C13-3(CBC12-C-C12-CBC12-3C27-3C12-)CB2(C12-C-)C12-3C26-5A8-9A5-2(11A4-)11A6-7A9-A3BA12-2(B14-)B44-3(B14-)2(B29-4(B14-))B73-3A9-9A5-11A4-11A5-9A7-7A10-3A400-7A7-2(9A6-)9A8-5A415-5A9-7A7-9A7-7A11-A404-A27-5A7-A2-5A2-A8-3A28-A434-A479-A412-
