model
size = 3 3 31, scale = 0.05, origin = -y
material deform = 1, fade = true, lighting = smooth, roughness = 0.3, metalness = 0.6
  colors = A:#222 B:#630 C:#933 D:#700 E:#555 F:#500 G:#633 H:#400 I:#800
voxels
9A2(DA)CAHADAHAFCIAD2(AF)ACAD2(AF)AICDAH2(AD)AC2(AD)2(AF)C2(DA)IADACAHAFADAFC2(DA)FAHACADAH2(AF)C2(DA)FADAC2(AF)4AC4A2G2B2(C8B)C3BG4B2(C8B)C6BGBC8BC5BG2BA4B9A4BA4B4AC4A4BC2BGB4AC4A9E3-2(E-E6-)3E3-
