model
size = 3 3 31, scale = 0.05, origin = -y
material deform = 1, fade = true, lighting = smooth, roughness = 0.3, metalness = 0.6
  colors = A:#222 B:#630 C:#050 D:#933 E:#555 F:#040 G:#633 H:#080
voxels
9A2(CA)D2(AC)AFACD2FC2(AF)AD2(AHAC)D2(CA)FACAD2(ACAF)D3(CA)FADACAHAFACD2(CA)HACAD4(AF)D4(CA)DACAF4AD4A2G2B2(D8B)D3BG4B2(D8B)D6BGBD8BD5BG2BA4B9A4BA4B4AD4A4BD2BGB4AD4A9E3-2(E-E6-)3E3-
