model
size = 15 25 29, scale = 0.05, origin = -y
material deform = 1, fade = true, lighting = smooth, roughness = 0.3, metalness = 0.6
  colors = A:#DDD B:#111 C:#C0F D:#EEE E:#E00 F:#00F G:#FF0
voxels
363-9B365-B9-B362-2B11-2B8(360-B13-B)330-5(B13-2B13-B315-)B13-2B13-B236-2B13-2B77-B13-B197-2(11A4-)11A28-2A13-2A62-B13-B212-2(11A4-)11A6-6A16-2A13-2A47-B13-B227-2(11A4-)11A6-6A9-6A-2A6-6A-2A32-B13-B242-2(11A4-)11A6-6A8-7A-2A5-10A17-B13-B257-5(11A4-)11A2-B13-B272-4(11A4-)11A2-B-11A-B287-2(11A4-)C9DC4-CE2C3D4C4-4C3D2CBC2-2B11C2B287-2(11A4-)4CFGE4C8-2(3B12-)3B293-2(11A4-)4CFGE4C8-3D12-D-D12-3D293-2(11A4-)4CFGE4C334-11A4-11A347-
