model
size = 15 25 29, scale = 0.05, origin = -y
material deform = 1, fade = true, lighting = smooth, roughness = 0.3, metalness = 0.6
  colors = A:#111 B:#EEE C:#E00 D:#00F E:#FF0
voxels
363-9A365-A9-A362-2A11-2A8(360-A13-A)330-5(A13-2A13-A315-)A13-2A13-A236-2A13-2A77-A13-A197-2(11A4-)11A28-2A13-2A62-A13-A212-2(11A4-)6AB4A6-6A16-2A13-2A47-A13-A227-2(11A4-)6AB4A6-6A9-6A-2A6-6A-2A32-A13-A242-2(11A4-)11A6-A4BA8-2A4BA-2A5-10A17-A13-A257-5(11A4-)11A2-A13-A272-4(11A4-)11A2-A-11A-A287-2(11A4-)11B4-BC9B4-9BAB2-2A11B2A287-2(11A4-)4BDEC4B8-2(3A12-)3A293-2(11A4-)4BDEC4B8-3B12-B-B12-3B293-2(11A4-)4BDEC4B334-11A4-11A347-
