model
size = 17 22 11, scale = 0.05, origin = -y
material deform = 1, fade = true, lighting = smooth, roughness = 0.3, metalness = 0.6
  colors = A:#F2E3CF B:#FCEACD C:#E7C8BC D:#EEE E:#4D2A0A F:#FFF G:#FE5C7D
voxels
119-10(12A5-)12A78-2A2-4A6-2(5A2B6A4-)3(13A4-)13A2-15A2-3(12A5-)10A-A5-9A-2A5(5-12A)78-2A2-4A6-5A2B6A4-3ABA4B4A4-A2B10A3(4-13A)2-15A2-4(12A5-)9A-2A5(5-12A)92-2(13B4-)B11AB3(4-B12A)2-15A2-4(12A5-)9A-2A5(5-12A)5-3(2A15-)2A34-2(13B4-)B11AB3(4-B12A)2-15A2(2D12A3-)2D2(12A5-)9A-2A5(5-12A)5-2(AC15-)2A15-2A34-2(13B4-)B11AB3(4-B12A)2-15A2(2D12A3-)2D2(12A5-)2(9A-2A5-)2(A10-A5-)12A5-12A4(15-2A)24-2(13B4-)B11AB3(4-B12A)2-15A2-4(12A5-)2(9A-2A5-)2(A10-A5-)12A5-12A2(15-CA)2(15-2A)7-2A7-4A2(4-2A9B2A)4(4-13A)2-15A2-4(12A5-)A9-2A3(5-A10-A)2(5-12A)75-2A7-2(4A4-2A7B)4A4(4-13A)2-15A2-4(12A5-)A9-2A3(5-A10-A)2(5-12A)192-2(12A5-)2(10A-A5-)12A5-A9-2A3(5-A10-A)2(5-12A)192-2(A2C6A2CA5-)2(A2EA4FA2EA5-)5A2G5A6(5-12A)73-
