model
size = 31, scale = 0.05, origin = -y
material deform = 1, fade = true, lighting = smooth, roughness = 0.3, metalness = 0.6
  colors = A:#42602D B:#3C2F41 C:#C99833 D:#533D5B E:#E8B647 F:#AF5F3C G:#FB966E H:#2EA9DF I:#0B1013 J:#724938 K:#B47157 L:#51A8DD M:#0F2540 N:#00AA90 O:#F7C242 P:#DB4D6D Q:#0F4C3A R:#D0104C S:#FEDFE1 T:#DDA52D U:#8F77B5 V:#8A6BBE W:#E87A90 X:#0D5661 Y:#336774 Z:#9F353A Aa:#9E7A7A Ab:#D05A6E Ac:#B5495B Ad:#F9BF45 Ae:#69B0AC Af:#20604F Ag:#77428D Ah:#B28FCE Ai:#BA9132 Aj:#0C4842 Ak:#81C7D4 Al:#ED784A Am:#7B90D2 An:#F05E1C Ao:#08192D Ap:#005CAF Aq:#0B346E Ar:#00896C As:#90B44B At:#096148 Au:#986DB2 Av:#6A4C9C Aw:#DCB879 Ax:#0089A7 Ay:#D19826 Az:#33A6B8 Ba:#4F726C Bb:#111
voxels
12-7Ar365-Ah2-Au2-Ag25-2BbAu2Bb27-3Bb26-3DBb3B26-UBbV27-U-Av-V25-U2-Av2-V365-7Aq52-13Ar235-Ah5-Au5-Ag19-Ah4-Au4-Ag21-Ah3-Au3-Ag23-Ah2-Au2-Ag25-Ah-Au-Ag27-AhAAg23-5DABbA5B23-UAV27-U-Av-V25-U2-Av2-V23-U3-Av3-V21-U4-Av4-V19-U5-Av5-V235-13Aq109-17Ar138-Ah7-Au7-Ag15-Ah6-Au6-Ag17-Ah5-Au5-Ag19-Ah4-Au4-Ag21-Ah3-Au3-Ag23-Ah2-Au2-Ag25-Ah-Au-Ag27-AhAAg21-7D3A7B21-UAV27-U-Av-V25-U2-Av2-V23-U3-Av3-V21-U4-Av4-V19-U5-Av5-V17-U6-Av6-V15-U7-Av7-V138-17Aq168-19Ar74-Ah8-Au8-Ag13-Ah7-Au7-Ag15-Ah6-Au6-Ag17-Ah5-Au5-Ag19-Ah4-Au4-Ag21-Ah3-Au3-Ag23-Ah2-Au2-Ag25-Ah-Au-Ag27-AhAAg20-8D3A8B20-UAV27-U-Av-V25-U2-Av2-V23-U3-Av3-V21-U4-Av4-V19-U5-Av5-V17-U6-Av6-V15-U7-Av7-V13-U8-Av8-V74-19Aq228-21Ar10-Ah9-Au9-Ag11-Ah8-Au8-Ag13-Ah7-Au7-Ag15-Ah6-Au6-Ag17-Ah5-Au5-Ag19-Ah4-Au4-Ag21-Ah3-Au3-Ag23-Ah2-Au2-Ag25-Ah-Au-Ag27-AhAAg19-9D3A9B19-UAV27-U-Av-V25-U2-Av2-V23-U3-Av3-V21-U4-Av4-V19-U5-Av5-V17-U6-Av6-V15-U7-Av7-V13-U8-Av8-V11-U9-Av9-V10-21Aq257-As10-Ac10-An8-Y10KA10FQ10-Ah8-Au8-Ag13-Ah7-Au7-Ag15-Ah6-Au6-Ag17-Ah5-Au5-Ag19-Ah4-Au4-Ag21-Ah3-Au3-Ag23-Ah2-Au2-Ag25-Ah-Au-Ag27-AhAAg18-10D3A10B18-UAV27-U-Av-V25-U2-Av2-V23-U3-Av3-V21-U4-Av4-V19-U5-Av5-V17-U6-Av6-V15-U7-Av7-V13-U8-Av8-V10-Ak10MA10IAf8-Am10-Z10-Ap224-As11-Ac11-An7-As10-Ac10-An9-K9-Ac9-F8-3Y9KA9F3Q10-Ah7-Au7-Ag15-Ah6-Au6-Ag17-Ah5-Au5-Ag19-Ah4-Au4-Ag21-Ah3-Au3-Ag23-Ah2-Au2-Ag25-Ah-Au-Ag27-AhAAg17-11D3A11B17-UAV27-U-Av-V25-U2-Av2-V23-U3-Av3-V21-U4-Av4-V19-U5-Av5-V17-U6-Av6-V15-U7-Av7-V10-3Ak9MA9I3Af8-M9-Z9-I9-Am10-Z10-Ap7-Am11-Z11-Ap160-As12-Ac12-An5-As11-Ac11-An7-As10-Ac10-An9-K9-Ac9-F11-K8-Ac8-F8-5Y8KA8F5Q10-Ah6-Au6-Ag17-Ah5-Au5-Ag19-Ah4-Au4-Ag21-Ah3-Au3-Ag23-Ah2-Au2-Ag25-Ah-Au-Ag27-AhAAg16-12D3A12B16-UAV27-U-Av-V25-U2-Av2-V23-U3-Av3-V21-U4-Av4-V19-U5-Av5-V17-U6-Av6-V10-5Ak8MA8I5Af8-M8-Z8-I11-M9-Z9-I9-Am10-Z10-Ap7-Am11-Z11-Ap5-Am12-Z12-Ap128-As12-Ac12-An5-As11-Ac11-An7-As10-Ac10-An9-K9-Ac9-F11-K8-Ac8-F13-K7-Ac7-F9-6Y7KA7F6Q11-Ah5-Au5-Ag19-Ah4-Au4-Ag21-Ah3-Au3-Ag23-Ah2-Au2-Ag25-Ah-Au-Ag27-AhAAg16-12D3A12B16-UAV27-U-Av-V25-U2-Av2-V23-U3-Av3-V21-U4-Av4-V19-U5-Av5-V11-6Ak7MA7I6Af9-M7-Z7-I13-M8-Z8-I11-M9-Z9-I9-Am10-Z10-Ap7-Am11-Z11-Ap5-Am12-Z12-Ap96-As13-Ac13-An3-As12-Ac12-An5-As11-Ac11-An7-As10-Ac10-An9-K9-Ac9-F11-K8-Ac8-F13-K7-Ac7-F15-K6-Ac6-F9-8Y6KA6F8Q11-Ah4-Au4-Ag21-Ah3-Au3-Ag23-Ah2-Au2-Ag25-Ah-Au-Ag27-AhAAg15-13D3A13B15-UAV27-U-Av-V25-U2-Av2-V23-U3-Av3-V21-U4-Av4-V11-8Ak6MA6I8Af9-M6-Z6-I15-M7-Z7-I13-M8-Z8-I11-M9-Z9-I9-Am10-Z10-Ap7-Am11-Z11-Ap5-Am12-Z12-Ap3-Am13-Z13-Ap64-As13-Ac13-An3-As12-Ac12-An5-As11-Ac11-An7-As10-Ac10-An9-K9-Ac9-F11-K8-Ac8-F13-K7-Ac7-F15-K6-Ac6-F17-K5-Ac5-F10-9Y5KA5F9Q12-Ah3-Au3-Ag23-Ah2-Au2-Ag25-Ah-Au-Ag27-AhAAg15-13D3A13B15-UAV27-U-Av-V25-U2-Av2-V23-U3-Av3-V12-9Ak5MA5I9Af10-M5-Z5-I17-M6-Z6-I15-M7-Z7-I13-M8-Z8-I11-M9-Z9-I9-Am10-Z10-Ap7-Am11-Z11-Ap5-Am12-Z12-Ap3-Am13-Z13-Ap64-As13-Ac13-An3-As12-Ac12-An5-As11-Ac11-An7-As10-Ac10-An9-K9-Ac9-F11-K8-Ac8-F13-K7-Ac7-F15-K6-Ac6-F17-K5-Ac5-F19-K4-Ac4-F11-10Y4KA4F10Q13-Ah2-Au2-Ag25-Ah-Au-Ag27-AhAAg15-13D3A13B15-UAV27-U-Av-V25-U2-Av2-V13-10Ak4MA4I10Af11-M4-Z4-I19-M5-Z5-I17-M6-Z6-I15-M7-Z7-I13-M8-Z8-I11-M9-Z9-I9-Am10-Z10-Ap7-Am11-Z11-Ap5-Am12-Z12-Ap3-Am13-Z13-Ap32-As14-Ac14-An-As13-Ac13-An3-As12-Ac12-An5-As11-Ac11-An7-As10-Ac10-An9-K9-Ac9-F11-K8-Ac8-F13-K7-Ac7-F15-K6-Ac6-F17-K5-Ac5-F19-K4-Ac4-F21-K3-Ac3-F11-12Y3KA3F12Q13-Ah-Au-Ag27-AhAAg14-14D3A14B14-UAV27-U-Av-V13-12Ak3MA3I12Af11-M3-Z3-I21-M4-Z4-I19-M5-Z5-I17-M6-Z6-I15-M7-Z7-I13-M8-Z8-I11-M9-Z9-I9-Am10-Z10-Ap7-Am11-Z11-Ap5-Am12-Z12-Ap3-Am13-Z13-Ap-Am14-Z14-ApAs12-2OAc2O12-An-As13-Ac13-An3-As12-Ac12-An5-As11-Ac11-An7-As10-Ac10-An9-K9-Ac9-F11-K8-Ac8-F13-K7-Ac7-F15-K6-Ac6-F17-K5-Ac5-F19-K4-Ac4-F21-K3-Ac3-F23-K2-Ac2-F12-13Y2KA2F13Q14-AhAAg14-14D3A14B14-UAV14-Bb12Ak2MA2I12AfBb12-M2-Z2-I23-M3-Z3-I21-M4-Z4-I19-M5-Z5-I17-M6-Z6-I15-M7-Z7-I13-M8-Z8-I11-M9-Z9-I9-Am10-Z10-Ap7-Am11-Z11-Ap5-Am12-Z12-Ap3-Am13-Z13-Ap-Am12-2NZ2N12-ApAs13-3O13-An-As13-Ac13-An3-As12-Ac12-An5-As11-Ac11-An7-As10-Ac10-An9-K9-Ac9-F11-K8-Ac8-F13-K7-Ac7-F15-K6-Ac6-F17-K5-Ac5-F19-K4-Ac4-F21-K3-Ac3-F23-K2-Ac2-F25-K-Ac-F13-14YKAF14QD16A2B11ABBb13AkMAI13Af2Bb12-M-Z-I12-Bb12-M2-Z2-I23-M3-Z3-I21-M4-Z4-I19-M5-Z5-I17-M6-Z6-I15-M7-Z7-I13-M8-Z8-I11-M9-Z9-I9-Am10-Z10-Ap7-Am11-Z11-Ap5-Am12-Z12-Ap3-Am13-Z13-Ap-Am13-3N13-ApAs11-3WO3P11-An-As7-6WBb6P7-An3-As4-8WA8P4-An5-As2-9WA9P2-An7-As10WA10PAn8-AxA9WA9PABa7-3AxA8WA8PA3Ba5-5AxA7WA7PA5Ba4-6AxA6WA6PA6Ba3-8AxA5WA5PA8Ba2-9AxA4WA4PA9Ba2-10AxA3WA3PA10Ba-12AxA2WA2PA12Ba13AxAWAPA-12BaBb15AF2-11A3Bb13A-A2B10A3Bb29ABb13AzASARA13At12AzA2SA2RA12At-10AzA3SA3RA10At2-9AzA4SA4RA9At2-8AzA5SA5RA8At3-6AzA6SA6RA6At4-5AzA7SA7RA5At5-3AzA8SA8RA3At7-AzA9SA9RAAt8-Am10SA10RAp7-Am2-9SA9R2-Ap5-Am4-8SA8R4-Ap3-Am7-6SBb6R7-Ap-Am11-3SN3R11-ApAs14-O14-An-As13-Ab13-An3-As12-Ab12-An5-As11-Ab11-An7-As10-Ab10-An9-J9-Ab9-G11-J8-Ab8-G13-J7-Ab7-G15-J6-Ab6-G17-J5-Ab5-G19-J4-Ab4-G21-J3-Ab3-G23-J2-Ab2-G25-J-Ab-G13-14XJAG14NE29ACBb13AjLAH13Ae2Bb12-L-Aa-H12-Bb12-L2-Aa2-H23-L3-Aa3-H21-L4-Aa4-H19-L5-Aa5-H17-L6-Aa6-H15-L7-Aa7-H13-L8-Aa8-H11-L9-Aa9-H9-Am10-Aa10-Ap7-Am11-Aa11-Ap5-Am12-Aa12-Ap3-Am13-Aa13-Ap-Am14-N14-ApAs14-Ab14-An-As13-Ab13-An3-As12-Ab12-An5-As11-Ab11-An7-As10-Ab10-An9-J9-Ab9-G11-J8-Ab8-G13-J7-Ab7-G15-J6-Ab6-G17-J5-Ab5-G19-J4-Ab4-G21-J3-Ab3-G23-J2-Ab2-G12-13X2JA2G13N14-AiAAd14-14E3A14C14-OAT14-Bb12Aj2LA2H12AeBb12-L2-Aa2-H23-L3-Aa3-H21-L4-Aa4-H19-L5-Aa5-H17-L6-Aa6-H15-L7-Aa7-H13-L8-Aa8-H11-L9-Aa9-H9-Am10-Aa10-Ap7-Am11-Aa11-Ap5-Am12-Aa12-Ap3-Am13-Aa13-Ap-Am14-Aa14-ApAs14-Ab14-An-As13-Ab13-An3-As12-Ab12-An5-As11-Ab11-An7-As10-Ab10-An9-J9-Ab9-G11-J8-Ab8-G13-J7-Ab7-G15-J6-Ab6-G17-J5-Ab5-G19-J4-Ab4-G21-J3-Ab3-G11-12X3JA3G12N13-Ai-Aw-Ad27-AiAAd14-14E3A14C14-OAT27-O-Ay-T13-12Aj3LA3H12Ae11-L3-Aa3-H21-L4-Aa4-H19-L5-Aa5-H17-L6-Aa6-H15-L7-Aa7-H13-L8-Aa8-H11-L9-Aa9-H9-Am10-Aa10-Ap7-Am11-Aa11-Ap5-Am12-Aa12-Ap3-Am13-Aa13-Ap-Am14-Aa14-Ap32-As13-Ab13-An3-As12-Ab12-An5-As11-Ab11-An7-As10-Ab10-An9-J9-Ab9-G11-J8-Ab8-G13-J7-Ab7-G15-J6-Ab6-G17-J5-Ab5-G19-J4-Ab4-G11-10X4JA4G10N13-Ai2-Aw2-Ad25-Ai-Aw-Ad27-AiAAd15-13E3A13C15-OAT27-O-Ay-T25-O2-Ay2-T13-10Aj4LA4H10Ae11-L4-Aa4-H19-L5-Aa5-H17-L6-Aa6-H15-L7-Aa7-H13-L8-Aa8-H11-L9-Aa9-H9-Am10-Aa10-Ap7-Am11-Aa11-Ap5-Am12-Aa12-Ap3-Am13-Aa13-Ap64-As13-Ab13-An3-As12-Ab12-An5-As11-Ab11-An7-As10-Ab10-An9-J9-Ab9-G11-J8-Ab8-G13-J7-Ab7-G15-J6-Ab6-G17-J5-Ab5-G10-9X5JA5G9N12-Ai3-Aw3-Ad23-Ai2-Aw2-Ad25-Ai-Aw-Ad27-AiAAd15-13E3A13C15-OAT27-O-Ay-T25-O2-Ay2-T23-O3-Ay3-T12-9Aj5LA5H9Ae10-L5-Aa5-H17-L6-Aa6-H15-L7-Aa7-H13-L8-Aa8-H11-L9-Aa9-H9-Am10-Aa10-Ap7-Am11-Aa11-Ap5-Am12-Aa12-Ap3-Am13-Aa13-Ap64-As13-Ab13-An3-As12-Ab12-An5-As11-Ab11-An7-As10-Ab10-An9-J9-Ab9-G11-J8-Ab8-G13-J7-Ab7-G15-J6-Ab6-G9-8X6JA6G8N11-Ai4-Aw4-Ad21-Ai3-Aw3-Ad23-Ai2-Aw2-Ad25-Ai-Aw-Ad27-AiAAd15-13E3A13C15-OAT27-O-Ay-T25-O2-Ay2-T23-O3-Ay3-T21-O4-Ay4-T11-8Aj6LA6H8Ae9-L6-Aa6-H15-L7-Aa7-H13-L8-Aa8-H11-L9-Aa9-H9-Am10-Aa10-Ap7-Am11-Aa11-Ap5-Am12-Aa12-Ap3-Am13-Aa13-Ap96-As12-Ab12-An5-As11-Ab11-An7-As10-Ab10-An9-J9-Ab9-G11-J8-Ab8-G13-J7-Ab7-G9-6X7JA7G6N11-Ai5-Aw5-Ad19-Ai4-Aw4-Ad21-Ai3-Aw3-Ad23-Ai2-Aw2-Ad25-Ai-Aw-Ad27-AiAAd16-12E3A12C16-OAT27-O-Ay-T25-O2-Ay2-T23-O3-Ay3-T21-O4-Ay4-T19-O5-Ay5-T11-6Aj7LA7H6Ae9-L7-Aa7-H13-L8-Aa8-H11-L9-Aa9-H9-Am10-Aa10-Ap7-Am11-Aa11-Ap5-Am12-Aa12-Ap128-As12-Ab12-An5-As11-Ab11-An7-As10-Ab10-An9-J9-Ab9-G11-J8-Ab8-G8-5X8JA8G5N10-Ai6-Aw6-Ad17-Ai5-Aw5-Ad19-Ai4-Aw4-Ad21-Ai3-Aw3-Ad23-Ai2-Aw2-Ad25-Ai-Aw-Ad27-AiAAd16-12E3A12C16-OAT27-O-Ay-T25-O2-Ay2-T23-O3-Ay3-T21-O4-Ay4-T19-O5-Ay5-T17-O6-Ay6-T10-5Aj8LA8H5Ae8-L8-Aa8-H11-L9-Aa9-H9-Am10-Aa10-Ap7-Am11-Aa11-Ap5-Am12-Aa12-Ap160-As11-Ab11-An7-As10-Ab10-An9-J9-Ab9-G8-3X9JA9G3N10-Ai7-Aw7-Ad15-Ai6-Aw6-Ad17-Ai5-Aw5-Ad19-Ai4-Aw4-Ad21-Ai3-Aw3-Ad23-Ai2-Aw2-Ad25-Ai-Aw-Ad27-AiAAd17-11E3A11C17-OAT27-O-Ay-T25-O2-Ay2-T23-O3-Ay3-T21-O4-Ay4-T19-O5-Ay5-T17-O6-Ay6-T15-O7-Ay7-T10-3Aj9LA9H3Ae8-L9-Aa9-H9-Am10-Aa10-Ap7-Am11-Aa11-Ap224-As10-Ab10-An8-X10JA10GN10-Ai8-Aw8-Ad13-Ai7-Aw7-Ad15-Ai6-Aw6-Ad17-Ai5-Aw5-Ad19-Ai4-Aw4-Ad21-Ai3-Aw3-Ad23-Ai2-Aw2-Ad25-Ai-Aw-Ad27-AiAAd18-10E3A10C18-OAT27-O-Ay-T25-O2-Ay2-T23-O3-Ay3-T21-O4-Ay4-T19-O5-Ay5-T17-O6-Ay6-T15-O7-Ay7-T13-O8-Ay8-T10-Aj10LA10HAe8-Am10-Aa10-Ap257-21Al10-Ai9-Aw9-Ad11-Ai8-Aw8-Ad13-Ai7-Aw7-Ad15-Ai6-Aw6-Ad17-Ai5-Aw5-Ad19-Ai4-Aw4-Ad21-Ai3-Aw3-Ad23-Ai2-Aw2-Ad25-Ai-Aw-Ad27-AiAAd19-9E3A9C19-OAT27-O-Ay-T25-O2-Ay2-T23-O3-Ay3-T21-O4-Ay4-T19-O5-Ay5-T17-O6-Ay6-T15-O7-Ay7-T13-O8-Ay8-T11-O9-Ay9-T10-21Ao228-19Al74-Ai8-Aw8-Ad13-Ai7-Aw7-Ad15-Ai6-Aw6-Ad17-Ai5-Aw5-Ad19-Ai4-Aw4-Ad21-Ai3-Aw3-Ad23-Ai2-Aw2-Ad25-Ai-Aw-Ad27-AiAAd20-8E3A8C20-OAT27-O-Ay-T25-O2-Ay2-T23-O3-Ay3-T21-O4-Ay4-T19-O5-Ay5-T17-O6-Ay6-T15-O7-Ay7-T13-O8-Ay8-T74-19Ao168-17Al138-Ai7-Aw7-Ad15-Ai6-Aw6-Ad17-Ai5-Aw5-Ad19-Ai4-Aw4-Ad21-Ai3-Aw3-Ad23-Ai2-Aw2-Ad25-Ai-Aw-Ad27-AiAAd21-7E3A7C21-OAT27-O-Ay-T25-O2-Ay2-T23-O3-Ay3-T21-O4-Ay4-T19-O5-Ay5-T17-O6-Ay6-T15-O7-Ay7-T138-17Ao109-13Al235-Ai5-Aw5-Ad19-Ai4-Aw4-Ad21-Ai3-Aw3-Ad23-Ai2-Aw2-Ad25-Ai-Aw-Ad27-AiAAd23-5EABbA5C23-OAT27-O-Ay-T25-O2-Ay2-T23-O3-Ay3-T21-O4-Ay4-T19-O5-Ay5-T235-13Ao52-7Al365-Ai2-Aw2-Ad25-2BbAw2Bb27-3Bb26-3EBb3C26-OBbT27-O-Ay-T25-O2-Ay2-T365-7Ao12-
