model
size = 20 22 22, scale = 0.05, origin = -y
material deform = 1, fade = true, lighting = smooth, roughness = 0.3, metalness = 0.6
  colors = A:#DDD B:#900 C:#EEE D:#BBB E:#400 F:#111 G:#300 H:#500 I:#AAA J:#444 K:#800 L:#B00 M:#FF6 N:#222 O:#600
voxels
224-2E8-2E5-18B-3BGHGE3GH2E2GHG5B3GE2GH2(EG)H2G2E5BGHO7G2EHG3B-K17B5-2H8-2H292-4A15-6A2(14-2AC3A)14-6A15-4A296-4A14-8A12-8A11-AC7AD10-2C7AD2(10-10A)11-8A12-7AC14-4A234-8A12-8A11-10A9-C11A4(8-12A)8-2C10A9-D9A11-8A13-6A193-5A2DA11-10A9-AD10A8-12A7-14A6-13AC6-14A6-D13A6-14A6-C13A7-12A8-AC10A9-10A12-5AD153-2ADAI3A12-8A10-11AC8-12A7-14A6-14A5-3(16A4-)16A5-14A6-C13A7-12A8-AC10A10-7AD14-AD2A134-3AIAI2A11-10A9-12A7-14A5-3(16A4-)3(16A-B2-)16A4-16A5-D13A7-12A9-10A11-8A132-3A3I2A10-12A7-13AD6-14A5-16A4-16A3-2(18A2B)18AEB18AB2-16A-B2-16A5-C13A6-14A7-12A10-8A14-4A55-4ADA14-6A14-4AIA12-10A9-12A7-13AD5-16A4-16A3-18A-B18A2B18A2E2(18AEB)18AB2-16A4-16A5-13AC7-12A9-10A12-6A34-3(6A14-)I4AD12-10A9-12A7-14A5-15AC4-C15A3-18A-B2(18ABE)18A2H18AEB18AK2-16A4-16A5-14A7-12A9-10A12-6A34-5AD14-6A2C12-5AD2C12-I5A2C10-9ADC8-12A7-D13A5-16A4-16A3-18A-B18A2B18ALE18ABE18A2B18AB2-16A4-16A5-14A7-12A9-10A12-6A33-C6A12-2C6A2C10-2C5AF12-2C5AF11-C8A2F9-12A7-C13A5-15AD4-16A3-18A-L18A-B2(18A2B)18ABK18A3-16A4-16A5-14A7-12A9-10A12-6A32-2C6A2C10-2C6A2C12-F5A2C12-F4AI2C11-F6ADC9-12A7-14A6-13AD5-16A4-16A3-18A-B18A2B18AGB18AB2-16A4-16A5-14A6-14A7-AC10A10-C7A14-2ACA33-2(C8AC10-)2(C8A11-)CD6AD11-D8AD9-D10AD7-13AD5-2(16A4-)16A2-B-16A-BG-16A-EB-16A-B2-16A4-16A5-14A7-12A9-10A11-8A51-C8AC10-C8AC11-2(8A12-)D6AD9-4(14A6-)14A5-16A2-B-16A-BE-16A-EB-16A-B3-14A6-14A7-12A8-12A10-8A14-4A53-C8AC10-C8AC11-8A12-8A10-C11A7-D13A5-15AD2(4-16A)5-14A6-14A3-B2-14A2-BE2-14A2-EB2-14A2-B3-14A7-12A8-12A9-9AC12-6A72-C8AC10-C8AC11-8A12-8A10-12A7-13AD5-2(16A4-)16A5-14A7-12A4-B3-12A3-BH3-12A3-GB3-12A3-B4-12A9-10A11-6A2C13-5AC77-2A13-A2(CD)CMDCA11-A2(DC)MDC12-2(CD)CMDC12-D6AD10-3ADA2DAD3A7-6A2F6A5-7A2F6AC4-7A2F7A4-6AD2AD6A5-14A6-FD11AN3-B-J2FD8AD3F-BE-3FD8AD3F-EB-3FD8AD3F-B2-N2FJ8AFNF9-8A14-4A95-6A13-4(CA)12-3(C-)C13-3(C-)C14-3(C-)A13-7A9-5AJ2-J5A2(6-4ADJ2-JD4A)6-4A2D2J2D4A6-5AD2AD5A4-BHB13A2B-5B12A3BG4B10A4BH5B8A2C5B-5B8A5B3-E15B111-2A17-4A76-4A16-A2-A12-3A-A2-A-3A7-2C2ACA2-AC3AC6-C3A2C2A2C3AC6-G4AD2AD4AB4-2B6A2H6A2B-B8A2H8ABE18AEL18AL-B16AB3-11BE3BE230-C2-C16-C2-C12-2C2(2-C)2-2C8-2(2C3-)2C7-5BH2CH5B4-KB5AB2HB5A2B-B8A2H8ABE18AEB18AB-B16AB3-5BE10B305-2(5B4-)2B5AB2HB5A2B-B8A2B8AKE18AEB18AB-B16AB3-3BK4BK3B2(EB)102-
