model
size = 30 26 17, scale = 0.05, origin = -y
material deform = 1, fade = true, lighting = smooth, roughness = 0.3, metalness = 0.6
  colors = A:#9CF B:#00D C:#444 D:#DDD E:#00B F:#222 G:#930 H:#B00 I:#002 J:#00A K:#963 L:#EEE M:#06F N:#0CC O:#BBB P:#111 Q:#800 R:#00E S:#555 T:#888 U:#FC3 V:#F60 W:#F90 X:#960 Y:#D00 Z:#777 Aa:#966 Ab:#FC0 Ac:#FF3 Ad:#933 Ae:#700 Af:#0CF Ag:#AAA Ah:#0C9 Ai:#0FF Aj:#0FC Ak:#0C0 Al:#A00
voxels
7-2(D14-)3(L14-D14-)10(L14-)D3(14-L)14-D14-L2(14-D)464-7(D14-)D44-5(D14-)O2(14-D)44-8(D14-)O14-D374-2(D14-)2(O2(14-D)14-)3(D14-)D44-5(D14-)2(O14-)9(D14-)L2(14-D)14-O4(14-D)224-36(D14-)O3(14-D)2(14-L)103-2(3I12-)E2B12-2B8(E12-EAB12-BA)E12-EAB2-8T2-BAE12-EAB-T8-T-BAE12-EAB12-BAE12-EAB3-F2-N-Af3-BAE12-EAB2-2(F-)Ah-Ai3-BAE12-EAB3-F2-Af-Aj3-2(BAE12-EAB12-)BAE12-EAB2-Ak2-5F2(2-BAE12-EAB5-F3-F)2-BAE12-IAI2-Al2-5F2-IAI2(12-HAH)13-2H12-2H43-O2D12-O2D11-I3A2I8-2I3AI7(10-B3AE10-E3AB)10-B3AECSC4-CSCE3AB10-B3AE10CE3AE10-B3AEC8KCE3AB10-B3AEK8CKE3AB10-E3AE9CSE3AB10-B3AE2(2CK)CK2CE3AE10-M3AECKAg2(KC)K2CE3AM10-M3AE2(2CK)CK2CE3AM10-M3AECS4C2(SC)E3AM10-M3AE10CE3AM10-M3AECK2C5KCE3AM10-B3AE3CSKLZLKCE3AB10-B3AE4CK3LKCE3AB10-I3AICK2C5KCI3AI10-Y3AH7CSCTH3AH11-3HY10-3HQ41-5D10-5D9-2(I5AI8-)E4AE10-E4(4AE8-E4AJ10-J)2(4AE8-E4AE10-E)4AE8-E5A3C4F3C5A12(E8-E20A)E8-I20AI8-Q5A10C5AY9-5H-CS6C-HY3H39-2D3-D10-D3-2D7-IAAbWVWAI8-IAWVWAbAI6-B6A3F4P3F6A3(B6-B5AJ4-LD4-J5A)B6-B5AJ4-2D4-J5AB6-B5AE4-LD4-E5AB6-B6A2C2-2D2-2C6AB6-B8A2F2A2F8A3(B6-B22A)R6-E8(22AB6-B)22AB7-I20AI8-H5A10C5AH9-2HA2H-8C-2HA2H12-Q4-3CS2C4-Q7-D3-D4-D10-D4-D3-3D-IAVUAcVAI2FP2ZP2FIAVAcUVAI-D2O2D7A2FP4AP2F7A3DL2D6AJ3-D2ND3-J6A2DL-2D6AJ3-D2ND3-J6AOD2-2D6AJ3-D2ND3-J6A2D3-O6AJ3-D2ND3-J6AD4-L7A2C-D2AD-2C7AL5-B7AC-D2AD-C7AB6-R8AF4AF8A12(B6-B22A)B7-I20AI8-H5A10C5AH9-H3AH-8C-H3AH11-2QAe3-6C3-Q2Ae2(10-D4-D)7-IAWAcUWAI2FP2ZP2FIAWUAcWAI6-B6A2FP4AP2F6A4(B6-B5AJ3-D2ND3-J5A)B6-B6A2C-D2AD-2C6AB6-B8AF4AF8A6(B6-B22A)M3(6-B22AB)6-B22AE6-B22AB6-R22AB6-B22AB7-I20AI8-H5A10C5AH9-Q3AH-8C-H3AH11-3Q3-6C3-3Q10-OD3-D10-D3-2D7-IAAbUVUAI8-IAUVUAbAI6-B6A3F4P3F6A4(B6-B5AJ4-2D4-J5A)B6-B5AE4-2D4-E5AB6-B6A2C2F2A2F2C6AB6-B22AR6-B22AM11(6-B22AB)7-I20AI8-H5A10C5AQ9-2HA2H-8C-2HA2H12-Ae14-Q12-5D10-5D9-2(I5AI8-)B4AE10-E4AB8-R4AJ10-J4AB8-B4AJ10-J4AM2(8-B4AJ10-J4AB)8-B4AE10-E4AB8-B4AE3-4F3-E4AB8-B5A10C2(5AB8-B5A2C6F2C)5AB8-R5A2C6F2C5AB8-B3(5AC8FC5AB8-M)4(5AC8FC5AB8-B)5AC8FC5AR8-B5AC8FC5AB8-I5A4C2S4C5AI8-H5A10C5AH9-5H10-5H41-3D12-DOD11-2(I3AI10-)2(B3AE10-E3AB10-)R3AE10-E3AB10-E2(3AE10-E3AB10-B)3AE10-E3AE2(10-B3AE10-E3AB)2(10-B3AEG8-GE3AB)4(10-B3AE10-E3AB)10-E2(3AE10-E3AB10-B)3AE10-E3AE3(10-B3AE10-E3AB)10-I3AIAaG6-AaGI3AI2(10-H3AH)11-Y2H12-3H72-2(3I12-)4(3B12-)M2B12-E2B12-BRB12-2BR12-3B12-2BE2(12-3B)12-REB4(12-3B)-2G6-2G-3B12-BEB-2G6-2G-2BM5(12-3B)12-BEB12-BRM12-3B12-BRB2(12-BMB12-3B)12-BMB12-BEB12-BMB12-BRB12-3B12-M2B12-3B12-3I-GAa6-2G-3I12-3H12-2HY377-2G4-2G22-2G4-2G291-2G6-2G20-GAd6-2G412-6G22-10G20-2G6-2G260-2G6-GAa442-2G2X2G22-3GX2GX3G20-2G6-2G20-AdG6-2G20-XG6-GX20-GX6-XG20-2G6-GAd20-AaG6-2G20-2G6-2G20-AdG2(6-2G20-2G)6-2G130-
