model
size = 23 21 23, scale = 0.05, origin = -y
material deform = 1, fade = true, lighting = smooth, roughness = 0.3, metalness = 0.6
  colors = A:#242424 B:#B700FF C:#FFC700 D:#2C2C2C E:#444 F:#FFE700 G:#E1A500 H:#343434 I:#C18A00 J:#FFF56A K:#7800FF L:#282828 M:#202020 N:#5800FF O:#7000FF
voxels
-3C20-CA2C19-C2A2C18-C3A2C17-C4A2C16-C5A2C15-CI5A2C15-C2AHA2H2C14-C3A4H2C13-C3AH4A2C12-CI8A2C12-C5AM3A2C11-FC9A2C11-FI9A2C10-JCI5A3HA2C10-JCI3A5HA2C10-JFC5A3HA2C11-J2CI7A2C12-J4C5A2C15-8C19-6C2(22-C)2(A21-C)A22-2(A23-)AN22-3A20-4A20-2AB2A5(18-6A)19-5A22-2(2A21-)4A20-CGI3ACG22-A22-2(2A21-)IA21-C2A20-C2-M19-C2-AK21-A3B19-A5B17-2A5B16-2A6B16-2A3B2A3(B15-8A)B17-6AK18-4AB21-3A21-4A16-3CGI4AG2C22-I22-AE3(21-2A)21-3A20-I2AK19-C-A4B16-C-A5B2(17-A6B)16-A7B15-A5BA3B14-8A2B14-9AB14-8AB17-5ABK18-5A20-6A14-2CI2D5A2C24-C22-I22-AE4(21-2A)B20-2A2B19-I-A3B17-C-A4B16-C-A5B17-D6B17-A6B16-2A7B15-A9B14-9AB15-A2D4AB2(18-6A)E13-FCI4D3AE2C25-2(C22-)A22-AE3(21-2A)K2(20-2AB)20-2A2B19-C-A3B17-C-A4B16-J-DA4B18-A6B16-2A7B15-3A7B15-AD6AK16-2D5A18-6AE13-FCID2AD3AD2C49-2(C22-)A22-AE3(21-2A)K3(20-2AB)20-I-A2B18-C-A3B17-J-DA3B19-D5B18-2A6B16-AD2A5B16-DAB5A17-6AE13-FC2D6AD2C73-2(C22-)A22-AE3(21-2A)2(B20-2A)B20-2(A-AB19-)C-D3B17-F2-D3B19-3A2B20-DA4B18-DA4BK18-AB4AE13-JFI7ADGC97-2(C22-)A22-AE3(21-2A)2(B20-2A)B20-A-AB19-A-D2B18-C2-D2B17-J2-3AB20-D2A2B20-DA2B20-A4B-AE13-FID7AGC121-C22-G2(22-A)E3(21-2A)2(B20-2A)2B19-A-DAB18-I2-D2B17-F2-3A2(B20-D2A)B20-2A3B2AE13-JF8AGC145-C22-G2(22-A)E3(21-2A)B20-2A2B19-2ADB19-A2-D2B17-C2-2A2B16-F2-D3AB20-D2AB20-2A2BA2E14-FI7A2C169-C22-G2(22-A)E21-2A21-HA2(B20-2A)2B19-2ADAB18-I2-2AB17-C2-2(D2AB20-)3A2BE15-JF7AGC193-C22-G2(22-A)E2(21-HA)K20-2AOB19-2AD2B18-2A-2AB17-G2-DA2B16-F3-DA2B19-4ABAE15-FI2L4AGC217-C22-G22-A22-HE2(21-HA)21-2ANB19-3AKB18-I-DNKB17-F2-DNK21-5AE15-JF2(AL)2A2C241-C22-G22-A22-HE21-HA3(21-2A)D20-F2-D22-AD2A2E16-FIL4AGC265-C22-G2(22-H)E21-2A21-AD21-2AD20-F-2D21-2ADAE18-FAL3AGC289-C22-G22-E22-AE21-2A21-AM21-CD21-F-2DAE19-FAL2A2C313-C22-G2(22-A)E21-AM21-GD21-FADAE19-FC3AGC337-C22-G2(22-A)E21-IA21-F2AE20-F3AGC361-C22-G22-E22-2(AE21-F)2AGC385-C22-G22-AE21-CAE20-FCAGC409-2(C22-)GE21-FAGC433-2(C22-)3C20-
