model
size = 27 4 25, scale = 0.05, origin = -y
material deform = 1, fade = true, lighting = smooth, roughness = 0.3, metalness = 0.6
  colors = A:#EEE B:#111 C:#777
voxels
9-CAB3AB20-C3(AB)20-2A2(BA)B20-3(BA)B18-2(BA7-2A16-)2A7-2A16-BA7-2A14-3(2A11-2A12-)AB11-2A11-3(A15-A10-)A15-A9-3(A17-A8-)A17-A7-4(2A18-A6-)3(A19-A6-)A19-B5-2(A21-B4-)A21-A4-A21-B4(4-A21-A)3-2(B23-C2-)B23-A2-B23-B4(2-A23-A)2-A3(23-B2-B)23-B4(2-A23-A)2-B23-A3(2-B23-B)4(2-A23-A)2(2-C23-B)2-A23-B2-B23-B3-4(A21-A4-)2(B21-A4-)A21-A4-B21-A5-3(A19-A6-)B4(19-A6-A)19-A7-3(A17-A8-)A17-A9-A15-A2C3A5-A15-A2C2A6-A15-A2C3A5-A15-A2C4A5-3(2A11-2A3C9-)2A11-BA3C11-2(2A7-AB16-)2A7-2A16-2A7-AB18-B3ABAC20-3(BA)C20-2(BA)B2A20-3(BA)B11-
