model
size = 22 15 30, scale = 0.05, origin = -y
material deform = 1, fade = true, lighting = smooth, roughness = 0.3, metalness = 0.6
  colors = A:#FF0 B:#100 C:#EEE D:#C30 E:#FFF
voxels
53-4B17-AB2E5(BA16-AB2A)BA259-2(4A18-)4A85-2A20-2A151-4A17-3(A4BA16-)6A17-B2AB18-B2-B19-2(2A20-)2A128-6A16-A4B2(A16-AB2-B)A16-6A39-B2-B18-B2AB19-2(2A20-)2A106-6A16-A4B2(A16-AB2-B)A106-2(2A20-)2A106-6A16-A4BA16-AB154-2A20-2A106-6A16-A4BA152-B18-B2A20-2A106-2(B-)2B174-2(B18-B2-)B305-2A19-B2AB283-2(2A20-)2A262-2A19-B2AB19-2A20-2A196-2A20-2A19-2(B2-B18-)B2AB19-2A33-4B12-4B-6C-8B-6C7-3B2E3B2(14-8B)39-2B19-B2AB19-2A20-2A19-B2AB97-6B10-6B6C10A6C-5C10A5C8-2(9A13-)9A14-7B16-B2AB19-2A20-2A120-6B10-6B6CA8-A6C-2B3CA8DA3C2B7-2(A8DA12-)A8DA13-8BA15-B2AB19-2A142-6B10-6B6CA8-A6C-5CAD6-DA5C7-AD6-DA11-BAD6-DAB10-BA8DAB11-A8BA15-B2-B163-6B10-6B6CA8-A6C-2B3CAD6-DA3C2B7-AD6-DA11-BAD6-DAB10-BA8DAB11-A3B2A3BA182-6B10-6B6CA8-A6C-5CAD6-DA5C7-AD6-DA11-BAD6-DAB10-BA8DAB11-AB6ABA183-4B12-4B-6CA8-A6C6-AD6-DA12-AD6-DA11-BAD6-DAB10-BA8DAB11-AB6ABA210-A8-2(A12-AD6-D)A11-BAD6-DAB10-BA8DAB11-A8BA210-A8-2(A12-AD6-D)A11-BAD6-DAB10-BA8DAB11-AB6A2(BA210-A8-2(A12-AD6-D)A11-BAD6-DAB10-BA2D4-2DAB11-ABA4-A)BA183-4B12-4B-6CA8-A6C6-AD6-DA12-AD6-DA11-BAD6-DAB10-BA2D4-2DAB11-ABA4-ABA182-6B10-6B6CA8-A6C-5CAD6-DA5C7-AD6-DA11-BAD6-DAB10-BA2D4-2DAB11-ABA4-ABA182-6B10-6B6CA8-A6C-2B3CAD6-DA3C2B7-AD6-DA11-BAD6-DAB10-BA8DAB11-AB6ABA14-3(B4DB16-)2B2D2B17-4B75-6B10-6B6CA8-A6C-5CAD6-DA5C7-AD6-DA11-BAD6-DAB10-BA8DAB11-A8BA14-A4-A16-A4-A140-6B10-6B6C-8A-6C-2B3CA8DA3C2B7-3(A8DA12-)A8BA14-A4-A16-A4-A140-6B10-6B6C2-B4AB2-6C-5C-2B4A-B-5C8-B-5A3(B14-B6A)B15-6A16-6A141-4B12-4B-6C2-2B2A2B2-6C8-4(6A16-)2(AB2ABA16-)AB2ABA140-
