model
size = 29 11 28, scale = 0.05, origin = -y
material deform = 1, fade = true, lighting = smooth, roughness = 0.3, metalness = 0.6
  colors = A:#CF7C00 B:#3FF C:#111 D:#FFF E:#FF0 F:#222 G:#BBB H:#EEE
voxels
90-2(E-4B-E7-)D5B9-D5B7-2B2D4B-H3FH-2B2D4B6-2B2D4B-5F-2B2D4B6-5B3D-H3FH-5B3D7-4B2D9-4B2D2(7-E-3BD-E)216-4(G-)G280-2(11C18-)11C249-2(C11-C16-)C11-C246-2(2C13-2C12-)2C13-2C243-2(C17-C10-)C17-C241-2(C19-C8-)C19-C239-2(C21-C6-)C21-C237-2(C23-C4-)C23-C236-2(C23-C4-)C23-C235-9(2(C25-C2-)C25-C234-)A25-A-GA25-AG-2(A25-A234-2(A25-A2-))A25-A205-3(A25-A2-)A25-A176-A25-A2-A25-A-EA25-AE-A25-A-EA25-AE232-E27-E29-E27-E91-6A9-6A2(7-8A)2(5-3A4-3A)2(3-3A6-3A)2-2A8-2A3-2A8-2A-E2A8-2A3-2A8-2AE-2A8-2A3-2A8-2A-E3A6-3A3-3A6-3AE2-2(3A4-3A5-)2(8A7-)6A9-6A8-6A9-6A2(7-8A)2(5-3A4-3A)2(3-3A6-3A)3(2-2A8-2A3-2A8-2A)2-2(3A6-3A3-)2(3A4-3A5-)2(8A7-)6A9-6A8-6A9-6A2(7-8A)2(5-3A4B3A)2(3-3A6B3A)3(2-2A8B2A3-2A8B2A)2-2(3A6B3A3-)2(3A4B3A5-)2(8A7-)6A9-6A4-
