model
size = 20 15 32, scale = 0.05, origin = -y
material deform = 1, fade = true, lighting = smooth, roughness = 0.3, metalness = 0.6
  colors = A:#444 B:#888 C:#09F D:#111 E:#F63
voxels
124-A10-A225-A16-A144-3B8-3B124-A16-A143-6B4-6B123-A16-A142-8B2-8B88-6A14-6A8-A5-6A5-A8-6A14-6A107-9B2-9B66-2(8A12-)8A7-A4-8A4-A7-2(8A12-)8A86-9B2-9B66-2(8A12-)8A7-A3-10A3-A6-3(10A10-)10A65-9B2-9B66-2(8A12-)8A7-A3-10A3-A6-4(10A10-)10A45-9B2-9B86-8A12-8A7-A3-10A3-A6-4(10A10-)10A11-8A27-8B2-8B82-A4-8A4-A7-8A7-A3-10A3-A2-A3-10A3-A6-3(10A10-)10A11-8A27-8B2-8B82-A4-8A4-2(A7-8A11-10A6-A3-10A3-A6-4(10A10-)10A11-8A7-8B2-8B82-A16-)2(A7-8A11-10A6-A3-10A3-A6-4(10A10-)10A11-8A8-7B2-7B83-A16-)A2-A16-A7-8A7-A3-10A3-A6-4(10A10-)10A11-8A8-7B2-7B103-A16-A7-8A7-A3-10A3-A6-4(10A10-)10A11-8A9-6B2-6B104-A16-A7-8A7-2A2-10A2(2-2A)2-10A2-2A6-2(10A10-)10A11-8A29-6B2-6B104-A16-A23-2A12-2A4-2A3-6A3-2A9-2(6A14-)6A50-6B2-6B104-A16-A24-2A-11A6-2A-11A9-3(8A12-)8A30-5B2-5B105-A16-A7-8A10-11A9-11A4(10-10A)11-8A10-5B2-5B105-A16-A2-3A2-8A2-3A3-16A5-14A8-3(10A10-)10A11-8A11-4B2-4B53-A2-A74-8A11-5(10A10-)10A11-8A12-3B2-3B54-A2-A73-6(10A10-)10A11-8A74-A2-A93-10A9-12A10-3(8A12-)8A74-A2-A132-A10-A13-2A18-2A117-A2-A116-4A12-A2-6A2-A11-6A14-6A12-2C6A3(2C10-2C-A2-A-)2C13-A2-A152-A2-6A2-A11-6A14-6A12-2C6A2C10-3C4A3C2(10-4C2-4C)169-A3-A2EA3-A11-6A14-6A12-2(4C2A4C10-)4C2-4C10-4C2-4C169-A4-2E4-A70-2D4-2D12-2D4-2D190-A4-2E4-2(A288-A10-)A184-
