model
size = 32 32 11, scale = 0.05, origin = -y
material deform = 1, fade = true, lighting = smooth, roughness = 0.3, metalness = 0.6
  colors = A:#100 B:#EEE C:#000 D:#002
voxels
878-3A28-6A26-7A26-5B27-5B601-8A22-13A2-2B9-2B2-16AC2AB6-3BA-20A3B3-2B25AD2B3-27ADB3-28A5-26A6-25A8-23A11-8A5-6A19-2A5-4A21-2B5-B24-2B5-B314-4A25-10A21-12A20-13A2(18-14A)18-3(15A17-)4A6-5A17-4A6-5AB13-2B5A6-4AB14-7A6-7A12-A5-A6-2A5-2A4-2B4-7A6-2A5-A3-AB-B11A6-11AB3-11A2(6-10A)6-9A7-10A6-9A8-9A6-8A12-6A6-7A18-B7-B23-B7-B22-11B21-11A10(20-12A)20-13A18-14A18-15A17-3A2-10A3(16-4A7-5A)15-B4A7-5AB14-5A7-5AB13-A3-2A7-7A12-A12-2A5-A11-6A7-2A10-2B11A7-11AB3-10A7-11A4-10A7-10A6-2(9A7-)10A6-9A9-8A6-8A14-ACBA7-ABCA20-B7-B22-B8-AB3(20-2A8-2A)2(19-3A8-2A)19-7(3A8-3A18-)3A5(8-4A16-4A)8-4A15-B4A8-4AB14-5A8-4AB13-A3-2A8-6A12-A13-A5-A11-6A8-A10-2B11A8-10AB2-11A8-10A4-10A8-9A5-10A8-9A6-9A8-8A8-9A6-8A13-ACABA7-AB2CA19-B7-B21-B10-B2(20-A10-A)19-9(2A10-2A18-)2A6(10-3A16-3A)10-3A15-B3A10-3AB14-4A10-3AB13-A3-A10-5A12-A19-A11-5A19-A2B10A10-9AB2-10A10-9A3-10A10-9A4-9A10-8A6-8A10-7A8-9A6-8A12-A2CABA7-AB2C2A18-B7-B21-B10-B20-A10-A19-10(2A10-2A18-)2A10-2A17-5(3A10-3A16-)3A10-3A15-B3A10-3AB14-4A10-3AB13-A14-5A12-A19-A11-5A19-A2B10A10-9AB2-10A10-9A3-10A10-9A4-9A10-8A6-8A10-8A8-8A6-8A12-A2CABA7-ABAC2A18-B7-B21-B9-AB20-A9-2A20-2A2(8-2A19-3A)9(8-3A18-3A)5(8-4A16-4A)8-4A15-B4A8-4AB14-5A8-4AB13-A13-6A12-A13-A5-A11-6A8-A9-A2B11A8-10AB2-11A8-10A3-11A8-9A5-10A8-9A7-8A8-8A9-8A6-8A13-2CABA7-ABACA19-B7-B22-10B4(22-10A)21-11A21-8(12A20-)14A17-15A3(16-16A)15-B16AB14-16AB13-20A13-15A4-2A11-15A2(4-A)2B29AB2-13A5-11A4-12A5-10A6-11A5-9A8-10A5-8A11-7A6-7A15-ACBA7-ABACA19-B7-B477-2(4A28-)4A18-15A17-16A15-B10A4B2A2B10-3B18A2B7-2B22A4B3-2B25A3B-2B27A2B2-B28A4-14A-12A6-12A3-10A8-10A5-8A10-8A6-7A13-4ABA6-2AB3A19-B7-B-CA20-B7-B509-4(4A28-)4B184-2B-2B26-BAB-BAB24-B2AB-B2AB22-B2AB3-B2AB21-BCB5-BAB22-B7-B23-B7-B11-
