model
size = 28 12 28, scale = 0.05, origin = -y
material deform = 1, fade = true, lighting = smooth, roughness = 0.3, metalness = 0.6
  colors = A:#FC0 B:#E00 C:#D00 D:#A00 E:#00E F:#0A0
voxels
38-8A50-4A23-4(A4CA22-)ACD2CA23-ACDA25-2A51-8A50-4A23-3(A4BA22-)A2BDBA22-A2BDBA23-A2BA25-2A77-12A16-A-8A-A18-6(2A4B2A20-)3A2B3A21-2A2B2A23-4A25-2A19-4A8-4A12-AF2A8-2AFA13-3A2-4A2-3A19-2(4A20-2A2-4A2-2A20-)4A25-2A26-2A74-3A11-4A11-2A11-3A12-2(2A11-3A40-)2A11-3A12-A14-A122-2A15-3A9-A15-2A10-A15-2A38-A15-2A37-2A15-3A2(8-EA16-AE)91-2A17-3A7-A17-2A8-2(A17-2A36-)2(2A16-2A8-)2A16-2A9-A16-A63-2A19-3A4-2A19-3A5-2(A19-2A34-)A19-2A6-A20-A117-2A20-2A4-FA20-AF4-2A20-2A33-A20-A34-A20-A144-2A21-3A2-2A21-3A3-2(A21-2A32-)A21-2A143-2A22-2A3-A22-A4-2(A22-A32-)A22-A142-2A24-2A-7(A24-A2-)A24-A85-2A24-2A-A24-A2-A24-A-2A4(24-4A)24-2A-A24-A2-A24-A57-2A24-2A-A24-A-ABA22-ABA2B3(A22-A4B)A22-A2BDBA22-A2B2A24-2A-A24-A2-A24-A29-2A24-2A-A24-A-ABA22-ABA2B3(A22-A4B)A22-AB2DBA22-A2BDBA22-A2BABA22-ABA-A24-A2-A24-A-2A24-2A-A24-A-ABA22-ABA2B5(A22-A4B)A22-ABDABA22-ABA-A24-A2-A24-A-2A24-2A-A24-A-ABA22-ABA2B4(A22-A4B)A22-A2B2A24-2A-A24-A2-A24-A29-2A24-2A-A24-A2-A24-A-2A4(24-4A)24-2A-A24-A2-A24-A57-2A24-2A-7(A24-A2-)A24-A86-2A23-A3-A22-A4-2(A22-A32-)A22-A143-3A21-2A2-3A21-2A3-2(2A21-A32-)2A21-A144-2A20-2A4-FA20-AF4-2A20-2A33-A20-A34-A20-A145-3A19-2A4-3A19-2A5-2(2A19-A34-)2A19-A6-A20-A118-3A17-2A7-2A17-A8-2(2A17-A36-)2A17-A2(8-2A16-2A)9-A16-A65-3A15-2A9-2A15-A10-2A15-A38-2A15-A37-3A15-2A2(8-EA16-AE)93-4A2(11-3A)11-2A12-2(3A11-2A40-)3A11-2A12-A14-A124-4A8-4A12-AF2A8-2AFA13-3A2-4A2-3A19-2(4A20-2A2-4A2-2A20-)4A25-2A26-2A77-12A16-A-8A-A18-6(2A4B2A20-)3A2B3A21-2A2B2A23-4A25-2A13-
