model
size = 14 28 23, scale = 0.05, origin = -y
material deform = 1, fade = true, lighting = smooth, roughness = 0.3, metalness = 0.6
  colors = A:#888 B:#FF0 C:#FC9 D:#FFC E:#444 F:#DDD G:#EEE H:#EEC2C2 I:#222 J:#00E K:#111 L:#777 M:#F96
voxels
148-4(2B12-)2B302-2C11-4C9-FC3-C2B6-F2(C-)C2B6-FC3-C2B6-F5C2B7-4C3B8-2C-3B11-3B248-3B9-2C3B8-C2AC2B7-F4ACB6-G2A3C2AB5-G2ACAC2AB5-G2A3C2A2B4-G2AC4AB6-F5A2B7-C2AC4B7-2C-3B8-2(2B12-)2B11-3B3(12-2B)154-3B8-3CA2B7-F5A2B6(5-E7AB)6-F5A3B6-C2AC2B7-K-5B8-6B3(9-5B)8-6B9-5B149-2C3B7-FC4AB6-G7AB5-E7A3B2-10A3B-2(10A2B2-)10A2B3-E7AB5-G7A2B5-I5AB7-KB2A4B2(7-7B)8-5B9-5B8-6B9-5B108-2B12-2B-3B8-2B-3B7-CA7B3-FC4A5B2-G7A4B2-E7A3B2-10A2(2B2-J9A)3B-10A3B2-E7A4B2-G7AB6-I5A2B6-KB2A4B2(7-7B)8-3(7B7-)5B108-2B10-2(DCAC-3B6-)D2AC-5B3-F4AC5B2-G7A4B2-E7A3B2-10A2(2B2-J9A)2B2-10A2B3-E7A3B3-G7AB6-I5A2B7-2(D3A5B5-)D3A5B4-10B4-9B5-10B7-B-5B89-D3C10-DCAC10-2(D2AC-3B6-)D2AC-3B5-F4AC3B4-G7A2B4-E7A2B3-3(10A2B2-)10AB4-E7A2B4-G7A2B5-I5A3B6-D3A6B4-D3A5B5-2(D3A5B4-B)D3A4B5-9B8-3(2B12-)2B38-D3C10-2(D2AC-4B5-)3(D3AC4B5-)D4A4B4-F5A5B2-2(E7A3B3-)3(E7A2B4-)E7A2B5-F5A2(3B6-D4A)2-3B4-D4A2-2B5-D4A2-2B4-BD3A6B3-BD3A4B4-2BD3A4B4-7B11-2(2B12-)2B38-D3CB10-HAC-4B6-H2AC2(4B5-D4A)5B4-2(D4A4B5-)D4A5B3-F5A4B3-G7A3B3-2(E7A2B4-)G7A2B5-F5A2(3B6-D4A4B5-D4A)2(4B5-D4A)6B-2BD3A4B3-3BD3A5B2-8B11-3B11-2(2B12-)B11-D3C11-HAC11-H2AC7(4B5-D4A)4B4-F5A4B4-E5A2B6-E5A3B5-F5A4(3B6-D4A)4B5-D4A3B6-D4A4B3-2BD4A5B2-2BD4A5B-3BD3A2B5-3BD3A2B8-6B9-3B12-2B24-D3C2B9-M2A2B9-H3AB8-D4A2B7-D4A2B5-2CL5(4A2B7-D)3A3B7-D3A3B7-E2(3A3B7-D)2(4A4B5-D)4A2B7-2(D4A-4B4-)2(D4A5B2-2B)D4A-4B3-BD3A3B6-BD3A2B8-6B10-3B11-2B24-D3C2B9-M2A2B9-H3A2(B8-D4A)B6-2CL4A2B5-2CL4A3B4-2CL3(4A3B6-D)3A4B6-D3A4B6-E2(3A4B6-D)2(4A4B5-D)4A3B6-D4A5B4-D4A6B3-D4A5B2(2-2BD4A-4B)3-BD3A2B6-2BD3AB7-7B11-3B10-3B24-D3C2B9-H2A2B9-H3AB8-D4A3B6-D4A3B4-2CL3(4A3B6-D)4A4B5-D4A3B5-F5A3B5-E5A4B4-2E4A3B5-F5A2(3B6-D4A)6B3-D4A4B5-2(D4A5B4-)D4A5B2-2(2BD4A4B3-)2(2BD3A2B6-)8B8-6B10-2B28-2B8-D3C2(2B9-H2A)C3B6-D4A4B5-2(D4A3B6-)D3AC-2B6-D3AC-2B5-F5A4B3-G7A3B3-2(E7A2B4-)G7A2B5-F5A3B6-D4A6B3-D4A2B-B5-D4A2B-2B4-D4A-B-2B4-D4A-4B4-D4A4B4-BD3A6B2-2BD3A6B2-12B4-6B8-7B8-3B11-3B24-D3C2(10-D2AC)2-4(2B6-D3AC-)2B5-F4AC-2(2B4-2(E7A3B3-)E7A)2B5-F5A4B2(5-D4AB2-B)5-D4A3B6-D4A-3B5-D3A2-3B4-BD3A7B-2BD3A6B2-2B-9B5-2(4B10-)3B11-3B38-2(D3C10-)2(D2AC10-)D2AC9-F4AC7-G6AC6-E7A2B4(3-10AB)4-E7A2B4-G7A3B4-I5AB2-B5-D3A3B-B5-D3A4B6-2(D3A5B3-2B)D3A6B3-4B-6B5-9B5-3(3B11-)3B66-2(D3C10-)D2AC9-F4AC7-G6AC6-E7A2B3-10A2(B3-J9A)2B2-10A3B2-E7A3B3-G7A3B4-I5A4B2(5-D3A5B)5-D3A2-3B3-5B3-4B2-11B4-8B8-3B11-3B10-4B2(11-3B)95-2C10-FC2A2C7-G6AC6-E7A2B3-10A2(B3-J9A)2B2-10A2B3-E7A3B3-G7A3B4-I5A4B4-KB2A7B4-9B5-10B4-9B4-10B4-7B10-4B24-B124-2C10-FC2A2C7-G6AC6-E7A3B2(2-10A2B)2-10A3B-10A2B3-E7A3B3-G7A4B3-I5A4B4-KB2C3B5(8-6B)10-4B162-4C9-F4AC7-E6AC4(3B3-E7A)3B3-E6AC3B4-F4AC4B5-C2AC5B4-K18-B9-2B12-2B15-3B191-2C11-C2AC9-F4AC7-G2A3CAC6-G2A2(CA)C6-G2A3CAC6-G6AC7-F4AC9-C2AC11-2C278-2C11-4C9-FC3-C8-F2(C-)C8-FC3-C8-F5C9-4C11-2C176-
