model
size = 13 25 13, scale = 0.05, origin = -y
material deform = 1, fade = true, lighting = smooth, roughness = 0.3, metalness = 0.6
  colors = A:#FC0 B:#00E C:#09F
voxels
316-5A319-A5-A317-A7-A316-A7-A315-A9-A314-A9-A313-2(A11-A312-)2(A11-A299-)A11-A45-A11-3A10-3A2(11-A)-A10-A-A9-2(A3-A8-)A3-A7-2(A5-A6-)2(A5-)2(A7-A4-)A7-A3-2(A9-A2-)A9-A-A2(11-2A)11-A45-A11-ABA9-A3BA8-ABCBA9-ABA11-A253-
