model
size = 19 6 9, scale = 0.05, origin = -y
material deform = 1, fade = true, lighting = smooth, roughness = 0.3, metalness = 0.6
  colors = A:#111 B:#555
voxels
5-10A9-5B5A2(14-B4A)43-16A3-4B10-2(2A17-)A13-B4A23-18A-B15-2A17-2A16-2A3(17-A13-B4A4-19AB3(16-2A))17-A13-B4A4-18A-B15-2A17-2A16-2A17-A13-B4A5-16A3-4B10-2(2A17-)A13-B4A28-10A9-5B5A2(14-B4A)42-
