model
size = 28 27 27, scale = 0.05, origin = -y
material deform = 1, fade = true, lighting = smooth, roughness = 0.3, metalness = 0.6
  colors = A:#FFF B:#D2D2D2 C:#FEBFC7 D:#990027 E:#CAD2E9 F:#FF7200
voxels
5-9(A-)A9-20A8-20A9-18A10-18A14-10A19-8A23-2A548-5AC12AC3A2(6-22A)7-20A8-20A10-16A13-14A17-8A544-6AE12AD4A2(4-24A)5-22A6-22A7-20A9-18A12-14A300-2A48-2A188-14A4B2DE3A4-14A4B2D5A3-14A4B2D6A3-13A4B2D5A4-13A4BAD5A5-15ABAD4A7-14ABAE3A10-12AB3A271-2A24-6A18-14A13-16A176-13A4BCDE3A4-14A4BCD5A3-2(14A4BCD6A2-)14A4BCD6A4-15ABCD4A6-15ABCE4A8-13AB4A268-6A20-10A15-16A11-18A174-14A4B2D3E3A4(2-14A4B2D6A)3-16AB2D5A5-15AB2E4A7-14ABE3A12-14A15-12A213-10A17-12A10-2A-18A7-22A6-23A2(4-24A)4-A84-13A4B2D3E2A3-3(14A4B2D6A2-)14A4B2D6A3-16AB2D5A4-16AB7A6-14ABE3A12-14A14-14A15-12A184-12A15-14A9-22A4-25A2-5AC20A2(2-26A)3-25A2(14-14A)4-14A4B2D3E3A4(2-14A4B2D6A)3-16AB2D5A4-16AB7A5-15ABE3A12-2(14A14-)14A16-11A155-14A13-16A7-23A3-26A2-5AB20A3(2-26A)2(14-14A)5-13A4B2D3E2A3-4(14A4B2D6A2-)17AB2D6A3-16ABAD5A5-15AB2E2A12-2(14A14-)14A16-12A17-9A127-16A10-19A6-24A2-26A2-5AB20A3(2-26A)2(14-14A)4-14A4B2D3E3A4(2-14A4B2D6A)2-17AB2D6A2-17ABAD6A3-16AB2E2A2-A9-2(11ABEA14-)14A15-13A16-11A19-7A23-2(3A25-)3A18-16A10-19A7-3AB19A2-6AB19A2-5A2B2(19A2-6AB)19A2-26A2(14-14A)5-12A7C3E2A3-2(13A7C6A2-)2(13A5B2D6A2-)17AB2D6A2-17ABAD6A3-16AB2E2A2-A9-2(11ABEA14-)14A14-14A16-11A18-9A21-2(6A22-)2A2C2A15-18A9-20A6-3AB19A3-5AB19A2-5A2B2(19A2-6AB)19A3-25A2(14-14A)4-6(13A5C8A2-)13A5C8A3-12A5B4A2-A9-2(7A5B2A14-)7A4B3A14-5A6B3A16-3A6B2A18-2A6BA19-4A3BC2(A19-4A4C)A14-18A9-20A8-AB19A5-2(AB)19A5-A3B2(19A5-3AB)19A5-23A2(14-14A)5-12A5C7A3-6(13A5C8A2-)13A5B4A2-2A8-2(7A5B2A14-)7A4B3A14-5A6B3A16-3A6B2A18-2A6BA19-AC6B2(A19-A7C)A13-20A8-21A4(7-AB19A)6-2AB19A6-22A14-14A32-3(13A5C7A3-)4(13A5C8A2-)13A3BFB4A2-2A8-2(7A3BFB2A14-)7A3BDB2A14-5A5BDB2A16-3A5BD2A18-2A5BDA19-AC6B2(A19-A7C)A13-20A8-21A4(7-AB19A)6-2AB19A6-22A14-14A33-12A7C5A3-2(5A-7A7C6A2-)3(13A7C6A2-)13A7C6A3-12A7B2A2-A9-3(7A6BA14-)5A8BA16-3A6B2A18-2A6BA19-A2C4BC2(A19-A7C)A14-18A9-20A6-A2(-AB19A4-2A)-A2(B19A4-4A)B-12A3-3A5-17A3-3A14-8A3-3A14-14A4-13A2(7C6A2-5A-7A)4(7C6A2-13A)7C6A3-12A7B2A2-A9-3(7A6BA14-)3A10BA16-2A6B3A18-A6B2A19-A3C2BC2(A20-A6C)A15-18A9-20A5-24A3-25A2(2-26A)2-7A-11A4-3A3-18A4-3A14-7A4-3A14-14A5-12A8C4B3-2(5A-7A8C4BA2-)3(13A12BA2-)13A6B7A3-12A6B3A2-A9-3(7A6BA14-)3A10BA16-3A5B3A18-5A2B3(A21-4A2C)A16-16A11-18A6-24A3(2-26A)2-7A-11A4-3A2-19A4-3A14-7A4-3A14-14A4-13A7C3D2(3A2-13A7C3E)3A2-13A3B3D2(4E3A2-13A6B)4E3A3-12A6B6A5-11A6B3A12-2(7A6BA14-)7A6BA15-2A10B18-2A7B23-4A24-2(3A25-)3A17-16A11-18A6-24A2(2-26A)2-12A3-11A2-7A8-4A4-3A2-26A2(14-14A)5-21CD2A3-6A13C7A2-6A10C2DC7A2-6A3E4-B2-3D7A2-6A3E10B7A3-5A3E10B6A4-8A10B6A5-7A10B5A10-2(6A7BA14-)6A7BA16-4A7B19-2A5B129-5AB8A13-14ABA7-19AB3A3-2(21AB4A2-)12A7-2AB4A2-7A16-3A2-22ACA16-10ACA16-12A6-A21C2DCA2-6A13C4AECA2-6A10C2BC4AECA2-6A3E7-3B7A2-6A3E10B7A3-5A3E10B6A4-11A7B6A5-10A7B5A10-6A7BA14-6A7BA15-5A7B18-3A6B22-2AB132-12A15-13AB8-19AB3A4-20AB3A3-21AB4A2-12A7-2AB4A2-8A15-3A3-23A2(16-12A)7-5A17CEA3-6A13C4AE2A2-6A10C2BC4AE2A2-6A3E4-B2-3B7A2-6A3E10B7A3-5A3E10B6A4-11A7B5A7-9A7B4A11-6A7BA15-5A7B17-4A6B20-2A4B160-6A3BA17-7A3B2A10-12A4B2AB2A7-15AB2AB3A6-18AB4A4-10A7-2AB4A4-24A4-4A80-6A17CE4-6A13C4AEA3-6A10C2BC4AE2A2-6A3E4-B2-2B8A2-6A3E9B8A3-23A6-22A8-18A268-6A20-10A15-16A11-12A2(B2A)7-18AB4A2(5-23A)5-A83-5A18CA3-6A13C4ACA4-5A13C4AC2A3-5A3C4-C-3C7A4-5A12C7A5-22A6-21A10-16A271-2A24-6A18-14A13-16A176-5A16C2A5-5A13C6A5-4A10C9A5-4A3C4-C-C8A6-4A10C8A7-20A8-19A13-13A300-2A22-10A17-13A178-A18CA8-A16C4A7-A13C7A8-A12C7A8-2A11C7A9-18A10-13A19-10A329-4A22-8A182-3(19A9-)19A10-18A11-16A15-9A21-5A548-8(A-)A11-19A9-19A10-17A12-14A16-11A20-5A571-
