model
size = 27 18 23, scale = 0.05, origin = -y
material deform = 1, fade = true, lighting = smooth, roughness = 0.3, metalness = 0.6
  colors = A:#FFAA57 B:#84492C C:#FEAE89 D:#000 E:#A17A43 F:#FEEA41 G:#037C30 H:#A9523A I:#94453E J:#8E695F K:#FFF L:#01512E M:#259A3E N:#FFA5A5
voxels
249-A-ADA25-DA24-ADA25-DA2-2C21-DA25-D26-D293-A-ADA20-5AD16A5-5AD2A4C2(19-AD2AC2-C)19-AD2A23-ADA24-4D216-A20-8A18-9A17-14A12-20A7-8A5B6C-A6-8A2B9C-4A3-8AB10C9-7AB3C4-3C12-4A3DC20-4D52-D132-2A4-A3-A14-12A14-10A16-11A16-2A8B9A7-3A8D10A6-3A11DB4DCA6-3A2B9F2J3ICA6-A4B6F3B2J2I2C7-2A3B5K2B8C8-2AC6BD2C17-2C4BD22-5D22-2DL2D104-A7-A-A15-2A3-7A13-21A5-15A11-2A8BD5A10-3A5B3-2B-2D4A7-3A9D4B8A3-3A11DB4DC6-4AH10F2J3IC6-2A15B3IC7-2A17BC8-A9B9C9-3C2B3GD19-2CBK3GD21-2DGMLD102-2A-12A12-15A10-16A10-17A8-2A15B2A7-2A7B3-6B2DA6-2A12D5BC7-2A12D6EC6-A-3H8FJ6EC6-2A12B6EC7-2A17BC8-A7B-B9C9-3C2B3GD9C9-3CBD3G-CN5C14-2DL2GD2-2C72-A-7A17-19A7-8A-7A9-22A4-17AC8-AD16BC7-2A7B4-6BC7-2A12D5BC6-3A12D5E2C5-3A4H7FJ5E2C6-3A11B5E2C7-2A16B2C8-A6B2-B9C9-3C2B4G-8C9-3CBD2G-G9C12-2DMGLD2-2C47-6A19-11A15-13A13-8A-6A10-16ABA8-17AC7-2A17BC6-3A17BC7-2A12DE3B-C6-3A12D4EB2C5-3A4H6F2J4EB2C5-4A11B4EB2C6-3A16B2C8-A6B2-B10C8-3C2B3G2-9C8-3CBK2G2-10C11-2DLGMD51-7A17-12A15-13A13-8A-6A10-16AC8-18AC7-2A2(17BC6-3A)12DE3B-C6-3A12D4EB2C5-3A4H6F2J4EB2C4-5A11B4EB2C5-4A14BIB2C7-2AD5B2-B10C8-3C2B2G3-9C8-3C2D4G10C12-DGLGD51-6A18-12A15-13A13-8A-6A10-16AC8-18AC7-2A17BC6-3A17BC5-4A12D3EB-C6-3A12D4E-2C5-3A4H6F2J4E-2C4-5A11B4E-2C5-4A14BI-2C7-2A2D6B2-5C-3C7-A3CD-4G6C-3C8-3C2D4G10C12-DMGMD27-2A20-A-6A18-12A15-13A13-8A-6A10-16AC8-18AC7-2A17BC6-3A17BC5-4A12D5EC6-3A12D4E3C5-3A4H6F2J4E3C4-5A11B5EBC5-4A14B2IBC7-2A4D2-3B10C7-A3C5DF10C8-3C3D-DB10C13-2D-D-2C3-N20-2A20-A-6A18-12A15-13A13-8A-6A10-16AC8-18AC7-2A17BC6-3A17BC5-4A12D4E-C5-4A12D4E3C5-3A4H6F2J4E3C4-5A11B5EBC5-4A14B2IBC7-2A4D2-3B10C7-A3C3D-DF10C8-3C5DB10C13-4D-2C3-N20-2A22-6A18-12A15-13A13-8A-6A10-16AC8-18AC7-2A17BC6-3A17BC5-4A12D4E-C6-3A12D4E3C5-3A4H6F2J4E3C4-5A11B5EBC5-4A14B2IBC7-2A2D7B10C8-3C5DB10C8-3CD-3DB10C13-4D25-A25-6A18-12A14-14A13-8A-6A10-16AC8-18AC7-2A2(17BC6-3A)12D5EC8-2A11D4E3C6-3A2H7F2J4E3C5-4A11B5EBC6-3A14B2IBC8-AD7BD10C8-3C4BD-10C8-3C2D2G-D10C12-DMGLD51-6A18-12A15-13A11-10A-6A10-16AC8-18AC7-3A16BC6-4A16BC7-2A12D5EC7-3A11D4E3C6-3A2H7F2J4E3C6-3A11B5EBC7-2A14B2IBC8-A8BD10C8-3C4BGD10C8-3CBK3GD10C11-2D3GD51-6A20-10A15-13A12-9A-6A10-16AC8-18AC2(7-3A14B3C)8-A12D4EBC8-2A11D4E3C6-3AH9FJ4E3C6-3A11B5E2C7-2A14B2I2C8-A5BI2BD9C9-3C2B-BGD9C9-3CBD3GD9C12-D-LGLD2-2C74-7A18-17A8-8A-6A10-22A3-19A2(7-3A6B11A)2(8-19A)C6-3A-8AFJ4E3C6-3A13B3E2C7-2A15BI2C8-A8BD9C9-3CBI2BGD9C9-3CBD3GDCN5C14-D-MLGD2-2C76-A24-9A15-15A9-15A-A9-2A5B9A10-3A5B9A10-2A6B9A9-20A7-20A8-11A2F3EB2C8-2A2B7F7BC9-ACB6K8BC10-CBKB2-2BD9C9-3C4BGD8C11-2CBK3GD21-2D2GMD137-4A13-21A5-20A6-23A4-17A9-24A3-19A4-A5-9A2B6C10-A9B7C11-A8B7C11-C3BD2BDC4-3C11-2C2BDBD22-2D2GD22-2DL2D164-A-A15-12A2(14-13A)15-15A11-16A11-9A2B5C11-4ABDB9C12-3AD-B3C19-A2D-ADAC20-2D-D26-D24-2D245-2A22-5A22-17A6-8ABA17-6A4C18-6A-C19-6A22-3D-D23-3D24-D273-AC21-D3-AC21-D2-2AC21-D2(2-C)20-2(D26-)D408-2C147-
