model
size = 27 18 23, scale = 0.05, origin = -y
material deform = 1, fade = true, lighting = smooth, roughness = 0.3, metalness = 0.6
  colors = A:#84492C B:#000 C:#FEAE89 D:#A17A43 E:#FEEA41 F:#037C30 G:#A9523A H:#94453E I:#8E695F J:#FFF K:#01512E L:#259A3E M:#1E1729 N:#FFA5A5
voxels
249-B-3B26-B24-B-B29-2C49-B26-B292-B-3B20-2BAB3A15B5-6BMB4C19-M3B2(C2-C19-4B)23-3B24-4B216-B20-8B18-9B17-2BA3BA7B12-B2AB3AB7A4BC7-B12A6C-B6-5B5A9C-4B3-5B4A10C9-4B4A3C4-3C12-C3A3BC5-C14-4B52-B132-2B4-B3-B14-12B14-B8AB16-B9AB16-B10A8B7-12B7ACB6-14BA4BCB6-B2G2A9E2I3HCB6-B4A6E3A2I2H2C7-B4A5J2A4C2A2C8-2BC6AB2C3-2C12-2C4AB22-5B22-2BK2B104-B7-B-B15-2B3-7B13-8B3A10B5-B8A6B11-B9A6B10-B7A3-2A-6B7-12B8A4B3-14BA4BA2B4-B4G10E2I3HA2B4-B16A3HAB6-B19AC7-B9A9C9-3C2A3FB19-2CAJ3FB21-2BFLKB102-2B-12B12-8B4A3B10-2B3A3B6A2B10-B14A2B8-2B15A2B7-B8A3-6A3B6-14B7AB5-14B6DAB5-B-3G8EI6DAB5-B13A7DC6-B19AC7-B7A-A10C8-3C2A3FB9C9-3CAB3F-CN2C17-2BK2FB76-B-7B17-3B7A3B13-2B6A-5A2B9-2B15A5B4-B16AC8-2B16AC7-B8A4-6AC7-14B5AC6-15B5D3C4-B6G7EI5D3C5-B13A5D3C6-B17A3C7-B6A2-A10C8-3C2A4F-9C8-3CAB2F-F10C11-2BLFKB51-6B19-2B6A3B15-2B10AB13-2B6A-5AB10-2B15A5B4-B16AC7-2B17AC6-B19AC7-14BD3A-C6-15B4DA5C2-B6G6E2I4DA5C2-B14A4DA5C3-2B17A4C6-B6A2-A11C7-3C2A3F2-10C7-3CAJ2F2-10C11-2BKFLB51-6B18-3B6A3B15-2B10AB13-B7A-5AB10-2B15A8-2B16AC7-B18AC6-B19AC6-15BD3A-C6-15B4DA5C2-B6G6E2I4DA5C-B15A4DA5C2-3B15AHA5C4-3B5A2-A12C6-3C2A2F3-10C7-3C2B4F11C11-BFKFB51-6B18-3B6A3B15-2B10AB13-B7A-5AB10-2B14AC8-2B16AC7-B18A2C5-B19A2C4-16B3DA-2C5-15B4D-5C2-B6G6E2I4D-5C-B15A4D-5C2-3B15AH-5C4-4B6A2-5C-5C5-B3CB-4F6C-5C6-3C-B4F11C11-BLFLB27-2B20-B-3B2AB18-3B6A3B15-2B10AB13-B7A-5AB10-2B14AC8-2B16AC7-B18A2C5-B19A2C4-16B5D2C5-15B4D6C2-B6G6E2I4D6C-B15A5D4AC2-3B15A2H4AC4-6B2-3A12C5-B3C-4BE12C6-3C-2B-BA11C11-3B-B3C3-C20-2B20-B-3B2AB18-3B6A3B15-2B10AB13-B7A-5AB10-2B14AC8-2B16AC7-B18A2C5-B19A2C4-16B4D-2C4-BG14B4D6C2-B6G6E2I4D6C-B15A5D4AC2-3B15A2H2A3C4-6B2-3A12C5-B3C3B-BE12C6-3C-4BA11C11-5B3C3-C20-2B22-3B2AB18-3B6A3B15-2B10AB13-B7A-5AB10-2B14AC8-2B16AC7-B18A2C5-B19A2C4-16B4D-2C5-15B4D6C2-B6G6E2I4D6C-B15A5D4AC2-3B15A2H2A3C4-4B7A12C6-3C5BA11C7-3CB-3BA11C12-4B25-B25-6B18-3B6A3B14-3B10AB13-B7A-5AB10-2B14AC8-2B16AC7-B18AC6-B19AC6-15B5DC8-13B4D6C3-B4G7E2I4D6C2-B14A5D4AC3-2B15A2H2A2C6-2B7AB11C7-3C4AB-11C7-3C2B2F-B11C11-BLFKB51-6B18-3B6A3B15-2B10AB11-3B7A-5AB10-2B14AC8-2B16AC7-B18AC6-B19AC7-14B5DC7-14B4D5C4-B4G7E2I4D5C4-B13A5DA3C5-B15A2HA3C6-B8AB11C7-3C4AFB11C7-3CAJ3FB10C11-2B3FB51-6B20-B6A3B15-2B10AB12-2B7A-5AB10-2B14AC8-2B14A2(3C7-B16A)3C8-13B4DAC8-13B4D4C5-B3G9EI4D4C5-B13A5D3C6-B15A2H3C7-B5AH2AB9C9-3C2A-AFB9C9-3CAB3FB9C12-B-KFKB78-7B18-2B7A3B13-2B6A-5AB10-2B15A5B3-2B14A2(3C7-B16A)3C8-13B3D2AC8-13B4D3C6-B2G-9EI4D4C5-B15A3DC8-B16AHC9-B8AB9C9-3CAH2AFB9C9-3CAB3FBCN2C17-B-LKFB80-B24-9B15-8B4A3B9-3B12A-B9-B14A2(C10-B15A)C9-BAB2A9B2D3AC7-BAB2A9B3DA2C8-2B2A9E3DA2C8-2B2A7E7AC9-BCA6J8AC10-CAJA2-2AB9C9-3C4AFB8C11-2CAJ3FB21-2B2FLB137-4B13-21B5-B12A7B6-B13A2B11-B13A3B9-3BA9BD4A5B4-3BA9B4D2C10-B10A6C10-B2(9A7C11-)C3AB2ABC4-3C11-2C2ABAB22-2B2FB22-2BK2B164-B-B15-12B2(14-13B)15-6B3A2C4B11-7B8AC11-B10A5C11-B4ABA9C12-B2AB-A3C4-2C13-3B-3BC5-C14-2B-B26-B24-2B245-2B22-3BAC22-3B2A10B8-7B2AB17-6B4C18-5BC-C19-4B-B22-2(B-)B23-3B24-B273-2C25-2C24-3C24-C2-C483-2C147-
