model
size = 31 31 13, scale = 0.05, origin = -y
material deform = 1, fade = true, lighting = smooth, roughness = 0.3, metalness = 0.6
  colors = A:#111 B:#3F0 C:#888 D:#FFF E:#9CF
voxels
135-B7-B23-B5-B25-B3-B27-B-2(B29-)B-B27-B3-B25-B5-B23-B7-B25-3B26-7B24-B5-B25-4B26-B4-2B24-B2-B3-B22-B7-B22-B2(-2B)-B22-2(B2-)B-B23-B6-B24-B4-B26-4B209-3(11A20-)AB7ABA20-B9AB7(20-11A)20-BD7A2B19-2ABA5BAB2A2(18-13A)17-5A5B5A16-11AB4A14-8AB3A2B3A14-12A2B3A13-13A2B4A12-7A2(B2A)2B4A11-14A2B5A10-7ABD5AB6A11-7A6B6A13-17A17-11A143-13(A11-A18-)A11-A17-2A11-2A16-A13-A15-2A13-2A14-A15-A13-2A15-2A12-2A15-2A11-3A15-3A9-2(4A15-4A8-)4A15-4A9-4A13-4A11-5A9-5A13-17A16-13A21-7A82-14(A13-A16-)A13-2(A15-)A196-4A17-4A5-5A17-5A6-4A15-4A9-2(5A11-)4A11-A2CA13-17A16-13A21-7A50-15(A15-A14-)A15-A226-3A21-3A3-5A19-5A4-6A13-6A7-6A11-6A9-5A11-2AC2A12-5A7-5A16-3A7-3A21-A5-A19-15(A15-A14-)A15-A256-3A23-3A-5A21-5A2-3A21-3A6-5A13-5A9-5A11-5A13-2A11-2A18-3A5-3A17-15(A15-A14-)A15-A256-3A23-3A-5A21-A2C2A-4A21-AE2A4-3A19-ACA7-6A11-6A10-4A11-4A16-A9-A17-15(2A14-A14-)A15-A256-3A23-3A-5A21-2AC2A-4A21-4A4-3A19-3A7-6A11-6A10-4A11-4A16-A9-A17-15(2A14-A14-)A15-A256-3A23-3A-5A21-5A2-3A21-3A6-5A13-5A9-5A11-5A13-2A11-2A18-3A5-3A17-15(A15-A14-)A15-A226-3A21-3A3-4A21-4A6-A19-3A7-4A15-4A2(9-6A)12-6A5-6A16-4A5-4A21-7A19-15(A15-A14-)A15-A196-3A19-3A5-A-3A17-5A7-3A15-4A9-4A13-4A11-19A13-17A16-13A21-7A51-15(A13-A16-)A13-2A2(14-A15-A)13-2A15-2A12-2A15-2A11-3A15-3A9-2(4A15-4A8-)5A13-5A10-4A11-5A11-6A7-6A13-17A16-13A20-9A82-14(13A18-)14A2(16-15A)15-17A14-17A13-2(19A12-)19A11-21A10-21A11-19A13-17A17-11A134-
