model
size = 12 21 11, scale = 0.05, origin = -y
material deform = 1, fade = true, lighting = smooth, roughness = 0.3, metalness = 0.6
  colors = A:#111 B:#C96 C:#222 D:#DDD E:#F96 F:#60C G:#CC3 H:#99F I:#C36 J:#060 K:#306 L:#9CF
voxels
16-A11-6(A-A9-)4(C-C9-)2(C-)F2(7-2(C-)G)7-2(C-)B7-CAC9-CAC72-5(A11-)6(A9-A-)A4B5-A-AB4-7A5-3A2(CA)B4-3A2(CA)5-3A2(CA)6-A4CA22-2(A9-A-)A-5(A7-2(A-))A7-2(C-)A5-A2(-C)-A5-A2(-C)2A5-A2(-C)A6-A-2CA4B3-A-2C2A4B-2A-2C2A3B2-ABA2C2A2BD-2A2B2C2AD2B-2A2B2C2AHBF-2A2B2C2A2B4-A3C4A113-3(A9-A-)A-C5B2-2(A-)CA4B2-A-A2C2A3B2-A-A2C2A-2B-A2BA2C2AJLK-A3B2C2A2DB-A3B2C2AHBF-A3B2C2A3B2-2A3CB4A6-CA102-2(A11-)A4-4B3-A3-C5B2-A3-CA3BI2-A-B2CA4B2-A2B2C5B-A3B2C2B3D-A3B2CBE2DB-A3B2CBE2BF-A3B2C5B2-2A3CB4A5-2CA103-2(A11-)A3-4B4-A2-C5B3-A2-CA3BI2-2AB2CA4B2-A2B2C6BA3B2C5B2(-A3B2C2E3B)-A3B2C5B2-2A3CB4A5-2CA129-C-4B5-A2C5B2-2(A-)C4BI2-A-A2C5B2-3A2C5B-AB2A2C2B3D-AB2A2CBE2DB-A3B2CBE2BF-A3B2C5B2-2A3CB4A5-2CA96-A11-5(A5-)2(A3-C2A3B2-)A2-2C2A3B2-A-A2C2A-2B-AB2A2C2AJLK-AB2A2C2A2DB-A3B2C2AHBF-A3B2C2A3B2-2A3CB4A6-CA47-4(A11-)2(A8-C2-)2(A6-A-C2-)A6-A-C-3A3B2-A-C-3A4B-A-C3A-3B2-2AC4A2BD2-2AC4AD2B2-ABC4AHBF2-ABC4A2B4-A2C5A81-A10-2A8-A-2A6(8-A2-A)-3B4-A2-AB6-2C3A7-2C3AB5-2(A2C3A6-)A2C3A32-2(A11-)9(A-A9-)2(A-)F2(7-2(A-)G)7-2(A-)B7-3A9-3A41-
