model
size = 14 15 11, scale = 0.05, origin = -y
material deform = 1, fade = true, lighting = smooth, roughness = 0.3, metalness = 0.6
  colors = A:#FB0 B:#FFBC74 C:#222 D:#FFD000 E:#F6A869 F:#F19448 G:#C38654 H:#FE0 I:#E5E5E5 J:#C1C1C1 K:#1A97B7
voxels
73-4(2(AD)A2DAD5-)2(AD)A2DAD131-6(9A5-)4(AD)A2(5-3(AD)A2D)61-2(10B4-)8(8AD5-)8AD61-2(10B4-)9A5-9A2-D5(ADC9A2D)ADC9AD3-10AD3-3(AD)3A5-9D8-6C5-3(10B4-)3A6B2E3-9B2E2AD10CE2A3(D8C5A)D10C3AD10CA-AD11A-AH9A4-10A8-7C2(4-10B)2-2E10B2-ED3A6B2E-ED9BEGDCD9B2E2(DAD10B-)DAD8B3ADAD9BC2(AD)10CA-AC11A-AH9A4-10D8-C4B2C2(4-10B)2-2E10B2-GE9BC2-2E10B-3A3(10B-A2C)8B2ADA2C9BCDA12CD-AC10AD-AH9A4-10A8-C4BCE4-10B4-6BG3B4-10B4-4B3G3B4-A5B2FBC4-A5B2F2B-D3A3BCB2FCB-D3A5B2FCB-D3AC8B-D3AC5B2CB-D3A5C2B2CA-13A-AH9A4-10D8-7B5-4B3G2B5-4B3I2B2(5-E8B)4-ABJKJ2B3C4-AB3F2B3C3-DA3BEB4C3-DA4BCBE2B3-D2AB2C5B3-D2A2C6B-4A2C3A2B2CD4-9AD2-A9D11-3D67-B51-3A2-3A40-2A6-8A194-2A9-5A29-
