model
size = 9 11 5, scale = 0.05, origin = -y
material deform = 1, fade = true, lighting = smooth, roughness = 0.3, metalness = 0.6
  colors = A:#222 B:#717171
voxels
65-3(5A4-)5A2-3A3(6(3-6A)3-42A)6(3-6A)3-33A3B3A
