model
size = 28 32 32, scale = 0.05, origin = -y
material deform = 1, fade = true, lighting = smooth, roughness = 0.3, metalness = 0.6
  colors = A:#EEE B:#0E0 C:#050
voxels
181-2A51-A6-A43-A5-A4-A5-A15-A2-2A2-A78-A2-A16-B2-A12-A2-B10-B14-B12-B14-B10-B2-A12-A2-B16-A2-A78-A2-2A2-A15-A5-A4-A5-A43-A6-A51-2A278-2A51-A6-A43-A5-A4-A5-A15-A2-2A2-A78-A2-A16-B2-A12-A2-B10-B14-B12-B14-B10-B2-A12-A2-B16-A2-A78-A2-2A2-A15-A5-A4-A5-A43-A6-A51-2A409-B2(2-A)2-2A2(2-A)2-B42-A6-A46-A4-2A4-A46-A6-A20-A6-A46-A4-2A4-A46-A6-A42-B2(2-A)2-2A2(2-A)2-B404-A10-A99-A2-A6-A2-A95-C8-2A8-C45-2A26-2A45-C8-2A8-C95-A2-A6-A2-A99-A10-A242-C6-C18-B2-B4-B2-B18-A6-A20-A6-A79-2A47-B3-A2-2A2-A3-B42-2(A-)A2-2(A-)A44-A-8A-A16-A-8A-A44-2(A-)A2-2(A-)A42-B3-A2-2A2-A3-B47-2A79-A6-A20-A6-A18-B2-B4-B2-B18-C6-C353-B2-A6-A2-B41-B3-A2-2A2-A3-B38-B3-A-8A-A3-B12-3(12A16-)12A12-B3-A-8A-A3-B38-B3-A2-2A2-A3-B41-B2-A6-A2-B356-2A157-C2-A5-2A5-A2-C9-C16-C11-16A12-C14AC10-A2-14A2-A10-3(16A12-)16A10-A2-14A2-A10-C14AC12-16A11-C16-C9-C2-A5-2A5-A2-C157-2A138-2B23-2(A6-A48-)A6-A17-B5-2A5-B17-A6-A14-C2B14A2BC8-20A8-2C16A2C7-2AC16AC2A4-B-C20AC-B5-BC16ACB2(8-C18AC)8-BC16ACB5-B-C20AC-B4-2AC16AC2A7-2C16A2C8-20A8-C2B14A2BC14-A6-A17-B5-2A5-B17-2(A6-A48-)A6-A23-2B129-C2-A12-A2-C61-C2-C18-C2-C34-2CBA-8A-AB2C10-18A7-B22AB6-B18AB3(8-20A)2(8-B18AB)3(8-20A)8-B18AB6-B22AB7-18A10-2CBA-8A-AB2C34-C2-C18-C2-C61-C2-A12-A2-C179-C12-C97-AC12ACA11-18A9-B18AB2(8-20A)7-22A4-B-22A-B4-3(22A6-)22A4-B-22A-B4-22A7-2(20A8-)B18AB9-18A11-AC12ACA97-C12-C185-A6-A51-2A15-A-B2AC12AC2AB-A8-16A11-18A6-A-22A-A5-20A7-9(22A6-)22A7-20A5-A-22A-A6-18A11-16A8-A-B2AC12AC2AB-A15-2A51-A6-A106-A2-A25-2A48-A5-2A5-A45-8A17-14A13-16A11-18A9-2(20A8-)20A7-22A4-26A3-3(24A4-)24A3-26A4-22A7-2(20A8-)20A9-18A11-16A13-14A17-8A45-A5-2A5-A48-2A25-A2-A100-A2-B2-A6-A2-B2-A15-6A21-8A11-A5-14A5-A7-16A11-18A9-2(20A8-)20A6-7(24A4-)24A6-2(20A8-)20A9-18A11-16A7-A5-14A5-A11-8A21-6A15-A2-B2-A6-A2-B2-A98-B6-B71-B3-10A3-B15-B6AB20-8A17-14A8-A-22A-A2-A3-18A3-A5-2(20A8-)20A5-A-22A-A3-24A4-24A2-56A2-24A4-24A3-A-22A-A5-2(20A8-)20A5-A3-18A3-A2-A-22A-A8-14A17-8A20-B6AB15-B3-10A3-B71-B6-B77-6A18-A2-8A2-A17-8A20-8A17-14A13-16A11-18A9-20A7-22A7-20A7-22A5-24A4-24A3-26A2-26A3-24A4-24A5-22A7-20A7-22A7-20A9-18A11-16A13-14A17-8A20-8A17-A2-8A2-A18-6A107-4A23-6A21-8A19-10A16-14A14-14A13-16A11-18A9-2(20A8-)20A7-22A4-26A3-24A3-26A2-26A3-24A3-26A4-22A7-2(20A8-)20A9-18A11-16A13-14A14-14A16-10A19-8A21-6A23-4A53-2A20-C-2A-4A-2A-C19-B2AB15-A3-B-10A-B3-A12-10A11-A2-18A2-A9-14A7-A2-A-18A-A2-A5-18A8-22A7-20A7-22A6-22A5-24A4-24A2-56A2-24A4-24A5-22A6-22A7-20A7-22A8-18A5-A2-A-18A-A2-A7-14A9-A2-18A2-A11-10A12-A3-B-10A-B3-A15-B2AB19-C-2A-4A-2A-C20-2A26-2A20-C-2A-4A-2A-C19-B2AB15-A3-B-10A-B3-A12-10A11-A2-18A2-A9-14A7-A2-A-18A-A2-A5-18A8-22A7-20A7-22A6-22A5-24A4-24A2-56A2-24A4-24A5-22A6-22A7-20A7-22A8-18A5-A2-A-18A-A2-A7-14A9-A2-18A2-A11-10A12-A3-B-10A-B3-A15-B2AB19-C-2A-4A-2A-C20-2A53-4A23-6A21-8A19-10A16-14A14-14A13-16A11-18A9-2(20A8-)20A7-22A4-26A3-24A3-26A2-26A3-24A3-26A4-22A7-2(20A8-)20A9-18A11-16A13-14A14-14A16-10A19-8A21-6A23-4A107-6A18-A2-8A2-A17-8A20-8A17-14A13-16A11-18A9-20A7-22A7-20A7-22A5-24A4-24A3-26A2-26A3-24A4-24A5-22A7-20A7-22A7-20A9-18A11-16A13-14A17-8A20-8A17-A2-8A2-A18-6A77-B6-B71-B3-10A3-B15-B6AB20-8A17-14A8-A-22A-A2-A3-18A3-A5-2(20A8-)20A5-A-22A-A3-24A4-24A2-56A2-24A4-24A3-A-22A-A5-2(20A8-)20A5-A3-18A3-A2-A-22A-A8-14A17-8A20-B6AB15-B3-10A3-B71-B6-B98-A2-B2-A6-A2-B2-A15-6A21-8A11-A5-14A5-A7-16A11-18A9-2(20A8-)20A6-7(24A4-)24A6-2(20A8-)20A9-18A11-16A7-A5-14A5-A11-8A21-6A15-A2-B2-A6-A2-B2-A100-A2-A25-2A48-A5-2A5-A45-8A17-14A13-16A11-18A9-2(20A8-)20A7-22A4-26A3-3(24A4-)24A3-26A4-22A7-2(20A8-)20A9-18A11-16A13-14A17-8A45-A5-2A5-A48-2A25-A2-A106-A6-A51-2A15-A-B2AC12AC2AB-A8-16A11-18A6-A-22A-A5-20A7-9(22A6-)22A7-20A5-A-22A-A6-18A11-16A8-A-B2AC12AC2AB-A15-2A51-A6-A185-C12-C97-AC12ACA11-18A9-B18AB2(8-20A)7-22A4-B-22A-B4-3(22A6-)22A4-B-22A-B4-22A7-2(20A8-)B18AB9-18A11-AC12ACA97-C12-C179-C2-A12-A2-C61-C2-C18-C2-C34-2CBA-8A-AB2C10-18A7-B22AB6-B18AB3(8-20A)2(8-B18AB)3(8-20A)8-B18AB6-B22AB7-18A10-2CBA-8A-AB2C34-C2-C18-C2-C61-C2-A12-A2-C129-2B23-2(A6-A48-)A6-A17-B5-2A5-B17-A6-A14-C2B14A2BC8-20A8-2C16A2C7-2AC16AC2A4-B-C20AC-B5-BC16ACB2(8-C18AC)8-BC16ACB5-B-C20AC-B4-2AC16AC2A7-2C16A2C8-20A8-C2B14A2BC14-A6-A17-B5-2A5-B17-2(A6-A48-)A6-A23-2B138-2A157-C2-A5-2A5-A2-C9-C16-C11-16A12-C14AC10-A2-14A2-A10-3(16A12-)16A10-A2-14A2-A10-C14AC12-16A11-C16-C9-C2-A5-2A5-A2-C157-2A356-B2-A6-A2-B41-B3-A2-2A2-A3-B38-B3-A-8A-A3-B12-3(12A16-)12A12-B3-A-8A-A3-B38-B3-A2-2A2-A3-B41-B2-A6-A2-B353-C6-C18-B2-B4-B2-B18-A6-A20-A6-A79-2A47-B3-A2-2A2-A3-B42-2(A-)A2-2(A-)A44-A-8A-A16-A-8A-A44-2(A-)A2-2(A-)A42-B3-A2-2A2-A3-B47-2A79-A6-A20-A6-A18-B2-B4-B2-B18-C6-C242-A10-A99-A2-A6-A2-A95-C8-2A8-C45-2A26-2A45-C8-2A8-C95-A2-A6-A2-A99-A10-A404-B2(2-A)2-2A2(2-A)2-B42-A6-A46-A4-2A4-A46-A6-A20-A6-A46-A4-2A4-A46-A6-A42-B2(2-A)2-2A2(2-A)2-B256-
