model
size = 24 31 15, scale = 0.05, origin = -y
material deform = 1, fade = true, lighting = smooth, roughness = 0.3, metalness = 0.6
  colors = A:#FFF B:#EEE C:#009B00 D:#00B100 E:#008600
voxels
5-4B6A2B2A10-2B4AB3A2(BA)10-EC2EC5E2DCD10-ED2(2CE)CDCEDC10-2ED2(C2E)2D3E10-2DC3D3ECDE2D10-E2D2(CD2E)CDE10-DCBEDB2DA2CBEC10-ECB2CACDA2DBDC10-DC2BAECDBA2BCE10-ECB2(EDA)CEA2E10-2D4B2E2A2BCE10-2CD2(EC)DEC2DCE10-CEA2BA2D3ABED10-DCADEADC2(A2E)10-ECBAEBDEBEDB2C10-E3DCBECBDCBCE10-EC2(BA)EC2A2BDE10-D2(2EC)3ECECD10-2D2CED2E2CEC2E10-CDC2BAB2A2BC2D10-DC2A3B2ABAB2E10-E3A6-2BAE10-2BA8-2AB10-2A10-B2(A10-B12-)B10-B12-B80-2BA4BABA2B3ABAB6-3A2BA3B2(AB)3A2B6-2C6A2B3AB2AEC6-EDBA2B3A2(2BA)BED6-CD4A2(BA)4B2AEC6-DC2A3B4ABA2BADC6-2D2A4B2A2B2(AB)ED6-DEB4AB2A2B2(AB)CE6-DCAB7A2B3ACD6-2E3A2BA3B4ABCD6-2C3(2AB)3A2BDE6-DEB2ABA3BAB4ACE6-2C3A4B2A4BA2D6-DE2(A2B)2AB5ADE6-DE5B5A2(BA)CD6-CE2(2BA)4B4A2E6-DC5BA4B3ABCD6-CE3BA3B2A3BAB2D6-AC2B6AB4ABDA6-AE2ABA2B2(AB)4AEA6-BD3BABA2BA4BADA6-BCBA3BAB5ABADA6-BE3(AB)2A2(BA)2BEA6-ADB2AB6-B3ADA6-A2BAB8-B3AB6-BAB12-BAB6-BAB12-2BA7-2A12-BA9-B12-B55-2(2BA)BAB2-ABA6B4-B5ABAB2-B3ABA2BA4-EBAB5A2-2(AB)4AE4-DABA4BA2-8AE4-E2A2B2ABA2-4AB3AE4-C2ABA2BAB2-2A2BAB2AD4-D2(BA)3BA2-3B5AC4-DABA2B3A2-2BA2B2ABE4-E4ABA2B2-5B2ABD4-D2(AB)4A2-A4BA2BE4-C3A3BAB2-2B6AC4-D8B2-3A5BD4-C2BABA2BA2-A5BABC4-E4A2BAB2-A6BAD4-EB3A2(BA)2-2A2(2BA)D4-C2A4B2A2-BAB2A2BAE4-D8A2-A2B2A3BD4-BA3BAB2A2-BA2B3ABA4-2BAB3A2B2-3ABAB3A4-3AB4AB2-A2B2A3BA4-A2B2A2BAB2-BAB2A2B2A4-ABA3B3A2-2A3B2(AB)4-BAB-BA8-AB-ABA4-2AB-B10-B-ABA4-3B14-3A4-3B14-3B4-B2A14-3B5-BA14-2B7-A14-A8-A14-B29-2A5-BA4-AB5-2B2-2B5-2B4-2B5-2B2(2-CB5-2A4-2B5-AC)2-DA5-AB4-2B5-AC2-DA5-BA4-2A5-AC2-EA5-BA4-BA5-BC2-CA5-BA4-2B5-BE2-EB5-BA4-2A5-AD2-EB5-AB4-BA5-AE2-CB5-AB4-2A5-BE2-DB5-2A4-BA5-AE2-EB5-BA4-AB5-BE2-CA5-BA4-AB5-BC2-DA5-2A4-2B5-AD2-EB5-2B4-2B5-BE2-BA5-2B4-2B5-2A2-2B5-AB4-BA5-2A3-A5-2B4-2B5-A172-B18-B3-2B18-BA2-2BA16-2BA3-AB16-2A27-2(B20-B2-)E3(20-E2-C)20-D2-C20-C2-C20-E2-D20-C2-C20-D2-E20-D2-D20-E2(2-C20-C)2(2-E20-C)2-A20-A2-B20-B218-2(A20-B2-)A20-B3-BA16-2A2-B22-AB22-BC22-DC22-EC22-2C22-ED22-2C22-2E22-DC22-C2(D22-E)C2(22-CD)22-CA22-BA22-A264-A22-2A22-A-BAB16-3B-B22-2A22-BD22-DC22-E2(C22-D)C22-CD22-DC22-CD22-CE22-2C22-ED22-2D22-2C22-DB22-AB22-B264-B22-BA22-A-2A18-2A-B22-AB22-BA13(22-2A)22-2B22-A264-B22-AB22-B-AB18-2A-A22-2B22-BC22-2D22-2C22-CE22-2E22-2D22-2C22-EC22-CD22-DC22-ED22-EC22-2D22-EB22-2A22-A264-B22-2A22-A-2A18-AB-B22-2A22-AC22-CD22-2C22-DC22-DE22-CE22-ED22-DC22-2E22-D2(E22-C)D22-DC22-CB22-2B22-B264-B22-AB22-B-BAB16-A2B2-A20-B2-A20-A2-D20-E2-E20-C2-C20-C2-E20-E2-D2(20-C2-D20-D2-E)20-D2-C20-E2-D2(20-E2-C)20-C2-C20-E2-A20-A2-A20-B218-B20-A2-A20-A2-B20-B3-AB16-2B3-2A18-2B2-BA18-2A2-2E18-EC2-DB18-BE2-EA18-AC2-DB18-BE2-EB18-AE2-EB18-BD2-DB2(18-AD2-DA)18-AC2-DB18-AD2-CA18-BC2-CB18-AD2-EA18-AE2-DB18-BC2-2A18-2B2-2B18-2B3-B18-A172-A18-B3-2B18-AB2-2A18-BA3-2A16-2B28-2AB14-ABA4-B2A14-2AB4-E2A2(14-ABD4-EBA)14-2AC4-D2A14-2AE4-E2A14-ABE4-DAB14-2BE4-D2B14-BAE4-D2A14-BAD4-D2A14-2BD4-EBA14-2AC4-E2A14-ABD4-EBA14-2BE4-CAB2(14-ABD4-DBA)14-2BC4-BAB14-2BA4-2BA14-2AB4-2BA14-3A4-2BA14-ABA4-ABA14-2BA4-BAB14-A2B4-B2A14-3B4-ABA14-3A4-BAB14-BAB4-2(BA)12-2(BA)4-3A14-2AB5-B16-B54-2B4AB2A3B6A6-BA2B2A2B5A3B2A6-ED5A2BA2B2ABACD6-CDB2ABAB2A3BABA2E6-DEABA3B3AB2A2BCD6-2C2AB5A4BAB2E6-DCBAB4AB2A3BACD6-DE2B3A4(BA)BEC6-2EB3ABA4B2ABADC6-CDA3BA5B2(AB)2C6-2C2(A2B)2A3BA2BEC6-DEB4AB3ABA3B2D6-EDBAB4ABAB2ABADC6-DE2A4BAB2(A2B)DC6-DEAB3A2BA4BAB2E6-2EA4B3A2BA3B2C6-2D2B4AB7ADC6-DC2(BA)3BA3B2ABCD6-CD3ABA2BAB4ABCD6-AD4B2A2B2A4BDB6-ACA5BA3B2(AB)DB6-AC6B3A2B2ABCA6-AE2B2A5B2AB2ACB6-ADAB10-2ADA6-3A12-3B6-3B12-A2B6-2A14-AB7-B14-A81-2AB4A2B2ABAB10-3AB4A2B2(AB)10-2CD2EC2DECDCED10-CEC3E2(DC)EDCD10-C2(D2C)2DCDCEC10-CEDECD2C3DE2C10-EDCAB2C3ABC2E10-DCD2ADCABA2BCE10-C2EBADCEDC2BDC10-DCDAB2(ED)E2BEC10-E2D2B2(CE)D2A2D10-C2E2ACED3BAED10-2ED2ADCD3BA2E10-EDCABE2C2D2ADC10-2CE2B3DCD2B2C10-CDB2A2EA3BAED10-C2EAB2E2BABDED10-DC3D2E2CE2D2E10-CDE2C4EDCDED10-D2CDCEC2D2ECDE10-CE4C3(ED)EC10-CBA9BAD10-2BA8-B2A2(10-2B)2(10-A12-A)125-
