model
size = 30 21 15, scale = 0.05, origin = -y
material deform = 1, fade = true, lighting = smooth, roughness = 0.3, metalness = 0.6
  colors = A:#FFF B:#EEE C:#E31F17 D:#EC4D38 E:#E62E22 F:#5FF G:#EF5D44 H:#7FF I:#E93E2D J:#F26C4F K:#9FF L:#E00F0B M:#D00 N:#F7CB39 O:#F7D45F P:#F7DC85
voxels
5-JLMDC10-DEDJG608-2MIDLJCLC6-IMDI2DEGC8-2D3G10-MIDGC10-GJC2E10-DGIEI10-GJC2I10-MG2EL10-IGL2C10-DMDEJ487-ILE5-2IL4-DID5-MJG5-CE5-IE6-DM5-GC6-2D5-JI6-CJ5-CD6-JG5-IE6-2G5-2D6-CL5-ED6-CL5-LG8-2A2BA10-A3BA10-AB3A10-A4B10-3ABA10-AB3A10-4BA10-BA2BA10-B2A2B10-4BA10-B4A10-BAB2A10-2ABAB10-ABA2B10-2(BA)5-BA5-A3B10-4B4-2A2B4-3AB10-B3A4-4B4-3BA10-2(A2BA4-)2ABA10-BA2B4-AB2A4-A2BA10-2ABA4-4A4-B3A10-K2HK12-HKFK10-2FKH12-2(HF)10-2H2K12-H3F6-DGI7-2CL2-GLJ7-ELG3-LJ7-2C4-DE7-IJ4-GJ7-ED4-CD7-2C4-DM7-GI4-2D7-LC4-CM7-GL4-JL7-JI6-A5-A8-A5-B8-A5-A8-B2(5-A8-A)5-B8-A2(5-B8-B)5-A8-B5-B8-A5-B3-2B3-A5-A8-B5-2A-2B2A-AB5-A8-B4-4BABA2B2AB4-A8-A4-2B2A3B2AB2A4-B8-B4-ABA2(2B2A)B4-A8-A4-3ABA3B2(AB)4-A8-A4-3BAB3A2B2A4-B8-B4-3BA2BAB4A4-A8-K4-KHFHKFK2H3F4-F8-K4-2K2(FK)2HFKHK4-F8-F4-KFK2FK4FKF4-H5-JE9-GC2-GM9-EM3-M9-E4-G9-E4-D9-D4-M9-G4-E9-C4-C9-E4-E9-G4-J9-I5-B7-A6-A3(7-A6-B)7-B3(6-B7-A)6-A7-A6-B7-A6-A7-B-2BAB-A7-B6-A7-3B4AB7-A6-A9-A2BA9-A6-B8-2BA3B8-A6-B8-3(BA)8-A6-A8-AB2ABA8-B6-A8-ABA2BA8-A6-B8-AB2A2B8-A6-H22-H6-F22-F6-K22-H3-ED11-J2-G11-EG-J11-C2-E11-C2-I11-E2-C11-C2-L11-D2-J11-G2-I11-I2-D11-D3-2(B9-A4-)A9-A3(4-A9-B)4-B9-A4-A9-B4-A9-A4-A9-B4-B9-AB4A9-A2(4-A24-A4-B24-B)4-B24-B4-B24-A4-A24-A4-H24-F4-F24-H4-H24-K2-GI11-L2-I11-CG-D11-G2-L11-D2-M11-C2-G11-I2-D11-G2-C11-E2-D11-C2-M11-C3-3(B9-B4-)A9-B4-B9-A4-A2(9-A4-B)9-A4-A9-BA2-BA9-A4-B10-2ABA10-2(A4-A24-)B4(4-A24-A)4-A24-B4-K24-F4-H24-H4-H24-K2-CD11-E2-J11-MG-I11-J2-E11-L2-D11-C2-I11-M2-E2(11-D2-J)11-G2-J11-D3-2(B9-A4-)2(A9-B4-A9-A4-)A9-A4-B9-B4-A9-2B2-BA9-A4-A10-A2BA10-B4-B24-A4-A3(24-B4-B)24-B4-A24-A4-B24-A4-H24-K4-F24-K4-H24-F2-MD11-L2-E11-2E-E11-L2-I11-D2-L11-C2-L11-E2-L11-M2-C11-C2-G11-J2-M11-I3-B9-A2(4-A9-B)4-B5(9-B4-A)9-2B2-2B9-A4-B9-3(BA)9-A2(4-A24-B)4-B24-A4(4-A24-B)4-K24-H4-H24-K4-H24-H2-GJ11-G2-D11-JE-D11-L2-L11-D2(2-M11-E)2-J11-E2-M11-I2-J11-E2-I11-E3-2(A9-A4-)2(B9-A4-A9-B4-)B9-B4-B9-A4-B2(9-B4-A)2(9-A4-A)9-A2B3A9-3(A4-B24-)2(B4-A24-)A4-A24-B4-K24-F4-F24-F4-K24-H3-EI9-IL2-2J9-MC3-I9-G4-L9-M4-C9-M4-M9-E4-G9-J4-M9-I4-C9-G4-L9-J5-2(A7-B6-)A7-A6-A7-B2(6-B7-A)2(6-A7-A)2(6-B7-A)6-A2(7-B6-B)7-2BABA3B7-B6-A2(22-A6-B)2(22-B6-B)22-A6-A22-B6-K22-K6-F22-F6-H22-F4-CGE7-CIC2-EME7-EDE3-GL7-ED4-GL7-LJ4-ED7-DC4-CI7-DM4-CE7-LM4-JC7-MD4-GD7-2C4-2I7-JI6-B2(5-A8-B5-B8-A)5-B8-B5-A8-A5-B2(8-A5-A)8-B5-B8-A2(5-B8-B)5-BA3B5A5-B8-A8-2B2A8-A8-B9-BA9-B8-A9-AB9-A8-A9-BA9-2(A8-)4A2(8-A)7-4BAB7-B8-FKH4F2K2HF2HK3HFK2H8-HF2(KH)2FHKHFH3FH2FK2F8-FK2H2FHF3KHKH2KFH2F2K6-MJM5-MJC4-IGI5-M2E5-DC5-2M6-EM5-CL6-IL5-2G6-GL5-LI6-JL5-LE6-CD5-EJ6-DL5-CJ6-ED5-GC8-7B6-A2B2(AB)10-A2B2ABA6-2(BA)2BA10-2(AB)2AB6-4B3A10-A2BAB-A6-A-2A3B10-3A2(BA)B4-AB2A2B2A10-5B3-A2-A3-3A2B9-A2-2BA6-A3-3A2-B8-B2-2AB3-B2A4-BAB2-A8-B2-2BA4-2B4-A2B2-B2(8-B9-2B9-A)8-AB7-A2-B7-BA8-2AB2A3BA4-A5BA2B11-2A3B6-2A3B70-CE2LGELMC6-GJD2EIGLE8-3M2D10-DM2CI10-CG2CL10-L3JM10-JCIDC10-EJM2G10-MICJI10-CICGE103-3A8-BAB14-3A2BAB4-B2A2B2A12-2A4B2A2-2A4B2A11-B2OPAONPA2-AOANBOBPA10-BNAPBNANB2-ANAOANBOB10-3(BP)ABA2-AOPNBA2OB10-3(AO)BAB2-BPAOANAPA10-B3NAO2NA2-A3NBO2PB11-2ABAB2AB2-2ABA3BA12-3A3BA4-2A2B2AB14-A2B8-3A73-2(LJ)M10-DCIDE605-
