model
size = 32 18 12, scale = 0.05, origin = -y
material deform = 1, fade = true, lighting = smooth, roughness = 0.3, metalness = 0.6
  colors = A:#FFF B:#000E0F C:#001D1F D:#000 E:#0086A1 F:#002C2E G:#003A3E H:#00494D I:#00F2FF J:#00676D K:#00585D L:#008E96 M:#00A2AB N:#007A81 O:#00CAD5 P:#00B6C0 Q:#001C23 R:#00DEEA
voxels
23-5I2(12-20A)12-20D13-19B15-17C17-15F19-13G20-4HA7H21-4KA6K22-4JA5J23-2NANA4N24-2LALA3L24-3MAMA2M25-3PAPA26-4OAO27-4RA27-5I2(11-7A8-6A)11-7D8-6D12-5B9-6B26-6C26-6F27-4G28-4H29-2K298-2(26A6-)26D7-25B9-23C16-16F18-14G19-4HAH4E3H20-4KAK2E3K22-4JA4J24-2NANA3N25-2LALA2L25-3M2(AM)26-3PAPA26-4OAO27-4RA2(27-5I)6-13AQ15A3-29A3-12D13E4D5-27B6-26C11-21F14-18G16-16H17-15K18-14J19-12N21-11L22-M2E6ML22-3P7A23-8OP23-2R7A2(24-8I)3-14A7Q10A-31A-D27E3D2-30B4-28C8-5F16-3F12-2G15-3G14-H14-3H15-A13-3K16-J12-3J17-A11-3N18-2L9-2L20-A3M6-2M20-4P6-2A21-AEO6-2O21-ROR6-2A22-AI6-2I22-2I6-2I2-14A8Q42AD27E4D-31B3-12C2A4CA10C5-7F17-3F9-4G16-3G12-2H15-HEH14-A14-2K16-J13-2J17-A12-2N18-2L10-2L19-A2M8-ML19-3P8-2A20-AO8-2O20-2R8-2A21-A8-2I21-I8-2I-14AQ6AQ42AD20EA6E4D-31B3-11CA2CA3CA10C5-7F18-2F8-5G17-2G11-3H16-2H14-A15-2K15-J14-2J16-A13-N18-2L11-L19-A2M9-M19-3P9-A20-AO9-O20-2R9-A21-A9-RA20-I9-22AQ43AD27E4D-31B3-11CA3CA2CA10C5-7F18-2F8-5G17-2G11-3H16-2H14-A15-2K15-J14-2J16-A13-2N17-2L11-L19-A2M9-M19-3P9-A20-AO9-O20-2R9-A21-A9-RA20-I9-16A8Q42AD27E4D-31B3-11CA4CACA10C5-7F18-2F8-5G17-2G11-3H16-2H14-A15-2K15-J14-2J16-A13-N18-2L11-L19-A2M9-M19-3P9-A20-AO9-O20-2R9-A21-A9-RA20-I9-2A-13A8Q10A-31A-31D2-30B3-12C2A3C2A10C6-6F18-2F9-4G17-2G12-2H15-HEH14-A14-2K16-J13-2J17-A12-2N18-2L10-2L19-A2M8-ML19-3P8-2A20-AO8-OP20-2R8-2A21-A8-2I21-I8-2I3-12AQ6AQ9A3-29A3-29D4-28B5-27C9-4F16-3F11-3G15-3G14-H14-3H15-A13-KEK16-J12-3J17-A11-3N18-2L9-2L20-A3M6-2M20-2PMP6-2A21-APO6-OP21-3R6-2A22-AI6-2I22-2(2I6-)2(26A6-)26D6-26B9-23C11-21F13-19G16-16H17-15K18-14J19-13N20-12L21-10M22-3P7A23-8OP23-2R7A2(24-8I)3-
