model
size = 32 18 12, scale = 0.05, origin = -y
material deform = 1, fade = true, lighting = smooth, roughness = 0.3, metalness = 0.6
  colors = A:#FFF B:#000E0F C:#001D1F D:#000 E:#0086A1 F:#002C2E G:#003A3E H:#00494D I:#00F2FF J:#008E96 K:#00676D L:#00585D M:#00A2AB N:#007A81 O:#001C23 P:#00CAD5 Q:#00B6C0 R:#00DEEA
voxels
38-2(7A8-6A11-)7D8-6D12-5B9-6B26-6C26-6F27-4G28-4H29-2L271-2(20A12-)20D13-19B15-17C17-15F19-13G20-4HA7H21-4LA6L22-4KA5K23-2NANA4N24-2JAJA3J24-3MAMA2M25-3QAQA26-4PAP27-4RA2(27-5I)9-2(26A6-)26D6-26B9-23C11-21F13-19G16-16H17-15L18-14K19-13N20-12J21-10M22-3Q7A23-9P23-2R7A2(24-8I)5-12A8O9A3-29A3-29D4-28B5-27C9-4F16-3F11-3G15-3G14-H14-3H15-A13-LEL16-K12-3K17-A11-3N18-2J9-2J20-A2MJ6-2M20-2Q2M6-2A21-A2Q6-2P21-2RP6-2A22-AI6-2I22-2I6-2I3-12A10O9A-31A-31D2-30B3-12C2A4CA10C6-6F18-2F9-4G17-2G12-2H15-HEH14-A14-2L16-K13-2K17-A12-2N18-2J10-2J19-AMJ8-JM19-2QM8-2A20-AQ8-2P20-2R8-2A21-A8-2I21-I8-2I-12AO5AE4AO40AD27E4D-31B3-11CA2CA3CA10C5-7F18-2F8-5G17-2G11-3H16-2H14-A15-2L15-K14-2K16-A13-N18-2J11-J19-AMJ9-M19-2QM9-A20-AQ9-P20-2R9-A21-A9-RA20-I9-14AO4AE5AO40AD27E4D-31B3-11CA3CA2CA10C5-7F18-2F8-5G17-2G11-3H16-2H14-A15-2L15-K14-2K16-A13-2N17-2J11-J19-AMJ9-M19-2QM9-A20-AQ9-P20-2R9-A21-A9-RA20-I9-14AO3AE6AO40AD20EA6E4D-31B3-11CA4CACA10C5-7F18-2F8-5G17-2G11-3H16-2H14-A15-2L15-K14-2K16-A13-N18-2J11-J19-AMJ9-M19-2QM9-A20-AQ9-P20-2R9-A21-A9-RA20-I9-15A10O41AD27E4D-31B3-12C2A3C2A10C5-7F17-3F9-4G16-3G12-2H15-HEH14-A14-2L16-K13-2K17-A12-2N18-2J10-2J19-AMJ8-2M19-2QM8-2A20-AQ8-2P20-2R8-2A21-A8-2I21-I8-2I-14A8O9A-31A-D27E3D2-30B4-28C8-5F16-3F12-2G15-3G14-H14-3H15-A13-3L16-K12-3K17-A11-3N18-2J9-2J20-A2MJ6-2M20-2Q2M6-2A21-AEP6-2P21-3R6-2A22-AI6-2I22-2I6-2I2(3-29A)3-12D13E4D5-27B6-26C11-21F14-18G16-16H17-15L18-14K19-2N3J7N21-11J22-M2E7M22-3Q7A23-9P23-2R7A2(24-8I)2(6-26A)6-26D7-25B9-23C16-16F18-14G19-4HAH4E3H20-4LAL2E3L22-4KA4K24-2NANA3N25-2JAJA2J25-3M2(AM)26-3QAQA26-4PAP27-4RA2(27-5I)5-
