model
size = 32 18 12, scale = 0.05, origin = -y
material deform = 1, fade = true, lighting = smooth, roughness = 0.3, metalness = 0.6
  colors = A:#FFF B:#F6F62D C:#EEF42D D:#FFF82D E:#0086A1 F:#E6F32D G:#70FF23 H:#DDF12D I:#D5F02D J:#ACF22A K:#C5ED2E L:#CDEE2D M:#A0F429 N:#B8EF2C O:#88F926 P:#94F727 Q:#7CFC24
voxels
38-2(7A8-6A11-)7D8-6D12-5B9-6B26-6C26-6F27-4H28-4I29-2L271-2(20A12-)20D13-19B15-17C17-15F19-13H20-4IA7I21-4LA6L22-4KA5K23-2NANA4N24-2JAJA3J24-3MAMA2M25-3PAPA26-4OAO27-4QA2(27-5G)9-2(26A6-)26D6-26B9-23C11-21F13-19H16-16I17-15L18-14K19-13N20-12J21-10M22-3P7A23-9O23-2Q7A2(24-8G)5-12A8G9A3-29A3-29D4-28B5-27C9-4F16-3F11-3H15-3H14-I14-3I15-A13-LEL16-K12-3K17-A11-3N18-2J9-2J20-A2MJ6-2M20-2P2M6-2A21-A2P6-2O21-2QO6-2A22-AG6-2G22-2G6-2G3-12A10G9A-31A-31D2-30B3-12C2A4CA10C6-6F18-2F9-4H17-2H12-2I15-IEI14-A14-2L16-K13-2K17-A12-2N18-2J10-2J19-AMJ8-JM19-2PM8-2A20-AP8-2O20-2Q8-2A21-A8-2G21-G8-2G-12AG5AD4AG40AD27E4D-31B3-11CA2CA3CA10C5-7F18-2F8-5H17-2H11-3I16-2I14-A15-2L15-K14-2K16-A13-N18-2J11-J19-AMJ9-M19-2PM9-A20-AP9-O20-2Q9-A21-A9-QA20-G9-14AG4AD5AG40AD27E4D-31B3-11CA3CA2CA10C5-7F18-2F8-5H17-2H11-3I16-2I14-A15-2L15-K14-2K16-A13-2N17-2J11-J19-AMJ9-M19-2PM9-A20-AP9-O20-2Q9-A21-A9-QA20-G9-14AG3AD6AG40AD20EA6E4D-31B3-11CA4CACA10C5-7F18-2F8-5H17-2H11-3I16-2I14-A15-2L15-K14-2K16-A13-N18-2J11-J19-AMJ9-M19-2PM9-A20-AP9-O20-2Q9-A21-A9-QA20-G9-15A10G41AD27E4D-31B3-12C2A3C2A10C5-7F17-3F9-4H16-3H12-2I15-IEI14-A14-2L16-K13-2K17-A12-2N18-2J10-2J19-AMJ8-2M19-2PM8-2A20-AP8-2O20-2Q8-2A21-A8-2G21-G8-2G-14A8G9A-31A-D27E3D2-30B4-28C8-5F16-3F12-2H15-3H14-I14-3I15-A13-3L16-K12-3K17-A11-3N18-2J9-2J20-A2MJ6-2M20-2P2M6-2A21-AEO6-2O21-3Q6-2A22-AG6-2G22-2G6-2G2(3-29A)3-12D13E4D5-27B6-26C11-21F14-18H16-16I17-15L18-14K19-2N3J7N21-11J22-M2E7M22-3P7A23-9O23-2Q7A2(24-8G)2(6-26A)6-26D7-25B9-23C16-16F18-14H19-4IAI4E3I20-4LAL2E3L22-4KA4K24-2NANA3N25-2JAJA2J25-3M2(AM)26-3PAPA26-4OAO27-4QA2(27-5G)5-
