model
size = 32 32 14, scale = 0.05, origin = -y
material deform = 1, fade = true, lighting = smooth, roughness = 0.3, metalness = 0.6
  colors = A:#11684F B:#F9E9F9 C:#2F7852 D:#9ACCB7 E:#389999 F:#116D54 G:#288988 H:#38AB91 I:#48999D J:#388989 K:#317E71 L:#92B1B1
voxels
269-CA29-C2AC28-A2(2-A27-2A)2-A28-C2-5(A31-)2(A30-C)A29-CAF29-CA30-AF7(30-2A)28-6A38-5A4-6A20-C2A3-6A22-AC2-A27-CA2-A28-F2-A28-A2-A27-CA2-A12-CA13-CA2-A11-C2AC12-2A2-A11-A2-A12-2A2-A10-2A2-A12-CA2-A5-3A2-2A2-A4-3A5-CA2-A4-5A2-C2-A3-5A5-A2-A3-CAD2BG5-A3-AC2BAC4-A2-A3-AD4BA4-A2-AD4BAC4-A-A3-ABDAEBEC3-A2-A2BAEBDC4-3A2-CBLA2D2BC3-A-2CBA2DFBA4-A-A2-ABDIAKABAC2-A-GBAE2ADBA3-A2-A-2AB2AI2AB2A-CA-2(AB)DACB2A2(2-A)-C2(AB)AJHBA2-CA-EBDBEAEB2A-C2(A2-)C2(BD)C2BC-CAF-CA2BDADBA2-2A2-A2-2A2BABDA2-CA3-A2BADBHC2-2A2-A3-A3BCDA2-AF3-CA2BCDA3-2A2-A3-ACBD2AC2-2A3-CADEC2A3-2A2-A4-5A3-2A4-C4A4-CA2-A5-3A4-2A5-3A5-C2(A2-A12-2A14-)F2-A12-2A13-CA2-6A7-2A13-AC2-6A5-6A10-CA26-5AC26-5A4-6A20-C2A3-6A22-AC2-A27-CA2-A28-F2-A28-A2-A27-CA2-A12-CA13-CA2-A11-C2AC12-2A2-A11-A2-A12-2A2-A10-2A2-A12-CA2-A5-3A2-2A2-A4-3A5-CA2-A4-5A2-C2-A3-5A5-A2-A3-CAD2BG5-A3-AC2BAC4-A2-A3-AD4BA4-A2-AD4BAC4-A-A3-ABDAEBEC3-A2-A2BAEBDC4-3A2-CBLA2D2BC3-A-2CBA2DFBA4-A-A2-ABD2AKABAC2-A-GBAE2ADBA3-A2-A-2AB2AI2AB2A-CA-2(AB)DACB2A2(2-A)-C2(AB)AJHBA2-CA-EBDBEAEB2A-C2(A2-)C2(BD)C2BC-CAF-CA2BDADBA2-2A2-A2-2A2BABDA2-CA3-A2BADBHC2-2A2-A3-A3BCDA2-AF3-CA2BCDA3-2A2-A3-ACBD2AC2-2A3-CADEC2A3-2A2-A4-5A3-2A4-C4A4-CA2-A5-3A4-2A5-3A5-C2(A2-A12-2A14-)F2-A12-2A13-CA2-6A7-2A13-AC2-6A5-6A10-CA26-5AC26-5A4-6A20-C2A3-6A22-AC2-A27-CA2-A28-F2-A28-A2-A27-CA2-A12-CA13-CA2-A11-C2AC12-2A2-A11-A2-A12-2A2-A10-2A2-A12-CA2-A5-3A2-2A2-A4-3A5-CA2-A4-5A2-C2-A3-5A5-A2-A3-CAD2BG5-A3-AC2BAC4-A2-A3-AD4BA4-A2-AD4BAC4-A-A3-ABDAEBEC3-A2-A2BAEBDC4-3A2-CBLA2D2BC3-A-2CBA2DFBA4-A-A2-ABD2AKABAC2-A-GBAE2ADBA3-A2-A-2AB2AI2AB2A-CA-2(AB)DACB2A2(2-A)-C2(AB)AJHBA2-CA-EBDBEAEB2A-C2(A2-)C2(BD)C2BC-CAF-CA2BDADBA2-2A2-A2-2A2BABDA2-CA3-A2BADBHC2-2A2-A3-A3BCDA2-AF3-CA2BCDA3-2A2-A3-ACBD2AC2-2A3-CADEC2A3-2A2-A4-5A3-2A4-C4A4-CA2-A5-3A4-2A5-3A5-C2(A2-A12-2A14-)F2-A12-2A13-CA2-6A7-2A13-AC2-6A5-6A10-CA26-5AC26-5A4-6A20-C2A3-6A22-AC2-A27-CA2-A28-F2-A28-A2-A27-CA2-A12-CA13-CA2-A11-C2AC12-2A2-A11-A2-A12-2A2-A10-2A2-A12-CA2-A5-3A2-2A2-A4-3A5-CA2-A4-5A2-C2-A3-5A5-A2-A3-CAD2BG5-A3-AC2BAC4-A2-A3-AD4BA4-A2-AD4BAC4-A-A3-ABDAEBEC3-A2-A2BAEBDC4-3A2-CBLA2D2BC3-A-2CBA2DFBA4-A-A2-ABD2AKABAC2-A-GBAE2ADBA3-A2-A-2AB2AI2AB2A-CA-2(AB)DACB2A2(2-A)-C2(AB)AJHBA2-CA-EBDBEAEB2A-C2(A2-)C2(BD)C2BC-CAF-CA2BDADBA2-2A2-A2-2A2BABDA2-CA3-A2BADBHC2-2A2-A3-A3BCDA2-AF3-CA2BCDA3-2A2-A3-ACBD2AC2-2A3-CADEC2A3-2A2-A4-5A3-2A4-C4A4-CA2-A5-3A4-2A5-3A5-C2(A2-A12-2A14-)F2-A12-2A13-CA2-6A7-2A13-AC2-6A5-6A10-CA26-5AC26-5A4-6A20-C2A3-6A22-AC2-A27-CA2-A28-F2-A28-A2-A27-CA2-A12-CA13-CA2-A11-C2AC12-2A2-A11-A2-A12-2A2-A10-2A2-A12-CA2-A5-3A2-2A2-A4-3A5-CA2-A4-5A2-C2-A3-5A5-A2-A3-CAD2BG5-A3-AC2BAC4-A2-A3-AD4BA4-A2-AD4BAC4-A-A3-ABDAEBEC3-A2-A2BAEBDC4-3A2-CBLA2D2BC3-A-2CBA2DFBA4-A-A2-ABD2AKABAC2-A-GBAE2ADBA3-A2-A-2AB2AI2AB2A-CA-2(AB)DACB2A2(2-A)-C2(AB)AJHBA2-CA-EBDBEAEB2A-C2(A2-)C2(BD)C2BC-CAF-CA2BDADBA2-2A2-A2-2A2BABDA2-CA3-A2BADBHC2-2A2-A3-A3BCDA2-AF3-CA2BCDA3-2A2-A3-ACBD2AC2-2A3-CADEC2A3-2A2-A4-5A3-2A4-C4A4-CA2-A5-3A4-2A5-3A5-C2(A2-A12-2A14-)F2-A12-2A13-CA2-6A7-2A13-AC2-6A5-6A10-CA26-5AC26-5A4-6A20-C2A3-6A22-AC2-A27-CA2-A28-F2-A28-A2-A27-CA2-A12-CA13-CA2-A11-C2AC12-2A2-A11-A2-A12-2A2-A10-2A2-A12-CA2-A5-3A2-2A2-A4-3A5-CA2-A4-5A2-C2-A3-5A5-A2-A3-CAD2BG5-A3-AC2BAC4-A2-A3-AD4BA4-A2-AD4BAC4-A-A3-ABDAEBEC3-A2-A2BAEBDC4-3A2-CBLA2D2BC3-A-2CBA2DFBA4-A-A2-ABD2AKABAC2-A-GBAE2ADBA3-A2-A-2AB2AI2AB2A-CA-2(AB)DACB2A2(2-A)-C2(AB)AJHBA2-CA-EBDBEAEB2A-C2(A2-)C2(BD)C2BC-CAF-CA2BDADBA2-2A2-A2-2A2BABDA2-CA3-A2BADBHC2-2A2-A3-A3BCDA2-AF3-CA2BCDA3-2A2-A3-ACBD2AC2-2A3-CADEC2A3-2A2-A4-5A3-2A4-C4A4-CA2-A5-3A4-2A5-3A5-C2(A2-A12-2A14-)F2-A12-2A13-CA2-6A7-2A13-AC2-6A5-6A10-CA26-5AC26-5A4-6A20-C2A3-6A22-AC2-A27-CA2-A28-F2-A28-A2-A27-CA2-A12-CA13-CA2-A11-C2AC12-2A2-A11-A2-A12-2A2-A10-2A2-A12-CA2-A5-3A2-2A2-A4-3A5-CA2-A4-5A2-C2-A3-5A5-A2-A3-CAD2BG5-A3-AC2BAC4-A2-A3-AD4BA4-A2-AD4BAC4-A-A3-ABDAEBEC3-A2-A2BAEBDC4-3A2-CBLA2D2BC3-A-2CBA2DFBA4-A-A2-ABD2AKABAC2-A-GBAE2ADBA3-A2-A-2AB2AI2AB2A-CA-2(AB)DACB2A2(2-A)-C2(AB)AJHBA2-CA-EBDBEAEB2A-C2(A2-)C2(BD)C2BC-CAF-CA2BDADBA2-2A2-A2-2A2BABDA2-CA3-A2BADBHC2-2A2-A3-A3BCDA2-AF3-CA2BCDA3-2A2-A3-ACBD2AC2-2A3-CADEC2A3-2A2-A4-5A3-2A4-C4A4-CA2-A5-3A4-2A5-3A5-C2(A2-A12-2A14-)F2-A12-2A13-CA2-6A7-2A13-AC2-6A5-6A10-CA26-5AC26-5A30-C2A31-AC30-CA31-F31-A30-CA15-CA13-CA14-C2AC12-2A14-A2-A12-2A13-2A2-A12-CA8-3A2-2A2-A4-3A5-CA7-5A2-C2-A3-5A5-A6-CAD2BG5-A3-AC2BAC4-A6-AD4BA4-A2-AD4BAC4-A5-ABDAEBEC3-A2-A2BAEBDC4-2A3-CBLA2D2BC3-A-2CBA2DFB2(A4-)ABD2AKABAC2-A-GBAE2ADBA3-A4-2AB2AI2AB2A-CA-2(AB)DACB2A2-A4-C2(AB)AJHBA2-CA-EBDBEAEB2A-CA5-C2(BD)C2BC-CAF-CA2BDADBA2-2A5-2A2BABDA2-CA3-A2BADBHC2-2A6-A3BCDA2-AF3-CA2BCDA3-2A6-ACBD2AC2-2A3-CADEC2A3-2A7-5A3-2A4-C4A4-CA8-3A4-2A5-3A5-C2(A15-2A14-)F15-2A13-CA15-2A13-AC13-6A10-CA26-5AC240-CA29-C2AC28-A2-A27-2A2-A22-3A2-2A2-A4-3A14-5A2-C2-A3-5A12-CAD2BG5-A3-AC2BAC11-AD4BA4-A2-AD4BAC10-ABDAEBEC3-A2-A2BAEBDC9-CBLA2D2BC3-A-2CBA2DFBA9-ABD2AKABAC2-A-GBAE2ADBA8-2AB2AI2AB2A-CA-2(AB)DACB2A7-C2(AB)AJHBA2-CA-EBDBEAEB2A8-C2(BD)C2BC-CAF-CA2BDADBA9-2A2BABDA2-CA3-A2BADBHC10-A3BCDA2-AF3-CA2BCDA11-ACBD2AC2-2A3-CADEC2A12-5A3-2A4-C4A14-3A4-2A5-3A22-3(2A30-)2A28-6A284-CA29-C2AC28-A2-A27-2A2-A22-3A2-2A2-A4-3A14-5A2-C2-A3-5A12-CAD2BG5-A3-AC2BAC11-AD4BA4-A2-AD4BAC10-ABDAEBEC3-A2-A2BAEBDC9-CBLA2D2BC3-A-2CBA2DFBA9-ABD2AKABAC2-A-GBAE2ADBA9-AB2AI2AB2A-CA-2(AB)DACB2A8-2(AB)AJHBA2-CA-EBDBEAEB2A8-C2(BD)C2BC-CAF-CA2BDADBA9-2A2BABDA2-CA3-A2BADBHC10-A3BCDA2-AF3-CA2BCDA11-ACBD2AC2-2A3-CADEC2A12-5A3-2A4-C4A14-3A4-2A5-3A22-3(2A30-)2A28-6A284-CA29-C2AC28-A2-A27-2A2-A22-3A2-2A2-A4-3A14-5A2-C2-A3-5A12-CAD2BG5-A3-AC2BAC11-AD4BA4-A2-AD4BAC10-ABDAEBEC3-A2-A2BAEBDC10-BLA2D2BC3-A-2CBA2DFBA10-BD2AKABAC2-A-GBAE2ADBA8-A-B2AI2AB2A-CA-2(AB)DACB2A7-C-2(BA)JHBA2-CA-EBDBEAEB2A9-2(BD)C2BC-CAF-CA2BDADBA10-A2BABDA2-CA3-A2BADBHC10-A3BCDA2-AF3-CA2BCDA11-ACBD2AC2-2A3-CADEC2A12-5A3-2A4-C4A14-3A4-2A5-3A22-3(2A30-)2A28-6A284-CA29-C2AC28-A2-A27-2A2-A22-3A2-2A2-A4-3A15-4A2-C2-A3-5A14-D2BG5-A3-AC2BAC13-4BA4-A2-AD4BAC12-DAEBEC3-A2-A2BAEBDC9-C2-A2D2BC3-A-2CBA2DFBA9-A2-2AKABAC2-A-GBAE2ADBA8-2A2-AI2AB2A-CA-2(AB)DACB2A7-CA2-BAJHBA2-CA-EBDBEAEB2A8-C2-BDC2BC-CAF-CA2BDADBA9-A2-BABDA2-CA3-A2BADBHC12-2BCDA2-AF3-CA2BCDA13-BD2AC2-2A3-CADEC2A13-4A3-2A4-C4A14-3A4-2A5-3A22-3(2A30-)2A28-6A284-CA29-C2AC28-A2-A27-2A2-A22-3A2-2A2-A4-3A14-5A2-C2-A3-5A12-CAD2BG5-A3-AC2BAC11-AD4BA4-A2-AD4BAC10-ABDAEBEC3-A2-A2BAEBDC9-CBLA2D2BC3-A-2CBA2DFBA9-ABDIAKABAC2-A-GBAE2ADBA8-2AB2AI2AB2A-CA-2(AB)DACB2A7-C2(AB)AJHBA2-CA-EBDBEAEB2A8-C2(BD)C2BC-CAF-CA2BDADBA9-2A2BABDA2-CA3-A2BADBHC10-A3BCDA2-AF3-CA2BCDA11-ACBD2AC2-2A3-CADEC2A12-5A3-2A4-C4A14-3A4-2A5-3A22-3(2A30-)2A28-6A47-
