model
size = 25 19 17, scale = 0.05, origin = -y
material deform = 1, fade = true, lighting = smooth, roughness = 0.3, metalness = 0.6
  colors = A:#FEDFC3 B:#000 C:#562E17 D:#84492C E:#C2C3C7 F:#9AD0FF G:#EDE8FF H:#9AA9BC I:#94453E J:#CAD2E9 K:#FFAA57
voxels
261-2(B24-)3A22-B24-B220-3A2(21-4A)2(20-5A20-6A)2(19-6A)-A22-2(B24-)B171-7A2(16-9A)15-16A9-A-14A9-16A2(8-17A)9-5A2-9A9-5A2-11A8-16A12-8A19-2B144-4A5EA3E11-15A8-17A10-15A8-9A-C6A8-4A3-2ABC6A8-3(19A6-)6A2-11A7-4A3-11A7-18A11-13A14-B3F2A86-2(6B19-)4B4A4(EA)E2A4-6B15A3(4-3B18A)4-4B6-8A-4A2-4B-2A2-14A2-4B-14A2C2A2(2-3B20A)2-4B5A2-12A2-4B19A8-5AJB9A13-BG-H2A86-6B18-9B16-5B6A3EA5E3-7B15A3-4B18A3-2B20A4-3B18A4-4B6-8A-4A2-4B5-15A-4B4-11A2C3A2(-4B20A)-4B5A2-13A-4B19A7-6AGB10A12-BG-H86-B23-12B13-2(7B15A3-)4B18A3-2B20A4-3B18A4-7B3-8A-C3A2-7B2-9A-C4A-7B2-9A-2C3A-4B14A-5A-4BA2D11A-5A-5BAD11A-5A-4B14A-5A-5B18A2-6B4-B2FH110-14B11-7B9A2(2EA)3-7B15A3-4B16A-A3-2B18A-A5-2B18A5-6B3-9A2C2A3-2(6B2-10A2C3A2-)3B15A2C3A2-3B15A2D3A2-5B13A2D3A2-3B15A2D3A2-4B18A3-5B4-2B7-B6-3B22-6B24-B42-12B13-7B9A3(EA)3-7B15A3-4B16A-A3-2B18A-A5-2B16ACA5-6B2A-8A-2C2A3-2(6B2-10A2C3A2-)3B15A2C3A-4B15A2D3A8B-11A2D3A5B15AID3A6B18A-4B3-3B-2B2-2AB2-B-A2-4B23-6B24-B42-11B14-7B10AEA2EA3-7B15A3-4B5A2D11A3-2B5A4D11A5-2B16ACA5-6B-A-8A-C3A3-2(6B2-10AC4A2-)3B15AC4A2-2B8A-7AD4A2-4B14A3D2A2-3B15AI2D2A2-4B18A3-2B-3B3-2B7-B6-6B19-6B22-3B42-2B23-7B4A2(EA)E6A3-7B15A3-4B18A3-2B20A5-2B5A2D9ACA5-6B-11AC3A3-2(6B2-10AC4A2-)3B15AC4A2-2B8A-7AD4A2-5B13A3D2A2-3B15AI2DA3-4B18A3-4B5-B2FH12-3B22-3B103-3A5E4A11-15A9-16A8-17A8-5A2D10A8-2A3-15A5-2A3-11AC3A5-2A4-10AC3A5-16AC3A5-8A-7A2(D3A6-15A)D3A7-6AJB9A6-2B5-BG-H12-2B154-9A13-12A13-13A12-4A2D9A10-A3-11A10-A4-13A7-A4-10AC2A7-15AC2A7-7A-7AD2A7-17A8-17A10-5AGB8A14-BG-H2A189-7A17-13A12-15A2(10-6A-8A)10-2(17A8-)7A-9A8-12A14-11A17-8A19-B3F2A190-6A18-7A18-4(13A12-)16A9-11A14-11A15-10A17-8A19-2B347-2(2A23-)2A-A21-2A24-B24-2B348-2(B24-)3A22-B-K22-B113-
