model
size = 18 30 21, scale = 0.05, origin = -y
material deform = 1, fade = true, lighting = smooth, roughness = 0.3, metalness = 0.6
  colors = A:#100 B:#000 C:#099 D:#C39 E:#96F F:#093 G:#633 H:#93C I:#939 J:#336 K:#339 L:#636 M:#003 N:#9CC O:#669 P:#63C Q:#C99 R:#FCC S:#9C6 T:#936 U:#969 V:#6C3 W:#663
voxels
8-Q16-2F16-A17-A483-2A-2ANT11-2D2AP2A11-2ADQVOE10-AK2C2ALU10-F2ACAT2A10-AN2AE2AD10-PA2GA2EA11-OAJAU2A12-5A13-AHD-A13-2A2-D13-AL16-T321-A6-2A9-HD4-A3E8-2A4-O3A8-2A4-L3A8-FA4-4A8-AN3-2A2D9-PA3-2E2A9-VOA2-UA2F8-4A-4A9-AR2AH2D2A9-2AI4ADF9-AC2ALF2A10-2CAT2ARA11-AE4AI13-2EM282-2A7-2C7-AHD6-2A7-3A6-2G6-2EC7-2J6-2AF7-2A6-3A7-2H6-2AP7-2A6-2DV6-3L6-3A6-3Q6-2AR6-2F7-3A5-D2A7-2IC5-2A9-KC4-RAM9-2AEA-2AIS10-GA2EMAKA11-AUASFA12-5B245-2A8-2A5-2CH8-2A5-2CA8-2C5-2AC8-2A5-2GF8-2A5-2JA8-2G5-2A9-2A5-2H9-A6-2A8-2D6-2C8-2L6-2R4(7-2A)7-2E7-2FA6-2A8-AGA4-K2A9-JAU2-F2A11-7B12-5B16-B111-DWD14-LWC2L13-CWCLC13-AC3A14-3G22-2A9-2A5-2A9-2I5-2A9-2K5-2A9-2A5-2C9-2N5-2A9-2A5-2A9-2O4-2G10-2A4-2A10-2A4-FA9-2A5-2A9-2T5-2A9-A7-2M8-E7-2S8-U8-AG6-2A9-JA5-2D9-3B3-3B10-8B11-6B14-3B16-BA16-AIU14-MAK2A12-BSFA5D9-B2AN5AW8-BAP8A10-3A-4A14-4A13-4C15-2B3-2O11-R2(4-2A11-A)4-2I11-F4-2K11-A4-2A11-P4-2N11-V4-2A10-2C4-2O10-2A4-L11-A5-A10-2A5-2A9-2E5-2E9-2A5-3A8-2A6-2AG7-2A7-AJ7-2D8-2B5-3B9-2B4-AB11-3B-3B12-2BA3B12-BAR3A12-3AI3A11-BMA-3A11-BS3-5D7-2B6-4A6-2B6-2(4A14-)4I14-4K14-3B2-2V11-2A3-2A11-2A3-2R11-2M3-2A11-2S3-2A11-2A3-2F11-2A3-2A11-2Q3-2P10-2A4-V11-A5-A11-C5-T11-C5-A11-A5-2E10-G5-2U10-J6-2A9-A6-2DJ7-2H7-3B6-2B8-3B5-2B10-2B2(4-2B11-B)A3-2G11-2A3-3J9-2B5-2A9-2B5-4H7-2B6-4A5-2B7-4C14-4R2(14-4A)14-3B2-Q12-2A3-F12-2A3-A12-2E3-A12-2A3-M12-2A3-S12-2A2-2A12-2D2-2A11-2A3-2Q2(11-2A3-2A)11-A4-2E11-A5-A11-C5-2A10-A6-2A9-A6-2DJ8-G7-3B7-B9-BD6-B9-3B5-B10-2B5-2B10-B5-2C10-A5-2A9-2B6-A9-B7-3G6-2B7-4A5-2B7-3(4A14-)4M14-3B2-2D12-T3-2L12-A3-2A12-E3-2A12-U3-E13-A2-2A12-2D2-2(2A12-A3-)2D12-O2(3-2C11-2A)3-2A11-I4-2G11-K5-2J10-2A5-2A9-2N5-2HJ8-2A6-3B7-B8-2B7-B9-2B6-2B9-2B5-2B10-B6-K9-BA6-A9-2B6-2N8-B7-3A6-2B7-4O5-2B7-3(4A14-)4E14-3B2-2A12-A3-2A12-E3-2T12-A3-A13-A3-E12-2A2-2U12-2D2-2A12-A3-2D12-F3-2A12-V3-2C12-A3-2A11-2R3-2A11-2A3-2G11-2A4-2A10-2F5-2A9-2A6-AJ8-2P2(7-2B)8-BD6-2B8-2B6-2B9-2B6-B10-B6-A9-BA6-2F8-B7-2A8-B7-2P8-B7-3V6-2B7-4A14-4T14-4A14-3E20-2A12-C3-2A12-A3-A13-G3-E13-J3-A12-2A3-A12-2H2-2A12-A3-2D12-L3-2A12-Q3-KB12-F3-2A11-2A3-2N11-2A3-2A11-2M4-2O11-S5-2A9-2A6-AI8-2A2(7-2B)8-BC6-2B8-2B7-B9-2B6-B10-B6-M9-BA6-2S2(8-B7-2A)8-B7-3Q6-2B7-3F15-4A14-3E15-3A20-2A2(12-A3-2C)12-G3-2A12-A3-G13-A3-J12-2A2-2A12-A3-2H12-A3-2A12-D3-AB11-2L3-2F11-2A3-2A11-A4-2P11-2E4-2V10-2A5-2A9-2A5-2RI8-2A6-3B7-B8-2B7-2B8-2B6-2B9-2B5-2B10-B6-E9-BA6-2A8-2B6-2A8-B7-3A6-2B7-4D5-2B7-4L14-4C14-4A14-4G14-3B2-2A11-2A3-2C11-2N3-2A11-2A3-2A11-2O3-2G11-2A3-2A11-2A3-A12-2I3-A12-A3-2A11-2A3-FB11-2A3-2A11-T4-2A11-A5-M11-E5-2S10-U6-2A9-A7-AI8-D8-2B7-B9-BC6-B9-3B5-B10-2B5-2B10-B5-2E10-A5-2U9-2B6-2A8-B7-3D6-2B7-4A5-2B7-3(4A14-)4G14-3B2-2I11-F4-2K11-A4-2A11-P4-2N11-V4-2A11-A4-2O11-R4-2A11-A4-2A11-C4-I11-2A4-K2(11-A5-A)11-E5-2E10-A5-2A10-A6-2A9-A7-AI7-2D8-2B6-2B9-BC5-2B10-2B2(4-2B11-B)U3-2A11-B4-3A9-2B5-2A9-2B5-4D7-2B6-4A5-2B7-2(4A14-)4N14-4A14-3B3-2(A11-A5-)F11-M5-A11-S5-P11-A4-2V11-A4-2A11-Q4-2R10-2C4-2A10-2A4-A11-C5-D10-2C5-2A9-2A5-2A9-2G5-3T8-2J6-2A8-2A7-EI7-2H8-2B5-3B9-BC4-CB11-3B2-2B12-3BM2B12-2BAS2G12-2B2A3J11-2BA-3A11-2B3-5H7-2B6-4A6-2B6-4C14-4F14-4A14-4P14-3B3-2Q9-2A5-2F9-2A5-2A9-2E5-2A9-2A5-2M9-2A5-2S9-2A5-2A9-2D5-A10-2K4-2Q10-A5-2F9-2C5-2D9-2A5-2A9-A7-2A8-G7-2A8-A8-EA6-2A8-AIA5-2A9-3B3-3B10-8B11-6B14-4B15-AB16-3A14-B4A12-2BAS5A9-2B8A8-2B2A7C10-3A-2(4A14-)3M15-2B5-DK8-D7-LA8-A7-2A8-A7-AE8-T6-2E9-A6-2A9-E6-2A9-U6-2A9-A6-2D8-2I6-2L8-2K6-2J8-A7-2A7-2N7-2H7-2A7-3A6-2O8-C2A4-3A9-I3A-DQA11-7B12-5B15-2B111-3I14-KW3K13-3AWA13-2A2WA14-3E23-UKC6-2D7-3A6-2A7-DA7-2A7-AE2(7-2A)7-2E7-TA2(7-2A)6-3A6-2ED6-3F6-2UK2(6-3A)6-2A7-2AN6-2F7-3A5-M2A8-AO4-ASP9-4A-3AV10-2AH2D3A11-4ADQ14-3B247-2CA2-F2J9-2AF3-4A8-3A2-AE2H9-EMP2-G3A9-ASV2-JA2C9-3A-3A2C9-2AR-AHD2A9-DQAI3AL9-AK2C2ALFQ9-3ACAT2AF9-ON2AE4A9-2A2GA2EMA10-OAJAUAS11-7A13-H2D285-C2ALF13-F2AC2A12-AN2AEA12-PA2G2A12-VOAJAC12-6A12-R2A-D13-AIA-A13-CA2-F13-CA2-A13-AE16-G335-
