model
size = 13 16 32, scale = 0.05, origin = -y
material deform = 1, fade = true, lighting = smooth, roughness = 0.3, metalness = 0.6
  colors = A:#200F00 B:#121212 C:#FF3
voxels
17-2(4A9-)2(4B9-)4B10-2B127-6(6A7-)7(6B7-)6B8-4B9-3B8-6(8A5-)8(8B5-)7B18-5(10A3-)B8AB3-B-B6AB3-10B3(3-B7-2B)3-3(B7-B4-)B7-B16-5(11A2-)B9AB2-2B-B6AB2-11B2(2-2B7-2B)2-2B8-B2-2B7-2B3-2(B7-B4-)B7-B16-5(12A-)B9A2(2B-)B6A2B-12B-2B7-3B-3(2B7-2B2-)2B7-B4-B7-B29-5(12A-)2(B9A2(2B-)B6A2B-12B2(-2B7-3B)-2(2B7-2B2-)2B7-B4-B7-B29-4(12A-)B11A-)B9A2(2B-)B6A2B-12B2(-2B7-3B)-2(2B7-2B2-)2B7-B4-B7-B28-52AB11A2B10A3B2A-7A18B7-6B7-3B-2B7-2B2-2B7-2B3-B7-B4-B7-B28-52AB11A2B10A3B2A-7A18B2(7-6B)2(7-2B3-B)2(7-B4-B)7-B15-52AB11A2B10A3B2A-7A18B2(7-6B)2(7-2B3-B)7-B4-B7-B5-7B7-4B5-4(12A-)B9A2B-B10AB-B2A-7AB-12B-3B7-2B-3B7-6B2(7-2B3-B)7-B5-7B6-6B57-9A4-B7A2B2-B9AB2-B2A-6A2B-12B2(-3B7-2B)-3B7-B4-B6-2B4-9B5-7B6-6B57-9A4-B7A2B2-B9AB2-B2A-6A2B-12B2(-3B7-2B)-3B6-2B4-2B5-2B4-BA6B5-C6BC5-8C56-9A4-B7A2B2-B9AB2-B2A-6A2B-12B2(-3B7-2B)-3B6-2B4-2B-5B5-8B5-C6BC69-9A4-B7A2B2-B9AB2-B2A-6A2B-12B-3B7-2B-3B6-3B-3B6-2B4-2B-5B5-BA6B5-C6BC69-9A4-B7A2B2-B9AB2-B2A-6A2B-12B-3B7-2B-3B6-2(3B-)B4-2B4-8B5-C6BC82-9A4-B7A2B2-B9AB2-B2A-6A2B-12B-3B7-2B-3B6-3B2-2B-B4-2B4-8B5-C6BC82-10A3-B8AB2-B10AB-B2A-7AB-12B-3B7-2B-3B6-3B2-2B-B4-2B4-8B5-C6BC82-11A2-B9AB-B11A2B2A-8A12B-4B7-2B-3B6-3B2-BC-B4-2B4-7CB5-C6BC82-11A2-B9AB-B11A2B2A-8A39B2-BC8B4-8C55-51A2(2B11A)2B2A-8A39B2-10B67-51A2(2B11A)2B2A-8A39B3-8B68-39AB3(11A2B)2A-8A39B79-39AB3(11A2B)2A-8A27B3-6B82-39AB3(11A2B)2A-8A26B92-2(12A-)11A2(B-B10A)B-B7A4B-B2A-7AB-12B4-6B95-2(12A-)3(B10AB-)B7A4B2-B8AB4-9B107-2(10A3-)3(B8AB3-)B6A3B4-B5A2B6-7B109-2(8A5-)3(B6AB5-)B5A2B6-2B2AB9-4B112-2(6A7-)3(B4AB7-)2B2A2B9-2B123-
