model
size = 21 22 21, scale = 0.05, origin = -y
material deform = 1, fade = true, lighting = smooth, roughness = 0.3, metalness = 0.6
  colors = A:#FF3 B:#111
voxels
156-3A17-5A15-3(7A14-)7A15-5A17-3A269-5A15-7A13-9A11-5(11A10-)11A11-9A13-7A15-5A204-7A13-9A11-11A9-7(13A8-)13A9-11A11-9A13-7A161-7A12-11A9-13A8-13A7-7(15A6-)15A7-13A8-13A9-11A12-7A119-7A12-11A9-13A7-15A6-15A5-7(17A4-)17A5-15A6-15A7-13A9-11A12-7A78-5A14-9A10-13A7-15A6-15A5-17A4-17A3-5(19A2-)19A3-17A4-17A5-15A6-15A7-13A10-9A14-5A57-7A12-11A9-13A7-15A5-17A4-17A3-7(19A2-)19A3-17A4-17A5-15A7-13A9-11A12-7A37-3A15-9A10-13A7-15A5-17A4-17A3-2(19A2-)19A-84A-2(19A2-)19A3-17A4-17A5-15A7-13A10-9A15-3A17-5A13-11A9-13A7-15A5-17A3-2(19A2-)19A-6(B20A)-2(19A2-)19A3-17A5-15A7-13A9-11A13-5A15-7A12-11A9-13A7-15A5-17A3-19A2-B18A-8(B20A)-B18A2-19A3-17A5-15A7-13A9-11A12-7A14-7A12-11A9-13A7-15A5-B16A3-B18A2-B18A-4(2B19A)B20A3(2B19A)-B18A2-B18A3-B16A5-15A7-13A9-11A12-7A14-7A12-11A9-13A7-15A5-17A3-19A2-B18A-8(B20A)-B18A2-19A3-17A5-15A7-13A9-11A12-7A15-5A13-11A9-13A7-15A5-17A3-2(19A2-)19A-6(B20A)-2(19A2-)19A3-17A5-15A7-13A9-11A13-5A17-3A15-9A10-13A7-15A5-17A4-17A3-2(19A2-)19A-84A-2(19A2-)19A3-17A4-17A5-15A7-13A10-9A15-3A37-7A12-11A9-13A7-15A5-17A4-17A3-7(19A2-)19A3-17A4-17A5-15A7-13A9-11A12-7A57-5A14-9A10-13A7-15A6-15A5-17A4-17A3-5(19A2-)19A3-17A4-17A5-15A6-15A7-13A10-9A14-5A78-7A12-11A9-13A7-15A6-15A5-7(17A4-)17A5-15A6-15A7-13A9-11A12-7A119-7A12-11A9-13A8-13A7-7(15A6-)15A7-13A8-13A9-11A12-7A161-7A13-9A11-11A9-7(13A8-)13A9-11A11-9A13-7A204-5A15-7A13-9A11-5(11A10-)11A11-9A13-7A15-5A269-3A17-5A15-3(7A14-)7A15-5A17-3A156-
