model
size = 31 31 4, scale = 0.05, origin = -y
material deform = 1, fade = true, lighting = smooth, roughness = 0.3, metalness = 0.6
  colors = A:#081818
voxels
14-A21-A22-2A6-3A18-4A6-2A-2A14-3A-A8-A2-2A11-3A2-2A8-A3-2A8-2A5-A10-A4-2(2A5-)2A10-A5-2A2-2A6-2A11-2A5-4A7-A13-2(A7-)2A13-A15-2(A14-2A13-)2A13-2A15-2A11-2A17-2A9-2A19-2A7-2A21-2A5-2A4-2A17-2A2-2A3-5A10-A8-8A3-A9-12A2(9-A)21-A7-2A21-A7-A22-A6-A23-2A4-2A24-A4-A25-A3-A26-A3-A27-2(A-A28-)2A22-A22-2A6-3A18-4A6-2A-2A14-3A-A8-A2-2A11-3A2-2A8-A3-2A8-2A5-A10-A4-2(2A5-)2A10-A5-2A2-2A6-2A11-2A5-4A7-A13-2(A7-)2A13-A15-2(A14-2A13-)2A13-2A15-2A11-2A17-2A9-2A19-2A7-2A21-2A5-2A4-2A17-2A2-2A3-5A10-A8-8A3-A9-12A2(9-A)21-A7-2A21-A7-A22-A6-A23-2A4-2A24-A4-A25-A3-A26-A3-A27-2(A-A28-)2A30-2(A22-)2A6-3A18-4A6-2A-2A14-3A-A8-A2-2A11-3A2-2A8-A3-2A8-2A5-A10-A4-2(2A5-)2A10-A5-2A2-2A6-2A11-2A5-4A7-A13-2(A7-)2A13-A15-2(A14-2A13-)2A13-2A15-2A11-2A17-2A9-2A19-2A7-2A21-2A5-2A4-2A17-2A2-2A3-5A10-A8-8A3-A9-12A2(9-A)21-A7-2A21-A7-A22-A6-A23-2A4-2A24-A4-A25-A3-A26-A3-A27-2(A-A28-)2A30-2(A22-)2A6-3A18-4A6-2A-2A14-3A-A8-A2-2A11-3A2-2A8-A3-2A8-2A5-A10-A4-2(2A5-)2A10-A5-2A2-2A6-2A11-2A5-4A7-A13-2(A7-)2A13-A15-2(A14-2A13-)2A13-2A15-2A11-2A17-2A9-2A19-2A7-2A21-2A5-2A4-2A17-2A2-2A3-5A10-A8-8A3-A9-12A2(9-A)21-A7-2A21-A7-A22-A6-A23-2A4-2A24-A4-A25-A3-A26-A3-A27-2(A-A28-)2A30-A17-
