model
size = 31 31 4, scale = 0.05, origin = -y
material deform = 1, fade = true, lighting = smooth, roughness = 0.3, metalness = 0.6
  colors = A:#092A2E B:#152629 C:#0B2320 D:#0A2326
voxels
16-A22-2C3A8-4A15-B2CAC5-2CA2C17-2BC2B2-6C20-2DC3BD2B19-A2B2(DA)2C4B16-ADBD3AB2DB2CABA14-2(2BA)BADCAD2B2CABA11-BA2B4ADBC3D3BDB3A7-2AB3A2-A2DBCBDA2BABD2B2A5-2AC2A3-2ADABCABDA2B-2ABDA5-BC2A3-2AD2ABCB2ADABA2-A2CA3-3A4-2ACDA-AC2A-2DABA3-ACA-2A6-2AC2A-BCBA-B2DBA5-2A7-2AC2A-2AC5AD2A13-6A-2BC3A-ABDBA12-2AC2B2-ABC2BA-AB2D2A10-4ABA2-2AC3A2-ABD2A10-4AB3-2BAB2A3-BACA10-ACAB4-ABC2A5-ACAB9-3A5-2BC2A6-ACA8-ACB6-ABC2A6-3A8-2A7-2B2(3A7-)A8-2AC2A8-CA17-ACA10-C17-ACA2(28-3A)29-2(A30-)A23-2C3A8-4A15-B2CAC5-2CA2C17-2BC2B2-6C20-2DC3BD2B19-A2B2(DA)2C4B16-ADBD3AB2DB2CABA14-2(2BA)BADCAD2B2CABA11-BA2B4ADBC3D3BDB3A7-2AB3A2-A2DBCBDA2BABD2B2A5-2AC2A3-2ADABCABDA2B-2ABDA5-BC2A3-2AD2ABCB2ADABA2-A2CA3-3A4-2ACDA-AC2A-2DABA3-ACA-2A6-2AC2A-BCBA-B2DBA5-2A7-2AC2A-2AC5AD2A13-6A-2BC3A-ABDBA12-2AC2B2-ABC2BA-AB2D2A10-4ABA2-2AC3A2-ABD2A10-4AB3-2BAB2A3-BACA10-ACAB4-ABC2A5-ACAB9-3A5-2BC2A6-ACA8-ACB6-ABC2A6-3A8-2A7-2B2(3A7-)A8-2AC2A8-CA17-ACA10-C17-ACA2(28-3A)29-3(A30-)A23-2C3A8-4A15-B2CAC5-2CA2C17-2BC2B2-6C20-2DC3BD2B19-A2B2(DA)2C4B16-ADBD3AB2DB2CABA14-2(2BA)BADCAD2B2CABA11-BA2B4ADBC3D3BDB3A7-2AB3A2-A2DBCBDA2BABD2B2A5-2AC2A3-2ADABCABDA2B-2ABDA5-BC2A3-2AD2ABCB2ADABA2-A2CA3-3A4-2ACDA-AC2A-2DABA3-ACA-2A6-2AC2A-BCBA-B2DBA5-2A7-2AC2A-2AC5AD2A13-6A-2BC3A-ABDBA12-2AC2B2-ABC2BA-AB2D2A10-4ABA2-2AC3A2-ABD2A10-4AB3-2BAB2A3-BACA10-ACAB4-ABC2A5-ACAB9-3A5-2BC2A6-ACA8-ACB6-ABC2A6-3A8-2A7-2B2(3A7-)A8-2AC2A8-CA17-ACA10-C17-ACA2(28-3A)29-3(A30-)A23-2C3A8-4A15-B2CAC5-2CA2C17-2BC2B2-6C20-2DC3BD2B19-A2B2(DA)2C4B16-ADBD3AB2DB2CABA14-2(2BA)BADCAD2B2CABA11-BA2B4ADBC3D3BDB3A7-2AB3A2-A2DBCBDA2BABD2B2A5-2AC2A3-2ADABCABDA2B-2ABDA5-BC2A3-2AD2ABCB2ADABA2-A2CA3-3A4-2ACDA-AC2A-2DABA3-ACA-2A6-2AC2A-BCBA-B2DBA5-2A7-2AC2A-2AC5AD2A13-6A-2BC3A-ABDBA12-2AC2B2-ABC2BA-AB2D2A10-4ABA2-2AC3A2-ABD2A10-4AB3-2BAB2A3-BACA10-ACAB4-ABC2A5-ACAB9-3A5-2BC2A6-ACA8-ACB6-ABC2A6-3A8-2A7-2B2(3A7-)A8-2AC2A8-CA17-ACA10-C17-ACA2(28-3A)29-3(A30-)A15-
