model
size = 27 31 4, scale = 0.05, origin = -y
material deform = 1, fade = true, lighting = smooth, roughness = 0.3, metalness = 0.6
  colors = A:#0B3235 B:#0A262F
voxels
7-3A17-5A3B-14BA8-BA2-AB2-BA5-2BA9-2(B3-AB2-BA5-BA10-)B3-AB2-BA5-2A10-B3-AB2-BA5-2A9-2B3-AB2-2A5-2A9-AB3-AB2-2A6-2A8-A4-2A2-2A6-2A8-B4-A4-2A5-2A8-2(B4-)2A6-A4-7A2-B5-A6-2A3-2A4-A2-B5-A7-A3-2A4-A-2A5-2A6-B3-2A4-A-B6-2A3-6BA-2A2-2A-A6-2A3-2B4-A-2A2-A-2A7-A3-2B4-A2-A-2A-BA7-A3-AB4-A2-3A2-B8-A2(3-2A)7-A9-A3-2A2-A8-A9-B4-3A2(9-B)16-B5-A7BA8-A6B2(2A-)B-A-2A8-A2-2A2(-A)-2A-B-A2-A8-A2-A3-2A-2A3-A2-A8-2A5-A3-A5-A10-A5-A3-A4-2A10-2(2A3-)2A2-2A12-A2-2A5-4A8-5A3B-14BA8-BA2-AB2-BA5-2BA9-2(B3-AB2-BA5-BA10-)B3-AB2-BA5-2A10-B3-AB2-BA5-2A9-2B3-AB2-2A5-2A9-AB3-AB2-2A6-2A8-A4-2A2-2A6-2A8-B4-A4-2A5-2A8-2(B4-)2A6-A4-7A2-B5-A6-2A3-2A4-A2-B5-A7-A3-2A4-A-2A5-2A6-B3-2A4-A-B6-2A3-6BA-2A2-2A-A6-2A3-2B4-A-2A2-A-2A7-A3-2B4-A2-A-2A-BA7-A3-AB4-A2-3A2-B8-A2(3-2A)7-A9-A3-2A2-A8-A9-B4-3A2(9-B)16-B5-A7BA8-A6B2(2A-)B-A-2A8-A2-2A2(-A)-2A-B-A2-A8-A2-A3-2A-2A3-A2-A8-2A5-A3-A5-A10-A5-A3-A4-2A10-2(2A3-)2A2-2A12-A2-2A5-4A14-3A18-5A3B-14BA8-BA2-AB2-BA5-2BA9-2(B3-AB2-BA5-BA10-)B3-AB2-BA5-2A10-B3-AB2-BA5-2A9-2B3-AB2-2A5-2A9-AB3-AB2-2A6-2A8-A4-2A2-2A6-2A8-B4-A4-2A5-2A8-2(B4-)2A6-A4-7A2-B5-A6-2A3-2A4-A2-B5-A7-A3-2A4-A-2A5-2A6-B3-2A4-A-B6-2A3-6BA-2A2-2A-A6-2A3-2B4-A-2A2-A-2A7-A3-2B4-A2-A-2A-BA7-A3-AB4-A2-3A2-B8-A2(3-2A)7-A9-A3-2A2-A8-A9-B4-3A2(9-B)16-B5-A7BA8-A6B2(2A-)B-A-2A8-A2-2A2(-A)-2A-B-A2-A8-A2-A3-2A-2A3-A2-A8-2A5-A3-A5-A10-A5-A3-A4-2A10-2(2A3-)2A2-2A12-A2-2A5-4A14-3A18-5A3B-14BA8-BA2-AB2-BA5-2BA9-2(B3-AB2-BA5-BA10-)B3-AB2-BA5-2A10-B3-AB2-BA5-2A9-2B3-AB2-2A5-2A9-AB3-AB2-2A6-2A8-A4-2A2-2A6-2A8-B4-A4-2A5-2A8-2(B4-)2A6-A4-7A2-B5-A6-2A3-2A4-A2-B5-A7-A3-2A4-A-2A5-2A6-B3-2A4-A-B6-2A3-6BA-2A2-2A-A6-2A3-2B4-A-2A2-A-2A7-A3-2B4-A2-A-2A-BA7-A3-AB4-A2-3A2-B8-A2(3-2A)7-A9-A3-2A2-A8-A9-B4-3A2(9-B)16-B5-A7BA8-A6B2(2A-)B-A-2A8-A2-2A2(-A)-2A-B-A2-A8-A2-A3-2A-2A3-A2-A8-2A5-A3-A5-A10-A5-A3-A4-2A10-2(2A3-)2A2-2A12-A2-2A5-4A14-3A18-
