model
size = 32 15 12, scale = 0.05, origin = -y
material deform = 1, fade = true, lighting = smooth, roughness = 0.3, metalness = 0.6
  colors = A:#081808 B:#081818 C:#080818
voxels
256-A32-3(A31-)A203-4A3-A23-2A2-2A-2A23-3(A4-A-A24-)A4-A2-A23-2A2-2A27-4A2-BA30-A31-2A31-A66-A30-3A30-A15-3A3-4A3-3A-A15-3A-2A2-2(2A-)ABA16-2A-A4-A-A3-B18-A-A4-A-A19-A2-A-A4-A-A3-A17-2A-A4-A2-A20-A2(2-2A)3-A17-2(4A2-)B5A26-A31-2A31-A66-A30-3A30-A13-5A3-4A3-3A-3A10-2A-3A-2A2-2(2A-)ABA-A10-A3-2A-A4-A-A3-B18-A-A4-A-A19-A2-A-A4-A-A3-A13-A3-2A-A4-A2-A5-A10-A3-A2(2-2A)2(3-A)11-6A2-4A2-B7A24-A17-A13-2A16-A14-A66-A11-A18-3A30-A13-5A3-4A3-3A-3A9-2(3A-)2A2-2(2A-)ABA-2A8-2A3-2A-A4-A-A3-B3-A8-A5-A-A4-A-A7-A8-2(A2-)A-A4-A-2(A3-)A8-2A3-2A-A4-A2-A5-A10-A3-A2(2-2A)2(3-A)10-7A2-4A2-B8A8-A14-A16-2A13-2A16-2(A14-)A51-A10-2A18-3A9-A20-A5-A4-A2-5A3-4A3-3A-3A9-2(3A-)2A2-2(2A-)ABA-2A8-2A3-2A-A4-A-A3-B3-A8-A5-A-A4-A-A7-A8-2(A2-)A-A4-A-2(A3-)A-A6-2A3-2A-A4-A2-A5-A10-A3-A2(2-2A)2(3-A)10-7A2-4A2-B8A8-2(A14-)A-2A13-2A8-A4-A2-A14-A13-2A51-A10-2A18-3A9-A20-A5-A4-A2-5A3-4A3-3A-3A9-2(3A-)2A2-2(2A-)ABA-2A8-2A3-2A-A4-A-A3-B3-A8-A5-A-A4-A-A7-A8-2(A2-)A-A4-A-2(A3-)A-A6-2A3-2A-A4-A2-A5-A10-A3-A2(2-2A)2(3-A)10-7A2-4A2-B8A8-2(A14-)A-2A13-2A8-A4-A2-A14-A13-2A51-A10-2A18-3A8-2A20-A5-2(2A2-)5A3-4A3-3A-3A3-2(A2-)2(3A-)2A2-2(2A-)ABA-2A5-A2-2A3-2A-A4-A-A3-B3-3(A2-)A5-A-A4-A-A7-A2-A5-2(A2-)A-A4-A-2(A3-)A-2A2-A2-2A3-2A-A4-A2-A5-A3-A2-2(A3-)A2(2-2A)2(3-A)7-A2-7A2-4A2-B8A5-A2-A14-A10-A2-2A-2A13-2A8-2(2A2-)A14-A13-2A51-A10-2A18-3A8-2A20-A5-2(2A2-)5A3-4A3-3A-3A3-2(A2-)2(3A-)2A2-2(2A-)ABA-2A5-A2-2A3-2A-A4-A-A3-B3-3(A2-)A5-A-A4-A-A7-A2-A5-2(A2-)A-A4-A-2(A3-)A-2A2-A2-2A3-2A-A4-A2-A5-A3-A2-2(A3-)A2(2-2A)2(3-A)7-A2-7A2-4A2-B8A5-A-2A14-A10-A2-2A-2A13-2A8-2(2A2-)A14-A13-2A51-A10-2A18-3A8-2A20-A5-2(2A2-)5A3-4A3-3A-3A3-2(A2-)2(3A-)2A2-2(2A-)ABA-2A5-A2-2A3-2A-A4-A-A3-B3-3(A2-)A5-A-A4-A-A7-A2-A-A3-2(A2-)A-A4-A-2(A3-)A-2A2-A2-2A3-2A-A4-A2-A5-A3-A2-2(A3-)A2(2-2A)2(3-A)7-A2-7A2-4A2-B8A5-A-2A14-A10-A2-2A-2A13-2A8-2(2A2-)A14-A13-2A51-A10-2A18-3A8-2A20-A5-2(2A2-)5A3-4A3-3A-3A3-2A-A2-2(3A-)2A2-2(2A-)ABA-2A3-A-A2-2A3-2A-A4-A-A3-B3-A2-2A-A2-A5-A-A4-A-A7-A2-3A3-2(A2-)A-A4-A-2(A3-)A-2A2-A2-2A3-2A-A4-A2-A5-A3-A2-2(A3-)A2(2-2A)2(3-A)5-A-A2-7A2-4A2-B8A3-A-A2-A14-A10-2(2A-)2A13-2A8-2(2A2-)A14-A13-2A51-A10-2A18-3A9-A20-A5-A3-2A2-5A3-4A3-3A-3A4-A-A2-2(3A-)2A2-2(2A-)ABA-2A3-C-A2-2A3-2A-A4-A-A3-B3-A3-B-A2-A5-A-A4-A-A7-A3-2A3-2(A2-)A-A4-A-2(A3-)A-A3-A2-2A3-2A-A4-A2-A5-A4-A-2(A3-)A2(2-2A)2(3-A)5-A-A2-7A2-4A2-B8A3-A-A2-A14-A10-2(2A-)2A13-2A8-2(2A2-)A14-A13-2A28-
