model
size = 32 12 24, scale = 0.05, origin = -y
material deform = 1, fade = true, lighting = smooth, roughness = 0.3, metalness = 0.6
  colors = A:#FC3 B:#F00 C:#111
voxels
104-7A24-9A23-9A24-7A26-6A27-3A187-7A24-9A23-9A24-7A26-6A27-3A186-9A22-12A2(19-13A)20-12A21-11A21-10A24-5A122-8A22-13A17-15A17-2(16A16-)16A17-14A19-13A20-10A117-12A18-16A15-17A15-3(18A14-)18A15-16A18-13A114-14A16-18A13-19A13-3(20A12-)19A14-18A16-15A112-16A14-20A4(11-21A)2(12-20A)13-18A110-6A4-8A13-20A11-21A11-23A8-25A2(8-24A)9-23A10-7A4-10A107-5A7-6A12-9A2-11A10-24A7-26A6-27A5-27A6-26A6-9A3-13A8-7A6-11A25-6A73-5A9-7A10-8A5-11A7-10A3-16A3-10A3-16AB2-2(10A3-15A4-)10A4-14AC4-8A6-12A-C5-6A8-11A23-8A25-6A41-4A10-9A8-7A7-14A3-9A6-14A3-9A5-16A2B9A5-14A3B-9A6-13A4-9A6-13AC4-7A8-12AC5-5A10-11A21-10A23-8A27-2A11-3A12-9A6-7A9-13A3-8A7-14A3-8A7-15AB-8A7-14A3B8A7-14A2(3-8A8-12AC)4-6A9-12A21-10A23-8A25-2(6A9-3A12-9A6-7A9-13A3-7A9-13AC2-8A8-13A2B-8A8-13A3B2(8A7-14A3-)7A9-12AC4-5A10-12A21-11A21-10A24-)6A9-3A12-9A6-7A9-13A3-8A7-14A3-8A7-15AB-8A7-14A3B8A7-14A2(3-8A8-12AC)4-6A9-12A21-10A23-8A25-6A9-4A10-9A8-7A7-14A3-9A6-14A3-9A5-16A2B9A5-14A3B-9A6-13A4-9A6-13AC4-7A8-12AC5-5A10-11A21-10A23-8A27-2A11-5A9-7A10-8A5-11A7-10A3-16A3-10A3-16AB2-2(10A3-15A4-)10A4-14AC4-8A6-12A-C5-6A8-11A23-8A25-6A42-5A7-6A12-9A2-11A10-24A7-26A6-27A5-27A6-26A6-9A3-13A8-7A6-11A25-6A74-6A4-8A13-20A11-21A11-23A8-25A2(8-24A)9-23A10-7A4-10A108-16A14-20A4(11-21A)2(12-20A)13-18A112-14A16-18A13-19A13-3(20A12-)19A14-18A16-15A114-12A18-16A15-17A15-3(18A14-)18A15-16A18-13A117-8A22-13A17-15A17-2(16A16-)16A17-14A19-13A20-10A150-9A22-12A2(19-13A)20-12A21-11A21-10A24-5A114-
