model
size = 22 21 4, scale = 0.05, origin = -y
material deform = 1, fade = true, lighting = smooth, roughness = 0.3, metalness = 0.6
  colors = A:#FF0 B:#181808
voxels
9-6A7-3A3-2A6-2A3-6A3-2A6-2A2(3-3A)2(2-6A2-3A6-3A)2-6A2-3A9-2(2A6-2A12-)2(2A6-)72A2-6A2-12A2(2-6A)3-2(16A6-)16A9-2(10A12-)10A14-6A8-3A3-2A6-2A3-6A3-2A6-2A2(3-3A)2(2-6A2-3A6-3A)2-6A2-3A9-2(2A6-2A12-)2(2A6-)72A2-6A2-12A2(2-6A)2(3-2(16A6-)16A9-2(10A12-)10A14-6A16-6A8-3A3-2A6-2A3-6A3-2A6-2A2(3-3A)2(2-6A2-3A6-3A)2-6A2-3A9-2(2A6-2A12-)2(2A6-)72A2B6A2B12A2(2B6A))3-2(16A6-)16A9-2(10A12-)10A14-6A16-6A8-
