model
size = 31 31 32, scale = 0.05, origin = -y
material deform = 1, fade = true, lighting = smooth, roughness = 0.3, metalness = 0.6
  colors = A:#080818 B:#FFB71C C:#0FF D:#F9E9E9
voxels
43-7B24-7B880-BD27BD2BD27BDB899-BD27BD2BD7B14A6BDB9-14A17-14A11-3(8A4C2A4C8A5-)3(2(2A2C)10A2(2C2A)5-)3(2A2C2A14C2A2C2A5-)3(2A22C2A5-)2(4A4C2A6C2A4C4A5-)4A4C2A6C2A4C4A7-2(4A14C4A9-)4A14C4A11-3(4A2C6A2C4A13-)3(2A2C4A2-4A2C2A13-)2(6A6-6A13-)2(6A6-)BD27BD10B14A8B9-14A17-14A11-3(8A4C2A4C8A5-)3(2(2A2C)10A2(2C2A)5-)3(2A2C2A14C2A2C2A5-)3(2A22C2A5-)2(4A4C2A6C2A4C4A5-)4A4C2A6C2A4C4A7-2(4A14C4A9-)4A14C4A11-3(4A2C6A2C4A13-)3(2A2C4A2-4A2C2A13-)2(6A6-6A13-)2(6A6-)40B14A8B9-14A17-14A11-3(8A4C2A4C8A5-)3(2(2A2C)10A2(2C2A)5-)3(2A2C2A14C2A2C2A5-)3(2A22C2A5-)2(4A4C2A6C2A4C4A5-)4A4C2A6C2A4C4A7-2(4A14C4A9-)4A14C4A11-3(4A2C6A2C4A13-)3(2A2C4A2-4A2C2A13-)2(6A6-6A13-)2(6A6-)BD27BD2BD7B14A6BDB9-14A17-14A11-3(8A4C2A4C8A5-)3(2(2A2C)10A2(2C2A)5-)3(2A2C2A14C2A2C2A5-)3(2A22C2A5-)2(4A4C2A6C2A4C4A5-)4A4C2A6C2A4C4A7-2(4A14C4A9-)4A14C4A11-3(4A2C6A2C4A13-)3(2A2C4A2-4A2C2A13-)2(6A6-6A13-)2(6A6-)2(BD27BD2BD27BDB899-)62B900-BD25BDB2-29B2(901-BD25BDB2-BD25BDB)901-29B2-29B901-2BD23BD2B2-29B902-2(BD23BDB4-BD23BDB903-)27B4-27B904-BD21BDB6-25B905-BD21BDB6-BD21BDB905-25B6-BD21BDB905-2BD19BD2B6-25B906-BD19BDB8-BD19BDB907-23B8-BD19BDB907-2BD17BD2B8-23B908-BD17BDB10-BD17BDB909-21B10-2BD15BD2B910-BD15BDB12-19B911-2BD13BD2B12-2BD13BD2B912-17B14-2BD11BD2B914-2BD9BD2B16-15B916-2BD7BD2B18-2B2D5B2D2B918-3B2DB2D3B20-4B3D4B909-
