model
size = 30 31 32, scale = 0.05, origin = -y
material deform = 1, fade = true, lighting = smooth, roughness = 0.3, metalness = 0.6
  colors = A:#FF0 B:#080818 C:#F9E9E9
voxels
30-AC26AC2AC26ACA852-6A24-6A892-3ACA2C3A20-4A2C4A889-2AC6AC2A18-2A2C4A2C2A887-2AC8AC2A16-14A885-16A14-2AC10AC2A883-2AC12AC2A12-2AC12AC2A882-AC14ACA12-18A881-20A10-2AC14AC2A880-AC16ACA10-AC16ACA879-2AC16AC2A8-22A878-22A8-AC18ACA878-AC18ACA8-AC18ACA877-2AC18AC2A6-24A876-24A2(6-AC20ACA876-AC20ACA)6-24A875-26A4-26A2(874-AC22ACA4-AC22ACA)873-2AC22AC2A2-28A872-28A2-28A2(872-AC24ACA2-AC24ACA)872-AC24ACA2-28A871-60A2(870-AC26AC2AC26ACA)870-AC26AC2AC6A13B7ACA8-14B16-14B10-3(8B4A2B4A8B4-)3(2(2B2A)10B2(2A2B)4-)3(2B2A2B14A2B2A2B4-)3(2B22A2B4-)2(4B4A2B6A2B4A4B4-)4B4A2B6A2B4A4B6-2(4B14A4B8-)4B14A4B10-3(4B2A6B2A4B12-)3(2B2A4B2-4B2A2B12-)2(6B6-6B12-)2(6B6-)38A13B9A8-14B16-14B10-3(8B4A2B4A8B4-)3(2(2B2A)10B2(2A2B)4-)3(2B2A2B14A2B2A2B4-)3(2B22A2B4-)2(4B4A2B6A2B4A4B4-)4B4A2B6A2B4A4B6-2(4B14A4B8-)4B14A4B10-3(4B2A6B2A4B12-)3(2B2A4B2-4B2A2B12-)2(6B6-6B12-)2(6B6-)AC26AC9A13B9A8-14B16-14B10-3(8B4A2B4A8B4-)3(2(2B2A)10B2(2A2B)4-)3(2B2A2B14A2B2A2B4-)3(2B22A2B4-)2(4B4A2B6A2B4A4B4-)4B4A2B6A2B4A4B6-2(4B14A4B8-)4B14A4B10-3(4B2A6B2A4B12-)3(2B2A4B2-4B2A2B12-)2(6B6-6B12-)2(6B6-)AC26AC2AC6A13B7ACA8-14B16-14B10-3(8B4A2B4A8B4-)3(2(2B2A)10B2(2A2B)4-)3(2B2A2B14A2B2A2B4-)3(2B22A2B4-)2(4B4A2B6A2B4A4B4-)4B4A2B6A2B4A4B6-2(4B14A4B8-)4B14A4B10-3(4B2A6B2A4B12-)3(2B2A4B2-4B2A2B12-)2(6B6-6B12-)2(6B6-)
