model
size = 31 32 32, scale = 0.05, origin = -y
material deform = 1, fade = true, lighting = smooth, roughness = 0.3, metalness = 0.6
  colors = A:#FF0 B:#F9E9E9 C:#180808 D:#CBCB00 E:#E8E9E8 F:#585858
voxels
43-7A24-7D24-7A880-3(AB27AB249A-5(29A2-)14A-14A2-14A-14A3-4(13A-13A4-)3(12A3-12A4-)12A3-12A5-2(11A3-11A6-)10A5-10A6-10A5-10A2(7-8A)8-8A7-8A2(9-6A)2(11-4A)6-)31AD29AD31A6B5C9B5C12B5C9B5C11BCF5C7B2CF4C10BCF5C7B2CF4C9BCF7C5B2CF6C8BCF7C5B2CF6C4B-3(3B9C5B9C3B2-)2(3B6CE2C5B6CE2C3B2-)3B6CE2C2B-2B6CE2C3B2-3B6CE2C2B-2B6CE2C3B3-2(3B4CE2C3B-3B4CE2C3B4-)2(4B5C4B-4B5C4B4-)12B3-12B3(4-12A3-12A)5-2(11A3-11A6-)10A5-10A6-10A5-10A2(7-8A)8-8A7-8A2(9-6A)2(11-4A)6-AB27ABAD29AD31A6B5C9B5C12B5C9B5C11BCF5C7B2CF4C10BCF5C7B2CF4C9BCF7C5B2CF6C8BCF7C5B2CF6C4B-3(3B9C5B9C3B2-)2(3B6CE2C5B6CE2C3B2-)3B6CE2C2B-2B6CE2C3B2-3B6CE2C2B-2B6CE2C3B3-2(3B4CE2C3B-3B4CE2C3B4-)2(4B5C4B-4B5C4B4-)12B3-12B4-C10BC3-C10BC2(4-12A3-12A)5-2(11A3-11A6-)10A5-10A6-10A5-10A2(7-8A)8-8A7-8A2(9-6A)2(11-4A)6-AB27ABAD29AD31A7B3C11B3C13B5C9B5C11BCF5C7B2CF4C10BCF5C7B2CF4C9BCF7C5B2CF6C8BCF7C5B2CF6C4B-3(3B9C5B9C3B2-)2(3B6CE2C5B6CE2C3B2-)3B6CE2C2B-2B6CE2C3B2-3B6CE2C2B-2B6CE2C3B3-2(3B4CE2C3B-3B4CE2C3B4-)4B5C4B-4B5C4B4-5B3C5B-5B3C5B4-12B3-12B4-C10BC3-C10BC2(4-12A3-12A)5-2(11A3-11A6-)10A5-10A6-10A5-10A2(7-8A)8-8A7-8A2(9-6A)2(11-4A)6-AB27ABAD29ADAB27ABA560-12C3-12C2(4-12A3-12A)5-2(11A3-11A6-)10A5-10A6-10A5-10A2(7-8A)8-8A7-8A2(9-6A)2(11-4A)6-31AD29AD31A561-5(C-)C3-5(C-)C314-AB25ABA2-D27AD2-29A562-4(C-)C7-4(C-)C314-AB25ABA2-D27AD2-AB25ABA564-3(C-)C7-3(C-)C316-AB25ABA2-D27AD2-AB25ABA566-C-C11-C-C318-29A2-D27AD2-29A901-2AB23AB2A2-D27AD2-29A902-2(AB23ABA4-D25AD4-AB23ABA903-)27A4-D25AD4-27A904-AB21ABA6-D23AD6-25A905-AB21ABA6-D23AD6-AB21ABA905-25A6-D23AD6-AB21ABA905-2AB19AB2A6-D23AD6-25A906-AB19ABA8-D21AD8-AB19ABA907-23A8-D21AD8-AB19ABA907-2AB17AB2A8-D21AD8-23A908-AB17ABA10-D19AD10-AB17ABA909-21A10-D19AD10-2AB15AB2A910-AB15ABA12-D17AD12-19A911-2AB13AB2A12-D17AD12-2AB13AB2A912-17A14-D15AD14-2AB11AB2A914-2AB9AB2A16-D13AD16-15A916-2AB7AB2A18-D11AD18-2A2B5A2B2A918-3A2BA2B3A20-2D7A2D20-4A3B4A909-
