model
size = 31 31 32, scale = 0.05, origin = -y
material deform = 1, fade = true, lighting = smooth, roughness = 0.3, metalness = 0.6
  colors = A:#FF1B1B B:#F2BB08 C:#180808 D:#181808 E:#080818 F:#180818 G:#F9E9E9 H:#282808
voxels
43-7A24-7A880-AG27AG2AG27AGA899-AG27AG2AG4A14C4D2C3AGA6-2(14C4D2C11-)3(2C2B2F2B2E2C2B2E2B2D11-)3(4C2B2F4B2E2B2D2C11-)3(6C2B2F2C2B2E2D2C11-)3(2C16B2D11-)3(2C4B2F4B2E4B2D11-)2(4C12B2D2C11-)4C12B2D2C13-2(4C8B2H2D15-)4C8B2H2D17-2(4C4B2F2C19-)4C4B2F2C21-2(8C23-)8C11-AG27AG7A14C4D2C5A6-2(14C4D2C11-)3(2C2B2F2B2E2C2B2E2B2D11-)3(4C2B2F4B2E2B2D2C11-)3(6C2B2F2C2B2E2D2C11-)3(2C16B2D11-)3(2C4B2F4B2E4B2D11-)2(4C12B2D2C11-)4C12B2D2C13-2(4C8B2H2D15-)4C8B2H2D17-2(4C4B2F2C19-)4C4B2F2C21-2(8C23-)8C11-37A14C4D2C5A6-2(14C4D2C11-)3(2C2B2F2B2E2C2B2E2B2D11-)3(4C2B2F4B2E2B2D2C11-)3(6C2B2F2C2B2E2D2C11-)3(2C16B2D11-)3(2C4B2F4B2E4B2D11-)2(4C12B2D2C11-)4C12B2D2C13-2(4C8B2H2D15-)4C8B2H2D17-2(4C4B2F2C19-)4C4B2F2C21-2(8C23-)8C11-AG27AG2AG4A14C4D2C3AGA6-2(14C4D2C11-)3(2C2B2F2B2E2C2B2E2B2D11-)3(4C2B2F4B2E2B2D2C11-)3(6C2B2F2C2B2E2D2C11-)3(2C16B2D11-)3(2C4B2F4B2E4B2D11-)2(4C12B2D2C11-)4C12B2D2C13-2(4C8B2H2D15-)4C8B2H2D17-2(4C4B2F2C19-)4C4B2F2C21-2(8C23-)8C11-2(AG27AG2AG27AGA899-)62A900-AG25AGA2-29A2(901-AG25AGA2-AG25AGA)901-29A2-29A901-2AG23AG2A2-29A902-2(AG23AGA4-AG23AGA903-)27A4-27A904-AG21AGA6-25A905-AG21AGA6-AG21AGA905-25A6-AG21AGA905-2AG19AG2A6-25A906-AG19AGA8-AG19AGA907-23A8-AG19AGA907-2AG17AG2A8-23A908-AG17AGA10-AG17AGA909-21A10-2AG15AG2A910-AG15AGA12-19A911-2AG13AG2A12-2AG13AG2A912-17A14-2AG11AG2A914-2AG9AG2A16-15A916-2AG7AG2A18-2A2G5A2G2A918-3A2GA2G3A20-4A3G4A909-
