model
size = 30 31 32, scale = 0.05, origin = -y
material deform = 1, fade = true, lighting = smooth, roughness = 0.3, metalness = 0.6
  colors = A:#080818 B:#F00 C:#0FF D:#F9E9E9
voxels
42-6B24-6B852-BD26BD2BD26BDB870-BD26BD2BD7B13A6BDB8-14A16-14A10-3(8A4C2A4C8A4-)3(2(2A2C)10A2(2C2A)4-)3(2A2C2A14C2A2C2A4-)3(2A22C2A4-)2(4A4C2A6C2A4C4A4-)4A4C2A6C2A4C4A6-2(4A14C4A8-)4A14C4A10-3(4A2C6A2C4A12-)3(2A2C4A2-4A2C2A12-)2(6A6-6A12-)2(6A6-)BD26BD10B13A8B8-14A16-14A10-3(8A4C2A4C8A4-)3(2(2A2C)10A2(2C2A)4-)3(2A2C2A14C2A2C2A4-)3(2A22C2A4-)2(4A4C2A6C2A4C4A4-)4A4C2A6C2A4C4A6-2(4A14C4A8-)4A14C4A10-3(4A2C6A2C4A12-)3(2A2C4A2-4A2C2A12-)2(6A6-6A12-)2(6A6-)39B13A8B8-14A16-14A10-3(8A4C2A4C8A4-)3(2(2A2C)10A2(2C2A)4-)3(2A2C2A14C2A2C2A4-)3(2A22C2A4-)2(4A4C2A6C2A4C4A4-)4A4C2A6C2A4C4A6-2(4A14C4A8-)4A14C4A10-3(4A2C6A2C4A12-)3(2A2C4A2-4A2C2A12-)2(6A6-6A12-)2(6A6-)BD26BD2BD7B13A6BDB8-14A16-14A10-3(8A4C2A4C8A4-)3(2(2A2C)10A2(2C2A)4-)3(2A2C2A14C2A2C2A4-)3(2A22C2A4-)2(4A4C2A6C2A4C4A4-)4A4C2A6C2A4C4A6-2(4A14C4A8-)4A14C4A10-3(4A2C6A2C4A12-)3(2A2C4A2-4A2C2A12-)2(6A6-6A12-)2(6A6-)2(BD26BD2BD26BDB870-)60B871-BD24BDB2-28B2(872-BD24BDB2-BD24BDB)872-28B2-28B872-2BD22BD2B2-28B873-2(BD22BDB4-BD22BDB874-)26B4-26B875-BD20BDB6-24B876-BD20BDB6-BD20BDB876-24B6-BD20BDB876-2BD18BD2B6-24B877-BD18BDB8-BD18BDB878-22B8-BD18BDB878-2BD16BD2B8-22B879-BD16BDB10-BD16BDB880-20B10-2BD14BD2B881-BD14BDB12-18B882-2BD12BD2B12-2BD12BD2B883-16B14-2BD10BD2B885-2BD8BD2B16-14B887-2BD6BD2B18-2B2D4B2D2B889-3B2DBD3B20-4B2D4B880-
