model
size = 30 31 32, scale = 0.05, origin = -y
material deform = 1, fade = true, lighting = smooth, roughness = 0.3, metalness = 0.6
  colors = A:#F0F B:#FF0 C:#180808 D:#181808 E:#080818 F:#180818 G:#F9E9E9 H:#282808
voxels
42-6A24-6A852-AG26AG2AG26AGA870-AG26AG2AG4A13C4D2C3AGA5-2(14C4D2C10-)3(2C2B2F2B2E2C2B2E2B2D10-)3(4C2B2F4B2E2B2D2C10-)3(6C2B2F2C2B2E2D2C10-)3(2C16B2D10-)3(2C4B2F4B2E4B2D10-)2(4C12B2D2C10-)4C12B2D2C12-2(4C8B2C2D14-)4C8B2C2D16-2(4C4B2F2C18-)4C4B2F2C20-2(8C22-)8C11-AG26AG7A13C4D2C5A5-2(14C4D2C10-)3(2C2B2F2B2E2C2B2E2B2D10-)3(4C2B2F4B2E2B2D2C10-)3(6C2B2F2C2B2E2D2C10-)3(2C16B2D10-)3(2C4B2F4B2E4B2D10-)2(4C12B2D2C10-)4C12B2D2C12-2(4C8B2H2D14-)4C8B2H2D16-2(4C4B2F2C18-)4C4B2F2C20-2(8C22-)8C11-36A13C4D2C5A5-2(14C4D2C10-)3(2C2B2F2B2E2C2B2E2B2D10-)3(4C2B2F4B2E2B2D2C10-)3(6C2B2F2C2B2E2D2C10-)3(2C16B2D10-)3(2C4B2F4B2E4B2D10-)2(4C12B2D2C10-)4C12B2D2C12-2(4C8B2H2D14-)4C8B2H2D16-2(4C4B2F2C18-)4C4B2F2C20-2(8C22-)8C11-AG26AG2AG4A13C4D2C3AGA5-2(14C4D2C10-)3(2C2B2F2B2E2C2B2E2B2D10-)3(4C2B2F4B2E2B2D2C10-)6C2B4C2B2E2D2C10-6C2BF3C2B2E2D2C10-6C2B4C2B2E2D2C3(10-2C16B2D)3(10-2C4B2F4B2E4B2D)3(10-4C12B2D2C)12-4C8B3CD2(14-4C8B2C2D)16-2(4C4B2F2C18-)4C4B2F2C20-2(8C22-)8C11-2(AG26AG2AG26AGA870-)60A871-AG24AGA2-28A2(872-AG24AGA2-AG24AGA)872-28A2-28A872-2AG22AG2A2-28A873-2(AG22AGA4-AG22AGA874-)26A4-26A875-AG20AGA6-24A876-AG20AGA6-AG20AGA876-24A6-AG20AGA876-2AG18AG2A6-24A877-AG18AGA8-AG18AGA878-22A8-AG18AGA878-2AG16AG2A8-22A879-AG16AGA10-AG16AGA880-20A10-2AG14AG2A881-AG14AGA12-18A882-2AG12AG2A12-2AG12AG2A883-16A14-2AG10AG2A885-2AG8AG2A16-14A887-2AG6AG2A18-2A2G4A2G2A889-3A2GAG3A20-4A2G4A880-
