model
size = 32 20 32, scale = 0.05, origin = -y
material deform = 1, fade = true, lighting = smooth, roughness = 0.3, metalness = 0.6
  colors = A:#171828 B:#00FF8C C:#1AD960 D:#00FF6A E:#0F9 F:#009A69 G:#00A040 H:#009F79 I:#00BD42
voxels
33-AB26ABA2-AB26ABA558-6A26-6A600-3ABA2B3A22-4A2B4A597-2AB6AB2A20-2A2B4A2B2A595-2AB8AB2A18-14A593-16A16-2AB10AB2A591-2AB12AB2A14-2AB12AB2A590-AB14ABA14-18A589-20A12-2AB14AB2A588-AB16ABA12-AB16ABA587-2AB16AB2A10-22A586-22A10-AB18ABA586-AB18ABA10-AB18ABA585-2AB18AB2A8-24A584-24A2(8-AB20ABA584-AB20ABA)8-24A583-26A6-26A2(582-AB22ABA6-AB22ABA)581-2AB22AB2A4-28A580-28A4-28A2(580-AB24ABA4-AB24ABA)580-AB24ABA4-28A579-30A2-30A3(578-AB26ABA2-AB26ABA)6-22A10-AI3E2AB6AB2A3BFA10-6AB8AB6A10-ACG2ABC8ACB2AGCA10-AB2AFB2AH2B5ABF2ACA10-AE2AC5A2B5AC2AB2A8-2AB2AD6A2B4A2(B2A)8-ACB2AB7ABC3AB2ABCA8-ABC2AD8AB3AB2ACBA8-AB3AD8ABC2AB3AB2A7-AB3AD9AD2ABA-AB2A6-A2BA-ADF2AB5ABAFCA-A2BA6-AB2A-2ABADE2(2AB)AB2A-2ABA3-4AB2A-2A2(CAB)D2ADAC2A-2AB5AG2ABA3-3AB2ADC6A2-2AB2AG2A2(CB)A5-4AE6A4-ABC2E3AFB2A6-7A7-2AEF2A-5A8-3A9-5A2(2-30A)6-22A10-AI3E2AB6AB2A3BFA10-6AB8AB6A10-ACG2ABC8ACB2AGCA10-AB2AFB2AH2B5ABF2ACA10-AE2AC5A2B5AC2AB2A8-2AB2AD6A2B4A2(B2A)8-ACB2AB7ABC3AB2ABCA8-ABC2AD8AB3AB2ACBA8-AB3AD8ABC2AB3AB2A7-AB3AD9AD2ABA-AB2A6-A2BA-ADF2AB5ABAFCA-A2BA6-AB2A-2ABADE2(2AB)AB2A-2ABA3-4AB2A-2A2(CAB)D2ADAC2A-2AB5AG2ABA3-3AB2ADC6A2-2AB2AG2A2(CB)A5-4AE6A4-ABC2E3AFB2A6-7A7-2AEF2A-5A8-3A9-5A2-AB26ABA2-30A6-22A10-AI3E2AB6AB2A3BFA10-6AB8AB6A10-ACG2ABC8ACB2AGCA10-AB2AFB2AH2B5ABF2ACA10-AE2AC5A2B5AC2AB2A8-2AB2AD6A2B4A2(B2A)8-ACB2AB7ABC3AB2ABCA8-ABC2AD8AB3AB2ACBA8-AB3AD8ABC2AB3AB2A7-AB3AD9AD2ABA-AB2A6-A2BA-ADF2AB5ABAFCA-A2BA6-AB2A-2ABADE2(2AB)AB2A-2ABA3-4AB2A-2A2(CAB)D2ADAC2A-2AB5AG2ABA3-3AB2ADC6A2-2AB2AG2A2(CB)A5-4AE6A4-ABC2E3AFB2A6-7A7-2AEF2A-5A8-3A9-5A2(2-AB26ABA)577-
