model
size = 32 16 4, scale = 0.05, origin = -y
material deform = 1, fade = true, lighting = smooth, roughness = 0.3, metalness = 0.6
  colors = A:#002111 B:#04240F C:#00250E D:#001B0F
voxels
3-A26-D7-A3D2-A6-A2-4A17-A8-A16-B4-AB8-BA4-B10-A4-A2-3A5-A4-B10-D3-B5-2A5-B3-A10-A3-C6-2A4-A3-A9-BA3-A7-AB2(3-A)B8-AB3-C8-2(A3-)BA8-A4-C8-AB2-A4-A8-A4-C9-C2-A4-A7-2A4-C3-A5-A2-B4-2A2(6-A)-CD2(2-A)-3(A6-)2(B-A)C2-C-B2(6-A)8-A2-CB11-A3-2(BA)11-D12-AB2D6-A3D2-A6-A2-4A17-A8-A16-B4-AB8-BA4-B10-A4-A2-3A5-A4-B10-D3-B5-2A5-B3-A10-A3-C6-2A4-A3-A9-BA3-A7-AB2(3-A)B8-AB3-C8-2(A3-)BA8-A4-C8-AB2-A4-A8-A4-C9-C2-A4-A7-2A4-C3-A5-A2-B4-2A2(6-A)-CD2(2-A)-3(A6-)2(B-A)C2-C-B2(6-A)8-A2-CB11-A3-2(BA)11-D12-AB2D2-A26-D8-A3D2-A6-A2-4A17-A8-A16-B4-AB8-BA4-B10-A4-A2-3A5-A4-B10-D3-B5-2A5-B3-A10-A3-C6-2A4-A3-A9-BA3-A7-AB2(3-A)B8-AB3-C8-2(A3-)BA8-A4-C8-AB2-A4-A8-A4-C9-C2-A4-A7-2A4-C3-A5-A2-B4-2A2(6-A)-CD2(2-A)-3(A6-)2(B-A)C2-C-B2(6-A)8-A2-CB11-A3-2(BA)11-D12-AB2D2-A26-D8-A3D2-A6-A2-4A17-A8-A16-B4-AB8-BA4-B10-A4-A2-3A5-A4-B10-D3-B5-2A5-B3-A10-A3-C6-2A4-A3-A9-BA3-A7-AB2(3-A)B8-AB3-C8-2(A3-)BA8-A4-C8-AB2-A4-A8-A4-C9-C2-A4-A7-2A4-C3-A5-A2-B4-2A2(6-A)-CD2(2-A)-3(A6-)2(B-A)C2-C-B2(6-A)8-A2-CB11-A3-2(BA)11-D12-AB2D2-A26-D2-
