model
size = 15 12 5, scale = 0.05, origin = -y
material deform = 1, fade = true, lighting = smooth, roughness = 0.3, metalness = 0.6
  colors = A:#C6C B:#111 C:#222 D:#936 E:#F06 F:#C06 G:#F36 H:#C09 I:#C03 J:#0F6 K:#C0C
voxels
37-A13-A-A11-A3-A9-A5-A7-2(A3-)A5-A3-A-A3-A5-A-A3-A-A7-A5-A56-B13-B-B11-B3-B9-B5-2(B7-)B5-B4-A4-B3-B4-B-B4-2(B3-)B-B3-B5-B-B3-B-B7-B5-B26-A13-AHA11-AFBFA9-AIB-BJA7-AGB3-BGA5-AEB5-BEA3-AEB3-K3-BEA-ADB3-BCB3-BDA-ADB-BA-AB-BDA3-ADBDA-ADBDA5-ADA3-ADA7-A5-A26-C13-C-C11-C3-C9-C5-2(C7-)C5-C4-A4-C3-C4-A-A4-2(C3-)C-C3-C5-C-C3-C-C7-C5-C56-A13-A-A11-A3-A9-A5-A7-2(A3-)A5-A3-A-A3-A5-A-A3-A-A7-A5-A34-
