model
size = 23 18 10, scale = 0.05, origin = -y
material deform = 1, fade = true, lighting = smooth, roughness = 0.3, metalness = 0.6
  colors = A:#555 B:#111
voxels
68-2A691-19A4-19A18-5A348-3A12B6A2-3A12-6A17-6A346-2AB2A11B3AB5A-2A11-3A-3A16-3A-3A322-A21-2A3BA11B2A3B3A3-A11-2A3-2A16-2A3-2A45-13(2A21-)2A3BA6B-9B3A3-A16-2A21-2A22-2A183-A6(21-2A)3BA5B3-3B2A3B3A3-A11-2A3-2A16-2A3-2A22-2A321-2AB2A5B3-3B3AB5A-2A11-3A-3A16-3A-3A22-2A322-3A5B5-2B6A2-3A12-6A17-6A23-2A323-7A5-7A2(18-5A)2-
