model
size = 27 32 27, scale = 0.05, origin = -y
material deform = 1, fade = true, lighting = smooth, roughness = 0.3, metalness = 0.6
  colors = A:#777
voxels
10-7A20-7A21-5A23-3A776-2(11A16-)11A17-9A19-7A745-4A7-4A3(12-15A)13-13A15-11A714-4A11-4A2(8-6A7-6A)8-19A9-17A11-15A15-9A20-2(5A22-)5A24-A583-3A15-3A2(6-5A11-5A)6-2(7A7-)19A9-18A10-15A16-7A21-5A22-5A23-3A24-3A25-A529-2A17-2A2(6-4A13-4A)6-5A11-5A6-8A5-8A7-19A9-17A13-11A19-3(5A22-)5A23-3A25-A26-A474-2A19-2A2(4-4A15-4A)4-5A13-5A5-6A9-6A6-21A7-19A11-13A18-4(5A22-)5A23-3A24-3A25-2(A26-)A269-4(A26-)A15-2A19-2A2(4-3A17-3A)4-4A15-4A4-5A13-5A2(5-8A)7-19A10-15A15-9A20-5(5A22-)5A23-3A24-3A25-2(A26-)A107-3(A26-)A25-2(3A24-)3A25-A41-2A21-2A2(2-3A19-3A)2-4A17-3A4-5A13-5A4-7A9-6A6-8A5-8A8-17A13-11A19-7(5A22-)5A23-3A24-3A25-4(A26-)A25-3A23-2(5A22-)5A23-3A25-A26-A41-2A21-2A2(2-3A19-3A)2-4A17-4A2-5A15-4A4-6A11-6A5-7A7-7A8-17A12-13A18-8(5A22-)5A23-5(3A24-)3A23-2(5A22-)5A23-3A24-3A25-A67-2A23-5A21-6A21-3A-3A19-3A2-5A15-5A2-7A11-6A4-7A9-6A7-19A11-13A18-16(5A22-)5A23-3A24-3A25-A94-2A23-5A21-6A21-7A19-4A-4A17-4A2-6A13-5A4-6A11-5A7-19A10-15A17-15(5A22-)5A23-3A24-3A25-A26-A94-2A23-5A21-6A21-7A19-9A17-4A2-6A13-5A4-6A11-5A7-19A10-15A17-14(5A22-)5A23-3A24-3A25-A26-A121-2A23-5A21-6A21-7A19-9A17-4A2-6A13-5A4-6A11-5A7-19A10-15A17-13(5A22-)5A23-3A24-3A25-A26-A148-2A23-5A21-6A21-7A19-9A17-4A2-6A13-5A4-6A11-5A7-19A10-15A17-11(5A22-)5A23-2(3A24-)3A25-A26-A175-2A23-5A21-6A21-7A19-4A-4A17-4A2-6A13-5A4-6A11-5A7-19A10-15A17-9(5A22-)5A23-2(3A24-)3A25-2(A26-)A202-2A23-5A21-6A21-3A-3A19-3A2-5A15-5A2-7A11-6A4-7A9-6A7-19A11-13A18-7(5A22-)5A23-2(3A24-)3A25-2(A26-)A257-2A21-2A2(2-3A19-3A)2-4A17-4A2-5A15-4A4-6A11-6A5-7A7-7A8-17A12-13A18-6(5A22-)5A23-3A24-3A25-2(A26-)A311-2A21-2A2(2-3A19-3A)2-4A17-3A4-5A13-5A4-7A9-6A6-8A5-8A8-17A13-11A19-4(5A22-)5A23-2(3A24-)3A25-A26-A366-2A19-2A2(4-3A17-3A)4-4A15-4A4-5A13-5A2(5-8A)7-19A10-15A15-9A20-2(5A22-)5A23-3(3A24-)3A25-A26-A393-2A19-2A2(4-4A15-4A)4-5A13-5A5-6A9-6A6-21A7-19A11-13A18-2(5A22-)5A23-3A24-3A25-2(A26-)A448-2A17-2A2(6-4A13-4A)6-5A11-5A6-8A5-8A7-19A9-17A13-11A19-5A22-5A23-3A25-A26-A529-3A15-3A2(6-5A11-5A)6-2(7A7-)20A8-18A10-15A16-7A21-5A24-A26-A584-4A11-4A2(8-6A7-6A)8-19A9-17A11-15A14-11A689-4A7-4A3(12-15A)13-13A16-9A20-5A694-3(11A16-)11A17-9A20-5A723-2(7A20-)7A21-5A23-3A741-
