model
size = 30 13 6, scale = 0.05, origin = -y
material deform = 1, fade = true, lighting = smooth, roughness = 0.3, metalness = 0.6
  colors = A:#FC0 B:#FF3 C:#222 D:#333 E:#444 F:#555
voxels
133-3B26-B3AB24-2(B5AB23-)B5AB24-B3AB26-3B177-3B26-B3AB24-2(B5AB23-)B5AB24-B3AB26-3B137-2B19-4B5-A4B14-2B3AB4-B4A3B3-BAB5-2B4AB4-B7A2BAC2DA4B6AB4-B9A5C11AB2-B10A2C2DC11AB2-B10AC3EC11AB3-B5A4BA3CA4B6AB4-B3A3B4-BAB5-3B3AB4-B2A2B16-2B2AB4-3B20-3B34-5A18-3A4-A2C4A14-6A2-2A2C3D3A11-B5CA2-3AC2DEDCA-2(AB)2-4A3E2FDA2-7AC2DA2C2D2ADED3CD2EF4A2D3C4A6CD9ADE2A7E4D2C2D2CD7C2AC3ACD3C2A3CD3E5C2D4ED11A2C2AF2E2(3AC)D3E2A-ACA3C2D2A2-BAB2-3AC4A2CA2-A5D3A9-4AD4CA2-2AE4A14-3A3DA2-5A18-5A3-5A18-2A5-A2C4A14-6A2-2A2C3D3A11-B5CA2-3AC2DEDCBA-BAB2-4A3E2FDA2-7AC2DCAC2D2ADED3CD2EF5AD3C4A6CD9ADE2AEA5E4D2C2D2CD7C2AC4AD3C2A3CD3E5C2D4ED11A2C2AF2E2ADC3ACD3E2A-3A3C2DBA2-BAB2-3AC4A2CA2-2A4D3A9-4AD4CA2-2AE4A14-3A3DA2-5A18-5A34-3B18-4B5-BA3B14-3B3A5-B4A2B3-BAB2(5-B6A)2BAC2DA4B7A4-AB8A5C11AB2-2AB8A2C2DC11AB3-AB8AC3EC11AB4-B5A3BA3CA4B7A5-B3A2B4-BAB5-2B5A5-BA2B16-2B3A5-2B20-3B32-
