model
size = 27 28 14, scale = 0.05, origin = -y
material deform = 1, fade = true, lighting = smooth, roughness = 0.3, metalness = 0.6
  colors = A:#0FF B:#00E C:#0FC D:#0CC E:#09C F:#0F9 G:#9D6D0E H:#0F6 I:#963 J:#930 K:#EEE L:#111 M:#0CF N:#008 O:#200 P:#AAA
voxels
521-3L5-3L262-B186-B7-B49-B510-B26-B159-B7-B18-B7-B22-B26-B483-B4-B20-2A26-B132-B7-B17-2A6-2A18-2(B3-)B21-2A26-B51-2(B3-B22-)2A2-2A21-B3-B324-B2(21-B4-B20-2A26-B132-B7-B17-2A6-2A18-2(B3-)B21-2A26-B78-B3-B22-2A2-2A21-B3-B297-B25-2A)21-B4-B20-2A2(26-B)105-B7-B17-2A6-2A18-2(B3-)B18-B2-2A3-B22-B26-B51-B3-B22-2A2-2A21-B3-B297-B25-2A21-B4-B20-2A25-2A-4(E26-)E22-B-2EBE2-B17-2A-EC2BE2A17-2A2EC2BE2A18-E2C2AC2E19-E2C2AC2E20-EC2BC2E21-E2BCE22-2(B-)B22-B-E-B324-B25-2A26-B22-DED-B22-2(DED24-)DED23-2DED22-D2EFE2D20-DEC2F2E2D17-D2EC2F2(2E2D16-DE3CFC)2E2D16-2DEC2FC2E2D18-DE2FCED21-DEF2D22-BDEDB24-2(D26-)D215-C26-C25-2(C-)B21-C-B-2(2A20-C-DED)-C20-C-DED22-C-DED-C21-2DED-C17-2C-D2EFE2D3B14-C2-DEC2F2E2DB14-C-D2EC2F2(2E2D-C12-C-DE3CFC)2E2D-C12-C-2DEC2FC2E2D2C13-C2-DE2FCED2-C15-2C-DEF2D-2C18-C-DED-C21-2(C-D-C22-)C-D-C23-C-C25-C107-A26-A25-ACA24-ACA22-2ACBC2A20-ACBDB2CA6-A4-A6-ACBDEDBCA5-A6-A5-ACBDEDBCA4-A8-A5-CBDED2B4-A10-2A2-ACBDEDBCA2-A12-3A2B2DEDBC4A12-A2CBD2EFE2D3C14-C2BDEC2F2E2DCA12-ACBD2EC2F2(2E2DBCA10-ACBDE3CFC)2E2DBCA10-ACB2DEC2FC2E2D2CA11-AC2BDE2FCED2BCA13-A2CBDEF2DB2CA15-2ACBDEDBC2A18-2(ACBDBCA20-)ACBDBCA21-ACBCA23-ACA25-A53-B25-BAB24-BAB23-BAFAB21-2BAFA2B19-B2AFHF2AB6-6B6-BAFHAH2FAB4-BAB2-BAB4-BAFHADAHFAB3-BAB4-BAB3-BAFHADAHFAB2-BAB6-BA2B2-BFHADAHAB2-BAB8-B2A2BAFHADAHFA2BAB10-B3AFH2ADAHF4AB10-BA2FHA2DCD2A3FB12-BF2HADF2C2D2AFAB10-BAFHA2DF2C2(2D2AHFAB8-BAFHAD3MCM)2D2AHFAB8-BAFH2ADM2CF2D2A2FAB9-BAF2HAD2CFDA2HFAB11-BA2FHADCDAH2FAB13-B2AFHADAHF2AB15-2BAFHAHFA2B17-BAFHAHFAB18-BAFHAHFAB19-BAFHFAB21-BAFAB23-BAB25-B161-J25-3J23-3(5J22-)5J21-2J3OJ20-IGO3GOG18-4G2I3G2I16-2I2K2IG2K3G14-IGK2NKGKPNK2I14-2GKPNKGK2NK2I14-GIG2(2K3G)15-2G2LG2I2L2I18-2G3I2G21-GI3G23-2GI24-IGI24-I2G25-G590-2L3-2L253-
