model
size = 22 6 22, scale = 0.05, origin = -y
material deform = 1, fade = true, lighting = smooth, roughness = 0.3, metalness = 0.6
  colors = A:#FC0 B:#070 C:#FF3 D:#080 E:#03F F:#050 G:#E00 H:#06F I:#00B
voxels
54-DB20-BD20-FB20-BD42-DB20-BD20-DB20-BD41-4A4(18-A2BA)18-4A38-8A14-E6CE14-8A16-4A36-2(A10-)2A8-2A10-2CA6-A2C10-3A6-3A2(10-A)31-A12-A8-2A10-2A8-GA10-AG8-2A10-2A8-A12-A29-A14-A6-2A12-2A6-CA12-AC6-2A12-2A6-A14-A50-A14-A6-C14-C6-A14-A71-A15-2A4-H15-AI4-A15-2A70-A16-A4-C16-C4-A16-A47-A18-A2-2A16-2A2-AC2(16-2A2-2A)16-2A2(2-A18-A)-DBA16-ABF2BC16-AB2DBA16-A2BFBA16-ABD-A18-A2-A18-A-FBA16-AB2DBC16-A4BA16-AB2DBA16-A2B-2(A18-A2-)2A16-2A2-AC2(16-2A2-2A)16-2A2-A18-A25-A16-A4-C16-C4-A16-A70-A15-2A4-H15-AE4-A15-2A71-A14-A6-C14-C6-A14-A50-A14-A6-2A12-2A6-CA12-AC6-2A12-2A6-A14-A29-A12-A8-2A10-2A8-GA10-AG8-2A10-2A8-A12-A31-2(A10-)3A6-3A10-2CA6-A2C10-3A6-3A2(10-A)56-8A14-H6CE14-8A16-4A40-4A4(18-A2BA)18-4A9-
