model
size = 30 32 3, scale = 0.05, origin = -y
material deform = 1, fade = true, lighting = smooth, roughness = 0.3, metalness = 0.6
  colors = A:#DDD B:#111 C:#A00 D:#CF3 E:#E00
voxels
13-4A25-6A23-8A21-10A19-12A17-14A15-16A13-18A11-20A9-22A7-11A-12A5-11A2(3-12A)-A-13A-62A2-22A2-3A4-20A4-A6-4(18A12-)18A11-20A9-22A7-24A5-3(5A2-)5A5-5A2-3A4-3A2-5A7-2A2-A-2A6-2A-A2-2A9-2A-3A8-3A-2A11-4A10-4A13-2A12-2A2(14-A)20-4A25-6A23-5AB2A21-10A19-12A17-14A15-16A13-18A11-20A9-22A7-24A5-26A3-28A-62A2-22A2-3A4-20A4-A6-4(18A12-)18A11-20A9-22A7-24A5-3(5A2-)5A5-5A2-3A4-3A2-5A7-2A2-A-2A6-2A-A2-2A9-2A-3A8-3A-2A11-4A10-4A13-2A12-2A2(14-A)80-4B25-6B23-2B4C2B21-2B-C2-C-2B19-2B8-2B17-2B-C6-C-2B15-2B2-C6BC2-2B13-2B2-3B4-3B2-2B11-2B-3B8-3B-2B9-5B6-B5-5B7-3B9-B8-3B5-B10-2(B-)B9-B15-5B52-B8-B19-3B6-3B17-B-D-B4-B-D-B16-BDEDB4-BDEDB16-B-D-B4-B-D-B17-3B6-3B14-B4-B8-B4-B9-B20-B7-B22-B5-B24-B5-B8-B4-B8-B7-3(B6-)B9-B4-B8-B4-B11-B2-B10-B2-B13-2B12-2B2(14-B)7-
