model
size = 32 31 32, scale = 0.05, origin = -y
material deform = 1, fade = true, lighting = smooth, roughness = 0.3, metalness = 0.6
  colors = A:#F0F B:#F2BB08 C:#180808 D:#181808 E:#080818 F:#180818 G:#F9E9E9 H:#282808
voxels
44-8A24-8A908-AG28AG2AG28AGA928-AG28AG2AG4A15C4DC4AGA6-2(14C4D2C12-)3(2C2B2F2B2E2C2B2E2B2D12-)3(4C2B2F4B2E2B2D2C12-)3(6C2B2F2C2B2E2D2C12-)3(2C16B2D12-)3(2C4B2F4B2E4B2D12-)2(4C12B2D2C12-)4C12B2D2C14-2(4C8B2C2D16-)4C8B2C2D18-2(4C4B2F2C20-)4C4B2F2C22-2(8C24-)8C12-AG28AG7A15C4DC6A6-2(14C4D2C12-)3(2C2B2F2B2E2C2B2E2B2D12-)3(4C2B2F4B2E2B2D2C12-)3(6C2B2F2C2B2E2D2C12-)3(2C16B2D12-)3(2C4B2F4B2E4B2D12-)2(4C12B2D2C12-)4C12B2D2C14-2(4C8B2H2D16-)4C8B2H2D18-2(4C4B2F2C20-)4C4B2F2C22-2(8C24-)8C12-38A15C4DC6A6-2(14C4D2C12-)3(2C2B2F2B2E2C2B2E2B2D12-)3(4C2B2F4B2E2B2D2C12-)3(6C2B2F2C2B2E2D2C12-)3(2C16B2D12-)3(2C4B2F4B2E4B2D12-)2(4C12B2D2C12-)4C12B2D2C14-2(4C8B2H2D16-)4C8B2H2D18-2(4C4B2F2C20-)4C4B2F2C22-2(8C24-)8C12-AG28AG2AG4A15C4DC4AGA6-2(14C4D2C12-)3(2C2B2F2B2E2C2B2E2B2D12-)3(4C2B2F4B2E2B2D2C12-)3(6C2B2F2C2B2E2D2C12-)3(2C16B2D12-)3(2C4B2F4B2E4B2D12-)2(4C12B2D2C12-)4C12B2D2C14-2(4C8B2C2D16-)4C8B2C2D18-2(4C4B2F2C20-)4C4B2F2C22-2(8C24-)8C12-2(AG28AG2AG28AGA928-)64A929-AG26AGA2-30A2(930-AG26AGA2-AG26AGA)930-30A2-30A930-2AG24AG2A2-30A931-2(AG24AGA4-AG24AGA932-)28A4-28A933-AG22AGA6-26A934-AG22AGA6-AG22AGA934-26A6-AG22AGA934-2AG20AG2A6-26A935-AG20AGA8-AG20AGA936-24A8-AG20AGA936-2AG18AG2A8-24A937-AG18AGA10-AG18AGA938-22A10-2AG16AG2A939-AG16AGA12-20A940-2AG14AG2A12-2AG14AG2A941-18A14-2AG12AG2A943-2AG10AG2A16-16A945-2AG8AG2A18-2A2G6A2G2A947-3A2G2A2G3A20-4A2GA2G3A938-
