model
size = 27 11 20, scale = 0.05, origin = -y
material deform = 1, fade = true, lighting = smooth, roughness = 0.3, metalness = 0.6
  colors = A:#C0C B:#F9F
voxels
37-10B2(21-6A)22-4A180-10B2(21-6A)22-4A205-2B4A5-A2B3(17-10A)18-8A20-6A148-2B4A9-A2B13-4A5-5A14-2(12A15-)12A16-10A18-8A22-2A94-2B4A13-AB11-3A9-4A12-2(4A5-5A13-)4A5-5A14-3A5-4A16-2A5-3A18-8A22-2A66-B6A13-AB11-2A2(11-3A)2(9-4A11-3A)9-4A12-2A9-3A14-A9-2A16-2A5-3A18-8A62-B6A15-AB9-2A13-3A2(9-3A11-4A)10-2A11-3A11-2A11-3A12-A11-2A14-2A7-3A16-10A19-6A35-B7A15-AB9-2A13-3A3(9-3A11-4A)10-2A11-3A11-2A11-3A12-2A9-3A14-12A17-8A34-B6A17-AB7-2A15-3A7-3A13-4A8-2(2A13-3A9-)2A13-3A10-A13-2A12-A11-2A14-12A16-10A20-4A8-B7A17-AB7-2A15-3A2(7-3A13-4A)8-2A13-3A9-2A13-3A10-A13-2A12-A11-2A14-12A16-2(10A19-6A7-B7A17-AB7-2A15-3A2(7-3A13-4A)8-2A13-3A9-2A13-3A10-A13-2(2A11-)3A12-14A15-)10A19-6A7-B7A17-AB7-2A15-3A2(7-3A13-4A)8-2A13-3A9-2A13-3A10-A13-2A12-A11-2A14-12A16-10A19-6A8-B7A15-2AB7-3A13-4A7-4A11-5A8-2(3A11-4A9-)3A11-4A10-2A11-3A12-2A9-3A14-12A16-10A20-4A9-B7A15-AB9-2A13-3A3(9-3A11-4A)10-2A11-3A11-2A11-3A12-3A7-4A14-12A17-8A35-B7A13-2AB9-3A11-2(4A9-)5A9-4A9-5A10-3A9-4A11-3A9-4A12-2A9-3A14-3A5-4A16-10A19-6A37-B6A13-AB11-3A9-4A3(11-5A5-6A)12-4A5-5A14-3A5-4A16-10A18-8A64-2B6A9-3AB11-5A5-6A12-2(14A13-)14A14-12A16-10A18-8A22-2A69-2B6A5-3A2B13-14A14-2(12A15-)12A16-10A18-8A22-2A98-2B10A2B3(18-9A)18-8A20-6A142-
