model
size = 20 9 20, scale = 0.05, origin = -y
material deform = 1, fade = true, lighting = smooth, roughness = 0.3, metalness = 0.6
  colors = A:#111 B:#222 C:#555
voxels
94-3A17-3A13-A3-3A103-2A178-3A177-4A176-5A15-4A138-A17-6A14-4A-A16-2B2A116-A17-3AB3A13-A-AB3A17-3A96-A19-2A16-9A11-7A15-BA-3A14-2A-2A76-2A17-4A14-10A12-A2-2A14-3A2-3A13-2A2-2A57-A18-2A-A15-5A12-A2(-4A)10-5A-4A11-3A2(-2A)11-2A2-A2-2A55-A17-B4A-A12-6A-2A9-14A2-A4-A3B4A2-3A7-6A-2A2-A9-A5-A74-AB3A2-A12-BA-2AC-2A8-16A6-2A-A4-7A6-B6-6A6-2A7-4A7-2A8-A51-A2-2A-C12-AB4AC-3AC5-10A-3AB3A4-A2-7AB2ABA6-B7A2-3A7-2B2-4A2-2A8-2A4-A3-A33-2A18-2A-C13-A2B4ACA8-11A2B3A4-5A4-7A5-4A2-A-B5A5-15A7-3B3A-A4-A7-AB2-2A-A18-A15-A2-3A-2C10-A2(B-)5A8-A2-2A2-9A4-5A3-7A5-3A5-AB5A4-9A-5A8-A-B2AB3A10-2B-4A20-A18-2A14-A2-3AB-AC8-A-8A2B3A5-3A2(B5A)5-2AB3A-A-5A5-4A3B7A7-A-A2B7A8-A2B2A58-A-3B13-7A2-4A8-3A-2A2-5A6-3A2B8A6-2A3B8A8-A-B8A9-2BA59-A19-11A9-AB7A10-3AB6A8-A2-B2AB-3A11-5A-3A10-AB82-8A13-B5A11-3AB5A13-2AB3A12-5A-2A77-2B17-5A15-A2-2A12-3A3-2A13-3A-A14-A2-A27-
