model
size = 32 16 31, scale = 0.05, origin = -y
material deform = 1, fade = true, lighting = smooth, roughness = 0.3, metalness = 0.6
  colors = A:#4B4B4B B:#FFC400 C:#00B1FF D:#00DFFF E:#0052FF F:#0078FF G:#0063FF H:#00C3FF I:#008FFF
voxels
256-2D28-2D480-2H28-2H480-2C28-2C480-2I28-2I3(480-2F28-2F)2(480-IE28-EI)3(449-G28-G-IE28-EI)5(449-E28-E-CE28-EC)4(449-G28-G-F30-F)2(480-F30-F)480-I30-I480-C30-C480-H30-H480-D30-D355-4A3C5A2-5A3C4A4-5A5C4A2-4A5C5A2-4ADHCGCHD3A2-3ADHCGCHD4A2-4ADHCGCHD8A2(DHCGCHD4A2-4ADHCGCHD3A2-3A)DHCGCHD4A2-5A2CF2C4A2-4A2CF2C5A2(4-4A3C4A)139-A14-A15-3A12-3A13-2(5A10-)3A3C4A4-4A3C3A6-5A3-5A2-2(5A3-)5A5-4A2-4A5-5A2-3AD7-D2A2-2A2(D7-D3A2-3AD7-D6A)D7-D3A2-3AD7-D2A2-2AD7-D3A2-5A5-4A2-4A5-2(5A3-)5A2-5A3-5A5-4A3D2A8-2A3D4A7-7A10-7A11-3A12-3A15-A14-A46-2(A3-A10-)9A6-9A7-11A4-11A5-5A3-4A4-4A3-5A4-4A5-4A2-4A5-4A3-4A7-3A2-3A2(7-4A2-4A7-8A)7-4A2-4A7-3A2-3A7-4A3-2ABA5-AB2A2-2ABA5-AB2A4-3ABA3-AB3A2-3ABA3-AB3A5-3AB7A4-7AB3A7-9A6-9A9-7A8-7A11-5A10-5A43-A5-A8-A5-A9-3A3B2A8-2A3B3A7-3AB3-B2A6-2AB3-B3A6-2AB5-B2A4-2AB5-B2A6-AB7-BA4-AB7-BA5-AB9-BA2-A2(B9-BA4-AB9-B4A)2(B9-BA4-AB9-BA2-A)B9-BA5-A2B5-2BA4-A2B5-2BA7-AB4-2BA6-A2B4-BA9-A4B2A8-2A4BA11-5A10-5A13-3A12-3A7-
