model
size = 22 17 23, scale = 0.05, origin = -y
material deform = 1, fade = true, lighting = smooth, roughness = 0.3, metalness = 0.6
  colors = A:#FFF B:#0063FF C:#008FFF D:#0039FF E:#00C3FF F:#00F5FF G:#00B1FF
voxels
9-4A368-8A364-12A361-14A359-16A11-6F16-6A16-6E16-6A16-6C16-6A16-6B16-6A16-6D2(16-6A16-6B)16-6A16-6C16-6A10-18A8-3F4-3F12-10A12-10E12-10A12-10C12-10A12-10B12-10A12-10D2(12-10A12-10B)12-10A12-10C12-10A7-2(7A6-)12F10-12A10-12E10-4A4-4A10-3C6-3C10-4A4-4A10-12B10-12A10-12D2(10-12A10-12B)10-12A10-12C10-12A6-6A8-6A5-2(3F8-)2(3A8-)2(3E8-)2(3A8-)2(3C8-)4A6-4A8-14B8-14A8-14D2(8-14A8-14B)8-14A8-14C8-14A5-5A10-5A5-2F10-2F8-2A10-2A8-2E10-2E8-2A10-2A2(8-3C)2(8-3A)8-14B8-14A8-14D2(8-14A8-14B)8-14A8-14C8-3A8G3A4-6A10-6A4-2F10-2F8-2A10-2A8-2E10-2E8-2A10-2A8-2C10-2C2(8-3A)8-14B8-14A8-14D2(8-14A8-14B)8-14A8-14C8-3AGA4GAG3A4-5A12-5A3-3F10-3F6-3A10-3A6-3E10-3E6-3A10-3A6-3C10-3C6-4A8-4A6-16B6-16A6-16D2(6-16A6-16B)6-16A6-16C6-4AGA4GAG4A3-5A12-5A3-3F10-3F6-3A10-3A6-3E10-3E6-3A10-3A6-3C10-3C6-4A8-4A6-16B6-16A6-16D2(6-16A6-16B)6-16A6-16C6-16A3-5A12-5A3-3F10-3F6-3A10-3A6-3E10-3E6-3A10-3A6-3C10-3C6-4A8-4A6-16B6-16A6-16D2(6-16A6-16B)6-16A6-16C6-5A6B5A3-5A12-5A3-4F8-4F6-4A8-4A6-4E8-4E6-4A8-4A6-4C8-4C6-4A8-4A6-16B6-16A6-16D2(6-16A6-16B)6-16A6-16C6-4A8B4A4-5A10-5A5-2(3F8-)2(3A8-)2(3E8-)2(3A8-)2(3C8-)2A-A6-A-2A8-14B8-14A8-14D2(8-14A8-14B)8-14A8-14C8-3A8B3A5-5A10-5A5-2(3F8-)4A6-4A8-4E6-4E8-4A6-4A8-3C-6C-3C8-14A8-14B8-14A8-14D2(8-14A8-14B)8-14A8-14C8-2(4AB)4A2(6-6A)7-3F6-3F10-12A10-12E10-12A10-12C10-4A4-4A10-12B10-12A10-12D2(10-12A10-12B)10-12A10-12C10-3AB4AB3A7-18A8-10F12-10A12-10E12-10A12-10C12-10A12-10B12-10A12-10D2(12-10A12-10B)12-10A12-10C12-10A9-16A10-8F14-8A14-8E14-8A14-8C14-8A14-8B14-8A14-8D2(14-8A14-8B)14-8A14-8C14-8A11-14A13-4F18-4A18-4E18-4A18-4C18-4A18-4B18-4A18-4D2(18-4A18-4B)18-4A18-4C18-4A14-12A364-8A368-4A361-
