model
size = 30 32 17, scale = 0.05, origin = -y
material deform = 1, fade = true, lighting = smooth, roughness = 0.3, metalness = 0.6
  colors = A:#111 B:#F96 C:#306 D:#001 E:#EEE F:#B00 G:#222
voxels
7-2(3B27-)3B897-2(3B27-)3B786-D110-2(3B11-3B13-)3B11-3B621-D29-D25-2D-3D-2D21-D2(-3D)2(21-9D)2(21-3D3-3D)22-D24-2(3B11-3B13-)3B11-3B75-4(13C17-)11(13A17-)4A5B4A81-6B23-7B22-3(9BD19-D)3(9BD20-)D-D3-3D17-2(3B11-3B13-)3B11-3B75-4(13C17-)10A2BA8(17-13A)2(16-14A)16-5A5B4A21-2(5B25-)5B24-7B21-D9B20-D9BD19-D9BD20-2(9BD19-D)9BD20-2D-D3-2D17-2(3B11-3B13-)3B11-3B75-4(13C17-)10A2BA8(17-13A)15-16A13-18A11-8A5B7A9-B2A6-5B5-2AB7-2BA7-5B6-A2B5-3B8-5B7-3B3-3B8-7B7-3B-3B8-9B7-5B9-9BD7-3B10-3(9BD19-D)9BD20-4D2-3D17-2(3B11-3B13-)3B11-3B75-4(13C17-)10A2BA8(17-13A)15-16A13-18A11-8A5B7A9-B2A6-5B5-2AB7-2BA7-5B6-A2B5-3B8-5B7-3B3-3B8-7B7-3B-3B7-D9BD6-5B8-D9BD7-3B9-D9BD7-2B10-D9B8-2B10-D9BD19-D9BD20-5D-3D17-2(3B11-3B13-)3B11-3B75-4(13C17-)10A2BA8(17-13A)15-16A13-18A11-9A4B7A9-B2A16-2AB7-2BA18-A2B5-3B20-3B3-3B8-7B7-3B-3B7-D9B7-5B3(8-D9BD7-4B)8-D9BD19-D9BD20-9D17-2(3B11-3B13-)3B11-3B75-4(13C17-)3(13A17-)3AE3A4E2(2A17-2(3AE)2AE)2A17-2AEA3(E2A)17-AE3AEA4E2A17-13A2(17-6AB6A)17-5A3B5A139-9BD20-9B21-4(9BD20-)2D2-6D16-2(3B11-3B13-)3B11-3B73-3(5C8-4C13-)5C8-4C500-3F26-F3-F27-B29-B26-EGE-EGE23-3E-3ED47-2(3B11-3B13-)3B11-3B73-3(5C8-4C13-)5C8-4C561-B141-2(2(3B11-3B13-)3B11-3B73-3(5C8-4C13-)5C8-4C703-)2(4(3B11-3B13-)2(3C11-3C13-)5(2C13-)2C703-)4(3B11-3B13-)2(3C11-3B13-)2(2C13-2B13-)2C13-2B703-6(3B27-)2(2B28-)2B711-
