model
size = 29 32 16, scale = 0.05, origin = -y
material deform = 1, fade = true, lighting = smooth, roughness = 0.3, metalness = 0.6
  colors = A:#036 B:#03F C:#100 D:#FC3 E:#9CF
voxels
13-5C371-5A24-6A22-7A21-9A18-13A15-6(15A14-)15A15-13A717-D-D2(26-B-B)24-2CB-B2C21-C3B-3BC19-C4B-4BC17-C4BC-C4BC15-C4BC3-C4BC14-C3BC5-C3BC830-3A-3A21-3A3-3A19-3A5-3A18-2A7-2A15-C3BC7-C3BC650-2(8A-8A12-)17A11-19A10-20A8-10A-10A8-9A3-8A10-7A5-6A16-A7-A20-A7-A16-C3BC7-C3BC102-11B18-11C11(18-11A)17-2(13A16-)13A15-15A14-C14A2(C12-C15A)C11-C17AC10-18AC10-19AC8-10A-10A8-9A3-8A10-7A5-6A16-2(A7-A20-)A7-A16-C3BC7-C3BC10-3C3B56-B11AB16-C11AC12(16-13A)15-15A14-15A13-C15AC12-B15AB11-B17AB10-B17AB9-B19AB7-BC19ACB6-BC20AB6-C7A7-7AC2(7-7A)9-6A7-6A11-5A7-5A14-3A7-3A18-A7-A20-C7-C13-C2B3-B9-3B3C10-4B26-B13-B14-C13-C13(14-A13-A)13-C15-C12-B15-B174-3A5-B3A17-3AB5-C3A15-3AC7-5A11-5A9-2(4A11-)5A7-5A14-3A7-3A18-C7-C13-C2B3-B9-B2-3BC9-4B9-3B13-B15-B12-C15-C13(12-A15-A)12-C15-C12-B15-B181-B2A26-2C2A19-2ACB3-6A13-5AC5-6A11-6A7-5A11-5A10-4A8-5A16-C7-C13-C2B3-B9-B2-3BC9-4B9-3B13-B15-B12-C15-C13(12-A15-A)12-C15-C12-B15-B209-B2A23-2AB-C2A21-2AC3-2A21-2A5-4A15-4A8-5A8-7A14-C7-C14-C2B2-B9-B2-3BC10-3B9-3B13-B15-B12-C15-C13(12-A15-A)12-C15-C12-B15-B209-B2A23-2ABC3A21-3AC-3A21-AEA3-3A19-3A7-5A8-7A14-C7-C14-C2B2-B9-B2-2BC11-3B9-3B13-B15-B12-C15-C13(12-A15-A)12-C15-C12-B15-B209-B2A23-2ABC3A21-3AC-3A21-3A3-3A19-3A7-5A8-7A14-C7-C15-CB2-B9-B2-2BC11-3B9-3B13-B15-B12-C15-C13(12-A15-A)12-C15-C12-B15-B209-2BA23-2AB-C2A21-2AC3-2A21-2A5-4A15-4A8-5A8-7A14-C7-C15-CB2-B9-B2-BC12-3B9-3B13-B15-B12-C15-C13(12-A15-A)12-C15-C12-B15-B182-BA27-2C21-ACB5-A19-2AC5-4A15-4A7-6A9-6A10-4A8-5A16-B7-B15-CB2-11B2-BC12-15B13-B15-B12-C15-C13(12-A15-A)12-C15-C12-B15-B175-AB6-B2A17-3AB6-C2A15-3AC7-4A13-4A9-19A11-17A14-13A19-8B16-C15-C13-15B14-B13-B14-C13-C14(14-A13-A)13-CA13-AC12-BA13-AB11-B2A13-2AB10-B2A13-2AB9-B3A13-3AB7-BC3A13-3ACB6-B4A13-4AC6-BC3A13-4AC8-4A11-5A9-6A7-6A11-17A14-13A18-9A75-2C11B2C15-13B16-13C14(16-13A)15-15A14-C13AC13-C15AC11-2(C17AC10-)C17AC9-C20A8-C20A9-19A11-17A15-11A134-3C5B3C9-
