model
size = 17 6 14, scale = 0.05, origin = -y
material deform = 1, fade = true, lighting = smooth, roughness = 0.3, metalness = 0.6
  colors = A:#100 B:#FC3 C:#111
voxels
7-5B18-3B7-5B2-ACB7-B3AB4AB7-2BCABAC2A8-2(B3A)42-2(2A3B2A10-)2A3B2A58-2(2BA7-A2B4-)2BA7-A2B54-2(B13-B2-)B13-B52-2(A2(15-2A)15-A51-)3(B2(15-2B)15-B51-)A2(15-2A)15-A51-A2(15-2A)15-A52-2(B13-B2-)B13-B54-2(B11-B4-)B11-B56-2(B9AB6-)B9AB20-
