model
size = 32 16 31, scale = 0.05, origin = -y
material deform = 1, fade = true, lighting = smooth, roughness = 0.3, metalness = 0.6
  colors = A:#750CFF B:#FFF C:#00B1FF D:#FF211F E:#00DFFF F:#5E0CFF G:#890CFF H:#00C3FF I:#FF482D J:#FF5D2D K:#B80CFF L:#0078FF M:#EA00FF N:#FFC400
voxels
256-2F28-2F480-2A28-2A480-2G28-2G480-2K28-2K480-2M28-2M480-KB28-BK480-GB28-BG480-AB28-BA480-3(FB28-BF449-A28-A-)5(FB28-BF449-G28-G-)FB28-BF4(449-B28-B-A30-A)480-A30-A480-F30-F480-A30-A480-G30-G480-K30-K480-M30-M355-3AB3CB4A2-4AB3CB3A4-5A5C4A2-4A5C5A2-4AEHCLCHE3A2-3AEHCLCHE4A2-4AEHCACHE8AEHCACHE4A2-4AEHCACHE3A2-3AEHCACHE4A2-4AEHCLCHE3A2-3AEHCLCHE4A2-5A2CL2C4A2-4A2CL2C5A2(4-3AB3CB3A)139-B14-B15-3B12-3B13-2(5B10-)2AB3CB3A4-3AB3CB2A6-4AB3-B4A2-4AB3-B4A3-A4B5-B3A2-3AB5-4BA2-2ABE7-E2A2-2AE7-EB2A2-2ABE7-E2B2A2BE7-EB2A2-BABE7-E2B2A2BE7-EBAB2-2ABE7-E2B2-2BE7-EB2A2-4AB5-B3A2-3AB5-B4A3-4AB3-2B3A2-3A2B3-B4A5-3AB3EBA8-AB3EB3A7-2A5B10-5B2A11-3B12-3B15-B14-B16-2(A14-)2(5A10-)2A5B2A6-2A5B2A7-4A4B3A4-3A4B4A5-2A3B3-2B2A4-2A2B3-3B2A4-A3B5-2B2A2-2A2B5-3BA3-2A2B7-2BA2-A2B2(7-2B2A2-2A2B7-3B2A3B)7-2B2A2-2A2B7-2BA2-A2B7-2B2A3-2A2B5-2B2A2-2A2B5-2B2A4-3ANB3-BNB2A2-2ABNB3-BN3A5-3A6B2A4-2A6B3A7-2A5B2A6-2A5B2A9-A5BA8-A5BA11-A3BA10-A3BA13-2(3A12-)7A8-7A9-2A4D2A8-2A4D2A7-3AI3-J2A6-2AJ3-I3A6-2AJ5-J2A4-2AJ5-J2A6-AI7-IA4-AI7-IA5-AD9-DA2-2(AD9-DA4-AD9-DA2B)2(AD9-DA4-AD9-DA2-)AD9-DA5-AIJ5-2IA4-A2I5-JIA7-AI5-JA6-AJ5-IA9-A5DA8-A5DA11-5A10-5A13-3A12-3A7-
