model
size = 20 27 15, scale = 0.05, origin = -y
material deform = 1, fade = true, lighting = smooth, roughness = 0.3, metalness = 0.6
  colors = A:#369 B:#069 C:#C90 D:#3CF E:#093 F:#0F3
voxels
469-2A18-2A435-A5-2A12-2A3-3A12-2A3-AEA12-3A-2B2A12-A2B2ABA14-5A494-3A-4A11-9A12-6ADA497-2A12-3A2-4A11-E3A-4A11-2A5-2A491-A18-4A3-4A9-3A5-2AE489-A18-2AB17-E2A7-2A10-A7-A468-3A17-C2AB17-2AB7-2A9-AB7-2A467-3A17-C2AB7-3A7-C2A7-2AC8-EB7-2A466-4A16-D4A7-B3A6-CAB7-BAC8-AB7-AD446-4A15-5A9-4A3-4AB7-B4A5-CAB7-BAC8-AB7-2A32-AB17-A2BA16-5B14-2A3BA2BA10-2BA7BA8-A10B2A7-12B2A5-F5B-6BAB5-D3B5-6B4-F4B5-6BA3-A3B3-B3-6B3-5B5-8B-D5B5-8B-A7B-10B-D18B-18BC-E17BC-19B-9B-A8B-8B3-A7B-6BA5-A6B7A7-A4BA-6A7-6A2-D3AB7-B2ABA5-CAB7-2AC8-EB7-BD32-2A17-4A16-5A14-8AB10-9A2B8-11A2B7-11ACBA5-F14A5-15A4-F15AB3-B16A3-B17A2(-B18A)-E17AB-B17AC-B17AB3(-B18A)-E19AB6A5-7A-5AB7-B5A2-AB2AB7-B2A2B5-CAB7-2AC8-A8-BE13-A19-BAB16-A2BCA15-2AB2CB13-5ACB12-5ADAC11-BAE2ABAD2C9-2AB6ADC9-3FAB5ADC7-AE8ABA2CA5-3F2AB4ABADC2A3-4AB7ABA2CA3-4AB8ABACAB2-2AB10ABA2CE-2(2AB)9ABA2C-2AEB11A2BAC-B3AD11AB2A-BEAD12ABAE-BAD14ABA-16A3B-19AB19AE18AB-7A5-7A2-2B2AB7-B3AB5-CA8-BAC8-A9-A174-A19-AB18-AB17-3AB15-AB4A14-2A3BA13-2(BA)2B2A11-AB7A11-DB8A9-11A9-AB10A7-B11AE6-14A5-AB15A3-AEB15A2-2AB3A5-7A2-B4A7-B3AB5-BA9-AC313-C18-ABC16-2ADCB15-2ADCA15-3AD2C13-5ADCA11-2AB3AD2CA9-B2(AE)3ADCB9-2B2AB4A2CA8-ABA5-BA2C7-2AB7-BECA43-
