model
size = 11 14 19, scale = 0.05, origin = -y
material deform = 1, fade = true, lighting = smooth, roughness = 0.3, metalness = 0.6
  colors = A:#000 B:#D9CDC1 C:#84492C D:#EDE8FF E:#FFF F:#1E1729
voxels
34-9(9A2-)9A7-4A13-2(10A-)8ABA8(-10A)-9A6-6A2-A9-2(10A-)8ABA8(-10A)-9A2-10A2-A9-2(10A-)A8BA5(-A2B7A)3(-A2C7A)2-AC6A3-9A2-A9-2(10A-)A8BA5(-A2B7A)-A2B3A3-A-A2B7A2-2B7A-BEC6A2-BE8A2-A9-2(10A-)2A2B5CA-A2B7A-2AB7A-A2B5A2(-A)2(2B7A-A)2B7A2-2BA2-4A-3BA-5A-BECA-4A2-BE8A12-10A-10A2-A2B5CA-3B7A2-2B7A-3B5A-A3-B3(7A-3B)2A-4ADF2B7ADFEC6A-2D-E7A11-11A-10A3-2B5CA3(2-2B7A3-B7A)2-2B2A-4A2(2D2B7ADFEC6A-2D-E7A11-11A-10A3-2B5CA3(2-2B7A3-B7A)2-2B7A)2-2B7A2D-E6A4-E7A11-11A-10A3-2B5CA3(2-2B7A3-B7A)2-BC7A2DBC7ADFEC6A-2D-E7A11-11A-10A3-2B5CA3(2-2B7A3-B7A)2-BC7A2DBC7ADFEC4A3-2D-E7A2-A9-10A-10A2-A6BCA-3B7A2(2-2B5A-A-3B5A-A)-2BC5A-A-2BC7ADFBC7ADFEC4A-A-2D-E7A2-A9-2(10A-)A-6BCA-A2B7A-A-B3(5A2(-A)2B)5A2(-A)BC5A-A2-BC7A-2BC7A-BEC4A-A2-BE4A-3A2-A9-2(10A-)A7BCA5(-A2B7A)2(-ABC7A)2-BC7A-BEC4A-A2-BE5A-2A2-A9-2(10A-)4(A7BCA-)AB7CA-AB5C3(ACA-A6C)-2A2-6A-A3-A6-2A2-A9-3(10A-)6(9A2-)9A3-8A2(2-7A-A)3-A10-2A9-2A8-7(9A2-)9A3(6-5A)61-4A7-4A5(6-5A)7-4A8-3A2-
