model
size = 11 21 19, scale = 0.05, origin = -y
material deform = 1, fade = true, lighting = smooth, roughness = 0.3, metalness = 0.6
  colors = A:#000 B:#D9CDC1 C:#84492C D:#1E1729 E:#FFF F:#94453E
voxels
12-18(9A2-)9A7-4A13-8(10A-)2(8ABA-)8(10A-)9A6-6A8-3A2(-7AB2A)4(-7A2BA)4(-8ABA)8(-10A)-9A2-10A7-B3A2(-6A2B2A)4(-6A3BA)-2A2B2A3BA-2A7B2(A-A8B)A5(-A2B7A)3(-A2C7A)2-AC6A3-9A-A3-3B3A-A3-5B2(2(A-)7B)2(2(A-)5B2-)2(A-)4B3-2(A-)2B2-B2-2(A-)7B2(A-A8B)A5(-A2B7A)-A2B3A3-A-A2B7A2-2B7A-BEC6A2-BE8A-3A2B2C3A-3A2B4(4CA-2A3B)2C-CA-2A3BC2-C2(A-2A3B4C)A-A4B4CA-2A2B5CA-A2B7A-2AB7A-A2B5A2(-A)2(2B7A-A)2B7A2-2BA2-4A-3BA-5A-BECA-4A2-BE8A-4AB2C3A3(-A4B4CA)-2A3B2C-CA-A4B2C-CA-2A3BC2-CA-A4B4CA-2A3BC2-CA-A4BC2-CA2-A2B5CA-3B7A2-2B7A-3B5A-A3-B3(7A-3B)2A-4A2D2B7A2DEC6A-2D-E7A4-AB2C3A3(-A4B4CA)-2A3B4CA-A4B2(CA-)2A3B2C-CA-A4B4CA-2A3BC2-CA-A4BC2-CA3-2B5CA2(2-2B7A3-B7A)2(2-2B7A)2-2B2A-4A2D2B7A2DEC6A-2D-E7A4-AB2C3A3(-A4B4CA)-A-3B2A2CA-A4BAC-C2(A-)3B2C-CA-A4BC-ACA2-A3BC2-CA2-4BC2-CA3-2B5CA2(2-2B7A3-B7A)3(2-2B7A)2D2B7A2DEC6A-2D-E7A-4AB2C2(3A-)B2C-C2(A-ABA2-4C)A-A2B2-4C2(A-A4B2C-C)A-A4B4CA3-3B4CA2-4B4CA3-2B5CA2(2-2B7A3-B7A)4(2-2B7A)2D-E6A4-E7A4-AB2C3A3(-A4B4CA)-A-3B4CA-A4B2C-C2(A-)3B2C-CA-A4B4CA3-A2B4CA2-4B4CA3-2B5CA2(2-2B7A3-B7A)2-2B2(7A2-BC)7A2DBC7A2DEC6A-2D-E7A4-AB2C3A3(-A4B4CA)-2A3B3ACA-A4B4CA-2A3B4CA-A4B4CA-3A2B4CA-A4B4CA3-2B5CA2(2-2B7A3-B7A)2-2B2(7A2-BC)7A2DBC7A2DEC4A3-2D-E7A-4AB2C3A-ABA2B4C2(A-A7BC)A-2A6B2(-A)6B2-A-2A5B2-A-A6B2-A-3A5BCA-A7BCA2-A6BCA-3B7A2(2-2B5A-A-3B5A-A)-2BC5A-A-2BC7A2DBC7A2DEC4A-A-2D-E7A5-B2C3A-AB-2B4C2(A-A7BC)A-A2-5B2(-A)3(2-4B2-A-A)2-5BCA-A7BC2(A-)6BCA-A2B7A-A-B3(5A2(-A)2B)5A2(-A)BC5A-A2-BC7A-2BC7A-BEC4A-A2-BE4A-3A4-A3C3A-A2-B5CA-A7BCA-A2-5BFA-A2-5BCA-A2-5B2A-A2-5B2(-A)2(2-4B2-A-A)2(7BCA-A)5(2B7A-A)BC7A-ABC7A2-BC7A-BEC4A-A2-BE5A-2A2(-10A)-7AB2(CA-6A2B)CA2(-5A3B2A)-5A3BCA-2A6B5(CA-A7B)CA-AB7CA-AB5C3(ACA-A6C)-2A2-6A-A3-A6-2A-10A-2(9A2-)8ACA-7ACA13(2-9A)3-8A2(2-7A-A)18(2-9A)3(6-5A)138-4A7-4A5(6-5A)7-4A8-3A2-
