model
size = 15 32 12, scale = 0.05, origin = -y
material deform = 1, fade = true, lighting = smooth, roughness = 0.3, metalness = 0.6
  colors = A:#A0A0A0 B:#1F1F1F C:#181818 D:#1A1A1A E:#EEE F:#1D1D1D G:#767676 H:#FAFAFA I:#E8E8E8 J:#050505 K:#1B1B1B L:#F4F4F4 M:#A1A1A1 N:#040404
voxels
3-5BC5BL4-5G10-AE3A10-JA2ED10-A2CAF10-2C2AD10-2E2AF10-CEFIA10-CEFCA11-C2JAH10-CJ2DH10-DCF2DC9-CAFAC10-2KCFA10-2CDFCA9-CACFCA9-AEID2F9-AEID2J9-4A2J9-F2AFJA9-DMHEFA9-D2C4A8-3C4A2-E5-AECM2D3-A5-2MFD2A3-D5-D2MFCI2-AC5-DA2MCA2-AD4-C2D2C2A2-AD3-A2C2DI2A2-CA2-AE5AKCA-2A2-2AKCA3C5A2-5BA5B2L309-D2FD7-C4A2CDJ4-EA2C2A3D2JA3-3AC2IAC2J2D3-C2ACAJH3CHA3-E3A2J2IA3C3-EAE2A2I2CH2I3-AE2A4C4A3-5A2CI3AI3-H9A2I4-5BC3B6-5BA3B294-A3FHA6-A2C7A4-12A3-D11A3-12A2(3-C11A)3-E11A3-12A3-H11A2-13A2(2-BA11B)4-6G9-AH2A2D9-3A2DA9-5DA9-A4DA9-E3H2A9-E4FE9-H3C2FE8-DH4CF8-AJH2CAF9-2HAC2A9-2CAIAE9-AFAIEA9-AD3ED9-2A2J2D8-E2ADJCD8-DAICAC9-DE2CFC9-DECAFIA8-D2C6A6-10A4-2(12A3-)2(E11A3-)3(12A3-)12A2-13A2(2-13B)2-2G6-G6-2A6-F6-2D2(6-A)D6-D2(7-A6-A)7-2(D6-A)6-AD6-E6B2A6-C7AE6-8AE6-D7AED4-D10A4-2FE8A4-FDC6AIF4-2C7ADF4-C7AC2A4-2C6AC2ACA2-11ACH2-AD11A9(2-13A)-14A2(2-13B)-G8-G5-A2(8-A5-D)8-AD2(4-2D7-2A)4-AD7-2A4-2A7-AD4-EH7B3A3-AC10A3-F10AD3-2(12A2-G)2(13A-G)12AF-G12A2DGA13BGA13-2G14-G14-A2(14-D)14-F14-E2(14-C)2(14-A)2(14-B)14-G8-G5-I8-F2(5-C8-A)F4-A8-AE4-J8-AE4-H8-AE4-F8-AC4-I8B3A3-I11A3-11AD2-G12A2-F12A2-12A-A-F13A-C12AF-C12AHAFA13BGA13-2A14-G14-A14-E14-D14-F14-J14-C14-A14-E14-A2(14-B)14-G8-G5-A8-A5-C8-H5-A8-AF4-C8-AE4-J8-AH4-C8-AF4-F8-AC4-E8B3A3-F10AE3-I10AD2-G11AE2-12AF2-E13A-F13A-C13A-E14AEA13BGA13-EA14-G14-E14-A2(14-F)2(14-J)14-C14-E14-A14-C14-A14-G8-G5-C8-F5-C8-E5-A8-AE4-E8-2A4-C8-AD2(4-C8-AH)4-A8B2AH3-F10AH3-11AD2-G11AE2-E11AF2-C12AE-14A-F13A-E16A13BGA13-EA14-G2(14-A)14-C2(14-F)14-D14-C14-A14-E2(14-B)14-G8-G5-C8-E5-I8-A5-I8-2A4-I8-AC4-C8-AD4-I2(8-AH4-A)8B2A2(H3-11A)D2-G11AI2(2-13A)E-C13A-14A-15AHA13BGA13-2A14-G2(14-A)14-E14-N14-F2(14-C)2(14-A)2(14-B)14-G8-G5-A8-A5-J8-D2(5-A8-A)D4-J8-AD4-A8-AE4-A8-2A4-A8B2AD3-H10AD3-11AD3-AH9AI2(2-G2K10A)E-GAK10AF-GAK10AH-G12ACAGA13BGC13-GC14-G14-A14-E14-F14-J14-C2(14-A)14-C14-E2(14-B)15-2G5-G7-FA5-D7-JA5-A7-2E5-2A6-AC5-AD6-2C5-HE6-2A5-HA6-2C5-HAI5-AJC4B2AE5-AID5ACD6-HD6AE6-CD6AC6-2K6ACA5-2K6ADA5-KC6A2C5-2C6A2C5-JE7AC4-11AFA2-AEF6AIA2F2-CEF6A2IHF2-3D7A2HA2-DAC10A2-CJC6A2(CA)2-11ACA2-AE7AI3A2-A2C10A2-13A2-9A2E2A2-10AE2A2-E4A2E3AE2A2(2-5BA5B2L)
