model
size = 27 31 27, scale = 0.05, origin = -y
material deform = 1, fade = true, lighting = smooth, roughness = 0.3, metalness = 0.6
  colors = A:#9CF
voxels
10-7A21-5A23-3A776-11A16-11A17-9A19-7A745-2(15A12-)15A13-13A15-11A714-6A7-6A2(8-19A)9-17A11-15A15-9A20-2(5A22-)5A24-A583-5A11-5A6-7A7-7A6-21A7-19A9-18A10-15A16-7A21-5A22-5A23-3A24-3A25-A529-4A13-4A6-5A11-5A6-8A5-8A6-21A7-19A9-17A13-11A19-3(5A22-)5A23-3A25-A26-A474-4A15-4A4-5A13-5A4-7A9-7A2(5-8A)6-21A7-19A11-13A18-4(5A22-)5A23-3A24-3A25-2(A26-)A269-4(A26-)A15-3A17-3A4-4A15-4A4-5A13-5A4-7A9-7A2(5-8A)7-19A10-15A15-9A20-5(5A22-)5A23-3A24-3A25-2(A26-)A107-3(A26-)A25-2(3A24-)3A25-A41-3A19-3A2-4A17-4A2-6A13-5A4-6A11-6A4-7A9-6A6-8A5-8A8-17A13-11A19-7(5A22-)5A23-3A24-3A25-4(A26-)A25-3A23-2(5A22-)5A23-3A25-A26-A41-3A19-3A2-4A17-4A2-5A15-5A2-6A13-5A4-6A11-6A5-7A7-7A8-6A5-6A12-13A18-8(5A22-)5A23-5(3A24-)3A23-2(5A22-)5A23-3A24-3A25-A67-3A21-7A19-4A-5A15-5A2-6A13-6A2-7A11-6A4-7A9-2(6A7-)6A11-13A18-16(5A22-)5A23-3A24-3A25-A94-3A21-7A19-9A17-5A-5A15-5A2-6A13-5A4-6A11-5A7-5A9-5A10-15A17-15(5A22-)5A23-3A24-3A25-A26-A94-3A21-7A19-9A17-11A15-5A2-6A13-5A4-6A11-5A7-5A9-5A10-15A17-14(5A22-)5A23-3A24-3A25-A26-A121-3A21-7A19-9A17-11A15-5A2-6A13-5A4-6A11-5A7-5A9-5A10-7A-7A17-13(5A22-)5A23-3A24-3A25-A26-A148-3A21-7A19-9A17-11A15-5A2-6A13-5A4-6A11-5A7-5A9-5A10-15A17-11(5A22-)5A23-2(3A24-)3A25-A26-A175-3A21-7A19-9A17-5A-5A15-5A2-6A13-5A4-6A11-5A7-5A9-5A10-15A17-9(5A22-)5A23-2(3A24-)3A25-2(A26-)A202-3A21-7A19-4A-5A15-5A2-6A13-6A2-7A11-6A4-7A9-2(6A7-)6A11-13A18-7(5A22-)5A23-2(3A24-)3A25-2(A26-)A257-3A19-3A2-4A17-4A2-5A15-5A2-6A13-5A4-6A11-6A5-7A7-7A8-6A5-6A12-13A18-6(5A22-)5A23-3A24-3A25-2(A26-)A311-3A19-3A2-4A17-4A2-6A13-5A4-6A11-6A4-7A9-6A6-8A5-8A8-17A13-11A19-4(5A22-)5A23-2(3A24-)3A25-A26-A366-3A17-3A4-4A15-4A4-5A13-5A4-7A9-7A2(5-8A)7-19A10-15A15-9A20-2(5A22-)5A23-3(3A24-)3A25-A26-A393-4A15-4A4-5A13-5A4-7A9-7A2(5-8A)6-21A7-19A11-13A18-2(5A22-)5A23-3A24-3A25-2(A26-)A448-4A13-4A6-5A11-5A6-8A5-8A6-21A7-19A9-17A13-11A19-5A22-5A23-3A25-A26-A529-5A11-5A6-7A7-7A6-21A7-20A8-18A10-15A16-7A21-5A24-A26-A584-6A7-6A2(8-19A)9-17A11-15A14-11A689-2(15A12-)15A13-13A16-9A20-5A694-2(11A16-)11A17-9A20-5A723-7A20-7A21-5A23-3A741-
