model
size = 22 28 22, scale = 0.05, origin = -y
material deform = 1, fade = true, lighting = smooth, roughness = 0.3, metalness = 0.6
  colors = A:#D0004C B:#00AA90 C:#A8D8B9
voxels
185-4A17-2A2-2A15-3A2-3A12-12A8-16A5-A3-3(A-)2A-A3-A4-2(A-)A3-A-A2-2(A-)A4-A-3A2(-A)2-2(A-)3A4-2(A3-)A-2A-A3-A5-16A8-12A12-3A2-3A15-6A18-2A305-4A17-2A2-2A15-3A2-3A12-12A8-16A5-A3-A-2A3(-A)3-A4-2(A-)A2-A-A3-2(A-)A4-3A2(-A)2-2(A-)3A-A4-A3-A-2A-2(A3-)A5-16A8-12A12-3A2-3A15-6A18-2A305-4A17-6A15-3A2B3A13-4A2B4A11-12A7-18A4-A3CACA4CACA3CA4-2(AC)A8C2(AC)A4-3(AC)A4C3(AC)A4-A3CA8CA3CA4-B16AB7-12A11-B3A2B3AB13-B6AB15-2B2A2B17-4B259-6B15-2B4A2B13-2B6A2B11-2B8A2B9-2B10A2B7-2B12A2B5-18A3-3(B18AB2-)B18AB3-18A5-2B12A2B7-2B10A2B9-2B8A2B11-2B6A2B13-2B4A2B15-6B213-8B13-2B6A2B11-2B8A2B9-2B10A2B7-2B12A2B6-B14A2B4-B16AB3-B18AB2-B18AB-44A-B18AB2-B18AB3-18A5-17A5-16A7-14A9-12A11-10A13-8A168-8A13-10A11-12A9-14A7-16A5-B16AB4-B16AB3-B18AB2-B18AB-88A-B18AB2-B18AB3-18A4-18A5-16A7-14A9-12A11-10A13-8A125-6A14-10A11-12A9-14A7-16A5-B16AB4-B16AB3-B18AB2-B18AB-132A-B18AB2-B18AB3-18A4-18A5-16A7-14A9-12A11-10A14-6A83-4A15-10A11-12A9-14A7-15A7-16A5-B16AB3-20A-220A-B18AB3-18A5-16A6-16A7-14A9-12A11-10A15-4A41-2A17-8A13-10A10-14A8-14A7-16A5-B16AB4-B16AB2-66A-C18AC-66A2-B16AB3-C18AC2-C18AC-22A-B18AB2-B18AB3-18A5-16A6-16A7-14A10-10A13-8A17-2A18-6A15-8A12-12A9-14A7-16A6-16A5-B16AB3-B18AB3(-22A-C18AC)-22A2-B16AB4-B16AB3-C18AC-44A-B18AB3-18A4-18A5-16A7-14A9-12A12-8A15-6A16-6A14-10A11-12A9-14A7-16A5-B16AB4-B16AB2-44A3(-C18AC-22A)2-B16AB3-C18AC2-C18AC-44A-B18AB2-B18AB3-18A5-16A7-14A9-12A11-10A14-6A15-3A2B3A13-10A11-12A9-14A7-16A5-B16AB3-B18AB-44A2(-C18AC-22A)-C18AC-154A-B18AB3-18A5-16A7-14A9-12A11-4A2B4A13-3A2-3A14-3A2B3A13-10A11-12A9-14A7-16A5-B16AB3-B18AB-44A2(-C18AC-22A)-C18AC-154A-B18AB3-18A5-16A7-14A9-12A11-4A2B4A13-3A2-3A15-6A14-10A11-12A9-14A7-16A5-B16AB4-B16AB2-44A3(-C18AC-22A)2-B16AB3-C18AC2-C18AC-44A-B18AB2-B18AB3-18A5-16A7-14A9-12A11-10A14-6A16-6A15-8A12-12A9-14A7-16A6-16A5-B16AB3-B18AB3(-22A-C18AC)-22A2-B16AB4-B16AB3-C18AC-44A-B18AB3-18A4-18A5-16A7-14A9-12A12-8A15-6A18-2A17-8A13-10A10-14A8-14A7-16A5-B16AB4-B16AB2-66A-C18AC-66A2-B16AB3-C18AC2-C18AC-22A-B18AB2-B18AB3-18A5-16A6-16A7-14A10-10A13-8A17-2A41-4A15-10A11-12A9-14A7-15A7-16A5-B16AB3-20A-220A-B18AB3-18A5-16A6-16A7-14A9-12A11-10A15-4A83-6A14-10A11-12A9-14A7-16A5-B16AB4-B16AB3-B18AB2-B18AB-132A-B18AB2-B18AB3-18A4-18A5-16A7-14A9-12A11-10A14-6A125-8A13-10A11-12A9-14A7-16A5-B16AB4-B16AB3-B18AB2-B18AB-88A-B18AB2-B18AB3-18A4-18A5-16A7-14A9-12A11-10A13-8A168-8B13-2B6A2B11-2B8A2B9-2B10A2B7-2B12A2B6-B14A2B4-B16AB3-B18AB2-B18AB-44A-B18AB2-B18AB3-18A5-17A5-16A7-14A9-12A11-10A13-8A213-6B15-2B4A2B13-2B6A2B11-2B8A2B9-2B10A2B7-2B12A2B5-18A3-3(B18AB2-)B18AB3-18A5-2B12A2B7-2B10A2B9-2B8A2B11-2B6A2B13-2B4A2B15-6B259-4A17-6A15-3A2B3A13-4A2B4A11-12A7-18A4-A3CACA4CACA3CA4-2(AC)A8C2(AC)A4-3(AC)A4C3(AC)A4-A3CA8CA3CA4-B16AB7-12A11-B3A2B3AB13-B6AB15-2B2A2B17-4B141-
