model
size = 32 12 28, scale = 0.05, origin = -y
material deform = 1, fade = true, lighting = smooth, roughness = 0.3, metalness = 0.6
  colors = A:#444 B:#222 C:#F7CB39 D:#F7DC85 E:#F7D45F F:#5FF G:#9FF H:#7FF I:#DCB834 J:#C2A52E K:#D00 L:#E62E22 M:#EC4D38 N:#E31F17
voxels
8-ECEDCDED2CE2DCEC2D13-ED2CEC2EDC3(ED)2C13-DE16-EC12-D-3E3CD2CE2(DEC)-C13-2E-DC3-DCD-2C-E-C14-CE2D2(C-)2D2(CE)2-2E14-D3-E-2D2C-C3(-E)14-E2(-D)3-DC3-D3-C14-D-C-3DCEC-E-3D2C14-E3-DE-CEC3-EC-CD13-D-2D2CDC4EC5D-C12-CE16-EC145-4A2E2C2A22-3B2C2BC2B22-3ACE2AC2A22-4B2CEC2B275-7A2E2C5A16-6B2C2BC5B16-6ACE2AC5A16-7B2CEC5B270-9A2E2C7A12-8B2C2BC7B12-8ACE2AC7A12-9B2CEC7B267-7A8-7A10-7B8-7B10-7A8-7A10-7B8-7B265-6A12-6A8-6B12-6B8-6A12-6A8-6B12-6B263-5A16-5A6-5B16-5B6-5A16-5A6-5B16-5B261-5A18-5A4-5B18-5B4-5A18-5A4-5B18-5B259-5A20-5A2-5B20-5B2-5A20-5A2-5B20-5B258-4A22-4A2-4B22-4B2-4A22-4A2-4B22-4B257-2(5A22-5A5B22-5B)2(256-2(4A24-4A4B24-4B))2(256-2(3A26-3A3B26-3B))2(256-2(4A24-4A4B24-4B))256-2(5A22-5A5B22-5B)257-4A22-4A2-4B22-4B2-4A22-4A2-4B22-4B258-5A20-5A2-5B20-5B2-5A20-5A2-5B20-5B259-5A18-5A4-5B18-5B4-5A18-5A4-5B18-5B261-5A16-5A6-5B16-5B6-5A16-5A6-5B16-5B263-6A12-6A8-6B12-6B8-6A12-6A8-6B12-6B265-7A8-7A10-7B8-7B10-7A8-7A10-7B8-7B267-20A12-20B12-20A12-20B141-E2C3E2CD4C4EC13-2CE3D2E2DCE3CDC3E12-C3E4C3D2ECE3DEC12-CDC3DC2D2E4C2(DC)D12-C3EC4E2D2C2DC3DE12-2(DEC)ECE3DCDCE2DEC12-ECD2(EC)DECDED6CD12-DEC2DEDEC2E2DECDCE2C12-ECE2DCE3DCEC2E2DE2D12-DE2D3C2ECEC5ECDC12-E2CD2EDED2CDE3DCECD13-3EDC2DE2C2DE3CDC14-EDC2E2C4DE2DEDCD13-ECI2JI2CICJ3I4C2E12-DJ2(DE)CEDE2D2ED2CDIC12-CDHK5FEDHLGHF2H2D12-2EFHF3GFDE2G3FHFCD12-DCHF2G3FED3GF2GHCD12-2C2(FG)2HGCE2FHF2GFDC12-CEH2GHG2HECGHF3HF2D12-DCHF2GHMFDEHF2HGNGDE12-DC3DEDCEDE2DCEC2DCE12-2DJ3I3CI4JICJI2C13-C2EDED2E2(2CD)C3D14-ED2CEC2EDC3(ED)2C13-DE16-EC12-D-3E3CD2CE2(DEC)-C13-2E-DC3-DCD-2C-E-C14-CE2D2(C-)2D2(CE)2-2E14-D3-E-2D2C-C3(-E)14-E2(-D)3-DC3-D3-C14-D-C-3DCEC-E-3D2C14-E3-DE-CEC3-EC-CD13-D-2D2CDC4EC5D-C12-CE16-EC13-ECEDCDED2CE2DCEC2D7-
