model
size = 32 26 23, scale = 0.05, origin = -y
material deform = 1, fade = true, lighting = smooth, roughness = 0.3, metalness = 0.6
  colors = A:#555 B:#F0F C:#6F9 D:#222
voxels
326-6C8-6C11-10C2-10C10-2C5-8C5-2C10-2C5-C6-C5-2C10-2C5-C-4C-C5-2C10-2C5-C-C2-C-C5-2C10-2C5-C6-C5-2C10-22C11-7C6-7C555-8A6-8A9-11A2D11A8-3A5-8A5-3A8-3A-3B-A6DA-3B-3A8-3A-B3-8A3-B-3A8-3A2(-B)-3A2D3A2(-B)-3A8-3A5-8A5-3A8-24A8-9A6-9A9-22A521-24A7-3(26A6-)6A2D10A2D6A6-6AD12AD6A4(6-26A)7-24A456-24A8-24A6-9(28A4-)28A5-26A297-2(20A12-)20A11-22A9-24A7-26A5-10(28A4-)28A5-26A13-12B2(20-12A)176-2(20A12-)20A11-22A8-26A5-12(28A4-)9A10-9A11-BA10-AB19-A10-A20-A10-A144-20A11-22A10-22A11-20A9-26A5-13(28A4-)2(9A10-)3B10-3B17-2A10-2A19-A10-A112-7A6-7A11-22A9-24A7-26A6-26A5-14(28A4-)2(9A10-)3B10-3B17-2A10-2A19-A10-A16-2(A18-A12-)4A12-4A11-8A6-8A9-24A7-2(26A6-)26A5-6(28A4-)28A2-2B6(28A4B)28A2B2-2(9A10-)3B10-3B17-2A10-2A19-A10-A15-2(2A18-2A10-)5A12-5A9-9A6-9A7-3(26A6-)26A5-5(28A4-)28A2-2B28A4B28A2B3-4(D24AD6-)D24AD3-2B28A4B10A8-10A2B8-3B10-3B17-2A10-2A19-A10-A14-3(3A18-3A8-)3A18-3A7-3(4A18-4A6-)4A18-4A5-5(28A4-)28A2-2B28A4B28A2B3-5(D24AD6-)D24AD3-2B10A8-10A5B5-3B10-3B5-3B2(9-2A10-2A19-A10-A14-3A18-3A7-2(4A18-4A6-)4A18-4A5-4(5A18-5A4-)5(28A4-)28A2-2B28A2B3-7(D24AD6-)D8A8-8AD3-11B10-11B)9-2A10-2A19-A10-A14-3A18-3A7-2(4A18-4A6-)4A18-4A5-4(5A18-5A4-)5(28A4-)28A2-2B28A3B30AB3-5(D24AD6-)D24AD3-B11A8-11A4B5-3B10-3B5-3B9-2A10-2A19-A10-A14-3A18-3A7-2(4A18-4A6-)4A18-4A5-4(5A18-5A4-)5(28A4-)28A2-2B28A4B28A2B3-4(D24AD6-)D24AD3-2B28A4B10A8-10A2B8-3B10-3B17-2A10-2A19-A10-A14-3(3A18-3A8-)3A18-3A7-3(4A18-4A6-)4A18-4A5-6(28A4-)28A2-2B5(28A4B)28A3B-28A-B2-10A8-10A2(10-3B)17-2A10-2A19-A10-A15-2A18-2A9-2(3A18-3A8-)3A18-3A7-3(4A18-4A6-)4A18-4A5-14(28A4-)10A8-10A2(10-3B)17-2A10-2A19-A10-A16-A18-A12-A18-A10-3A18-3A8-3A18-3A7-3(4A18-4A6-)4A18-4A5-4(13A2D13A4-)10(28A4-)10A8-10A10-4B8-4B17-3A8-3A19-2A8-2A48-A18-A10-3A18-3A8-3A18-3A7-3(4A18-4A6-)4A18-4A5-4(13A2D13A4-)10(28A4-)28A11-4B6-4B19-3A6-3A80-A18-A11-5A12-5A9-9A6-9A8-9A6-9A7-2(10A6-)11A4-11A6-A6D5A2-5A6DA5-13A2-13A4-3A7D3A2-3A7D3A4-13A2-13A4-5A6D2A2-2A6D5A10(4-28A)2(4-12A)12-3B6-3B269-8C10-8C5-2A6-2C8-2C6-2A4-3A8C6-8C3A4-3A7-C6-C7-3A4-5A8C2-8C5A4-5A6-2C2-2C6-5A2(4-8A5C2A5C8A)6(4-28A)5-26A7-24A359-A24-A2(6-2A22-2A)2(6-4A18-4A)2(6-7A5-2A5-7A)2(6-26A6-3A20B3A)6-26A7-24A649-22A9-2A20-2A8-24A8-2A20-2A9-22A229-
