model
size = 20 21 12, scale = 0.05, origin = -y
material deform = 1, fade = true, lighting = smooth, roughness = 0.3, metalness = 0.6
  colors = A:#444 B:#222 C:#F0F D:#0FC
voxels
207-6C14-C4-C14-C3-2C14-C4-C14-6C273-2(B6-B12-A6-A12-)A6-A291-6(3A-2A-3A10-)BAB-2B-BAB10-3B-2B-3B268-5AB2AB5A6-AB3AB2AB3ABA6-5AB2AB5A6-AB3AB2AB3ABA5-2(2AB3AB)2A4-3B3AB2AB3A3B2(4-7B2A7B)247-10A8-2(14A6-)14A5-2(16A4-)6B4A6B2-2B7-2A7-4B6-4A6-2B9-2A17-3(4A36-)4A35-2(6A14-)6A12-10A8-14A5-B14AB5-14A4-2(18A2-)7B4A7B-2B7-2D7-4B6-4A6-2B9-3(2D17-4A17-)2D17-4A35-2(6A14-)6A12-10A8-14A5-B14AB5-14A4-18A2-B16AB2-7B4A7B-2B16-4B6-4A6-2B28-4(4A36-)2(4A16-)4A14-8A9-14A5-B14AB5-14A4-2(18A2-)18B-2B16-4B16-2B168-3(4A16-)4A14-8A9-2(14A6-)14A5-2(16A4-)16B2-2B16-4B16-2B188-3(4A16-)4A11-2(14A6-)2(2ABA2B2A2BAB2A6-)2AB8AB2A6-14B3-2B16-4B16-2B169-5(2A18-)2A13-12A2(8-A-A2-2A2-A-A)8-A-8A-A8-A-2A4B2A-A5-2B5A4B5A2B2-6B-4B-6B348-6A14-A4-A9-5BA3-2A5B4-5BA4-A5B9-6A147-
