model
size = 28 30 10, scale = 0.05, origin = -y
material deform = 1, fade = true, lighting = smooth, roughness = 0.3, metalness = 0.6
  colors = A:#FC3 B:#FF0
voxels
432-2B26-2B782-2B26-2B419-2B26-9B19-B8A2B17-BA7B2A2B15-BA7-B2AB15-BA8-B2AB14-BA9-BAB14-2(BA9-B2AB13-)BA9-B2AB12-B2A9-B2AB11-B3AB7-B3A12B4AB6-B3AB-B14A7B4AB-2(B24AB2-)B14A7B4AB-11B4AB6-B3AB12-B3AB7-B3AB12-2B4(A9-B2AB13-B)A9-BAB14-BA8-B2AB14-BA7-B2AB15-BA7B2A2B15-B8A2B17-9B19-B6(27-2A26-9A19-11A17-13A15-2A7-4A15-2A8-4A14-2A9-3A14-2(2A9-4A13-)2A9-4A12-3A9-4A11-5A7-21A6-5A-27A-2(26A2-)27A-16A6-5A12-5A7-5A12-3A4(9-4A13-2A)9-3A14-2A8-4A14-2A7-4A15-13A15-11A17-9A19-A)27-2B26-BA7B19-B8A2B17-BA7B2A2B15-BA7-B2AB15-BA8-B2AB14-BA9-BAB14-2(BA9-B2AB13-)BA9-B2AB12-B2A9-B2AB11-B3AB7-B3A12B4AB6-B3AB-B15A6B4AB-2(B11A2B11AB2-)B15A6B4AB-11B4AB6-B3AB12-B3AB7-B3AB12-B2A4(9-B2AB13-BA)9-BAB14-BA8-B2AB14-BA7-B2AB15-BA7B2A2B15-B8A2B17-9B19-B14-
