model
size = 15 25 10, scale = 0.05, origin = -y
material deform = 1, fade = true, lighting = smooth, roughness = 0.3, metalness = 0.6
  colors = A:#E00 B:#111 C:#600 D:#400 E:#30C F:#90C G:#FF0
voxels
20-2D2-2D9-BD2-DB31-A14-B5-B8-A5-B8-B5-B8-A2-7B2(5-B)8-A5-B8-B5-B6-5A3(3-B6-2(A-)A)3-B6-2(A3-)B14-B318-2(2C13-)2C327-4C9-C-4C-C9-4C11-2CEC11-4C8-2(2A6-2A5-)2A6-2A247-6A9-CF4C8-2CF5C7-2CF5C8-C4EC7-2AC4EC2A4-3A-4C-2(2A4-3A6-)3A3-3A6-2A5-A8-A37-2D2-2D3(9-2B2-2B)9-6B9-6D3(9-6B)9-BC2BCB9-6B9-AC2BCA9-A4CA2(9-CF4C)8-C2F5C6-A3C4ECA5-2A2C4ECA4-3A6C3A3-4A4-4A2-4A6-4A-4A6-4A2-2A8-2A3-2A8-2A4-2A6-2A7-2D2-2D3(9-2B2-2B)9-6B9-D4BD2(9-BC2BCB)4(9-B4CB)9-A4CA9-CF4C8-C2F3CFC7-C2F3CFC6-A3C2E3GA5-2A2C2E2G2A4-4A4C4A3-4A4-4A2-4A6-4A-4A6-4A2-2A8-2A3-2A8-2A4-2A6-2A7-2D2-2D3(9-2B2-2B)9-6B9-DB2DBD9-6B9-BD2BDB9-6B7-3BD2BD3B5-10B5-3BD2BD3B7-A4CA10-4B10-6B9-5BC7-A5C2GCA5-2A4CGC2A4-4A4C4A3-4A4-4A2-4A6-4A-4A6-4A2-2A8-2A3-2A8-2A4-2A6-2A7-2D2-2D9-BD2-DB127-2B6-2B5-2B6-2B7-6A10-4C10-C4-C9-BA2-AB9-4CGC10-4C115-2D2-2D9-BD2-DB127-2B6-2B5-2B6-2B53-A2-A11-4C130-2D2-2D9-BD2-DB127-2B6-2B5-2B6-2B197-
