model
size = 32 30 12, scale = 0.05, origin = -y
material deform = 1, fade = true, lighting = smooth, roughness = 0.3, metalness = 0.6
  colors = A:#FFF B:#00F5FF C:#00DFFF D:#00C3FF E:#008FFF F:#750CFF G:#00B1FF H:#890CFF I:#B80CFF J:#0078FF K:#5E0CFF L:#0063FF M:#0052FF N:#4100FF O:#EA00FF P:#0028FF Q:#0039FF
voxels
394-12A19-14A17-16A15-3A12F3A14-3AKA8HAK3A14-3AKA8IAK3A13-20A12-5A10I5A11-5A12H5A10-5A12F5A11-5AK8AK5A13-4AK8AK4A17-12A532-12A19-14A17-16A15-3A12F3A14-3AKA8HAK3A14-3AKA8IAK3A13-20A12-5A10I5A11-5A12H5A10-5A12F5A11-5AK8AK5A13-4AK8AK4A17-12A211-5B4-5B18-BKFH2B2-2BHFKB18-BKFHIB2-B2(IHFKB18-BKFHI4B)IHFKB18-BKFH6BHFKB18-BKF8BFKB18-BK10BKB3(18-14B)17-CB12-BC16-C14-C16-A14-A15-A16-A13-DA16-AD12-DA16-AD11-J2A16-2AJ9-EG2A16-2AGE8-E3A16-3AE8-E2A18-2AE9-GA18-AG11-DA16-AD13-D2CA10-A2CD16-C12BC21-GDC2BCDG24-N6-N148-10(C14-C16-)C14-C15-C16-C14-C16-C13-D18-D12-D18-D11-LA18-AL10-JA18-AJ10-GA18-AG8-J-A20-A-J5-L2JA20-A2JL6-EA20-AE9-GA18-AG11-D2A14-2AD13-DC14-CD16-3B8N3B20-3NP2QP3N146-11(C16-C14-)C16-C13-D18-D12-D18-D11-LG18-GL10-LG18-GL103-LJ24-JL3-ML2J22-2JLM4-JE22-EJ7-EGA18-AGE9-GD2A14-2ADG12-DC-N10-N-CD14-D2C2K8-2K2CD15-2K12-2K16-K14-K110-11(D18-D12-)D18-D11-LG18-GL229-2MLJ24-JL2M2-LJG22-GJL6-E22-E9-GD2E14-2EDG12-C-F12-F-C14-D-F12-F-D14-D16-D109-10(E18-E12-)E18-E11-MG18-GM261-2MLJ24-JL2M-2MAG22-GA2M4-JE22-EJ7-EGD2E14-2EDGE9-GD2-F12-F2-DG11-D2-F12-F2-D12-D2-F12-F2-D108-10(E18-E12-)E18-E11-MG18-GM261-2MLJ24-JL2M-2MAG22-GA2M4-JE22-EJ7-EGD2EF12-F2EDGE9-GD2-FH10-HF2-DG11-D2-FH10-HF2-D12-D3-H10-H3-D108-11(D18-D12-)D18-D11-LG18-GL229-2MLJ24-JL2M2-LJG22-GJL6-E22-E9-GD2EI12-I2EDG10-GD2-F2I8-2IF2-DG11-D2-EI10-IE2-D12-D3-I10-I3-D16-I10-I49-11(C16-C14-)C16-C13-D18-D12-D18-D11-LG18-GL10-LG18-GL103-LJ24-JL3-ML2J22-2JLM4-JE22-EJ7-EGA18-AGE9-GD2O14-2ODG12-DC2O10-2OCD14-D2CKO8-OK2CD14-DCEGO8-OGECD14-DC2-O8-O2-CD18-O8-O51-10(C14-C16-)C14-C15-C16-C14-C16-C13-D18-D12-D18-D11-LG18-GL10-JA18-AJ10-GA18-AG8-J-A20-A-J5-L2JA20-A2JL6-EJ20-JE9-GJ18-JG11-D2C14-2CD13-2C14-2C16-3BGDC2BCDG3B18-3B8-3B18-2B10-2B82-5B4-5B18-BKFH2B2-2BHFKB18-BKFHIB2-B2(IHFKB18-BKFHI4B)IHFKB18-BKFH6BHFKB18-BKF8BFKB18-BK10BKB3(18-14B)17-CB12-BC16-C14-C16-A14-A15-A16-A13-DA16-AD12-DA16-AD11-J2A16-2AJ9-EG2A16-2AGE8-E3A16-3AE8-E2A18-2AE9-GA18-AG11-DA16-AD13-2CBA10-AB2C16-14B21-GDC2BCDG140-
