model
size = 19 28 18, scale = 0.05, origin = -y
material deform = 1, fade = true, lighting = smooth, roughness = 0.3, metalness = 0.6
  colors = A:#0052FF B:#FFF C:#0063FF D:#0078FF E:#008FFF F:#00B1FF G:#890CFF H:#B80CFF I:#00C3FF J:#EA00FF K:#00DFFF L:#00F5FF M:#750CFF N:#0039FF O:#0028FF P:#4100FF Q:#5E0CFF
voxels
5-4B14-5B3A10-2B4-4A8-2B5-5A6-2B6-6A5-B7-7A3-2B7-8A2-J8-9A-H8-8A2-G8-8A2-M8-8A2-Q8-8A2-P8-8A2-O8-8A2-N8-8A2-A8-8A2-C8-8A2-D8-8A2-E8-8A2-F8-8A2-I8-9A-K8-8A2-L8-7A3-2B7-6A5-B7-5A6-B7-4A8-B6-3A10-2B2-3B13-5B3A10-2B4-4A8-2B5-5A6-2B6-6A5-B7-7A3-2B7-8A2-J8-9A-H8-8A2-G8-8A2-M8-8A2-Q8-8A2-P8-8A2-O8-8A2-N8-8A2-A8-8A2-C8-8A2-D8-8A2-E8-8A2-F8-8A2-I8-9A-K8-8A2-L8-7A3-2B7-6A5-B7-5A6-B7-4A8-B6-3A10-2B2-3B13-4B15-5B3AC9-2B4-4A8-2B5-5A6-2B6-6A5-B7-7A3-2B7-8A2-J8-9A-H8-8A2-G8-8A2-M8-8A2-Q8-8A2-P8-8A2-O8-8A2-N8-8A2-A8-8A2-C8-8A2-D8-8A2-E8-8A2-F8-8A2-I8-9A-K8-8A2-L8-7A3-2B7-6A5-B7-5A6-B7-4A8-2B5-3AC9-2B2-3B13-4B20-3AC15-4AD14-5A14-6A13-7A12-8A11-9A10-12(8A11-)9A10-8A11-7A12-6A13-5A14-4AD14-3AC53-3AC15-4AD14-5AE13-6A13-7A12-8A11-9A10-12(8A11-)9A10-8A11-7A12-6A13-5AE13-4AD14-3AC53-3AC15-4AD14-5AE13-6AF12-7A12-8A11-9A10-2(8A11-)7AG2(11-7AM)2(11-8A)11-7AH11-7AG3(11-8A)11-9A10-8A11-7A12-6AF12-5AE13-4AD14-3AC53-3AC15-4AD14-5AE13-6AF12-7AI11-8A11-9A10-2(8A11-)7AG3(11-8A)11-7AJ11-7AH11-7AG2(11-7AM)11-8A11-9A10-8A11-7AI11-6AF12-5AE13-4AD14-3AC53-3AC15-4AD14-5AE13-6AF12-7AI11-8AK10-9A10-2(8A11-)7AG11-7AH11-7AJ11-8A11-7AJ11-7AH11-7AG3(11-8A)11-9A10-4(8AK10-7AI11-6AF12-5AE13-4AD14-3AC53-3AC15-4AD14-5AE13-6AF12-7AI11-8AK10-9AL9-2(8A11-)7AG11-7AH11-7AJ11-8A11-7AJ11-7AH11-7AG3(11-8A)11-9AL9-)8AK10-7AI11-6AF12-5AE13-4AD14-3AC53-3AC15-4AD14-5AE13-6AF12-7AI11-8AK10-9A10-2(8A11-)7AG11-7AH11-7AJ11-8A11-7AJ11-7AH11-7AG3(11-8A)11-9A10-8AK10-7AI11-6AF12-5AE13-4AD14-3AC53-3AC15-4AD14-5AE13-6AF12-7AI11-8A11-9A10-2(8A11-)7AG3(11-8A)11-7AJ11-7AH11-7AG2(11-7AM)11-8A11-9A10-8A11-7AI11-6AF12-5AE13-4AD14-3AC53-3AC15-4AD14-5AE13-6AF12-7A12-8A11-9A10-2(8A11-)7AG2(11-7AM)2(11-8A)11-7AH11-7AG3(11-8A)11-9A10-8A11-7A12-6AF12-5AE13-4AD14-3AC53-3AC15-4AD14-5AE13-6A13-7A12-8A11-9A10-12(8A11-)9A10-8A11-7A12-6A13-5AE13-4AD14-3AC53-3AC15-4AD14-5A14-6A13-7A12-8A11-9A10-12(8A11-)9A10-8A11-7A12-6A13-5A14-4AD14-3AC48-5B3AC9-2B4-4A8-2B5-5A6-2B6-6A5-B7-7A3-2B7-8A2-J8-9A-H8-8A2-G8-8A2-M8-8A2-Q8-8A2-P8-8A2-O8-8A2-N8-8A2-A8-8A2-C8-8A2-D8-8A2-E8-8A2-F8-8A2-I8-9A-K8-8A2-L8-7A3-2B7-6A5-B7-5A6-B7-4A8-2B5-3AC9-2B2-3B13-4B11-
