model
size = 32, scale = 0.05, origin = -y
material deform = 1, fade = true, lighting = smooth, roughness = 0.3, metalness = 0.6
  colors = A:#903 B:#C03 C:#600 D:#F06
voxels
749-A2-C27-2A2-2C26-2A2-C28-A2-C827-2A30-2A2-C26-3A2-C2-A23-3A2-C2-A24-2A2-C858-3A2-C25-2(4A2-C2-A22-)4A2-C2-2A62-A791-3A29-3A2-C25-4A2-C2-2A21-4A2-C2-2A85-4A2-C2-2A21-4A2-C2-A22-4A2-C2-A23-3A2-C27-2A700-A29-A-A8-2A85-2A4-C2-2(2A21-2A7-)2A21-A8-2(2A21-4A2-C2-)A24-2A2-C666-2A91-A10-3(2A30-)3(2A19-B10-)2A30-A31-A418-A2-2B25-3A2-3B17-A2-C2-4A2-3B16-2A2(2-C2-4A2-3B17-A)2-C2-4A2-2B24-4A2-B80-4A2-C23-A-4A2-C22-2B-2A-A2-C23-5(B-A29-)B-4A26-B-3A3-C26-3A2-C313-3A26-BA-3A8-2A2(16-BA-4A2-C2-4A)17-A-4A2-C2-4A17-A-4A2-C2-3A18-A-4A2-C2-2A19-A-4A2-C2-A22-4A2-C67-3A2-B16-4A26-B-4A2-C2-2A19-B-2A-A2-C2-3A18-B-2A7-3A2(18-B-A9-2A)18-B-A9-A18-2B-A8-2A18-2B10-2A18-2B-A8-2A19-B-2A7-A22-4A2-C2-A24-2A2-C309-3(B31-)B63-B76-3A21-3A2-C2-4A22-A2-C2-4A19-4A2-C2-4A17-B-4A2-C2-3A18-B-A8-3A3(18-B-A9-2A)18-B-A9-A3(18-2B10-2A)19-B-2A7-A22-4A2-C2-A23-3A2-C328-2B30-2(3B2-D26-)3B2-D71-B31-B708-3A29-3A2-2C2-2A20-4A2-2C2-3A2-2B12-B2-4A2-2C2-3A2-3B11-BA-4A2-2C2-3A2-3B2-D90-3B2-D27-2B2-2D25-2(3B2-D26-)3B29-2B30-B562-2A2-2C26-2A2-2C2-3A20-3A2-2C2-2A21-3A2-2C2-3A2-2B76-BA-4A2-C2-3A5-B2-D8-BA-4A2-C10-B2-D8-BA-2A27-BA-A19-2D7-2B-2A17-3D7-2B-4A12-B2-2D8-2B-4A2-C9-B2(2-D12-4A2-C2-4A2-2B)13-B-3A3-C2-4A2(17-B-A10-2A)17-B-A9-2A18-B-A9-2A17-2B-A9-A18-2B10-2A18-B11-2A283-2C2-3A22-A2-2C2-3A21-2A2-2C2-3A21-A61-3A4-C2-3A2-2B8-D2-B3-2A23-D2-B28-D2-2BA26-D2-3B23-2(D2-)2B22-3D2-D2-3B21-2D3-D2-3B-A-2A15-3D6-3B-4A12-B2-2D9-B-4A2-C8-2B2-D12-4A2-C3-3A2-2B13-B-2A10-A2-B14-2(B-A10-2A17-)B11-2A17-2B11-2A177-2B10-2A18-2B-2A7-A20-B-4A2-C2-A23-3A2-C188-A2-2C2-3A2-B17-2A3-2C2-3A2-B17-2A53-2(2D30-)2D2-2B24-D-2D2-2B23-2D-2D2-B23-2D3-D2-2B21-3D3-D2-3B2-2A13-B2-2D7-3B-3A12-2B2-D10-B-3A9-A2-2B15-2A9-2A2-B14-B-A10-2A176-2B11-A3(18-2B10-2A)19-B-A8-A20-B-3A3-C2-A23-3A2-C67-3A657-B-A10-2A17-B11-2A18-B11-2A17-2B11-A18-2B10-2A18-B11-2A18-2B10-A19-2B-A5-C2-A20-B-4A2-C2-A23-3A2-C91-2A2-2C2-3A2-B19-A2(2-2C2-3A21-2A)2-2C2-3A2-B17-3A2-2C2-3A2-B17-2A84-3D29-2D29-4D2-B24-2D-2D2-B23-2D628-3A2-B21-2(3C2-3A2-2B17-A2-)3C4-A21-A2-3C2-3A21-A2-3C2-2A77-D29-3D2-B187-2D2-B22-3D3-D2-B19-B2-2D4-D2-3B-3A12-2B2-D8-3B-3A9-A2-2B15-2A9-2A2-B14-B-A10-2A17-B-3A8-2A16-2(2B11-2A17-)3(2B10-2A18-)2B10-A155-C-C2(2-3A2-2B17-A2-3C)2-A4-2B17-A2-3C3-2A21-A2-3C2-3A24-3C207-2D30-2D29-4D26-2D2-2D25-3D3-D2-B3-A15-B2-2D4-D2-3B-2A10-A2-2B2-D8-3B-2A10-A2-B16-2(2A9-2A17-B-)3A7-2A18-B-3A7-2A17-2B11-2A17-2B262-C-C2-4A2-B20-3C2-2A25-3C2-A26-3C2-3A204-D2-B26-3D2-B26-2D30-2D4-2B23-3D27-2D2-2D3-2B17-B2-3D2-2D2-3B-2A13-2B2-2D4-D2-3B-3A2-C6-A2-2B11-3B-3A2-C5-2A2-B16-2A9-2A17-B-A285-2B-A5-C2-A87-A9-2A2-B180-3C2-3A262-3D25-2B2-2D307-2(C2-A18-2B8-)C2-A83-B-4A2-C2-A23-3A2-C36-2A2-B81-3(A31-)A118-D2-2B26-2D2-B26-3D296-A9-2A17-B-A9-2A18-B-3A7-2A17-2(2B8-C2-A18-)2B8-C2-A50-2B7-C2-A20-B-2A4-C2-A22-4A2-C2-A24-2A2-C39-B27-2A2-B18-A2-3C2-3A21-A2-3C2-2A22-A2-2C3-2(2A22-A2-3C2-)2A298-D54-A2-2B2-D17-C5-2A2-2B20-3C3-2A2-B22-C3-2A30-2A27-3(C2-A28-)C2-A50-2B8-C21-2B-A5-2C22-B-2A4-2C24-3A2-3C26-A2-C68-2A2-B18-A2-C-C2-3A21-A2-C-C2-2A25-3C304-2D4-2B-A22-2D3-3B25-2D2-3B-A23-2D2-3B-3A25-3B-3(3A29-)2A28-B-A29-B-A102-C2-A27-2C30-2C29-3C29-2C402-D2(2-B27-2D)2-3B22-D2-2D2-3B-A19-2(2D2-)3B-A15-B2-2D3-2D2-3B-2A9-2A2-2B2-2D7-3B-2A8-3A2-2B15-2A8-3A2-B16-3A2-3C2-2A2-B18-2A2-C-2(C2-2A20-2A5-)C2-A51-B-A28-2(2B30-)2B31-B-A29-B-3A29-3A231-2A22-A2-3C2-2A25-3C145-D2-2B27-D2-2B21-D-D3-D2-3B-A13-3B2-3D3-D2-3B-A6-C2-2A2-3B2-2D9-B-2A4-2C2-2A2-3B13-B-3A2-3C2-2A2-2B16-3A2-3C2-2A21-2A2-3C2-A22-2A2-3C2-A83-2(B-A6-C2-A19-)B8-C2-A18-2B8-C21-2B-A5-2C22-B-2A3-3C22-B-3A2-2C26-2A2-2C133-A2-B27-2A2-B26-3A25-2C2-A27-2C226-2A2-3B2-3D16-2C2-2A2-3B2-2D17-2C2-2A2-3B2-D18-2C2-2A2-B23-2C2-A27-2C30-2C56-2A4-2C2-A21-2A5-3(C2-A19-B-A6-)C22-B-A5-2C22-B-A4-3C22-B-3A2-2C25-3A2-2C27-A159-A2-C28-A2-2(C31-)C182-3B29-3B-A27-3B-3A2-C23-2B-3A2-C24-B-3A2-C26-3A2-C27-2A2-C64-2C6(31-C)262-2B30-2B26-A31-A255-2A2-3B2-D22-2A2-B150-C27-2A2-C26-3A2-2C25-2A4-C23-2(B-A29-)2(B-A5-C23-)B-2(3A2-2C25-)3A2-C225-C29-3C29-C184-B30-2B-3A2-2C23-B-3A2-3C24-3A2-3C953-2A2-C91-2A2-C123-2A2-C26-2(3A2-2C25-)2A4-2(2C22-B-A5-)2C22-B-3A2-3C24-3A2-2C25-3A2-C795-2A2(2-2C25-3A)2-2C25-2A4-2C24-3A2-3C24-3A2-2C25-3A2-C831-C27-2A2(2-2C25-3A)2-C26-3A2-C27-2A2-C175-
