model
size = 32 10 12, scale = 0.05, origin = -y
material deform = 1, fade = true, lighting = smooth, roughness = 0.3, metalness = 0.6
  colors = A:#100 B:#630 C:#111 D:#492B00 E:#001 F:#222 G:#800 H:#B00 I:#A00 J:#E00 K:#45331E L:#D00
voxels
286-CA223-2(C317-A)290-F28-A-A255-2A29-2A28-ACF2A30-A222-AC26-GE4AC25-LE2BAC28-4AC30-A69-B24-A4-DB-B22-A-AC-2B12-3B9-C-CA-2B10-2(D3B)5-G2E4AD6B4-2B5-2DBK2BIG3B2A3-2B2-3BD2B8-D3BG4B2AC24-HIEB3A28-2C2A31-2C125-AC29-2A28-E4AF24-HGEB3A26-JEA-F29-2A-A29-A161-A29-2AC28-C2A31-CAC93-2A159-AC29-CA30-F319-C31-CF65-
