model
size = 7 32 3, scale = 0.05, origin = -y
material deform = 1, fade = true, lighting = smooth, roughness = 0.3, metalness = 0.6
  colors = A:#0FC B:#DDD C:#900 D:#309 E:#222 F:#AAA G:#777 H:#BBB I:#444 J:#555 K:#888 L:#E00 M:#EEE
voxels
66-6(2A5-)2G5-IG3(5-IH)4-LIL2-14B45-C4-5C2-2C2-C4-8(F6-)F5-6(ADA4-)GDG4-G3(DK4-H)DK4-2DB2-2B3D3B5DB3-6(2E5-)2C3-2C2MC2-CM2-C67-6(2A5-)2G5-JG5-JF2(5-JH)4-LIL2-14B45-2C3-5C2-2C2-C-
