model
size = 26 31 4, scale = 0.05, origin = -y
material deform = 1, fade = true, lighting = smooth, roughness = 0.3, metalness = 0.6
  colors = A:#E00 B:#CF3 C:#FF0
voxels
682-B58-B76-8A17-10A16-10A15-12A13-14A11-8A4C4A10-4A5C2A2C3A9-4A2C12A7-10A5C5A6-5A6C9A3(6-20A)2-B3-20A2-2(B-)20A2-4B20A3-B-B20A3-B2-3A5C4A5C3A4-B-2(4AC2AC)4A-B2-2B3A5C4A5C3A2(-B3-B20A)-2B-B-20AB-3B-20A3B-2B20A2-20B2-B4-21B9-4B2-3B3-2B12-B-4B5-3B13-11B19-2B434-2(B25-)2B25-B2(25-2B)22-B2-2B19-B-B3-B2-2B7-2B4-B2(-5B)-6B2-B3-2B-12B-3B11-2B2-4B-6B11-7B22-4B5-2B14-2B3-5B676-B-2B9-6B-5B3-B11-4B-3B6-B12-3B2-2B25-B64-
