model
size = 20 25 6, scale = 0.05, origin = -y
material deform = 1, fade = true, lighting = smooth, roughness = 0.3, metalness = 0.6
  colors = A:#EEE B:#111 C:#CF3 D:#0E0 E:#C33 F:#E00
voxels
169-2E335-8A11-10A10-10A9-12A7-14A5-6A4B6A4-5A6B5A3-6A6B6A-7A6B15A4B130A7B2A7B4A4B2CB2AB2C4B4ABC2FC2B2A2BC2FCB4AB2CFC2B2A2BCF2CB4AB4C2B2A2B4CB4A7B2A7B62A128-2(4D16-)4D2(477-2E17-A2-A)477-2E349-
