model
size = 31 25 31, scale = 0.05, origin = -y
material deform = 1, fade = true, lighting = smooth, roughness = 0.3, metalness = 0.6
  colors = A:#9CC
voxels
12-7A27-A-A734-14A20-A-2(A2-)A-A729-17A15-A-2A-A-4A2(-A)727-19A12-2(A-)2A2(-A)-5A-A24-A700-21A11-A-A2-A-7A-A-2A17-A-3A-2A2-A23-A3-A667-9A7-7A11-2(A-)15A14-2A-5A2(-2A)19-A-3A5-A23-2A638-8A11-6A6-A2-2A-16A-2A10-A2-A-10A-2A17-2A-8A20-6A3-A23-3A606-8A13-6A6-2A2-19A7-2A5-14A-2A13-13A19-2A-6A-2A20-5A2(28-3A)544-7A15-5A7-2A-5A5-7A-3A8-A-18A15-13A-2A15-12A19-8A-A23-7A24-6A26-5A27-2A481-7A17-5A5-A-5A9-8A9-7A5-9A12-5A5-7A12-A-5A5-4A2-A15-A-2A5-3A21-10A2(22-8A)23-7A26-4A28-2A-A26-A-2A28-A358-6A19-4A3-8A11-6A-A5-8A9-7A10-6A8-6A11-6A8-5A14-4A8-A2-A17-3A4-4A20-11A20-10A22-9A22-8A24-6A26-4A28-A29-2(2A30-)A264-6A19-4A4-2A-3A13-7A6-6A11-7A7-7A10-5A10-7A9-3A13-6A9-2A17-3A6-5A17-3A5-5A18-3A5-4A20-2A5-4A21-A5-3A2(23-7A)25-6A25-3A2-A26-4A28-2A-A28-2A2(30-A)31-A137-6A21-4A2-7A13-9A4-A-4A11-8A7-5A11-6A9-6A10-3A13-5A10-2A15-4A8-4A16-3A7-5A16-3A7-4A18-2A7-4A19-A7-3A21-9A22-8A24-7A24-6A2(26-5A)27-3A29-3A28-3A29-3A30-4A102-6A21-6A-5A15-5A-A5-4A15-2A-A8-5A14-4A9-4A14-2A11-5A12-A15-3A10-3A15-3A9-4A16-2A9-3A17-2A9-3A18-A9-3A19-11A21-9A22-9A23-7A24-7A25-6A26-4A27-4A28-3A29-5A2-2A22-8A25-5A26-A2-A40-6A21-12A15-8A-7A15-5A-A4-6A14-2A-A9-4A14-2A11-5A13-A14-3A11-3A14-3A10-4A15-2A9-4A17-A9-3A18-A9-2A2(19-12A)20-10A22-8A23-8A2(24-7A)6-A18-6A6-2A18-5A5-3A18-6A3-3A20-10A22-8A24-4A-A26-3A10-6A21-4A2-6A15-4A-A5-5A15-3A-A7-5A14-2A11-4A14-A14-3A13-A14-3A11-2A15-3A10-4A14-3A2(9-5A15-2A)9-2A-A16-13A19-12A19-11A2(21-10A)22-8A24-7A25-6A6-A19-5A6-A20-5A4-A22-8A25-4A27-4A40-6A21-7A-4A15-8A-2A-4A15-6A4-7A14-3A-A6-6A14-A12-5A13-A14-3A11-2A15-3A10-4A15-2A9-4A16-2A9-4A17-A9-3A18-13A19-11A20-10A22-8A23-8A24-7A25-5A27-3(4A28-)A-2A28-A-2A71-6A21-4A2-6A15-5A-A3-A2-3A15-4A8-A-3A14-A-2A10-3A14-2A13-3A12-A15-3A10-3A16-2A9-4A16-2A9-3A18-A9-2A19-2A8-2A20-11A21-9A23-8A23-7A25-5A26-5A27-4A28-3A29-2A30-2A29-A106-6A21-6A-A-4A13-5A3(-A)2-6A11-5A2-A6-6A11-4A10-7A10-3A13-5A10-2A16-3A8-3A17-3A2(7-4A18-2A)7-3A20-A7-3A21-10A22-8A24-2(5A26-)5A27-A-2A29-A30-A31-A169-6A19-4A3-3A2-2A13-3A-3A5-2A-4A11-5A10-6A10-3A13-6A9-3A15-4A8-3A17-3A6-4A3(18-3A5-5A)18-3A5-4A20-8A24-7A25-2A-3A26-4A28-A-A30-A263-6A18-5A3-A-6A11-5A2(-A)7-5A9-3A-2A11-6A8-5A12-6A8-4A15-4A6-4A18-4A4-4A19-12A19-10A21-9A23-8A24-7A25-5A27-A-2A29-2A30-A294-7A17-5A2-A2-7A9-6A-A11-5A5-8A13-5A5-7A13-6A5-4A-A16-4A4-3A20-6A-2A23-2A-5A23-7A25-6A26-4A28-3A29-A390-7A15-5A5-10A5-9A-A6-2A2-A-11A-4A13-2A-11A2-A15-12A20-8A24-3A2-A26-4A28-3A30-A482-8A13-6A6-19A-3A-A9-A-2A-11A3-A13-A-10A19-9A25-4A29-2A576-8A11-7A5-A2-18A-3A9-A-A2-10A-A3-A13-A-8A22-3A-2A-A637-9A7-8A9-15A-2A-A12-A3-6A-A3-A2-A17-3A29-A642-21A10-A-4A-10A2(-A)15-A2(-3A)2-A-A19-2A674-19A13-A-2A-4A-A2-2A-2A15-A2-3A2(2-A)699-17A14-2(A-)8A-A23-A708-13A18-2(A-)7A-A734-7A25-2(A-)A726-
