model
size = 32, scale = 0.05, origin = -y
material deform = 1, fade = true, lighting = smooth, roughness = 0.3, metalness = 0.6
  colors = A:#FCC B:#111 C:#EEE D:#E00
voxels
-31B203A3(7B4D21A)2(11B21A)2B7C2B79A10B3A10B9AB3C2B3CB3AB2C2B4C2(B9AB8CB3AB8C)B10A8B5A8B80AB7AB22AB9AB107A160B768A15(BA)B2A15(BA)2B15(AB)2A15(BA)129B13(A23(30-2A)2(30-AB30-BA)30-AB2(30-2B)30-33BA24(30-2A)30-AB30-BA30-AB3(30-2B)30-33B)A23(30-2A)2(30-AB30-BA)30-AB2(30-2B)30-33BA26(30-2A)30-AB3(30-2B)2(30-33BA27(30-2A)30-AB2(30-2B))30-33B
