model
size = 31 22 30, scale = 0.05, origin = -y
material deform = 1, fade = true, lighting = smooth, roughness = 0.3, metalness = 0.6
  colors = A:#E00 B:#FFA9BA C:#400 D:#800 E:#B00 F:#222 G:#111 H:#630
voxels
16-H742-A681-A30-A619-A30-A29-3A29-A588-A29-3A2(28-ABA)29-A526-B29-3A4(28-ABA)28-3A29-A464-B29-2(3B28-)ABA27-2(A3BA26-)A3BA27-3A29-A433-B29-3B28-3B27-A3BA26-A3BA25-A5BA24-A5BA25-5A27-3A29-A402-B29-3B28-3B27-5B25-3(A5BA24-)A5BA25-5A27-3A29-A371-B30-B29-3B27-5B25-3(A5BA24-)AF3BFA23-E-2AB2A-E21-E2-5A2-E19-E4-3A4-E17-E6-A6-2(E15-)E13-E17-E11-E19-E9-E21-E7-E23-E5-E25-E3-D27-D140-B29-3B27-5B25-7B2(24-A5BA)24-BF3BFB23-B2FABA2FB21-BE2F3A2FEB19-BED-5A-DEB17-BED3-3A3-DEB15-BED11-DEB13-BED13-DEB11-BED15-DEB9-BED17-DEB7-2ED19-D2E5-DED21-DED3-3D23-3D-G2C25-2CG-F27-FG77-B29-3B27-5B25-2(7B24-)A5BA24-2A3B2A24-3AB3A23-2EF3AF2E21-ED2F3A2FDE19-E2DF5AF2DE17-E2DC2-3A2-C2DE15-E2DC9-C2DE13-E2DC11-C2DE11-E2DC13-C2DE9-E2DC15-C2DE7-2D2C17-2C2D6-2C21-2C5-2CF21-F2C2-2G2F23-2FG108-3B27-5B26-5B25-2(7B24-)2A3B2A24-3AB3A24-7A24-AD3ADA24-CF3AFC23-CF5AFC21-2C2-3A2-2C19-2C9-2C17-2C11-2C15-2C13-2C12-D2C15-2CD9-3C17-3C8-GF19-FG6-2G23-2G3-2G25-2G78-B29-3B27-5B26-5B25-2(7B24-)3(A5BA24-)AC3BCA24-C5AC23-CF-3A-FC21-CF3-A3-FC19-CF9-FC17-CF11-FC15-CF13-FC13-CF15-FC11-GF17-FG8-2G21-2G142-B29-3B27-5B26-5B25-2(7B24-)2(A5BA24-)AG3BGA24-7A24-G5AG23-G2-3A2-G21-G3-3A3-G19-G5-A5-G17-G13-2(G15-)G12-2G17-2G206-B29-3B27-5B26-5B25-2(7B24-)A5BA24-2A3B2A2(24-7A)26-3A27-5A26-5A28-A309-B29-3B27-5B26-5B25-2(7B24-)2A3B2A24-2A3B2A25-4(5A26-)5A27-3A339-B29-3B27-2(5B26-)2(A3BA26-)A3-A5(26-5A)27-3A370-B29-3B28-3B27-A3BA26-A-B-A2(26-5A)26-G3AG2(26-5A)27-3A432-B29-3B27-A3-A5(26-5A)27-3A463-B29-3A27-3(5A26-)5A27-3A556-A29-3A27-5A27-ABA29-A588-A29-AHA29-H681-2(H712-)2(H681-H712-)H15-
