model
size = 21 30 30, scale = 0.05, origin = -y
material deform = 1, fade = true, lighting = smooth, roughness = 0.3, metalness = 0.6
  colors = A:#555 B:#C30 C:#FF0 D:#E00 E:#00E F:#60F G:#EEE H:#0E0 I:#90F J:#111
voxels
534-2B358-2H19-2H12-2D19-2D87-2H19-2H61-2I13-2C4-2I13-2C363-2H19-2H12-2D19-2D87-2H19-2H61-2I13-2C4-2I13-2C1069-2I19-2I112-2C19-2C472-2I19-2I80-2E19-2E-2D6-2C11-2D6-2C104-2D19-2D279-2C19-2C146-2E19-2E-2D19-2D112-2D19-2D279-2C19-2C11-2C19-2C36-2D19-2D86-2H19-2H26-2I19-2I256-2(8A-2F10-)8A13-8A14-2F19-2F26-2C19-2C36-2D19-2D79-2C5-2H12-2C5-2H26-2I19-2I29-2I19-2I184-6A12-2(12AF8-)12A9-12A7-2D3-2F14-2D3-2F182-2H3-2C14-2H3-2C85-2I19-2I163-6A13-10A9-3(14A7-)14A6-2D19-2D152-2F6-2E11-2F6-2E4-2H19-2H255-6A13-10A9-14A6-3(16A5-)16A153-2E19-2E4-2F6-2E11-2F6-2E261-6A13-10A10-12A8-14A5-3(18A3-)18A2E7-6A6-2E42-2F19-2F64-2E19-2E295-8A11-12A8-14A6-16A4-3(18A3-)18A2E5-10A4-2E7-6A29-2F19-2F35-2D19-2D237-2B10-2B72-10A10-12A8-14A6-16A3-3(20A-)20A5-12A10-10A13-6A2F19-2F43-2D19-2D28-2C19-2C47-2E19-2E116-2B10-2B71-12A8-14A6-16A4-18A2-3(20A-)20A4-14A2C6-12A-2C8-7A2F19-2F94-2C19-2C47-2E19-2E115-4B3-2A3-4B6-2(2B4-2A4-2B7-)2B4-2A4-2B8-12A8-14A6-16A4-18A2-3(20A-)20A4-14A2C6-12A-2C7-10A323-4B3-2A3-4B6-2(2B4-2A4-2B7-)2B4-2A4-2B8-12A8-14A6-16A4-18A2-3(20A-)20A3-16A6-14A8-12A322-4B8-4B70-12A8-14A6-16A4-18A2-3(20A-)20A3-16A6-14A8-12A13-4A304-6B6-6B69-12A8-14A6-16A4-18A2-3(20A-)20A3-16A6-14A8-12A12-6A303-6B6-6B70-10A10-12A8-14A6-16A3-3(20A-)20A3-16A6-14A8-12A11-8A15-4A165-3(2A19-)2A52-8B4-8B70-8A11-12A8-14A6-16A4-3(18A3-)18A4-16A6-14A8-12A11-8A14-6A16-4A17-4A18-2A82-5(2A19-)2A31-8B4-8B71-6A13-10A10-12A8-14A5-3(18A3-)18A5-14A8-12A10-10A12-8A14-6A15-6A16-4A17-4A18-2(2A19-)2A18-4(4A17-)4A18-2A31-8B4-8B92-6A13-10A9-14A6-3(16A5-)16A6-14A8-12A11-8A14-2(6A15-)6A16-4A17-4A18-2(2A19-)2A18-4A17-4A15-2G4A2G2(13-3G2A3G)16-2A32-6B6-6B114-6A13-10A9-3(14A7-)14A8-12A10-10A13-6A15-6A16-4A143-4A17-4A15-2G4A2G2(13-3G2A3G)203-6A12-3(12A9-)12A10-10A13-6A206-2A18-B2AB17-B2AB16-J4-J245-3(8A13-)8A14-6A227-2B18-4B17-4B585-2B18-4B18-2B586-2B19-2B628-2B115-
