model
size = 17 32 32, scale = 0.05, origin = -y
material deform = 1, fade = true, lighting = smooth, roughness = 0.3, metalness = 0.6
  colors = A:#303230 B:#4B7B9D C:#FAED27 D:#303E5D E:#212523
voxels
263-A524-3(3A14-)3A473-3A82-3A420-CA14-3C15-2C3A13-3(C16-)C15-2C3A11-3C15-CA240-4(A16-)A63-3(2A14-C)E4A13-2(E3A10-D2-)E3A13-E3A11-CE4A11-C2A14-C2A15-2A189-A16-A15-4(3A14-)3A15-2(A16-)A12-3(2A14-C)E4A11-2(C-E4A9-D)C-E4A10-C-E2D2A10-CE4A11-C2A14-C2A15-2A189-A16-A15-6(3A14-)3(3A11-2A-)3A-4A5-C7A4-A4-C2A2D2A2(6-A3-CE5A)10-2(CE5A6-A3-)C7A4-A4-C2A5-4A6-2(2A15-)2A189-A15-5(3A14-)4(3A11-2A-)3A-4A5-8A4-A4-C6A6-A2-C4A-2A6-A2-C7A6-D2(2-C7A6-A)3-C7A4-A4-7A-4A6-3(2A-3A11-)DA-3A14-3A15-5(A16-)A50-A15-4(3A14-)B2A14-3(B2A11-2A-)B2A10-4AB2A-4A5-8A4-A4-7A6-A3-C6A6-A2-C7A6-B2-C7A6-A3-C6A6-A3-8A4-A4-4AB2A-4A5-4A3(B2A11-2A-)2(B2A14-)5(3A14-)3A15-A33-A15-3(3A14-)2(B2A14-)2(B2A11-2A-)2(B2A10-4A)B2A-4A5-8A4-A3-C7A6-A2-C7A6-A-DC7A6-B-D2(C7A6-A2-)B8A4-A4-4AB2A-4A5-4AB2A10-4A2(B2A11-2A-)3(B2A14-)4(3A14-)3A15-A33-A16-A15-2(3A14-)2(B2A14-)2(B2A11-2A-)B2A10-4AC2A10-4AB2A-4A4-C8A4-A3-C7A6-A2-C7A6-A2DC7A6-3D2(C7A6-A2-)C8A4-A3-B4AB2A-4A5-4AC2A10-4A2(B2A11-2A-)3(B2A14-)3(3A14-)3A15-A67-A15-2(3A14-)B2A14-2(B2A11-2A-)3(B2A10-4A)B2A-4A4-C8A4-A3-C7A6-A-2C7A6-AD2C7A7-D2C7A6-A-2C7A6-A2-C8A4-A3-B4AB2A-4A5-2(4AB2A10-)4AB2A11-2A-B2A11-DA-2(B2A14-)2(3A14-)3A15-A84-A15-3(3A14-)2(B2A11-2A-)2(B2A10-4A)B2A9-C4AB2A9-C2(7A8-2C)2(7A7-D2C)2(7A8-2C)7A2(9-C4AB2A)2(10-4AB2A)2(11-2A-B2A)4(14-3A)15-A84-A15-3(3A14-)2(3A11-2A-)3A2(10-7A)9-C7A-4A4-C8A4-A2-2C7A6-A-2C7A6-AD2C7A7-D2(2C7A6-A-)2C8A4-A3-C7A-4A4-C2(7A10-)7A2(11-2A-3A)3(14-3A)15-A101-A15-3(3A14-)2(B2A11-2A-)3(B2A10-4A)B2A-4A4-C8A4-A3-C7A6-A-2C7A6-AD2C7A6-2D2C7A6-A-2C7A6-A2-C4AB3A4-A3-B4AB2A-4A5-2(4AB2A10-)4AB2A11-2A-B2A11-DA-3(3A14-)3A15-A101-A15-2(3A14-)2(B2A14-)2(B2A11-2A-)2(B2A10-4A)B2A-4A4-C8A4-A3-C7A6-A2-C7A6-AD2C7A6-BD2C2(7A6-A2-C)4AB3A4-A3-B4AB2A-4A5-4AB2A10-4A2(B2A11-2A-)2(B2A14-)3A14-3A15-A118-A16-A15-3A3(14-B2A)2(11-2A-B2A)10-4AC2A10-4AB2A-4A5-8A4-A3-C7A6-A2-C7A6-A-DC7A6-B-D2(C7A6-A2-)B4AB3A4-A4-4AC2A-4A5-4AB2A10-4A2(B2A11-2A-)2(B2A14-)3A15-A152-A15-3A3(14-B2A)3(11-2A-B2A)10-4AB2A-4A5-8A4-A4-7A6-A3-7A6-A2-C7A6-D2-C2(7A6-A3-)4AB3A4-A4-4AB2A-4A5-4A2(B2A11-2A-)B2A11-DA-2(B2A14-)3A15-A152-A15-2(3A14-)2(B2A14-)3(B2A11-2A-)B2A-4A5-8A4-A4-7A2(6-A3-5A-A)10-2(7A6-A3-)4AB3A4-A4-4AB2A-4A6-2(2A-B2A11-)2A-2(B2A14-)3A15-A169-A15-5(3A14-)4(3A11-2A-)3A10-2(5A12-)6A11-7A4(11-2A-3A)2(14-3A)15-A186-A15-2(3A14-)4(B2A14-)2(B2A11-2A-)3A11-2A-3A11-3(2A15-)2A2-A12-2(2A-3A11-)2A-3(3A14-)3A15-A202-3A7(14-B2A)2(14-3A)11-3(2A15-)2A2-A16-A15-3(3A14-)3A15-A219-3A5(14-B2A)14-C2A14-B2A2(14-3A)83-A15-3(3A14-)3A235-3A7(14-B2A)2(14-3A)83-A15-2(3A14-)3A15-A237-A15-3A6(14-B2A)2(14-3A)15-2A66-A15-2(3A14-)3A253-A16-A15-7(3A14-)3A15-2A66-A15-3A14-3A15-A288-A15-6(3A14-)3A15-2A82-3A14-3A321-2(A16-)A15-3(3A14-)3A15-2A82-3A15-A356-A16-A15-2(3A14-)3A15-2A83-A390-2(A16-)A15-3A15-2A508-A15-3A15-2A525-A16-2A296-
