model
size = 24 29 25, scale = 0.05, origin = -y
material deform = 1, fade = true, lighting = smooth, roughness = 0.3, metalness = 0.6
  colors = A:#6B4897 B:#080A09 C:#000 D:#140E12 E:#FEEDE9 F:#FCE6E5 G:#7454A2 H:#F9E1E1 I:#8D6CB9 J:#161A18 K:#FFF L:#B775E1 M:#7F5FAC N:#B05F5F O:#281515 P:#363636 Q:#9D79C8 R:#494358 S:#FFED8D T:#302C2C U:#F2D9D9 V:#E4D9DD W:#90797F X:#ECA2A2 Y:#BD6E6E Z:#8E3939 Aa:#463752 Ab:#351818 Ac:#8C7373 Ad:#FBF6F6 Ae:#F1E9E9 Af:#251E1E Ag:#DA4E64 Ah:#E15A69 Ai:#CB4057 Aj:#7F0020 Ak:#600 Al:#F0D1C6 Am:#472D2D An:#EABDBA Ao:#B6A6A6 Ap:#300
voxels
301-A23-A143-A526-2A22-GA22-G2A92-3A22-2A457-A23-2A23-I42-4A19-3AI2A18-6A18-2A2-2A43-2AG20-G3A429-A3-A18-2A3-AG16-2A2-JDAGA14-2A2-DJD-IA14-AM2BD2B2-2A13-A-5B-C2A13-A-2A3CA2-A14-3ACB2AG16-2AI2BI3A15-3A2BAGA16-5A-GA17-AG2A20-AG2A405-A-B19-AGA3DG2A15-2AJD2JB2A14-2A2(DJ)2DC2A12-2AD8BA12-2A7B2C2A11-GI2C3BCB2CIA11-A5CB5CM11-AI2A2C2BCAICA12-2ABC3B3AC13-2AGC3BG2A14-2AG3A-AGA-A13-3AGA5-A14-3A357-4B19-D7BD14-2(BD)3BD2B14-B2D3CB2DBD13-2AD2BJ2(DB)D12-A2BCBD5BDA11-A2BC5B2CBA10-A3C3B2CB3CA10-2A5CB6C10-AI5C2B2CBCG11-GCGBC3BAC2BG12-A7BC2BA12-2A2C2B2CG3A12-5AGBAG3A13-4AG20-2A288-3C18-2B3(CB)16-2(D3B)15-5BDBD2B14-6BD4B13-2B2C3D2CBD11-2B2(CB)6C2J10-B2C3BC3B2CJD10-I2C3(2BC)DB10-A3C4BCB-3C10-A3C8-2CA9-AB2C7-BCBA9-2AC2B6-BCBA9-GI2BA5-2ABA11-G2A2B3-C2A2B12-A2BCAB2CB3A13-4A2C2B2A14-4A167-2(2C22-)2C21-5C18-6C17-8C16-2B5C2B14-10B13-C3BJ2BD3BA12-2B2CB2C2B2CDA10-2B3CB2CB3CDA10-BDB7C4BA9-D3B2C2B3CB2DG9-D2CB2C2B2CBC2BA9-2DCB2C2(2BC)D2B8-BDJ10-JBI8-DADB9-DCI9-JDB9-DCA9-BGC9-2BA9-BGBA6-A3B11-G2A-CA-2C2AB13-AGAB2A3BGA14-4AC2B2GA15-3A27-A23-2A41-A70-C-3C20-5C18-2CB3C18-BC3B2C16-C6BC15-2CB2(D2B)C14-C2BJ2B2DB2C12-3CBD2BDCB3C10-2(2CBC2B)CB10-6C2-6CA8-4B3C2-3C3BA9-D2B2C4-2CB-2BA7-BJ2BC6-2C2BGA7-BD-C8-C-2BA7-3B11-BCA7-3B11-2B8-2BD11-2B-A6-BID10-BCB2A7-DBA8-2BD-2A7-BCB7-AB2A11-CBA-B2ACBG2A13-2BABA4B2A14-4ACBG-A21-2A22-2A41-2A22-2A46-C3-2C17-2C4-C17-8C16-2(2BC)2B16-CD3BJDCB13-2CB2D2BJDJC13-3C5BCBJ2C10-BCJ2CB2-2BCJ2C8-A2BCBC6-CB3C7-AD3CB6-C2BCB7-GD2BC8-2(CB)7-ADB2C8-2CBGA6-A2D2B8-3BAG6-ABDCB8-3B2A2(6-A2B12-CBA)6-AI2C11-2C8-CBC10-2BC2A7-BC10-CBCA2-2AG3-CBC8-CAB2A9-CAC6-2B2C11-C2BACABCAC2A14-4ABAB2AG15-2A2-2AG21-G2A41-2A22-2A69-2(C6-C16-)2B4-3B14-BDB4-BDB13-C3B4-3B12-2CBD6-JB-C9-A3B8-2BC8-AB3CH6-HB2CB7-A2BCB8-2C2B7-A2BCB8-BCBD6-GA-D-B8-C-BDA5-2AD2BC8-C2BJA5-AB2JB10-2BAG5-ABDB12-CDA6-3B12-CBA6-ABC12-CBA6-2A2C10-2CA4-3A-A2C10-BC2A2-2AG3A3C9-CB2A3-5A3C6-B-CBAGA8-ACBC2A-5BCA12-2BACA2B2AG16-2AB3A21-AGA17-A23-GAG2-A19-AG2-A66-2(C6-C16-)C6-2C13-2CB6-2BC12-C2B6-DB2C10-2C2BH4-H3BC9-2(BC)2H4-2HCBC9-BHB2H6-2H3B8-2HCH7-2HCFB7-B2FCH8-HC2F6-ABF2BC8-2CBFB5-A3B2C8-2CDBD5-A2B2C11-2BA5-AB-D12-2BG5-GB-C12-B2A6-A-C12-C2A-A4-AC-B11-CB3A2-2A-ACB10-BC2A3-G5A2B9-CBA6-4A2B8-CB2A8-3A3C3-3BC2A10-2AIBACABAC3A14-B4AI2A20-AGA17-A23-3A-2A18-3A-2A90-C6-C16-C6-2C14-2B6-CB2C11-CB-H4-H-D2C10-2CJ2H4-2HJFC10-CF2H6-2HFC9-2BF2H7-2HFC8-BDBH8-3HB7-2BHF10-HFB7-3BH10-HBD7-4B11-2B7-3B12-JB6-AB-2B11-DB6-AB-B12-2BA5-GC-C12-BC3A4-G-CB11-2C-2A4-2G-B10-CBAGA4-AIBGB10-2B-A6-4A9-2BI9-2A3BC-A2B2CB2G10-4ACBA3BC2A13-2AB2AIAGA15-2A2-3A17-3A22-6A19-2A-2A90-2(C6-C16-)BH8-C11-CEFH4-HFE2C11-B2F6-2FBC10-2B2H6-2H2BC9-B3H7-2HBC8-BJE10-F2B8-BJF10-FJB7-2BDFD8-DFDB7-3BD10-DBD7-BCHD10-DHC7-2BHD10-BHB7-C-C12-2B7-C-C12-2C-G5-C-CB11-BC2G5-2B-C10-2B2A7-B12-BC2A7-A2B8-3B2A8-2(2AB)4-2B3A10-2AG2BCA3BAG14-9A15-3A-2A19-6A18-AGI3A22-2A136-C-F2H2-2HF-C11-JC2FH4-HFEC11-BCFE7-FCB9-2BFH9-FB9-3B10-FBC8-C2B2-DT2-TD2-3B9-2BOAbOD2-DOAbO3B8-BFBO2D4-2DODF2D-A5-BF3D6-3DF2B6-2BFC10-CF2B6-BCHC10-CHDBA5-C-C12-H2B6-C-C12-CB7-3C12-CBA6-DB-B10-CB2A6-DJB11-CBA8-2J2B7-B2CAG9-D3BA3-3B3A11-5BA2B4A14-3A2G3A16-4AI19-AG3A20-4A90-2(C22-D)C2-5H2-C11-D2C2F4H2F-C11-DCE2F4-2FEC10-BDCE8-E2C9-B2C10-C2B8-3B3C4-3C3B8-BAC2KCT2-TC2KCMD7-BCGC2K2D2-2D2KCGDJ-A4-BCF2C2D4-2DKCF2D-A5-CF2CD6-DC-FMD-A5-GFC10-CFGBA6-CFC10-CF2BA2-5CB12-3BA3-2B-CB12-2BA5-2BC2B11-CBA5-BD3B10-BCA7-2DB11-2CA8-D2BC7-2CIA10-J3BAB2-2AC3A11-D2BAB7A13-B5AG2A16-5A20-4A114-C22-2C8-B13-2C-F4HF2-C11-2B2EF4HF2ECB10-2B2E6-2ECB10-BA-2C4-2C-AB9-CBE-CAj4-ZAk-E2B8-2CU2R2C2-2CAaRUAB8-CA-2KR4-Aa2K-A2D6-CBAC2KR4-R2KCA-D6-2BGCRKC4-CKRCFAD2A4-C2B-3C4-4C2(BA)5-CAB12-2(BA)-3C-2BFB11-F2BA-3CBCBF12-2BA3-C5B12-2CA5-2BC2B11-2CA5-3BCB11-CA7-DB3C8-3BA8-D2BC-B4-2C2BA10-2DB2AB3-5A11-D2AI8A14-3AB2AGA168-B14-C8-2B12-2C-EF2HFE2-B12-B-3E2H4EB11-2B2ESN2YNS2EBD10-BDE3C2-3C-ED9-CBP2CAgAh2-ZAi2CTB9-2CE4C2-5C2(2D8-7C-6C)2DJ5-2C-6C2-5CJDA5-2C-B4C4-4CFD2A5-2(C-)2C6-2CDFB2A-2C2-BCF11-BFBA2-2C3BCF11-BFBA4-BDBCF11-BHB2A4-ADBH11-BHB2A5-G2BH10-2BAG7-ABAC8-CB3A7-2ABA2B4-B2C3A9-4AB-2A-B4A11-12A17-B2A189-2F18-C-2EF3E2-B12-C-8E-B12-C2ESN2XNS2EDB10-BC2ES4NS2EDB10-2B4C2-4CAfB9-2CAmAn2LC-2C2KCAo2B8-2CD3LC-2C3KD2B2A3-2C-2CD3LC-2C3KV2BM5-B3CF3LC2-C3KF2BA5-B2C2F4C2-4CBFBA6-BC2F2C6-C-BF2A6-BCFC10-BFA7-2B2F10-BF2A5-A2B2F10-BF3A4-2A2B2H8-2HBAGA5-2AB3H6-2HC3A7-2A4B5-BC3A8-G2ABAB4-2B3AG9-14A13-3A2B4A233-4E2-J15-8EBD11-AC4EAdAe3E-B11-AC4E2N4E2B10-AC5E-4E2B10-ACQU6EUAl3B8-A2CQ2L4E2K2-2B5-CB-A2CDLO4EOK2D2BA5-2BAGCDOEC2E2VOD3BA5-2B2AC2F2C2-2C2F2BAG6-B2ACF2EW2-W2EFC2B7-B2ABF2E4-2EFPBA8-2A4F4-4FBA8-AB5F2-4F3A9-2B4H2F2H2FCBA9-AB9HBCA10-2AGB6HCB2A11-3AG8A14-5AC3A16-2A2B-A241-J18-2E3-D16-6E2-2(D11-A2-8E-)J11-G-Q-6E2-D11-ICQ3-2E4-DA9-2ACQ-DP2ETD2-BG9-2ACI2DC2ECJ2DBCA8-GBCICApC2ECAcCD2CA8-G2BI2EAc2EW3ECAG8-G2BQP2EF3E2PCAG8-3AC8F2A2G9-ABG8FAC2A9-4A5FHA2C2A9-2AGB6H4A11-AGCG2AG5A13-7AC2A15-3A3B22-B286-3(2E22-)2E4-D23-DA10-A-I9-IA10-A-I2-I5-I3A9-AGQAIC2E2-2AI2A9-AGQGIP2EP2-A3B9-A2GA-F2EFP3AB10-A2GI-2A2F-4A10-AMGI3AF-5A11-GI4A-G5A12-5A2G4A13-G4AGBC-A15-4A3B21-2B357-FE23-2A21-AGA20-IM2A2-IA15-GI5AMA14-AM-2A-I3AGA11-2AIA-6AMB11-8AGC2B12-IG5AGB2D13-I6A3B15-5ACGC15-5ABA2C16-4AC2B19-2A2B406-2A21-3A20-4A19-I4A-IA15-M4AGI3A15-4AI3AG14-4AI3AGA14-2A2(IA)BAB15-GM3ABC2B15-M3AGACB16-5A2C19-3A478-2A2(21-3A)IA18-AGAI3A17-2AI4A17-G5AG17-5AG18-4AG249-
