model
size = 26 11 28, scale = 0.05, origin = -y
material deform = 1, fade = true, lighting = smooth, roughness = 0.3, metalness = 0.6
  colors = A:#D9ADE4 B:#010101 C:#060606 D:#090909 E:#1A1A1A F:#141414 G:#111 H:#0F0F0F I:#0C0C0C J:#040404 K:#000 L:#1C1C1C M:#222 N:#171717 O:#131314
voxels
168-2C220-B24-2B24-B234-B24-3B22-3B24-B208-B24-2B24-3B22-3B24-B234-B24-3B22-3B24-B208-B24-3B22-3B24-B234-B24-3B22-2B234-B24-3B22-3B24-B208-B24-3B22-2B234-2B22-3B24-B234-I24-IC24-C234-2(C24-CB24-B208-B24-B)H24-HC24-C208-C24-CB24-2B24-B208-4(B24-2B24-B234-)B24-2B3(24-B208-B2(24-2B))24-B208-2(B24-2B24-B234-)B24-BC24-C109-4C8-4C9-DH2AID6-DI2AHD7-E6AG4-G6AE5-K7AE4-E7AK2-GDF8AF2-F8AFD2GJE8AE2-E8AEJG2DE8AN2-N8AE2D2-E7AO4-O7AE5-D5ADF4-FD5AD7-2B3CJ6-J3C2B2(10-2C)11-3C10-3C9-D3CHD6-DH3CD7-E5AJG4-GJ4ADE5-2F6AE4-E6A2F3-HE8AF2CF8AEH-ILM8AD2CD8AMLIGDF7A2D2B2D7AFDG3-E6AE4-E6AE6-IH4AGK4-KG4AHI7-B4CI6-I4CB2(10-2C)6-
