model
size = 15 18 13, scale = 0.05, origin = -y
material deform = 1, fade = true, lighting = smooth, roughness = 0.3, metalness = 0.6
  colors = A:#1F1F1F B:#262626 C:#323232 D:#414141 E:#5A5B5A F:#555655 G:#0F0F0F H:#3A3C3A I:#161616 J:#4A4A48 K:#515150 L:#2C2F2C M:#070707 N:#000 O:#464643
voxels
85-H2(13-C)12-2C12-CHFC10-2CFC11-CKC11-CHF125-BH12-2BJ11-BLOE10-2B2H10-3CDA9-A2CDN9-3AHK9-4AB9-2ACACH8-2ACFCG8-2ACFDL9-A2CFJG9-2CF2C11-2CE81-2B12-2BM11-BLIL10-2BLH10-2C2BM9-AJAEG9-4AM9-5AH7-6AF7-4A-AI8-A2B-JNG8-2A2B2G9-ACFCG10-AICG13-FC52-3D11-3DJ10-B2DE10-3BL11-BJ2E10-2BJE9-A2BHE10-AOAFJ8-C4AK7-6AHF6-3AC2-HG7-A2B2-HG7-2AK3BKG8-A3BFG9-A2IKL12-IC14-C37-3D11-2DGE10-B2LG10-3BL10-BLBEG9-3BJE10-2AHN10-ADABI8-J4AE8-CB3ACG6-2AFA3-B7-2AC3-2G6-2AK4-G8-A2IK-G9-A2IK2G11-2IG13-C23-2D12-3D12-2DE11-BLD11-2BFJ10-3AK10-2A2DJ8-3ADFK9-3ADE8-J4AB9-B3ACE6-AHBA3-E7-2AL3-KM7-2A4-G8-A2IK-2G8-A2IKGM11-2IM13-E23-2D12-2DE11-DLFM10-3BL10-A2BLE9-2ABAI10-4AN8-4AOM9-4AN8-F5A8-CBK2ABA6-2AFA3-G7-2AI3-EM7-AK3BKG8-AILKGDM8-A2IK2M11-ICM13-C24-D12-B2D11-2BDE10-2BHE10-2BDFJ9-3BJF9-3BJD9-A2BJFE7-A-3A2D8-4ABK7-6AOE6-4A3-E7-A2B3-NJ7-5BMN8-A3BGM9-2IBEM11-2IC14-C37-2BH11-2BGF10-B2LG10-3BE10-3BMB9-4BK9-2ABJD9-2A-A2J7-6AE7-6ACN6-3A2-2EN7-A3-EHE8-2A-CFEB8-AKCEBE9-CFC2E12-2C52-B2H11-2BH11-BLHF10-2B2D10-2BDFM9-3BJF9-A2B2J9-4AJ8-5ADJ7-3ACAHIK7-A-3CKE7-3A2CED8-2ANEDF10-FAFE11-FH122-B13-3B11-D2B11-C3BCA9-3B-CF9-3BCF9-2ACFC10-ACK12-CDC13-G137-2H12-HFB11-BDBH11-CDH11-FCB12-2CH12-CBD12-DF166-FH12-KNL11-DIG12-KJC11-FNE12-HNF12-2C100-
