model
size = 22 24 12, scale = 0.05, origin = -y
material deform = 1, fade = true, lighting = smooth, roughness = 0.3, metalness = 0.6
  colors = A:#2C2F2C B:#565957 C:#3F3F3F D:#262626 E:#515551 F:#1F1F1F G:#070707 H:#4E4E4C I:#0F0F0F J:#464643 K:#4A4C46 L:#3A3C3A M:#323232 N:#161616 O:#000
voxels
314-C2A18-C4A16-C2(5A17-)4A19-2A479-AJ19-ABLB17-A4BA15-EBD2EA16-BEDEBA17-JF2L19-NA352-AB19-3AB18-E2AJK16-2BL3A15-5BE15-2BD2ED16-2ADE2D16-3A2H19-AB246-2C2D17-2C3D16-2C4DC14-2C4DCJ13-2C4DCB14-AHA3DJC13-2ABEAD2C14-B-ABACJ14-B3-3B14-2B3-BH14-L2A2-D16-4AHD17-3AE19-2A57-2F19-3E18-C4E16-2CDI2E15-2C3DJ15-2C3DCB14-2C2(3DCB13-3C)3D2J12-4C4DJC2(11-4C4D2C)12-3C5DCJ11-3C5D2C11-3CA4D2CB11-3CF3DJCB12-CB3FDACB13-B2-2FBC2B12-4A-BCJB13-4AB2CB15-2A2BCH17-AL55-2(ED)18-EF3D16-3E2FD15-CHD2EMF14-2C3D3E13-2C4DBC13-2C4DLJB12-2CK3DH2(CB11-B3C4D)CB11-BJ2C4DCB10-3BC4-DC2B9-3BC6-2B10-2BC6-3B9-2EC7-2B10-2C2A5-2B10-2CFAF4-3B10-CFA3FA2-2B11-CF2A2FA-2BD11-C5AF2BD13-4AF2BE15-2A2CBE18-2C53-3ED17-3E3D15-2CEDFDE15-2C2IDFE14-2C2-2I2EF11-B2C4-I2E11-BEC5-2BE10-2BC5-BE11-E2B6-B10-2H2B6-BK9-2HE7-BK9-E2H8-K9-2H9-JK9-H9-2K9-B10-K10-B-A7-2D9-K-2A7-D10-C2F3A4-2G10-CF-F3A2-GO11-F2-A2F2-DG17-F-KD17-FB2K18-CBK51-EL2E18-EF2E17-BIE2F-E14-2B3I2FE13-2B3-2IEFE11-2B5-2IE11-2B7-BE10-2B7-K10-2(3B7-2K9-)3B8-2(K9-2B9-)2K8-2B10-K9-B10-MK8-CB10-D9-CF9-G10-J3F6-2G10-C4F5-G11-L2-3F3-2G16-F-K2D16-FKC2K17-JKG19-C31-EK2E18-EF2E17-BIEF2-E14-2B3I2FE13-2B3-2IE2F11-2B5-2IE11-2B7-BE10-2B7-D11-2B7-MJ9-3BH6-MJ9-2B2M7-2(J9-2B9-)MK8-JH8-2HJ9-C9-HDC8-2C10-I9-C10-O10-C2F7-NG10-C3F6-G11-C2-3F2-3G15-2FO2DG16-F2G2D17-BOG51-4E18-3E3A15-BCE2FAE15-BC2I2FE14-BJA3IEME12-2BC3-ICJ11-C2BA3-BCEG10-C2BCA2-HBN11-2CBCA2-EHG10-CH3C3-ABID9-4C4-AEGN9-3C-C4-2HO9-3C6-AHGD9-CD7-2CD9-C2D7-CG10-B9-2G9-J9-2G10-H2F5-DCIG10-C3F4-DCG11-H2-3F2-2G16-2FING17-MGIG18-BEG52-E2A18-2EF3A16-3EF2A15-CHI2EFA14-BC2A2I2E13-BC4AC2E12-JC5ACE12-L2C4AJC11-BE2C4AKH11-2JBC4AEH11-CBEC4AEH11-CEBC4A2EB9-2CBLC5ABO10-CB-C5ALJ10-J2B5-2BKB10-B3A3-AHBN11-BCA4-JBGN10-2BFA3-AE2G11-HB2F-AH-2BG11-2C-2FAHGNI16-F2B2G17-BHGI18-C76-2EF18-3E2F18-2EGEF16-2A4E15-4AIE16-2(4A17-)4A16-5A15-JC4A14-2BC5A12-2BJC5A13-JBH5AB12-ABH5AB13-BH5AJB12-BJ5AC2B12-C6A2B13-C5A2BE15-F2A3B17-2CBG79-
