model
size = 32 8 32, scale = 0.05, origin = -y
material deform = 1, fade = true, lighting = smooth, roughness = 0.3, metalness = 0.6
  colors = A:#080 B:#FFF C:#FFA500 D:#070 E:#960
voxels
32-2(E31-)E159-6(2(E31-)E191-)2(E31-)E117-5C30-5C34-2(E31-)E81-3B30-3B5C30-5C32-C-2(E31-)E47-2B30-5B30-3B5C30-5C32-2C2(E31-)E45-4B28-7B30-3B5C30-5C32-2CE31-E8-3A20-E8-4A14(31-A5B27-8B30-3B5C30-5C32-2C2D6A24-D11A20-D6-6A)31-A5B27-8B30-3B5C30-2C2-C32-2C2D6A24-D11A20-D6-6A31-A5B27-8B30-3B3C70-C2D6A24-D11A20-D6-6A31-A5B27-8B30-3B74-2D6A24-D11A20-D6-6A31-A5B27-6B109-2D6A24-D11A20-D6-6A31-A2B30-2B113-2D6A24-D11A20-D6-5A180-2D6A24-D9A22-D6-3A182-
