model
size = 28 26 3, scale = 0.05, origin = -y
material deform = 1, fade = true, lighting = smooth, roughness = 0.3, metalness = 0.6
  colors = A:#122829 B:#06373A
voxels
5-A24-AB2A5-B2A2-2B4-A2-2A2-AB5-2A2-2(A3-)3A3-4A5-AB2A-A3-A2-2A-A3-B3A5-A2-A-A3-A-2A2(2-A)B2-3A3-B3A-A2-4A3-A2-A4-2B2A2-2B5-AB5-2A-B2A5-A6-A10-A3-A42-A2-3A15-2A5-A3-A16-2A2-A-2A3-A17-A2-A-A4-A17-A2-A-A3-3A16-A-4A2-2A-2A15-3A-BA-2A3-A13-4A2-BA-A4-2A90-A2-A-A2-3A4-3A10-A2-A-A3-A4-AB-BA9-2A2(-A)3-A4-A3-3A3B10A2-3A2(3-A)4-3A2B3A2-A-2A-A3-2A-2A4-A2(-B)A5-2(2A2-)B3A5-B-B7-A24-AB2A5-B2A2-2B4-A2-2A2-AB5-2A2-2(A3-)3A3-4A5-AB2A-A3-A2-2A-A3-B3A5-A2-A-A3-A-2A2(2-A)B2-3A3-B3A-A2-4A3-A2-A4-2B2A2-2B5-AB5-2A-B2A5-A6-A10-A3-A42-A2-3A15-2A5-A3-A16-2A2-A-2A3-A17-A2-A-A4-A17-A2-A-A3-3A16-A-4A2-2A-2A15-3A-BA-2A3-A13-4A2-BA-A4-2A90-A2-A-A2-3A4-3A10-A2-A-A3-A4-AB-BA9-2A2(-A)3-A4-A3-3A3B10A2-3A2(3-A)4-3A2B3A2-A-2A-A3-2A-2A4-A2(-B)A5-2(2A2-)B3A5-B-B7-A24-AB2A5-B2A2-2B4-A2-2A2-AB5-2A2-2(A3-)3A3-4A5-AB2A-A3-A2-2A-A3-B3A5-A2-A-A3-A-2A2(2-A)B2-3A3-B3A-A2-4A3-A2-A4-2B2A2-2B5-AB5-2A-B2A5-A6-A10-A3-A42-A2-3A15-2A5-A3-A16-2A2-A-2A3-A17-A2-A-A4-A17-A2-A-A3-3A16-A-4A2-2A-2A15-3A-BA-2A3-A13-4A2-BA-A4-2A90-A2-A-A2-3A4-3A10-A2-A-A3-A4-AB-BA9-2A2(-A)3-A4-A3-3A3B10A2-3A2(3-A)4-3A2B3A2-A-2A-A3-2A-2A4-A2(-B)A5-2(2A2-)B3A5-B-B2-
