model
size = 32 22 3, scale = 0.05, origin = -y
material deform = 1, fade = true, lighting = smooth, roughness = 0.3, metalness = 0.6
  colors = A:#0A262F B:#0A2326 C:#122829
voxels
11-2A30-A-2A28-2A-2A16-A11-2A-2A15-2B2A2C7-2A-A15-A4B2A7-4A15-B3-2BA2-2A4-2A15-BA6-2BA-A2-2A16-B3-CA-AB-BA-3A-CBA12-CA2-A-C-A-2B2(-A)-B3-AC10-A-ABA2-3AB2(-A)-B2(A2-)A8-B2-C2B3-AB-CBA-B2(-A)-2A-4A3-CA-A2-2(B3-)3(B-)2(BA)-B-AB4-B2-3A3-B6-2A-A2(B-)B2-B-5A7-B9-AC-B-3AB3-2AB7-A8-BC2-B2-A2B4-3A6-AB11-AC3-B6-A7-2A14-CB2(30-A)B27-3AB27-AC16-2A30-A-2A28-2A-2A16-A11-2A-2A15-2B2A2C7-2A-A15-A4B2A7-4A15-B3-2BA2-2A4-2A15-BA6-2BA-A2-2A16-B3-CA-AB-BA-3A-CBA12-CA2-A-C-A-2B2(-A)-B3-AC10-A-ABA2-3AB2(-A)-B2(A2-)A8-B2-C2B3-AB-CBA-B2(-A)-2A-4A3-CA-A2-2(B3-)3(B-)2(BA)-B-AB4-B2-3A3-B6-2A-A2(B-)B2-B-5A7-B9-AC-B-3AB3-2AB7-A8-BC2-B2-A2B4-3A6-AB11-AC3-B6-A7-2A14-CB2(30-A)B27-3AB27-AC16-2A30-A-2A28-2A-2A16-A11-2A-2A15-2B2A2C7-2A-A15-A4B2A7-4A15-B3-2BA2-2A4-2A15-BA6-2BA-A2-2A16-B3-CA-AB-BA-3A-CBA12-CA2-A-C-A-2B2(-A)-B3-AC10-A-ABA2-3AB2(-A)-B2(A2-)A8-B2-C2B3-AB-CBA-B2(-A)-2A-4A3-CA-A2-2(B3-)3(B-)2(BA)-B-AB4-B2-3A3-B6-2A-A2(B-)B2-B-5A7-B9-AC-B-3AB3-2AB7-A8-BC2-B2-A2B4-3A6-AB11-AC3-B6-A7-2A14-CB2(30-A)B27-3AB27-AC5-
