model
size = 16 32 12, scale = 0.05, origin = -y
material deform = 1, fade = true, lighting = smooth, roughness = 0.3, metalness = 0.6
  colors = A:#630 B:#100 C:#960 D:#888
voxels
2-2D5BA5B8-6C2(10-6A)10-4(7A9-)6A10-2(6A2(9-7A)9-)2(7A9-)7A2(8-8A)2(5-A2-8A)5-2(A2-9A4-)2A-9A5(4-2A2-8A)4-13A3-2D5BA5B324-6A9-10A6-3(11A5-)5(12A4-)4BA2-6B3-4BA2-6B308-7A8-11A5-6(12A4-)3(13A3-)13B3-13B9-6C3(10-6A)11-4A12-4A10-6A9-7A10-6A3(11-5A)3(10-6A)8-8A2(7-9A)7-10A5-11A4-11A5-5(12A4-)4(13A3-)12BA3-12BA8-C6-C8-A2(6-A7-2A)6-A2(7-3A4-2A)7-3A4-A8-3A2(4-A7-4A)4BA7-9A7-10A5(5-11A)10(3-13A)3-3(14A2-)14B2-14B6-C8-C2(6-A8-A)5-2A8-A5-2A14-3(2A7-A6-)2A7-A5-3A7BA5-11A5-12A4-12AC3-12A2(C2-13A)C-14AC-13B3(AC14-)2(10(A15-)B15-B6-C8-C2(6-A8-A)6(5-2A8-A)4-3A8BA2(4-12A)C2(3-13A)2(2-14A)-15A14B2(2A14-)AC14-)10(A15-)B15-B6-C8-C2(6-A8-A)6(5-2A8-A)4-3A8BA2(4-12A)C2(3-13A)2-14A3-13A-15A14B2(2A14-)AC14-11(A15-)A6-C8-C2(6-A8-A)6(5-2A8-A)4-3A8BA2(4-12A)C2(3-13A)2(2-14A)-15A14B2(2A14-)AC14-10(A15-)B15-B6-C8-C2(6-A8-A)4(5-2A7-2A)5-2A7-A6-2A7-A5-3A7BA5-11A5-12A4-12AC3-12A2(C2-13A)C-14AC14B3(AC14-)10(A15-)B15-B7-C6-C3(8-A6-A)3(7-2A6-A)2(6-3A6-A)6-3A6BA6-10A6-9A5(6-10A)4-13(13A3-)2D5BA5B3-2D5BA5B2-
