model
size = 11, scale = 0.05, origin = -y
material deform = 1, fade = true, lighting = smooth, roughness = 0.3, metalness = 0.6
  colors = A:#E00 B:#F93 C:#0A0 D:#FC0
voxels
2-7A113-A7-A2-9A100-A9-A-A7-A3-7A90-2(A9-A-A7-A3-2(A5-)5A80-)A9-A-A7-A3-2(A5-)5A8-C9-2C10-2C9-C9-3B8-BDB8-3B4-2(A9-A-A7-A3-2(A5-)5A80-)A9-A-A7-A3-7A91-A7-A2-9A102-7A112-
