model
size = 27 30 10, scale = 0.05, origin = -y
material deform = 1, fade = true, lighting = smooth, roughness = 0.3, metalness = 0.6
  colors = A:#263838 B:#F11315 C:#B75C63
voxels
12-3C20-9A18-A7-A18-A7-3A2(16-5A5-A)17-2A2(26-A)27-A23-A3-A22-2A27-A34-A26-A25-2A23-4A21-6A2(19-8A)2(16-A4-6A)16-2A3-A2B3A21-A2B3A16-11A16-A5-4A17-A4-6A16-A2-8A19-A2B3A21-A2B2A19-9A18-A7-A11-8A7-10A2-A6-5A5-A6-A2-A6-5A5-A6-2A-5A3-2A15-A3-3A4-A10-2A3-A2-4A4-A10-2A3-A-7A3-A8-3A3-A-8A3-A7-3A3-A-A6-2A9-4A2-2A-2(A8-)4A2-A2-6A11-4A3-A2-3A2-2A10-6A-A2-3A13-9A2-4A10-10A3-4A8-8A2-3A3-2A7-10A2(2-3A)2-2A3-10A3-2A2-A3-A2-A4-9A2-3A-A3-A-2A4-9A4-A-A3-5A3-A2B7A3-A-A11-A2B11A-4A3-11A-5A4-3A3-A5-4A2-5A4-3A3-A4-12A2-9A2-14A2-5A6-A2B3A2-4A4-4A7-A2B2A3-4A15-3C21-9A18-A7-A11-8A7-10A2-A6-5A5-A6-A2-A6-5A5-A6-2A-5A3-2A15-A3-3A4-A10-2A3-A2-4A4-A10-2A3-A-7A3-A8-3A3-A-8A3-A7-3A3-A-A6-2A9-4A2-2A-2(A8-)4A2-A2-6A11-4A3-A2-3A2-2A10-6A-A2-3A13-9A2-4A10-10A3-4A8-8A2-3A3-2A7-10A2(2-3A)2-2A3-10A3-2A2-A3-A2-A4-9A2-3A-A3-A-2A4-9A4-A-A3-5A3-A2B7A3-A-A11-A2B11A-4A3-11A-5A4-3A3-A5-4A2-5A4-3A3-A4-12A2-9A2-14A2-5A6-A2B3A2-4A4-4A7-A2B2A3-4A15-3C21-9A18-A7-A11-8A7-10A2-A6-5A5-A6-A2-A6-5A5-A6-2A-5A3-2A15-A3-3A4-A10-2A3-A2-4A4-A10-2A3-A-7A3-A8-3A3-A-8A3-A7-3A3-A-A6-2A9-4A2-2A-2(A8-)4A2-A2-6A11-4A3-A2-3A2-2A10-6A-A2-3A13-9A2-4A10-10A3-4A8-8A2-3A3-2A7-10A2(2-3A)2-2A3-10A3-2A2-A3-A2-A4-9A2-3A-A3-A-2A4-9A4-A-A3-5A3-A2B7A3-A-A11-A2B11A-4A3-11A-5A4-3A3-A5-4A2-5A4-3A3-A4-12A2-9A2-14A2-5A6-A2B3A2-4A4-4A7-A2B2A3-4A15-3C21-9A18-A7-A12-7A7-9A10-5A5-A16-5A5-A10-4A3-2A19-3A4-A10-2A6-4A4-A10-2A6-6A3-A8-3A6-7A3-A7-3A12-2A9-4A14-A8-4A6-5A11-4A7-2A2-2A10-6A5-2A13-8A4-3A10-10A4-3A8-8A2-2A4-2A7-10A2-2A4-2A2-2A3-10A3-A7-A2-A4-9A2-A7-A-2A4-9A10-5A3-A2B7A17-A2B9A4-3A3-11A-5A4-3A3-A5-4A2-5A4-3A3-A4-12A4-7A2-14A4-3A6-A2B3A2-4A6-2A7-A2B2A3-4A15-3C21-9A18-A7-A12-7A7-9A10-5A5-A16-5A5-A10-4A3-2A19-3A4-A10-2A6-4A4-A10-2A6-6A3-A8-3A6-7A3-A7-3A12-2A9-4A14-A8-4A6-5A11-4A7-2A2-2A10-6A5-2A13-8A4-3A10-10A4-3A8-8A2-2A4-2A7-10A2-2A4-2A2-2A3-10A3-A7-A2-A4-9A2-A7-A-2A4-9A10-5A3-A2B7A17-A2B9A4-3A3-11A-5A4-3A3-A5-4A2-5A4-3A3-A4-12A4-7A2-14A4-3A6-A2B3A2-4A6-2A7-A2B2A3-4A15-3C21-9A18-A7-A12-7A7-9A10-5A5-A16-5A5-A10-4A3-2A19-3A4-A10-2A6-4A4-A10-2A6-6A3-A8-3A6-7A3-A7-3A12-2A9-4A14-A8-4A6-5A11-4A7-2A2-2A10-6A5-2A13-8A4-3A10-10A4-3A8-8A2-2A4-2A7-10A2-2A4-2A2-2A3-10A3-A7-A2-A4-9A2-A7-A-2A4-9A10-5A3-A2B7A17-A2B9A4-3A3-11A-5A4-3A3-A5-4A2-5A4-3A3-A4-12A4-7A2-14A4-3A6-A2B3A2-4A6-2A7-A2B2A3-4A15-3C21-9A18-A7-A14-5A7-7A12-5A5-A16-5A5-A12-2A3-2A20-2(2A4-A10-2A8-)4A3-A8-3A8-5A3-A7-3A12-2A9-4A14-A8-4A8-3A11-4A11-2A10-5A21-6A8-A10-8A8-A8-8A17-10A12-2A3-10A11-A2-A4-9A10-A-2A4-9A10-5A3-A2B7A17-A2B7A8-A3-11A-3A8-A3-A5-4A2-3A8-A3-A4-10A8-5A2-12A8-A6-A2B3A2-4A15-A2B2A3-4A15-3C21-9A18-A7-A16-3A7-5A14-5A5-A16-5A5-A17-2A2(26-A)22-2A3-A8-A12-3A3-A7-A14-2A9-2A16-A8-2A12-A11-3A12-2A10-3A23-4A21-6A19-8A17-10A12-2A3-10A14-A4-8A13-2A4-8A12-4A3-A2B5A19-A2B5A14-11A-A14-A5-4A2-A14-A4-8A12-3A2-10A17-A2B3A2-2A17-A2B2A3-2A17-3C21-9A18-A7-A16-3A7-5A14-5A5-A16-5A5-A17-2A2(26-A)22-2A3-A8-A12-3A3-A7-A14-2A9-2A16-A8-2A12-A11-3A12-2A10-3A23-4A21-6A19-8A17-10A12-2A3-10A14-A4-8A13-2A4-8A12-4A3-A2B5A19-A2B5A14-11A-A14-A5-4A2-A14-A4-8A12-3A2-10A17-A2B3A2-2A17-A2B2A3-2A17-3C13-
