model
size = 29 26 31, scale = 0.05, origin = -y
material deform = 1, fade = true, lighting = smooth, roughness = 0.3, metalness = 0.6
  colors = A:#00FCE7 B:#FCD200 C:#54FC00 D:#FC0093 E:#00897E F:#2500DF G:#DF00DF H:#00FC15 I:#FF791A J:#DF5D00 K:#FC6900
voxels
709-I-I599-C121-A3-A25-3A27-H542-C28-C15-C43-I11-I19-A5-A23-IA-AI26-H541-C17-C11-C15-C28-C14-A11-A17-A9-A20-A5-A24-AHA458-G7-G102-C17-C11-C15-C14-A11-A16-A11-A17-A9-A21-2A-2A26-H459-G7-G73-C17-C11-C15-C13-2(C14-)A11-A13-I3-I9-I3-I15-4A-4A24-H460-G5-G11-I10-G5-G10-I63-C17-C6-F4-C15-C4-F3-F4-B13-B4-F5-I-F3-A9-A3-F-I7-F5-AIA3-AIA5-F17-A-A27-H460-G5-G22-G5-G12-F25-F6-C17-C6-F4-B15-B4-F3-F4-C13-C4-F5-F4-C11-C4-F7-F5-AIA3-AIA5-F17-A-A27-H461-G3-G24-G3-G43-F2-C17-C2-F3-F4-C15-C4-F3-I4-C13-C4-I5-I4-C11-C4-I7-F2(5-2A)5-F16-A3-A25-AHA489-G3-G24-G3-G12-A30-F3-C15-C3-2(F4-)B13-B4-F5-I4-C11-C4-I7-F2(5-2A)5-F16-I3-I25-A-A27-H461-G3-G24-G3-G12-A29-A4-C15-C4-A8-C13-C10-F4-C11-C4-F7-F2(5-2A)5-F16-I3-I25-A-A27-H490-G3-G24-G3-G13-A25-A3-A4-C13-C4-A10-C11-C12-I2(5-2A)5-I16-I3-I25-A-A27-H28-H461-G3-G24-G3-G43-A4-C13-C4-A5-A4-C11-C4-A8-F3-C-A5-A-C3-F17-A3-A25-A-A27-H28-H490-G3-G24-G3-G14-A29-A4-C11-C4-A7-A-F2-BC-A3-A-CB2-F-A16-A3-A18-B6-A-A6-B20-H57-H461-G3-G24-G3-G44-A4-C11-C4-A7-A4-3C5-3C4-A10-F6-A-A6-F19-A-A19-B7-H7-B49-H490-G3-G24-G3-G45-A4-3C5-3C4-A17-A-A19-F6-A-A6-F10-B9-H8-B10-B17-B13-D5-H5-D22-H490-G3-G45-A4-C-C5-C-C4-A9-A4-C2-A-A2-C4-A12-F5-A-A5-F11-B9-H18-B9-H8-B10-B8-H8-B13-D5-H5-D484-G3-G52-C2(-A)-C16-A4-C2-A-A2-C4-A11-A-F4-A-A4-F-A20-H18-B9-H8-B10-D8-H8-B14-D4-H4-D17-D11-D341-K27-3E25-KEJEK25-EJE26-3E25-G3AG23-C-3A-C17-A3-C3-H3-C3-A12-A-2F4-H4-2F-A13-A6-H6-A12-B8-H8-B10-D8-H8-B11-B7-H7-D15-D9-D18-D9-D426-2(2E3-2E22-)CG3-GC21-C7-C17-A-F9-F-A14-A13-A41-B17-B11-B15-D44-D9-D18-D9-D425-2(E7-E20-)C7-C17-A-C9-C-A15-A11-A43-B15-B42-B5-B-B5-B17-D7-D19-D9-D19-D7-D425-2(E9-E18-)C9-C17-A11-A16-A11-A15-2(B13-)B15-B13-B5-B-B5-B15-D2-2B3-2B2-D18-D7-D20-D7-D21-3D-3D367-K11-K16-K11-K17-E9-E18-E9-E46-A11-A44-B13-B14-D5-B-B5-D18-2B3-2B20-2B7-2B19-D7-D21-2F3D2F25-H341-6(E11-E16-)A11-A16-B11-B15-B13-B15-B2-2B3-2B2-B17-2B7-2B48-2DF3DF2D24-H341-2(E11-E16-)4(J11-J16-)E11-E45-B11-B16-B2-2B3-2B2-B17-DB7-BD49-DFD-DFD25-D28-H341-7(E11-E16-)B11-B16-B2-B5-B2-B18-D7-D22-D3-D23-3D-3D25-D28-H341-K11-K16-K11-K104-2(E9-E18-)2(B9-B18-)2B7-2B21-D3-D25-3D27-D28-H516-2(E9-E18-)B9-B18-B9-B20-7D24-3D27-H28-H546-2(E7-E20-)B2-3D2-B20-B-5D-B24-H28-H604-JE5-EJ21-EJ3-JE22-F5-F21-2(F-)H2(-F)21-F5-F602-2(J2-)J23-2(JE)J25-EJE26-3E535-
