model
size = 16 32 16, scale = 0.05, origin = -y
material deform = 1, fade = true, lighting = smooth, roughness = 0.3, metalness = 0.6
  colors = A:#E25C29 B:#200000 C:#743104 D:#4C1702 E:#CA7508 F:#571D02 G:#C67A08 H:#DD960A I:#AB6A07 J:#360B01 K:#CC7208 L:#411101 M:#F69300 N:#C47D08 O:#6D2904 P:#622303 Q:#461A01 R:#DD880A S:#965705 T:#F9C16D U:#F7A224 V:#B75D07 W:#A75A06 X:#7F4504 Y:#B76907 Z:#FBD091 Aa:#2B0500
voxels
20-8B8-B2D2Q3B9-D4QJ10-DQ4D11-QO2C426-2L6B8-7LD9-3L3D10-2F2PDP11-FC2P441-L8BD6-L8AD6-2F6A2D7-F6AP8-2F4A2P9-2F2C2P11-F2CP13-2C393-L11B2(4-J10AD)5-2(F8AF6-)2F6A2C7-FC4A2C9-CF2A2C11-4C375-J13B2-J12AD3-J2(10AF4-F)10AF5-D8AF6-C8AF7-C6AC8-2C4A2C10-4C359-J13B2-J12AF2-B12AD2-F12AF3-F10AF4-D10AF5-D8AF6-C8AF7-C6AC9-C4AC11-4C342-J14BDJ14AF-B12AF2-D12AF2-J12AF3-D10AF4-D10AF5-D8AC6-C8AC7-C6AC9-2C3AC90-E14-2E13-WE13-2E14-E14-V15-I15-G3(15-M)11-E3-MG9-M5-M7-EM7-3G4EM37-J15BJ14AFJ14ACJ14AF-J12AC2-D12AC3-D10AC4-D10AC5-D8AC7-D6AC9-C4AI12-3S14-3(2E13-)YE13-3(EAE12-)EAE13-2E13-EAW13-EI14-EI12-E-2E12-2EGI11-2E2-2G10-AE2-GAG8-2E4-3G5-3E6-GAGE2GEIE8-G5E22-J15BJ14AFJ14ABJ14AF-J12AC2-D12AC3-D10AC4-D10AC5-D8AC7-D6AC9-C4AX11-S3AI12-I2AE12-IAH12-2IEH11-2IEH10-EI2AH10-E3A2E2(9-E3AEH)10-E2AEH11-G2AH10-U-GAWH10-MT2(GAH10-MAH)GAG9-E2AHG2AG7-2E2AHG3AG5-2E2AM2-G3AG3-G3AEU3-H3AE2G3AUT5-2H5AHT9-H2ETZ6-D15BD14AFD14ABD14AF-D12AC2-D12AC3-D10AC4-D10AC5-D8AC7-D6AC9-D4AX11-SNAI14-2N14-I15-I14-VH12-VAN3(11-I2AH)12-GAH12-GAI13-GAH13-GK12-U-GK12-2H-H11-IH2-HK10-IH2-HAK8-IH3-2HAK4-3G2H5-H2AEIGAIH8-K3R2H22-D15BD14AFD14ABD14AF-D12AC2-D12AC3-D10AC4-D10AC5-D8AC7-D6AC9-D4AX12-2S77-N13-2I2(13-IN)14-N14-GN14-3(K15-)G15-K11-R3-2K9-I5-2K6-2R7-K3NK2RH37-D15BD14AF-2(D12AF2-)D12AF3-D10AF4-D10AC5-D8AC6-D8AC7-D6AC9-DO2A2C342-D13B2-D12AF2-D12AJ2-D12AF3-D10AF4-D10AC5-D8AC6-D8AC7-D6AC9-D4AC11-D3C343-D13B2-D12AJ3-D10AAa4-D10AJ4-D10AC5-D8AC6-D8AC7-D6AC8-2O4A2C10-4C360-12B2(4-B10AJ)5-2(D8AC6-)2D6A2C7-2O4A2C9-2O2ADC11-O3C377-10B6-B8AB6-2D6AJB7-D6AD8-2Q4ACD9-Q2O3C11-O3C13-2C391-
