model
size = 32 12 15, scale = 0.05, origin = -y
material deform = 1, fade = true, lighting = smooth, roughness = 0.3, metalness = 0.6
  colors = A:#063
voxels
346-A319-2A30-A9-A322-A19-A6-2A4-A274-A31-A11-A20-A5-A18-A5-A25-A209-2A17-2A30-3A30-2A9-2A14-A4-3A4-A18-A7-A31-A169-3A12-2(3A13-)5A10-A17-A12-A17-2A3-2A6-4A15-A10-3A29-A28-A-2A28-A-A136-2A9-2A16-A14-A2(-2A)6-5A16-A10-3A23-A5-2A29-2A30-A61-A105-2A9-2A20-A9-A17-A19-4A3-5A28-A188-A74-A9-A49-A19-A2-A3-2A26-A193-A74-A9-A81-A19-A3-A2-A232-A9-A21-A9-A105-A-A29-A-A201-2A7-2A21-A9-A342-2A5-2A23-A7-A312-A5-A25-A5-A346-5A366-
