model
size = 24 32 14, scale = 0.05, origin = -y
material deform = 1, fade = true, lighting = smooth, roughness = 0.3, metalness = 0.6
  colors = A:#536899 B:#F1C088 C:#E5AA8A D:#527EAB E:#5477AC F:#A05B63 G:#5675A7 H:#6AA1CC I:#BA6A74 J:#716898 K:#5379A8 L:#CF7680 M:#5B81B0 N:#7F6D92 O:#7F729A P:#766C96
voxels
27-2(FCB12-LCB6-)BCB2(12-BCF6-BCL)12-BCB6-BCB12-FCB5-DBCB2D8-2DF2(CBD4-DBCB2D8-2DB)2(CLD4-DLCB2D8-2DB)CBD4-DBCF2D8-2DFCBD4-DBCFHD8-DHFCBD4-HBCB2H8-2HBCBH5-2(BCB12-BCL6-)BCB12-B2(CB6-FCB12-L)2(CB6-BCL12-B)2(CF6-BCB12-B)CB5-5I10-5I4-IBCBI10-IBCBI4-I3-I10-I3-I4-5I10-5I101-2(BCF12-BCB6-)BCB12-BCB6-B2(CB12-FCB6-F)2(CL12-BCB6-B)2(CB12-BCB6-B)2(CB12-BCL6-L)CB2(12-BCB6-BCF)12-BCB6-BCB12-LCB6-LCB12-LCF6-LCB12-BCF3(6-BCB12-BCB)2(6-FCB12-BCB)6-BCB12-B2(CB6-BCB12-F)CB197-9AG10A3-E5AGA2JGA2PK6AE2-E5AGAJAGA2JK6AE2-E5A2(GAJA)K6AE2-E5AGAJAGNJAK6AE2-E5AG2(A2J)AK6AE2-7AKAJA2J9A2-7AKAN2JN2AG6A2-7AK2A2J3AG6A2-7AKGAJ4AG6A2-7AKGAJN3AG6A2-8AGA2J3AG6A2-6AMAGANJAG8A2-6AMAG2AJOG2AK5A2-6AM4A2OG2AK5A2-6AM6AG2AK5A2-6AM2A4-G2AK5A2-7A8-AK5A3-4A12-4A4-4A12-4A5-4(3A12-3A6-)4(BCB12-BCB6-)BCB12-BCB76-9(22A2-)5(E20AE2-)2(22A2-)9A4-9A3-6A8-6A5-3A12-3A6-3A12-3A102-5(3A12-3A6-)BCB12-BCB52-22A-360A-9A4-9A3-6A8-6A5-3A12-3A222-2(3A12-3A6-)2(FCB12-BCF27-4A16(16-8A)16-4A2-2A16-2A269-3A12-3A6-)BCB12-BCB27-4A16(16-8A)16-4A291-3A12-3A6-BCB12-FCB27-4A16(16-8A)16-A2GA291-3A12-3A6-BCB12-F2(CB27-4A16(16-8A)16-4A2-2A16-2A269-3A12-3A6-BCB12-B)CB28-8A6-8A-10A10(4-20A)4-19A2(6-18A)6-17A8-8A-7A8-7A3-5A11-4A5-3A12-3A222-2(3A12-3A6-)BCB12-BCB28-8A6-8A5(2-10A)2(2-9AM2-10A)3(2-9AM2-K9A)2(2-10A2-K9A)3(2-10A)3(2-9A4-9A)2(2-8A6-8A)3-6A8-6A5-4A10-4A6-G2A12-3A102-3(3A12-AGA6-)2(3A12-3A6-)BCB12-BCB53-7A6-7A3-K8A4-9A2(2-K7A3EA2E8A)2-K8A4-9A2-A6D2A4-2A2(6DA2-A6DA3EA2EA)2(6DA2-A6D2A4-2A)6DA2-A2D2H2D2A4-2A2D2H2DE2-AD4HD2A4-2AD4HDE2-A6HA6-A6H2(E2-M7A6-7A)E2(2-M6A8-7A)2-M5A10-6A3-4A12-4A4-4A12-4A5-3(G2A12-3A6-)G2A12-AGA6-BCB12-BCB6-3B12-3B6-BCB12-B2(CB6-BCF12-F)CB51-
