model
size = 22 24 29, scale = 0.05, origin = -y
material deform = 1, fade = true, lighting = smooth, roughness = 0.3, metalness = 0.6
  colors = A:#006 B:#FC0 C:#1F9EFF D:#187CC9 E:#FFC822 F:#FFCE48 G:#FFCA0C H:#FFC814 I:#3D3D3D J:#FFCD38 K:#FFCF56 L:#06F M:#FFD15E N:#FFD46F
voxels
186-2B20-2B394-2A19-B2AB18-B2AB17-2B2A2B16-6B15-3B2A3B14-A2B2A2BA15-2B2A2B16-2B2A2B17-2(B2AB18-)B2AB19-2A193-8A14-3B2A3B15-2(2B2A2B16-)B4AB15-2B4A2B2(14-8A)12-2B3A2-3A2B11-4A2-4A13-2(8A14-)AB4ABA14-AB4ABA15-B4AB17-B2AB19-2A170-A8-A12-B8AB12-2BM4AM2B11-A2B2A2-2A2BA10-DABA4-ABAD10-C3A4-3AC9-CDCA6-ACDC7-2(5A6-)2B2A8-2A2B6-4A8-4A6-2(DC)A6-A2(CD)7-DCDA6-ADCD9-DC2A4-2ACD9-DC3A4-3ACD9-DABA4-ABAD11-A2BA2-A2BA13-3B2A3B15-2B2A2B18-2B124-2A10-2A2(8-ABA)7-3B3A4-3A3B2(6-5A)6-DC3A6-3ACD6-CD2A8-2ADC6-D3A8-3AD5-5A8-5A4-B2A12-2AB4-4A10-4A4-D4A8-4AD5-C3A8-3AC6-DC2A8-2ACD6-C3A8-3AC6-DC3A6-3ACD7-D4A4-4AD10-B3A2-3AB13-B6AB15-2B2A2B17-4B100-2A12-2A5-4A10-4A4-B-MA10-AM-B4-ABA12-ABA4-C2A12-2AC4-D2A12-2AD4-CA14-AC4-2A14-2A4-BA14-AB4-2A14-2A4-CA14-A2(C4-DA14-AD4-C2A12-2A)C5-D2A10-2AD7-3A8-3A9-2BA6-A2B10-3B2A2-2A3B12-2B4A2B16-B2AB77-A16-A4-2A14-2A4-B2A12-2AB4-2A14-2A4-DA14-AD4-CA14-AC4-DA14-AD4-2A14-2A4-BA14-AB4-2A14-2A3(4-DA14-AD4-CA14-AC)5-D2A10-2AD7-2(3A8-)B3A6-3AB9-2B2A4-2A2B12-AB4ABA16-B2AB55-A16-A4-2A14-2A4-BA14-AB4-2A14-2A4-CA14-AC4-DA14-AD4-CA14-AC3-2A16-2A2-BA16-AB2-2A16-2A2-CA16-AC3-DA14-AD4-CA14-AC3-DA16-AD3-CA14-AC4-DA14-AD5-CA12-AC6-2A12-2A7-2A10-2A8-B2A8-2AB9-5A2-5A12-A2B2A2BA17-2A34-A16-A4-2A14-2A4-BA14-AB3-2A16-2A2-DA16-AD2-CA16-AC2-DA16-AD2-2A16-2A2-BA16-AB2-2A16-2A2(2-DA16-AD2-CA16-AC)3-DA14-AD4-CA14-AC4-DA14-AD5-CA12-AC7-2A10-2A8-BA10-AB9-2A8-2A11-D3A2-3AD13-A2B2A2BA17-2A12-A16-A3-3A14-3A2-BA16-AB2-2A16-2A2-CA16-AC2-DA16-AD2-CA16-AC2-2A16-2A-BA18-AB-2A16-2A2(2-CA16-AC2-DA16-AD)2-CA16-AC3-DA14-AD4-CA14-AC4-DA14-AD5-2A12-2A7-BA10-AB9-2A8-2A11-C2A4-2AC13-AB4ABA16-B2AB11-A16-A3-2A16-2A2-BA16-AB2-2A16-2A2-DA16-AD-CA18-ACDA18-AD2A18-2ABA18-AB2A18-2ADA18-ADCA18-AC-DA16-AD2-CA16-AC2-DA16-AD2-CA16-AC3-DA14-AD4-CA14-AC4-2A14-2A5-BA12-AB7-2A10-2A9-CA8-AC11-D8AD13-A2B2A2BA9-A16-A3-2A16-2A2-BA16-AB-2A18-2ACA18-ACDA18-ADCA18-AC2A18-2ABA18-AB2A18-2A2(CA18-ACDA18-AD)-CA16-AC2-DA16-AD3-CA14-AC4-DA14-AD4-2A14-2A5-BA12-AB7-2A10-2A9-DA8-AD11-C8AC13-A2B2A2BA9-A16-A3-2A16-2A2-BA16-AB-2A18-2ADA18-ADCA18-ACDA18-AD2A18-4A18-3A20-3A2(18-4A)18-2ACA18-ACDA18-ADCA18-AC-DA16-AD3-CA14-AC4-2A14-2A4-BA14-AB5-2A12-2A7-D2A8-2AD9-CD8ADC12-A2B2A2BA9-A16-A3-2A16-2A2-BA16-AB-2A18-2ACA18-ACDA18-ADCA18-AC2A18-2AN3(20-2N)20-NM20-M2A18-2ACA18-ACDA18-AD-CA16-AC2-DA16-AD3-2A14-2A4-BA14-AB4-3A12-3A6-C2A8-2AC9-DC8ACD12-A2B2A2BA9-A16-A3-2A16-2A2-BA16-AB-2A18-2ADA18-ADCA18-AC2A18-2AN2(20-2N)20-NM2(20-2M)20-M2A18-2ADA18-ADCA18-AC-DA16-AD2-CA16-AC3-2A14-2A4-BA14-AB5-2A12-2A7-D2A8-2AD9-CD8ADC12-A2B2A2BA9-A16-A3-2A16-2A2-BA16-AB-2A18-2ACA18-AC2A18-2AM5(20-2M)20-MK20-2K20-K2A18-2A-DA16-AD2-CA16-AC3-DA14-AD4-2A14-2A4-BA14-AB5-2A12-2A7-C2A8-2AC9-DC8ACD12-A2B2A2BA9-A16-A3-2A16-2A2-BA16-AB-2A18-2ADA18-AD2A18-2AK20-2K20-KM2(20-2M)20-MK20-K-2(K18-K2-)2A16-2A2-CA16-AC3-DA14-AD4-CA14-AC4-2A14-2A5-BA12-AB7-2A10-2A9-C10AC11-DA2B2A2BAD16-2A12-A16-A3-2A16-2A2-BA16-AB-3A16-3ACIA16-AIC3A16-3AK3(20-2K)20-K-3(K18-K2-)2(F18-F2-)2A16-2A3-CA14-AC4-DA14-AD4-2A14-2A5-BA12-AB7-2A10-2A9-D10AD11-CA2B2A2BAC30-A16-A3-2A16-2A2-BA16-AB-3A16-3ADIA16-AIDAIA16-AIAK2(F18-F2K)F18-FK-3(F18-F2-)F18-F3-3(F16-F4-)2A14-2A4-CA14-AC5-3A10-3A7-BA10-AB9-12A11-DAB4ABAD15-B2AB33-A16-A3-2A16-2A2-2BA14-A2B2-3A14-3A2-CIA14-AIC2-3A14-3A5(2-F18-F)3-5(F16-F4-)2A14-2A5-DA12-AD7-2A10-2A8-BA10-AB9-12A11-CA2B2A2BAC52-A16-A3-2A16-2A2-2BA14-A2B2-3A14-3A2-DIA14-AID2-3A14-3A4(2-2F16-2F)3-3(F16-F4-)F16-F5-2(F14-F6-)2A12-2A7-CA10-AC8-2A10-2A8-B2A8-2AB9-12A12-A2B2A2BA53-A16-A4-2A14-2A4-B3A10-3AB4-4A10-4A4-C2A12-2AC4-3A12-3A6(4-J16-J)5-2(J14-J6-)2J12-2J7-J12-J8-2A10-2A8-D2A8-2AD9-4A4-4A10-2B8A2B12-A2B2A2BA75-2A14-2A4-4A10-4A4-4B2A6-2A4B4-5A8-5A4-D2I2A8-2A2ID4-5A8-5A4(4-J2E12-2EJ)5-2(JE12-EJ6-)JE12-EJ7-2E10-2E9-4(E10-)3A6-3A10-CD8ADC11-2AB4AB2A13-3B2A3B98-3A10-3A6-A2L10A2LA6-B2L2B6A2B2LB6-7A2-7A6-C3I3A2-3A3IC6-7A2-7A3(6-JBEH8-HEBJ)6-J2EH8-H2EJ7-2EH8-H2E9-EH8-HE10-2E8-2E11-EH6-HE2(12-2E6-2E)12-10A13-A2B2A2BA16-B2AB123-2(3A8-)2AL8AL2A8-BA2L6B2LAB8-14A8-D5I2A5ID8-14A8-E2B3G2-3G2BE8-E2BH2G2-2GH2BE8-2EBHG4-GHB2E9-E2HG4-G2HE10-E2HG4-G2HE11-EHG4-GHE13-HG4-GH14-H2G2-2GH15-HG2-GH16-E4HE16-6A167-12A10-A10LA10-B4L2B4LB10-12A10-C10IC10-12A2(10-EH8BHE)11-2HBG2BGB2H13-H2G2B2GH14-H2G2B2GH15-2G2B2G17-G2BG18-G2BG19-2B214-2(10A12-)2B6A2B12-10A12-D8ID12-10A13-HG4BGH14-HG4BGH15-2G2B2G17-G2BG18-G2BG19-2B20-2B260-6A16-2B2A2B15-3B2A3B14-AB4ABA14-AB4IBA14-8A15-2G2B2G17-G2BG19-2B20-2B371-2(B2AB18-)B2AB19-2A20-2B384-
