model
size = 22 24 29, scale = 0.05, origin = -y
material deform = 1, fade = true, lighting = smooth, roughness = 0.3, metalness = 0.6
  colors = A:#2D2D2D B:#D7FF00 C:#272727 D:#000 E:#3D3D3D F:#595959 G:#323232 H:#353535 I:#4B4B4B J:#666 K:#06F L:#717171 M:#FC0 N:#7F7F7F
voxels
186-2B20-2C394-2C19-4B18-4C17-6B16-6B15-3B2A3B14-B2C2A2CB15-6B16-6B17-4C2(18-4B)19-2B193-8D14-B2C2B2CB15-6C16-2C2A2C16-B4AB15-BC4ACB14-C6AC14-B6AB12-CB3A2-3ABC11-B3A2-3AB13-C6AC14-B6AB14-BC4ACB14-CB4ABC15-B4AB17-B2AB19-2C170-D8-D12-C8DC12-2CL4AL2C11-3C2A2-2A3C10-BCBA4-ABCB10-CB2A4-2ABC9-C2BA6-A2BC7-C2BCA6-AC2BC6-2B2A8-2A2B6-BCBA8-ABCB6-C3BA6-A3BC7-2BCA6-AC2B9-CB2A4-2ABC9-C2B2A4-2A2BC9-BCBA4-ABCB11-3BA2-A3B13-3C2A3C15-6B18-2C124-2D10-2D8-BCD8-DCB7-3C3A4-3A3C6-2C3A6-3A2C6-2B3A6-3A2B6-2B2A8-2A2B6-B3A8-3AB5-C4A8-4AC4-B2A12-2AB4-B3A10-3AB4-C4A8-4AC5-B3A8-3AB6-2B2A8-2A2B6-C3A8-3AC6-2B3A6-3A2B7-2C3A4-3A2C10-C3A2-3AC13-B6AB15-2C2A2C17-4C100-2D12-2D5-2CDA10-AD2C4-C-LA10-AL-C4-CMA12-AMC2(4-B2A12-2AB)2(4-CA14-AC2(4-BA14-AB))4-C2A12-2AC4-BA14-AB4-B2A12-2AB5-C2A10-2AC7-2CA8-A2C9-2BA6-A2B10-3C2A2-2A3C12-2C4A2C16-4C77-D16-D4-BD14-DB4-C2A12-2AC2(4-CA14-AC4-BA14-AB)4-BA14-AB2(4-CA14-AC2(4-BA14-AB))4-CA14-AC4-BA14-AB5-C2A10-2AC7-B2A8-2AB8-C3A6-3AC9-2C2A4-2A2C12-2C4A2C16-4B55-D16-D4-CD14-D3(C4-CA14-A)C2(4-BA14-AB)3-CA16-AC2(2-BA16-AB)2-CA16-AC3-BA14-AB4-BA14-AB3-CA16-AC3-BA14-AB4-BA14-AB5-CA12-AC6-BA12-AB7-CA10-AC8-C2A8-2AC9-2C3A2-3A2C12-3B2A3B17-2B34-D16-D4-CD14-DC4-CA14-AC3-3(CA16-AC2(2-BA16-AB)2-)CA16-AC2-BA16-AB3-2(BA14-AB4-)CA14-AC5-BA12-AB7-CA10-AC8-CA10-AC9-CA8-AC11-B3A2-3AB13-3B2A3B17-2B12-D16-D3-B2D14-2DB2(2-CA16-AC)2-BA16-AB2-CA16-AC2(2-BA16-AB)-CA18-AC-2(BA16-AB2-)CA16-AC3(2-BA16-AB)3-BA14-AB4-CA14-AC4-BA14-AB5-CA12-AC7-CA10-AC9-CA8-AC11-B2A4-2AB13-2B4A2B16-4B11-D16-D3-CD16-D3(C2-CA16-A)C-2(BA18-A2BA18-ABCA18-AC)BA18-AB-3(BA16-AB2-)BA16-AB3-CA14-AC4-BA14-AB4-CA14-AC5-CA12-AC7-CA10-AC9-BA8-AB11-B8AB13-8B9-D16-D3-CD16-DC2-CA16-AC-2(CA18-ACBA18-A2BA18-AB)DC18-CDB3(A18-A2B)A18-AB-BA16-AB2-BA16-AB3-CA14-AC4-BA14-AB4-CA14-AC5-CA12-AC7-CA10-AC9-BA8-AB11-B8AB13-8B9-D16-D3-BA16-AB2-CA16-AC-BA18-A2BA18-ABCA18-ACBA18-A2BA18-ABDC18-C2D20-3(2DC18-C)DB2(A18-A2B)A18-AB-CA16-AC3-BA14-AB2(4-CA14-AC)5-CA12-AC7-B2A8-2AB9-2B8A2B12-8B9-D16-D3-CA16-AC2-CA16-AC-BA18-ABCA18-ACBA18-A2BA18-ABDC18-CDN3(20-2N)20-NL20-LDC18-CDBA18-A2BA18-AB-CA16-AC2-BA16-AB3-2(CA14-AC4-)2CA12-A2C6-B2A8-2AB9-2B8A2B12-8B9-D16-D3-CA16-AC2-CA16-AC-CA18-ACBA18-A2BA18-ABDC18-CDN2(20-2N)20-NL2(20-2L)20-LDC18-CDBA18-A2BA18-AB-CA16-AC2-BA16-AB3-CA14-AC4-CA14-AC5-CA12-AC7-B2A8-2AB9-2B8A2B12-8B9-D16-D3-BA16-AB2-CA16-AC-BA18-A2BA18-ABDC18-CDL5(20-2L)20-LJ20-2J20-JDC18-CD-BA16-AB2-CA16-AC3-BA14-AB2(4-CA14-AC)5-CA12-AC7-B2A8-2AB9-2B8A2B12-8B9-D16-D3-CA16-AC2-CA16-AC-BA18-ABCA18-ACDC18-CDJ20-2J20-JL2(20-2L)20-LJ20-J-2(J18-J2-)DC16-CD2-BA16-AB3-CA14-AC4-BA14-AB4-CA14-AC5-CA12-AC7-CA10-AC9-B10AB11-4B2D4B16-2B12-D16-D3-CA16-AC2-CA16-AC-CDA16-ADCBEA16-AEBD2C16-2CDJ3(20-2J)20-J-3(J18-J2-)2(F18-F2-)DC16-CD3-2C14-2C4-BA14-AB4-CA14-AC5-CA12-AC7-CA10-AC9-B10AB11-10B30-D16-D3-BD16-DB2-CA16-AC-BDA16-AD2BEA16-AEBDEC16-CEDJ2(F18-F2J)F18-FJ-3(F18-F2-)F18-F3-3(F16-F4-)DC14-CD4-BA14-AB5-C2A10-2AC7-CA10-AC9-C10AC11-3B4D3B15-4B33-D16-D3-CD16-DC2-CMA14-AMC2-CDA14-ADC2-BEA14-AEB2-D2C14-2CD5(2-F18-F)3-5(F16-F4-)DC14-CD5-BA12-AB7-CA10-AC8-CA10-AC9-C10AC11-10B52-D16-D3-CD16-DC2-CMA14-AMC2-CDA14-ADC2-BEA14-AEB2-2DC14-C2D4(2-2F16-2F)3-3(F16-F4-)F16-F5-2(F14-F6-)DC12-CD7-BA10-AB8-CA10-AC8-C2A8-2AC9-2C8A2C12-8B53-D16-D4-BD14-DB2(4-C3A10-3AC)4-B2A12-2AB4-D2C12-2CD6(4-I16-I)5-2(I14-I6-)2I12-2I7-I12-I8-DC10-CD8-B2A8-2AB9-C3A4-3AC10-2C8A2C12-8C75-2D14-2D4-C3D10-3DC4-C3M2A6-2A3MC4-C3DA8-A3DC4-B2E2A8-2A2EB4-3D2C8-2C3D4(4-I2E12-2EI)5-2(IE12-EI6-)IE12-EI7-2E10-2E9-4(E10-)D2C6-2CD10-2B8A2B11-3C4A3C13-8C98-3D10-3D6-B2K10D2KB6-C2K2M6A2M2KC6-C3D3A2-3A3DC6-B3E3A2-3A3EB6-4D3C2-3C4D3(6-IAEH8-HEAI)6-I2EH8-H2EI7-2EH8-H2E9-EH8-HE10-2E8-2E11-EH6-HE2(12-2E6-2E)12-2D6C2D13-8B16-4C123-2(3D8-)CDK8DKDC8-CD2K6M2KDC8-C5D2A5DC8-B5E2A5EB8-6D2C6D8-E2A3G2-3G2AE8-E2AH2G2-2GH2AE8-2EAHG4-GHA2E9-E2HG4-G2HE10-E2HG4-G2HE11-EHG4-GHE13-HG4-GH14-H2G2-2GH15-HG2-GH16-E4HE16-6D167-12D10-B10KB10-C4K2M4KC10-C10DC10-B10EB10-12D2(10-EH8AHE)11-2HAG2AGA2H13-H2G2A2GH14-H2G2A2GH15-2G2A2G17-G2AG18-G2AG19-2A214-10D12-2C6D2C12-CM6DMC12-C8DC12-B8EB12-10D13-HG4AGH14-HG4AGH15-2G2A2G17-G2AG18-G2AG19-2A20-2A260-6D16-BC2BCB15-2CM2DM2C14-2C4D2C14-2B4E2B14-8D15-2G2A2G17-G2AG19-2A20-2A371-2(4C18-)4B19-2D20-2A384-
