model
size = 22 24 29, scale = 0.05, origin = -y
material deform = 1, fade = true, lighting = smooth, roughness = 0.3, metalness = 0.6
  colors = A:#2D2D2D B:#000 C:#FF2800 D:#FFF E:#EA1700 F:#F5F5F5 G:#FF6A00 H:#222 I:#F90 J:#00FF15 K:#00EF0B L:#FF2600 M:#FF4800 N:#F80 O:#FB0 P:#06F Q:#FC0 R:#FD0
voxels
186-DF20-FD394-JK19-BKJB18-4B17-DF2BDF16-3(FD)15-CBF2ADBC14-EBD2AFBE15-B2(FD)B16-B2(DF)B17-2(FD)18-2(DF)18-BDFB19-2B193-8B14-B3(JK)B15-B2(JK)B16-BK2AJB16-B4AB15-DF4ADF2(14-B6AB)12-CE3A2-3AEC11-C3A2-3AC13-C6AC14-E6AE14-CB4ABC14-EB4ABE15-E4AE17-E2AE19-2B170-B8-B12-10B12-DBQ4AQBF11-DFD2A2-2AFDF10-BDFA4-ADFB10-2B2A4-2A2B9-3BA6-A3B7-2(EC)A6-A2(CE)6-CE2A8-2AEC6-ECEA8-AECE6-2(CE)A6-A2(EC)7-CECA6-ACEC9-CE2A4-2AEC9-CEC2A4-2ACEC9-CECA4-ACEC11-CECA2-ACEC13-3B2A3B15-3(KJ)18-2B124-2B10-2B8-FDB8-BFD7-BDF3A4-3ADFB6-2B3A6-3A2B6-KB3A6-3ABJ6-JK2A8-2AJK6-B3A8-3AB5-C4A8-4AC4-E2A12-2AE4-C3A10-3AC4-E4A8-4AE5-E3A8-3AE6-CE2A8-2AEC6-E3A8-3AE6-CE3A6-3AEC7-CE3A4-3AEC10-B3A2-3AB13-J6AK15-2B2A2B17-2(CE)100-2B12-2B5-BDBA10-ABFB4-B-QA10-AQ-B4-BCA12-ACB4-J2A12-2AK4-K2A12-2AJ4-BA14-AB2(4-EA14-AE4-CA14-AC)2(4-CA14-AC4-E2A12-2AE)5-E2A10-2AE7-2BA8-A2B9-JKA6-AJK10-3B2A2-2A3B12-CE4AEC16-4B77-B16-B4-2B14-2B4-C2A12-2AC4-BA14-AB4-KA14-AJ4-JA14-AK4-BA14-AB4-CA14-AC4-EA14-AE4(4-BA14-AB)4-EA14-AE4-CA14-AC4-EA14-AE5-B2A10-2AB7-K2A8-2AJ8-B3A6-3AB9-EC2A4-2ACE12-2B4A2B16-2(DF)55-B16-B4-CB14-BC4-EA14-AE4-BA14-AB4-JA14-AK4-KA14-AJ4-BA14-AB3-EA16-AE2-BA16-AB2-DA16-AF2-FA16-AD3-DA14-AF4-FA14-AD3-BA16-AB3-EA14-AE4-CA14-AC5-BA12-AB6-JA12-AK7-BA10-AB8-C2A8-2AE9-2B3A2-3A2B12-FDF2ADFD17-JK34-B16-B4-EB14-BE4-BA14-AB3-BA16-AB2-KA16-AJ2-JA16-AK2(2-BA16-AB)3(2-DA16-AF2-FA16-AD)3-BA14-AB4-EA14-AE4-BA14-AB5-KA12-AJ7-BA10-AB8-EA10-AC9-BA8-AB11-F3A2-3AD13-JKJ2AKJK17-CE12-B16-B3-3B14-3B2-BA16-AB2-KA16-AJ2-JA16-AK2(2-BA16-AB)2-DA16-AF-FA18-AD-2(DA16-AF2-FA16-AD2-)DA16-AF2-FA16-AD3-2(BA14-AB4-)JA14-AK5-BA12-AB7-CA10-AE9-BA8-AB11-D2A4-2AF13-KJ4AKJ16-2(CE)11-B16-B3-2B16-2B2-KA16-AJ2-JA16-AK2-BA16-AB-BA18-ABD2(A18-A2FA18-A2D)A18-A2FA18-AD-DA16-AF2-FA16-AD2-DA16-AF2-FA16-AD3-BA14-AB4-KA14-AJ4-BA14-AB5-EA12-AE7-BA10-AB9-DA8-AF11-K8AJ13-4(EC)9-B16-B3-KB16-BJ2-JA16-AK-BA18-A2BA18-ABD2(A18-A2FA18-A2D)H18-H2(2FA18-A2DA18-A)F-FA16-AD2-DA16-AF3-FA14-AD2(4-BA14-AB)5-CA12-AC7-BA10-AB9-FA8-AD11-J8AK13-4(CE)9-B16-B3-JA16-AK2-BA16-AB-BA18-ABDA18-A2FA18-A2DA18-A2FA18-ADBH18-H2B20-3(2BH18-H)BFA18-A2DA18-A2FA18-AD-DA16-AF3-FA14-AD4-BA14-AB4-EA14-AC5-BA12-AB7-F2A8-2AD9-JK8AJK12-4(EC)9-B16-B3-BA16-AB2-BA16-AB-BA18-ABFA18-A2DA18-A2FA18-ADBH18-HBR3(20-2R)20-RQ20-QBH18-HBFA18-A2DA18-AF-FA16-AD2-DA16-AF3-BA14-AB4-CA14-AE4-2BA12-A2B6-D2A8-2AF9-KJ8AKJ12-4(CE)9-B16-B3-BA16-AB2-CA16-AE-BA18-ABDA18-A2FA18-ADBH18-HBR2(20-2R)20-RQ2(20-2Q)20-QBH18-HBDA18-A2FA18-AD-DA16-AF2-FA16-AD3-BA14-AB4-EA14-AC5-BA12-AB7-F2A8-2AD9-JK8AJK12-4(EC)9-B16-B3-CA16-AE2-EA16-AC-BA18-ABFA18-ADBH18-HBQ5(20-2Q)20-QO20-2O20-OBH18-HB-DA16-AF2-FA16-AD3-DA14-AF4-BA14-AB4-CA14-AE5-BA12-AB7-D2A8-2AF9-KJ8AKJ12-4(CE)9-B16-B3-EA16-AC2-CA16-AE-BA18-ABDA18-AFBH18-HBO20-2O20-OQ2(20-2Q)20-QO20-O-2(O18-O2-)BH16-HB2-FA16-AD3-DA14-AF4-FA14-AD4-BA14-AB5-EA12-AE7-BA10-AB9-D10AF11-2(KJ)2B2(KJ)16-CE12-B16-B3-CA16-AE2-EA16-AC-2BA16-A2BFDA16-A2DB2H16-2HBO3(20-2O)20-O-3(O18-O2-)2(I18-I2-)BH16-HB3-FH14-HD4-DA14-AF4-BA14-AB5-CA12-AC7-BA10-AB9-F10AD11-5(JK)30-B16-B3-EB16-BC2-CA16-AE-2BA16-A2B2DA16-ADFBDH16-HDBO2(I18-I2O)I18-IO-3(I18-I2-)I18-I3-3(I16-I4-)BH14-HB4-FA14-AD5-B2A10-2AB7-EA10-AC9-B10AB11-FDF4BDFD15-2(JK)33-B16-B3-CB16-BE2-ECA14-A2C2-2BA14-A2B2-FDA14-A2D2-B2H14-2HB5(2-I18-I)3-5(I16-I4-)BH14-HB5-DA12-AF7-BA10-AB8-CA10-AE9-B10AB11-5(DF)52-B16-B3-EB16-BC2-2CA14-ACE2-2BA14-A2B2-2DA14-ADF2-2BH14-H2B4(2-2I16-2I)3-3(I16-I4-)I16-I5-2(I14-I6-)BH12-HB7-FA10-AD8-BA10-AB8-E2A8-2AC9-2B8A2B12-4(DF)53-B16-B4-CB14-BE4-E3A10-3AC4-B3A10-3AB4-F2A12-2AD4-B2H12-2HB6(4-N16-N)5-2(N14-N6-)2N12-2N7-N12-N8-BH10-HB8-D2A8-2AF9-B3A4-3AB10-CE8AEC12-8B75-2B14-2B4-E3B10-3BC4-4C2A6-2A3CE4-4BA8-A4B4-3D2A8-2A2DF4-3B2H8-2H3B4(4-N2G12-2GN)5-2(NG12-GN6-)NG12-GN7-2G10-2G9-4(G10-)B2H6-2HB10-FD8AFD11-3B4A3B13-4(CE)98-3B10-3B6-C2P10B2PE6-E2P2C6A2C2PC6-4B3A2-3A4B6-F3D3A2-3A4D6-4B3H2-3H4B3(6-NCGM8-MGCN)6-N2GM8-M2GN7-2GM8-M2G9-GM8-MG10-2G8-2G11-GM6-MG2(12-2G6-2G)12-2B6H2B13-4(FD)16-4B123-2(3B8-)EBP8BPBC8-CB2P6C2PBE8-6B2A6B8-6D2A5DF8-6B2H6B8-G2C3L2-3L2CG8-G2CM2L2-2LM2CG8-2GCML4-LMC2G9-G2ML4-L2MG10-G2ML4-L2MG11-GML4-LMG13-ML4-LM14-M2L2-2LM15-ML2-LM16-G4MG16-6B167-12B10-C10PE10-E4P2C4PC10-12B10-F11D10-12B2(10-GM8CMG)11-2MCL2CLC2M13-M2L2C2LM14-M2L2C2LM15-2L2C2L17-L2CL18-L2CL19-2C214-10B12-EC6BEC12-2C6BCE12-10B12-9DF12-10B13-ML4CLM14-ML4CLM15-2L2C2L17-L2CL18-L2CL19-2C20-2C260-6B16-3(EC)15-E2C2BCEC14-8B14-F5DFD14-8B15-2L2C2L17-L2CL19-2C20-2C371-2(EC)18-4B18-2(FD)19-2B20-2C384-
