model
size = 32 27 13, scale = 0.05, origin = -y
material deform = 1, fade = true, lighting = smooth, roughness = 0.3, metalness = 0.6
  colors = A:#EEE B:#FC3
voxels
654-4B28-B2-B765-2B30-2B29-4B28-B2-B732-4A25-4(10A22-)10A26-2A666-2(10A22-)A3-2A3-A21-BA8-AB19-2BA8-A2B18-2B10A2B14-B4-5B2A5B4-B10-2B6-6B6-2B10-2B18-2B372-2B29-4B28-4B27-2B2-2B120-10A21-12A16-20A12-20A11-3(22A10-)22A11-B5-8A5-B12-B18-B149-2B59-8A23-10A20-14A18-2A2-6A2-2A21-B-4A-B24-B-4A-B25-2(6A26-)6A15-3B9-4A9-3B3-4B7-B-4A-B7-4B-5B6-10A6-9B2-6A8-6A2-4B-3B-6A10-6A-3B6-5A12-5A10-4A14-4A11-3A14-3A2(12-4A)12-7A6-7A12-20A12-B6-6A6-B19-2(6A26-)2A2-2A26-6A23-3B6A3B18-5B6A5B15-3B2-8A2-3B14-3B-4A2-4A-3B15-B6A2-6AB17-6A2-6A18-6A2-6A19-5A2-5A21-4A2-4A15-7B3A4-3A7B6-9B4A2-4A9B3-10B4A2-4A10B-7B3-5A2-5A3-9B-3B2(2-7A)2-3B-4B-3B6A8-6A3B-2B2-5A-2A12-2A-3A2B6-2A20-2A8-2A20-2A76-2A12-2A14-20A12-B6-6A6-B19-3(6A26-)6A23-3B6A3B18-3B8A5B15-5B7A6B14-4B10A4B15-B3A8-3AB17-2A10-2A18-3A8-3A19-2A8-2A14-5B-BA8-AB-5B7-8BA8-A8B4-4B3-3B10-3B3-4B-3B3-5B10-2(5B3-)7A8-6AB3-2B4-9A6-7A2B7-8A10-8A6-3A20-3A7-A22-A8-A22-A106-20A12-2(6A-)6A51-3(6A26-)A4-A23-3B6A3B18-5B6A5B16-3B10A3B16-B3A8-3AB17-A12-A18-2A10-2A19-2A8-2A14-6B2A8-A7B7-B7A10-8B4-3B24-A2B-3B26-4B4-6A10-6A4-B3-2(10A6-)3A3-2A10-2A3-3A6-3A20-3A2(6-2A22-2A)107-16A14-2(6A-)6A83-4(6A26-)6A24-10A20-2(5A4-5A18-)4A6-4A19-3A6-3A15-4B-3A6-3A-4B8-2B8A6-3A7B5-2BA22-3B3-3B-5A12-3A2B-3B4-B7A-A6-A-4A4B3(6-10A)2-2A2-10A2(6-3A20-3A)7-A22-A77-2(2A4-)2A15-20A12-3A5-A2-A5-3A179-3(6A26-)6A25-3(8A24-)8A16-8B8A8B7-9B10A7B6-8B-8A-A7B6-4B-2B12A2B-4B13-12A15-22A10-2A2-14A2-3(2A9-)2A8-2A20-2A45-2(2A4-)2A15-20A12-20A496-2(3A6-3A20-)3A6-3A48-4A12-4A11-2(22A10-)2(2A2-14A2-2A10-)22A10-22A12-2A14-2A654-2A14-2A13-3(6A8-6A12-)4A-A8-A-4A102-
