model
size = 23 24 17, scale = 0.05, origin = -y
material deform = 1, fade = true, lighting = smooth, roughness = 0.3, metalness = 0.6
  colors = A:#FEFEFE B:#FF8460 C:#000 D:#FF0F00 E:#0A0A0A F:#040404 G:#FCFCFC H:#F2F2F2 I:#F4F4F4 J:#0F0F0F K:#161717 L:#FFFFF5 M:#0D0D0D N:#F7F7F7
voxels
285-7B16-7B521-9B14-9B519-3B5-3B12-3B5-3B517-3B7-3B10-3B7-3B515-3B9-2B9-3B9-2B515-3B9-3B8-3B9-3B7(514-2B11-2B8-2B11-2B)495-7C12-2B-9C-2B8-2B11-2B237-9C13-CM8AC11-C11AK9-C13AC7-C15AF6-CAE2CJAI8AHC5-CAE3-C11AC4-CEC3-C11AC5-F4-C11AC2(2-2C)2-C12A2CAC2-CA2C9AL6AC2-C6A2-3D2-6AC2-C5A9-5AC3-C18AC4-C5AN4AG5AC6-C2(3A2-)4AC8-C2A2(2-3A)C9-C11AC10-C3AG7AC11-C10AC10-3C8AC11-C9AC12-2C7AC14-6CEC272-3D503-2(3D20-)3D285-
