model
size = 8 7 25, scale = 0.05, origin = -y
material deform = 1, fade = true, lighting = smooth, roughness = 0.3, metalness = 0.6
  colors = A:#777 B:#F90 C:#888 D:#555 E:#339
voxels
2(40-8B8A)32-16B8A32-8B8A40-8B8A16-E6-E16-8B8A8-E6-2E6D2E2-2D2-E3-2D3-3B2D3B8A16-E6-E16-8B8A40-2BCBC3B8A40-B5C2B3(8A40-2B3(CB))8A40-2B4C2B2(8A40-2B3(CB))8A40-B5C2B8A40-2BCBC3B8A16-E6-E16-2BCBC3B8A8-E6-2E6D2E2-2D2-E3-2D3-8B8A16-E6-E16-2(8B8A40-)16B2(8A40-8B)8A
