model
size = 14 13 24, scale = 0.05, origin = -y
material deform = 1, fade = true, lighting = smooth, roughness = 0.3, metalness = 0.6
  colors = A:#555 B:#C3C C:#777 D:#0FC
voxels
103-4C11-2C11-4C109-2B11-4B24-4B11-2B123-4B10-4B24-4B10-4B107-6B7-8B6-8B20-8B6-8B7-6B91-8A76-8A77-2A2B2A6-9A75-9A7-2A2B2A62-9A5-9A75-9A5-9A49-2A2B2A6-9A8-4A80-4A7-9A7-2A2B2A34-9A5-9A103-9A5-9A20-3A2B3A5-9A7-6A106-6A6-9A6-3A2B3A5-4A2B4A4-9A131-9A5-4A2B4A4-2AB-2B-B2A4-2(2A2B)A131-2(2A2B)A5-2(2AB-2B-B2A4-)2(2A2B)2A130-2(2A2B)2A4-2AB-2B-B2A4-A2(2B-)2BA4-2(2A2B)2A130-2(2A2B)2A2(4-A2(2B-)2BA)4-2(2A2B)2A4-10A102-10A4-2(2A2B)2A2(4-A2(2B-)2BA)3-3A2B2A2B3AD2-11AD2-10A74-10A4-11AD-3A2B2A2B3AD2-A2(2B-)2BA3-3AB-2B-B3A-D3A2B2A2B3A2(2D12A)D2-11A3-10A18-10A4-11A-D2(12A2D)3A2B2A2B3AD-3AB-2B-B3A2-3AB-2B-B3A-D3A2B2A2B3AD2-10A2-D12AD-12A3-10A18-10A3-12A-D12AD2-10A2-D3A2B2A2B3AD-3AB-2B-B3A4-3A2B3A3-D2(12A2D)12AD-12A3-10A18-10A3-12A-D2(12A2D)12AD3-3A2B3A49-7(6C8-)6C107-4(4C10-)4C136-2(4C11-2C11-4C150-)4C11-2C11-4C61-
