model
size = 18 18 30, scale = 0.05, origin = -y
material deform = 1, fade = true, lighting = smooth, roughness = 0.3, metalness = 0.6
  colors = A:#C0F B:#222 C:#444 D:#0FC
voxels
25-4B14-4B301-6B298-10B8-10B11-2(A2DA14-)A2DA244-12B6-12B8-2(3A2D3A10-)3A2D3A13-4(2D16-)2D155-12B6-12B7-2(4A2D4A8-)4A2D4A10-2A2D2A14-6(2D16-)2D100-14B4-14B6-2(10A8-)10A9-8A12-2(4A14-)4A15-3(2A16-)2A100-14B4-14B5-2(12A6-)12A7-10A9-2(8A10-)8A12-2(4A14-)A2CA14-A2DA98-16B2-16B4-2(12A6-)12A7-10A7-3(C10AC6-)C10AC10-4A14-A2CA14-4A98-16B2-16B3-2(14A4-)14A5-12A6-C10AC4-D2C10A2CD2-D2C10A2CD4-C10AC7-10A10-2A2C2A13-A2CA5(14-4C)7-36B-5A6C5A2-5A6C5A3-5A4C5A5-4A4C4A6-CA8CAC4-D2CA8CA2CD2-D2CA8CA2CD4-CA8CAC7-2A6C2A10-2A2C2A13-A2CA5(14-4C)7-36B-5A6C5A2-5A6C5A3-5A4C5A5-4A4C4A4(6-CA8CAC)7-2A6C2A10-2A2C2A13-A2CA5(14-4C)7-36B-5A6C5A2-5A6C5A3-6A2C6A5-5A2C5A7-4(10A8-)10A10-2(6A13-4D97-36B-5A6C5A2-5A6C5A3-6A2C6A5-5A2C5A7-10A8-10A9-8A11-2(6A12-))6A13-4D97-3(36B-5A6C5A2-5A6C5A3-6A2C6A5-5A2C5A7-10A8-10A9-8A11-6A12-6A13-4A115-)36B-5A6C5A2-5A6C5A3-6A2C6A5-5A2C5A7-10A8-10A9-8A11-6A13-4A14-4A115-2(36B-5A6C5A2-5A6C5A3-6A2C6A5-5A2C5A7-10A8-10A9-8A11-6A13-4D133-)36B-5A6C5A2-5A6C5A3-6A2C6A5-5A2C5A7-10A8-10A10-6A13-4A14-4D133-36B-5A6C5A2-5A6C5A3-6A2C6A5-5A2C5A7-10A8-10A10-6A13-4A151-36B2-2(4A6C4A4-)6A2C6A5-5A2C5A8-8A10-8A11-6A13-4A152-16B2-16B3-2(4A6C4A4-)6A2C6A6-4A2C4A10-6A12-6A13-4A14-4A152-16B2-16B4-2(12A6-)12A8-3A2C3A11-6A12-6A13-4D171-14B4-14B6-2(10A8-)10A10-6A13-4A14-4A190-12B6-12B8-2(8A10-)8A12-4A14-4D209-10B8-10B10-2(6A12-)6A13-4A228-8B10-8B12-2(4D14-)4D247-6B12-6B14-2D16-2D260-
