model
size = 26 32 25, scale = 0.05, origin = -y
material deform = 1, fade = true, lighting = smooth, roughness = 0.3, metalness = 0.6
  colors = A:#090 B:#0F6 C:#0C6 D:#0C0
voxels
612-2A2(25-A)749-B-A25-2A52-2A694-B27-A25-3A25-B54-2A692-3A25-2A109-2A24-B614-2(A25-)A113-B25-A611-2A24-B2A191-3A557-B24-2A25-A221-A25-2A54-C418-A25-4A22-2A-2A25-A252-C22-A25-3A5-A-C17-CD3-CD46-C4-C335-A24-BA312-2C20-C4-2C16-B-CD4-D19-AD4-3D17-2D3-3DC18-DC2-CD19-CD4-D20-DC313-A390-2A19-AD4-AC19-DC3-D25-C20-D340-2A389-A21-C77-C341-A387-B2A415-2(A25-)B361-2A142-2(A25-)A195-2A24-A25-A387-A195-2A169-B25-A438-A25-B144-B25-2A3(25-A)79-B36-2A386-A2(24-2A)248-2(A25-)2A24-2A25-3A25-2A9-2A14-A370-A25-A419-A14-3A25-2A25-B315-A189-A25-A24-2A23-2A24-A25-A49-AB24-2(A25-)A43-A315-B25-3A264-B50-A25-A23-3A49-B69-A270-A25-A22-4A20-3A23-B461-A23-B-A23-3A218-A610-A220-3AB607-A25-A24-2A170-2A658-A24-2A97-3A23-A22-4A655-B23-2A24-A23-B2A24-A24-2A46-B247-
