model
size = 7 32 11, scale = 0.05, origin = -y
material deform = 1, fade = true, lighting = smooth, roughness = 0.3, metalness = 0.6
  colors = A:#090 B:#0C0 C:#0C6 D:#0F6
voxels
206-BC6-2B220-B3C219-2BC6-B-C193-B19-B-C7-2B128-3A-A5-AD5-A5-2A4-A26-3(3BC3-)3B3-4B6-3B99-A28-2(A-)A24-2AD4-A6-B2(5-2B)5-3B4-3B5-2BC10-4BC2-2(A6-)A82-A5-2A5-A6-2A6-A2-3A45-3(2B5-)B21-B18-2A5-2(2A6-)A6-2A6-A5-DA37-A19-D11-D89-C19-D43-A6-A17-A2-A9-2A191-2(A6-)A3-4A3-A6-A191-D19-D11-D123-
