model
size = 32, scale = 0.05, origin = -y
material deform = 1, fade = true, lighting = smooth, roughness = 0.3, metalness = 0.6
  colors = A:#101111 B:#553E3E C:#100 D:#FDEFDA E:#FFF F:#887C7C G:#F92F62 H:#F8B148 I:#2A0E0E J:#946A6A K:#710016 L:#5D0808 M:#F14288 N:#F7A224 O:#C52323 P:#4F0005 Q:#FCE0B6 R:#A00 S:#F61969 T:#F9C16D U:#FF9D9D V:#360B01 W:#F9638D X:#FBD091 Y:#430B0B Z:#DD960A Aa:#F9245A Ab:#FF3B3B Ac:#FC8599 Ad:#8C5505 Ae:#BB6808 Af:#FC304A Ag:#C67A08 Ah:#200000 Ai:#774949 Aj:#B76907 Ak:#3B1501 Al:#FF7F75 Am:#F04481 An:#DD7A0A Ao:#DD880A Ap:#843505 Aq:#B75807 Ar:#770505 As:#900202
voxels
331-2I-2I23-A3I9A2I-A15-18A15-14A-A16-8A-3A20-A-6A791-2A6C2AI-5I2A11-A-11AI9A9-23A10-3A3-3A-12A10-2A4-2A2-11A11-2A8-H5-5A11-A3-2G4-2N-GO22-M4-H2-OG31-M511-F241-2I2C-4C-I2-2IA3I11-AI3ABCA2BAC10AI-I7-11A-13A8-5A-3A2-13A9-2A4-G3-AB3A2-6A7-4A3-OG3-2H6-4A10-A-N-2GAa2-3HN-G17-O-2H2G3-H3NM2G16-2MHN9-3G16-Aa-H480-I3F3DF6DIDI12-F2-7FI5F2-D17-11F21-F2B2(2FI)2F22-6BFI2B26-B86-I3C2(2-2C)-4C15-C3B2C3BI2DI4B-2IC2-I5-A-2AD2ABAB2ABA2D3AB2A2(C-)A5-A2-6A2B3AB7AD3CA5-A2-2A2-2OG3-2B2AO2-5AEA5-4A3-2GAc2-2HB7-4A6-A-A2-2N2G3-4H20-O2H2G3-HNH-M3G15-G-HN9-3GAa15-MAc12-2GAa31-Ac430-7F15D10-2FI5FD10FD2I11-19FI16-FB13F17-F10B4F19-6B26-3B-B27-2B2-2B21-2(C-)C2BC-CBC2BI16-I2(BC)4BC6BI2-I3-2A4-A-AB3A7B2D2A4BI2(3-2A)2-6AB-2AB2A2G2ABAI3-2A4-A2-A3-4G2A2BA2O2-A-AI3A4-4A2-N-3G2-2HAG6-5A5-A3-3H2G3-4H2-2G4-C10-G-2H-G4-3H-3G16-GH10-GB2G2S13-G3-6B4-3GS20-4B5-2G21-2B-B28-A376-4F3DAs4P6K5D9-5F4DC5KD2F3DF10-5F6C5D6F11-2F-2F2D8C4F2I12-F2-J4BDB4D6F16-J8BI5B18-9BI4BC16-J10B2-B-C15-J11BI15-3C7B2D5B-2C8-2A2-CB2ABG5B5ABCBI2(3-2A)2-I2A5GB-B2AG-2A2BAI2-IA3-2A6-4GA2H2AGO4A2(-2A)3-4A-3H4G-3H2(-O)5-C2A4-A4-3H3G2-4H2-2G4-2C10-3H6-2H3-2G17-H3-B-6B3GS18-2B4A5B2G20-BAB2A5B2G17-B2-4BAB2V2BG21-6A2-3A20-6A4-3A19-7A-3A9(21-11A)16-5DK3P7-2P2K3D8-DF5DC2KP5-P3C4D9-F2D7C4PK2DC2D3F8-2FD2F2D12C2D2F9-4F2-JB2D9C2D2F9-3B3-2J2D8C4BAi15-2J2D13BAi14-2J2D13B12-I-2JB2A2B2D2BD4B2C11-C3B2A2B5D2ADBI2B4-C3-AI-IB3A3G2B8A3BC3-A3-2A2-B2AB5G2-2AG-2ABABI2-IA3-2A2(-A)-5GB2H-2G-Af2A-A-C-IA2-5A-2H4G-4H2G7-C2A5-A3-3H2G2B-3H3-Af6-C8-S2-2H2-2B2-2H3-2G5-C11-2H5BA5B2G20-B4A6BG17-4B4A5B2G20-7AV3BG18-11A2BA11(18-14A)12-5D3K11-3P2KD8-5D3C9-4C3D8-2FD8C5-4C3D9-2F2D16C3D9-2FB2FJ15C2D10-3B3J13C3D11-2B4J2D8C2B2DB12-B4JD4C4D3B2DB11-3B2J2AD5C3D2BD2B9-C-C3BA6B6D2BDB3-I3-3ICB3ABGB2G-3B4ABABI3-A3-3AI2A2B3G3-H-2B6AB2-CA2-6AH2B3G-3H3GO-A4-C-2A-5A2-HB4G-4HG-G6-A-A3-A2-ArM-H2B2G2B3H2G9-C8-S-2H6B-H2A5-HN14-H-4B4A2BABAf18-3B9ABG16-3B10A2BG17-3B10AB18-13ABA11(17-15A)11-5D2K14-3C2KF5-5D3C12-L3C2DF6-F2D6C10-CL2CDJ-F5-2FD9C7-4CD9-F3D8C5-5CD8-2F3BFJ15C2DF10-2BF2J13C2DB8-B2-2BF2JD15C11-4B3D13CB9-2C2(BD)4B4C9DI2-I3-2I2BD3A4B2-4B7AI2CA3-7A2BGB2-2H4B6AIC11A2B3G-3H4GB2A3-AC3A-3AM-A4BGB-2B5G-B5-2A3-A-A2MBH5BA4B3G3-HN7-A2-2M2-5BA4B2A2(B-)AHN10-S-5B8A3BH4N12-3B10A2B-NHN13-2B11AB3-H12-B-13ABA2B14-16A2V11(14-18A)9-3DKP17-4CDF4-4D2C15-L3CD3F3-DF2D4C14-LC3D5-2FD7C12-L2C2J5-3F2D6C10-CL2C2F5-2F4D7C6-6CDF6-3FB3D5C6-3CILCJ6-2B2-B4D5C4-7C8-B2-B5D15CB8-2B5DBD13C2D3I3-IA2B4A4B-2H4B6ADB2-A-9A4B4H4B10A-2A-5A5B2H2GB2G2BA4-6A2-AM7BA2B5G2BA4-2A3-2A-SM7BA4BA2G2B2-2H5-2A2-2S6B2A3B3A5B3H9-S4B12A2B4H10-4B11A2B4HN10-3B13A2B-2H11-2B15A2B2(13-18AB)10(13-19A)9-2DR20-2YCDF4-3DK18-I3CDF4-4D2C17-2C2DF4-DF7C14-I3D5-2F2D6C13-LC2D5-2F3D6C13-IC2F4-2JF3D6C12-IC6-2J-FB3D5C6-2C2-LC8-J-B5D5C4-4CL3C7-3B6D15CDBI5-A2B5ABA7BA5C2A2BIA-AI7A5B2H4B3A2-6A-A2-2AB3A6BHG4B2A3-7A2-2A3BA2B4AGA5BA5-2A-2A2-3A2B2AB8A3B2AH6-2A4-4B11ABA2B2H12-3B13A2B2HN10-4B12A4BH11-3B14A2B2H11-2B17AB12-18A2B12-19AV10(12-20A)7-2DR22-2YD-F-4DK20-Y2CDF2-DI3DC20-2CD2F-DID6C17-C2DF2-5D5C16-ICD2F2-D2J2D6C15-ICF4-2JB2D7C20-2J2B3D5C12-L8-J2B5D4C6-2C2-LC8-J2B6D15CLIBIA3-2BD8A4B2A4C4AD2BA-AI10A6B6A2-2AE2(2A-)2A2B6AB2A3B4A3-7A2-A3B12A2B2A5-2A-3A-A4B15A2H6-2A2-MG-2B15AB3H8-MGBA2B13A2B3HN7-2G3B14A3B3H7-M-2B15A3B2H10-2B17AB12-B18AB12-19AV10(12-20A)6-3D23-PYD2F-3DK22-PKD2F-4DK22-KD2F-3D5C19-KD2F-5D4C18-IDJ4-2JD5C17-I2F4-2J2D8C20-2JB4D5C20-2J2B4D5C6-C4-L8-JB7D15CLI2BA2-2BD10A2B4AC7A2BA2-23A-3AE2A-5AB18A3-9A-2B16A4-3A-4A2G2B17A7-3AO2G2B17A4H5-O3GB18A4H6-MG2B18A4H7-G2B18A2B2H8-2B18A2B10-B19A2B10-20ABV10(10-22A)5-3D24-KD2F-3D24-R2DF-3DK24-L2F-3D3CI21-LDF-5D3C19-L2DF2-3J2D3C18-KFJ4-2J2D6C15-K5-3J3D6C21-2J5D7C4-2C4-IL6-2J8D15C3B-A2-2B17AC7A2BA2-CD28A-AD2A-19A-A-8A-GB18A4-2A-3A2-G2B17A-A5-A-GA2G2B17A-HAd6-4G2B17A2HZN5-4GB18A-HZH7-G2B18A2BT9-2(B19A2B10-)10(22A10-)22A5-3D24-KD2F-3D25-2DF-3DK24-RDF-3D2CIC21-LDF-5D2C21-LDF-3J2D3C19-I2DB-4JD6C16-K2B3-3J2D6C8-C6-LB5-2J3D2CD3C3-6C4-I2C5-JBDA6D13CI2CB-BA2-2B9A2C11ACA2B2A2-CB30ADA-G21A2-6A2-G21A2-2A-3A2-G2B18AAh5-3A3G2B17A2B7-4G2B17A2B8-3G2B17A2BH9-GB18A2B10-2B18A2B10-B19ABV11(10-22A)5-3D24-KD2F-3D25-R2F-3DC24-R2D-3D2CIC21-LDF-3D4C21-L2D-2JD4CI19-I3DF3JD4CI11-C6-K2BF2-2J2D4C2I8-2C6-LB5-JB2D6C6-4C4-I2C5-2B2AD3CD14CI2CB5-2B8A4C10ACA2B2A2-CBA-7A2C11A2-2A-5A-G19A4-7A-G20A3-A2-3A-2GB18A-Ah5-2A2-2G2B17A-B9-2G2B16AG2B9-2G2B17A2B11-2B17A2B10-2B18A2B10-B19ABAk11(10-22A)6-2D24-LD2F-3D25-LDF-3DP24-LDF-3D2CI22-L2D-4D2C22-ID2F2J2D2CI20-I2D2F-2JD4C19-KB2I2-2JB5C11-C6-LB5-JBD7C7-3C4-I2C6-2BA22CB-2A2-4BA3CA10C5A2-2B2A2-CBA-6A4C9A3-8A-G19A4-A-4A-2G19AB2(A2-)2(A-)2GB18ABC7-A-2G2B16A2GB9-2G2B16AG2B10-G-2B15AG2(2B11-2B17A)2B11-B19A11(12-20A)7-2D24-LD2F2-2D25-LDF2-2DP24-LDF2-2D2CI22-LD2F-4DI22-IDF2-4DK21-I2DF2-J2D2CI20-KB2F2-JFD4C19-LB6-BD7C8-2C4-I2C6-2B23CB-2A3-3B16C4ACA2B2A2-CB8A5C2(9A2-)18A2-8A2-G19A-2A6-A-2G2B17AAa10-2G3B16AG11-G-2B15A2G14-2B14ABG13-2B15A2BG11-2B17ABG11-B19A11(12-20A)8-D2(24-L2DF2-2D)P24-LD2F-I2DKI22-LD2F-4DI21-LD2F2-4DI21-LD2F3-FD2CI20-KB2F3-FB4C19-LB5-FBD7C9-C4-I2C6-2B23CB-2A2-4B12C8AC5A2-CB2A-5A5C18AB3-29A3-19A2-A3-A-2A2-3B16A12-5B15AAb11-B2-2B14ABG10-2H2-2B13A2B2G10-H2-2B13A2B2G9-H-B-15A2B2G11-2B17AGW11-10(19A13-)19A9-D24-KD2F3-2D23-K2DI3-2DP22-KD2F3-3DI21-KDFI3-3DI21-KD2F3-4DI20-ID2F3-3D3C19-IB2F3-FD5C2-C15-KB5-2BD8C8-C4-PCB5-3BA10C2-10CB-2A2-IC2BA10C8A2DAD3A-C2B-8A3C20A3-29A2-22A4-4A2-BH2B16A12-2H2B13A2B11-An2H-2B13A2B2G9-2H2-2B13A2B2G8-3H-3B13A2B2G8-2H2-B15A2BGW8-2H2-B17AW13-2(18A14-)5(I17A14-)18A3(14-16AIA)7-UE2D23-2D2F-2I3D22-RD2F2-E4D21-RDFI3-4DK20-RDF4-4DK20-ID2F3-J4DK19-ID2F2-2J3D3C2-C15-ID2F3-JBD8C14-I2B4-2B2D8C6-2C4-PB7-B2D9C4-6CP2CI3A4-C2A5CA3C2-5A6D4A2C20A6D7A2-17A3D2A2C6A2-17A2D3A5-2A3-2H2B13A2D2A10-Aq2H2B13A2B12-AoH2-B12A4BS9-H2N-3B11A3B2G9-2H2-3B12A4G8-3H2-2B13A2GAl14-AB13A2G15-15A2G15-2(I14A17-)15A3(17-I14A)4(17-15A)12-2E22-2DF4-3ED21-D3F2-3E3D19-KD2F3-4E2D2K2C15-K2D2F2-2JEF3D4C14-K2D2F2-3J2F2D6C13-D2F3-3JF2D7C13-R2F4-2JBD8C7-C4-KB6-2J2B8C6-3C2-K2B6-3B2D7C6-7CB2-A4-C2A2D3C4A4-4A5DI5ACE3A2D14A4DE9A-2AD14A4DA2C2A-3A2-2AD14A3DA6-4A-AHB14A2D2A11-2H2B12A3BAG10-NAgH3B11AB4G9-Ad4-G2B10AB4G9-NAd-3G3B8A2B2GMW9-T2-3G2B10ABAbM16-2B12AGM16-14A-G16-2(I13A18-)3(I12AI18-)2(13AI18-)2(14A18-)14A12-3E21-E2F4-4ED19-2D2F4-D3E2D3K15-RD2F4-DFE4D5C12-RD2F4-J3F3D5C11-R2D2F4-J3F2D6C12-D2F5-2J2FED6C7-C4-RBF5-2J2BE7C6-3C2-K2B6-J-2BE7C6-4CK2B9-2BED5CE6-5C2BI2-A4-CEA4D5A4-2A6DEI5AC3A4D11A6DE8AE2AE2D11A6D2C11A2D11A4DEC8-3AHA2D11A4DAC8-5A2B11A2D2B13-Ag-2BA3B7ADBGB2O12-2G5B7A2BGAbO13-3G4B7A2B2G14-3G4B7A2B16-GW-2B9A2(21-11A)21-AI9A21-2I9A21-I10A6(21-11A)15-4EDAj16-E2F7-4E2DK14-2D2F7-4E3DK13-2D2F7-4E2D4C11-R2DF5-F-2FDED5C11-RD2F5-J2-F2ED5C10-K2D2F5-J2-F2EB5C6-3CKD2B2F5-2J2BE3B4C6-4C3B10-2(B2E)2CE6-5CB11-C9E4-5C3B2I2A5-CAE3D2E3AK2-A8D4A2-ACA5ED2E7A8D10A3E4D7A6D2EC3A-7AE4D7A6D2A6-A3-4A3D7A4DEC-C8-5ABA2DB6A4D2B15-2G4B5A2D3B15-3G4B3A6B16-3GB-11B16-GMWG-2B3A2B-2BH21-7A25-2AI4A25-2I5A25-I6A8(25-7A)17-2ED2QAj6-D7-DE3F7-3EAEQ2F3-2D7-D4F7-12E9-D3F7-E-5E3CE10-2DIF8-F4E4C10-R2D2F9-3EB4C9-K3DFI9-4BE3CE4-5C3B2F9-4B5E4-4C3B12-4B5E4-D4CI13-C9E2-4CD3B-AI2A7-C11E5DB2DE4A2-5A4ED8E6DE5A-6A4E6D2E7D2A-3A-6A-AE14DAE2A2-2A-2A2-A-4A13D-A11-2A-3A2D2B7DBDB16-2G4B3D5BHAp16-4G2H-8B16-2GM2G-H-7BH22-4B2M2B2H397-EUQ5-DFEDEF6-5F7-FEU3QXT2F3E7-F2I2F7-4E2QEI5E7-E2F9-2E2-8E8-3E-I7-3F2E-5E8-D2EF-I8-3F2B5E4-7D11-3F-B6E2-E4C3BF10-2BF-B8E4CBAB12-5B9E4BI13-CE2B7E6CBIB-2AI2A6-C2A10E5D2B6A-7A7EA5E2D-2E6A-6A9EA3E4-8A2-7A7EA5D-5A-3A2-A-7A4E2A5D4A15-3AEB3E3D3BAe17-4GH9BAe16-5G2H7BHBH17-2M-2H3B3G4H20-2H2B3GW-HT21-H375-EU7-DFD-Q6-F-2F8-2E2-4QDF2E2F5-5F8-4EJQE2F3EFE5-4FI8-2E-12E3-5EF9-3F3E-9E2D4EF9-3F2B11E4DE3F10-F2B9EBF4B3F13-B-2EB5E4B16-3B2E2B5E4B15-C2I2(B3E)4C2B-2(I2A)7-I2AI3E2A8E2B7A2-6A4E5A9E6A2-6AE3AE4A8E3AI2A3-9AE5A7EA-2A2-A3-A4-8A2-5E2A17-A-BOB3A3E2B18-OGA2ONH3A3B19-GAGMG2HA2B3G-AeNH16-GM-4H4GM-ZTH19-4H3GM-HT22-2H374-A9-UEFXF17-2E4-XQ2D2EFX-F2-2FJI-F8-4E-3QF-2E2FE8F9-4ED15E3F9-4F3E-9E2D3E2F9-5F2E-6E3ID2E2F13-2F2EB6EF2-BI3F13-2FB-2B5E21-7BEA3B2-B14-AC-ABE3B2A7B2-4A7-3AC4E4AEB2EBEA-5A5-5AEAE6A5E2AC6A3-16A3E3AEA-4A4-15A2(2E2A)8-A4-2A-5A-9A14-A2-A3-BA-3ABA24-2BO3G25-HNB4GM21-M-4H2G2M25-HZ2-G27-T386-EFXF18-E4-2TQF-E2FX2F6-F9-2EA2-Q-2F2E5F-2FJ2F11-14E7F11-EF2E3-12E2F11-6F7EF2I3E-F12-5F4B3E-F2-IBF14-4F4BAEB4-2F15-I-3B2(-2B)21-C6BA4IB4-I-A8-AIC-C3E4A6BA2-4A5-5AC20A6-15A2E9A6-6A-5A2-3A-A2E2A-A7-A3-2A2-2A4-4A-2A16-A40-3O25-N2-2GMO25-HZ2-Am27-T418-2EX29-E3F7-2F10-EJ4-EF3E2F-F2UJ-3F10-3EU9E3F2-4F10-3F2EF5E2-3E2FE2F11-7F5E2F3E2F-F15-2F4BE2F-F-3F17-2F-3BEBF5-A17-I3-5B20-C2IBIBA-A6-A13-2A-I4E5A2(B2A)-AIA8-4AEA2E16A7-8AE17A2(7-9A)6-2A4-4A7-4A568-2EQ29-3EQ19-J5-7E7-2F10-3E2-5EF-4F-A3F11-AF2EU4FE10F12-A17FAF18-3FB3F-4FA23-2F31-B21-A-2I-A-2A5-IA14-A-AIAEI13A-I9-4A2E17A8-12A-11A8-8A6-7A-2A9-A-3A10-3A601-E-Q20-J6-E-E2QI19-EJ5-3EF-I22-J-U9F-FAF15-FE2JFI2F-6F22-5F3-3FA24-F58-AI-AI5-I15-2(A2I)5A3-5A12-21A12-9A-11A10-16A4-A11-10A4-2A555-
