model
size = 29 21 26, scale = 0.05, origin = -y
material deform = 1, fade = true, lighting = smooth, roughness = 0.3, metalness = 0.6
  colors = A:#E03C8A B:#86C166 C:#5DAC81 D:#1E88A8 E:#FB9966 F:#9B90C2 G:#FFB11B H:#EFBB24
voxels
58-B28-A643-H14-H562-A18-A10-2G14-2G11-2G14-2G10-2A-A12-A-2A11-A14-A448-A14-A11-A-4A8-4A-A9-A2B2A10-2A2BA10-DA-A10-A-AD10-BA-BA10-AB-AB9-3A-B10-B-3A11-D14-D13-A14-A359-3AB12-B3A10-3E-E8-E-3E9-D3A3B8-3B3AD7-D3A2BF8-F2B3AD7-D3AFBF8-FBF3AD6-2D3A2BF8-F2B3A2D7-4AB10-B4A9-2A-A12-A-2A2(12-A)13-A16-A329-5CB8-B5C2(8-7E)6-2D3A2B-A6-A-2B3A2D4-D-D2A-2B-A6-A-2B-2AD-D4-2D2A2-B-A6-A-B2-2A2D5-D-2A2-2BA6-A2B2-2A-D5-AD2A-2B10-2B-2ADA6-D2A-2B10-2B-2AD8-3AB12-B3A10-2A14-2A327-7CB8-B7C4-9EA6-A9E4-2D3A2-BA6-AB2-3A2D4-3D2(6-A)6-3D4-ED2(6-A)6-DE5-ED5-BA6-AB5-DE5-A6-B8-B6-A6-2A3-B10-B3-2A8-A2-B12-B2-A10-2AB12-B2A299-6C10-6C6-7CB8-B7C4-D2-3A3BA6-A3B3A2-D3-2D-A5-A6-A5-A-2D3-2D7-A6-A7-2D4-E7-A6-A7-E5-E6-BA6-AB6-E5-A6-B8-B6-A5-3A3-B10-B3-3A6-2A2-2B10-2B2-2A8-3AB12-B3A297-7CB8-B7C4-B7CB3A2E3AB7CB3-D2-AB4-A6-A4-BA2-D2-2D8-A6-A8-3D-D8-A6-A8-D3-2D7-A6-A7-2D4-D6-BA6-AB6-D5-A6-B8-B6-A5-2A4-B10-B4-2A6-BA2-2B10-2B2-AB8-3AB12-B3A10-B16-B3(11-A16-A)10-BA16-AB9-B18-B9-D18-D9-B18-B9-BA16-AB11-2AE10-E2A93-2D27-E551-A27-AB579-9(A27-A580-)A27-A579-2A27-A551-B27-2A579-2(B27-A580-)B27-A28-A522-
