model
size = 26 31 27, scale = 0.05, origin = -y
material deform = 1, fade = true, lighting = smooth, roughness = 0.3, metalness = 0.6
  colors = A:#604000 B:#E00 C:#200 D:#330 E:#A00 F:#111 G:#100 H:#EEE
voxels
340-4(22C4-)22C3-24B2-24B549-3(22C4-)4(C18A3C4-)C18A3C3-2B20A2B4(2-24B)445-4(22C4-)3(C12A9C4-)2(C20AC4-)C20AC3-3(2B20A2B2-)2(24B2-)24B168-8(4A22-)4A13-22C6(4-C12A9C)3(4-C20AC)3-3(2B20A2B2-)3(24B2-)24B140-8(8A18-)8A11-22C6(4-C12A9C)3(4-C20AC)3-3(2B20A2B2-)4(24B2-)24B112-8(12A14-)12A9-A21C5(4-13A9C)4-C12A9C3(4-C20AC)4-C2(20A2B2-2B)20A2B6(2-24B)84-6(16A10-)16A7-5(22A4-)22A2(2-24A)4(2-23AC)4-C20AC3-2(2B20A2B2-)6(24B2-)24B58-5(16A10-)16A7-5(22A4-)22A2-24A2-156A2-C20AC3-8(2B20A2B2-)24B58-5(16A10-)16A7-4(22A4-)22A2-24A2-50A-A2(2-24A)-77A2-C20AC4-C6(20A2B2-2B)20A2B3(2-24B)32-5(16A10-)16A7-4(22A4-)22A2-50A-A2-24A2-22A4-22A2-24A2-52A2-C20AC4-C20AC3-6(2B20A2B2-)2(24B2-)24B32-5(16A10-)16A7-4(22A4-)22A2-50A-A2-23A5-20A2-24A2-52A2-C23A2-C20AC4-C20AC3-6(2B20A2B2-)2(24B2-)24B32-5(16A10-)16A7-4(22A4-)22A2-50A-26A3-21A3-24A-27A2-C23A2-2(C20AC4-)C20AC3-6(2B20A2B2-)3(24B2-)24B6-5(16A10-)16A7-5(C21A4-)3(C23A2-)C21A4-2(C23A2-)4(C20AC4-)C20AC3-5(2B20A2B2-)3(24B2-)11B3E10B8-5(13A13-)13A8-15(C20AC4-)C20AC3-5(2B20A2B2-)3(24B2-)10B5E9B10-5(8A18-)8A11-6(C20AC4-)5(21AC4-)4(C20AC4-)C20AC3-5(2B20A2B2-)3(24B2-)10B2EB2E9B12-4(4A22-)4A14-19C6-C17A4C5(4-C20AC)5(4-22A)5(4-C20AC)4-C4(20A2B2-2B)20A2B3(2-24B)2-10B5E9B134-19C6-C17A4C5(4-C20AC)10(4-22A)4-C20AC3-4(2B20A2B2-)3(24B2-)11B3E10B110-16C8-19C6-C17A4C5(4-C20AC)10(4-22A)4-21AC3-2(2B20A2B2-)2(2B20C2B2-)3(24B2-)24B84-16C10-16C8-19C6-C17A4C5(4-C20AC)11(4-22A)3-2(2B20A2B2-)2(2B20C2B2-)2(24B2-)24B110-16C10-16C8-20C5-6(22C4-)3(22A4-)4A2D10A2D4A4-3AD2GD8AD2GD3A4-3ADHGD8ADGHD3A4-2A6D6A6D2A4(4-22A)3-24B2-2B20A2(2B2-2B20C)2B3(2-24B)245-6A18-10A96-6A20-6A22-2A24-2A75-F2-F15-7F4-7F57-24B2-2B20A2(2B2-2B20C)2B3(2-24B)375-6A20-6A22-2A24-2A169-24B2-2B20A2(2B2-2B20C)2B2(2-24B)403-2(2A24-)2A195-5(24B2-)24B403-2A24-2A221-4(24B2-)24B678-3(24B2-)24B704-2(24B2-)24B730-24B2-24B157-
