model
size = 29 32 31, scale = 0.05, origin = -y
material deform = 1, fade = true, lighting = smooth, roughness = 0.3, metalness = 0.6
  colors = A:#F99 B:#C39 C:#111 D:#09F E:#C09 F:#EEE G:#909 H:#06C I:#C06 J:#E00 K:#AAA L:#F69 M:#FC0 N:#FF0 O:#777
voxels
362-B28-B27-2(3B26-)BEB26-3B809-3(3B26-)E2B26-3B26-2BE26-3B925-3B26-E2B26-3B896-2(3B26-)BEB26-BEB867-4B3(24-5B)806-7C4(22-C5BC)22-7C775-9B19-11B16-15B13-17B10-BEB2E17B9-B2-B-7B2EBE2B10-B3-8B-B-2B22-B4-B504-6(22A7-)8A7B7A7-10A4B8A7-E21B7-22B2(6-23B)E6-B2EBE19B5-5B-9BE7B8-B2-B3-5B5-B14-B4-2B481-3(22A7-)A10B5A3B3A7-A11BE6B3A7-A10B2E6B3A7-A10BE9BA7-A10B2-8BA7-E10B2-9B7-11B2-9B6-12B2-10B4-13B2-10B5-7BG4B2-11B5-3B-2B-8BG3BE4B6-5B-3B4-B-3B-2B8-3B-3B8-2B12-B3-2B371-20A8-2(22A7-)7(A20BA7-)A10BE9BA7-11B2E9B7-12BE9B6-12B2-11B3-26B3-25B5-4BG2BG7BG4B2E3B4-3BG4BG2B-8B-3B6-BG5BG2B2-2B-B2(-2B)7-4BE3BGB2-B5-B2-B9-B3-2B313-17A11-20A8-2(22A7-)8(A20BA7-)2(22B7-)11B2E10B5-12B2E11B3-25B6-23B5-11B-3BG4B2E2B6-10B2-7BE3B6-E3BE4BGB-7BE2B9-2B3-B-B3-2B2-BE2-B16-B27-6A23-6C23-CK2CKC23-6C23-6A23-A4LA23-AL2ALA23-A4LA23-6A17-7A4B6A11-2A13B5A8-2A19B9(A7-A20B)A7-22B5-25B5-23BE5-25B3-13BE11B5-24B5-15BG7B7-10B-11B7-E3B2E3BGB-6BE3B10-B3-B2-B-3B-BE2-2B21-B20-10A3(19-10C)5(19-10A)15-4A10B3A11-2A13B5A8-2A19B4(A7-A20B)A5(7-22A)7-B20AB5-3B20A2B4-3B20A4B2-3B20A3B3-B-B20A3B4-11B2EBG9B5-14B-8B5-13B-11B6-E4B2E5B2-3B2E4B9-2B2-2B-2B2-B-B2-2B41-14A15-14C15-CK10CKC15-14C5(15-14A)13-17A11-20A8-6(22A7-)22A6-F22AF6-2(22A7-)B20AB6-2B20A2B3-4B20A4B2-3B20A4B-2B-B20A4B-2B-25B2-B-10BEB2G8B-2B-14B2-9B7-6BE16B10-B2-B-3B-4BE2B-B16-B5-B3-B12-16A3(13-16C)5(13-16A)12-17A11-20A8-6(22A7-)22A6-FB20AEF6-2(22A7-)B20AB5-3B20A2B3-4B20A4B2-3B20A4B-2B-B20A4B-2B2(-22B-2B2-B)-10BE2G9B7-22B8-5BE10BE4B9-E-2B3-B-E2-2B3-B12-16A13-6C2A8C13-6C2A7CK13-5C3A8C5(13-16A)12-17A11-20A8-22A7-22A5-2(26A3-25AN3-)26A3-AF22AFA5-2(22A7-)B20AB5-3B20A2B4-2(3B20A4B2-)3B20A4B-25B-28B-2B2-24B-2B5-21B8-8BG3BE6B11-E2-E5-E2-B3-2B12-16A13-6C2A8C13-K5C2A8C13-5C3A8C4(13-16A)13-17A11-18A10-19A9-22A5-26A3-24A-A4(3-26A)3-AF22AFA5-2(22A7-)B20AB5-3B20A2B3-4B20A4B-4B20A3BE2-3B20A4B2-24B-BE-25B-3B-24B-2B4-22B8-2BE5BG3BE6B11-E2-2E4-E2(2-2B)12-16A2(13-6C2A8C)13-5C3A8C3(13-16A)13-17A2(11-18A)10-19A7-26A3-24A-A3-26A5-2(22A7-)22A5-26A3-AF22AFA5-2(22A7-)B20AB5-3B2(20A2B3-4B)20A4B-4B20A5B-26BE-29B2-23BE3B3-21BE8-4B2(G3B)E6B11-2E2-EB3-2B2-2B-B13-16A13-6C2A8C13-6C2A7CK13-5C3A8C2(13-16A)13-17A2(11-18A)10-20A9-20A6-26A3-24A-A5-22A8-20A8-22A5-2(26A3-)AF22AFA5-2(22A7-)B20AB5-3B20A2B3-4B20A2B4-3B20A3BE-4B20A5B-E25BE-27BE3-26B4-G20BE8-BE2(2BG)4BE6B12-E3-B4-B3-B-B13-16A2(13-6C2A8C)13-5C3A8C2(13-16A)12-2(18A11-)19A2(9-20A)6-26A3-24A-A5-22A7-22A5-21A2-3A2(3-26A)4-FB20ABF6-2(22A7-)B20AB6-2B20A2B4-3B20A2B3-4B20A4B-4B20A5B-E27B2E27B2-26B4-22B7-G4BG2BG4BE4BG3B10-2B2-B4-2(B3-)B11-16A13-16C13-K13CKC13-16C2(13-16A)12-18A11-19A3(9-20A)6-O25A2(3-26A)5-22A5-26A3-26A5-22A6-FB20ABF6-2(22A7-)B20AB6-2B20AB4-4B20A2B4-3B20A4B2-3B20A4B3-2(E26B2-)26B4-21BE7-G4BG2BG4BE4BG3B11-B2-B3-2B2-2B3-B14-10A3(19-10C)2(19-10A)15-19A3(9-20A)8-7(22A7-)22A6-FB20ABF6-2(22A7-)B20AB6-2B20A2B3-4B20A2B4-3B20ABE4-3B20A2B5-E23BE4-E23B5-24B6-21BE7-BG3BG11BG3BE11-2(B2-)2B3-B4-B16-6A23-6C23-K4CK23-6C2(23-6A)16-2(20A9-)20A8-8(22A7-)22A6-F21ABF6-2(22A7-)B20AB6-2B20A2B3-4B20A2B4-3B20A2B3-4B20A2B5-26B3-24B5-23BE6-22B7-BG11BI3BG3BE10-EB2-B-2B3-2B2-2BE18-2A3(27-2C)27-2A18-19A10-2(20A9-)21A9(7-22A)6-F22AF6-2(22A7-)B20AB7-B20ABG4-B-B20A2B4-E-B20A3B2-4B20A2B3-27B3-25B5-24B6-22B8-G9B-I3BG3BEB10-E2-2B-B3-2B3-B156-19A10-20A9-21A5(7-22A)8-20A8-3(22A7-)22A6-F22AF6-2(22A7-)B20AB6-B21ABG4-3B20A2B4-3B20A3B3-E2B20ABG3-26BG2-27B5-24B5-23B7-3B2(E2B)I-I3BG2B2EB10-E2(2-B)3-B4-B129-16A11-19A10-20A8-4(22A7-)22A8-20A8-4(22A7-)22A6-F22AF6-2(22A7-)B20AB6-B22AE3-4B20ABG3-E3B20A3B3-E2B20A2B4-24BG3-26B5-24B6-11B-11B7-3BE2BE3B-I6BE2B10-2(B2-)B3-B4-B101-14A14-16A11-19A10-20A8-3(22A7-)22A8-20A8-5(22A7-)22A6-M22AM6-3(22A7-)B20AB5-3B20A2B4-3B20A3B3-E2B20A3B3-12BA12B3-13BA11BG4-25B6-10B2-I4BG5B7-3BE5B2-I9B10-E2(2-B)3-B4-B101-14A14-16A11-20A9-20A8-7(22A7-)3A5D6A5D3A7-2A7D4A7D2A2(7-A9D2A9DA)6-MA9D2A9DAM6-2(A9D2A9DA7-)2A7D4A7D2A7-3A5D6A5D3A7-22A6-B22AE4-E2B20A3B3-E25B3-25B4-12B-6BG5B6-6BG3B2-I3B3-B14-B2-B3-I6-B278-6J22-8J110-4A19-5F-4A-5F12-F5HF-2A-F5HF10-F7HF2-F7HF9-F7HF2-F7HF7-3F7D4F7D3F7-F7DF2-F7DF9-F7DF2-F7DF10-F5DF4-F5DF12-5F6-5F97-2(BG)4BE9-BG4B5-4BG3B2E-E7BG3B5-6BG3BE-E6BG4B6-6BG3B2-I3B3-2B12-2B2-B3-I431-4A25-4A26-2A263-2I27-I19-3B5-2I14-3B4-B5-I2-2B3-B9-2(2B3-)2I-2B3-2B10-2B3-B3-2I19-2(B3-)I432-2(2A27-)2A478-
