model
size = 26 29 24, scale = 0.05, origin = -y
material deform = 1, fade = true, lighting = smooth, roughness = 0.3, metalness = 0.6
  colors = A:#963 B:#5A3C00 C:#303 D:#2D1500 E:#001 F:#AAA
voxels
324-2A24-2A690-6(22B4-)22B500-19B5-11(22B4-)22B396-17B9-19B5-13(22B4-)22B168-6(6A20-)6A14-17B9-19B5-14(22B4-)22B140-6(10A16-)10A12-17B9-19B5-5(22B4-)10(B20AB4-)22B112-6(14A12-)14A10-2B14AB9-B16A2B5-2B19A14(B4-B20A)B2(4-22B)85-6(16A10-)2(16A9-B)16A2B5-2B19A14(B4-B20A)B3(4-22B)59-6(16A10-)2(16A9-B)16A2B5-2B19AB4-B20AB2-156A2-7(B20AB4-)2(22B4-)22B59-6(16A10-)17A2(8-18A)6-2B18ABA2-50A-131A2-7(B20AB4-)3(22B4-)22B33-5(16A10-)17A3(8-18A)4-50A-27A2-2(22A4-)22A2-52A2-7(B20AB4-)3(22B4-)22B33-4(16A10-)17A2(8-18A)7-20A6-20A3-50A-A2-22A5-20A5-22A2-78A2-7(B20AB4-)3(22B4-)22B33-3(16A10-)16A9-2(18A8-)19A2(6-20A)3-50A-A2-22A4-22A2-21A2-55A2-8(B20AB4-)4(22B4-)22B7-3(16A10-)16A9-18A8-19A3(6-20A)3-78A2-22A2-52A2-9(B20AB4-)4(22B4-)22B10-3(10A16-)10A12-19A3(6-20A)5-7(22A4-)9(B20AB4-)4(22B4-)22B12-3(6A20-)6A13-2(20A6-)20A5-8(22A4-)4(21AB4-)5(B20AB4-)4(22B4-)22B14-2(2A24-)2A15-19A7-2(20A6-)21A11(4-22A)4-21A5(B4-B20A)B4(4-22B)109-19A7-20A6-21A5(4-22A)5-20A5-6(22A4-)3(21AB4-)3(B20AB4-)3(22B4-)22B85-16A8-19A7-20A5-4(22A4-)22A5-20A5-10(22A4-)3(B20AB4-)2(22B4-)22B86-14A11-16A8-19A7-20A5-3(22A4-)22A5-20A5-11(22A4-)3(B20AB4-)22B4-22B112-14A11-16A8-20A6-20A5-8(22A4-)4A2C10A2C4A4-3AC2EC8AC2EC3A4-3ACFEC8ACEFC3A4-2A6C6A6C2A6(4-22A)5-20A299-6A19-8A97-6A20-6A22-2A24-2A75-D2-D15-7D4-7D560-6A20-6A22-2A24-2A674-2(2A24-)2A402-
