model
size = 18 22 15, scale = 0.05, origin = -y
material deform = 1, fade = true, lighting = smooth, roughness = 0.3, metalness = 0.6
  colors = A:#FFD000
voxels
132-5(6A12-)6A198-A16-2A15-3A3(14-4A)5(9-2A6-A)10-8A11-6A163-6(A17-)5(A7-2A8-)2(A8-)A9-9A10-6A146-6(A17-)A5-2A10-A5-2(2A16-)2A10-A5-2A10-A6-A10-A7-2A8-A8-9A10-6A128-6(A17-)A5-A11-A5-2(A17-)2(A11-A5-)A11-A6-3A8-A7-11A8-9A10-6A224-3(A17-)3(A12-A4-)4A9-A5-3A9-A6-12A7-9A222-A17-5(A12-A4-)4A9-A5-3A9-A6-12A7-11A8-8A204-6(A13-2A2-)4A10-2A2-4A10-2A4-14A3-15A2-16A-71A128-A17-5(A12-A4-)4A9-A5-3A9-A6-12A7-11A8-8A204-3(A17-)3(A12-A4-)4A9-A5-3A9-A6-12A7-9A108-6(A17-)A5-A11-A5-2(A17-)2(A11-A5-)A11-A6-3A8-A7-11A8-9A10-6A110-6(A17-)A5-2A10-A5-2(2A16-)2A10-A5-2A10-A6-A10-A7-2A8-A8-9A10-6A127-6(A17-)5(A7-2A8-)2(A8-)A9-9A10-6A162-A16-2A15-3A3(14-4A)5(9-2A5-2A)10-8A11-6A282-5(6A12-)6A168-
