model
size = 7 17 17, scale = 0.05, origin = -y
material deform = 1, fade = true, lighting = smooth, roughness = 0.3, metalness = 0.6
  colors = A:#FF0 B:#E00
voxels
42-3AB4A5B2A2(BA)B2A5B4AB3A70-3AB6AB3A35-3AB6AB3A42-3AB6AB3A63-3AB6AB3A28-3AB3A77-3AB3A21-3AB3A91-3AB3A14-3AB3A91-3AB3A7-3AB3A105-3AB4A5BA105-A5B2A3(BA)105-3(AB)2A5BA105-A5B4AB3A105-3AB3A7-3AB3A91-3AB3A14-3AB3A91-3AB3A21-3AB3A77-3AB3A28-3AB6AB3A63-3AB6AB3A42-3AB6AB3A35-3AB6AB3A70-3AB4A5B2A2(BA)B2A5B4AB3A42-
