model
size = 14 18 20, scale = 0.05, origin = -y
material deform = 1, fade = true, lighting = smooth, roughness = 0.3, metalness = 0.6
  colors = A:#EEE
voxels
20-3(2A12-)2A194-3(2A12-)2A208-3(2A12-)2A206-2(3(6A8-)6A10-3(2A12-)2A150-)7(6A8-)6A2(10-4A)10-3(2A12-)2A66-7(6A8-)6A2(10-4A)10-3(2A12-)2A64-4(10A4-)8A6-8A6(8-6A)8-4A10-4A2(12-2A)36-4(10A4-)8A6-8A6(8-6A)8-4A10-4A2(12-2A)34-3(84A2-3(10A4-)10A6-5(6A8-)6A10-2A12-2A6-)84A2-3(10A4-)10A6-5(6A8-)6A10-2A12-2A8-4(10A4-)8A6-8A6(8-6A)8-4A10-4A2(12-2A)36-4(10A4-)8A6-8A6(8-6A)8-4A10-4A2(12-2A)38-2(5(6A8-)6A2(10-4A)10-5(2A12-)2A66-)3(6A8-)6A10-3(2A12-)2A150-3(6A8-)6A10-3(2A12-)2A152-3(2A12-)2A202-
