model
size = 16 32 12, scale = 0.05, origin = -y
material deform = 1, fade = true, lighting = smooth, roughness = 0.3, metalness = 0.6
  colors = A:#111 B:#100 C:#888
voxels
2-2C5BA5B8-6B2(10-6A)10-4(7A9-)6A10-2(6A2(9-7A)9-)2(7A9-)7A2(8-8A)2(5-A2-8A)5-2(A2-9A4-)2A-9A5(4-2A2-8A)4-13A3-2C5BA5B324-6A9-10A6-3(11A5-)5(12A4-)4BA2-6B3-4BA2-6B308-7A8-11A5-6(12A4-)3(13A3-)13B3-13B9-6B3(10-6A)11-4A12-4A10-6A9-7A10-6A3(11-5A)3(10-6A)8-8A2(7-9A)7-10A5-11A4-11A5-5(12A4-)4(13A3-)12BA3-12BA8-B6-B8-A2(6-A7-2A)6-A2(7-3A4-2A)7-3A4-A8-3A2(4-A7-4A)4BA7-9A7-10A5(5-11A)10(3-13A)3-3(14A2-)14B2-14B6-B8-B2(6-A8-A)5-2A8-A5-2A14-3(2A7-A6-)2A7-A5-3A7BA5-11A5-12A4-12AB3-12A2(B2-13A)B-14AB-13B3(AB14-)2(10(A15-)B15-B6-B8-B2(6-A8-A)6(5-2A8-A)4-3A8BA2(4-12A)B2(3-13A)2(2-14A)-15A14B2(2A14-)AB14-)10(A15-)B15-B6-B8-B2(6-A8-A)6(5-2A8-A)4-3A8BA2(4-12A)B2(3-13A)2-14A3-13A-15A14B2(2A14-)AB14-11(A15-)A6-B8-B2(6-A8-A)6(5-2A8-A)4-3A8BA2(4-12A)B2(3-13A)2(2-14A)-15A14B2(2A14-)AB14-10(A15-)B15-B6-B8-B2(6-A8-A)4(5-2A7-2A)5-2A7-A6-2A7-A5-3A7BA5-11A5-12A4-12AB3-12A2(B2-13A)B-14A15B3(AB14-)10(A15-)B15-B7-B6-B3(8-A6-A)3(7-2A6-A)2(6-3A6-A)6-3A6BA6-10A6-9A5(6-10A)4-13(13A3-)2C5BA5B3-2C5BA5B2-
