model
size = 20 27 8, scale = 0.05, origin = -y
material deform = 1, fade = true, lighting = smooth, roughness = 0.3, metalness = 0.6
  colors = A:#667171 B:#7E8C8C C:#C18A26 D:#53380D E:#14141A F:#35353A G:#9F2E2E H:#000
voxels
49-2H17-A2HB15-2(3A3B14-)3A3B13-2(4A4B12-)4A4B11-5A5B9-6A6B7-7B7A5-2(5BH2B2AH5A4-)5BH2B2AH5A5-4BH2B2AH4A6-7B7A7-2(6B6A8-)4B4-4A7-4B6-4A6-3B8-3A6-2B10-2A5-2B12-2A4-B14-A210-4G16-4G96-4G16-4G395-2G2-2G14-2G2-2G94-2G2-2G14-2G2-2G393-2G4-2G12-2G4-2G92-2G4-2G12-2G4-2G2(392-G6-G12-G6-G92-G6-G12-G6-G)214-4E15-E4DE13-E6DE11-2(E8CE10-)E8DE9-E10D2(E8-E10C)E7-E12DE5-E14DE3-E16CE-E18C2(2E18D)E-E16CE2-E16CE3-2(E14DE4-)E14CE3-E6C4E6CE2-E5DE4-E5DE2-E4DE6-E4DE-E4CE8-E4C2E3CE10-E3CE-EDE12-EDE3-E14-E30-F2HF15-FA2HBF13-2(F3A3BF12-)F3A3BF11-2(F4A4BF10-)F4A4BF9-F5A5BF7-F6A6BF5-F7B7AF3-2(F8B8AF2-)F8B8AF3-F7B7AF4-F7B7AF5-2(F6B6AF6-)F4B4F4AF5-F4BF4-F4AF4-F3BF6-F3AF4-F2BF8-F2AF3-F2BF10-F2AF2-FBF12-FAF3-F14-F22-
