model
size = 32 31 27, scale = 0.05, origin = -y
material deform = 1, fade = true, lighting = smooth, roughness = 0.3, metalness = 0.6
  colors = A:#EEE B:#111 C:#90C D:#FF0 E:#3CF F:#0C0 G:#E00 H:#888 I:#96F J:#03C K:#050 L:#F60 M:#F36 N:#DDD
voxels
160-L8-L667-K8-K276-4D25-3L4D3L25-4D12-M8-M6-4D577-4F25-3K4F3K25-4F28-4F215-4D26-2L4D2L13-4G9-4D12-3M4G3M6-4D15-4G28-4G441-I8-I75-4F26-2K4F2K26-4F28-4F215-4D27-L4DL14-4G9-4D13-2M4G2M7-4D15-4G28-4G273-N8-N129-4C25-3I4C3I25-4C28-4C14-4F27-K4FK27-4F28-4F215-4D28-4D15-4G9-4D14-M4GM6-3A2D2(3A13-4G7-3A2-)3A229-4B25-3N4B3N25-4B28-4B68-4C26-2I4C2I26-4C28-4C14-2(4F28-)4F26-3A2F2(3A24-3A2-)3A182-2L16-2(4G28-)4G8-B4-B12-3A2G2(3A24-3A2-)3A178-4B26-2N4B2N26-4B28-4B68-4C27-I4CI27-4C28-4C47-2K92-B4-B266-2M92-B4-B211-4B27-N4BN27-4B28-4B68-2(4C28-)4C26-3A2C2(3A24-3A2-)3A658-2(4B28-)4B26-3A2B2(3A24-3A2-)3A35-2I92-B4-B724-2N92-B4-B377-I8-I953-4C25-3I4C3I25-4C28-4C371-B8-B511-4C26-2I4C2I26-4C28-4C342-4H25-3B4H3B25-4H28-4H450-4C27-I4CI27-4C28-4C342-4H26-2B4H2B26-4H28-4H450-2(4C28-)4C26-3A2C2(3A24-3A2-)3A276-4H27-B4HB27-4H28-4H483-2I92-B4-B309-2(4H28-)4H26-3A2H2(3A24-3A2-)3A125-J8-J724-2B92-B4-B129-4E25-3J4E3J25-4E28-4E892-4E26-2J4E2J26-4E28-4E526-J8-J356-4E27-J4EJ27-4E28-4E497-4E25-3J4E3J25-4E28-4E295-2(4E28-)4E26-3A2E2(3A24-3A2-)3A158-L8-L263-4E26-2J4E2J26-4E28-4E328-2J92-B4-B162-4D25-3L4D3L2(8-N)7-4D28-4D202-4E27-J4EJ27-4E28-4E408-M8-M172-4D14-4B8-2L4D2L9-3N4B3N7-4D14-4B10-4D14-4B184-2(4E28-)4E26-3A2E2(3A24-3A2-)3A76-K8-K227-4G25-3M4G3M25-4G28-4G111-4D14-4B9-L4DL11-2N4B2N8-4D14-4B10-4D14-4B217-2J92-B4-B80-4F25-3K4F3K25-4F28-4F166-4G26-2M4G2M26-4G28-4G111-4D14-4B10-4D13-N4BN9-4D14-4B8-3A2D3A12-4B8-3A2-3A24-3A2-3A349-4F26-2K4F2K26-4F28-4F166-4G27-M4GM27-4G28-4G129-4B11-2L15-4B28-4B26-3A2B3A7-B4-B11-3A2-3A24-3A2-3A331-4F27-K4FK27-4F28-4F166-2(4G28-)4G26-3A2G2(3A24-3A2-)3A96-2N92-B4-B364-2(4F28-)4F26-3A2F2(3A24-3A2-)3A133-2M92-B4-B626-2K92-B4-B322-
