model
size = 20 23 26, scale = 0.05, origin = -y
material deform = 1, fade = true, lighting = smooth, roughness = 0.3, metalness = 0.6
  colors = A:#6A4028 B:#EEA9A9 C:#F19483 D:#563F2E E:#F8C3CD F:#43341B
voxels
42-2(4B2-)4B4-2(4B2-)4B526-2(AF)A2F2(AF)A8-12A150-8A11-10A9-12A8-7A2(DA)D8-A2D4(AD)A10-4(AD)52-8C12-8C13-C4BC14-6B14-C4BC10-14FA4-FA12FAF4-2A12-2A28-8A11-10A10-5ADAD2A10-5(DA)31-4(AD)11-10A9-12A7-13AD6-14A7-D11A9-AD7AD12-3(AD)14-6C11-12C8-12C9-2(2C6B2C10-)2C6B2C7-F3A8E3AF3-A4F8A4FA7-4(AF)11-5(AF)9-D9ADA8-11AD8-D11A8-11AD8-6(DA)8-AD9AD7-AD11AD5-AD13AD4-D15A4-15AD5-D13A7-AD9AD10-4(AD)11-10C8-2(14C6-)2(14B6-)2C10B2C4-2A14E2A-20A-2AFAF9A2(FA)3-2AF11AFA5-2(13AD6-D13A6-)13AD5-2D13AD3-AD15AD2-D17A-18AD2AD18A-17AD3-D13ADA6-6(DA)8-12C6-2(16C4-)2(16B4-)2C12B2C2-F2-C12EC2-F20A-F16AF2-18A3-2(D15A4-15AD4-)D15A4-15AD3-D17A-60A-D17A3-15AD5-2(DA)D5A2(DA)7-12C6-2(16C4-)2(16B4-)2C12B2C2-F2-C12EC2-F20A-18A2-F16AF2-18A3-2(D15A4-15AD4-)D15A3-18A-40AD19A-17AD3-D15A5-AD9ADAD7-12C6-2(16C4-)2(16B4-)2C12B2C2-F2-C12EC2-F20A-F16AF2-18A2-F16AF3-2(15AD4-D15A4-)15AD3-D17A-59AD-D17A3-15AD5-D11ADA7-12C6-2(16C4-)2(16B4-)2C12B2C2-F2-C12EC2-F20A-18A2-F16AF2-18A3-2(D15A4-15AD4-)D15A3-18A-40AD19A-17AD3-D15A5-AD11AD7-12C6-2(16C4-)2(16B4-)BC12BCB2-F2-C12EC2-F20A-F16AF2-18A2-F16AF3-2(15AD4-D15A4-)15AD3-D17A-59AD-D17A3-15AD5-D11ADA8-10C7-2(16C4-)2(16B4-)BC12BCB2-F2-C12EC2-F20A-18A2-F16AF2-18A3-2(D15A4-15AD4-)D15A3-18A-40AD19A-17AD3-D15A5-AD11AD9-8C9-14C5-16C2(4-16B)4-BC12BCB2-F2-C12EC2-F20A-F16AF2-18A2-F16AF3-2(15AD4-D15A4-)15AD3-D17A-59AD-D17A3-15AD5-D11ADA10-6C10-14C5-CB12CBC2(4-16B)4-BC12BCB2-F2-C12EC2-F20A-18A2-F16AF2-18A3-2(D15A4-15AD4-)D15A3-18A-60A-17AD3-D15A5-AD11AD10-6C10-14C5-CB12CBC2(4-16B)4-BC12BCB2-F2-C12EC2-F20A-F16AF2-18A2-F16AF3-2(15AD4-D15A4-)15AD3-D17A-59AD-D17A3-15AD5-D11ADA10-6C10-14C6-B12CB5-2(16B4-)BC12BCB2-F2-C12EC2-F20A-18A2-F16AF2-18A3-2(D15A4-15AD4-)D15A3-18A-60A-17AD3-D15A5-AD11AD9-8C9-14C6-B12CB5-2(16B4-)BC12BCB2-F2-C12EC2-F20A-F16AF2-18A2-F16AF3-2(15AD4-D15A4-)15AD3-D17A-59AD-18A3-15AD5-DAD9ADA8-10C8-14C6-B12CB5-2(16B4-)BC12BCB2-F2-C12EC2-F20A-18A2-F16AF3-16A2(4-D15A4-15AD)4-D15A3-18A-60A-17AD3-D15A5-7(AD)7-12C7-B12CB6-B12CB5-2(16B4-)BC12BCB2-F2-C12EC2-F20A2-F14AF2(4-16A)5-13AD6-D13A6-13AD6-D13A5-15AD3-D17A2-18A-40A-18A3-15AD5-7(DA)6-14C2(6-B12CB)5-16B4-16B5-BE10BEB4-A2-C10EC2-A2-18A2-A-14A-A4-14A6-D11ADA7-D11A8-AD9AD8-DAD7ADA8-6(AD)7-AD9ADAD5-AD11ADAD3-AD15AD2-D15ADA2-AD15AD3-AD13AD5-7(AD)26-14C6-B12CB5-2B12C2B2(4-16B)5-BE10BEB5-F2-10E2-F4-16A4-A-6(AF)-A6-6(FA)9-2A4(FA)10-10A11-8A13-6A33-8A11-10A8-2(14A6-)3ADAD8A7-5(AD)2A47-14C6-B12CB5-2B12C2B2(4-16B)5-3EC6EC3E6-A12FA6-13FA6-A12-A285-16C2(4-B14CB)2(4-16B)5-2E10B2E27-6(AF)8-6(FA)286-4C-6C-4C2(4-B14CB)4-16B4-2(4E2B)4E7-10E347-4C-6C-4C2(4-B14CB)4-4B-6B-4B4-2(4E2-)4E364-4C-6C-4C2(4-B14CB)4-4B-6B-4B10-4E371-2C3-4C3-2C5-2(4B-6B-4B4-)3B3-4B3-3B382-
