model
size = 32 3 32, scale = 0.05, origin = -y
material deform = 1, fade = true, lighting = smooth, roughness = 0.3, metalness = 0.6
  colors = A:#FFF B:#DEDEDE C:#222832 D:#2C384A E:#2D2F32 F:#BE0909 G:#610404 H:#8A0707 I:#191919
voxels
65-I83-5D89-3DBAB3D85-3D3AB3A3D81-3D2A3(BA)B2AD81-DA3(B3A)2D79-2D2AB2(AF)3(AB)AD79-DB2(3AF)3AB2A2D77-2DABAF6(AB)D77-C2(3AB)3AF3ABAD76-2C2(BA)2(F2(AB)A)BD76-C2AB3(3AF)2A2D76-C4(AB)2(AFAB)AC77-C3(B3A)F3A2C76-E2C2A3(BA)2(FA)B2AC77-E-CA3(B3A)B2C76-2E-2C3A3(BA)B3AC77-E3-C2A2(B3A)B3C77-E3-3C3A2(BA)3C78-2E5-3CB2A3C80-E8-5C82-E6-3E85-IE3-4E56-I30-I5E27-I30-G30-HE2I29-2(H30-)2(GE3(G30-)HE3(H30-))GE3(G30-)HE2(H30-)I30-IEG30-I30-
