model
size = 31, scale = 0.05, origin = -y
material deform = 1, fade = true, lighting = smooth, roughness = 0.3, metalness = 0.6
  colors = A:#4B568B B:#4B4B4B C:#FFF
voxels
790-A30-2(A898-2(A30-))4(A30-)A773-3A28-3A29-4(A30-)A743-A29-2(3A28-)3A29-2(A30-)A680-3(3A28-)3A27-5A26-5A27-3A28-3A679-2(3A28-)3A27-4(5A26-)5A27-3A648-3A28-3A27-3(5A26-)5A25-2(7A24-)7A25-5A27-3A586-2(3A28-)3A27-5A25-6(7A24-)7A25-5A27-3A524-3A28-3A27-5A26-5A25-7A24-7A23-3(9A22-)9A23-7A24-7A25-5A26-5A28-A151-2(C2-)C24-C-3C-C4(24-7A)26-3A122-A29-3A28-3A27-5A25-7A23-6(9A22-)9A23-7A25-5A26-5A27-3A211-C7-C21-3(11A20-)11A22-7A25-5(5A26-)5A25-7A23-5(9A22-)9A21-11A21-9A23-7A25-5A26-5A27-3A209-C11-C18-4A5-4A18-3A7-3A18-2A9B2A18-13A19-11A23-3(5A26-)5A25-7A24-7A23-4(9A22-)9A21-2(11A20-)11A21-9A23-7A25-5A27-3A29-A178-2(C13-C16-)3A9-3A16-2A11-2A16-A2B9-2BA16-3A9B3A17-13A20-8(9A22-)9A21-4(11A20-)11A21-9A23-7A26-3A28-3A238-C15-C14-2A13-2A14-A15-A14-A3B9-3BA14-3A2B7-2B3A15-4A7B4A17-13A18-13A19-10(11A20-)11A21-9A23-7A25-5A27-3A29-A269-3A13-3A12-2A15-2A12-2AB13-B2A12-3AB11-B3A13-2A3B7-3B2A16-3A7B3A6(18-13A)19-4(11A20-)11A21-9A22-9A23-7A25-5A27-3A268-C17-C12-2A15-2A12-A17-A12-A2B13-2BA12-2AB13-B2A13-2AB11-B2A15-2A11B2A16-15A17-6(13A18-)13A19-2(11A20-)11A21-9A23-7A24-7A25-5A28-A237-2(C19-C10-)3A15-3A10-2A17-2A10-2AB15-B2A10-3AB13-B3A11-2A2B11-2B2A14-2A11B2A2(16-15A)17-6(13A18-)13A19-11A21-9A23-7A24-7A25-5A27-3A329-2A17-2A10-A19-A10-2AB15-B2A10-3AB13-B3A11-2A2B11-2B2A13-3A11B3A14-17A15-15A13-21A9-23A7-25A5-27A3-29A2-3A3-17A3-3A-3A5-15A5-5A7-13A7-3A10-9A10-A12-7A25-5A26-5A27-3A298-C19-C10-2A17-2A10-A19-A10-2AB15-B2A10-3AB13-B3A11-2A2B11-2B2A13-3A11B3A2(14-17A)15-15A16-15A17-13A18-13A19-2(11A20-)11A21-9A23-7A25-5A26-5A27-3A28-3A29-A237-2(C19-C10-)2A17-2A10-A19-A10-2AB15-B2A10-3AB13-B3A11-2A2B11-2B2A13-3A11B3A2(14-17A)15-7A-7A16-15A17-6A-6A18-13A19-5A-5A20-11A21-9A23-7A25-5A26-5A27-2(3A28-)3A29-A268-C19-C10-2A17-2A10-A19-A10-2AB15-B2A10-3AB13-B3A11-2A2B11-2B2A13-3A11B3A2(14-17A)15-15A16-15A17-13A18-13A19-11A20-11A22-7A25-5A26-5A27-2(3A28-)3A29-2(A30-)A268-2A17-2A10-A19-A10-2AB15-B2A10-3AB13-B3A11-2A2B11-2B2A13-3A11B3A14-17A15-15A16-15A17-13A18-13A19-11A20-11A21-9A24-5A26-5A27-2(3A28-)3A29-3(A30-)A206-2(C19-C10-)3A15-3A10-2A17-2A10-2AB15-B2A10-3AB13-B3A11-2A2B11-2B2A14-2A11B2A2(16-15A)17-13A18-13A19-11A20-11A21-9A23-7A25-5A27-2(3A28-)3A29-5(A30-)A207-C17-C12-2A15-2A12-A17-A12-2AB13-B2A12-2A2B11-2B2A13-A3B9-3BA15-3A9B3A16-15A17-13A18-13A19-11A20-11A21-9A23-7A25-5A27-3A28-3A29-8(A30-)A207-3A13-3A12-2A15-2A12-3A13-3A12-3AB11-B3A13-2A3B7-3B2A16-3C7B2(3C18-3C7A)3C19-11A20-11A21-9A23-7A25-5A27-3A122-7(A30-)A177-C15-C14-2A13-2A14-A15-A14-4A9-4A14-4AB7-B4A15-4A7B4A17-2(3C7A3C18-)3C7A3C20-9A23-7A25-5A27-3A246-6(A30-)A116-2(C13-C16-)3A9-3A16-2A11-2A16-3A9-3A16-3A9B3A17-13A18-3C7A3C18-B2C7A2CB18-3C7A3C22-5A27-3A370-5(A30-)A117-C11-C18-4A5-4A18-3A7-3A18-4A5B4A18-13A19-11A23-5A26-5A27-3A494-4(A30-)A88-C7-C21-2(11A20-)11A21-9A24-5A28-A619-2(A30-)A58-2(C2-)C24-C-3C-C2(24-7A)25-5A27-3A711-2(A30-)A15-
