model
size = 32 9 32, scale = 0.05, origin = -y
material deform = 1, fade = true, lighting = smooth, roughness = 0.3, metalness = 0.6
  colors = A:#FFD700
voxels
47-2A29-4A27-6A25-3A2-3A24-2A4-2A24-A6-A280-2(8A24-)8A213-2(3A8-3A18-)3A8-3A208-5(2A14-)2A205-2(A18-A12-)A18-A203-2(A20-A10-)A20-A201-2(A22-A8-)A22-A199-2(A24-A6-)A24-A197-2(A26-A4-)A26-A196-2(A26-A4-)A26-A195-2(2(A28-A2-)A28-A194-)2(A28-A2-)A28-A193-7(A2(30-2A)30-A192-)A2(30-2A)30-A193-2(2(A28-A2-)A28-A194-)2(A28-A2-)A28-A195-2(A26-A4-)A26-A196-2(A26-A4-)A26-A197-2(A24-A6-)A24-A199-2(A22-A8-)A22-A201-2(A20-A10-)A20-A203-2(A18-A12-)A18-A174-A14-A15-4(2A14-)A16-A146-A8-A20-2(3A8-3A18-)2A10-2A41-
