model
size = 14 26 7, scale = 0.05, origin = -y
material deform = 1, fade = true, lighting = smooth, roughness = 0.3, metalness = 0.6
  colors = A:#EEE B:#222 C:#111 D:#BDC0BA E:#DDD23B F:#FFFFFB
voxels
308-D12-3D10-ED-ED8-DA3-2DE2D2A3D296-D12-2D12-A104-2B11-4B9-2(6B8-)6B9-4B11-2B132-D12-DE12-E61-3AE9-AE2B-A7-A-4B-A5-E-B4-B-E3-A-B2-2B2-B-E2-AB2-4B2-BA2-E2-6B2-E3-A8BE5-A6BA7-E4BE9-E2BA117-D12-DA12-D75-4A9-6A7-8A5-10A3-12A2(2-5A2F5A)3-4A2F4A5-3A2F3A7-2A2F2A9-A2FA10-4D9-D4-D7-E2(6-D)6-A5-D8-D4-D8-D3-D10-D2-A10-E-D12-D89-4A9-E4-A7-A-4C-E5-A-C4-C-A3-E-C2-2C2-C-E2-AC2-4C2-C2(A2-)6C2-E3-E-6C-A5-A6CA7-A4CE9-A2CA277-2C11-4C9-2(6C8-)5C10-4C11-2C216-
