model
size = 21 14 26, scale = 0.05, origin = -y
material deform = 1, fade = true, lighting = smooth, roughness = 0.3, metalness = 0.6
  colors = A:#444 B:#B00 C:#A00 D:#D00 E:#777
voxels
104-3(A20-)A218-3D17-5D15-3D-3D14-2D3-2D14-3D-3D15-5D17-3D98-11A9-AE2A5-2AEA7-4A-5B-4A5-4A-7B-4A3-4(4A-9B-4A2-)4A-9B-4A3-4A-7B-4A5-4A-5B-4A7-AE2A5-2AEA9-11A10-11A9-13A7-2(5A5-)5A-5C-5A3-5A-2C3-2C-5A2-4A-2C5-2C-4A2-3(4A-C7-C-5A-)4A-2C5-2C2(-5A)-2C3-2C-5A3-5A-5C-2(5A5-)5A7-13A10-10A10-12A8-4A5C5A6-4AC5-C5A4-4AC7-C5A2-2(4AC9-C5A-)4A2(C9-C10A)C9-C5A2-4AC7-C5A4-4AC5-C5A6-4A5C5A8-12A19-2(A21-)A20-2A19-3A18-4A17-4(5A16-)3A18-2A19-2A18-2A40-2(A21-)A20-2A19-3A18-4(4A17-)3A18-2A2(19-A)62-2(A21-)A20-2A19-4(3A18-)2A2(19-A)104-2(A21-)A20-4(2A19-)A19-A124-3(A21-)3(A20-)2(A19-)A146-2(A21-)3(A20-)A19-A166-2(A21-)3(A20-)A19-A188-2(A21-3(A20-)A208-)A21-3(3(A20-)A230-)3(A20-)5(A251-2(A20-))A230-2(3(A20-)A209-)3(A20-)A126-
