model
size = 22 32 27, scale = 0.05, origin = -y
material deform = 1, fade = true, lighting = smooth, roughness = 0.3, metalness = 0.6
  colors = A:#0F3 B:#6C3 C:#6F6
voxels
45-25(B18-B2-)B18-B134-2(B18-B2-)23(C18-C2-)2(B18-B2-)B18-B112-15(B18-B2-)11(C18-C2-)B18-B2-B18-B134-2(B18-B2-)23(C18-C2-)B18-B2-B18-B134-13(B18-B2-)12(C18-C2-)B18-B200-4(B18-B2-)18(C18-C2-)B18-B164-4A17-6A15-2(8A14-)8A8-2B5-6A5-2B3-B6-4A6-B3(4-2B14-2B)4(4-B16-B)5(4-C16-C)3-2C16-2C2(2-C18-C)3(2-B18-B)119-6A15-8A13-10A11-4(12A10-)12A11-10A13-8A15-6A11-2B12-2B5(6-C14-C)5-2C14-2C3(4-B16-B)3-2B16-2B3(2-B18-B)140-8A13-10A11-12A9-6(14A8-)14A9-12A11-10A10-B2-8A2-B3(8-C12-C)7-2B12-2B6-B14-B5-2B14-2B4-B16-B251-8A12-12A9-14A8-14A7-6(16A6-)16A7-2(14A8-)B12AB8-C2-8A2-C8-C12-C2(8-B12-B)297-8A12-12A9-14A7-16A6-16A5-6(18A4-)18A5-16A6-16A7-14A8-B12AB8-B2-8A2-B8-B12-B298-6A14-10A10-14A7-16A6-16A5-18A4-18A3-4(20A2-)20A3-18A4-18A5-16A6-16A7-14A10-10A14-6A301-8A12-12A9-14A7-16A5-18A4-18A3-6(20A2-)20A3-18A4-18A5-16A7-14A9-12A12-8A280-4A15-10A10-14A7-16A5-18A4-18A3-2(20A2-)20A-66A-2(20A2-)20A3-18A4-18A5-16A7-14A10-10A15-4A259-6A13-12A9-14A7-16A5-18A3-2(20A2-)20A-110A-2(20A2-)20A3-18A5-16A7-14A9-12A13-6A257-2(8A12-12A9-14A7-16A5-18A3-20A2-20A-154A-20A2-20A3-18A5-16A7-14A9-12A12-8A256-)8A12-12A9-14A7-16A5-18A3-20A2-20A-154A-20A2-20A3-18A5-16A7-14A9-12A12-8A257-6A13-12A9-14A7-16A5-18A3-2(20A2-)20A-110A-2(20A2-)20A3-18A5-16A7-14A9-12A13-6A259-4A15-10A10-14A7-16A5-18A4-18A3-2(20A2-)20A-66A-2(20A2-)20A3-18A4-18A5-16A7-14A10-10A15-4A280-8A12-12A9-14A7-16A5-18A4-18A3-6(20A2-)20A3-18A4-18A5-16A7-14A9-12A12-8A301-6A14-10A10-14A7-16A6-16A5-18A4-18A3-4(20A2-)20A3-18A4-18A5-16A6-16A7-14A10-10A14-6A323-8A12-12A9-14A7-16A6-16A5-6(18A4-)18A5-16A6-16A7-14A9-12A12-8A366-8A12-12A9-14A8-14A7-6(16A6-)16A7-14A8-14A9-12A12-8A410-8A13-10A11-12A9-6(14A8-)14A9-12A11-10A13-8A455-6A15-8A13-10A11-4(12A10-)12A11-10A13-8A15-6A523-4A17-6A15-2(8A14-)8A15-6A17-4A405-
