model
size = 32, scale = 0.05, origin = -y
material deform = 1, fade = true, lighting = smooth, roughness = 0.3, metalness = 0.6
  colors = A:#360 B:#960 C:#0F3
voxels
12-10A14-24A7-26A5-28A3-30A-544A-2(30A2-)30A3-2(28A4-)28A5-2(26A6-)26A11-16A842-A11-4B11-A4-3A6-3AB2CB3A6-3A4-4A2-6A4B6A2-4A5-9A2B4A2B9A7-6A2B8A2B6A10-BA2B12A2BAB807-A12-4A12-A2-4A6-10A6-4A2-5A2-16A2-5A3-28A5-26A6-26A7-B22AB804-2A2(28-4A)28-2A-A28-A3-28A5-26A6-26A803-2A3(28-4A)28-2A-2A26-2A3-28A5-26A803-2A3(28-4A)28-5A26-3A-30A3-28A803-A28-A-2(2A2(28-4A)28-5A26-3A-30A3-28A834-)3(2A2(28-4A)28-5A26-35A-30A833-)2A2(28-4A)28-5A26-35A-30A865-7(2A28-4A28-5A26-67A864-)2A28-4A28-5A26-67A832-2A2(28-4A)28-5A26-67A800-2A3(28-4A)28-5A26-35A-30A769-2A4(28-4A)28-5A26-35A-30A737-2A5(28-4A)28-5A26-35A-30A705-2A6(28-4A)28-5A26-35A-30A673-2A7(28-4A)28-5A26-3A-30A3-28A514-2A12(28-4A)28-5A26-3A-30A3-28A322-2A18(28-4A)28-5A26-3A-30A3-28A130-2A24(28-4A)28-2A-2A26-2A3-28A5-26A36-A28-A-2A26(28-4A)28-2A-2A26-2A3-28A5-26A36-A28-A-2A24(28-4A)28-2A-2(A28-A2-)30A3-28A5-26A6-26A5-28A3-30A-672A-2(30A2-)30A3-2(28A4-)28A5-26A11-16A8-
