model
size = 32, scale = 0.05, origin = -y
material deform = 1, fade = true, lighting = smooth, roughness = 0.3, metalness = 0.6
  colors = A:#DDD B:#FC9 C:#F96 D:#777 E:#F99 F:#EEE G:#0FF H:#111
voxels
12-10A14-24A7-26A5-28A3-30A-544A-2(30A2-)30A3-2(28A4-)28A5-2(26A6-)26A11-16A12-8A8-8A7-6A14-6A5-4A20-4A3-4A22-4A-3A26-5A2(28-4A)28-3A2(30-2A)13-4B13-8(2A14-2B14-)3A4(28-4A)28-2A-A28-A2-A28-A3-A11-4A11-A4-3A6-10A6-3A4-4A2-16A2-4A5-26A7-24A10-20A9-11A4-11A5-10A2-4B2-10A3-8A5-4B5-8A-6A20-11A22-8A26-6A10-6E10-6A8-10E8-5A2(28-4A)11-6B11-6(4A12-4B12-)2(4A13-2B13-)5A2(12-2B12-6A)-10D-2B-10D-6A2-9D4-9D2-2(6A26-)6A11-4A11-3A-4A6-10A6-4A2-5A2-16A2-5A3-28A5-26A6-26A7-24A6-28A3-11A-6B-11A-9A2-10B2-15A3-C5B2C5BC3-11A3-BC12BCB3-8A4-3BC4B2C4BC3B4-6A3-20B3-6A3-4BC10BC4B3-5A2(5-4BC3B2C3BC4B5-4A)5-5BC6BC5B2(5-4A5-6BC4BC6B)5-4A4-7BC4BC7B4-4A2-9BC4BC9B2-4A-6B2C2BC4BC2B2C6B-4A9BCBC4BCBC9B4A5B4-4C2B4C4-5B4A4B2-2G2-3C2B3C2-2G2-4B5A2B2-G2HG2-2C2B2C2-G2HG2-2B6A2B2-GFHG2-2C2B2C2-GFHG2-2B6A2B2C4B2CBC2BCB2C4B2C2B2(6A11B4C11B)6A2-9B4C9B2-6A4-3B4C4A4C3B4-8A3-3C10A3C3-11A2-16A2-6A-30A3-28A5-26A6-26A4-30A-12AC6BC21A-C10BC-15A3-14B3-11A3-16B3-8A3-C18BC3-2(6A2-C20BC2-)5A3-2C18B2C3-4(4A2-3C18B3C2-)4A2-2C20B2C2-4A2-24B2-4AC26BC4A28B4A5B4C10B4C5B4A4BCF2BFC8BCF2BFC4B5A2(2BCF4BFC6BCF4BFC2B6A)3(26B6A)-C22BC-6A3-C7B4A7BC3-8A3-C2B10A2BC3-11A2-16A2-38A-30A3-28A5-26A3-44A8B21A-12B-14AC3-14B3-C10A-2C16B2C-8A2-C20BC2-6A-C22BC-6A2C22B2C5A3C22B3C6(4A2C24B2C)4(4A28B)5A5(26B6A)C24BC6A-2C8B4A8B2C-8A-2C3B10A3B2C-11A2-16A2-70A-30A3-28A2-44A8B21AC12BC15A3C14B3C11AC20BC8A2C22B2C6AC24BC6A26B5A10(28B4A)28B5A6(26B6A)C10B4A10BC8AC5B10A5BC11A2C16A2C70A-30A3-28A2-960A-30A3-28A2-4(992A-30A-)10208A3(-30A-992A)-30A-3(960A-30A3-28A2-)928A-30A3-28A5-26A4-30A-896A-30A3-28A5-26A5-28A3-30A-800A-2(30A2-)30A3-28A5-26A6-26A5-28A3-30A-672A-2(30A2-)30A3-2(28A4-)28A5-26A11-16A8-
