model
size = 16 14 31, scale = 0.05, origin = -y
material deform = 1, fade = true, lighting = smooth, roughness = 0.3, metalness = 0.6
  colors = A:#CF3 B:#FF0 C:#9CF D:#111 E:#F3F F:#EEE
voxels
3(D-)4D3(-D)3(A-)4A2(-A)-6A6F10AF4-5(F10AF-2A-)F21A65-14D2-AB12A-2AB11AB2A2B3A4E4(4AB2A2C3AE2AE)4AB2A2CB2(2AE)4AB2AC12ABA-3(E12-E2-)E12-E-5D2-2D2-5D2AB11AB4A10-ABA-4(DA10-AD2-)DA10-AD-3A10-AB4A10-ABA-E3(12-A2-A)12-E3-D3-E2-E3-D3-14A-2A7(12-4A)12-2A-3(E12-E2-)E12-E-6D4E6D14AB3A12-2A-4(D12-D2-)D12-D-2A12-4A12-2A-E3(12-A2-A)12-E3-D2(2-2E)2-D3-14A-2A7(12-4A)12-2A-3(E12-E2-)E12-E-5DE4-E5D14AB3A12-BA-4(D12-D2-)D12-D-2A12-4A12-2A-E3(12-A2-A)12-E3-D2-E-2E-E2-D3-14A-2A7(12-4A)12-2A-3(E12-E2-)E12-E-5D6E5DAB12ABAEBA10-ABEAB6(A10-AB2AC)A10-ABA-E3(12-A2-A)12-E3-D2-E4-E2-D3-AB12A-A2BA8-2ABAECBA8-2ABEA5(2CA8-2AB2A)CAE8-EABA-3(E12-E2-)E12-E-5D6E5DE3B10ABEA3BA6-3AB2A3BA6-3ABAE3CA6-3ABEA3(3CA6-3AB2A)3CA6-3AB4AEA6-AE3A66-D2-E4-E2-D3-AB2AB4AB2ABA-E2B2C6A4BE-DB2C6A2CBD-A4C6A4BA-D3C6A3BD-A4C6A4BA-D3C6A3CD-A4C6A4B4AE8AE3A64-5D6E5DA14B2A14BA-D12BD-A10C4BA-D9C3BD-E10C4BE-D3C6B3CD-A8C6B4AE8AE3A66-D2-E4-E2-D3-AB2AB4AB2ABA-A2B2CB3C6BA-DB2CB6CBCD-E10C4BE-D9C3BD-A10C4BA-D3C6B3CD-A8C6B4AE8AE3A64-5D6E5DE14BEA14BA-D12BD-A10C4BA-D9C3BD-A10C4BA-D3C6B3CD-E8C6BE3AE8AE3A66-D2-E4-E2-D3-AB2AB4AB2ABA-E2B2CB3C6BEA2B2CB3C6B2A10C4B2AB9C4BAE10C4BEAB3C10B2A8C6BA4EA6EA4E64-5D6E5D2A13B2A14BAE14BEA10C4B2AB9C4B2A10C4BAEB3C10BEA8C6B4AE8AE3A66-D2-E4-E2-D3-AB2AB4AB2ABA-A5B3C6B2A5B3C6BAE10C4BEA10C4B2A3CD6CD3B2A3CD6BD3BA4ED6EDB3E3-ED6-DE67-5D6E5D2A13B2(2A14B)2A10C4BAE10C4BEA3CD6CD3B5AD6AD4A3-AD6-DA85-D-DE4-ED-D3-ABA2B4A2BABA-A2(2BC2B3C6B2A)10C4B2A10C4BA4ED6ED4E3-ED6-DE99-5D6E5D2A13B3(2A14B)4A2B6A2B3A3-AD6-DA117-D3-E2-E3-D3-AB3AB2AB3ABA-A2(14B2A)14BA-2A2B6A2B2A4-AD6-DA115-6D4E6D2A13B3(2A14B)A-A3E2A2E2A3EA131-2D-D-2E-D-2D4-2(AB)A2BABA2B3-2(2A8BCBCA2-)2A2B6D3BA3-3A6-3A131-2D2-D4-D2-2D2-EB2AB4AB2AB2(E2-E9BCBC)E2-E12BE3-12A133-10D6-10B5-2(A10BA4-)A2B6D2BA5-2A6-2A133-2(D2-D4-)3AB4AB3A2(4-A8BCBA)4-A10BA5-10A134-2(D-)2D2(-D)6-EAB4ABA2(E6-E7BC)E6-EB6DBE7-A6-A136-8D4(8-A6BA)8-8A136-8D8-A6BA2(8-8A)8-A6BA9-6A138-6F10-6F42-6F10-6F133-
