model
size = 16 14 31, scale = 0.05, origin = -y
material deform = 1, fade = true, lighting = smooth, roughness = 0.3, metalness = 0.6
  colors = A:#FF0 B:#9CF C:#111 D:#E00 E:#EEE
voxels
3(C-)4C3(-C)3(A-)4A2(-A)-6A6E10AE4-5(E10AE-2A-)E21A65-14C2-14A-22A4D5(7A2B3AD2AD)7AB14A-3(D12-D2-)D12-D-5C2-2C2-5C19A10-3A-4(CA10-AC2-)CA10-AC-3A10-4ABA10-3A-D2(12-A2-A)12-A2-D12-A3-C3-D2-D3-C3-14A-2A7(12-4A)12-2A-3(D12-D2-)D12-D-6C4D6C18A12-2A-4(C12-C2-)C12-C-2A12-4A12-2A-D2(12-A2-A)12-A2-D12-A3-C2(2-2D)2-C3-14A-2A7(12-4A)12-2A-3(D12-D2-)D12-D-5CD4-D5C18A12-2A-4(C12-C2-)C12-C-2A12-4A12-2A-D2(12-A2-A)12-A2-D12-A3-C2-D-2D-D2-C3-14A-2A7(12-4A)12-2A-3(D12-D2-)D12-D-5C6D5C16AD2A10-2AD3A6(10-4ABA)10-3A-D2(12-A2-A)12-A2-D12-A3-C2-D4-D2-C3-14A-4A8-4ADB2A8-3ADA5(2BA8-5A)BAD8-D3A-3(D12-D2-)D12-D-5C6D5CD14AD5A6-10A6-5AD3BA6-4ADA3(3BA6-6A)3BA6-8ADA6-AD3A66-C2-D4-D2-C3-14A-D2A2B10AD-CA2B6A2BAC-A4B11A-C3B9AC-A4B11A-C3B6A3BC-A5B13AD8AD3A64-5C6D5C32A-C12AC-A10B5A-C9B3AC-D10B4AD-C3B6A3BC-A8B10AD8AD3A66-C2-D4-D2-C3-14A-3A2BA3B7A-CA2BA6BABC-D10B4AD-C9B3AC-A10B5A-C3B6A3BC-A8B10AD8AD3A64-5C6D5CD14AD16A-C12AC-A10B5A-C9B3AC-A10B5A-C3B6A3BC-D8B6AD3AD8AD3A66-C2-D4-D2-C3-14A-D2A2BA3B6AD3A2BA3B8A10B7A9B5AD10B4AD2A3B12A8B7A4DA6DA4D64-5C6D5C32AD14ADA10B7A9B6A10B5ADA3B10ADA8B10AD8AD3A66-C2-D4-D2-C3-14A-6A3B13A3B7AD10B4ADA10B6A3BC6BC5A3BC6AC4A3DBC6DCA3D3-DC6-CD67-5C6D5C49A10B5AD10B4ADA3BC6BC7ABC6AC4A3-AC6-CA85-C-CD4-DC-C3-14A-3AB2A3B10AB2A3B8A10B6A10B5A3DBC6DCA3D3-DC6-CD99-5C6D5C80A3-AC6-CA117-C3-D2-D3-C3-14A-48A-14A4-AC6-CA115-6C4D6C64A-A3D2A2D2A3DA131-2C-C-2D-C-2C4-12A3-2(10A2(BA)2-)4A6C4A3-3A6-3A131-2C2-C4-C2-2C2-D12A2(D2-D9ABAB)D2-D12AD3-12A133-10C6-10A5-2(12A4-)3A6C3A5-2A6-2A133-2(C2-C4-)12A2(4-9AB2A)4-12A5-10A134-2(C-)2C2(-C)6-D8A2(D6-D7AB)D6-DA6CAD7-A6-A136-8C5(8-8A)136-8C4(8-8A)9-6A138-6E10-6E42-6E10-6E133-
