model
size = 10 13 16, scale = 0.05, origin = -y
material deform = 1, fade = true, lighting = smooth, roughness = 0.3, metalness = 0.6
  colors = A:#DDD B:#D00 C:#E00 D:#111 E:#EEE
voxels
74-2E8-2E74-60A20B21-A9-A6-A2-A6-A-50AD8ADB8A11B38-A11-2(50AD8ADB8A11B50-)60AB8A11B4-2C44-74A2C4A4-2C8-2C34-80A14-2C34-5(80A50-)80A28-2(A2-A6-)A-80A31-A18-80A20-
