model
size = 20 20 21, scale = 0.05, origin = -y
material deform = 1, fade = true, lighting = smooth, roughness = 0.3, metalness = 0.6
  colors = A:#EEE B:#111
voxels
189-2A18-2A296-6A13-8A11-5(10A10-)10A11-8A13-6A194-6A12-10A10-10A9-5(12A8-)12A9-10A10-10A12-6A153-8A11-10A9-12A7-7(14A6-)14A7-12A9-10A11-8A113-6A12-10A9-12A7-14A6-14A5-5(16A4-)16A5-14A6-14A7-12A9-10A12-6A50-A12-A6-A4-4A4-A6-A-10A-A2(6-14A)5-2(16A4-)16A3-3(18A2-)18A3-2(16A4-)16A5-14A7-12A9-10A13-4A54-8A11-10A8-14A6-14A5-16A3-7(18A2-)18A3-16A5-14A6-14A8-10A11-8A35-2A15-8A10-12A7-14A5-16A4-16A3-2(18A2-)18A-40A-2(18A2-)18A3-16A4-16A5-14A7-12A10-8A15-2A17-4A13-10A9-12A7-14A5-16A3-2(18A2-)18A-80A-2(18A2-)18A3-16A5-14A7-12A9-10A13-4A15-2(6A12-10A8-14A5-16A4-16A3-18A2-18A-120A-18A2-18A3-16A4-16A5-14A8-10A12-6A14-)6A12-10A8-14A5-16A4-16A3-18A2-18A-120A-18A2-18A3-16A4-16A5-14A8-10A12-6A15-4A13-10A9-12A7-14A5-16A3-2(18A2-)18A-80A-2(18A2-)18A3-16A5-14A7-12A9-10A13-4A17-2A15-8A10-12A7-14A5-16A4-16A3-2(18A2-)18A-40A-2(18A2-)18A3-16A4-16A5-14A7-12A10-8A15-2A35-8A11-10A8-14A6-14A5-16A3-7(18A2-)18A3-16A5-14A6-14A8-10A11-8A29-A12-A6-A4-4A4-A6-A-10A-A2(6-14A)5-2(16A4-)16A3-3(18A2-)18A3-2(16A4-)16A5-14A7-12A9-10A13-4A75-6A12-10A9-12A7-14A6-14A5-5(16A4-)16A5-14A6-14A7-12A9-10A12-6A113-8A11-10A9-12A7-7(14A6-)14A7-12A9-10A11-8A153-6A12-10A10-10A9-5(12A8-)12A9-10A10-10A12-6A194-6A13-8A11-5(10A10-)10A11-8A13-6A255-4A15-2A2B2A14-2A2B2A13-A2B2A2BA12-8A13-6A147-
