model
size = 32 10 30, scale = 0.05, origin = -y
material deform = 1, fade = true, lighting = smooth, roughness = 0.3, metalness = 0.6
  colors = A:#A6FF32 B:#000
voxels
8-6A6-6A211-6A25-8A19-7A4-7A171-A22-A263-2A22-2A2(6-3A20-3A)231-A22-A7-2A22-2A5-3A22-3A4-3A22-3A260-2(2A24-2A4-)2A24-2A259-2(3A24-3A2-)2A26-2A257-3A26-3A-2A26-2A257-3(BA28-AB2A28-2A256-2A28-2ABA28-AB256-)BA28-AB2A28-2A224-BA28-AB2A28-2A256-2A28-2ABA28-AB256-BA28-AB2A28-2A257-A28-A2-A28-A258-B28-B2-B28-B258-2A26-2A2-2A26-2A226-BA26-AB2(2-2A26-2A)226-2A26-2A2-BA26-AB2-2A26-2A226-BA26-AB2-2A26-2A258-2A26-2A2-BA26-AB258-BA26-AB2-2A26-2A258-2A26-2A2-BA26-AB259-2A24-2A4-2A24-2A73-5A8-5A12-7A8-7A9-3A18-3A8-2A7-A4-A7-2A2(8-A)4-A8-A6-2A24-2A4-BA24-AB4-2A24-2A73-5A8-5A12-A5B2A6-2A5BA9-10A4-10A8-6A2(2-3A)2-6A7-5A5-2A2-2A5-5A5-B4A6-2A2-2A6-4AB4-4A7-2A2-2A7-4A4-B3A20-3AB6-3A18-3A80-A6-A21-5A4-5A16-3A4BA2-A4B3A13-A7BA2-A7BA10-2A8BA2-A8B2A7-2A8B6A8B2A6-A8B8A8BA7-10A4-10A10-2(7A6-)
