model
size = 22 14 18, scale = 0.05, origin = -y
material deform = 1, fade = true, lighting = smooth, roughness = 0.3, metalness = 0.6
  colors = A:#111 B:#BBB C:#90F D:#03F E:#0C0 F:#F60 G:#FF3 H:#E00
voxels
4-3A10-3A5-3B10-3B7(6-3A10-3A)6-3G10-3G6-3A10-3A6-3F10-3F6-3A10-3A6-3H10-3H5-5B8-5B2(4-5A8-5A)5-3A10-3A6-3A10-3A202-7B6-7B2(2-7A6-7A)3-5A8-5A4-5A8-5A5-3A10-3A180-7B6-7B4(2-7A6-7A)3-5A8-5A178-9B4-9B9C4-18C4-9C-7C6-7C2-7C6-7C3-5C8-5C178-9B4-9B9A4-18A4-9A-7A6-7A2-7A6-7A3-5A8-5A178-9B4-9B9D4-18D4-9D-7D6-7D2-7D6-7D3-5D8-5D178-9B4-9B9A4-18A4-9A-7A6-7A2-7A6-7A3-5A8-5A178-9B4-9B9E4-18E4-9E-7E6-7E2-7E6-7E3-5E8-5E2(178-9B4-9B9A4-18A4-9A-7A6-7A2-7A6-7A3-5A8-5A)5-3A10-3A157-9B4-9B9A4-18A4-9A-7A6-7A2-7A6-7A3-5A8-5A4-5A8-5A5-3A10-3A135-9B4-9B9A4-18A4-9A-2(7A6-7A2-)7A6-7A3-5A8-5A4-5A8-5A5-3G10-3G6-3A10-3A6-3F10-3F6-3A10-3A6-3H10-3H6-3A10-3A3-9B4-9B9A4-18A4-9A-4(7A6-7A2-)6A8-5A4-5G8-5G4-5A8-5A4-5F8-5F4-5A8-5A4-5H8-5H4-5A8-5A3-7B6-7B7(2-7A6-7A)2-7G6-7G2-7A6-7A2-7F6-7F2-7A6-7A2-7H6-7H2-7A6-7A2-7B6-7B7(2-7A6-7A)2-7G6-7G2-7A6-7A2-7F6-7F2-7A6-7A2-7H6-7H2-7A6-7A3-5B8-5B7(4-5A8-5A)4-5G8-5G4-5A8-5A4-5F8-5F4-5A8-5A4-5H8-5H4-5A8-5A4-5B8-5B7(4-5A8-5A)4-5G8-5G4-5A8-5A4-5F8-5F4-5A8-5A4-5H8-5H4-5A8-5A2-
