model
size = 31 31 13, scale = 0.05, origin = -y
material deform = 1, fade = true, lighting = smooth, roughness = 0.3, metalness = 0.6
  colors = A:#C69 B:#111
voxels
104-A7-A21-2A7-2A22-A5-A25-A3-A27-A-2(A29-)A-A27-A3-A25-A5-A22-2A7-2A21-A2-3A2-A23-7A24-A5-A25-4A26-A4-2A24-A2-A3-A22-A7-A22-A2(-2A)-A22-2(A2-)A-A23-A6-A24-A4-A26-4A209-12(11A20-)11A19-2(13A18-)13A17-15A16-16A2(14-17A)13-19A12-19A11-21A10-21A11-19A13-17A17-11A143-13(A11-A18-)A11-A17-2A11-2A16-A13-A15-2A13-2A14-A15-A13-2A15-2A12-2A15-2A11-3A15-3A9-2(4A15-4A8-)4A15-4A9-4A13-4A11-5A9-5A13-17A16-13A21-7A82-14(A13-A16-)A13-2(A15-)A196-4A17-4A5-5A17-5A6-4A15-4A9-2(5A11-)4A11-4A13-17A16-13A21-7A50-15(A15-A14-)A15-A226-3A21-3A3-5A19-5A4-6A13-6A7-6A11-6A9-5A11-5A12-5A7-5A16-3A7-3A21-A5-A19-15(A15-A14-)A15-A256-3A23-3A-5A21-5A2-3A21-3A6-5A13-5A9-5A11-5A13-2A11-2A18-3A5-3A17-15(A15-A14-)2(A15-A256-3A23-3A-5A21-5A-4A21-4A4-3A19-3A7-6A11-6A10-4A11-4A16-A9-A17-15(2A14-A14-))A15-A256-3A23-3A-5A21-5A2-3A21-3A6-5A13-5A9-5A11-5A13-2A11-2A18-3A5-3A17-15(A15-A14-)A15-A226-3A21-3A3-4A21-4A6-A19-3A7-4A15-4A2(9-6A)12-6A5-6A16-4A5-4A21-7A19-15(A15-A14-)A15-A196-3A19-3A5-A-3A17-5A7-3A15-4A9-4A13-4A11-19A13-17A16-13A21-7A51-15(A13-A16-)A13-2A2(14-A15-A)13-2A15-2A12-2A15-2A11-3A15-3A9-2(4A15-4A8-)2AB2A13-5A10-4A11-5A11-6A7-6A13-17A16-13A20-9A82-14(13A18-)14A2(16-15A)15-17A14-17A13-2(19A12-)19A11-21A10-21A11-19A13-17A17-11A134-
