model
size = 17 32 16, scale = 0.05, origin = -y
material deform = 1, fade = true, lighting = smooth, roughness = 0.3, metalness = 0.6
  colors = A:#0B0 B:#111 C:#00E D:#BBB
voxels
208-2(5A12-)5A13-3(3A14-)3A16-2A14-4A12-3(6A11-)6A12-4A14-2A284-2(5A12-)5A13-4(3A14-)3A16-2A14-4A12-2(6A11-)6A12-4A14-2A301-2(5A12-)5A13-2(5A12-)6A11-6A10-8A9-8A8-3(10A7-)10A8-8A9-8A10-6A12-4A184-6A10-2(8A9-)8A2(7-10A)7-3(11A6-)11A2(5-12A)5-11A6-11A5(5-12A)6-10A7-10A8-8A10-6A132-6A10-8A9-9A3(7-10A)2(6-11A)5-12A4-13A4(4-12AB)4-14A3-13A4(3-14A)4-2(12A5-)12A6-10A8-8A10-6A44-6A11-7A10-8A2(9-9A)8-11A6-11A3(4-13A)5-12A3-14A3-13A4-11AB5-12AB2(4-12AC)4-12AB3-2(15A2-)5(14A3-)14A4-13A4-12A6-10A8-8A10-6A27-7A10-8A9-9A8-10A7-11A5-4(13A4-)13A3(3-14A)3-2(12AB4-)12A2(C3-13A)B3-15A2-15A3(-16A)-15A3(3-14A)4-12A5-12A6-10A8-8A12-2A12-7A10-8A9-10A7-11A6-12A4-11AD5-3(13A4-)12A4-15A2-2(14A3-)12A4(B3-13A)B3-15A5(-16A)-15A3(3-14A)4-12A6-10A8-8A11-4A11-7A10-8A9-10A7-11A6-12A4-11A6-2(3(13A4-)12A4-2(15A2-)14A3-14A4(2-15A)6(-16A)-15A2-15A2(3-14A)4-12A6-10A8-8A10-6A10-7A10-8A9-10A7-11A6-12A4-11AD5-)3(13A4-)12A4-15A2-2(14A3-)12A4(B3-13A)B3-15A5(-16A)-15A3(3-14A)4-12A6-10A8-8A11-4A11-7A10-8A9-9A8-10A7-11A5-4(13A4-)13A3(3-14A)3-2(12AB4-)12A2(C3-13A)B3-15A2-15A3(-16A)-15A3(3-14A)4-12A5-12A6-10A8-8A12-2A12-6A11-7A10-8A2(9-9A)8-11A6-11A3(4-13A)6-11A3-14A3-13A4-11AB5-12AB2(4-12AC)4-12AB3-2(15A2-)5(14A3-)14A4-13A4-12A6-10A8-8A10-6A98-6A10-8A9-9A4(7-10A)6-11A5-12A4-13A4(4-12AB)4-14A3-13A4(3-14A)4-2(12A5-)12A6-10A8-8A10-6A149-6A10-8A3(8-9A)7-10A7-3(11A6-)2(11A3(5-12A)5-)12A5-12A6-10A7-10A8-8A10-6A248-2(5A12-)5A13-2(5A12-)6A11-6A10-9A8-9A4(7-10A)8-8A9-8A10-6A12-4A75-
