model
size = 18 32 16, scale = 0.05, origin = -y
material deform = 1, fade = true, lighting = smooth, roughness = 0.3, metalness = 0.6
  colors = A:#0B0 B:#111 C:#050 D:#00E
voxels
220-2(3A15-)5A14-3A71-2A15-4A13-3(6A12-)6A13-4A15-2A301-2(A17-)5A14-3A89-2A15-4A13-2(6A12-)6A13-4A15-2A319-2(5A13-)2(5A14-)4A13-6A12-6A11-8A10-8A9-3(10A8-)10A9-8A10-8A11-6A13-4A195-6A11-2(8A10-)8A8-5(11A7-)11A2(6-12A)6-11A7-11A5(6-12A)7-10A8-10A9-8A11-6A140-6A11-8A10-8A9-2(10A8-)10A2(7-11A)6-12A5-13A4(5-12AB)5-14A4-13A4(4-14A)5-2(12A6-)12A7-10A9-8A11-6A47-6A12-7A11-8A2(10-9A)9-10A8-10A2(6-12A)6-13A6-12A4-14A4-13A5-11AB6-12AB5-12AD2(5-12AB)4-2(15A3-)5(14A4-)14A5-13A5-12A7-10A9-8A11-6A29-7A11-8A10-9A9-10A8-11A6-2(13A5-)12A6-13A5-13A3(4-14A)4-2(12AB5-)12A2(B4-13A)B4-15A3-15A4(2-16A)3-2(14A4-)14A5-12A6-12A7-10A9-8A13-2A13-7A11-7AC10-10A8-11A7-12A5-13A5-14A4-2(13A5-)12A5-15A3-2(14A4-)12A4(B4-13A)B4-15A6(2-16A)3-2(14A4-)14A5-12A7-10A9-8A12-4A12-7A11-8A10-10A8-11A7-12A5-13A5-14A4-2(13A5-)12A5-16A2-15A3-14A4-14A3(3-15A)3-16A-17A-2(16A2-)15AC4(2-16A)3-14A4-13AC5-12A7-10A9-8A11-6A11-7A11-8A10-10A8-11A7-11AC5-13A5-14A4-2(13A5-)12A5-16A2-15A3-14A4-14A3(3-15A)3-16A-17A-6(16A2-)16A3-14A4-14A5-12A7-10A9-8A11-5AC11-7A11-8A10-10A8-11A7-12A5-13A5-14A4-2(13A5-)12A5-15A3-2(14A4-)12A4(B4-13A)B4-15A6(2-16A)3-2(14A4-)14A5-12A7-10A9-8A12-4A12-7A11-8A10-9A9-10A8-11A6-2(13A5-)12A6-13A5-13A3(4-14A)4-2(12AB5-)12A2(B4-13A)B4-15A3-15A4(2-16A)3-2(14A4-)14A5-12A6-12A7-10A9-8A13-2A13-6A12-7A11-8A2(10-9A)9-10A8-10A2(6-12A)6-13A7-11A4-14A4-13A5-11AB6-12AB5-12AD2(5-12AB)4-2(15A3-)5(14A4-)14A5-13A5-12A7-10A9-8A11-6A104-6A11-8A10-8A9-3(10A8-)10A7-11A6-12A5-13A4(5-12AB)5-14A4-13A4(4-14A)5-2(12A6-)12A7-10A9-8A11-6A158-6A11-8A2(9-9A)9-10A7-10AC4(7-11A)3(6-12A)6-11A5(6-12A)7-10A8-10A9-8A11-6A210-2(7A11-)7A2(10-8A)10-2(5A14-)4A13-6A12-6A11-9A9-9A4(8-10A)9-8A10-8A11-6A13-4A80-
