model
size = 23 28 21, scale = 0.05, origin = -y
material deform = 1, fade = true, lighting = smooth, roughness = 0.3, metalness = 0.6
  colors = A:#EEE B:#111 C:#FFC D:#E00
voxels
353-C3A19-C3A20-2A594-2(C5A17-)2C4A262-B328-2C6A2-B11-3C6A3-B10-3C6A2-B257-2B327-3C7A3B8-5C7A-2B9-4C7A-2B21-B232-2B247-B22-2B2(22-B)11-3CA-6A2B7-6CA-6A3B6-6C3-5A2B19-4B20-2B202-4A-4B12-7A-3B12-7A19-3A68-2(B20-B-)2B20-4B19-4B20-3B19-4B19-3B22-2B17-5A3B4-5C6-6AB5-5C8-4AB5-2C10-2BA2B20-4B19-2(B-)B176-5A-2(2B13-8A)B14-8AB16-5AB17-5A2B16-2(4A2B17-)4AB14-B3-4A3B12-B2-5A3B13-B6A3B13-B7A2B13-B7A3B13-B7AB16-6AB6-3C7-6A2B4-4C8-5A2B3-3C9-2B3A2B17-7B18-3B-B18-2(B-)B17-B2-B20-B-B22-B87-5A2(2B13-8A)2(3B12-8A)3B12-7A3B13-B5A2B15-B2(5A2B13-3B)6A2B11-3B7AB13-2B7AB-B11-2B8A2B12-B8AB13-B8AB15-B6AB5-3C7-B6AB5-3C8-B5AB4-3C11-3AB17-2B2A3B16-3B-5B2(15-8B)16-5B-B17-6B19-B2-B61-5A4(15-8A)B14-7AB15-2(7A2B14-)2(7AB15-)7AB14-B8A2B11-2B8A3B10-2B8A3B11-B8A3B11-2B7A3B3-2C8-B6A3B3-2C9-B5A2B3-2C10-2B3A2B16-2B3A3B15-2B5A2B15-B5A-B2(14-2B5A2B)16-B4A-B16-7B61-5A15-4(8AB14-)4(7AB15-)7A2B14-8A2B13-2(8AB14-)8AB13-B8A2B15-6AB5-C11-5A2B4-C11-5A2B3-2C12-4AB18-5AB16-7AB15-2D5AB15-7AB16-6A2B12-3B6A2B13-3B3A2B18-3B41-5A4(15-8A)2(15-7AB)-B13-7AB-B13-2(7A2B14-)4(8A3B12-)8A3B4-C8-B6A3B3-3C7-2B5A3B3-2C8-2B5A3B2-2C11-B4AB17-B5A3B3(13-B7A2B)14-B6AB15-B6AB16-B3A2B18-3B41-5A4(B14-8A)2B13-7A3B13-7A4B12-7A3B13-2(7A2B14-)7AB15-8AB14-2(8A2B13-)8AB6-2C8-6AB5-3C9-5AB5-3C7-2B5AB4-3C9-2B4AB17-B5AB14-2B2(7A2B13-B)7AB14-2B6A2B14-B6AB16-2B2A2B17-4B21-B19-5A2(15-8A)2B13-8A2B13-3(7AB15-)7A2B14-3(7AB15-)2(8AB14-)8A2B13-8A3B4-2C7-7A3B3-3C9-5A3B3-2C9-B5A3B2-3C10-B4A3B15-B5A2B4(15-B6AB)15-2B4A2B16-5B20-B43-4A15-8AB14-8A15-8AB14-7A2B15-6A3B14-5A3B14-B5AB16-B5AB15-B7A2B13-B7A2B2(12-2B8AB)12-2B8A2B11-2B8A2B4-4C4-2B7AB5-5C5-2B5A2B3-4C8-B5A2B4-C10-2B3AB19-5B17-7B16-2B3A2B15-4B3AB15-8B16-B-4B19-B-B20-B44-3A16-8A16-7A16-6AB16-5A2B17-4A2B17-3A3B2(17-3A-2B)16-5AB15-B6A2B14-B7A2B2(14-8AB)8-C5-8AB6-4C6-6AB6-5C5-B5AB7-C8-B4AB18-B-3B19-B-2B21-2B19-5B17-6B18-B2-2B21-B20-B67-2A3B15-5AB17-5A21-A3B19-3B18-3A2B20-4(2B21-)2B-2B18-4B16-6A2B16-5A2B8-C-C5-6AB7-5C4-6AB8-4C5-4AB10-C6-B4AB17-6B19-3B20-4B19-4B20-B-2B21-2B134-2(B22-)B136-2B21-2B23-B22-B19-4AB10-3C5-4AB9-4CA4-4AB9-4C2A2-B4AB10-3CA4-B2A2B19-3B20-3B21-B22-B25-B431-3AB12-2CA4-4AB9-4C2A3-4AB10-3C3A2-3A2B11-2CA4-3B45-B503-3AB13-C2(8AB12-2C)7AB14-C4A3B46-B503-2AB14-C7A2B12-2C7A2B13-C6AB16-5A21-B530-A2B17-5A17-6A17-5A19-3A240-
