model
size = 32, scale = 0.05, origin = -y
material deform = 1, fade = true, lighting = smooth, roughness = 0.3, metalness = 0.6
  colors = A:#F0F B:#3FF C:#001 D:#99F
voxels
8-C2B2D8A2D2BC8-5D-4A8-4A-5D4-5B-3A2-A4CA2-3A-5B4-BC5-A12-A5-CB2-B30-2B8-B12-B8-2B8-A12-A8-B8-2A12-2A17-A12-A50-A12-2(A18-AB10-B)A50-A12-A9-B-2A6-B10-B6-2A-2BA-A24-A-AB41-D12-A18-D159-B5-2A5-B18-A5-2B5-2(A20-3C-2B-3C-)A16-3A2C3-2B3-2C3A14-3A5-2A5-3A14-A6C4A6CA14-18A7-64A10D12B10D14-5(4B28-)4B508-5(4D28-)4D14-3D11A4D11A45D2(12B20D)12B10D14-5(4B28-)4B508-4D5(28-4A)14-64A96B14-5(4B28-)4B508-4D5(28-4A)14-33A9-12A9-A15B2A30B2A47B14-5(4B28-)4B508-4D5(28-4A)14-33A9-12A9-A10D2(2B8A2B20D)12B10D14-5(4B28-)4B509-2D5(30-2A)15-A2(14-2A)30-A12B8A24B8A44B4-10C4B10C18-4(4B28-)4B509-2D29-4(C2AC28-)C2AC14-B14-2A14-2B30-B12-2A4B2A24-8A24-8B16-10C4B10C17-C4BC26-C4BC27-2(4B28-)4B509-2D29-4(C2AC28-)C2AC29-2A59-2A4B2A80-11C2-11C17-2C2-2C26-2C2-2C635-4(C2-C28-)C2-C90-2A4B2A80-3(11C2-11C17-2C2-2C26-2C2-2C635-4(C2-C28-)C2-C91-A4BA81-)11C2-11C17-2C2-2C26-2C2-2C604-2D29-4(C2AC28-)C2AC29-2A60-A4BA81-11C2-11C17-2C2-2C26-2C2-2C604-2D6(30-2A)60-A4BA26-6A26-6B17-11C2B11C17-2C2B2C26-2C2B2C28-2(2B30-)2B509-4D4(28-4A)27-6A26-6A25-A6-A25-A4BA26-6A26-6B17-11C2B11C17-2C2B2C26-2C2B2C28-2(2B30-)2B509-4D4(28-4A)27-6A26-6A25-2(A6-A24-2A4B2A24-8A24-8B16-10C-2B-10C19-2(2B30-)2B29-4B28-4B508-4B4(28-4A)26-2(8A24-))2(A6-A24-2A4B2A24-8A24-8B16-10C-2B-10C19-2(2B30-)2B27-8B24-8B504-2A4B2A6(24-8A)24-)A6-A2(24-8A)24-8B16-8C8B8C6-8C2-8B2(2-8C4-8C2-3A2B3A)2(2-8C4-8C2-8B)2-2(8C4-8C12-)8C131-9(11C8-11C2-)11C2A4B2A11C13-6(8A24-)A6-A12-6B6A8-6A18B8A115B8A2B8A14B8A2B8A39B10A12B6(20AB10-B)10A-9AD10-D9A3-8AD10-D8A3-3(9AB10-B9A2-)10B10-10B2-10B10-10B-11B10-22B10-14B11A4B11A3B142A4B28A4B26A8B12A6B2A4B8-4B2A18B2(2AB)2A204B10A6(12B20A)12B10A-9A12D9A3-8A12D8A3-3(9A12B9A2-)30B2-30B-67B3(11A4B11A6B)11AB2AB11A3B128-6B2A4B8-4B2A18B2(2AB)2A204B10A6(12B20A)12B10A-9A12D9A2-C8A12D8AC3(2-9A12B9A)2(2-30B)322-5B2A4B8-4B2A5B2-11B2(2AB)2A11B2-30B-C5(30B2C)9A12B9AC-6(9A12B9A2-)9A12D9A2-C8A12D8AC3(2-9A12B9A)2(2-30B)329-4B8-4B16-4B2(2AB)2A4B16-16B8-4C4(4-16B4-8C)4-16B4-12C2A12B2A8C-2(7C2A12B2A7C2-)4(9A12B9A2-)9A12D9A2-C8A12D8AC3(2-9A12B9A)2(2-30B)329-4B8-4B16-4B2(2AB)2A4B16-16B8-4C5(4-16B4-8C)4-2A12B2A4-4C8-2A12B2A16-2A12B2A8-10A3(12B20A)12B10A-9A12D9A3-8A12D8A3-9A12B9A2(2-3A2C4A12B4A2C3A)2(2-3B2C20B2C3B)-4B2C20B2C39B3(11A4B11A6B)11A4B11A3B136-4B8-4B16-2B4AB2AB4A3(2B16-2B12A)2B3(16-16B)16-2A12B2(2A16-2A4BA2BA4B)2A8-10A3(4B4A4B20A)4B4A4B10A-9A5D2A5D9A3-8A5D2A5D8A3-9A5B2A5B9A-4A2C4A5B2A5B4A2C8A2-4A5B2A5B4A2-4A4B2(2-9B2A9B2-8B)2-9B2A9B2-19B2A18B3(11A4B11A6B)11A4B11A3B136-2(4A8-)8B2(6A4C6A16B)6A4C6A18B3C-4C-3C15B6C-CA4-AC-6C10B7C-2A2-2A-7C7B5C-4C-6A-4C-5C2B2A2(5C-)4A2(-5C)4A7C5A-2A-5A2(7C4A)CA2-AC4A7C4A5C-C4ACA2-AC4AC-5C4A7C4ACA2-AC2(4A7C)14A7C4A7C5A4-5A7C2A-A7C4A6-4A7CA2-A7C14A7CA2-A3C2-2C14A2C2-3CA-2AC4-2C14A2C4-C4AC4-2C2A3-4A3-2A2C4-C2A3C4-2C14A2C4-6C4-2C14A2C4-3CB2C4-18A4-2(2CB)4-18A4-B5C26A3(6C11A4D11A)3C128-2D10A8-10A2D8B6A4C6A16B3A10-3A13B-2B2A12-2A2B-10B-4B12-4B-6B4A-4A12-4A-4AB-4A3-2A12-2A2(3-4A)2-2A12-2A2-4A3-6A18-2(6A2-)A12-A2-6A2-4A-A-4A8-4A-A-4A2-4A4-4A6-4A4-4A2-6A-5A6-5A-6A2-12A6-12A-B11A8-11AB-10A10-10A2-2A4-4A10-4A4-2A2-A6-16A6-A-2B3(6-CA5-2A5-AC6-4B)6-C14AC2(6-4B6-16A)6-2B-2B26A2B2-2B11A4B11A2B-3B11A4B11A3B5-2(AC7A4B7ACA10-)9A4B9A10-9A4B9A5-10C2D8A2D10C2-10A8-10A4-6B6A4C6A6B4-B2C-3C2A10-2A3C-2CB2-3BC5-A12-A5-C6BC4-CB12-BC4-C4B3A4-2A12-2A4-3AB-3A3-3A12-3A3-3A2-4A4-A12-A4-4A3-3A22-3A5-2A4-A12-A4-2A4-A7-A2B8-2BA7-A2-A7-A3B6-3BA7-A2-4A4-A3B6-3BA4-4A2-6A2-A3B6-3BA2-6A-B9A2B8-2B9A2B2A-6AB10-B6A-2AB8-2AB10-B2A16-2(2A5B)2A16-CB5-2A5-3(BC16-CB12-)BC2(16-7B2A7B)15-7(7A4B7A14-)3C2D8A2D3C9-10A8-10A4-6B6A4C6A6B4-B3C2-C2A10-2AC2-3CB2-3B6-A12-A6-6B6-B12-B6-4B-A6-A12-A6-A-B2-2A4-2A12-3(2A4-)2A12-2A4-2A5-A24-2(A12-)A19-B10-B20-B10-B11-A-A5-AB10-BA5-A-A2-A-A5-AB10-BA5-2(A-)B6A2-AB10-BA2-6A2BA2(-3A)12-2(3A-)AB8-2A12-2A16-2(2A5B)2A4(16-C14-C)16-B14-B16-7B2A7B15-4(7A4B7A14-)3(18A14-)3C2D8A2D3C7-
