model
size = 18 32 13, scale = 0.05, origin = -y
material deform = 1, fade = true, lighting = smooth, roughness = 0.3, metalness = 0.6
  colors = A:#FF0
voxels
330-6A11-8A9-10A7-12A6-12A5-6A2-6A2(4-5A)4-4A6-4A4-3A8-3A98-6A11-8A9-10A7-4(12A6-)5A2-5A6-4A4-4A2(6-3A)5-4A2-2A2-4A2(4-3A2-4A2-3A)4-2A2-6A2-2A4-2A-8A-2A4-A2-8A2-A6-10A7-12A6-12A5-6A2-6A2(4-5A)3-5A6-5A2-4A8-4A2-16A3-4(14A4-)14A7-3A2-3A45-10A7-12A5-10(14A4-)6A2-6A3-7A3-6A2-6A4-6A2(2-5A6-5A)2-4A7-5A2-3A9-4A2-3A10-2(3A2-2A11-)3A2-A14-A75-A17-4A5-5A4-14A6-10A10-2A2-2A8-2A11-A4-A12-A3-9(2A12-2A2-)3(2A13-A2-)5(A14-A2-)A14-A-2A14-4A14-2A-A14-A111-3A7-4A4-4A6-4A5-4A4-4A5-A12-A3-A14-A2-A14-A-2A5(14-4A)14-2A-7(A14-A2-)A14-A-2A4(14-4A)14-2A146-2A9-3A4-4A6-4A3-A14-A-2A20(14-4A)14-2A146-2A9-3A4-3A8-3A2-A8(16-2A)5(15-3A)15-8(4A14-)2A139-3A4-3A8-3A5-2A8-2A3-A16-2A16-6(3A15-)3A8(14-4A)14-2A-4(A14-A2-)A14-A111-A17-3A8-3A4-3A8-3A21-A14-A2-A13-2A-2A10(14-4A)14-2A-6(A14-A2-)A13-2(2A2-2A12-)2A2-A13-2A75-A17-3A8-3A4-3A8-3A39-6(A14-A2-)2A13-A16(2-2A12-2A)2-A14-A39-2A10-2A4-3A8-3A4-2A-A6-4A6-A8-A42-3(2A11-A4-)12(A12-A4-)4(2A11-A4-)2A11-A3-2(3A11-2A2-)2A12-2A2(2-2A11-3A)2-4A9-3A3-14A5-5A2-5A7-2A6-2A62-2(11A7-)11A4(6-12A)5-10(14A4-)14A5-2(12A6-)12A5-3(14A4-)14A5-12A7-3A4-3A171-2A4-2A10-3A2-3A9-9A9-10A8-10A7-11(12A6-)12A7-10A8-10A9-8A11-6A132-
