model
size = 32 5 12, scale = 0.05, origin = -y
material deform = 1, fade = true, lighting = smooth, roughness = 0.3, metalness = 0.6
  colors = A:#C1693C B:#714922 C:#985F2A D:#43341B E:#78552B
voxels
4-5A58-2(5A27-)5A59-3(5A27-)5A58-7A2-3A20-A2B4A2-3A20-A2C4A2-3A20-7A2-3A51-14A18-A5B8A18-A5C8A18-14A49-11A2D3A16-A14BA16-A14CA16-16A21-D26-5AE4AD2-D3A15-A15BA15-A15CA15-17A20-2(D21-D4-5AE3AD4-15D3-A15B2A12D2-A15C2A12-D-17A14-D5-)D26-5AE4AD2-D3A15-2A14BA15-2A14CA15-17A47-11A2D3A16-2A13BA16-2A13CA16-16A49-14A18-2A4B8A18-2A4C8A18-14A51-7A2-3A20-A2B4A2-3A20-A2C4A2-3A20-7A2-3A18-
