model
size = 30 8 11, scale = 0.05, origin = -y
material deform = 1, fade = true, lighting = smooth, roughness = 0.3, metalness = 0.6
  colors = A:#FFF B:#FFD900 C:#FF211F D:#0052FF E:#FF482D F:#FFE866 G:#FF722D H:#00F5FF I:#00DFFF J:#00C3FF K:#00B1FF L:#008FFF M:#0078FF N:#0063FF O:#FF5D2D P:#FFE033
voxels
-C26-C2-A26-A-2A3(26-4A)26-2A-A26-A2-C26-C2-CA24-AC2-2A24-2A-3A3(24-6A)24-3A-2A24-2A2-CA24-AC2-C2A22-2AC2-3A22-3A-4A22-4AF3A22-3A2F3A22-3AF4A22-4A-3A22-3A2-C2A22-2AC2-C3A20-3AC2(2-4A20-4A-5A3(20-10A)20-5A-4A20-4A2(2-C3A20-3AC))2-4A20-4A-5A20-5AP4A20-4A2P4A20-4AP5A20-5A-4A20-4A2(2-C3A20-3AC)2-4A20-4A-5A3(20-10A)20-5A-4A20-4A2-C3A20-3AC2-E3A20-3AE2-4A20-4A-5A3(20-10A)20-5A-4A20-4A2-E3A20-3AE3-O2A20-2AO3-4A20-4A-5A20-5AB4A20-4A2B4A20-4AB5A20-5A-4A20-4A3-O2A20-2AO5-G22AG5-26A2-5AHIJKLMN6DNMLKJIH70AHIJKLMN6DNMLKJIH5A2-26A5-G22AG7-22A7-24A3-5A20-6AB2A22B2(2AB)2A22B2AB6A20-5A3-24A7-22A4-
