model
size = 30 9 9, scale = 0.05, origin = -y
material deform = 1, fade = true, lighting = smooth, roughness = 0.3, metalness = 0.6
  colors = A:#F6F B:#C3F C:#C6C
voxels
145-C238-2(3A27-)3A176-5B3(25-B3AB)25-5B116-3A26-B3AB24-C5AC2-C3-C16-C5AC23-C5AC24-B3AB26-3A58-C28-3A26-B3AB2(3-C)16-C5AC-C21AC5A2C-C3-C16-C5AC24-B3AB26-3A28-C58-3A26-B3AB24-C5AC2-C3-C16-C5AC23-C5AC24-B3AB26-3A116-5B3(25-B3AB)25-5B176-2(3A27-)3A238-C124-
