model
size = 26 27 8, scale = 0.05, origin = -y
material deform = 1, fade = true, lighting = smooth, roughness = 0.3, metalness = 0.6
  colors = A:#EEE B:#111
voxels
37-2B2A21-3B3A19-4B4A17-2(5B5A16-)5B5A15-6(6B6A14-)B4-BA4-A18-2B2A18-3(6B6A14-)6B6A15-5B5A660-5B13-3A5-6B11-5A4-6B10-7A3-6B10-6A5-5B10-5A7-3B11-4A10-B12-A69-2B2A20-4B4A17-5B5A15-6B6A13-7B7A11-8B8A9-3(9B9A8-)9B9A9-3(8B8A10-)8B8A9-9B9A7-2(10B10A6-)10B10A5-BA9B9ABA3-B2A9B8A3BA2-B3A8B8A3BA2-4A8B7A5B2(A-2(6A6B))A-5A-B11-A5BA-3A16-2A3BA37-2B2A20-4B4A17-5B5A15-6B6A13-7B7A11-8B8A9-3(9B9A8-)9B9A9-3(8B8A10-)8B8A9-9B9A7-10B10A5-11B11A4-11B11A3-2B-9B9A-2A2-B3-8B8A3-A-2B3-8B8A3-2AB5-7B7A5-2(AB6-6B6A6-)AB5-2B10-2A5-AB3-3B12-3A3-A5B16-5A11-2B2A20-4B4A17-5B5A15-4B2A2B4A13-7B7A11-8B8A9-3(9B9A8-)9B9A9-8B8A10-3B3A2B2A3B3A10-2B5ABA5B2A10-2B4A2B2A4B2A9-4B2A3B3A2B4A4(8-9B9A)9-8B8A11-7B7A13-6B6A15-5B5A123-2B2A20-4B4A17-3B4-3A15-4B8A13-7B7A11-6(8B8A10-)3B3A2B8A10-2B5AB8A10-2B4A2B8A10-3B2A3B4(8A10-8B)8A11-7B7A13-6B6A15-5B5A149-2B2A20-4B4A17-3B4-2A16-4B8A14-6B6A13-6(7B7A12-)2B3A2B7A12-B5AB7A12-B4A2B7A12-2B2A3B4(7A12-7B)7A13-6B6A15-5B5A175-2B2A20-4B4A18-4B4A17-3B7A16-5B5A15-6B6A14-6B4(7A12-7B)7A12-2B3A2B2A3B2A12-B5ABA5BA12-B4A2B2A4BA12-2B2A3B3A2B2A3(12-7B7A)13-6B6A15-5B5A190-
