model
size = 27 18 20, scale = 0.05, origin = -y
material deform = 1, fade = true, lighting = smooth, roughness = 0.3, metalness = 0.6
  colors = A:#630 B:#CC6 C:#FF9 D:#300 E:#996 F:#633
voxels
194-3C22-2C3B20-2C2B3C19-C2B3CB20-4C2BC22-3C324-3C22-2C3B20-2C2B3C19-C2B3CB20-4C2BC22-3C191-13C14-13B94-3B23-C2AB21-3C2AB2(19-7C)20-7C22-3C189-17C10-13BA3B10-13BAB67-2(6B21-)5B22-4B23-3B238-19C8-14BA3BC8-14BA3B10-B13AB12-B13A13-3BF5B18-4F4B19-4F3B20-4F2B21-4FB22-4B158-5D22-5D20-21C6-15B2A4B6-C14BAE3B8-B14A3B9-B14AB11-B14A12-B13A13-6A3(21-5AD)5(22-5D)21-7D20-7D18-23C4-2BE13B2A2EBEB4-2BE13BA2E3B6-BE14A2E2B7-BE14AEBC8-BE14AB10-B15A11-B5A-8A12-2(7AD19-)7A2(D20-D5A)D20-5DAD2(20-2D3-2D)19-3D3-3D18-3D3-3D17-24C3-B2A13B2A2E4B3-B2A13BA3E4B3-B16A3E3B4-B16AE4B5-B16A4B6-C16AB9-B16A10-B8AD2-4A11-9AD17-9A2(D18-D7A)D18-9D2(18-2D5-2D)17-2(3D5-3D16-)25C2-B2A13B2A2E4BC2-B2A13BA2(3E4B3-B16A)E5B4-B16AE3BC5-B16A4B6-B16AB9-B16A10-B15A11-13A15-2(D8AD17-)8DAD2(17-D7-2D)16-2(2D7-3D15-)25C2-B2A13B2A4E3B2-B2A13B2A2(4E2B3-B17A)5B4-B17A4B5-B17A3B6-B16A2B8-B16AC9-B16A10-13A15-2(D8AD17-)10D2(17-D8-D)16-2(2D8-2D15-)25C2-B2A13B2A4E3B2-B2A13B2A4EBC3-B17AE5B3-B17AE4B4-B17AE3B5-B17AE2B6-B16A2B8-B16AB9-B16A10-13A15-2(D8AD17-)10D2(17-D8-D)16-2(2D8-2D15-)25C2-B2A13B2ABE5B2-B2A13B2A2(B3E2B3-B17A)B3EB4-B17A4B5-B17A3B6-B16A2B8-B16AC9-B16A10-13A15-2(D8AD17-)10D2(17-D8-D)16-2(2D8-2D15-)25C2-B2A13B2ABE4BC2-B2A13B2A2(B3E2B3-B17A)5B4-B17A4B5-B17A2BC6-B16A2B8-B16AB9-B16A10-13A15-2(D8AD17-)10D2(17-D8-D)16-2(2D8-2D15-)25C2-B2A13BA8B2-B2A13BA2(7B3-B16A)6B4-B16A5B5-B16A4B6-B16AB9-B16A10-B15A11-13A15-2(D8AD17-)10D2(17-D7-2D)16-2(2D7-3D15-)24C3-B2A13BA7B3-B2A13BA6BC3-B16A6B4-B16A5B5-B16A4B6-C16AB9-B16A10-B8AD-5A11-9AD17-9A2(D18-D7A)D18-7DAD2(18-2D5-2D)17-2(3D5-3D16-)23C4-CBA13BA6B4-2BA13BA5B6-B15A4B7-B15A3B8-B15AB10-B15A11-B5A-8A12-2(7AD19-)7A2(D20-D5A)D20-7D2(20-2D3-2D)19-3D3-DAD18-3D3-3D18-21C6-15BA5B6-15BA4B8-B14A3B9-B14AB11-B14A12-B13A13-3(6A21-)5AD5(22-5D)21-2(7D20-)19C8-14BA4B8-14BA2BC10-B13AB12-B13A13-B6F2B18-B6FB19-B4F2B20-B2F3B21-B2F2B22-4B158-2(5D22-)17C10-13BA3B10-15B67-2(6B21-)5B22-4B23-3B241-13C14-13B94-3B23-C2AB21-3C2AB19-5CAC19-7C20-7C22-3C184-
