model
size = 16 10 18, scale = 0.05, origin = -y
material deform = 1, fade = true, lighting = smooth, roughness = 0.3, metalness = 0.6
  colors = A:#DDD B:#111 C:#EEE D:#BBB E:#FF3 F:#3FF G:#FF6
voxels
20-3B15-2B15-9B100-3B15-2B15-9B115-3B15-2A15-9AB7-C8A98-3B15-2A15-DA15-9AB7-2(D2A)DAD81-2B15-2A16-A16-2A15-9AB7-9A64-3B13-E-4A12-2A2C13-C2ADA12-9A9-9AB8-5AE2A2(8-F6-F)16-BCA13-A-4A12-D3A13-5A12-2(AC5A11-)3AC3AB8-7A33-BCA13-C-4A12-4A13-5A12-AD5A11-ADC4A11-7AB8-7A10-5A18-BAD13-A-4A12-2(CA)13-5A12-C6A11-G6A11-3ADC2AB8-7A10-5A12-ADA3-B2A13-D-AE2A12-2ACA13-C4A12-2(7A11-)C6AB8-7A10-D4A12-3A3-BCA13-A-4A12-2(CA)13-5A12-7A11-2CAC3A11-7AB8-7A10-5A12-ACD3-B2A13-C-4A12-4A13-5A12-C6A11-2AD4A11-AC5AB8-7A10-5A12-E2A3-BAC13-A-4A12-EA2C13-5A12-7A11-AD5A11-3AC3AB8-7A10-3ADA18-B2A13-A-4A12-D3A13-3ACA12-A2C4A11-CD5A11-2AEAD2AB8-7A33-3B13-D-4A12-C2AE13-C4A12-D8A9-3AC5AB8-4AE3A2(8-F6-F)17-2B15-2A16-A16-DA15-9AB7-9A66-3B2(15-2A)15-9AB7-2ADC2AD2A83-3B15-2A15-9AB7-AD2AC4A96-
