model
size = 15 21 9, scale = 0.05, origin = -y
material deform = 1, fade = true, lighting = smooth, roughness = 0.3, metalness = 0.6
  colors = A:#AAA B:#888 C:#BBB D:#EEE E:#FF3 F:#3FF
voxels
E5(13-2E)13-3E3(11-4E)11-2E-3(E11-E2-)7(EC9-CE2-)EC9-CE-3C4(9-6C)9-3C3B9-6B9-3B3A9-6A9-3A3D9-3D-2(2B9-2B2-)6(2A9-2A2-)2(2C9-2C2-)DC9-CD-4B7-8B7-4B4A7-8A7-4AD3C7-4D-2(3B7-3B2-)2(3A7-3A2-)3D7-3D3-2(2B7-2B4-)6(2A7-2A4-)2(2C7-2C4-)DC7-CD2-F6BC6BF-6BC6B2(2-6AC6A)2-D8C4D3-2(5BC5B4-)2(5AC5A4-)5DC5D5-2(4BC4B6-)6(4AC4A6-)2(9C6-)D7CD3-F-5BC5B-F2-5BC5B2(4-5AC5A)4-D7C3D5-2(4BC4B6-)2(4AC4A6-)4DC4D7-2(BEBCBEB8-)6(AEACAEA8-)2(7C8-)3DC3D7-2(E3BC3BE6-)2(E3AC3AE6-)D6C2D7-2(E2BC2BE8-)2(E2AC2AE8-)3DC3D10-2(BCB12-)6(ACA12-)2(3C12-)DCD10-2(3BC3B8-)2(3AC3A8-)2D3C2D10-2(BCB12-)2(ACA12-)3D13-10(D14-)D13-2(BDB12-)2(ADA12-)3D13-4(D14-)D164-F5(14-D)247-
