model
size = 31 32 31, scale = 0.05, origin = -y
material deform = 1, fade = true, lighting = smooth, roughness = 0.3, metalness = 0.6
  colors = A:#F66 B:#E00
voxels
899-15(A-)63A930-A29-32A899-A29-2A29-32A930-A29-32A899-A29-2A29-5A23B4A930-A29-5A23B4A899-A29-2A29-15A3B14A930-A29-15A3B14A899-A29-2A29-15A3B14A930-A29-5A23B4A899-A29-2A29-5A23B4A930-A29-5A2B8A3B8A2B4A899-A29-2A29-5A2B8A3B8A2B4A930-A29-5A2B8A3B8A2B4A899-A29-2A29-5A2BA3B4A3BA3B4A2B4A15-29(A30-)A15-2(A14-)5A2B2A3B3A3B2A3B3A2B4A899-A29-2A29-5A2B3A3B2A3B3A3B2A2B4A930-A29-5A2B4A3BA3B4A3BA2B4A899-A29-2A29-5A2B8A3B8A2B4A930-A29-5A2B8A3B8A2B4A899-A29-2A29-5A2BA3B4A3BA3B4A2B4A930-A29-5A2B2A3B3A3B2A3B3A2B4A899-A29-2A29-5A2B3A3B2A3B3A3B2A2B4A930-A29-5A2B4A3BA3B4A3BA2B4A899-A29-2A29-5A2B8A3B8A2B4A930-A29-5A2B8A3B8A2B4A899-A29-2A29-5A2B8A3B7A3B4A930-A29-5A2B8A3B7A3B4A899-A29-2A29-32A930-A29-32A899-15(A-)63A
