model
size = 30 32 32, scale = 0.05, origin = -y
material deform = 1, fade = true, lighting = smooth, roughness = 0.3, metalness = 0.6
  colors = A:#1A1B26 B:#00FF9F C:#2AFFAF D:#55FFBF E:#7FFFCF
voxels
433-4A25-3(6A24-)6A25-4A627-2A27-4A25-6A23-A6-A172-8A24-4A27-2A467-2B20-2B6-A22-A47-2A26-6A21-12A18-12A17-4A6B4A16-4A6B4A20-4(6B24-)6B15-A3-16A3-A12-12A19-10A21-8A23-6A25-4A27-2A347-3B18-3B6-3A18-3A6-2A7-6A7-2A13-4A2-4A19-12A16-16A14-16A13-2(2A4C6D4C2A12-)2A4C6D4C2A14-2(4C6D4C16-)4C6D4C11-A2-A-4C6D4C-A2-A2(6-24A)8-20A11-18A13-16A15-14A17-12A19-10A22-6A205-4A56-4A2(16-4B)6-AB2A6-4A6-2ABA6-4A4-8A4-4A6-2A3-14A3-2A7-A-18A-A8-A-18A-A10-18A11-A18DA10-A18DA9-2A18D2A10-18D13-16D10-A3-16D3-A6-4A16D4A3(6-24A)7-4A14B4A8-B3AB12AB3AB9-3AB12AB3A12-AB12ABA16-12A21-6A25-4A173-10A50-10A13-AB2A16-2(2ABA6-AB2A3-10A3-)2ABA2(6-24A)7-22A8-4AB12AB4A3(8-A3DB12AB3DA)9-3DB12AB3D8-A2-2DB12AB2D2-A6-AE3DB12AB3DEA6-AB2ADB12ABD2A2(BA6-AB3AB12AB3A)BA6-AB2A16B2ABA6-AB3AB12AB3ABA7-3(BA)B8A3(BA)B8-3(BA)B8A3(BA)B9-3AB12AB3A11-2AB12AB2A14-B12AB19-8A25-2A143-12A20-8B20-12A12-AB2A5-6B5-2ABA6-AB2A-14A-2A2(BA6-AB20A)BA2(6-24A)7-3A2B12A2B3A3(8-AD3B12A3BDA)7-2(AED3B12A3BDEA6-)ABD3B12A3BD5(BA6-AB2A2B12A2B2A)BA6-4(AB)8A4(BA)7-3(BA)B8A3(BA)B8-3(BA)B8A3(BA)B9-3(AB)8A3(BA)11-2AB12AB2A14-B12AB18-10A138-14A18-4B2A4B18-14A11-A3B3-4B2A4B3-3BA6-A3B16A3BA6-AB2A-B12AB-2ABA6-AB3AB12AB3ABA6-AB2A2B12A2B2ABA6-4A2B12A2B4A6-3A3B12A3B3A6-2AD3B12A3BD2A7-A4B12A4BA7-4(A5B12A5BA6-)AB2A2B12A2B2AB4(A6-A5B12A5B)A2(6-2(A3B)8A2(3BA))7-3(BA)B8A3(BA)B8-3(BA)B8A3(BA)B9-3(AB)8A3(BA)11-2AB12AB2A14-B12AB136-14A18-2B6A2B18-14A11-A3BA4B6A4BA2(3BA6-A3B-B12AB-)3B3(A6-AB2A2B12A2B2AB)A6-4A2B12A2B4A6(6-A5B12A5BA)6-AB2A2B12A2B2AB4(A6-A5B12A5B)A3(6-2(A3B)8A2(3BA))7-2A2(BA)B8A2(BA)B2A8-3(BA)B8A3(BA)B9-3(AB)8A3(BA)11-2AB12AB2A15-12A106-2(16A14-)16A10-A3B16A3BA6-A3B-B12AB-3B2(A6-A5B12A5B)4(A6-AB2A2B12A2B2AB)5(A6-A5B12A5B)A6-AB2A2B12A2B2AB4(A6-A5B12A5B)A4(6-2(A3B)8A2(3BA))7-2A2(BA)B8A2(BA)B2A8-3(BA)B8A3(BA)B9-3AB12AB3A13-B12AB18-10A77-2(16A14-)16A10-2(A3B-B12AB-3BA6-)3(A5B12A5BA6-)2(AB2A2B12A2B2ABA6-)4A2B12A2B4A6-A5B12A5BA6-AC4B12A4BCA5-3(A2C4B12A4B2CA4-)A2C2A2B12A2B2A2(2CA4-A2C4B12A4B)2CA5-6(A5B12A5BA6-)AB3AB12AB3ABA7-4AB12AB4A8-4AB12AB4A12-B12AB17-12A21-6A49-2(16A14-)16A10-A3B-B12AB-3B5(A6-A5B12A5B)A2(6-4A2B12A2B4A)6-AC2A2B12A2B2ACA5-4(A2C4B12A4B2CA4-)A2C2A2B12A2B2A3(2CA4-A2C4B12A4B)2CA5-6(A5B12A5BA6-)AB3AB12AB3ABA7-4AB12AB4A8-4AB12AB4A9-3AB12AB3A15-10A47-2(16A14-)AB12ABA10-A3B-B12AB-3B6(A6-A5B12A5B)A6-AC2A2B12A2B2ACA5-A2C2A2B12A2B2A2CA4-A2C4B12A4B2CA3-3(8B12A8B2-)4B2A2B12A2B2A4B2-8B12A8B3-2(A2C4B12A4B2CA4-)A2C4B12A4B2CA5-5(A5B12A5BA6-)A5B12A5BA7-4AB12AB4A8-4AB12AB4A9-3AB12AB3A12-16A44-2(16A14-)AB12ABA10-6(A5B12A5BA6-)AC4B12A4BCA5-A2C4B12A4B2CA4-A2C2A2B12A2B2A2CA3-4(8B12A8B2-)4B2A2B12A2B2A4B2(2-8B12A8B)3-2(A2C4B12A4B2CA4-)A2C4B12A4B2CA5-4(A5B12A5BA6-)A5B12A5BA7-A4B12A4BA8-4AB12AB4A9-20A12-16A20-4A20-2(16A14-)AB12ABA10-5(A5B12A5BA6-)A5B12A5BA5-A2C4B12A4B2CA4-A2C4B12A4B2CA3-3B3A2B12A2B3A3B2(2-8B12A8B)-3A2(6B12A6B6A)2B2A2B12A2B2A2B3A-2(8B12A8B2-)8B12A8B3-A2C4B12A4B2CA4-A2C4B12A4B2CA5-4(A5B12A5BA6-)A5B12A5BA7-A4B12A4BA8-4AB12AB4A9-20A10-20A17-6A19-2(16A14-)AB12ABA10-5(A5B12A5BA6-)A5B12A5BA5-A2C4B12A4B2CA4-A2C4B12A4B2CA3-8B12A8B2-8B12A8B-3A6B12A6B3A2-2(26B4-)26B2-3A6B12A6B3A-8B12A8B2-8B12A8B3-A2C4B12A4B2CA4-A2C4B12A4B2CA5-4(A5B12A5BA6-)A5B12A5BA7-A4B12A4BA8-4AB12AB4A9-20A10-20A16-8A18-2(16A14-)AB12ABA10-5(A5B12A5BA6-)A5B12A5BA5-A2C4B12A4B2CA4-A2C4B12A4B2CA3-8B12A8B2-8B12A8B-3A6B12A6B3A2-2(26B4-)26B2-3A6B12A6B3A-8B12A8B2-8B12A8B3-A2C4B12A4B2CA4-A2C4B12A4B2CA5-4(A5B12A5BA6-)A5B12A5BA7-A4B12A4BA8-4AB12AB4A9-20A10-20A16-8A18-2(16A14-)AB12ABA10-5(A5B12A5BA6-)A5B12A5BA5-A2C4B12A4B2CA4-A2C4B12A4B2CA3-8B12A8B2-8B12A8B-3A6B12A6B3A2-2(26B4-)26B2-3A6B12A6B3A-8B12A8B2-8B12A8B3-A2C4B12A4B2CA4-A2C4B12A4B2CA5-4(A5B12A5BA6-)A5B12A5BA7-A4B12A4BA8-4AB12AB4A9-20A10-20A16-8A18-2(16A14-)AB12ABA10-5(A5B12A5BA6-)A5B12A5BA5-A2C4B12A4B2CA4-A2C4B12A4B2CA3-2(8B12A8B2-)8B12A8B-3A2(6B12A6B6A)6B12A6B3A-2(8B12A8B2-)8B12A8B3-A2C4B12A4B2CA4-A2C4B12A4B2CA5-4(A5B12A5BA6-)A5B12A5BA7-A4B12A4BA8-4AB12AB4A9-20A10-20A17-6A19-2(16A14-)AB12ABA10-2A4B12A4B2A5(6-A5B12A5BA)6-AC4B12A4BCA5-A2C4B12A4B2CA4-A2C4B12A4B2CA3-6(8B12A8B2-)8B12A8B3-2(A2C4B12A4B2CA4-)A2C4B12A4B2CA5-4(A5B12A5BA6-)A5B12A5BA7-ABA2B12A2BABA8-3A-B12AB-3A9-20A12-16A20-4A20-2(16A14-)AB12ABA11-A2B-B12AB-2BA7-2A4B12A4B2A5(6-A5B12A5BA)6-AC4B12A4BCA5-A2C4B12A4B2CA4-A2C4B12A4B2CA3-4(8B12A8B2-)8B12A8B3-2(A2C4B12A4B2CA4-)A2C4B12A4B2CA5-5(A5B12A5BA6-)2(A2B)12A2(2BA)7-AB2-B12AB2-BA8-3A-B12AB-3A9-20A12-16A45-14A16-14A15-AB12ABA11-A2B-B12AB-2BA8-A4B12A4BA7-2A4B12A4B2A5(6-A5B12A5BA)6-AC4B12A4BCA5-7(A2C4B12A4B2CA4-)A2C4B12A4B2CA5-6(A5B12A5BA6-)A5B12A5BA7-A2B-B12AB-2BA8-4AB12AB4A9-20A15-10A49-12A18-12A16-16A11-3A-B12AB-3A8-A2B-B12AB-2BA8-A4B12A4BA7-2A4B12A4B2A5(6-A5B12A5BA)6-AC4B12A4BCA5-5(A2C4B12A4B2CA4-)A2C4B12A4B2CA5-6(A5B12A5BA6-)A5B12A5BA7-2(A2B-B12AB-2BA8-)22A13-12A21-6A52-10A20-10A18-14A12-22A8-A2B-B12AB-2B2(A8-A4B12A4B)A7-2A4B12A4B2A17(6-A5B12A5BA)7-A4B12A4BA8-A2B-B12AB-2BA8-2ABAB12ABAB2A8-2A2-14A2-2A14-10A81-8A23-6A21-AB8ABA13-6AB8AB6A2(8-A2B-BAB8ABAB-2BA)2(8-A4BAB8ABA4BA)7-2A4B12A4B2A15(6-A5B12A5BA)7-A4B12A4B2(A8-A2B-BAB8ABAB-2B)A8-2AB3AB8AB3AB2A8-2A3-AB8ABA3-2A16-6A85-4A54-8A15-3A-2AB8AB2A-3A8-A2B3AB8AB3A2BA8-A2B-BAB8ABAB-2BA8-2AB-BAB8ABAB-B2A8-A4BAB8ABA4BA8-A4B12A4BA7-2A4B12A4B2A13(6-A5B12A5BA)7-A4B12A4BA8-A2B-B12AB-2BA8-A2B-BAB8ABAB-2BA8-A2B2(AB)8A2(BA)2BA8-2AB-2AB8AB2A-B2A8-2A5-8A5-2A188-3A3-B8AB3-3A8-A2B-2AB8AB2A-2BA8-A2B3AB8AB3A2BA9-AB-BAB8ABAB-BA9-2AB-BAB8ABAB-B2A2(8-A4B12A4BA)7-2A4B12A4B2A2(6-A5B12A5BA)2(6-A-4B12A4B-A)8-4B12A4B10-4B12A4B8-2(A-4B12A4B-A6-)2(A5B12A5BA6-)A5B12A5BA7-A4B12A4BA8-2AB-B12AB-B2A9-AB-B12AB-BA9-A2B2(AB)8A2(BA)2BA8-A2B-2AB8AB2A-2BA8-2AB3-B8AB3-B2A8-2A18-2A188-3A6-4A6-3A8-A2B3-B8AB3-2BA9-AB-2AB8AB2A-BA11-B3AB8AB3AB12-B-BAB8ABAB-B11-AB-B12AB-BA9-A2B-B12AB-2BA8-A4B12A4BA7-2AB-2B12A2B-B2A6-A5B12A5BA6-A3-2B12A2B3-A9-3(3B12A3B12-)3B12A3B9-A3-2B12A2B3-2(A6-A5B12A5B)A7-A2B-B12AB-2BA9-AB-B12AB-BA11-B-B12AB-B12-BAB12ABAB11-AB-2AB8AB2A-BA9-A2B3-B8AB3-2BA8-2AB6-4A6-B2A8-2A18-2A188-2AB16-B2A9-AB6-4A6-BA11-B3-B8AB3-B14-2AB8AB2A15-3AB8AB3A13-BAB12ABAB11-AB-B12AB-BA9-A2B-B12AB-2BA8-AB2-B12AB2-BA7-2A4B12A4B2A11-B12AB16-B12AB15-2B12A2B14-2B12A2B15-B12AB16-B12AB11-A3B-B12AB-3BA7-A2B-B12AB-2BA9-AB-B12AB-BA11-BAB12ABAB13-16A15-14A14-B3-B8AB3-B11-AB6-4A6-BA9-2AB16-B2A8-2A18-2A189-AB16-BA11-B16-B47-8A20-AB8ABA17-14A14-B16AB11-2(AB)12A2(BA)9-AB2-B12AB2-BA9-AB-B12AB-BA13-5(B12AB16-)B12AB12-A2B-B12AB-2BA9-2(AB)12A2(BA)11-B16AB14-14A17-12A20-8A47-B16-B11-AB16-BA9-2A18-2A190-B16-B108-6A22-10A19-12A15-B-14A-B11-AB16ABA11-B16AB13-5(16A14-)16A12-AB16ABA11-B16AB15-12A19-10A22-6A108-B16-B11-A18-A377-6A23-8A21-10A19-6(12A18-)12A19-10A21-8A23-6A312-
