model
size = 32, scale = 0.05, origin = -y
material deform = 1, fade = true, lighting = smooth, roughness = 0.3, metalness = 0.6
  colors = A:#000 B:#CFCFCF C:#161102 D:#0A0606 E:#FFCE9C F:#FEFEFE G:#A78865 H:#AAA I:#5B2509 J:#D87758 K:#3B3B3B L:#8D372D M:#FFC292 N:#FFE2AE O:#FFB184 P:#81473F Q:#FFF9C4 R:#C4C4C4 S:#B2B2B2 T:#FF9C6F U:#FCA476 V:#2E2713 W:#1F1B09 X:#756A4C Y:#FFFED3 Z:#FFD3A4 Aa:#FFFDCD Ab:#FFFFE3 Ac:#8B8160 Ad:#F78659 Ae:#5E5947 Af:#E59A74 Ag:#5C5437
voxels
4-2(C-)C3-2C6-C2-3C2(-C)9-4D-3D-2(2D2-)D14-4D-11D-D15-2(16D16-)16D17-3D8A3D18-2D2AVLPLIW2A2D19-AIX4EMTLIA21-G7ETJ21-EGNYN4EOJO20-ZGAaAb5EMJM20-2G2Q5EOJAc21-PNQ5EUP17-4A2-GN5EAd2-4A10-7A-I5EUL-7A7-3AAeHR3A-Af4EJ-3A2SH3A5-3A5B3AAg4EI3A5B3A4-2AR6B2ADM2EO3A7B2A3-2AH2BF5B2AG2EG2A3BF4BSCA2-2AHB2F6B2A2E2AR2BF6B2A2-2AB2F7B2A2E2A2B2F6B2A2-2A2BF7B6A2BF7B2A3-2A2BF5BK7A2BF5B3A-5A6BK2A4-3A6B7A-3AH3BK2A6-3AH3B3A-2A4-3AD4A8-8A8-C6A10-6AC7-9C7-10C5-11C5-13C2-13C4-13C3-7C-4C4-3C-8C651-13A1010-A13-A1008-A15-A1006-A17-A1004-A19-A1002-A21-A1000-A23-A998-A25-A996-A27-A995-A28-A994-A28-A962-2(2(A28-A2-)A28-A930-)5(A28-A34-2(A28-A930-2(A28-A2-))A28-A930-)A28-A34-A28-A930-2(A28-A2-)A28-A930-A27-K2(A2-A28-)A321-
