model
size = 28 32 32, scale = 0.05, origin = -y
material deform = 1, fade = true, lighting = smooth, roughness = 0.3, metalness = 0.6
  colors = A:#DCCDA9 B:#D5B78D C:#C09668 D:#281818 E:#180808 F:#F9E9E9 G:#B27F50 H:#93522D I:#CD8D52 J:#6C3618 K:#685850 L:#979997 M:#898B87 N:#D3D4D3 O:#081808 P:#283918 Q:#A9A9A7 R:#BBBBBA S:#263838 T:#488918 U:#787978 V:#383838 W:#17282C X:#081818 Y:#485858 Z:#182818 Aa:#384848 Ab:#263828 Ac:#282818 Ad:#AA989B Ae:#334838 Af:#748D91 Ag:#506E70 Ah:#080818 Ai:#484848 Aj:#A9B3B9 Ak:#385858 Al:#186858 Am:#F83955 An:#343848 Ao:#F6C835 Ap:#D2F9F6 Aq:#687B78 Ar:#686868 As:#B9B9A9 At:#281828 Au:#3A755C Av:#EED8DF Aw:#536858 Ax:#48382F Ay:#383828 Az:#787868 Ba:#285948 Bb:#326868 Bc:#171828 Bd:#686858 Be:#585858 Bf:#282839 Bg:#594848 Bh:#786868 Bi:#687968 Bj:#284848 Bk:#484838 Bl:#485848 Bm:#585848 Bn:#181808 Bo:#392828 Bp:#8A796B Bq:#E8E9E8 Br:#382839 Bs:#285858 Bt:#385847 Bu:#8E7886 Bv:#92B1B1 Bw:#BDA7A1 Bx:#6F778F By:#180818 Bz:#8D7352 Ca:#B0DB83 Cb:#F0C76F Cc:#489989 Cd:#8C98AF Ce:#484858 Cf:#588389 Cg:#174D50 Ch:#584738 Ci:#68687B Cj:#786858 Ck:#4DAA8B Cl:#F11315 Cm:#AED4CF Cn:#5C9B9D Co:#4F556C Cp:#92B092 Cq:#383808 Cr:#647C56 Cs:#695869 Ct:#686848 Cu:#381818 Cv:#F9E9F9
voxels
560-BCB25-FAB25-2F26-FB729-D25-D6-D159-E3D2ED21-E2D3-E-D19-ED2E4-E5-D13-D8-D4-D576-D24-D-4E-E2D19-E-D2-4E3-D14-ED-E-2E2-D3-D14-D2-E-E2-DE3-2(D14-D2-DE4-DE2-)D14-D12-D14-D-2E9-D14-D2(-E)4-D-E-D14-4D2E-E2DED3E2(DE)D8-3D3E2-4(ED)4E459-D61-D46-D2-D4-2D18-E7D2E4D2ED2E9-ED2(2E3D)3(ED)E9-D3E2DE2-2ED5EDE9-2EDE3D2E3DED3E2D9-ED2EDED2E3D2(ED)2ED9-2D2EDED3E2D8E8-3D2(ED)E-D2-2E14-A3D2EDE-D3-E14-A2DE3D3E2D6ED2E7-A19DE7-A2(2D2E)11D431-D24-4E5-D20-ED5ED6-D13-ED5-3E4-D14-D5-D18-EDE3D4E3D3E12-A16D11-A17DE9-AJ5D2E10D2(9-A17DE)9-ADAB14DE9-A2DA4D2EDED4ED2E8-A7D2E2(DE)D2E2D2E7-15D2A3DE7-V8D8A2BDE7-AyBrAtSAkBjAfAqV2SQVQ3R2Aa2E343-2E-D4-3E17-2E-D7-E16-2E-D5-D21-D5-D18-5D2E2D4ED2E12-E5DE2D2E2(2DE)11-E4D5E3D2EDED10-5DED2E4D3ED11-A16D11-ABCIC4A6B2D2E9-H3J2H6A3BC3DE8-An2JKC2B6A3BCD2E8-AnC2B2ABA3F2A2BABDE9-AnA2BABA4F4A2BDE9-AaBA2BA4F8DE9-Bt2(B2A)12DE8-S2DAB9D3AB2DE7-3D2A2D3F7AB2D8-T5A2F5ATAYABDE8-TAxAtAgBaAfCdAgAiSAgVAc-V-2YAwD22-2P294-6E20-14E14-15E13-2(16E12-)14DCE12-L13DCDE2(11-A16D)11-C2B6ABG2BC4D10-HBCIC4A6B3DE9-An3J2H6A3BC3D9-An2JKC2B6A3BCD2E8-AiC2B2ABA3F2A2BAB2D2E7-AnA2BABA4F4A2B2D2E7-AaBA2BA4F6AB3DE7-AkB2AB3AF8AB2D3E5-Ak3ABA4F7AB2D2E6-Y6A3F7AB2D8-Co4AT2F6AT2AB2D8-CiBrBfAuBs-CeAgV-RLAcD-XAgBxAqE22-3P291-12E-E14-L4A5B2CDCE13-AB5A4B2CBE13-A3IC6B2CBCE12-ABC2IC2BA3B3CE12-A2GIB2CB2A3B2CE12-A4HJ2EHBC2B2CDE11-AC3I2CBCH2(CB)CDE11-C2(BA)6B4C2D2E9-C2B6ABG2BCI3DE2D7-AnBCIC4A6BC4D8-An3J2H6A3BCG2DE8-An2JKC2B6A3BC3D2E6-AnC2B2ABA3F2A2BABC2D2E6-AiA2BABA4F4A3B3DE6-ArBA2BA4F6A2B3DE6-BjB2AB3AF8A2B3D6-Bj3ABA4F7AB3DED5-Y6A3F7AB2DE7-Y2A2TA2F9AB2DE7-AkS3-BfAfBbVWNUZAbSAeCfBxAqDE21-Ab2P263-8E-2D17-16D12-L4A5B2CBCD13-LB5A4B2C2BD12-As3IC6B2CBCBE11-AkBC2IC2BA3B3C2E11-Bb2GIB2CB2A3B2CE12-Ag4HJ2EHBC2B3C3E10-Au3I2CBCH2(CB)2CD2E9-Ak2(BA)6B4CG2D3E8-AuB6ABG2BC2I5DE7-AuCIC4A6BC2G2DE8-Au2J2H6A3BC2G2DE7-Ak2JKC2B6A3B2C4DE5-BbC2B2ABA3F2A2BAB2C3DE5-AkA2BABA4F4A3BC2DE6-AgBA2BA4F6A2BC3DE5-AqB2AB3AF8A2B3DE5-Be3ABA4F7AB4DE5-Aq6A3F7AB2D-D6-Ag5A2F9AB2D2ED5-AuAn3WCgCfBb2AgBcWS2AaW3AkD-2D19-QAfP319-5E3DED6E12-LB5A4B2C2BCE11-L3IC6B2CBCBE11-CiBC2IC2BA3B4CE12-UGIB2CB2A3B3C2E11-U3HJ2EHBC2B4C2E9-MC3I2CBCH2(CB)2CIGE9-U2(BA)6B4CGC2G2D7-Bu2B6ABG2BC2I3G2D7-UBCIC4A6BC3G2D7-M3J2H6A3BC3GDE7-M2JKC2B6A3B2CG3D6-ArC2B2ABA3F2A2BAB2CG3D6-Ag2BABA4F4A3BCGDE6-BsBA2BA4F6A2BCGH3D4-AkB2AB3AF8A2BDE2-E4-Ah3ABA4F7AB2DE2-D4-Cq6A3F7ABD2E2D5-O5A2F9A2D-3ED4-OAfW3RCmAjBvLU3Q2AjBvRY3ED19-PAeAb319-9E8D11-LB5A4BE5D11-L3IC6B2CBCBD11-LBC2IC2BA3B5CE10-Af2GIB2CB2A3B5CE10-U3HJ2EHBC2B5CE9-AkC3I2CBCH2(CB)2CIGE9-Aq2(BA)6B4CGC2G2D7-Ag2B6ABG2BC2I3GHD7-AfBCIC4A6BC3GHD7-Af3J2H6A3BC4GD7-Aq2JKC2B6A3B2C2GHD6-AfC2B2ABA3F2A2BAB2CG2DE5-AkA2BABA4F4A3BCG3D5-AaBA2BA4F6A2BCG3D5-AwB2AB3AF8A2B2DE6-Ah3ABA4F7AB2D2E6-Ah6A3F7A2D2E7-P5A2F9AD5E5-PAf2NAs3R2Bw2AsR3AsBwRMV3E16-Ao2-3Al323-7E17-11E17-12E5D11-L11E4C2D10-L2GIB2CB2A3B4CD10-D4HJ2EHBC2B5C2D8-AfC3I2CBCH2(CB)2CI2GD8-Ar2(BA)6B4CGC2GHD7-Aw2B6ABG2BC2I3GHE7-BjBCIC4A6BC3G2HD6-Ag3J2H6A3BC4GHE6-Af2JKC2B6A3B2C2GHE6-CnC2B2ABA3F2A2BAB2CGHDE5-LA2BABA4F4A3BCG3DE4-CpBA2BA4F6A2BC5D4-MB2AB3AF8AB2D2-D5-O3ABA4F7ABDE8-O6A3F7A4DE6-O2A2Aa4Y5Aa3Y2D3E6-OTAd2-T-Ao10-SBkE18-Am2-Al2P22-Am324-5E79-L2GIB2CB2A3B4CD10-Bn4HJ2EHBC2B5CD10-D3I2CBCH2(CB)2CI2GD9-DABA6B4CGC2GHD7-Bd2B6ABG2BC2I3GHDE6-UBCIC4A6BC3GH-E6-Ac3J2H6A3BC4GHD6-Ac2JKC2B6A3B2C2GHD6-MC2B2ABA3F2A2BAB2CGH3E4-WA2BABA4F4A3BCG3DE4-AiBA2BA4F6A2BC5D4-AbB2AB3AF8AB3DED5-S3ABA4F7AB3D-D5-Ae6A3F7AB4DE5-X5A2F9AB2DHD6-XAfNBh2UAzU2BhAzBh2BdKAr2BdMBm2D11-T-Cl6-BiCkAb22-Am27-Ao380-L5GCB2A3B4C11-R4HJ2EHBC2B5CD9-AhC3I2CBCH2(CB)2CI2GD9-DABA6B4CGC2GHD8-DB6ABG2BC2I3G2-D7-DCIC4A6BC3GH-D7-D2J2H6A3BC4G-D7-DJKC2B6A3B2C2GH7-VC2B2ABA3F2A2BAB2CGH7-BoA2BABA4F4A3BCGH7-AcBA2BA4F6A2BCGDG6-SB2AB3AF8A2B2DG6-Ab3ABA4F7A2B2DG6-Cr6A3F7A2BCHG6-O5A2F9A2BCHG6-PBy3-T5-VAiArUMArUBtCJG13-Ao6-UAjCc50-Am27-Am352-L5GCB2A3B3CH11-L4HJ2EHBC2B4CH10-AtC3I2CBCH2(CB)2CI2G9-At2(BA)6B4CGC2G9-Bo2B6ABG2BC2I3G9-AtBCIC4A6BC3G10-D2J2H6A3BC4G2-G5-B2JKC2B6A3B2C2G2-B5-DC2B2ABA3F2A2BAB2CG2-H2C3-AtA2BABA4F4A3BCGH2-GC4-OA2BA4F6A2BCGHG-H2C3-O2AB3AF8A2BC-G-H2C3-O2ABA4F7A2BCHG-H3C2-O5A3F7A2BCHG-G2CI-Ab5A2F4AT4A2BCHG2-2CI-PV2AhOXBcBfW2ZM-ZAwAaVBeSCJG2-CI2C5-T-Am6-Q9-CHC8-Am16-2JC8-Ao16-CB13-Ao296-4IC6B2CBCB12-2BC2IC2BA3B4CH11-Y2GIB2CB2A3B3CH11-Ae4HJ2EHBC2B4C11-AcC3I2CBCH2(CB)2CI2G9-At2(BA)6B4CGC2G10-DB6ABG2BC2I3G-GJC6-DCIC4A6BC5GHBC5-D2J2H6A3BC4GCHGAI3-Bu2JKC2B6A3B2C2G-GB2A3-AcC2B2ABA3F2A2BAB2CG-BHCF3-DA2BABA4F4A3BCG-BJGCI3-OA2BA4F6A2BCG-BH-GA2-SB2AB3AF8A2BC-CH-G-I-Ae3ABA4F7A2BC-CH-J-C-Ae6A3F7A2BCHGCG3-CO5A2F9A2BCH4G2-CTLBeAaOZWArZRAiLVSUAbAeYZCJ3GJ2-C4-2T8-Cc7-2HD2-C22-4JA8-Am15-JCB9-Am3-Am184-AB2A6B4C14-3A2BA6B2CG13-5A5B2CB2C13-LB5A4B2C2BC12-L3IC6B2CBCBH11-LBC2IC2BA3B5C11-L2GIB2CB2A3B4C12-D3HJ2EHBC2B4C12-D3I2CBCH2(CB)2CI12-DABA6B4CGCH11-DB6ABG2BC2I3G2-2C5-AcBCIC4A6BC5GHBA5-D2J2H6A3BC4GCHG5-Bp2JKC2B6A3B2C4GB5-DC2B2ABA3F2A2BAB2C2GB6-AhA2BABA4F4A3BC2GB7-OA2BA4F6A2BC2GB6-AeB2AB3AF8A2BCGCA6-O2ABA4F7A2BCHCB5-Ae6A3F7A2BCHGC5-P5A2F9A2BCH2G5-PQW2ZWBiLAbArOAjArVLAbAiAwAeCH2G9-T9-Al7-H27-J28-JC10-Ao3-Ao128-3B6C3G16-BA7B3CG15-LB2A6B4C14-L2A2BA6B2CG13-W4A5B2CBCH13-SB5A4B2C2BC12-U3IC6B2CBCBH11-UBC2IC2BA3B5C11-U2GIB2CB2A3B4C11-U4HJ2EHBC2B4C11-AqC3I2CBCH2(CB)2CI11-S2(BA)6B4CGH11-S2B6ABG2BC2IGH10-SBCIC4A6BC3G9-Ai3J2H6A3BC4G8-V2JKC2B6A3B2C2G8-AbC2B2ABA3F2A2BAB2C2G7-AhA2BABA4F4A3BC2G8-OA2BA4F6A2B3G8-O2AB3AF8ABGCG8-O2ABA4F7ABGCH7-P6A3F7AB2GH7-Ab5A2F9A2BCH7-TAaYVAiWUAb2AaZYBlBdAbVAgBxBlCH11-T5-D2AuBaP18-ZAcZ2AcE2K20-THJKDMD23-Am3-Am100-BAC2BGC3GB17-3B6C3G16-CjA7B3CG15-BmB2A6B4C14-S2A2BA6B2CH13-Bi4A5B2CBCH13-ZB5A4B2C2BG12-Az3IC6B2CBCB12-BpBC2IC2BA3B5C11-Az2GIB2CB2A3B2CBC11-Az4HJ2EHBC2B3CB11-SC3I2CBCH2(CB)2CB11-S2(BA)6B4CGC11-Ai2B6ABG2BC2IG11-BlBCIC4A6BC2G10-Y3J2H6A3BC2G10-Ai2JKC2B6A3B2CG9-ByC2B2ABA3F2A2BAB2CG8-AhA2BABA4F4A3BCG8-AhBA2BA4F6A2B2G8-PB2AB3AF8ABGC8-P3ABA4F7ABGC8-O6A3F7A2BG8-Ab5A2F9A2BCH7-Ab-2(QAj)2RAjR2(2AjQ)AjRAeCH11-T4NQ3AlBaP19-DBMKE2KJ20-HJKDMDJ22-Ao2MKAoJ99-BA2GB5GB17-L2B6C3G16-UA7B3C16-ArB2A6B3C15-Bi2A2BA6BC2H13-Ay4A5B2CBCG13-AwB5A4B2C2B13-S3IC6B2CBCB12-VBC2IC2BA3B3CB12-L2GIB2CB2A3B3C12-Bc4HJ2EHBC2B3C12-AnC3I2CBCH2(CB)2CB11-M2(BA)6B4CBC11-Ac2B6ABG2BCIBI11-AcBCIC4A6BC2G10-Bt3J2H6A3BC2G10-Bg2JKC2B6A3B2C10-AhC2B2ABA3F2A2BAB2C9-AhA2BABA4F4A3BC9-PBA2BA4F6A2BCG8-PB2AB3AF8A2BC8-O3ABA4F7AB2C8-O6A3F7A2BC9-T4A2F9A2BC8-XTN2Q8AdLAdQ2AdQCH12-QAlQ2Al2Ba3P19-DBMKE2KJ19-2HJKDMDJD21-Am3ApFAp71-C2GC5G19-LAC2BGC2GCB17-K2B6C3G16-RA7B3CG15-QB2A6B3CH14-Aw2A2BA6BCG14-S4A5B2CBCG13-AgB5A4B2C2B13-Bt3IC6B2C2B13-ZBC2IC2BA3B2C2B12-L2GIB2CB2A3B3C12-Bu4HJ2EHBC2B2CB12-RC3I2CBCH2(CB)2C12-Q2(BA)6B4CBC11-Ae2B6ABG2BC3I11-AhBCIC4A6BCG11-Av3J2H6A3BC2G10-R2JKC2B6A3B2C10-AcC2B2ABA3F2A2BAB2C9-AeA2BABA4F4A3BC9-AiBA2BA4F6A2BC9-AbB2AB3AF8ABC9-O3ABA4F7AB2C9-S5A3F7A2BC8-O5A2F9A2BG8-OTU15-VC13-LAuQ2AlAb4P18-CDBMKE2KJ20-FJKDMDJD21-MApNFN2Ap42-8G20-2CBCG2HJC19-QAC2BGC3GC17-Bg2B6C3G16-QA7B2CG16-LB2A6B2CH15-V2A2BA6BCG14-Bn4A5B2CBC14-AtB5A4B2CB14-Bo3IC6B2C2B13-OBC2IC2BA3B2CB13-L2GIB2CB2A3B2CB12-U4HJ2EHBC2B2CB12-RC3I2CBCH2(CB)2C12-Q2(BA)6B5C12-S2B6ABG2BC3I11-SBCIC4A6BCG12-Bc2J2H6A3BC2G10-W2JKC2B6A3B2C10-AyC2B2ABA3F2A2BABC10-AiA2BABA4F4A3BC9-AxBA2BA4F6A2BC9-BzB2AB3AF8ABC9-Bz3ABA4F7ABC9-O6A3F7A2BC8-O5A2F9A2BC8-OTAsBgChBg10KBmKQC13-TAlT4-2PCb18-CDB4XKJN19-FJKDMDJD21-M2(FN)FAp42-H5G2C20-BqCBCG2HJC19-QAC2BGC4G17-K2B6C3G16-AsA7B2CH16-QB2A6B2CG15-Aa2A2BA6B2C14-Q4A5B2CBC14-LB5A4B2CB14-V3IC6BC2B15-ByC2IC2BA3BC2B13-L2GIB2CB2A3B2C13-Bh4HJ2EHBC2B2CB12-RC3I2CBCH3(CB)12-L2(BA)6B4CG12-An2B6ABG2BC2I12-SBCIC4A6BCG11-Br3J2H6A3BCG11-Ax2JKC2B6A3B2C11-Br2B2ABA3F2A2BABC10-SA2BABA4F4A3B10-AiBA2BA4F6A2BC9-BzB2AB3AF8ABC9-Ct3ABA4F7A2B9-Ah6A3F7A2B9-O5A2F9A2B9-PTNAv2NAv3NBq5Av2BqBvC13-P7-PAo18-C3XFE2XJN19-FJKDMDJDN19-MAp2(FN)2FL13-4G24-LGKHC3G20-NCBCG2HJGH18-AsAC2BGC4G17-U2B6CGH17-NA7B2CH16-QB2A6B2CG15-Y2A2BA6BC15-W4A5B3C15-BeB5A4B2C16-Bc2IC6B2CB15-AhC2IC2BA3BCB14-N2GIB2CB2A3BCB13-Ad4HJ2EHBC2B2C13-NC3I2CBCH2(CB)2C12-R2(BA)6B4CG13-WB6ABG2BC2I13-WCIC4A6BCG11-Bf3J2H6A3BCG12-AtJKC2B6A3BC12-At2B2ABA3F2A2BABC10-SA2BABA4F4A3B10-SBA2BA4F6A2BC9-CjB2AB3AF8ABC9-Cu3ABA4F7A2B10-At5A3F7A2B9-Ah5A2F9A2B9-PBb16-B17-2FM2-XAo18-2XBMKEFXJN19-FJKDMDJDN19-MAp2(FN)2FL13-GC2G24-LGKH2G2C20-AvCBCG2HJ2H18-LAC2BGC3GH17-Bg2B6CGH17-QA7B2CH16-AjB2A6B2C16-V2A2BA6BC15-Z4A5B2CB15-AaB5A4BCB16-X2IC6B2C16-AhC2IC2BA2B-C15-M2GIB2CB2AB-BC14-Bh4HJ2EHBC-BC14-NC3I2CBCH2(CB)C13-R2(BA)6B4CG12-Bs2B6ABG2BC2I13-WCIC4A6BC12-Au3J2H6A3BC12-Ag2JKC2B6A3B12-SC2B2ABA3F2A2BAB11-BlA2BABA4F4A3B10-BeBA2BA4F6A2B10-AzB2AB3AF8AB10-Ac3ABA4F7AB10-D6A3F7AB10-Bo5A2F9A2B9-BpTAcAy2BkBmBeBnAyAcBkAyZAcBnAyWB16-4F2-XCb18-XFBMKEFXJN19-CaJKDMDJDN19-N7FL13-4G24-LGKH3CG20-NCBCG2HJ2H18-AdAC2BGC2GH18-Ch2B6C2G17-QA7B2C17-QB2A6B2C16-Ai2A2BA6B16-Z4A5BCB16-YB5A4BCB16-O2IC6B2C16-OC2IC2BA3BC15-M2GIB2CB2A3B15-U4HJ2EHBC2B15-AsC3I2CBCHCBC15-R2(BA)6B3C14-Af2B6ABG2BCI14-WCIC4A6B13-Bs3J2H6A3B13-Ba2JKC2B6A3B12-AkC2B2ABA3F2A2BA12-AiA2BABA4F4A2B11-LBA2BA4F6AB11-AbB2AB3AF8AB10-Bp3ABA4F7AB10-Ay6A3F7AB10-N5A2F9AB10-Cv-Z2AxBpBlV2AeABmCAcAxDKB16-6FB2O18-XDBMKEKOJ20-NJKDMDJD21-2FH2KJF14-H2GC24-LGKH2C2G20-NCBCG2HJH19-QAC2BGC3G18-Bg2B6C2G17-AdA7B2C17-AjB2A6B2C16-W2A2BA6B16-W4A7B16-YB5A5B17-Z2IC6BC16-XBC2IC2BA3B16-M2GIB2CB2A2B16-U4HJ2EHBCB16-RC3I2CBCHCBC15-R2(BA)6B3C14-Cg2B6ABG2BC14-AfBCIC4A5B14-Bf3J2H6A2B14-Af2JKC2B6AB14-BjC2B2ABA3F2A2B13-WA2BABA4F4A13-BoBA2BA4F5A13-BnB2AB3AF7A12-Z3ABA4F7A11-O6A3F7AB10-Bu5A2FA-7AB10-LBbZ2AxF4B-BC4AB18-4F21-ZDBMKEKBJ20-CaJKDMDJD21-LFH2KJF14-2G2C24-LGKH3GH20-AvCBCG2HJ20-LAC2BGC2G19-K2B6CG18-AdA7BC18-RB2A6B18-U2A2BA4B18-Bi4A3BCB18-WB5A3B18-S3IC5B18-BcBC2IC2BA2B17-M2GIB2CB2AB17-Az4HJ2EHBC17-RC3I2CBCHCBC15-L2(BA)6B2C15-L2B6ABG2B15-LBCIC4A4B15-Ce3J2H6A2B14-Cd2JKC2B6AB14-AfC2B2ABA3F2AB14-AgA2BABA4F3A14-AqBA2BA4F5A13-AeB2AB3AF7A12-Bk3ABA4F6A12-RA-4A3F7A11-RA-2A5-6A12-CsA2BA8-2A21-F2MF24-MKE2K22-ApKDMDJ23-FHEKJ15-2HJH24-LGKHJ3H20-NCBCG2HJ20-AdAC2BGCG20-K2B6C19-AdA6B20-RB2A3B21-Ab2A2B23-L4A2B21-ArB5AB20-M3IC4B19-BfBC2IC2BAB18-M2GIB2CB2AB17-5HJ2EHBC17-AC3I2CBCHCB16-C2(BA)6BC16-C2B6AB-B16-LBCIC-3A4B15-L3J2H6AB15-L2JKC2B6A15-AqC2BA-BA3F2AB14-AqA2BA-A4F3A14-YBAB2-4F5A13-AaBA3-2AF7A12-Ae2A4-3F6A12-V2A8-5A12-L2A10-A14-LA138-HGJH24-LGKH3J21-NCBCG2HJ20-QAC2BGCG20-K2B5C20-AdA5B21-2B2AB23-2(A27-)B27-4ICB22-2BC2IC2B20-H2GIB2CB2A130-2H26-HJEJHB22-L2JKC4-2A17-VC2BA4-2F2A15-AwA2B4-3F2A15-LBA5-2FAF2A14-LBA5-F6A13-LA7-F5A13-FA10-2A14-FA26-FA140-2J24-HG2H2J22-2CBCGH22-BAC2BGC21-3B4C21-BA3B359-HJ2EH23-B2JKC23-SC2BA23-LAB25-LBA25-AB2(26-FA)26-F671-BJEJ24-B2JB24-FCB25-FAB25-2(AB26-)F223-
