model
size = 25 30 32, scale = 0.05, origin = -y
material deform = 1, fade = true, lighting = smooth, roughness = 0.3, metalness = 0.6
  colors = A:#180808 B:#F9E9E9 C:#281818 D:#DCCDA9 E:#C09668 F:#D5B78D G:#6C3618 H:#93522D I:#B27F50 J:#CD8D52 K:#283918 L:#685850 M:#081808 N:#080818 O:#186858 P:#081818 Q:#898B87 R:#263828 S:#979997 T:#182818 U:#285948 V:#5858A9 W:#3A755C X:#D3D4D3 Y:#282818 Z:#488918 Aa:#334838 Ab:#A9A9A7 Ac:#180818 Ad:#BBBBBA Ae:#74B9ED Af:#A7ABC9 Ag:#787978 Ah:#4598E4 Ai:#686868 Aj:#647C56 Ak:#489989 Al:#383838 Am:#55A3E7 An:#585858 Ao:#A9B3B9 Ap:#AA989B Aq:#383828 Ar:#485838 As:#64AEEA At:#2682DE Au:#954869 Av:#506E70 Aw:#484848 Ax:#93D2EF Ay:#695869 Az:#263838 Ba:#687968 Bb:#4DAA8B Bc:#385858 Bd:#687B78 Be:#368DE1 Bf:#686858 Bg:#68687B Bh:#ADD1F1 Bi:#748D91 Bj:#B9B9A9 Bk:#181808 Bl:#485889 Bm:#4A3848 Bn:#485848 Bo:#588D75 Bp:#0757B3 Bq:#282839 Br:#6A78AA Bs:#BDA7A1 Bt:#392828 Bu:#92B092 Bv:#92B1B1 Bw:#787868 Bx:#484838 By:#E9DAC8 Bz:#384848 Ca:#588389 Cb:#333858 Cc:#485858 Cd:#4F556C Ce:#282808 Cf:#171828 Cg:#075CBD Ch:#389989 Ci:#3B99C9 Cj:#704A18 Ck:#59A3CE Cl:#F0C76F Cm:#6F778F Cn:#343848 Co:#284848 Cp:#326868 Cq:#385847
voxels
275-C24-C100-C24-2A22-4A21-2A48-2A2-2A244-2(BD23-)AaD2F-HJN17-RM2FD8-F2EF8-Bm3MP8-2ME2F7-N3MK8-P3M2F6-5K8-2(PM)2F7-KO3K7-2K2PZFE5-MOAk2WZOZ4-5KPFE5-KOAb2WSWAb2OR7KFI5-ROApBsApAbOAb2O2U6KFEG4-ZAd7XAb3OU4KFEGA3-R9-C2WUK2RKFEGA3-R9-N4O3KFE2G3-O9-NAnSAdAkBb2KFE2G3-R9-NAiSAdAbAoAkZFEGA3-K9-TAgAbXAgAoAk2FEGA3-K9-AzAnSAoBaBbR2F2CA13-Bt4O2KF4C3-Ar9-NZ5OFC3A3-M9-NQBuAdKAaRFC3AC2-T9-MAiSAdAbBiKMFC2AC2-Av9-Bv3OR2KMF2CA3-BcD2FDHJLB2OUO4KMFCA4-RD7CQKUR3KM2FC2A3-Aq2C3AC2ACQBEH2E2F3AC3-DCA6-10CA5-AC7-2A2(CA)2CMA6-C8-C-C2-C35-B24-BD23-AD3IECF5-G11-BkD3ITCN5-GHIE8-ND3IP2N5-GHIEF7-ND3IPN-N3-PGHIEF7-MD3I2P2-2N-PGHIE2F6-MD3IE3PNA2PGHIE2F6-PD3IECF4PLGHIE2FE5-KD3IECFQLA2LGHIEF2I5-KD3IECFQLA2LGHIE2F-G4-AbD3IECFQLA2LGHIE2FEGAC2-RBq4TYT2YA2LGHIE2FE2GC2-O4V3T2YA2LGHIE2FE2G3-BoV2Au2AfV3YA2LGHIE2FE2G3-BjAx2VAuBh2Af2YA2LGHIE2FEGAC2-RBrAeVAeBhAfAx2YA2LGHIE2FEGA3-KVAhAmVAe2Af2SA2LGHIE2FEGA3-P4AhAsAfAx2SA2LGHIE2F2CA3-MAhBe2AtAh2Ae2SA2LGHIE2FCAC3-MVBeAtBeV2Q2SA2LGHIE2FCA4-MAyAiBgAg3Q2SA2LGHIE2FECA3CAvBf2Ai2AgSQ2SA2LGHIE2FEGA-C-AdD3IECFQLA2LGHIE2FE2A3-YD5CFQLA2LGHIE2FE2A3-Aq2C2AC3ALA2LGHIE2FEAC3-DCA6-CA2LGHIEF3A4-2C7-A7CA-A5-AC7-2(CA)C3A58-BD23-JDEH2-HG5-CH10-JDEHG2HGN4-CHE9-NDEHG2HGN4-CH2E8-NDEHG2H2N2-2NCH3E7-MDEHG2H5NGCH3E7-PDEHG2HGLCQCGCH4E6-KDEHG2HGLCQCGCH4EI5-MDEHG2HGLCQCGCH4EI5-KDEHG2HGLCQCGCH4E2G4-AgDEHG2HGLCQCGCH5EGA3-UDEHG2HGLCQCGCH5ECAC2-ODEHG2HGLCQCGCH5ECAC2-AyDEHG2HGLCQCGCH5ECAC2-AiDEHG2HGLCQCGCH5ECAC2-R2(DEHG2HGLCQCGCH5ECAC2-K)DEHG2HGLCQCGCH5EC2A2-PDEHG2HGLCQCGCH5E3C2-MDEHG2HGLCQCGCH5E2C3-MDEHG2HGLCQCGCH5E2CAC-AvDEHG2HGLCQCGCH5EC2A2-BDEHG2HGLCQCGCH5E2A3-BxDEHG2H3CQCGCH5EAC3-AqD8CQCGCH5EA4-D2C2AC2A10C3A4-3C2(2-A)2(CA)4CA7-2CA5-4C2-C2A58-2DE22-CjDEJ3-2G4-E11-NDEJH3GH4-N2E9-NDEJH3GN4-N3E8-TDEJH3GH4N5E7-AaDEJH3G2H2LG6E6-PDEJH3G2H2LG6E6-KDEJH3G2H2LG6EIG4-UDEJH3G2H2LG6EIG4-ODEJH3G2H2LG6EIG4-QDEJH3G2H2LG6EIGCA2-WDEJH3G2H2LG6EIGCA2-BoDEJH3G2H2LG6EIGCA2-ApDEJH3G2H2LG6EIGCA2-QDEJH3G2H2LG6EIGCA2-UDEJH3G2H2LG6EIGCA2-RDEJH3G2H2LG6EIGCA2-KDEJH3G2H2LG6EIGCA2-MDEJH3G2H2LG6EIGCA2-PDEJH3G2H2LG6EIGC2A-AaDEJH3G2H2LG6EIGC2ACBdDEJH3G2H2LG6EIGCA2-ByDEJH3G2H2LG6EIA4-CDEJH2G2CH2LG6EIAC3-BwDEJHG4C2LG6E2A4-D16C2A-A4-4C4A2(2CA)C2A8-C3A4-A2C3-2C59-BDFE21-ClDF2EJ2-HIJFE12-NDF2E2JIH4-EIFE8-MDF2E2JIN4-NIF2E7-ArDF2E2JIH4NEIF2EI6-AjDF2E2JIHIJ2(F2EI)6-UDF2E2JIHIJ2(F2EI)6-ZDF2E2JIHIJ2(F2EI)H5-WDF2E2JIHIJ2(F2EI)JG4-XDF2E2JIHIJ2(F2EI)JGA3-2(AcDF2E2JIHIJ2(F2EI)JG2A2-)2(AlDF2E2JIHIJ2(F2EI)JG3A-)AcDF2E2JIHIJ2(F2EI)JG3A-AlDF2E2JIHIJ2(F2EI)JG3A-W3(DF2E2JIHIJ2(F2EI)JG3A-K)DF2E2JIHIJ2(F2EI)JG3A-AaDF2E2JIHIJ2(F2EI)JG2AC-BzDF2E2JIHIJ2(F2EI)JG3A-2DF2E2JIHIJ2(F2EI)JG2A2-BkDF2E2JIHIJ2(F2EI)J2A3-BjDF2E2J2CIJ2(F2EI)2AC3-D15CACA6-3C3A2CA2C5AC8-2CA4-A2CA4-C59-2BDB21-SBDBFEI3H4-FE9-NBDBFEI5HI2(EF)8-MBDBFEI2H4N2(EF)E7-KBDBFEI5HI2(EF)2E6-P2(BDBFEI5HI2(EF)2E6-K)BDBFEI5HI2(EF)2EH5-O2(BDBFEI5HI2(EF)2EIGA3-Ac)BDBFEI5HI2(EF)2EI2GC2-5(AcBDBFEI5HI2(EF)2EI2GCA-)AbBDBFEI5HI2(EF)2EI2GCA-KBDBFEI5HI2(EF)2EI2GCA-ZBDBFEI5HI2(EF)2EI2GCA-KBDBFEI5HI2(EF)2EI2GCA-MBDBFEI5HI2(EF)2EI2GAC-MBDBFEI5HI2(EF)2EI2GA2-XBDBFEI5HI2(EF)2EIG2A2-ABDBFEI5HI2(EF)2E3A3-Ap5CI2C3H6CA-AC3-D3CACA2C6A2CA8-ACA3-2A-A3-2C-C7-2C2-4ACAC64-3BDB9-E10-Cm2BDBD-H5-IEDF8-N2BDBDE2HLH3IEDFE7-M2BDBDE2HLH3IEDF2E6-K2BDBDE2HLH3IEDF2E6-P2BDBDE2HLH3IEDF2E6-K2BDBDE2HLH3IEDF2E6-Z2BDBDE2HLH3IEDF2E6-Ad2(2BDBDE2HLH3IEDF2EIG2A2-T)2BDBDE2HLH3IEDF2EIGCA2-2(Bp2BDBDE2HLH3IEDF2EIGCAC-)Cg2BDBDE2HLH3IEDF2EIGCAC-Cf2BDBDE2HLH3IEDF2EIGC2A-Ac2BDBDE2HLH3IEDF2EIGC2A-Ab2BDBDE2HLH3IEDF2EIGCAC-Ap2BDBDE2HLH3IEDF2EIGC2A-W2BDBDE2HLH3IEDF2EIGCAC-K2BDBDE2HLH3IEDF2EIG2(CA)M2BDBDE2HLH3IEDF2EIGC2A-M2BDBDE2HLH3IEDF2EIG2A2-Bm2BDBDE2HLH3IEDF2EI3A2-Bl2BDBDE2HLH3IEDF2E2AC3-9CLHI6C2A2C3-D3CAC10ACA7-A-A4-C2-C3-C2-C7-2A-C-A3-A65-6BD4-4DF9-Bd7B5DBD2F8-N10B2DBD2FE7-T10B2DBD2F2E6-K10B2DBD2F2E6-T10B2DBD2F2E6-Z10B2DBD2F2E6-Aj10B2DBD2F2EH5-X10B2DBD2F2EH-2(CA2-Al10B2DBD2F2EHG)CA2-As10B2DBD2F2EHGCAC-Ck10B2DBD2F2EHGC2A-Ci10B2DBD2F2EHGC2A-Ae10B2DBD2F2EHGC2A-T10B2DBD2F2EHGC2A-Ad10B2DBD2F2EHGCAC-Ao10B2DBD2F2EHGC2A-Z10B2DBD2F2EHG2(CA)Aj10B2DBD2F2EHGCAC-M10B2DBD2F2EHGC2A-M10B2DBD2F2EHG2A2-Cb10B2DBD2F2EHA4-Bl10B2DBD2F2E2AC3-11C2A5C2AC4-4C2A2C3A-6A8-2A2-C-AC-C2-AC2-C10-5A-C65-8B7DF9-Bc12B2D2F8-N12B2D2FE7-M4(12B2D2F2E6-K)12B2D2F2EH5-O2(12B2D2F2EHG3C-Aq)12B2D2F2EHG3C2(-Am12B2D2F2EHG2CA)-Am12B2D2F2EHG3C-As12B2D2F2EHG2CA-Ac12B2D2F2EHG3CAAo12B2D2F2EHG2C2AO2(12B2D2F2EHG3C-K)12B2D2F2EHG2CA-P12B2D2F2EHGC2A-M12B2D2F2EHGCAC-M12B2D2F2EHAC3-Ca12B2D2F2E2AC3-11C2A2D2F2A-C4-D5ACAC9A2(7-A)-A2-AC2-C10-CA3-2C65-12B3DF9-Co11B3D2F8-N11B3D2FE7-2(M11B3D2F2E6-)K11B3D2F2E6-2(R11B3D2F2EIG4-)X11B3D2F2EIG2C2-Al11B3D2F2EIG2CA-Cn11B3D2F2EIG2CA-Am11B3D2F2EIG2CA-Ah11B3D2F2EIG2CA-Am11B3D2F2EIG2C2AAe11B3D2F2EIG2C2AAc11B3D2F2EIG2C2AAd11B3D2F2EIG2C2ABb11B3D2F2EIG2C2AK11B3D2F2EIG2CA-K11B3D2F2EIG2C2AP11B3D2F2EIG2CA-M11B3D2F2EIG3C-M11B3D2F2EIA4-Bc11B3D2F2EAC4-17C2AC5-2(AC)2ACA2CA3C5A11-C2-A-AC-A3-C7-A7-2C65-11B4D10-Cp10B4D2F8-N10B4D3F7-K10B4D3F7-Ar10B4D3FE6-Aj10B4D3FEI5-Cq10B4D3FEIH4-W10B4D3FE2I4-X10B4D3FE2IC2A-Aw10B4D3FE2ICA2-Aw10B4D3FE2ICAC-V10B4D3FE2IC2A-As2(10B4D3FE2IC3AAe)10B4D3FE2IC3AAw10B4D3FE2IC3AX10B4D3FE2IC3AAb10B4D3FE2IC2A-W10B4D3FE2IC3AAa10B4D3FE2IC3ABn10B4D3FE2IC2A-K10B4D3FE2I2(C-)Ce10B4D3FEIA4-Bn10B4D3FE2A4-S16C3A5-4C2ACA6C5A7-3AC3-A3C-A3-C10-C4-2CA64-11B4D10-Bi10B5D9-N10B5DF8-M10B5D2F7-R10B5D2F7-U10B5D3FJ5-R10B5D3FJ5-O10B5D3FJHCA2-O10B5D3FJHC2A-An10B5D3FJHCA2-An10B5D3FJHCAC-V10B5D3FJHC2A-As10B5D3FJHC3AAx10B5D3FJHC2ACAe10B5D3FJHC3AAl10B5D3FJHC3AAd10B5D3FJHC2A-O10B5D3FJHC3AR10B5D3FJHC3AK10B5D3FJHC2A-U10B5D3FJHC-A-M10B5D3FJHA-C-M10B5D2FAJA4-Cd10B5DFA-2A4-D2C8B5DF3AC4-3C2A10C4A7-2A-C4A2-C2A3-C7-A7-CA67-7B5D11-9B6D10-N8B7DF8-M8B7DFE7-T8B7DFE7-R8B7DF3E5-K8B7DF3EH4-O8B7DF3EGCA2-O8B7DF3EGC3-Bf8B7DF3EGCAC-Ay8B7DF3EGC2A-Ah8B7DF3EGCAC-V8B7DF3EGCA2CBr8B7DF3EGCA-CV8B7DF3EGC2A-Bq8B7DF3EGCAC-Ad8B7DF3EGC2A-O8B7DF3EG2(CA)K8B7DF3EGC3AK8B7DF3EGC2A-R8B7DF3EGA2C-M8B7DA3EA4-M8B7D3AEA4-Cc8B7D2A-2A4-D15CA-2AC4-C2A2C3ACA5C4A10-C-2AC-5A2-C12-A2-C91-9B6D10-N8B7D9-M8B7DF8-K8B7DFE7-M8B7DF2E6-K8B7DF2E-H4-K8B7DF3EHCA2-X8B7DF3EHCA2-Ai8B7DF3EHCAC-Bg8B7DF3EHC2A-At8B7DF3EHCAC-Am8B7DF3EH2(CA)V8B7DF3EHCA-CAu8B7DF3EHCAC-T8B7DF3EHCA2CX8B7DF3EHC2A-W8B7DF3EH2(CA)K8B7DF3EHC2A-K8B7DF3EHAC2-M8B7DA3EHA3-M8B6D4AEA4-M8B6DA3-A5-Aw8B6D2A2-2A4-D15C5A4-6C4A3C3A2C2-C5-A2-C2-2C-A2-2A11-A2-2A94-10B4D11-N9B5D10-M9B5D2F8-K9B5D3F7-2(K9B5D4F6-)O9B5D4F3-C2-W9B5D4FE2-C2-Ag9B5D4FE2-CA-Ag9B5D4FE-2CA-At9B5D4FEH2C2-V9B5D4FEH2C2AAe9B5D4FEHCAC-Af9B5D4FEH2C2-T9B5D4FEHCA2-X9B5D4FEH2C2AW9B5D4FEH2C2AK9B5D4FEHC2A-K9B5D4FEH2C2-P9B5D4AEHA3-M9B4D2A3-2A4-M9B4DA10-Aa9B5D2A2-2A4-D5CB3CAC4ACA2-C4-3A2CA3C6AC13-C9-A10-2A2-6A90-11B2D12-Ac10B3DF10-Az10B3D2F9-K10B3D3F8-K10B3D4F7-K10B3D4FE6-U10B3D4FE3-C2-W10B3D4FE2-AC2-S10B3D4F2EG2(A-)Q10B3D4F2EGACA-Ae10B3D4F2EGAC2-Af10B3D4F2EG2A-CAf10B3D4F2EG2AC-V10B3D4F2EG2A2-Y10B3D4F2EG2A2-X10B3D4F2EGAC2AW10B3D4F2EGAC2AU10B3D4F2EG2A2-U10B3D2F2A2EGAC2-K10B3DF2ACAEGA3-T10B3DA4-2A4-M10B3D2A9-T10B3DF2A2-A5-D9BC4A4-C5-A2C2ACA2C2A-A-2AC10-2C5-A15-2AC2-4AC90-10B2D13-Bd9B4DF10-M9B4D2F9-K9B4D3F8-P9B4D3FE7-K9B4D3FEF6-K9B4D3FEF2-2A2-O2(9B4D3FEF-GA3-S)9B4D3FEFJGA3-S9B4D3FEFJG2A2-S9B4D3FEFJG2AC-2(Y9B4D3FEFJG2A2-)Y9B4D3FEFJG3A-X9B4D3FEFJG4AO9B4D3FEFJG3A-Z9B4D2F2AFJG2A2-K9B4DFA2CAJGAC2-P9B4D2A3-3A3-M9B4DA4-A5-M9B4D2A9-M9B3D4A2-C5-D4C2A5C4A9-3A2C2-C-2A3-2AC8-3AC5-2A3-A11-4A2-4A2(-A)85-6B19-S10B2D2F10-M10B2D3F9-K10B2D4F8-P2(10B2D5F7-K)10B2D5FE2-AC2-O2(10B2D5FE-GA3-S)10B2D5FEIGA3-S10B2D5FEIGAC2-S10B2D5FEIGA2C-2(Y10B2D5FEIG2A2-)Y10B2D5FEIGACA-Ab10B2D5FEIGAC2AO10B2D5FEIG2A2-Z10B2D3F2AEIG2A2-K10B2D2F2ACAIGAC2-M10B2DF2AC2-3A3-M10B2DFA10-M10B2D2F2A8-8C2B2C5A8-D5A5CA-2AC9-A-2A4-3A3-AC10-2A5-A-A3-A12-C2-3AC2A114-2D8B3DF11-MD8B3D2FJ9-ArD8B3D2FJE8-AjD8B3D2FJEJ7-KD8B3D2FJEJ7-ZD8B3D2F2(JE)2GA3-UD8B3D2F2(JE)2G4-OD8B3D2F2(JE)2GA3-AiD8B3D2F2(JE)2GA3-ZD8B3D2F2(JE)2GA3-AnD8B3D2F2(JE)2GAC2-AgD8B3D2F2(JE)2G2A2-AnD8B3D2F2(JE)2G3A-WD8B3D2F2(JE)2G2AC-OD8B3D2F2(JE)2G2AC-KD8B3D2F2(JE)2G2A2-UD8B3D2F2(JE)2G2A2-KD8B3D2FJ2AE2GAC2-AaD8B3D2F2AC3A4-MD8B3D2FA9-ND8B3D2F2A8-D3A9C3A9-CA-3A-5C-3A12-2C2-2A-3A-2AC16-A-2A2-2A17-4A88-H24-H3EF5DFE2F11-D3EF3DFDFE2FJH9-T3EF3DFDFE2FJH9-Aa3EF3DFDFE2FJHI8-2(K3EF3DFDFE2FJHIH-G2A3-)K3EF3DFDFE2FJHI2HGA4-O3EF3DFDFE2FJHI2HG2A3-Ad3EF3DFDFE2FJHI2HG2A3-O3EF3DFDFE2FJHI2HG2A3-Ao3EF3DFDFE2FJHI2HG2AC2-X3EF3DFDFE2FJHI2HG2A3-Ad3EF3DFDFE2FJHI2HG3A2-2(U3EF3DFDFE2FJHI2HG4A-)2(K3EF3DFDFE2FJHI2HG3A2-)P3EF3DFDFE2FJHI2HGAC3-M3EF3DFDFE2FJH4A5-M3EF3DFDFE2FJH2ACA5-NA2EF3DFDFE2FJ2AC-A5-D2A2CA8C2A9-A2-2A-6C4A9-A-CA3-2A-2A2-2AC8-A2-C2-2AC-3A-AC16-A-CA89-2HIH21-2HIHI3EFJ2IE12-D2(HI)3EFJ2IEJHG9-M2(HI)3EFJ2IEJHGH2G6-M2(HI)3EFJ2IEJHGH2GA5-P2(2(HI)3EFJ2IEJHGH2G2A4-K)2(HI)3EFJ2IEJHGH2G2A4-R2(HI)3EFJ2IEJHGH2G3A3-Ab2(HI)3EFJ2IEJHGH2G3AC2-O2(HI)3EFJ2IEJHGH2G4AC-Ba2(HI)3EFJ2IEJHGH2G4A2-Ag2(HI)3EFJ2IEJHGH2G4A2-Ak4(2(HI)3EFJ2IEJHGH2G4A2-K)2(HI)3EFJ2IEJHGH2G4A2-M2(HI)3EFJ2IEJHGH2GA-C3-M2(HI)3EFJ2IEJHGH2GA5-N2(HI)3EFJ2IEJH5A5-N2(HI)3EFJ2IEJ2A-C7-D4A9C2A9-A-2A-A6C3AC12-C3-AC2(-2A)C9-A5-2A24-A69-G7-C14-A6GHG-H5-G8-A6GHGI3H4G8-D6GHGI3H4GC2A5-Ak6GHGI3H4GC3A4-M6GHGI3H4GC3A4-P6GHGI3H4GC4A3-P2(6GHGI3H4GC3A4-K)6GHGI3H4GC3AC3-K6GHGI3H4GC3A2C2-O6GHGI3H4GC4AC2-R6GHGI3H4GC4A3-Ak6GHGI3H4GC4A3-K6GHGI3H4GC3AC3-R2(6GHGI3H4GC5A2-K)6GHGI3H4GC5A2-P6GHGI3H4GC4A3-M6GHGI3H4GC3AC3-M6GHGI3H4GC2A5-N6GHGI3H2G5A5-DG12C3AC7-9C6A10-A-ACA3C-AC-3A12-CA3-AC3A2-C17-A24-A21-C24-2C19-C2A3C4-2C13-C2A3CGA7G2C8-C2A3CGA7G2C2A6-D2A3CGA7G2C2A6-Ch2A3CGA7G2C3A5-3(K2A3CGA7G2C4A4-)Aa2A3CGA7G2C4A4-U2A3CGA7G2C4AC3-Z2A3CGA7G2C5AC2-R2A3CGA7G2C4A4-R2A3CGA7G2C5A3-Ba2A3CGA7G2C4AC3-R2A3CGA7G2C4AC3-K2(2A3CGA7G2C5A3-U)2(2A3CGA7G2C5A3-T)2A3CGA7G2C4AC3-M2A3CGA7G2C4A4-D2A3CGA6G6A5-D12CA3-C7-2CACA2C3A-4A10-A-2A2-2(2A-)ACA12-CA2-2AC2A3-C17-A48-2C18-2A3-3C17-4C-3C3-2C11-2C2AC2AGCG2C4AC8-2C2AC2AGCG2C6A7-2C2AC2AGCG2C7A6-D2(C2A)GCG2C8A5-N2(C2A)GCG2C8A5-M2(C2A)GCG2C8A5-Aa2(C2A)GCG2C8A5-P2(C2A)GCG2C9A4-K2(C2A)GCG2C8AC4-R2(C2A)GCG2C9AC3-Aj2(C2A)GCG2C8A5-R2(C2A)GCG2C9A4-R2(C2A)GCG2C8AC4-K2(C2A)GCG2C9A4-Z2(C2A)GCG2C10A3-M2(C2A)GCG2C9A4-P2(C2A)GCG2C9A4-Aj2(C2A)GCG2C9AC3-2(M2(C2A)GCG2C8A5-)D8CG2C8A5-13CA3-C7-C4A2-2A3-3A10-A-A4-A5-A18-C5-C69-2C15-A-A2-CA-2C15-C3A2CA5C2-2C9-5ACACGA2CAC2A2C2(7-5ACACGA2CAC3AC)A6-D4ACACGA2CAC3ACA6-Av4ACACGA2CAC3ACA6-M4ACACGA2CAC3A3C2(5-M4ACACGA2CAC3AC2A)5-P4ACACGA2CAC3ACAC5-K4ACACGA2CAC3AC-A5-K4ACACGA2CAC3ACA6-K4ACACGA2CAC3AC2A5-K4ACACGA2CAC3ACAC5-K4ACACGA2CAC3AC2A5-W4ACACGA2CAC3AC2A5-P4ACACGA2CAC3AC2A5-M4ACACGA2CAC3AC2AC4-2(M4ACACGA2CAC3AC2A5-)D4ACACGA2CAC3ACA6-A8CA2CAC3ACA6-2AC2A2CA4C-C3-C7-A-A3-A-A4-A119-A24-2C24-C-C13-C-A3-A2-3C13-3AC7AC3ACA8-2(3AC7A2(CA)C2A7-)D2AC7A2(CA)C2A7-N2AC7A3(CA)C2(7-T2AC7A2(CA)C2A)7-K2AC7A2(CA)C2A7-P2AC7A3(CA)8-P2AC7A2(CA)C2A7-P2AC7A2(CA)C3A6-M2(2AC7A2(CA)C2A7-P)2(2AC7A2(CA)C3A6-K)2AC7A2(CA)C2A7-T2AC7A2(CA)C3A6-D2AC7A2(CA)C2A7-3AC7A2(CA)C2A7-11A2(CA)2C9-C2-A2CAC2ACA13-A4-A151-A52-C13-C15A2(9-16A)-A7-17AC7-D3(17A7-M)2(16A8-M)15A9-P15A9-Aa16A8-M16A8-Az17A7-T17A7-M15A9-D15A9-18A7-15A10-16A11-3A-A-2A2-A212-C11-2C11-4AC2A-6AC10-4A-10A10-3(4AC11A9-)D3AC11A9-R3AC10A-C8-M3AC10A-C8-Aa3AC10A10-M3AC10A10-Aa3AC8A12-Aa3AC9A11-M3AC9A11-Aj3AC10A10-Ar3AC10A-C8-D3AC8AC2A9-4AC9A-A9-4AC9A2-C8-4AC9A11-4AC-3A2(-A)262-C12-C11-A-2A-4A-2A-AC10-4A-10A10-15A10-14A11-13A12-2(D12AC11-)M2AC-C8A11-M3AC6AC13-M-4AC6A3(12-M12A)12-D11A13-12A13-13A12-11A-2A11-11A19-3A292-C24-C-2A-A3-4A-C10-5ACA-4A2C11-5AC7A12-G3C3A2CACA13-11AC13-3AC6AC-C12-D2A-3C2ACA14-D3C-2C3A15-D2-A4C3A14-D-3AC2A2CA14-D9A15-D9A-A13-10A15-9A-A14-10A15-10A17-5A368-C24-C2A2C-A2-2A14-C4-2C18-A-2A2CAC2A2C13-C5-3A-C14-C7-A-C14-C7-2C18-A21-2C-AC-CA17-C3ACA2C17-C3A2C4A15-2(C3A)CA15-CA-2(AC)A17-C3AC2A-A16-C2-AC2A-A216-
