model
size = 19 30 32, scale = 0.05, origin = -y
material deform = 1, fade = true, lighting = smooth, roughness = 0.3, metalness = 0.6
  colors = A:#979997 B:#180808 C:#281818 D:#DCCDA9 E:#D5B78D F:#C09668 G:#6C3618 H:#B27F50 I:#93522D J:#F9E9E9 K:#283918 L:#081808 M:#080818 N:#081818 O:#186858 P:#CD8D52 Q:#263828 R:#180818 S:#383818 T:#182818 U:#898B87 V:#488918 W:#285948 X:#3A755C Y:#334838 Z:#D3D4D3 Aa:#BBBBBA Ab:#282818 Ac:#647C56 Ad:#383838 Ae:#74B9ED Af:#A9A9A7 Ag:#5858A9 Ah:#64AEEA Ai:#585858 Aj:#55A3E7 Ak:#588D75 Al:#787978 Am:#686868 An:#B9B9A9 Ao:#485838 Ap:#A9B3B9 Aq:#484848 Ar:#383828 As:#AA989B At:#0757B3 Au:#263838 Av:#687968 Aw:#489989 Ax:#A7ABC9 Ay:#68687B Az:#485848 Ba:#687B78 Bb:#181808 Bc:#2682DE Bd:#4598E4 Be:#695869 Bf:#686858 Bg:#171828 Bh:#075CBD Bi:#485889 Bj:#385858 Bk:#748D91 Bl:#284848 Bm:#506E70 Bn:#585848 Bo:#954869 Bp:#282839 Bq:#6A78AA Br:#93D2EF Bs:#282808 Bt:#385847 Bu:#4DAA8B Bv:#343848 Bw:#3B99C9 Bx:#59A3CE By:#92B1B1 Bz:#8C98AF Ca:#333858 Cb:#326868 Cc:#4A3848 Cd:#6F778F Ce:#588389 Cf:#389989 Cg:#4F556C Ch:#384848 Ci:#F0C76F Cj:#485858 Ck:#787868 Cl:#E9DAC8 Cm:#704A18 Cn:#0649A2 Co:#AE663E Cp:#92B092 Cq:#786868
voxels
25-2(C2-)2B3-B6-BAb3LNB2Y4LB4-BCE14-3BE12-Ar2-2BF15-3C16-2(BCE15-C)B2(C18-)B133-G19-3(F18-)EHE19-HG18-I19-I18-I6-U17-B-IB18-D245-B18-2B18-B17-C54-B-B55-C18-C319-2C18-C2B-B14-2C2B14-2BC3B14-BC3B15-4B16-C-B13-C2-2CB12-CB3C13-C-4B2C13-6B13-2BCB2C14-5C16-3B15-2C17-C265-B2-C13-4BCB14-3BCB12-5BCB11-B-4BCB13-4BCB11-B2-3BCB10-B2-BC2BCB11-BC3B2CB10-C6B2C9-2C6B2(CB10-7B)CB9-2CB-BG2BCB9-C-B-4BCB11-B-BC2BCB14-3B-B14-2C240-2(C-)B-3BC9-2B-C6B8-2CB-C6B9-CBC7B9-B-C6BD9-2BC-5BD9-2BC6BD8-3BC6BD9-CBC6BD8-2(BC)6BD8-C2BC6BD8-2CB2(C6BD9-2B)2(C7B8-2CB)C7B10-BC7B13-6B13-2C207-B4-C9-C-B-6B8-B3C7B7-2CBC-7B8-3C7BD8-B2C7BM8-2(B2(2C7BL7-2B)2C7BL7-C)B2C7BBy8-B2C7BBz8-B2C7BD2(8-B2C8B)8-C-C8B10-C8B11-BC2(2-B)189-C8-2B-B-2B3-B8-11B6-C-11B6-2C10BD7-11BL6-7B5AAo6-7B5AAc6-C6B5AL6-7B5AY5-C7B5AY7-6B5AL7-6B5AY6-C6B5AL5-C-6B5AQ8-5B5AU7-11BD7-12B7-C11B7-C-10B11-8B12-C24-C18-C124-C16-3BC5B-B7-4BC7B5-C5BC6BD6-5BC6BM5-6BC6BL5-6BCB5AT5-6BCB5AAu5-6BCB5AL5-6BCB5AY4-C6BCB5AN2(6-5BCB5AL)5-C5BCB5AL5-6BCB5AL6-5BCB5AL7-4BCB5AZ6-5BC6BD2(6-C4BC7B)7-C-2BC7B11-C25-2(B18-)C90-B15-C-2(BC)B8-2(C2B)2CBCB7-B2(C2B)2CBC2B5-CB2(C2B)2CBCBM5-B2C2BC2B2CBCBT5-B2C2BC2B2CBCBK4-B-2C2BC2B5AK4-2B2C2BC2B5AN3-3B2C2BC2B5AN4-2B2C2BC2B5AL3-2C3(B2C2BC2B5AN5-)B2C2BC2B5AK4-2B2(2C2BC2B5AT5-B)2C2BC2B5AM6-2C2BC2B2CBCBBl6-2C2BC2B2CBCBD6-C3BC2B2CBC2B8-2BC2B2CBC2B10-C2B2CBC2B16-3C2(18-B)86-C-3B2-B11-5B2C2B7-BC3BC2B2C2B6-2BC3BC2B2CBD5-C-BC3BC2B2CBL5-2(3BC)2B2CBL4-2BSBC3BC5AL3-3BSBC3BC5AN3-3BSBC3BC5AX4-2BSBC3BC5AK3-B-BSBC3BC5AK2-C3BSBC3BC5AK3-C-BSBC3BC5AK5-BSBC3BC5AK4-2BSBC3BC5AN3-3B3(SBC3BC5AL5-B)SBC3BC2B2CBBm5-CSBC3BC2B2CBAy6-2BC3BC2B2CBD8-4BC2B2C2B9-2(C2B)2C2B10-2C2-C-2CB14-4CB18-B69-B17-C2B2-B10-2CB3C2B2CB6-2(BC)SB2C2B2CD3-2C2BCBCSB2C2B2CL3-6BCSB2C2B2CL5-2BCBCSBC5AAc3-3B2CBCSBC5AN5-3CBCSBC5AL5-3CBCSBC5AV2-BCB3CBCSBC5AK2(2-BCB3CBCSBC5AQ)2-2CB3CBCSBC5AAc3-CB3CBCSBC5AQ3-CB3CBCSBC5AK3-CB3CBCSBC5AN3-2B3CBCSBC5AY4-4CBCSBC5AL4-4CBCSBC5AM5-B2CBCSB2C2B2CBk5-C3BCSB2C2B2CD8-BCSB2C2B2CB7-B-3B2C2B2CB11-3C2B2CB14-3CB15-C73-2B13-C2-C4B-C9-C3B2C3BCB7-BC2(G2C)GCGD3-C2-2BC2(G2C)GCGL3-3BCBC2(G2C)GCGT3-C4BCG2CG5AT2(5-2(BC)G2CG5AW)2-B2CGCBCG2CG5AK2-B2CGCBCG2CG5AQ2-B2CGCBCG2CG5AAv2-3C2(GCBCG2CG5AQ3-2C)GCBCG2CG5AV3-2CGCBCG2CG5AW3-2CGCBCG2CG5AY3-BCGCBCG2CG5AK4-BGCBCG2CG5AK4-CGCBCG2CG5AK4-BGCBC2(G2C)GCGCf4-2BCBC2(G2C)GCGD7-2B2(G2C)GC2G7-B-GBCG2CGC2G11-C3-GC17-2B72-C16-C3B12-C2-B2C2B-CB8-3BGI2GIBGD5-3BC3GI2G2IGM5-3B2(C3GI2G2IGL3-C4B)C3GI5AN4-BG2BC3GI5AK2-C-BG2BC3GI5AK2-BCBG2BC3GI5AQ-4BG2BC3GI5AK2-BCBG2BC3GI5AAw2-2CBG2BC3GI5AQ3-CBG2BC3GI5AO2-2CBG2BC3GI5AK2-B2(CBG2BC3GI5AK3-)C2(BG2BC3GI5AN4-)BG2BC3GI5AL5-G2BC3GI2G2IGAw6-2BC3GI2G2IGD6-2BCG-GI2G2I2G7-BCG4-G2I-G94-B11-C6-B7-C2-C2BCB2-2B7-BC8B2C8-3BHIGI3HM4-4B2I2HIGI3HM4-3BG2I2HIGI3HL3-C3BG2I2HIGI3HL3-2BCBG2I2HI5AK4-BCBG2I2HI5AK2-C-BCBG2I2HI5AK-3BGCBG2I2HI5AK2-2BGCBG2I2HI5AAw-C2BGCBG2I2HI5AAl-2CBGCBG2I2HI5AAv2-2(CBG)2I2HI5AO2-2(CBG)2I2HI5AAf2-2(CBG)2I2HI5AQ2-2B2(GCBG2I2HI5AK3-B)GCBG2I2HI5AN4-G2(CBG2I2HI5AL5-)C2-2I2HIGI3HA10-2HIGI4H14-I110-C-C3-2B5-C-C3-4B2-2B4-C7B2C3BCD7-3BEHI2FE2FM6-2BIFEHI2FE2FL5-2B2IFEHI5AL4-B2G2IFEHI5AN3-CB2G2IFEHI5AK2-CB3G2IFEHI5AK-C2B2(3G2IFEHI5AW-3B)3G2IFEHI5AAa-2BC3G2IFEHI5AZ-3C3G2IFEHI5AAp2-2C3G2IFEHI5AO2-2C3G2IFEHI5AAa2-BC3G2IFEHI5AO2-BC3G2IFEHI5AK2-2B3G2IFEHI5AK4-B2G2IFEHI5AK5-2G2IFEHI5AY4-2G2-IFEHI5AT8-IFEHI2FE2FA12-I2FE3F125-C-CB2-2B3-2C-BC2-5B2-2B3-C5B-BCB2C2BED3-CB-4B2DE3D2EM3-CB2-BFE2DE5AL4-3BHFE2DE5AY3-2B2IHFE2DE5AK4-B2IHFE2DE5AW3-BG2IHFE2DE5AK-C2BG2IHFE2DE5AO-2BCG2IHFE2DE5AX-2BCG2IHFE2DE5AAi2-BCG2IHFE2DE5AAl2-BCG2IHFE2DE5AAi2-BCG2IHFE2DE5AV2-BCG2IHFE2DE5AAm2-BCG2IHFE2DE5AO2-BCG2IHFE2DE5AW4-G2IHFE2DE5AV4-G2IHFE2DE5AK4-G-IHFE2DE5AAc8-FE2DE5AAo9-E2DE5AL12-E3D2ED108-C11-C4-C-2B2-2B5-2B3-4BC3BC4-C2B-4B2D4JD3-C6B4D4JL2-C3B-2BE3D5AL4-3BF2E3D5AL4-BIHF2E3D5AK2-2BGIHF2E3D5AV3-BGIHF2E3D5AO-C2BGIHF2E3D5AAf-B2CGIHF2E3D5AAb-2BCGIHF2E3D5AAb2-BCGIHF2E3D5AAb2-2C2(GIHF2E3D6A2-BC)GIHF2E3D6A-B2CGIHF2E3D6A2-BCGIHF2E3D5AO4-GI2(HF2E3D5AK6-)HF2E3D5AN7-F2E3D5AK8-2E3D5AL11-3D4JA13-D5J85-B15-C2-B2-2CB2-2B4-C2B3-4BJ2BJD3-4B-3BD6JL3-7B2D6JL3-C5BE2DJ5AL2-C2BH2F2E2DJ5AN2-3BH2F2E2DJ5AK2-2BIH2F2E2DJ5AV2-2BIH2F2E2DJ5AO-CB2IH2F2E2DJ5AZ2(2-B2IH2F2E2DJ5AAb)2-C2IH2F2E2DJ5AAb2(-CB2IH2F2E2DJ6A)2-B2IH2F2E2DJ6A-BC2IH2F2E2DJ6A4-IH2F2E2DJ5AO5-H2(2F2E2DJ5AK6-)2F2E2DJ5AN7-F2E2DJ5AK8-2E2DJ5AL11-D6JBa12-7J67-B15-3B3-C9-3C-8B-BC3-C3B2-3B4CBCD3-7B2D2J4AT3-7B2D2J4AL3-3BFEBE2DJ5AT3-2BPF3E2DJ5AK2-C2B2(PF3E2DJ5AW3-BH)PF3E2DJ5AX-CB2HPF3E2DJ5AZ2-B2HPF3E2DJ5AAb2-B2HPF3E2DJ5AAg2-B2HPF3E2DJ5AAx-BC2HPF3E2DJ5AAxCBC2HPF3E2DJ5AAe2-B2HPF3E2DJ5AU2-BGHPF3E2DJ6A5-PF3E2DJ5AX5-PF3E2DJ5AW2(6-F3E2DJ5AK)7-3E2DJ5AK8-2E2DJ5AAu10-2D6JR12-7J66-2B15-B-2B-2C10-C5-6B2C3-C-2B-4B6CD3-5B-B3DJ4AY4-2B2FBE3DJ4AL3-CB3F2E3D5AL3-2B3F2E3D5AN3-B4F2E3D5AK2-CB4F2E3D5AK2-BH4F2E3D5AX2-BH4F2E3D5AZ-2BH4F2E3D5AT-2BH4F2E3D5AAx-BGH4F2E3D5AAe-BGH4F2E3D5AAg2CGH4F2E3D5ABc-CGH4F2E3D5AAl-CBG4F2E3D5AAl5-3F2E3D5AX5-3F2E3D5AO2(6-2F2E3D5AK)7-F2E3D5AK8-2E3D5AL9-E3D5JM11-ED6J81-C2B4-2C3-B5-CB2-B-3B6C5-5B6C2JD3-C5B2E2DJ4AAq3-C2B2F3E2DJ4AL3-2B3F3E2D5AL3-CB3F3E2D5AL3-B4F3E2D5AK2-CB4F3E2D5AK2-BH4F3E2D5AX2-BH4F3E2D5AZ-2BH4F3E2D5AT-2BH4F3E2D5ABo-BGH4F3E2D5AAgCBGH4F3E2D5AAj-CGH4F3E2D5ABc-CGH4F3E2D5AAy2-BG4F3E2D5AAm4-4F3E2D5AZ5-3F3E2D5AK6-2F3E2D5AK7-F3E2D5AL7-F3E2D5AK8-3E2D5AL8-3E2D5JM10-E2D6J64-3B6-2B5-C2-B-B2-2CB8-5B2-3B5C3-C7B5C2JD3-3BF4E3D4ACj4-2BF4E3D4AL3-2B2F4E2D5AL3-BH2F4E2D5AQ3-BH2F4E2D5AK2-CBH2F4E2D5AK-CB2H2F4E2D5AO-2B2H2F4E2D5AAa-2B2H2F4E2D5ABp-BG2H2F4E2D5AAg2BG2H2F4E2D5ABqC2G2H2F4E2D5AAg-2G2H2F4E2D5ABd-2B2H2F4E2D5ABe4-H2F4E2D5ABf4-H2F4E2D5AO5-2F4E2D5AO6-5E2D5AK7-4E2D5AQ7-4E2D5AT8-3E2D5AL8-3E3D4JM9-2E3D4JA12-2D5J45-B5-C2-2B6-3B4-2CB2-B5-C-4B-2B2CB3C3-C7B3D4JD3-3B5E3D4ACg4-2B5E3D4AL4-BF5E2D5AL3-BHF5E2D5AW2-BIHF5E2D5AK-CBIHF5E2D5AQ-2BIHF5E2D5AO-BGIHF5E2D5AAa-BGIHF5E2D5AAd-BGIHF5E2D5AAeBCGIHF5E2D5ABrBCGIHF5E2D5AAh-CGIHF5E2D5AAg4-HF5E2D5AAi6-5E2D5AAi2(5-F5E2D5AO)6-5E2D5AQ7-4E2D5AW7-4E2D5AQ8-3E2D5AL8-3E3D4JM8-D2E3D4JBk11-3D5J53-4B5-4B4-2C3-B4-C6B-B3C3B3-C3B11CD2-C3B4E4D4JAz3-CBF4E4D4JBs3-BHF4E3D5AK3-BHF4E3D5AAz2-BGHF4E3D5AY-CBGHF4E3D5AXC2BGHF4E3D5AAf-B2GHF4E3D5AZ-B2GHF4E3D5AAq-B2GHF4E3D5AAe2B2GHF4E3D5AAe-B2GHF4E3D5AAh2-BGHF4E3D5AAg4-HF4E3D5AAq6-4E3D5AAq5-F4E3D5AZ5-F4E3D5AX5-5E3D5ABt6-4E3D5AAc7-3E3D5AAo8-2E3D5AK8-2E3D5AM8-DE4D4JCb11-3D5J62-2B-B5-C7-C4B2CB-B6C3-4B4CB6CD3-C2BFE7D3JBj2-2CB2FE7D3JL3CBH2FE5D5AL2-BIH2FE5D5AN2CBIH2FE5D5AK2-BIH2FE5D5AK-BCIH2FE5D5ABu-BCIH2FE5D5AAa2BCIH2FE5D5ARB2CIH2FE5D5AAe-BCIH2FE5D5AAj-2BIH2FE5D5ABd2-BIH2FE5D5AAj4-H2FE5D5ABv4-H2FE5D5AAd5-2FE5D5AZ5-2FE5D5AQ5-EFE5D5AQ6-2E5D5AK6-2E5D5AL7-6D5AL8-5D5AM8-7D3JBl10-5D4J64-2B9-B4-3B3C2B-3C3B3-3B4CDCB5CD5-B2E7D3JCe4-BF2E7D3JL-2CBHF2E5D5AL2-BGHF2E5D5AN2CBGHF2E5D5AK-CBGHF2E5D5AK-B2GHF2E5D5AO-C2GHF2E5D5AAp2B2GHF2E5D5AR2B2GHF2E5D5AAh-B2G2(HF2E5D5AAj2-BG)HF2E5D5AAj2(4-HF2E5D5AAr)4-2F2E5D5AO5-F2E5D5AK5-3E2(5D5AK6-2E)5D5AK7-6D5AL7-E5D5AM8-7D3JBj10-5D4J64-B10-B5-2(2BC)B-3CB2C5-B6CB2C2DCD4-BF2E4F2E4DBi3-BHF2E4F2E4DCa-2CBHF2E4FE5AL2-BGHF2E4FE5AL2CBGHF2E4FE5AAc-2BGHF2E4FE5AV-2CGHF2E4FE5AAp-2CGHF2E4FE5AAa2(CG)HF2E4FE5AB-GCGHF2E4FE5AAe-BCGHF2E4FE5ABw-2BGHF2E4FE5ABx-2BGHF2E4FE5AAh3-G2(HF2E4FE5AAd4-)2F2E4FE5AZ4-2F2E4FE5AAc5-3E4FE5AV6-2E4FE5AT6-2E4FE5AK7-E4FE5AT7-E4FE5AM8-4F2E4DBa14-4DJ47-C4-C3-B5-B3-C3-2B-BC5-5B2CB7C5-B9CEDCD4-BEF2GCBC2GHEDJBi3-BHEF2GCBC2G4ACc-2CB2(HEF2GCBCG5AL-CBG)HEF2GCBCG5AK-2BGHEF2GCBCG5AX-CBGHEF2GCBCG5AAs-2BGHEF2GCBCG5AAf-2BGHEF2GCBCG5AR-2BGHEF2GCBCG5ABg2-BGHEF2GCBCG5ABh-2BGHEF2GCBCG5AAt2-BGHEF2GCBCG5AAt3-G2(HEF2GCBCG5AT4-)FEF2GCBCG5AAa4-FEF2GCBCG5AV5-EF2GCBCG5AK5-EF2GCBCG5AN6-F2GCBCG5AK6-F2GCBCG5AL7-2GCBC3G3AM7-2GCBCG2-EDJCd8-GCB5-DJD47-C3-2B9-5BC2B3CB2C5-2B11CD4-BE3IH2FPFH2FEAs2-C-BE3IH2FPFH2FEB2-2BHE3IH2FPF4AZ-CBGHE3IH2FPF4AL2-BGHE3IH2FP5AL-2BGHE3IH2FP5AK-2BGHE3IH2FP5AV-2BGHE3IH2FP5AK-2BGHE3IH2FP5AAf5(2-BGHE3IH2FP5AR)3-G2(HE3IH2FP5AR4-)HE3IH2FP5AO2(4-FE3IH2FP5AK)5-E3IH2F3M3AN6-3IH2F3M3AK6-3IH5M3AL7-2IH2FPA-F2AM7-2IH2FPF2-FEA17-ED44-C2-C4-4B6-2(2BC)2B6C5-B12CD4-BEFH2FGC2BCIHFAn3-BHEFH2FGC2BCIHFBb2-2BHEFH2FGC2B4AD-CBGHEFH2FGC2B4ACh2-BGHEFH2FGCB5AY2-BGHEFH2FGCB5AN2(2-BGHEFH2FGCB5AK)2-BGHEFH2FGCB5AX2-BGHEFH2FGCB5AAd2-BGHEFH2FGCB5AR2-BGHEFH2FGCB5AAd3-GHEFH2FGCB5AAd2-BGHEFH2FGCB5AR3-GHEFH2FGCB5AR4-HEFH2FGCB5AZ4-HEFH2FGCB5AX4-FEFH2FGCB5AV4-FEFH2FGC3M3AW4-FEFH2FGC3-M2AAc5-EFH2FMC3-M2AAo7-H2F5-M2AL8-2FMCB2MP2FM9-FGC3B3-Ci18-E44-C2-B-2B3CB2C5-2BCB10C5-B12CD4-BE2FC2GBU2(CG)ICk2-2BHE2FC2GBUC4AC3-CHE2FC2GBUC4ACl-CBCHE2FC2GBUC4ABa-CBCHE2FC2GBUC4AY-CBCHE2FC2GBU5A2-2BCHE2FC2GBU5AL-2BCHE2FC2GBU2A2TAbK2-BCHE2FC2GBU2A2TBbQ2-BCHE2FC2GBU2ARAtAhW2-BCHE2FC2GBU2ATCnAeU2-BCHE2FC2GBU2ATAtAeAs3-CHE2FC2GBU2ATBhAhAk2-BCHE2FC2GBU2ATAgAhX3-CHE2FC2GBU2ATBgAeU4-HE2FC2GBU2A2TAbO4-HE2FC2GBU5AW4-FE2FC2G4B3AK4-FE2FCG2B3M3AN4-F2-FCB-M3-M2AY7-FCGM4-B2AT8-CG5-B2AM8-CG5-BAPM15-BI-Cm18-D44-B-CBC2B3CB2C5-BCB11C4-B2F3LAuYAzAc4ND4-BFT7LN3KAr2-2BHK3L3NVW4KAb3-BEVL2N3K2V2KVKAa3-BLNQN7KOAnOBm2-CBLN3KLKWQX2OAaOL-CBE2NW3KOWKX2OAmOL-CBENKQ4K2OZR2TAb2-B-EQ2V2AfAlAaUBn2R3-K2-CFKQKVAkAmAaUBn2R3-K4-V2(KQ)WAv2X2R3-Q4-Q2K2QKW2OAdR3-An4-2KQK2OCp2AkAdR3-Ak3-GVKOVAkBeAaAsCqAdR3-O3-GKVAcAaApAyAaUAi2R3-Q3-G2KQAcAnAmAaUAi2R3-Af4-H2KVAcUZABf2R3-K4-H3K2QOWXAd4RK4-F5KOQ3-2MAnN4-3F3K2-2M-2MOL7-HG7-MKL8-IBM5-MKM8-CoG6-MKM8-G7-2ABb15-GCIP18-D38-
