model
size = 20 22 5, scale = 0.05, origin = -y
material deform = 1, fade = true, lighting = smooth, roughness = 0.3, metalness = 0.6
  colors = A:#000 B:#676C60 C:#FFF D:#15130D E:#6C4732 F:#080100 G:#61391F H:#563E31 I:#463026 J:#21180E K:#333733 L:#080904 M:#150600 N:#412511 O:#532E19 P:#6E4D38 Q:#46372F R:#332823 S:#4D3B33 T:#2D3334 U:#5D4740 V:#311F16 W:#2C2723 X:#424742 Y:#170B03 Z:#AA6C4C Aa:#231A16 Ab:#814929 Ac:#77462A Ad:#1B1913 Ae:#FFECC5 Af:#4B3227 Ag:#58351A Ah:#BB7652 Ai:#4C2916 Aj:#A2653E Ak:#311B0D Al:#815132 Am:#5A5D58 An:#D3DBEA Ao:#A7A1A2 Ap:#B88056 Aq:#D39568 Ar:#D8956C As:#906342 At:#CECED3 Au:#FAFFFF Av:#B3BDCE Aw:#CAD8EF Ax:#C9D3E2 Ay:#EFFFFF Az:#6C686C Ba:#936853 Bb:#928983 Bc:#CECECA Bd:#A9ABB0 Be:#68727E Bf:#B5C4D1 Bg:#5E5B5B Bh:#6F5145 Bi:#715347 Bj:#715E54 Bk:#BAB8B5 Bl:#838386 Bm:#DBECFC Bn:#A7AEB1 Bo:#744C38 Bp:#865847 Bq:#956558 Br:#9A7165 Bs:#4A4C4E Bt:#5A3B2A Bu:#A4674C Bv:#9A604A Bw:#AC6D53 Bx:#98654C By:#2E2618 Bz:#925D42 Ca:#BB7458 Cb:#E88E83 Cc:#FFA49A Cd:#FFA9A1 Ce:#D89377 Cf:#714F3F Cg:#764A35 Ch:#9C5949 Ci:#C07167 Cj:#D88679 Ck:#C57C72 Cl:#AC725D Cm:#4B311F Cn:#775138 Co:#976549 Cp:#C08367 Cq:#E2A181 Cr:#DEA68B Cs:#C0927B Ct:#97725B Cu:#975D3D Cv:#9C6245 Cw:#B87B59 Cx:#C0896F Cy:#FEC0A7 Cz:#FCBFA1 Da:#B6795D Db:#C47E58 Dc:#A76744 Dd:#97512C De:#A4623A Df:#E39A6D Dg:#B36F45 Dh:#D48863 Di:#E09F81 Dj:#EFA780 Dk:#955D3A Dl:#814C29 Dm:#D68D67 Dn:#CA835E Do:#A25E3A Dp:#FFB183 Dq:#FFD69F Dr:#FFE0AC Ds:#DE9065 Dt:#ECA27E Du:#FFD9AE Dv:#CF8B5D Dw:#985D38 Dx:#CC8860 Dy:#CF8865 Dz:#8D512E Ea:#C47747 Eb:#FFAC74 Ec:#FFC995 Ed:#E29874 Ee:#F9B384 Ef:#544A32 Eg:#895633 Eh:#AE714E Ei:#9D6242 Ej:#8D4F2B Ek:#985127 El:#F49868 Em:#FCA979 En:#F2B18D Eo:#EAB192 Ep:#FFC4A1 Eq:#E7A67C Er:#5B3827 Es:#F09A67 Et:#DE936A Eu:#9C8174 Ev:#3D2E23 Ew:#D88E62 Ex:#906C59 Ey:#4F5954 Ez:#77482C Fa:#814F30 Fb:#884F2B Fc:#9A5930 Fd:#CA845D Fe:#804427 Ff:#A26F4F Fg:#9A6D4E Fh:#464432 Fi:#906345 Fj:#D69368 Fk:#EAA176 Fl:#E8A680 Fm:#AE7B5D Fn:#725949 Fo:#83624F Fp:#4E5347 Fq:#322C14 Fr:#865838 Fs:#BA805B Ft:#E39A67 Fu:#EC9F68 Fv:#FAB07E Fw:#FFC298 Fx:#FFCFB1 Fy:#E2B69F Fz:#886754 Ga:#5D5849 Gb:#9A603B Gc:#BA7649 Gd:#D88D5E Ge:#E09C71 Gf:#EAAB8B Gg:#E3B19D Gh:#B18976 Gi:#BB774C Gj:#C28462 Gk:#CC957B Gl:#B58E7C Gm:#444740 Gn:#80543A Go:#4E4A49
voxels
3-12B425-18B422-BAn5CAoPApAqArAsQAtAuAvA2BAwAxAy3CAzR2SHBaIBbBcBd2A2-TBeBf2CBgJIBhBiUQBjBkBl3A2-3ABmBnAVBoBpBqBrUWBs4A2-3AXKYBtZBuBvBwBxBy5A2-4ALDBzCaCbCcCdCeCfAa4A2-AD3AVCgChCiCjCkClHI4A2-AD2AMCmCnCoCpCqCrCsCtE4A2-4ANAbCuZCvCwCxCyCzDaN3A2-4AAcDbDcDdDeDfDgDhDiDjDk3A2-4ADlDmDnDoDpDqDrDsDtDuDv3A2-Ad2AFDwDxDyDzEaEbEcEd2AeEeF2A2-Ef2AFEgEhEiEjEkElEmEnEoEpEqM2A4-2AOEErOGEsEtEAfEuAb3A4-DAAgEvREGEwAhAiAfExAj3A4-EyAAgEzFaFbFcFdAhFeAcFfFg2AL4-FhAYJAiFiFjFkFlFmPFnFoALFp4-FqAMOFrFsFtFuFvFwFxFyFzA6-GaKAAkGGbGcGdGeGfGgGhAaJ8-KANAlAjGiGjGkGlWX10-GmFAkGAlGnHGoAm15-AdTAm8-20B424-15B421-
