model
size = 32 12 10, scale = 0.05, origin = -y
material deform = 1, fade = true, lighting = smooth, roughness = 0.3, metalness = 0.6
  colors = A:#48FF00 B:#32FFEA C:#32FF8E D:#E00
voxels
195-2(AB3A27-AB3A315-)AB3A26-2AB4A25-BAB4A26-AB3A251-AB3A26-2AB4A24-3AB5A23-2(AB)5A24-2AB4A26-AB3A187-AB3A26-2AB4A23-D3AB5A19-A2-D3AB7A17-2A2-2(AB)7A17-2A2-3AB5A19-A4-2AB4A26-AB3A92-4C27-3C28-2AB4A23-2D2AB5A23-3AB7A17-2A-D3AB29ABAB27A-3AB7A17-2A2-3AB5A24-2AB4A26-3C30-4C28-4C27-3C28-2AB4A23-2D2AB5A23-3AB7A17-2A-D3AB29ABAB27A-3AB7A17-2A2-3AB5A24-2AB4A26-3C30-4C91-AB3A26-2AB4A23-D3AB5A19-A2-D3AB7A17-2A2-2(AB)7A17-2A2-3AB5A19-A4-2AB4A26-AB3A187-AB3A26-2AB4A24-3AB5A23-2(AB)5A24-2AB4A26-AB3A251-AB3A26-2AB4A25-BAB4A26-AB3A152-
