model
size = 21 32 14, scale = 0.05, origin = -y
material deform = 1, fade = true, lighting = smooth, roughness = 0.3, metalness = 0.6
  colors = A:#222 B:#3A1C74 C:#63C D:#412083 E:#FC3 F:#855CD8 G:#000 H:#5027A0 I:#331966 J:#7547D2 K:#482491 L:#EEE M:#BBB N:#F93 O:#9571DE P:#A585E5 Q:#B59AEB R:#777 S:#300 T:#FF9 U:#FF3 V:#99C
voxels
24-7AK6AB6-2B6AD6A6-2B13A6-6B9A6-9B5AB6-10B5A6-2D3BD3BH2B3A6-7D4BKB2A6-2K3A2D4A4B6-K2H3LKA4LBKB6-HFHA2LHKLDAMLBD6-HFJAMLFHK2ALK2B6-JF2AMLJA2HLMLDB6-J2CLMLFAL2AML2D6-FJ2F2L2F4LH2K6-FJ2FO3P2FCJFHK6-JG2FO4QOFCJFH6-FJGFOG2QGPGFG2J6-HGJ2FGPQGP2(GF)J6-DHGH3GOPGOF2GJ6-D2KJ8F2CJ6-DHGDGJFG2CGFGJF6-B3(DG)JGFGCGJF6-2BDG2D2(GD)JG3J7-3B6DJKJH9-4B3D3KD113-11(15A6-)15A5-17A4-4A4L2A3L4A4-3ALM2AL2A2L5A4-4AL5ALM5A4-3ALML4ALM5A3-4ALM2(2AL)ML5A2-5A4L2A2L6A3(2-19A)2-4(A2M)3(AM)A2-4(2AM)AM2A2MA2-ARM2AMA2(M2A)3(MA)2-A2M2AM2(A2M)AM2A2MA2-19A109-11(15A6-)15A5-3(17A4-)17A3-19A6(2-I17AI)2-I4(2GA)2(GA)GI2-IA3(G2A)GAG2A2GI2-ASG2AGA2(G2A)3(GA)2-2(2AG)2(A2G)A2(G2A)2-19A5-14A67-A-15A-A2-A-A13-A-A2-A-2A11-2A6(-A2-A-15A)-A7(2-19A)2-I17AI-C4(I17AI2C)I17AI3C2(17A4C)17A2C-2(I17AI2-)19A4-16A6-14A46-E17A5(E2-EA15-A)E2-E2A13-2A2(E2-EA15-A)6(E2-E17-)E-CI17-I2CI17-IC168-2C17-4C17-2C-I17-I2-3A13-3A4-16A9-7E14-7N8-19A13(2-A17-A)-CI17-IC252-2C17-2C-I17-I2-2A15-2A4-2A2E7-2E3A2(7-2E)6-C17A4(C2-C17-)C3(2-H17-H)3(2-D17-D)2(2-B17-B)-CB17-BC294-2C17-2C-I17-I3-2A13-2A6-2(NE9-EN5-C17A4(C2-C17-)C3(2-H17-H)3(2-D17-D)2(2-B17-B)-CB17-BC294-2C17-2C-I17-I2-3A13-3A5-)NE9-EN5-C17A4(C2-C17-)C3(2-H17-H)3(2-D17-D)2(2-B17-B)-CB17-BC294-2C17-2C-IA15-AI4-AE11-EA7-NE9-EN5-19A13(2-A17-A)-CI17-IC252-2C17-2C-I15-AFI3-2A13-2A6-NE9-EN26-E17A14(E2-E17-)E-CI17-I2CI17-IC168-2C17-4C3-A13-2C2-A15-D4-2A11-3D7-ANE7-ENA47-16(19A2-)16AT2A-CI15AEAI2CI15AUAI2CI15AEA2(I2CI17A)I3C2(17A4C)17A2C2-16AD4-15A2D4-6A5E2A4D5-B2A9E71-8AK6ABA4-3B2(6AD)4-3B14A4-D6B10A4-10B5ABA4-11B6A4-3D3BD3BH2B4A4-8D4BKB2AD4-6K5D5BA4-HK4H3K4DBK2B4-2HFHF3H2K2D3BDB4-2HF3J2FH3KDK3B4-2(FJ)2CF2J2H2K2D2B4-FJ2C4FCJFH2K3D4-2FJ3F2OFCJ2FH2KD4-HFJ2FO3P2FCJFHKD4-HJG2FO4QOVCJFHK4-JFJGFOG2QGPGFG2JH4-KHGJ2FGPQGP2(GF)JF4-2DHGH3GOPGOF2GJF4-2DKBJ8F2C2J4-2DHGDGJFG2CGFGJ2F4-2B3(DG)JGFGCGJ2F4-3BDG2D2(GD)JG3JF4-2A3B6DJKJ2HD4-3AKA2B3D3K4D4-8A2B7D5-AB2A7N4D87-
