model
size = 26 27 9, scale = 0.05, origin = -y
material deform = 1, fade = true, lighting = smooth, roughness = 0.3, metalness = 0.6
  colors = A:#F93 B:#EEE C:#F60 D:#F96 E:#F99 F:#111
voxels
470-5A13-3A5-6A11-5A4-6A10-7A3-6A10-6A5-5A10-5A7-3A11-4A10-A12-A93-8A17-10A15-12A13-14A11-16A9-3(18A8-)18A9-3(16A10-)16A9-18A7-2(20A6-)20A5-AD18ADA3-A3D16A3DA2-4D16A4D2-5D14A5D2(A-6D12A6D)A-5D-A11-A5DA-3D16-A4DA61-8A17-10A15-12A13-14A11-16A9-3(18A8-)18A9-3(16A10-)16A9-18A7-C18AC5-2C18A2C4-2C18A2C3-2C-18A-2C2-C3-16A3-C-2C3-16A3-3C5-14A5-2(2C6-CA3C2A3CAC6-)2C5-2C10-2C5-2C3-3C12-3C3-6C16-5C35-8A17-10A15-12A13-14A11-16A9-3(C16AC8-)C16AC9-16A10-3A3B4A3B3A10-2(2A5B)2A10-2A4B4A4B2A9-C3A2B6A2B3A3(C8-C16A)C8-18A9-16A11-14A13-12A15-A3C2A3CA147-8A17-3A4-3A15-4A4B4A13-C12AC11-3(C14AC10-)3(16A10-)3A3B4A3B3A10-2(2A5B)2A10-2A4B4A4B2A10-3A2B6A2B3A4(10-16A)11-14A13-12A15-2AC4AC2A173-8A17-3A4-2A16-C3A4B3AC14-C10AC13-C5A2E5AC12-C12AC4(12-14A)12-2A3B4A3B2A12-A5B2A5BA12-A4B4A4BA12-2A2B6A2B2A4(12-14A)13-12A15-10A199-8A18-8A17-3A4B3A16-10A15-C4A2E4AC13-C12AC4(12-14A)12-2A3B4A3B2A12-A5B2A5BA12-A4B4A4BA12-2A2B6A2B2A3(12-14A)13-12A15-10A201-4C21-2A2C2A19-8A17-2CA4BA2C16-C8AC16-C3A2E3AC15-2C8A2C4(14-12A)14-A3B4A3BA13-C5B2A5BC12-C4B4A4BC13-A2B6A2BA2(14-12A)14-5C2A5C15-3C4A3C358-2E24-2E98-3A4-3A15-A3BA2-A3BA14-2BF2B2-2BF2B14-2BFBA2-ABF2B14-A2BA4-A2BA15-2A6-2A294-
