model
size = 12 14 32, scale = 0.05, origin = -y
material deform = 1, fade = true, lighting = smooth, roughness = 0.3, metalness = 0.6
  colors = A:#0F0F0F B:#373737 C:#1E1E1E D:#323232 E:#0A0A0A F:#3C3C3C G:#141414 H:#8D1204 I:#282828 J:#BB1313 K:#379D30 L:#D7387F M:#124BC6 N:#D97708
voxels
16-4C8-4C139-6C6-G4CG3(6-AE2HEA)6-2E2H2E7-3(4H8-)4H54-2C2(FD)2C4-G6BG3(4-AH6A)4-EH5A3(E4-E6H)E6-4H53-2C6H2C2-GBH6BG6(2-2A6-2A)2-2E6-2E61-2C3(FD)HD2CG2BH7BG-6(A8-A2-)E8-E61-C5(FD)CG2BHB4J2BGNA8-AN-5(A8-A2-)E8-E2-E8-E49-C2(DF)4JDFCG2B2HB2J3BG2A2(8-4A)8-2A-4(A8-A2-)E8-E49-C2(FD)JDFJFDCG5B2J3BGK4(A8-A2K)A8-AK-2(A8-A2-)E8-E49-C2(DF)JFDJDFCG2B5J3BG2A5(8-4A)8-2A-A8-A2(2-E8-E)37-CFD6JFDCG2BJ2B2J3BGM5(A8-A2M)A8-AM-2(A8-A2-)E8-E37-C5(DF)CG2BJ2B2J3BG2A4(8-4A)8-2A-3(A8-A2-)E8-E2-E8-E25-2C4(DF)2CG2BJ2B2J3BGLA8-A2LA8-AL-6(A8-A2-)E8-E2-E8-E16-6H4-C4(FD)C2-GB6JBG5(2-A8-A)4(2-E8-E)3-2C4I2C5-C4IC6-C4IC4-C4(DF)C2-GB6JBG4(2-A8-A)2(2-E8-E)3-3(A6-A4-)C6IC27-CFN3(FD)C2-G8BG3(2-A8-A)2(2-E8-E)3-3(A6-A4-)G6LG39-CDN3(DF)C2-G8BG3(2-A8-A)2-E8-E3-3(A6-A4-)C6IC51-CF6NDC2-G8BG3(2-A8-A)2-E8-E3-2(A6-A4-)G6MG63-C4(DF)C2-G8BG2(2-A8-A)2(2-E8-E)3-2(A6-A4-)C6IC62-2C2(F2KD)2CG10BG-2(A8-A2-)E8-E3-2(A6-A4-)G6KG74-C2(FD)2K2(FD)CG10BGA10-A-A8-A2-E8-E3-2(A6-A4-)C6IC74-C2(DF)2K2(DF)CG10BGA10-A-A8-A2-E8-E3-A6-A4-G6NG86-C2(FD2K)FDCG10BGA10-A-E8-E2-E8-E3-A6-A4-C6IC86-C5(DF)CG10BGA10-A-E8-E3-A6-A4-G6JG98-CFD6MFDCG10BG-E8-E2-E8-E3-C6-C5-6I99-C5(DF)CG10BG-E8-E3-A6-A4-C6IC6-4I100-C2(FD)4LFDCG10BG-E8-E3-A6-A4-A6CA110-2CFDFLFDLD2CG10BG-E8-E3-A6-A5-6A112-CDFDLDFLFC2-G8BG3-A6-A2(4-2A)6-4A113-2C6L2C2-G8BG3-A6-A4-8A124-2C2(DF)2C4-G6BG4-A6-A5-6A126-C2(FD)C6-G4BG6-6A138-2CFD2C6-C4BC7-4A136-
