model
size = 20 26 20, scale = 0.05, origin = -y
material deform = 1, fade = true, lighting = smooth, roughness = 0.3, metalness = 0.6
  colors = A:#222 B:#ECB88A C:#FFFFFB
voxels
306-8A12-8A472-8A12-8A490-12A8-12A313-2B17-4B15-6B14-6B15-4B17-2B72-14A6-14A272-2B16-6B13-8B12-8B11-10B10-10B11-8B12-8B13-6B16-2B31-16A4-16A9-9(6A14-)6A55-4B14-8B11-10B10-10B9-3(12B8-)12B9-10B10-10B11-8B14-4B9-18A2-18A6-9(10A10-)10A34-2B15-8B11-10B9-2(12B8-)12B7-14B6-14B7-2(12B8-)12B9-10B11-8B7-18A2-18A5-9(12A8-)12A31-6B12-10B9-12B8-12B7-5(14B6-)14B7-12B8-12B9-10B5-40A4-9(12A8-)12A13-2B15-8B11-10B9-12B7-2(14B6-)14B5-16B4-16B5-2(14B6-)14B7-12B9-10B5-40A3-9(14A6-)14A11-4B14-8B10-12B8-12B7-14B6-14B5-3(16B4-)16B5-14B6-14B7-12B8-2(12B4-40A3-9(14A6-)14A10-6B12-10B9-12B7-14B6-14B5-5(16B4-)16B5-14B6-14B7-)12B4-40A3-9(14A6-)14A11-4B14-8B10-12B8-12B7-14B6-14B5-3(16B4-)16B5-14B6-14B7-12B8-12B4-40A3-9(14A6-)14A12-2B15-8B11-10B9-12B7-2(14B6-)14B5-16B4-16B5-2(14B6-)14B7-12B9-10B5-40A3-9(14A6-)14A30-6B12-10B9-12B8-12B7-5(14B6-)14B7-12B8-12B9-10B5-40A4-9(12A8-)12A33-2B15-8B11-10B9-2(12B8-)12B7-14B6-14B7-2(12B8-)12B9-10B11-8B7-18A2-18A5-9(12A8-)12A52-4B14-8B11-10B10-10B9-3(12B8-)12B9-10B10-10B11-8B14-4B9-18A2-18A6-9(10A10-)10A51-3C2-3C11-10C9-12C8-C-8C-C11-2C2B2C16-2B36-A4-A33-A-A2-A-A13-A4-A29-16A4-16A9-9(6A14-)6A136-2B18-2B132-14A6-14A487-12A8-12A204-
