model
size = 30 31 24, scale = 0.05, origin = -y
material deform = 1, fade = true, lighting = smooth, roughness = 0.3, metalness = 0.6
  colors = A:#2A4A5B B:#F70 C:#46647C
voxels
216-3B12-5B8-6B8-7B9-6B6-9B9-6B5-8B11-6B3-8B13-7B-8B14-14B17-14B16-16B14-19B11-8B-11B11-7B4-10B9-8B5-8B9-8B6-7B10-8B6-6B10-19B12-17B15-14B20-8B729-2A24-2A2-2A24-2A603-2A22-2A4(4-CA22-AC)4-2A22-2A63-2A24-2A2(2-CA24-AC)2-2A24-2A543-2A22-2A4-CA22-AC124-CA22-AC4-2A22-2A3-2A24-2A2-CA24-AC62-CA24-AC2-2A24-2A484-3(A22-A5-CA22-AC184-CA22-AC3-CA24-AC122-CA24-AC-3A24-6A24-3A423-)A22-A5-CA22-AC184-CA22-AC3-CA24-AC122-CA24-AC-3A24-6A24-3A393-A22-A6-A22-A5-2A22-2A4-CA22-AC124-CA22-AC4-2A22-2A3-2A24-2A2-CA24-AC62-CA24-AC2-2A24-2A-3A24-6A24-3A393-A22-A6-A22-A5-2(2A22-2A4-)4(CA22-AC4-)2A22-2A4-2A22-2A3-2(2A24-2A2-)2(CA24-AC2-)2A24-2A2-3(2A24-2A-3A24-6A24-3A393-A22-A6-A22-A5-7(2A22-2A4-)2A22-2A3-5(2A24-2A2-))4(2A24-2A-3A24-6A24-3A363-2(A22-A6-)A22-A5-7(2A22-2A4-)2A22-2A3-5(2A24-2A2-))2A24-2A-3A24-6A24-3A306-2A14-2A10-4A14-4A7-5A14-5A6-3A18-3A6-A22-A5-7(2A22-2A4-)2A22-2A3-5(2A24-2A2-)2A24-2A-4A22-8A22-4A2-2A22-2A6-4A14-4A10-2A14-2A194-2A10-2A14-2(4A10-)6A10-6A2(8-4A14-4A)7-3A18-3A5-4A18-4A3(4-3A21-2A)3-3(3A22-3A2-)3A22-3A-4A22-7A3(24-6A)24-7A22-10A18-14A14-8A2-6A14-6A6-2(6A10-)4A10-4A14-2A10-2A110-A4-A22-3A4-3A18-5A4-5A16-4A6-4A3(16-2A10-2A)12-4(4A14-4A8-)4A14-4A5-4A21-3(3A2-3A22-)3A-4A5(22-8A)22-4A4-2(4A14-4A8-)6A10-6A12-4A6-4A2(16-5A4-5A)18-3A4-3A22-A4-A26-2A26-6A22-10A20-4A2-4A2(20-3A4-3A)16-3B-3A4-3A-5B8-6B3A4-A7B9-4B12-5B9-4B12-3B11-4B12-BA2(12-4B12-2A)12-2(A2B15-4A8-)A2B15-2B2A8-A2B15-3BA8-3(2AB15-5B7-)3A15-5B7-3A15-4B8-4A14-3BA12-2A12-2B14-2A10-2B16-2A10-2A18-3A4-3A20-4A2-4A2(20-10A)22-6A26-2A27-4(4A26-)4A19-3B4-4A4-5B8-6B3-4A-7B9-6B3A4-8B9-6B3A4-6B11-6B3A4-4B13-7BAB4-3B14-9B4-B2A15-5B7-2B-2A13-5B7-4BA13-5B7-7B11-5B7-8B11-4B7-10B9-4B9-8B9-4B10-7B10-3B10-A6B10-3B10-6B12-2B10-5B25-4B16-3A4-5B18-3A4-3A23-4(4A26-)4A199-3B12-5B8-6B8-7B9-6B3-3A9B9-6B3-2A8B11-6B3-8B13-7B-8B14-14B17-14BA15-16B14-19B11-8B-11B11-7B4-10B9-7B4-2A8B9-7B4-3A7B10-6B4-3A-6B10-6B4-9B12-5B4-8B15-3B4-7B19-A8B21-4A349-3B12-5B8-6B8-7B9-6B6-9B9-6B5-8B11-6B3-8B13-7B-8B14-14B17-14B16-16B14-19B11-8BA11B11-7B4A10B9-8B3A2-8B9-8B3A3-7B10-8B2A4-6B10-19B12-17B15-14B20-8B188-
