model
size = 30 31 9, scale = 0.05, origin = -y
material deform = 1, fade = true, lighting = smooth, roughness = 0.3, metalness = 0.6
  colors = A:#777 B:#FF9B00 C:#004 D:#39C E:#007 F:#002 G:#005 H:#888 I:#F3C J:#FF0 K:#FC6 L:#FCC M:#F3F N:#FCF O:#FF3 P:#FF9 Q:#FFF R:#F6F
voxels
431-8A2(22-8H)22-8A830-3A6-3A2(18-3H6-3H)18-3A6-3A827-2A10-2A2(16-2H10-2H)16-2A10-2A412-2A26-6A22-10A18-6A2-6A14-6A6-2(6A10-)6A7-5A14-5A2(6-3A18-3A)5-4A18-4A3(4-3A20-3A)3-4A20-4A3(2-3A3-2F12-2F3-3A)-4A3-2F12-2F3-7A3(24-6A)24-7A22-10A18-14A14-8A2-8A10-2(8A6-)8A10-8A2-8A14-14A18-10A22-6A26-2A26-6A22-10A18-6A2F6A14-6A2F2C2F6A10-6A3F2CGE3F6A7-5A2F2CF2CGEF2C2F5A6-3A2F3CGFC2GEF3CG2F3A6-3A2F2C2GFC2GEF2C2G2F3A5-4A2FC3GFC2GEFC3GFC4A4-3A2(FC)3GFC2GEFC3GF3C2(2A4-3A2(FC)3GFC2GEFC3GFCGC)2A3-4A2(FC)3GFC2GEFC3GFCGC2(3A2-3AFCGFC3GFC2GEFC3GFCGF)3A2-3AFCG3(FC2GE)FCGF3A-4AFCG3(FC2GE)FCGF7A3(FCG3(EFC2G)EF2GEF6A)FCG3(EFC2G)EF2GEF7A2F3(EFC2G)EFC2F10A2F2(C2GEF)C2GE2F14A2FGEFC2GEFCG2F8A2-8A3FC2GE3F8A6-8A2FGE2F8A10-8A2F8A14-14A18-10A22-6A26-2A26-6A22-10A18-14A14-18A10-22A7-2(24A6-)24A5-3(26A4-)26A3-3(28A2-)28A-240A2-26A6-22A10-18A14-14A18-10A22-6A26-2A26-6A22-10A18-6AGF6A14-6A2GEC2F6A10-6A2G3E3C2F6A7-5A2G5E5C2F5A6-3A2G7E7C2F3A6-3AG8E8CF3A5-4AG8E9C4A3(4-3AG9E9CFC2A)3-4AG9E9CFC3(3A2-3AG10E10CF)3A-4AG10E10CF7A3(G11E11CF6A)G11E11CF7A2G9E9C2F10A2G7E7C2F14A2G5E5C2F8A2-8A2G3E3C2F8A6-8A2GEC2F8A10-8AGF8A14-14A18-10A22-6A26-2A26-6A22-10A18-6A2-6A14-6A6-2(6A10-)6A7-3ABJP12-B4DA6-A5DB8-Q6D2A6-A5DI6-J7DJ2A5-2A6D5-7DK-4A4-2A6D3-K7D4-3A4-2AI5DI-7DQ5-3A4-2AL13D7-3A3-4A12DIB6-4A2-3A-15DM5-3A2-3A-18DL2(2-3A)-L7D-BK9D-3A-4A2-7D4-L8DO6A3-7DR5-P7D6A3-N7D6-N6D6A4-7DM6-6D6A4-K18D-7A4-17D-10A4-NI11DM14A6-OBI3DIJ8A2-8A10-2(8A6-)8A10-8A2-8A14-14A18-10A22-6A198-3B12-5B8-6B8-7B9-6B6-9B9-6B5-8B11-6B3-8B13-7B-8B14-14B17-14B16-16B14-19B11-8B-11B11-7B4-10B9-8B5-8B9-9B5-7B10-8B6-6B10-19B12-17B15-14B20-8B188-
