model
size = 32 32 6, scale = 0.05, origin = -y
material deform = 1, fade = true, lighting = smooth, roughness = 0.3, metalness = 0.6
  colors = A:#FC0 B:#F00 C:#EEE
voxels
5-24A7-24A8-24A6-28A4-28A2-4A6(24-8A)2-11C2-7C2-2(8A-13C-8C-)2(8A-2(3C2-)3C6-3C-)3(8A-2(3C2-)3C-8C-)8A-2(3C2-)3C6-3C-8A-2(3C2-)3C-8C-8A-2(3C2-)3C-7C2-8A-2(3C2-)3C-6C3-6(8A24-)4A2-28A4-28A6-2(24A8-)24A6-28A4-28A2-4A6(24-8A)2-7C2-11C2-2(8A-8C-13C-)2(8A-3C6-2(3C2-)3C-)3(8A-8C-2(3C2-)3C-)8A-3C6-2(3C2-)3C-8A-8C-2(3C2-)3C-8A2-7C-2(3C2-)3C-8A3-6C-2(3C2-)3C-6(8A24-)4A2-28A4-28A6-3(24A8-)24A6-28A4-28A2-4A6(24-8A)2-7C2-11C2-2(8A-8C-13C-)2(8A-3C6-2(3C2-)3C-)3(8A-8C-2(3C2-)3C-)8A-3C6-2(3C2-)3C-8A-8C-2(3C2-)3C-8A2-7C-2(3C2-)3C-8A3-6C-2(3C2-)3C-6(8A24-)4A2-28A4-28A6-24A8-24A6-28A4-28A2-68A23(24B8A)24B68A2-3(28A4-)28A2-68A23(24B8A)24B68A2-28A4-28A6-24A8-24A6-28A4-28A2-4A6(24-8A)2-11C2-7C2-2(8A-13C-8C-)2(8A-2(3C2-)3C6-3C-)3(8A-2(3C2-)3C-8C-)8A-2(3C2-)3C6-3C-8A-2(3C2-)3C-8C-8A-2(3C2-)3C-7C2-8A-2(3C2-)3C-6C3-6(8A24-)4A2-28A4-28A6-24A8-24A4-
