model
size = 21 32 21, scale = 0.05, origin = -y
material deform = 1, fade = true, lighting = smooth, roughness = 0.3, metalness = 0.6
  colors = A:#EEE B:#3CF C:#BBB
voxels
595-3(7A14-)7A581-7A12-3(11A10-)11A559-5A13-3A5-3A9-A11-A8-A11B2(A8-A11-)A537-5A14-2A5-2A10-2A9-2A7-A13-A6-A13B2(A6-A13-)A11-5A499-5A14-2A5-2A10-2A9-2A7-A13-A5-A15-A4-A15BA4-A10-2C3-A4-A15-A8-9A14-5A436-5A16-5A14-2A5-2A11-2(A9-)A11-A6-2A13-2A3-A17-A2-A17BA2-A10-3C4-A2-A17-A6-11A12-7A393-5A16-5A15-2A3-2A14-A5-A12-2A7-2A9-A11-A7-A13-A5-A15-A3-A17-A2-A17BA2-A3-2C12-A2-A17-A6-11A11-9A15-3A354-3A16-7A14-2A3-2A13-2A5-2A12-A7-A11-2(A9-)A11-A7-A13-A4-2A15-2A-A19-2A19B2A4-3C12-2A19-A4-13A9-11A13-5A18-14(A20-)A19-3A17-5A14-9A12-2A5-2A11-2A7-2A10-A9-2A8-A11-A7-A13-A5-A15-A3-A17-A-A19-2A19B2A5-2C12-2A19-A4-13A9-11A12-7A16-14(3A18-)3A17-5A15-7A13-9A12-2A5-2A11-2A7-2A10-A9-2A8-A11-A7-A13-A5-A15-A3-A17-A-A19-2A19B2A11-2C6-2A19-A4-13A9-11A12-7A15-15(5A16-)5A15-7A13-9A12-2A5-2A11-2A7-2A10-A9-2A8-A11-A7-A13-A5-A15-A3-A17-A-A19-2A19B2A11-2C6-2A19-A4-13A9-11A12-7A16-14(3A18-)3A17-5A15-7A13-9A12-3A3-3A11-3A5-3A10-A9-2A8-A11-A7-A13-A5-A15-A3-A17-A-A19-2A19B2A2-2C7-2C6-2A19-A4-13A9-11A13-5A18-14(A20-)A19-3A17-5A14-9A12-9A11-4A3-4A10-A9-2A8-A11-A7-A13-A5-A15-A3-A17-A-A19-2A19B2A2-2C11-2C2-2A19-A5-11A11-9A15-3A354-3A16-7A14-7A13-9A12-A7-2A10-A9-2A8-A11-A7-A13-A4-2A15-2A-A19-2A19B2A15-2C2-2A19-A5-11A12-7A393-5A16-5A15-7A14-A5-A12-2A7-2A9-A11-A7-A13-A5-A15-A3-A17-A2-A17BA2-A6-3C8-A2-A17-A7-9A14-5A436-5A16-5A14-2A5-2A11-2(A9-)A11-A6-2A13-2A3-A17-A2-A17BA2-A6-3C8-A2-A17-A9-5A499-5A14-2A5-2A10-2A9-2A7-A13-A5-A15-A4-A15BA4-A6-3C6-A4-A15-A535-5A14-2A5-2A10-2A9-2A7-A13-A6-A13B2(A6-A13-)A557-5A13-3A5-3A9-A11-A8-A11B2(A8-A11-)A578-7A12-2A7-2A10-2A7B2(2A10-2A7-)2A600-3(7A14-)7A7-
