model
size = 13 12 32, scale = 0.05, origin = -y
material deform = 1, fade = true, lighting = smooth, roughness = 0.3, metalness = 0.6
  colors = A:#000 B:#FFFEFE C:#040009 D:#130200 E:#0B0000 F:#FFFDF3 G:#1A0905 H:#44383C I:#100511 J:#0A010B K:#837375 L:#816254 M:#65493E N:#6B5C62 O:#FDE5D9 P:#928289 Q:#FFF3E4 R:#54494D S:#180E19 T:#FFF4EB U:#76686C V:#7B5D52 W:#FBDBCB X:#6C5145 Y:#1E131B Z:#6A4D41 Aa:#FEE2D3 Ab:#342A33 Ac:#9A8482 Ad:#130A14 Ae:#1B121C Af:#74594C Ag:#D9BCB2 Ah:#FEF9ED Ai:#C8A998 Aj:#FEEADA Ak:#816559 Al:#927364 Am:#8C7165 An:#74605D Ao:#0B0511 Ap:#443A43 Aq:#2C222B Ar:#CDB0A5 As:#725549 At:#C4A6A1 Au:#594D55 Av:#4C434B Aw:#746363 Ax:#96796A Ay:#C3ABA5 Az:#190300 Ba:#533B32 Bb:#E3C3B2 Bc:#ECCFBF Bd:#645353 Be:#7B625A Bf:#C4A290 Bg:#7C6054 Bh:#3C323A Bi:#D4BBB2 Bj:#E3C4BB Bk:#FEEBE2 Bl:#171018 Bm:#E3CBC4 Bn:#92766B Bo:#AB928A Bp:#DBC2BB Bq:#EACDC2 Br:#393036 Bs:#211621 Bt:#F5E1DB Bu:#4A3D42 Bv:#655A63 Bw:#7D6965 Bx:#8C7B82 By:#312630 Bz:#32201E Ca:#B39A94 Cb:#291E25 Cc:#241B24 Cd:#948183 Ce:#84716E Cf:#745B53 Cg:#A4867A Ch:#F2D3C4 Ci:#42291F Cj:#4B2B1A Ck:#F7DED4 Cl:#BA9A8B Cm:#53454B Cn:#EBCBBB Co:#ECDAD9 Cp:#796C73 Cq:#4D3934 Cr:#2B1C1B Cs:#6D5854 Ct:#B29283 Cu:#89767A Cv:#7A5B4C Cw:#1C1113 Cx:#9B8074 Cy:#725344 Cz:#140A0A Da:#9E8278 Db:#6B5A5B Dc:#73656A Dd:#D2B4AB De:#5C525A Df:#CAABA3 Dg:#CBAB9C Dh:#53413D Di:#A18375 Dj:#351E16 Dk:#BA9E99 Dl:#E7C8B8 Dm:#0D0915 Dn:#8A6B5C Do:#050311 Dp:#A18680 Dq:#8A736B Dr:#A99493 Ds:#83685C Dt:#4B3A3A Du:#997B6C Dv:#896D61 Dw:#7B6B6B Dx:#382C34 Dy:#EBD3CB Dz:#A88D8C Ea:#9F8C8F Eb:#8B7B7B Ec:#43312B Ed:#5B433B Ee:#BCA39B Ef:#F6E4E3 Eg:#AA9BA2 Eh:#AA8C82 Ei:#31252B Ej:#C2A59B Ek:#DCC1B4 El:#5B4B4B Em:#4E4144 En:#11050B Eo:#433332 Ep:#DFBDAD Eq:#5B4135 Er:#583D31 Es:#4C332B Et:#CCB4B0 Eu:#24110C Ev:#665759 Ew:#64422F Ex:#9B8885 Ey:#8C7974 Ez:#F3DCD3 Fa:#93807D Fb:#E4D3D1 Fc:#1A1421 Fd:#F2D5C9 Fe:#FCECEB Ff:#B7A09C Fg:#514445 Fh:#D3B3A4 Fi:#F6D9CA Fj:#BBAAAB Fk:#BA9D93 Fl:#B3A3A5 Fm:#AA9798 Fn:#997C73 Fo:#CCB2AB Fp:#A38C8A Fq:#D3B5B1 Fr:#BBA5A3 Fs:#836D6A Ft:#62545A Fu:#321C14 Fv:#624539 Fw:#B2958A Fx:#DABAAB Fy:#3C3032 Fz:#AD8C7B Ga:#4D3126 Gb:#442C24 Gc:#3B231B Gd:#230A01 Ge:#25191B Gf:#271714 Gg:#220E09 Gh:#533426 Gi:#331506 Gj:#381908 Gk:#130D19 Gl:#5B3B29 Gm:#A6918B Gn:#CCBBBA Go:#CAB8B6 Gp:#7B6563 Gq:#5C4944 Gr:#523D3A Gs:#927A74 Gt:#F5EAE3 Gu:#A39393 Gv:#E9D6D5 Gw:#9C8A8A Gx:#322423 Gy:#D3C3C5 Gz:#A48983 Ha:#826A63 Hb:#190D12 Hc:#231412 Hd:#B39D9A He:#DDC9C8 Hf:#C7AEAA Hg:#856E6E Hh:#D5B8AA Hi:#644B42 Hj:#8A7573 Hk:#624E4B Hl:#22161C Hm:#6B626B Hn:#745D59 Ho:#452D26 Hp:#6C544C Hq:#52382C Hr:#2B1207 Hs:#D5AF99 Ht:#382625 Hu:#EAD1C8 Hv:#E4C2AE Hw:#D8B5A6 Hx:#2C1913
voxels
42-AjBbClAiDlF7-2B3AhF7-2B3FCk9-KEx74-DkBoGmEy8-BpBqCkOEzO7-AjBoBb2BcAa7-FaBoCmHBdCn8-DmAb2N9-BrAbBsC9-2Fc2C9-RDmC10-RSDo47-F2DpGpAnEy2Be5-Fd6-Cl5-Aj6-T5-Ac2-DqDr2-Ff5-DoBuRDtDrBvRAo5-DoBuBrDtAc-Ap7-HFgBwAn-C7-HRBw-Bs8-CpDwU-C10-DxAq34-ArGqGrCqCrDt2CsCt4-Bp7-Dk4-Aj2-BwGs3-Dy4-H-Dk2-Dz-K5-BhCu4-EaBr5-DxEb3-Bx-Ap5-2Ap3-K-C5-AoAn2-Gv-By7-Gw2-CoPAd45-Bo2EcCwECwGxEdCx4-Bi7-At4-Bq-BwBdAnDz2-Fi4-AuEe4-Bi-K4-H6-AvA4-H5-KBr5-2Aw4-NAe5-AvBp3-PAu11-PAv45-AyBzCw3ACzBzCx4-Ay7-Ca3-F-AtGzHaDaFkBj-O3-ADb6-2Ac3-2Cb6-KC3-CbDb6-KA4-Dc5-FmAp5-U5-PAw57-EhCrE3AEHcFn4-Bi7-Ay3-F-Fo2CaDpAtBj-Ck3-ABd6-BjAc3-AFp6-BxDx3-AFp6-HdEi3-IDw6-AwA4-U5-HeK57-ArCrE3A2GFn4-Ar7-Ay4-AtEjFqFrDzAtEkAgDy3-AFs7-Eb3-ADd7-El3-ABq6-BiCe3-BlBm6-AcH11-P57-BqEcDE2DEGCf4-Ag7-Ay4-AgBfAgHfAyFoAgBj-Bk2-AHg7-ExH2-BsDy7-AwA2-ACk7-El3-DcF6-EbEm11-Ft57-BjEe4D2EX4-Ag8-Bi3-Ch-BjFqAtDf2Dd-O2-A-Ek6-BiH2-EmO7-BnA2-BuBc7-DbC2-FaT6-FmBh3-K7-U58-Ee4E2AAfW3-Bp8-Ay3-Bt-AaDlAr2DfEj-Q2-A-Cn6-AtBd2-2Ac7-BnEo2-CdDl7-BnA2-Dw7-KEl3-Bx7-K58-2Bz3E2AFuAg3-Bp8-Ag3-Bq-AjAaEpDgFkEh-Fd2-A-Ch6-DfAn2-HjAh7-DnEo2-U8-HkA2-An7-AwFg3-U7-N4-Cu6-FHm45-Ff3E2D2EDg4-Bm7-Dd3-W-WFiBbFw2Da-Ar2-A-Ch6-LDh2-CeAa7-MDh2-Aw8-CqA2-Fs7-AnFy3-U7-Au4-Dc5-AeBtBv4-NO4-IFlAe32-Et5D2EDi4-Bm8-O2-B-FhCnFxCtBnDv2-Q-A-Bb6-M-Cc-CsCv7-Ga-A-2Dh5-EuA-A2-HnDa4-2A-Cw3-Ce4-3A-A3-EvBkCz2-A2-Au4-A-YEv-A2-C5-CuAH-HBsDe6-Fj-CmCpEmA8-Et3D2G2DDn4-Bm8-Ca2-B-ClEpAiAlBgM2-Bk-Cr-Dg6-Gc-Fy-BzCv6-DjGd-A-GeGa5-Eu2-A2-EiAk5-Dj-A3-YBw5-Cj-C3-Y-A3-Di-H4-Fr2-Bn-Et2-P5-N2-Cd-EvAv6-PFeAqBhBy9-ArG2D4GLAi3-Fb8-Dg2-Co-LFzDuAlErGcFu-Ar-En-Di7-BeEo-GAz6-Hr-2A-EnGi6-Gj2A2-CZ5-Ew-Cc3-A-A3-Du2-Ab3-A2-Di-Ba2-Ab5-K2-Db3-Aq5-YEa2-BlBxBu8-IAe10-Ca3D4GBaHs2-Ef6-AzD-Fw2-Bt-CjLCyEwEr2-HtBn-Cz-Gl8-By-GGi8-2A-AAz6-Dj2A2-G-A3-ACj-Cc3-C2-3A3-Bh4-Ce2-A3-De5-Ce4-I-J5-CCdJAoC-H20-CqG2D2GEuHxBaHw2-Ef4-CiD2A2-Hv-Hu-CjGlEw4-Cf-ChCz-Gj8-AAuAGh8-2A-ACs5-4A2-I-2(A3-)A2-A-2A2-A2-Ap4-Bd-J-I3-I4-Au-DmGkIJBvGk6-U25-DrCq2D2GGfCiEsBf2-Bm3-GdE3A2-Cg-CxDCjGh5-Cf-ChEAz9-2CA9-2A-A7-3A2-3A4-A-Ap4-By4-A2-Cp4-BsGeAoS2C2R5-CBdAeSI-DcBh31-AaEd2Gg2AzGfCiGbHqEjAi-Bm-3AE3A2-CgB-A7-Hp-Bb3A8-2CA9-2A-3A5-3A2-A-A4-A-By4-CbCABlSCA-J4-Cb-CBlSI-Av6-Bh37-CxHoBaCiDjEsGbCiEqBa2AiBf2-7A2-AiBc-A7-A-Bb2A9-2CA9-CA-3A4-4A3-DeP3-JA-Bv4-Ei-AdAeBlJ-FtJ5-AqN4-Bu44-Fz2BaEdMEsFvEr2EqCgFxBf2-7A2-EkBc-Az7-A-Ez2A9-AAq2C8-C2(A-)N5-AAvC3-Y-CA3C-Au5-AeHlAoCJ-Cm56-EpCtXZHiM2ZFv2MAlAaHh2-3A-2A2-A2Q-E3-A2-3AQAdA9-AR2Ao7-3A2-2N4-SIBrC4-NAe3CBlJ7-Cc61-F2Dq2CfVAfX3MCgWB-2A3-A2-A-WBA2-7A-TH10-EnUJAb7-AvCA2-2AbS2-AJIDe5-YAd2CACA69-BEhLBg2BeAfX2MZCgWB-5A-2A-2WBA10-QHA9-HTAAd7-AdCA2-AbBvIC3AJAq6-IJ2A71-BkClDsVBeAkVXZ2AsAx-B2-3A5-2AaB-A8-2BkEaAq9-2Cd-AdC6-2CA2-CcS5CSC6-Y75-CtL2AfBgAf3Z2Ax-B-A6-X2Ax-B-A8-Q-BCu8-RFl2-IYK4-HbBxAdA3-YH2PEgFjEgCm82-AkAfAsAfBgAs3X4-WVCv3-As2Cy2Ax-BO9-Ah-BGy8-EgB2-CpB6-BEf4-8B84-3VAsCy6-ODs2AkVCvAsLVFhAj2-B8-2F2-TGu7-2B2-Bt2B5-BGt5-7B95-QBf2AmL2Bg2LCn3-BT6-AjF3-BT6-2F4-2B4-B-Ah5-7B96-Bf3Am2DvAkDu5-T4-DsL-F3-2B6-2F4-BtT4-FeF6-6B97-BAlAm2AlAm7-AhBcDnAlAkLBoF5-BF4-2F5-BOCoGoGnFb-Q7-Co4B82-
