model
size = 20 32 16, scale = 0.05, origin = -y
material deform = 1, fade = true, lighting = smooth, roughness = 0.3, metalness = 0.6
  colors = A:#FEB02C B:#FE6C4A C:#F7F64D D:#FE8E32 E:#FCEA37 F:#FDCF2D G:#F2F66F H:#FE4F4D I:#D1EC4F J:#F7D04A K:#B2D350 L:#108DEF M:#CFF46F N:#29AFF8 O:#FE7332 P:#AEF48B Q:#FE8A4B R:#4AD2ED S:#AED76B T:#FAAD4B U:#2E4BA9 V:#CBD44A W:#F95069 X:#2BD1F5 Y:#076E8E Z:#4CD2CD Aa:#334D00 Ab:#FACC15 Ac:#8EF4AE Ad:#6DD6A9 Ae:#99E873 Af:#2892F1 Ag:#000632 Ah:#00114D Ai:#B2D032 Aj:#11AEF2 Ak:#ADD18C Al:#70EEB0 Am:#FC3450 An:#F5F98B Ao:#75E892 Ap:#91EC8F Aq:#015171 Ar:#FC2F6C As:#FDAF11 At:#2D91B4 Au:#6EF5CD Av:#AB2B8E Aw:#FD8E11 Ax:#F87213 Ay:#FF9188 Az:#FD8B6E Ba:#FE5234 Bb:#146CAF Bc:#0752D0 Bd:#8BD38A Be:#325BE8 Bf:#2FD3CF Bg:#92B02E Bh:#012A6E Bi:#034E92 Bj:#303293 Bk:#4CF6F1 Bl:#08AD92 Bm:#D6E336 Bn:#296DF0 Bo:#52E7B1 Bp:#CAD569 Bq:#B8E856 Br:#06338E Bs:#F8706B Bt:#D42A57 Bu:#078CCF Bv:#6BF8F1 Bw:#ABF6AE Bx:#B1EC70 By:#ADB331 Bz:#039175 Ca:#2FD5B1 Cb:#D4C911 Cc:#5239C5 Cd:#2E93C9 Ce:#94D370 Cf:#CC296B Cg:#076ED3 Ch:#14CAF1 Ci:#30B0B1 Cj:#08ADD3 Ck:#BE5DC2 Cl:#10C9B3 Cm:#489646 Cn:#2C6DCE Co:#024F52 Cp:#29878C Cq:#8F2D90 Cr:#0D4EAD Cs:#89B5C8 Ct:#0A1767 Cu:#1071E8 Cv:#3636AA Cw:#00304D Cx:#4C1796 Cy:#34ECF3 Cz:#2CC793 Da:#50D491 Db:#D0258E Dc:#9050A3 Dd:#97FBF0 De:#8E950D Df:#AFC415 Dg:#0231AC Dh:#F0D16D Di:#703094 Dj:#972977 Dk:#90D24F Dl:#078A8F Dm:#6ED26F Dn:#51CA73 Do:#329529 Dp:#53890C Dq:#51B290 Dr:#72D391 Ds:#70BA4D Dt:#72A710 Du:#73B872 Dv:#296EB6 Dw:#D0486B Dx:#6F5393 Dy:#000015 Dz:#691671 Ea:#502F96 Eb:#38098A Ec:#89FACE Ed:#4FD3B2 Ee:#34E9D3 Ef:#FBFCCE Eg:#FBFAAF Eh:#AA29A9 Ei:#6C33B2 Ej:#506C00 Ek:#73CB54 El:#D2CAE1 Em:#91C631 En:#718C07 Eo:#AC9013 Ep:#9EA6A5 Eq:#65959B Er:#9332BD Es:#EA2A88 Et:#AC8F93 Eu:#046E73 Ev:#50F2D2 Ew:#4BB2CB Ex:#B3B44C Ey:#4992A3 Ez:#67936F Fa:#F41A4A Fb:#5366D7 Fc:#546BE6 Fd:#14CFCB Fe:#0F8FAC Ff:#90AF4F Fg:#EE1B66 Fh:#8B2BAD Fi:#2DB58B Fj:#689D1A Fk:#F794A8 Fl:#0F655C Fm:#AFD1AA Fn:#4947A8 Fo:#4B5511 Fp:#9B6FA6 Fq:#CCB43A Fr:#FFB3AB Fs:#7170B4 Ft:#61B3D3 Fu:#991268 Fv:#377696 Fw:#524AD4 Fx:#F8B065 Fy:#18E8EB Fz:#874BC8 Ga:#3050D3 Gb:#674BCE Gc:#199D66 Gd:#36AA51 Ge:#139150 Gf:#CCD434 Gg:#FC3234 Gh:#6C37C2 Gi:#05B3B0 Gj:#B0B40C Gk:#EF5C87 Gl:#4AB6F3 Gm:#948C29 Gn:#4BB357 Go:#6DB033 Gp:#5273AA Gq:#ADA2C5 Gr:#D2B207 Gs:#C5992E Gt:#4BB1B3 Gu:#30AECD Gv:#15158A Gw:#0A2D30 Gx:#FFA896 Gy:#17E6D2 Gz:#CEF48C Ha:#8E8CA1 Hb:#CA906A Hc:#638EF3 Hd:#1358E9 He:#CBF9A9
voxels
26-Cj3X4-CiEd10-CyBkX5-2Ao10-AuAcAu5-Ap11-ApAcBw17-2M18-I338-KBo4-ZAdBd10-KAePAe2-2ApAdSBx10-S2P2-BxApBx2M10-3K2-BxAiKM18-By93-DgBc17-Ga2Be18-2N18-2X18-X19-Ec535-2Cx-CvEbCn2NCgBc-Hd8-2Gb-Ga-Af3NCuLAj8-Cu2-2AfL2Cy2N2Aj11-2NFd2Au2RBk12-CyXBk2AuEcEvBk12-Au-Ac2EfHeGBv13-BwP4G13-MGJ2G2C14-4GC15-2C2G452-DcCx2FzEb2BbBu-BcCgDg-Cc2Fc4-FpCcHcFb-L2Bu-2CuBc-BnFc5-Cu3L-L2Ch-N2Aj-2L5-AfChLX-FdBoCz-X2Bv8-Bf2ChX-Fd2Bo-Ev2Bv8-BfAlDdBwEcAcAe-4P9-2Al2BwPAeEk2M2P9-IMAn-JIEm2M2G9-I3An2JCbCM2G10-AnG2CAAb4C10-4C3EC2E11-3C2FJF2E12-3A-A2F389-Di-2Cx-Cr2Cg3-2CvCcCxFs4-Fb5-Ch4-DgBc2-Cn4-Cg5-Ch4-Bu2L-Cn4-Af5-Gy4-BvFyLBkCj4-Bf10-BvFyEpBkCy4-Ca6-Bz3-PApAkEc5-2Bd5-Cm3-PApPGz5-2K5-Dt3-2GCM6-IAn4-Dt3-2GC7-2I8-3C7-2(2C8-)2E2C-AAbA-HaJE9-E2FHb4ATA11-3ATFxTDTA367-2FwEb9-BjEbCrCvBj3-BnFb10-Dg-Bc-Cn3-BnL13-BuCn3-XN13-2Cj3-XN13-EdZ3-2Ac13-Dr4-2Ac13-Ce5-S13-V5-SDr11-CV5-VCe11-2C5-CE10-2C6-An-E9-2E7-FEF7-2F9-2ATATFxTD3T9-A3D3QD2T12-2D332-2U13-3Bc2-BeAf13-2Bu3-2Af13-Bu-Bf2-2R13-CjCaAd2-BkBv14-Ca2(4-Ac14-Dk)4-2M13-V4-2I13-Bm4-GC13-E5-C12-GE5-2F11-J6-2F10-FA7-2A9-2T7-A-D2-3QDTGxT9-D3Q2B2AzBQT10-2QAz2B2Az2B72-2UFn2UDzU13-5U2DzU12-BiY2At2Y13-3Y2AtYAqY12-2Cw2AqEu2AqCoY11-2(Ah19-)Ah8-Bh10-Ah8-Ah10-Ag8-Ct9-DyAg34-BiGw14-GvBc2-Bn15-2L2-N15-CjBf2-2R15-Ad2-R15-2Ae2-PAc14-2Ae2-2P14-BqI3-M14-2G3-G14-An4-2J13-E4-JDh13-E4-TF12-2Ab5-2A11-A6-2D10-2D7-DDh9-OD7-2Q8-BO9-3BBsAy3BsAy-B9-BsB2W2H2BsWH11-Dw2Bt2HBa2Fa12-Eq2EaAmDwAv2FuDz11-U2EaUCv4Bj10-Fv2U-UCv3BjBrBi9-Fv2Bb-DvBbYBiBrBiBb9-AtBb3-2YAqCwAqCs9-AtCwCo-CwYAqCoCwCoAq9-DyAh8-Ah10-Dy8-3(Ah19-)Ah9-3(2Ag8-)Ag5-Cr16-Cg-GuCu16-AjN-N16-Ee2-R16-Ao2-R16-Bx2-P16-Bq2-BpM15-I2-2V15-G2-JDh14-EgG2-2J14-E4-J14-F4-TA12-DA4-DA12-2D5-2D11-D6-2D11-D7-2O9-OB7-2Ay8-H-B8-FrH7-2H9-AmW6-Fa2Bt9-DjDc7-2Bt9-2Dj7-2Di9-DxU7-BrBb9-Dx9-BbFt7-2At9-2Cs7-CpAt9-CpEu118-DyAg7-BhAg9-Ah5-Y16-CgAfEwAt16-R-PEy16-R2PCe16-DaAeAn2By15-KI-BgFq15-BmC-BgFq15-BmE-GsGr15-J3-Aw14-EA3-D14-FA3-Ba14-AD3-2Ba13-A4-2O13-D5-Ba12-DO5-2Ba11-Q7-Ba11-B7-2Ay9-HB7-DwFr9-H9-Am8-Am2(Bt9-Dj9-)Di9-Dx9-FsDv7-EzDx9-BbFt7-Ez11-Gt7-Cm11-Cp127-BhCt9-Ah5-Bl15-2CiCpBoZ15-Ci2-BwBd16-Dn-BwCe16-Df-MV16-DfI-2V15-DfE2-Dh15-FE2-Dh15-2F2-2(A15-A3-)2Ax13-2D3-2Ax13-2O4-O13-Ba5-O12-2B5-OBa11-W7-Am11-H7-Cf10-HCf7-2Cf9-2Cf8-Di9-Dw9-Gp9-Av9-At9-FpCs8-Dq9-GqEy7-2Dq10-Ey7-Ex11-Eq7-De11-Ez7-Fo11-Aa87-BhAg18-2Bh9-Ct5-BfBz13-CoCi-CpZEvAu14-2Cz-AcBdAl14-GnDn-AcBdZ14-GoFjBqMSAd14-EmDfI-SI14-BmDfI2-An14-EFC2-An14-FAbC2-FA13-DAb3-2A13-DAw3-AD13-D5-OAz11-AyO5-2Az11-BsB5-2B11-2H6-H11-W7-Am11-Ar7-2Cq9-AvCf7-2Cq9-Av9-Fn9-Dv9-Cd9-Dv9-Ew9-2Cs8-Ew9-2Ad7-2Du9-2Ad7-Du11-Ak7-Ex11-Ex7-De11-Fo7-Aa59-Dg19-BhAg9-CtBi18-2Ct4-2BfCa6-2Y4-EuCl-2Et-AuAl13-Dr-BdEt-AcAe13-Ae-Bd2-ZAe13-Bq4-ApBq13-I4-2I13-Eg4-GC13-G4-CE13-E4-E-A12-A5-FA11-2A5-2D11-2D5-Q-B10-AzO6-AzH9-2B7-2H9-2H7-HAm9-HAm7-AmAr9-2Ar7-FgEs9-Av9-Cq9-Av9-Cc4(9-Cd)9-Gl2(9-Z)8-DuCe9-AdBd7-2Ce9-2Ak7-S11-Bp7-K11-Bg7-Gm11-Aa7-Bi19-Br11-Cr7-Br10-BrCr18-2Bi26-ClFl2BlCpEq-DlFe2Cl-CoDqEd5-Al-DnCz2Bz2-BlGiCl2-DmDr5-Bx-2Ds2Do2-CmFm3-DkAe5-BqI2DsDp3-CmFm3-2Bq5-IV2ByDp3-DtBg3-VI5-CJ2ByEn3-DtK3-CAn5-2C2CbDe3-CbGj3-EG5-2E2AbEo3-CbAb3-FE5-EA2AsAw3-Ab-As-A2F6-ADAwAx5-As-AwA7-2D2Ax5-Aw-OD7-QBAx6-O-BO8-H2B5-BQ2B8-HAyB5-2BH9-2AyH5-Am2H9-2ArW5-Gk2Ar9-EsArW6-EsEr9-CqCc7-2Er9-2Cc7-2Af9-2Cd7-2Af9-2R7-2X9-2R7-2R9-AdBo8-Al2(8-2Z9-Ak)Bp7-S11-Bp7-FfEn10-Ep7-FlAa9-AaBh18-BrCr18-Br47-CaFiGc-DlBz-2Dl-ClBlFiDa6-AlAoGd-2Bz-CiBl-2CaDnDm6-2SFj-GeDo2-Cm2ElDm2Ek7-VDe-DpDo2-CmElDm2AiEm7-VDe-Dp3-Bg4AiV7-2D-En3-BgAiGf2BmE7-EJ-Eo3-Cb2AbBm2E8-J-Eo3-Cb2Ab3F10-As-JF-2AsAwDA10-As2AAb3AsAwD10-Ax-AJ2A2AwAxGg10-BQ3D2BO2B10-OB2QO4B12-7B13-4HB2WAm12-3WAmW2Fk12-3WEhArW2DbCk11-2AvCk3-2DbGh11-Fh2Ck4-DcBe11-CnBn5-BnN11-RAj5-2N11-RX5-NR10-2Ad7-2Ak9-Z9-Ak8-2Al9-BpI7-ApKBg2Aa2Ej2Aa2-KM8-KBgAa5-2AaKEp18-AaBh90-Y2AqX3-2BlCz10-Fe-BkEe3-Da-Ao10-Da-Au2Ao2-Da-Dk10-Ap-Ap2Ao2-Ff2V10-MEf2IAi2-Ai2V10-IEg2IAi2-BmE11-2CGCS3-E11-C2G2S3-E11-2E3J15-2FJFJ15-FA2-A117-2EhArFg15-CkEiFhAvDb15-Ck2EiAv2Dc13-2Bn5Be13-Aj2LAj3L13-2AjLAj2LN11-AdBfBo2DdZAlZEe2Ak9-2AoBo2DdZAl2-SAk9-BxS2K2SK2-2M9-4K2SKAi-2Bp10-BgAa4-AaEjBpK105-
