model
size = 13 32 11, scale = 0.05, origin = -y
material deform = 1, fade = true, lighting = smooth, roughness = 0.3, metalness = 0.6
  colors = A:#1FAEB3 B:#C9594A C:#0098FE D:#0DA1DB E:#718480 F:#74837E G:#A7685D H:#059CED I:#7C7E79 J:#72837E K:#977168 L:#6C8683 M:#0DA1DD N:#678984 O:#449A9C P:#628B88 Q:#58C9CC R:#3D9D9F S:#38A1A2 T:#688884 U:#7E7E77 V:#847B72 W:#3B9FA1 X:#B56254 Y:#59908D Z:#59908E Aa:#539392 Ab:#5E8D8B Ac:#59C9CC Ad:#5DCACE Ae:#10A4D4 Af:#069CEC Ag:#0BA1DE Ah:#1FACB1 Ai:#A16C62 Aj:#3A9FA1 Ak:#5B8E8D Al:#8B776F Am:#8D766F An:#817C76 Ao:#658986 Ap:#92746A Aq:#58908E Ar:#4C9795 As:#B86054 At:#77817B Au:#678986 Av:#5E79A7 Aw:#27A9AC Ax:#3F9D9D Ay:#5BC9CC Az:#5BC9CE Ba:#1AABBB Bb:#17A7C4 Bc:#13A6CE Bd:#10A4D3 Be:#17A9C4 Bf:#1AABBD Bg:#2EA6A9 Bh:#409C9D Bi:#459A9A Bj:#628B89 Bk:#5D8E8B Bl:#429C9C Bm:#18A9C0 Bn:#12A6CE Bo:#12A6CF Bp:#17A9C2 Bq:#9C6F65 Br:#638B88 Bs:#10A2D4 Bt:#0A9FE5 Bu:#9D6D63 Bv:#867972 Bw:#77817C Bx:#35A2A4 By:#36A1A4 Bz:#17A7C5 Ca:#3B98AB Cb:#76817C Cc:#897771 Cd:#987167 Ce:#519393 Cf:#6A769D Cg:#569290 Ch:#4F9595 Ci:#4E9595 Cj:#549290 Ck:#608D89 Cl:#62C9CC Cm:#5EC9CC Cn:#90746C Co:#31A4A6 Cp:#40BFC4 Cq:#5BC7CA Cr:#5BCACE Cs:#62CACE Ct:#5DC9CC Cu:#0B9FE2
voxels
342-2(5A8-)5A358-2A3-2A5-4(9A4-)9A5-7A19-3(2A3-2A6-)2A3-2A5-8(3A3-3A4-)3A3-2A5-3A3-2A6-2A4-A6-2(2A4-)3(3A3-3A4-)4(4A-4A4-)4A-4A3-2(11A2-)3(2A7-2A2-)A-A2-2A-2A4-BaBbAeMBcBdAeBeBf4-9C2(4-4A-4A)2(3-5A-4A)3-AAh3A-4A3-AiBg2(-2A)-NBh2-IA2(-2A)-ABi2-JA2(-2A)-AO2-NA2(-2A)-AS2-BjA2(-2A)-AAj2-AkA2(-2A)-AS2-Bk4A-4AJ2-Bl4A-4AP2-K-3A-4AP2-5A-5A2-5A-3A-A2-A-3A-4A3-5A-5A2(2-3(2A-)2A)2-2A2-A-A3(2(2-2A)2-3A)2-2A2-A3-3A2-2A3(2-A9-A)2-A8-2A2-2A7-2A2-BmBn7-BoBp2-3C5-3C2-2A2-3(A-)2(A2-2A2-A-A3-)A2-BBq2-A-A2-BrB2-BAl2-A-A2-2K2-2B2-A-A2-AN5(2-B3-A-A3-B)2-B3-A-A3-J2-B3-A-A3-P2-KA2-A-A2-2L2-AiA2-A-A2-2T2-BuA2-A-A2-AU2-2V2-A-A2-AAm2-Bv3-A-A2-AI2-An3-A-A2-ABw-AU3-A-A3-I-AJ3-A5-J-BAo3-2A4-E-ApBx3-2A4-AqB2Ar9-RBUA9-WXNA9-YB2O9-FBGW9-E2-By9-L2-E9-Z2-Bz9-Ca2-2C7-2C2-2A2(4-A2(2-2A))4-A2-2A2-AlA4-A2-2As2-CbA4-A2-RB2-EA2-A-A2-IB2-AaA2-A-A2-WX2-AaA2-A-A2-2At2-Ab3-A5-Cc2-P3-A5-V2-Au3-A4-ACd2-I3-A5-F2-Ap3-A4-CeX2-Y3-A4-2G2-Ab3-A5-B2-G2(3-A-A3-B-AB)5-A3-2(B-AB9-)B-2B9-4B9-3B4(11-2B)10-4B2(9-3BE)9-2B-Av9-Cf2-C9-C3(2-2(2A-)2(A-)A)2-2(2A-)2(A-)Cg2-2A2-2(A-)AR4-2A2(-A)-2A4-3A3-A-A3-4A2-A2-2A2(2-4A2-A-3A)2-4A2-2(A-)A2-4A4-2AF2-2A-A5-2A2-YA-2(A2-)2Aw2-AbA-2(A2-)AR2-AhA2-A-A2-AAx2-AjA2-A-A2-ACh-AO3-A-A2-ACi-AAa3-A-A3-Z-ACj3-A-A3-Ao-LAx3-A-A3-TFE4-3A3-A2F11-LAu11-CkCl11-CmAn11-ZK11-AkCnA9-AAqGS9-CoAmBG9-QB-Av9-Ac2-C9-C3-4(2A-A-4A4-)4A-4A4-A-2A-4A4-2A-A8(-4A4-4A)-4A3-5A-5A2-5A-3A-A2-5A2(-2A)2(2-3(2A-)2A)2-A2-2A2(-2A2-A)-2A2(3-4A3-3A)3-2AAyA4-2A3-ACpAdCq9-2AdAQ9-Cr2ACs9-AcA-Az9-AcA-Ct8-AAy2-AzH7-HCu2-2C7-2C4-7(3A-3A6-)3A-3A31-2(3A3-3A4-)3A3-3A5-3(2A3-2A6-)2A2(3-3A4-3A)3-3A2(3-4A)2-4A2(2-5A)-5A2-5A-5A3(2-11A)2-Q6A-3A2-Q3A4-3A2-2A5-4A2-3A4-M3A2-AMAgH3-M2Af4-3C3-3C290-3(2A5-2A4-)2A3-4A4-9A4-2(8A5-)8A6-AgBtDBs2HC6-7C385-3D10-3D18-
