model
size = 20 32 16, scale = 0.05, origin = -y
material deform = 1, fade = true, lighting = smooth, roughness = 0.3, metalness = 0.6
  colors = A:#FFF
voxels
26-4A4-2(2A10-3A5-)A11-3A17-2A18-A338-A5-3A10-2(4A2-5A9-)4A2-4A11-A6-A93-2A17-3A2(18-2A)18-A19-A535-2A2(-3A)-A8-2A2(-A)-5A8-A2-3A-5A11-2(3A-4A12-)2(A-)2A-A13-2A17-3A2(18-2A)454-8A2(-3A)4-2(4A2(-3A)-2A5-)2(4A2(-3A)8-)7A-4A9-11A9-3A-7A9-11A2(10-10A)11-9A13-A2-3A389-A-2A-3A3-5A4-A5-A4-2A2-A4-A5-A4-3A-A4-A5-A4-5A4-A10-5A4-A6-2(A3-4A5-2A5-)A3-4A6-2A4-A3-2(3A7-2A8-)2A8-4A2(-3A)9-10A11-9A367-3A9-5A3-2A10-2(A-)A3(3-2A13-2A)3-2A13-A4-2A13-A5-A13-A2(5-2A11-2A)5-2A10-2A6-A-A9-2A7-3A7-2A9-11A9-10A12-2A332-2A13-3A2-2A13-2A3-2A13-A-A2-2A13-3A2-2A2(14-A4-A)14-3(A4-2A13-)A5-A12-2A5-2A11-A6-2A10-2A7-2A9-2A7-A-A2-7A9-11A10-9A72-3A2-2A13-3A-4A12-9A2(10-10A)5(10-A8-A)9-2A34-2A14-2(2A2-A15-)2A2-2A15-A2-A15-2(2A2-2A14-)2(2A3-A14-)2(A4-2A13-)A4-2A12-2A5-2A11-A6-2A10-2A7-2A9-2A7-2A8-2A9-9A-A9-10A11-8A12-9A11-9A10-2(3A-7A9-)2A3-6A9-3A-7A9-2A8-A10-A8-3(A19-)A9-3(2A8-)A5-A16-A-2A16-2A-4(A16-A2-)2(2A15-A2-)2A14-2A2-2A14-A4-A14-A2(4-2A12-2A)5-2A11-A6-2A11-A7-2A9-2A7-2A8-A-A8-2A7-2A9-2A6-3A3(9-2A7-2A)9-A2(9-2A7-2A)9-2A118-2A8-A9-A5-A16-4A16-A-2A16-4A16-5A3(15-2A-2A)15-A3(3-A14-2A)3-2A13-A4-2A13-A5-A12-2A5-2A11-A7-A11-A7-2A9-2A7-2A2(9-A)8-2A5(9-A)9-2A7-2A9-2A2(7-A11-A)128-A9-A5-A15-5A15-A2-2(2A16-A-)2A16-2A-2A3(15-2A2-A)15-A3-A15-A2(3-2A13-2A)4-A13-A5-A12-2A5-2A2(11-A7-A)10-2A7-2A9-2A8-5(A9-)2A8-A9-2A7-2A10-3(A7-A11-)A87-2A18-2A9-A5-2A13-2A-4A2(14-2A-3A)14-6A14-3A-2A2(14-3A2-A)14-3A2-2(2A13-2A3-)2A13-A3(5-2A11-2A)6-2(A11-A7-)2A9-2A7-2A6(9-A)9-2A8-A9-2A7-2A9-2A3(7-A11-A)7-A59-A19-2A9-2A18-2A4-3A6-2A4-2(2A-)2A13-A2(-2A)13-A-A2-5(2A13-A4-)A-A12-A2(5-2A11-2A)5-A-A10-2A6-4(2A9-2A7-)2A11(9-A)8-2(2A9-2A7-)3(A11-A7-)A19-A11-A7-A10-2A18-2A26-6A-4A-3A5-A-4A2-3A2-2A5-A-4A2-2A3-2A5(5-5A2(3-2A))5-5A3-2(A-)3A6-2(4A5-A-2A7-)3A6-A-2A8-3A5-4A8-3(3A5-3A9-)3A6-5(2A9-2A7-)2A9-2A8-2(A8-2A9-)2A7-A11-A7-2A10-A7-2A9-2(2A18-)A47-2(3A2(-2A)-4A6-)3A2(-2A2-6A7-2A)2(-A3-6A7-2A)-A3-6A8-A-A3-6A10-A-2A-5A10-9A10-A-8A10-10A10-9A12-7A13-8A12-7A12-9A11-3A3-3A11-3A4-3(2A11-2A5-)2A10-2A7-2A2(9-A)8-2A9-2A7-9A2-2A8-3A5-4A18-2A90-4A3-3A10-A-2A3-2(A-A10-A-3A2-)2(3A10-5A2-)2A2(11-5A3-A)11-2(5A15-)2A2-A117-4A15-5A15-6A3(13-7A)11-11A2(9-7A2-2A)9-8A-2A10-2A4-4A105-
