model
size = 26 32 14, scale = 0.05, origin = -y
material deform = 1, fade = true, lighting = smooth, roughness = 0.3, metalness = 0.6
  colors = A:#EEE B:#DDD C:#AAA D:#009 E:#00C
voxels
62-2A2C2A20-2A2CBA20-2A2C2A20-AB2C2A21-A2CA22-A2CA21-3(2A2C2A20-)BA2C2A20-AB2C3B19-2A2C2A20-BA2CA21-2A2CA22-A2CA-A19-2A2C2A19-3A2C3A17-4A2CAB2A16-3AB2C2(AB)16-3AB2C4A16-3A-2C-B2A15-4AC2DCB2AB15-2ABC2DC3A16-3AC2DE3A17-AC4-2B19-C4-B122-4AB5A-C14-11AC13-13A12-B12AB13-13A14-4AB6AB13-12A15-11A15-9ABA15-2A2B5ABA15-4ABAB4A15-6AB2ABA14-B5ABA2B2A16-3A2B4A16-10A16-B3AB5A16-3A2B5A16-5A2B3A17-B7A18-3AB3A19-2A2BABA20-A2B2A22-B3A253-4AB7AC13-12AC12-14A12-12ABA12-4A2B8A12-5AB7A13-3AB9A12-5AB7AB12-6AB7A13-AB11A12-6A4B4A12-6A2BAB4A14-4A3BAB2A14-AB3A4B2A16-B9A16-7AB2A16-5A3B2A16-3ABA2B3A17-10A14-A-11A13-3A2B2A2BABA15-2A2B2(2AB)A15-5A4B2A15-7A3B18-2(2AB)A199-11A-A12-14A11-7A2B6A12-4A2B8A11-5AB9A11-5A2B5AB2A11-B2(3A3B)2A10-5A3B3A2B3A10-4A2BAB8A11-2A5B7A12-2ABAB2AB5AB12-BA2B3A2(BA)2BA12-2BA2B4AB4A12-B3AB7ABA14-11A14-7AB4A13-5AB2AB5A13-7A3B3A12-4AB9A12-4AB10A10-16A10-8AB3A2B2A10-10A4B2A10-3AB11AB10-5AB4AB5A10-10AB5A11-6A3B5A143-4A3B6A13-4A2B7A12-5A5B4A12-3A2BA3B4ABA11-3ABA2BAB4ABA10-5ABAB8A10-A3BA2BA2(B3A)10-4A3B2(2AB)3A10-4A3B9A10-3A8B5A10-2A4B3AB6A11-5B2(3AB)A12-5B4AB4A12-3A4B7A12-B2A5B6A12-B5AB4AB2A12-BA5B2AB4A11-3AB2AB3A2B4A10-4A2BAB8A10-A3BAB10A10-ABA2B11A10-4AB11A10-2(5AB)4A10-AB4AB8AB10-16A10-8AB7A10-8A2B6A13-10A118-5A3B2AB3A12-5A3B6A12-B4A4B3ABA8-A3-2A2(BA)2B5AB8-A3-6A3B4AB2(12-6A3B5A)11-3A2(B2A)B6A10-3AB4A2B5AB10-3AB2A3B7A10-B2A2B2ABAB6A10-2(3AB)AB4A2B11-9AB4A12-3A4B7A12-2A6B6A12-5A3B2A2(BA)12-4A4B4ABA11-4A5BAB5A10-4AB2AB8A6-2A2-4A4B6ABA-3A2-2A2-3A3B6A2B2A-3A2-AB2-3A3BA3B6A-3A3-8AB12AB4-A-5A2B13A4-A2-9AB9A6-6AB11A8-7AB10A10-14A14-12A89-B4A6-B4A10-B5A2B8A5-3C2-7AB2A2B2(AB)2-3C4A-7A2BA2B2ABA-A2B5A-7A2B2AB2A2B-A2BA-3A-7ABAB6A-3B2-3A-10A2B4A-3B2-ABA-3AB2A2(B4A)-2AB2-3A-3AB3A3B6A-A2B2-3A-6A2B8A-3A-4A-2ABAB2A4B5A-2B6A-2AB4A3B2(2AB)-AB4ABA-8A3BA2BAB-4A-3A-3BA2B2(AB)6A-B2A2-3A-2B2A2BA3B6A-ABA2-3A-AB3AB2A4BA2BA-ABA2-9A5B3AB6A2-AB3A3B2(A2B)10A-2AB18A-12AB2A2B8A-12AB9AB24AB21ABAB19A2B15A-24A3-22A4-9A3B10A5-20A7-9AB8A9-16A15-B6A19-6A41-B6ABA5B2A5-C-AC-7ABA3B4A-CB-CA2-A-7A2BAB3A2B-B2-BA2-A-7A2BA2B2ABA-B2-BA2-A-9A4B3A-2(B2-A)-9A3B4A-A2-2A2-A-11AB4A-A2-2A2-A-8A4B4A-A2-3A-A-5AB10A-B-4A3-2AB6A5BAB3-4A3-2AB5A2BA5B3-11AB3ABA3B3A3B11A2BA5BAB2A3B3A-3AB3A2BA7B4AB-2A-3AB5A5B2AB3A2B-2A-9AB2AB3AB5A-5AB3AB4A2B6A2BAB5AB6AB18A2B5A2B8A-8AB4A3B9A2B3AB3A3B2A2B15AB3A3B2A2B4AB6AB12A2B15A-12AB11A2-24A3-11AB10A4-21AB4-22A6-18A9-16A14-A6-A40-9AB2AB3A5-CAC2-9A2B5A2-2BC3A2-7A2B6AB2-2B4A2-7A3B6A2-2B4A2-9AB6A2-4A2BA-6AB9A-4AB3A-2AB11ABA-4A2(BA)-2AB5A4B4A-A2(2BA-)2(2ABAB)6A-A2B-4A-2AB4A4B2A2BA-7AB-2A4BA2B2(2AB)A-A2B4AB-2A3B2AB4AB2A2-8A2-2AB3A2BA3B2A2-9A-2AB3ABA2BAB2A-10A-7A4BA2B-4BA-3AB3A4BAB4ABA4BA-10ABA6B2A3B14AB3AB6A2B13A2B10A2B12AB3A2(BA)2B8AB22A-21A2BA2-5AB2A2B14A2-5AB6A2BAB8A3-4AB6AB10A4-9A2B11A4-2(BA)3B2AB12A4-2AB7A-11A7-6A4-6A11-3ABA5-4A15-A6-A40-16A6-2C2-7ABAB6A2-2C2-2A2-7AB8A2-2C2-2A2-16A2-2B2-AB2-7AB6ABA2(2-2A)2-B5AB9A2(2-2A)2-6AB9A2(2-2A)2-5AB3A3B4A2-2B2-ABA-4AB2ABAB6A-3A2-3A-2ABAB4A2B2ABA2(2-3A)2-6A2(B2A)2B2-3A2-2AB2-4A3BAB3ABA2(2-3A)2-2AB6AB2ABA2(2-3A)2-2(4AB)2ABA2-3B2-4A-4ABAB6AB-A3B2-2(BA)-4A2(B3A)2B-A2BA-13A3B6A3B4AB9AB7A4B14A2B3AB4A2B14AB3AB2ABA3BA-14AB9A2-12A3B9A2-12AB4AB6A2-12AB11A3-11AB10A4-15AB6A4-20A2B5-9A-10A8-6A4-6A12-2C2A5-ACA16-A6-A40-16A10-6AB9A10-5AB2AB7A10-5A2BAB7A10-5ABA2B7A10-8AB4AB2A11-7AB4ABA12-8A3BAB9-A3-A-10A5-B4-A4-7A2(BA)2B3-B4-2A3-8AB3A3-AB4-2A3-3AB2A3BA2B3-AB2(4-AB2-4AB5A2B2A2-2A)4-2A2-5AB3A2B3A2-2B4-BA2-B3A3B2AB4A2-2A3-3A2-4AB2(2A2B)2A-3A2-AB22A2-2B9A2B3AB7A2-B6AB8AB4ABAB3-6AB8AB6A4-2(6AB)6A2B4-6ABAB2AB3A3B2ABA4-11A2B9A5-AB3A3B2AB9A6-20A6-19AB8-16A11-14A14-C2A3-3AC18-A4-A42-6A2B6A12-14A2(12-4AB2AB6A)12-5ABA2B5A12-3ABA2B7A12-6ABAB5A12-6A3B5A13-B2AB8A14-4AB7A14-A-2AB5A-A14-4A2B4A-A13-11ABA13-9AB4A13-2(2AB)6A14-2A2B8A13-4AB9A11-14A2B10-7AB9A9-17A9-14AB2A8-11AB6A7-7AB4AB7A6-4AB5AB9A7-18A8-6AB11A9-14ABA11-8AB5A14-2C6A2C16-9AC18-6A43-4A4-4A14-4A4-4A15-A2(BA-)3A16-4A3B3A16-10A16-8ABA16-10A16-6A2(BA)16-10A16-11A16-4AB3A18-ABA2B5A17-2B2A2B-A16-3ABA2B3A16-ABA3BAB3A15-AB8A15-7AB4A13-13AB12-8AB6A11-11A2B3A10-AB13A11-16A10-15A11-11A2B2A12-7AB2AB3A14-8A18-C6AC18-C2A2E2AC19-6A20-5A22-4A44-B3ABAC4AB15-AB-2ACB-2A16-2AB2AC4A16-5ACB3A16-3ABA2(C4A16-5A)C4A17-2ABAC2AB18-4ACABA18-4AC3A18-4ACABA19-A2BCB2A19-3AC2B2A18-2B4A18-A2B2A2B3A16-5AC4A15-4A4B4A14-4A2(B3A)14-8A2(BA)14-10A2B14-12A14-2(3AB)4A14-12A14-4ACBACB3A15-2AC4DC2A18-C4DC21-4D49-2(2D24-)2D12-
