model
size = 28 32 28, scale = 0.05, origin = -y
material deform = 1, fade = true, lighting = smooth, roughness = 0.3, metalness = 0.6
  colors = A:#B3004D B:#EEE
voxels
37-10B18-10B830-10B18-10B855-16B12-16B851-4B13-B10-18B849-4B15-B8-5B10-5B13-2(6(10A18-)6(10B18-))5(10A18-)10A12-5B16-B6-5B12-5B11-2(6(A10-A16-)6(B10-B16-))5(A10-A16-)12A10-5B17-2B4-5B14-5B9-2(6(A12-A14-)6(B12-B14-))5(A12-A14-)14A8-5B18-3B2-5B16-5B7-2(6(A14-A12-)6(B14-B12-))5(A14-A12-)16A7-4B19-3B2-4B18-4B6-2(6(A16-A10-)6(B16-B10-))5(A16-A10-)18A6-2B21-3B2-3B19-4B5-2(6(A18-A8-)6(B18-B8-))5(A18-A8-)20A4-B24-7B20-4B3-2(6(A20-A6-)6(B20-B6-))5(A20-A6-)22A3-B24-6B6(22-3B3-2(6(A20-A6-)6(B20-B6-))5(A20-A6-)22A3-B26-4B)2(22-3B3-2(6(A20-A6-)6(B20-B6-))5(A20-A6-)22A3-B24-6B)21-4B3-2(6(A20-A6-)6(B20-B6-))5(A20-A6-)22A4-B22-3B2-3B19-4B5-2(6(A18-A8-)6(B18-B8-))5(A18-A8-)20A5-B21-4B2-4B17-5B6-2(6(A16-A10-)6(B16-B10-))5(A16-A10-)18A6-2B19-5B2-5B15-6B7-2(6(A14-A12-)6(B14-B12-))5(A14-A12-)16A8-2B17-5B4-5B13-6B9-2(6(A12-A14-)6(B12-B14-))5(A12-A14-)14A10-2B15-5B6-5B11-6B11-2(6(A10-A16-)6(B10-B16-))5(A10-A16-)12A12-2B13-5B8-5B9-6B13-2(6(10A18-)6(10B18-))5(10A18-)10A14-2B11-5B10-18B851-3B8-5B12-16B846-
