model
size = 32 12 15, scale = 0.05, origin = -y
material deform = 1, fade = true, lighting = smooth, roughness = 0.3, metalness = 0.6
  colors = A:#FF3 B:#F5F11E C:#FF0
voxels
346-A319-CA30-A9-A322-A19-A6-2A4-A274-B31-B11-A20-A5-B18-A5-A25-A209-2A17-2(2C30-A)B9-2A14-A4-2AC4-A18-A7-C31-A169-2BA12-3B13-3A13-5A10-C17-C12-C17-CA3-BA6-C3A15-A10-C2A29-C28-C-CA28-A-A136-2A9-AB16-B14-A-CA-2A7-CB2A16-A10-CBA23-A5-CA29-CA30-A61-A105-BC9-2B20-A9-A17-A19-4A3-AB3A28-A188-A74-A9-A49-B19-A2-C3-2A26-A193-A74-A9-A81-A19-A3-A2-A232-C9-B21-A9-A105-C-C29-A-A201-BA7-AB21-A9-A342-BA5-AB23-A7-A312-B5-B25-A5-A346-5A366-
