model
size = 30 31 9, scale = 0.05, origin = -y
material deform = 1, fade = true, lighting = smooth, roughness = 0.3, metalness = 0.6
  colors = A:#777 B:#004 C:#007 D:#002 E:#005 F:#FF0 G:#FF9B00 H:#888
voxels
431-8A2(22-8H)22-8A830-3A6-3A2(18-3H6-3H)18-3A6-3A827-2A10-2A2(16-2H10-2H)16-2A10-2A412-2A26-6A22-10A18-6A2-6A14-6A6-2(6A10-)6A7-5A14-5A2(6-3A18-3A)5-4A18-4A3(4-3A20-3A)3-4A20-4A3(2-3A3-2D12-2D3-3A)-4A3-2D12-2D3-7A3(24-6A)24-7A22-10A18-14A14-8A2-8A10-2(8A6-)8A10-8A2-8A14-14A18-10A22-6A26-2A26-6A22-10A18-6A2D6A14-6A2D2B2D6A10-6A3D2BEC3D6A7-5A2D2BD2BECD2B2D5A6-3A2D3BEDB2ECD3BE2D3A6-3A2D2B2EDB2ECD2B2E2D3A5-4A2DB3EDB2ECDB3EDB4A4-3A2(DB)3EDB2ECDB3ED3B2(2A4-3A2(DB)3EDB2ECDB3EDBEB)2A3-4A2(DB)3EDB2ECDB3EDBEB2(3A2-3ADBEDB3EDB2ECDB3EDBED)3A2-3ADBE3(DB2EC)DBED3A-4ADBE3(DB2EC)DBED7A3(DBE3(CDB2E)CD2ECD6A)DBE3(CDB2E)CD2ECD7A2D3(CDB2E)CDB2D10A2D2(B2ECD)B2EC2D14A2DECDB2ECDBE2D8A2-8A3DB2EC3D8A6-8A2DEC2D8A10-8A2D8A14-14A18-10A22-6A26-2A26-6A22-10A18-14A14-18A10-22A7-2(24A6-)24A5-3(26A4-)26A3-3(28A2-)28A-240A2-26A6-22A10-18A14-14A18-10A22-6A26-2A26-6A22-10A18-6AED6A14-6A2ECB2D6A10-6A2E3C3B2D6A7-5A2E5C5B2D5A6-3A2E7C7B2D3A6-3AE8C8BD3A5-4AE8C9B4A3(4-3AE9C9BDB2A)3-4AE9C9BDB3(3A2-3AE10C10BD)3A-4AE10C10BD7A3(E11C11BD6A)E11C11BD7A2E9C9B2D10A2E7C7B2D14A2E5C5B2D8A2-8A2E3C3B2D8A6-8A2ECB2D8A10-8AED8A14-14A18-10A22-6A26-2A26-6A22-10A18-6A2-6A14-6A6-2(6A10-)6A7-5A14-5A2(6-3A18-3A)5-4A18-4A4-3A20-2(3A4-2A10FG-8FG)3A3-3A10G2-8G-4A2-3A22-2(3A2-3A3(2FG-)2FG7-)3A-4A3(2FG-)2FG7-7A3(4(-2FG)8-6A)-3(2G2-)2G9-7A22-10A18-14A14-8A2-8A10-2(8A6-)8A10-8A2-8A14-14A18-10A22-6A346-2(10FG-8FG9-)10G2-8G40-6(3(2FG-)2FG15-)3(2G2-)2G282-
