model
size = 30 31 24, scale = 0.05, origin = -y
material deform = 1, fade = true, lighting = smooth, roughness = 0.3, metalness = 0.6
  colors = A:#2A4A5B B:#E57600 C:#FAB700 D:#46647C
voxels
364-2(10BC-9BC8-)10C2-10C38-6(3(2BC-)2BC15-)3(2C2-)2C823-2A24-2A2-2A24-2A603-2A22-2A4(4-DA22-AD)4-2A22-2A63-2A24-2A2(2-DA24-AD)2-2A24-2A543-2A22-2A4-DA22-AD124-DA22-AD4-2A22-2A3-2A24-2A2-DA24-AD62-DA24-AD2-2A24-2A484-3(A22-A5-DA22-AD184-DA22-AD3-DA24-AD122-DA24-AD-3A24-6A24-3A423-)A22-A5-DA22-AD184-DA22-AD3-DA24-AD122-DA24-AD-3A24-6A24-3A393-A22-A6-A22-A5-2A22-2A4-DA22-AD124-DA22-AD4-2A22-2A3-2A24-2A2-DA24-AD62-DA24-AD2-2A24-2A-3A24-6A24-3A393-A22-A6-A22-A5-2(2A22-2A4-)4(DA22-AD4-)2A22-2A4-2A22-2A3-2(2A24-2A2-)2(DA24-AD2-)2A24-2A2-3(2A24-2A-3A24-6A24-3A393-A22-A6-A22-A5-7(2A22-2A4-)2A22-2A3-5(2A24-2A2-))4(2A24-2A-3A24-6A24-3A363-2(A22-A6-)A22-A5-7(2A22-2A4-)2A22-2A3-5(2A24-2A2-))2A24-2A-3A24-6A24-3A306-2A14-2A10-4A14-4A7-5A14-5A6-3A18-3A6-A22-A5-7(2A22-2A4-)2A22-2A3-5(2A24-2A2-)2A24-2A-4A22-8A22-4A2-2A22-2A6-4A14-4A10-2A14-2A194-2A10-2A14-2(4A10-)6A10-6A2(8-4A14-4A)7-3A18-3A5-4A18-4A3(4-3A21-2A)3-3(3A22-3A2-)3A22-3A-4A22-7A3(24-6A)24-7A22-10A18-14A14-8A2-6A14-6A6-2(6A10-)4A10-4A14-2A10-2A110-A4-A22-3A4-3A18-5A4-5A16-4A6-4A3(16-2A10-2A)12-3(4A14-4A8-)B20-C8-B20-C5-4A21-3(3A2-3A22-)3A-4A5(22-8A)22-4A4-2(4A14-4A8-)6A10-6A12-4A6-4A2(16-5A4-5A)18-3A4-3A22-A4-A26-2A26-6A22-10A20-4A2-4A4(20-3A4-3A)18-2(2A10-2A16-)2A10-2A12-2(4B14-3BC8-)A3C14-4C8-4A14-6(4A8-ABCA2B12-)4A8-AC2A2C12-4A8-4A14-4A12-2(2A10-2A16-)2A10-2A18-3A4-3A20-4A2-4A2(20-10A)22-6A26-2A27-6(4A26-)4A23-2(3A4-3A20-)3A4-3A14-2(6B10-5BC8-)6C10-6C12-2A6(10-2A12-2BC-2B)10-2A12-2C2-2C10-2A16-2A10-2A18-2(3A4-3A20-)3A4-3A23-4(4A26-)4A266-2(4A26-)4A17-2(10BCA9BC8-)9C4-9C14-3A4-3A6(14-2BC-2BCAB4-BCA)14-2C2-2C2AC4-C2A20-3A4-3A23-2(4A26-)4A497-2(10BC-9BC8-)10C2A10C17-4A17-6(2(2BC-)2BCA2BC15-)2(2C2-)2C2A2C25-4A253-
