model
size = 14 12 32, scale = 0.05, origin = -y
material deform = 1, fade = true, lighting = smooth, roughness = 0.3, metalness = 0.6
  colors = A:#3DAE6A B:#2C7F4C C:#FFF D:#1F1F1F
voxels
18-2(6A8-)2(CA2CAC8-)6A9-4A79-6A8-6A147-8A6-8A145-10A4-3A4B3A144-10A4-2A6B2A143-12A2-2A8B2A142-12A2-2A8B2A141-4A2B2A2B6A10B2A140-6A2B8A10B2A140-4A2B2A2B6A10B2A140-16A10B2A140-2(4AB)6A10B2A140-4AB2ABAB6A10B2A140-4A6B6A10B2A140-16A10B2A140-4A2BA3B6A10B2A140-6A2BAB6A10B4(4A10-)2A-2A8-2A3-2(9A5-)A13-A25-4A6B6A10B4(4A10-)2A-2A8-2A3-10A4-D9A4-DA7-A4-2A7-A4-A11-16A10B2A2C10-4C10-2C2A10-4A10-2A-2A8-2A3-10A4-D8AD4-DA6-AD4-2A6-2A4-A8-A2-5A4B7A10B2A2C10-4C10-2C2A10-4A10-2A-2A8-2A3-10A4-9AD4-A7-AD4-A7-2A13-A2-2(4AB)6A10B4(4A10-)2A-2A8-2A3-10A5-9A2(13-A)16-2(4AB)6A10B2A2C10-4C10-2C2A10-4A10-2A-2A8-2A3-10A5-8A45-5A4B7A10B2A2C10-4C10-2C2A10-4A10-2A-2A8-2A3-10A5-8A45-16A10B4(4A10-)2(2A-2A8-2A3-10A5-8A45-4AB11A10B2A2C10-4C10-2C2A10-4A10-)2A-2A8-2A3-10A5-8A45-4A6B6A10B4(4A10-)2A-2A8-2A3-10A5-8A45-17A8B3A2C10-4C10-2C2A10-4A10-2A-2A7-3A4-8A6-8A45-18A6B4A2C10-4C10-2C2A10-4A10-2A2-2(2A6-)6A8-6A48-10A4-2A6B2A2(4-2C6-2C)2(4-2A6-2A)6-A4-A9-4A10-4A49-10A4-3A4B3A2(4-2C6-2C)2(4-2A6-2A)6-AD2ADA9-A2-A65-2(6A8-)2(CA2CAC8-)6A8-6A88-
