model
size = 5 27 28, scale = 0.05, origin = -y
material deform = 1, fade = true, lighting = smooth, roughness = 0.3, metalness = 0.6
  colors = A:#EEE B:#111
voxels
10-4B31-2(85B45-)5B85A5B35-5B95A5B30-5B14AB4AB9A4(B4A)B10AB4AB3(3A2B)3AB10A5B30-5B14AB4AB9A4(B4A)B14AB5AB9AB14A5B30-5B69AB25A5B30-5B14A2(B4AB9A)B4AB10AB3A2B3(4AB)14A5B30-5B10A2(B2(3A2B)4A)B3A2B3AB10AB8A2(B4A)2B3AB10A5B30-5B10AB7(3A2B)3AB10A4(B4A)B14A5B30-5B14A5(B4A)2(2B3A)B14A4(B4A)B10A5B30-5B40AB4AB14AB3A2B3(4AB)3AB10A5B30-5B14A3(B4A)2(2B3A)2(B4A)B10AB3A4(B4A)B10A5B30-5B14A3(B4A)2(2B3A)2(B4A)B45A5B30-5B40AB3A2B3AB10AB3A2B3(4AB)14A5B30-5B40AB3A2B3AB10AB3A4(B4A)B10A5B30-5B10A4(B4A)B2(3A2B)4AB49A5B30-5B10A4(B4A)B2(3A2B)4AB14AB3A2B3(4AB)14A5B30-5B44AB4AB10AB3A3(B4A)2B3AB10A5B25-6B14A6(B4A)B3A2B3AB10A4(B4A)B14A5B20-5B5AB14AB7(3A2B)3AB14A4(B4A)B10A5B15-5B25AB3A2B3A2(B4A2(2B3A))B14A2B3(4AB)3AB10A5B10-6B29A2(B4AB9A)B4AB14AB3A4(B4A)B10A5B10-5B85AB29A5B5-5B15A5B4AB10AB4AB9A4(B4A)B14AB13AB9AB10A10B15A5B5-5B10AB4AB9A4(B4A)B18A4(2B3A)B10A10B10A5B10-5B95A10B3A7B20-5B85A5B5-
