model
size = 32 16 5, scale = 0.05, origin = -y
material deform = 1, fade = true, lighting = smooth, roughness = 0.3, metalness = 0.6
  colors = A:#CCC B:#3098CC C:#FCCC00 D:#FCFCFC E:#202020 F:#ECECEC G:#545454 H:#747474 I:#444 J:#B8B8B8 K:#888 L:#DC0000 M:#A80000
voxels
5-2D2A2D24-D8AD21-D10AD5-5E-6E2-D5A2-5AD4-5E-6EC-4AD4-D4A15-BCD3AD6-D3AD2(-G)-M3(-G)-2GCD3A8-3AD10-3I3C2(3A10-3A-I2-F2H2-I3KI2C)D3A8-3AD10-3I3CD3AD6-D3AD2(-G)-M3(-G)-2GC-4AD4-D4A15-BC-D5A2-5AD4-5E-6EC2-D10AD5-5E-5EC4-D8AD24-2D2A2D25-D2-2A2-D22-D-8A-D5-12C2-D-10A-D3-C4E8B3-12A4-C4E8BED4A-4D-4AD12C4B-3A-D4-D-3A-4B2C2J8B-3AD6-D3A-4B2C2J8B2(4AD6-D4AB4F2H2F7B)-3AD6-D3A-4B2C2J8B-3A-D4-D-3A-4B2C2J8BD4A-4D-4AD12C4B2-12A4-2C3E8BE-D-10A-D3-2C3E7BC3-D-8A-D5-12C5-D2-2A2-D24-D2-2A2-D22-D-8A-D19-D-10A-D3-C4E8B3-12A4-C4E8BED4A-4D-4AD12C4B-3A-D4-D-3A-4BCK2J6BL2-3AD6-D3A-B3HIK2J6B2(L-4AD6-D4AB4F2H2F5B)L2-3AD6-D3A-B3HIK2J6BL2-3A-D4-D-3A-4BCK2J6BL-D4A-4D-4AD12C4B2-12A4-2C3E8BE-D-10A-D3-2C3E7BC3-D-8A-D22-D2-2A2-D24-D2-2A2-D22-D-8A-D5-12C2-D-10A-D3-C4E8B3-12A4-C4E8BED4A-4D-4A-12C4B-3A-D4-D-3A-4B2C2J8B-3AD6-D3A-4B2C2J8B2(4AD6-D4AB4F2H2F7B)-3AD6-D3A-4B2C2J8B-3A-D4-D-3A-4B2C2J8BD4A-4D-4AD12C4B2-12A4-2C3E8BE-D-10A-D3-2C3E7BC3-D-8A-D5-12C5-D2-2A2-D25-2D2A2D24-D8AD21-D10AD6-4E-6E2-D5A2-5AD5-4E-6EC-4AD4-D4A15-BCD3AD6-D3A2-2(G-)M3(-G)-2GCD3A8-3A11-3I3C2(3A10-2A2-I2-F2H2-I3KI2C)D3A8-3A11-3I3CD3AD6-D3A2-2(G-)M3(-G)-2GC-4AD4-D4A15-BC-D5A2-5AD5-4E-6EC2-D10AD6-4E-5EC4-D8AD24-2D2A2D21-
