model
size = 32 16 7, scale = 0.05, origin = -y
material deform = 1, fade = true, lighting = smooth, roughness = 0.3, metalness = 0.6
  colors = A:#545454 B:#888 C:#747474 D:#30CCFC E:#EC0000
voxels
6-4C26-8C23-10C9-2A10-5C2-5C19-4C6-4C-15A2-3C8-4CA2-8A2-A3-3C8-4CA2-8A2-A2-2(3C10-3CA2-A6-2(A2-))4C8-4CA2-8A2-A3-3C8-4CA2-8A2-A3-4C6-4C-15A3-5C2-5C21-10C9-2A12-8C26-4C27-2C2B2C24-C8BC21-C10BC8-2A9-C12BC-15A2-4BC4-C4B-15A-C3BC6-C3BCA2E11A2-C3B8-3BCA2E11A2(2-4B8-4BA2EA6D4A)2-C3B8-3BCA2E11A2-C3BC6-C3BCA2E11A3-4BC4-C4B-15A2-C12BC-15A3-C10BC8-2A11-C8BC24-2C2B2C25-C2-2B2-C22-C-8B-C19-C-10B-C7-2A10-12B7-4A7-C4B-4D-4BC5D4A7D-3B-D4-D-3B-16A-3BD6-D3B-2(16A4BD6-D4B)16A-3BD6-D3B-16A-3B-D4-D-3B-16AC4B-4D-4BC5D4A7D2-12B7-4A8-C-10B-C7-2A10-C-8B-C22-C2-2B2-C24-C2-2B2-C22-C-8B-C19-C-10B-C7-2A10-12B7-4A7-C4B-4D-4BC5D4A7D-3B-D4-D-3B-14AE2-3BD6-D3B-2(14AE-4BD6-D4B)14AE2-3BD6-D3B-14AE2-3B-D4-D-3B-14AE-C4B-4D-4BC5D4A7D2-12B7-4A8-C-10B-C7-2A10-C-8B-C22-C2-2B2-C24-C2-2B2-C22-C-8B-C19-C-10B-C7-2A10-12B7-4A7-C4B-4D-4BC5D4A7D-3B-D4-D-3B-16A-3BD6-D3B-2(16A4BD6-D4B)16A-3BD6-D3B-16A-3B-D4-D-3B-16AC4B-4D-4BC5D4A7D2-12B7-4A8-C-10B-C7-2A10-C-8B-C22-C2-2B2-C25-2C2B2C24-C8BC21-C10BC8-2A9-C12BC-15A2-4BC4-C4B-15A-C3BC6-C3BCA2E11A2-C3B8-3BCA2E11A2(2-4B8-4BA2EA6D4A)2-C3B8-3BCA2E11A2-C3BC6-C3BCA2E11A3-4BC4-C4B-15A2-C12BC-15A3-C10BC8-2A11-C8BC24-2C2B2C27-4C26-8C23-10C9-2A10-5C2-5C19-4C6-4C-15A2-3C8-3C-A2-8A2-A3-3C8-4CA2-8A2-A2-2(3C10-3CA2-A6-2(A2-))4C8-4CA2-8A2-A3-3C8-4CA2-8A2-A3-4C6-4C-15A3-5C2-5C21-10C9-2A12-8C26-4C22-
