model
size = 32 18 7, scale = 0.05, origin = -y
material deform = 1, fade = true, lighting = smooth, roughness = 0.3, metalness = 0.6
  colors = A:#050 B:#960 C:#070 D:#C09
voxels
16-A31-2A2(2-A-2C)18-2A2-2AC3-2AC19-2(2A30-)2A2-B-B3-B-B19-3A-BAB-A2(-B)-A17-16A16-2(2A30-)16A16-3A-BAB-A2(-B)-A17-2A2-B-B3-B-B19-2(2A30-)2A2-2AC3-2AC19-2A2(2-A-2C)18-A31-A20-2A2C2A5-2A2(-A)3-A-2(A3-)A8BA3-2A2-2A-5A-3A2-A10BA2-5AB-B3AB-B3-A12BA-2A2-A5-A6-4BA4-A4B-2A-BA-B2-BA-B3-A3BA6-A3B3A-BA4-BA5-A3B8-3B17A2(C3B8-4B2A13B-)A3B8-3B18A3BA6-A3B3A-BA4-BA6-4BA4-A4B-2A-BA-B2-BA-B4-A12BA-2A2-A5-A7-A10BA2-5AB-B3AB-B5-A8BA3-2A2-2A-5A-3A5-2A2C2A5-2A2(-A)3-A-A3-A16-A31-A19-A2-2C2-A4-2A2(-A)C2-A-AC5-A-8B-A2-2AC2ABA-C2ABA2-2(A-)10B-A-3A5B2A4B2A2-12B2-2A2(3-B-B)2-A4B-4A-4B3A-B2(-5B)-3B-A4-A-3B-2A3-2(3B-B-)3BA6-A3B17A2(C3BA6-A4B16A)-3BA6-A3B17A-3B-A4-A-3BC2A3-3B-B-3B-BA4B-4A-4B3A-B2(-5B)2-12B2-2A2(3-B-B)3-A-10B-A-3A5B2A4B2A2-A-8B-A2-2AC2ABA-C2ABA2-A4-A2-2C2-A4-2A2(-A)C2-A-AC19-A31-A19-A2-2C2-A4-2A-C5-C8-A-8B-A2-2A4C-3A2C-3A-A-10B-A-2A2(2-4C)4-12B2-3A3-B-A3-B3-A4B-4A-4B3A12B3-3B-A4-A-3B-2A-B2(-3B-A)-3BA6-A3B17AC3BA6-A4B14AD-C3BA6-A4B14AD2-3BA6-A3B17A-3B-A4-A-3B3A-B-3B-A-3B-2A4B-4A-4B3A12B4-12B2-3A3-B-A3-B4-A-10B-A-2A2(2-4C)4-A-8B-A2-2A4C-3A2C-3A4-A2-2C2-A4-2A-C5-C22-A31-A19-A2-2C2-A4-2A2(-A)C2-A-AC5-A-8B-A2-2AC2ABA-C2ABA2-2(A-)10B-A-3A5B2A4B2A2-12B2-2A2(3-B-B)2-A4B-4A-4B3A-B2(-5B)-3B-A4-A-3B-2A3-2(3B-B-)3BA6-A3B17A2(C3BA6-A4B16A)-3BA6-A3B17A-3B-A4-A-3BC2A3-3B-B-3B-BA4B-4A-4B3A-B2(-5B)2-12B2-2A2(3-B-B)3-A-10B-A-3A5B2A4B2A2-A-8B-A2-2AC2ABA-C2ABA2-A4-A2-2C2-A4-2A2(-A)C2-A-AC19-A31-A20-2A2C2A5-2A2(-A)3-A-2(A3-)A8BA3-2A2-2A-5A-3A2-A10BA2-5AB-B3AB-B3-A12BA-2A2-A5-A6-4BA4-A4B-2A-BA-B2-BA-B3-A3BA6-A3B3A-BA4-BA5-A3B8-3B17A2(C3B8-4B2A13B-)A3B8-3B18A3BA6-A3B3A-BA4-BA6-4BA4-A4B-2A-BA-B2-BA-B4-A12BA-2A2-A5-A7-A10BA2-5AB-B3AB-B5-A8BA3-2A2-2A-5A-3A5-2A2C2A5-2A2(-A)3-A-A3-A16-2(A31-)2A2(2-A-2C)18-2A2-2AC3-2AC19-2(2A30-)2A2-B-B3-B-B19-3A-BAB-A2(-B)-A17-16A16-2(2A30-)16A16-3A-BAB-A2(-B)-A17-2A2-B-B3-B-B19-2(2A30-)2A2-2AC3-2AC19-2A2(2-A-2C)18-A15-
