model
size = 32 16 7, scale = 0.05, origin = -y
material deform = 1, fade = true, lighting = smooth, roughness = 0.3, metalness = 0.6
  colors = A:#51A8DD B:#0F4C3A C:#535953 D:#777
voxels
147-5A-A31-A30-A31-2A69-A26-4A-A25-A2-2A135-2B2A2B24-B8AB21-B10AB19-B5A2-5AB18-4AB4-B4A-12B-BA-B3AB6-B3A15B-2B3A8-3A3BA2-7B2-2B3A10-3A2B-A-7BA-2B3A10-3A2B-A-12B3A8-3A6BA-10B3AB6-B3A2(2B2-)9B-4AB4-B4A-6BA-7B2-B5A2-5AB19-B10AB21-B8AB24-2B2A2B25-B2-2A2-B22-B-8A-B19-B-10A-B19-12A18-B4A-4B-4AB17-3A-B4-B-3A-15C2-3AB6-B3A-2(15C-4AB6-B4A)15C2-3AB6-B3A-15C2-3A-B4-B-3A-15C-B4A-4B-4AB18-12A19-B-10A-B19-B-8A-B22-B2-2A2-B24-B2-2A2-B22-B-8A-B19-B-10A-B19-12A18-B4A-4B-4AB15D2-3A-B4-B-3A-16D-3AB6-B3A-2(16D4AB6-B4A)16D-3AB6-B3A-16D-3A-B4-B-3A-16DB4A-4B-4AB15D3-12A19-B-10A-B19-B-8A-B22-B2-2A2-B24-B2-2A2-B22-B-8A-B19-B-10A-B19-12A18-B4A-4B-4AB17-3A-B4-B-3A-15C2-3AB6-B3A-2(15C-4AB6-B4A)15C2-3AB6-B3A-15C2-3A-B4-B-3A-15C-B4A-4B-4AB18-12A19-B-10A-B19-B-8A-B22-B2-2A2-B25-2B2A2B24-B8AB21-B10AB19-B5A2-5AB18-4AB4-B4A-12B-BA-B3AB6-B3A15B-2B3A8-3A3BA2-7B2-2B3A10-3A2B-A-7BA-2B3A10-3A2B-A-12B3A8-3A6BA-10B3AB6-B3A2(2B2-)9B-4AB4-B4A-6BA-7B2-B5A2-5AB19-B10AB21-B8AB24-2B2A2B168-5A-A31-A30-A31-2A69-A26-4A-A25-A2-2A130-
