model
size = 32 16 7, scale = 0.05, origin = -y
material deform = 1, fade = true, lighting = smooth, roughness = 0.3, metalness = 0.6
  colors = A:#51A8DD B:#0F4C3A C:#535953 D:#777
voxels
113-A9-A2-A18-A9-A2-2A27-A54-2A31-A4-4A22-2A4-2A-2A27-2(A-)A168-2B2A2B24-B8AB21-B10AB19-B12AB-16B-4AB4-B4A-5B2-2B-7B3AB6-B3A6B-A2B2(-3B)3A8-3A6BA-6BA2B4A8-4A5B-A6B-2B4A8-4A5B2A10B3A8-3A6BA-10B3AB6-B3A6B2-9B-4AB4-B4A18-B12AB19-B10AB21-B8AB24-2B2A2B25-B2-2A2-B22-B-8A-B19-B-10A-B19-12A2-B14C2B4A-4B-4A2B14CB-3A-B4-B-3A-B14CB-3AB6-B3A-2(B14CB4AB6-B4A)B14CB-3AB6-B3A-B14CB-3A-B4-B-3A-B14C2B4A-4B-4AB18-12A19-B-10A-B19-B-8A-B22-B2-2A2-B24-B2-2A2-B22-B-8A-B19-B-10A-B19-12A2-16DB4A-4B-4AB16D-3A-B4-B-3A-16D-3AB6-B3A-2(16D4AB6-B4A)16D-3AB6-B3A-16D-3A-B4-B-3A-16DB4A-4B-4AB18-12A19-B-10A-B19-B-8A-B22-B2-2A2-B24-B2-2A2-B22-B-8A-B19-B-10A-B19-12A2-B14C2B4A-4B-4A2B14CB-3A-B4-B-3A-B14CB-3AB6-B3A-2(B14CB4AB6-B4A)B14CB-3AB6-B3A-B14CB-3A-B4-B-3A-B14C2B4A-4B-4AB18-12A19-B-10A-B19-B-8A-B22-B2-2A2-B25-2B2A2B24-B8AB21-B10AB19-B12AB-16B-4AB4-B4A-5B2-2B-7B3AB6-B3A6B-A2B2(-3B)3A8-3A6BA-6BA2B4A8-4A5B-A6B-2B4A8-4A5B2A10B3A8-3A6BA-10B3AB6-B3A6B2-9B-4AB4-B4A18-B12AB19-B10AB21-B8AB24-2B2A2B134-A9-A2-A18-A9-A2-2A27-A54-2A31-A4-4A22-2A4-2A-2A27-2(A-)A163-
