model
size = 32 16 7, scale = 0.05, origin = -y
material deform = 1, fade = true, lighting = smooth, roughness = 0.3, metalness = 0.6
  colors = A:#0F4C3A B:#51A8DD C:#535953 D:#777
voxels
154-2(B-)B27-B2-2B18-B8-3B29-B-3B18-B5-2B2-B21-B2-2B-B-3B21-B2-B-B29-B-B142-2B2A2B24-B8AB21-B10AB19-B5A2-5AB18-4AB4-B4A-7A2-6A-B3AB6-B3AB6A-9AB3A8-3AB5AB-12A10-7A2-13A10-19AB3A8-3AB16AB3AB6-B3AB16A-4AB4-B4A-15A2-B5A2-5AB19-B10AB21-B8AB24-2B2A2B25-B2-2A2-B22-B-8A-B19-B-10A-B19-12A18-B4A-4B-4ABA16-3A-B4-B-3A-A14C2-3AB6-B3A-A2(14C-4AB6-B5A)14C2-3AB6-B3A-A14C2-3A-B4-B-3A-A14C-B4A-4B-4ABA17-12A19-B-10A-B19-B-8A-B22-B2-2A2-B24-B2-2A2-B22-B-8A-B19-B-10A-B19-12A18-B4A-4B-4AB15D2-3A-B4-B-3A-16D-3AB6-B3A-2(16D4AB6-B4A)16D-3AB6-B3A-16D-3A-B4-B-3A-16DB4A-4B-4AB15D3-12A19-B-10A-B19-B-8A-B22-B2-2A2-B24-B2-2A2-B22-B-8A-B19-B-10A-B19-12A18-B4A-4B-4ABA16-3A-B4-B-3A-A14C2-3AB6-B3A-A2(14C-4AB6-B5A)14C2-3AB6-B3A-A14C2-3A-B4-B-3A-A14C-B4A-4B-4ABA17-12A19-B-10A-B19-B-8A-B22-B2-2A2-B25-2B2A2B24-B8AB21-B10AB19-B5A2-5AB18-4AB4-B4A-7A2-6A-B3AB6-B3AB6A-9AB3A8-3AB5AB-12A10-7A2-13A10-19AB3A8-3AB16AB3AB6-B3AB16A-4AB4-B4A-15A2-B5A2-5AB19-B10AB21-B8AB24-2B2A2B175-2(B-)B27-B2-2B18-B8-3B29-B-3B18-B6-B2-B21-B2-2B3-3B21-B2-B-B29-B-B137-
