model
size = 32 16 7, scale = 0.05, origin = -y
material deform = 1, fade = true, lighting = smooth, roughness = 0.3, metalness = 0.6
  colors = A:#222 B:#555 C:#777 D:#566C73 E:#51A8DD F:#3C2F41 G:#AAA H:#C46243 I:#7DB9DE J:#994639 K:#6699A1 L:#EEE
voxels
156-L-F358-6C24-C8AC21-C10AC19-C5A2-5AC-A-2A2-2A-A-5A-4AC4-C4A-16AC3AC6-C3AC16AC3A8-3ACA2(2K2F2J2I2E2H2GAC2A10-4A)2K2F2J2I2E2H2GAC3A8-3ACA2K2F2J2I2E2H2GAC3AC6-C3ACA2K2F2J2I2E2H2GA-4AC4-C4A-A2K2F2J2I2E2H2GA-C5A2-5AC-16A2-C10AC21-C8AC24-6C25-C2-2C2-C22-C-8A-C19-C-10A-C19-12A2-B-2B2-2B-B-5BC4A-4E-4AC15B2-3A-E4-E-3A-15B2-3AE6-E3A-16BC3AE6-E4A15B-C3AE6-E4A15B2-3AE6-E3A-16B-3A-E4-E-3A-15B-C4A-4E-4AC15B3-12A2-B-2B-B2-B3-B2-B-C-10A-C19-C-8A-C22-C2-2C2-C24-C2-2C2-C22-C-8A-C19-C-10A-C19-12A2-D-2D2-2D-D-5DC4A-4E-4AC15D2-3A-E4-E-3A-15D2-3AE6-E3A-16DC3AE6-E4A15D-C3AE6-E4A15D2-3AE6-E3A-16D-3A-E4-E-3A-15D-C4A-4E-4AC15D3-12A2-D-2D-D2-D3-D2-D-C-10A-C19-C-8A-C22-C2-2C2-C24-C2-2C2-C22-C-8A-C19-C-10A-C19-12A2-B-2B2-2B-B-5BC4A-4E-4AC15B2-3A-E4-E-3A-15B2-3AE6-E3A-16BC3AE6-E4A15B-C3AE6-E4A15B2-3AE6-E3A-16B-3A-E4-E-3A-15B-C4A-4E-4AC15B3-12A2-B-2B-B2-B3-B2-B-C-10A-C19-C-8A-C22-C2-2C2-C25-6C24-C8AC21-C10AC19-C5A2-5AC-A-2A2-2A-A-5A-4AC4-C4A-16AC3AC6-C3AC16AC3A8-3ACA2(2K2F2J2I2E2H2GAC2A10-4A)2K2F2J2I2E2H2GAC3A8-3ACA2K2F2J2I2E2H2GAC3AC6-C3ACA2K2F2J2I2E2H2GA-4AC4-C4A-A2K2F2J2I2E2H2GA-C5A2-5AC-16A2-C10AC21-C8AC24-6C177-L-F353-
