model
size = 32 16 7, scale = 0.05, origin = -y
material deform = 1, fade = true, lighting = smooth, roughness = 0.3, metalness = 0.6
  colors = A:#CCC B:#36F C:#007 D:#FFF E:#777 F:#09F
voxels
147-5F-F31-F30-F31-2F69-F26-4F-F25-F2-2F135-2D2A2D24-D8AD21-D10AD19-D12AD18-4AD4-D4A-12B-BFBD3AD6-D3AD14B-BD3A8-3AD2BF2-7B2-2B4A8-4A2B-F-7BF-2B4A8-4A2B-F-11BD3A8-3AD5BF-9BD3AD6-D3AD5B2-9B-4AD4-D4A-6BF-7B2-D12AD19-D10AD21-D8AD24-2D2A2D25-D2-2A2-D22-D-8A-D19-D-10A-D19-12A18-D4A-4D-4AD17-3A-D4-D-3A-15C2-3AD6-D3A-2(15C-4AD6-D4A)15C2-3AD6-D3A-15C2-3A-D4-D-3A-15C-D4A-4D-4A19-12A19-D-10A-D19-D-8A-D22-D2-2A2-D24-D2-2A2-D22-D-8A-D19-D-10A-D19-12A18-D4A-4D-4AD15E2-3A-D4-D-3A-16E-3AD6-D3A-2(16E4AD6-D4A)16E-3AD6-D3A-16E-3A-D4-D-3A-16ED4A-4D-4AD15E3-12A19-D-10A-D19-D-8A-D22-D2-2A2-D24-D2-2A2-D22-D-8A-D19-D-10A-D19-12A18-D4A-4D-4AD17-3A-D4-D-3A-15C2-3AD6-D3A-2(15C-4AD6-D4A)15C2-3AD6-D3A-15C2-3A-D4-D-3A-15C-D4A-4D-4AD18-12A19-D-10A-D19-D-8A-D22-D2-2A2-D25-2D2A2D24-D8AD21-D10AD19-D12AD18-4AD4-D4A-12B-BF-D3AD6-D3AD14B-BD3A8-3AD2BF2-7B2-2B4A8-4A2B-F-7BF-2B4A8-4A2B-F-11BD3A8-3AD5BF-9BD3AD6-D3AD5B2-9B-4AD4-D4A-6BF-7B2-D12AD19-D10AD21-D8AD24-2D2A2D168-5F-F31-F30-F31-2F69-F26-4F-F25-F2-2F130-
