model
size = 32 16 5, scale = 0.05, origin = -y
material deform = 1, fade = true, lighting = smooth, roughness = 0.3, metalness = 0.6
  colors = A:#777 B:#DB4D6D C:#24936E D:#222 E:#444 F:#EEE G:#555 H:#BBB I:#888 J:#592C63
voxels
5-2B2E2B24-B8AB5-13B3-B10AB4-6D-6DB-B5A2-5AB3-6D-6DB-4AB4-B4A17-B3AB6-B3A2-2(G-)J2(-G)BGB2G-B3A8-3A11-3E3-2(E2A10-3A-E2-F2A2-E3IE2-)B3A8-3A11-3E3-B3AB6-B3A2-2(G-)J2(-G)BGB2G2-4AB4-B4A18-B5A2-5AB4-5DB6DB2-B10AB5-5DB6DB3-B8AB5-13B6-2B2E2B25-B2-2E2-B22-B-8A-B4-13B2-B-10A-B3-5D8CD2-12A4-5D8CDB4A-4B-4A13B4C-3A-B4-B-3A-4C2B2H8C-3AB6-B3A-4C2B2H8C2(E3AB6-B4AC4F2A2F7C)-3AB6-B3A-4C2B2H8C-3A-B4-B-3A-4C2B2H8CB4A-4B-4A13B4C2-12A4-5D8CD-B-10A-B3-5D8CD2-B-8A-B4-B17-B2-2E2-B24-B2-2E2-B22-B-8A-B4-13B2-B-10A-B3-5D8CD2-12A4-5D8CDB4A-4B-4A13B4C-3A-B4-B-3A-4CBI2H7C2-3AB6-B3A-C3AEI2H7C2(-E3AB6-B4AC4F2A2F6C)2-3AB6-B3A-C3AEI2H7C2-3A-B4-B-3A-4CBI2H7C-B4A-4B-4A13B4C2-12A4-5D8CD-B-10A-B3-5D8CD2-B-8A-B4-13B5-B2-2E2-B24-B2-2E2-B22-B-8A-B4-13B2-B-10A-B3-5D8CD2-12A4-5D8CDB4A-4B-4A13B4C-3A-B4-B-3A-4C2B2H8C-3AB6-B3A-4C2B2H8C2(E3AB6-B4AC4F2A2F7C)-3AB6-B3A-4C2B2H8C-3A-B4-B-3A-4C2B2H8CB4A-4B-4A13B4C2-12A4-5D8CD-B-10A-B3-5D8CD2-B-8A-B4-B17-B2-2E2-B25-2B2E2B24-B8AB5-13B3-B10AB4-2B4DB6DB-B5A2-5AB3-2B4DB6DB-4AB4-B4A17-B3AB6-B3A2-2(G-)J2(-G)BGB2G-B3A8-3A11-3E3-2(E2A10-3A-E2-F2A2-E3-E2-)B3A8-3A11-3E3-B3AB6-B3A2-2(G-)J2(-G)BGB2G2-4AB4-B4A18-B5A2-5AB3-2B4DB6DB2-B10AB4-2B4DB6DB3-B8AB5-13B6-2B2E2B21-
