model
size = 32 16 5, scale = 0.05, origin = -y
material deform = 1, fade = true, lighting = smooth, roughness = 0.3, metalness = 0.6
  colors = A:#FCFC98 B:#FCCC30 C:#202020 D:#ECECEC E:#444 F:#EC0000
voxels
5-2B2A2B24-B8AB21-B10AB4-AC2-C-C2AC2-CA-B12AB3-AC2-C-C2AC2-CA-4AB4-B4A-15BFB3AB6-B3A2B15-B3A8-3A10B2E5B4A8-4A9B2E5B4A8-4A16-B3A8-3A16BFB3AB6-B3AB2-AC2-C-C2AC2-CA-4AB4-B4A3-AC2-C-C2AC2-CA-B12AB19-B10AB21-B8AB24-2B2A2B25-B2-2A2-B22-B-8A-B4-14A-B-10A-B3-2C-2CA4C2A2C2-12A4-5CA4C2A2CB4A-4B-4ABD2B5-D7B-3A-B4-B-3A-D2B5-D6B2-3AB6-B3A-2(D2B5-D7B4AB6-B4A)D2B5-D7B-3AB6-B3A-D2B5-D7B-3A-B4-B-3A3-2C2ACA4C2A2CB4A-4B-4AB2-2C2ACA4C2A2C2-12A4-14A-B-10A-B19-B-8A-B22-B2-2A2-B24-B2-2A2-B22-B-8A-B19-B-10A-B3-14D2-12A4-14CB4A-4B-4ABD15B-3A-B4-B-3A-D15B-3AB6-B3A-2(D15B4AB6-B4A)D15B-3AB6-B3A-D15B-3A-B4-B-3A3-14CB4A-4B-4AB2-14D2-12A19-B-10A-B19-B-8A-B22-B2-2A2-B24-B2-2A2-B22-B-8A-B4-14A-B-10A-B3-2CAC2A4C2A2C2-12A4-2CAC2A4C2A2CB4A-4B-4ABD2B5-D7B-3A-B4-B-3A-D2B5-D7B-3AB6-B3A-2(D2B5-D2E5B4AB6-B4A)D2B5-D7B-3AB6-B3A-D2B5-D7B-3A-B4-B-3A3-2C2ACA4C2A2CB4A-4B-4AB2-2C2ACA4C2A2C2-12A4-14A-B-10A-B19-B-8A-B22-B2-2A2-B25-2B2A2B24-B8AB21-B10AB4-AC-C2-C2AC2-CA-B12AB3-AC-C2-C2AC2-CA-4AB4-B4A-15BFB3AB6-B3AB16-B3A8-3A10B2E5B4A8-4A9B2E5B4A8-4A16-B3A8-3A16BFB3AB6-B3AB2-AC2-C-C2AC2-CA-4AB4-B4A3-AC2-C-C2AC2-CA-B12AB19-B10AB21-B8AB24-2B2A2B21-
