model
size = 32 16 7, scale = 0.05, origin = -y
material deform = 1, fade = true, lighting = smooth, roughness = 0.3, metalness = 0.6
  colors = A:#CCC B:#EEE C:#FFF D:#020 E:#111 F:#E00 G:#0D0 H:#555
voxels
155-F-F359-2C2A2C24-C8AC21-C10AC2-14B3-C5A2-5AC-16B-4AC4-C4A-B9E2(BF)2BC3AC6-C3ACBE5G3E6BC3A8-3ACB9EB3-2B3A10-3ABE3G5E6B3A10-3AB9EB3-2BC3A8-3ACBE7GE6BC3AC6-C3ACB9EB3-2B-4AC4-C4A-16B-C5A2-5AC-14B4-C10AC21-C8AC24-2C2A2C25-C2-2A2-C22-C-8A-C19-C-10A-C-15B3-12A2-16BC4A-4F-4ACH9D4BH2-3A-F4-F-3A-B9D6B-3AF6-F3A-B9DB3H2B4AF6-F4AB9D4BF-4AF6-F4ABD6-2DB3H2B-3AF6-F3A-BD6-2D6B-3A-F4-F-3A-H9DB4H-C4A-4F-4AC16B2-12A2-15B2-C-10A-C19-C-8A-C22-C2-2A2-C24-C2-2A2-C22-C-8A-C19-C-10A-C-15B3-12A2-16BC4A-4F-4AC16B-3A-F4-F-3A-16B-3AF6-F3A-14BF-4AF6-F4A13BF2-4AF6-F4A14BF2-3AF6-F3A-16B-3A-F4-F-3A-16BC4A-4F-4AC16B2-12A2-15B2-C-10A-C19-C-8A-C22-C2-2A2-C24-C2-2A2-C22-C-8A-C19-C-10A-C-15B3-12A2-16BC4A-4F-4ACH9D4BH2-3A-F4-F-3A-B9D6B-3AF6-F3A-B9DB3H2B4AF6-F4AB9D4BF-4AF6-F4ABD6-2DB3H2B-3AF6-F3A-BD6-2D6B-3A-F4-F-3A-H9DB4H-C4A-4F-4AC16B2-12A2-15B2-C-10A-C19-C-8A-C22-C2-2A2-C25-2C2A2C24-C8AC21-C10AC2-14B3-C12AC-16B-4AC4-C4A-B9E2(BF)2BC3AC6-C3ACBE5G3E6BC3A8-3ACB9EB3-2B3A10-3ABE3G5E6B3A10-3AB9EB3-2BC3A8-3ACBE7GE6BC3AC6-C3ACB9EB3-2B-4AC4-C4A-16B-C5A2-5AC-14B4-C10AC21-C8AC24-2C2A2C176-F-F354-
