model
size = 32 16 7, scale = 0.05, origin = -y
material deform = 1, fade = true, lighting = smooth, roughness = 0.3, metalness = 0.6
  colors = A:#3CF B:#36F C:#007 D:#777 E:#09F F:#39F
voxels
154-E3-E27-E2-2E18-E8-3E29-E-3E18-E5-2E2-E21-E2-2E-E-3E21-E2-E-E29-E-E142-2B2F2B24-B8AB21-B10AB19-B12AB18-4AB4-B4A-B2-B-2B2-3B-2B-B3AB6-B3A7B-10B3A8-3A6BE-9BF3A8-4A4B2-10BF3A8-4A17B3A8-3A18B3AB6-B3A14B-2B-4AB4-B4A-2B-4B4-2B-B2-B12AB19-B10AB21-B8AB24-2B2F2B25-B2-2F2-B22-B-8A-B19-B-10A-B19-12A18-B4A-4B-4A2B16-3A-B4-B-3A-B13C3-3AB6-B3A-2(B14C-F3AB6-B4A)B14C2-3AB6-B3A-B14C2-3A-B4-B-3A-B12C-C-B4A-4B-4A2B17-12A19-B-10A-B19-B-8A-B22-B2-2F2-B24-B2-2F2-B22-B-8A-B19-B-10A-B19-12A18-B4A-4B-4ABD2-D-2D2-3D-2D2-3A-B4-B-3A-16D-3AB6-B3A-2(16DF3AB6-B4A)16D-3AB6-B3A-16D-3A-B4-B-3A-16DB4A-4B-4AB2D-4D4-2D-D3-12A19-B-10A-B19-B-8A-B22-B2-2F2-B24-B2-2F2-B22-B-8A-B19-B-10A-B19-12A18-B4A-4B-4A2B16-3A-B4-B-3A-B14C2-3AB6-B3A-2(B14C-F3AB6-B4A)B14C2-3AB6-B3A-B14C2-3A-B4-B-3A-B14C-B4A-4B-4A2B17-12A19-B-10A-B19-B-8A-B22-B2-2F2-B25-2B2F2B24-B8AB21-B10AB19-B12AB18-4AB4-B4A-B2-B-2B2-3B-2B-B3AB6-B3A7B-10B3A8-3A6BE-9BF3A8-4A4B2-10BF3A8-4A17B3A8-3A18B3AB6-B3A17B-4AB4-B4A-2B-4B4-2B-B2-B12AB19-B10AB21-B8AB24-2B2F2B175-E3-E27-E2-2E18-E8-3E29-E-3E18-E6-E2-E21-E2-2E3-3E21-E2-E-E169-
