model
size = 32 16 7, scale = 0.05, origin = -y
material deform = 1, fade = true, lighting = smooth, roughness = 0.3, metalness = 0.6
  colors = A:#3CF B:#36F C:#007 D:#777 E:#09F F:#39F
voxels
113-E9-E2-E18-E9-E2-2E27-E54-2E31-E4-4E22-2E4-2E-2E27-2(E-)E168-2B2F2B24-B8AB21-B10AB19-B12AB-15B2-4AB4-B4A-5B2-2B-7B3AB6-B3A6B-E2B2(-3B)3A8-3A6BE-6BE2BF3A8-4A5B-E6B-2BF3A8-4A5B2E10B3A8-3A6BE-10B3AB6-B3A6B2-8B2-4AB4-B4A18-B12AB19-B10AB21-B8AB24-2B2F2B25-B2-2F2-B22-B-8A-B19-B-10A-B19-12A2-B15-B4A-4B-4A2B14C2-3A-B4-B-3A-B14C2-3AB6-B3A-2(B14C-F3AB6-B4A)B14C2-3AB6-B3A-B14C2-3A-B4-B-3A-B15-B4A-4B-4AB18-12A19-B-10A21-B-8A-B22-B2-2F2-B24-B2-2F2-B22-B-8A-B19-B-10A-B19-12A2-15D-B4A-4B-4AB16D-3A-B4-B-3A-16D-3AB6-B3A-2(16DF3AB6-B4A)16D-3AB6-B3A-16D-3A-B4-B-3A-15D-B4A-4B-4AB18-12A19-B-10A-B19-B-8A-B22-B2-2F2-B24-B2-2F2-B22-B-8A-B19-B-10A-B19-12A2-B15-B4A-4B-4A2B14C2-3A-B4-B-3A-B14C2-3AB6-B3A-2(B14C-F3AB6-B4A)B14C2-3AB6-B3A-B14C2-3A-B4-B-3A-B15-B4A-4B-4AB18-12A19-B-10A21-B-8A-B22-B2-2F2-B25-2B2F2B24-B8AB21-B10AB19-B12AB-15B2-4AB4-B4A-5B2-2B-7B3AB6-B3A6B-E2B2(-3B)3A8-3A6BE-6BE2BF3A8-4A5B-E6B-2BF3A8-4A5B2E10B3A8-3A6BE-10B3AB6-B3A6B2-8B2-4AB4-B4A18-B12AB19-B10AB21-B8AB24-2B2F2B134-E9-E2-E18-E9-E2-2E27-E54-2E31-E4-4E22-2E4-2E-2E27-2(E-)E163-
