model
size = 32 16 7, scale = 0.05, origin = -y
material deform = 1, fade = true, lighting = smooth, roughness = 0.3, metalness = 0.6
  colors = A:#555 B:#14AC00 C:#CB0003
voxels
208-15A49-16A16-16A48-15A134-2A2B2A24-A8BA21-A10BA19-A5B2-5BA18-4BA4-A4B-6A10-A3BA6-A3B7A8B2-A3B8-3B16A-3B10-22B10-3B17A3B8-3B18A3BA6-A3BA16B-4BA4-A4B-15A2-A5B2-5BA-6A7B5-A10BA21-A8BA24-2A2B2A25-A2-2B2-A22-A-8B-A19-A-10B-A19-12B18-A4B-4C-4B7A11-3B-C4-C-3B-6A11-3BC6-C3B-15A-4BC6-C4B13A2B-4BC6-C4B16A-3BC6-C3B-16A-3B-C4-C-3B-13A2B-A4B-4C-4B16A3-12B19-A-10B-A19-A-8B-A22-A2-2B2-A24-A2-2B2-A22-A-8B-A19-A-10B-A19-12B18-A4B-4C-4B7A11-3B-C4-C-3B-6A8B3-3BC6-C3B-15A-4BC6-C4B13A7BC6-C4B16A-3BC6-C3B-16A-3B-C4-C-3B-13A3BA4B-4C-4B16A3-12B2-6A7B4-A-10B-A19-A-8B-A22-A2-2B2-A24-A2-2B2-A22-A-8B-A19-A-10B-A19-12B18-A4B-4C-4B7A11-3B-C4-C-3B-6A11-3BC6-C3B-15A-4BC6-C4B13A2B-4BC6-C4B16A-3BC6-C3B-16A-3B-C4-C-3B-13A2B-A4B-4C-4B16A3-12B19-A-10B-A19-A-8B-A22-A2-2B2-A25-2A2B2A24-A8BA21-A10BA19-A5B2-5BA18-4BA4-A4B-6A10-A3BA6-A3B7A8B2-A3B8-3B16A-3B10-22B10-3B17A3B8-3B18A3BA6-A3BA16B-4BA4-A4B-15A2-A5B2-5BA-6A7B5-A10BA21-A8BA24-2A2B2A229-15A49-16A16-16A48-15A129-
