model
size = 32 16 10, scale = 0.05, origin = -y
material deform = 1, fade = true, lighting = smooth, roughness = 0.3, metalness = 0.6
  colors = A:#222 B:#CCC C:#EEE D:#FFF E:#700 F:#888 G:#D00 H:#0E0 I:#00F J:#0F3 K:#800
voxels
339-2E-2G27-2E-2G443-2E-2G27-2E-2G442-7F2(25-2(F2C)F)25-7F141-4D26-8D23-10D3-16C2(2-5D)2-C16-4D6-4D-16C-3D8-4DC16-3D8-4D2(16C3D10-3D)10CH-C2-C4D8-4D10C-HC2-C-3D8-4D10CH-C2-C-4D6-4D-10C-H2(C2-)2(5D2-)16C3-10D23-8D26-4D27-2D2B2D24-D8BD21-D10BD2-16C-D12BD2-13AI2-4BD4-D4B-C14ACD3BD6-D3BD-13AI-D3B8-3BDC14AC4B8-4BC13AG-4B8-4BC9AJCAG2-D3B8-3BDC9ACJAI2CD3BD6-D3BDC9AJCACIC-4BD4-D4B-C3A5CACJKG3-D12BD-C14AC2-D10BD2-16C3-D8BD24-2D2B2D25-D2-2B2-D22-D-8B-D19-D-10B-D-16C2-12B3-13AI-D4B-4E-4BDC14AC-3B-E4-E-3B2-13AI2-3BE6-E3B-C14AC4BE6-E4BC13AG-4BE6-E4BC14AC-3BE6-E3B-C14AH-3B-E4-E-3B-C14AHD4B-4E-4BDC14AC2-12B2-C14AC-D-10B-D-C14-C2-D-8B-D22-D2-2B2-D24-D2-2B2-D22-D-8B-D19-D-10B-D-16C2-12B3-13AI-D4B-4E-4BDC14AC-3B-E4-E-3B2-13AI2-3BE6-E3B-C14AC4BE6-E4BC13AG-4BE6-E4BC14AC-3BE6-E3B-C14AH-3B-E4-E-3B-C14AHD4B-4E-4BDC14AC2-12B2-C14AC-D-10B-D-C14-C2-D-8B-D22-D2-2B2-D25-2D2B2D24-D8BD21-D10BD2-16C-D12BD2-13AI2-4BD4-D4B-C14ACD3BD6-D3BD-13AI-D3B8-3BDC14AC4B8-4BC13AG-4B8-4BC9AJCAG2-D3B8-3BDC9ACJAI2CD3BD6-D3BDC9AJCACIC-4BD4-D4B-C3A5CACJKG3-D12BD-C14AC2-D10BD2-16C3-D8BD24-2D2B2D27-4D26-8D23-10D3-16C2(2-5D)2-C16-4D6-4D-16C-3D8-3D-C16-3D8-4D2(16C3D10-3D)10CH-C2-C4D8-4D10C-HC2-C-3D8-4D10CH-C2-C-4D6-4D-10C-H2(C2-)2(5D2-)16C3-10D23-8D26-4D296-7F2(25-2(F2C)F)25-7F135-
