model
size = 32 16 12, scale = 0.05, origin = -y
material deform = 1, fade = true, lighting = smooth, roughness = 0.3, metalness = 0.6
  colors = A:#545454 B:#444 C:#747474 D:#30CCFC E:#00FC30 F:#EC0000
voxels
113-A2-3A474-A2-3A506-6A57-16A16-A6-2A23-2(A6-9A16-)A6-2A23-16A273-6A57-16A16-A6E2A4D-2D2(16-A6E9A)16-A6E2A4D-2D16-16A198-4C26-8C23-10C4-6A11-2(5C2-)9A4DA2D-4C6-4C-16A-3C8-4C12AD-2A-3C8-4C2(16A3C10-3C)12AD-2A4C8-4C16A-3C8-4C9A4DA2D-4C6-4C-9A4-A4-5C2-5C21-10C23-8C26-4C27-2C2B2C24-C8BC21-C10BC3-6A10-C12BC-9A4DA2D-4BC4-C4B-16AC3BC6-C3BC12AD-2AC3B8-3BC2(14AF-4B8-4B)12AD-2AC3B8-3BC16AC3BC6-C3BC9A4DA2D-4BC4-C4B-9A4-A3-C12BC19-C10BC21-C8BC24-2C2B2C25-C2-2B2-C22-C-8B-C19-C-10B-C2-5A12-12B2-6A8-2DC4B-4D-4BC6A8-2A-3B-D4-D-3B-6A8-2A-3BD6-D3B-2(6A8-F-4BD6-D4B)6A8-2A-3BD6-D3B-6A8-2A-3B-D4-D-3B-6A8-2DC4B-4D-4BC6A12-12B19-C-10B-C19-C-8B-C22-C2-2B2-C24-C2-2B2-C22-C-8B-C19-C-10B-C2-5A12-12B2-6A8-2DC4B-4D-4BC6A8-2A-3B-D4-D-3B-6A8-2A-3BD6-D3B-2(6A8-F-4BD6-D4B)6A8-2A-3BD6-D3B-6A8-2A-3B-D4-D-3B-6A8-2DC4B-4D-4BC6A12-12B19-C-10B-C19-C-8B-C22-C2-2B2-C25-2C2B2C24-C8BC21-C10BC3-6A10-C12BC-9A4DA2D-4BC4-C4B-16AC3BC6-C3BC12AD-2AC3B8-3BC2(14AF-4B8-4B)12AD-2AC3B8-3BC16AC3BC6-C3BC9A4DA2D-4BC4-C4B-9A4-A3-C12BC19-C10BC21-C8BC24-2C2B2C27-4C26-8C23-10C4-6A11-2(5C2-)9A4DA2D-4C6-4C-16A-3C8-3C-12AD-2A-3C8-4C2(16A3C10-3C)12AD-2A4C8-4C16A-3C8-4C9A4DA2D-4C6-4C-9A4-A4-5C2-5C21-10C23-8C26-4C103-6A57-16A16-A6E2A4D-2D2(16-A6E9A)16-A6E2A4D-2D16-16A273-6A57-16A16-A6-2A23-2(A6-9A16-)A6-2A23-16A192-
