model
size = 5 16 28, scale = 0.05, origin = -y
material deform = 1, fade = true, lighting = smooth, roughness = 0.3, metalness = 0.6
  colors = A:#EEE B:#111
voxels
-3B6-4B26-2B-37B35-2B-42B35-5B35A5B30-5B14AB4A2B4AB3A2B3AB5A5B30-5B10AB4AB8AB15A5B30-5B14AB4A3(2B3A)B5A5B30-5B40A5B30-5B10AB4AB3(3A2B)9A5B30-5B10AB3AB5AB9AB3AB5A3B-B30-5B19A2(B4A)B10A5B30-5B10A3(B4A)B14A5B30-5B9AB4AB5A2(B9A)5B30-5B10A3(B4A)B14A5B30-5B14A4(B4A)B5A5B30-5B10A2(B4A)B3A2B4AB9A5B30-5B14AB4A2B3A2(B4A)B5A5B30-5B10A4(B4A)B9A5B30-5B14A3(B4A)B10A5B30-5B5AB4AB13AB9AB5A5B25-6B18A3(B4A)B10A5B20-5B5AB19A2(B4A)B14A5B15-5B25AB3AB9AB5AB3AB5A5B10-6B33A3(2B3A)B4AB5A5B10-5B60A5B5-5B15A5B4AB10A2(B4A)B2(3A2B)3AB5A10B15A5B5-5B14AB4A2B19A10B10A5B10-5B10AB4AB8A2(2B3A)B5A10B3A7B20-5B35A5B
