model
size = 26 32 26, scale = 0.05, origin = -y
material deform = 1, fade = true, lighting = smooth, roughness = 0.3, metalness = 0.6
  colors = A:#FFF
voxels
10-8A17-62(8A18-)8A16-31(2A8-2A14-)2A8-2(2A12-)31(2A10-2A12-)2A9-31(A16-A8-)A16-A7-31(A18-A6-)A18-A5-63(A20-A4-)A20-A3-63(A22-A2-)A22-A-A255(24-2A)24-A-63(A22-A2-)A22-A3-63(A20-A4-)A20-A5-31(A18-A6-)A18-A7-31(A16-A8-)A16-A9-31(2A12-2A10-)2(2A12-)31(2A8-2A14-)2A8-2A7-
