model
size = 26 29 26, scale = 0.05, origin = -y
material deform = 1, fade = true, lighting = smooth, roughness = 0.3, metalness = 0.6
  colors = A:#8D8D8D B:#999 C:#000
voxels
10-2B4A2B355-14(2B4A2B18-)2B4A2B356-15(2B4A2B18-)2B4A2B278-2(2B4A2B18-)2B4A2B16-15(AB8-BA14-)AB8-BA198-2(2B4A2B18-)2B4A2B16-2(AB8-BA14-)AB8-BA2(12-2A)15(10-2A12-2A)118-2(8C18-)8C16-2(AB8-BA14-)AB8-BA2(12-2A)2(10-2A12-2A)9-15(B16-B8-)B16-B65-8C18-8C16-2(2C8-2C14-)2C8-2C2(12-2A)2(10-2A12-2A)9-2(B16-B8-)B16-B7-15(B18-B6-)B18-B38-8C16-2C8-2C14-2C8-2C13-5(C12-)C10-AB14-B2(A8-A16-)A7-2(A18-A6-)A18-A5-15(A20-A4-)A20-A11-8C16-2C8-2C13-3(C12-)C11-2(C14-C10-)C14-C9-2(A16-A8-)A16-A7-2(A18-A6-)A18-A5-15(A20-A4-)A20-A10-C8-C14-2C10-2C11-C14-C10-C14-C9-2(C16-C8-)C16-C7-2(A18-A6-)A18-A5-2(A20-A4-)A20-A3-15(A22-A2-)A22-A8-C10-C13-C12-C11-C14-C10-C14-C9-2(C16-C8-)C16-C7-2(B18-B6-)B18-B5-2(B20-B4-)B20-B3-15(B22-B2-)B22-B7-2(C12-C11-C14-C9-C16-C8-C16-C7-2(C18-C6-)C18-C5-2(B20-B4-)B20-B3-2(B22-B2-)B22-B-B15(24-2B)24-B6-)4(C12-C11-C14-C9-C16-C8-C16-C7-2(C18-C6-)C18-C5-2(A20-A4-)A20-A3-2(A22-A2-)A22-A-A15(24-2A)24-A6-)C12-C11-C14-C9-C16-C8-C16-C7-2(C18-C6-)C18-C5-2(B20-B4-)B20-B3-2(B22-B2-)B22-B-B15(24-2B)24-B6-C12-C11-C14-C9-C16-C8-C16-C7-2(C18-C6-)C18-C5-2(B20-B4-)B20-B3-2(B22-B2-)B22-B-B15(24-2B)24-B7-C10-C13-C12-C11-C14-C10-C14-C9-2(C16-C8-)C16-C7-2(B18-B6-)B18-B5-2(B20-B4-)B20-B3-15(B22-B2-)B22-B9-C8-C14-2C10-2C11-C14-C10-C14-C9-2(C16-C8-)C16-C7-2(A18-A6-)A18-A5-2(A20-A4-)A20-A3-15(A22-A2-)A22-A10-8C16-2C8-2C13-3(C12-)C11-2(C14-C10-)C14-C9-2(A16-A8-)A16-A7-2(A18-A6-)A18-A5-15(A20-A4-)A20-A37-8C16-2C8-2C14-2C8-2C13-5(C12-)C10-AB14-B2(A8-A16-)A7-2(A18-A6-)A18-A5-15(A20-A4-)A20-A63-8C18-8C16-2(2C8-2C14-)2C8-2C2(12-2A)2(10-2A12-2A)9-2(B16-B8-)B16-B7-15(B18-B6-)B18-B116-2(8C18-)8C16-2(AB8-BA14-)AB8-BA2(12-2A)2(10-2A12-2A)9-15(B16-B8-)B16-B195-2(2B4A2B18-)2B4A2B16-2(AB8-BA14-)AB8-BA2(12-2A)15(10-2A12-2A)274-2(2B4A2B18-)2B4A2B16-15(AB8-BA14-)AB8-BA7-
