model
size = 16 17 9, scale = 0.05, origin = -y
material deform = 1, fade = true, lighting = smooth, roughness = 0.3, metalness = 0.6
  colors = A:#8640FF B:#111 C:#888 D:#5BFAD2 E:#DDD F:#EEE G:#231E17 H:#EB6EFF I:#777
voxels
-8(3C2E12-)3C2EG11-3CG13-C2G13-G2-G16-G65-2(3C2E12-)4(4CE12-)4CE6-8A2CE5-8A3CEG3-8A3CG4-8A-C2G4-8A-G2-G3-8A5-G2-8A8-8A42-2(A6-A8-)A6DA4(8-8A)6-7(8A8-)8A42-2(A6-A8-)7DA8-HBI4B2(A8-A6B)A8-A5B2A6-2A5B6(A8-A6B)A8-8A65-3A6-7DA-2A5-DBI4BA2-A5-HBI4BA8-A6BA8-A5B2A6-2A5B6(A8-A6B)A8-8A65-A8-7DA8-DBI4BA2-A5-HBI4BA2-A5-A6BA8-A5B2A6-2A5B6(A8-A6B)A8-8A8-2H4-2D8-H6-D10-2(A6-A8-)7DA8-HBI4BA8-A6BA2-A5-A6BA8-A5B2A6-2A5B6(A8-A6B)A8-8A42-2(A6-A8-)A6DA8-A6HA3(8-8A)6-2A5B6(A8-A6B)A8-8A152-8A6-5B2A5B4-B3FB2AB3FB4-2(BF)4B2(FB)4-B3FB2AB3FB4-5B2A5B6-8A8-8A38-
