model
size = 32 10 23, scale = 0.05, origin = -y
material deform = 1, fade = true, lighting = smooth, roughness = 0.3, metalness = 0.6
  colors = A:#1F1F1F B:#3D3D3D C:#353535
voxels
66-4(A26-A4-)A26-A164-4(A26-A4-)A26-A228-2(A26-A4-)A26-A227-7(2(A28-A2-)A28-A226-)2(A28-A2-)A28-A225-4(A2(30-2A)30-A224-)A2(30-2A)30-A225-2(2(A28-A2-)A28-A226-)2(A28-A2-)A28-A259-2(2(A26-A4-)A26-A228-)2(A26-A4-)A26-A72-6A8-6A11-2A4C2A6-2A4C2A9-2A2C3BC2A4-2AC3B2C2A7-2A2C5BC2A2-2AC5B2C2A6-A2C7BCA2-AC7B2CA6-AC9BC2AC9BCA6-A2C7B2C2A2C7B2CA6-2A2C5B2C4A2C5B2C2A7-2A6C3A2-3A6C2A9-8A6-8A5-
