model
size = 31 32 17, scale = 0.05, origin = -y
material deform = 1, fade = true, lighting = smooth, roughness = 0.3, metalness = 0.6
  colors = A:#222 B:#FFF C:#060606 D:#E00 E:#200
voxels
8-15B16-4A2BABA2B4A16-3AB2ABAB2AB3A16-2A2(B4A)B2A16-2(AB4AB)A16-B4AB3AB4AB16-4AB5AB4A16-3AB7AB3A16-2AB9AB2A16-AB11ABA16-B3AC5AC3AB16-3AC7AC3A16-AC2AC5AC2ACA17-2(AC)5A2(CA)18-6(AC)A18-2(AC)A3C2(AC)A18-2ACA2(CE)CAC2A18-3A2CDCD2C3A18-A2CA5CA2CA18-CA9CAC18-C3A5C3AC17-4ACA3CAC4A14-5AC3AB3AC5A2(12-4AC4AB4AC4A)13-3AC4AB4AC3A15-3AC3AB3AC3A16-7AB7A18-4A3B4A20-3A2(BA)B3A21-A2(B2A)BA49-2(B15-B14-)A15-A14-2(3AB2AB)3A14-2(2AB)5A2(B2A)14-AB2AB7AB2ABA14-B2AB9AB2AB14-2AB11AB2A14-AB13ABA2(14-17A)14-B15AB3(14-17A)15-4(15A16-)15A11-4B-B13AC-4B6-4AC15AC4A2(6-25A)7-23A8-23A9-21A12-17A15-15A17-13A19-11A22-7B18-2(B17-B12-A17-A12-)3(A17-A12-)B17-B12-A17-3(A12-AB15-B)A12-2B15-2B13-5(A15-A14-)2(A15-)A13-A10-B5-B13-B5-B4-A4-2A13-2A2(4-A)25-A4-2A23-2A4-3A21-3A5-3A19-3A6-4A17-4A7-4A16-3A10-2A15-2A14-2A11-2A17-2A9-2A20-B7-B16-2(B19-B2(10-A19-A)10-)2(A19-A10-)B19-B11-4(A17-A12-)B17-B12-A17-A13-4(A15-A14-)A15-A8-B5-B15-B5-B2(2-A27-A)2-2A25-2A3-2A23-2A4-3A21-3A4-4A19-4A5-4A17-4A7-4A15-4A11-2(A15-)A13-A17-2B9-2B14-2(B19-B3(10-A19-A)10-)A19-A10-2B17-AB2(10-2A17-2A)11-2(A17-A12-)B17-B13-4(A15-A14-)A15-A8-B5-B15-B5-B2(2-A27-A)2-A26-2A2-2A25-2A2-3A23-3A3-3A21-3A4-4A19-4A5-4A17-4A8-3A15-3A2(13-A)17-B11-B14-2(B19-B4(10-A19-A)10-)B19-B4(10-A19-A)11-B17-B3(12-A17-A)13-A15-A7-B6-B15-B6-BA2(28-3A)28-2A-A26-2A2-2A25-2A2-3A23-3A3-3A21-3A5-4A17-4A7-4A15-4A11-2A14-A16-B12-B13-2(B19-B10-)4(A19-A10-)B19-B4(10-A19-A)10-B19-B3(10-A19-A)10-2A17-2A10-BA17-AB11-2(A17-A12-)2A15-2A2(6-B)15-B6-BA3(28-3A)28-2A-A26-2A2-2A25-2A3-2A23-2A4-3A21-3A6-2A19-2A10-2A15-2A14-2(B13-)2(B19-B10-A19-A10-)3(A19-A10-)B19-B4(10-A19-A)10-B19-B2(10-A19-A)2(10-2A17-2A)10-BA17-AB11-A17-A12-2A15-2A6-B5-2B15-2B5-BA4(28-3A)28-2A-A26-2A2-2A25-2A3-2A23-2A5-3A19-3A9-2A15-2A14-2(B13-)2(B19-B2(10-A19-A)10-)2(A19-A10-)B19-B4(10-A19-A)10-B19-B10-A19-A3(10-2A17-2A)10-BA17-AB10-3A15-3A5-B5-2B15-2B5-BA4(28-3A)28-2A-A26-2A2-2A25-2A3-2A23-2A5-3A19-3A9-2A15-2A14-2(B13-)2(B19-B3(10-A19-A)10-)A19-A10-B19-B4(10-A19-A)10-B19-B3(10-2A17-2A)11-A17-A12-BA15-AB6-B5-2B15-2B5-BA3(28-3A)28-2A-A26-2A2-2A25-2A3-2A23-2A4-3A21-3A6-2A19-2A10-2A15-2A14-2(B13-)3(B19-B4(10-A19-A)10-)BA17-AB10-2A17-2A11-2(A17-A12-)2A15-2A2(6-B)15-B6-BA2(28-3A)28-2A-A26-2A2-2A25-2A2-3A23-3A3-3A21-3A5-3A19-3A7-4A15-4A11-2(A15-)2(B13-)2(B19-B10-)4(A19-A10-)B19-B4(10-A19-A)10-B19-B3(10-A19-A)11-B17-B3(12-A17-A)13-B15-B8-B5-B15-B5-B3(2-A27-A)2-2A25-2A2-3A23-3A3-3A21-3A4-4A19-4A5-4A17-4A8-3A15-3A2(13-A)17-2B9-2B14-2(B19-B10-A19-A10-)3(A19-A10-)B19-B10-A19-A3(10-2A17-2A)11-B17-B2(12-A17-A)12-BA15-AB12-2A15-2A13-A15-A14-B15-B14-A15-A8-B5-B15-B5-B2(2-A27-A)2-2A25-2A3-2A23-2A4-3A21-3A4-4A19-4A5-4A17-4A7-4A15-4A11-2A13-2A16-2AB7-B2A45-2(B19-B2(10-A19-A)10-)2(A19-A10-)B19-B11-3(A17-A12-)B17-B2(12-A17-A)13-2(B15-B14-A15-A14-)A15-A9-B4-B15-2(B4-)2(A25-A4-)2A23-2A4-3A21-3A5-3A19-3A6-4A17-4A7-4A15-4A10-2A15-2A14-3AB7-B3A76-2(B17-B3(12-A17-A)12-)A17-A12-BA15-AB3(12-2A15-2A)13-B15-B14-A15-A14-2A13-2A14-BA13-AB2(14-2A13-2A)15-A13-A11-3B2-B13-B2-3B3(6-3A19-3A)7-2A19-2A8-4A15-4A9-3A15-3A12-2(A15-)4AB5-B4A108-2B13-2B2(14-AB13-BA3(14-2A13-2A)14-BA13-AB)2(14-AB13-BA)14-2BA11-A2B14-ABA11-ABA15-BA11-AB4(16-2A11-2A)14-3BA11-A3B11-4A13-4A10-3A15-3A10-3A15-B2A11-2A15-2(2A13-)2A15-5AB3-B5A16-4AB5-B4A141-13B18-5A3B5A18-B3A2(BA)B3AB18-2(AB)2AB2A3BA18-2A2(B3A)B2A18-3A2(B2A)B3A18-4A5B4A18-BA2B2AB2A2BAB18-A2(B4A)BA18-2(BA)5B2(AB)18-4(B2A)B18-2A4(BA)B2A18-2AB2A3B2AB2A18-6BA6B18-2AB2A3B2AB2A18-2A4(BA)B2A18-4(B2A)B18-2(BA)5B2(AB)18-A2(B4A)BA18-BA2B2AB2A2BAB18-4A5B4A17-4A2(B2A)B4A15-8AB8A14-8AB8A15-6AB-B6A17-4AB3-B4A195-
