model
size = 31 32 17, scale = 0.05, origin = -y
material deform = 1, fade = true, lighting = smooth, roughness = 0.3, metalness = 0.6
  colors = A:#F0C B:#609 C:#06F D:#FF0 E:#0F9 F:#111 G:#F60 H:#E00 I:#EEE J:#FC9
voxels
8-2(15A16-)2(15H16-)2(15G16-)2(15D16-)2(15E16-)2(15C16-)15B17-13B2(18-13A)2(18-13H)2(18-13G)18-13D17-15D14-4E2(3FE)3F4E12-5EF2EFEF2EF5E12-5CF2CFCF2CF5C13-4CF2CFCF2CF4C15-3B2FB3F2B2F2B16-15B18-11A20-11A21-9F49-2(A15-A14-)H15-H14-17H2(14-17G)2(14-17D)2(14-17E)2(14-17C)2(14-17B)14-17A15-15A2(16-15H)2(16-15G)11-4D-15D-4D6-25D2(6-25E)7-23C8-23C9-21B12-17B15-15A17-13A19-11F22-7F18-2(A17-A12-)2(H17-H12-)2(G17-G12-)2(D17-D12-)E17-E12-2E15-2E2(12-2C15-2C)12-2B15-2B13-B15-B2(14-A15-A)2(14-H15-H)14-2(G15-)G13-G10-D5-D13-D5-2(D4-)2D13-2D4-D4-E25-E4-2E23-2E4-3C21-3C5-3C19-3C6-4B17-4B7-4B16-3B10-2A15-2A14-2A11-2A17-2F9-2F20-F7-F16-2(A19-A10-)2(H19-H10-)2(G19-G10-)2(D19-D10-)E19-E11-E17-E2(12-C17-C)2(12-B17-B)12-A17-A13-A15-A2(14-H15-H)2(14-G15-G)8-D5-D15-D5-D2-D27-D2-E27-E2-2E25-2E3-2C23-2C4-3C21-3C4-4B19-4B5-4B17-4B7-4A15-4A11-2(A15-)F13-F17-2F9-2F14-2(A19-A10-)2(H19-H10-)2(G19-G10-)2(D19-D10-)E19-E10-2E17-2E2(10-2C17-2C)11-2(B17-B12-)A17-A13-A15-A2(14-H15-H)2(14-G15-G)8-D5-D15-D5-D2-D27-D2-E27-E2-E26-2E2-2C25-2C2-3C23-3C3-BDB21-3B4-4B19-4B5-4A17-AI2A8-3A15-3A2(13-F)17-F11-F14-2(A19-A10-)2(H19-H10-)2(G19-G10-)2(D19-D10-)2(E19-E10-)2(C19-C10-)2(B19-B10-)A19-A11-A17-A2(12-H17-H)12-G17-G13-G15-G7-D6-D15-D6-2D28-2DE28-3E28-2E-C26-2C2-2C25-2C2-3B23-3B3-BDB21-3B5-4A17-4A7-4A15-4A11-2F14-F16-F12-F13-2(A19-A10-)2(H19-H10-)2(G19-G10-)2(D19-D10-)2(E19-E10-)2(C19-C10-)2(B19-B10-)A19-A10-2A17-2A10-2H17-2H11-H17-H12-G17-G12-2G15-2G2(6-D)15-D6-2D28-2DE28-3E28-2EC28-2C-C26-2C2-2B25-2B3-2B23-2B4-3A21-3A6-2A19-2A10-2F15-2F14-2(F13-)2(A19-A10-)2(H19-H10-)2(G19-G10-)2(D19-D10-)2(E19-E10-)2(C19-C10-)2(B19-B10-)A19-A10-2A17-2A2(10-2H17-2H)11-G17-G12-2G15-2G6-D5-2D15-2D5-2D28-2DE28-3E28-2EC28-3C28-2C-B26-2B2-2B25-2B3-2A23-2A5-3A19-3A9-2F15-2F14-2(F13-)2(A19-A10-)2(H19-H10-)2(G19-G10-)2(D19-D10-)2(E19-E10-)2(C19-C10-)2(B19-B10-)A19-A10-2A17-2A2(10-2H17-2H)10-2G17-2G10-3G15-3G5-D5-2D15-2D5-2D28-2DE28-3E28-2EC28-3C28-2C-B26-2B2-2B25-2B3-2A23-2A5-3A19-3A9-2F15-2F14-2(F13-)2(A19-A10-)2(H19-H10-)2(G19-G10-)2(D19-D10-)2(E19-E10-)2(C19-C10-)2(B19-B10-)A19-A10-2A17-2A2(10-2H17-2H)11-G17-G12-2G15-2G6-D5-2D15-2D5-2D28-2DE28-3E28-2EC28-2C-C26-2C2-2B25-2B3-2B23-2B4-3A21-3A6-2A19-2A10-2F15-2F14-2(F13-)2(A19-A10-)2(H19-H10-)2(G19-G10-)2(D19-D10-)2(E19-E10-)2(C19-C10-)2(B19-B10-)A19-A10-2A17-2A10-2H17-2H11-H17-H12-G17-G12-2G15-2G2(6-D)15-D6-2D28-2DE28-3E28-2E-C26-2C2-2C25-2C2-3B23-3B3-BDB21-3B5-3A19-3A7-4A15-4A11-2(F15-)2(F13-)2(A19-A10-)2(H19-H10-)2(G19-G10-)2(D19-D10-)2(E19-E10-)2(C19-C10-)2(B19-B10-)A19-A11-A17-A2(12-H17-H)12-G17-G13-G15-G8-D5-D15-D5-D2-D27-D2(2-E27-E)2-2C25-2C2-3C23-3C3-3B21-3B4-4B19-4B5-4A17-4A8-3A15-3A2(13-F)17-2F9-2F14-2(A19-A10-)2(H19-H10-)2(G19-G10-)2(D19-D10-)E19-E10-2E17-2E2(10-2C17-2C)11-2(B17-B12-)A17-A12-2A15-2A12-2H15-2H13-H15-H2(14-G15-G)8-D5-D15-D5-D2-D27-D2-E27-E2-2E25-2E3-2C23-2C4-CIC21-3C4-4B19-4B5-4B17-4B7-4A15-4A11-2A13-2A16-3F7-3F45-2(A19-A10-)2(H19-H10-)2(G19-G10-)2(D19-D10-)E19-E11-E17-E2(12-C17-C)2(12-B17-B)12-A17-A13-A15-A2(14-H15-H)2(14-G15-G)9-D4-D15-2(D4-)D25-D4-E25-E4-2E23-2E4-3C21-3C5-3C19-3C6-4B17-4B7-4B15-4B10-2A15-2A14-4A7-4A76-2(A17-A12-)2(H17-H12-)2(G17-G12-)2(D17-D12-)E17-E12-2E15-2E2(12-2C15-2C)12-2B15-2B13-B15-B14-A15-A14-2A13-2A2(14-2H13-2H)14-2G13-2G15-G13-G11-3D2-D13-D2-3D6-3D19-3D2(6-3E19-3E)7-2C19-2C8-4C15-4C9-3B15-3B12-2(B15-)5A5-5A108-2(2A13-2A14-)2(2H13-2H14-)2(2G13-2G14-)2(2D13-2D14-)2(2E13-2E14-)2(2C13-2C14-)2B13-2B14-3B11-3B14-3A11-3A15-2A11-2A2(16-2H11-2H)2(16-2G11-2G)14-2(4D11-)4D13-4D2(10-3E15-3E)11-2C15-2(2C13-)2C15-6B3-6B16-5B5-5B141-13F18-6FI6F4(18-5FIFI5F)2(18-2D3FIFI3F2D)18-3EFI3FIF3E18-2E2F5I2F2E2(18-4C5J4C)2(18-4B2JH2J4B)18-2A2J2FJ2F2J2A2(18-2FJF5JFJ2F)18-F11IF2(18-I8FE2FI)18-F11IF17-D2F2J5F2J2FD15-4E9F4E14-4E9F4E15-7C-7C17-5C3-5C195-
