model
size = 31 32 17, scale = 0.05, origin = -y
material deform = 1, fade = true, lighting = smooth, roughness = 0.3, metalness = 0.6
  colors = A:#5B0900 B:#000 C:#450B00 D:#F27935 E:#FFCE92 F:#FFAB63 G:#FFA75E H:#AE4412 I:#FFFFC4 J:#FF7740 K:#FF9D54 L:#FFBF76 M:#FFC981 N:#FFB36C O:#FFB66F P:#FFBA7C Q:#FFF R:#FFC288 S:#FFBA79 T:#FFC280 U:#FFBA76 V:#FFBF74 W:#FFE29C X:#FFBD7C Y:#FFA162 Z:#FFEDAE Aa:#6B2C0B Ab:#9B1C00 Ac:#FFB576 Ad:#FFBF7E Ae:#FFCC8B Af:#A93E09 Ag:#BA6D35 Ah:#FFA75D Ai:#FFB568 Aj:#FFA15D Ak:#FF9556 Al:#E78949 Am:#E5904F An:#FFB877 Ao:#A46236 Ap:#F59A58 Aq:#FF9047 Ar:#DE8847 As:#F79A5B At:#FFA768 Au:#FFAC65 Av:#FFBD7E Aw:#FAB074 Ax:#FFB071 Ay:#E59758 Az:#F7A765 Ba:#F59F60 Bb:#FFF0B1 Bc:#FFEFAB Bd:#FFECA2 Be:#FFC Bf:#FFECB1 Bg:#FFBD81 Bh:#FFC586 Bi:#F9A663 Bj:#FFBD76 Bk:#E38949 Bl:#FFBD83 Bm:#FFA96F Bn:#F29760 Bo:#FFAC71 Bp:#FFC076 Bq:#FFB679 Br:#D98147 Bs:#9D4515 Bt:#C97135 Bu:#FFC481 Bv:#FFAC68 Bw:#F4883D Bx:#FF9F59 By:#C57644 Bz:#A44A1A Ca:#CE5D24 Cb:#F27E3B Cc:#F9833B Cd:#E57230 Ce:#D16027 Cf:#FFB077 Cg:#FFA965 Ch:#FFBF7C Ci:#FFB167 Cj:#FFC78B Ck:#FF9256 Cl:#DD6222 Cm:#FF8B49 Cn:#FA7638 Co:#FF8D49 Cp:#FF8D47 Cq:#FA8340 Cr:#FF9A54 Cs:#FFA459 Ct:#FFB16C Cu:#FFA159 Cv:#FF904E Cw:#FF8D4C Cx:#FF9753 Cy:#FC7E3D Cz:#FFA767 Da:#FF8D4F Db:#FF8D4A Dc:#FFC983 Dd:#FFC276 De:#FFC47C Df:#FFC27E Dg:#FFB065 Dh:#FFC97E Di:#FFE7A6 Dj:#FFB376 Dk:#FFF9BF Dl:#FFD19A Dm:#FFCE90 Dn:#FFE8A1 Do:#FFD490 Dp:#FFCF89 Dq:#FCA15E Dr:#FFD48D Ds:#FFFFC9 Dt:#FFE5AC Du:#FF9D65 Dv:#FFAB72 Dw:#FFC58B Dx:#FFB87C Dy:#FF9858 Dz:#FF9856 Ea:#FFDE9D Eb:#B86A31 Ec:#FFD892 Ed:#FFD69A Ee:#FFE5A9 Ef:#FFBD79 Eg:#FFFCB6 Eh:#FF9F56 Ei:#FCB374 Ej:#FFD192 Ek:#FFB684 El:#FFE0B3 Em:#FFE2B5 En:#FFD4A4 Eo:#FCBA90 Ep:#BB6340 Eq:#FFF9BA Er:#CE8851 Es:#FFEAAB Et:#FFE3A9 Eu:#C03A0B Ev:#E85B24 Ew:#F4632E Ex:#E7A97B Ey:#FF9249 Ez:#652505 Fa:#E89D60 Fb:#FF9D60 Fc:#E24F21 Fd:#FF986C Fe:#FF9A6D Ff:#FF8858 Fg:#C93F0D Fh:#FFCC84 Fi:#FFD697 Fj:#A76D47 Fk:#5D2104 Fl:#F2843B Fm:#040000 Fn:#FAB171 Fo:#FFC984 Fp:#F9773A Fq:#F46C33 Fr:#FA713A Fs:#F26D35 Ft:#FFC781 Fu:#F7B374 Fv:#D1884E Fw:#FFA96A Fx:#FFC783 Fy:#FFC98B Fz:#FFD69D Ga:#FFDDA2 Gb:#FC8 Gc:#F0A262 Gd:#89441C Ge:#8B3407 Gf:#DE8D4F Gg:#FFB879 Gh:#FFA967 Gi:#EDA667 Gj:#BB652E Gk:#FF954F Gl:#FFAB6C Gm:#FFAC67 Gn:#C9793F Go:#FFB579 Gp:#C7763B Gq:#C9672B Gr:#A2491A Gs:#FF9C58 Gt:#C97235 Gu:#C2561D Gv:#FFBA72 Gw:#F9893F Gx:#210000 Gy:#EC7E36 Gz:#F5863D Ha:#ED7933 Hb:#B36A35 Hc:#844721 Hd:#E88B49 He:#ED8035 Hf:#974918 Hg:#D38B4F Hh:#D68447 Hi:#150000 Hj:#E87730 Hk:#FFCF95 Hl:#E88E53 Hm:#FF9049 Hn:#CA591D Ho:#BA5B21 Hp:#B54A13 Hq:#C26026 Hr:#FFC283 Hs:#B34C15 Ht:#FA8945 Hu:#EF7C35 Hv:#D1793B Hw:#FFB56D Hx:#FFC07B Hy:#E79D63 Hz:#FFAE6C
voxels
8-2BC2BH5BHBCB16-8BC6B16-C2BC3BH3BC3B16-3B2ABH2AC5B16-3BHnGuHoBGt2Af5B16-BCGrGqGpGoBPGnHpHC3B16-2BHqBHr2AeAdGlBHs4B16-BAaGjGiGhAcGgAdAcGfAgGe3B16-BGdBGcGbGaFzFyFxFwFv4B16-2BFuFtYFsFrFqFpFoFnBFm2B16-BFjFiFhFgFfFeFdFcFbWFaEz2B16-BExZUAbJEwEvEuAbEtEsEr2B16-BREqSEpEoEnEmElEkEjIEiAaB17-EEgMEfZEeEdXYXQEcEb18-EaIWDzDyDxDwDvDuDtDsDrDq18-DoDnIDmEDlDkDjTDiDhVDg18-DeDdVDcDbDaCzCyCxCwCvCuG18-CtCsCrCqCpCoCnCmClCkCjGCi18-OCgECfCeCdCcCbCaBzByBxK18-BvBuBtBsBrBqBpTBoBnBmBlBk18-BiSBhBgBfBeBdBcBbERBaAz17-BHyAyAxAwPAvNAuAtAsArHzOB14-2ABAoAnAmAlAkAjNMBFLAiAhB2A12-2A2BApGBjHxChUHwDfDpLEh2B2A12-2ABFkBHtGkGmGsBEyKAq2BBwB2A13-A2BHv2BHu2BFl6BA14-ABD3BF2(D2B)J2BA15-7BF7B17-BJ11B19-4BD3BFBD21-9B49-A15-B2(14-A15-A)3(14-A15BA)14-A5B4C6BA14-A5BCBQC6BA14-A5BCQBC6BA14-A5B4C6B5(A14-A15B)A15-4(15B16-)15B11-4B-15B-4B6-25B2(6-5A15B5A)7-4A15B4A8-4A15B4A9-3A15B3A12-A15BA15-15B17-13B19-11B22-7B18-A17-B8(12-A17-A)4(12-2A15-2A)13-5(A15-A14-)2(A15-)B13-B10-B5-B13-B5-2(B4-)2B13-2B4-B4-A25-A4-2A23-2A4-3A21-3A5-3A19-3A6-4A17-4A7-4A16-3A10-2A15-2A14-2B11-2B17-2B9-2B20-B7-B16-A19-B8(10-A19-A)11-5(A17-A12-)A17-A13-4(A15-A14-)A15-A8-B5-B15-B5-B2-B27-B2-A27-A2-2A25-2A3-2A23-2A4-3A21-3A4-4A19-4A5-4A17-4A7-4A15-4A11-2(A15-)B13-B17-2B9-2B14-A19-B8(10-A19-A)3(10-2A17-2A)11-2(A17-A12-)A17-A13-4(A15-A14-)A15-A8-B5-B15-B5-B2-B27-B2-A27-A2-A26-2A2-2A25-2A2-3A23-3A3-3A21-3A4-4A19-4A5-4A17-4A8-3A15-3A2(13-B)17-B11-B14-A19-B14(10-A19-A)11-3(A17-A12-)A17-A13-A15-A7-B6-B15-B6-2B28-2BA28-3A28-2A-A26-2A2-2A25-2A2-3A23-3A3-3A21-3A5-4A17-4A7-4A15-4A11-AB14-A16-B12-B13-A19-B14(10-A19-A)2(10-2A17-2A)11-2(A17-A12-)2A15-2A2(6-B)15-B6-2B3(28-3B)28-2B-B26-2B2-2B25-2B3-2B23-2B4-3B21-3B6-2B19-2B10-2B15-2B14-2(B13-)A19-B14(10-A19-A)3(10-2A17-2A)11-A17-A12-2A15-2A6-B5-2B15-2B5-2B4(28-3B)28-2B-B26-2B2-2B25-2B3-2B23-2B5-3B19-3B9-2B15-2B14-2(B13-)15(B19-B10-)4(BA17-AB10-)B2A15-2A2(B5-)2B15-2B5-2B4(28-3B)28-2B-B26-2B2-2B25-2B3-2B23-2B5-3B19-3B9-2B15-2B14-2(B13-)A19-B14(10-A19-A)3(10-2A17-2A)11-A17-A12-2A15-2A6-B5-2B15-2B5-2B28-2BA2(28-3A)28-2A-A26-2A2-2A25-2A3-2A23-2A4-3A21-3A6-2A19-2A10-2A15-2A14-2(B13-)A19-B14(10-A19-A)2(10-2A17-2A)11-2(A17-A12-)2A15-2A2(6-B)15-B6-2B28-2BA28-3A28-2A-A26-2A2-2A25-2A2-3A23-3A3-3A21-3A5-3A19-3A7-4A15-4A11-2(A15-)2(B13-)A19-B14(10-A19-A)11-3(A17-A12-)A17-A13-A15-A8-B5-B15-B5-B2-B27-B2(2-A27-A)2-2A25-2A2-3A23-3A3-3A21-3A4-4A19-4A5-4A17-4A8-3A15-3A2(13-B)17-2B9-2B14-A19-B8(10-A19-A)3(10-2A17-2A)11-3(A17-A12-)2A15-2A12-2A15-2A13-2(A15-A14-)A15-A8-B5-B15-B5-B2-B27-B2-A27-A2-2A25-2A3-2A23-2A4-3A21-3A4-4A19-4A5-4A17-4A7-4A15-4A11-AD13-BA16-2BA7-A2B45-A19-B8(10-A19-A)11-5(A17-A12-)A17-A13-4(A15-A14-)A15-A9-B4-B15-2(B4-)B25-B4-A25-A4-2A23-2A4-3A21-3A5-3A19-3A6-4A17-4A7-4A15-4A10-2A15-2A14-3BA7-A2BD76-A17-B8(12-A17-A)4(12-2A15-2A)13-2(A15-A14-)3(2A13-2A14-)2A13-2A15-A13-A11-3B2-A13-B2-3B6-3B19-3B2(6-3A19-3A)7-2A19-2A8-4A15-4A9-3A15-3A12-2(A15-)BDB2A5-2A3B108-AB13-2B14-AC12(13-BA14-AB)A11-ABA14-ABA11-ABA15-4(BA11-AB16-)BA11-AB14-3BA11-A3B11-4B13-4B2(10-3A15-3A)11-2A15-2A13-AB13-BA15-BJ2B2A3-2ABJ2B16-4BA5-A3BD141-13B18-BCBGuBHlGt2AfABCB18-BGrGqGpGoHkPGnBH3B18-HiBHhB2AeAdGlAg4B18-AaGjGiGhAcGgAdAcGfAgGe2B18-GdHgGcGbGaFzFyFxFwFvHfBC18-HcFuFtYFsFrFqFpFoFnHbFmB18-FjFiFhFgFfFeFdFcFbWFaEzB18-ExZUAbJEwEvEuAbEtEsErB18-REqSEpEoEnEmElEkEjIEiAa18-EEgMEfZEeEdXYXQEcEb18-EaIWDzDyDxDwDvDuDtDsDrDq18-DoDnIDmEDlDkDjTDiDhVDg18-DeDdVDcDbDaCzCyCxCwCvCuG18-CtCsCrCqCpCoCnCmClCkCjGCi18-OCgECfCeCdCcCbCaBzByBxK18-BvBuBtBsBrBqBpTBoBnBmBlBk18-BiSBhBgBfBeBdBcBbERBaAz18-BAyAxAwPAvNAuAtAsArBO18-AoAnAmAlAkAjNMGvFLAiAh18-BApGBjBChUBDfDpLEhB17-BFkHdBGkGmGsHmEyKAqBGwBwB15-ABGxBGyGzBHaBFlHeBDHj2BA14-A2B2(DB)3ABD4BA15-D5BA-A3BF2B17-3BDA3-A4B195-
