model
size = 31 32 17, scale = 0.05, origin = -y
material deform = 1, fade = true, lighting = smooth, roughness = 0.3, metalness = 0.6
  colors = A:#00A0FF B:#0080FF C:#005FFF D:#0040FF E:#0020FF F:#00F G:#9CF
voxels
8-5(15F16-)5(15E16-)2(15D16-)15D17-2(13D18-)5(13C18-)13B17-15B14-2(19B12-)19B13-17A15-15A16-15A18-11A20-11A21-9A49-5(17F14-)5(17E14-)4(17D14-)17D15-4(15C16-)15C11-4B-15B-4B3(6-25B)7-23B8-23A9-21A12-17A15-15A17-13A19-11A22-7A18-5(F17-F12-)4(E17-E12-)2E15-2E3(12-2D15-2D)13-2(D15-D14-)3(C15-C14-)2(C15-)C13-C10-B5-B13-B5-2(B4-)2B13-2B2(4-B)25-B4-2B23-2B4-3B21-3B5-AGA19-AGA6-4A17-4A7-4A16-3A10-2A15-2A14-2A11-2A17-2A9-2A20-A7-A16-5(F19-F10-)3(E19-E10-)E19-E11-E17-E5(12-D17-D)13-4(C15-C14-)C15-C8-B5-B15-B5-2(B2-B27-)B2-2B25-2B3-2B23-2B4-AGA21-AGA4-4A19-4A5-4A17-4A7-4A15-4A11-2(A15-)A13-A17-2A9-2A14-5(F19-F10-)4(E19-E10-)2E17-2E2(10-2D17-2D)11-2(D17-D12-)D17-D13-4(C15-C14-)C15-C8-B5-B15-B5-2(B2-B27-)B2-B26-2B2-2B25-2B2-3A23-AGA3-3A21-3A4-4A19-4A5-4A17-4A8-3A15-3A2(13-A)17-A11-A14-5(F19-F10-)5(E19-E10-)4(D19-D10-)D19-D11-3(C17-C12-)C17-C13-C15-C7-B6-B15-B6-2B2(28-3B)28-2B-B26-2B2-2A25-2A2-3A23-3A3-3A21-3A5-4A17-4A7-4A15-4A11-2A14-A16-A12-A13-5(F19-F10-)5(E19-E10-)5(D19-D10-)2C17-2C10-2C17-2C11-2(C17-C12-)2C15-2C2(6-B)15-B6-2B3(28-3B)28-2B-A26-2A2-2A25-2A3-2A23-2A4-3A21-3A6-2A19-2A10-2A15-2A14-2(A13-)5(F19-F10-)5(E19-E10-)5(D19-D10-)2(2C17-2C10-)2C17-2C11-C17-C12-2C15-2C6-B5-2B15-CB5-2B3(28-3B)28-2BA28-2A-A26-2A2-2A25-2A3-2A23-2A5-3A19-3A9-2A15-2A14-2(A13-)5(F19-F10-)5(E19-E10-)5(D19-D10-)4(2C17-2C10-)3C15-3C5-B5-2B15-CB5-2B3(28-3B)28-2BA28-2A-A26-2A2-2A25-2A3-2A23-2A5-3A19-3A9-2A15-2A14-2(A13-)5(F19-F10-)5(E19-E10-)5(D19-D10-)2(2C17-2C10-)2C17-2C11-C17-C12-2C15-2C6-B5-2B15-CB5-2B3(28-3B)28-2B-A26-2A2-2A25-2A3-2A23-2A4-3A21-3A6-2A19-2A10-2A15-2A14-2(A13-)5(F19-F10-)5(E19-E10-)5(D19-D10-)2C17-2C10-2C17-2C11-2(C17-C12-)2C15-2C2(6-B)15-B6-2B2(28-3B)28-2B-B26-2B2-2A25-2A2-3A23-AGA3-3A21-AGA5-3A19-AGA7-4A15-4A11-2(A15-)2(A13-)5(F19-F10-)5(E19-E10-)4(D19-D10-)D19-D11-3(C17-C12-)C17-C13-C15-C8-B5-B15-B5-3(B2-B27-)B2-2B25-2B2-3A23-AGA3-3A21-AGA4-4A19-A2GA5-4A17-AG2A8-3A15-3A2(13-A)17-2A9-2A14-5(F19-F10-)4(E19-E10-)2E17-2E2(10-2D17-2D)11-3(D17-D12-)2C15-2C12-2C15-2C13-2(C15-C14-)C15-C8-B5-B15-B5-2(B2-B27-)B2-2B25-2B3-2B23-2B4-3A21-AGA4-4A19-A2GA5-4A17-A2GA7-4A15-4A11-2A13-2A16-3A7-3A45-5(F19-F10-)3(E19-E10-)E19-E11-E17-E5(12-D17-D)13-4(C15-C14-)C15-C9-B4-B15-2(B4-)2(B25-B4-)2B23-2B4-3B21-3B5-3A19-AGA6-4A17-AG2A7-4A15-4A10-2A15-2A14-4A7-4A76-5(F17-F12-)4(E17-E12-)2E15-2E3(12-2D15-2D)13-2(D15-D14-)3(2C13-2C14-)2C13-2C15-C13-C11-3B2-B13-B2-3(3B6-3B19-)3B7-2B19-2B8-4A15-4A9-3A15-3A12-2(A15-)5A5-5A108-5(2F13-2F14-)5(2E13-2E14-)3(2D13-2D14-)3D11-3D14-3D11-3D15-4(2C11-2C16-)2C11-2C14-2(4B11-)4B13-4B2(10-3B15-3B)11-2B15-2B2(13-2A)15-6A3-6A16-5A5-5A141-5(13F18-)5(13E18-)5(13D18-)5(13C18-)13B17-15B15-17B14-17B15-7B-7B17-5A3-5A195-
