model
size = 32 32 18, scale = 0.05, origin = -y
material deform = 1, fade = true, lighting = smooth, roughness = 0.3, metalness = 0.6
  colors = A:#FFFAFA B:#D3D3D3 C:#F5F5F5 D:#C0C0C0 E:#F00
voxels
824-E991-E990-2(E32-)E924-E32-E65-E32-E858-E32-E131-E32-E793-E31-E197-E32-E99-16D6(16-D6B2D6BD)16-16D32-8D6(24-D6BD)2(24-8D)6(24-D6BD)24-8D8-16D4(16-D6B2D6BD)12-E3-D6B2D6BD13-E2-D6B2D6BD16-16D16-B6A2B6AB6(16-C6A2C6AC)16-B6A2B6AB32-B6AB6(24-C6AC)2(24-B6AB)6(24-C6AC)24-B6AB8-B6A2B6AB5(16-C6A2C6AC)13-E2-C6A2C6AC2(14-E-2(B6A2B6AB16-)6(C6A2C6AC16-)B6A2B6AB32-B6AB6(24-C6AC)2(24-B6AB)6(24-C6AC)24-B6AB8-B6A2B6AB6(16-C6A2C6AC))2(16-B6A2B6AB15-EB6A2B6AB6(16-C6A2C6AC)16-B6A2B6AB32-B6AB6(24-C6AC)2(24-B6AB)6(24-C6AC)24-B6AB8-B6A2B6AB6(16-C6A2C6AC))14-E-2(B6A2B6AB16-)6(C6A2C6AC16-)B6A2B6AB32-B6AB6(24-C6AC)2(24-B6AB)6(24-C6AC)24-B6AB8-B6A2B6AB5(16-C6A2C6AC)13-E2-C6A2C6AC14-E-B6A2B6AB16-16D6(16-D6B2D6BD)16-16D32-8D6(24-D6BD)2(24-8D)6(24-D6BD)24-8D8-16D4(16-D6B2D6BD)12-E3-D6B2D6BD13-E2-D6B2D6BD16-16D677-E31-E197-E32-E792-E32-E131-E32-E858-E32-E65-E32-E924-2(E32-)E198-
