model
size = 29 14 25, scale = 0.05, origin = -y
material deform = 1, fade = true, lighting = smooth, roughness = 0.3, metalness = 0.6
  colors = A:#C0C0C0 B:#FFFAFA C:#F00
voxels
147-3(C28-)C290-C28-C86-C28-C204-C27-2C27-C144-C28-2C28-C116-C28-C260-C28-C58-C28-C318-C28-C58-C28-C260-C28-C116-C28-C90-2B27-2B81-C28-C174-C28-C53-5A2B2AB10-B2A6-5A2B2AB10-B2A39-C28-C232-C28-C22-6A2B2AB10-B2A5-6A2B2AB10-B2A11-C28-C311-3A5B2-2AB8-B2A5-3A5B2-2AB8-B2A352-3AB7-2AB8-B2A4-3AB7-2AB8-B2A351-3AB8-2AB8-B2A3-3AB8-2AB8-B2A350-3AB10-2AB6-B2A3-3AB10-2AB6-B2A351-2AB11-2AB6-B2A3-2AB11-2AB6-B2A350-2AB12-2AB6-B2A2-2AB12-2AB6-B2A350-2(2AB13-2AB4-B2A3-2AB13-2AB4-B2A351-)2AB13-2AB4-B2A3-2AB13-2AB4-B2A352-2AB13-2AB2-B2A5-2AB13-2AB2-B2A353-3AB12-2AB2-B2A5-3AB12-2AB2-B2A354-3AB11-2AB2-B2A6-3AB11-2AB2-B2A355-3AB11-2A2B2A8-3AB11-2A2B2A357-3A4B7-2A2B2A9-3A4B7-2A2B2A358-6A7-6A10-6A7-6A359-5A8-4A12-5A8-4A180-
