model
size = 19 31 24, scale = 0.05, origin = -y
material deform = 1, fade = true, lighting = smooth, roughness = 0.3, metalness = 0.6
  colors = A:#AAA B:#E00 C:#A00 D:#888 E:#9CF F:#6F3 G:#111 H:#6C3 I:#0C0 J:#D00 K:#3F6
voxels
521-3A14-7A547-H18-F18-H531-2(F18-)K18-I18-F493-H18-F18-I3(18-F)18-H474-2(F18-)F37-F18-I18-F474-H18-F18-I3(18-F)18-H493-F15-3AF3A12-3AF4A14-I18-I509-7A11-A3CH3C2A8-2A3-H3-2A13-H509-7A11-10A7-3A7C3A6-3A7-4A485-3A14-7A11-10A7-3ACA3J5A5-3AB2C3-4C2A4-3A10-2A465-5A13-7A11-10A8-4A3B5A6-2A3C5B4A4-2AB3C5B3C2A2-3A12-2A65-5D375-5A13-7A11-9A9-4A3B4A7-3A2C5B3A5-2A4C6B3A3-2AB4C6B2C2A2-2A13-3A63-3DE3D15-D321-3A15-5A13-7A11-9A9-4A3J4A7-4A6B3A6-2A2C7B3A4-A4C8B3A2-A5C7B-2CA-2A15-2A63-D4EB2D12-5D300-3A15-5A13-7A11-4AB4A10-3A4B3A8-3A5B3A7-3A7B3A5-3AC8B3A3-2A3C9B3A2-A4C8B-2C4A15-2A62-2DE3-B2D12-D3ED15-3D225-A-A2(16-3A)15-5A14-6A12-3A2B2A11-3A3B3A9-3A5B3A8-2A6BC3A6-2A7B-B2A5-3A7B-2B2A3-2A2C7B-3B2A-2A3C7B-3BC4A15-2A62-2DE3-BED12-DE-E2D14-DED17-11(G18-)G17-AEA16-AEA15-5A14-2AB3A12-2A3B2A11-3A3B-2A9-3A4B-3A8-2A6BC3A6-2A7B-B2A5-2A8B-2B2A3-2AC-6B2-3B2A-2A2C-6B2-3B2C3A16-A62-2DE3-B2D12-D3ED15-3D225-A-A2(16-3A)15-5A14-6A12-3AB3A11-3A3B3A9-3A4B-3A8-2A6BC3A6-3A6B-B2A5-3A7B-2B2A3-3AC6B2-3B2A-2A3C6B2-3BC4A15-2A63-D4EB2D12-5D300-3A15-5A13-7A11-9A10-3A3B4A8-3A5B3A7-3AB-5B3A5-3AB2-6B3A3-3ACB2-8B2A2-A3CB2-8BC4A15-2A63-7D355-5A13-7A11-9A9-4A3B4A7-4A4B-4A6-3AC2-5B3A4-2A3C2-7B2A2-A4C3-7BCA-2A15-2A65-3D376-5A13-7A10-10A9-5A2B4A7-4A6B3A5-2A5C6B2A3-2A6C7B2A2-2A13-2A465-3A14-7A11-9A9-5AB5A7-2A4C-4B2A5-2A5C-5B2A3-3A11-3A501-7A11-9A9-A2C9A6-2A8C4A4-3A8-4A521-7A11-A7CA9-2A7C3A6-3A7-3A541-7A11-9A9-11A61-
