model
size = 19 31 24, scale = 0.05, origin = -y
material deform = 1, fade = true, lighting = smooth, roughness = 0.3, metalness = 0.6
  colors = A:#AAA B:#60F C:#66F D:#888 E:#9CF F:#6F3 G:#111 H:#6C3 I:#0C0 J:#E00 K:#3F6
voxels
521-3A14-7A547-H18-F18-H531-2(F18-)K18-I18-F493-H18-F18-I3(18-F)18-H474-2(F18-)F37-F18-I18-F474-H18-F18-I3(18-F)18-H493-F15-3AF3A12-3AF4A14-I18-I509-7A11-A3BH3B2A8-2A3-H3-2A13-H509-7A11-10A7-3A7B3A6-3A7-4A485-3A14-7A11-10A7-3ACA3C5A5-3A-CB3C4B2A4-3A10-2A465-5A13-7A11-10A8-4A3-5A6-2A6C2B4A4-2A-8C3B2A2-3A12-2A65-5D375-5A13-7A11-9A9-4A3B4A7-3A7B3A5-2A2C5B2-B3A3-2A-7C2-C2B2A2-2A13-3A63-3DE3D15-D321-3A15-5A13-7A11-9A9-4A3B4A7-4A6B3A6-2A9B3A4-A2C10B3A2-A13C2BA-2A15-2A63-D4EJ2D12-5D300-3A15-5A13-7A11-4AB4A10-3A4B3A8-3A5B3A7-3A7B3A5-3A9B3A3-2A2C10B3A2-A13C2B4A15-2A62-2DE3-J2D12-D3ED15-3D225-A-A2(16-3A)15-5A14-6A12-3A2B2A11-3A3B3A9-3A5B3A8-2A7B3A6-2A9B2A5-3A10B2A3-2A2C11B2A-2A14CB4A15-2A62-2DE3-JED12-DE-E2D14-DED17-11(G18-)G17-AEA16-AEA15-5A14-2AB3A12-2A3B2A11-3A4B2A9-3A5B3A8-2A7B3A6-2A9B2A5-2A11B2A3-2AC12B2A-2A14C2B3A16-A62-2DE3-J2D12-D3ED15-3D225-A-A2(16-3A)15-5A14-6A12-3AB3A11-3A3B3A9-3A5B3A8-2A7B3A6-3A8B2A5-3A10B2A3-3A12B2A-2A14CB4A15-2A63-D4EJ2D12-5D300-3A15-5A13-7A11-9A10-3A3B4A8-3A4B-3A7-3A7B3A5-3A9B3A3-3A12B2A2-A14CB4A15-2A63-7D355-5A13-7A11-9A9-4A3B4A7-4A5B4A6-3A8B3A4-2A12B2A2-A14CBA-2A15-2A65-3D376-5A13-7A10-10A9-5A2B4A7-4A6B3A5-2A11B2A3-2A12CB2A2-2A13-2A465-3A14-7A11-9A9-5AB5A7-2A9B2A5-2A-9CB2A3-3A11-3A501-7A11-9A9-A2B9A6-2A2C6B4A4-3A8-4A521-7A11-A7BA9-2A7C3A6-3A7-3A541-7A11-9A9-11A61-
