model
size = 10 11 9, scale = 0.05, origin = -y
material deform = 1, fade = true, lighting = smooth, roughness = 0.3, metalness = 0.6
  colors = A:#777 B:#888 C:#DDD D:#EEE E:#AAA F:#555 G:#960 H:#F96 I:#FCF J:#FFF K:#111 L:#F90 M:#BBB
voxels
13-B2-B6-A2-A2(6-4A)76-B2-B6-A2-A5-A-2A-3(A4-)6A73-AF4-BA3(2-A6-B)3-2AB3A53-A9-A6-B12-A6-B3-A4-B3-2A4-AB4-A3B54-A6-B2-A6-B3-B4-B3-A6-B2-2A4-2B-2A-A3B-3BE6-2EGE6-EG2F6-2F21-A6-B12-AC4-CB3-B4-B3-2A4-2B4-A3B34-J6-J2(2-A6-A)2-A6-B2-AC4BCB2-ACLB-LCB3-A5B56-2D6-G4HG4-2D2I2D4-CE2CMC4-5CD86-2I7-K2-K63-
