model
size = 27 30 19, scale = 0.05, origin = -y
material deform = 1, fade = true, lighting = smooth, roughness = 0.3, metalness = 0.6
  colors = A:#009 B:#005 C:#111 D:#39C E:#6C6 F:#399 G:#6FC H:#EEE I:#F66
voxels
524-B53-B755-B53-B611-3B4-3B17-3A4-3A5(17-10A)2(C16-10A)3(17-10A)17-2(AD)6A3(23-4A)395-3B4-3B17-3A4-3A4(17-10A)H16-10AC16-10A17-9AE17-7A2C2(E17-9A)E17-2(AD)6A23-3AG2(23-4A)395-3B4-3B17-3A4-3A3(17-10A)2(C16-10A)17-10A3(17-9AF)17-9AE17-2(AD)6A23-4A23-3AG23-4A395-3B4-3B17-3A4-3A3(17-10A)H16-10AC16-2(10A17-)3(9AC17-)9AE17-2(AD)6A23-4A23-3AG23-4A395-3B4-3B17-3A4-3A2(17-10A)2(C16-10A)2(17-10A)3(17-9AF)17-9AE17-10A23-3AG2(23-4A)449-10A17-10AH16-10AC16-7(10A17-)10A528-2B10AC14-2B10AH14-2B10AC14-2(2B10A15-)2B10AI14-4(2B10A15-)2B6A4D15-2B25-7B20-7B452-4(2B10AC14-)2(2B10AI14-)5(2B10A15-)2B25-7B20-7B452-2B10AC14-2B10AH14-2B10AC14-2(2B10A15-)2B10AI14-4(2B10A15-)2B6A4D15-2B25-7B20-7B454-10A17-10AH16-10AC16-7(10A17-)10A476-3B4-3B17-3A4-3A2(17-10A)2(C16-10A)2(17-10A)4(17-9AE)17-10A23-3AG2(23-4A)395-3B4-3B17-3A4-3A3(17-10A)H16-10AC16-2(10A17-)3(9AF17-)9AE17-2(AD)6A23-4A23-3AG23-4A395-3B4-3B17-3A4-3A3(17-10A)2(C16-10A)17-10A3(17-9AC)17-9AE17-2(AD)6A23-4A23-3AG23-4A395-3B4-3B17-3A4-3A4(17-10A)H16-10AC16-10A17-9AF17-7A2C2(F17-9A)E17-2(AD)6A23-3AG2(23-4A)41-12(B25-)B21-5B15-3B4-3B17-3A4-3A5(17-10A)2(C16-10A)3(17-10A)17-2(AD)6A3(23-4A)539-B53-B755-B53-B231-
