model
size = 32 32 30, scale = 0.05, origin = -y
material deform = 1, fade = true, lighting = smooth, roughness = 0.3, metalness = 0.6
  colors = A:#BBB B:#30F C:#555 D:#FC3 E:#444
voxels
-64A29(30-2A)30-35A2(-A)-20A2-30A2-136A10(21-11A)21-134A320-34A2(EA)E20A2-30A2-611A320-59A2E30A2E611A2(320-704A)320-19490A9(27B5A)10BD6BD9B5A10BDB2D3BD9B5A8B3DB2DB3D2(9B5A8B2(DB)2D2(BD))9B2(5A27B)5A5B2D4(BD)B3D2(BD)4B5A5BD2B7(DB)D4B5A5B2DB2(2D2B)2(DB)2D5B5A5BD2B7(DB)D4B5A5B2DB2(2D2B)3DB2D5B4(5A27B)261A24(27-5A)27-197A26(27-5A)27-165A27(28-4A)28-99AC28A29(C2AC28-)C2A30C33A
