model
size = 31 32 17, scale = 0.05, origin = -y
material deform = 1, fade = true, lighting = smooth, roughness = 0.3, metalness = 0.6
  colors = A:#141414 B:#0F0F0F C:#FF571D D:#FF8000 E:#F60 F:#FF493A G:#F90 H:#FF1D92 I:#FFB300 J:#FF3A57 K:#FF2C75 L:#FF0FAF
voxels
8-15B16-2A11F2A16-15A16-2A5CA5C2A16-15A16-2A11E2A16-15A16-2A5DA5D2A16-15A16-2A11G2A16-15A16-2A11I2A16-15A17-2A2GA3GA2G2A18-13A18-A11DA18-13A18-2(A5E)A18-13A18-A11CA18-13A17-3A9F3A14-19A12-4A11J4A12-19A13-3A5KA5K3A15-15A16-3A2HA3HA2H3A18-11A20-A9LA21-9A49-B15-B2(14-A15-A)12(14-17A)15-4(15A16-)15A11-4B-15A-4B3(6-25A)7-23A8-23A9-21A12-17A15-15A17-13A19-11A22-7B18-B17-B8(12-A17-A)4(12-2A15-2A)13-5(A15-A14-)2(A15-)A13-A10-B5-A13-A5-B4-A4-2A13-2A2(4-A)25-A4-2A23-2A4-3A21-3A5-3A19-3A6-4A17-4A7-4A16-3A10-2A15-2A14-2A11-2A17-2A9-2A20-B7-B16-B19-B8(10-A19-A)11-5(A17-A12-)A17-A13-4(A15-A14-)A15-A8-B5-A15-A5-B2(2-A27-A)2-2A25-2A3-2A23-2A4-3A21-3A4-4A19-4A5-4A17-4A7-4A15-4A11-2(A15-)2A11-2A18-B9-B15-B19-B8(10-A19-A)3(10-2A17-2A)11-2(A17-A12-)A17-A13-4(A15-A14-)A15-A8-B5-A15-A5-B2(2-A27-A)2-A26-2A2-2A25-2A2-3A23-3A3-3A21-3A4-4A19-4A5-4A17-4A8-3A15-3A2(13-A)17-B11-B14-B19-B14(10-A19-A)11-3(A17-A12-)A17-A13-A15-A7-B6-A15-A6-BA2(28-3A)28-2A-A26-2A2-2A25-2A2-3A23-3A3-3A21-3A5-4A17-4A7-4A15-4A11-2A13-2A16-B11-B14-B19-B14(10-A19-A)2(10-2A17-2A)11-2(A17-A12-)2A15-2A6-B6-A15-A6-BA3(28-3A)28-2A-A26-2A2-2A25-2A3-2A23-2A4-3A21-3A6-2A19-2A10-2A15-2A14-2(B13-)B19-B14(10-A19-A)3(10-2A17-2A)11-A17-A12-2A15-2A6-B5-2A15-2A5-BA4(28-3A)28-2A-A26-2A2-2A25-2A3-2A23-2A5-3A19-3A9-2A15-2A14-2(B13-)B19-B14(10-A19-A)4(10-2A17-2A)10-3A15-3A5-B5-2A15-2A5-BA4(28-3A)28-2A-A26-2A2-2A25-2A3-2A23-2A5-3A19-3A9-2A15-2A14-2(B13-)B19-B14(10-A19-A)3(10-2A17-2A)11-A17-A12-2A15-2A6-B5-2A15-2A5-BA3(28-3A)28-2A-A26-2A2-2A25-2A3-2A23-2A4-3A21-3A6-2A19-2A10-2A15-2A14-2(B13-)B19-B14(10-A19-A)2(10-2A17-2A)11-2(A17-A12-)2A15-2A6-B6-A15-A6-BA2(28-3A)28-2A-A26-2A2-2A25-2A2-3A23-3A3-3A21-3A5-3A19-3A7-4A15-4A11-2(A15-)2(B13-)B19-B14(10-A19-A)11-3(A17-A12-)A17-A13-A15-A8-B5-A15-A5-B3(2-A27-A)2-2A25-2A2-3A23-3A3-3A21-3A4-4A19-4A5-4A17-4A8-3A15-3A2(13-A)17-2B9-2B14-B19-B8(10-A19-A)3(10-2A17-2A)11-3(A17-A12-)2A15-2A12-2A15-2A13-2(A15-A14-)A15-A8-B5-A15-A5-B2(2-A27-A)2-2A25-2A3-2A23-2A4-3A21-3A4-4A19-4A5-4A17-4A7-4A15-4A11-2A13-2A16-2AB7-B2A45-B19-B8(10-A19-A)11-5(A17-A12-)A17-A13-4(A15-A14-)A15-A9-B4-A15-A4-B2(4-A25-A)4-2A23-2A4-3A21-3A5-3A19-3A6-4A17-4A7-4A15-4A10-2A15-2A14-3AB7-B3A76-B17-B8(12-A17-A)4(12-2A15-2A)13-2(A15-A14-)3(2A13-2A14-)2A13-2A15-A13-A11-3B2-A13-A2-3B3(6-3A19-3A)7-2A19-2A8-4A15-4A9-3A15-3A12-2(A15-)4AB5-B4A108-2B13-2B12(14-2A13-2A)2(14-3A11-3A)15-4(2A11-2A16-)2A11-2A14-2(4A11-)4A13-4A2(10-3A15-3A)11-2A15-2(2A13-)2A15-5AB3-B5A16-4AB5-B4A141-13B18-A11IA18-13A18-2A9G2A18-13A18-A11DA18-13A18-A2EA5EA2EA18-13A18-A11CA18-13A18-2A9F2A18-13A18-A11JA18-13A18-2(A5K)A18-13A18-A11HA18-13A18-2A2LA3LA2L2A18-13A17-3A9H3A15-17A14-8AB8A15-6AB-B6A17-4AB3-B4A195-
