model
size = 31 31 9, scale = 0.05, origin = -y
material deform = 1, fade = true, lighting = smooth, roughness = 0.3, metalness = 0.6
  colors = A:#09C B:#111 C:#FF3 D:#063
voxels
76-CBC28-CBC27-3(2CB2C26-)2CB2C25-5(3CB3C24-)3CB3C23-5(4CB4C22-)4CB4C20-13B18-13B21-3(7B24-)2(B2-)B24-B5-B25-B3-B27-3B152-CBC28-CBC27-3(2CB2C26-)2CB2C25-5(3CB3C24-)3CB3C23-5(4CB4C22-)4CB4C20-13B18-13B21-3(7B24-)2(B2-)B24-B5-B25-B3-B27-3B88-7A21-13A16-17A13-19A11-21A9-23A7-25A5-27A4-27A3-2(29A2-)29A-139AD77A-2(29A2-)29A3-27A4-27A5-25A7-23A9-21A11-19A13-17A16-13A21-7A24-7A21-13A16-17A13-19A11-21A9-23A7-25A5-27A4-27A3-2(29A2-)29A-217A-2(29A2-)29A3-27A4-27A5-25A7-23A9-21A11-19A13-17A16-13A21-7A24-7A21-13A16-5A7-5A2(13-3A)11-3A15-3A9-2A19-2A7-2A21-2A5-3A21-3A4-2A23-2A3-2(2A25-2A2-)2A25-2A-2A7-B11-B5(7-4A7-A11-A)7-4A7-B11-B7-2A-2(2A25-2A2-)2A25-2A3-2A23-2A4-3A21-3A5-2A21-2A7-2A19-2A9-3A15-3A11-2(3A13-)5A7-5A16-13A21-7A24-7A21-3A7-3A16-2(2A13-)A17-A11-A19-A9-A21-A7-A23-A5-A25-A4-A25-A3-2(A27-A2-)A27-A-A8-B11-B5(8-2A8-A11-A)8-2A8-B11-B8-A-2(A27-A2-)A27-A3-A25-A4-A25-A5-A23-A7-A21-A9-A19-A11-A17-A2(13-2A)16-3A7-3A21-7A393-2(B11-B5(18-A11-A)18-B11-B762-)B11-2(B18-13B18-B11A)B18-13B18-B11-B381-
