model
size = 31 32 17, scale = 0.05, origin = -y
material deform = 1, fade = true, lighting = smooth, roughness = 0.3, metalness = 0.6
  colors = A:#DF0000 B:#700 C:#FFF
voxels
8-15B16-15A16-6ACAC6A16-7A2C2(6A16-6ACAC)6A16-6A3C6A16-15A2(16-6A3C6A16-8AC6A)16-6A3C6A17-13A2(18-7AC5A)18-5A3C5A18-5ACAC5A18-5A3C5A18-13A18-5A3C5A17-6ACAC6A14-2(8ACAC8A12-)19A13-7A3C7A15-6AC8A16-6A3C6A18-6AC4A20-4A3C4A21-9A49-B15-B2(14-A15-A)12(14-17A)15-4(15A16-)15A11-4B-B13AB-4B3(6-25A)7-23A8-23A9-21A12-17A15-15A17-13A19-11A22-7B18-B17-B8(12-A17-A)4(12-2A15-2A)13-5(A15-A14-)2(A15-)A13-A10-B5-B13-B5-B4-A4-2A13-AB2(4-A)25-A4-2A23-2A4-3A21-3A5-3A19-3A6-4A17-4A7-4A16-3A10-2A15-2A14-2A11-2A17-2A9-2A20-B7-B16-B19-B8(10-A19-A)11-5(A17-A12-)A17-A13-4(A15-A14-)A15-A8-B5-B15-B5-B2(2-A27-A)2-2A25-2A3-2A23-2A4-3A21-3A4-4A19-4A5-4A17-4A7-4A15-4A11-2(A15-)A13-A17-2B9-2B14-B19-B8(10-A19-A)3(10-2A17-2A)11-2(A17-A12-)A17-A13-4(A15-A14-)A15-A8-A5-B15-B5-B2(2-A27-A)2-A26-2A2-2A25-2A2-3A23-3A3-3A21-3A4-4A19-4A5-4A17-4A8-3A15-3A2(13-A)17-B11-B14-B19-B14(10-A19-A)11-3(A17-A12-)A17-A13-A15-A7-B6-B15-B6-BA2(28-3A)28-2A-A26-2A2-2A25-2A2-3A23-3A3-3A21-3A5-4A17-4A7-4A15-4A11-2A14-A16-B12-B13-B19-B14(10-A19-A)2(10-2A17-2A)11-2(A17-A12-)2A15-2A2(6-B)15-B6-BA3(28-3A)28-2A-A26-2A2-2A25-2A3-2A23-2A4-3A21-3A6-2A19-2A10-2A15-2A14-2(B13-)B19-B14(10-A19-A)3(10-2A17-2A)11-A17-A12-2A15-2A6-B5-BA15-AB5-BA4(28-3A)28-2A-A26-2A2-2A25-2A3-2A23-2A5-3A19-3A9-2A15-2A14-2(B13-)B19-B14(10-A19-A)4(10-2A17-2A)10-3A15-3A2(5-B)A15-AB5-BA4(28-3A)28-2A-A26-2A2-2A25-2A3-2A23-2A5-3A19-3A9-2A15-2A14-2(B13-)B19-B14(10-A19-A)3(10-2A17-2A)11-A17-A12-2A15-2A6-B5-BA15-AB5-BA3(28-3A)28-2A-A26-2A2-2A25-2A3-2A23-2A4-3A21-3A6-2A19-2A10-2A15-2A14-2(B13-)B19-B14(10-A19-A)2(10-2A17-2A)11-2(A17-A12-)2A15-2A2(6-B)15-B6-BA2(28-3A)28-2A-A26-2A2-2A25-2A2-3A23-3A3-3A21-3A5-3A19-3A7-4A15-4A11-2(A15-)2(B13-)B19-B14(10-A19-A)11-3(A17-A12-)A17-A13-A15-A8-B5-B15-B5-B3(2-A27-A)2-2A25-2A2-3A23-3A3-3A21-3A4-4A19-4A5-4A17-4A8-3A15-3A2(13-A)17-2B9-2B14-B19-B8(10-A19-A)3(10-2A17-2A)11-3(A17-A12-)2A15-2A12-2A15-2A13-2(A15-A14-)A15-A8-B5-B15-B5-B2(2-A27-A)2-2A25-2A3-2A23-2A4-3A21-3A4-4A19-4A5-4A17-4A7-4A15-4A11-2A13-2A16-2AB7-B2A45-B19-B8(10-A19-A)11-5(A17-A12-)A17-A13-4(A15-A14-)A15-A9-B4-B15-2(B4-)2(A25-A4-)2A23-2A4-3A21-3A5-3A19-3A6-4A17-4A7-4A15-4A10-2A15-2A14-3AB7-B3A76-B17-B8(12-A17-A)4(12-2A15-2A)13-2(A15-A14-)3(2A13-2A14-)2A13-2A15-A13-A11-3B2-B13-B2-3B3(6-3A19-3A)7-2A19-2A8-4A15-4A9-3A15-3A12-2(A15-)4AB5-B4A108-2B13-2B12(14-2A13-2A)2(14-3A11-3A)15-4(2A11-2A16-)2A11-2A14-3BA11-A3B11-4A13-4A2(10-3A15-3A)11-2A15-2(2A13-)2A15-5AB3-B5A16-4AB5-B4A141-13B16(18-13A)2(18-8A3C2A18-13A)17-9A3C3A15-17A14-8AB8A15-6AB-B6A17-4AB3-B4A195-
