model
size = 30 31 24, scale = 0.05, origin = -y
material deform = 1, fade = true, lighting = smooth, roughness = 0.3, metalness = 0.6
  colors = A:#2A4A5B B:#F00 C:#C80000 D:#960000 E:#46647C F:#4B4B4B
voxels
333-9D6-8D7-11B3-C9B4-2(C13B2-C10B3-)2(C3B-)C3B10-3B3-2(C3B-)C3B3-7D3B3(3-2(C3B-)C3B3-10B)3-2(C3B-)C3B10-3B3-2(C3B-)C3B2-C10B3-2(C3B-)C3B2-C9BF3-2(C3B-)C3B2-C8B785-2A24-2A2-2A24-2A603-2A22-2A4(4-EA22-AE)4-2A22-2A63-2A24-2A2(2-EA24-AE)2-2A24-2A543-2A22-2A4-EA22-AE124-EA22-AE4-2A22-2A3-2A24-2A2-EA24-AE62-EA24-AE2-2A24-2A484-3(A22-A5-EA22-AE184-EA22-AE3-EA24-AE122-EA24-AE-3A24-6A24-3A423-)A22-A5-EA22-AE184-EA22-AE3-EA24-AE122-EA24-AE-3A24-6A24-3A393-A22-A6-A22-A5-2A22-2A4-EA22-AE124-EA22-AE4-2A22-2A3-2A24-2A2-EA24-AE62-EA24-AE2-2A24-2A-3A24-6A24-3A393-A22-A6-A22-A5-2(2A22-2A4-)4(EA22-AE4-)2A22-2A4-2A22-2A3-2(2A24-2A2-)2(EA24-AE2-)2A24-2A2-3(2A24-2A-3A24-6A24-3A393-A22-A6-A22-A5-7(2A22-2A4-)2A22-2A3-5(2A24-2A2-))4(2A24-2A-3A24-6A24-3A363-2(A22-A6-)A22-A5-7(2A22-2A4-)2A22-2A3-5(2A24-2A2-))2A24-2A-3A24-6A24-3A306-2A14-2A10-4A14-4A7-5A14-5A6-3A18-3A6-A22-A5-7(2A22-2A4-)2A22-2A3-5(2A24-2A2-)2A24-2A-4A22-8A22-4A2-2A22-2A6-4A14-4A10-2A14-2A194-2A10-2A14-2(4A10-)6A10-6A2(8-4A14-4A)7-3A18-3A5-4A18-4A3(4-3A21-2A)3-3(3A22-3A2-)3A22-3A-4A22-7A3(24-6A)24-7A22-10A18-14A14-8A2-6A14-6A6-2(6A10-)4A10-4A14-2A10-2A110-A4-A22-3A4-3A18-5A4-5A16-4A6-4A3(16-2A10-2A)12-4(4A14-4A8-)4A14-4A5-4A21-3(3A2-3A22-)3A-4A5(22-8A)22-4A4-2(4A14-4A8-)6A10-6A12-4A6-4A2(16-5A4-5A)18-3A4-3A22-A4-A26-2A26-6A22-10A20-4A2-4A4(20-3A4-3A)18-2A10-2A16-2A10-2A11-7D10-6D7-7B12-5B4-C8B12-6B3-C6B14-6B3-C3BACB14-3A3B3-C3BACB14-3D3B3(3-C3BACB14-6B)3-C3BACB14-3A3B3-C3BACB14-6B3-C3BACB14-5BF3-C3BACB14-4B12-2(2A10-2A16-)2A10-2A18-3A4-3A20-4A2-4A2(20-10A)22-6A26-2A27-6(4A26-)4A23-3A4-3A20-3A4-3A13-9DA4-A8D7-10B7-7B4-C11B7-8B3-C8B10-8B3-C3B-C3B10-2A3-3B3-C3B-C3B10-5D3B3(3-C3B-C3B10-8B)3-C3B-C3B10-2A3-3B3-C3B-C3B10-8B3-C3B-C3B10-7BF3-C3B-C3B10-6B14-2(3A4-3A20-)3A4-3A23-4(4A26-)4A266-4A26-4A16-9D-4A-8D7-11B3AC9B4-C13B2AC10B3-C11B4-C10B3-C3B-C3BACB4-3A5-3B3-C3B-C3BACB4-A7D3B3(3-C3B-C3BACB4-A10B)3-C3B-C3BACB4-3A5-3B3-C3B-C3BACB4-C10B3-C3B-C3BACB4-C9BF3-C3B-C3BACB4-C8B17-2(4A26-)4A466-9D6-8D7-11B3-C9B4-C13B2-C10B3-C13B2AC10B3-2(C3B-)C3B2A8-3B3-2(C3B-)C3B2A-7D3B3(3-2(C3B-)C3B2A-10B)3-2(C3B-)C3B2A8-3B3-2(C3B-)C3B2AC10B3-2(C3B-)C3B2AC9BF3-2(C3B-)C3B2AC8B244-
