model
size = 7 5 14, scale = 0.05, origin = -y
material deform = 1, fade = true, lighting = smooth, roughness = 0.3, metalness = 0.6
  colors = A:#4A225D
voxels
7-3(A6-)A8-3(4A3-)4A10-3(5A2-)5A3(12-3(2A5-)2A)11-3(3A4-)3A2(11-3(2A5-)2A)11-3(3A4-)3A10-3(3A4-)3A2(11-3(2A5-)2A)12-3(2A5-)2A6-A5-
