model
size = 7 5 14, scale = 0.05, origin = -y
material deform = 1, fade = true, lighting = smooth, roughness = 0.3, metalness = 0.6
  colors = A:#4A225D
voxels
13-3(A6-)A-3(5A2-)5A8-3(6A-)6A8-3(3(2A5-)2A12-)3(3A4-)3A12-3(2A5-)2A13-3(2A5-)2A2(12-3(3A4-)3A)12-3(2A5-)2A13-3(2A5-)2A12-4(2A5-)A-
