model
size = 31 29 20, scale = 0.05, origin = -y
material deform = 1, fade = true, lighting = smooth, roughness = 0.3, metalness = 0.6
  colors = A:#A100FF B:#E100FF C:#FF44D6 D:#FAFF7F E:#7F00FF F:#B200FF G:#FF7B1D H:#F3F3F3 I:#D21EFF J:#5900FF K:#172BFF L:#006AFF M:#FF8737 N:#FBFF2B O:#0FB P:#00FEFF Q:#00BFFF R:#FFA113 S:#FFCB2E T:#FFB23F U:#FFF V:#0B0B0B W:#005D72 X:#0A0A0A Y:#FDFDFD Z:#008780 Aa:#00AF7D Ab:#00CE97 Ac:#BCBCBC
voxels
36-U4I6-5F15-2(I-)I6-2(F-)F859-I6F23-2A10B18-3AB4-7B16-U2A8-5B15-3A10-4B28-2(3C29-)3C28-3C29-3G2(29-2G)2(29-2M)28-3M28-2R28-2(3R27-)2(4T26-)4S27-2S206-6F23-2I10F18-3A12B16-3A13B15-3AB5-8B14-3AB7-6B2(27-5C)27-4C28-4C27-4G28-2(4G27-)4M27-4M26-4M27-2(4R26-)5R2(25-5T)25-5S26-4S27-2N176-7F22-2I11F17-3A12B16-3A13B15-3AB4-9B14-3AB7-7B26-3(5C27-)4C27-5G2(27-4G)2(27-4M)26-5M26-R2MR26-2(5R25-)2(6T24-)6S25-5S26-3N175-7F22-2I11F17-3A12B16-3A13B15-3AB4-9B14-3AB7-6B3(27-5C)27-4C28-3G28-2(4G27-)2(4M27-)3M27-4R26-2(5R25-)5T25-5T2(26-4S)27-2N176-7F22-2I9F19-3A11B17-3AB4-7B16-3AB7-5B15-3AB9-4B28-3(3C29-)2C29-3G2(29-2G)3(29-2M)28-3(3R27-)2(3T27-)3S28-2S265-3AB27-U2A2(B27-3A)B736-5IUI7F17-IU5I7F17-7AH6B3(17-7A7B)17-EU5E2(7C17-7E)7C17-3EU3E7C17-7J7G18-6J6G19-6J6G20-3KUK5M116-3L3R24-4L4R2(23-4Q4T)23-PU2P4S24-3P3S201-13I13F5-13I13F7-11A6H5B9-11A2H9B9-2AU8A2H9B9-11A11B10-10E10C13-2(8E8C15-)U7E8C3(15-8J8G)16-3(7K7M17-)LU5L7R18-2(5LH6R19-)2(5QH6T19-)5PH6S19-5PH6S20-5O5N22-4O4N138-13I13F5-13I6F5B2F7-4(11A6H5B9-)11E11C11-9E9C13-9E9C14-8E8C3(15-8J8G)15-U7K8M16-2(7K7M17-)7L6H2(R17-6L7H)R2(17-6QH7T)2(17-6PH7S)18-5OH6N19-6O6N21-U3O4D107-13I13F5-13I6F5B2F7-4(11A6H5B9-)11E11C11-9E9C13-9E9C14-8E7HC3(15-8J8G)15-8K7HM16-2(7K6HM17-)7L6H2(R17-6L7H)R2(17-6Q7HT)17-6PH5N2S17-U5PH5N2S18-5OH6N19-6O6N21-4O4D107-U12I13F5-13I6F2B5F7-2(11A6H5B9-)P10A6H5B9-11A6H5B10-10E10C12-9E9C13-9E9C14-8E7HC3(15-8J8G)15-8K8M16-2(7K6HM17-)7L6H2(R17-6L7H)R2(17-6Q7HT)2(17-6PH5N2S)18-5OH6N19-6O6N21-4O4D111-9I9F13-9I6F2BF4(13-9A6D3B)3(13-9E9C)14-8E7DC15-8J8G15-U7J8G15-8J8G15-8K8M16-2(7K6DM17-)7L2(6DR17-6LH)6DR2(17-6QH6DT)2(17-6PH5N2S)18-5OH6N19-6O6N21-4O4D25-2O2(2D28-O)-D20-9I9F13-9I6F2BF4(13-9A6D3B)3(13-9E9C)14-8E7DC3(15-8J8G)15-8K8M16-2(7K6DM17-)7L6DR17-6LH6DR17-U5LH6DR2(17-6QH6DT)2(17-6PH5N2S)17-6OH7N16-8O6D2N15-8O8D15-4O2-2O2D2-4D15-4O3-OD3-4D15-2O7-D4-2D14-9I9F13-9I6F2BF4(13-9A6D3B)3(13-9E9C)14-8E7DC3(15-8J8G)16-7K7M2(17-7K6DM)17-7L2(6DR17-6LH)6DR2(17-6QH6DT)2(17-6PH5N2S)17-O6H7N16-OQOH4O6DSN15-O2QH4O5D2SD15-O2QO3-O4-D2SD15-OQ2O8-2DSD15-2O12-2D14-9I9F13-9I6F2BF13-9A9B13-U8A2(9B13-9A)9B14-4(8E8C15-)8J8G15-8J8G16-7J7G17-7K7M2(17-7K6DM)15-9L6D3R14-7LH6D2R15-7LH6D2R16-2(6QH6DT17-)6PH5N2S17-6PH5N2S18-6H6N19-OH4O5DN20-5O5D21-O8-D80-2(8I8F15-)7AP3(8B15-8A)8B15-8E8C16-7E7C17-5EUE7C17-P6E7C2(17-7J7G)18-4JPJ6G19-U5K6M18-6K2V6M17-KY5K5MYM15-7L4V7R14-4LU3L2RV5R15-8LV3RY3R16-7Q2V3TYT17-U6Q2T3X2T2(17-7PS4N2S)18-6P6N19-6O2N2X2N21-OU2O4D112-2(4I8-4F15-)2(4A8-4B15-)4A-3W3P-4B15-4AW6-P4B16-3E2-2W2A2-3C19-Z-3Z3J-P21-Aa-3Aa3L-P21-Ab-3Ab3Q-P21-O2-2O2P2-P22-O6-P24-3O3P50-2V14-2V15-2V10-2V47-2(2V12-)3V7-2V3-V3-2V19-4V3-V20-3U4-3U-3V16-UL2QU2-U2PQU19-U2VLU2-UQ2VU19-LUV2U2-2UVAcU20-3L4-3U142-2(4I8-4F15-)3AU8-4B15-4A8-4B16-3A8-3B17-U2A8-3B17-3E8-3C698-5I6-5F15-5I6-5F847-
