model
size = 31 30 19, scale = 0.05, origin = -y
material deform = 1, fade = true, lighting = smooth, roughness = 0.3, metalness = 0.6
  colors = A:#2B3340 B:#43FFFB C:#CA7A2C D:#00C5ED E:#08192D F:#FFF G:#3A3226 H:#E98B2A I:#000 J:#00D0FF K:#994639 L:#006284 M:#4A593D N:#00E5FF O:#00A4B7 P:#A8D8B9
voxels
43-7A23-12A18-4A4-7A16-3A8-5A15-3A10-4A28-2(3A29-)3A28-2(3A29-)6(2A29-)2A28-3A27-4A24-6A25-4A265-6A23-12A18-15A16-16A15-4A5-8A14-4A7-6A2(27-5A)2(27-4A28-4A)6(27-4A)26-5A25-6A23-7A24-6A26-3A234-7A22-13A17-15A16-16A15-4A4-9A14-4A7-7A26-3(5A27-)4A27-5A3(27-4A)27-2AHA3(27-4A)26-5A25-6A23-7A24-6A26-3A234-7A22-13A17-15A16-16A15-4A4-9A14-4A7-6A3(27-5A)27-4A28-3A28-3(4A27-)2AHA3(27-4A)26-5A25-2(6A24-)6A26-3A234-7A22-11A19-14A17-4A4-7A16-4A7-2AB2A15-4A9-AB2A28-3(ABA29-)AB29-A7(BA29-)BA28-ABA27-2(AB2A26-)AB2A27-2A228-3ABAB2ABAB3A3(17-3AB10A)2(17-3AB4ABAB3A)17-4BAB2ABA4B17-5AB2AB5A17-6B2A6B17-14A17-4B6A4B18-2AB2A2B2AB2A19-2AB2A2B2AB2A20-2B6A2B116-6A24-8A2(23-3A2B3A)23-8A24-6A232-26A5-26A7-3(22A9-)22A10-A18BA13-2(16A15-16B15-)16A15-16A16-14B17-14A2(17-6A2B6A)18-5(12A19-)12A20-4A2B4A22-3A2B3A169-26A5-26A7-4(22A9-)2A18B2A11-18A13-18B14-16A15-16B2(15-16A)15-16B16-8(14A17-)14A18-12A19-12A21-8A138-26A5-26A7-4(22A9-)2A18B2A11-18A13-18B14-16A15-16B2(15-16A)15-16B16-7(14A17-)2A2D10A17-14A18-12A19-12A21-8A138-26A5-4B18A4B7-3(22A9-)22A10-A18BA12-18A13-18B14-16A15-16B2(15-16A)15-16B16-7(14A17-)2A2D10A17-14A18-12A19-12A21-8A142-6(18A13-)18B13-18A13-2B9A7B14-16A15-16B2(15-16A)15-B13A2B16-7(14A17-)2A2D10A17-14A18-12A19-12A21-8A25-4A28-2AB28-AB30-B21-6(18A13-)18B13-18A13-2B14A2B14-16A15-B14AB2(15-16A)15-5B9A2B16-7(14A17-)2A2D6A2D2A2(17-14A)16-2(16A15-)B3A2(2-3AB)15-AB2A2-3A3-2ABA15-2A12-2A45-5(18A13-)17AB13-2B16A13-18A13-2B14A2B14-16A15-B14AB15-AP14A15-3A7C6A16-4BC8AB7(17-A4C9A)17-AC2DC5A2D2A17-A4C9A17-14A16-16A15-BAB10ABAB16-A2(BA3-)ABA16-A-2A3-A4-2A-A15-2A12-2A45-4(18A13-)16A2B13-18A14-B13AHA15-13A2HA15-B12AHAB15-13A2HA15-B13AHB15-AP14A16-2A7C5A17-4BC6A3B2(17-A4C9A)15-2A5C11A14-A5C10A15-A5C8AHA16-2(A4C9A17-)AC2DC5A2D2A17-A4C9A18-12A19-12A20-10A21-A8-A111-3(16A15-)6AB2AB6A15-7A2B6AB15-16A15-B5AB2AB3A2HA16-6A2B6A17-2B12A17-2AB3A2B6A17-5AB2FB5A17-3B3A2B3A3B18-2AB6AB2A19-3B6A3B18-14A16-B5AI2AI5AB14-2AB5A2I5AB2A14-2AB10AB2A15-B6A2G6AB16-5A4G5A17-5AB2AB5A17-2A2DKB2ABK2D2A17-2A2GK4BK2G2A18-AMGAB2ABAGMA19-5B2A5B21-8A143-2(4A27-)2(4A8-4A15-)4A8-2A2B15-4A8-2A2B16-3A8-2AB28-2AB333-2J24-3F-4J-3F18-FBNOF4-FONBF17-F2ILF4-FL2IF17-5E4-5E18-3E6-3E203-2(4A27-)2ABA27-2ABA28-2(ABA8-3A17-)2BA8-3A28-3A27-2AB2A26-2AB2A635-5A26-2AB2A223-A-B-A26-2AB2A635-5A26-A-B-A889-
