model
size = 8 7 13, scale = 0.05, origin = -y
material deform = 1, fade = true, lighting = smooth, roughness = 0.3, metalness = 0.6
  colors = A:#4A225D
voxels
28(5A3-)2(6A2-)4(5A3-)5A4-2(5A3-5A43-)6A2-6A42-2(7A-7A41-)7A-7A42-5A3-5A44-3A5-3A42-
