model
size = 31 32 17, scale = 0.05, origin = -y
material deform = 1, fade = true, lighting = smooth, roughness = 0.3, metalness = 0.6
  colors = A:#2D0000 B:#111 C:#A00 D:#400 E:#500 F:#700 G:#D00 H:#380000 I:#800 J:#B00 K:#060606 L:#070707 M:#F8F8F8 N:#888
voxels
8-15B16-2G3A2KIKI3A2G16-2G3AIKI2K3A2G2(16-2C3A2(IK)I3A2C)16-2C3AI3KI3A2C16-2C3A2(IK)I3A2C2(16-2I3A2(IK)I3A2I)16-2F3A2KIKI3A2F16-2F3AIKI2K3A2F16-FI3A2(IK)I3AIF16-2E3A2(IK)I3A2E17-E2A2BK4B2AE18-E2A3(BC)B2AE18-D2A3(BC)B2AD18-D2AB5CB2AD18-DAB7CBAD18-DB4(CE)CBD18-DB2CB3CB2CBD18-DB4(CE)CBD17-HDB9CBDH14-3AD2B7C2BD3A12-3AH3B5C3BH3A12-3AH4BABK4BH3A13-AHA3B2(IK)I3B2HA14-3A3B2KIKI3B3A14-3A3BIKI2K3B3A15-2A3B2(IK)I3B2A17-A3BI3KI3BA20-2A2(IK)I2A49-B15-B2(14-G15-G)2(14-J15EJ)14-C4E6L5EC14-C4EL4GL5EC14-I4ELGKMGL5EI14-I4ELGMKGL5EI14-5FL4GL6F14-5F6L6F14-17F3(14-17E)15-4(15D16-)15H11-4C-15H-4C6-4B18H3B2(6-25A)7-23A8-23A9-21A12-17A15-15A17-13A19-5AN5A22-7C18-B17-B2(12-G17-G)2(12-J17-J)2(12-C17-C)2(12-I17-I)3(12-2F15-2F)12-2E15-2E13-2(E15-E14-)3(D15-D14-)2(D15-)H13-H10-C5-H13-H5-C4-B4-2H13-2H4-B4-A25-A4-2A23-2A4-3A21-3A5-3A19-3A6-4A17-4A7-4A16-3A10-2A15-2A14-2A11-2A17-2A9-2A20-C7-C16-B19-B2(10-G19-G)2(10-J19-J)2(10-C19-C)2(10-I19-I)11-3(F17-F12-)E17-E2(12-E17-D)13-4(D15-D14-)H15-H8-C5-H15-H5-C2-B27-B2-A27-A2-2A25-2A3-2A23-2A4-3A21-3A4-4A19-4A5-4A17-4A7-4A15-4A11-2(A15-)A13-A17-2C9-2C14-B19-B2(10-G19-G)2(10-J19-J)2(10-C19-C)2(10-I19-I)3(10-2F17-2F)11-E17-E2(12-E17-D)13-4(D15-D14-)H15-H8-C5-H15-H5-C2-B27-B2-A27-A2-A26-2A2-2A25-2A2-3A23-3A3-3A21-3A4-4A19-4A5-4A17-4A8-3A15-3A2(13-A)17-C11-C14-B19-B2(10-G19-G)2(10-J19-J)2(10-C19-C)2(10-I19-I)3(10-F19-F)10-E19-E2(10-E19-D)11-3(D17-D12-)D17-D13-H15-H7-C6-H15-H6-CB28-2BA28-3A28-2A-A26-2A2-2A25-2A2-3A23-3A3-3A21-3A5-4A17-4A7-4A15-4A11-2A14-A16-C12-C13-B19-B2(10-G19-G)2(10-J19-J)2(10-C19-C)2(10-I19-I)3(10-F19-F)10-E19-E2(10-E19-D)2(10-2D17-2D)11-2(D17-D12-)2H15-2H6-C6-H15-H6-CB3(28-3B)28-2B-B26-2B2-2B25-2B3-2B23-2B4-3B21-3B6-2B19-2B10-BA15-2B14-2(C13-)15(B19-B10-)2(2B17-DB10-)2B17-DB11-B17-B12-BH15-HB6-C5-DH15-DH5-2C28-GCG3(28-3G)28-2G-G26-2G2-2G25-2G3-2G23-2G5-3G19-3G9-GC15-CG14-2(C13-)15(B19-B10-)3(2B17-DB10-)2B17-2B10-2BH15-H2B5-C5-DH15-DH5-2C28-GCG3(28-3G)28-2G-G26-2G2-2G25-2G3-2G23-2G5-3G19-3G9-GC15-CG14-2(C13-)B19-B2(10-G19-G)2(10-J19-J)2(10-C19-C)2(10-I19-I)3(10-F19-F)10-E19-E2(10-E19-D)3(10-2D17-2D)11-D17-D12-2H15-2H6-C5-DH15-DH5-CB3(28-3B)28-2B-B26-2B2-2B25-2B3-2B23-2B4-3B21-3B6-2B19-2B10-BA15-2B14-2(C13-)B19-B2(10-G19-G)2(10-J19-J)2(10-C19-C)2(10-I19-I)3(10-F19-F)10-E19-E2(10-E19-D)2(10-2D17-2D)11-2(D17-D12-)2H15-2H6-C6-H15-H6-CB28-2BA28-3A28-2A-A26-2A2-2A25-2A2-3A23-3A3-3A21-3A5-3A19-3A7-4A15-4A11-2(A15-)2(C13-)B19-B2(10-G19-G)2(10-J19-J)2(10-C19-C)2(10-I19-I)3(10-F19-F)10-E19-E2(10-E19-D)11-3(D17-D12-)D17-D13-H15-H8-C5-H15-H5-C2-B27-B2(2-A27-A)2-2A25-2A2-3A23-3A3-3A21-3A4-4A19-4A5-4A17-4A8-3A15-3A2(13-A)17-2C9-2C14-B19-B2(10-G19-G)2(10-J19-J)2(10-C19-C)2(10-I19-I)3(10-2F17-2F)11-3(E17-E12-)2D15-2D12-2D15-2D13-2(D15-D14-)H15-H8-C5-H15-H5-C2-B27-B2-A27-A2-2A25-2A3-2A23-2A4-3A21-3A4-4A19-4A5-4A17-4A7-4A15-4A11-2A13-2A16-ABC7-CBA45-B19-B2(10-G19-G)2(10-J19-J)2(10-C19-C)2(10-I19-I)11-3(F17-F12-)2(E17-E12-)E17-E13-4(D15-D14-)H15-H9-C4-H15-H4-C4-B25-B4-A25-A4-2A23-2A4-3A21-3A5-3A19-3A6-4A17-4A7-4A15-4A10-2A15-2A14-2ABC7-CB2A76-B17-B2(12-G17-G)2(12-J17-J)2(12-C17-C)2(12-I17-I)3(12-2F15-2F)12-2E15-2E13-2(E15-E14-)3(2D13-2D14-)2D13-2D15-H13-H11-3C2-H13-H2-3C6-3B19-H2B2(6-3A19-3A)7-2A19-2A8-4A15-4A9-3A15-3A12-2(A15-)2AB2C5-C2B2A108-2B13-2B2(14-2G13-2G)2(14-2J13-2J)2(14-2C13-2C)2(14-2I13-2I)3(14-2F13-2F)14-2E13-2E2(14-3E11-2ED)15-4(2D11-2D16-)2H11-2H14-B3H11-3HB11-B3H13-4H2(10-3A15-3A)11-2A15-2(2A13-)2A15-2A2B2C3-2C2B2A16-2A2BC5-C2B2A141-13B2(18-3GC3GIGC3G)2(18-3JCJGJIJC3J)2(18-5CGCI5C)2(18-3ICIG3IC3I)18-3F7B2(3F18-3F3(BC)B)3F18-3EB5CB3E18-2EB7CB2E18-EB4(CE)CBE18-DB2CB3CB2CBD18-DB4(CE)CBD18-DB9CBD18-D2B7C2BD18-H3B5C3BH18-H11BH17-HA11B2H15-3A11B3A14-3A4B3C4B3A15-2A3B2C-2C3B2A17-A3BC3-C3BA195-
