model
size = 31 32 17, scale = 0.05, origin = -y
material deform = 1, fade = true, lighting = smooth, roughness = 0.3, metalness = 0.6
  colors = A:#F8F8F8 B:#C0C
voxels
8-15A16-15B6(16-15A)16-4A7B4A16-2A3B5A3B2A16-A2B9A2BA16-2B11A2B16-B13AB17-2A3BA2B3ABA18-AB3A4(BA)18-A3B3A3(BA)18-2(AB)A7BA18-6(AB)A18-2(AB)A3B2(AB)A18-9A2(BA)18-13A17-2B11A2B14-3A2B9A2B3A12-4A3B5A3B4A12-6A7B6A13-17A15-15A16-15A18-11A20-11A21-9A49-A15-A14-B15-B14-A15-A10(14-17A)2(14-AB13ABA)15-4(B13AB16-)B13AB11-4A-B13AB-4A6-5B15A5B2(6-25A)7-23A8-23A9-21A12-17A15-15A17-13A19-11A22-7B18-A17-A12-B17-B7(12-A17-A)4(12-2A15-2A)13-5(A15-A14-)2(A15-)A13-A10-A5-A13-A5-A4-B4-2A13-2A4-B4-A25-A4-2A23-2A4-3A21-3A5-3A19-3A6-4A17-4A7-4A16-3A10-2A15-2A14-2A11-2A17-2A9-2A20-B7-B16-A19-A10-B19-B7(10-A19-A)11-5(A17-A12-)A17-A13-4(A15-A14-)A15-A8-A5-A15-A5-A2-B27-B2-A27-A2-2A25-2A3-2A23-2A4-3A21-3A4-4A19-4A5-4A17-4A7-4A15-4A11-2(A15-)A13-A17-2B9-2B14-A19-A10-B19-B7(10-A19-A)3(10-2A17-2A)11-2(A17-A12-)A17-A13-4(A15-A14-)A15-A8-A5-A15-A5-A2-B27-B2-A27-A2-A26-2A2-2A25-2A2-3A23-3A3-3A21-3A4-4A19-4A5-4A17-4A8-3A15-3A2(13-A)17-B11-B14-A19-A10-B19-B13(10-A19-A)11-3(A17-A12-)A17-A13-A15-A7-A6-A15-A6-AB28-ABA28-3A28-2A-A26-2A2-2A25-2A2-3A23-3A3-3A21-3A5-4A17-4A7-4A15-4A11-2A14-A16-B12-B13-A19-A10-B19-B13(10-A19-A)2(10-2A17-2A)11-2(A17-A12-)2A15-2A2(6-A)15-A6-AB28-ABA2(28-3A)28-2A-A26-2A2-2A25-2A3-2A23-2A4-3A21-3A6-2A19-2A10-2A15-2A14-2(B13-)A19-A10-B19-B13(10-A19-A)3(10-2A17-2A)11-A17-A12-2A15-2A6-A5-2A15-2A5-AB28-ABA3(28-3A)28-2A-A26-2A2-2A25-2A3-2A23-2A5-3A19-3A9-2A15-2A14-2(B13-)A19-A10-B19-B13(10-A19-A)4(10-2A17-2A)10-3A15-3A5-A5-2A15-2A5-AB28-ABA3(28-3A)28-2A-A26-2A2-2A25-2A3-2A23-2A5-3A19-3A9-2A15-2A14-2(B13-)A19-A10-B19-B13(10-A19-A)3(10-2A17-2A)11-A17-A12-2A15-2A6-A5-2A15-2A5-AB28-ABA2(28-3A)28-2A-A26-2A2-2A25-2A3-2A23-2A4-3A21-3A6-2A19-2A10-2A15-2A14-2(B13-)A19-A10-B19-B13(10-A19-A)2(10-2A17-2A)11-2(A17-A12-)2A15-2A2(6-A)15-A6-AB28-ABA28-3A28-2A-A26-2A2-2A25-2A2-3A23-3A3-3A21-3A5-3A19-3A7-4A15-4A11-2(A15-)2(B13-)A19-A10-B19-B13(10-A19-A)11-3(A17-A12-)A17-A13-A15-A8-A5-A15-A5-A2-B27-B2(2-A27-A)2-2A25-2A2-3A23-3A3-3A21-3A4-4A19-4A5-4A17-4A8-3A15-3A2(13-A)17-2B9-2B14-A19-A10-B19-B7(10-A19-A)3(10-2A17-2A)11-3(A17-A12-)2A15-2A12-2A15-2A13-2(A15-A14-)A15-A8-A5-A15-A5-A2-B27-B2-A27-A2-2A25-2A3-2A23-2A4-3A21-3A4-4A19-4A5-4A17-4A7-4A15-4A11-2A13-2A16-2AB7-B2A45-A19-A10-B19-B7(10-A19-A)11-5(A17-A12-)A17-A13-4(A15-A14-)A15-A9-A4-A15-2(A4-)B25-B4-A25-A4-2A23-2A4-3A21-3A5-3A19-3A6-4A17-4A7-4A15-4A10-2A15-2A14-3AB7-B3A76-A17-A12-B17-B7(12-A17-A)4(12-2A15-2A)13-2(A15-A14-)3(2A13-2A14-)2A13-2A15-A13-A11-3A2-A13-A2-3A6-2BA19-A2B2(6-3A19-3A)7-2A19-2A8-4A15-4A9-3A15-3A12-2(A15-)4AB5-B4A108-2A13-2A14-2B13-2B11(14-2A13-2A)2(14-3A11-3A)15-4(2A11-2A16-)2A11-2A14-2(4A11-)3BA13-A3B2(10-3A15-3A)11-2A15-2(2A13-)2A15-5AB3-B5A16-4AB5-B4A141-13A18-13B10(18-13A)18-AB3A2BA3B2A18-4(AB)3ABA18-3(AB)5ABA18-A7BA3BA18-6(AB)A18-2(AB)A3B2(AB)A18-2(AB)9A2(18-13A)17-15A15-17A14-8AB8A15-6AB-B6A17-4AB3-B4A195-
