model
size = 13 24 28, scale = 0.05, origin = -y
material deform = 1, fade = true, lighting = smooth, roughness = 0.3, metalness = 0.6
  colors = A:#6AB3CC B:#62593B C:#111 D:#EEE E:#6F6936 F:#FF0 G:#FF3
voxels
18-3B10-3C569-CFC10-CFC8-7B6-7B7-5B8-5C230-CFC10-CFC20-3(9B4-)9C7-FCF10-3A11-A64-A11-3(3A10-)3A9-3(5A8-)C3AC9-CFC10-CFC33-9B4-BE5BEB4-BEG3C2EB4-9C5-FC3DCF6-2A3D2A6-7A8-5(3A10-)3A9-2(5A8-)4(A3-A8-)C3-C57-11B2-2BE5B2EB2-2BEB3C3EB2-3CB7C3-2CB3D3C4-AC4A2CA4-ACA3-ACA5-4(2A3-2A6-)8(2A3-A7-)2C3-C56-16BE2BD5E4BC2B2C4EBCD2C2B7C-F2C2B3D2CF2-A2C5A2CA3-AC5-CA4-2(2A5-)3(2A3-2A6-)8(A5-A6-)C5-C55-17BDBD5E4B2CB2C4EBC4DB2D2B2DC-3CDB3D3C2-A2C5A2CA3-2A5-2A4-2(2A5-)2A3-2A10(6-A5-A)6-C5-C55-17B3D5E4B5C4EBC7D2B2DC-F2C5D2CF2-A2C5A2CA3-2(2A5-)12(A5-A6-)C5-C55-4B6-19B5C4EBC7DBC2DC-3C5D3C2-2AC5AC2A4-13(A5-A6-)C5-C55-2B10-17B5C4EBC7DBC2DC-F2C5D2CF2-11A4-13(A5-A6-)C5-C68-13BC2D5C3EB2C7DBC2DC-2AC5DC2A4-7A13(6-A5-A)6-C5-C68-13BCDB7C2BC-F2C5D2CF2-2AC5DC2A4-7A4(6-A5-A)5(6-7A)4(6-2A3-2A)6-CA3-AC7-A3-A56-13BC2D6C3BC-3C5D3C2-2AC5DC2A4-7A4(6-A5-A)2(6-AD3ADA)2(6-2A3-2A)6-AC3-CA4(6-7A)6-C5AC8-3A57-13BCDG6C3BC-F2C5D2CF2-2AC5DC2A4-A5CA6-AC2A2CA6-A5CA6-A5DA6-AD3ADA2(6-2A3-2A)7-AC-CA8-A-C-A8-AC-CA8-C3-C8-AC-CA8-A-C-A8-AC-CA8-C3-C69-13BC2D6C3BC-3C5D3C2-2AC5DC2A4-3(A5DA6-)AD3ADA6-2A3-2A7-A3-A8-C3-C173-13BCDG10C-F2C5D2CF2-2AC5DC2A4-2(A5DA6-)AD3ADA6-ADC-CDA7-A-C-A9-C-C174-13BC11B2C2D10C-A2C5D2CA3-AC5DCA5-A5DA6-AD3ADA6-2A3-2A7-C3-C199-13BC11BC-F9CF2-A2C5DC2A3-AC5D2A5-A5DA6-A5DA7-5A212-13BC11BC-11C2-2AC4D2C2A3-AC4D2CA4-2AC3DC2A6-5A9-3A213-13BC11BC-F9CF2-A2C4D3CA2-2AC4D2C2A3-2AC3DC2A6-5A225-13BC11BC-11C2-A2C4D3CA2-2AC4D2C2A4-AC3DCA7-5A225-13BC11BC-F9CF2-A2C4D3CA3-AC4D2CA5-AC3DCA7-5A225-13B6CBC4BC-3CD7C3-AC4D2CA4-AC4D2CA5-AC3DCA7-5A226-11B2-5CBCB3C3-F7CF4-A3C2D2CA5-A2C2DCA6-2AC2D2A8-3A227-11B2-5CBCB3C4-7C6-A5CA6-2A3C2A7-5A240-9B4-4CBCB2C6-F3CF8-A3CA9-3A255-7B6-3CB3C8-CFC10-3A265-
