model
size = 32 32 29, scale = 0.05, origin = -y
material deform = 1, fade = true, lighting = smooth, roughness = 0.3, metalness = 0.6
  colors = A:#FFF B:#FCFAF2 C:#EEE D:#A5DEE4 E:#DDD F:#222 G:#FEDFE1 H:#B28FCE I:#DC9FB4 J:#3C2F41 K:#6E75A4 L:#4E4F97 M:#8A6BBE N:#7B90D2 O:#888 P:#6A4C9C Q:#70649A R:#BBB S:#BDC0BA T:#91989F U:#111 V:#FFFFFB W:#005CAF X:#2E5C6E Y:#6699A1 Z:#261E47 Aa:#81C7D4 Ab:#577C8A Ac:#7DB9DE Ad:#AAA Ae:#69B0AC Af:#8B81C3 Ag:#D7C4BB Ah:#787D7B Ai:#3F2B36 Aj:#77969A Ak:#566C73 Al:#255359 Am:#78C2C4 An:#26453D Ao:#305A56 Ap:#574C57 Aq:#211E55 Ar:#373C38 As:#9B90C2 At:#113285 Au:#8F77B5 Av:#777 Aw:#444
voxels
271-A30-3A29-3A28-5A26-7A25-7A26-5A28-3A29-3A30-A701-B2ACAB25-2B4ACB23-8A2C20-B9AB2A2(19-11A2B)20-10AB22-9A24-7A26-5A27-5A28-3A353-A281-BAC2A2BA23-AC5A2B22-9ABAC19-2C10AC2A16-2B13AC16-12A4B17-11A3B18-11A2BA18-AB9AB2A18-2B11A21-9AB22-9A24-7A26-6A27-3A506-4A2B3A22-BC2(B3C)BC19-A3B8AB18-2AC9A2(CB)15-2BC12A2CA14-BCB15A13-2B17AC12-2B13A3B2C13-14A3BA14-18A14-17AB15-B15A16-B11A2BA19-10A2B20-11A22-9A24-8A25-5A441-B4CB2CBC21-6AB5AB17-14ACA15-C14A3B12-AC16ABACA9-21ACB9-B21AB10-22A10-21A11-20AB12-19AB12-18A2B12-3B15A2B13-2B16A15-16A17-13AB19-12A21-10A22-10A23-7A27-4A376-C7ABA2B18-CB12ABC16-14ABA14-16ABABC10-24A8-22A2B8-B21A2B8-B2(22A10-)20A2B10-20AB12-19AB12-2B17AB13-B16AB15-16A16-14AB18-13A20-11A2(22-10A)24-6A28-2A102-A207-B2CB11C2B13-2BACB8ABA3B2A12-3A2B12AB2AB10-C17ABA3B8-B18A3(BA)C6-25AC2(6-B22A3B)6-26A6-25A2(8-B20A3B)9-20A2B10-B19A2B10-B-17A3B12-17A2B13-15A2BA15-14A2B16-15A18-B12A20-11A23-8A25-5A27-5A116-A160-3AB11CBAC12-21A11-21A10-23A8-C24AB5-27A5-24A3B5-2B22A3B5-27A6-26A7-2(B23A8-)24A8-B20A2B10-20A2B11-19AB12-19AB13-17A16-15A18-13A20-12A21-10A23-7A26-5A28-3A213-AB16C13-AB19A10-B21AC8-2B22AB6-AB25A5-2C26A4(4-28A)4-27A2(6-2B24A)6-25A8-B23A8-B22A10-20ABA10-20A2(B12-19A)14-B16A16-B14A19-12A21-9A23-8A25-6A28-2A182-A2B12A3BA12-21A10-24A7-C24AB5-26A2B4-27AB3-B27AB3-C27AB3-29A4-B27A4-28A4-26AB6-25AB6-26A6-AB23A8-B22AB8-23A10-22A10-B20A12-B18A14-2B16A15-B14A18-14A19-11A22-8A25-6A27-4A29-DAD149-3BA10B6A11-C20AC9-24A7-C25A5-28A2(3-29A)3-B28A3-29A3-2B27A4-28A4-B25A2B5-25AB6-26A6-25AB7-2(23AB8-)23A10-22A10-AB20A11-A2B17A13-AB15A17-B13A18-D12AD20-9A23-D7A26-5A27-D3AD114-2A3B2A9B4A11-4A2B2A9B5AC8-ABC23A6-2B24AB4-27A2B3-29A2-D30AD-30A2-B28AC2-30AD-30A2-30A3-26A2B4-B25A2B5-26A6-25AB6-B25A7-24AB7-25A7-B23A8-A2B20AB9-CB21A9-A2B16ABAC11-18ABC14-16A16-D-11A2-D18-11A22-D8AD23-D6A27-4AD81-21A10-C23A7-C26A5-B25A2B3-B26A2B3-C29A-D31AD30AD-B28AC2-31AD30AD-31A2-29A3-28A5-2(25AB6-)26A7-24AB7-C24A7-25A7-C24A7-C23A7-25A8-23AC9-A2-17A2(CA)11-2D13AD2-2A14-11AD20-D9AD23-8A25-5AD81-21A10-C23A7-2B25A5-C25A2B3-B26A2B3-C29A-30AC-D30AD-30A2-C28AC-D31A-30AD-B2(29A3-)26A2B5-25AB6-26A6-B25A7-C24A7-B23AC7-B24A5-AC24A2(C5-26A)2C5-25A2CA4-3A2-AD12ADAC6A11-12A3-C3A13-D9A24-D6AD25-6A26-DA2-D50-22A9-C23A7-C25AC5-28A3-B27AB3-C29A-30AC-D31A-30AD-C28AC-32AD30AD-30A3-29A3-28A4-B27A5-25AB6-26A7-C24A6-25AC6-C24AC5-GIG21AAh2GA3-2IGIG20AQGHA3-P3G2I19AGI2HK2-GAGNG18AKGIHIGQ2-M7AD11A2DAIHIG2HM2-L4A3-D12A2-C2A2HA3-3A6-10A7-3A3-A10-7AD8-3A13-D5A2D10-A14-DA-2D50-22A9-24AB6-C25AC4-D28A3-B27A2B2-B29A2-C28AC-31A2D30AD-C28AC-30AC-D31A-30AD-2B28A3-B27A4-28A5-B25A6-26A7-23AC7-C25A6-C24AGK4-GIG21AAh2G2K2-2IGIG20AQGH2I2-P3G2I19AGI2HK2-GAGNG18AKGIHIGQ2-M7AD11A2DAIHIG2HM2-L5A2-D11AD2-2AN2H2A-5A5-10AD5-5A-5A5-D-7A8-4A-2A10-D5AD10-3A14-2AD13-2A36-21AC9-25A6-C25AC4-D26A2B3-2(B29A2-)C28AC-30AC-D30AD-C60AC-D31A-30AD-2B28A3-B27A4-28A5-26A6-26A7-C22AB7-25A6-AI24AGA3-AGIG21AAh2GKA2-2IGIG20AQGH2I2-P3G2I19AGI2HK-AG2ANGHM16AKGIHIGQAuPMHA3H2MD11ADAAkIHIG2HMKML4HMK-D11AD2-PGN2HMP2LH2NHM4-D10A4-Q3M2LAuW2PHK-A3-2D7A4-A2-K2L2WK3A9-6A10-4L14-2AD11-4A36-B20AC9-2B23A6-C25AC4-D28A3-29AB2-B28AB2-C29A-30AC-D31A-30AD-C28AC-32AD31A-30A3-28A4-B27A5-26A6-26A7-24A8-C22AC7-I23AC6-GIG21AC6-2I3-20AQ-H4-P5-19AGI2HK7-HM16AKGIHAGQ2AM4-H2MD11ADAAkIHIG2AM2AL3-HMK-13A2-PGN2HMPAL-2NHM4-D10A4-Q3M2L-W2PHK6-8AD6-K2L2W-LPK9-D5A10-4L-A7-A4-A13-2K2P26-2(A4-)21AC9-25A6-C25AC4-29A3-D28AB2-29AB2-B29A2-C28AC-32AD31A-C28AC-30AC-D30AD-31A2-28A4-28A5-26A6-26A7-C23A2(8-23AC)9-22A11-20AQ12-18AC13-M16AKG13-2AD11ADAAkIH11-H2A-D11A3-2AN5-L4-M4-D9AD4-Q2M4-W2PHK6-D7AD6-K2L3-LPK9-D5AD9-L17-A13-2K2P36-5C16AC9-B24A6-C25AC4-C28A3-D29A2(2-30A)2-C29A-30AC-D30AD-C29AD30AC-D31A-31A2-28A4-28A5-27A5-26A7-2(24A8-)24A9-22A11-21A12-19A14-16AKG16-12A-2AH18-9A23-8A25-6A27-4A83-4C16AC9-25A7-C25A4-2C26AB3-TE28A2-DE28A2-AR27AC2-TSV27A-DTAB25AVC-AAj3A2CB21ABED-TACAg2RSEB14AC2ECVAC2ACS2RSDAaAdSB4AESC4ABE4RS2C-ACBEADAe2YAeE4ASAdC4AS2YAeDCSAdC2DASADAl2FJAbAmC2AE2OEV2AEAbXJZXAaAAgAhA2-BCAbU2JFAnYE2AAdJFOC2ATAoFUAiFXDA4-ADXFJ2FZAbE2AEAdTSB2AAjJUJ2FZAcA4-VEL2FApT2KE8AVKJAiZApAvXNA4-EANAqArRAEAsE8AVAfLFAwEBDAcA5-2CNLEVRAgV9AAgLAtL4AE6-AEAcHREC4A2K4AVEMNCAVA8-A2E2B4AQMAfQ4A2E3RA10-CB6AW2NW3A2B3EA12-7ACNAaC7ADA13-2AC4A2D7A17-14A20-2AB5ACE24-C4AB27-E2AC28-C2AE29-2A84-4C17A10-23A8-26A6-C26A4-28A4-29A4-28A2-A2-26AD2-2A-26A3-4A2CB21A5-A3-3AB14AC2EC3A2-A3-ADAa2AB4AEOE4ABE4ADA3-A2-ADAe2YAeE4ACFC4ASYAaAcN2ADA4-ADAl2FJAbAmC2A-OFO3AEAbXJZXAaA-D4-AAbUJUFAnYE2A2(FJ)F2ATAoFUAiFXDA5-AX2(FU)ZAbE2AEJTJE2AAjJUJ2FZAcA5-AL2FUAEKE9AKUAiZJUXNA6-NAqArD2AAsE9AAfLFUZBDAc7-ANLE2AEV9AEAAtL4A8-4AEC4A2K5AEANC2A13-5AQMAfQ9A15-4AW2NW4A21-3ACNAaC3A23-3A2D3A23-10A25-4A28-4A29-2A148-4C16A11-B22A9-23AB7-B23A2BA5-C25AC4-D28A4-28A5-27A3-A-25AD4-3A2CB21A5-D3-3AB14AC2EC9-A2-2AB4AEOE4ABE4A14-E4ACFC4ASE3-A15-C2A-OFO3AE21-E2A2(FJ)F2AE21-E2AEJFJE2AE21-E2(9AE22-)9A23-3A2K4A24-AQMAfQA28-2N30-NAa28-A4-A27-A2-A29-2A30-2A181-3C16A11-B20AB10-23AB8-23A2B6-B26A4-D28A3-29A5-27A5-25A6-2A3-20A14-14A19-4AEOE4A21-4ACFC4A21-E2A-OFO3AE21-E2A2(FJ)F2AE21-E2AEJFJE2AE22-9A23-9A24-7A26-A2K2A220-2A181-16C2A13-B20A10-2B20AC9-2B22A7-2B24A6-AB25A6-B26A5-26A7-24A11-19A15-14A19-4AEOE4A21-4ACFC4A22-2A-OFO3A23-2A2(FJ)F2A23-2AEJFJE2A23-9A24-7A26-5A284-2A150-15C2A14-2B17A12-B21A9-2B22A9-2B21A9-24A9-23A9-22A13-16A18-2A8C2A23-E3OE25-3AEOE3A21-T-4CF4C22-2EA-OFO-A22-T2-A2(FJ)FA23-2EAEJFJEA2(25-7A)468-14CA16-B12A4B14-2B18A12-20AB11-B18A2B11-22A11-21A12-3A11C5A15-14A120-F5-T22-A-OFO-A2E23-A2(FJ)FA2-T22-AEJFJEA2E23-7A26-5A501-AB10C3B18-3B6A3BABA16-2A2B11ABA16-16A16-A3C9AC2A18-AC6A3C248-2(FJ)F27-EJFJE28-3A571-B4CB24-B10A20-13A873-
