model
size = 13 24 28, scale = 0.05, origin = -y
material deform = 1, fade = true, lighting = smooth, roughness = 0.3, metalness = 0.6
  colors = A:#D00 B:#62593B C:#111 D:#EEE E:#6F6936 F:#FF0 G:#6AB3CC H:#FF3
voxels
18-3B10-3C569-CFC10-CFC8-7B6-7B7-5B8-5C230-CFC10-CFC20-3(9B4-)9C7-FCF10-3A11-A64-A11-3(3A10-)3A9-3(5A8-)C3AC9-CFC10-CFC33-9B4-BE5BEB4-BEH3C2EB4-CA4C2AC5-FC3DCF2(6-7A)8-5(3A10-)3A9-2(5A8-)4(A3-A8-)C3-C57-11B2-2BE5B2EB2-2BEB3C3EB2-CACB2(2CA)C3-CAB3D2AC4-9A4-ACA3-ACA5-4(2A3-2A6-)8(2A3-A7-)2C3-C56-16BE2BD5E4BC2B2C4EBCDAC2BC2(A2C)-FAC2BDADCAF2-AC7ACA3-AC5-2A4-AG5-GA5-3(2A3-2A6-)8(A5-A6-)C5-C55-17BDBD5E4B2CB2C4EBCA3DBAD2BDAC-CACDBDADCAC2-AC7ACA3-2A5-2A4-2A5-GA5-2A3-2A10(6-A5-A)6-C5-C55-17B3D5E4B5C4EBCA4DAD2BDAC-FAC2D2ADCAF2-AC7ACA3-2(2A5-)12(A5-A6-)C5-C55-4B6-19B5C4EBCA4DADBCDAC-3C2DA2D3C2-11A4-13(A5-A6-)C5-C55-2B10-17B5C4EBCA4DADBCDAC-FAC3DADCAF2-11A4-13(A5-A6-)C5-C68-13BC2D5C3EB2CA4DADBCDAC-2AC2D2ADC2A4-7A13(6-A5-A)6-C5-C68-13BCDB7C2BC-F2C2DA2D2CF2-2AC2D2ADC2A4-7A4(6-A5-A)5(6-7A)4(6-2A3-2A)6-CA3-AC7-A3-A56-13BC2D6C3BC-3C5D3C2-2AC2D2ADC2A4-7A4(6-A5-A)2(6-AD5A)2(6-2A3-2A)6-AC3-2A4(6-AG5A)6-C5AC8-3A57-13BCDH6C3BC-F2C5D2CF2-2AC2D2ADC2A4-A4C2A6-AC2GC2A6-A4C2A6-A2DAD2A6-AD5A2(6-2A3-2A)7-AC-CA8-A-C-A8-AC-CA8-C3-C8-AC-CA8-A-C-A8-AC-CA8-C3-C69-13BC2D6C3BC-3C5D3C2-2AC2D2ADC2A4-3(A4D2A6-)AD5A6-2A3-2A7-A3-A8-C3-C173-13BCDH10C-F2C5D2CF2-2AC2D2ADC2A4-2(A4D2A6-)AD5A6-ADC-C2A7-A-C-A9-C-C174-13BC11B2C2D10C-A2C2DA2D2CA3-AC2D2ADCA5-A4D2A6-AD5A6-2A3-2A7-C3-C199-13BC11BC-F9CF2-A2C2DA2DCGA3-AC2D2ADGA5-A4D2A6-A4D2A7-5A212-13BC11BC-11C2-AGC2DAD2CGA3-AC3DA2CA4-2ACD5A6-A3GA9-3A213-13BC11BC-F9CF2-A2C2DAD3CA2-AGC2DAD2CGA3-2ACD5A6-5A225-13BC11BC-11C2-A2C2DAD3CA2-2AC2D2A2C2A4-ACDAD2A7-5A225-13BC11BC-F9CF2-A2C2DAD3CA3-AC3DA2CA5-ACDAD2A7-5A225-13B6CBC4BC-3CD7C3-AC3DA2CA4-AC3DA2CA5-ACDAD2A7-5A226-11B2-5CBCB3C3-F7CF4-A3CDA2CA5-A2C2D2A6-2ACD3A8-3A227-11B2-5CBCB3C4-7C6-A4C2A6-2A3C2A7-5A240-9B4-4CBCB2C6-F3CF8-A3CA9-3A255-7B6-3CB3C8-CFC10-3A265-
