model
size = 22 32 27, scale = 0.05, origin = -y
material deform = 1, fade = true, lighting = smooth, roughness = 0.3, metalness = 0.6
  colors = A:#444 B:#111 C:#555
voxels
230-2B19-A2BA3(18-A2BC)17-2A2BAC16-2A2B2A16-6B17-4B17-6B17-A2B2A370-2B19-A2BC2(18-A2BA)18-C2BA18-C3A17-A-2A-A16-A-2A-A15-2A-5A14-C5ACA14-C-A2-A-A14-A-A2-A-A13-2B2A2-2A2B16-2A16-2B2A2-2A2B12-4A2-A-2A13-3A2B3A15-2A2B2A17-A2BA195-2(2B20-)2B19-2(A2BA18-)A2-A17-2(A-2A-A16-)C-2A-A15-C2A2-2AC14-2CA2-2AC14-C-A2-A-A14-A-A2-A-2A12-A-2A3-A-A12-A-A4-A-C12-A-A4-A-2A10-4A4-4A10-B2A6-2AB31-2B2(2A2-)2A2B9-A3(-2A)-A10-11AC11-2A-4A-AC12-3A-2A-3A14-2A2B2A16-2A2B2A149-A2BA18-A2-A17-6A2(16-A-2A-A)15-8A15-2A2-A-A14-3A2-2AC13-AC2A2-3AC12-C-A4-A-C12-A-A4-A-A12-A-A4-A-2A10-2C2A4-2A-A10-C-A6-A-C10-A-A6-A-C9-4A6-2A2(-A8-A)-A8-B2A8-2AB29-B2A10-2AB7-4(A-A8-)2A-2A4-2A-2A9-A-3A2-3A-A10-12A11-2A-4A-2A13-3A2B3A15-2A2B2A18-2B84-2A2B2A16-5AC2(A14-A-A2-A-)A14-C-A2-A-C13-A-A4-A-A12-C2A4-A-C12-2A6-AC11-3(A-A6-A-A10-)3A6-3A9-2(C-A8-A-A8-)C-A8-A-C7-A-A10-A-C6-A-A10-A-A6-B2A10-2AB28-BA12-AB2(6-A-A10-A-A)7-4(A-A8-)A2-A6-A2-A9-C-2A4-2A-A11-C2-4A2-2A11-2A6-2A13-3A2-3A15-2A2B2A81-2A4-2A13-A-A4-A-C12-A-A4-A-A12-C2A4-3A11-2(C-A6-A-A10-)C-A6-A-A9-3(A-A8-)A-C2(8-A-A)8-2A10-2A7-A2(-A10-A-A6-C)-A10-A-C5-A-A12-A-C4-A-A12-A-A4-B2A12-2AB4-B16-B4-B2A12-2AB5-2(2A12-2A6-)A-A10-A-C6-A-A10-A-A7-C4(-A8-A)C-2A4-2A2-A9-C2-A4BA2-A11-A3-AB3-A13-3AB-3A18-B81-3A6-2AC10-A-A6-A-C10-2A8-2A9-3(C-A8-A-A8-)CA10-2A7-A-A10-A-C6-A-A10-A-A6-2A12-2A5-A-A12-A-C4-C-A12-A-A4-C-A12-A-C4-C-A12-3A4-2A14-2A3(4-BA14-AB)4-2A14-2A2(4-A-A12-A-A)5-2A12-2A6-C2(-A10-A-A6-A)2-A8-A2-A7-A-2A6-2A-A9-C2-AB2-BA2-A10-2A3-2B3-2A12-3A2BA2C78-2A8-AC9-2(A-A8-)2A10-2A8-2A10-2A7-A2(-A10-A-A6-C)A12-2A6-2A12-2A5-2(A-A12-A-A4-)2A2(14-2A4-CA)14-AC4-CA15-A4-A16-A4-B16-AB2-BA16-AB2-B-A14-A-B3-2(2A14-2A4-)2A14-AC4-A-A12-A-A5-2A12-2A6-CA12-2A2(6-A-A10-A-A)7-C-2A6-2A-A9-A2-2A3BA2-A11-4A2B2A2C97-3A10-3A6-A-A11-2A6-2A12-AC6-2A12-2A5-A-A12-A-C4-C-A12-A-A2(4-2A14-2A)4-2A14-AC4-2A14-2A3-2A16-2A2-CA2(16-2A2-2A)16-2A3(2-BA16-AB)2-2A16-2A3-2A14-2A4-CA2(14-2A4-2A)14-2A2(4-A-A12-A-A)5-A-A10-A-A6-A2-A8-A2-A7-C2-3A3-2A2-A9-11AC15-2B100-3A12-3A4-A-A12-A-C4-2A14-2A4-2A14-AC4-2A14-2A4-CA14-2A3-3(2A16-2A2-)2A16-AC3(2-2A16-2A)3(2-BA16-AB)2(2-2A16-2A)2-CA16-2A3-2A14-2A4-CA14-AC2(4-2A14-2A)4-A-A12-A-A5-A-A10-A-A7-A-2A6-2A-A9-2AC9A13-2A2B2A98-2(2A14-2A4-)2A14-AC3-2A16-AC3(2-2A16-2A)2-CA4(16-2A2-2A)16-AC2-2A16-2A3(2-BA16-AB)4(2-2A16-2A)2-C-A15-AC3-2(2A14-2A4-)C-A12-A-A4-A-A12-A-A5-A-3A6-3A-A7-C2A-6A-C2A11-C2A2BCAC118-6(2A16-2A2-)CA16-AC2-2A2(16-2A2-CA)17-A2-A18-C2-A18-A2-B2(18-A2BA)18-AB-2A17-A3(2-2A16-2A)2-CA16-AC2-2A16-AC2-A-A15-2A3-CA14-2A4-A-A12-A-A5-A-2A8-2A-A7-2A-8A-2A10-AC2A2B2A2C117-3(2A16-2A2-)CA16-2A2-2A16-2A2-CA16-2A2-A18-C2-C18-A2-C18-2ACA18-4A18-AC2A18-2AB2(A18-A2B)A18-AB2A18-2A-A18-A2(2-2A16-AC)2-CA16-AC2-CA16-2A2-2A16-AC2-C-A14-A-A3-A-A12-A-A5-A-2A8-2A-A7-2A-8A-2A10-2C2A2B2(CA)139-2A16-2A2-2A16-AC2-CA17-A2-A18-A2-C18-AC2A2(18-2ACA)18-4A2(18-AC2A)18-2AB2(A18-A2B)A18-AB2A18-4A18-2A-A18-2(C2-CA16-A)C2(2-2A16-2A)2-C-A14-A-C3-CA14-AC4-A-2A10-2A-A5-15AC9-AC2A2BA2CA139-A18-A2-2A16-2A2-C18-A-2A18-4A18-AC2A2(18-2ACA)3(18-4A)18-2AB2(A18-A2B)A18-AB2A18-4A18-2A-A18-C2-C18-C2(2-2A16-2A)2-2A16-AC2-C-A14-A-C3-CA14-AC4-A-2A10-2A-C5-7A2-7A9-4A2BA2CA161-A18-A-CA18-2ACA18-4A18-AC2A2(18-2ACA)18-A2CA18-2ACA18-4A18-2AB2(A18-A2B)A18-AB2A18-4A18-2A-A18-2A-CA2(16-2A2-2A)16-AC2-2A16-AC2-A-A14-A-A3-2A14-2A5-C2A10-2A-C5-AC5A2-7A9-4A2BA2CA161-A18-A2-A18-2A-A18-A2-A18-A-2A18-2ACA2(18-4A)18-2ACA18-AC2A18-2AB2(A18-A2B)A18-AB2A18-4A18-2A-A18-2A-CA2(16-2A2-2A)16-AC2-2A16-2A2-A-A14-A-A3-A-A12-A-A5-C-A10-A-C6-AC14A9-4A2B2ACA161-2(A18-A2-)C18-A-CA4(18-4A)2(18-AC2A)18-2AB2(A18-A2B)A18-AB2A18-4A18-2A-2A16-2(A-)CA16-2A2-CA16-AC2-2A16-AC2-A-A14-A-A3-2A14-AC4-A-A12-A-C5-A-A10-A-A7-C13A10-2C2A2B2ACA183-A18-A2-C5(18-4A)2(18-AC2A)18-2AB2(A18-A2B)A18-AB2A18-3A-A16-2(A-)2A16-2A2-CA16-2A2-2A16-AC2-A-A14-A-A3-2A14-AC4-A-A12-A-C4-A2-A10-A2-A5-A2-A8-A2-A7-CA-8A-2A10-AC2A2B2A2C183-2A16-2A2-CA17-A-2A2(18-4A)18-2ACA18-4A18-2A-2A17-AC-2A16-2A3(2-BA16-AB)4(2-2A16-2A)2-A-A14-A-A3-CA14-2A4-C-A12-A-C4-A-A11-A2-A5-A-2A8-A2-A6-A3-2A4-2A3-C7-2AC2-4A2-2CA11-C2A2B2AC184-5(2A16-2A2-)2A16-AC3(2-2A16-2A)3(2-BA16-AB)2-A-A15-2A2(2-A-A14-A-A)3-2A14-AC4-2A14-2A4-A-A12-A-C4-A-A12-A-A5-A-A10-A-A6-A2-2A6-2A2-C7-A3-6A3-A9-2ACA4-A2CA14-A2BA186-A17-2(2A2-2A16-)2A2(2-A-A14-A-A)2-C3(-A14-A-A2-A)-A14-A-A2(2-B-A14-A-B)3-BA14-A-B3-3(2A14-2A4-)A-A12-A-A4-A-A12-A-A5-2A12-2A6-A-A10-A-A6-A2-A8-A2-A7-A2-3A3-2A2-2A8-A4-3A3-A11-4A2B2ACA228-2(2A14-2A4-)2A14-AC5(4-2A14-2A)4-BA14-A2(B4-B-A12-A-)B2(4-A-A12-A-A)5-2(2A12-2A6-)A-A10-A-A6-A-A10-A-A7-2(A-A8-)A2-2A4-2A2-A9-A3-4A3-A11-A8-A13-3A2B3A229-C2A12-3A4-C2(-A12-A-A4-A)2(-A12-A-A4-C)-A12-A-C4-A-A12-A-A5-2A12-2A6-BA12-A2(B6-B-A10-A-)B2(6-A-A10-A-A)6-A-2A8-2A-A6-AC2A8-4A7-2(A-A8-)A-2A6-2A-A9-A-3A2-3A-A10-2A2-4A2-2A10-2A8-2A12-3A2B3A252-2A12-2A6-2CA10-A-A6-A-A10-A2(-A6-C-2A8-2A)-C6-A-2A8-2A-A2(6-4A8-4A)6-2B2A8-2A2B7-2(B-A8-A-B8-)2(A-2A6-2A-A8-)2A-A6-A-2A9-C-2A4-2A-C10-C-2A4-2A-A10-2A-6A-2A11-2(2A2-)CA13-3A2-3A14-3A2B3A18-B279-4A4-3ACA8-2C3A4-5A8-2C-2A4-2A-2A8-2C-2A4-2A-CA8-2C-2A4-2A-2A9-A-2A4-2A-C10-A-3A2-3A-A2(10-2B3A2-3A2B)10-2B8A2B10-2A-6A-2A10-12A11-2(10A12-)9AC13-3A2B3A15-2A2BAC18-2B324-4A2B4A12-2C2A2B4A12-4C2B2ACA12-C3A2B2A2C12-4C2B3CA12-3CA2B2ACA12-2ACA2B4A13-3(8B14-)3A2BACA15-2A2BAC16-2A2BAC17-A2BA19-2B164-
