model
size = 5 34 36, scale = 0.05, origin = -y
material deform = 1, fade = true, lighting = smooth, roughness = 0.3, metalness = 0.6
  colors = A:#700 B:#500 C:#9CF
voxels
78-A164-A163-2A3-2A28-2A109-B3-2B18-2A3-2A23-2A3-2A113-2B3-2A13-2A3-2A4-A18-2A3-2A24-A88-2B3-2(2A13-2(2A3-))2A18-2A4-A63-2B3-2B18-2B4(3-2A)2-3A3-2A8-3(2A3-)2A8-2(2A3-)2A68-2(2B3-)2B18-3(2A3-)2A2-2A3-3A2(3-2A)2(2-3A)3-2A8-2A3-2A34-A39-B3(3-2B)13-2A2-2A3-2(3A2-)2A3-3A3-2A2-3A2-2A3-3A8-2(2A3-)2A23-2A3-2A4-A43-5(2B3-)2A2-3A2-2A3-3A2-A4-2A3-2(3A2-)A4-3A3-2A2-3A2(3-2A)13-3(2A3-)2A24-B4-B23-3(2B2-A)2B3-2A2-2(3A2-A4-)A4-3A2-2(A4-)2(3A2-)2A4-2A8-4(2A3-)2A29-B3(3-2B)13-2B2-A2B2-2(2A3-)2(3A2-)B2-B-B2A2-4(B2AB-)3AB-3A2-2A3-A5-2A3-2A2(2-3A)2(3-2A)43-5(2B3-)2B2-3A2-2(A4-)3A2-B2AB-B2(2A3B)2AB-B2A3B3(2AB-B)2-B-2(3A2-)ACA2-2A3-3A3-2A53-2B3-3(2B2-A)2B2(2-3A)2-A2-B-3AB-B6(2A3B)A-3B2AB-B2AB-3A2-A4-2A3-3A3-2A24-A3-2A4-A28-2(2B2-A)4-AB3-2(3A2-)3A2B3A6(3B2A)2B3A2BA2CB-B2CB-3AB-A4-3A8(3-2A)42-2(A2B2-)2A2(-B)2-3B2A3BA-11B15-16BA2C2BA2CB-3AB-A2-B-A4-2A3-3A2-3A3-2A63-2B2-3B2-B2(2A3B)2A6B30-6BA2C2BA2CB-3AB-B2-B-3A2-3A2(3-2A)73-2B2-3B-15B30-11BA2CB-B2CB-2(3A2-)3A3(3-2A)77-3B-10B35-6BA2C3B2CB-3AB-A4-2A3-3A2-3A5(3-2A)4-A58-2B41-6BA2C3B2CB-3AB-A4-2A3-3A2-3A5(3-2A)4-A96-6BA2C2BA2CB-B2CB-2(3A2-)3A3(3-2A)121-6BA2C2BA2CB-B2CB-A2-B-3A2-3A2(3-2A)116-16B3A2B3AB-B2AB-A2-B-A4-2A3-3A2-3A3-2A91-21B4(3A2B)3AB-5(3A2-)3A3(3-2A)82-5(3A2B)2A-2B2(3AB-)3A2-A4-2A3-3A3-2A24-A3-2A4-A72-3A2BA2-2(2B3AB-3A)B-3AB-A2-B-3(3A2-)2A3-3A3-2A102-3A2-A2-5(B-3A)2-2A3-A5-2A3-2A2(2-3A)2(3-2A)97-2(3A2-2(A4-))2(3A2-)2A4-2A8-4(2A3-)2A92-3A2-A4-2A3-2(3A2-)A4-3A3-2A2-3A2(3-2A)13-3(2A3-)2A87-3A2-2A3-3A3-2A2-3A2-2A3-3A8-2(2A3-)2A23-2A3-2A4-A83-2A2-2A3-3A2(3-2A)2(2-3A)3-2A8-2A3-2A34-A83-2A2-3A3-2A8-3(2A3-)2A8-2(2A3-)2A113-2(2(2A3-)2A13-)2A3-2A113-2A3-2A4-A18-2A3-2A24-A108-2A3-2A23-2A3-2A133-2A3-2A28-2A66-
