model
size = 20 10 32, scale = 0.05, origin = -y
material deform = 1, fade = true, lighting = smooth, roughness = 0.3, metalness = 0.6
  colors = A:#4A225D B:#000
voxels
13-2(2AB)A8(12-2(2AB)2A)12-2(2AB)2202A170(9-11A)10(9-2AB8A)20(12-8A)
