model
size = 32 19 32, scale = 0.05, origin = -y
material deform = 1, fade = true, lighting = smooth, roughness = 0.3, metalness = 0.6
  colors = A:#000 B:#FFF C:#E1FF00 D:#00B7B6 E:#E5E300 F:#00FF6A G:#F28F00 H:#00C8A4 I:#00DA91 J:#EAC700 K:#1CFF5D L:#00A6C8 M:#C1FF0F N:#0095DA O:#F67300 P:#2462EF Q:#8AFF29 R:#00EB7F S:#410057 T:#FB5700 U:#55005C V:#690061 W:#7D0066 X:#90006B Y:#A5FF1C Z:#0083ED Aa:#0072FF Ab:#37FF50 Ac:#6EFF36 Ad:#B80075 Ae:#EEAB00 Af:#53FF43 Ag:#4354E1 Ah:#6346D3 Ai:#A40070 Aj:#CC007A Ak:#FF3B00 Al:#8238C5
voxels
356-3B5-S5-B2-B-B2-B10-B5-SUV4-B2-B-B2-B10-B4-SUVWX3-4B-2B-B10-B3-SUVWXAiAd2(2-B)4-B10-B3-UVWXAiAdAj2(2-B)3-3B8-3B3-WX-AdAj4-2B5-B440-H540-R7-P208-C478-C70-Aj581-B117-M419-K53-B38-X100-Ab318-R84-B20-B78-U59-G368-Z54-Ab100-B53-E4-Ad38-R481-L-B10-O7-V66-Aj63-Ac310-J33-C6-K3-H23-Q102-F22-C516-V23-B30-G22-Z10-J30-B9-Ab392-P22-F35-D18-E96-E18-B9-B17-H34-D203-J165-Ac17-Ah19-I7-P17-S4-F4-B14-G10-K2-B21-C27-G37-W24-T7-Y314-E63-E12-D78-O11-X5-B2-B20-W6-I8-Z44-C6-K34-F177-J97-C68-Af15-Al13-Q39-B55-S6-R21-E38-Ad8-D29-I18-E17-D234-J96-E18-Ag15-Y28-B35-Q12-B20-V8-B19-S16-B62-D2-L20-K343-Y16-Ah17-Af7-L23-S28-Y2-U9-N38-Aa15-X-Ad21-B29-O30-Ak162-Ae64-E65-M72-I50-B56-P40-J41-K-B339-E33-M26-G17-N37-Ah11-C13-B4-B13-M49-B15-U5-F3-H38-B15-X44-H15-E334-Aa34-Ag20-F14-P4-G39-U19-A14-Ai87-Ae7-Ac60-A88-G66-C98-Q74-N6-Ah5-O2-B5-Ac15-Ag43-E-M45-L9-Ak18-I28-K6-D-B12-J5-Ac14-D167-A130-C6-A52-G78-B-D4-Aa-P7-G12-F13-Aa26-N16-V2-Ai10-L13-B20-L-L6-O10-Af6-I16-J302-A16-C5-Ab4-H35-Z12-G10-K9-Aa14-C20-P65-ZA22-D5-N-N49-Ab18-T-G4-C-Y5-K211-E66-Y16-A9-Ae52-P7-T68-J27-T29-A10-W9-B22-Q6-B50-Ae6-Q13-H8-A63-G207-A26-F11-Al12-M23-A22-B10-O28-A19-B61-F7-B7-Ak48-F4-H5-D11-C5-Af4-F-R26-A4-A46-A64-E61-A62-A11-A27-Ac22-O14-I36-N5-Ag3-A44-W14-Aa37-T26-N20-F4-D29-I14-O30-A4-A16-A73-A99-C-A59-A18-A17-Q3-K14-A67-T86-N26-I12-A-T39-M23-A13-Af8-H2-H10-A4-3(A7-)A98-A97-Y33-A-A2-A-A4-A-A8-A17-L12-A28-A21-D43-A60-Z5-O27-A33-A49-F17-A3-A6-A-A4-A3-A39-A34-A61-A64-A4-A42-A6-A22-D17-J17-Aa24-R14-A33-T23-Z100-LA27-D2-A22-R-I2-H15-A2-A-A5-A4-A141-A91-A7-A4-A-A7-A12-M84-Ag16-Ab2-R68-L61-B23-Q48-A8-A7-2(A4-)A10-2A30-AGA29-AGAeA29-AJEA28-AJECA27-AJECMA27-AECMYA24-3AECMYQ18A5-AGAeJECMYQAcAfAbKFRIHDLNZAaPAgAh2AlA3-AOGAeJECMYQAcAfAbKFRIHDLNZAa2PAg3AhA-ATOG3BCMYQAcSAbKFRIB2DBNBAaPB3AgP2ATOGAeBECMYQSUVAbKFRBHDBNBZAaB4P2ATO2GBJECMSUVWXKFR4BL2BZB4Aa2AAkTOGBJECSUVWXAiAd2FBIHB2L2NB4Z2AAkTOGBJECUVWXAiAdAjKFB2IB2DL3B3N2AAkTO3B2ECWXQAdAjAb2KF2BIH3DB4LA-AAkTOGAeJECMYQ2AcAfAbK2FR2I2H5DA3-ATOGAeJE2CMYQAc2AfAbK2F2R2I4HA5-26A327-3B5-S5-B2-B-B2-B10-B5-SUV4-B2-B-B2-B10-B4-SUVWX3-4B-2B-B10-B3-SUVWXAiAd2(2-B)4-B10-B3-UVWXAiAdAj2(2-B)3-3B8-3B3-WX-AdAj4-2B5-B101-
