model
size = 18 32 13, scale = 0.05, origin = -y
material deform = 1, fade = true, lighting = smooth, roughness = 0.3, metalness = 0.6
  colors = A:#222 B:#C36 C:#933 D:#C63 E:#693 F:#33C G:#C39 H:#090 I:#E47329 J:#06C K:#993 L:#A83800 M:#396 N:#C99 O:#339 P:#663
voxels
330-6A11-8A9-10A7-12A6-12A5-6A2-6A2(4-5A)4-4A6-4A4-3A8-3A98-BFEDOD11-FM2FI3E9-2B3EFEKCD7-GB2EFEFCK3D6-2B3F2EIEHDL6-BAE2F2ED2E2D2(6-2B3F3EH3D)6-2B2F4-H3D6-2BF6-3D5-3BF2-2A2-3DC4-3B2-F3A2-2DC4-2B3-J3A2-2IC4-2B2-6A2-AC4-G2-8A-AL4-A2-8A2-A6-10A7-12A6-12A5-6A2-6A2(4-5A)3-5A6-5A2-4A8-4A2-16A3-4(14A4-)14A7-3A2-3A45-EHF4-DED7-2BFM2FD4ED5-GJ2B3EFEKC2DC4-3B2EFEFCK3DC4-3B3F2EDEP3D4-2BAE2F2ED2E2D3(C4-3B3F3EK3D)C4-3B3F4H2(3DC4-3B3F3AI)3DC4-3B2JF3A2I2DC3-4B10A2C2-4G10ACL2(2-5A6-5A)2-4A7-5A2-3A9-4A2-3A10-2(3A2-2A11-)3A2-A14-A75-A17-4A5-5A4-14A6-10A10-2A2-2A8-BA10-H-C3-J12-CD2-B14-C2-A14-D2-J14-C2-B14-D8(2-B14-C)2-G14-L5(2-A14-A)-2A14-4A14-2A-A14-A111-3A7-4A4-4A6-4A5-4A4-4A5-J12-I3-B14-C2-B14-C-6(2B14-2C)-5(B14-C2-)G14-L2(2-A14-A)-2A4(14-4A)14-2A146-2A9-3A4-4A6-4A3-B14-D-2B14-2CGB14-2C2B14-CD10(2B14-2C)2G14-CL2A6(14-4A)14-2A146-2A9-3A4-3A8-3A2-B16-CB16-DB16-CJ16-CG16-D3(B16-C)6(B15-2C)2G14-CL2A6(14-4A)14-2A139-3A4-3A8-3A5-2A8-2A3-A16-DB16-6(C2B15-)C6(2B14-2C)2G14-CL2A14-4A14-2A-4(A14-A2-)A14-A111-A17-3A8-3A4-3A8-3A21-B14-C2-J13-AC-2B14-2CGB14-CD9(2B14-2C)-B14-C2-G14-L4(2-A14-A)2-A13-2(2A2-2A12-)2A2-A13-2A75-A17-3A8-3A4-3A8-3A39-GBA10-E2C2-B13-CI2-B13-2C2-J14-C2-B14-D8(2-B14-C)2-2B13-C2-2G13-L4(2-2A13-A)4(2-2A12-2A)2-A14-A39-2A10-2A4-3A8-3A4-2A-A6-4A6-A8-A42-BAEHBFEIO2(DE)D4-3BFM2FD4ED2(C4-B12-)D4-G2(12-C4-B)12-D7(4-B12-C)4-G12-L5(4-A12-A)3-3(2A12-2A2-)2(2A11-3A2-)4A9-3A3-14A5-5A2-5A7-2A6-2A97-F2B3EFEKC2D6-2B2EFEFCK2DL6-2B3F2EDEP2D5-2BAE2F2ED2E2D4(C4-3B3F3EK3D)3(C4-3B3F3AN3D)C4-3B10AC4-3G10AL3(4-14A)5-2(12A6-)12A5-3(14A4-)14A5-4ABFED4A7-3A4-3A153-2E-EF-KD10-B2F2EIEH9-AH2F2(2ED)8-B3F3EHDL7-2(2B3F3EH3D6-)2B3F4H2(3D6-2B3F3AI)3D6-2B3J3A4I6-2B10A6-2G10A6-12A6-G3AJ2(AH)A2I6-B3AF2(AE)A2D6-3BAFA3EADA6-2(BA)F2AE2ADA6-3BAF2(AE)ADA7-10A8-10A9-8A11-6A132-
