model
size = 12 14 32, scale = 0.05, origin = -y
material deform = 1, fade = true, lighting = smooth, roughness = 0.3, metalness = 0.6
  colors = A:#FFF7F0 B:#1E1E1E C:#323232 D:#3C3C3C E:#F60 F:#DB5700 G:#D45400 H:#ED5F00 I:#CF6 J:#D7387F K:#BB1313 L:#F06 M:#379D30 N:#CFC O:#CFF P:#FC6 Q:#F3C R:#F3F S:#FF9 T:#CC3 U:#CC6 V:#D97708 W:#CC0 X:#F00 Y:#F33 Z:#FCF Aa:#F09 Ab:#124BC6 Ac:#F93 Ad:#FC9 Ae:#F39 Af:#FFC Ag:#F90 Ah:#F9F Ai:#F30 Aj:#CC9 Ak:#F36 Al:#CF9 Am:#FC0 An:#F0F Ao:#141414 Ap:#F99 Aq:#FC3 Ar:#F69 As:#F03 At:#CF0 Au:#8D1204 Av:#FF0 Aw:#F66 Ax:#F63 Ay:#F9C Az:#FCC Ba:#CCF Bb:#FFF Bc:#CF3 Bd:#FF6 Be:#F6F Bf:#F96 Bg:#FF3 Bh:#F6C Bi:#F0C Bj:#CCC
voxels
16-4B8-4B139-6B6-Ar4BAr6-ER2FST6-RP2FUO6-AeT2FZAw6-AcO2FAvBd7-3(4F8-)4F54-2B2(CD)2B4-X6AX4-AfAyEAeBcZAgBj4-Ax2ArAkApAgTAt4-LAqNLBaBdAtX4-2SAxAyBiAlAdBb4-P6FAj4-N6FN4-H6FH6-4F53-2B6Au2B2-Bg-6A-Ad2-AhL6-TAh2-ZU6-UAe2-BcZ6-AaT2-AgAi6-AnAz2-OAl6-TY2-YAe6-PI2-2H6-2H61-2B2C2(DC)AuD2BAm10AAl-An8-X2-P8-Bd2-Af8-Af2-Ay8-Al2-N8-Bg2-Bd8-Ac2-H8-H61-BC2D2(CD)2CDBI3A4G3AAqBbAr8-BaR-O8-Az2-As8-Af2-S8-E2-Am8-I2-W8-Q2-P8-T2-H8-H49-BD2CD4KDCBAv4A2G4ARAwO8-WENL8-BeWYS8-NO-Aa8-Bf2-Aj8-L2-R8-O2-L8-Bf2-H8-H49-BC2DC2(KCD)BAc4A2G4AAkOU8-AaUAkAn8-WSEL8-WApRU8-AsAc2O8-AmZ-Aa8-Bf2-Ai8-Q2-H8-H49-BD2CD2(KDC)BAa4A2G4AAgXAl8-NAfIAm8-AnAkNQ8-Q2IAi8-BcAyAeL8-WAyAaP8-SAd-Aj8-Af2-R8-At2-H8-H37-BCD6KCDBAc4A2G4ARAsBe8-IWRAw8-SAcAyT8-BbAmAdQ8-2AjBcBh8-YAwTQ8-UAj-T8-Aq2-X8-T2-H8-H37-BD2C2(DC)2DCBBa4A2G4AAiAqAn8-WAxAtAi8-BhRIL8-QPOAt8-RAsAfP8-AzBh-As8-Aq2-I8-Ac2-Q8-Ap2-T8-Aa2-H8-H25-2B2D2(CD)2C2BAm4A2G4AAfLU8-AnXNAy8-2Z-S8-N2-Az8-P2-Bj8-U2-Be8-W2-As8-L2-U8-W2-Q8-Aa2-H8-H16-6E4-B2C2(DC)2DB2-I3A3G2AN2-Ah8-Q2-Ax8-I2-I8-Ae2-Ax8-X2-Ag8-N2-Aa8-Bc2-U8-Bi2-I8-S2-S8-Bd3-2E4A2E5-E4AE6-E4AE4-B2D2(CD)2CB2-Bi3A3G2AX2-Y8-Am2-Ak8-Ah2-Q8-Az2-Ad8-Ad2-Bg8-Ar2-Ac8-X3-Z6-U4-Ah6-X4-E6-E4-E6AE27-BCV2(DC)2DB2-Aj8AAe2-Af8-I2-Ag8-Bg2-Y8-Ba2-O8-Be2-R8-Ag3-Aq6-P4-Aa6-T4-E6-E4-Ao6JE39-BDV2(CD)2CB2-Ae8AAi2-Z8-L2-Bf8-Af2-Ah8-E2-Y8-O3-N6-Y4-E6-Ad4-Aa6-E4-E6AE51-BC6VDB2-Ai8AAl2-Aq8-O2-W8-Al2-L8-U2-An8-Ac3-Am6-S4-S6-U4-Ao6AbAo63-B2D2(CD)2CB2-W8AAk2-Ae8-I2-Bh8-P2-N8-Am2-X8-R3-Q6-N4-E6-E4-E6AE62-2BC2MCD2MD2BL10AL-Ah8-Av2-T8-Z2-Ag8-Bb3-N6-P4-Av6-Aa4-Ao6MAo74-BC2DC2MD2CDBAd10ABgQ10-S-X8-Bc2-Ag8-Aw3-Ah6-P4-E6-E4-E6AE74-BD2CD2MC2DCBAc10AAcY10-Ap-Ah8-Ax2-Y8-Y3-Q6-Ai4-Ao6VAo86-BCD2MDC2MCDBBa10ARAh10-Av-R8-Y2-Al8-Ad3-E6-E4-E6AE86-BD2C2(DC)2DCBO10ABfT10-Aa-W8-Ak3-E6-E4-Ao6KAo98-BCD6AbCDBP10AQ-Q8-O2-L8-At3-E6-E5-6A99-BD2C2(DC)2DCBAc10AAz-Av8-X3-Aj6-Bb4-E6AE6-4A100-BC2DC4JCDBBi10AAq-Aw8-Al3-Z6-Ap4-Ap6ES110-2B2CDJDCJD2BL10AAk-S8-I3-An6-R5-UAtArAfAvAd112-B2DCJCDJCB2-Be8AAj3-L6-Ap4-AeAi4-NY6-AhINY113-2B6J2B2-Ap8AAn3-Ad6-I4-AjAkZAxAeAtPBd124-2B2(DC)2B4-Ai6AL4-W6-Ar5-AlBhPAgIAk126-B2(CD)B6-Z4AI6-AgAsAmAsIO138-2BCD2B6-B4AB7-AwBbBaAd136-
