model
size = 12 14 32, scale = 0.05, origin = -y
material deform = 1, fade = true, lighting = smooth, roughness = 0.3, metalness = 0.6
  colors = A:#C8C8C8 B:#232323 C:#323232 D:#3C3C3C E:#303030 F:#141414 G:#7C7C7C H:#525252 I:#6B6B6B J:#5A5A5A K:#636363 L:#FAFAFA M:#848484 N:#379D30 O:#8D8D8D P:#969696 Q:#1E1E1E R:#4A4A4A S:#D7387F T:#124BC6 U:#747474 V:#959595 W:#BB1313 X:#D97708 Y:#282828 Z:#393939 Aa:#414141 Ab:#9E9E9E Ac:#8D1204 Ad:#252525 Ae:#A6A6A6
voxels
16-4B8-4B139-6B6-E4BE6-2Ae2F2Ae6-2Ab2F2Ab6-VAb2FAbV6-2V2F2V7-3(4F8-)4F54-2B2(DC)2B4-E6AE2(4-Ab6QAb)4-V6QV4-O6QO4-O6FO4-M6FM4-G6FG6-4F53-2B6Ac2B2-E8AE2-AbV6-VAb2-2V6-2V2-VO6-OV2-2O6-2O2-2M6-2M2-MG6-GM2-2G6-2G61-2B3(DC)AcC2BE10AE-2(V8-V2-)2(O8-O2-)M8-M2(2-G8-G)61-B5(DC)BE4A4L2AEXV8-VX-2(O8-O2-)2(M8-M2-)G8-G2(2-U8-U)49-B2(CD)4WCDBE5A2L3AE2O8-4O8-2O2M8-2M-M8-M2(2-G8-G)2-U8-U2-I8-I49-B2(DC)WCDWDCBE5A2L3AENO8-O2(2NM8-M)2(2NG8-G)N-2(U8-U2-)I8-I49-B2(CD)WDCWCDBE2A5L3AE2M8-4M8-2M2G8-4G8-2GUG8-G2UG8-GU-2(I8-I2-)K8-K37-BDC6WDCBE2AL2A2L3AETM8-M4(2TG8-G)2TI8-IT-I8-I2(2-K8-K)37-B5(CD)BE2AL2A2L3AE2G8-2GUG8-G2UG8-GUIG8-G3I8-2I-I8-I2(2-K8-K)2-J8-J2-H8-H25-2B4(CD)2BE2AL2A2L3AESG8-G2SG8-GS-U8-U2(2-I8-I)2(2-K8-K)2(2-J8-J)2-H8-H16-6F4-B4(DC)B2-EA6LAE2-G8-G2-U8-U2(2-I8-I)2(2-K8-K)2(2-J8-J)2-H8-H3-2P4A2P5-P4AP6-P4AP4-B4(CD)B2-EA6LAE2-U8-U2(2-I8-I)2(2-K8-K)2-J8-J3-J6-J2(4-H6-H)4-P6AP27-BDX3(DC)B2-E8AE2(2-I8-I)2(2-K8-K)2-J8-J3-J6-J2(4-H6-H)4-F6SF39-BCX3(CD)B2-E8AE2-I8-I2(2-K8-K)2-J8-J3-J6-J2(4-H6-H)4-P6AP51-BD6XCB2-E8AE2(2-K8-K)2(2-J8-J)3-2(H6-H4-)F6TF63-B4(CD)B2-E8AE2-K8-K2(2-J8-J)2-H8-H3-H6-H4-R6-R4-P6AP62-2B2(D2NC)BQE10AE-2(J8-J2-)H8-H3-H6-H4-R6-R4-F6NF74-B2(DC)2N2(DC)BE10AEJ10-J-H8-H2-H8-H3-2(R6-R4-)P6AP74-B2(CD)2N2(CD)BE10AEH10-H-H8-H2-R8-R3-R6-R4-F6XF86-B2(DC2N)DCQE10AEH10-H-R8-R2-R8-R3-R6-R4-P6AP86-B5(CD)BE10AER10-R-R8-R3-R6-R4-F6WF98-BDC6TDCQE10AE-R8-R2-Aa8-Aa3-P6-P5-6A99-B5(CD)BE10AE-Aa8-Aa3-Aa6-Aa4-P6AP6-4A100-B2(DC)4SDCBE10AE-Aa8-Aa3-Aa6-Aa4-Z6PZ110-2BDCDSDCSC2BE10AE-Aa8-Aa3-Z6-Z5-Z4EZ112-BCDCSCDSDB2-E8AE3-Aa6-Aa4-ZE4-EZ6-E2YE113-2B6S2B2-E8AE3-Z6-Z4-ZE4YEZ124-2B2(CD)2B4-E6AE4-Z6-Z5-E4YE126-B2(DC)B6-E4AE6-EY2AdYE138-2BDC2B6-B4AB7-Y2AdY136-
