model
size = 12 14 32, scale = 0.05, origin = -y
material deform = 1, fade = true, lighting = smooth, roughness = 0.3, metalness = 0.6
  colors = A:#C8C8C8 B:#232323 C:#323232 D:#3C3C3C E:#303030 F:#141414 G:#7C7C7C H:#525252 I:#6B6B6B J:#5A5A5A K:#636363 L:#848484 M:#379D30 N:#8D8D8D O:#969696 P:#1E1E1E Q:#4A4A4A R:#D7387F S:#124BC6 T:#747474 U:#FAFAFA V:#959595 W:#BB1313 X:#D97708 Y:#282828 Z:#393939 Aa:#414141 Ab:#9E9E9E Ac:#8D1204 Ad:#252525 Ae:#A6A6A6
voxels
16-4B8-4B139-6B6-E4BE6-2Ae2F2Ae6-2Ab2F2Ab6-VAb2FAbV6-2V2F2V7-3(4F8-)4F54-2B2(DC)2B4-E6AE2(4-Ab6PAb)4-V6PV4-N6PN4-N6FN4-L6FL4-G6FG6-4F53-2B6Ac2B2-E8AE2-AbV6-VAb2-2V6-2V2-VN6-NV2-2N6-2N2-2L6-2L2-LG6-GL2-2G6-2G61-2B3(DC)AcC2BE10AE-2(V8-V2-)2(N8-N2-)L8-L2(2-G8-G)61-B5(DC)BE3A4U3AEXV8-VX-2(N8-N2-)2(L8-L2-)G8-G2(2-T8-T)49-B2(CD)4WCDBE4A2U4AE2N8-4N8-2N2L8-2L-L8-L2(2-G8-G)2-T8-T2-I8-I49-B2(DC)WCDWDCBE4A2U4AEMN8-N2(2ML8-L)2(2MG8-G)M-2(T8-T2-)I8-I49-B2(CD)WDCWCDBE4A2U4AE2L8-4L8-2L2G8-4G8-2GTG8-G2TG8-GT-2(I8-I2-)K8-K37-BDC6WDCBE4A2U4AESL8-L4(2SG8-G)2SI8-IS-I8-I2(2-K8-K)37-B5(CD)BE4A2U4AE2G8-2GTG8-G2TG8-GTIG8-G3I8-2I-I8-I2(2-K8-K)2-J8-J2-H8-H25-2B4(CD)2BE4A2U4AERG8-G2RG8-GR-T8-T2(2-I8-I)2(2-K8-K)2(2-J8-J)2-H8-H16-6F4-B4(DC)B2-E3A3U2AE2-G8-G2-T8-T2(2-I8-I)2(2-K8-K)2(2-J8-J)2-H8-H3-2O4A2O5-O4AO6-O4AO4-B4(CD)B2-E3A3U2AE2-T8-T2(2-I8-I)2(2-K8-K)2-J8-J3-J6-J2(4-H6-H)4-O6AO27-BDX3(DC)B2-E8AE2(2-I8-I)2(2-K8-K)2-J8-J3-J6-J2(4-H6-H)4-F6RF39-BCX3(CD)B2-E8AE2-I8-I2(2-K8-K)2-J8-J3-J6-J2(4-H6-H)4-O6AO51-BD6XCB2-E8AE2(2-K8-K)2(2-J8-J)3-2(H6-H4-)F6SF63-B4(CD)B2-E8AE2-K8-K2(2-J8-J)2-H8-H3-H6-H4-Q6-Q4-O6AO62-2B2(D2MC)BPE10AE-2(J8-J2-)H8-H3-H6-H4-Q6-Q4-F6MF74-B2(DC)2M2(DC)BE10AEJ10-J-H8-H2-H8-H3-2(Q6-Q4-)O6AO74-B2(CD)2M2(CD)BE10AEH10-H-H8-H2-Q8-Q3-Q6-Q4-F6XF86-B2(DC2M)DCPE10AEH10-H-Q8-Q2-Q8-Q3-Q6-Q4-O6AO86-B5(CD)BE10AEQ10-Q-Q8-Q3-Q6-Q4-F6WF98-BDC6SDCPE10AE-Q8-Q2-Aa8-Aa3-O6-O5-6A99-B5(CD)BE10AE-Aa8-Aa3-Aa6-Aa4-O6AO6-4A100-B2(DC)4RDCBE10AE-Aa8-Aa3-Aa6-Aa4-Z6OZ110-2BDCDRDCRC2BE10AE-Aa8-Aa3-Z6-Z5-Z4EZ112-BCDCRCDRDB2-E8AE3-Aa6-Aa4-ZE4-EZ6-E2YE113-2B6R2B2-E8AE3-Z6-Z4-ZE4YEZ124-2B2(CD)2B4-E6AE4-Z6-Z5-E4YE126-B2(DC)B6-E4AE6-EY2AdYE138-2BDC2B6-B4AB7-Y2AdY136-
