model
size = 23 9 18, scale = 0.05, origin = -y
material deform = 1, fade = true, lighting = smooth, roughness = 0.3, metalness = 0.6
  colors = A:#1A1A1A B:#A57C1F C:#35271C D:#2F231A E:#32251B F:#38291D G:#2D2219 H:#3D2C1F I:#433021
voxels
2-9A3B9A-7A7-7A-2AG2DEC2A5-2ACE2DG3A2GD2ECF2A3-2AFC2ED2G2AG2DE2CFH2A-2AHF2CE2DG2AGD2EC2FHIA-AIH2FC2EDG2AGDE2CF2HIA-AI2HF2CEDG2AGDEC2FH2IABA2IH2FCEDG3ADECF2HI2A-2AI2HFCED2A46-B3(21-2B)3(21-B184-B)21-2B12(21-B184-B)21-B78-B3-B19-B-B79-B21-B46-
