model
size = 32 10 5, scale = 0.05, origin = -y
material deform = 1, fade = true, lighting = smooth, roughness = 0.3, metalness = 0.6
  colors = A:#111 B:#FFC408 C:#FFB11B
voxels
46-C-C29-5C26-C3-C27-C3-C28-4C27-C3-C28-5C27-C-C60-6A25-2A4B2A23-2A6B2A11-12A8B11A-2(AB)2(ACB)2A8B2A2(BCA)BAB-3(AB)CABC2A8B2A2(CBA)BAB-12A8B11A12-2A6B2A23-2A4B2A25-6A138-2(3(2A30-)2A223-)3(A31-)A96-
