model
size = 32 14 32, scale = 0.05, origin = -y
material deform = 1, fade = true, lighting = smooth, roughness = 0.3, metalness = 0.6
  colors = A:#FFF B:#111 C:#EEE D:#FCFAF2 E:#6A4028 F:#43341B G:#566C73 H:#4B4E2A I:#563F2E J:#6E552F K:#F9BF45 L:#616138 M:#7D532C N:#74673E O:#897D55 P:#78552B Q:#62592C R:#4D5139 S:#3C2F41 T:#26453D U:#91989F V:#876633 W:#985F2A X:#7D6C46 Y:#82663A Z:#4A593D Aa:#967249 Ab:#855B32 Ac:#3A3226 Ad:#947A6D Ae:#877F6C Af:#89916B Ag:#A36336 Ah:#646A58 Ai:#6C6A2D Aj:#867835 Ak:#405B55 Al:#91AD70 Am:#96632E An:#8D742A Ao:#516E41 Ap:#6C6024 Aq:#838A2D Ar:#6A8372 As:#554236 At:#A28C37 Au:#B07736 Av:#B68E55 Aw:#B17844
voxels
40-4A-6A-4A15-18C13-CA16CAC11-CAB16CBAC9-3(CA2B16C2BAC8-)CA2B16C2BAC9-CAB16CBAC11-CA16CAC13-18C15-16C242-K10-K84-Ad10-Ad333-K7A10-7AK7-7A10-7A8-7A10-7A7-Ad7A10-7AAd11-3A10-3A265-9A-10B-9A-10AC10BC21A2(10B22A)10B11A5-6A10B6A8-K6-K-8B-K6-K163-11AC8-C12AD8AC10BC8AD2AD8AC10BC8ADA-D-7BC10BC7B3(-D2-D-26B)-D-AD9A10B9ADA12-8B15-W6-W10-W6-W2(5-2S)10-2S5-2S46-8A14-10A8-10A2-12A8B13AD28ADA-D-26B-D4-2(26B6-)26B4-D-26B-D2-D-26B-D-12A8B12A33-TAa2IF3-AwAa10-AaJ3-FIJPT13-8A15-26A4-11A8C11A-32A-D-26B-D4-4(26B6-)26B4-D-26B-D2-2D26B2D-12A8-12A-AuKW2JFJQAvK10-KAnJHNOIENF9-16A10-28A2-32A2-D26BD5-6(26B6-)26B4-2D26B2D-12A8-12ASKAaMGOPAmAtKAn10-VKVAbKGLE2JS5-22A6-30A-32A2-D26BD5-6(26B6-)26B4-2D26B2D-13A6-13AEOWJUGAmMOAaQ10-IVAiJWRUIEPE3-26A3-64A2-D26BD5-6(26B6-)26B4-2D26B2D-13A6-13AAbAaMLUNAgNAlAk12-LAjQWAsUIEPF-30A-64A2-D26BD5-6(26B6-)26B4-2D26B2D-13A6-13AAgAaMXUYAgAkAlL12-HYLPILHFEI-30A-64A2-D26BD5-5(26B6-)26B5-D26BD3-DA26BAD-13A6-13AVAbEXO2MNOI12-TLGETURF2E-11A-6A-11A-12AC6AC44A2-D26BD5-5(26B6-)26B5-D26BD3-DA26BAD-13A6-13AVMEGOMPNXF12-Ac2G2EURFJE2-10A-6A-10A2-12AC6AC44A2-D26BD5-5(26B6-)26B5-D26BD3-DA26BAD-13A6-13AVMELO2MNXF12-AcLZEIUHEJI2-10A-6A-10A3-11AC6AC11A-32A2-D26BD5-5(26B6-)26B5-D26BD3-DA26BAD-13A6-13A2AbELUPEQNQ12-FNLETUAcEJF3-9A-6A-9A4-11AC6AC11A2-30A3-D26BD5-5(26B6-)26B5-D26BD3-DA26BAD-15A2-15APYERGFEQOQ12-HAfZEILAcFJP3-9A-6A-9A5-10AC6AC10A3-30A3-D26BD5-4(26B6-)26B5-D26BD4-D26BD3-DA26BAD-15A2-15AEVEHUHWIOLF10-FLGIEHG2FQE4-8A-6A-8A6-10AC6AC10A3-30A3-2(D26BD4-)D26BD5-26B6-26B5-2(D26BD4-)D26BD3-DA26BAD-15A2-15AFYMIGLEKHORF8-HZGAcEIGTFEJF4-8A-6A-8A6-10AC6AC10A3-30A3-7(D26AD4-)D26AD3-D13A2B13AD-15A2-15A-VAbEHAfHKEZAeRF6-QLGAcEFRGFEQF6-7A-6A-7A9-8AC6AC8A8-24A7-26A6-26A5-5(D26AD4-)D26AD3-D28AD2-30A2-EOWI2GIKEHXGR2HIN2XLFMEHAeTFIJ7-7A-6A-7A10-7AC6AC7A9-3C18A3C8-24A7-26A6-26A5-5(D26AD4-)2(28A4-)VYMFOGFMIHGNLOGLRH2EFZAfHFEKF8-2(6A-)6A11-7AC6AC7A9-3C18A3C8-24A7-2(26A6-)4(C24AC6-)C24AC5-AC24ACA4-28A4-FAj2ETArGT3E3FIF2EFSLAeHFMKE11-4A-6A-4A14-2C4AC6AC4A2C10-3C18A3C3(8-C22AC)7-2(2C22A2C6-)4(C24AC6-)26A6-EK2ET2GH3F3E3FHKAiS2EQE12-4A-6A-4A14-2C4AC6AC4A2C11-2C18A2C9-4(C22AC8-)C22AC7-4(C24AC6-)26A7-EK2EFR3G2R3HApAqKHF2EJE13-4A-6A-4A15-C4AC6AC4AC12-2C18A2C10-C20AC9-4(C22AC8-)4(2C20A2C8-)24A9-EXJ2EFT2ZAo2AhZ3F2EJQF14-4A-6A-4A15-C4AC6AC4AC12-2C18A2C10-C20AC9-3(C22AC8-)C22AC9-4(C20AC10-)22A11-FVN3E7F2EPXPF15-4A-6A-4A15-C4AC6AC4AC13-C18AC11-C20AC9-3(C22AC8-)C22AC9-C20AC11-3(C18AC12-)20A14-EY2NJ5EJNYPF17-4A-6A-4A15-C4AC6AC4AC13-C18AC11-C20AC9-3(C22AC8-)C22AC9-C20AC11-C18AC13-2(18A14-)18A17-FIEJY2JPEFI19-4A-6A-4A15-18C13-CA16CAC11-C2A16C2AC9-3(C3A16C3AC8-)C3A16C3AC9-C2A16C2AC11-CA16CAC13-18C15-16C17-14A49-4A-6A-4A15-18C13-CA16CAC11-C2A16C2AC9-3(C3A16C3AC8-)C3A16C3AC9-C2A16C2AC11-CA16CAC13-18C15-16C18-12A50-4A-6A-4A15-18C13-CA16CAC11-C2A16C2AC9-3(C3A16C3AC8-)C3A16C3AC9-C2A16C2AC11-CA16CAC13-18C15-16C20-8A52-4A-6A-4A15-18C13-CA16CAC11-C2A16C2AC9-3(C3A16C3AC8-)C3A16C3AC9-C2A16C2AC11-CA16CAC13-18C15-16C72-
