model
size = 31 18 32, scale = 0.05, origin = -y
material deform = 1, fade = true, lighting = smooth, roughness = 0.3, metalness = 0.6
  colors = A:#FFF B:#FCFAF2 C:#0B1013 D:#EEE E:#985F2A F:#F9BF45 G:#947A6D H:#43341B I:#B68E55 J:#3C2F41 K:#3A3226 L:#78552B M:#B35C37 N:#222 O:#B07736 P:#26453D Q:#577C8A R:#89916B S:#6A4028 T:#616138 U:#897D55 V:#535953 W:#91AD70 X:#967249 Y:#BC9F77 Z:#B4A582 Aa:#405B55 Ab:#7D6C46 Ac:#62592C Ad:#6E552F Ae:#444 Af:#656765 Ag:#563F2E Ah:#C1693C Ai:#855B32 Aj:#877F6C Ak:#465D4C Al:#4F4F48 Am:#2EA9DF An:#6A8372 Ao:#4B4E2A Ap:#876633
voxels
129-2D27-2D2(29-D)30-D29-6(D30-)D31-2D71-3F4G24-6BA4E26-4BA3G27-3BA2F28-BAG29-BA3(E29-B)A2(E29-B)2(G29-B)G30-G2(29-E)28-2E25-F3G13-5F7C20-10B5C26-4B4C27-3BA2C28-BAC2(29-B2C2(29-BC))2(29-BC)29-2C2(29-C)28-2C23-G2E3C13-12C17-3F10B5C14-2B10-4B4C27-3BA2C28-BAC2(29-B2C2(29-BC))2(29-BC)29-2C2(29-C)28-2C21-G2E5C13-12C17-3C10B5C11-G2F2B10-4B4C9-2B16-3BA2C28-BAC2(29-B2C2(29-BC))2(29-BC)29-2C2(29-C)28-2C20-FE7C13-12C17-3C10B5C11-3C2B10-4B4C6-2EF2B16-3BA2C6-B21-BAC2(29-B2C2(29-BC))2(29-BC)29-2C2(29-C)48-G2EC20-12C17-3C10B5C11-3C2B10-4B4C6-3C2B16-3BA2C4-EAB21-BAC3-G2B23-2(B2C2(29-BC)29-)2(BC29-)2C29-C77-GE23-12C17-3C10B5C11-3C2B10-4B4C6-3C2B16-4B2C4-CAB21-BAC3-2CB23-B2C2-EB25-BC-FA26-BC-F27-B2C4(29-BC)29-2C29-C75-F2E24-6C23-3C10B16-3C2B10-4B10-3C2B16-3B7-CAB21-2B4-2CB23-B4-CB25-B2-2CB25-B2-FB26-B2-FB27-B-F28-3(B30-)B105-FE58-10B16-2C-2B10-4B10-3C2B16-3B7-CAB21-2B4-2CB23-B4-CB25-B2-2CB25-B2-CB26-B2-2(CB27-B-)2(FB27-B-)GB29-GB100-2FE59-6B4A19-2B10-4A13-2B16-3A7-C2B21-2A5-CB23-A4-CB25-A2-2CB25-A2-CB26-A2-CB27-A-CB27-D-4(CB29-)EB68-GE61-10A19-2A10-4A13-2B16-3A8-2B21-2A6-B23-A5-B25-A4-B25-A3-B26-A3-B27-A-CB27-D-4(CB29-)G3B28-G2AB28-E2FNJGE62-10A19-2A10-4A13-2A16-3A8-BA21-2A6-B23-A5-B25-A4-B25-A3-B26-A3-B27-D2-4(B30-)B31-2B29-7B24-Ap2LAdHE63-10A19-2A10-4A13-2A16-3A8-2A21-2A6-A23-A5-A25-A4-A25-A3-A26-D3-5(B30-)B31-2B31-5B26-T2WAo63-10A19-2A10-4A13-2A16-3A8-2A21-2A6-A23-A5-A25-A4-A25-D3-6(A30-)A31-2A31-5B25-FQAmQAn63-10A19-2A10-4A13-2A16-3A8-2A21-2A6-A23-A5-A25-D4-A29-6(A30-)A31-2A31-5B25-F2ZRUJ62-10A19-2A10-4A13-2A16-3A8-2A21-2D6-A23-D5-A30-A29-6(A30-)A31-2A31-5B25-LI2XUK62-10A19-2A10-4A13-2A16-A2D8-2A2(29-A)30-A29-6(A30-)A31-2A31-5B25-OVAkAlVJ62-10A19-2A10-4A13-2A16-D10-2A2(29-A)30-A29-6(A30-)A31-2A31-5B25-H2PAaQK62-10A19-2A10-3AD13-2A27-2A2(29-A)30-A29-6(A30-)A31-2A31-5B25-L2RAjRH62-10A19-2A10-2AD14-2A27-2A2(29-A)30-A29-6(A30-)A31-2A31-5B25-OY3IAd62-10A19-2A10-AD15-2A27-2A2(29-A)30-A29-6(A30-)A31-2A31-5B25-HAh3MAi62-10A19-2A10-2D15-2A27-2A2(29-A)30-A29-6(A30-)A31-2A31-5B25-HOE2SH62-9AD19-2(2A27-)2A2(29-A)30-A29-6(A30-)A31-2A31-5B25-Ag3IRIJ61-8A2D19-2(2A27-)2A2(29-A)30-A29-6(A30-)A31-2A31-5B25-AcTWPWUK61-7A2D20-2(2A27-)2A2(29-A)30-A29-6(A30-)A31-2A31-5B25-LAf2Q2VK61-6AD22-2(2A27-)2A2(29-A)30-A29-6(A30-)A31-2A31-5B25-L2AaAe2PJ61-5A2D22-2(2A27-)2A2(29-A)30-A29-6(A30-)A31-2A31-5B25-LTAbUAbTAc61-4A2D23-2(2A27-)2A2(29-A)30-A29-6(A30-)A31-2A31-5B25-OXYZYFIJ60-2AD26-2(2A27-)2A2(29-A)30-A29-6(A30-)A31-AB31-B4A24-HK3M2SGH60-3D26-2(2A27-)2A2(29-A)30-A29-6(A30-)A31-AB31-B4A24-J4N2KHO89-2D2(27-2A)2(29-A)30-A29-6(A30-)A31-2A31-2D56-
