model
size = 32 5 27, scale = 0.05, origin = -y
material deform = 1, fade = true, lighting = smooth, roughness = 0.3, metalness = 0.6
  colors = A:#6A4028 B:#43341B C:#566C73 D:#4B4E2A E:#563F2E F:#6E552F G:#F9BF45 H:#616138 I:#7D532C J:#74673E K:#897D55 L:#78552B M:#62592C N:#4D5139 O:#3C2F41 P:#26453D Q:#91989F R:#876633 S:#985F2A T:#7D6C46 U:#82663A V:#4A593D W:#967249 X:#855B32 Y:#3A3226 Z:#947A6D Aa:#877F6C Ab:#89916B Ac:#A36336 Ad:#646A58 Ae:#6C6A2D Af:#867835 Ag:#405B55 Ah:#91AD70 Ai:#96632E Aj:#8D742A Ak:#516E41 Al:#6C6024 Am:#838A2D An:#6A8372 Ao:#554236 Ap:#A28C37 Aq:#B07736 Ar:#B68E55 As:#B17844
voxels
2(10-Z)141-Z24-Z198-G6-G10-G6-G166-S6-S10-S6-S2(5-2O)10-2O5-2O131-PW2EB3-AsW10-WF3-BEFLP130-AqGS2FBFMArG10-GAjFDJKEAJB129-OGWICKLAiApGAj10-RGRXGCHA2FO128-AKSFQCAiIKWM10-ERAeFSNQEALA128-XWIHQJAcJAhAg12-HAfMSAoQEALB128-AcWITQUAcAgAhH12-DUHLEHDBAE128-RXATK2IJKE12-PHCAPQNB2A128-RIACKILJTB12-Y2C2AQNBFA128-RIAHK2IJTB12-YHVAEQDAFE128-2XAHQLAMJM12-BJHAPQYAFB128-LUANCBAMKM12-DAbVAEHYBFL128-ARADQDSEKHB10-BHCEADC2BMA128-BUIECHAGDKNB8-DVCYAECPBAFB129-RXADAbDGAVAaNB6-MHCYABNCBAMB130-AKSE2CEGADTCN2DEJ2THBIADAaPBEF132-RUIBKCBIEDCJHKCHND2ABVAbDBAGB132-BAf2APAnCP3A3BEB2ABOHAaDBIGA134-AG2AP2CD3B3A3BDGAeO2AMA136-AG2ABN3C2N3DAlAmGDB2AFA138-ATF2ABP2VAk2AdV3B2AFMB140-BRJ3A7B2ALTLB143-AU2JF5AFJULB147-BEAFU2FLABE11-
