model
size = 30 28 28, scale = 0.05, origin = -y
material deform = 1, fade = true, lighting = smooth, roughness = 0.3, metalness = 0.6
  colors = A:#F36 B:#FFF C:#6CC D:#F93 E:#F99 F:#F39 G:#EEE H:#FC6 I:#F69 J:#FFC K:#FCC L:#F9C M:#FC3 N:#C36 O:#9CC P:#FC9 Q:#C9C R:#FF9 S:#CFF T:#F96 U:#C69 V:#C99
voxels
39-3BFGDBF2BHB19-2BFIBEF2B21-D2B2IF4B22-2BGH2B711-2H2BFBDGF3B19-3BFEBIFB21-4BF2I3B22-2BHG2B741-H11ABL16-G9A2BA17-E10ADC17-2CB6ADFB19-BG2BMJ2BDB22-3BG2B675-QIDC2B14AB3Q7-A2C2BA9-3A2B2A8-2C2BLA10-2A2B2C9-MBKE3A6-3AFDBM10-4BG10ACKD2B11-2BE2CE6ADFBQDB13-FBLE3B3C2B3DF14-6BCPDICBHGHB16-4BCDGAC2BJC19-2BCIACOB24-B2CO26-B2GB495-8A12-4AI6-F5A13-4AF6-C5A13-3A2C7-H4A12-4AH8-B5A10-5AB9-2B5A6-5A2B12-F14AF14-GB13AG16-J11AC17-JR8AHB19-D2B4A2BI20-ADB4ABEM21-K6BE24-4B435-O2A19-2AD5-CA21-AC5-BA21-AC6-B2A19-AB7-BA18-AB8-B2A15-3AB9-2BA14-A2B10-IF3A12-ABI10-EF2BA11-ABAE11-I2B2A8-2A2BI13-FBD3A4-3ALEF14-BHN3A4-3ABCB16-BE8AEB19-BTB4ABLB21-3BFIF2B22-PBIEBVFB24-FBDG345-BA21-2A2(B4-BA22-A)B5-B2A19-AB7-BA18-AB8-B2A15-3AB9-BA15-2AB10-B3A13-2AB10-4A13-3A11-B2A12-2AB13-B2A10-2AB14-B2A10-2AB15-B2A8-2AB16-BU3A4-3AGB17-BD8AEB18-BM8A2B19-3B4AF2B21-2BAEBEFB24-BF2I284-B2A2(22-AB4-BA)22-AB4-DA21-2AD5-DA20-AD6-DA20-AD7-BA18-AB8-B2A16-2AB9-BA16-AB10-BA16-AB11-BA14-AB12-E2A13-AE13-EA12-AE14-E2A10-2AE15-B2A8-2AB16-B2A8-2AB17-B3A4-3AB19-B8AB20-3B4A3B22-2BHG2B24-2BMJ2B25-4B194-BA23-AB3-HA23-AB3-DA23-AL4-FA22-AF4-KA22-AK5-QA20-AQ6-DA20-AD6-H3A18-AH7-H2A17-AH9-BA16-AB10-EA16-AE10-CA15-A2C11-CA14-AC12-G2A13-AG13-2EA11-AE15-BA11-AB15-B2A8-2AB16-H2PA6-A2BH17-D3A4-3AD19-FB6ADF20-KS6ADK21-EB4ABDQ23-B3CB25-CJDF26-CDGN103-B2A23-AH3-BA23-AG3-DA23-AE3-BA23-AC4-CA22-AC4-BA22-AB5-DA20-AD6-GA20-AG6-2JA19-AJ7-J2A17-AJ9-LA16-AL10-BA16-AB10-IA16-AI11-GA14-AG12-GBA13-AG12-G2BA12-AG13-B2A11-AB15-B2A8-2AB16-D2A9-AD17-B2A6-2AB18-C2A6-2AC19-B8AB20-D2B5ABD21-2B4ACB22-2B4ACB23-BCKN2C25-B3C43-B2A23-2AH-B2A24-AB-D2A24-AB2-FA24-AF2-2A24-2A3-FA22-AF5-DA20-AD6-HA20-AH6-2BA19-AB7-B2A17-AB8-2EA17-AE8-2CA16-A2C9-CA16-AC10-E2A15-AE11-EA14-AE2(12-B2A13-AB)13-BA12-AB14-D3A10-AD15-F2A9-AF16-3A9-2A17-F3A6-AF18-D3A5-2AD19-H2A4-2AH20-B2A4-2AB21-B6AB22-2B4A2B23-2BHGHB12-2(B2A24-AB-)B2A24-AB2(2-DA24-AD)3-DA22-AD4-BA22-AB4-B2A21-AB5-BA20-AB6-B2A19-AB7-BA18-AB8-EA18-AE8-2EA17-AE9-LA16-AL2(10-BA16-AB)11-BA14-AB12-BA14-AB13-B3A10-AB15-2(D2A9-AD16-)D2A8-AD3(18-BA8-AB)19-BA6-AB20-B2A4-2AB21-D6AE11-2(F2A24-AB-)B2A24-AB-B2A2(24-AB2-BA)24-AB3-BA22-AB2(4-CA22-AC)5-O2A19-AO7-2(BA18-AB8-)BA18-AB9-2(BA16-AB10-)FA16-AF11-FA14-AF12-FA14-AF13-2(BA12-AB14-)BA11-2AB15-B2A8-A2B16-B2A8-2AB17-2(CA8-AC18-)CA7-A2C19-BA6-AB20-B2A4-2AB10-G2A24-2AGI2A25-A2I2A25-AIB2A25-AB-BA24-AB2-BA24-AB3-CA22-AC4-IA22-AI4-2A22-2A5-CA20-AC6-OA20-AO6-BA20-AB7-BA18-AB8-BA18-AB9-FA16-AF10-VA16-AV10-GA16-AG11-EA14-AE12-IA14-AI13-2(BA12-AB14-)BA10-3AB15-C2A8-2AC16-F2A8-2AF16-N2A8-2AN17-CA8-AC18-CA8-AC19-HA6-AH10-D2A25-ADB2A25-ABI2A25-AIG2A25-AG-JA24-AJ2-GA24-AG3-CA22-AC4-DA22-AD4-GA22-AG5-2A20-2A6-CA20-AC6-GA20-AG7-BA18-AB8-BA18-AB9-IA16-AI10-BA16-AB10-DA16-AD11-BA14-AB12-IA14-AI13-GA12-AG14-JA12-AJ14-BA12-AB15-C2A8-2AC16-D2A8-2AD16-G2A8-2AG17-NA8-AN18-CA8-AC19-GA6-AG10-B2A25-ABE2A25-AEF2A25-AFH2A25-AH-MA24-AM2-BA24-AB3-CA22-AC4-PA22-AP4-DA22-AD5-IA20-AI6-CA20-AC6-GA20-AG7-BA18-AB8-BA18-AB9-FA16-AF10-EA16-AE10-BA16-AB11-EA14-AE12-FA14-AF13-HA12-AH14-MA12-AM14-BA12-AB15-C2A8-2AC16-J2A8-2AJ16-D2A8-2AD17-KA8-AK18-CA8-AC19-HA6-AH10-F2A25-A2F2A25-AFB2A25-A2B2A25-AB-BA24-AB2-BA24-AB3-BA22-AB2(4-CA22-AC)5-CA20-AC2(6-BA20-AB)7-BA18-AB8-BA18-AB9-BA16-AB10-IA16-AI10-FA16-AF11-2A14-2A12-BA14-AB13-2(BA12-AB14-)BA12-AB15-B2A8-2AB2(16-C2A8-2AC)17-CA8-AC18-BA8-AB19-BA6-AB10-B3(2A25-A2B)2A25-AB-BA24-AB2-BA24-AB3-2(BA22-AB4-)BA22-AB5-2(BA20-AB6-)BA20-AB7-BA18-AB8-BA18-AB9-2(BA16-AB10-)2BA15-AB11-BA14-AB12-BA14-AB13-2(BA12-AB14-)BA12-AB15-2(B2A8-2AB16-)B2A8-2AB17-BA8-AB18-BA8-AB19-BA6-AB10-B3(2A25-A2B)2A25-AB-GA24-AG2-EA24-AE3-2(BA22-AB4-)BA22-AB5-B2A18-2AB7-BA18-AB8-DA18-AD8-K2A17-AK9-TA16-AT10-BA16-AB10-PA15-2AP11-BA14-AB12-BA14-AB13-2(BA12-AB14-)SA12-AS15-EA9-2AE16-B2A8-2AB17-BA8-AB18-BA8-AB19-B2A5-2AB19-B2A4-2AB20-D8AD10-H2A25-AHB2A25-A2B2A25-AB-CA24-AC2-BA24-AB3-CA22-AC4-EA22-AE4-BA22-AB5-BA20-AB6-R2A18-2AR7-DA18-AD8-2A18-2A8-E3A16-AE9-2BA15-AB10-2DA15-AD10-2MA13-3AM11-H2A12-2AH12-2BA12-A2B13-BA12-AB15-CA10-AC16-BA10-AB16-2C10A2C17-E10AE18-BH8A2B18-2B8A2B19-RB6ABR20-D2B4A2BD21-EBHGH2BD11-H2A24-2AHG2A24-AG2-EA24-AE2-CA24-AC3-GA22-AG4-CA22-AC5-LA20-AL2(6-BA20-AB)7-JA18-AJ9-DA16-AD10-N2A15-AN10-2EA15-AE11-UA14-AU12-DA14-AD12-H2A12-2AH13-2HA11-AH15-BA10-AB16-EA10-AE17-C2A6-2AC18-S2A6-2AS19-C8AC20-E2B3C3BE21-BCFDJC2B22-BCNGDC2B23-2CNKCB25-3CB44-2(BA24-AB2-)LA24-AL3-EA22-AE4-BA22-AB5-EA20-AE2(6-BA20-AB)7-BA18-AB9-2(BA16-AB10-)H2A15-AH11-FA15-F12-DA14-AD13-DA12-AD14-HA12-AH15-BA10-AB16-B2A8-2AB17-K3A4-3AK19-ED6ABE20-BD6ASB21-DB4ABE23-B3C2B25-FDJC26-NGDC104-B2A23-2(AB2-BA24-)AB3-KA22-AK4-BA22-AB5-2(BA20-AB6-)BA20-AB7-BA18-AB9-BA16-AB10-2BA15-AB10-2B2A12-3AB11-2BA12-2AB12-2J2A10-3AJ13-B3A8-3AB14-B3A8-3AB15-B4A4-4AB16-3B8A3B17-BD2B4A4B21-2BGH2B24-2BJM2B25-4B194-2CA22-2AC3-CA22-AC4-BA22-AB4-B2A21-AB5-BA20-AB6-B3A18-AB7-B2A16-2AB8-F3A15-2AF8-F4A13-2AF10-F3A12-3AF11-B3A10-3AB12-B3A10-3AB13-BC2A8-2AFB14-B2G3A4-3AUDB15-BGE8A2DB16-CGB8AMHC17-C2BF4A2BHC20-BFEBEA2B24-2IFB285-D2A20-2AD2(4-CA22-AC)5-HA20-AH7-HA18-AH8-B2A16-2AB9-FBA14-A2B10-EBA14-AFB10-CAB3A10-ABFC11-E2B2A8-2A2BE13-IEL3A4-3ADBI14-HCB3A4-3AN2H16-IC8AEH19-ELB4ABTB21-2BFIF3B22-BFVBEIBP24-GDBF345-I6A13-5AI5-I4A14-4AI6-G4A14-4AG7-G4A12-4AG8-G5A10-5AG9-2B5A6-5A2B12-F14AF14-B14AB15-D12AD17-2B8ARB19-E2B4A2BF20-CEB4ABDG21-E6BK24-4B436-IAO2B15AC3I7-2C2B2A9-3AB3C8-C3B2A10-2A2B2C9-2BDF3A6-3AEK2B10-2BDKC10AG4B11-BDQBFD6AE2CE2B13-F3D2B3C3BELBF14-LHGHBCIDPC5BL15-EJ2BCAGDC4BE19-BOCAIC2B24-O2CB26-B2GB501-C12ABC15-GB9AB2G16-BD10AEB17-BFD6ABCB19-AD2BJM2BGB22-2BG3B672-
