model
size = 31 32 17, scale = 0.05, origin = -y
material deform = 1, fade = true, lighting = smooth, roughness = 0.3, metalness = 0.6
  colors = A:#1A1A1A B:#060606 C:#FFF
voxels
8-15B16-15A16-14AC16-13A2C16-C11A2CB16-2C9A2C2B16-B2C8AC3B16-2B2C7AC3B16-3B2C6AC3B16-4B2C5AC3B16-5B2C4AC3B16-C5B2C3AC3B16-2C4B2C3AC3B17-2C2B2C4AC2B18-ACB2C5AC2B18-2CB2(C6AC2B18-C2B)3(C6AC2B18-3B)C6AC2B17-4B2C5AC3B14-A2C4BC5AC3BCA12-2AC4B2C4AC3BCA12-2AC5B2C3AC3BCA13-A2C5B5C3BC15-A2C7B2C3B16-2A2C8B3C18-A2C7BC20-2A4C4BC21-4A5C49-B15-B2(14-A15-C)14-C2A-12AC14-C5(15AC14-B)2(15AC14-C)15AC14-16A2(C14-15AB)C15-2(14AB16-)2(C13AB16-)C13AB11-4B-B13AB-4B6-4AC15AC4A2(6-25A)7-23A8-23A9-18AC2A12-16AC15-15A17-13A19-10AC22-7B18-B17-B12-A2(17-A12-C)5(17-A12-B)17-A2(12-CA15-2A)2(12-2A15-2A)13-2(A15-A14-)4(A15-C14-)CA13-AC9-B4-CA13-AC4-B4-A4-2A13-2A2(4-A)25-A4-2A23-2A4-3A21-3A5-3A19-3A6-5A15-5A7-4A15-4A10-2A15-2A14-2A11-2A17-2A9-2A20-B7-B16-B19-B10-A2(19-A10-C)4(19-A10-B)2(19-A10-C)5(A17-A12-)A17-A13-4(A15-A14-)A15-A8-B5-A15-A5-B2(2-A27-A)29-2A3-2A23-2A4-3A21-3A4-4A19-4A5-4A17-4A7-4A15-4A11-2(A15-)A13-A17-2B9-2B14-B19-B2(10-A19-A)2(10-C19-A)2(10-B19-A)2(10-C19-A)3(10-2A17-2A)11-2(A17-A12-)A17-A13-4(A15-A14-)A15-A8-B5-A15-A5-B33-A27-A2-A61-3A23-3A3-3A21-3A4-4A19-4A5-4A17-4A8-3A15-3A2(13-A)17-B11-B14-B19-B3(10-A19-A)10-C19-A10-2(C30-)C7(19-A10-A)19-A11-3(A17-A12-)A17-A13-A15-A7-B6-A15-A6-BA28-2A31-A28-2A32-2A25-2A2-3A23-3A3-3A21-3A5-4A17-4A7-4A15-4A11-2A14-A16-B12-B13-B19-B2(10-A19-A)10-A30-A2(19-A10-C)2(30-A)19-A30-5(A10-A19-)A2(10-2A17-2A)11-2(A17-A12-)2A15-2A6-B6-A15-A6-BA28-2A31-A28-2A32-A26-2A2-2A25-2A3-2A23-2A4-3A21-3A6-2A19-2A10-2A15-2A14-2(B13-)B19-B2(10-A19-A)10-2(A30-)2(A19-A10-)A81-5(A10-A19-)A3(10-2A17-2A)11-A17-A12-2A15-2A6-B5-2A15-2A5-B2(A28-2A31-)A28-2A-A26-2A2-2A25-2A3-2A23-2A5-3A19-3A9-2A15-2A14-2(B13-)B19-B3(10-A19-A)10-2(A30-)A19-A30-A41-A30-A19-A30-3(A10-A19-)A4(10-2A17-2A)10-3A15-3A5-B5-2A15-2A5-B2(A28-2A31-)A28-2A-A26-2A2-2A25-2A3-2A23-2A5-3A19-3A9-2A15-2A14-2(B13-)B19-B4(10-A19-A)2(10-A81-A10-A19-A)2(10-A19-A)3(10-2A17-2A)11-A17-A12-2A15-2A6-B5-2A15-2A5-BA28-2A31-A28-2A32-A26-2A2-2A25-2A3-2A23-2A4-3A21-3A6-2A19-2A10-2A15-2A14-2(B13-)B19-B4(10-A19-A)30-A41-A30-A19-A30-A41-4(A19-A10-)2A17-2A10-2A17-2A11-2(A17-A12-)2A15-2A6-B6-A15-A6-BA28-2A31-A28-2A32-2A25-2A2-3A23-3A3-3A21-3A5-3A19-3A7-4A15-4A11-2(A15-)2(B13-)B19-B6(10-A19-A)10-A81-5(A10-A19-)A11-3(A17-A12-)A17-A13-A15-A8-B5-A15-A5-B33-A27-A2-A27-A33-3A23-3A3-3A21-3A4-4A19-4A5-4A17-4A8-3A15-3A2(13-A)17-2B9-2B14-B19-B8(10-A19-A)3(10-2A17-2A)11-3(A17-A12-)2A15-2A12-2A15-2A13-2(A15-A14-)A15-A8-B5-A15-A5-B2(2-A27-A)34-2A23-2A4-3A21-3A4-4A19-4A5-4A17-4A7-4A15-4A11-2A13-2A16-2AB7-B2A45-B19-B10-3(A19-A10-A30-)A19-A10-A19-A11-5(A17-A12-)A17-A13-4(A15-A14-)A15-A9-B4-A15-A4-B2(4-A25-A)4-2A23-2A4-3A21-3A5-3A19-3A6-4A17-4A7-4A15-4A10-2A15-2A14-3AB7-B3A76-B17-B2(12-A17-A)3(12-A30-A17-A)12-2A15-2A29-2(2A12-2A15-)2A13-2(A15-A14-)3(2A13-2A14-)2A13-2A15-A13-2A10-3B2-A13-A2-3B3(6-3A19-3A)7-2A19-2A8-4A15-4A9-3A15-3A12-2(A15-)4AB5-B4A108-2B13-2B2(14-2A13-2A)14-2A29-2A13-2A14-A30-A14-2A45-2A13-2A14-A14-2A29-2(2A14-2A13-)2A2(14-3A11-3A)15-4(2A11-2A16-)2A12-A14-3BA11-A-2B11-4A13-A-2A2(10-3A15-3A)11-2A15-2(2A13-)2A15-5AB3-B5A16-4AB5-B4A141-13B18-13A18-10A2-A18-12A19-11A-A18-12A19-A-8A2-A18-A-10A20-12A18-13A18-5A-7A18-2A-A-8A18-2(A-)9A18-2A-10A2(18-13A)18-9A-3A18-7A2(-2A)18-8A-2A-A18-9A-2A19-10A-2A17-12A-2A15-17A14-8AB8A15-6AB-B6A17-4AB3-B4A195-
