model
size = 11 22 14, scale = 0.05, origin = -y
material deform = 1, fade = true, lighting = smooth, roughness = 0.3, metalness = 0.6
  colors = A:#5C5C5C B:#272727
voxels
14-10(4A7-)4A29-4A7-4A195-B-B2(239-A-A)118-11(3A8-)A-A19-3A8-3A83-10(7A4-)7A6-A-A6-2(7A4-)7A7-A10-A61-10(9A2-)9A4-5A4-2(9A2-)9A5-3A8-3A60-10(9A2-)9A3-7A3-2(9A2-)9A4-5A6-5A8-A10-A38-121A2-7A3-9A-22A2-7A4-7A6-3A8-3A9-A10-A16-121A2-7A3-9A-22A-9A2-9A4-5A6-5A7-3A8-3A9-A5-121A2-7A3-9A-22A-8A3-8A6-3A8-3A9-A10-A16-10(10A-)10A3-7A3-9A2(-10A)3-6A5-6A8-A10-A39-10(9A2-)9A4-5A4-2(9A2-)9A4-4A7-4A60-10(8A3-)8A15-6A5-7A4-7A6-2A9-2A60-
