model
size = 25 24 22, scale = 0.05, origin = -y
material deform = 1, fade = true, lighting = smooth, roughness = 0.3, metalness = 0.6
  colors = A:#EEE B:#9FF C:#FF3 D:#555 E:#0E0 F:#777 G:#00E H:#D00 I:#0F3
voxels
28-C7-3C7-2(C6-C17-)C256-2(C17-C6-)C17-C180-21A8-2(13A12-)2A9-2A12-2A4-I4-2A12-2A2-G3-H2-2A12-2A2-H3-G2-2A12-2A2-G-I-H2-2A12-2A2-H3-G2-2A12-2A2-G3-H2-2A12-2A4-I4-2A2(12-13A)283-21A5-3(19A6-)19A7-11(17A8-)17A181-21A5-7(19A6-)19A7-7(17A8-)17A122-F58-21A5-13(19A6-)19A7-17A8-17A9-15A23-F24-F23-2F24-F24-2F23-F8-21A14(4-2A17-2A)5-A17-A7-17A9-15A148-F8-21A2(4-2A17-2A)4-10(2A17-3A3-)2A17-2A4-2A17-2A5-A17-A7-17A9-15A157-21A2(4-2A17-2A)3-8(3A17-3A2-)3A17-3AE-3A17-3A3-2A17-2A4-2A17-2A5-A17-A7-17A9-15A12-11A134-21A2(4-2A17-2A)3-2(3A17-3A2-)5(3A17-4A-)3A4(17-4AE3A17-3AE-3A17-3A3-2A17-2A4-2A17-2A5-A17-A7-17A9-15A12-11A134-21A2(4-2A17-2A)3-3A17-3A2-3A17-3A-4A5(17-8A))17-4AE3(3A17-3A2-3A17-3A3-2A17-2A4-2A17-2A5-A17-A7-17A9-15A12-11A134-21A2(4-2A17-2A)3-3A17-3A2-3A17-3A-4A5(17-8A)17-4A-)3A17-3A2-3A17-3A3-2A17-2A4-2A17-2A5-A17-A7-17A9-15A12-11A134-21A2(4-2A17-2A)3-9(3A17-3A2-)3A17-3A3-2A17-2A4-2A17-2A5-A17-A7-17A9-15A16-3D138-21A2(4-2A17-2A)3-9(3A17-3A2-)3A17-3A3-2A17-2A4-2A17-2A5-A17-A7-17A9-15A16-3C138-21A2(4-2A17-2A)3-9(3A17-3A2-)3A17-3A3-2A17-2A4-2A17-2A5-A17-A7-17A181-21A14(4-2A17-2A)5-A17-A7-17B181-21A14(4-2A17B2A)5-A17BA7-17B182-D7-3D7-2(D6-D17B)D7-9(17B8-)17B7-2(D17BD6-)D17BD203-
