model
size = 27 22 16, scale = 0.05, origin = -y
material deform = 1, fade = true, lighting = smooth, roughness = 0.3, metalness = 0.6
  colors = A:#111 B:#CF6
voxels
40-A776-3B7-3B2(14-3A7-3A)14-AB2A5-2ABA14-2AB2A3-2AB2A15-A2BA3-A2BA17-3A3-3A420-A3B7-3BA12-4A7-4A12-B3A7-3AB12-B4A5-4AB12-B5A3-5AB12-B13AB12-B5A3-5AB12-BA2(11-AB)A11-ABA10-2BA11-A2B2(10-2A13-2A)253-3B11-3B8-3B2A5-B5-5B7-2(4A5-A5-4A8-4A5-B5-4A8-)4A5-A5-4A8-4A11-4A8-2B2A11-2A2B8-4A11-4A8-B3A11-4A8-3A13-3A8-B2A13-2AB9-BA13-AB10-2B13-2B195-2B2-2A13-2A2-2B2-6A6-A6-6A-B6A6-A6-6A2(2B2AB3A13-3AB2A)B-2AB3A13-3AB2A2-6A13-6A3(2-B4A15-4AB)3-B3A15-3AB4-B3A15-3AB5-2BA15-A2B8-2A13-2A10-AB13-BA167-2B23-3B2A2(10-A)3B3A9-B9-5(3A2B3A19-)3AB-2(B2A19-2AB2-)B2A19-2AB3-2B19-2B89-B13-B181-2(A26-A539-A26-B539-)A26-A509-BA3-AB23-A26-B536-A-BAB-A23-A563-B5-B588-A3-A590-B-B579-
