model
size = 32 32 21, scale = 0.05, origin = -y
material deform = 1, fade = true, lighting = smooth, roughness = 0.3, metalness = 0.6
  colors = A:#036 B:#EEE C:#DDD D:#06C E:#AAA F:#111 G:#39F H:#BBB
voxels
972-8B24-8B984-8B24-8B655-2(2B23-B6-)2(2B22-2B6-)2B4-14A4-2B6-2B4-14A4-2B5-3B4-14A4-3B3-4B4-14A4-4B-5B4-14A4-10B4-14A4-9B8-2B4A2B8-7B9-8B9-3B643-2(5B20-B6-)5B16-5B6-2B3A16-2(3A2B6-2B3A-14A-)3A2B5-3B22A3B3-4B22A4B-5B-2A-14A-2A-10B2-18A2-9B7-3B4A3B7-7B8-10B8-3B42-12A19-2(2A10-2A18-)2A10-2A17-5(3A10-3A16-)BA12-AB15-8(2BA12-A2B14-)2BA12-A2B11-5B14A2B11-4B-14A13-4B-14A-4B8-B22AB8-B3A-14A-3AB7-2B3A-14A-3A2B5-3B3A-14A-3A3B3-4B3A-14A-3A4B-5B-2A-14A-2A-10B2-18A2-9B4-6B4A6B4-7B7-12B7-3B11-A8-A22-10A20-2(3A8-3A18-)3A8-3A17-3(4A8-4A16-)3A10-3A16-3A-8A-3A16-2A12-2A15-B2A12-2AB7(14-2BA12-A2B)14-2B14A2B10-3(26B6-)2B22A4(2B6-2B3A-14A-3A)2B6-2B-2A-14A-2A-2B6-2B2-18A2-2B11-6B4A6B18-12B21-A8-A22-10A20-2A10-2A17-6(3A10-3A16-)A2B10A2BA2(16-16A)15-2(2B14A2B14-)2B14A2B13-BC-14A-CB11-3(2BC-14A-C2B10-)2BC-14A-C2B9-3(24B8-)B22AB8-B22AB7-2B22A2(2B6-2B-20A-)2B4-4B-2A-14A-2A-2(4B2-)18A2-4B10-B12AB20-10B54-A3-2A3-A21-12A18-3(16A16-)3(4A8-4A16-)A2BA8BA2BA16-A2B-8B-2BA16-A14BA16-A2(4B-)4BA16-A4B-B2-B-4BA15-2A4B-B2-B-4B2A14-C5B-B2-B-5B4(C14-C7B2-7B)C11-2(4C7A2-7A4C8-)4C6A4-6A4C8-C3A6B4-6B3AC8-4A16B4A7-BC3A16B3ACB6-BC-2A16B2A-CB6-BC3-2A12B2A3-CB4-3BC3-2A12B2A3-C3B2-3BC5-12A5-C3B10-B12AB20-10B23-8A23-10A22-10A20-14A17-2(16A16-)3(4A8-4A16-)A2BA8BA2BA16-A2B-2B4A2B-2BA16-16A15-18A14-8A2B8A13-9A2B9A13-5(8A2B8A14-)2(18A14-)18A12-9A4B9A2(10-22A)11-20A16-12A18-A-12A-A18-12A20-12A21-10B23-8A23-10A22-10A21-12A18-2(16A16-)3(4A8-4A16-)A2B-3B2-3B-2BA16-A2B-2B4A2B-2BA16-16A15-2(18A14-)18A12-22A12-4(18A14-)18A13-20A13-18A12-2(22A10-)22A11-20A16-3(12A20-)12A22-8B24-3A2-3A23-2(4A2-4A22-)10A20-3A8B3A17-4(4A8-4A16-)A2B-2B4-2B-2BA16-A2B-2B4A2B-2BA3(16-16A)15-8(18A14-)18A12-2(22A10-)22A11-20A16-3(12A20-)12A21-10B23-A6-A23-3A4-3A22-A-6A-A22-2A6-2A22-A8BA19-4(4A8-4A16-)A4B6-4BA16-A2B-2B4A2B-2BA16-16A14-2B16A2B14-16A15-18A15-16A15-18A13-20A12-20A13-3(18A14-)18A12-2(22A10-)22A11-20A16-3(12A20-)12A21-10B24-6A24-10A19-3B-8A-3B16-3B10A3B16-3BA8BA3B14-4B2A8-2A4B3(12-2B4A8-4A2B)11-3BA4B6-4BA3B8-5BA2B-2B4A2B-2BA4(5B6-5B16A)5B7-4B16A4B11-6(18A14-)18A12-22A10-22A11-20A12-20A16-3(12A20-)4A4B4A21-3B4-3B24-6A24-10A19-C2E10A2EC16-C2E2A-4B-2A2EC16-C2EA8BA2EC14-E2C2EA2B4-2BA2E2CE2(12-4E2A8-2A4E)12-EB4A8-4ABE11-2EBA4B6-4BAB2E8-4EBA2B2-B4AB2-2BAB4E6-2E3B16A3B2E3(6-5B16A5B)7-4B16A4B12-16A15-5(18A14-)18A12-22A10-22A11-20A12-20A16-3(12A20-)12B85-10A21-CA-6A-AC20-C2A6-2AC20-CA8BAC20-CA2(2B-)2BAC2(20-2A8-2A)18-A-2A8-2A-A15-2A3B8-3B2A14-2A2B-2B4A2B-2B2A14-18A10-2(4B18A4B6-)2B22A2B7-B22AB9-8(22A10-)22A11-20A12-AD16ADA12-20A13-18A16-14A23-4B60-4A25-10A2(22-D8AD)22-D8BD22-D2(2B-)2BD85-2B8-2B17-18B14-2A5B4A5B2A12-22A8-2(2B22A2B6-)2B22A2B7-B22AB9-22A12-18A16-14A19-12A21-2(10A22-)10A16-A5-10A5-A10-2B4-10A4-2B11-2B2-12A2-2B14-D-12A-D17-14A18-14A20-10A25-4B60-4A26-3(8A24-)A6BA86-C10-C20-2B8-2B17-18B14-7B4A7B12-22A8-2B3A-14A-3A2B6-2B22A2B6-3B20A3B7-B22AB9-4(22A10-)22A11-20A12-B18AB14-16A15-18A15-16A17-2D10A2D19-12A22-8A26-4B92-4A27-6A26-6A25-A6-A80-2B20-2B9-2B3-C3(-2B)-C3-2B11-3B-12B-3B13-18B14-7B4A7B12-3A2B12A2B3A8-2B22A2B6-2B2AB16AB2A2B6-4B18A4B7-3B18A3B9-2B3D12A3D2B10-B20AB11-20A12-2A2G12A2G2A13-18A13-B18AB12-2B16A2B14-7A2D7A17-5AD2AD5A17-2B3AD4AD3A2B19-2D6A2D25-4A29-2B125-2(A2DA28-)4A114-2B20-2B9-2B3-C10-C3-2B11-3B-12B-3B13-3B12C3B14-3BC10DC3B12-3AD14AD3A10-2A3B3A6B3A3B2A10-AD3B3A2C2B2C3A3BDA9-7BD2AD2BD2AD7B8-7B2D2A2B2A2D7B9-2B3-2A-DC2BCD-2A3-2B10-B2-C2(2B4C)2BC2-B12-C2B2F8B2F2BC14-BH2F3B-2C-3B2FHB14-B2F3B-A2BA-3B2FB14-2(4B3-)4B13-4B3-6B3-4B18-3B2-3B23-3B4-3B21-3B6-3B593-3B4-4B4-3B14-3B5-2B5-3B13-2(2B7-)2B21-2B926-2B30-2B591-
