model
size = 16 14 32, scale = 0.05, origin = -y
material deform = 1, fade = true, lighting = smooth, roughness = 0.3, metalness = 0.6
  colors = A:#000 B:#0040FC C:#CCC
voxels
38-4A4(11-5A)12-3A108-6A5(9-7A)10-6A121-8A10(7-A)8-8A10-4B12-4B13-2B74-10A5(5-A9-A)6-7AB2A7-7B9-7B10-6B10-5B13-B42-11A5-4(A10-A4-)A3-2A-A3-A4-8A2BA7-2(B5-2B8-)2B4-2B8-3B-3B10-5B12-3B14-B10-12A4(3-A11-A)3-A2-7A2-A4-8A2B2A5-2(2B6-B7-)2B5-2B8-B5-2B8-2B3-2B10-6B10-5B8-12A3(3-A11-A)3-A3-2(2A2-)A3-A2(2-3A)-A3-10AB2A5-2(B7-2B6-)2B6-B7-2B5-2B8-B5-2B8-2B4-B22-13A3(3-A11-A)3-A2(2-3A)-A3-A-3A4-4A3-11ABA5-2(B7-2B6-)2(B7-)2B6-B7-2B5-2B8-B28-13A3-3(A12-A2-)A-4A2-3A2(2-A)-2A6-2A-A2-13A4-2B8-B2(6-B7-2B)6-2(B7-)2B5-2B37-13A3-2(A12-A2-)A3-A4-A3-A2-A-3A4-3A-A2-3A8-A-A2-3A6-4A4-B9-B5-2B2(7-2B6-B)6-2B7-B6-2B37-13A3-2(A12-A2-)A2-2A5-2(A2-)A-3A4-3A-A2-3A8-A-A2-3A8-BA4-B9-B5-2B7-2B5-2B2(7-B)6-2B7-B6-2B37-13A3-2(A12-A2-)A-3A4-3A-A2-A-2A6-2A2(-A)-2A8-3A2-3A8-B2A3-B9-B5-2B7-2B5-2B2(7-B)6-2B7-B6-B38-13A2-2(A13-A-)A2-3A5-2A2(-A)2-A8-3(A-)2A8-3A2-8A3-B2A3-B9-B5-2B7-2B5-2B7-B2(6-2B)7-B6-2B36-15A-A13-A-A3-A9-A-A2-2A6-2A2(-A)2-A8-3A-A-2A8-3A-15A3-B9-B5-B8-2(2B5-2B7-)B7-B6-2B7-B28-15A-A13-A-A3-A9-A-A2-2A7-2(A-)A2-A8-3A-A-2A8-3A-15A3-2(B9-B5-)2B7-2B5-2B2(7-B)6-2B7-B6-B21-15A-A13-A-A2-2A7-2(A-)A2-2A7-3A-A2-A8-3A-A-2A8-2(A-)15A3-B9-2B4-B9-B5-B8-2B5-2B7-2B6-B6-2B7-2B5-B21-15A-A13-A-A2-2A7-2(A-)2(A2-A8-3A-)A-2A8-2(A-)12AB2A2-2B9-2B3-2B9-2B4-B9-B5-2B7-2B6-2B4-3B8-2B3-2B21-15A-A14-2(2A2-A8-2A-)2A2-2A7-A2-2A-2A8-A2-14ABA2-2(2B9-2B3-)2B9-2B4-2B7-2B6-9B8-7B11-B-B7-17A14-2A2-A9-A-2A2-2A7-2A-2A2-2A7-A2-2A-2A8-2A-14AB2A-2(2B10-B3-)2B9-2B4-2B7-2B6-BC7B8-CA4BC10-5A6-17A14-2A-2A9-A-2A2-3A5-3A-2A2-2A7-A2-2A-2A8-2A-17A-2B10-2B2-2B10-B3-2B9-2B4-3B5-3B6-9B9-2B-3B21-17A14-2A-2A2-5A2-4A2-11A-2A2-2A6-2A2-2A-2A8-2A-14AB2A-2B10-2B2-2B10-B3-2B9-2B4-4B4-3B7-8B8-CAB-BAC10-5A6-17A2(14-2A)3-8A3-2A2-3A4-3A2-2A-2A8-2A-14AB2A-2B10-2B2-2B10-B4-B9-2B4-5B2-4B7-8B9-2B-3B21-17A2(14-2A)4-7A3-2A2-4A3-3A2-2A-2A8-2A-14AB2A-2B10-2B2-2B10-B4-2B8-2B5-10B7-C5BC10-5A22-17A2(14-2A)4-6A4-2A2-10A2-2A-3A7-2A-A-14A2-2B10-2B3-B10-B4-2B7-3B5-9B9-6B38-14A2-2(A13-A-)A4-5A4-A-A2-9A-A2-A-2A7-3A2-14A3-B10-B4-2B8-2B5-2B6-2B7-6BCB8-CA3BAC10-5A23-14A2(2-A12-A)2-A5-3A4-2(A2-)8A2(2-A)-2A6-2A-A3-10A2BA3-2B8-2B4-2B8-B6-AB5-2BA7-8B10-B-B41-12A4-A11-A3-2(A10-A4-)A-8A-A4-4A5-3A4-12A5-B8-B6-B7-2B6-A3B2-3BA8-6B56-10A5-3(A10-A4-)A2-6A2-A4-A-3A3-4A5-10A4(6-2B)7-A6BA9-5B57-10A3(6-A8-A)6-A2-5A-A6-10A6-8ABA2(6-2B)8-B4-2B9-A4BA12-2B59-8A7-3(A8-A6-)A3-2A3-A6-A-6A-A7-8A8-2B4-2B8-3B2-2B11-A2BA74-7A9-4(A6-A8-)A-4A-A8-8A9-6B10-5B13-2A76-5A11-A4-4(A9-A5-)A10-6A11-4B13-2B87-
