model
size = 25 32 27, scale = 0.05, origin = -y
material deform = 1, fade = true, lighting = smooth, roughness = 0.3, metalness = 0.6
  colors = A:#09F B:#C03 C:#36C D:#939 E:#C06 F:#66C G:#39F H:#909 I:#C09 J:#0CF K:#906 L:#63C
voxels
237-2A21-B2A2BA18-5B2AB16-B2A2B2AB2A15-2A2BH2B2ABA13-2AB3A2BA3B13-2BE2A19-A2BA21-EGA22-3A2(22-2A)B22-GBA23-B355-BA22-4B21-AD2BA18-B2A5B16-BCA2BA3BA15-4B2A2B3A13-2AB7ABA13-AE7A3B13-DB7A-A2B11-2B8A-B2A11-B9AK3B10-B6A7-B9-6A19-5A20-2B3A20-AE2A21-4A21-B3A22-BA23-2A24-AB201-B2A5B17-3B2A3B17-2BIAE2BA17-5B3A16-BAF2B2A3B15-2AB4A4B13-E2AB5ABDB13-2B7ADBD13-B8A-2B12-AB4A2-2A3-B11-B3A9-A10-B3A10-A-BA7-F2A11-3B7-HB2A11-2BHB6-ABA12-2HAH6-B2A12-2ABA5-B2A14-BAB5-3A16-A5-3A16-2A4-ABA16-2A4-2B17-2B4-B2A16-2B4-3A16-2A5-B2A15-2A6-3A14-2B7-BA14-A8-3A13-A9-CBG12-B10-2BA11-B11-D3A6-3A14-3AB2AD3AD16-2ACDB14-2B10A13-2B8ABA13-BF7ABIB13-AC7A-BI13-5A2-2A2-B13-B3A4-A3-B12-4A8-B12-2A10-AB9-3A11-2ABA7-3A12-3B6-3A13-BAB6-B2A13-ABA6-B2A13-4B4-2BA14-4B4-B2A14-BA2B3-3A15-4A3-BAB15-AB2A3-ABA17-2B3-3A17-2A3-BAB17-2A3-3B17-2B3-ABA17-2B4-2A17-3A3-3A16-2A6-2A15-2A7-2A14-2B7-3A13-2A8-3A12-2G9-3A11-B11-4A5-3DAD12-12A15-7A-A9-BC2A8-A2L10-4A8-B2A10-AB2A8-3B10-B3A9-2B9-FB2A10-3B8-3BA11-2FBF6-3B12-4B6-A2B12-2BAB5-4A12-4A5-ABA16-A4-3BA16-B4-3B17-2B3-ABA17-2B3-BAB17-2A3-ABA17-2B2(2-4A17-2A)2-2(AB)17-2A2-4B17-2B2-2(BA)17-2B3-3A17-2A3-BAB17-3A2-ABA17-BAB3-3A16-3A3-2A-A15-3A5-A-A14-2D7-2A14-2B8-2A13-2A9-2A12-A10-4A7-4A12-12A15-F4AL3A8-B2A12-BL8-B2(2A12-2B7-2B)2A12-2B7-B3A12-2BAB2(5-4A12-4A)5-AB2A12-2ABA3-2(BC)14-2BCB3-2(CB)17-C3-4B17-B4-3B17-2B3-ABA17-2B2-4A17-2A2-2(AB)17-2A2-2(BE)17-2B2-2(EA)17-2E2-2(AB)17-2A2-4B17-2B2-2(BA)17-2B2-4A17-3A2-3A17-3A2-BAB17-3A2-ABA17-BAB3-3A16-3A5-2A15-3A6-2A14-2B7-A-A13-2B8-A-A12-2A9-B-BA7-4A11-2B-3A3-4A14-6AB3A8-BA13-2FB6-2BA15-B5-FBFA15-F5-CFCA15-C5-BCB16-BC4-ABA16-AB4-3A16-2A4-BAB16-BA3-4B16-2B3-4B17-B3-2(BA)17-2B2-2(AE)17-2A2-2(EB)17-2E2-2(BA)17-2B2-4A17-2A2-2(AB)17-2A2-4B17-2B2-2(BA)17-2B2-4A17-3A-2(AB)17-3A-2(BA)17-BAB-4A17-3A2-3A17-3A2-BAB17-3A3-B2A16-BAB5-2A15-CAC6-2A14-2A7-3A13-2A8-3A12-2C9-4A7-4A11-5A4-3A15-2AK2ABF2B7-BAB15-2B5-2(3B17-B4-)ABA17-B4-3A17-A3-2(AB)17-A3-2(BE)17-B3-2(EB)17-E2(3-4B17-B)3-2(BA)17-2B2-4A17-2A2-2(AD)17-2A2-2(DB)17-2D2-2(BA)17-2B-2ABAB17-2A2-4B17-2B2-2(BG)17-BAB2GAGA17-GAG-4A17-3A-2(AB)17-3A-2(BA)17-BAB2-3A17-3A2-DAD17-3A2-BD2A16-DAD5-2A15-BAB6-2A14-2A8-A14-2A23-2A78-CA16-BC5-ACA17-C3-2(AB)17-A3-2(BA)17-B3-4A17-A3-2(AB)17-A2(3-4B17-B)2-2BABA17-B2-5A17-A3-2(AB)17-2A2-2(BA)17-2B-5A17-2A-2ABAB17-2A-5B17-2B-2BABA17-2B-5A17-2A-2AEAE17-3A2EAEA17-EAE5A17-3A-4A17-3A-2(AB)17-3A-4B17-BAB2-ABA17-BAB2-4A16-3A23-A24-B24-A103-BA18-C3-BAB18-B3-3A18-A3-ABA18-A4(3-3B18-B)2-2BAB18-2B2(-4A18-2A)-2ABA18-2A-2BFB18-2B-2FBF18-2F2(-4B18-2B)-2BAB18-2B-4A18-5ABA18-3A2BEB18-BAB-EAE18-EAE-AGA18-3A-GBG18-GAG2-AB18-BAB2-2A18-3A23-2(A24-)B103-BA18-B3-BE19-B3-EA19-E3-AC19-A3-CB19-C2-3B19-B2-2BA19-B2-3A19-A2-2AB19-2A-2BA19-2B-3A19-2A-2AB19-2A-3B19-2B-2BA19-2B-3A19-JA-3A19-2A-2AC19-3A2CA19-CAC3A19-5AB19-3A3B19-BAB-BA19-BAB-2A19-3A2-B19-3A22-BAB23-2(A24-)A103-A19-B3-AB19-A3(3-2B19-B)2-3B19-B2-2BA19-B2-3A19-A2-3A19-2A-2AB19-2A4(-3B19-2B)-2BA19-2B-3A19-2A-2AG19-2A-2GB19-GAG2BC19-BAB2CA19-CAF2AB19-3A-BA19-BAB-2A19-3A2-A19-3A22-3A23-B2(24-A)103-A19-A3-2A19-A2-2AB19-A2-3B19-B2-2BA19-B2-3A19-A2-2AB19-A2-2BA19-B2-3A19-2A-2AB19-2A-3B19-2B-2BA19-2B2(-3A19-2A)-2AB19-2A-2BA19-2B-3A19-2A-2AB19-3A3B19-BA3BA19-BAB3(-2A19-3A)2-A19-3A22-3A23-A24-B24-A103-B19-A3-2B2(19-B2-3B)19-B2-2BE19-B2-2EA19-E2-3A19-A2-2AB19-A2-2(3B19-2B-)2BC19-2B-2CB19-2C-2BA19-2B2(-3A19-2A)-2AB19-2A-2BD19-2B-2DA19-DAD2AC19-3A2CA19-CAC2(-2A19-3A)-AE19-3A2-K19-EAE22-KAK23-2(A24-)B103-B19-B3-2B19-B2-2BA19-B2-3A19-A2-2AB19-A2-2BC19-B2-2CA19-C2-2AF19-A2-2FB19-2F-2BE19-2B-2EA19-2E-3A19-2A-2AB19-2A-2BA19-2B-3A19-2A-2AB19-2A-3B19-2B-2BA19-BAB3A19-6A3(19-3A-2A)19-3A2-B19-3A22-BAB23-2(A24-)A103-D19-B3-DB19-D3-2B19-B3-BA19-B3-2A19-A2-2AB19-A2(2-3B19-B)2-2BA19-2B-2AB19-2A-2BA19-2B2(-3A19-2A)-2AB19-2A-3B19-2B-2BA19-2B-3A19-2A-2AE19-3A2EA19-EAE3A19-6A19-3A-AB19-3A-BA19-BAB2-A19-3A22-3A23-2(A24-)A103-2A18-D2(3-2A19-A)3-AB19-A3-BA19-B2-3A19-A2-2AB19-A2-3B19-B2-2(2BA19-2B-3A19-2A-2AB19-2A-)3B19-2B-2BA19-2B-3A19-6A19-5AD19-3A2DA19-DAD3A19-3A-AB19-3A-2B19-BAB2-A19-BAB22-3A23-2(A24-)A103-BA18-A3-BAB18-B3-3A18-A3-ABA18-A2(3-3B18-B)3-BAB18-B3-ABA18-A2-2BAB18-B2-2(4A18-2A-)2ABA18-2A-4B18-2B-2BAB18-2B-4A18-2A-2ABA18-2A-2BAB18-2B-4A18-7A18-5ABA18-3A-BGB18-BAB-GAG18-GAG-3A2(18-3A2-2A)18-3A23-2(A24-)L103-3A15-BAB4-BAB17-A3-2(BA)17-B3-2(AJ)17-A3-2(JB)17-J3-4B17-B3-2(BA)17-B3-4A17-A2-2ACAC17-A2-2CACA17-C3-4A17-2A2-2(AB)17-2A-5B17-2B-2BABA17-2B2(-5A17-2A)-2ABAB17-2A-2BABA17-BAB5A17-5ABAB17-3A-4B17-BAB-2(BA)17-BAB-4A17-3A2-3A17-3A2-4A16-3A23-K2(24-A)24-B78-3A15-BA5-CAC17-A4-BCB17-C4-3B17-B4-ABA17-B3-2(AC)17-A3-2(CD)17-C3-2(DA)17-D3-4A17-A3-2(AB)17-A3-4B17-2B2-2(BA)17-2B2-4A17-2A2-2(AB)17-2A2-2(BA)17-2B-5A17-2A2-4A17-2A2-2(AB)17-3A2BDBD17-BAB-2(DA)17-DAD2(-4A17-3A)2(2-3A17-3A)2-4A16-3A5-KA15-3A6-2A14-2B8-A14-2A23-2A80-2A13-B2A6-3A14-2A5-2(BA)14-ABA4-3B15-3B4-ABA15-BAB2(4-3A15-3A)4-BAB15-ABA3-2(BA)15-BAB3-2(AC)16-CA3-2(CB)16-BC3-2(BA)17-2B2(2-4A17-2A)2-2(AD)17-2A2-2(DA)17-2D2-4A17-2A2-2(AD)17-2A2-2(DB)17-DAD-2(BA)17-BAB2(-4A17-3A)2-FAF17-3A2-AFA17-FAF3-3A16-3A5-2A15-3A6-2A14-2C7-A-A13-2A8-3A12-2A9-4A7-4A11-5A5-2A15-AB7A9-B4A8-3BA8-B4A8-4B7-B5A8-A3B7-5A10-3A7-AB3A10-3A7-B3A12-2BAB5-5A11-4A4-2(HA)15-HA4-BHBA15-BH3-2(BA)16-AB3-4A16-2A4-3A17-2A3-3A2(17-2A2-4A)17-2A2-2(AB)17-2A2-4B17-2B2-2(BA)17-2B2-4A17-2A2-2(AB)17-2A2-2(BA)17-2B3-2(3A17-3A2-)BAB17-3A3-B2A16-BAB5-2A15-3A6-2A14-2A7-A-A13-2A8-B-A12-2A9-A-2A6-5A11-2A-3A3-3AF14-AB3AFA3F10-B4A6-B2A11-ABC2A6-3B11-2AB2A6-A2B10-2BJ2A7-3A9-2A2BA9-2A9-2(BA)10-2A2BA6-AB2A10-3BAB6-ABA14-2A5-AB2A14-BA5-2BA15-2B4-AB2A15-AB4-4A16-3(2A3-3A17-)2A2-4A17-2A2-2(AB)17-2A2-2(BA)17-2B2-4A17-2A3-3A17-2A3-EAE17-2A3-AEA17-EAE2-3A17-3A3-3A16-3A3-2A-A15-3A5-A-A14-2F7-BA14-2A8-2A13-2A9-BA12-A10-3FA6-5A12-F6A-4A15-5AF3A13-AB7A16-AB8A15-B7ABA14-2B6ABAB14-8A-2A13-B8A-GA14-3A4-A2-2G11-B3A9-2B10-3A10-2A9-3A11-2A8-ABA12-3A7-2AB12-4A6-3A12-5A5-BA15-B2A4-2BA15-3B3-ABA16-A2B5(3-3A17-2A)3-BAB17-2A4-BA17-2B4-3A16-2A6-3A14-2A7-2A14-2A7-3A13-2A8-3A12-2A9-B2A11-A11-4A5-3A2F12-6ABA3BA15-7A17-B2ABA20-B3AB20-AB2ADG18-3AB2A2B16-AB3ABGBA15-C2ABGADB2A15-D8AIA13-2AB6AI2B13-C8ABAB13-4A3-2A-3A11-5A4-A-3A11-B3A7-H2A10-AB2A8-A2H2A8-B2A13-2A6-IB2A13-IA6-3A14-AI5-4A15-A5-3A16-A5-ACA16-A5-C2A16-2C2(4-3A16-2A)5-BA16-2A5-3A15-2B6-3A14-2A7-2A14-2A7-ABA13-A9-2A13-A10-AB2(A11-)5A5-2AF13-AB8A18-F4A144-GA22-ABIA20-H2AB3A17-A2B2(2AB)15-BC5A2BA15-2B9A13-B9ABA13-B8A3B12-10A-A3B10-10A-4A9-AB5A6-3A9-5A20-4A21-D3A20-4A21-4A22-B2A22-BA23-2A24-A429-B2A22-4A20-3AHB2A17-5AB2AB15-B3AB5AB14-AD2ABI5A13-3ABA20-B2AB20-2AB22-2AD22-2B23-GB23-2A23-A243-
