model
size = 5 32 14, scale = 0.05, origin = -y
material deform = 1, fade = true, lighting = smooth, roughness = 0.3, metalness = 0.6
  colors = A:#808080 B:#949494 C:#525252 D:#303030 E:#000 F:#646464 G:#121212 H:#767676 I:#242424 J:#D0D0D0 K:#BEBEBE L:#ACACAC M:#888 N:#4B4B4B O:#404040 P:#FFF Q:#E2E2E2
voxels
3-E128-4(E4-)E129-Q159-2(J14-)J129-2(K14-)K129-2(L14-)L124-A8(4-B)114-A9-2(M14-)M9-21(A4-)A3-AN3(A-)3AN2A2-P9-H14-H4-H114-A9-F14-F9-2(F4-)F119-A6(4-C)9-C139-O19-O124-5(D4-)D9-D139-2(I9-)I139-2(G9-)G2-
