model
size = 25 32 27, scale = 0.05, origin = -y
material deform = 1, fade = true, lighting = smooth, roughness = 0.3, metalness = 0.6
  colors = A:#55CDFC B:#F7A8B8 C:#EEE
voxels
237-2A21-6A18-8A16-10A15-11A13-12A13-5A19-4A21-2(3A22-)2A2(22-3A)23-A355-2A22-4A21-5A18-8A16-10A15-11A13-12A13-5A-7A12-4A5-4A11-4A7-4A10-2(3A9-)3A10-3A8-4A21-4(3A22-)A-A2(23-2A)24-2A201-2(2B6A17-)B7A17-8A16-10A15-11A13-12A13-5A3-4A13-3A6-4A11-4A7-4A10-2(3A9-)3A10-3A9-3A11-2(3A7-3A12-)3A6-4A13-2A6-3A14-3A5-3A15-3A4-3A17-2(A4-2A18-)A4-A-A17-A5-2A17-A5-A-A16-A6-A-A14-2A7-2A14-2A7-3A13-A9-3A11-2A10-3A9-2A12-4A5-3A14-10A18-5A14-C3B4-4A13-3B5-4A13-3B6-3A13-2BA6-3A13-BA7-3A13-2A8-3A12-2A9-2A12-A2(10-3A9-3A)11-A-A2(7-3A13-2A)6-3A14-2A6-3A15-2(2A4-3A16-)2A4-2A17-2A4-3(2A18-2A3-)2A19-2(A4-2A18-)2A4-2A17-A6-2A15-2A7-2A14-2A7-A-A13-2A8-A-A11-2(A-A9-)A-A11-A-2A5-2A-A13-2A-8A16-6A13-CA9-3A11-CA10-2A11-BA10-2A10-2BA10-2A9-3BA10-3A2(8-2BA12-2A)7-2B2A12-A-A6-B2A14-2A5-B3A14-2A5-4A15-A5-2(3A16-2A4-)2A17-2A4-2A17-2A3-2A19-A3-2(2A19-2A2-)2A20-A2-2A20-2(A3-2A19-)2A3-2A18-2A3-A-A17-2A4-A-A16-2A5-A-A15-A7-2A14-2A8-2A12-A-A9-2A10-A-A10-4A7-A-A13-11A16-7A10-BC2(A12-2A7-3C)A2(12-2A7-2C2A)12-2A7-BC2A13-2A5-2B3A13-2A5-B4A13-2A5-B2A16-2A3-BA-A16-2A3-B2(2A17-2A4-)A3(19-A3-2A)2(19-2A2-2A)3(20-A2-2A)20-2(2A2-2A19-)2A3-2A18-2A4-2A17-2A5-2A16-2A6-2A14-2A7-A-A13-2A8-A-A11-2A10-A-2A8-A-A11-2A-3A2-5A14-9A8-B2A14-A6-BC2A14-A6-2(2C2A14-2A5-)2(2CA15-2A5-)CA17-A5-BA17-A4-B2A17-2A3-B2A18-2(A3-BA19-)A3-4(2A19-2A2-)2(2A20-A2-)3(2A20-2A-)2A21-A2-2A19-2A3-2A18-2A4-2A17-2A5-2A16-2A6-2A14-2A7-3A13-2A8-3A11-2A10-4A7-2A-A11-5A3-5A14-9A7-2BA15-2(2A5-2B16-)2(2A5-CA16-)2A4-2CA17-A4-2(2CA17-2A3-)BA18-2A2(3-BA19-A)3-2(BA19-2A2-)2A19-2A2-2A19-2A-3A2(20-A2-2A)20-5A20-2A3(-2A21-A)2-2A20-A2-A-A18-2A3-3A17-2A5-2A16-2A6-2A14-2A8-A14-2(2A22-)2A55-2B16-2A5-2B17-A4-3B17-A4-2B2(A17-A4-2C)2(A17-2A3-2C)A17-2A2-2CA19-A2-2B2(A19-A3-B)A19-2A2(-B2A20-A)2(-3A20-A)-A22-A-A22-5A21-4A3(21-A-2A)21-A2-3A19-A3-3A18-A177-2B2(17-A4-3B)17-2(A4-BA18-)A4-CA18-2A2(3-CA19-A)2-2CA19-A2-C2(2A19-A2-B)2A19-2A3(-B2A20-A)-3A20-2(A-A22-)3A23-4A3(21-A-2A)21-A2-A21-A24-A176-3B17-2(A4-2B18-)2(A4-BA18-)A3-B-A18-2A2-C-A19-A2-2CA3(19-A2-C2A)2(19-2A-B2A)2(20-A-B2A)20-A-B22-A-A2(22-3A)23-2(4A21-)2(A-2A21-)A2-A21-A24-A176-3(2B18-A4-)BA18-A4-BA18-A3-BCA18-2A2-BCA19-A2-2CA3(19-A2-C2A)19-2A-C2A19-2A3(-B2A20-A)-B2(22-A-A)22-3A23-2A23-4A2(21-A-2A)21-A2-A21-A24-A176-2B18-A4-2B18-A3-BCB18-A3-BCA18-A3-B-A18-A3-BCA18-2A2-BCA19-A2-2C2(A4(19-A2-C2A)19-2A3(-B2A20-A)-B2(22-A-A)22-3A23-2A23-3(A-2A21-)A2-A21-A24-A176-2B18-A4-2B18-A3-BCB18-A3-BCA18-A3-B-A18-A3-BCA18-2A2-BCA19-A2-CB)A4(19-A2-C2A)19-2A3(-B2A20-A)-B2(22-A-A)22-3A23-2A23-3(A-2A21-)A2-A21-A24-A176-3(2B18-A4-)BA18-A4-BA18-A3-BCA18-2A2-BCA19-A2-2CA3(19-A2-C2A)19-2A-C2A19-2A3(-B2A20-A)-B2(22-A-A)22-3A23-2A23-4A2(21-A-2A)21-A2-A21-A24-A176-3B17-2(A4-2B18-)2(A4-BA18-)A3-B-A18-2A2-C-A19-A2-2CA3(19-A2-C2A)2(19-2A-B2A)2(20-A-B2A)20-A-B22-A-A2(22-3A)23-2(4A21-)2(A-2A21-)A2-A21-A24-A177-2B2(17-A4-3B)17-2(A4-BA18-)A4-2(CA18-2A3-)C2(A19-A2-CB)2(A19-A2-2B)A19-2A2(-2BA20-A)-B2A20-A-3A20-2(A-A22-)3A23-4A3(21-A-2A)21-A2-2A20-A24-A177-2B16-2A5-2B16-2A4-3B17-A4-2BA2(17-A4-C2A)17-A4-CA18-2A3-CA18-2A2-C-A19-A2-2B2(A19-A3-B)A19-2A2(-2BA20-A)2(-3A20-A)-A22-A-A22-5A21-4A3(21-A-2A)21-A2-3A19-A3-3A18-A177-3B15-2(2A5-2B16-)2(2A5-CA16-)2A2(4-2CA17-A)4-2CA17-2A3-B2A17-2A2(3-BA19-A)3-2(BA19-2A2-)2A19-2A2-2A19-2A-3A19-2A2-2A20-A2-2A20-5A20-2A3(-2A21-A)2-2A20-A2-A-A18-2A3-3A17-2A5-2A16-2A6-2A14-2A8-A14-2(2A22-)2A23-A32-B2A13-2A6-2B2(2A14-A6-2C)A15-A6-2(2CA15-2A5-)2CA16-A5-BA17-A4-2(B2A17-2A3-)2(BA19-A3-)2A19-A3-3(2A19-2A2-)2(2A20-A2-)3(2A20-2A-)2A20-2A2-2A19-2A3-2A18-2A4-2A17-2A5-2A16-2A6-2A14-2A7-A-A13-2A8-3A11-2A10-4A7-2A-A11-5A3-5A14-9A9-BCA11-3A2(7-3CA12-2A)7-2C2A12-2A7-2CA13-2A7-BCA13-A-A5-2B2A14-2A5-B3A14-2A5-B2A15-2A4-B3A16-2A3-B2(2A17-2A4-)A3(19-A3-2A)2(19-2A2-2A)3(20-A2-2A)20-A3-2A19-2A2-2A19-2A3-2A18-2A4-2A17-2A5-2A16-2A6-2A14-2A7-A-A13-2A8-A-A11-2A10-A-2A7-2A-A11-2A-3A2-2A-2A14-9A11-2CB8-3A11-C2B8-3A11-3B9-2A10-4B9-2A9-4B10-2A9-3BA10-A-A8-2B2A11-2A7-2B2A12-2A7-B3A13-2A5-B3A14-2A5-4A15-A5-3(3A16-2A4-)2A17-2A3-A-A17-2A3-2(2A19-2A2-)2A20-A3-A20-2(A3-2A19-)2A3-2A18-2A3-A-A17-2A4-A-A16-2A5-A-A15-A7-2A14-2A8-2A12-A-A9-2A10-A-A10-4A7-A-A13-11A16-7A15-2BA2-4A16-2(2B4-4A15-)B6-3A14-2A6-3A14-A-10A13-A8-3A11-3A9-3A10-2A10-3A9-3A11-3A7-3A12-3A2(7-3A13-2A)6-3A14-A-A4-4A14-A-A4-A-A16-2A4-3A16-2A4-2A17-3A2(3-2A18-2A)3-2A19-2(A4-2A18-)A5-2A17-A6-2A15-2A7-2A14-2A7-A-A13-2A8-A-A11-3A2(9-A-A)11-A-2A5-2A-A13-2A-8A16-6A18-2(B4A20-)6A18-7A17-8A16-10A15-11A13-12A13-4A4-5A11-4A7-3A11-3A9-3A10-2(3A9-)3A11-2A9-3A11-A-A7-3A12-A-A6-4A12-3A6-3A14-3A5-3A15-2A5-2(3A16-2A4-)3A2(17-A5-2A)17-A5-A-A16-A6-A-A14-2A7-2A14-2A7-3A13-2A8-3A12-2A2(9-3A)11-4A5-3A14-10A18-5A144-2A22-4A20-7A17-9A15-11A14-11A13-13A12-5A3-5A11-4A6-5A10-3A8-2(4A9-)3A9-3A22-2A23-2A2(22-3A)3(23-2A)24-A430-2A22-4A20-7A17-9A15-11A14-11A13-5A20-3A21-2(3A22-)3(2A23-)A243-
