model
size = 31 15 23, scale = 0.05, origin = -y
material deform = 1, fade = true, lighting = smooth, roughness = 0.3, metalness = 0.6
  colors = A:#777 B:#111 C:#FF0
voxels
434-A514-3(6A25-)6A26-4A28-2A291-17A2-4A8-17A2-4A15-16A19-12A20-11A21-10A21-9A23-7A27-2A197-A22-3A5-13A10-3A6-14A7-4A13-7A7-4A16-5A5-4A17-14A18-13A18-12A20-10A23-7A163-A25-2A3-7A18-3A3-12A13-3A6-10A11-4A12-5A10-3A14-5A8-4A15-6A5-5A16-14A17-14A18-12A21-9A158-A2-A26-2A2-9A18-2A3-11A14-3A9-6A13-2(3A12-)4A13-4A9-4A14-5A7-5A15-16A16-14A18-12A20-10A127-2A29-2A-4A24-2A-10A17-3A5-7A16-3A10-3A14-3A12-3A13-3A12-4A11-4A13-5A8-4A15-7A2-7A16-14A18-12A21-8A97-2(2A29-)10A21-2A2-9A17-3A8-4A16-3A11-2A14-4A11-3A13-3A12-4A11-4A13-5A8-4A15-6A4-5A17-13A20-10A24-3A69-2A29-AC29-AB6A23-AB-9A19-AB7-5A16-2AB11-2A15-2AB11-2A14-4A11-3A12-4A12-5A10-4A13-6A6-5A15-7A-7A18-12A21-7A67-2A2(29-AC)3A26-AB9A20-AB6-6A17-AB11-BA15-2AB11-BA15-3A11-BA14-3A12-B3A11-4A12-C4A9-4A15-5A5-5A17-13A20-9A26-A39-2(2A29-)AC2A27-AC8A21-2A5-7A17-2A11-2A16-2A11-2A15-3A11-2A14-4A11-C2A13-3A12-5A10-3A15-4A7-5A16-13A19-10A25-3A38-2(2A29-)3A28-AC8A21-AC5-7A17-2A11-2A16-2A11-2A15-3A11-CA15-3A11-3A13-3A12-4A11-4A14-4A8-4A16-5A2-6A19-10A24-5A37-2(2A29-)4A27-10A21-AC5-7A17-AC11-2A16-2A11-CA15-3A11-2A14-4A11-3A13-3A12-5A10-3A15-4A7-5A16-13A19-10A25-3A38-2A2(29-AB)3A26-AB9A20-AB5-7A17-AC11-CA15-2AC11-BA15-3A11-BA14-3A12-B3A11-4A12-B4A9-4A15-5A6-4A17-13A20-9A26-A39-2A2(29-AB)5A24-AB-9A19-AB6-6A16-2AB11-2A15-2AC11-2A14-4A11-3A13-3A12-5A10-4A13-5A7-5A15-7A2-6A18-12A21-7A67-2(2A29-)10A21-2A2-9A18-2A8-4A16-3A11-2A14-4A11-3A13-3A12-4A11-4A13-5A8-4A15-6A4-5A17-13A19-11A24-3A69-2A29-2A-3A25-2A-10A17-3A4-8A16-3A9-4A14-3A12-3A13-3A12-4A11-4A13-5A8-4A15-6A4-6A16-14A18-12A21-8A97-A2-A26-2A2-9A18-2A2-12A15-2A9-6A13-2(3A12-)4A13-3A11-4A13-5A7-5A15-7A2-7A16-14A18-12A20-10A100-A24-3A3-6A19-3A3-12A13-3A6-10A12-3A12-4A11-3A14-5A8-4A15-5A6-5A15-15A17-14A18-12A21-9A25-3A104-A22-3A5-12A11-3A5-14A8-4A13-7A7-4A15-6A5-5A16-7A-6A17-14A18-12A20-11A22-7A165-16A3-5A7-16A3-5A13-18A18-12A2(20-11A)21-9A23-8A25-4A211-3(8A23-)7A25-6A26-4A286-
