model
size = 16 9 32, scale = 0.05, origin = -y
material deform = 1, fade = true, lighting = smooth, roughness = 0.3, metalness = 0.6
  colors = A:#FFF B:#EEE C:#DDD D:#7B90D2 E:#B28FCE F:#A5DEE4 G:#FCFAF2 H:#8A6BBE I:#4E4F97 J:#7DB9DE K:#FFFFFB L:#72636E M:#BBB N:#533D5B O:#261E47 P:#6A4C9C Q:#BDC0BA R:#211E55 S:#9B90C2 T:#8B81C3 U:#8F77B5 V:#3C2F41 W:#4A225D X:#113285 Y:#3A8FB7 Z:#6E75A4 Aa:#81C7D4
voxels
83-XY2IZ61-7A8-9A7-5(10A6-)9A8-7A8-9A6-11A5-5(12A4-)11A6-9A2(6-10A)2B3-4(11A2BA2-)11A2BA3-10A2B4-10A6-10A5-6(B10A2BA2-)B10A2BA3-10A7-G8A5-Q2G8AB4-5(QG9ABAB2-)Q2G8AB6-2G7A9-2G5A8-3G5AB6-4(L3G5ABAC4-)L3G5ABAC5-3G5AB8-2G5A11-BCKA11-GBCKA2B8-4(LGBCKA2BA7-)LGBCKA2BA8-GBCKA2B10-BCKA13-CK2A11-2(LCK2AB10-)3(LCK2ABA9-)LCK2AB10-LCK2AB11-CK2A3(12-B3A)B11-3(B3ABA10-)B3AB11-B3A12-B3A3(11-C4A)2(B10-C4A)BA9-2(C4AB10-)C4A11-C4A10-CK3A10-LCK3AB9-2(LCK3A2B8-)LCK3A2BA7-2(LCK3A2B8-)LCK3AB10-CK3A12-G3A10-CBG3AB9-2(CBG3A2B8-)CBG3A2BA7-2(CBG3A2B8-)CBG4A11-G3A12-A12-M2BA4BA2(7-M2BA5B)3(A6-M2BA5B)7-M2BA4BA10-A28-2CABA4B7-2C7B6-2(M2C7BA5-)M2C7BA6-2C7B7-2C4BA2B39-2C4BC2B6-3(S2C4BC2BA4-M)2(S2C4BC2BA5-)S2CA3BC2B38-2(3CA)CA5-4(N9CBA4-)N9CBA5-5CA3CA38-A8CB5-3(U9CBA3-M)U9CBA4-U9CBA5-CA7CB38-2(2C2-)CB4-4(NE2C4E2FCBA3-)NE2CEC2E2FCBA5-2(2C2-)CB37-C2-C6-2B3-T5EC2EFA3(2B2-MT8E2F)2B3-T8EFA2B4-C2-C6-2B46-4(B3-N9E2F)B3-N7ECE2FB15-B51-H3EC5E2F3-2(MH9E2FA2-)MH9E2FA3-H2EC6E2F67-N2E2(DE)DCDJA4-N2E7DJFCB2-N2E7DJFCA2-N2E7DJFCB2-N2E2(2DE)DJA69-9DJF4-2(I9DJFB3-)I9DJFB4-6DC2DJF69-3H6DJF4-I2H7DJFA2(3-I2H7DJFB)4-3H6DJF69-2H3DP3D2F4-2(I2H3DP3D2FB3-)I2H3DP3D2FA4-2H3DP3D2F69-PH3D-2DJF5-WPH3DO2DJFB4-WPH3DI2DJFB4-WPH3DO2DJFB5-PH3D-2D-F70-IH2DH-2DJF5-RIH2DHO2DJFA4-RIH2DHI2DJFB4-RIH2DHO2DJFB6-H2DH-2D-F70-IH2D2-2DJ6-VIH2D2O2DJ6-VIH2D2I2DJB5-VIH2D2O2DJ8-H2D2-2D73-H2D2-DJ8-RH2DIODJ8-RH2D2IDJFAa6-RH2DIODJ9-H2D2-D75-2D2-D11-2D2ID10-I2D2ID2F9-2D2ID11-2D2-D91-2D2I11-X2D2I2J10-2D2I57-
