model
size = 8 6 22, scale = 0.05, origin = -y
material deform = 1, fade = true, lighting = smooth, roughness = 0.3, metalness = 0.6
  colors = A:#FFF B:#FCFAF2 C:#EEE D:#B28FCE E:#FEDFE1 F:#986DB2 G:#70649A
voxels
27-2G6-2G13-4A3-6A-16A-6A3-4A3-3A2BA-32A-3A2BA-16AB7AB23A2BAB26A2(B2A)B3A2BAB4A2B5AB15AB7AB6ABA2B5AB2AB4AB8AB7A2B7AB4AB3AB4AB48A-3A-2A-22A2(B2ABA)-3A-2A10-2(B5A2-)6A2-2(B2A)18-3(6A2-)6A18-2B3A2(B2-B4A)B2-2B2A2B18-A2CBCA2(2-6A)2-A2CBCA18-CB2CBC2(2-6C)2-2B2C2B18-2(CB)2C2(2-6C)2-2(CB)2C18-C4EC2(2-6C)2-C4EC18-2E2(DE)2(2-6E)2-2E2(DE)18-E4DE2(2-6E)2-E4DE18-3(6D2-)6D18-DF2DFD2(2-F4DF)2-DF2DFD19-4F3-G4FG2-G4FG3-4F21-2F5-G2FG4-G2FG5-2F11-
