model
size = 20 33 14, scale = 0.05, origin = -y
material deform = 1, fade = true, lighting = smooth, roughness = 0.3, metalness = 0.6
  colors = A:#EEE B:#111 C:#BBB D:#B00 E:#A00 F:#700 G:#AAA H:#DDD
voxels
504-FBFC4-CF2C8-CF2C4-4C8-4C4-2CFC8-2CFC4-CFBF88-CF2C4-FBFC8-FBFC4-2(CF)390-3C2-C2A13-C-2C-C13-C2-CA2-C15-2(CA18-)CD12-C5-CA5-C7-C4-CA4-C9-C3-CA3-C11-C5G-C12-CG3-G-C13-5G10-2C4AC2-5CFC4-2C4AC2-5CBF6-2(AE)4-4A8-2AEB4-4A8-3AE4-2AEA8-AE2A4-AEBE8-EBEA4-2AEA8-AE2A4-4A8-4A4-E3A8-4A4-BEAE8-3AE4-E3A8-2AEB4-4A8-E2AE4-3AE8-BE2A4-2AEB8-E3A4-3AE7-5A4-AE3A6-3AEA4-EBE2A6-2AEBE4-AE2AD6-3AEA4-5A6-E4A4-5A6-BE3A4-C4A6-E5A2-5AE6-12AEB6-AE11AE6-EBE11A6-AE8AE3A6-2(4AE)BE2A6-3AEBE4AE2AC6-4AE9A6-14A6-D12AD6-3BC6BC3B10-5A9-C6AC2-8C2-C6AF2-7CA2(3-2A)2-2A3-EA4-2A3-AE2(2-2A3-2A4-2A3-2A)2-2A3-2A4-3A2-AE2-2A2(2-3A4-3A2(2-2A))2-2AE4-3A2-2A2-EA2-AEB4-3A3(2-2A)E4-DA3-AE2-2A3-2A4-3A2(2-2A)2-3A4-AEA-3A2-3A-AEA4-3A-3A2-3A-3A4-2A3-2A2-EA3-2A4-2A3-2A2-2A3-AD4-2A3-2A2-2A3-AB4-2A3-AD2-2A3-AD4-2A3-2A2-2A3-2A4-EA3-2A2-DA3-2A4-2A3-2A2-2A3-2(2A4-)4A4-AE2(4-2A12-2A)4-2A12-AD4-2A12-2A4-CA12-AC2(4-2A12-2A)4-C15A4-C15B23-C6AF2-F6AC2-F2A3-AB2-CA3-2AF3-A5-E2(2-A5-A4-A5-A)2-A5-A4-A5-E2-A5-A4-D5-B2-A5-E4-A5-E2(2-A5-A4-A5-A)2-A5-E4-D5-A2-A5-A4-B5-A2-B5-A4-D2(5-A2-A5-A4-A)5-A2-E5-D4-A5-A2-B5-A3-2A5-D2-E5-2A2-2A5-A2-A5-AD2-2A5-A2-A5-2A2-DA3(5-A2-A5-2A2-2A)5-4A5-2(2A2-2A14-)AD2-DA14-AB2(2-2A14-AD2-2A14-2A)3-4A8-4AC3-16BC21-FC6AC2-C6ACFB2A5-F2-F5-2AB-FA5-A2-A5-AE2(2-2A5-A2-A5-2A)2-DA5-A2-A5-AD2-BA5-E2-A5-AB2-DA5-A2-A5-AE3(2-2A5-A2-A5-2A)2-DA14-2A2-2A5-A2-E5-2A2-2A5-A2-A5-AD2-2A5-A2-A5-AB2-DA5-A2-A5-AD2-2A14-2A2-A16-A2-D16-A2-B16-A2-D16-A2-A7-AD7-A2-A7-2A7-A2-A16-A-DA16-2ABA16-A2DA16-4A16-AD-A16-B2-2A14-AD2-3A12-3A2-18B21-2C6AC2-F6A2CF2A5-C2-C5-2AE-2(2A14-2A2-)2(2A14-AH2-)DA14-AE7(2-2A14-2A)2-DA14-AD2-BA14-2A2-D2(16-A2-A)16-A2-D16-A2-A16-D2-A7-2A7-A2-A16-A-2A16-4A16-2AD18-2A18-3A16-4A16-AD-A16-A2-D2A12-3A2-18B22-2(C6AC2-)CA5-C2-C5-AC3-2(A5-A2-A5-A4-)A5-A2-A5-D4-A5-A2-A5-H3-2A5-A2-A5-2A3-D5-A2-D5-A3-2A5-A2-A5-2A2-2A5-A2-A5-2A3-A5-A2-E5-A4-A5-A2-E5-D4-A5-D2(2-A5-A4-A5-A)2-A5-A3-DA5-A2-E5-2A2-2A5-A2-A5-3(2A2-2A14-)AD2-D7-2A7-B2-A7-2A7-D2-A16-A-2A16-3A18-2A18-DA18-2A18-3A16-2A-A16-A-2C2A12-2AD-2C17B22-C6AC2-C6AB2-C3A-2AC2-C2A-3AC2(3-2A)2-2A3-2A4-2A3-2A2-2A3-AD4-2A3-2A2-2A3-AB4-2A3-2A2-2A3-AD4-DA3-2A2-DA3-2A4-BA3-2A2-BA3-2A4-DA3-2A2-DA2(3-2A4-2A3-2A2-2A)3-AD4-DA3-AD2-2A3-AB4-2A3-AB2-2A3-AD4-2A3-AD2(2-2A3-2A4-2A3-2A)2-2A3-2(2A4-)A2-D4-AE2(4-A5-A2-A5-A)3-DA5-A2-A5-2A2-BA5-A2-A5-AD2-DA2(6-2A)2-A16-A-2A16-3A18-DA18-BD18-DA18-3A16-2A-A16-A2-2A14-2A2-18B23-FC3A2C2-2C3ACB4-C5AC2-F5AF5-AD2ADA2-2(D2A)6-DBD2A4-ADBDA6-AD3A4-2ADAD6-3ADA4-5A6-2ADBD4-3ADA6-D2ADA4-DADBD6-5A4-3ADA6-5A4-5A6-D4A4-5A6-BD3A4-AD2AE6-D3AD4-DBD2A6-5A4-AD3A6-2AD2A4-5A6-ADBD2A2-D5AE4-7A2-BD3AEB4-3A-3A2-D2A-2AE4-3A-ADA2-3A-3A4-3A-ABD2-3A-3A4-DA2(2-3A)2-2A3-3A4-4A4-3A2-2A14-2A-2A16-4A16-2AD18-DBA16-2ADA16-4A16-AD-2A14-2A2-5A8-5A2-18B24-BF2CFC2-F4CF6-F2CFBF2-BF4C288-D8-A9-3A6-3A8-3A6-ADA7-3AD6-DBDA6-6A2-6A5-3A2-6A2-3A3-3A5-2A5-3A2-DA14-AD-2A16-4A16-2ADA16-2A-A16-D2-2A14-AB2-DA14-AD3-16AC3-2B-12B2C425-3AD4-2ADA7-6A2-6A4-2D2A2-2AD3A2-3AE2-B2A4-4A4-2AB2-DA14-AD3(2-2A14-2A)2-D2A12-2AD3-B3A8-4A4-D15A5-C14B446-4A4-4A6-HD5A2-2AD3A5-D5ADBD6AD4-3A2-2AD3A2-3A4-2A4-4A4-2A4-3A2-6A2-3A4-16A4-6AD9A5-D3ADB2(D3A)6-C-2(3AD)BDC7-C6-C4-C467-H20-CF2C4-DBDC7-3(C4AC2-C4AC6-)C4AC2-C4AC53-C19-C29-
