model
size = 12 11 9, scale = 0.05, origin = -y
material deform = 1, fade = true, lighting = smooth, roughness = 0.3, metalness = 0.6
  colors = A:#33C B:#DDD C:#AAA D:#369 E:#888 F:#EEE G:#004 H:#777 I:#111 J:#F96 K:#FCF L:#C60 M:#555 N:#FFF O:#960 P:#3CF Q:#BBB R:#09C S:#09F
voxels
16-2(D2-D8-)4D8-4D92-E2-E8-H2-H7-A-2A-A6-A4-A6-6A89-AM4-E3(A4-A6-)A5-6A65-A6-A4-A6-A16-A6-A5-H4-A5-AG4-GA6-4A66-A6-A4-A6-A5-A4-A5-A6-A4-AG4-GA3-2H-R2PS-2E-CLC6-CL2CLC6-CL3CM6-M2C26-A6-A16-AB4-BA5-E4-A5-AG4-GA6-4A42-N6-N3(4-A6-A)4-AB4EBA4-AB2I-IBA5-6A68-2F8-O4JO6-2F2K2F6-BC2BQB6-5BF104-2K9-I2-I76-
