model
size = 12 24 12, scale = 0.05, origin = -y
material deform = 1, fade = true, lighting = smooth, roughness = 0.3, metalness = 0.6
  colors = A:#EBB471 B:#E16B8C C:#AF5F3C D:#00AA90 E:#FFF F:#FBE251 G:#2EA9DF
voxels
185-2B46-2G274-2B225-B10-2B3A7-2B10-GB10-BGBDB7-4BEB7-D2BE164-B11-3(B2A9-)B2C8-2A2-2A6-4B8-4BDB6-2B2-2B5-E2B2-2BF5-BD2-2B8-2B94-3(2A10-)2A8-6C4(6-6A)B5-CA4CB4-3A2-3AB4-8B3-3B2-4B2-3B4-BFB2-E2B4-3B2-2(3B4-)6B7-2E2B56-4A8-4C4(8-4A)7-C4AC4(6-6A)6-C4AC4-2A6-2A3-2B4-BF2(4-2B)3-B8-B2-B8-D2-3B4-3B3-3B2-2BE4-6BFB6-3BF21-2A10-2A9-4A8-C2AC7-4(6A6-)C4AC6-6A5-3(8A4-)2C4A2C3-2A6-2A3-B6-F4-D6-B3-D8-B-2B8-BD-3B4-3B3-GB4-BE4-G7B5-6B8-2B2(10-2A)9-4A8-C2AC7-4(6A6-)C4AC6-6A5-3(8A4-)4C2A2C3-2A6-2A3-B6-B4-B6-B3-B8-B-2B8-2B-3B4-3B3-2(2B4-)8B5-D3BDB8-2B33-4A8-4C4(8-4A)7-C4AC4(6-6A)6-3C2AC4-2A6-2A3-3(2B4-)2B3-B8-F2-F8-B2-3B4-3B3-3B2-2BG4-D6BG6-3BD69-3(2A10-)2A8-6C4(6-6A)6-6C5-3A2-3A5-6B5-3B2-3B3-F2B4-3B2-3B4-2BF2-2(3B4-)E5B7-E3B153-3(2A10-)2C8-2A2-2A8-2B8-6B6-2B2-2B5-3B2-3B5-2B2-BE8-2B191-B10-2B9-4A9-2B10-2B9-4B7-5BE7-4B52-
