model
size = 12 14 32, scale = 0.05, origin = -y
material deform = 1, fade = true, lighting = smooth, roughness = 0.3, metalness = 0.6
  colors = A:#FFEF9F B:#1E1E1E C:#323232 D:#3C3C3C E:#F6D402 F:#FFDF00 G:#FFD400 H:#A76514 I:#ECC904 J:#564E17 K:#E0CE77 L:#E3BE06 M:#DAB308 N:#D1A80A O:#C79C0B P:#BE910D Q:#124BC6 R:#379D30 S:#B5860F T:#D7387F U:#141414 V:#D97708 W:#BB1313 X:#AC7B11
voxels
16-4B8-4B139-6B6-J4BJ6-2F2H2F6-2E2H2E6-2I2H2I6-2L2H2L7-3(4H8-)4H54-2B2(DC)2B4-J6AJ4-8F4-8E4-8I4-8L4-M6HM4-N6HN4-O6HO6-4H53-2B6G2B2-J8AJ2-2F6-2F2-2E6-2E2-2I6-2I2-2L6-2L2-2M6-2M2-2N6-2N2-2O6-2O61-2B3(DC)GC2BJ10AJ-F8-F2-E8-E2-I8-I2-L8-L2-M8-M2-N8-N2-O8-O61-B5(DC)BJ3A4G3AJVF8-FV-E8-E2-I8-I2-L8-L2-M8-M2-N8-N2-O8-O2-P8-P49-B2(CD)4GCDBJ4A2G4AJ2F8-2F2E8-2E2I8-2I-L8-L2-M8-M2-N8-N2-O8-O2-P8-P49-B2(DC)GCDGDCBJ4A2G4AJRF8-F2RE8-E2RI8-I2RL8-L2RM8-MR-N8-N2-O8-O2-P8-P49-B2(CD)GDCGCDBJ4A2G4AJ2F8-2F2E8-2E2I8-2I2L8-2L2M8-2M2N8-2N-O8-O2-P8-P2-S8-S37-BDC6GDCBJ4A2G4AJQF8-F2QE8-E2QI8-I2QL8-L2QM8-M2QN8-NQ-O8-O2-P8-P2-S8-S37-B5(CD)BJ4A2G4AJ2F8-2F2E8-2E2I8-2I2L8-2L2M8-2M-N8-N2-O8-O2-P8-P2-S8-S2-X8-X25-2B4(CD)2BJ4A2G4AJTF8-F2TE8-ET-I8-I2-L8-L2-M8-M2-N8-N2-O8-O2-P8-P2-S8-S2-X8-X16-6H4-B4(DC)B2-J3A3G2AJ2-F8-F2-E8-E2-I8-I2-L8-L2-M8-M2-N8-N2-O8-O2-P8-P2-S8-S3-2H4K2H5-H4KH6-H4KH4-B4(CD)B2-J3A3G2AJ2-F8-F2-E8-E2-I8-I2-L8-L2-M8-M2-N8-N3-O6-O4-P6-P4-S6-S4-H6KH27-BDG3(DC)B2-J8AJ2-F8-F2-E8-E2-I8-I2-L8-L2-M8-M3-N6-N4-O6-O4-P6-P4-U6TU39-BCG3(CD)B2-J8AJ2-F8-F2-E8-E2-I8-I2-L8-L3-M6-M4-N6-N4-O6-O4-H6KH51-BD6GCB2-J8AJ2-F8-F2-E8-E2-I8-I2-L8-L3-M6-M4-N6-N4-U6QU63-B4(CD)B2-J8AJ2-F8-F2-E8-E2-I8-I2-L8-L3-M6-M4-N6-N4-H6KH62-2B2(D2GC)2BJ10AJ-F8-F2-E8-E2-I8-I3-L6-L4-M6-M4-U6RU74-B2(DC)2G2(DC)BJ10AJF10-F-E8-E2-I8-I3-L6-L4-M6-M4-H6KH74-B2(CD)2G2(CD)BJ10AJF10-F-E8-E2-I8-I3-L6-L4-U6VU86-B2(DC2G)DCBJ10AJF10-F-E8-E2-I8-I3-L6-L4-H6KH86-B5(CD)BJ10AJF10-F-E8-E3-I6-I4-U6WU98-BDC6GDCBJ10AJ-F8-F2-E8-E3-H6-H5-6K99-B5(CD)BJ10AJ-F8-F3-E6-E4-H6KH6-4K100-B2(DC)4GDCBJ10AJ-F8-F3-E6-E4-I6HI110-2BDCDGDCGC2BJ10AJ-F8-F3-E6-E5-6I112-BCDCGCDGDB2-J8AJ3-F6-F2(4-2E)6-4I113-2B6G2B2-J8AJ3-F6-F4-8E124-2B2(CD)2B4-J6AJ4-F6-F5-6E126-B2(DC)B6-J4AJ6-6F138-2BDC2B6-B4AB7-4F136-
