model
size = 12 14 32, scale = 0.05, origin = -y
material deform = 1, fade = true, lighting = smooth, roughness = 0.3, metalness = 0.6
  colors = A:#FFEF9F B:#1E1E1E C:#FFD400 D:#323232 E:#3C3C3C F:#F6D402 G:#FFDF00 H:#A76514 I:#ECC904 J:#564E17 K:#E0CE77 L:#E3BE06 M:#DAB308 N:#D1A80A O:#C79C0B P:#BE910D Q:#124BC6 R:#379D30 S:#B5860F T:#D7387F U:#141414 V:#D97708 W:#BB1313 X:#AC7B11
voxels
16-4B8-4B139-6B6-J4BJ6-2G2H2G6-2F2H2F6-2I2H2I6-2L2H2L7-3(4H8-)4H54-2B2(ED)2B4-J6AJ4-8G4-8F4-8I4-8L4-M6HM4-N6HN4-O6HO6-4H53-2B6C2B2-J8AJ2-2G6-2G2-2F6-2F2-2I6-2I2-2L6-2L2-2M6-2M2-2N6-2N2-2O6-2O61-2B3(ED)CD2BJ10AJ-G8-G2-F8-F2-I8-I2-L8-L2-M8-M2-N8-N2-O8-O61-B5(ED)BJ4A4C2AJVG8-GV-F8-F2-I8-I2-L8-L2-M8-M2-N8-N2-O8-O2-P8-P49-B2(DE)4CDEBJ5A2C3AJ2G8-2G2F8-2F2I8-2I-L8-L2-M8-M2-N8-N2-O8-O2-P8-P49-B2(ED)CDECEDBJ5A2C3AJRG8-G2RF8-F2RI8-I2RL8-L2RM8-MR-N8-N2-O8-O2-P8-P49-B2(DE)CEDCDEBJ2A5C3AJ2G8-2G2F8-2F2I8-2I2L8-2L2M8-2M2N8-2N-O8-O2-P8-P2-S8-S37-BED6CEDBJ2AC2A2C3AJQG8-G2QF8-F2QI8-I2QL8-L2QM8-M2QN8-NQ-O8-O2-P8-P2-S8-S37-B5(DE)BJ2AC2A2C3AJ2G8-2G2F8-2F2I8-2I2L8-2L2M8-2M-N8-N2-O8-O2-P8-P2-S8-S2-X8-X25-2B4(DE)2BJ2AC2A2C3AJTG8-G2TF8-FT-I8-I2-L8-L2-M8-M2-N8-N2-O8-O2-P8-P2-S8-S2-X8-X16-6H4-B4(ED)B2-JA6CAJ2-G8-G2-F8-F2-I8-I2-L8-L2-M8-M2-N8-N2-O8-O2-P8-P2-S8-S3-2H4K2H5-H4KH6-H4KH4-B4(DE)B2-JA6CAJ2-G8-G2-F8-F2-I8-I2-L8-L2-M8-M2-N8-N3-O6-O4-P6-P4-S6-S4-H6KH27-BEC3(ED)B2-J8AJ2-G8-G2-F8-F2-I8-I2-L8-L2-M8-M3-N6-N4-O6-O4-P6-P4-U6TU39-BDC3(DE)B2-J8AJ2-G8-G2-F8-F2-I8-I2-L8-L3-M6-M4-N6-N4-O6-O4-H6KH51-BE6CDB2-J8AJ2-G8-G2-F8-F2-I8-I2-L8-L3-M6-M4-N6-N4-U6QU63-B4(DE)B2-J8AJ2-G8-G2-F8-F2-I8-I2-L8-L3-M6-M4-N6-N4-H6KH62-2B2(E2CD)2BJ10AJ-G8-G2-F8-F2-I8-I3-L6-L4-M6-M4-U6RU74-B2(ED)2C2(ED)BJ10AJG10-G-F8-F2-I8-I3-L6-L4-M6-M4-H6KH74-B2(DE)2C2(DE)BJ10AJG10-G-F8-F2-I8-I3-L6-L4-U6VU86-B2(ED2C)EDBJ10AJG10-G-F8-F2-I8-I3-L6-L4-H6KH86-B5(DE)BJ10AJG10-G-F8-F3-I6-I4-U6WU98-BED6CEDBJ10AJ-G8-G2-F8-F3-H6-H5-6K99-B5(DE)BJ10AJ-G8-G3-F6-F4-H6KH6-4K100-B2(ED)4CEDBJ10AJ-G8-G3-F6-F4-I6HI110-2BEDECEDCD2BJ10AJ-G8-G3-F6-F5-6I112-BDEDCDECEB2-J8AJ3-G6-G2(4-2F)6-4I113-2B6C2B2-J8AJ3-G6-G4-8F124-2B2(DE)2B4-J6AJ4-G6-G5-6F126-B2(ED)B6-J4AJ6-6G138-2BED2B6-B4AB7-4G136-
