model
size = 15 32 30, scale = 0.05, origin = -y
material deform = 1, fade = true, lighting = smooth, roughness = 0.3, metalness = 0.6
  colors = A:#4A225D
voxels
24-3(5A10-)5A406-7305A375-90A390-75A405-8(60A420-)60A421-3(14A-)14A426-3(9A6-)9A420-
