model
size = 20 10 32, scale = 0.05, origin = -y
material deform = 1, fade = true, lighting = smooth, roughness = 0.3, metalness = 0.6
  colors = A:#4A225D B:#000
voxels
-2(2AB)2A11-9(2(2AB)2A12-)2211A169(9-11A)10(9-8AB2A)9-20(8A12-)
