model
size = 18 24 10, scale = 0.05, origin = -y
material deform = 1, fade = true, lighting = smooth, roughness = 0.3, metalness = 0.6
  colors = A:#EEE B:#111 C:#700 D:#0CF E:#009 F:#00B G:#00A
voxels
206-2A16-2A48-B-B4-B-B454-2A3(14-4A)14-2A2-4A6-4A5-3A6-3A9-6A222-144A2-14A5-12A8-8A28-8A8-12A5-14A3-16A-252A-16A3-14A5-12A8-8A46-8A9-10A8-10A6-14A3-16A2-16A-180A-16A2-16A3-14A6-10A10-6A65-8A9-A-6A-A10-6A11-8A8-12A5-14A4-14A3-2(16A2-)16A-36A-16A2-AB12ABA3(2-16A)4-12A8-8A13-2A86-6A12-6A13-4A14-4A12-8A9-2A6B2A8-10A7-12A6-12A5-3(14A4-)14A5-12A5-B12AB6-10A5-16A8-4A14-A2-A103-6A13-4A15-2A15-4A12-A6CA10-A6-A10-A6CA9-A2-4A2-A7-2A-6A-2A6-3A2B2A2B3A6-12A8-8A7-5B4A5B5-ADEAB2ABAEDA5-5B4A5B10-2A10-3B8A3B9-A2-A14-A2-A104-4A15-2A16-2A15-4C13-6C11-C6-C10-8C12-C2AC15-2A16-2B14-B4AB13-4A15-2A12-DF2-2A2-DG6-3(B-)2A3(-B)10-2A13-B2A2-2AB12-B2-B123-2A16-2A51-4C31-6C13-C2AC51-3(2A16-)2A10-2(B-)B4-2(B-)B26-2B2-2B132-
