model
size = 12 20 32, scale = 0.05, origin = -y
material deform = 1, fade = true, lighting = smooth, roughness = 0.3, metalness = 0.6
  colors = A:#FF9 B:#FFF C:#0B0000 D:#F00 E:#FF3 F:#FFC G:#FCF H:#FE0000 I:#FF0 J:#100 K:#F30 L:#FCC M:#FF6
voxels
16-2(6B6-)2(6D6-)5D175-2(6B6-)6D6-LD2LDL6-L2DLDL5-3(DL)D5-DLD4L2(6-6D)7-B2DB2(8-4D)8-3D9-3C79-8B2(4-2B)4-D6BD4-DG4-GD4-DL4-L2(D4-DL4-G)K4-D2A2-2AK4-BA4GAB4-2B3GAB2(5-2D3AGD)5-2D2AG2D5-2C3A2C5-7C8-2C54-9B3-2B6-B3-D2B3A-BD3-DG-3A2-D3-DL5A-D3-DL-4A-D3-DL-3A2-K3-DA6-K3-BA6-B3-B2G4-AB2(3-DAG4-AH)3-D2G3-2GD3-C2A-4AC3-C7AC4-7C52-10B2-B-5A-2B2-DB5A-BD2-D-6AD3-D-2A-3A2(D3-D-6A)K3-B-5A-K3-B2-4A-B3-BG-3A2(2-D)A2(2-4A-H3-D)G-4A-AD-CA2-A2C3AC2-C2A4C2AC2-3C4-2C51-10B2-B7A-B2-D7AB2(D2-DA5-A-)D2-D2A4-A-K2-B2A4-2AK2-B3A2-2A2(-B)A-6A-B-DG-7AD2(-D2-7AH)-DA-2A2-2AGH-CG-AC3-AGH-C2AC4-CAC2-2C5-2C51-10B2-B7A-B2-D7AB3(D2-DA5-A-)2(K2-BA5-A-)2(B-)2A4-A-B-DG2A3(4-A-H-D2-A)4-A-H-D-2A4-AGH-C2A5-A-C-3C5-3C50-10B2-B7A2B2-D7AB2(K-DA6-AG)K-DA6-2AK2-B6-AB2-B2A5-2A2(B-)A5-A-B4(-D-A5-A-H)-D-A5-AGH-C2A5-2AC-3C5-3C49-10B2-2B7AB3-D7A2(K2-DA6-A)4(B2-BA6-A)B2-DA6-2AH-D2A3(5-A-H-D-A)5-AGH-DGA5-CGC-C2A5-2C3-2C5-2C4-C33-10B2-B8AB2-D8AK2-DA6-AK5(2-BA6-AB)2-3(DA6-2AH-)DA6-AH2-D-A5-AH2-D2A5-CH2-C2A3(C3-CA)C4-C3-3C5-C4-C16-10B2-B8AB2-D8AK2(2-BA6-AB)-C2A3(6-AB2-BA)6-AB2(2-DA6-AH)2-D-A5-AH2-D2A5-AH2-DGA4-2AH2-D2A3-2CAH3-C2A3C2AC3-C2A3CAC5-2C2F2AC5-6C7-C2-C5-10B2(2-B8AB)2(2-BA6-AB-C2A6-AB)2(2-BA6-AB)2-DA6-AB3-DA5-AC2-DGA4-A-H2-DF7AH3-C6AIH3-C2A2C2AFC3-C6AFC3-C4A-AC5-C3A-C6-C4AC7-4C5-10B2-B7A-B2-B8AB-CM7-AB2-B3(7-AB-CM)7-AB2-B7-AB3-DA5-AB3-DA4-AIC3-D6AFC3-C6AC4-C7AC3-CA3-3AC3-C2A2-2AFC4-C4A2C5-CAF2AC6-5C8-3C6-10B2-B5-2A2B2-B8AB-CA8-B2-B8-B-CA2(8-B-CM)8-B2-B7-AB3-CA4-AFC3-C6AFC3-CI5A2(C4-CI4AI)C4-2CI2AI2C4-2C4I2C6-2(AK)8-2(KF)29-10B2-B7-2B2-B7-A2(B2-B8-B-CA8-)B2-B7-AB2-CA6-J4-CA4-AC4-C6AC4-CI3A2IC5-B3IBC6-B4CB7-4C8-4C52-11B-2B3(8-B2-B)8-B-CA2(8-B2-B)7-2B2-CA5-BC4-CA3-2AC4-C5AFC4-2CI2ABC7-3B89-11B-BA7-A2(B-D9-)2(B2-B8-)B2-B7-AB2-BA5-BAJ2-C2A4-AC4-C6AC4-CI3AIC6-5C100-11B-B3(9-B-D)9-B2-B8-B2-B7-2B2-CA5-BAJ2-C2A3-2AC4-C6AC4-CBIAICB7-3C101-11B-B4(9-B-D)A8-B2-JAB5-BJ2-C2A-B2-AJ3-CF6AC4-CI4AB6-C4BC111-11B-B2(9-B-D)2(9-D-D)A8-J2-JA5-BAJ2-C2A3-2AC4-C5AIC4-6CB123-13B8-AFBD8-AF2DB8-D-D9-C-DA8-C2-J2A4-A-C2-CF6AC4-CI3AI2C5-B3CB124-13B8-BABD10-2D9-D-DF8-D2-CA7-C2-C3A2-2AFC2-CI5AIC4-2C3I2C7-3B125-13B9-ABD10-2D9-D-DF8-D2-CA6-EC2-CE6AFC3-CI3AI2C5-B3CB136-13B10-BD10-2DF8-FD-D8-D2-C3E2-2EC3-2C5EFC4-2CB2ICB7-3B137-13B10-BD10-2DF8-FD-D2E6-D3-C7EC4-2C3E2J5-B3CB148-13B10-BD10-D-D8-FD-DFE5-ED3-C6E2C4-6J7-3B149-14B9-B-D9-D-D8-FD-DF2E3-EFD3-2CE-3EC6-5J160-11B-B9-B-D9-D-DF7-FD2-D2E3-2ED4-2C3E2C7-3J161-11B-2B8-B-DB8-D2-D7-FD2-D7ED4-3C2E2C8-2J162-10B2-B7-2B2-D7-BD2-D7-D3-2D5EFD5-5CD172-9B3-2B6-B3-DF2(6-D4-D)5EFD5-D3C2D173-2(8B4-)DF4-BD4-DF3-BFD4-2D2FEFD7-4D171-
