model
size = 31 31 32, scale = 0.05, origin = -y
material deform = 1, fade = true, lighting = smooth, roughness = 0.3, metalness = 0.6
  colors = A:#4D9DE0 B:#E4AB00 C:#444 D:#555 E:#2ACE79
voxels
4-B680-B2E28-2(B3E27-)3(B2E28-)BE29-B30-B240-2C30-C929-C30-CD29-2C919-C8-CD20-D8-2CD19-D8-2CD918-D8-2CD2(18-2D8-3C)18-2D29-D624-CD30-D210-2D8-CDC18-2D8-2DC17-3D8-3D17-3D624-D30-2D29-2D188-CD18-2(3D7-C3D17-)3D7-CDC18-3D624-3D28-4D28-C2D175-CDC7-2CD18-CAC6-3CD17-2C-C6-4C18-3C6-2D648-3D28-C2(3D28-)2D114-2D8-D19-CA2D3-3C3D17-2C-2D2-6C19-2CD4-3CD680-3D28-3D27-C3D28-2D83-3D27-CA5D3C2D18-2C-3DCDC-2CD19-2C5D2C2D21-2C688-3(3D27-C)2D52-5D2C23-CA-A6CD19-2C2-D4-3C20-D2CD5CD22-2CD528-4D28-3D124-2D28-C2DC26-2C3D25-3C2D23-2CD3C2D21-5D3C22-2CA3-3C21-2C5-3C21-3C-2(D2C)22-3CDC528-2(3D28-)3D29-D94-2D27-2CDC25-D2C-2D22-2C2DC-C2D21-5D3CD21-2CA3-3C21-B2A4-2C21-2BA3-3C22-2BA2CD2C24-2B2C530-3(3C28-)2C29-2C57-D3-2C2D22-4D3C2D21-4DA-2CD21-C2D4-CD21-B2C4-ACD20-2BA4-2DC20-BAB4-3D21-B2A2-3D23-5B2D25-B504-C29-3C28-D2C27-2D2C26-3DC26-4DC25-5D25-C4A3C22-2C2(A-)3C21-B2C4-AC21-2BC5-AC20-3B5-2D20-3A5-2D21-2A5-2D22-5A2BD23-3A2B26-3AB503-C29-D2C27-2DC27-3DC26-2D-DC24-C2D-2D24-2CA2-AC23-B2C3-AC22-2BC4-2C21-3B5-2C20-2AB5-3C19-2A6-A2C20-2A5-2AC20-3A3-2A2B21-3A2-2AB23-6AB25-5A532-3D27-4C26-3CD25-3C-CD24-BCA2-2C23-2B3-A2C22-2B4-AC21-ABA5-AD20-3A5-2AC19-3A6-2B20-2A6-2(AB21-2A5-)2B22-3A3-AB23-5A3B24-4AB28-A533-CD28-4C25-BCA2CD24-2BC-3C22-3B3-2C21-4A4-2C20-3A6-2C20-2A6-2B20-2A7-2E20-2A6-BE20-3A5-AB21-2A6-AB21-3A3-3A22-6ABA24-4AB2(28-2B)28-B503-2B27-5B25-6B22-4AB2-2B21-2A6-2B20-2A6-A2B19-3A6-BE20-2A7-BE19-3A6-AB20-2A7-AB20-2A6-2A21-3A4-BA22-7AB23-4A3E26-2A2E26-2AB28-BA532-3B24-5A3B22-3A2-2A2B21-2A5-3B20-2A7-B20-2A7-AB19-3A7-AB19-2A7-2AB18-3A7-2A19-3A6-BA20-3A5-AB21-6A3E23-5A2E26-2ABE26-3A28-BA530-4A25-7A23-2A4-3B21-2A6-AB20-2A7-AB19-2A8-AB18-2A8-2A19-2A7-3A18-2A8-BA18-B2A7-AB19-B3A6-E20-B7A2E21-2B5ABE23-3B3AB26-B2A28-B502-A27-6A24-3A-2A2B21-3A5-2A20-3A6-2A19-3A7-2A18-3A8-2A18-2A9-2A17-B2A7-ABA17-EBA8-AB18-E2A7-2E19-EA7-2E20-E2B-4ABE21-2EB5AB23-3E3A28-BA530-3A26-2A5B22-4A-2ABA21-2A5-ABA20-2A7-B2A18-2A8-B2A17-BA9-BA17-EBA9-BA16-2EB8-2AB17-EB8-A2E18-2E8-2E19-EA7-BE20-EBA3-3AB21-BE7A23-B3E2A28-2B500-A29-A2B25-4A3E23-3A3-2EB21-2A5-2EBA18-B2A7-EBA17-EBA8-EBA16-EB10-EB17-EB9-2EB16-2B9-2E18-2B8-2(BE19-2B7-A)B21-BA4-3A22-2B5A26-4B530-2B27-3A2E24-5A2E22-3A4-3E19-EB2A5-3EB17-EBA8-2EB17-EB9-2EB16-BE10-2E17-2B9-2E17-3B8-BE19-BA7-AB20-B2A5-2A22-2BA3-3A23-2BA-2A26-2BAB28-BE499-B30-AB26-4ABE23-6ABE21-EB2A4-B2E19-2E8-2(3E17-2B9-)2E17-2BA8-B2E18-2B8-BE20-BA6-AB21-2BA4-2A23-B2A2-2A25-BA-2A27-BAB28-BE498-B2(30-A)26-6AB22-EB3A-2ABE20-2E6-AB2E18-2B8-B2E17-3B8-B2E18-2B8-BE20-BA6-AB21-2BA5-AB22-B2A3-2A24-2B2-2A26-2B2A28-2B28-BE28-2B498-B30-A27-5A24-EB6A22-2EB3-3AB20-2B6-2ABE19-2B7-ABE20-BA6-ABE20-B2A5-AB22-2BA3-2A24-BA2-3A25-BA-2A27-B2A27-3B27-B2E28-BE528-B30-B27-2BABA24-2EBA-B2A22-2B5-3A22-BA5-2AB21-2BA4-2AB22-2BA3-2A24-BA3-2A25-2B-2A27-B2A28-B2A27-3B27-B2E28-BE28-2B528-B29-BEB25-2EBAEBA24-BA2-EB2A23-B2A3-2A24-B2A2-3A24-2B2-3A25-2B-2A27-B3A27-B2A27-2BA28-BEB2(27-B2E)28-B559-B28-2B2E26-B3AEBA25-2B2ABA26-2B-B4(A27-3B)28-BEB2(28-BE)28-B2E28-B619-B3E27-B3EB27-2BEB27-B-2B27-B2-3(B27-2BE)2(28-BE)29-BE29-B27-
