model
size = 15 31 32, scale = 0.05, origin = -y
material deform = 1, fade = true, lighting = smooth, roughness = 0.3, metalness = 0.6
  colors = A:#2ACE79 B:#555 C:#4D9DE0 D:#E4AB00 E:#9CF F:#444 G:#F49F66 H:#FF0 I:#1A3D5E J:#0FD K:#111
voxels
82-G14-G689-3(D14-)D341-D2-C2-D7-D3-C3-D10-C24-C3-3D3-C3-2(AC2-D3AD2-CA2-)AC2-D3AD2-CA-D2(A3-D3AD3-A2D)A4-DAD4-A2(2D5-DAD5-)D7-D14-D224-A12-D3AD9-CD3ADC7-CAD3ADAC5-DACD3ADCAD3-2AC-D3AD-C2A2-2AC-D3AD-C2A-DAC2-5A2-CA2DAC2-D3AD2-CA2DAC3-3C3-CADCA5-C5-A2CA5-C5-ACDA11-A2D13-D232-C13-3C12-3C10-CD3ADC7-2CAC3A2C5-2C2AC4ACD3-DAC-5A-3A2-2AC-5A-C2A-DAC2-5A2-CADCAC2-5A2-CA2CAC2-D3CD2-CA2CA10-2A2CA11-ACDA11-AD95-2(4BF10-)B2F2B10-B2F2B12-F88-3A11-5A10-5A9-2DC2A2D7-2(C2A)DAC5-2C2AC5AD3-D2C2AC6A3-2AC-5A-3A2-AC2-5A-C2A-DAC-7A-2ADC2A-7A-2A2C2A-2(D2C)D-2A2CA10-2ACDA11-AD96-2FB10-7B8-2B2(-B)F8-FB-F-2B8-FB2F3B9-2BF2B10-5B11-F2B42-3D11-C3AC10-C3AC9-D5AD7-CDAC-3AC6-C2AC4AC5-D3A-A-3AD3-5A-A-4A3-3AC2(A-)AC3A-D2A-C2(A-)A2C2ADC2A-C2(A-)AC-2A2C-A-7A-A-2C2A-DCDADCD-2ACDA11-AD110-B2F2B8-9B7-F2-B2-2F7-2(B2-)B8-2B-B-2B8-2B2(-B)F8-F5BF8-F4BF10-5D10-5C10-DA3D9-2(D5AD8-)DA3-AD7-CD6AC5-D8AC5-3A2-A-3AD3-4A2-A-4A2-D2A-2(A2-)3AD-C2A-C2-A2-C-2A2C2(-A)2(2-A)-A-2C2A-A-3A-A-2ACDA2-DCDADCD2-AD124-F2(B2F)7-9B3(6-2B2-B2-2B)6-2B2(2-B)8-B2-B-2B8-2B-B-2B8-7D8-7C8-C5AC7-D3A-2AD7-C2A2-3AC6-C2A3-2AC6-C7AC5-D8ACD4-3A2-A2-3A3-D3A2-A2-3A3-CA-C2(2-A)CAD-C2A-C2-A2-C-2A2C2A-2(A2-)A-2ACD2A-7A-2AD4-DCDADCD126-2BF4B2FB5-4B-B-3B5-3B2(2-B)F5-3B2-B2-2B6-2B2-B2-2B6-F2(B2-)2B6-2B2-B2-2B6-3B2(-B)F8-3F3EF8-DBE-2ED7-CB2E-2E2C6-CB2E-E-BC6-D-E2-E2AD6-CBE3-EBC5-D2A-5ACD4-9ACA4-3A2-A2-3A3-D3A2-A2-3AD2-2(CA)2(2-A)CAC-C2A-C2-A2-C-2A2C2A-C2-A2-C-2AD-D2-7A2-A5-2(D2C)D126-2BF4B3F5-3B2-B-2BF5-3B2-B2-2B6-2B2(2(2-B)F6-2F)2-B2-2B6-2B2-B-2B7-8B8-2B3E2B8-FBE-EBF7-DB2E-EBD7-CB2E-2EBC6-C-E2-EA-C6-DBE3-EBD5-2(3A-)2A5-11A4-D2A2-A2-3A3-C3A2-A2-3AD2-CA-C2-A2-C-AC2-CA-A2-A-AC-AD2-D2(A-2A-)A6-7A8-D5CD127-BFB2F4B6-2B2-B2(2-2B6-2B2-E)2-B8-F2-E-2B8-FB2(-E-2B8-2B)3EB9-2B2-E2B8-FBE-EBF8-B2E-EBF7-DB2E-2EBD2(6-CBE3-EBC)5-D8AD5-11A4-D2A2-A-3AD4-C2A2-A-3AC3-CA-2A2(-A)C-AC2-D2(A-2A-)AD5-2A2(-A)9-6A10-5D129-2B2F2BF8-F2(B-)BF8-F2(B-)3(2B8-2B-B-)B2(10-5B)9-3B-3B8-2BE-E2B8-F2E-EBF8-I2E-2EI7-DBE3-EBD6-CBE3-EBC6-C7AC5-D3A-A-3AD4-C3A2(-A)CAC4-2(CA)2(-A)CAC4-DAC2(A-)ACAD7-A-3A10-5A10-2AD2A12-D132-B2F2B10-5B10-2B2FB10-FB3F2(10-F3BF)10-4BF10-5B10-FB-BF9-2BE-E2B8-FE3-BF2(8-IE3-EI)7-DBE3-EBD6-D7AD5-C3A-A-2AC6-2CA-3A2C5-CA-C3AC-AC4-DA-C3AC-AD7-C3AC10-4A12-ADA148-2(B14-)2(F14-)B14-B13-3B11-2(5B10-)BE-EF9-F2E-EJ9-J2E-E2J8-I2E-EBI8-I2E-E2I7-D7AD6-C7AC6-3C4A2C6-D-C3AC-D9-2(ADA12-)ADA253-B13-FBF11-5B10-B3EB10-JE-EJ9-J2E-EJ10-JE-EJ9-2IE-E2I2(8-C5AC)8-DCADACD10-ADA313-B13-FBF11-B3EB10-JE-EJ10-KE-EK10-J2EBJ10-I3EI9-3C2A2C9-5D356-3H11-HG3H10-HG-2H10-HG3H11-IAI11-2IC2I11-CIC28-2(I14-)I313-3H11-2(HG3H10-)HG3H11-3H28-2(I14-)I28-3I312-3H11-5H11-2(3H12-)HGH87-3I298-H13-3(3H12-)G2H13-G88-3I298-H13-3(HGH12-)3G103-I298-3H2(12-HGH)12-2GH12-3G402-3G12-HGH12-H2G12-3G13-G403-3G12-H2G2(12-3G)417-3G12-H2G12-3G13-G418-2(3G12-)3G417-2(3G12-)3G13-G418-2(3G12-)2G434-G13-3G13-G419-2(G14-)G434-G14-G367-
